Workbook
Name Department: MD!$A$19:$A$36
Name LIST_CT: MD!$B$4:$B$11
Name Mth_PP: '>PowerPoint'!$B$2
Name PreviousCell: !A1048576

Sheet >PowerPoint
A2: Tháng | B2: 12

Sheet Định nghĩa
A1: ĐỊNH NGHĨA PHÂN LOẠI Ý TƯỞNG
A3: STT | B3: LOẠI | C3: ĐỊNH NGHĨA
A4: 1 | B4: Tăng năng suất | C4: Giảm lao động, giảm di chuyển, giảm chờ đợi
A5: 2 | B5: Tự động hóa | C5: Áp dụng MMTB để tăng hiệu suất làm việc, tăng an toàn lao động,…
A6: 3 | B6: Giảm hao hụt trong sản xuất | C6: Giảm hao hụt mất đi | D6: Hao hụt
A7: 4 | B7: Tiết kiệm năng lượng | C7: Tiết kiệm điện, nước, xăng dầu,…
A8: 5 | B8: Giảm tỷ lệ phó sản | C8: Giảm tỷ lệ phó sản phát sinh trong sản xuất | D8: Hao hụt
A9: 6 | B9: Gia tăng giá trị phó sản | C9: Xử lý tái sử dụng phó sản, gia công phó sản để bán
A10: 7 | B10: Kiểm soát giá mua
A11: 8 | B11: Khác
A15: BỘ PHẬN
A17: STT | B17: BỘ PHẬN
A18: 1 | B18: SX PET
A19: 2 | B19: SX HDPE
A20: 3 | B20: Tự động hóa
A21: 4 | B21: Phòng Mua
A22: 5 | B22: Kỹ Thuật
A23: 6 | B23: Kế Toán Quản Trị
A24: 7 | B24: Kế Toán Tài Chính
A25: 8 | B25: Quản Lý Chất Lượng HDPE
A26: 9 | B26: Quản Lý Chất Lượng PET
A27: 10 | B27: Kho
A28: 11 | B28: Cung ứng
A29: 12 | B29: R&D
... A34: 17 | B34: VPGĐ

Sheet Nội dung
C4: KẾT QUẢ THỰC HIỆN TIẾT KIỆM
C6: CHI PHÍ BÌNH QUÂN / TẤN
C8: PHÂN TÍCH NHÂN TỐ TÁC ĐỘNG CHI PHÍ /TẤN
C10: KẾ HOẠCH ĐẠT MỤC TIÊU

Sheet Trình bày
A2: Link
A3: 2023-SANXUAT-TK-303 | B3: Sản xuất | C3: 1. GIẢM TỶ LỆ PHÓ SẢN PHÁT SINH - XỬ LÝ B8 NGAY TẠI CHUYỀN.
C5: Trước cải tiến | E5: Sau cải tiến
C6: Chai B8 được lựa ra -> ép kiện -> lưu kho -> băm lại -> rửa nóng -> rửa lạnh -> phối trộn 25% Tỷ lệ chai B8: 6% | E6: Sắp xếp lại nhân công lựa và trang bị công cụ dao, kéo, kềm để xử lý các chai này trong lúc sản xuất để đưa vào Băm, không lưu kho. Tỷ lệ chai B8: 0%
C8: Sau cải tiến giảm tỷ lệ phó sản chai dơ B8 phát sinh tại chuyền từ 6% còn 0% => giảm giá thành 20 USD/tấn.
A22: 2023-SANXUAT-TK-706 | B22: Sản xuất | C22: 2. GIẢM TỶ LỆ PHÓ SẢN PHÁT SINH - QUAY ĐẦU RỬA LẠI ZIGZAG, TOMRA ĐỂ THU HỒI VẢY TẠO HẠT
C23: Trước cải tiến | E23: Sau cải tiến
C24: Phó sản sinh ra -> lưu kho -> phân loại -> xử lý theo từng loại phó sản Tỷ lệ zigzag: 4,9% Tỷ lệ Tomra: 3,2% | E24: Phó sản sinh ra -> phân loại + xử lý quay đầu tại chuyền Tỷ lệ zigzag: 0,1% Tỷ lệ Tomra: 0,6%
C25: Sau cải tiến quay đầu phó sản Zigzag, Tomra => giảm 29$/ tấn
A28: 2023-VANPHONG-TK-466 | B28: Tự động hóa | C28: 3. CẢI TIẾN LỘT NHÃN BÌNH LAVIE 5 GALLON + CẤP LIỆU VÀO MÁY BĂM CARN-01
C30: Trước cải tiến | E30: Sau cải tiến
C31: Lột nhãn bằng tay -> bỏ bình sau lột nhãn vào bao Jumbo -> kéo bao Jumbo đến máy băm để băm. Khâu lột nhãn : cần 5 người Khâu băm: cần 2 người Tổng cộng: 7 người | E31: 1. Lắp đặt máy khò nhiệt để dễ lột nhãn 2. Đặt máy khò gần máy băm 3. Công nhân lột nhãn nhanh -> bỏ thẳng và băng tải dẫn lên máy băm => tiết kiêm được 2 nhân công => nhân sự cần cho công đoạn này: 5 người
C32: Sau cải tiến => giảm giá thành 10 USD/tấn
A46: RECKT-23.182.045 | B46: Tự động hóa | C46: 4. CẢI TIẾN LẮP THIẾT BỊ XẢ BAO JUMBO VẢY 500kg TỰ ĐỘNG - GIẢM NGƯỜI CHUYỀN RỬA
C48: Trước cải tiến | E48: Sau cải tiến
C49: - Xe nâng nâng bao vảy lên vị trí khung đỡ để nhân viên mở đáy bao -> đặt lên khung -> nhân viên này phụ trách xả vảy ra khỏi bao (thường xuyên dùng dụng cụ tác động vào bao để vảy rơi xuống) - Mỗi trạm xả bao cần xe nâng và 1 nhân viên đứng xả vảy | E49: Lắp đặt Palang xả bao tự động: nhân viên dùng xe nâng tay kéo bao Jumbo đến vị trí cần nạp liêu, dùng Palang cẩu bao lên và bấm nút xả bao tự động. (Palang có hệ thống vỗ bao tự động) => Giảm 1 xe nâng và 0,5 công | G49: Hiện tại đã làm 5 trạm:
G50: Rửa nóng 1
G51: Rửa lạnh 1
G52: Rửa lạnh 2
G53: Star 2
G54: Star 3
G55: 257tr/hệ
A66: 2023-SANXUAT-TK-705 | B66: Sản xuất | C66: 5. ĐẦU TƯ XE NÂNG CÂN ĐIỆN TỬ, GIẢM NGƯỜI CHUYỀN RỬA
C68: Trước cải tiến | E68: Sau cải tiến
C69: Vảy sạch được cân bằng cân bàn: Nhân viên đóng gói bao vảy từ máy rửa khi khối lượng gần đầy thì dùng xe nâng dầu nâng lên cân bàn kiểm tra khối lượng, nếu thiếu thì châm thêm, nếu dư thì xúc ra bớt. Nhân công đóng gói: 1 người Nhân công đứng cân: 1 người Xe nâng: 1 | E69: Đầu tư xe nâng tay có cân: Bao vảy đặt trên xe nâng có cân -> khi đủ khối lượng thì nhân viên kéo bao ra. Nhân công đóng gói: 1 người => giảm 1 người, 1 xe nâng + 1 tài xế | G69: Đã đầu tư bao nhiêu cái, giá bao nhiêu?
C70: Sau cải tiến xả bao jumbo và xe nâng có cân điện tử => giảm giá thành 2 USD/tấn.
H71: Đã mua 5 cái, giá ~ 38tr/cái
A89: 2023-VANPHONG-TK-560 | B89: Tự động hóa | C89: 6. CẢI TIẾN QUY TRÌNH LỰA CHAI TRÊN CHUYỀN BĂM PET 1 và 2 | G89: Tự động hóa
C91: Trước cải tiến | E91: Sau cải tiến
C92: Trên băng tải lựa chai của chuyển băm 1 và 2 các nhân viên vừa lựa chai và xử lý nhãn. Chuyền Băm 1: cần 8 người Chuyền Băm 2: cần 10 người | E92: Lắp thêm các vách ngăn bằng inox, phân 2 người đầu tiên chỉ lựa chai, chai còn nhãn thì bỏ vào vách ngăn inox để những người tiếp theo xử lý lột nhãn rồi bỏ chai lại vào băng tải. Chuyền Băm 1: cần 6 người => tiết kiệm 2 người Chuyền Băm 2: cần 9 người => tiết kiệm 1 người
C93: Sau cải tiến => giảm giá thành 2 USD/tấn.
A110: 2023-SANXUAT-TK-705 | B110: Sản xuất | C110: 7. CẢI TIẾN GIẢM XE NÂNG CHUYỀN TẠO HẠT
C112: Trước cải tiến | E112: Sau cải tiến | G112: Đã đầu tư bao nhiêu cái, giá bao nhiêu?
C113: Các vị trí ra hạt dùng xe nâng lớn (dầu hoặc điện) để lấy hạt. Nguy cơ va chạm, mất an toàn lao động và ảnh hưởng khói dầu đến sản phẩm. | E113: Đàu tư xe nâng tay điện. Nhân viên vận hành xử dụng xe nâng tay để lấy hạt => giảm 2 tài xế và xe nâng lớn | G113: Đã mua 1 cái, giá ~ 81tr/cái
C114: Sau cải tiến => giảm giá thành 2 USD/tấn thành vảy rPET băm chưa rửa.
A135: 2024-SANXUAT-TK-186 | B135: Sản xuất | C135: 8. XỬ LÝ PHÓ SẢN HD QMT LOẠI 2 THÀNH VẢY HV01.3 | G135: 8. XỬ LÝ PHÓ SẢN HD THỔI TRONG VẢY L2 QMT
C137: Trước cải tiến | E137: Sau cải tiến
C138: Phó sản loại 2 từ vảy QMT chưa có hướng xử lý để tồn kho | E138: Đem tách màu -> vảy HV01.3 -> tạo ra hạt MBF01. => tăng giá trị sản phẩm | G138: 160012457 | H138: Phó Sản HD Thổi Trong Vảy L1 QMT
C139: Sau cải tiến đã xử lý 180,9 tấn, thu lợi 668 triệu. | G139: 160012458 | H139: Phó Sản HD Thổi Trong Vảy L2 QMT
G141: 160012450 | H141: Vảy HD Thổi Trong HV-01.3
...

Sheet Tóm tắt
A1: 1. | B1: ="TÌNH HÌNH THỰC HIỆN CẢI TIẾN ĐẾN THÁNG "&TEXT(Mth_PP,"00")&" /2025" -> TÌNH HÌNH THỰC HIỆN CẢI TIẾN ĐẾN THÁNG 12 /2025
A3: STT | B3: Nội dung | C3: Giá trị
A4: 1 | B4: Mục tiêu giá trị cải tiến tiết kiệm 2025 (tỷ) | C4: =Q21 -> 50000
A5: 2 | B5: % Mục tiêu giá trị tiết kiệm / doanh thu 2025 | C5: =C4/Q24 -> 0.024225368
A6: 3 | B6: ="Giá trị tiết kiệm thực hiện lũy kế đến T"&Mth_PP&"/2025 (tỷ)" -> Giá trị tiết kiệm thực hiện lũy kế đến T12/2025 (tỷ) | C6: =Q14 -> 38926.054
A7: 4 | B7: % thực hiện giá trị tiết kiệm / doanh thu | C7: =Q18 -> 0.02528975
A8: 5 | B8: ="Đến tháng "&Mth_PP&" tỷ lệ % hoàn thành mục tiêu giá trị tiết kiệm 2025:" -> Đến tháng 12 tỷ lệ % hoàn thành mục tiêu giá trị tiết kiệm 2025: | C8: =C6/C4 -> 0.77852108
R10: 1 | S10: 2 | T10: 3 | U10: 4 | V10: 5 | W10: 6 | X10: 7 | Y10: 8 | Z10: 9 | AA10: 10 | AB10: 11 | AC10: 12
A11: STT | B11: Diễn giải | C11: 2023 | D11: T1/24 | E11: T2 | F11: T3 | G11: T4 | H11: T5 | I11: T6 | J11: T7 | K11: T8 | L11: T9 | M11: T10 | N11: T11 | O11: T12 | P11: 2024 | Q11: Lũy kế 2025 | R11: T1/25 | S11: T2 | T11: T3 | U11: T4 | V11: T5 | W11: T6 | X11: T7 | Y11: T8 | Z11: T9 | AA11: T10 | AB11: T11 | AC11: T12
A12: 1 | B12: Số ý tưởng cải tiến khả thi | C12: 15 | D12: 16 | E12: 2 | F12: 14 | G12: 13 | H12: 15 | I12: 37 | J12: 27 | K12: 27 | L12: 29 | M12: 25 | N12: 41 | O12: 21 | P12: =SUM(D12:O12) -> 267 | Q12: =SUM(R12:AC12) -> 250 | R12: 3 | S12: 3 | T12: 22 | U12: 42 | V12: 44 | W12: 24 | X12: 20 | Y12: 17 | Z12: 15 | AA12: 10 | AB12: 25 | AC12: 25
A13: 2 | B13: - Trong đó số ý tưởng đem lại giá trị tiết kiệm | C13: 15 | D13: 8 | E13: 2 | F13: 2 | G13: 2 | H13: 4 | I13: 1 | J13: 4 | K13: 2 | L13: 4 | M13: 2 | N13: 9 | O13: 5 | P13: =SUM(D13:O13) -> 45 | Q13: =SUM(R13:AC13) -> 78 | R13: 3 | S13: 3 | T13: 8 | U13: 9 | V13: 9 | W13: 9 | X13: 6 | Y13: 7 | Z13: 7 | AA13: 4 | AB13: 6 | AC13: 7
A14: 3 | B14: Giá trị tiết kiệm đã thực hiện (trđ) | C14: 8910 | D14: ='GTTK chung'!AX143/10^6 -> 1373.0045 | E14: ='GTTK chung'!AY143/10^6 -> 800.03973 | F14: ='GTTK chung'!AZ143/10^6 -> 1588.4742 | G14: ='GTTK chung'!BA143/10^6 -> 1473.7039 | H14: ='GTTK chung'!BB143/10^6 -> 1692.3523 | I14: ='GTTK chung'!BC143/10^6 -> 1461.3109 | J14: ='GTTK chung'!BD143/10^6 -> 2024.4786 | K14: ='GTTK chung'!BE143/10^6 -> 5210.0133 | ... O14: ='GTTK chung'!BI143/10^6 -> 3832.2542 | P14: =SUM(D14:O14) -> 35633.354 | Q14: =SUM(R14:AC14) -> 38926.054 | R14: =IF(Mth_PP>=R$10,'GTTK chung'!AJ143/10^6,0) -> 2819.4198 | S14: =IF(Mth_PP>=S$10,'GTTK chung'!AK143/10^6,0) -> 3540.6355 | T14: =IF(Mth_PP>=T$10,'GTTK chung'!AL143/10^6,0) -> 1384.2882 | U14: =IF(Mth_PP>=U$10,'GTTK chung'!AM143/10^6,0) -> 2451.4174 | V14: =IF(Mth_PP>=V$10,'GTTK chung'!AN143/10^6,0) -> 6343.0406 | W14: =IF(Mth_PP>=W$10,'GTTK chung'!AO143/10^6,0) -> 3559.933 | X14: =IF(Mth_PP>=X$10,'GTTK chung'!AP143/10^6,0) -> 3634.5071 | Y14: =IF(Mth_PP>=Y$10,'GTTK chung'!AQ143/10^6,0) -> 5611.7852 | ... AC14: =IF(Mth_PP>=AC$10,'GTTK chung'!AU143/10^6,0) -> 1603.54
A15: 4 | B15: Giá trị tiết kiệm kế hoạch (trđ) | D15: ='GTTK chung'!AX147/10^6 -> 1133.6667 | E15: ='GTTK chung'!AY147/10^6 -> 1173.6667 | F15: ='GTTK chung'!AZ147/10^6 -> 1283.6667 | G15: ='GTTK chung'!BA147/10^6 -> 1283.6667 | H15: ='GTTK chung'!BB147/10^6 -> 1283.6667 | I15: ='GTTK chung'!BC147/10^6 -> 2535.0952 | J15: ='GTTK chung'!BD147/10^6 -> 1825.0952 | K15: ='GTTK chung'!BE147/10^6 -> 1825.0952 | ... O15: ='GTTK chung'!BI147/10^6 -> 5385.0952 | P15: =SUM(D15:O15) -> 22804 | Q15: =SUM(R15:AC15) -> 50000 | R15: =IF(Mth_PP>=R$10,'GTTK chung'!AJ147/10^6,0) -> 2980 | S15: =IF(Mth_PP>=S$10,'GTTK chung'!AK147/10^6,0) -> 2990 | T15: =IF(Mth_PP>=T$10,'GTTK chung'!AL147/10^6,0) -> 4459 | U15: =IF(Mth_PP>=U$10,'GTTK chung'!AM147/10^6,0) -> 3365 | V15: =IF(Mth_PP>=V$10,'GTTK chung'!AN147/10^6,0) -> 3355 | W15: =IF(Mth_PP>=W$10,'GTTK chung'!AO147/10^6,0) -> 6159 | X15: =IF(Mth_PP>=X$10,'GTTK chung'!AP147/10^6,0) -> 3415 | Y15: =IF(Mth_PP>=Y$10,'GTTK chung'!AQ147/10^6,0) -> 3510 | ... AC15: =IF(Mth_PP>=AC$10,'GTTK chung'!AU147/10^6,0) -> 8368
A16: 5 | B16: % Giá trị tiết kiệm đã thực hiện sv kế hoạch | D16: =IFERROR(D14/D15,0) -> 1.2111184 | E16: =IFERROR(E14/E15,0) -> 0.68165839 | F16: =IFERROR(F14/F15,0) -> 1.2374507 | G16: =IFERROR(G14/G15,0) -> 1.1480425 | H16: =IFERROR(H14/H15,0) -> 1.3183736 | I16: =IFERROR(I14/I15,0) -> 0.57643233 | J16: =IFERROR(J14/J15,0) -> 1.1092454 | K16: =IFERROR(K14/K15,0) -> 2.8546528 | ... AC16: =IFERROR(AC14/AC15,0) -> 0.19162763
A17: 6 | B17: Doanh thu (trđ) | C17: 685519.22 | D17: 95961.617 | E17: 68939.747 | F17: 92109.508 | G17: 97489.093 | H17: 102365 | I17: 68093.17 | J17: 56451.27 | K17: 154027.87 | L17: 156829.9 | M17: 116812.6 | N17: 76126.14 | O17: 105815.34 | P17: =SUM(D17:O17) -> 1191021.2 | Q17: =SUM(R17:AC17) -> 1539202.8 | R17: 114462.51 | S17: 187999.46 | T17: 150253.33 | U17: 125429.65 | V17: 152067.14 | W17: 119134.67 | X17: 137991.41 | Y17: 168442.65 | Z17: 84710.435 | AA17: 108928.56 | AB17: 88347.881 | AC17: 101435.08 | AD17: Tự gõ thêm
A18: 7 | B18: % Giá trị cải tiến tiết kiệm / doanh thu | C18: =IFERROR(C14/C17,0) -> 0.012997447 | D18: =IFERROR(D14/D17,0) -> 0.014307851 | E18: =IFERROR(E14/E17,0) -> 0.011604912 | F18: =IFERROR(F14/F17,0) -> 0.017245496 | G18: =IFERROR(G14/G17,0) -> 0.015116603 | H18: =IFERROR(H14/H17,0) -> 0.016532529 | I18: =IFERROR(I14/I17,0) -> 0.021460462 | J18: =IFERROR(J14/J17,0) -> 0.03586241 | ... AC18: =IFERROR(AC14/AC17,0) -> 0.015808535
B21: Giá trị tiết kiệm kế hoạch (trđ) - Đạt bổ lại từ T8 | D21: ='GTTK chung'!AX147/10^6 -> 1133.6667 | E21: ='GTTK chung'!AY147/10^6 -> 1173.6667 | F21: ='GTTK chung'!AZ147/10^6 -> 1283.6667 | G21: ='GTTK chung'!BA147/10^6 -> 1283.6667 | H21: ='GTTK chung'!BB147/10^6 -> 1283.6667 | I21: ='GTTK chung'!BC147/10^6 -> 2535.0952 | J21: ='GTTK chung'!BD147/10^6 -> 1825.0952 | K21: ='GTTK chung'!BE147/10^6 -> 1825.0952 | ... O21: ='GTTK chung'!BI147/10^6 -> 5385.0952 | P21: =SUM(D21:O21) -> 22804 | Q21: =SUM(R21:AC21) -> 50000 | R21: ='GTTK chung'!AJ147/10^6 -> 2980 | S21: ='GTTK chung'!AK147/10^6 -> 2990 | T21: ='GTTK chung'!AL147/10^6 -> 4459 | U21: ='GTTK chung'!AM147/10^6 -> 3365 | V21: ='GTTK chung'!AN147/10^6 -> 3355 | W21: ='GTTK chung'!AO147/10^6 -> 6159 | X21: ='GTTK chung'!AP147/10^6 -> 3415 | Y21: ='GTTK chung'!AQ147/10^6 -> 3510 | ... AC21: ='GTTK chung'!AU147/10^6 -> 8368
B22: Giá trị tiết kiệm kế hoạch (trđ) - Cũ | D22: ='GTTK chung'!AX151/10^6 -> 1133.6667 | E22: ='GTTK chung'!AY151/10^6 -> 1173.6667 | F22: ='GTTK chung'!AZ151/10^6 -> 1283.6667 | G22: ='GTTK chung'!BA151/10^6 -> 1283.6667 | H22: ='GTTK chung'!BB151/10^6 -> 1283.6667 | I22: ='GTTK chung'!BC151/10^6 -> 2455.0952 | J22: ='GTTK chung'!BD151/10^6 -> 1755.0952 | K22: ='GTTK chung'!BE151/10^6 -> 1755.0952 | ... O22: ='GTTK chung'!BI151/10^6 -> 5385.0952 | P22: =SUM(D22:O22) -> 22374 | Q22: =SUM(R22:AC22) -> 0
B24: Doanh thu NS (trđ) | D24: 67851.85 | E24: 87319.475 | F24: 92151.1 | G24: 104778.43 | H24: 115974.55 | I24: 114450.4 | J24: 168962.82 | K24: 163198.48 | L24: 164820.86 | M24: 180708.39 | N24: 171078.56 | O24: 173350.77 | P24: =SUM(D24:O24) -> 1604645.7 | Q24: =SUM(R24:AC24) -> 2063952.1 | R24: 100827.36 | S24: 122613.53 | T24: 119512.19 | U24: 131181.8 | V24: 173339.44 | W24: 166096.72 | X24: 190799.85 | Y24: 189650.59 | Z24: 224394.41 | AA24: 228412.04 | AB24: 209261.95 | AC24: 207862.2

Sheet Thống kê theo phân loại
A1: 2. | B1: GIÁ TRỊ TIẾT KIỆM THEO NHÓM MỤC TIÊU
B3: ĐVT: triệu đồng | S3: =S4&".24" -> 2.24 | T3: =T4&".24" -> 3.24 | U3: =U4&".24" -> 4.24 | V3: =V4&".24" -> 5.24 | W3: =W4&".24" -> 6.24 | X3: =X4&".24" -> 7.24 | Y3: =Y4&".24" -> 8.24 | Z3: =Z4&".24" -> 9.24 | ... AC3: =AC4&".24" -> 12.24
A4: STT | B4: Nhóm mục tiêu | C4: 1.24 | D4: 2.24 | E4: 3.24 | F4: 4.24 | G4: 5.24 | H4: 6.24 | I4: 7.24 | J4: 8.24 | K4: 9.24 | L4: 10.24 | M4: 11.24 | N4: 12.24 | O4: 2024 | P4: 2025 | Q4: %2025 | R4: 1.25 | S4: 2 | T4: 3 | U4: 4 | V4: 5 | W4: 6 | X4: 7 | Y4: 8 | Z4: 9 | AA4: 10 | AB4: 11 | AC4: 12 | AF4: Rank | AG4: STT | AH4: Nhóm mục tiêu | AI4: 2025 | AJ4: 1.25 | AK4: 2 | AL4: 3 | AM4: 4 | AN4: 5 | AO4: 6 | AP4: 7 | AQ4: 8 | AR4: 9 | AS4: 10 | AT4: 11 | AU4: 12 | AW4: Số liệu_Rank
A5: 1 | B5: =INDEX($AH$5:$AH$12,MATCH($A5,$AF$5:$AF$12,0)) -> Kiểm soát giá mua | C5: =SUMIFS('GTTK chung'!AX$4:AX$143,'GTTK chung'!$E$4:$E$143,$B5)/10^6 -> 585.03792 | D5: =SUMIFS('GTTK chung'!AY$4:AY$143,'GTTK chung'!$E$4:$E$143,$B5)/10^6 -> 41.204 | E5: =SUMIFS('GTTK chung'!AZ$4:AZ$143,'GTTK chung'!$E$4:$E$143,$B5)/10^6 -> 901.89337 | F5: =SUMIFS('GTTK chung'!BA$4:BA$143,'GTTK chung'!$E$4:$E$143,$B5)/10^6 -> 668.32915 | G5: =SUMIFS('GTTK chung'!BB$4:BB$143,'GTTK chung'!$E$4:$E$143,$B5)/10^6 -> 229.23847 | H5: =SUMIFS('GTTK chung'!BC$4:BC$143,'GTTK chung'!$E$4:$E$143,$B5)/10^6 -> 239.86231 | I5: =SUMIFS('GTTK chung'!BD$4:BD$143,'GTTK chung'!$E$4:$E$143,$B5)/10^6 -> 682.26801 | J5: =SUMIFS('GTTK chung'!BE$4:BE$143,'GTTK chung'!$E$4:$E$143,$B5)/10^6 -> 434.30448 | ... N5: =SUMIFS('GTTK chung'!BI$4:BI$143,'GTTK chung'!$E$4:$E$143,$B5)/10^6 -> 46.896868 | O5: =SUM(C5:N5) -> 12553.577 | P5: =SUM(R5:AC5) -> 13135.545 | Q5: =P5/P$13 -> 0.33744867 | R5: =SUMIFS(AJ$5:AJ$12,$AF$5:$AF$12,$A5) -> 1578.087 | S5: =SUMIFS(AK$5:AK$12,$AF$5:$AF$12,$A5) -> 2434.8426 | T5: =SUMIFS(AL$5:AL$12,$AF$5:$AF$12,$A5) -> 130.49078 | U5: =SUMIFS(AM$5:AM$12,$AF$5:$AF$12,$A5) -> 1048.6522 | V5: =SUMIFS(AN$5:AN$12,$AF$5:$AF$12,$A5) -> 1068.1828 | W5: =SUMIFS(AO$5:AO$12,$AF$5:$AF$12,$A5) -> 523.52433 | X5: =SUMIFS(AP$5:AP$12,$AF$5:$AF$12,$A5) -> 1888.3505 | Y5: =SUMIFS(AQ$5:AQ$12,$AF$5:$AF$12,$A5) -> 2645.2808 | ... AC5: =SUMIFS(AU$5:AU$12,$AF$5:$AF$12,$A5) -> 348.41577 | AF5: =_xlfn.RANK.AVG($AW5,$AW$5:$AW$12,0) -> 6 | AG5: 1 | AH5: Tăng năng suất | AI5: =SUM(AJ5:AU5) -> 769.90102 | AJ5: =SUMIFS('GTTK chung'!AJ$4:AJ$143,'GTTK chung'!$E$4:$E$143,$AH5)/10^6 -> 233.96003 | AK5: =SUMIFS('GTTK chung'!AK$4:AK$143,'GTTK chung'!$E$4:$E$143,$AH5)/10^6 -> 192.87787 | AL5: =SUMIFS('GTTK chung'!AL$4:AL$143,'GTTK chung'!$E$4:$E$143,$AH5)/10^6 -> 191.42907 | AM5: =SUMIFS('GTTK chung'!AM$4:AM$143,'GTTK chung'!$E$4:$E$143,$AH5)/10^6 -> 151.63405 | AN5: =SUMIFS('GTTK chung'!AN$4:AN$143,'GTTK chung'!$E$4:$E$143,$AH5)/10^6 -> 0 | AO5: =SUMIFS('GTTK chung'!AO$4:AO$143,'GTTK chung'!$E$4:$E$143,$AH5)/10^6 -> 0 | AP5: =SUMIFS('GTTK chung'!AP$4:AP$143,'GTTK chung'!$E$4:$E$143,$AH5)/10^6 -> 0 | AQ5: =SUMIFS('GTTK chung'!AQ$4:AQ$143,'GTTK chung'!$E$4:$E$143,$AH5)/10^6 -> 0 | ... AU5: =SUMIFS('GTTK chung'!AU$4:AU$143,'GTTK chung'!$E$4:$E$143,$AH5)/10^6 -> 0 | AW5: =AI5+COUNTIFS(AI$5:AI5,AI5)*0.01 -> 769.91102
A6: 2 | B6: =INDEX($AH$5:$AH$12,MATCH($A6,$AF$5:$AF$12,0)) -> Giảm hao hụt trong sản xuất | C6: =SUMIFS('GTTK chung'!AX$4:AX$143,'GTTK chung'!$E$4:$E$143,$B6)/10^6 -> 0 | D6: =SUMIFS('GTTK chung'!AY$4:AY$143,'GTTK chung'!$E$4:$E$143,$B6)/10^6 -> 0 | E6: =SUMIFS('GTTK chung'!AZ$4:AZ$143,'GTTK chung'!$E$4:$E$143,$B6)/10^6 -> 19.545754 | F6: =SUMIFS('GTTK chung'!BA$4:BA$143,'GTTK chung'!$E$4:$E$143,$B6)/10^6 -> 19.545754 | G6: =SUMIFS('GTTK chung'!BB$4:BB$143,'GTTK chung'!$E$4:$E$143,$B6)/10^6 -> 50.49203 | H6: =SUMIFS('GTTK chung'!BC$4:BC$143,'GTTK chung'!$E$4:$E$143,$B6)/10^6 -> 94.041796 | I6: =SUMIFS('GTTK chung'!BD$4:BD$143,'GTTK chung'!$E$4:$E$143,$B6)/10^6 -> 19.545754 | J6: =SUMIFS('GTTK chung'!BE$4:BE$143,'GTTK chung'!$E$4:$E$143,$B6)/10^6 -> 108.85238 | ... N6: =SUMIFS('GTTK chung'!BI$4:BI$143,'GTTK chung'!$E$4:$E$143,$B6)/10^6 -> 1177.3296 | O6: =SUM(C6:N6) -> 3097.1917 | P6: =SUM(R6:AC6) -> 13127.535 | Q6: =P6/P$13 -> 0.3372429 | R6: =SUMIFS(AJ$5:AJ$12,$AF$5:$AF$12,$A6) -> 643.66103 | S6: =SUMIFS(AK$5:AK$12,$AF$5:$AF$12,$A6) -> 440.46678 | T6: =SUMIFS(AL$5:AL$12,$AF$5:$AF$12,$A6) -> 203.81421 | U6: =SUMIFS(AM$5:AM$12,$AF$5:$AF$12,$A6) -> 85.071216 | V6: =SUMIFS(AN$5:AN$12,$AF$5:$AF$12,$A6) -> 4105.9403 | W6: =SUMIFS(AO$5:AO$12,$AF$5:$AF$12,$A6) -> 1061.0261 | X6: =SUMIFS(AP$5:AP$12,$AF$5:$AF$12,$A6) -> 843.26026 | Y6: =SUMIFS(AQ$5:AQ$12,$AF$5:$AF$12,$A6) -> 2168.0207 | ... AC6: =SUMIFS(AU$5:AU$12,$AF$5:$AF$12,$A6) -> 389.25069 | AF6: =_xlfn.RANK.AVG($AW6,$AW$5:$AW$12,0) -> 4 | AG6: 2 | AH6: Gia tăng giá trị phó sản | AI6: =SUM(AJ6:AU6) -> 3965.5121 | AJ6: =SUMIFS('GTTK chung'!AJ$4:AJ$143,'GTTK chung'!$E$4:$E$143,$AH6)/10^6 -> 0 | AK6: =SUMIFS('GTTK chung'!AK$4:AK$143,'GTTK chung'!$E$4:$E$143,$AH6)/10^6 -> 0 | AL6: =SUMIFS('GTTK chung'!AL$4:AL$143,'GTTK chung'!$E$4:$E$143,$AH6)/10^6 -> 56.7825 | AM6: =SUMIFS('GTTK chung'!AM$4:AM$143,'GTTK chung'!$E$4:$E$143,$AH6)/10^6 -> 384.04499 | AN6: =SUMIFS('GTTK chung'!AN$4:AN$143,'GTTK chung'!$E$4:$E$143,$AH6)/10^6 -> 511.7685 | AO6: =SUMIFS('GTTK chung'!AO$4:AO$143,'GTTK chung'!$E$4:$E$143,$AH6)/10^6 -> 497.56731 | AP6: =SUMIFS('GTTK chung'!AP$4:AP$143,'GTTK chung'!$E$4:$E$143,$AH6)/10^6 -> 494.3551 | AQ6: =SUMIFS('GTTK chung'!AQ$4:AQ$143,'GTTK chung'!$E$4:$E$143,$AH6)/10^6 -> 85.67415 | ... AU6: =SUMIFS('GTTK chung'!AU$4:AU$143,'GTTK chung'!$E$4:$E$143,$AH6)/10^6 -> 387.9075 | AW6: =AI6+COUNTIFS(AI$5:AI6,AI6)*0.01 -> 3965.5221
A7: 3 | B7: =INDEX($AH$5:$AH$12,MATCH($A7,$AF$5:$AF$12,0)) -> Khác | C7: =SUMIFS('GTTK chung'!AX$4:AX$143,'GTTK chung'!$E$4:$E$143,$B7)/10^6 -> 0.48 | D7: =SUMIFS('GTTK chung'!AY$4:AY$143,'GTTK chung'!$E$4:$E$143,$B7)/10^6 -> 72 | E7: =SUMIFS('GTTK chung'!AZ$4:AZ$143,'GTTK chung'!$E$4:$E$143,$B7)/10^6 -> 56.96 | F7: =SUMIFS('GTTK chung'!BA$4:BA$143,'GTTK chung'!$E$4:$E$143,$B7)/10^6 -> 80 | G7: =SUMIFS('GTTK chung'!BB$4:BB$143,'GTTK chung'!$E$4:$E$143,$B7)/10^6 -> 98.351589 | H7: =SUMIFS('GTTK chung'!BC$4:BC$143,'GTTK chung'!$E$4:$E$143,$B7)/10^6 -> 90.5256 | I7: =SUMIFS('GTTK chung'!BD$4:BD$143,'GTTK chung'!$E$4:$E$143,$B7)/10^6 -> 337.17721 | J7: =SUMIFS('GTTK chung'!BE$4:BE$143,'GTTK chung'!$E$4:$E$143,$B7)/10^6 -> 828.5918 | ... N7: =SUMIFS('GTTK chung'!BI$4:BI$143,'GTTK chung'!$E$4:$E$143,$B7)/10^6 -> 1799.6019 | O7: =SUM(C7:N7) -> 6923.5434 | P7: =SUM(R7:AC7) -> 4788.5143 | Q7: =P7/P$13 -> 0.12301566 | R7: =SUMIFS(AJ$5:AJ$12,$AF$5:$AF$12,$A7) -> 361.38621 | S7: =SUMIFS(AK$5:AK$12,$AF$5:$AF$12,$A7) -> 165.44825 | T7: =SUMIFS(AL$5:AL$12,$AF$5:$AF$12,$A7) -> 529.66271 | U7: =SUMIFS(AM$5:AM$12,$AF$5:$AF$12,$A7) -> 478.34446 | V7: =SUMIFS(AN$5:AN$12,$AF$5:$AF$12,$A7) -> 301.50613 | W7: =SUMIFS(AO$5:AO$12,$AF$5:$AF$12,$A7) -> 1223.3442 | X7: =SUMIFS(AP$5:AP$12,$AF$5:$AF$12,$A7) -> 179.32877 | Y7: =SUMIFS(AQ$5:AQ$12,$AF$5:$AF$12,$A7) -> 391.68254 | ... AC7: =SUMIFS(AU$5:AU$12,$AF$5:$AF$12,$A7) -> 268.8903 | AF7: =_xlfn.RANK.AVG($AW7,$AW$5:$AW$12,0) -> 1 | AG7: 3 | AH7: Kiểm soát giá mua | AI7: =SUM(AJ7:AU7) -> 13135.545 | AJ7: =SUMIFS('GTTK chung'!AJ$4:AJ$143,'GTTK chung'!$E$4:$E$143,$AH7)/10^6 -> 1578.087 | AK7: =SUMIFS('GTTK chung'!AK$4:AK$143,'GTTK chung'!$E$4:$E$143,$AH7)/10^6 -> 2434.8426 | AL7: =SUMIFS('GTTK chung'!AL$4:AL$143,'GTTK chung'!$E$4:$E$143,$AH7)/10^6 -> 130.49078 | AM7: =SUMIFS('GTTK chung'!AM$4:AM$143,'GTTK chung'!$E$4:$E$143,$AH7)/10^6 -> 1048.6522 | AN7: =SUMIFS('GTTK chung'!AN$4:AN$143,'GTTK chung'!$E$4:$E$143,$AH7)/10^6 -> 1068.1828 | AO7: =SUMIFS('GTTK chung'!AO$4:AO$143,'GTTK chung'!$E$4:$E$143,$AH7)/10^6 -> 523.52433 | AP7: =SUMIFS('GTTK chung'!AP$4:AP$143,'GTTK chung'!$E$4:$E$143,$AH7)/10^6 -> 1888.3505 | AQ7: =SUMIFS('GTTK chung'!AQ$4:AQ$143,'GTTK chung'!$E$4:$E$143,$AH7)/10^6 -> 2645.2808 | ... AU7: =SUMIFS('GTTK chung'!AU$4:AU$143,'GTTK chung'!$E$4:$E$143,$AH7)/10^6 -> 348.41577 | AW7: =AI7+COUNTIFS(AI$5:AI7,AI7)*0.01 -> 13135.555
A8: 4 | B8: =INDEX($AH$5:$AH$12,MATCH($A8,$AF$5:$AF$12,0)) -> Gia tăng giá trị phó sản | C8: =SUMIFS('GTTK chung'!AX$4:AX$143,'GTTK chung'!$E$4:$E$143,$B8)/10^6 -> 0 | D8: =SUMIFS('GTTK chung'!AY$4:AY$143,'GTTK chung'!$E$4:$E$143,$B8)/10^6 -> 0 | E8: =SUMIFS('GTTK chung'!AZ$4:AZ$143,'GTTK chung'!$E$4:$E$143,$B8)/10^6 -> 0 | F8: =SUMIFS('GTTK chung'!BA$4:BA$143,'GTTK chung'!$E$4:$E$143,$B8)/10^6 -> 0 | G8: =SUMIFS('GTTK chung'!BB$4:BB$143,'GTTK chung'!$E$4:$E$143,$B8)/10^6 -> 0 | H8: =SUMIFS('GTTK chung'!BC$4:BC$143,'GTTK chung'!$E$4:$E$143,$B8)/10^6 -> 0 | I8: =SUMIFS('GTTK chung'!BD$4:BD$143,'GTTK chung'!$E$4:$E$143,$B8)/10^6 -> 356.46654 | J8: =SUMIFS('GTTK chung'!BE$4:BE$143,'GTTK chung'!$E$4:$E$143,$B8)/10^6 -> 3324.7192 | ... N8: =SUMIFS('GTTK chung'!BI$4:BI$143,'GTTK chung'!$E$4:$E$143,$B8)/10^6 -> 0 | O8: =SUM(C8:N8) -> 3702.5856 | P8: =SUM(R8:AC8) -> 3965.5121 | Q8: =P8/P$13 -> 0.10187295 | R8: =SUMIFS(AJ$5:AJ$12,$AF$5:$AF$12,$A8) -> 0 | S8: =SUMIFS(AK$5:AK$12,$AF$5:$AF$12,$A8) -> 0 | T8: =SUMIFS(AL$5:AL$12,$AF$5:$AF$12,$A8) -> 56.7825 | U8: =SUMIFS(AM$5:AM$12,$AF$5:$AF$12,$A8) -> 384.04499 | V8: =SUMIFS(AN$5:AN$12,$AF$5:$AF$12,$A8) -> 511.7685 | W8: =SUMIFS(AO$5:AO$12,$AF$5:$AF$12,$A8) -> 497.56731 | X8: =SUMIFS(AP$5:AP$12,$AF$5:$AF$12,$A8) -> 494.3551 | Y8: =SUMIFS(AQ$5:AQ$12,$AF$5:$AF$12,$A8) -> 85.67415 | ... AC8: =SUMIFS(AU$5:AU$12,$AF$5:$AF$12,$A8) -> 387.9075 | AF8: =_xlfn.RANK.AVG($AW8,$AW$5:$AW$12,0) -> 8 | AG8: 4 | AH8: Giảm tỷ lệ phó sản | AI8: =SUM(AJ8:AU8) -> 42.662102 | AJ8: =SUMIFS('GTTK chung'!AJ$4:AJ$143,'GTTK chung'!$E$4:$E$143,$AH8)/10^6 -> 2.325523 | AK8: =SUMIFS('GTTK chung'!AK$4:AK$143,'GTTK chung'!$E$4:$E$143,$AH8)/10^6 -> 0 | AL8: =SUMIFS('GTTK chung'!AL$4:AL$143,'GTTK chung'!$E$4:$E$143,$AH8)/10^6 -> 0 | AM8: =SUMIFS('GTTK chung'!AM$4:AM$143,'GTTK chung'!$E$4:$E$143,$AH8)/10^6 -> 11.872 | AN8: =SUMIFS('GTTK chung'!AN$4:AN$143,'GTTK chung'!$E$4:$E$143,$AH8)/10^6 -> 4.128579 | AO8: =SUMIFS('GTTK chung'!AO$4:AO$143,'GTTK chung'!$E$4:$E$143,$AH8)/10^6 -> 24.336 | AP8: =SUMIFS('GTTK chung'!AP$4:AP$143,'GTTK chung'!$E$4:$E$143,$AH8)/10^6 -> 0 | AQ8: =SUMIFS('GTTK chung'!AQ$4:AQ$143,'GTTK chung'!$E$4:$E$143,$AH8)/10^6 -> 0 | ... AU8: =SUMIFS('GTTK chung'!AU$4:AU$143,'GTTK chung'!$E$4:$E$143,$AH8)/10^6 -> 0 | AW8: =AI8+COUNTIFS(AI$5:AI8,AI8)*0.01 -> 42.672102
A9: 5 | B9: =INDEX($AH$5:$AH$12,MATCH($A9,$AF$5:$AF$12,0)) -> Tự động hóa | C9: =SUMIFS('GTTK chung'!AX$4:AX$143,'GTTK chung'!$E$4:$E$143,$B9)/10^6 -> 386.36125 | D9: =SUMIFS('GTTK chung'!AY$4:AY$143,'GTTK chung'!$E$4:$E$143,$B9)/10^6 -> 92.051947 | E9: =SUMIFS('GTTK chung'!AZ$4:AZ$143,'GTTK chung'!$E$4:$E$143,$B9)/10^6 -> 131.32679 | F9: =SUMIFS('GTTK chung'!BA$4:BA$143,'GTTK chung'!$E$4:$E$143,$B9)/10^6 -> 108.801 | G9: =SUMIFS('GTTK chung'!BB$4:BB$143,'GTTK chung'!$E$4:$E$143,$B9)/10^6 -> 114.8619 | H9: =SUMIFS('GTTK chung'!BC$4:BC$143,'GTTK chung'!$E$4:$E$143,$B9)/10^6 -> 103.7016 | I9: =SUMIFS('GTTK chung'!BD$4:BD$143,'GTTK chung'!$E$4:$E$143,$B9)/10^6 -> 57.6468 | J9: =SUMIFS('GTTK chung'!BE$4:BE$143,'GTTK chung'!$E$4:$E$143,$B9)/10^6 -> 63.5328 | ... N9: =SUMIFS('GTTK chung'!BI$4:BI$143,'GTTK chung'!$E$4:$E$143,$B9)/10^6 -> 133.18714 | O9: =SUM(C9:N9) -> 1757.3777 | P9: =SUM(R9:AC9) -> 2757.1574 | Q9: =P9/P$13 -> 0.070830642 | R9: =SUMIFS(AJ$5:AJ$12,$AF$5:$AF$12,$A9) -> 0 | S9: =SUMIFS(AK$5:AK$12,$AF$5:$AF$12,$A9) -> 307 | T9: =SUMIFS(AL$5:AL$12,$AF$5:$AF$12,$A9) -> 272.10897 | U9: =SUMIFS(AM$5:AM$12,$AF$5:$AF$12,$A9) -> 206.35084 | V9: =SUMIFS(AN$5:AN$12,$AF$5:$AF$12,$A9) -> 255.10135 | W9: =SUMIFS(AO$5:AO$12,$AF$5:$AF$12,$A9) -> 223.02556 | X9: =SUMIFS(AP$5:AP$12,$AF$5:$AF$12,$A9) -> 214.37779 | Y9: =SUMIFS(AQ$5:AQ$12,$AF$5:$AF$12,$A9) -> 243.59032 | ... AC9: =SUMIFS(AU$5:AU$12,$AF$5:$AF$12,$A9) -> 196.88347 | AF9: =_xlfn.RANK.AVG($AW9,$AW$5:$AW$12,0) -> 3 | AG9: 5 | AH9: Khác | AI9: =SUM(AJ9:AU9) -> 4788.5143 | AJ9: =SUMIFS('GTTK chung'!AJ$4:AJ$143,'GTTK chung'!$E$4:$E$143,$AH9)/10^6 -> 361.38621 | AK9: =SUMIFS('GTTK chung'!AK$4:AK$143,'GTTK chung'!$E$4:$E$143,$AH9)/10^6 -> 165.44825 | AL9: =SUMIFS('GTTK chung'!AL$4:AL$143,'GTTK chung'!$E$4:$E$143,$AH9)/10^6 -> 529.66271 | AM9: =SUMIFS('GTTK chung'!AM$4:AM$143,'GTTK chung'!$E$4:$E$143,$AH9)/10^6 -> 478.34446 | AN9: =SUMIFS('GTTK chung'!AN$4:AN$143,'GTTK chung'!$E$4:$E$143,$AH9)/10^6 -> 301.50613 | AO9: =SUMIFS('GTTK chung'!AO$4:AO$143,'GTTK chung'!$E$4:$E$143,$AH9)/10^6 -> 1223.3442 | AP9: =SUMIFS('GTTK chung'!AP$4:AP$143,'GTTK chung'!$E$4:$E$143,$AH9)/10^6 -> 179.32877 | AQ9: =SUMIFS('GTTK chung'!AQ$4:AQ$143,'GTTK chung'!$E$4:$E$143,$AH9)/10^6 -> 391.68254 | ... AU9: =SUMIFS('GTTK chung'!AU$4:AU$143,'GTTK chung'!$E$4:$E$143,$AH9)/10^6 -> 268.8903 | AW9: =AI9+COUNTIFS(AI$5:AI9,AI9)*0.01 -> 4788.5243
A10: 6 | B10: =INDEX($AH$5:$AH$12,MATCH($A10,$AF$5:$AF$12,0)) -> Tăng năng suất | C10: =SUMIFS('GTTK chung'!AX$4:AX$143,'GTTK chung'!$E$4:$E$143,$B10)/10^6 -> 279.07186 | D10: =SUMIFS('GTTK chung'!AY$4:AY$143,'GTTK chung'!$E$4:$E$143,$B10)/10^6 -> 196.4322 | E10: =SUMIFS('GTTK chung'!AZ$4:AZ$143,'GTTK chung'!$E$4:$E$143,$B10)/10^6 -> 301.92445 | F10: =SUMIFS('GTTK chung'!BA$4:BA$143,'GTTK chung'!$E$4:$E$143,$B10)/10^6 -> 275.31098 | G10: =SUMIFS('GTTK chung'!BB$4:BB$143,'GTTK chung'!$E$4:$E$143,$B10)/10^6 -> 500.2596 | H10: =SUMIFS('GTTK chung'!BC$4:BC$143,'GTTK chung'!$E$4:$E$143,$B10)/10^6 -> 445.73381 | I10: =SUMIFS('GTTK chung'!BD$4:BD$143,'GTTK chung'!$E$4:$E$143,$B10)/10^6 -> 378.27478 | J10: =SUMIFS('GTTK chung'!BE$4:BE$143,'GTTK chung'!$E$4:$E$143,$B10)/10^6 -> 318.19793 | ... N10: =SUMIFS('GTTK chung'!BI$4:BI$143,'GTTK chung'!$E$4:$E$143,$B10)/10^6 -> 584.48332 | O10: =SUM(C10:N10) -> 4549.3283 | P10: =SUM(R10:AC10) -> 769.90102 | Q10: =P10/P$13 -> 0.019778553 | R10: =SUMIFS(AJ$5:AJ$12,$AF$5:$AF$12,$A10) -> 233.96003 | S10: =SUMIFS(AK$5:AK$12,$AF$5:$AF$12,$A10) -> 192.87787 | T10: =SUMIFS(AL$5:AL$12,$AF$5:$AF$12,$A10) -> 191.42907 | U10: =SUMIFS(AM$5:AM$12,$AF$5:$AF$12,$A10) -> 151.63405 | V10: =SUMIFS(AN$5:AN$12,$AF$5:$AF$12,$A10) -> 0 | W10: =SUMIFS(AO$5:AO$12,$AF$5:$AF$12,$A10) -> 0 | X10: =SUMIFS(AP$5:AP$12,$AF$5:$AF$12,$A10) -> 0 | Y10: =SUMIFS(AQ$5:AQ$12,$AF$5:$AF$12,$A10) -> 0 | ... AC10: =SUMIFS(AU$5:AU$12,$AF$5:$AF$12,$A10) -> 0 | AF10: =_xlfn.RANK.AVG($AW10,$AW$5:$AW$12,0) -> 5 | AG10: 6 | AH10: Tự động hóa | AI10: =SUM(AJ10:AU10) -> 2757.1574 | AJ10: =SUMIFS('GTTK chung'!AJ$4:AJ$143,'GTTK chung'!$E$4:$E$143,$AH10)/10^6 -> 0 | AK10: =SUMIFS('GTTK chung'!AK$4:AK$143,'GTTK chung'!$E$4:$E$143,$AH10)/10^6 -> 307 | AL10: =SUMIFS('GTTK chung'!AL$4:AL$143,'GTTK chung'!$E$4:$E$143,$AH10)/10^6 -> 272.10897 | AM10: =SUMIFS('GTTK chung'!AM$4:AM$143,'GTTK chung'!$E$4:$E$143,$AH10)/10^6 -> 206.35084 | AN10: =SUMIFS('GTTK chung'!AN$4:AN$143,'GTTK chung'!$E$4:$E$143,$AH10)/10^6 -> 255.10135 | AO10: =SUMIFS('GTTK chung'!AO$4:AO$143,'GTTK chung'!$E$4:$E$143,$AH10)/10^6 -> 223.02556 | AP10: =SUMIFS('GTTK chung'!AP$4:AP$143,'GTTK chung'!$E$4:$E$143,$AH10)/10^6 -> 214.37779 | AQ10: =SUMIFS('GTTK chung'!AQ$4:AQ$143,'GTTK chung'!$E$4:$E$143,$AH10)/10^6 -> 243.59032 | ... AU10: =SUMIFS('GTTK chung'!AU$4:AU$143,'GTTK chung'!$E$4:$E$143,$AH10)/10^6 -> 196.88347 | AW10: =AI10+COUNTIFS(AI$5:AI10,AI10)*0.01 -> 2757.1674
A11: 7 | B11: =INDEX($AH$5:$AH$12,MATCH($A11,$AF$5:$AF$12,0)) -> Tiết kiệm năng lượng | C11: =SUMIFS('GTTK chung'!AX$4:AX$143,'GTTK chung'!$E$4:$E$143,$B11)/10^6 -> 0 | D11: =SUMIFS('GTTK chung'!AY$4:AY$143,'GTTK chung'!$E$4:$E$143,$B11)/10^6 -> 0 | E11: =SUMIFS('GTTK chung'!AZ$4:AZ$143,'GTTK chung'!$E$4:$E$143,$B11)/10^6 -> 0 | F11: =SUMIFS('GTTK chung'!BA$4:BA$143,'GTTK chung'!$E$4:$E$143,$B11)/10^6 -> 0 | G11: =SUMIFS('GTTK chung'!BB$4:BB$143,'GTTK chung'!$E$4:$E$143,$B11)/10^6 -> 0 | H11: =SUMIFS('GTTK chung'!BC$4:BC$143,'GTTK chung'!$E$4:$E$143,$B11)/10^6 -> 0 | I11: =SUMIFS('GTTK chung'!BD$4:BD$143,'GTTK chung'!$E$4:$E$143,$B11)/10^6 -> 0 | J11: =SUMIFS('GTTK chung'!BE$4:BE$143,'GTTK chung'!$E$4:$E$143,$B11)/10^6 -> 0 | ... N11: =SUMIFS('GTTK chung'!BI$4:BI$143,'GTTK chung'!$E$4:$E$143,$B11)/10^6 -> 0 | O11: =SUM(C11:N11) -> 0 | P11: =SUM(R11:AC11) -> 339.2267 | Q11: =P11/P$13 -> 0.0087146439 | R11: =SUMIFS(AJ$5:AJ$12,$AF$5:$AF$12,$A11) -> 0 | S11: =SUMIFS(AK$5:AK$12,$AF$5:$AF$12,$A11) -> 0 | T11: =SUMIFS(AL$5:AL$12,$AF$5:$AF$12,$A11) -> 0 | U11: =SUMIFS(AM$5:AM$12,$AF$5:$AF$12,$A11) -> 85.44758 | V11: =SUMIFS(AN$5:AN$12,$AF$5:$AF$12,$A11) -> 96.41288 | W11: =SUMIFS(AO$5:AO$12,$AF$5:$AF$12,$A11) -> 7.109589 | X11: =SUMIFS(AP$5:AP$12,$AF$5:$AF$12,$A11) -> 14.834686 | Y11: =SUMIFS(AQ$5:AQ$12,$AF$5:$AF$12,$A11) -> 77.536721 | ... AC11: =SUMIFS(AU$5:AU$12,$AF$5:$AF$12,$A11) -> 12.192308 | AF11: =_xlfn.RANK.AVG($AW11,$AW$5:$AW$12,0) -> 2 | AG11: 7 | AH11: Giảm hao hụt trong sản xuất | AI11: =SUM(AJ11:AU11) -> 13127.535 | AJ11: =SUMIFS('GTTK chung'!AJ$4:AJ$143,'GTTK chung'!$E$4:$E$143,$AH11)/10^6 -> 643.66103 | AK11: =SUMIFS('GTTK chung'!AK$4:AK$143,'GTTK chung'!$E$4:$E$143,$AH11)/10^6 -> 440.46678 | AL11: =SUMIFS('GTTK chung'!AL$4:AL$143,'GTTK chung'!$E$4:$E$143,$AH11)/10^6 -> 203.81421 | AM11: =SUMIFS('GTTK chung'!AM$4:AM$143,'GTTK chung'!$E$4:$E$143,$AH11)/10^6 -> 85.071216 | AN11: =SUMIFS('GTTK chung'!AN$4:AN$143,'GTTK chung'!$E$4:$E$143,$AH11)/10^6 -> 4105.9403 | AO11: =SUMIFS('GTTK chung'!AO$4:AO$143,'GTTK chung'!$E$4:$E$143,$AH11)/10^6 -> 1061.0261 | AP11: =SUMIFS('GTTK chung'!AP$4:AP$143,'GTTK chung'!$E$4:$E$143,$AH11)/10^6 -> 843.26026 | AQ11: =SUMIFS('GTTK chung'!AQ$4:AQ$143,'GTTK chung'!$E$4:$E$143,$AH11)/10^6 -> 2168.0207 | ... AU11: =SUMIFS('GTTK chung'!AU$4:AU$143,'GTTK chung'!$E$4:$E$143,$AH11)/10^6 -> 389.25069 | AW11: =AI11+COUNTIFS(AI$5:AI11,AI11)*0.01 -> 13127.545
A12: 8 | B12: =INDEX($AH$5:$AH$12,MATCH($A12,$AF$5:$AF$12,0)) -> Giảm tỷ lệ phó sản | C12: =SUMIFS('GTTK chung'!AX$4:AX$143,'GTTK chung'!$E$4:$E$143,$B12)/10^6 -> 122.05351 | D12: =SUMIFS('GTTK chung'!AY$4:AY$143,'GTTK chung'!$E$4:$E$143,$B12)/10^6 -> 398.35158 | E12: =SUMIFS('GTTK chung'!AZ$4:AZ$143,'GTTK chung'!$E$4:$E$143,$B12)/10^6 -> 176.82381 | F12: =SUMIFS('GTTK chung'!BA$4:BA$143,'GTTK chung'!$E$4:$E$143,$B12)/10^6 -> 321.717 | G12: =SUMIFS('GTTK chung'!BB$4:BB$143,'GTTK chung'!$E$4:$E$143,$B12)/10^6 -> 699.14871 | H12: =SUMIFS('GTTK chung'!BC$4:BC$143,'GTTK chung'!$E$4:$E$143,$B12)/10^6 -> 487.44574 | I12: =SUMIFS('GTTK chung'!BD$4:BD$143,'GTTK chung'!$E$4:$E$143,$B12)/10^6 -> 193.09946 | J12: =SUMIFS('GTTK chung'!BE$4:BE$143,'GTTK chung'!$E$4:$E$143,$B12)/10^6 -> 131.81464 | ... N12: =SUMIFS('GTTK chung'!BI$4:BI$143,'GTTK chung'!$E$4:$E$143,$B12)/10^6 -> 90.7554 | O12: =SUM(C12:N12) -> 3049.7507 | P12: =SUM(R12:AC12) -> 42.662102 | Q12: =P12/P$13 -> 0.0010959781 | R12: =SUMIFS(AJ$5:AJ$12,$AF$5:$AF$12,$A12) -> 2.325523 | S12: =SUMIFS(AK$5:AK$12,$AF$5:$AF$12,$A12) -> 0 | T12: =SUMIFS(AL$5:AL$12,$AF$5:$AF$12,$A12) -> 0 | U12: =SUMIFS(AM$5:AM$12,$AF$5:$AF$12,$A12) -> 11.872 | V12: =SUMIFS(AN$5:AN$12,$AF$5:$AF$12,$A12) -> 4.128579 | W12: =SUMIFS(AO$5:AO$12,$AF$5:$AF$12,$A12) -> 24.336 | X12: =SUMIFS(AP$5:AP$12,$AF$5:$AF$12,$A12) -> 0 | Y12: =SUMIFS(AQ$5:AQ$12,$AF$5:$AF$12,$A12) -> 0 | ... AC12: =SUMIFS(AU$5:AU$12,$AF$5:$AF$12,$A12) -> 0 | AF12: =_xlfn.RANK.AVG($AW12,$AW$5:$AW$12,0) -> 7 | AG12: 8 | AH12: Tiết kiệm năng lượng | AI12: =SUM(AJ12:AU12) -> 339.2267 | AJ12: =SUMIFS('GTTK chung'!AJ$4:AJ$143,'GTTK chung'!$E$4:$E$143,$AH12)/10^6 -> 0 | AK12: =SUMIFS('GTTK chung'!AK$4:AK$143,'GTTK chung'!$E$4:$E$143,$AH12)/10^6 -> 0 | AL12: =SUMIFS('GTTK chung'!AL$4:AL$143,'GTTK chung'!$E$4:$E$143,$AH12)/10^6 -> 0 | AM12: =SUMIFS('GTTK chung'!AM$4:AM$143,'GTTK chung'!$E$4:$E$143,$AH12)/10^6 -> 85.44758 | AN12: =SUMIFS('GTTK chung'!AN$4:AN$143,'GTTK chung'!$E$4:$E$143,$AH12)/10^6 -> 96.41288 | AO12: =SUMIFS('GTTK chung'!AO$4:AO$143,'GTTK chung'!$E$4:$E$143,$AH12)/10^6 -> 7.109589 | AP12: =SUMIFS('GTTK chung'!AP$4:AP$143,'GTTK chung'!$E$4:$E$143,$AH12)/10^6 -> 14.834686 | AQ12: =SUMIFS('GTTK chung'!AQ$4:AQ$143,'GTTK chung'!$E$4:$E$143,$AH12)/10^6 -> 77.536721 | ... AU12: =SUMIFS('GTTK chung'!AU$4:AU$143,'GTTK chung'!$E$4:$E$143,$AH12)/10^6 -> 12.192308 | AW12: =AI12+COUNTIFS(AI$5:AI12,AI12)*0.01 -> 339.2367
B13: CỘNG | C13: =SUM(C5:C12) -> 1373.0045 | D13: =SUM(D5:D12) -> 800.03973 | E13: =SUM(E5:E12) -> 1588.4742 | F13: =SUM(F5:F12) -> 1473.7039 | G13: =SUM(G5:G12) -> 1692.3523 | H13: =SUM(H5:H12) -> 1461.3109 | I13: =SUM(I5:I12) -> 2024.4786 | J13: =SUM(J5:J12) -> 5210.0133 | ... P13: =SUM(P5:P12) -> 38926.054 | Q13: =P13/P$13 -> 1 | R13: =SUM(R5:R12) -> 2819.4198 | S13: =SUM(S5:S12) -> 3540.6355 | T13: =SUM(T5:T12) -> 1384.2882 | U13: =SUM(U5:U12) -> 2451.4174 | V13: =SUM(V5:V12) -> 6343.0406 | W13: =SUM(W5:W12) -> 3559.933 | X13: =SUM(X5:X12) -> 3634.5071 | Y13: =SUM(Y5:Y12) -> 5611.7852 | ... AC13: =SUM(AC5:AC12) -> 1603.54 | AH13: CỘNG | AI13: =SUM(AI5:AI12) -> 38926.054 | AJ13: =SUM(AJ5:AJ12) -> 2819.4198 | AK13: =SUM(AK5:AK12) -> 3540.6355 | AL13: =SUM(AL5:AL12) -> 1384.2882 | AM13: =SUM(AM5:AM12) -> 2451.4174 | AN13: =SUM(AN5:AN12) -> 6343.0406 | AO13: =SUM(AO5:AO12) -> 3559.933 | AP13: =SUM(AP5:AP12) -> 3634.5071 | ... AU13: =SUM(AU5:AU12) -> 1603.54
B14: Check | O14: =O13-'GTTK chung'!$BJ$143/10^6 -> 0 | P14: =P13-'GTTK chung'!$AV$143/10^6 -> 0 | AH14: Check | AI14: =AI13-'GTTK chung'!$AV$143/10^6 -> 0 | AJ14: =AJ13-'GTTK chung'!AJ143/10^6 -> 0 | AK14: =AK13-'GTTK chung'!AK143/10^6 -> 0 | AL14: =AL13-'GTTK chung'!AL143/10^6 -> 0 | AM14: =AM13-'GTTK chung'!AM143/10^6 -> 0 | AN14: =AN13-'GTTK chung'!AN143/10^6 -> 0 | AO14: =AO13-'GTTK chung'!AO143/10^6 -> 0 | AP14: =AP13-'GTTK chung'!AP143/10^6 -> 0 | AQ14: =AQ13-'GTTK chung'!AQ143/10^6 -> 0 | ... AU14: =AU13-'GTTK chung'!AU143/10^6 -> 0
A16: 3. | B16: GIÁ TRỊ TIẾT KIỆM THEO BỘ PHẬN
B17: ĐVT: triệu đồng
A18: STT | B18: BỘ PHẬN | C18: 1.24 | D18: 2.24 | E18: 3.24 | F18: 4.24 | G18: 5.24 | H18: 6.24 | I18: 7.24 | J18: 8.24 | K18: 9.24 | L18: 10.24 | M18: 11.24 | N18: 12.24 | O18: 2024 | P18: KH 2025 | Q18: TT 2025 | R18: % TT sv KH | S18: 1.25 | T18: 2 | U18: 3 | V18: 4 | W18: 5 | X18: 6 | Y18: 7 | Z18: 8 | AA18: 9 | AB18: 10 | AC18: 11 | AD18: 12 | AF18: Rank | AG18: STT | AH18: BỘ PHẬN | AI18: 2025 | AJ18: 1.25 | AK18: 2 | AL18: 3 | AM18: 4 | AN18: 5 | AO18: 6 | AP18: 7 | AQ18: 8 | AR18: 9 | AS18: 10 | AT18: 11 | AU18: 12 | AW18: Số liệu TT_Rank | AY18: Mục tiêu | BA18: Rank_Thực tế | BB18: Số liệu KH_Rank | BC18: Rank_Kế hoạch
A19: 1 | B19: =INDEX($AH$19:$AH$32,MATCH($A19,$AF$19:$AF$32,0)) -> Kỹ Thuật | C19: =IF($B19="Kế toán",SUM(C$36:C$38),IF($B19="Quản lý chất lượng",SUM(C$40:C$41),SUMIFS('GTTK chung'!AX$4:AX$143,'GTTK chung'!$G$4:$G$143,$B19)/10^6)) -> 556.59492 | D19: =IF($B19="Kế toán",SUM(D$36:D$38),IF($B19="Quản lý chất lượng",SUM(D$40:D$41),SUMIFS('GTTK chung'!AY$4:AY$143,'GTTK chung'!$G$4:$G$143,$B19)/10^6)) -> 0 | E19: =IF($B19="Kế toán",SUM(E$36:E$38),IF($B19="Quản lý chất lượng",SUM(E$40:E$41),SUMIFS('GTTK chung'!AZ$4:AZ$143,'GTTK chung'!$G$4:$G$143,$B19)/10^6)) -> 24.478717 | F19: =IF($B19="Kế toán",SUM(F$36:F$38),IF($B19="Quản lý chất lượng",SUM(F$40:F$41),SUMIFS('GTTK chung'!BA$4:BA$143,'GTTK chung'!$G$4:$G$143,$B19)/10^6)) -> 89.104991 | G19: =IF($B19="Kế toán",SUM(G$36:G$38),IF($B19="Quản lý chất lượng",SUM(G$40:G$41),SUMIFS('GTTK chung'!BB$4:BB$143,'GTTK chung'!$G$4:$G$143,$B19)/10^6)) -> 291.89948 | H19: =IF($B19="Kế toán",SUM(H$36:H$38),IF($B19="Quản lý chất lượng",SUM(H$40:H$41),SUMIFS('GTTK chung'!BC$4:BC$143,'GTTK chung'!$G$4:$G$143,$B19)/10^6)) -> 292.11951 | I19: =IF($B19="Kế toán",SUM(I$36:I$38),IF($B19="Quản lý chất lượng",SUM(I$40:I$41),SUMIFS('GTTK chung'!BD$4:BD$143,'GTTK chung'!$G$4:$G$143,$B19)/10^6)) -> 867.87556 | J19: =IF($B19="Kế toán",SUM(J$36:J$38),IF($B19="Quản lý chất lượng",SUM(J$40:J$41),SUMIFS('GTTK chung'!BE$4:BE$143,'GTTK chung'!$G$4:$G$143,$B19)/10^6)) -> 126.2427 | ... N19: =IF($B19="Kế toán",SUM(N$36:N$38),IF($B19="Quản lý chất lượng",SUM(N$40:N$41),SUMIFS('GTTK chung'!BI$4:BI$143,'GTTK chung'!$G$4:$G$143,$B19)/10^6)) -> 1323.3643 | O19: =SUM(C19:N19) -> 6207.375 | P19: =SUMIFS(AY$19:AY$32,$AF$19:$AF$32,$A19) -> 7250 | Q19: =SUM(S19:AD19) -> 8116.2135 | R19: =Q19/P19 -> 1.1194777 | S19: =SUMIFS(AJ$19:AJ$32,$AF$19:$AF$32,$A19) -> 618.57657 | T19: =SUMIFS(AK$19:AK$32,$AF$19:$AF$32,$A19) -> 2685.8001 | U19: =SUMIFS(AL$19:AL$32,$AF$19:$AF$32,$A19) -> 203.37224 | V19: =SUMIFS(AM$19:AM$32,$AF$19:$AF$32,$A19) -> 548.3141 | W19: =SUMIFS(AN$19:AN$32,$AF$19:$AF$32,$A19) -> 1817.5794 | X19: =SUMIFS(AO$19:AO$32,$AF$19:$AF$32,$A19) -> 180.74745 | Y19: =SUMIFS(AP$19:AP$32,$AF$19:$AF$32,$A19) -> 468.85834 | Z19: =SUMIFS(AQ$19:AQ$32,$AF$19:$AF$32,$A19) -> 874.07642 | ... AD19: =SUMIFS(AU$19:AU$32,$AF$19:$AF$32,$A19) -> 40.166408 | AE19: =Q19/$Q$33 -> 0.20850337 | AF19: =BA19+BC19 -> 3 | AG19: 1 | AH19: SX PET | AI19: =SUM(AJ19:AU19) -> 5671.7553 | AJ19: =SUMIFS('GTTK chung'!AJ$4:AJ$143,'GTTK chung'!$G$4:$G$143,$AH19)/10^6 -> 0 | AK19: =SUMIFS('GTTK chung'!AK$4:AK$143,'GTTK chung'!$G$4:$G$143,$AH19)/10^6 -> 153.5 | AL19: =SUMIFS('GTTK chung'!AL$4:AL$143,'GTTK chung'!$G$4:$G$143,$AH19)/10^6 -> 144.84716 | AM19: =SUMIFS('GTTK chung'!AM$4:AM$143,'GTTK chung'!$G$4:$G$143,$AH19)/10^6 -> 463.61502 | AN19: =SUMIFS('GTTK chung'!AN$4:AN$143,'GTTK chung'!$G$4:$G$143,$AH19)/10^6 -> 1026.9614 | AO19: =SUMIFS('GTTK chung'!AO$4:AO$143,'GTTK chung'!$G$4:$G$143,$AH19)/10^6 -> 669.60518 | AP19: =SUMIFS('GTTK chung'!AP$4:AP$143,'GTTK chung'!$G$4:$G$143,$AH19)/10^6 -> 607.6077 | AQ19: =SUMIFS('GTTK chung'!AQ$4:AQ$143,'GTTK chung'!$G$4:$G$143,$AH19)/10^6 -> 322.53488 | ... AU19: =SUMIFS('GTTK chung'!AU$4:AU$143,'GTTK chung'!$G$4:$G$143,$AH19)/10^6 -> 387.9075 | AW19: =AI19+COUNTIFS(AI$19:AI19,AI19)*0.01 -> 5671.7653 | AY19: ='SX PET'!O4/10^6 -> 3500 | BA19: =IF($AI19=0,0,RANK($AW19,$AW$19:$AW$32,0)) -> 3 | BB19: =IF($BA19=0,AY19+COUNTIFS(AY$19:AY19,AY19)*0.01,0) -> 0 | BC19: =IF($BA19=0,MAX($BA$19:$BA$32)+RANK($BB19,$BB$19:$BB$32,0),0) -> 0
A20: 2 | B20: =INDEX($AH$19:$AH$32,MATCH($A20,$AF$19:$AF$32,0)) -> Phòng Mua | C20: =IF($B20="Kế toán",SUM(C$36:C$38),IF($B20="Quản lý chất lượng",SUM(C$40:C$41),SUMIFS('GTTK chung'!AX$4:AX$143,'GTTK chung'!$G$4:$G$143,$B20)/10^6)) -> 28.443 | D20: =IF($B20="Kế toán",SUM(D$36:D$38),IF($B20="Quản lý chất lượng",SUM(D$40:D$41),SUMIFS('GTTK chung'!AY$4:AY$143,'GTTK chung'!$G$4:$G$143,$B20)/10^6)) -> 41.204 | E20: =IF($B20="Kế toán",SUM(E$36:E$38),IF($B20="Quản lý chất lượng",SUM(E$40:E$41),SUMIFS('GTTK chung'!AZ$4:AZ$143,'GTTK chung'!$G$4:$G$143,$B20)/10^6)) -> 901.89337 | F20: =IF($B20="Kế toán",SUM(F$36:F$38),IF($B20="Quản lý chất lượng",SUM(F$40:F$41),SUMIFS('GTTK chung'!BA$4:BA$143,'GTTK chung'!$G$4:$G$143,$B20)/10^6)) -> 668.32915 | G20: =IF($B20="Kế toán",SUM(G$36:G$38),IF($B20="Quản lý chất lượng",SUM(G$40:G$41),SUMIFS('GTTK chung'!BB$4:BB$143,'GTTK chung'!$G$4:$G$143,$B20)/10^6)) -> 229.23847 | H20: =IF($B20="Kế toán",SUM(H$36:H$38),IF($B20="Quản lý chất lượng",SUM(H$40:H$41),SUMIFS('GTTK chung'!BC$4:BC$143,'GTTK chung'!$G$4:$G$143,$B20)/10^6)) -> 124.53159 | I20: =IF($B20="Kế toán",SUM(I$36:I$38),IF($B20="Quản lý chất lượng",SUM(I$40:I$41),SUMIFS('GTTK chung'!BD$4:BD$143,'GTTK chung'!$G$4:$G$143,$B20)/10^6)) -> 28.2719 | J20: =IF($B20="Kế toán",SUM(J$36:J$38),IF($B20="Quản lý chất lượng",SUM(J$40:J$41),SUMIFS('GTTK chung'!BE$4:BE$143,'GTTK chung'!$G$4:$G$143,$B20)/10^6)) -> 434.30448 | ... N20: =IF($B20="Kế toán",SUM(N$36:N$38),IF($B20="Quản lý chất lượng",SUM(N$40:N$41),SUMIFS('GTTK chung'!BI$4:BI$143,'GTTK chung'!$G$4:$G$143,$B20)/10^6)) -> 14.459268 | O20: =SUM(C20:N20) -> 10059.598 | P20: =SUMIFS(AY$19:AY$32,$AF$19:$AF$32,$A20) -> 7250 | Q20: =SUM(S20:AD20) -> 7688.5202 | R20: =Q20/P20 -> 1.0604855 | S20: =SUMIFS(AJ$19:AJ$32,$AF$19:$AF$32,$A20) -> 1471.2709 | T20: =SUMIFS(AK$19:AK$32,$AF$19:$AF$32,$A20) -> 369.18423 | U20: =SUMIFS(AL$19:AL$32,$AF$19:$AF$32,$A20) -> 124.33074 | V20: =SUMIFS(AM$19:AM$32,$AF$19:$AF$32,$A20) -> 442.38637 | W20: =SUMIFS(AN$19:AN$32,$AF$19:$AF$32,$A20) -> 1012.2285 | X20: =SUMIFS(AO$19:AO$32,$AF$19:$AF$32,$A20) -> 439.63299 | Y20: =SUMIFS(AP$19:AP$32,$AF$19:$AF$32,$A20) -> 1513.6281 | Z20: =SUMIFS(AQ$19:AQ$32,$AF$19:$AF$32,$A20) -> 2022.9145 | ... AD20: =SUMIFS(AU$19:AU$32,$AF$19:$AF$32,$A20) -> 0 | AE20: =Q20/$Q$33 -> 0.19751604 | AF20: =BA20+BC20 -> 4 | AG20: 2 | AH20: SX HDPE | AI20: =SUM(AJ20:AU20) -> 3464.6566 | AJ20: =SUMIFS('GTTK chung'!AJ$4:AJ$143,'GTTK chung'!$G$4:$G$143,$AH20)/10^6 -> 2.325523 | AK20: =SUMIFS('GTTK chung'!AK$4:AK$143,'GTTK chung'!$G$4:$G$143,$AH20)/10^6 -> 91.995754 | AL20: =SUMIFS('GTTK chung'!AL$4:AL$143,'GTTK chung'!$G$4:$G$143,$AH20)/10^6 -> 328.24345 | AM20: =SUMIFS('GTTK chung'!AM$4:AM$143,'GTTK chung'!$G$4:$G$143,$AH20)/10^6 -> 229.54223 | AN20: =SUMIFS('GTTK chung'!AN$4:AN$143,'GTTK chung'!$G$4:$G$143,$AH20)/10^6 -> 180.68804 | AO20: =SUMIFS('GTTK chung'!AO$4:AO$143,'GTTK chung'!$G$4:$G$143,$AH20)/10^6 -> 117.48093 | AP20: =SUMIFS('GTTK chung'!AP$4:AP$143,'GTTK chung'!$G$4:$G$143,$AH20)/10^6 -> 116.84703 | AQ20: =SUMIFS('GTTK chung'!AQ$4:AQ$143,'GTTK chung'!$G$4:$G$143,$AH20)/10^6 -> 960.03429 | ... AU20: =SUMIFS('GTTK chung'!AU$4:AU$143,'GTTK chung'!$G$4:$G$143,$AH20)/10^6 -> 245.41286 | AW20: =AI20+COUNTIFS(AI$19:AI20,AI20)*0.01 -> 3464.6666 | AY20: =' SX HDPE.PP'!O4/10^6 -> 2000 | BA20: =IF($AI20=0,0,RANK($AW20,$AW$19:$AW$32,0)) -> 4 | BB20: =IF($BA20=0,AY20+COUNTIFS(AY$19:AY20,AY20)*0.01,0) -> 0 | BC20: =IF($BA20=0,MAX($BA$19:$BA$32)+RANK($BB20,$BB$19:$BB$32,0),0) -> 0
A21: 3 | B21: =INDEX($AH$19:$AH$32,MATCH($A21,$AF$19:$AF$32,0)) -> SX PET | C21: =IF($B21="Kế toán",SUM(C$36:C$38),IF($B21="Quản lý chất lượng",SUM(C$40:C$41),SUMIFS('GTTK chung'!AX$4:AX$143,'GTTK chung'!$G$4:$G$143,$B21)/10^6)) -> 221.08907 | D21: =IF($B21="Kế toán",SUM(D$36:D$38),IF($B21="Quản lý chất lượng",SUM(D$40:D$41),SUMIFS('GTTK chung'!AY$4:AY$143,'GTTK chung'!$G$4:$G$143,$B21)/10^6)) -> 189.00799 | E21: =IF($B21="Kế toán",SUM(E$36:E$38),IF($B21="Quản lý chất lượng",SUM(E$40:E$41),SUMIFS('GTTK chung'!AZ$4:AZ$143,'GTTK chung'!$G$4:$G$143,$B21)/10^6)) -> 276.18667 | F21: =IF($B21="Kế toán",SUM(F$36:F$38),IF($B21="Quản lý chất lượng",SUM(F$40:F$41),SUMIFS('GTTK chung'!BA$4:BA$143,'GTTK chung'!$G$4:$G$143,$B21)/10^6)) -> 420.63784 | G21: =IF($B21="Kế toán",SUM(G$36:G$38),IF($B21="Quản lý chất lượng",SUM(G$40:G$41),SUMIFS('GTTK chung'!BB$4:BB$143,'GTTK chung'!$G$4:$G$143,$B21)/10^6)) -> 239.68791 | H21: =IF($B21="Kế toán",SUM(H$36:H$38),IF($B21="Quản lý chất lượng",SUM(H$40:H$41),SUMIFS('GTTK chung'!BC$4:BC$143,'GTTK chung'!$G$4:$G$143,$B21)/10^6)) -> 173.49949 | I21: =IF($B21="Kế toán",SUM(I$36:I$38),IF($B21="Quản lý chất lượng",SUM(I$40:I$41),SUMIFS('GTTK chung'!BD$4:BD$143,'GTTK chung'!$G$4:$G$143,$B21)/10^6)) -> 202.3854 | J21: =IF($B21="Kế toán",SUM(J$36:J$38),IF($B21="Quản lý chất lượng",SUM(J$40:J$41),SUMIFS('GTTK chung'!BE$4:BE$143,'GTTK chung'!$G$4:$G$143,$B21)/10^6)) -> 182.94672 | ... N21: =IF($B21="Kế toán",SUM(N$36:N$38),IF($B21="Quản lý chất lượng",SUM(N$40:N$41),SUMIFS('GTTK chung'!BI$4:BI$143,'GTTK chung'!$G$4:$G$143,$B21)/10^6)) -> 96.511266 | O21: =SUM(C21:N21) -> 2455.7487 | P21: =SUMIFS(AY$19:AY$32,$AF$19:$AF$32,$A21) -> 3500 | Q21: =SUM(S21:AD21) -> 5671.7553 | R21: =Q21/P21 -> 1.6205015 | S21: =SUMIFS(AJ$19:AJ$32,$AF$19:$AF$32,$A21) -> 0 | T21: =SUMIFS(AK$19:AK$32,$AF$19:$AF$32,$A21) -> 153.5 | U21: =SUMIFS(AL$19:AL$32,$AF$19:$AF$32,$A21) -> 144.84716 | V21: =SUMIFS(AM$19:AM$32,$AF$19:$AF$32,$A21) -> 463.61502 | W21: =SUMIFS(AN$19:AN$32,$AF$19:$AF$32,$A21) -> 1026.9614 | X21: =SUMIFS(AO$19:AO$32,$AF$19:$AF$32,$A21) -> 669.60518 | Y21: =SUMIFS(AP$19:AP$32,$AF$19:$AF$32,$A21) -> 607.6077 | Z21: =SUMIFS(AQ$19:AQ$32,$AF$19:$AF$32,$A21) -> 322.53488 | ... AD21: =SUMIFS(AU$19:AU$32,$AF$19:$AF$32,$A21) -> 387.9075 | AE21: =Q21/$Q$33 -> 0.14570589 | AF21: =BA21+BC21 -> 8 | AG21: 3 | AH21: Tự động hóa | AI21: =SUM(AJ21:AU21) -> 1880.9378 | AJ21: =SUMIFS('GTTK chung'!AJ$4:AJ$143,'GTTK chung'!$G$4:$G$143,$AH21)/10^6 -> 0 | AK21: =SUMIFS('GTTK chung'!AK$4:AK$143,'GTTK chung'!$G$4:$G$143,$AH21)/10^6 -> 153.5 | AL21: =SUMIFS('GTTK chung'!AL$4:AL$143,'GTTK chung'!$G$4:$G$143,$AH21)/10^6 -> 88.064661 | AM21: =SUMIFS('GTTK chung'!AM$4:AM$143,'GTTK chung'!$G$4:$G$143,$AH21)/10^6 -> 79.570028 | AN21: =SUMIFS('GTTK chung'!AN$4:AN$143,'GTTK chung'!$G$4:$G$143,$AH21)/10^6 -> 215.31144 | AO21: =SUMIFS('GTTK chung'!AO$4:AO$143,'GTTK chung'!$G$4:$G$143,$AH21)/10^6 -> 194.94361 | AP21: =SUMIFS('GTTK chung'!AP$4:AP$143,'GTTK chung'!$G$4:$G$143,$AH21)/10^6 -> 170.64551 | AQ21: =SUMIFS('GTTK chung'!AQ$4:AQ$143,'GTTK chung'!$G$4:$G$143,$AH21)/10^6 -> 191.49512 | ... AU21: =SUMIFS('GTTK chung'!AU$4:AU$143,'GTTK chung'!$G$4:$G$143,$AH21)/10^6 -> 140.07103 | AW21: =AI21+COUNTIFS(AI$19:AI21,AI21)*0.01 -> 1880.9478 | AY21: ='Phân bổ của TĐH'!O4/10^6 -> 5250 | BA21: =IF($AI21=0,0,RANK($AW21,$AW$19:$AW$32,0)) -> 8 | BB21: =IF($BA21=0,AY21+COUNTIFS(AY$19:AY21,AY21)*0.01,0) -> 0 | BC21: =IF($BA21=0,MAX($BA$19:$BA$32)+RANK($BB21,$BB$19:$BB$32,0),0) -> 0
A22: 4 | B22: =INDEX($AH$19:$AH$32,MATCH($A22,$AF$19:$AF$32,0)) -> SX HDPE | C22: =IF($B22="Kế toán",SUM(C$36:C$38),IF($B22="Quản lý chất lượng",SUM(C$40:C$41),SUMIFS('GTTK chung'!AX$4:AX$143,'GTTK chung'!$G$4:$G$143,$B22)/10^6)) -> 75.794164 | D22: =IF($B22="Kế toán",SUM(D$36:D$38),IF($B22="Quản lý chất lượng",SUM(D$40:D$41),SUMIFS('GTTK chung'!AY$4:AY$143,'GTTK chung'!$G$4:$G$143,$B22)/10^6)) -> 31.324059 | E22: =IF($B22="Kế toán",SUM(E$36:E$38),IF($B22="Quản lý chất lượng",SUM(E$40:E$41),SUMIFS('GTTK chung'!AZ$4:AZ$143,'GTTK chung'!$G$4:$G$143,$B22)/10^6)) -> 58.715965 | F22: =IF($B22="Kế toán",SUM(F$36:F$38),IF($B22="Quản lý chất lượng",SUM(F$40:F$41),SUMIFS('GTTK chung'!BA$4:BA$143,'GTTK chung'!$G$4:$G$143,$B22)/10^6)) -> 13.10017 | G22: =IF($B22="Kế toán",SUM(G$36:G$38),IF($B22="Quản lý chất lượng",SUM(G$40:G$41),SUMIFS('GTTK chung'!BB$4:BB$143,'GTTK chung'!$G$4:$G$143,$B22)/10^6)) -> 473.95208 | H22: =IF($B22="Kế toán",SUM(H$36:H$38),IF($B22="Quản lý chất lượng",SUM(H$40:H$41),SUMIFS('GTTK chung'!BC$4:BC$143,'GTTK chung'!$G$4:$G$143,$B22)/10^6)) -> 240.25712 | I22: =IF($B22="Kế toán",SUM(I$36:I$38),IF($B22="Quản lý chất lượng",SUM(I$40:I$41),SUMIFS('GTTK chung'!BD$4:BD$143,'GTTK chung'!$G$4:$G$143,$B22)/10^6)) -> 76.139331 | J22: =IF($B22="Kế toán",SUM(J$36:J$38),IF($B22="Quản lý chất lượng",SUM(J$40:J$41),SUMIFS('GTTK chung'!BE$4:BE$143,'GTTK chung'!$G$4:$G$143,$B22)/10^6)) -> 184.13775 | ... N22: =IF($B22="Kế toán",SUM(N$36:N$38),IF($B22="Quản lý chất lượng",SUM(N$40:N$41),SUMIFS('GTTK chung'!BI$4:BI$143,'GTTK chung'!$G$4:$G$143,$B22)/10^6)) -> 95.763739 | O22: =SUM(C22:N22) -> 1590.696 | P22: =SUMIFS(AY$19:AY$32,$AF$19:$AF$32,$A22) -> 2000 | Q22: =SUM(S22:AD22) -> 3464.6566 | R22: =Q22/P22 -> 1.7323283 | S22: =SUMIFS(AJ$19:AJ$32,$AF$19:$AF$32,$A22) -> 2.325523 | T22: =SUMIFS(AK$19:AK$32,$AF$19:$AF$32,$A22) -> 91.995754 | U22: =SUMIFS(AL$19:AL$32,$AF$19:$AF$32,$A22) -> 328.24345 | V22: =SUMIFS(AM$19:AM$32,$AF$19:$AF$32,$A22) -> 229.54223 | W22: =SUMIFS(AN$19:AN$32,$AF$19:$AF$32,$A22) -> 180.68804 | X22: =SUMIFS(AO$19:AO$32,$AF$19:$AF$32,$A22) -> 117.48093 | Y22: =SUMIFS(AP$19:AP$32,$AF$19:$AF$32,$A22) -> 116.84703 | Z22: =SUMIFS(AQ$19:AQ$32,$AF$19:$AF$32,$A22) -> 960.03429 | ... AD22: =SUMIFS(AU$19:AU$32,$AF$19:$AF$32,$A22) -> 245.41286 | AE22: =Q22/$Q$33 -> 0.089006108 | AF22: =BA22+BC22 -> 2 | AG22: 4 | AH22: Phòng Mua | AI22: =SUM(AJ22:AU22) -> 7688.5202 | AJ22: =SUMIFS('GTTK chung'!AJ$4:AJ$143,'GTTK chung'!$G$4:$G$143,$AH22)/10^6 -> 1471.2709 | AK22: =SUMIFS('GTTK chung'!AK$4:AK$143,'GTTK chung'!$G$4:$G$143,$AH22)/10^6 -> 369.18423 | AL22: =SUMIFS('GTTK chung'!AL$4:AL$143,'GTTK chung'!$G$4:$G$143,$AH22)/10^6 -> 124.33074 | AM22: =SUMIFS('GTTK chung'!AM$4:AM$143,'GTTK chung'!$G$4:$G$143,$AH22)/10^6 -> 442.38637 | AN22: =SUMIFS('GTTK chung'!AN$4:AN$143,'GTTK chung'!$G$4:$G$143,$AH22)/10^6 -> 1012.2285 | AO22: =SUMIFS('GTTK chung'!AO$4:AO$143,'GTTK chung'!$G$4:$G$143,$AH22)/10^6 -> 439.63299 | AP22: =SUMIFS('GTTK chung'!AP$4:AP$143,'GTTK chung'!$G$4:$G$143,$AH22)/10^6 -> 1513.6281 | AQ22: =SUMIFS('GTTK chung'!AQ$4:AQ$143,'GTTK chung'!$G$4:$G$143,$AH22)/10^6 -> 2022.9145 | ... AU22: =SUMIFS('GTTK chung'!AU$4:AU$143,'GTTK chung'!$G$4:$G$143,$AH22)/10^6 -> 0 | AW22: =AI22+COUNTIFS(AI$19:AI22,AI22)*0.01 -> 7688.5302 | AY22: ='Phòng mua-XNK'!O4/10^6 -> 7250 | BA22: =IF($AI22=0,0,RANK($AW22,$AW$19:$AW$32,0)) -> 2 | BB22: =IF($BA22=0,AY22+COUNTIFS(AY$19:AY22,AY22)*0.01,0) -> 0 | BC22: =IF($BA22=0,MAX($BA$19:$BA$32)+RANK($BB22,$BB$19:$BB$32,0),0) -> 0
A23: 5 | B23: =INDEX($AH$19:$AH$32,MATCH($A23,$AF$19:$AF$32,0)) -> Quản Lý Chất Lượng | C23: =IF($B23="Kế toán",SUM(C$36:C$38),IF($B23="Quản lý chất lượng",SUM(C$40:C$41),SUMIFS('GTTK chung'!AX$4:AX$143,'GTTK chung'!$G$4:$G$143,$B23)/10^6)) -> 0 | D23: =IF($B23="Kế toán",SUM(D$36:D$38),IF($B23="Quản lý chất lượng",SUM(D$40:D$41),SUMIFS('GTTK chung'!AY$4:AY$143,'GTTK chung'!$G$4:$G$143,$B23)/10^6)) -> 0 | E23: =IF($B23="Kế toán",SUM(E$36:E$38),IF($B23="Quản lý chất lượng",SUM(E$40:E$41),SUMIFS('GTTK chung'!AZ$4:AZ$143,'GTTK chung'!$G$4:$G$143,$B23)/10^6)) -> 0 | F23: =IF($B23="Kế toán",SUM(F$36:F$38),IF($B23="Quản lý chất lượng",SUM(F$40:F$41),SUMIFS('GTTK chung'!BA$4:BA$143,'GTTK chung'!$G$4:$G$143,$B23)/10^6)) -> 0 | G23: =IF($B23="Kế toán",SUM(G$36:G$38),IF($B23="Quản lý chất lượng",SUM(G$40:G$41),SUMIFS('GTTK chung'!BB$4:BB$143,'GTTK chung'!$G$4:$G$143,$B23)/10^6)) -> 25.717932 | H23: =IF($B23="Kế toán",SUM(H$36:H$38),IF($B23="Quản lý chất lượng",SUM(H$40:H$41),SUMIFS('GTTK chung'!BC$4:BC$143,'GTTK chung'!$G$4:$G$143,$B23)/10^6)) -> 69.743085 | I23: =IF($B23="Kế toán",SUM(I$36:I$38),IF($B23="Quản lý chất lượng",SUM(I$40:I$41),SUMIFS('GTTK chung'!BD$4:BD$143,'GTTK chung'!$G$4:$G$143,$B23)/10^6)) -> 356.46654 | J23: =IF($B23="Kế toán",SUM(J$36:J$38),IF($B23="Quản lý chất lượng",SUM(J$40:J$41),SUMIFS('GTTK chung'!BE$4:BE$143,'GTTK chung'!$G$4:$G$143,$B23)/10^6)) -> 86.677685 | ... N23: =IF($B23="Kế toán",SUM(N$36:N$38),IF($B23="Quản lý chất lượng",SUM(N$40:N$41),SUMIFS('GTTK chung'!BI$4:BI$143,'GTTK chung'!$G$4:$G$143,$B23)/10^6)) -> 309.91836 | O23: =SUM(C23:N23) -> 1504.0483 | P23: =SUMIFS(AY$19:AY$32,$AF$19:$AF$32,$A23) -> 4250 | Q23: =SUM(S23:AD23) -> 3053.6536 | R23: =Q23/P23 -> 0.71850673 | S23: =SUMIFS(AJ$19:AJ$32,$AF$19:$AF$32,$A23) -> 273.36062 | T23: =SUMIFS(AK$19:AK$32,$AF$19:$AF$32,$A23) -> 13.202904 | U23: =SUMIFS(AL$19:AL$32,$AF$19:$AF$32,$A23) -> 132.63109 | V23: =SUMIFS(AM$19:AM$32,$AF$19:$AF$32,$A23) -> 125.53165 | W23: =SUMIFS(AN$19:AN$32,$AF$19:$AF$32,$A23) -> 626.80467 | X23: =SUMIFS(AO$19:AO$32,$AF$19:$AF$32,$A23) -> 278.35134 | Y23: =SUMIFS(AP$19:AP$32,$AF$19:$AF$32,$A23) -> 255.18688 | Z23: =SUMIFS(AQ$19:AQ$32,$AF$19:$AF$32,$A23) -> 394.27648 | ... AD23: =SUMIFS(AU$19:AU$32,$AF$19:$AF$32,$A23) -> 183.2984 | AE23: =Q23/$Q$33 -> 0.078447551 | AF23: =BA23+BC23 -> 1 | AG23: 5 | AH23: Kỹ Thuật | AI23: =SUM(AJ23:AU23) -> 8116.2135 | AJ23: =SUMIFS('GTTK chung'!AJ$4:AJ$143,'GTTK chung'!$G$4:$G$143,$AH23)/10^6 -> 618.57657 | AK23: =SUMIFS('GTTK chung'!AK$4:AK$143,'GTTK chung'!$G$4:$G$143,$AH23)/10^6 -> 2685.8001 | AL23: =SUMIFS('GTTK chung'!AL$4:AL$143,'GTTK chung'!$G$4:$G$143,$AH23)/10^6 -> 203.37224 | AM23: =SUMIFS('GTTK chung'!AM$4:AM$143,'GTTK chung'!$G$4:$G$143,$AH23)/10^6 -> 548.3141 | AN23: =SUMIFS('GTTK chung'!AN$4:AN$143,'GTTK chung'!$G$4:$G$143,$AH23)/10^6 -> 1817.5794 | AO23: =SUMIFS('GTTK chung'!AO$4:AO$143,'GTTK chung'!$G$4:$G$143,$AH23)/10^6 -> 180.74745 | AP23: =SUMIFS('GTTK chung'!AP$4:AP$143,'GTTK chung'!$G$4:$G$143,$AH23)/10^6 -> 468.85834 | AQ23: =SUMIFS('GTTK chung'!AQ$4:AQ$143,'GTTK chung'!$G$4:$G$143,$AH23)/10^6 -> 874.07642 | ... AU23: =SUMIFS('GTTK chung'!AU$4:AU$143,'GTTK chung'!$G$4:$G$143,$AH23)/10^6 -> 40.166408 | AW23: =AI23+COUNTIFS(AI$19:AI23,AI23)*0.01 -> 8116.2235 | AY23: ='Kỹ Thuật'!O4/10^6 -> 7250 | BA23: =IF($AI23=0,0,RANK($AW23,$AW$19:$AW$32,0)) -> 1 | BB23: =IF($BA23=0,AY23+COUNTIFS(AY$19:AY23,AY23)*0.01,0) -> 0 | BC23: =IF($BA23=0,MAX($BA$19:$BA$32)+RANK($BB23,$BB$19:$BB$32,0),0) -> 0
A24: 6 | B24: =INDEX($AH$19:$AH$32,MATCH($A24,$AF$19:$AF$32,0)) -> Kế hoạch | C24: =IF($B24="Kế toán",SUM(C$36:C$38),IF($B24="Quản lý chất lượng",SUM(C$40:C$41),SUMIFS('GTTK chung'!AX$4:AX$143,'GTTK chung'!$G$4:$G$143,$B24)/10^6)) -> 0 | D24: =IF($B24="Kế toán",SUM(D$36:D$38),IF($B24="Quản lý chất lượng",SUM(D$40:D$41),SUMIFS('GTTK chung'!AY$4:AY$143,'GTTK chung'!$G$4:$G$143,$B24)/10^6)) -> 0 | E24: =IF($B24="Kế toán",SUM(E$36:E$38),IF($B24="Quản lý chất lượng",SUM(E$40:E$41),SUMIFS('GTTK chung'!AZ$4:AZ$143,'GTTK chung'!$G$4:$G$143,$B24)/10^6)) -> 0 | F24: =IF($B24="Kế toán",SUM(F$36:F$38),IF($B24="Quản lý chất lượng",SUM(F$40:F$41),SUMIFS('GTTK chung'!BA$4:BA$143,'GTTK chung'!$G$4:$G$143,$B24)/10^6)) -> 0 | G24: =IF($B24="Kế toán",SUM(G$36:G$38),IF($B24="Quản lý chất lượng",SUM(G$40:G$41),SUMIFS('GTTK chung'!BB$4:BB$143,'GTTK chung'!$G$4:$G$143,$B24)/10^6)) -> 0 | H24: =IF($B24="Kế toán",SUM(H$36:H$38),IF($B24="Quản lý chất lượng",SUM(H$40:H$41),SUMIFS('GTTK chung'!BC$4:BC$143,'GTTK chung'!$G$4:$G$143,$B24)/10^6)) -> 0 | I24: =IF($B24="Kế toán",SUM(I$36:I$38),IF($B24="Quản lý chất lượng",SUM(I$40:I$41),SUMIFS('GTTK chung'!BD$4:BD$143,'GTTK chung'!$G$4:$G$143,$B24)/10^6)) -> 0 | J24: =IF($B24="Kế toán",SUM(J$36:J$38),IF($B24="Quản lý chất lượng",SUM(J$40:J$41),SUMIFS('GTTK chung'!BE$4:BE$143,'GTTK chung'!$G$4:$G$143,$B24)/10^6)) -> 0 | ... N24: =IF($B24="Kế toán",SUM(N$36:N$38),IF($B24="Quản lý chất lượng",SUM(N$40:N$41),SUMIFS('GTTK chung'!BI$4:BI$143,'GTTK chung'!$G$4:$G$143,$B24)/10^6)) -> 0 | O24: =SUM(C24:N24) -> 0 | P24: =SUMIFS(AY$19:AY$32,$AF$19:$AF$32,$A24) -> 750 | Q24: =SUM(S24:AD24) -> 2521.2706 | R24: =Q24/P24 -> 3.3616941 | S24: =SUMIFS(AJ$19:AJ$32,$AF$19:$AF$32,$A24) -> 0 | T24: =SUMIFS(AK$19:AK$32,$AF$19:$AF$32,$A24) -> 0 | U24: =SUMIFS(AL$19:AL$32,$AF$19:$AF$32,$A24) -> 56.841896 | V24: =SUMIFS(AM$19:AM$32,$AF$19:$AF$32,$A24) -> 13.897994 | W24: =SUMIFS(AN$19:AN$32,$AF$19:$AF$32,$A24) -> 830.74617 | X24: =SUMIFS(AO$19:AO$32,$AF$19:$AF$32,$A24) -> 284.59789 | Y24: =SUMIFS(AP$19:AP$32,$AF$19:$AF$32,$A24) -> 227.18483 | Z24: =SUMIFS(AQ$19:AQ$32,$AF$19:$AF$32,$A24) -> 398.45956 | ... AD24: =SUMIFS(AU$19:AU$32,$AF$19:$AF$32,$A24) -> 51.802854 | AE24: =Q24/$Q$33 -> 0.064770772 | AF24: =BA24+BC24 -> 9 | AG24: 6 | AH24: R&D | AI24: =SUM(AJ24:AU24) -> 1756.9569 | AJ24: =SUMIFS('GTTK chung'!AJ$4:AJ$143,'GTTK chung'!$G$4:$G$143,$AH24)/10^6 -> 0 | AK24: =SUMIFS('GTTK chung'!AK$4:AK$143,'GTTK chung'!$G$4:$G$143,$AH24)/10^6 -> 0 | AL24: =SUMIFS('GTTK chung'!AL$4:AL$143,'GTTK chung'!$G$4:$G$143,$AH24)/10^6 -> 0 | AM24: =SUMIFS('GTTK chung'!AM$4:AM$143,'GTTK chung'!$G$4:$G$143,$AH24)/10^6 -> 0 | AN24: =SUMIFS('GTTK chung'!AN$4:AN$143,'GTTK chung'!$G$4:$G$143,$AH24)/10^6 -> 515.19285 | AO24: =SUMIFS('GTTK chung'!AO$4:AO$143,'GTTK chung'!$G$4:$G$143,$AH24)/10^6 -> 308.59722 | AP24: =SUMIFS('GTTK chung'!AP$4:AP$143,'GTTK chung'!$G$4:$G$143,$AH24)/10^6 -> 133.86889 | AQ24: =SUMIFS('GTTK chung'!AQ$4:AQ$143,'GTTK chung'!$G$4:$G$143,$AH24)/10^6 -> 248.03011 | ... AU24: =SUMIFS('GTTK chung'!AU$4:AU$143,'GTTK chung'!$G$4:$G$143,$AH24)/10^6 -> 48.116945 | AW24: =AI24+COUNTIFS(AI$19:AI24,AI24)*0.01 -> 1756.9669 | AY24: ='Phòng R&D'!O4/10^6 -> 7250 | BA24: =IF($AI24=0,0,RANK($AW24,$AW$19:$AW$32,0)) -> 9 | BB24: =IF($BA24=0,AY24+COUNTIFS(AY$19:AY24,AY24)*0.01,0) -> 0 | BC24: =IF($BA24=0,MAX($BA$19:$BA$32)+RANK($BB24,$BB$19:$BB$32,0),0) -> 0
