Workbook

Sheet Sheet1
B2: Căn cứ:
B3: 1 Mục tiêu LN của các trạm 2% (hoặc không lỗ)
B4: 2 Bám sát giá thị trường
B5: 3 Tăng và đảm bảo sản lượng để trạm tối ưu chi phí
B6: 4 Xem xét các chi phí không hợp lý
B7: 5. Chi phí sản xuất của từng trạm
B8: 6. Khoản GAP hiện hành
B9: Đề xuất hướng điều chỉnh GAP theo từng trạm như sau:
B11: KHÁNH NGA
B12: GIÁ BÁN | D12: Giá duyệt (sau điều chỉnh) | F12: GAP (sau điều chỉnh)
B13: 1 | C13: Lấy chi phí KN | D13: =2700-3000 -> -300
B14: 2 | C14: LN Mục tiêu 2% | D14: -200 | F14: =5000+D14+D13 -> 4500
B16: ĐỒNG LÂM
D17: Giá duyệt | F17: GAP
C18: Cộng chi phí thuê xưởng | D18: -300
C19: LN Mục tiêu 2% | D19: -200 | F19: =5000+D18+D19 -> 4500
B23: ĐAI LỘC
C24: =990-915 -> 75 | D24: Giá duyệt | F24: GAP
C25: Hỗ trợ giá bán bù chi phí thuê xưởng cao | D25: 0
C26: LN Mục tiêu 0% (không lỗ) | F26: 5000
C28: Hỗ trợ giá bán bù chi phí thuê xưởng cao => Giữ nguyên GAP | D28: 400
C29: Chuyền Băm và rữa HD _Pulian
C30: KH 1 tháng 200 triệu

Sheet Cảnh báo giá mua từ trạm
B3: C:\Data\GĐ Tài chính\Cost Controlling\Costing Flow Chart\Báo CT _Model\PET_FULL_CFO_OPTIMIZATION.xlsx
B5: Cty | C5: CPC
B6: Cty | C6: Far Eastern
B7: Cty | C7: Nhóm Trung Quốc
C9: 1 Mục tiêu LN của các trạm 2% (hoặc không lỗ)
C10: 2 Bám sát giá thị trường
C11: 3 Tăng và đảm bảo sản lượng để trạm tối ưu chi phí
C12: 4 Xem xét các chi phí không
C14: KHÁNH NGA
C15: GIÁ BÁN | E15: Giá duyệt | F15: GAP
C16: 1 | D16: Lấy chi phí KN
C17: 2 | D17: LN Mục tiêu 2% | E17: -200 | F17: =-11300*2% -> -226
C19: ĐỒNG LÂM
E20: Giá duyệt | F20: GAP
D21: Cộng chi phí thuê xưởng | E21: -300 | G21: 150000000 | H21: 500000 | I21: =G21/H21 -> 300
D22: LN Mục tiêu 2% | E22: -200 | F22: =-11300*4% -> -452 | H22: =H21*E21 -> -150000000
H23: =H21*E22 -> -100000000
H24: =H23+H22 -> -250000000
C26: ĐAI LỘC
D27: =990-915 -> 75 | E27: Giá duyệt | F27: GAP | G27: 990 | H27: 1000000
D28: Hỗ trợ giá bán bù chi phí thuê xưởng cao | E28: 400 | G28: =E28*1000*990 -> 396000000 | H28: =G28/H27 -> 396
D29: LN Mục tiêu 0%
G30: =G27*113*1000 -> 111870000
D32: Chuyền Băm và rữa HD _Pulian
D33: KH 1 tháng 200 triệu

Sheet BOM chuẩn DLOC
B2: BẢNG TÍNH SETTLEMENT RULE BOM - ROUTING (co-product)
M3: Hide | P3: Giá BO sau Phân loại
B4: I. | C4: CÔNG ĐOẠN PHÂN LOẠI CHAI | D4: BOM - KẾ HOẠCH | F4: Sản lượng thành phẩm thực tế | G4: Hệ số quy đổi | H4: Sản lượng thành phẩm quy đổi | I4: Giá trị nguyên liệu phân bổ cho thành phẩm quy đổi | J4: Settlement rule - BOM | K4: Settlement rule - ROUTING | L4: Ghi chú | M4: Giá bán hiện tại | N4: Hệ số quy đổi giá bán | O4: Gap (đảm bảo chi phí và lợi nhuận) | P4: GT NVL | Q4: CFSX | R4: GT SP Trạm | S4: LG | T4: % | V4: Đlộc | X4: KN | Z4: ĐLâm | AB4: Giá thị trường
D5: Số lượng | E5: Tỷ lệ | F5: (1) | G5: (2) | H5: (3)= (1)*(2) | I5: (4) | J5: Tỷ lệ | K5: Tỷ lệ | M5: =MAX(V5,X5,Z5) -> 0.10667325 | U5: Hao hụt | V5: ='[2]1. Đại Lộc'!$O$334 -> 0.10096034 | X5: ='[2]2. Khánh Nga'!$O$39 -> 0.097733527 | Z5: ='[2]3. Đồng Lâm'!$O$344 -> 0.10667325
B6: 150000001 | C6: Chai PET xá | D6: 1000 | E6: =SUM(E7:E20) -> 1 | I6: =D6*$M$6 -> 11300000 | J6: =SUM(J7:J19) -> 1 | K6: =SUM(K7:K19) -> 1 | M6: 11300 | Q6: 3000 | V6: ='[3]3.CP_TAN'!$Q$78 -> 3684.4011 | X6: ='[3]3.CP_TAN'!$R$78 -> 2894.8843 | Z6: ='[3]3.CP_TAN'!$S$78 -> 2609.6553 | AB6: 10000
B7: 160000001 | C7: Chai PET B1.1 | D7: 540 | E7: 0.54 | F7: =D7 -> 540 | G7: 1.25 | H7: =F7*G7 -> 675 | I7: =$I$6/$H$21*H7 -> 7257373.9 | J7: =I7/$I$6 -> 0.64224548 | K7: =J7 -> 0.64224548 | L7: (4) = Tổng giá trị NVL /(Tổng số lượng TP quy đổi) * Sl Tp quy đổi. (5) = Giá trị nguyên liệu phân bổ cho thành phẩm quy đổi / Tổng giá trị nguyên liệu phân bổ cho thành phẩm quy đổi | M7: =ROUND($M$6+$M$6*$M$5+O7,-2) -> 16400 | N7: =M7/$M$21 -> 1.2471483 | O7: 3900 | P7: =I7/F7 -> 13439.581 | Q7: =$Q$6*K7 -> 1926.7364 | R7: =P7+Q7 -> 15366.318 | S7: =M7-R7 -> 1033.6822 | T7: =S7/M7 -> 0.063029403 | U7: ='[2]1. Đại Lộc'!B327 -> % Chai B1 | V7: ='[2]1. Đại Lộc'!O327 -> 0.65050165 | W7: ='[2]2. Khánh Nga'!B32 -> % Chai B1 | X7: ='[2]2. Khánh Nga'!O32 -> 0.5258354 | Y7: ='[2]3. Đồng Lâm'!B337 -> % Chai B1 | Z7: ='[2]3. Đồng Lâm'!O337 -> 0.50053443 | AB7: 14500 | AC7: 11200 | AE7: =T7*V7 -> 0.041000731 | AF7: =ROUND($M$6+$M$6*$M$5,-2) -> 12500
B8: 160000081 | C8: Chai PET B1.3 | F8: =D8 -> 0 | H8: =F8*G8 -> 0 | I8: =$I$6/$H$21*H8 -> 0 | J8: =I8/$I$6 -> 0 | K8: =J8 -> 0 | N8: =M8/$M$21 -> 0 | O8: =O7 -> 3900 | P8: =I8/F8 -> #DIV/0! | Q8: =$Q$6*K8 -> 0 | R8: =P8+Q8 -> #DIV/0! | S8: =M8-R8 -> #DIV/0! | T8: =S8/M8 -> #DIV/0! | AE8: =T8*V8 -> #DIV/0!
B9: 160000002 | C9: Chai PET B2.2 | D9: 30 | E9: 0.03 | F9: =D9 -> 30 | G9: 1.1 | H9: =F9*G9 -> 33 | I9: =$I$6/$H$21*H9 -> 354804.95 | J9: =I9/$I$6 -> 0.031398668 | K9: =J9 -> 0.031398668 | M9: =ROUND($M$6+$M$6*$M$5+O9,-2) -> 14500 | N9: =M9/$M$21 -> 1.1026616 | O9: 2000 | P9: =I9/F9 -> 11826.832 | Q9: =$Q$6*K9 -> 94.196004 | R9: =P9+Q9 -> 11921.028 | S9: =M9-R9 -> 2578.9724 | T9: =S9/M9 -> 0.17786017 | U9: ='[2]1. Đại Lộc'!B328 -> % Chai B2.2 | V9: ='[2]1. Đại Lộc'!O328 -> 0.0053561787 | W9: ='[2]2. Khánh Nga'!B33 -> % Chai B2.2 | X9: ='[2]2. Khánh Nga'!O33 -> 0.078724377 | Y9: ='[2]3. Đồng Lâm'!B338 -> % Chai B2.2 | Z9: ='[2]3. Đồng Lâm'!O338 -> 0.08356034 | AE9: =T9*V9 -> 0.00095265083
B10: 160000063 | C10: Chai PET B4 | D10: 20 | E10: 0.02 | F10: =D10 -> 20 | G10: 1 | H10: =F10*G10 -> 20 | I10: =$I$6/$H$21*H10 -> 215033.3 | J10: =I10/$I$6 -> 0.019029496 | K10: =J10 -> 0.019029496 | M10: =ROUND($M$6+$M$6*$M$5+O10,-2) -> 13000 | N10: =M10/$M$21 -> 0.98859316 | O10: 500 | P10: =I10/F10 -> 10751.665 | Q10: =$Q$6*K10 -> 57.088487 | R10: =P10+Q10 -> 10808.754 | S10: =M10-R10 -> 2191.2464 | T10: =S10/M10 -> 0.16855742 | U10: ='[2]2. Khánh Nga'!B35 -> % Chai B4 | V10: ='[2]2. Khánh Nga'!O35 -> 0.014912634 | W10: ='[2]2. Khánh Nga'!B35 -> % Chai B4 | X10: ='[2]2. Khánh Nga'!O35 -> 0.014912634 | Y10: ='[2]3. Đồng Lâm'!B340 -> % Chai B4 | Z10: ='[2]3. Đồng Lâm'!O340 -> 0.019139602 | AE10: =T10*V10 -> 0.0025136351
B11: 160000004 | C11: Chai PET B5 | D11: 20 | E11: 0.02 | F11: =D11 -> 20 | G11: 1 | H11: =F11*G11 -> 20 | I11: =$I$6/$H$21*H11 -> 215033.3 | J11: =I11/$I$6 -> 0.019029496 | K11: =J11 -> 0.019029496 | M11: =ROUND($M$6+$M$6*$M$5+O11,-2) -> 13000 | N11: =M11/$M$21 -> 0.98859316 | O11: =O10 -> 500 | P11: =I11/F11 -> 10751.665 | Q11: =$Q$6*K11 -> 57.088487 | R11: =P11+Q11 -> 10808.754 | S11: =M11-R11 -> 2191.2464 | T11: =S11/M11 -> 0.16855742 | U11: ='[2]2. Khánh Nga'!B36 -> % Chai B5 | V11: ='[2]2. Khánh Nga'!O36 -> 0.019802359 | W11: ='[2]2. Khánh Nga'!B36 -> % Chai B5 | X11: ='[2]2. Khánh Nga'!O36 -> 0.019802359 | Y11: ='[2]3. Đồng Lâm'!B341 -> % Chai B5 | Z11: ='[2]3. Đồng Lâm'!O341 -> 0.010656982 | AE11: =T11*V11 -> 0.0033378344
C12: Chai PET B6.1 | F12: =D12 -> 0 | H12: =F12*G12 -> 0 | I12: =$I$6/$H$21*H12 -> 0 | J12: =I12/$I$6 -> 0 | K12: =J12 -> 0 | N12: =M12/$M$21 -> 0 | O12: =O8 -> 3900 | P12: =I12/F12 -> #DIV/0! | Q12: =$Q$6*K12 -> 0 | R12: =P12+Q12 -> #DIV/0! | S12: =M12-R12 -> #DIV/0! | T12: =S12/M12 -> #DIV/0! | AE12: =T12*V12 -> #DIV/0!
B13: 160000005 | C13: Chai PET B6.2 | D13: 270 | E13: 0.27 | F13: =D13 -> 270 | G13: 1.1 | H13: =F13*G13 -> 297 | I13: =$I$6/$H$21*H13 -> 3193244.5 | J13: =I13/$I$6 -> 0.28258801 | K13: =J13 -> 0.28258801 | M13: =ROUND($M$6+$M$6*$M$5+O13,-2) -> 14500 | N13: =M13/$M$21 -> 1.1026616 | O13: =O9 -> 2000 | P13: =I13/F13 -> 11826.832 | Q13: =$Q$6*K13 -> 847.76403 | R13: =P13+Q13 -> 12674.596 | S13: =M13-R13 -> 1825.4044 | T13: =S13/M13 -> 0.12588996 | U13: ='[2]1. Đại Lộc'!B329 -> % Chai B6.2 | V13: ='[2]1. Đại Lộc'!O329 -> 0.19170632 | W13: ='[2]2. Khánh Nga'!B34 -> % Chai B6.2 | X13: ='[2]2. Khánh Nga'!O34 -> 0.23118717 | Y13: ='[2]3. Đồng Lâm'!B339 -> % Chai B6.2 | Z13: ='[2]3. Đồng Lâm'!O339 -> 0.26757253 | AE13: =T13*V13 -> 0.024133901
B14: 160000007 | C14: Nắp HD Ép Các Màu HDE-06 | D14: 10 | E14: 0.01 | F14: =D14 -> 10 | G14: 0.6 | H14: =F14*G14 -> 6 | I14: =$I$6/$H$21*H14 -> 64509.99 | J14: =I14/$I$6 -> 0.0057088487 | K14: =J14 -> 0.0057088487 | M14: =ROUND($M$6+$M$6*$M$5+O14,-2) -> 7500 | N14: =M14/$M$21 -> 0.57034221 | O14: -5000 | P14: =I14/F14 -> 6450.999 | Q14: =$Q$6*K14 -> 17.126546 | R14: =P14+Q14 -> 6468.1256 | S14: =M14-R14 -> 1031.8744 | T14: =S14/M14 -> 0.13758325 | U14: ='[2]2. Khánh Nga'!B37 -> % Nắp | V14: ='[2]2. Khánh Nga'!O37 -> 0.031786115 | W14: ='[2]2. Khánh Nga'!B37 -> % Nắp | X14: ='[2]2. Khánh Nga'!O37 -> 0.031786115 | Y14: ='[2]3. Đồng Lâm'!B342 -> % Nắp | Z14: ='[2]3. Đồng Lâm'!O342 -> 0.0029470813 | AE14: =T14*V14 -> 0.0043732371
C15: Chai PET B7.1 | E15: 0 | N15: =M15/$M$21 -> 0 | P15: =I15/F15 -> #DIV/0! | Q15: =$Q$6*K15 -> 0 | R15: =P15+Q15 -> #DIV/0! | S15: =M15-R15 -> #DIV/0! | T15: =S15/M15 -> #DIV/0! | AE15: =T15*V15 -> #DIV/0!
B16: 160000084 | C16: Chai PET B7.2 | E16: 0 | N16: =M16/$M$21 -> 0 | O16: -1000 | P16: =I16/F16 -> #DIV/0! | Q16: =$Q$6*K16 -> 0 | R16: =P16+Q16 -> #DIV/0! | S16: =M16-R16 -> #DIV/0! | T16: =S16/M16 -> #DIV/0! | U16: ='[2]2. Khánh Nga'!B38 -> % Chai B7.2 | V16: ='[2]2. Khánh Nga'!O38 -> 1.842727e-05 | W16: ='[2]2. Khánh Nga'!B38 -> % Chai B7.2 | X16: ='[2]2. Khánh Nga'!O38 -> 1.842727e-05 | Y16: ='[2]3. Đồng Lâm'!B343 -> % Phó sản | Z16: ='[2]3. Đồng Lâm'!O343 -> 0.0089157794
B17: 160000062 | C17: Cổ Chai PET | E17: 0 | N17: =M17/$M$21 -> 0 | O17: 2000 | P17: =I17/F17 -> #DIV/0! | Q17: =$Q$6*K17 -> 0 | R17: =P17+Q17 -> #DIV/0! | S17: =M17-R17 -> #DIV/0! | T17: =S17/M17 -> #DIV/0!
B18: 160000006 | C18: Hao Hụt - Tạp chất | D18: 10 | E18: 0.01 | P18: =I18/F18 -> #DIV/0! | Q18: =$Q$6*K18 -> 0 | R18: =P18+Q18 -> #DIV/0! | S18: =M18-R18 -> #DIV/0! | T18: =S18/M18 -> #DIV/0!
B19: 800000006 | C19: Hao hụt - nhãn chai PET | D19: 60 | E19: 0.06 | P19: =I19/F19 -> #DIV/0! | Q19: =$Q$6*K19 -> 0 | R19: =P19+Q19 -> #DIV/0! | S19: =M19-R19 -> #DIV/0! | T19: =S19/M19 -> #DIV/0!
C20: Hao hụt vô hình | D20: =D6-SUM(D7:D19) -> 40 | E20: 0.04 | P20: =I20/F20 -> #DIV/0! | Q20: =$Q$6*K20 -> 0 | R20: =P20+Q20 -> #DIV/0! | S20: =M20-R20 -> #DIV/0! | T20: =S20/M20 -> #DIV/0!
C21: TỔNG | D21: =SUM(D7:D20) -> 1000 | E21: =SUM(E7:E20) -> 1 | F21: =SUM(F7:F20) -> 890 | G21: =SUM(G7:G20) -> 6.05 | H21: =SUM(H7:H20) -> 1051 | I21: =SUM(I7:I20) -> 11300000 | M21: =AVERAGE(M7:M19) -> 13150 | P21: =I21/F21 -> 12696.629 | T21: =S21/M21 -> 0
P22: =10000/(F21/1000)-P21 -> -1460.6742
B24: II. | C24: CÔNG ĐOẠN BĂM CHAI B6.2 | D24: BOM - KẾ HOẠCH | F24: Sản lượng thành phẩm thực tế | G24: Hệ số quy đổi | H24: Sản lượng thành phẩm quy đổi | I24: Giá trị nguyên liệu phân bổ cho thành phẩm quy đổi | J24: Settlement rule - BOM | K24: Settlement rule - ROUTING | L24: Ghi chú | M24: Giá bán hiện tại | N24: Hệ số quy đổi giá bán
D25: Số lượng | E25: Tỷ lệ | F25: (1) | G25: (2) | H25: (3)= (1)*(2) | I25: (4) | J25: Tỷ lệ | K25: Tỷ lệ
B26: 160000005 | C26: Chai PET B6.2 | D26: 600 | F26: =SUM(F27:F31) -> 1080 | G26: =SUM(G27:G31) -> 4.1 | I26: =I13/F13*D26 -> 7096099
B27: 160000027 | C27: Vảy PET B6.2_A6 | D27: =D26*E27 -> 510 | E27: 0.85 | F27: =D27 -> 510 | G27: 1.35 | H27: =F27*G27 -> 688.5 | I27: =$I$26/$H$31*H27 -> 6886066.4 | J27: =I27/$I$26 -> 0.97040169 | K27: =J27 -> 0.97040169 | L27: (4) = Tổng giá trị NVL /(Tổng số lượng TP quy đổi) * Sl Tp quy đổi. (5) = Giá trị nguyên liệu phân bổ cho thành phẩm quy đổi / Tổng giá trị nguyên liệu phân bổ cho thành phẩm quy đổi | M27: =ROUND($M$13+O27,-2) -> 16500 | N27: =M27/$M$31 -> 1.2692308 | O27: 2000 | P27: 2500
B28: 160000059 | C28: Vảy nắp hỗn hợp B6.2 | D28: =D26*E28 -> 30 | E28: 0.05 | F28: =D28 -> 30 | G28: 0.7 | H28: =F28*G28 -> 21 | I28: =$I$26/$H$31*H28 -> 210032.53 | J28: =I28/$I$26 -> 0.029598309 | K28: =J28 -> 0.029598309 | M28: =ROUND($M$14+O28,-2) -> 9500 | N28: =M28/$M$31 -> 0.73076923 | O28: =O27 -> 2000 | P28: 2500
C29: Phó sản bụi cám | D29: =D26*5% -> 30
C30: Hao hụt vô hình | D30: =D26*5% -> 30
C31: TỔNG | D31: =SUM(D27:D30) -> 600 | F31: =SUM(F27:F30) -> 540 | G31: =SUM(G27:G30) -> 2.05 | H31: =SUM(H27:H30) -> 709.5 | M31: =AVERAGE(M27:M30) -> 13000
C33: Vảy PET_A5.1 mua ngoài | AB33: 16300

Sheet BOM chuẩn KN
B2: BẢNG TÍNH SETTLEMENT RULE BOM - ROUTING (co-product)
M3: Hide | P3: Giá BO sau Phân loại | AG3: T4 | AJ3: =AJ5-AJ6 -> 4.687753e+08
B4: I. | C4: CÔNG ĐOẠN PHÂN LOẠI CHAI | D4: BOM - KẾ HOẠCH | F4: Sản lượng thành phẩm thực tế | G4: Hệ số quy đổi | H4: Sản lượng thành phẩm quy đổi | I4: Giá trị nguyên liệu phân bổ cho thành phẩm quy đổi | J4: Settlement rule - BOM | K4: Settlement rule - ROUTING | L4: Ghi chú | M4: Giá bán hiện tại | N4: Hệ số quy đổi giá bán | O4: Gap (đảm bảo chi phí và lợi nhuận) | P4: GT NVL | Q4: CFSX | R4: GT SP Trạm | S4: LG | T4: % | V4: Đlộc | X4: KN | Z4: ĐLâm | AB4: Giá thị trường | AG4: SL | AH4: DT | AI4: GV | AJ4: LG | AK4: CF | AL4: LNTT | AM4: %LNST
D5: Số lượng | E5: Tỷ lệ | F5: (1) | G5: (2) | H5: (3)= (1)*(2) | I5: (4) | J5: Tỷ lệ | K5: Tỷ lệ | M5: =MAX(V5,X5,Z5) -> 0.10667325 | U5: Hao hụt | V5: ='[2]1. Đại Lộc'!$O$334 -> 0.10096034 | X5: ='[2]2. Khánh Nga'!$O$39 -> 0.097733527 | Z5: ='[2]3. Đồng Lâm'!$O$344 -> 0.10667325 | AJ5: ='[4]KE30-KhanhNga'!$AK$2 -> 1108265483
B6: 150000001 | C6: Chai PET xá | D6: 1000 | E6: =SUM(E7:E20) -> 1 | I6: =D6*$M$6 -> 11300000 | J6: =SUM(J7:J19) -> 1 | K6: =SUM(K7:K19) -> 1 | M6: 11300 | Q6: =X6 -> 2894.8843 | V6: ='[3]3.CP_TAN'!$Q$78 -> 3684.4011 | X6: ='[3]3.CP_TAN'!$R$78 -> 2894.8843 | Z6: ='[3]3.CP_TAN'!$S$78 -> 2609.6553 | AB6: 10000 | AG6: =SUM(AG7:AG16) -> 641114 | AH6: =SUM(AH7:AH16) -> 9692325500 | AI6: =SUM(AI7:AI16) -> 9.0528353e+09 | AJ6: =SUM(AJ7:AJ16) -> 6.3949019e+08 | AK6: =SUM(AK7:AK16) -> 522969527 | AL6: =SUM(AL7:AL16) -> 1.1652066e+08 | AM6: =AL6/AH6 -> 0.012021951
B7: 160000001 | C7: Chai PET B1.1 | D7: 540 | E7: 0.54 | F7: =D7 -> 540 | G7: 1.25 | H7: =F7*G7 -> 675 | I7: =$I$6/$H$21*H7 -> 7257373.9 | J7: =I7/$I$6 -> 0.64224548 | K7: =J7 -> 0.64224548 | L7: (4) = Tổng giá trị NVL /(Tổng số lượng TP quy đổi) * Sl Tp quy đổi. (5) = Giá trị nguyên liệu phân bổ cho thành phẩm quy đổi / Tổng giá trị nguyên liệu phân bổ cho thành phẩm quy đổi | M7: =ROUND($M$6+O7,-2) -> 15800 | N7: =M7/$M$21 -> 1.2169448 | O7: ='GAP (KN)'!J9 -> 4500 | P7: =I7/F7 -> 13439.581 | Q7: =$Q$6*K7 -> 1859.2263 | R7: =P7+Q7 -> 15298.808 | S7: =M7-R7 -> 501.19232 | T7: =S7/M7 -> 0.031721033 | U7: ='[2]1. Đại Lộc'!B327 -> % Chai B1 | V7: ='[2]1. Đại Lộc'!O327 -> 0.65050165 | W7: ='[2]2. Khánh Nga'!B32 -> % Chai B1 | X7: ='[2]2. Khánh Nga'!O32 -> 0.5258354 | Y7: ='[2]3. Đồng Lâm'!B337 -> % Chai B1 | Z7: ='[2]3. Đồng Lâm'!O337 -> 0.50053443 | AB7: 14500 | AC7: 11200 | AE7: =T7*V7 -> 0.020634584 | AF7: =ROUND($M$6+$M$6*$M$5,-2) -> 12500 | AG7: ='[4]KE30-KhanhNga'!$I$4+'[4]KE30-KhanhNga'!$I$5 -> 407227 | AH7: =AG7*M7 -> 6434186600 | AI7: =AG7*R7 -> 6.2300876e+09 | AJ7: =AH7-AI7 -> 2.0409905e+08 | AK7: ='[4]PL-KhanhNga'!$BO$14+'[4]PL-KhanhNga'!$BO$15 -> 522969527 | AL7: =AJ7-AK7 -> -3.1887048e+08
B8: 160000081 | C8: Chai PET B1.3 | F8: =D8 -> 0 | H8: =F8*G8 -> 0 | I8: =$I$6/$H$21*H8 -> 0 | J8: =I8/$I$6 -> 0 | K8: =J8 -> 0 | N8: =M8/$M$21 -> 0 | O8: =O7 -> 4500 | AE8: =T8*V8 -> 0 | AH8: =AG8*M8 -> 0 | AI8: =AG8*R8 -> 0 | AJ8: =AH8-AI8 -> 0 | AL8: =AJ8-AK8 -> 0
B9: 160000002 | C9: Chai PET B2.2 | D9: 30 | E9: 0.03 | F9: =D9 -> 30 | G9: 1.1 | H9: =F9*G9 -> 33 | I9: =$I$6/$H$21*H9 -> 354804.95 | J9: =I9/$I$6 -> 0.031398668 | K9: =J9 -> 0.031398668 | M9: =ROUND($M$6+O9,-2) -> 14300 | N9: =M9/$M$21 -> 1.1014121 | O9: ='GAP (KN)'!J11 -> 3000 | P9: =I9/F9 -> 11826.832 | Q9: =$Q$6*K9 -> 90.895509 | R9: =P9+Q9 -> 11917.727 | S9: =M9-R9 -> 2382.2729 | T9: =S9/M9 -> 0.16659251 | U9: ='[2]1. Đại Lộc'!B328 -> % Chai B2.2 | V9: ='[2]1. Đại Lộc'!O328 -> 0.0053561787 | W9: ='[2]2. Khánh Nga'!B33 -> % Chai B2.2 | X9: ='[2]2. Khánh Nga'!O33 -> 0.078724377 | Y9: ='[2]3. Đồng Lâm'!B338 -> % Chai B2.2 | Z9: ='[2]3. Đồng Lâm'!O338 -> 0.08356034 | AE9: =T9*V9 -> 0.00089229926 | AG9: ='[4]KE30-KhanhNga'!$I$6 -> 47471 | AH9: =AG9*M9 -> 678835300 | AI9: =AG9*R9 -> 5.6574642e+08 | AJ9: =AH9-AI9 -> 1.1308888e+08 | AL9: =AJ9-AK9 -> 1.1308888e+08
B10: 160000063 | C10: Chai PET B4 | D10: 20 | E10: 0.02 | F10: =D10 -> 20 | G10: 1 | H10: =F10*G10 -> 20 | I10: =$I$6/$H$21*H10 -> 215033.3 | J10: =I10/$I$6 -> 0.019029496 | K10: =J10 -> 0.019029496 | M10: =ROUND($M$6+O10,-2) -> 13000 | N10: =M10/$M$21 -> 1.0012837 | O10: ='GAP (KN)'!J10 -> 1700 | P10: =I10/F10 -> 10751.665 | Q10: =$Q$6*K10 -> 55.088187 | R10: =P10+Q10 -> 10806.753 | S10: =M10-R10 -> 2193.2467 | T10: =S10/M10 -> 0.16871129 | U10: ='[2]2. Khánh Nga'!B35 -> % Chai B4 | V10: ='[2]2. Khánh Nga'!O35 -> 0.014912634 | W10: ='[2]2. Khánh Nga'!B35 -> % Chai B4 | X10: ='[2]2. Khánh Nga'!O35 -> 0.014912634 | Y10: ='[2]3. Đồng Lâm'!B340 -> % Chai B4 | Z10: ='[2]3. Đồng Lâm'!O340 -> 0.019139602 | AE10: =T10*V10 -> 0.0025159296 | AG10: ='[4]KE30-KhanhNga'!$I$7 -> 12220 | AH10: =AG10*M10 -> 158860000 | AI10: =AG10*R10 -> 1.3205852e+08 | AJ10: =AH10-AI10 -> 26801475 | AL10: =AJ10-AK10 -> 26801475
B11: 160000004 | C11: Chai PET B5 | D11: 20 | E11: 0.02 | F11: =D11 -> 20 | G11: 1 | H11: =F11*G11 -> 20 | I11: =$I$6/$H$21*H11 -> 215033.3 | J11: =I11/$I$6 -> 0.019029496 | K11: =J11 -> 0.019029496 | M11: =ROUND($M$6+O11,-2) -> 13000 | N11: =M11/$M$21 -> 1.0012837 | O11: =O10 -> 1700 | P11: =I11/F11 -> 10751.665 | Q11: =$Q$6*K11 -> 55.088187 | R11: =P11+Q11 -> 10806.753 | S11: =M11-R11 -> 2193.2467 | T11: =S11/M11 -> 0.16871129 | U11: ='[2]2. Khánh Nga'!B36 -> % Chai B5 | V11: ='[2]2. Khánh Nga'!O36 -> 0.019802359 | W11: ='[2]2. Khánh Nga'!B36 -> % Chai B5 | X11: ='[2]2. Khánh Nga'!O36 -> 0.019802359 | Y11: ='[2]3. Đồng Lâm'!B341 -> % Chai B5 | Z11: ='[2]3. Đồng Lâm'!O341 -> 0.010656982 | AE11: =T11*V11 -> 0.0033408814 | AG11: ='[4]KE30-KhanhNga'!$I$8 -> 20768 | AH11: =AG11*M11 -> 269984000 | AI11: =AG11*R11 -> 2.2443465e+08 | AJ11: =AH11-AI11 -> 45549348 | AL11: =AJ11-AK11 -> 45549348
C12: Chai PET B6.1 | F12: =D12 -> 0 | H12: =F12*G12 -> 0 | I12: =$I$6/$H$21*H12 -> 0 | J12: =I12/$I$6 -> 0 | K12: =J12 -> 0 | N12: =M12/$M$21 -> 0 | O12: =O8 -> 4500 | AE12: =T12*V12 -> 0 | AH12: =AG12*M12 -> 0 | AI12: =AG12*R12 -> 0 | AJ12: =AH12-AI12 -> 0 | AL12: =AJ12-AK12 -> 0
B13: 160000005 | C13: Chai PET B6.2 | D13: 270 | E13: 0.27 | F13: =D13 -> 270 | G13: 1.1 | H13: =F13*G13 -> 297 | I13: =$I$6/$H$21*H13 -> 3193244.5 | J13: =I13/$I$6 -> 0.28258801 | K13: =J13 -> 0.28258801 | M13: =ROUND($M$6+O13,-2) -> 14300 | N13: =M13/$M$21 -> 1.1014121 | O13: =O9 -> 3000 | P13: =I13/F13 -> 11826.832 | Q13: =$Q$6*K13 -> 818.05958 | R13: =P13+Q13 -> 12644.891 | S13: =M13-R13 -> 1655.1088 | T13: =S13/M13 -> 0.11574188 | U13: ='[2]1. Đại Lộc'!B329 -> % Chai B6.2 | V13: ='[2]1. Đại Lộc'!O329 -> 0.19170632 | W13: ='[2]2. Khánh Nga'!B34 -> % Chai B6.2 | X13: ='[2]2. Khánh Nga'!O34 -> 0.23118717 | Y13: ='[2]3. Đồng Lâm'!B339 -> % Chai B6.2 | Z13: ='[2]3. Đồng Lâm'!O339 -> 0.26757253 | AE13: =T13*V13 -> 0.022188449 | AG13: ='[4]KE30-KhanhNga'!$I$9 -> 147022 | AH13: =AG13*M13 -> 2102414600 | AI13: =AG13*R13 -> 1.8590772e+09 | AJ13: =AH13-AI13 -> 2.4333741e+08 | AL13: =AJ13-AK13 -> 2.4333741e+08
B14: 160000007 | C14: Nắp HD Ép Các Màu HDE-06 | D14: 10 | E14: 0.01 | F14: =D14 -> 10 | G14: 0.6 | H14: =F14*G14 -> 6 | I14: =$I$6/$H$21*H14 -> 64509.99 | J14: =I14/$I$6 -> 0.0057088487 | K14: =J14 -> 0.0057088487 | M14: =ROUND($M$6+O14,-2) -> 7500 | N14: =M14/$M$21 -> 0.57766367 | O14: ='GAP (KN)'!J12 -> -3800 | P14: =I14/F14 -> 6450.999 | Q14: =$Q$6*K14 -> 16.526456 | R14: =P14+Q14 -> 6467.5255 | S14: =M14-R14 -> 1032.4745 | T14: =S14/M14 -> 0.13766327 | U14: ='[2]2. Khánh Nga'!B37 -> % Nắp | V14: ='[2]2. Khánh Nga'!O37 -> 0.031786115 | W14: ='[2]2. Khánh Nga'!B37 -> % Nắp | X14: ='[2]2. Khánh Nga'!O37 -> 0.031786115 | Y14: ='[2]3. Đồng Lâm'!B342 -> % Nắp | Z14: ='[2]3. Đồng Lâm'!O342 -> 0.0029470813 | AE14: =T14*V14 -> 0.0043757804 | AG14: ='[4]KE30-KhanhNga'!$I$10 -> 6406 | AH14: =AG14*M14 -> 48045000 | AI14: =AG14*R14 -> 41430968 | AJ14: =AH14-AI14 -> 6614031.6 | AL14: =AJ14-AK14 -> 6614031.6
C15: Chai PET B7.1 | E15: 0 | N15: =M15/$M$21 -> 0 | AE15: =T15*V15 -> 0 | AH15: =AG15*M15 -> 0 | AI15: =AG15*R15 -> 0 | AJ15: =AH15-AI15 -> 0 | AL15: =AJ15-AK15 -> 0
B16: 160000084 | C16: Chai PET B7.2 | E16: 0 | N16: =M16/$M$21 -> 0 | O16: -1000 | P16: =I16/F16 -> #DIV/0! | Q16: =$Q$6*K16 -> 0 | R16: =P16+Q16 -> #DIV/0! | S16: =M16-R16 -> #DIV/0! | T16: =S16/M16 -> #DIV/0! | U16: ='[2]2. Khánh Nga'!B38 -> % Chai B7.2 | V16: ='[2]2. Khánh Nga'!O38 -> 1.842727e-05 | W16: ='[2]2. Khánh Nga'!B38 -> % Chai B7.2 | X16: ='[2]2. Khánh Nga'!O38 -> 1.842727e-05 | Y16: ='[2]3. Đồng Lâm'!B343 -> % Phó sản | Z16: ='[2]3. Đồng Lâm'!O343 -> 0.0089157794 | AH16: =AG16*M16 -> 0 | AJ16: =AH16-AI16 -> 0 | AL16: =AJ16-AK16 -> 0
B17: 160000062 | C17: Cổ Chai PET | E17: 0 | N17: =M17/$M$21 -> 0 | O17: 2000 | AH17: ='[4]KE30-KhanhNga'!$K$11 -> 78728160
B18: 160000006 | C18: Hao Hụt - Tạp chất | D18: 10 | E18: 0.01
B19: 800000006 | C19: Hao hụt - nhãn chai PET | D19: 60 | E19: 0.06
C20: Hao hụt vô hình | D20: =D6-SUM(D7:D19) -> 40 | E20: 0.04
C21: TỔNG | D21: =SUM(D7:D20) -> 1000 | E21: =SUM(E7:E20) -> 1 | F21: =SUM(F7:F20) -> 890 | G21: =SUM(G7:G20) -> 6.05 | H21: =SUM(H7:H20) -> 1051 | I21: =SUM(I7:I20) -> 11300000 | M21: =AVERAGE(M7:M19) -> 12983.333 | P21: =I21/F21 -> 12696.629 | T21: =S21/M21 -> 0
P22: =10000/(F21/1000)-P21 -> -1460.6742
B24: II. | C24: CÔNG ĐOẠN BĂM CHAI B6.2 | D24: BOM - KẾ HOẠCH | F24: Sản lượng thành phẩm thực tế | G24: Hệ số quy đổi | H24: Sản lượng thành phẩm quy đổi | I24: Giá trị nguyên liệu phân bổ cho thành phẩm quy đổi | J24: Settlement rule - BOM | K24: Settlement rule - ROUTING | L24: Ghi chú | M24: Giá bán hiện tại | N24: Hệ số quy đổi giá bán
D25: Số lượng | E25: Tỷ lệ | F25: (1) | G25: (2) | H25: (3)= (1)*(2) | I25: (4) | J25: Tỷ lệ | K25: Tỷ lệ
B26: 160000005 | C26: Chai PET B6.2 | D26: 600 | F26: =SUM(F27:F31) -> 1080 | G26: =SUM(G27:G31) -> 4.1 | I26: =I13/F13*D26 -> 7096099
B27: 160000027 | C27: Vảy PET B6.2_A6 | D27: =D26*E27 -> 510 | E27: 0.85 | F27: =D27 -> 510 | G27: 1.35 | H27: =F27*G27 -> 688.5 | I27: =$I$26/$H$31*H27 -> 6886066.4 | J27: =I27/$I$26 -> 0.97040169 | K27: =J27 -> 0.97040169 | L27: (4) = Tổng giá trị NVL /(Tổng số lượng TP quy đổi) * Sl Tp quy đổi. (5) = Giá trị nguyên liệu phân bổ cho thành phẩm quy đổi / Tổng giá trị nguyên liệu phân bổ cho thành phẩm quy đổi | M27: =ROUND($M$13+O27,-2) -> 16300 | N27: =M27/$M$31 -> 1.2635659 | O27: 2000 | P27: 2500
B28: 160000059 | C28: Vảy nắp hỗn hợp B6.2 | D28: =D26*E28 -> 30 | E28: 0.05 | F28: =D28 -> 30 | G28: 0.7 | H28: =F28*G28 -> 21 | I28: =$I$26/$H$31*H28 -> 210032.53 | J28: =I28/$I$26 -> 0.029598309 | K28: =J28 -> 0.029598309 | M28: =ROUND($M$14+O28,-2) -> 9500 | N28: =M28/$M$31 -> 0.73643411 | O28: =O27 -> 2000 | P28: 2500
C29: Phó sản bụi cám | D29: =D26*5% -> 30
C30: Hao hụt vô hình | D30: =D26*5% -> 30
C31: TỔNG | D31: =SUM(D27:D30) -> 600 | F31: =SUM(F27:F30) -> 540 | G31: =SUM(G27:G30) -> 2.05 | H31: =SUM(H27:H30) -> 709.5 | M31: =AVERAGE(M27:M30) -> 12900
C33: Vảy PET_A5.1 mua ngoài | AB33: 16300

Sheet BOM chuẩn DLA
B2: BẢNG TÍNH SETTLEMENT RULE BOM - ROUTING (co-product)
M3: Hide | P3: Giá BO sau Phân loại | AG3: T4 | AH3: =AH5-AH6 -> 75597922 | AI3: =AI5-AI6 -> -2.7385409e+08 | AJ3: =AJ5-AJ6 -> 3.4945201e+08
B4: I. | C4: CÔNG ĐOẠN PHÂN LOẠI CHAI | D4: BOM - KẾ HOẠCH | F4: Sản lượng thành phẩm thực tế | G4: Hệ số quy đổi | H4: Sản lượng thành phẩm quy đổi | I4: Giá trị nguyên liệu phân bổ cho thành phẩm quy đổi | J4: Settlement rule - BOM | K4: Settlement rule - ROUTING | L4: Ghi chú | M4: Giá bán hiện tại | N4: Hệ số quy đổi giá bán | O4: Gap (đảm bảo chi phí và lợi nhuận) | P4: GT NVL | Q4: CFSX | R4: GT SP Trạm | S4: LG | T4: % | V4: Đlộc | X4: KN | Z4: ĐLâm | AB4: Giá thị trường | AG4: SL | AH4: DT | AI4: GV | AJ4: LG | AK4: CF | AL4: LNTT
D5: Số lượng | E5: Tỷ lệ | F5: (1) | G5: (2) | H5: (3)= (1)*(2) | I5: (4) | J5: Tỷ lệ | K5: Tỷ lệ | M5: =MAX(V5,X5,Z5) -> 0.10667325 | U5: Hao hụt | V5: ='[2]1. Đại Lộc'!$O$334 -> 0.10096034 | X5: ='[2]2. Khánh Nga'!$O$39 -> 0.097733527 | Z5: ='[2]3. Đồng Lâm'!$O$344 -> 0.10667325 | AH5: ='[4]KE30-DongLam'!$K$2 -> 7009495222 | AI5: ='[4]KE30-DongLam'!$AJ$2 -> 6103584508 | AJ5: ='[4]KE30-DongLam'!$AK$2 -> 905910714
B6: 150000001 | C6: Chai PET xá | D6: 1000 | E6: =SUM(E7:E20) -> 1 | I6: =D6*$M$6 -> 11300000 | J6: =SUM(J7:J19) -> 1 | K6: =SUM(K7:K19) -> 1 | M6: 11300 | Q6: =Z6 -> 2609.6553 | V6: ='[3]3.CP_TAN'!$Q$78 -> 3684.4011 | X6: ='[3]3.CP_TAN'!$R$78 -> 2894.8843 | Z6: ='[3]3.CP_TAN'!$S$78 -> 2609.6553 | AB6: 10000 | AG6: =SUM(AG7:AG16) -> 461494 | AH6: =SUM(AH7:AH16) -> 6933897300 | AI6: =SUM(AI7:AI16) -> 6.3774386e+09 | AJ6: =SUM(AJ7:AJ16) -> 5.564587e+08 | AK6: =SUM(AK7:AK16) -> 467209211 | AL6: =SUM(AL7:AL16) -> 89249491 | AM6: =AL6/AH6 -> 0.012871476
B7: 160000001 | C7: Chai PET B1.1 | D7: 540 | E7: 0.54 | F7: =D7 -> 540 | G7: 1.25 | H7: =F7*G7 -> 675 | I7: =$I$6/$H$21*H7 -> 7257373.9 | J7: =I7/$I$6 -> 0.64224548 | K7: =J7 -> 0.64224548 | L7: (4) = Tổng giá trị NVL /(Tổng số lượng TP quy đổi) * Sl Tp quy đổi. (5) = Giá trị nguyên liệu phân bổ cho thành phẩm quy đổi / Tổng giá trị nguyên liệu phân bổ cho thành phẩm quy đổi | M7: =ROUND($M$6+O7,-2) -> 15800 | N7: =M7/$M$21 -> 1.2169448 | O7: ='GAP (KN)'!J9 -> 4500 | P7: =I7/F7 -> 13439.581 | Q7: =$Q$6*K7 -> 1676.0393 | R7: =P7+Q7 -> 15115.621 | S7: =M7-R7 -> 684.3793 | T7: =S7/M7 -> 0.043315146 | U7: ='[2]1. Đại Lộc'!B327 -> % Chai B1 | V7: ='[2]1. Đại Lộc'!O327 -> 0.65050165 | W7: ='[2]2. Khánh Nga'!B32 -> % Chai B1 | X7: ='[2]2. Khánh Nga'!O32 -> 0.5258354 | Y7: ='[2]3. Đồng Lâm'!B337 -> % Chai B1 | Z7: ='[2]3. Đồng Lâm'!O337 -> 0.50053443 | AB7: 14500 | AC7: 11200 | AE7: =T7*V7 -> 0.028176574 | AF7: =ROUND($M$6+$M$6*$M$5,-2) -> 12500 | AG7: ='[4]KE30-DongLam'!$AL$4+'[4]KE30-DongLam'!$AL$5 -> 264497 | AH7: =AG7*M7 -> 4179052600 | AI7: =AG7*R7 -> 3.9980363e+09 | AJ7: =AH7-AI7 -> 1.8101627e+08 | AK7: ='[4]PL-DongLam'!$BO$14+'[4]PL-DongLam'!$BO$15 -> 467209211 | AL7: =AJ7-AK7 -> -2.8619294e+08
B8: 160000081 | C8: Chai PET B1.3 | F8: =D8 -> 0 | H8: =F8*G8 -> 0 | I8: =$I$6/$H$21*H8 -> 0 | J8: =I8/$I$6 -> 0 | K8: =J8 -> 0 | N8: =M8/$M$21 -> 0 | O8: =O7 -> 4500 | AE8: =T8*V8 -> 0 | AH8: =AG8*M8 -> 0 | AI8: =AG8*R8 -> 0 | AJ8: =AH8-AI8 -> 0 | AL8: =AJ8-AK8 -> 0
B9: 160000002 | C9: Chai PET B2.2 | D9: 30 | E9: 0.03 | F9: =D9 -> 30 | G9: 1.1 | H9: =F9*G9 -> 33 | I9: =$I$6/$H$21*H9 -> 354804.95 | J9: =I9/$I$6 -> 0.031398668 | K9: =J9 -> 0.031398668 | M9: =ROUND($M$6+O9,-2) -> 14300 | N9: =M9/$M$21 -> 1.1014121 | O9: ='GAP (KN)'!J11 -> 3000 | P9: =I9/F9 -> 11826.832 | Q9: =$Q$6*K9 -> 81.939701 | R9: =P9+Q9 -> 11908.771 | S9: =M9-R9 -> 2391.2287 | T9: =S9/M9 -> 0.16721879 | U9: ='[2]1. Đại Lộc'!B328 -> % Chai B2.2 | V9: ='[2]1. Đại Lộc'!O328 -> 0.0053561787 | W9: ='[2]2. Khánh Nga'!B33 -> % Chai B2.2 | X9: ='[2]2. Khánh Nga'!O33 -> 0.078724377 | Y9: ='[2]3. Đồng Lâm'!B338 -> % Chai B2.2 | Z9: ='[2]3. Đồng Lâm'!O338 -> 0.08356034 | AE9: =T9*V9 -> 0.00089565373 | AG9: ='[4]KE30-DongLam'!$I$6 -> 51840 | AH9: =AG9*M9 -> 741312000 | AI9: =AG9*R9 -> 6.173507e+08 | AJ9: =AH9-AI9 -> 1.239613e+08 | AL9: =AJ9-AK9 -> 1.239613e+08
B10: 160000063 | C10: Chai PET B4 | D10: 20 | E10: 0.02 | F10: =D10 -> 20 | G10: 1 | H10: =F10*G10 -> 20 | I10: =$I$6/$H$21*H10 -> 215033.3 | J10: =I10/$I$6 -> 0.019029496 | K10: =J10 -> 0.019029496 | M10: =ROUND($M$6+O10,-2) -> 13000 | N10: =M10/$M$21 -> 1.0012837 | O10: ='GAP (KN)'!J10 -> 1700 | P10: =I10/F10 -> 10751.665 | Q10: =$Q$6*K10 -> 49.660425 | R10: =P10+Q10 -> 10801.326 | S10: =M10-R10 -> 2198.6745 | T10: =S10/M10 -> 0.16912881 | U10: ='[2]2. Khánh Nga'!B35 -> % Chai B4 | V10: ='[2]2. Khánh Nga'!O35 -> 0.014912634 | W10: ='[2]2. Khánh Nga'!B35 -> % Chai B4 | X10: ='[2]2. Khánh Nga'!O35 -> 0.014912634 | Y10: ='[2]3. Đồng Lâm'!B340 -> % Chai B4 | Z10: ='[2]3. Đồng Lâm'!O340 -> 0.019139602 | AE10: =T10*V10 -> 0.002522156 | AG10: ='[4]KE30-DongLam'!$I$7 -> 6563 | AH10: =AG10*M10 -> 85319000 | AI10: =AG10*R10 -> 70889099 | AJ10: =AH10-AI10 -> 14429901 | AL10: =AJ10-AK10 -> 14429901
B11: 160000004 | C11: Chai PET B5 | D11: 20 | E11: 0.02 | F11: =D11 -> 20 | G11: 1 | H11: =F11*G11 -> 20 | I11: =$I$6/$H$21*H11 -> 215033.3 | J11: =I11/$I$6 -> 0.019029496 | K11: =J11 -> 0.019029496 | M11: =ROUND($M$6+O11,-2) -> 13000 | N11: =M11/$M$21 -> 1.0012837 | O11: =O10 -> 1700 | P11: =I11/F11 -> 10751.665 | Q11: =$Q$6*K11 -> 49.660425 | R11: =P11+Q11 -> 10801.326 | S11: =M11-R11 -> 2198.6745 | T11: =S11/M11 -> 0.16912881 | U11: ='[2]2. Khánh Nga'!B36 -> % Chai B5 | V11: ='[2]2. Khánh Nga'!O36 -> 0.019802359 | W11: ='[2]2. Khánh Nga'!B36 -> % Chai B5 | X11: ='[2]2. Khánh Nga'!O36 -> 0.019802359 | Y11: ='[2]3. Đồng Lâm'!B341 -> % Chai B5 | Z11: ='[2]3. Đồng Lâm'!O341 -> 0.010656982 | AE11: =T11*V11 -> 0.0033491493 | AG11: ='[4]KE30-DongLam'!$I$8 -> 3401 | AH11: =AG11*M11 -> 44213000 | AI11: =AG11*R11 -> 36735308 | AJ11: =AH11-AI11 -> 7477692 | AL11: =AJ11-AK11 -> 7477692
C12: Chai PET B6.1 | F12: =D12 -> 0 | H12: =F12*G12 -> 0 | I12: =$I$6/$H$21*H12 -> 0 | J12: =I12/$I$6 -> 0 | K12: =J12 -> 0 | N12: =M12/$M$21 -> 0 | O12: =O8 -> 4500 | AE12: =T12*V12 -> 0 | AH12: =AG12*M12 -> 0 | AI12: =AG12*R12 -> 0 | AJ12: =AH12-AI12 -> 0 | AL12: =AJ12-AK12 -> 0
B13: 160000005 | C13: Chai PET B6.2 | D13: 270 | E13: 0.27 | F13: =D13 -> 270 | G13: 1.1 | H13: =F13*G13 -> 297 | I13: =$I$6/$H$21*H13 -> 3193244.5 | J13: =I13/$I$6 -> 0.28258801 | K13: =J13 -> 0.28258801 | M13: =ROUND($M$6+O13,-2) -> 14300 | N13: =M13/$M$21 -> 1.1014121 | O13: =O9 -> 3000 | P13: =I13/F13 -> 11826.832 | Q13: =$Q$6*K13 -> 737.45731 | R13: =P13+Q13 -> 12564.289 | S13: =M13-R13 -> 1735.7111 | T13: =S13/M13 -> 0.1213784 | U13: ='[2]1. Đại Lộc'!B329 -> % Chai B6.2 | V13: ='[2]1. Đại Lộc'!O329 -> 0.19170632 | W13: ='[2]2. Khánh Nga'!B34 -> % Chai B6.2 | X13: ='[2]2. Khánh Nga'!O34 -> 0.23118717 | Y13: ='[2]3. Đồng Lâm'!B339 -> % Chai B6.2 | Z13: ='[2]3. Đồng Lâm'!O339 -> 0.26757253 | AE13: =T13*V13 -> 0.023269006 | AG13: ='[4]KE30-DongLam'!$I$9 -> 127949 | AH13: =AG13*M13 -> 1829670700 | AI13: =AG13*R13 -> 1.6075882e+09 | AJ13: =AH13-AI13 -> 2.220825e+08 | AL13: =AJ13-AK13 -> 2.220825e+08
B14: 160000007 | C14: Nắp HD Ép Các Màu HDE-06 | D14: 10 | E14: 0.01 | F14: =D14 -> 10 | G14: 0.6 | H14: =F14*G14 -> 6 | I14: =$I$6/$H$21*H14 -> 64509.99 | J14: =I14/$I$6 -> 0.0057088487 | K14: =J14 -> 0.0057088487 | M14: =ROUND($M$6+O14,-2) -> 7500 | N14: =M14/$M$21 -> 0.57766367 | O14: ='GAP (KN)'!J12 -> -3800 | P14: =I14/F14 -> 6450.999 | Q14: =$Q$6*K14 -> 14.898128 | R14: =P14+Q14 -> 6465.8972 | S14: =M14-R14 -> 1034.1028 | T14: =S14/M14 -> 0.13788038 | U14: ='[2]2. Khánh Nga'!B37 -> % Nắp | V14: ='[2]2. Khánh Nga'!O37 -> 0.031786115 | W14: ='[2]2. Khánh Nga'!B37 -> % Nắp | X14: ='[2]2. Khánh Nga'!O37 -> 0.031786115 | Y14: ='[2]3. Đồng Lâm'!B342 -> % Nắp | Z14: ='[2]3. Đồng Lâm'!O342 -> 0.0029470813 | AE14: =T14*V14 -> 0.0043826815 | AG14: ='[4]KE30-DongLam'!$I$10 -> 7244 | AH14: =AG14*M14 -> 54330000 | AI14: =AG14*R14 -> 46838959 | AJ14: =AH14-AI14 -> 7491040.9 | AL14: =AJ14-AK14 -> 7491040.9
C15: Chai PET B7.1 | E15: 0 | N15: =M15/$M$21 -> 0 | AE15: =T15*V15 -> 0 | AH15: =AG15*M15 -> 0 | AI15: =AG15*R15 -> 0 | AJ15: =AH15-AI15 -> 0 | AL15: =AJ15-AK15 -> 0
B16: 160000084 | C16: Chai PET B7.2 | E16: 0 | N16: =M16/$M$21 -> 0 | O16: -1000 | P16: =I16/F16 -> #DIV/0! | Q16: =$Q$6*K16 -> 0 | R16: =P16+Q16 -> #DIV/0! | S16: =M16-R16 -> #DIV/0! | T16: =S16/M16 -> #DIV/0! | U16: ='[2]2. Khánh Nga'!B38 -> % Chai B7.2 | V16: ='[2]2. Khánh Nga'!O38 -> 1.842727e-05 | W16: ='[2]2. Khánh Nga'!B38 -> % Chai B7.2 | X16: ='[2]2. Khánh Nga'!O38 -> 1.842727e-05 | Y16: ='[2]3. Đồng Lâm'!B343 -> % Phó sản | Z16: ='[2]3. Đồng Lâm'!O343 -> 0.0089157794 | AH16: =AG16*M16 -> 0 | AJ16: =AH16-AI16 -> 0 | AL16: =AJ16-AK16 -> 0
B17: 160000062 | C17: Cổ Chai PET | E17: 0 | N17: =M17/$M$21 -> 0 | O17: 2000 | AH17: =
B18: 160000006 | C18: Hao Hụt - Tạp chất | D18: 10 | E18: 0.01
B19: 800000006 | C19: Hao hụt - nhãn chai PET | D19: 60 | E19: 0.06
C20: Hao hụt vô hình | D20: =D6-SUM(D7:D19) -> 40 | E20: 0.04
C21: TỔNG | D21: =SUM(D7:D20) -> 1000 | E21: =SUM(E7:E20) -> 1 | F21: =SUM(F7:F20) -> 890 | G21: =SUM(G7:G20) -> 6.05 | H21: =SUM(H7:H20) -> 1051 | I21: =SUM(I7:I20) -> 11300000 | M21: =AVERAGE(M7:M19) -> 12983.333 | P21: =I21/F21 -> 12696.629 | T21: =S21/M21 -> 0
P22: =10000/(F21/1000)-P21 -> -1460.6742
B24: II. | C24: CÔNG ĐOẠN BĂM CHAI B6.2 | D24: BOM - KẾ HOẠCH | F24: Sản lượng thành phẩm thực tế | G24: Hệ số quy đổi | H24: Sản lượng thành phẩm quy đổi | I24: Giá trị nguyên liệu phân bổ cho thành phẩm quy đổi | J24: Settlement rule - BOM | K24: Settlement rule - ROUTING | L24: Ghi chú | M24: Giá bán hiện tại | N24: Hệ số quy đổi giá bán
D25: Số lượng | E25: Tỷ lệ | F25: (1) | G25: (2) | H25: (3)= (1)*(2) | I25: (4) | J25: Tỷ lệ | K25: Tỷ lệ
B26: 160000005 | C26: Chai PET B6.2 | D26: 600 | F26: =SUM(F27:F31) -> 1080 | G26: =SUM(G27:G31) -> 4.1 | I26: =I13/F13*D26 -> 7096099
B27: 160000027 | C27: Vảy PET B6.2_A6 | D27: =D26*E27 -> 510 | E27: 0.85 | F27: =D27 -> 510 | G27: 1.35 | H27: =F27*G27 -> 688.5 | I27: =$I$26/$H$31*H27 -> 6886066.4 | J27: =I27/$I$26 -> 0.97040169 | K27: =J27 -> 0.97040169 | L27: (4) = Tổng giá trị NVL /(Tổng số lượng TP quy đổi) * Sl Tp quy đổi. (5) = Giá trị nguyên liệu phân bổ cho thành phẩm quy đổi / Tổng giá trị nguyên liệu phân bổ cho thành phẩm quy đổi | M27: =ROUND($M$13+O27,-2) -> 16300 | N27: =M27/$M$31 -> 1.2635659 | O27: 2000 | P27: 2500
B28: 160000059 | C28: Vảy nắp hỗn hợp B6.2 | D28: =D26*E28 -> 30 | E28: 0.05 | F28: =D28 -> 30 | G28: 0.7 | H28: =F28*G28 -> 21 | I28: =$I$26/$H$31*H28 -> 210032.53 | J28: =I28/$I$26 -> 0.029598309 | K28: =J28 -> 0.029598309 | M28: =ROUND($M$14+O28,-2) -> 9500 | N28: =M28/$M$31 -> 0.73643411 | O28: =O27 -> 2000 | P28: 2500
C29: Phó sản bụi cám | D29: =D26*5% -> 30
C30: Hao hụt vô hình | D30: =D26*5% -> 30
C31: TỔNG | D31: =SUM(D27:D30) -> 600 | F31: =SUM(F27:F30) -> 540 | G31: =SUM(G27:G30) -> 2.05 | H31: =SUM(H27:H30) -> 709.5 | M31: =AVERAGE(M27:M30) -> 12900
C33: Vảy PET_A5.1 mua ngoài | AB33: 16300

Sheet BOM&NRV
B2: BẢNG TÍNH SETTLEMENT RULE BOM - ROUTING (co-product)
M3: Hide
B4: I. | C4: CÔNG ĐOẠN PHÂN LOẠI CHAI | D4: BOM - KẾ HOẠCH | F4: Sản lượng thành phẩm thực tế | G4: Hệ số quy đổi | H4: Sản lượng thành phẩm quy đổi | I4: Giá trị nguyên liệu phân bổ cho thành phẩm quy đổi | J4: Settlement rule - BOM | K4: Settlement rule - ROUTING | L4: Ghi chú | M4: Giá bán hiện tại | N4: Hệ số quy đổi giá bán | P4: GT NVL | Q4: CFSX | R4: GT SP Trạm | S4: LG | T4: %
D5: Số lượng | E5: Tỷ lệ | F5: (1) | G5: (2) | H5: (3)= (1)*(2) | I5: (4) | J5: Tỷ lệ | K5: Tỷ lệ
B6: 150000001 | C6: Chai PET xá | D6: 1000 | E6: =SUM(E7:E20) -> 1 | I6: =D6*10000 -> 10000000 | J6: =SUM(J7:J19) -> 1 | K6: =SUM(K7:K19) -> 1 | Q6: 3000
B7: 160000001 | C7: Chai PET B1.1 | D7: 540 | E7: 0.54 | F7: =D7 -> 540 | G7: 1.25 | H7: =F7*G7 -> 675 | I7: =$I$6/$H$21*H7 -> 6422454.8 | J7: =I7/$I$6 -> 0.64224548 | K7: =J7 -> 0.64224548 | L7: (4) = Tổng giá trị NVL /(Tổng số lượng TP quy đổi) * Sl Tp quy đổi. (5) = Giá trị nguyên liệu phân bổ cho thành phẩm quy đổi / Tổng giá trị nguyên liệu phân bổ cho thành phẩm quy đổi | M7: =ROUND(11000+11000*14%+4000,-2) -> 16500 | N7: =M7/$M$21 -> 1.2222222 | P7: =I7/F7 -> 11893.435 | Q7: =$Q$6*K7 -> 1926.7364 | R7: =P7+Q7 -> 13820.171 | S7: =M7-R7 -> 2679.8287 | T7: =S7/M7 -> 0.16241386
B8: 160000081 | C8: Chai PET B1.3 | F8: =D8 -> 0 | H8: =F8*G8 -> 0 | I8: =$I$6/$H$21*H8 -> 0 | J8: =I8/$I$6 -> 0 | K8: =J8 -> 0 | N8: =M8/$M$21 -> 0 | P8: =I8/F8 -> #DIV/0! | Q8: =$Q$6*K8 -> 0 | R8: =P8+Q8 -> #DIV/0! | S8: =M8-R8 -> #DIV/0! | T8: =S8/M8 -> #DIV/0!
B9: 160000002 | C9: Chai PET B2.2 | D9: 30 | E9: 0.03 | F9: =D9 -> 30 | G9: 1.1 | H9: =F9*G9 -> 33 | I9: =$I$6/$H$21*H9 -> 313986.68 | J9: =I9/$I$6 -> 0.031398668 | K9: =J9 -> 0.031398668 | M9: =ROUND(11000+11000*14%+2500,-2) -> 15000 | N9: =M9/$M$21 -> 1.1111111 | P9: =I9/F9 -> 10466.223 | Q9: =$Q$6*K9 -> 94.196004 | R9: =P9+Q9 -> 10560.419 | S9: =M9-R9 -> 4439.5814 | T9: =S9/M9 -> 0.29597209
B10: 160000063 | C10: Chai PET B4 | D10: 20 | E10: 0.02 | F10: =D10 -> 20 | G10: 1 | H10: =F10*G10 -> 20 | I10: =$I$6/$H$21*H10 -> 190294.96 | J10: =I10/$I$6 -> 0.019029496 | K10: =J10 -> 0.019029496 | M10: =ROUND(11000+11000*14%+1000,-2) -> 13500 | N10: =M10/$M$21 -> 1 | P10: =I10/F10 -> 9514.7479 | Q10: =$Q$6*K10 -> 57.088487 | R10: =P10+Q10 -> 9571.8363 | S10: =M10-R10 -> 3928.1637 | T10: =S10/M10 -> 0.29097509
B11: 160000004 | C11: Chai PET B5 | D11: 20 | E11: 0.02 | F11: =D11 -> 20 | G11: 1 | H11: =F11*G11 -> 20 | I11: =$I$6/$H$21*H11 -> 190294.96 | J11: =I11/$I$6 -> 0.019029496 | K11: =J11 -> 0.019029496 | M11: =ROUND(11000+11000*14%+1000,-2) -> 13500 | N11: =M11/$M$21 -> 1 | P11: =I11/F11 -> 9514.7479 | Q11: =$Q$6*K11 -> 57.088487 | R11: =P11+Q11 -> 9571.8363 | S11: =M11-R11 -> 3928.1637 | T11: =S11/M11 -> 0.29097509
C12: Chai PET B6.1 | F12: =D12 -> 0 | H12: =F12*G12 -> 0 | I12: =$I$6/$H$21*H12 -> 0 | J12: =I12/$I$6 -> 0 | K12: =J12 -> 0 | N12: =M12/$M$21 -> 0 | P12: =I12/F12 -> #DIV/0! | Q12: =$Q$6*K12 -> 0 | R12: =P12+Q12 -> #DIV/0! | S12: =M12-R12 -> #DIV/0! | T12: =S12/M12 -> #DIV/0!
B13: 160000005 | C13: Chai PET B6.2 | D13: 270 | E13: 0.27 | F13: =D13 -> 270 | G13: 1.1 | H13: =F13*G13 -> 297 | I13: =$I$6/$H$21*H13 -> 2825880.1 | J13: =I13/$I$6 -> 0.28258801 | K13: =J13 -> 0.28258801 | M13: =ROUND(11000+11000*14%+2500,-2) -> 15000 | N13: =M13/$M$21 -> 1.1111111 | P13: =I13/F13 -> 10466.223 | Q13: =$Q$6*K13 -> 847.76403 | R13: =P13+Q13 -> 11313.987 | S13: =M13-R13 -> 3686.0133 | T13: =S13/M13 -> 0.24573422
B14: 160000007 | C14: Nắp HD Ép Các Màu HDE-06 | D14: 10 | E14: 0.01 | F14: =D14 -> 10 | G14: 0.6 | H14: =F14*G14 -> 6 | I14: =$I$6/$H$21*H14 -> 57088.487 | J14: =I14/$I$6 -> 0.0057088487 | K14: =J14 -> 0.0057088487 | M14: =ROUND(11000+11000*14%-5000,-2) -> 7500 | N14: =M14/$M$21 -> 0.55555556 | P14: =I14/F14 -> 5708.8487 | Q14: =$Q$6*K14 -> 17.126546 | R14: =P14+Q14 -> 5725.9753 | S14: =M14-R14 -> 1774.0247 | T14: =S14/M14 -> 0.23653663
C15: Chai PET B7.1 | E15: 0 | N15: =M15/$M$21 -> 0 | P15: =I15/F15 -> #DIV/0! | Q15: =$Q$6*K15 -> 0 | R15: =P15+Q15 -> #DIV/0! | S15: =M15-R15 -> #DIV/0! | T15: =S15/M15 -> #DIV/0!
B16: 160000084 | C16: Chai PET B7.2 | E16: 0 | N16: =M16/$M$21 -> 0 | P16: =I16/F16 -> #DIV/0! | Q16: =$Q$6*K16 -> 0 | R16: =P16+Q16 -> #DIV/0! | S16: =M16-R16 -> #DIV/0! | T16: =S16/M16 -> #DIV/0!
B17: 160000062 | C17: Cổ Chai PET | E17: 0 | N17: =M17/$M$21 -> 0 | P17: =I17/F17 -> #DIV/0! | Q17: =$Q$6*K17 -> 0 | R17: =P17+Q17 -> #DIV/0! | S17: =M17-R17 -> #DIV/0! | T17: =S17/M17 -> #DIV/0!
B18: 160000006 | C18: Hao Hụt - Tạp chất | D18: 10 | E18: 0.01 | P18: =I18/F18 -> #DIV/0! | Q18: =$Q$6*K18 -> 0 | R18: =P18+Q18 -> #DIV/0! | S18: =M18-R18 -> #DIV/0! | T18: =S18/M18 -> #DIV/0!
B19: 800000006 | C19: Hao hụt - nhãn chai PET | D19: 60 | E19: 0.06 | P19: =I19/F19 -> #DIV/0! | Q19: =$Q$6*K19 -> 0 | R19: =P19+Q19 -> #DIV/0! | S19: =M19-R19 -> #DIV/0! | T19: =S19/M19 -> #DIV/0!
C20: Hao hụt vô hình | D20: =D6-SUM(D7:D19) -> 40 | E20: 0.04 | P20: =I20/F20 -> #DIV/0! | Q20: =$Q$6*K20 -> 0 | R20: =P20+Q20 -> #DIV/0! | S20: =M20-R20 -> #DIV/0! | T20: =S20/M20 -> #DIV/0!
C21: TỔNG | D21: =SUM(D7:D20) -> 1000 | E21: =SUM(E7:E20) -> 1 | F21: =SUM(F7:F20) -> 890 | G21: =SUM(G7:G20) -> 6.05 | H21: =SUM(H7:H20) -> 1051 | I21: =SUM(I7:I20) -> 10000000 | M21: =AVERAGE(M7:M19) -> 13500 | P21: =I21/F21 -> 11235.955 | T21: =S21/M21 -> 0
P22: =10000/(F21/1000)-P21 -> 0
B24: II. | C24: CÔNG ĐOẠN BĂM CHAI B6.2 | D24: BOM - KẾ HOẠCH | F24: Sản lượng thành phẩm thực tế | G24: Hệ số quy đổi | H24: Sản lượng thành phẩm quy đổi | I24: Giá trị nguyên liệu phân bổ cho thành phẩm quy đổi | J24: Settlement rule - BOM | K24: Settlement rule - ROUTING | L24: Ghi chú | M24: Giá bán hiện tại | N24: Hệ số quy đổi giá bán
D25: Số lượng | E25: Tỷ lệ | F25: (1) | G25: (2) | H25: (3)= (1)*(2) | I25: (4) | J25: Tỷ lệ | K25: Tỷ lệ
B26: 160000005 | C26: Chai PET B6.2 | D26: 600 | F26: =SUM(F27:F31) -> 1080 | G26: =SUM(G27:G31) -> 4.1 | I26: =I13/F13*D26 -> 6279733.6
B27: 160000027 | C27: Vảy PET B6.2_A6 | D27: =D26*E27 -> 510 | E27: 0.85 | F27: =D27 -> 510 | G27: 1.35 | H27: =F27*G27 -> 688.5 | I27: =$I$26/$H$31*H27 -> 6093864.1 | J27: =I27/$I$26 -> 0.97040169 | K27: =J27 -> 0.97040169 | L27: (4) = Tổng giá trị NVL /(Tổng số lượng TP quy đổi) * Sl Tp quy đổi. (5) = Giá trị nguyên liệu phân bổ cho thành phẩm quy đổi / Tổng giá trị nguyên liệu phân bổ cho thành phẩm quy đổi | M27: 18500 | N27: =M27/$M$31 -> 1.3214286
B28: 160000059 | C28: Vảy nắp hỗn hợp B6.2 | D28: =D26*E28 -> 30 | E28: 0.05 | F28: =D28 -> 30 | G28: 0.7 | H28: =F28*G28 -> 21 | I28: =$I$26/$H$31*H28 -> 185869.49 | J28: =I28/$I$26 -> 0.029598309 | K28: =J28 -> 0.029598309 | M28: 9500 | N28: =M28/$M$31 -> 0.67857143
C29: Phó sản bụi cám | D29: =D26*5% -> 30
C30: Hao hụt vô hình | D30: =D26*5% -> 30
C31: TỔNG | D31: =SUM(D27:D30) -> 600 | F31: =SUM(F27:F30) -> 540 | G31: =SUM(G27:G30) -> 2.05 | H31: =SUM(H27:H30) -> 709.5 | M31: =AVERAGE(M27:M30) -> 14000

Sheet GAP
B3: BẢNG TÍNH GIÁ MUA CHAI, VẢY TỪ CÁC TRẠM
J4: Giá B0 | K4: Giá B0 | L4: Giá B0 | M4: Giá B0 | N4: Giá B0 | O4: Giá B1
I5: ĐVT: đồng/ký | J5: 9500 | K5: 10000 | L5: 10000 | M5: 11300 | N5: 12500 | O5: 14000
B6: Nhóm chai PET | C6: Thành phần chai PET sau phân loại | D6: Giá B0 | E6: Hao hụt | G6: Gap (đảm bảo chi phí và lợi nhuận) | H6: Giá mua theo công thức | I6: Giá mua đề xuất
E7: Tỷ lệ | F7: Quy ra tiền
B8: A. Giá mua Chai
B9: Chai PET nhóm 1 | C9: B1.1 + B1.2 + B1.3 + B2.1 + B3 + B6.1 | D9: 11300 | E9: 0.11 | F9: =D9*E9 -> 1243 | G9: 3500 | H9: =D9+F9+G9 -> 16043 | I9: 16300 | J9: =I9-D9 -> 5000 | K9: 5000 | L9: 15800 | M9: 16300 | N9: 17500 | O9: 18000 | P9: ='[5]BOM (DLoc) (18.05)'!$M$7 -> 17100 | Q9: =P9-O9 -> -900
B10: Chai PET nhóm 2 | C10: B4 + B5 | D10: 11300 | E10: 0.11 | F10: =D10*E10 -> 1243 | G10: 500 | H10: =D10+F10+G10 -> 13043 | I10: 13300 | J10: =I10-D10 -> 2000 | K10: 2000 | L10: 12800 | M10: 13300 | N10: 14500 | O10: 15000
B11: Chai PET nhóm 3 | C11: B2.2 + B6.2 | D11: 11300 | E11: 0.11 | F11: =D11*E11 -> 1243 | G11: 2000 | H11: =D11+F11+G11 -> 14543 | I11: 14800 | J11: =I11-D11 -> 3500 | K11: 3500 | L11: 14300 | M11: 14800 | N11: 16000 | O11: 16500 | P11: ='[5]BOM (DLoc) (18.05)'!$M$13 -> 14100 | Q11: =P11-O11 -> -2400
B12: Chai PET nhóm 4 | C12: Nắp HD Ép, cổ chai, PP (quai) | D12: 11300 | E12: 0.11 | F12: =D12*E12 -> 1243 | G12: -5000 | H12: =D12+F12+G12 -> 7543 | I12: 7800 | J12: =I12-D12 -> -3500 | K12: -3500 | L12: 7300 | M12: 7800 | N12: 9000 | O12: 9500 | P12: ='[5]BOM (DLoc) (18.05)'!$M$14 -> 7300 | Q12: =P12-O12 -> -2200
B13: B. Giá mua Vảy | L13: =J13-K13 -> 0
B14: Nhóm 1 | C14: Vảy B6.2 | D14: =I11 -> 14800 | E14: 0.08 | F14: =D14*E14 -> 1184 | G14: 2000 | H14: =D14+F14+G14 -> 17984 | I14: 17800 | J14: =I14-D14 -> 3000 | K14: 3000 | L14: 17300 | M14: 17800 | N14: 19000 | O14: 19000
C15: Phó sản | K15: -8000
B16: BẢNG COPY QUA TỜ TRÌNH DUYỆT
B17: Mã SAP | C17: Tên Chai | D17: Giá đề xuất
C18: Chai PET B1.1 | D18: =$I$9 -> 16300
C19: Chai PET B1 KPL (B1.2) | D19: =D18-500 -> 15800
C20: Chai PET B1.3 | D20: =$I$9 -> 16300
B21: 150000004 | C21: Chai PET B2.1 | D21: =$I$9 -> 16300
B22: 150000050 | C22: Chai PET B2.2 | D22: =$I$11 -> 14800
B23: 150000005 | C23: Chai PET B3 | D23: =$I$9 -> 16300
B24: 150000014 | C24: Chai PET B4 | D24: =$I$10 -> 13300
B25: 150000015 | C25: Chai PET B5 | D25: =$I$10 -> 13300
B26: 150000016 | C26: Chai PET B6.1 | D26: =$I$9 -> 16300
B27: 150000114 | C27: Chai PET B6.2 | D27: =$I$11 -> 14800
C28: Nắp HD Ép, cổ chai | D28: =$I$12 -> 7800
C29: PP (quai) | D29: =$I$12 -> 7800
B30: 150000061 | C30: Vảy PET B6.2_A6 | D30: =I14 -> 17800

Sheet GAP (KN)
B3: BẢNG TÍNH GIÁ MUA CHAI, VẢY TỪ CÁC TRẠM
J4: Gap (đảm bảo chi phí và lợi nhuận) | K4: Giá B0 | L4: Giá B0 | M4: Giá B0 | N4: Giá B0 | O4: Giá B1 | R4: CL sau áp giá mới
I5: ĐVT: đồng/ký | K5: 10000 | L5: 10000 | M5: 11300 | N5: 12500 | O5: 14000
B6: Nhóm chai PET | C6: Thành phần chai PET sau phân loại | D6: Giá B0 | E6: Hao hụt | G6: Trình GAP (đảm bảo chi phí và lợi nhuận) | H6: Giá mua theo công thức | I6: Giá mua đề xuất
E7: Tỷ lệ | F7: Quy ra tiền
B8: A. Giá mua Chai
B9: Chai PET nhóm 1 | C9: B1.1 + B1.2 + B1.3 + B2.1 + B3 + B6.1 | D9: 11300 | E9: 0.11 | F9: =D9*E9 -> 1243 | G9: =3500-200 -> 3300 | H9: =D9+F9+G9 -> 15843 | I9: 15800 | J9: =I9-D9 -> 4500 | K9: 5000 | L9: 15800 | M9: 16300 | N9: 17500 | O9: 18000 | P9: ='[5]BOM (DLoc) (18.05)'!$M$7 -> 17100 | Q9: =P9-O9 -> -900 | R9: =I9-M9 -> -500 | S9: 5000
B10: Chai PET nhóm 2 | C10: B4 + B5 | D10: 11300 | E10: 0.11 | F10: =D10*E10 -> 1243 | G10: 500 | H10: =D10+F10+G10 -> 13043 | I10: 13000 | J10: =I10-D10 -> 1700 | K10: 2000 | L10: 12800 | M10: 13300 | N10: 14500 | O10: 15000 | R10: =I10-M10 -> -300 | S10: 2000
B11: Chai PET nhóm 3 | C11: B2.2 + B6.2 | D11: 11300 | E11: 0.11 | F11: =D11*E11 -> 1243 | G11: =2000-200 -> 1800 | H11: =D11+F11+G11 -> 14343 | I11: 14300 | J11: =I11-D11 -> 3000 | K11: 3500 | L11: 14300 | M11: 14800 | N11: 16000 | O11: 16500 | P11: ='[5]BOM (DLoc) (18.05)'!$M$13 -> 14100 | Q11: =P11-O11 -> -2400 | R11: =I11-M11 -> -500 | S11: 3500
B12: Chai PET nhóm 4 | C12: Nắp HD Ép, cổ chai, PP (quai) | D12: 11300 | E12: 0.11 | F12: =D12*E12 -> 1243 | G12: -5000 | H12: =D12+F12+G12 -> 7543 | I12: 7500 | J12: =I12-D12 -> -3800 | K12: -3500 | L12: 7300 | M12: 7800 | N12: 9000 | O12: 9500 | P12: ='[5]BOM (DLoc) (18.05)'!$M$14 -> 7300 | Q12: =P12-O12 -> -2200 | R12: =I12-M12 -> -300 | S12: -3500
B13: B. Giá mua Vảy | L13: =J13-K13 -> 0
B14: Nhóm 1 | C14: Vảy B6.2 | D14: =I11 -> 14300 | E14: 0.08 | F14: =D14*E14 -> 1144 | G14: 2000 | H14: =D14+F14+G14 -> 17444 | I14: 17300 | J14: =I14-D14 -> 3000 | K14: 3000 | L14: 17300 | M14: 17800 | N14: 19000 | O14: 19000 | R14: =I14-M14 -> -500 | S14: 3000
C15: Phó sản | K15: -8000 | S15: -8000
B16: BẢNG COPY QUA TỜ TRÌNH DUYỆT
B17: Mã SAP | C17: Tên Chai | D17: Giá đề xuất
C18: Chai PET B1.1 | D18: =$I$9 -> 15800
C19: Chai PET B1 KPL (B1.2) | D19: =D18-500 -> 15300
C20: Chai PET B1.3 | D20: =$I$9 -> 15800
B21: 150000004 | C21: Chai PET B2.1 | D21: =$I$9 -> 15800
B22: 150000050 | C22: Chai PET B2.2 | D22: =$I$11 -> 14300
B23: 150000005 | C23: Chai PET B3 | D23: =$I$9 -> 15800
B24: 150000014 | C24: Chai PET B4 | D24: =$I$10 -> 13000
B25: 150000015 | C25: Chai PET B5 | D25: =$I$10 -> 13000
B26: 150000016 | C26: Chai PET B6.1 | D26: =$I$9 -> 15800
B27: 150000114 | C27: Chai PET B6.2 | D27: =$I$11 -> 14300
C28: Nắp HD Ép, cổ chai | D28: =$I$12 -> 7500
C29: PP (quai) | D29: =$I$12 -> 7500
B30: 150000061 | C30: Vảy PET B6.2_A6 | D30: =I14 -> 17300

Sheet GAP (DLA)
B3: BẢNG TÍNH GIÁ MUA CHAI, VẢY TỪ CÁC TRẠM
J4: Giá B0 | K4: Giá B0 | L4: Giá B0 | M4: Giá B0 | N4: Giá B0 | O4: Giá B1 | R4: CL sau áp giá mới
I5: ĐVT: đồng/ký | J5: 9500 | K5: 10000 | L5: 10000 | M5: 11300 | N5: 12500 | O5: 14000
B6: Nhóm chai PET | C6: Thành phần chai PET sau phân loại | D6: Giá B0 | E6: Hao hụt | G6: Gap (đảm bảo chi phí và lợi nhuận) | H6: Giá mua theo công thức | I6: Giá mua đề xuất
E7: Tỷ lệ | F7: Quy ra tiền
B8: A. Giá mua Chai
B9: Chai PET nhóm 1 | C9: B1.1 + B1.2 + B1.3 + B2.1 + B3 + B6.1 | D9: 11300 | E9: 0.11 | F9: =D9*E9 -> 1243 | G9: =3500-200 -> 3300 | H9: =D9+F9+G9 -> 15843 | I9: 15800 | J9: =I9-D9 -> 4500 | K9: 5000 | L9: 15800 | M9: 16300 | N9: 17500 | O9: 18000 | P9: ='[5]BOM (DLoc) (18.05)'!$M$7 -> 17100 | Q9: =P9-O9 -> -900 | R9: =I9-M9 -> -500
B10: Chai PET nhóm 2 | C10: B4 + B5 | D10: 11300 | E10: 0.11 | F10: =D10*E10 -> 1243 | G10: 500 | H10: =D10+F10+G10 -> 13043 | I10: 13000 | J10: =I10-D10 -> 1700 | K10: 2000 | L10: 12800 | M10: 13300 | N10: 14500 | O10: 15000 | R10: =I10-M10 -> -300
B11: Chai PET nhóm 3 | C11: B2.2 + B6.2 | D11: 11300 | E11: 0.11 | F11: =D11*E11 -> 1243 | G11: =2000-200 -> 1800 | H11: =D11+F11+G11 -> 14343 | I11: 14300 | J11: =I11-D11 -> 3000 | K11: 3500 | L11: 14300 | M11: 14800 | N11: 16000 | O11: 16500 | P11: ='[5]BOM (DLoc) (18.05)'!$M$13 -> 14100 | Q11: =P11-O11 -> -2400 | R11: =I11-M11 -> -500
B12: Chai PET nhóm 4 | C12: Nắp HD Ép, cổ chai, PP (quai) | D12: 11300 | E12: 0.11 | F12: =D12*E12 -> 1243 | G12: -5000 | H12: =D12+F12+G12 -> 7543 | I12: 7500 | J12: =I12-D12 -> -3800 | K12: -3500 | L12: 7300 | M12: 7800 | N12: 9000 | O12: 9500 | P12: ='[5]BOM (DLoc) (18.05)'!$M$14 -> 7300 | Q12: =P12-O12 -> -2200 | R12: =I12-M12 -> -300
B13: B. Giá mua Vảy | L13: =J13-K13 -> 0
B14: Nhóm 1 | C14: Vảy B6.2 | D14: =I11 -> 14300 | E14: 0.08 | F14: =D14*E14 -> 1144 | G14: 2000 | H14: =D14+F14+G14 -> 17444 | I14: 17300 | J14: =I14-D14 -> 3000 | K14: 3000 | L14: 17300 | M14: 17800 | N14: 19000 | O14: 19000 | R14: =I14-M14 -> -500
C15: Phó sản | K15: -8000
B16: BẢNG COPY QUA TỜ TRÌNH DUYỆT
B17: Mã SAP | C17: Tên Chai | D17: Giá đề xuất
C18: Chai PET B1.1 | D18: =$I$9 -> 15800
C19: Chai PET B1 KPL (B1.2) | D19: =D18-500 -> 15300
C20: Chai PET B1.3 | D20: =$I$9 -> 15800
B21: 150000004 | C21: Chai PET B2.1 | D21: =$I$9 -> 15800
B22: 150000050 | C22: Chai PET B2.2 | D22: =$I$11 -> 14300
B23: 150000005 | C23: Chai PET B3 | D23: =$I$9 -> 15800
B24: 150000014 | C24: Chai PET B4 | D24: =$I$10 -> 13000
B25: 150000015 | C25: Chai PET B5 | D25: =$I$10 -> 13000
B26: 150000016 | C26: Chai PET B6.1 | D26: =$I$9 -> 15800
B27: 150000114 | C27: Chai PET B6.2 | D27: =$I$11 -> 14300
C28: Nắp HD Ép, cổ chai | D28: =$I$12 -> 7500
C29: PP (quai) | D29: =$I$12 -> 7500
B30: 150000061 | C30: Vảy PET B6.2_A6 | D30: =I14 -> 17300

Sheet GAP (DLO)
B3: BẢNG TÍNH GIÁ MUA CHAI, VẢY TỪ CÁC TRẠM
J4: Giá B0 | K4: Giá B0 | L4: Giá B0 | M4: Giá B0 | N4: Giá B0 | O4: Giá B1
I5: ĐVT: đồng/ký | J5: 9500 | K5: 10000 | L5: 10000 | M5: 11300 | N5: 12500 | O5: 14000
B6: Nhóm chai PET | C6: Thành phần chai PET sau phân loại | D6: Giá B0 | E6: Hao hụt | G6: Gap (đảm bảo chi phí và lợi nhuận) | H6: Giá mua theo công thức | I6: Giá mua đề xuất
E7: Tỷ lệ | F7: Quy ra tiền
B8: A. Giá mua Chai
B9: Chai PET nhóm 1 | C9: B1.1 + B1.2 + B1.3 + B2.1 + B3 + B6.1 | D9: 11300 | E9: 0.11 | F9: =D9*E9 -> 1243 | G9: =3500+200 -> 3700 | H9: =D9+F9+G9 -> 16243 | I9: 16300 | J9: =I9-D9 -> 5000 | K9: 5000 | L9: 15800 | M9: 16300 | N9: 17500 | O9: 18000 | P9: ='[5]BOM (DLoc) (18.05)'!$M$7 -> 17100 | Q9: =P9-O9 -> -900
B10: Chai PET nhóm 2 | C10: B4 + B5 | D10: 11300 | E10: 0.11 | F10: =D10*E10 -> 1243 | G10: =500+200 -> 700 | H10: =D10+F10+G10 -> 13243 | I10: 13300 | J10: =I10-D10 -> 2000 | K10: 2000 | L10: 12800 | M10: 13300 | N10: 14500 | O10: 15000
B11: Chai PET nhóm 3 | C11: B2.2 + B6.2 | D11: 11300 | E11: 0.11 | F11: =D11*E11 -> 1243 | G11: =2000 -> 2000 | H11: =D11+F11+G11 -> 14543 | I11: 14800 | J11: =I11-D11 -> 3500 | K11: 3500 | L11: 14300 | M11: 14800 | N11: 16000 | O11: 16500 | P11: ='[5]BOM (DLoc) (18.05)'!$M$13 -> 14100 | Q11: =P11-O11 -> -2400
B12: Chai PET nhóm 4 | C12: Nắp HD Ép, cổ chai, PP (quai) | D12: 11300 | E12: 0.11 | F12: =D12*E12 -> 1243 | G12: -5000 | H12: =D12+F12+G12 -> 7543 | I12: 7500 | J12: =I12-D12 -> -3800 | K12: -3500 | L12: 7300 | M12: 7800 | N12: 9000 | O12: 9500 | P12: ='[5]BOM (DLoc) (18.05)'!$M$14 -> 7300 | Q12: =P12-O12 -> -2200
B13: B. Giá mua Vảy | L13: =J13-K13 -> 0
B14: Nhóm 1 | C14: Vảy B6.2 | D14: =I11 -> 14800 | E14: 0.08 | F14: =D14*E14 -> 1184 | G14: 2000 | H14: =D14+F14+G14 -> 17984 | I14: 17800 | J14: =I14-D14 -> 3000 | K14: 3000 | L14: 17300 | M14: 17800 | N14: 19000 | O14: 19000
C15: Phó sản | K15: -8000
B16: BẢNG COPY QUA TỜ TRÌNH DUYỆT
B17: Mã SAP | C17: Tên Chai | D17: Giá đề xuất
C18: Chai PET B1.1 | D18: =$I$9 -> 16300
C19: Chai PET B1 KPL (B1.2) | D19: =D18-500 -> 15800
C20: Chai PET B1.3 | D20: =$I$9 -> 16300
B21: 150000004 | C21: Chai PET B2.1 | D21: =$I$9 -> 16300
B22: 150000050 | C22: Chai PET B2.2 | D22: =$I$11 -> 14800
B23: 150000005 | C23: Chai PET B3 | D23: =$I$9 -> 16300
B24: 150000014 | C24: Chai PET B4 | D24: =$I$10 -> 13300
B25: 150000015 | C25: Chai PET B5 | D25: =$I$10 -> 13300
B26: 150000016 | C26: Chai PET B6.1 | D26: =$I$9 -> 16300
B27: 150000114 | C27: Chai PET B6.2 | D27: =$I$11 -> 14800
C28: Nắp HD Ép, cổ chai | D28: =$I$12 -> 7500
C29: PP (quai) | D29: =$I$12 -> 7500
B30: 150000061 | C30: Vảy PET B6.2_A6 | D30: =I14 -> 17800

Sheet So sánh thiệt hại
B1: Giá chai B0 | C1: 10000 | K1: Giá chai B0 | L1: 10000 | T1: Giá chai B0 | U1: 10000 | AC1: Giá chai B0 | AD1: 11300
B2: Chi phí phân loại | C2: 3000 | K2: Chi phí phân loại | L2: 3000 | T2: Chi phí phân loại | U2: 3000 | AC2: Chi phí phân loại | AD2: 3000
B3: Tỷ lệ hao hụt thực tế | C3: 0.1 | K3: Tỷ lệ hao hụt thực tế | L3: 0.1 | T3: Tỷ lệ hao hụt thực tế | U3: 0.1 | AC3: Tỷ lệ hao hụt thực tế | AD3: 0.1
B4: Tổng chi phí | C4: =SUM(C1:C2) -> 13000 | K4: Tổng chi phí | L4: =SUM(L1:L2) -> 13000 | T4: Tổng chi phí | U4: =SUM(U1:U2) -> 13000 | AC4: Tổng chi phí | AD4: =SUM(AD1:AD2) -> 14300
B5: Chi phí hao hụt | C5: =C4*C3/(1-C3) -> 1444.4444 | K5: Chi phí hao hụt | L5: =L4*L3/(1-L3) -> 1444.4444 | T5: Chi phí hao hụt | U5: =U4*U3/(1-U3) -> 1444.4444 | AC5: Chi phí hao hụt | AD5: =AD4*AD3/(1-AD3) -> 1588.8889
B6: Giá bán hòa vốn đơn vị | C6: =+C4/(1-C3) -> 14444.444 | K6: Giá bán hòa vốn đơn vị | L6: =+L4/(1-L3) -> 14444.444 | T6: Giá bán hòa vốn đơn vị | U6: =+U4/(1-U3) -> 14444.444 | AC6: Giá bán hòa vốn đơn vị | AD6: =+AD4/(1-AD3) -> 15888.889
A7: STT | B7: Tên vật tư | C7: Cơ cấu thành phẩm thực tế | D7: Giá bán 3 trạm về DTR | J7: STT | K7: Tên vật tư | L7: Cơ cấu thành phẩm thực tế | M7: Giá bán 3 trạm về DTR | S7: STT | T7: Tên vật tư | U7: Cơ cấu thành phẩm thực tế | V7: Giá bán 3 trạm về DTR | AB7: STT | AC7: Tên vật tư | AD7: Cơ cấu thành phẩm thực tế | AE7: Giá bán 3 trạm về DTR
A8: 1 | B8: Chai PET B1 | C8: ='[6]4. 3 Trạm'!$S334 -> 0.51133536 | D8: =$C$1+GAP!$K$9 -> 15000 | J8: 1 | K8: Chai PET B1 | L8: ='[6]4. 3 Trạm'!$T334 -> 0.49706416 | M8: =$L$1+GAP!$K$9 -> 15000 | S8: 1 | T8: Chai PET B1 | U8: ='[6]4. 3 Trạm'!$U334 -> 0.50434739 | V8: =$U$1+GAP!$K$9 -> 15000 | AB8: 1 | AC8: Chai PET B1 | AD8: ='[6]4. 3 Trạm'!$V334 -> 0.51736865 | AE8: =$AD$1+GAP!$K$9 -> 16300
A9: 5 | B9: Chai PET B2.2 | C9: ='[6]4. 3 Trạm'!$S335 -> 0.064970641 | D9: =$C$1+GAP!$K$11 -> 13500 | J9: 5 | K9: Chai PET B2.2 | L9: ='[6]4. 3 Trạm'!$T335 -> 0.058399137 | M9: =$L$1+GAP!$K$11 -> 13500 | S9: 5 | T9: Chai PET B2.2 | U9: ='[6]4. 3 Trạm'!$U335 -> 0.055507957 | V9: =$U$1+GAP!$K$11 -> 13500 | AB9: 5 | AC9: Chai PET B2.2 | AD9: ='[6]4. 3 Trạm'!$V335 -> 0.044495104 | AE9: =$AD$1+GAP!$K$11 -> 14800
A10: 7 | B10: Chai PET B4 | C10: ='[6]4. 3 Trạm'!$S337 -> 0.015890206 | D10: =$C$1+GAP!$K$10 -> 12000 | J10: 7 | K10: Chai PET B4 | L10: ='[6]4. 3 Trạm'!$T337 -> 0.016398176 | M10: =$L$1+GAP!$K$10 -> 12000 | S10: 7 | T10: Chai PET B4 | U10: ='[6]4. 3 Trạm'!$U337 -> 0.01571854 | V10: =$U$1+GAP!$K$10 -> 12000 | AB10: 7 | AC10: Chai PET B4 | AD10: ='[6]4. 3 Trạm'!$V337 -> 0.015093888 | AE10: =$AD$1+GAP!$K$10 -> 13300
A11: 8 | B11: Chai PET B5 | C11: ='[6]4. 3 Trạm'!$S338 -> 0.016100854 | D11: =$C$1+GAP!$K$10 -> 12000 | J11: 8 | K11: Chai PET B5 | L11: ='[6]4. 3 Trạm'!$T338 -> 0.015470359 | M11: =$L$1+GAP!$K$10 -> 12000 | S11: 8 | T11: Chai PET B5 | U11: ='[6]4. 3 Trạm'!$U338 -> 0.01547887 | V11: =$U$1+GAP!$K$10 -> 12000 | AB11: 8 | AC11: Chai PET B5 | AD11: ='[6]4. 3 Trạm'!$V338 -> 0.015516825 | AE11: =$AD$1+GAP!$K$10 -> 13300
A12: 10 | B12: Chai PET B6.2 | C12: ='[6]4. 3 Trạm'!$S336 -> 0.26768431 | D12: =$C$1+GAP!$K$11 -> 13500 | J12: 10 | K12: Chai PET B6.2 | L12: ='[6]4. 3 Trạm'!$T336 -> 0.29014887 | M12: =$L$1+GAP!$K$11 -> 13500 | S12: 10 | T12: Chai PET B6.2 | U12: ='[6]4. 3 Trạm'!$U336 -> 0.27717466 | V12: =$U$1+GAP!$K$11 -> 13500 | AB12: 10 | AC12: Chai PET B6.2 | AD12: ='[6]4. 3 Trạm'!$V336 -> 0.27679036 | AE12: =$AD$1+GAP!$K$11 -> 14800
A13: 11 | B13: Nắp HD ép, cổ chai | C13: ='[6]4. 3 Trạm'!$S339 -> 0.015679732 | D13: =$C$1+GAP!$K$12 -> 6500 | J13: 11 | K13: Nắp HD ép, cổ chai | L13: ='[6]4. 3 Trạm'!$T339 -> 0.018909499 | M13: =$L$1+GAP!$K$12 -> 6500 | S13: 11 | T13: Nắp HD ép, cổ chai | U13: ='[6]4. 3 Trạm'!$U339 -> 0.018094122 | V13: =$U$1+GAP!$K$12 -> 6500 | AB13: 11 | AC13: Nắp HD ép, cổ chai | AD13: ='[6]4. 3 Trạm'!$V339 -> 0.023950693 | AE13: =$AD$1+GAP!$K$12 -> 7800
A14: 12 | B14: Phó sản | C14: ='[6]4. 3 Trạm'!$S341 -> 0.003848365 | D14: =$C$1+GAP!$K$15 -> 2000 | J14: 12 | K14: Phó sản | L14: ='[6]4. 3 Trạm'!$T341 -> 0.0040771834 | M14: =$L$1+GAP!$K$15 -> 2000 | S14: 12 | T14: Phó sản | U14: ='[6]4. 3 Trạm'!$U341 -> 0.0076438512 | V14: =$U$1+GAP!$K$15 -> 2000 | AB14: 12 | AC14: Phó sản | AD14: ='[6]4. 3 Trạm'!$V341 -> 0.0042130059 | AE14: =$AD$1+GAP!$K$15 -> 3300
A15: 13 | B15: Hao hụt | C15: ='[6]4. 3 Trạm'!$S$342 -> 0.10316976 | D15: =C15*$C$1 -> 1031.6976 | J15: 13 | K15: Hao hụt | L15: ='[6]4. 3 Trạm'!$S$342 -> 0.10316976 | M15: =L15*$L$1 -> 1031.6976 | S15: 13 | T15: Hao hụt | U15: ='[6]4. 3 Trạm'!$S$342 -> 0.10316976 | V15: =U15*$U$1 -> 1031.6976 | AB15: 13 | AC15: Hao hụt | AD15: ='[6]4. 3 Trạm'!$S$342 -> 0.10316976 | AE15: =AD15*$AD$1 -> 1165.8183
E17: Tháng 1 | N17: Tháng 2 | W17: Tháng 3 | AF17: Tháng 4
C18: Cơ cấu thành phẩm theo BOM | D18: CL | E18: ĐG | F18: SL | G18: TH SL | H18: GT | L18: Cơ cấu thành phẩm theo BOM | M18: CL | N18: ĐG | O18: SL | P18: TH SL | Q18: GT | U18: Cơ cấu thành phẩm theo BOM | V18: CL | W18: ĐG | X18: SL | Y18: TH SL | Z18: GT | AD18: Cơ cấu thành phẩm theo BOM | AE18: CL | AF18: ĐG | AG18: SL | AH18: TH SL | AI18: GT
A19: 1 | B19: Chai PET B1 | C19: 0.54 | D19: =C8-C19 -> -0.028664637 | E19: =D8*D19 -> -429.96956 | F19: ='[6]4. 3 Trạm'!S89 -> 467032 | G19: =F19*D19 -> -13387.303 | H19: =D8*G19 -> -2.0080954e+08 | J19: 1 | K19: Chai PET B1 | L19: 0.54 | M19: =L8-L19 -> -0.042935837 | N19: =M8*M19 -> -644.03755 | O19: ='[6]4. 3 Trạm'!T89 -> 299036 | P19: =O19*M19 -> -12839.361 | Q19: =M8*P19 -> -1.9259041e+08 | S19: 1 | T19: Chai PET B1 | U19: 0.54 | V19: =U8-U19 -> -0.035652613 | W19: =V8*V19 -> -534.78919 | X19: ='[6]4. 3 Trạm'!U89 -> 848224 | Y19: =X19*V19 -> -30241.402 | Z19: =V8*Y19 -> -4.5362103e+08 | AB19: 1 | AC19: Chai PET B1 | AD19: 0.54 | AE19: =AD8-AD19 -> -0.022631351 | AF19: =AE8*AE19 -> -368.89102 | AG19: ='[6]4. 3 Trạm'!V89 -> 446897 | AH19: =AG19*AE19 -> -10113.883 | AI19: =AE8*AH19 -> -1.6485629e+08
A20: 5 | B20: Chai PET B2.2 | C20: 0.03 | D20: =C9-C20 -> 0.034970641 | E20: =D9*D20 -> 472.10366 | F20: ='[6]4. 3 Trạm'!S90 -> 45769 | G20: =F20*D20 -> 1600.5713 | H20: =D9*G20 -> 21607712 | J20: 5 | K20: Chai PET B2.2 | L20: 0.03 | M20: =L9-L20 -> 0.028399137 | N20: =M9*M20 -> 383.38835 | O20: ='[6]4. 3 Trạm'!T90 -> 23322 | P20: =O20*M20 -> 662.32467 | Q20: =M9*P20 -> 8941383 | S20: 5 | T20: Chai PET B2.2 | U20: 0.03 | V20: =U9-U20 -> 0.025507957 | W20: =V9*V20 -> 344.35742 | X20: ='[6]4. 3 Trạm'!U90 -> 88500 | Y20: =X20*V20 -> 2257.4542 | Z20: =V9*Y20 -> 30475632 | AB20: 5 | AC20: Chai PET B2.2 | AD20: 0.03 | AE20: =AD9-AD20 -> 0.014495104 | AF20: =AE9*AE20 -> 214.52754 | AG20: ='[6]4. 3 Trạm'!V90 -> 31654 | AH20: =AG20*AE20 -> 458.82802 | AI20: =AE9*AH20 -> 6790654.6
A21: 7 | B21: Chai PET B4 | C21: 0.02 | D21: =C10-C21 -> -0.0041097939 | E21: =D10*D21 -> -49.317527 | F21: ='[6]4. 3 Trạm'!S92 -> 14995 | G21: =F21*D21 -> -61.626359 | H21: =D10*G21 -> -739516.31 | J21: 7 | K21: Chai PET B4 | L21: 0.02 | M21: =L10-L21 -> -0.0036018237 | N21: =M10*M21 -> -43.221884 | O21: ='[6]4. 3 Trạm'!T92 -> 10167 | P21: =O21*M21 -> -36.619741 | Q21: =M10*P21 -> -439436.9 | S21: 7 | T21: Chai PET B4 | U21: 0.02 | V21: =U10-U21 -> -0.0042814599 | W21: =V10*V21 -> -51.377518 | X21: ='[6]4. 3 Trạm'!U92 -> 28617 | Y21: =X21*V21 -> -122.52254 | Z21: =V10*Y21 -> -1470270.4 | AB21: 7 | AC21: Chai PET B4 | AD21: 0.02 | AE21: =AD10-AD21 -> -0.0049061125 | AF21: =AE10*AE21 -> -65.251296 | AG21: ='[6]4. 3 Trạm'!V92 -> 14779 | AH21: =AG21*AE21 -> -72.507437 | AI21: =AE10*AH21 -> -964348.91
