Workbook
Name \T: #REF!
Name __dao1: #REF!
Name __dao2: #REF!
Name __dap2: #REF!
Name __day1: #REF!
Name __day2: #REF!
Name __dbu1: #REF!
Name __dbu2: #REF!
Name __doi3: #REF!
Name __E99999: #REF!
Name __Jan02: #REF!
Name __lap1: #REF!
Name __lap2: #REF!
Name __vc1: #REF!
Name __vc2: #REF!
Name __vc3: #REF!
Name _01_01_99: #REF!
Name _01_02_99: #REF!
Name _01_03_99: #REF!
Name _01_04_99: #REF!
Name _01_05_99: #REF!
Name _01_06_99: #REF!
Name _01_07_99: #REF!
Name _01_08_1999: #REF!
Name _1CAP002: #REF!
Name _2STREO7: #REF!
Name _4GOIC01: #REF!
Name _4OSLCTT: #REF!
Name _6BNTTTH: #REF!
Name _6DCTTBO: #REF!
Name _6DD24TT: #REF!
Name _6FCOTBU: #REF!
Name _6LATUBU: #REF!
Name _6SDTT24: #REF!
Name _6TBUDTT: #REF!
Name _6TDDDTT: #REF!
Name _6TLTTTH: #REF!
Name _6TUBUTT: #REF!
Name _6UCLVIS: #REF!
Name _7DNCABC: #REF!
Name _7HDCTBU: #REF!
Name _7PKTUBU: #REF!
Name _7TBHT20: #REF!
Name _7TBHT30: #REF!
Name _7TDCABC: #REF!
Name _dao1: #REF!
Name _dao2: #REF!
Name _dap2: #REF!
Name _day1: #REF!
Name _day2: #REF!
Name _dbu1: #REF!
Name _dbu2: #REF!
Name _doi3: #REF!
Name _E99999: #REF!
Name _Jan02: #REF!
Name _lap1: #REF!
Name _lap2: #REF!
Name _vc1: #REF!
Name _vc2: #REF!
Name _vc3: #REF!

Sheet TH
A1: CHÀO GIÁ SUNTORY PEPSI 2026
A3: Kinh doanh đề xuất xem xét giá sàn EXW 1250 USD/tấn
A5: STT | B5: Mã | C5: Tên | D5: Đơn giá vốn (Vnđ/Kg) | E5: Đơn giá vốn (USD/tấn) | F5: Giá bán EXW Kinh doanh đề nghị (USD/tấn) | G5: Lợi nhuận sau thuế | H5: % Lợi nhuận sau thuế | I5: Giá bán duyệt tháng 3
A6: 1 | B6: 110000332 | C6: Hạt nhựa rPET iSS01084G | D6: =+ISS01084G!J105 -> 31924.322 | E6: =+ISS01084G!K105 -> 1204.6914 | F6: 1250 | G6: =+F6-E6 -> 45.308615 | H6: =+G6/F6 -> 0.036246892 | I6: 1250
A7: 2 | B7: 110000483 | C7: Hạt Nhựa rPET iSS01G-S | D7: =+'ISS01G-S'!J105 -> 31916.263 | E7: =+'ISS01G-S'!K105 -> 1204.3873 | F7: 1230 | G7: =+F7-E7 -> 25.612732 | H7: =+G7/F7 -> 0.020823359 | I7: 1230
B10: Tính toán cho chào giá phần tăng thêm sản lượng 1.500-4500 mt
A11: STT | B11: Mã | C11: Tên | D11: Đơn giá vốn (Vnđ/Kg) | E11: Đơn giá vốn (USD/tấn) | F11: Giá bán EXW đề nghị (USD/tấn) | G11: Lợi nhuận sau thuế | H11: % Lợi nhuận sau thuế | I11: Giá bán duyệt tháng 4 | J11: Giá đầu vào tăng | K11: Chai | L11: Tằng giá khác
A12: 1 | B12: 110000332 | C12: Hạt nhựa rPET iSS01084G | D12: ='ISS01084G (2)'!J105 -> 28638.681 | E12: ='ISS01084G (2)'!K105 -> 1080.7049 | F12: =F6+J12 -> 1375.4717 | G12: =+F12-E12 -> 294.76675 | H12: =+G12/F12 -> 0.2143023 | I12: =1280+90 -> 1370 | J12: =K12+L12 -> 125.4717 | K12: =(2000*1000)/26500 -> 75.471698 | L12: 50
A13: 2 | B13: 110000483 | C13: Hạt Nhựa rPET iSS01G-S | D13: ='ISS01G-S (2)'!J105 -> 28630.622 | E13: ='ISS01G-S (2)'!K105 -> 1080.4008 | F13: =F7+J13 -> 1355.4717 | G13: =+F13-E13 -> 275.07087 | H13: =+G13/F13 -> 0.20293369 | I13: =1280+30 -> 1310 | J13: =K13+L13 -> 125.4717 | K13: =(2000*1000)/26500 -> 75.471698 | L13: 50
A15: STT | B15: Mã | C15: Tên | D15: Đơn giá vốn (Vnđ/Kg) | E15: Đơn giá vốn (USD/tấn) | F15: Giá bán EXW đề nghị (USD/tấn) | G15: Lợi nhuận sau thuế | H15: % Lợi nhuận sau thuế | I15: Giá bán duyệt tháng 4 | J15: Giá đầu vào tăng | K15: Chai | L15: Tằng giá khác
A16: 1 | B16: 110000332 | C16: Hạt nhựa rPET iSS01084G | D16: =D12+J12*26500/1000 -> 31963.681 | E16: =E12+J12 -> 1206.1766 | F16: =F12 -> 1375.4717 | G16: =+F16-E16 -> 169.29505 | H16: =+G16/F16 -> 0.12308145 | I16: =1280+90 -> 1370 | J16: =K16+L16 -> 125.4717 | K16: =(2000*1000)/26500 -> 75.471698 | L16: 50
A17: 2 | B17: 110000483 | C17: Hạt Nhựa rPET iSS01G-S | D17: =D13+J13*26500/1000 -> 31955.622 | E17: =E13+J13 -> 1205.8725 | F17: =F13 -> 1355.4717 | G17: =+F17-E17 -> 149.59917 | H17: =+G17/F17 -> 0.11036687 | I17: =1280+30 -> 1310 | J17: =K17+L17 -> 125.4717 | K17: =(2000*1000)/26500 -> 75.471698 | L17: 50
A19: => Tăng/giảm:
A20: 1 | B20: 110000332 | C20: Hạt nhựa rPET iSS01084G | D20: =D16-D6 -> 39.359411 | E20: =E16-E6 -> 1.4852608 | F20: =F16-F6 -> 125.4717 | G20: =G16-G6 -> 123.98644 | H20: =H16-H6 -> 0.086834559 | I20: =I16-I6 -> 120
A21: 2 | B21: 110000483 | C21: Hạt Nhựa rPET iSS01G-S | D21: =D17-D7 -> 39.359411 | E21: =E17-E7 -> 1.4852608 | F21: =F17-F7 -> 125.4717 | G21: =G17-G7 -> 123.98644 | H21: =H17-H7 -> 0.089543511 | I21: =I17-I7 -> 80

Sheet Chart
C1: CHÀO GIÁ SUNTORY PEPSI 2026
D4: Tỷ giá USD: | E4: =+ISS01084G!K5 -> 26500
E5: ISS01084G | I5: ISS01G-S
A6: No. | B6: SAP | C6: Chi phí Cost Items | D6: Chi phí VNĐ /Kg | E6: Đơn giá USD /Tấn | F6: Cơ cấu % chi phí /Giá | H6: Chi phí VNĐ /Kg | I6: Đơn giá USD /Tấn | J6: Cơ cấu % chi phí /Giá
A7: A | B7: 1521 | C7: Chi phí nguyên vật liệu | D7: =+SUM(D8:D8) -> 15000 | E7: =D7*1000/$E$4 -> 566.03774 | F7: =E7/$E$26 -> 0.45283019 | H7: =+SUM(H8:H8) -> 15000 | I7: =H7*1000/$E$4 -> 566.03774 | J7: =I7/$E$26 -> 0.45283019
A8: 1 | B8: 1521 | C8: Chi phí chai B1 | D8: =+SUMIFS(ISS01084G!J:J,ISS01084G!D:D,Chart!B8) -> 15000 | E8: =D8*1000/$E$4 -> 566.03774 | F8: =E8/$E$26 -> 0.45283019 | H8: =+SUMIFS('ISS01G-S'!J:J,'ISS01G-S'!D:D,Chart!B8) -> 15000 | I8: =H8*1000/$E$4 -> 566.03774 | J8: =I8/$E$26 -> 0.45283019
A9: B | B9: 1522 | C9: Hao hụt về tiền | D9: =+SUMIFS(ISS01084G!J:J,ISS01084G!D:D,Chart!B9) -> 2929.8891 | E9: =D9*1000/$E$4 -> 110.56185 | F9: =E9/$E$26 -> 0.088449481 | H9: =+SUMIFS('ISS01G-S'!J:J,'ISS01G-S'!D:D,Chart!B9) -> 2929.8891 | I9: =H9*1000/$E$4 -> 110.56185 | J9: =I9/$E$26 -> 0.088449481
A10: C | C10: Chi phí sản xuất | D10: =SUM(D11:D17) -> 8816.8201 | E10: =D10*1000/$E$4 -> 332.71019 | F10: =E10/$E$26 -> 0.26616815 | H10: =SUM(H11:H17) -> 8808.761 | I10: =H10*1000/$E$4 -> 332.40607 | J10: =I10/$E$26 -> 0.26592486
A11: 2 | B11: LAB | C11: Chi phí nhân công | D11: =+SUMIFS(ISS01084G!J:J,ISS01084G!D:D,Chart!B11) -> 2638.9452 | E11: =D11*1000/$E$4 -> 99.582838 | F11: =E11/$E$26 -> 0.079666271 | H11: =+SUMIFS('ISS01G-S'!J:J,'ISS01G-S'!D:D,Chart!B11) -> 2638.9452 | I11: =H11*1000/$E$4 -> 99.582838 | J11: =I11/$E$26 -> 0.079666271
A12: =+A11+1 -> 3 | B12: DEP | C12: Khấu hao | D12: =+SUMIFS(ISS01084G!J:J,ISS01084G!D:D,Chart!B12) -> 2122.7599 | E12: =D12*1000/$E$4 -> 80.104146 | F12: =E12/$E$26 -> 0.064083317 | H12: =+SUMIFS('ISS01G-S'!J:J,'ISS01G-S'!D:D,Chart!B12) -> 2122.7599 | I12: =H12*1000/$E$4 -> 80.104146 | J12: =I12/$E$26 -> 0.064083317
A13: =+A12+1 -> 4 | B13: ELEC | C13: Chi phí gián tiếp | D13: =+SUMIFS(ISS01084G!J:J,ISS01084G!D:D,Chart!B13) -> 1752.4949 | E13: =D13*1000/$E$4 -> 66.131883 | F13: =E13/$E$26 -> 0.052905506 | H13: =+SUMIFS('ISS01G-S'!J:J,'ISS01G-S'!D:D,Chart!B13) -> 1752.4949 | I13: =H13*1000/$E$4 -> 66.131883 | J13: =I13/$E$26 -> 0.052905506
A14: =+A13+1 -> 5 | B14: OTH | C14: Điện | D14: =+SUMIFS(ISS01084G!J:J,ISS01084G!D:D,Chart!B14) -> 1478.1805 | E14: =D14*1000/$E$4 -> 55.780394 | F14: =E14/$E$26 -> 0.044624316 | H14: =+SUMIFS('ISS01G-S'!J:J,'ISS01G-S'!D:D,Chart!B14) -> 1478.1805 | I14: =H14*1000/$E$4 -> 55.780394 | J14: =I14/$E$26 -> 0.044624316
A15: =+A14+1 -> 6 | B15: BAG | C15: Đóng gói | D15: =+SUMIFS(ISS01084G!J:J,ISS01084G!D:D,Chart!B15) -> 408.84273 | E15: =D15*1000/$E$4 -> 15.428027 | F15: =E15/$E$26 -> 0.012342422 | H15: =+SUMIFS('ISS01G-S'!J:J,'ISS01G-S'!D:D,Chart!B15) -> 408.84273 | I15: =H15*1000/$E$4 -> 15.428027 | J15: =I15/$E$26 -> 0.012342422
A16: =+A15+1 -> 7 | B16: CHE | C16: Hóa chất | D16: =+SUMIFS(ISS01084G!J:J,ISS01084G!D:D,Chart!B16) -> 393.50254 | E16: =D16*1000/$E$4 -> 14.849152 | F16: =E16/$E$26 -> 0.011879322 | H16: =+SUMIFS('ISS01G-S'!J:J,'ISS01G-S'!D:D,Chart!B16) -> 385.44345 | I16: =H16*1000/$E$4 -> 14.545036 | J16: =I16/$E$26 -> 0.011636029
A17: =+A16+1 -> 8 | B17: H2O | C17: Nước | D17: =+SUMIFS(ISS01084G!J:J,ISS01084G!D:D,Chart!B17) -> 22.094374 | E17: =D17*1000/$E$4 -> 0.83374995 | F17: =E17/$E$26 -> 0.00066699996 | H17: =+SUMIFS('ISS01G-S'!J:J,'ISS01G-S'!D:D,Chart!B17) -> 22.094374 | I17: =H17*1000/$E$4 -> 0.83374995 | J17: =I17/$E$26 -> 0.00066699996
A18: D | C18: Giá thành (A+B+C) | D18: =SUM(D8:D10) -> 26746.709 | E18: =D18*1000/$E$4 -> 1009.3098 | F18: =E18/$E$26 -> 0.80744782 | H18: =SUM(H8:H10) -> 26738.65 | I18: =H18*1000/$E$4 -> 1009.0057 | J18: =I18/$E$26 -> 0.80720453
A19: E | C19: CP quản lý, bán hàng, lãi vay | D19: =+SUM(D20:D22) -> 5177.6126 | E19: =D19*1000/$E$4 -> 195.38161 | F19: =E19/$E$26 -> 0.15630528 | H19: =+SUM(H20:H22) -> 5177.6126 | I19: =H19*1000/$E$4 -> 195.38161 | J19: =I19/$E$26 -> 0.15630528
A20: 9 | B20: 642 | C20: Chi phí bán hàng | D20: =+SUMIFS(ISS01084G!J:J,ISS01084G!D:D,Chart!B20) -> 3098.1952 | E20: =D20*1000/$E$4 -> 116.91303 | F20: =E20/$E$26 -> 0.093530422 | H20: =+SUMIFS('ISS01G-S'!J:J,'ISS01G-S'!D:D,Chart!B20) -> 3098.1952 | I20: =H20*1000/$E$4 -> 116.91303 | J20: =I20/$E$26 -> 0.093530422
A21: 10 | B21: 641 | C21: Chi phí quản lý | D21: =+SUMIFS(ISS01084G!J:J,ISS01084G!D:D,Chart!B21) -> 1525.3261 | E21: =D21*1000/$E$4 -> 57.559475 | F21: =E21/$E$26 -> 0.04604758 | H21: =+SUMIFS('ISS01G-S'!J:J,'ISS01G-S'!D:D,Chart!B21) -> 1525.3261 | I21: =H21*1000/$E$4 -> 57.559475 | J21: =I21/$E$26 -> 0.04604758
A22: 11 | B22: 635 | C22: Chi phí lãi vay | D22: =+SUMIFS(ISS01084G!J:J,ISS01084G!D:D,Chart!B22) -> 554.09125 | E22: =D22*1000/$E$4 -> 20.909104 | F22: =E22/$E$26 -> 0.016727283 | H22: =+SUMIFS('ISS01G-S'!J:J,'ISS01G-S'!D:D,Chart!B22) -> 554.09125 | I22: =H22*1000/$E$4 -> 20.909104 | J22: =I22/$E$26 -> 0.016727283
A23: F | C23: Điểm hòa vốn (D+E) | D23: =+D18+D19 -> 31924.322 | E23: =D23*1000/$E$4 -> 1204.6914 | F23: =E23/$E$26 -> 0.96375311 | H23: =+H18+H19 -> 31916.263 | I23: =H23*1000/$E$4 -> 1204.3873 | J23: =I23/$E$26 -> 0.96350981
A24: 12 | B24: TAX | C24: Thuế thu nhập | D24: =+SUMIFS(ISS01084G!J:J,ISS01084G!D:D,Chart!B24) -> 200.11305 | E24: =D24*1000/$E$4 -> 7.5514359 | F24: =E24/$E$26 -> 0.0060411487 | H24: =+SUMIFS('ISS01G-S'!J:J,'ISS01G-S'!D:D,Chart!B24) -> 113.1229 | I24: =H24*1000/$E$4 -> 4.2687886 | J24: =I24/$E$26 -> 0.0034150309
A25: G | B25: LN | C25: Lợi nhuận sau thuế | D25: =+SUMIFS(ISS01084G!J:J,ISS01084G!D:D,Chart!B25) -> 1000.5653 | E25: =D25*1000/$E$4 -> 37.757179 | F25: =E25/$E$26 -> 0.030205743 | H25: =+SUMIFS('ISS01G-S'!J:J,'ISS01G-S'!D:D,Chart!B25) -> 565.61449 | I25: =H25*1000/$E$4 -> 21.343943 | J25: =I25/$E$26 -> 0.017075154
A26: H | C26: Giá bán | D26: =+D23+D24+D25 -> 33125 | E26: =D26*1000/$E$4 -> 1250 | F26: =E26/$E$26 -> 1 | H26: =+H23+H24+H25 -> 32595 | I26: =H26*1000/$E$4 -> 1230 | J26: =I26/$E$26 -> 0.984
C27: % Lãi gộp nguyên liệu/Giá bán | F27: =F26-F7-F9 -> 0.45872033 | J27: =J26-J7-J9 -> 0.44272033
E28: ="ĐIỂM HÒA VỐN "&ROUND(E23,0)&"$" -> ĐIỂM HÒA VỐN 1205$ | I28: ="ĐIỂM HÒA VỐN "&ROUND(I23,0)&"$" -> ĐIỂM HÒA VỐN 1204$

Sheet ISS01084G
A1: Danh mục | C1: 1
C2: PHƯƠNG ÁN SẢN XUẤT TỪ 100% CHAI RA HẠT ISS01084G (NÂNG IV 10h)
C4: Nguyên liệu: | D4: 100% chai vảy mua ngoài
C5: Thành phẩm: | D5: HẠT rPET iSS01084G (IV > 0,8) | J5: Tỷ giá USD: | K5: 26500
C7: No. | D7: Nhóm | E7: Mã SAP | F7: Chi phí Cost Items | G7: Đơn vị tính Unit | H7: Định mức Standard | I7: Đơn giá (VNĐ) | J7: Chi phí đơn vị (VNĐ /Kg) | K7: Đơn giá (USD /Tấn) | L7: % giá bán | M7: Cơ sở tính
C8: A | D8: CÔNG ĐOẠN TẠO VẢY THÔ:
B9: Chai | C9: I | D9: 1521 | F9: B1 - Chai PET tuyển nước ngọt | G9: vnđ /Kg | H9: 1 | I9: 15000 | J9: =I9 -> 15000 | K9: =J9/$K$5*1000 -> 566.03774 | L9: =J9/$J$58 -> 0.71542389
B10: Hao hụt | C10: II | D10: 1522 | F10: Hao hụt do băm chai B1 (chai khác loại, bao lót, kẽm, nắp) | G10: % | H10: =SUM(H11:H20) -> 0.17890491 | J10: =SUM(J11:J20) -> 1249.9477 | K10: =J10/$K$5*1000 -> 47.167838 | L10: =J10/$J$58 -> 0.059616163
E11: 160012437 | F11: Chai PET Phi Thực Phẩm | G11: % | H11: 0 | I11: 6000 | J11: =+($J$9-I11)*H11 -> 0 | K11: =J11/$K$5*1000 -> 0 | L11: =J11/$J$58 -> 0 | M11: Thu hồi theo giá thị trường
A12: Chai khác2 | E12: 160012250 | F12: Chai PET B8 Sau Phân Loại | G12: % | H12: 0 | I12: 11000 | J12: =+($J$9-I12)*H12 -> 0 | K12: =J12/$K$5*1000 -> 0 | L12: =J12/$J$58 -> 0 | M12: Thu hồi theo giá thị trường
A13: B4 | E13: 160012398 | F13: Chai PET B4 Sau Phân Loại | G13: % | H13: 0.0013146811 | I13: 12500 | J13: =+($J$9-I13)*H13 -> 3.2867028 | K13: =J13/$K$5*1000 -> 0.12402652 | L13: =J13/$J$58 -> 0.00015675905 | M13: Thu hồi theo giá thị trường
A14: B5 | E14: 160012252 | F14: Chai PET B5 Sau Phân Loại | G14: % | H14: 0.0020155036 | I14: 12500 | J14: =+($J$9-I14)*H14 -> 5.038759 | K14: =J14/$K$5*1000 -> 0.19014185 | L14: =J14/$J$58 -> 0.00024032324 | M14: Thu hồi theo giá thị trường
A15: B6 | E15: 160012247 | F15: Chai PET B6 Sau Phân Loại | G15: % | H15: 0.00065144366 | I15: 12300 | J15: =+($J$9-I15)*H15 -> 1.7588979 | K15: =J15/$K$5*1000 -> 0.066373505 | L15: =J15/$J$58 -> 8.3890504e-05 | M15: Thu hồi theo giá thị trường
A16: Olefin | E16: 160012335 | F16: Phó Sản PET B1/B8 Vảy-Nắp | G16: % | H16: 0.094914291 | I16: 10500 | J16: =+($J$9-I16)*H16 -> 427.11431 | K16: =J16/$K$5*1000 -> 16.117521 | L16: =J16/$J$58 -> 0.020371185 | M16: Thu hồi theo giá thị trường
A17: Bụi | E17: 160012334 | F17: Phó Sản PET Bụi Sàn Rung | G17: % | H17: 0.032148664 | I17: 5000 | J17: =+($J$9-I17)*H17 -> 321.48664 | K17: =J17/$K$5*1000 -> 12.131571 | L17: =J17/$J$58 -> 0.015333282 | M17: Thu hồi theo giá thị trường
A18: Tomra | E18: 160012268 | F18: Phó Sản PET Tomra Cổng 2 | G18: % | H18: 0.015908152 | I18: 10500 | J18: =+($J$9-I18)*H18 -> 71.586682 | K18: =J18/$K$5*1000 -> 2.7013842 | L18: =J18/$J$58 -> 0.0034143215 | M18: Thu hồi theo giá thị trường
A19: Zigzag | E19: 160012311 | F19: Phó Sản PET Zigzag | G19: % | H19: 0.0054188111 | I19: 11000 | J19: =+($J$9-I19)*H19 -> 21.675244 | K19: =J19/$K$5*1000 -> 0.81793375 | L19: =J19/$J$58 -> 0.0010337992 | M19: Thu hồi theo giá thị trường
A20: Mất đi | F20: Hao hụt nhãn, PVC, đất, cát, nước mất đi | G20: % | H20: 0.026533364 | I20: 0 | J20: =+($J$9-I20)*H20 -> 398.00046 | K20: =J20/$K$5*1000 -> 15.018885 | L20: =J20/$J$58 -> 0.018982603 | M20: Hao hụt mất đi
C21: III | F21: Chi phí băm vảy (bale to flake) | J21: =SUM(J22:J33) -> 2321.031 | K21: =J21*1000/$K$5 -> 87.586075 | L21: =J21/$J$58 -> 0.1107014
A22: Băm | C22: 0 | D22: REL01 | F22: Công suất máy (capacity) | G22: Kg /h | H22: 4800 | M22: Công suất máy 4800 (CW1: 1200, CW2:1200, Boretech 2400)
A23: Băm | F23: Hiệu suất máy | G23: % | H23: 0.6 | M23: Bình quân 3 tháng liền kề theo BI
A24: Băm | B24: NCTT | C24: =+C22+1 -> 1 | D24: LAB | E24: 622 | F24: Chi phí nhân công trực tiếp | G24: tháng | H24: 1 | I24: 1811265742 | J24: =+I24/($H$22*$H$23*24*30) -> 873.48849 | K24: =J24/$K$5*1000 -> 32.96183 | L24: =J24/$J$58 -> 0.041660969 | M24: 11 người lựa chai trên chuyền, 1 người cắt kiện, phế, 1 người đóng gói, 0,5 xe nâng
A25: Băm | B25: NCGT | C25: =+C23+1 -> 1 | D25: LAB | E25: 6271 | F25: Chi phí nhân công gián tiếp | G25: tháng | H25: 1 | I25: 7.5152141e+08 | J25: =+I25/($H$22*$H$23*24*30) -> 362.42352 | K25: =J25/$K$5*1000 -> 13.676359 | L25: =J25/$J$58 -> 0.017285763 | M25: Lương trưởng ca, hành chính, tổ trưởng, quản lý sản xuất gián tiếp như QC, Kỹ thuật
A26: Băm | B26: VTPX | C26: =+C24+1 -> 2 | D26: OTH | E26: 6272 | F26: Chi phí vật tư phân xưởng | G26: tháng | H26: 1 | I26: 3.3060958e+08 | J26: =+I26/($H$22*$H$23*24*30) -> 159.43749 | K26: =J26/$K$5*1000 -> 6.0165091 | L26: =J26/$J$58 -> 0.0076043592 | M26: Chi phí thực tế bình quân 3 tháng liền kề
A27: Băm | B27: CCDC | C27: =+C25+1 -> 2 | D27: OTH | E27: 6273 | F27: Chi phí CCDC, bảo trì | G27: tháng | H27: 1 | I27: 1.9855935e+08 | J27: =+I27/($H$22*$H$23*24*30) -> 95.755858 | K27: =J27/$K$5*1000 -> 3.6134286 | L27: =J27/$J$58 -> 0.0045670685 | M27: Chi phí thực tế bình quân 3 tháng liền kề
A28: Băm | B28: KH | C28: =+C26+1 -> 3 | D28: DEP | E28: 6274.1 | F28: Chi phí khấu hao MMTB chính | G28: tháng | H28: 1 | I28: 3.6698932e+08 | J28: =+I28/($H$22*$H$23*24*30) -> 176.98173 | K28: =J28/$K$5*1000 -> 6.6785559 | L28: =J28/$J$58 -> 0.0084411305 | M28: Chi phí thực tế bình quân 3 tháng liền kề theo danh sách TSCĐ
A29: Băm | B29: KH | C29: =+C27+1 -> 3 | D29: DEP | E29: 6274.2 | F29: Chi phí khấu hao MMTB phụ | G29: tháng | H29: 1 | I29: 2.9525985e+08 | J29: =+I29/($H$22*$H$23*24*30) -> 142.38997 | K29: =J29/$K$5*1000 -> 5.3732065 | L29: =J29/$J$58 -> 0.0067912792 | M29: Chi phí thực tế bình quân 3 tháng liền kề theo danh sách TSCĐ
A30: Băm | B30: KH | C30: =+C28+1 -> 4 | D30: DEP | E30: 6274.3 | F30: Chi phí khấu hao MMTB dùng chung | G30: tháng | H30: 1 | I30: 1.4463942e+08 | J30: =+I30/($H$22*$H$23*24*30) -> 69.752806 | K30: =J30/$K$5*1000 -> 2.6321814 | L30: =J30/$J$58 -> 0.0033268549 | M30: Chi phí thực tế bình quân 3 tháng liền kề theo danh sách TSCĐ
A31: Băm | B31: KH | C31: =+C29+1 -> 4 | D31: DEP | E31: 6274.4 | F31: Chi phí khấu hao nhà xưởng | G31: tháng | H31: 1 | I31: 1.7358714e+08 | J31: =+I31/($H$22*$H$23*24*30) -> 83.712935 | K31: =J31/$K$5*1000 -> 3.1589787 | L31: =J31/$J$58 -> 0.0039926822 | M31: Chi phí thực tế bình quân 3 tháng liền kề theo danh sách TSCĐ
A32: Băm | B32: Điện | C32: =+C27+1 -> 3 | D32: ELEC | E32: 6275 | F32: Điện (electronic) kwh | G32: Kwh | H32: 1 | I32: 3.3791931e+08 | J32: =+I32/($H$22*$H$23*24*30) -> 162.96263 | K32: =J32/$K$5*1000 -> 6.1495332 | L32: =J32/$J$58 -> 0.0077724905 | M32: Chi phí thực tế bình quân 3 tháng liền kề. CW1: 178 Kwh, CW2: 185 Kwh, Boretech: 132 Kwh
A33: Băm | B33: Khác | C33: =+C28+1 -> 4 | D33: OTH | E33: 6277.6278 | F33: Chi phí bằng tiền khác | G33: tháng | H33: 1 | I33: 4.0253876e+08 | J33: =+I33/($H$22*$H$23*24*30) -> 194.12556 | K33: =J33/$K$5*1000 -> 7.3254929 | L33: =J33/$J$58 -> 0.0092588042 | M33: Chi phí thực tế bình quân 3 tháng liền kề
D34: Cộng giá thành A0 - Vảy thô (I+II+III) | J34: =J9+J10+J21 -> 18570.979 | K34: =J34*1000/$K$5 -> 700.79165 | L34: =J34/$J$58 -> 0.88574145
C35: B | D35: CÔNG ĐOẠN RỬA VẢY:
C36: IV | F36: Chi phí A0 - Vảy thô | G36: Kg | H36: 1 | I36: =+J34 -> 18570.979 | J36: =+H36*I36 -> 18570.979 | K36: =J36*1000/$K$5 -> 700.79165 | L36: =J36/$J$58 -> 0.88574145
C37: V | F37: Chi phí rửa vảy, tách kim loại (clean flake) | J37: =SUM(J40:J57) -> 2395.6123 | K37: =J37*1000/$K$5 -> 90.400465 | L37: =J37/$J$58 -> 0.11425855
A38: Rửa | C38: 0 | D38: VBAL1 | F38: Công suất máy (capacity) | G38: Kg /h | H38: 10760 | M38: Công suất máy 5860 (CW1: 1800, CW2:1660, Boretech 2400)
A39: Rửa | F39: Hiệu suất máy | G39: % | H39: 0.81 | M39: Bình quân 3 tháng liền kề theo BI
A40: Zigzag | B40: Hao hụt | C40: =+C38+1 -> 1 | D40: 1522 | E40: 160012311 | F40: Phó Sản PET Zigzag | G40: % | H40: 0.0016854746 | I40: 11000 | J40: =+($J$34-I40)*H40 -> 12.760692 | K40: =J40/$K$5*1000 -> 0.48153554 | L40: =J40/$J$58 -> 0.00060862025 | M40: Thu hồi theo giá thị trường
A41: Tomra | B41: Hao hụt | C41: =+C40+1 -> 2 | D41: 1522 | E41: 160012419 | F41: Phó Sản PET Tomra Cổng 3 | G41: % | H41: 0.033714201 | I41: 9500 | J41: =+($J$34-I41)*H41 -> 305.82079 | K41: =J41/$K$5*1000 -> 11.540407 | L41: =J41/$J$58 -> 0.0145861 | M41: Thu hồi theo giá thị trường
A42: Bụi | B42: Hao hụt | C42: =+C41+1 -> 3 | D42: 1522 | E42: 160012336 | F42: Phó Sản PET Bụi Cám | G42: % | H42: 0.021619268 | I42: 5000 | J42: =+($J$34-I42)*H42 -> 293.39462 | K42: =J42/$K$5*1000 -> 11.071495 | L42: =J42/$J$58 -> 0.013993435 | M42: Thu hồi theo giá thị trường
...

Sheet ISS01G-S
A1: Danh mục | C1: 1
C2: PHƯƠNG ÁN SẢN XUẤT TỪ 100% CHAI RA HẠT ISS01G-S (NÂNG IV 10h)
C4: Nguyên liệu: | D4: 100% chai vảy mua ngoài
C5: Thành phẩm: | D5: HẠT rPET ISS01G-S (IV > 0,8) | J5: Tỷ giá USD: | K5: 26500
C7: No. | D7: Nhóm | E7: Mã SAP | F7: Chi phí Cost Items | G7: Đơn vị tính Unit | H7: Định mức Standard | I7: Đơn giá (VNĐ) | J7: Chi phí đơn vị (VNĐ /Kg) | K7: Đơn giá (USD /Tấn) | L7: % giá bán | M7: Cơ sở tính
C8: A | D8: CÔNG ĐOẠN TẠO VẢY THÔ:
B9: Chai | C9: I | D9: 1521 | E9: 150000187 | F9: Chai PET B1.3 | G9: vnđ /Kg | H9: 1 | I9: 15000 | J9: =I9 -> 15000 | K9: =J9/$K$5*1000 -> 566.03774 | L9: =J9/$J$58 -> 0.71542389
B10: Hao hụt | C10: II | D10: 1522 | F10: Hao hụt do băm chai B1 (chai khác loại, bao lót, kẽm, nắp) | G10: % | H10: =SUM(H11:H20) -> 0.17890491 | J10: =SUM(J11:J20) -> 1249.9477 | K10: =J10/$K$5*1000 -> 47.167838 | L10: =J10/$J$58 -> 0.059616163
E11: 160012437 | F11: Chai PET Phi Thực Phẩm | G11: % | H11: 0 | I11: 6000 | J11: =+($J$9-I11)*H11 -> 0 | K11: =J11/$K$5*1000 -> 0 | L11: =J11/$J$58 -> 0 | M11: Thu hồi theo giá thị trường
A12: Chai khác2 | E12: 160012250 | F12: Chai PET B8 Sau Phân Loại | G12: % | H12: 0 | I12: 11000 | J12: =+($J$9-I12)*H12 -> 0 | K12: =J12/$K$5*1000 -> 0 | L12: =J12/$J$58 -> 0 | M12: Thu hồi theo giá thị trường
A13: B4 | E13: 160012398 | F13: Chai PET B4 Sau Phân Loại | G13: % | H13: 0.0013146811 | I13: 12500 | J13: =+($J$9-I13)*H13 -> 3.2867028 | K13: =J13/$K$5*1000 -> 0.12402652 | L13: =J13/$J$58 -> 0.00015675905 | M13: Thu hồi theo giá thị trường
A14: B5 | E14: 160012252 | F14: Chai PET B5 Sau Phân Loại | G14: % | H14: 0.0020155036 | I14: 12500 | J14: =+($J$9-I14)*H14 -> 5.038759 | K14: =J14/$K$5*1000 -> 0.19014185 | L14: =J14/$J$58 -> 0.00024032324 | M14: Thu hồi theo giá thị trường
A15: B6 | E15: 160012247 | F15: Chai PET B6 Sau Phân Loại | G15: % | H15: 0.00065144366 | I15: 12300 | J15: =+($J$9-I15)*H15 -> 1.7588979 | K15: =J15/$K$5*1000 -> 0.066373505 | L15: =J15/$J$58 -> 8.3890504e-05 | M15: Thu hồi theo giá thị trường
A16: Olefin | E16: 160012335 | F16: Phó Sản PET B1/B8 Vảy-Nắp | G16: % | H16: 0.094914291 | I16: 10500 | J16: =+($J$9-I16)*H16 -> 427.11431 | K16: =J16/$K$5*1000 -> 16.117521 | L16: =J16/$J$58 -> 0.020371185 | M16: Thu hồi theo giá thị trường
A17: Bụi | E17: 160012334 | F17: Phó Sản PET Bụi Sàn Rung | G17: % | H17: 0.032148664 | I17: 5000 | J17: =+($J$9-I17)*H17 -> 321.48664 | K17: =J17/$K$5*1000 -> 12.131571 | L17: =J17/$J$58 -> 0.015333282 | M17: Thu hồi theo giá thị trường
A18: Tomra | E18: 160012268 | F18: Phó Sản PET Tomra Cổng 2 | G18: % | H18: 0.015908152 | I18: 10500 | J18: =+($J$9-I18)*H18 -> 71.586682 | K18: =J18/$K$5*1000 -> 2.7013842 | L18: =J18/$J$58 -> 0.0034143215 | M18: Thu hồi theo giá thị trường
A19: Zigzag | E19: 160012311 | F19: Phó Sản PET Zigzag | G19: % | H19: 0.0054188111 | I19: 11000 | J19: =+($J$9-I19)*H19 -> 21.675244 | K19: =J19/$K$5*1000 -> 0.81793375 | L19: =J19/$J$58 -> 0.0010337992 | M19: Thu hồi theo giá thị trường
A20: Mất đi | F20: Hao hụt nhãn, PVC, đất, cát, nước mất đi | G20: % | H20: 0.026533364 | I20: 0 | J20: =+($J$9-I20)*H20 -> 398.00046 | K20: =J20/$K$5*1000 -> 15.018885 | L20: =J20/$J$58 -> 0.018982603 | M20: Hao hụt mất đi
C21: III | F21: Chi phí băm vảy (bale to flake) | J21: =SUM(J22:J33) -> 2321.031 | K21: =J21*1000/$K$5 -> 87.586075 | L21: =J21/$J$58 -> 0.1107014
A22: Băm | C22: 0 | D22: REL01 | F22: Công suất máy (capacity) | G22: Kg /h | H22: 4800 | M22: Công suất máy 4800 (CW1: 1200, CW2:1200, Boretech 2400)
A23: Băm | F23: Hiệu suất máy | G23: % | H23: 0.6 | M23: Bình quân 3 tháng liền kề theo BI
A24: Băm | B24: NCTT | C24: =+C22+1 -> 1 | D24: LAB | E24: 622 | F24: Chi phí nhân công trực tiếp | G24: tháng | H24: 1 | I24: 1811265742 | J24: =+I24/($H$22*$H$23*24*30) -> 873.48849 | K24: =J24/$K$5*1000 -> 32.96183 | L24: =J24/$J$58 -> 0.041660969 | M24: 11 người lựa chai trên chuyền, 1 người cắt kiện, phế, 1 người đóng gói, 0,5 xe nâng
A25: Băm | B25: NCGT | C25: =+C23+1 -> 1 | D25: LAB | E25: 6271 | F25: Chi phí nhân công gián tiếp | G25: tháng | H25: 1 | I25: 7.5152141e+08 | J25: =+I25/($H$22*$H$23*24*30) -> 362.42352 | K25: =J25/$K$5*1000 -> 13.676359 | L25: =J25/$J$58 -> 0.017285763 | M25: Lương trưởng ca, hành chính, tổ trưởng, quản lý sản xuất gián tiếp như QC, Kỹ thuật
A26: Băm | B26: VTPX | C26: =+C24+1 -> 2 | D26: OTH | E26: 6272 | F26: Chi phí vật tư phân xưởng | G26: tháng | H26: 1 | I26: 3.3060958e+08 | J26: =+I26/($H$22*$H$23*24*30) -> 159.43749 | K26: =J26/$K$5*1000 -> 6.0165091 | L26: =J26/$J$58 -> 0.0076043592 | M26: Chi phí thực tế bình quân 3 tháng liền kề
A27: Băm | B27: CCDC | C27: =+C25+1 -> 2 | D27: OTH | E27: 6273 | F27: Chi phí CCDC, bảo trì | G27: tháng | H27: 1 | I27: 1.9855935e+08 | J27: =+I27/($H$22*$H$23*24*30) -> 95.755858 | K27: =J27/$K$5*1000 -> 3.6134286 | L27: =J27/$J$58 -> 0.0045670685 | M27: Chi phí thực tế bình quân 3 tháng liền kề
A28: Băm | B28: KH | C28: =+C26+1 -> 3 | D28: DEP | E28: 6274.1 | F28: Chi phí khấu hao MMTB chính | G28: tháng | H28: 1 | I28: 3.6698932e+08 | J28: =+I28/($H$22*$H$23*24*30) -> 176.98173 | K28: =J28/$K$5*1000 -> 6.6785559 | L28: =J28/$J$58 -> 0.0084411305 | M28: Chi phí thực tế bình quân 3 tháng liền kề theo danh sách TSCĐ
A29: Băm | B29: KH | C29: =+C27+1 -> 3 | D29: DEP | E29: 6274.2 | F29: Chi phí khấu hao MMTB phụ | G29: tháng | H29: 1 | I29: 2.9525985e+08 | J29: =+I29/($H$22*$H$23*24*30) -> 142.38997 | K29: =J29/$K$5*1000 -> 5.3732065 | L29: =J29/$J$58 -> 0.0067912792 | M29: Chi phí thực tế bình quân 3 tháng liền kề theo danh sách TSCĐ
A30: Băm | B30: KH | C30: =+C28+1 -> 4 | D30: DEP | E30: 6274.3 | F30: Chi phí khấu hao MMTB dùng chung | G30: tháng | H30: 1 | I30: 1.4463942e+08 | J30: =+I30/($H$22*$H$23*24*30) -> 69.752806 | K30: =J30/$K$5*1000 -> 2.6321814 | L30: =J30/$J$58 -> 0.0033268549 | M30: Chi phí thực tế bình quân 3 tháng liền kề theo danh sách TSCĐ
A31: Băm | B31: KH | C31: =+C29+1 -> 4 | D31: DEP | E31: 6274.4 | F31: Chi phí khấu hao nhà xưởng | G31: tháng | H31: 1 | I31: 1.7358714e+08 | J31: =+I31/($H$22*$H$23*24*30) -> 83.712935 | K31: =J31/$K$5*1000 -> 3.1589787 | L31: =J31/$J$58 -> 0.0039926822 | M31: Chi phí thực tế bình quân 3 tháng liền kề theo danh sách TSCĐ
A32: Băm | B32: Điện | C32: =+C27+1 -> 3 | D32: ELEC | E32: 6275 | F32: Điện (electronic) kwh | G32: Kwh | H32: 1 | I32: 3.3791931e+08 | J32: =+I32/($H$22*$H$23*24*30) -> 162.96263 | K32: =J32/$K$5*1000 -> 6.1495332 | L32: =J32/$J$58 -> 0.0077724905 | M32: Chi phí thực tế bình quân 3 tháng liền kề. CW1: 178 Kwh, CW2: 185 Kwh, Boretech: 132 Kwh
A33: Băm | B33: Khác | C33: =+C28+1 -> 4 | D33: OTH | E33: 6277.6278 | F33: Chi phí bằng tiền khác | G33: tháng | H33: 1 | I33: 4.0253876e+08 | J33: =+I33/($H$22*$H$23*24*30) -> 194.12556 | K33: =J33/$K$5*1000 -> 7.3254929 | L33: =J33/$J$58 -> 0.0092588042 | M33: Chi phí thực tế bình quân 3 tháng liền kề
D34: Cộng giá thành A0 - Vảy thô (I+II+III) | J34: =J9+J10+J21 -> 18570.979 | K34: =J34*1000/$K$5 -> 700.79165 | L34: =J34/$J$58 -> 0.88574145
C35: B | D35: CÔNG ĐOẠN RỬA VẢY:
C36: IV | F36: Chi phí A0 - Vảy thô | G36: Kg | H36: 1 | I36: =+J34 -> 18570.979 | J36: =+H36*I36 -> 18570.979 | K36: =J36*1000/$K$5 -> 700.79165 | L36: =J36/$J$58 -> 0.88574145
C37: V | F37: Chi phí rửa vảy, tách kim loại (clean flake) | J37: =SUM(J40:J57) -> 2395.6123 | K37: =J37*1000/$K$5 -> 90.400465 | L37: =J37/$J$58 -> 0.11425855
A38: Rửa | C38: 0 | D38: VBAL1 | F38: Công suất máy (capacity) | G38: Kg /h | H38: 10760 | M38: Công suất máy 5860 (CW1: 1800, CW2:1660, Boretech 2400)
A39: Rửa | F39: Hiệu suất máy | G39: % | H39: 0.81 | M39: Bình quân 3 tháng liền kề theo BI
A40: Zigzag | B40: Hao hụt | C40: =+C38+1 -> 1 | D40: 1522 | E40: 160012311 | F40: Phó Sản PET Zigzag | G40: % | H40: 0.0016854746 | I40: 11000 | J40: =+($J$34-I40)*H40 -> 12.760692 | K40: =J40/$K$5*1000 -> 0.48153554 | L40: =J40/$J$58 -> 0.00060862025 | M40: Thu hồi theo giá thị trường
A41: Tomra | B41: Hao hụt | C41: =+C40+1 -> 2 | D41: 1522 | E41: 160012419 | F41: Phó Sản PET Tomra Cổng 3 | G41: % | H41: 0.033714201 | I41: 9500 | J41: =+($J$34-I41)*H41 -> 305.82079 | K41: =J41/$K$5*1000 -> 11.540407 | L41: =J41/$J$58 -> 0.0145861 | M41: Thu hồi theo giá thị trường
A42: Bụi | B42: Hao hụt | C42: =+C41+1 -> 3 | D42: 1522 | E42: 160012336 | F42: Phó Sản PET Bụi Cám | G42: % | H42: 0.021619268 | I42: 5000 | J42: =+($J$34-I42)*H42 -> 293.39462 | K42: =J42/$K$5*1000 -> 11.071495 | L42: =J42/$J$58 -> 0.013993435 | M42: Thu hồi theo giá thị trường
...

Sheet ISS01084G (2)
A1: Danh mục | C1: 1
C2: PHƯƠNG ÁN SẢN XUẤT TỪ 100% CHAI RA HẠT ISS01084G (NÂNG IV 10h)
C4: Nguyên liệu: | D4: 100% chai vảy mua ngoài
C5: Thành phẩm: | D5: HẠT rPET iSS01084G (IV > 0,8) | J5: Tỷ giá USD: | K5: 26500
C7: No. | D7: Nhóm | E7: Mã SAP | F7: Chi phí Cost Items | G7: Đơn vị tính Unit | H7: Định mức Standard | I7: Đơn giá (VNĐ) | J7: Chi phí đơn vị (VNĐ /Kg) | K7: Đơn giá (USD /Tấn) | L7: % giá bán | M7: Cơ sở tính
C8: A | D8: CÔNG ĐOẠN TẠO VẢY THÔ:
B9: Chai | C9: I | D9: 1521 | F9: B1 - Chai PET tuyển nước ngọt | G9: vnđ /Kg | H9: 1 | I9: 15000 | J9: =I9 -> 15000 | K9: =J9/$K$5*1000 -> 566.03774 | L9: =J9/$J$58 -> 0.72795007
B10: Hao hụt | C10: II | D10: 1522 | F10: Hao hụt do băm chai B1 (chai khác loại, bao lót, kẽm, nắp) | G10: % | H10: =SUM(H11:H20) -> 0.17890491 | J10: =SUM(J11:J20) -> 1249.9477 | K10: =J10/$K$5*1000 -> 47.167838 | L10: =J10/$J$58 -> 0.060659968
E11: 160012437 | F11: Chai PET Phi Thực Phẩm | G11: % | H11: 0 | I11: 6000 | J11: =+($J$9-I11)*H11 -> 0 | K11: =J11/$K$5*1000 -> 0 | L11: =J11/$J$58 -> 0 | M11: Thu hồi theo giá thị trường
A12: Chai khác2 | E12: 160012250 | F12: Chai PET B8 Sau Phân Loại | G12: % | H12: 0 | I12: 11000 | J12: =+($J$9-I12)*H12 -> 0 | K12: =J12/$K$5*1000 -> 0 | L12: =J12/$J$58 -> 0 | M12: Thu hồi theo giá thị trường
A13: B4 | E13: 160012398 | F13: Chai PET B4 Sau Phân Loại | G13: % | H13: 0.0013146811 | I13: 12500 | J13: =+($J$9-I13)*H13 -> 3.2867028 | K13: =J13/$K$5*1000 -> 0.12402652 | L13: =J13/$J$58 -> 0.0001595037 | M13: Thu hồi theo giá thị trường
A14: B5 | E14: 160012252 | F14: Chai PET B5 Sau Phân Loại | G14: % | H14: 0.0020155036 | I14: 12500 | J14: =+($J$9-I14)*H14 -> 5.038759 | K14: =J14/$K$5*1000 -> 0.19014185 | L14: =J14/$J$58 -> 0.000244531 | M14: Thu hồi theo giá thị trường
A15: B6 | E15: 160012247 | F15: Chai PET B6 Sau Phân Loại | G15: % | H15: 0.00065144366 | I15: 12300 | J15: =+($J$9-I15)*H15 -> 1.7588979 | K15: =J15/$K$5*1000 -> 0.066373505 | L15: =J15/$J$58 -> 8.5359323e-05 | M15: Thu hồi theo giá thị trường
A16: Olefin | E16: 160012335 | F16: Phó Sản PET B1/B8 Vảy-Nắp | G16: % | H16: 0.094914291 | I16: 10500 | J16: =+($J$9-I16)*H16 -> 427.11431 | K16: =J16/$K$5*1000 -> 16.117521 | L16: =J16/$J$58 -> 0.02072786 | M16: Thu hồi theo giá thị trường
A17: Bụi | E17: 160012334 | F17: Phó Sản PET Bụi Sàn Rung | G17: % | H17: 0.032148664 | I17: 5000 | J17: =+($J$9-I17)*H17 -> 321.48664 | K17: =J17/$K$5*1000 -> 12.131571 | L17: =J17/$J$58 -> 0.015601748 | M17: Thu hồi theo giá thị trường
A18: Tomra | E18: 160012268 | F18: Phó Sản PET Tomra Cổng 2 | G18: % | H18: 0.015908152 | I18: 10500 | J18: =+($J$9-I18)*H18 -> 71.586682 | K18: =J18/$K$5*1000 -> 2.7013842 | L18: =J18/$J$58 -> 0.003474102 | M18: Thu hồi theo giá thị trường
A19: Zigzag | E19: 160012311 | F19: Phó Sản PET Zigzag | G19: % | H19: 0.0054188111 | I19: 11000 | J19: =+($J$9-I19)*H19 -> 21.675244 | K19: =J19/$K$5*1000 -> 0.81793375 | L19: =J19/$J$58 -> 0.0010518997 | M19: Thu hồi theo giá thị trường
A20: Mất đi | F20: Hao hụt nhãn, PVC, đất, cát, nước mất đi | G20: % | H20: 0.026533364 | I20: 0 | J20: =+($J$9-I20)*H20 -> 398.00046 | K20: =J20/$K$5*1000 -> 15.018885 | L20: =J20/$J$58 -> 0.019314965 | M20: Hao hụt mất đi
C21: III | F21: Chi phí băm vảy (bale to flake) | J21: =SUM(J22:J33) -> 2321.031 | K21: =J21*1000/$K$5 -> 87.586075 | L21: =J21/$J$58 -> 0.11263965
A22: Băm | C22: 0 | D22: REL01 | F22: Công suất máy (capacity) | G22: Kg /h | H22: 4800 | M22: Công suất máy 4800 (CW1: 1200, CW2:1200, Boretech 2400)
A23: Băm | F23: Hiệu suất máy | G23: % | H23: 0.6 | M23: Bình quân 3 tháng liền kề theo BI
A24: Băm | B24: NCTT | C24: =+C22+1 -> 1 | D24: LAB | E24: 622 | F24: Chi phí nhân công trực tiếp | G24: tháng | H24: 1 | I24: 1811265742 | J24: =+I24/($H$22*$H$23*24*30) -> 873.48849 | K24: =J24/$K$5*1000 -> 32.96183 | L24: =J24/$J$58 -> 0.042390401 | M24: 11 người lựa chai trên chuyền, 1 người cắt kiện, phế, 1 người đóng gói, 0,5 xe nâng
A25: Băm | B25: NCGT | C25: =+C23+1 -> 1 | D25: LAB | E25: 6271 | F25: Chi phí nhân công gián tiếp | G25: tháng | H25: 1 | I25: 7.5152141e+08 | J25: =+I25/($H$22*$H$23*24*30) -> 362.42352 | K25: =J25/$K$5*1000 -> 13.676359 | L25: =J25/$J$58 -> 0.017588415 | M25: Lương trưởng ca, hành chính, tổ trưởng, quản lý sản xuất gián tiếp như QC, Kỹ thuật
A26: Băm | B26: VTPX | C26: =+C24+1 -> 2 | D26: OTH | E26: 6272 | F26: Chi phí vật tư phân xưởng | G26: tháng | H26: 1 | I26: 3.3060958e+08 | J26: =+I26/($H$22*$H$23*24*30) -> 159.43749 | K26: =J26/$K$5*1000 -> 6.0165091 | L26: =J26/$J$58 -> 0.0077375022 | M26: Chi phí thực tế bình quân 3 tháng liền kề
A27: Băm | B27: CCDC | C27: =+C25+1 -> 2 | D27: OTH | E27: 6273 | F27: Chi phí CCDC, bảo trì | G27: tháng | H27: 1 | I27: 1.9855935e+08 | J27: =+I27/($H$22*$H$23*24*30) -> 95.755858 | K27: =J27/$K$5*1000 -> 3.6134286 | L27: =J27/$J$58 -> 0.0046470323 | M27: Chi phí thực tế bình quân 3 tháng liền kề
A28: Băm | B28: KH | C28: =+C26+1 -> 3 | D28: DEP | E28: 6274.1 | F28: Chi phí khấu hao MMTB chính | G28: tháng | H28: 1 | I28: 3.6698932e+08 | J28: =+I28/($H$22*$H$23*24*30) -> 176.98173 | K28: =J28/$K$5*1000 -> 6.6785559 | L28: =J28/$J$58 -> 0.0085889242 | M28: Chi phí thực tế bình quân 3 tháng liền kề theo danh sách TSCĐ
A29: Băm | B29: KH | C29: =+C27+1 -> 3 | D29: DEP | E29: 6274.2 | F29: Chi phí khấu hao MMTB phụ | G29: tháng | H29: 1 | I29: 2.9525985e+08 | J29: =+I29/($H$22*$H$23*24*30) -> 142.38997 | K29: =J29/$K$5*1000 -> 5.3732065 | L29: =J29/$J$58 -> 0.0069101861 | M29: Chi phí thực tế bình quân 3 tháng liền kề theo danh sách TSCĐ
A30: Băm | B30: KH | C30: =+C28+1 -> 4 | D30: DEP | E30: 6274.3 | F30: Chi phí khấu hao MMTB dùng chung | G30: tháng | H30: 1 | I30: 1.4463942e+08 | J30: =+I30/($H$22*$H$23*24*30) -> 69.752806 | K30: =J30/$K$5*1000 -> 2.6321814 | L30: =J30/$J$58 -> 0.003385104 | M30: Chi phí thực tế bình quân 3 tháng liền kề theo danh sách TSCĐ
A31: Băm | B31: KH | C31: =+C29+1 -> 4 | D31: DEP | E31: 6274.4 | F31: Chi phí khấu hao nhà xưởng | G31: tháng | H31: 1 | I31: 1.7358714e+08 | J31: =+I31/($H$22*$H$23*24*30) -> 83.712935 | K31: =J31/$K$5*1000 -> 3.1589787 | L31: =J31/$J$58 -> 0.0040625891 | M31: Chi phí thực tế bình quân 3 tháng liền kề theo danh sách TSCĐ
A32: Băm | B32: Điện | C32: =+C27+1 -> 3 | D32: ELEC | E32: 6275 | F32: Điện (electronic) kwh | G32: Kwh | H32: 1 | I32: 3.3791931e+08 | J32: =+I32/($H$22*$H$23*24*30) -> 162.96263 | K32: =J32/$K$5*1000 -> 6.1495332 | L32: =J32/$J$58 -> 0.0079085772 | M32: Chi phí thực tế bình quân 3 tháng liền kề. CW1: 178 Kwh, CW2: 185 Kwh, Boretech: 132 Kwh
A33: Băm | B33: Khác | C33: =+C28+1 -> 4 | D33: OTH | E33: 6277.6278 | F33: Chi phí bằng tiền khác | G33: tháng | H33: 1 | I33: 4.0253876e+08 | J33: =+I33/($H$22*$H$23*24*30) -> 194.12556 | K33: =J33/$K$5*1000 -> 7.3254929 | L33: =J33/$J$58 -> 0.0094209145 | M33: Chi phí thực tế bình quân 3 tháng liền kề
D34: Cộng giá thành A0 - Vảy thô (I+II+III) | J34: =J9+J10+J21 -> 18570.979 | K34: =J34*1000/$K$5 -> 700.79165 | L34: =J34/$J$58 -> 0.90124969
C35: B | D35: CÔNG ĐOẠN RỬA VẢY:
C36: IV | F36: Chi phí A0 - Vảy thô | G36: Kg | H36: 1 | I36: =+J34 -> 18570.979 | J36: =+H36*I36 -> 18570.979 | K36: =J36*1000/$K$5 -> 700.79165 | L36: =J36/$J$58 -> 0.90124969
C37: V | F37: Chi phí rửa vảy, tách kim loại (clean flake) | J37: =SUM(J40:J57) -> 2034.83 | K37: =J37*1000/$K$5 -> 76.786039 | L37: =J37/$J$58 -> 0.098750312
A38: Rửa | C38: 0 | D38: VBAL1 | F38: Công suất máy (capacity) | G38: Kg /h | H38: 15381.993 | I38: 1.7933333 | M38: Công suất máy 5860 (CW1: 1800, CW2:1660, Boretech 2400)
A39: Rửa | F39: Hiệu suất máy | G39: % | H39: 0.81 | I39: 15381.993 | M39: Bình quân 3 tháng liền kề theo BI
A40: Zigzag | B40: Hao hụt | C40: =+C38+1 -> 1 | D40: 1522 | E40: 160012311 | F40: Phó Sản PET Zigzag | G40: % | H40: 0.0016854746 | I40: 11000 | J40: =+($J$34-I40)*H40 -> 12.760692 | K40: =J40/$K$5*1000 -> 0.48153554 | L40: =J40/$J$58 -> 0.00061927644 | M40: Thu hồi theo giá thị trường
A41: Tomra | B41: Hao hụt | C41: =+C40+1 -> 2 | D41: 1522 | E41: 160012419 | F41: Phó Sản PET Tomra Cổng 3 | G41: % | H41: 0.033714201 | I41: 9500 | J41: =+($J$34-I41)*H41 -> 305.82079 | K41: =J41/$K$5*1000 -> 11.540407 | L41: =J41/$J$58 -> 0.014841485 | M41: Thu hồi theo giá thị trường
A42: Bụi | B42: Hao hụt | C42: =+C41+1 -> 3 | D42: 1522 | E42: 160012336 | F42: Phó Sản PET Bụi Cám | G42: % | H42: 0.021619268 | I42: 5000 | J42: =+($J$34-I42)*H42 -> 293.39462 | K42: =J42/$K$5*1000 -> 11.071495 | L42: =J42/$J$58 -> 0.014238442 | M42: Thu hồi theo giá thị trường
...

Sheet ISS01G-S (2)
A1: Danh mục | C1: 1
C2: PHƯƠNG ÁN SẢN XUẤT TỪ 100% CHAI RA HẠT ISS01G-S (NÂNG IV 10h)
C4: Nguyên liệu: | D4: 100% chai vảy mua ngoài
C5: Thành phẩm: | D5: HẠT rPET ISS01G-S (IV > 0,8) | J5: Tỷ giá USD: | K5: 26500
C7: No. | D7: Nhóm | E7: Mã SAP | F7: Chi phí Cost Items | G7: Đơn vị tính Unit | H7: Định mức Standard | I7: Đơn giá (VNĐ) | J7: Chi phí đơn vị (VNĐ /Kg) | K7: Đơn giá (USD /Tấn) | L7: % giá bán | M7: Cơ sở tính
C8: A | D8: CÔNG ĐOẠN TẠO VẢY THÔ:
B9: Chai | C9: I | D9: 1521 | E9: 150000187 | F9: Chai PET B1.3 | G9: vnđ /Kg | H9: 1 | I9: 15000 | J9: =I9 -> 15000 | K9: =J9/$K$5*1000 -> 566.03774 | L9: =J9/$J$58 -> 0.72795007
B10: Hao hụt | C10: II | D10: 1522 | F10: Hao hụt do băm chai B1 (chai khác loại, bao lót, kẽm, nắp) | G10: % | H10: =SUM(H11:H20) -> 0.17890491 | J10: =SUM(J11:J20) -> 1249.9477 | K10: =J10/$K$5*1000 -> 47.167838 | L10: =J10/$J$58 -> 0.060659968
E11: 160012437 | F11: Chai PET Phi Thực Phẩm | G11: % | H11: 0 | I11: 6000 | J11: =+($J$9-I11)*H11 -> 0 | K11: =J11/$K$5*1000 -> 0 | L11: =J11/$J$58 -> 0 | M11: Thu hồi theo giá thị trường
A12: Chai khác2 | E12: 160012250 | F12: Chai PET B8 Sau Phân Loại | G12: % | H12: 0 | I12: 11000 | J12: =+($J$9-I12)*H12 -> 0 | K12: =J12/$K$5*1000 -> 0 | L12: =J12/$J$58 -> 0 | M12: Thu hồi theo giá thị trường
A13: B4 | E13: 160012398 | F13: Chai PET B4 Sau Phân Loại | G13: % | H13: 0.0013146811 | I13: 12500 | J13: =+($J$9-I13)*H13 -> 3.2867028 | K13: =J13/$K$5*1000 -> 0.12402652 | L13: =J13/$J$58 -> 0.0001595037 | M13: Thu hồi theo giá thị trường
A14: B5 | E14: 160012252 | F14: Chai PET B5 Sau Phân Loại | G14: % | H14: 0.0020155036 | I14: 12500 | J14: =+($J$9-I14)*H14 -> 5.038759 | K14: =J14/$K$5*1000 -> 0.19014185 | L14: =J14/$J$58 -> 0.000244531 | M14: Thu hồi theo giá thị trường
A15: B6 | E15: 160012247 | F15: Chai PET B6 Sau Phân Loại | G15: % | H15: 0.00065144366 | I15: 12300 | J15: =+($J$9-I15)*H15 -> 1.7588979 | K15: =J15/$K$5*1000 -> 0.066373505 | L15: =J15/$J$58 -> 8.5359323e-05 | M15: Thu hồi theo giá thị trường
A16: Olefin | E16: 160012335 | F16: Phó Sản PET B1/B8 Vảy-Nắp | G16: % | H16: 0.094914291 | I16: 10500 | J16: =+($J$9-I16)*H16 -> 427.11431 | K16: =J16/$K$5*1000 -> 16.117521 | L16: =J16/$J$58 -> 0.02072786 | M16: Thu hồi theo giá thị trường
A17: Bụi | E17: 160012334 | F17: Phó Sản PET Bụi Sàn Rung | G17: % | H17: 0.032148664 | I17: 5000 | J17: =+($J$9-I17)*H17 -> 321.48664 | K17: =J17/$K$5*1000 -> 12.131571 | L17: =J17/$J$58 -> 0.015601748 | M17: Thu hồi theo giá thị trường
A18: Tomra | E18: 160012268 | F18: Phó Sản PET Tomra Cổng 2 | G18: % | H18: 0.015908152 | I18: 10500 | J18: =+($J$9-I18)*H18 -> 71.586682 | K18: =J18/$K$5*1000 -> 2.7013842 | L18: =J18/$J$58 -> 0.003474102 | M18: Thu hồi theo giá thị trường
A19: Zigzag | E19: 160012311 | F19: Phó Sản PET Zigzag | G19: % | H19: 0.0054188111 | I19: 11000 | J19: =+($J$9-I19)*H19 -> 21.675244 | K19: =J19/$K$5*1000 -> 0.81793375 | L19: =J19/$J$58 -> 0.0010518997 | M19: Thu hồi theo giá thị trường
A20: Mất đi | F20: Hao hụt nhãn, PVC, đất, cát, nước mất đi | G20: % | H20: 0.026533364 | I20: 0 | J20: =+($J$9-I20)*H20 -> 398.00046 | K20: =J20/$K$5*1000 -> 15.018885 | L20: =J20/$J$58 -> 0.019314965 | M20: Hao hụt mất đi
C21: III | F21: Chi phí băm vảy (bale to flake) | J21: =SUM(J22:J33) -> 2321.031 | K21: =J21*1000/$K$5 -> 87.586075 | L21: =J21/$J$58 -> 0.11263965
A22: Băm | C22: 0 | D22: REL01 | F22: Công suất máy (capacity) | G22: Kg /h | H22: 4800 | M22: Công suất máy 4800 (CW1: 1200, CW2:1200, Boretech 2400)
A23: Băm | F23: Hiệu suất máy | G23: % | H23: 0.6 | M23: Bình quân 3 tháng liền kề theo BI
A24: Băm | B24: NCTT | C24: =+C22+1 -> 1 | D24: LAB | E24: 622 | F24: Chi phí nhân công trực tiếp | G24: tháng | H24: 1 | I24: 1811265742 | J24: =+I24/($H$22*$H$23*24*30) -> 873.48849 | K24: =J24/$K$5*1000 -> 32.96183 | L24: =J24/$J$58 -> 0.042390401 | M24: 11 người lựa chai trên chuyền, 1 người cắt kiện, phế, 1 người đóng gói, 0,5 xe nâng
A25: Băm | B25: NCGT | C25: =+C23+1 -> 1 | D25: LAB | E25: 6271 | F25: Chi phí nhân công gián tiếp | G25: tháng | H25: 1 | I25: 7.5152141e+08 | J25: =+I25/($H$22*$H$23*24*30) -> 362.42352 | K25: =J25/$K$5*1000 -> 13.676359 | L25: =J25/$J$58 -> 0.017588415 | M25: Lương trưởng ca, hành chính, tổ trưởng, quản lý sản xuất gián tiếp như QC, Kỹ thuật
A26: Băm | B26: VTPX | C26: =+C24+1 -> 2 | D26: OTH | E26: 6272 | F26: Chi phí vật tư phân xưởng | G26: tháng | H26: 1 | I26: 3.3060958e+08 | J26: =+I26/($H$22*$H$23*24*30) -> 159.43749 | K26: =J26/$K$5*1000 -> 6.0165091 | L26: =J26/$J$58 -> 0.0077375022 | M26: Chi phí thực tế bình quân 3 tháng liền kề
A27: Băm | B27: CCDC | C27: =+C25+1 -> 2 | D27: OTH | E27: 6273 | F27: Chi phí CCDC, bảo trì | G27: tháng | H27: 1 | I27: 1.9855935e+08 | J27: =+I27/($H$22*$H$23*24*30) -> 95.755858 | K27: =J27/$K$5*1000 -> 3.6134286 | L27: =J27/$J$58 -> 0.0046470323 | M27: Chi phí thực tế bình quân 3 tháng liền kề
A28: Băm | B28: KH | C28: =+C26+1 -> 3 | D28: DEP | E28: 6274.1 | F28: Chi phí khấu hao MMTB chính | G28: tháng | H28: 1 | I28: 3.6698932e+08 | J28: =+I28/($H$22*$H$23*24*30) -> 176.98173 | K28: =J28/$K$5*1000 -> 6.6785559 | L28: =J28/$J$58 -> 0.0085889242 | M28: Chi phí thực tế bình quân 3 tháng liền kề theo danh sách TSCĐ
A29: Băm | B29: KH | C29: =+C27+1 -> 3 | D29: DEP | E29: 6274.2 | F29: Chi phí khấu hao MMTB phụ | G29: tháng | H29: 1 | I29: 2.9525985e+08 | J29: =+I29/($H$22*$H$23*24*30) -> 142.38997 | K29: =J29/$K$5*1000 -> 5.3732065 | L29: =J29/$J$58 -> 0.0069101861 | M29: Chi phí thực tế bình quân 3 tháng liền kề theo danh sách TSCĐ
A30: Băm | B30: KH | C30: =+C28+1 -> 4 | D30: DEP | E30: 6274.3 | F30: Chi phí khấu hao MMTB dùng chung | G30: tháng | H30: 1 | I30: 1.4463942e+08 | J30: =+I30/($H$22*$H$23*24*30) -> 69.752806 | K30: =J30/$K$5*1000 -> 2.6321814 | L30: =J30/$J$58 -> 0.003385104 | M30: Chi phí thực tế bình quân 3 tháng liền kề theo danh sách TSCĐ
A31: Băm | B31: KH | C31: =+C29+1 -> 4 | D31: DEP | E31: 6274.4 | F31: Chi phí khấu hao nhà xưởng | G31: tháng | H31: 1 | I31: 1.7358714e+08 | J31: =+I31/($H$22*$H$23*24*30) -> 83.712935 | K31: =J31/$K$5*1000 -> 3.1589787 | L31: =J31/$J$58 -> 0.0040625891 | M31: Chi phí thực tế bình quân 3 tháng liền kề theo danh sách TSCĐ
A32: Băm | B32: Điện | C32: =+C27+1 -> 3 | D32: ELEC | E32: 6275 | F32: Điện (electronic) kwh | G32: Kwh | H32: 1 | I32: 3.3791931e+08 | J32: =+I32/($H$22*$H$23*24*30) -> 162.96263 | K32: =J32/$K$5*1000 -> 6.1495332 | L32: =J32/$J$58 -> 0.0079085772 | M32: Chi phí thực tế bình quân 3 tháng liền kề. CW1: 178 Kwh, CW2: 185 Kwh, Boretech: 132 Kwh
A33: Băm | B33: Khác | C33: =+C28+1 -> 4 | D33: OTH | E33: 6277.6278 | F33: Chi phí bằng tiền khác | G33: tháng | H33: 1 | I33: 4.0253876e+08 | J33: =+I33/($H$22*$H$23*24*30) -> 194.12556 | K33: =J33/$K$5*1000 -> 7.3254929 | L33: =J33/$J$58 -> 0.0094209145 | M33: Chi phí thực tế bình quân 3 tháng liền kề
D34: Cộng giá thành A0 - Vảy thô (I+II+III) | J34: =J9+J10+J21 -> 18570.979 | K34: =J34*1000/$K$5 -> 700.79165 | L34: =J34/$J$58 -> 0.90124969
C35: B | D35: CÔNG ĐOẠN RỬA VẢY:
C36: IV | F36: Chi phí A0 - Vảy thô | G36: Kg | H36: 1 | I36: =+J34 -> 18570.979 | J36: =+H36*I36 -> 18570.979 | K36: =J36*1000/$K$5 -> 700.79165 | L36: =J36/$J$58 -> 0.90124969
C37: V | F37: Chi phí rửa vảy, tách kim loại (clean flake) | J37: =SUM(J40:J57) -> 2034.83 | K37: =J37*1000/$K$5 -> 76.786039 | L37: =J37/$J$58 -> 0.098750312
A38: Rửa | C38: 0 | D38: VBAL1 | F38: Công suất máy (capacity) | G38: Kg /h | H38: 15381.993 | M38: Công suất máy 5860 (CW1: 1800, CW2:1660, Boretech 2400)
A39: Rửa | F39: Hiệu suất máy | G39: % | H39: 0.81 | M39: Bình quân 3 tháng liền kề theo BI
A40: Zigzag | B40: Hao hụt | C40: =+C38+1 -> 1 | D40: 1522 | E40: 160012311 | F40: Phó Sản PET Zigzag | G40: % | H40: 0.0016854746 | I40: 11000 | J40: =+($J$34-I40)*H40 -> 12.760692 | K40: =J40/$K$5*1000 -> 0.48153554 | L40: =J40/$J$58 -> 0.00061927644 | M40: Thu hồi theo giá thị trường
A41: Tomra | B41: Hao hụt | C41: =+C40+1 -> 2 | D41: 1522 | E41: 160012419 | F41: Phó Sản PET Tomra Cổng 3 | G41: % | H41: 0.033714201 | I41: 9500 | J41: =+($J$34-I41)*H41 -> 305.82079 | K41: =J41/$K$5*1000 -> 11.540407 | L41: =J41/$J$58 -> 0.014841485 | M41: Thu hồi theo giá thị trường
A42: Bụi | B42: Hao hụt | C42: =+C41+1 -> 3 | D42: 1522 | E42: 160012336 | F42: Phó Sản PET Bụi Cám | G42: % | H42: 0.021619268 | I42: 5000 | J42: =+($J$34-I42)*H42 -> 293.39462 | K42: =J42/$K$5*1000 -> 11.071495 | L42: =J42/$J$58 -> 0.014238442 | M42: Thu hồi theo giá thị trường
...
