Workbook

Sheet Cảnh báo giá mua
B3: C:\Data\GĐ Tài chính\Cost Controlling\Costing Flow Chart\Báo CT _Model\PET_FULL_CFO_OPTIMIZATION.xlsx
B5: Cty | C5: CPC
B6: Cty | C6: Far Eastern
B7: Cty | C7: Nhóm Trung Quốc

Sheet Sheet3
B2: BẢNG TÍNH SETTLEMENT RULE BOM - ROUTING (co-product)
M3: Hide | P3: Giá BO sau Phân loại
B4: I. | C4: CÔNG ĐOẠN PHÂN LOẠI CHAI | D4: BOM - KẾ HOẠCH | F4: Sản lượng thành phẩm thực tế | G4: Hệ số quy đổi | H4: Sản lượng thành phẩm quy đổi | I4: Giá trị nguyên liệu phân bổ cho thành phẩm quy đổi | J4: Settlement rule - BOM | K4: Settlement rule - ROUTING | L4: Ghi chú | M4: Giá bán hiện tại | N4: Hệ số quy đổi giá bán | O4: Gap (đảm bảo chi phí và lợi nhuận) | P4: GT NVL | Q4: CFSX | R4: GT SP Trạm | S4: LG | T4: % | V4: Đlộc | X4: KN | Z4: ĐLâm | AB4: Giá thị trường
D5: Số lượng | E5: Tỷ lệ | F5: (1) | G5: (2) | H5: (3)= (1)*(2) | I5: (4) | J5: Tỷ lệ | K5: Tỷ lệ | M5: =MAX(V5,X5,Z5) -> 0.10667325 | U5: Hao hụt | V5: ='[1]1. Đại Lộc'!$O$334 -> 0.10096034 | X5: ='[1]2. Khánh Nga'!$O$39 -> 0.097733527 | Z5: ='[1]3. Đồng Lâm'!$O$344 -> 0.10667325
B6: 150000001 | C6: Chai PET xá | D6: 1000 | E6: =SUM(E7:E20) -> 1 | I6: =D6*$M$6 -> 11300000 | J6: =SUM(J7:J19) -> 1 | K6: =SUM(K7:K19) -> 1 | M6: 11300 | Q6: 3000 | V6: ='[2]3.CP_TAN'!$Q$78 -> 3684.4011 | X6: ='[2]3.CP_TAN'!$R$78 -> 2894.8843 | Z6: ='[2]3.CP_TAN'!$S$78 -> 2609.6553 | AB6: 10000
B7: 160000001 | C7: Chai PET B1.1 | D7: 540 | E7: 0.54 | F7: =D7 -> 540 | G7: 1.25 | H7: =F7*G7 -> 675 | I7: =$I$6/$H$21*H7 -> 7257373.9 | J7: =I7/$I$6 -> 0.64224548 | K7: =J7 -> 0.64224548 | L7: (4) = Tổng giá trị NVL /(Tổng số lượng TP quy đổi) * Sl Tp quy đổi. (5) = Giá trị nguyên liệu phân bổ cho thành phẩm quy đổi / Tổng giá trị nguyên liệu phân bổ cho thành phẩm quy đổi | M7: =ROUND($M$6+$M$6*$M$5+O7,-2) -> 16400 | N7: =M7/$M$21 -> 1.2471483 | O7: 3900 | P7: =I7/F7 -> 13439.581 | Q7: =$Q$6*K7 -> 1926.7364 | R7: =P7+Q7 -> 15366.318 | S7: =M7-R7 -> 1033.6822 | T7: =S7/M7 -> 0.063029403 | U7: ='[1]1. Đại Lộc'!B327 -> % Chai B1 | V7: ='[1]1. Đại Lộc'!O327 -> 0.65050165 | W7: ='[1]2. Khánh Nga'!B32 -> % Chai B1 | X7: ='[1]2. Khánh Nga'!O32 -> 0.5258354 | Y7: ='[1]3. Đồng Lâm'!B337 -> % Chai B1 | Z7: ='[1]3. Đồng Lâm'!O337 -> 0.50053443 | AB7: 14500 | AC7: 11200 | AE7: =T7*V7 -> 0.041000731 | AF7: =ROUND($M$6+$M$6*$M$5,-2) -> 12500
B8: 160000081 | C8: Chai PET B1.3 | F8: =D8 -> 0 | H8: =F8*G8 -> 0 | I8: =$I$6/$H$21*H8 -> 0 | J8: =I8/$I$6 -> 0 | K8: =J8 -> 0 | N8: =M8/$M$21 -> 0 | O8: =O7 -> 3900 | P8: =I8/F8 -> #DIV/0! | Q8: =$Q$6*K8 -> 0 | R8: =P8+Q8 -> #DIV/0! | S8: =M8-R8 -> #DIV/0! | T8: =S8/M8 -> #DIV/0! | AE8: =T8*V8 -> #DIV/0!
B9: 160000002 | C9: Chai PET B2.2 | D9: 30 | E9: 0.03 | F9: =D9 -> 30 | G9: 1.1 | H9: =F9*G9 -> 33 | I9: =$I$6/$H$21*H9 -> 354804.95 | J9: =I9/$I$6 -> 0.031398668 | K9: =J9 -> 0.031398668 | M9: =ROUND($M$6+$M$6*$M$5+O9,-2) -> 14500 | N9: =M9/$M$21 -> 1.1026616 | O9: 2000 | P9: =I9/F9 -> 11826.832 | Q9: =$Q$6*K9 -> 94.196004 | R9: =P9+Q9 -> 11921.028 | S9: =M9-R9 -> 2578.9724 | T9: =S9/M9 -> 0.17786017 | U9: ='[1]1. Đại Lộc'!B328 -> % Chai B2.2 | V9: ='[1]1. Đại Lộc'!O328 -> 0.0053561787 | W9: ='[1]2. Khánh Nga'!B33 -> % Chai B2.2 | X9: ='[1]2. Khánh Nga'!O33 -> 0.078724377 | Y9: ='[1]3. Đồng Lâm'!B338 -> % Chai B2.2 | Z9: ='[1]3. Đồng Lâm'!O338 -> 0.08356034 | AE9: =T9*V9 -> 0.00095265083
B10: 160000063 | C10: Chai PET B4 | D10: 20 | E10: 0.02 | F10: =D10 -> 20 | G10: 1 | H10: =F10*G10 -> 20 | I10: =$I$6/$H$21*H10 -> 215033.3 | J10: =I10/$I$6 -> 0.019029496 | K10: =J10 -> 0.019029496 | M10: =ROUND($M$6+$M$6*$M$5+O10,-2) -> 13000 | N10: =M10/$M$21 -> 0.98859316 | O10: 500 | P10: =I10/F10 -> 10751.665 | Q10: =$Q$6*K10 -> 57.088487 | R10: =P10+Q10 -> 10808.754 | S10: =M10-R10 -> 2191.2464 | T10: =S10/M10 -> 0.16855742 | U10: ='[1]2. Khánh Nga'!B35 -> % Chai B4 | V10: ='[1]2. Khánh Nga'!O35 -> 0.014912634 | W10: ='[1]2. Khánh Nga'!B35 -> % Chai B4 | X10: ='[1]2. Khánh Nga'!O35 -> 0.014912634 | Y10: ='[1]3. Đồng Lâm'!B340 -> % Chai B4 | Z10: ='[1]3. Đồng Lâm'!O340 -> 0.019139602 | AE10: =T10*V10 -> 0.0025136351
B11: 160000004 | C11: Chai PET B5 | D11: 20 | E11: 0.02 | F11: =D11 -> 20 | G11: 1 | H11: =F11*G11 -> 20 | I11: =$I$6/$H$21*H11 -> 215033.3 | J11: =I11/$I$6 -> 0.019029496 | K11: =J11 -> 0.019029496 | M11: =ROUND($M$6+$M$6*$M$5+O11,-2) -> 13000 | N11: =M11/$M$21 -> 0.98859316 | O11: =O10 -> 500 | P11: =I11/F11 -> 10751.665 | Q11: =$Q$6*K11 -> 57.088487 | R11: =P11+Q11 -> 10808.754 | S11: =M11-R11 -> 2191.2464 | T11: =S11/M11 -> 0.16855742 | U11: ='[1]2. Khánh Nga'!B36 -> % Chai B5 | V11: ='[1]2. Khánh Nga'!O36 -> 0.019802359 | W11: ='[1]2. Khánh Nga'!B36 -> % Chai B5 | X11: ='[1]2. Khánh Nga'!O36 -> 0.019802359 | Y11: ='[1]3. Đồng Lâm'!B341 -> % Chai B5 | Z11: ='[1]3. Đồng Lâm'!O341 -> 0.010656982 | AE11: =T11*V11 -> 0.0033378344
C12: Chai PET B6.1 | F12: =D12 -> 0 | H12: =F12*G12 -> 0 | I12: =$I$6/$H$21*H12 -> 0 | J12: =I12/$I$6 -> 0 | K12: =J12 -> 0 | N12: =M12/$M$21 -> 0 | O12: =O8 -> 3900 | P12: =I12/F12 -> #DIV/0! | Q12: =$Q$6*K12 -> 0 | R12: =P12+Q12 -> #DIV/0! | S12: =M12-R12 -> #DIV/0! | T12: =S12/M12 -> #DIV/0! | AE12: =T12*V12 -> #DIV/0!
B13: 160000005 | C13: Chai PET B6.2 | D13: 270 | E13: 0.27 | F13: =D13 -> 270 | G13: 1.1 | H13: =F13*G13 -> 297 | I13: =$I$6/$H$21*H13 -> 3193244.5 | J13: =I13/$I$6 -> 0.28258801 | K13: =J13 -> 0.28258801 | M13: =ROUND($M$6+$M$6*$M$5+O13,-2) -> 14500 | N13: =M13/$M$21 -> 1.1026616 | O13: =O9 -> 2000 | P13: =I13/F13 -> 11826.832 | Q13: =$Q$6*K13 -> 847.76403 | R13: =P13+Q13 -> 12674.596 | S13: =M13-R13 -> 1825.4044 | T13: =S13/M13 -> 0.12588996 | U13: ='[1]1. Đại Lộc'!B329 -> % Chai B6.2 | V13: ='[1]1. Đại Lộc'!O329 -> 0.19170632 | W13: ='[1]2. Khánh Nga'!B34 -> % Chai B6.2 | X13: ='[1]2. Khánh Nga'!O34 -> 0.23118717 | Y13: ='[1]3. Đồng Lâm'!B339 -> % Chai B6.2 | Z13: ='[1]3. Đồng Lâm'!O339 -> 0.26757253 | AE13: =T13*V13 -> 0.024133901
B14: 160000007 | C14: Nắp HD Ép Các Màu HDE-06 | D14: 10 | E14: 0.01 | F14: =D14 -> 10 | G14: 0.6 | H14: =F14*G14 -> 6 | I14: =$I$6/$H$21*H14 -> 64509.99 | J14: =I14/$I$6 -> 0.0057088487 | K14: =J14 -> 0.0057088487 | M14: =ROUND($M$6+$M$6*$M$5+O14,-2) -> 7500 | N14: =M14/$M$21 -> 0.57034221 | O14: -5000 | P14: =I14/F14 -> 6450.999 | Q14: =$Q$6*K14 -> 17.126546 | R14: =P14+Q14 -> 6468.1256 | S14: =M14-R14 -> 1031.8744 | T14: =S14/M14 -> 0.13758325 | U14: ='[1]2. Khánh Nga'!B37 -> % Nắp | V14: ='[1]2. Khánh Nga'!O37 -> 0.031786115 | W14: ='[1]2. Khánh Nga'!B37 -> % Nắp | X14: ='[1]2. Khánh Nga'!O37 -> 0.031786115 | Y14: ='[1]3. Đồng Lâm'!B342 -> % Nắp | Z14: ='[1]3. Đồng Lâm'!O342 -> 0.0029470813 | AE14: =T14*V14 -> 0.0043732371
C15: Chai PET B7.1 | E15: 0 | N15: =M15/$M$21 -> 0 | P15: =I15/F15 -> #DIV/0! | Q15: =$Q$6*K15 -> 0 | R15: =P15+Q15 -> #DIV/0! | S15: =M15-R15 -> #DIV/0! | T15: =S15/M15 -> #DIV/0! | AE15: =T15*V15 -> #DIV/0!
B16: 160000084 | C16: Chai PET B7.2 | E16: 0 | N16: =M16/$M$21 -> 0 | O16: -1000 | P16: =I16/F16 -> #DIV/0! | Q16: =$Q$6*K16 -> 0 | R16: =P16+Q16 -> #DIV/0! | S16: =M16-R16 -> #DIV/0! | T16: =S16/M16 -> #DIV/0! | U16: ='[1]2. Khánh Nga'!B38 -> % Chai B7.2 | V16: ='[1]2. Khánh Nga'!O38 -> 1.842727e-05 | W16: ='[1]2. Khánh Nga'!B38 -> % Chai B7.2 | X16: ='[1]2. Khánh Nga'!O38 -> 1.842727e-05 | Y16: ='[1]3. Đồng Lâm'!B343 -> % Phó sản | Z16: ='[1]3. Đồng Lâm'!O343 -> 0.0089157794
B17: 160000062 | C17: Cổ Chai PET | E17: 0 | N17: =M17/$M$21 -> 0 | O17: 2000 | P17: =I17/F17 -> #DIV/0! | Q17: =$Q$6*K17 -> 0 | R17: =P17+Q17 -> #DIV/0! | S17: =M17-R17 -> #DIV/0! | T17: =S17/M17 -> #DIV/0!
B18: 160000006 | C18: Hao Hụt - Tạp chất | D18: 10 | E18: 0.01 | P18: =I18/F18 -> #DIV/0! | Q18: =$Q$6*K18 -> 0 | R18: =P18+Q18 -> #DIV/0! | S18: =M18-R18 -> #DIV/0! | T18: =S18/M18 -> #DIV/0!
B19: 800000006 | C19: Hao hụt - nhãn chai PET | D19: 60 | E19: 0.06 | P19: =I19/F19 -> #DIV/0! | Q19: =$Q$6*K19 -> 0 | R19: =P19+Q19 -> #DIV/0! | S19: =M19-R19 -> #DIV/0! | T19: =S19/M19 -> #DIV/0!
C20: Hao hụt vô hình | D20: =D6-SUM(D7:D19) -> 40 | E20: 0.04 | P20: =I20/F20 -> #DIV/0! | Q20: =$Q$6*K20 -> 0 | R20: =P20+Q20 -> #DIV/0! | S20: =M20-R20 -> #DIV/0! | T20: =S20/M20 -> #DIV/0!
C21: TỔNG | D21: =SUM(D7:D20) -> 1000 | E21: =SUM(E7:E20) -> 1 | F21: =SUM(F7:F20) -> 890 | G21: =SUM(G7:G20) -> 6.05 | H21: =SUM(H7:H20) -> 1051 | I21: =SUM(I7:I20) -> 11300000 | M21: =AVERAGE(M7:M19) -> 13150 | P21: =I21/F21 -> 12696.629 | T21: =S21/M21 -> 0
P22: =10000/(F21/1000)-P21 -> -1460.6742
B24: II. | C24: CÔNG ĐOẠN BĂM CHAI B6.2 | D24: BOM - KẾ HOẠCH | F24: Sản lượng thành phẩm thực tế | G24: Hệ số quy đổi | H24: Sản lượng thành phẩm quy đổi | I24: Giá trị nguyên liệu phân bổ cho thành phẩm quy đổi | J24: Settlement rule - BOM | K24: Settlement rule - ROUTING | L24: Ghi chú | M24: Giá bán hiện tại | N24: Hệ số quy đổi giá bán
D25: Số lượng | E25: Tỷ lệ | F25: (1) | G25: (2) | H25: (3)= (1)*(2) | I25: (4) | J25: Tỷ lệ | K25: Tỷ lệ
B26: 160000005 | C26: Chai PET B6.2 | D26: 600 | F26: =SUM(F27:F31) -> 1080 | G26: =SUM(G27:G31) -> 4.1 | I26: =I13/F13*D26 -> 7096099
B27: 160000027 | C27: Vảy PET B6.2_A6 | D27: =D26*E27 -> 510 | E27: 0.85 | F27: =D27 -> 510 | G27: 1.35 | H27: =F27*G27 -> 688.5 | I27: =$I$26/$H$31*H27 -> 6886066.4 | J27: =I27/$I$26 -> 0.97040169 | K27: =J27 -> 0.97040169 | L27: (4) = Tổng giá trị NVL /(Tổng số lượng TP quy đổi) * Sl Tp quy đổi. (5) = Giá trị nguyên liệu phân bổ cho thành phẩm quy đổi / Tổng giá trị nguyên liệu phân bổ cho thành phẩm quy đổi | M27: =ROUND($M$13+O27,-2) -> 16500 | N27: =M27/$M$31 -> 1.2692308 | O27: 2000 | P27: 2500
B28: 160000059 | C28: Vảy nắp hỗn hợp B6.2 | D28: =D26*E28 -> 30 | E28: 0.05 | F28: =D28 -> 30 | G28: 0.7 | H28: =F28*G28 -> 21 | I28: =$I$26/$H$31*H28 -> 210032.53 | J28: =I28/$I$26 -> 0.029598309 | K28: =J28 -> 0.029598309 | M28: =ROUND($M$14+O28,-2) -> 9500 | N28: =M28/$M$31 -> 0.73076923 | O28: =O27 -> 2000 | P28: 2500
C29: Phó sản bụi cám | D29: =D26*5% -> 30
C30: Hao hụt vô hình | D30: =D26*5% -> 30
C31: TỔNG | D31: =SUM(D27:D30) -> 600 | F31: =SUM(F27:F30) -> 540 | G31: =SUM(G27:G30) -> 2.05 | H31: =SUM(H27:H30) -> 709.5 | M31: =AVERAGE(M27:M30) -> 13000
C33: Vảy PET_A5.1 mua ngoài | AB33: 16300

Sheet BOM&NRV
B2: BẢNG TÍNH SETTLEMENT RULE BOM - ROUTING (co-product)
M3: Hide
B4: I. | C4: CÔNG ĐOẠN PHÂN LOẠI CHAI | D4: BOM - KẾ HOẠCH | F4: Sản lượng thành phẩm thực tế | G4: Hệ số quy đổi | H4: Sản lượng thành phẩm quy đổi | I4: Giá trị nguyên liệu phân bổ cho thành phẩm quy đổi | J4: Settlement rule - BOM | K4: Settlement rule - ROUTING | L4: Ghi chú | M4: Giá bán hiện tại | N4: Hệ số quy đổi giá bán | P4: GT NVL | Q4: CFSX | R4: GT SP Trạm | S4: LG | T4: %
D5: Số lượng | E5: Tỷ lệ | F5: (1) | G5: (2) | H5: (3)= (1)*(2) | I5: (4) | J5: Tỷ lệ | K5: Tỷ lệ
B6: 150000001 | C6: Chai PET xá | D6: 1000 | E6: =SUM(E7:E20) -> 1 | I6: =D6*10000 -> 10000000 | J6: =SUM(J7:J19) -> 1 | K6: =SUM(K7:K19) -> 1 | Q6: 3000
B7: 160000001 | C7: Chai PET B1.1 | D7: 540 | E7: 0.54 | F7: =D7 -> 540 | G7: 1.25 | H7: =F7*G7 -> 675 | I7: =$I$6/$H$21*H7 -> 6422454.8 | J7: =I7/$I$6 -> 0.64224548 | K7: =J7 -> 0.64224548 | L7: (4) = Tổng giá trị NVL /(Tổng số lượng TP quy đổi) * Sl Tp quy đổi. (5) = Giá trị nguyên liệu phân bổ cho thành phẩm quy đổi / Tổng giá trị nguyên liệu phân bổ cho thành phẩm quy đổi | M7: =ROUND(11000+11000*14%+4000,-2) -> 16500 | N7: =M7/$M$21 -> 1.2222222 | P7: =I7/F7 -> 11893.435 | Q7: =$Q$6*K7 -> 1926.7364 | R7: =P7+Q7 -> 13820.171 | S7: =M7-R7 -> 2679.8287 | T7: =S7/M7 -> 0.16241386
B8: 160000081 | C8: Chai PET B1.3 | F8: =D8 -> 0 | H8: =F8*G8 -> 0 | I8: =$I$6/$H$21*H8 -> 0 | J8: =I8/$I$6 -> 0 | K8: =J8 -> 0 | N8: =M8/$M$21 -> 0 | P8: =I8/F8 -> #DIV/0! | Q8: =$Q$6*K8 -> 0 | R8: =P8+Q8 -> #DIV/0! | S8: =M8-R8 -> #DIV/0! | T8: =S8/M8 -> #DIV/0!
B9: 160000002 | C9: Chai PET B2.2 | D9: 30 | E9: 0.03 | F9: =D9 -> 30 | G9: 1.1 | H9: =F9*G9 -> 33 | I9: =$I$6/$H$21*H9 -> 313986.68 | J9: =I9/$I$6 -> 0.031398668 | K9: =J9 -> 0.031398668 | M9: =ROUND(11000+11000*14%+2500,-2) -> 15000 | N9: =M9/$M$21 -> 1.1111111 | P9: =I9/F9 -> 10466.223 | Q9: =$Q$6*K9 -> 94.196004 | R9: =P9+Q9 -> 10560.419 | S9: =M9-R9 -> 4439.5814 | T9: =S9/M9 -> 0.29597209
B10: 160000063 | C10: Chai PET B4 | D10: 20 | E10: 0.02 | F10: =D10 -> 20 | G10: 1 | H10: =F10*G10 -> 20 | I10: =$I$6/$H$21*H10 -> 190294.96 | J10: =I10/$I$6 -> 0.019029496 | K10: =J10 -> 0.019029496 | M10: =ROUND(11000+11000*14%+1000,-2) -> 13500 | N10: =M10/$M$21 -> 1 | P10: =I10/F10 -> 9514.7479 | Q10: =$Q$6*K10 -> 57.088487 | R10: =P10+Q10 -> 9571.8363 | S10: =M10-R10 -> 3928.1637 | T10: =S10/M10 -> 0.29097509
B11: 160000004 | C11: Chai PET B5 | D11: 20 | E11: 0.02 | F11: =D11 -> 20 | G11: 1 | H11: =F11*G11 -> 20 | I11: =$I$6/$H$21*H11 -> 190294.96 | J11: =I11/$I$6 -> 0.019029496 | K11: =J11 -> 0.019029496 | M11: =ROUND(11000+11000*14%+1000,-2) -> 13500 | N11: =M11/$M$21 -> 1 | P11: =I11/F11 -> 9514.7479 | Q11: =$Q$6*K11 -> 57.088487 | R11: =P11+Q11 -> 9571.8363 | S11: =M11-R11 -> 3928.1637 | T11: =S11/M11 -> 0.29097509
C12: Chai PET B6.1 | F12: =D12 -> 0 | H12: =F12*G12 -> 0 | I12: =$I$6/$H$21*H12 -> 0 | J12: =I12/$I$6 -> 0 | K12: =J12 -> 0 | N12: =M12/$M$21 -> 0 | P12: =I12/F12 -> #DIV/0! | Q12: =$Q$6*K12 -> 0 | R12: =P12+Q12 -> #DIV/0! | S12: =M12-R12 -> #DIV/0! | T12: =S12/M12 -> #DIV/0!
B13: 160000005 | C13: Chai PET B6.2 | D13: 270 | E13: 0.27 | F13: =D13 -> 270 | G13: 1.1 | H13: =F13*G13 -> 297 | I13: =$I$6/$H$21*H13 -> 2825880.1 | J13: =I13/$I$6 -> 0.28258801 | K13: =J13 -> 0.28258801 | M13: =ROUND(11000+11000*14%+2500,-2) -> 15000 | N13: =M13/$M$21 -> 1.1111111 | P13: =I13/F13 -> 10466.223 | Q13: =$Q$6*K13 -> 847.76403 | R13: =P13+Q13 -> 11313.987 | S13: =M13-R13 -> 3686.0133 | T13: =S13/M13 -> 0.24573422
B14: 160000007 | C14: Nắp HD Ép Các Màu HDE-06 | D14: 10 | E14: 0.01 | F14: =D14 -> 10 | G14: 0.6 | H14: =F14*G14 -> 6 | I14: =$I$6/$H$21*H14 -> 57088.487 | J14: =I14/$I$6 -> 0.0057088487 | K14: =J14 -> 0.0057088487 | M14: =ROUND(11000+11000*14%-5000,-2) -> 7500 | N14: =M14/$M$21 -> 0.55555556 | P14: =I14/F14 -> 5708.8487 | Q14: =$Q$6*K14 -> 17.126546 | R14: =P14+Q14 -> 5725.9753 | S14: =M14-R14 -> 1774.0247 | T14: =S14/M14 -> 0.23653663
C15: Chai PET B7.1 | E15: 0 | N15: =M15/$M$21 -> 0 | P15: =I15/F15 -> #DIV/0! | Q15: =$Q$6*K15 -> 0 | R15: =P15+Q15 -> #DIV/0! | S15: =M15-R15 -> #DIV/0! | T15: =S15/M15 -> #DIV/0!
B16: 160000084 | C16: Chai PET B7.2 | E16: 0 | N16: =M16/$M$21 -> 0 | P16: =I16/F16 -> #DIV/0! | Q16: =$Q$6*K16 -> 0 | R16: =P16+Q16 -> #DIV/0! | S16: =M16-R16 -> #DIV/0! | T16: =S16/M16 -> #DIV/0!
B17: 160000062 | C17: Cổ Chai PET | E17: 0 | N17: =M17/$M$21 -> 0 | P17: =I17/F17 -> #DIV/0! | Q17: =$Q$6*K17 -> 0 | R17: =P17+Q17 -> #DIV/0! | S17: =M17-R17 -> #DIV/0! | T17: =S17/M17 -> #DIV/0!
B18: 160000006 | C18: Hao Hụt - Tạp chất | D18: 10 | E18: 0.01 | P18: =I18/F18 -> #DIV/0! | Q18: =$Q$6*K18 -> 0 | R18: =P18+Q18 -> #DIV/0! | S18: =M18-R18 -> #DIV/0! | T18: =S18/M18 -> #DIV/0!
B19: 800000006 | C19: Hao hụt - nhãn chai PET | D19: 60 | E19: 0.06 | P19: =I19/F19 -> #DIV/0! | Q19: =$Q$6*K19 -> 0 | R19: =P19+Q19 -> #DIV/0! | S19: =M19-R19 -> #DIV/0! | T19: =S19/M19 -> #DIV/0!
C20: Hao hụt vô hình | D20: =D6-SUM(D7:D19) -> 40 | E20: 0.04 | P20: =I20/F20 -> #DIV/0! | Q20: =$Q$6*K20 -> 0 | R20: =P20+Q20 -> #DIV/0! | S20: =M20-R20 -> #DIV/0! | T20: =S20/M20 -> #DIV/0!
C21: TỔNG | D21: =SUM(D7:D20) -> 1000 | E21: =SUM(E7:E20) -> 1 | F21: =SUM(F7:F20) -> 890 | G21: =SUM(G7:G20) -> 6.05 | H21: =SUM(H7:H20) -> 1051 | I21: =SUM(I7:I20) -> 10000000 | M21: =AVERAGE(M7:M19) -> 13500 | P21: =I21/F21 -> 11235.955 | T21: =S21/M21 -> 0
P22: =10000/(F21/1000)-P21 -> 0
B24: II. | C24: CÔNG ĐOẠN BĂM CHAI B6.2 | D24: BOM - KẾ HOẠCH | F24: Sản lượng thành phẩm thực tế | G24: Hệ số quy đổi | H24: Sản lượng thành phẩm quy đổi | I24: Giá trị nguyên liệu phân bổ cho thành phẩm quy đổi | J24: Settlement rule - BOM | K24: Settlement rule - ROUTING | L24: Ghi chú | M24: Giá bán hiện tại | N24: Hệ số quy đổi giá bán
D25: Số lượng | E25: Tỷ lệ | F25: (1) | G25: (2) | H25: (3)= (1)*(2) | I25: (4) | J25: Tỷ lệ | K25: Tỷ lệ
B26: 160000005 | C26: Chai PET B6.2 | D26: 600 | F26: =SUM(F27:F31) -> 1080 | G26: =SUM(G27:G31) -> 4.1 | I26: =I13/F13*D26 -> 6279733.6
B27: 160000027 | C27: Vảy PET B6.2_A6 | D27: =D26*E27 -> 510 | E27: 0.85 | F27: =D27 -> 510 | G27: 1.35 | H27: =F27*G27 -> 688.5 | I27: =$I$26/$H$31*H27 -> 6093864.1 | J27: =I27/$I$26 -> 0.97040169 | K27: =J27 -> 0.97040169 | L27: (4) = Tổng giá trị NVL /(Tổng số lượng TP quy đổi) * Sl Tp quy đổi. (5) = Giá trị nguyên liệu phân bổ cho thành phẩm quy đổi / Tổng giá trị nguyên liệu phân bổ cho thành phẩm quy đổi | M27: 18500 | N27: =M27/$M$31 -> 1.3214286
B28: 160000059 | C28: Vảy nắp hỗn hợp B6.2 | D28: =D26*E28 -> 30 | E28: 0.05 | F28: =D28 -> 30 | G28: 0.7 | H28: =F28*G28 -> 21 | I28: =$I$26/$H$31*H28 -> 185869.49 | J28: =I28/$I$26 -> 0.029598309 | K28: =J28 -> 0.029598309 | M28: 9500 | N28: =M28/$M$31 -> 0.67857143
C29: Phó sản bụi cám | D29: =D26*5% -> 30
C30: Hao hụt vô hình | D30: =D26*5% -> 30
C31: TỔNG | D31: =SUM(D27:D30) -> 600 | F31: =SUM(F27:F30) -> 540 | G31: =SUM(G27:G30) -> 2.05 | H31: =SUM(H27:H30) -> 709.5 | M31: =AVERAGE(M27:M30) -> 14000

Sheet GAP
B3: BẢNG TÍNH GIÁ MUA CHAI, VẢY TỪ CÁC TRẠM
J4: Giá B0 | K4: Giá B0 | L4: Giá B0 | M4: Giá B0
I5: ĐVT: đồng/ký | J5: 9500 | K5: 10000 | L5: 10000 | M5: 11300
B6: Nhóm chai PET | C6: Thành phần chai PET sau phân loại | D6: Giá B0 | E6: Hao hụt | G6: Gap (đảm bảo chi phí và lợi nhuận) | H6: Giá mua theo công thức | I6: Giá mua đề xuất
E7: Tỷ lệ | F7: Quy ra tiền
B8: A. Giá mua Chai
B9: Chai PET nhóm 1 | C9: B1.1 + B1.2 + B1.3 + B2.1 + B3 + B6.1 | D9: 11300 | E9: 0.11 | F9: =D9*E9 -> 1243 | G9: 3500 | H9: =D9+F9+G9 -> 16043 | I9: 16300 | J9: =I9-D9 -> 5000 | K9: 5000 | L9: 15800 | M9: 16300
B10: Chai PET nhóm 2 | C10: B4 + B5 | D10: 11300 | E10: 0.11 | F10: =D10*E10 -> 1243 | G10: 500 | H10: =D10+F10+G10 -> 13043 | I10: 13300 | J10: =I10-D10 -> 2000 | K10: 2000 | L10: 12800 | M10: 13300
B11: Chai PET nhóm 3 | C11: B2.2 + B6.2 | D11: 11300 | E11: 0.11 | F11: =D11*E11 -> 1243 | G11: 2000 | H11: =D11+F11+G11 -> 14543 | I11: 14800 | J11: =I11-D11 -> 3500 | K11: 3500 | L11: 14300 | M11: 14800
B12: Chai PET nhóm 4 | C12: Nắp HD Ép, cổ chai, PP (quai) | D12: 11300 | E12: 0.11 | F12: =D12*E12 -> 1243 | G12: -5000 | H12: =D12+F12+G12 -> 7543 | I12: 7800 | J12: =I12-D12 -> -3500 | K12: -3500 | L12: 7300 | M12: 7800
B13: B. Giá mua Vảy | L13: =J13-K13 -> 0
B14: Nhóm 1 | C14: Vảy B6.2 | D14: =I11 -> 14800 | E14: 0.08 | F14: =D14*E14 -> 1184 | G14: 2000 | H14: =D14+F14+G14 -> 17984 | I14: 17800 | J14: =I14-D14 -> 3000 | K14: 3000 | L14: 17300 | M14: 17800
C15: Phó sản | K15: -8000
B16: BẢNG COPY QUA TỜ TRÌNH DUYỆT
B17: Mã SAP | C17: Tên Chai | D17: Giá đề xuất
C18: Chai PET B1.1 | D18: =$I$9 -> 16300
C19: Chai PET B1 KPL (B1.2) | D19: =D18-500 -> 15800
C20: Chai PET B1.3 | D20: =$I$9 -> 16300
B21: 150000004 | C21: Chai PET B2.1 | D21: =$I$9 -> 16300
B22: 150000050 | C22: Chai PET B2.2 | D22: =$I$11 -> 14800
B23: 150000005 | C23: Chai PET B3 | D23: =$I$9 -> 16300
B24: 150000014 | C24: Chai PET B4 | D24: =$I$10 -> 13300
B25: 150000015 | C25: Chai PET B5 | D25: =$I$10 -> 13300
B26: 150000016 | C26: Chai PET B6.1 | D26: =$I$9 -> 16300
B27: 150000114 | C27: Chai PET B6.2 | D27: =$I$11 -> 14800
C28: Nắp HD Ép, cổ chai | D28: =$I$12 -> 7800
C29: PP (quai) | D29: =$I$12 -> 7800
B30: 150000061 | C30: Vảy PET B6.2_A6 | D30: =I14 -> 17800

Sheet So sánh thiệt hại
B1: Giá chai B0 | C1: 10000 | K1: Giá chai B0 | L1: 10000 | T1: Giá chai B0 | U1: 10000 | AC1: Giá chai B0 | AD1: 11300
B2: Chi phí phân loại | C2: 3000 | K2: Chi phí phân loại | L2: 3000 | T2: Chi phí phân loại | U2: 3000 | AC2: Chi phí phân loại | AD2: 3000
B3: Tỷ lệ hao hụt thực tế | C3: 0.1 | K3: Tỷ lệ hao hụt thực tế | L3: 0.1 | T3: Tỷ lệ hao hụt thực tế | U3: 0.1 | AC3: Tỷ lệ hao hụt thực tế | AD3: 0.1
B4: Tổng chi phí | C4: =SUM(C1:C2) -> 13000 | K4: Tổng chi phí | L4: =SUM(L1:L2) -> 13000 | T4: Tổng chi phí | U4: =SUM(U1:U2) -> 13000 | AC4: Tổng chi phí | AD4: =SUM(AD1:AD2) -> 14300
B5: Chi phí hao hụt | C5: =C4*C3/(1-C3) -> 1444.4444 | K5: Chi phí hao hụt | L5: =L4*L3/(1-L3) -> 1444.4444 | T5: Chi phí hao hụt | U5: =U4*U3/(1-U3) -> 1444.4444 | AC5: Chi phí hao hụt | AD5: =AD4*AD3/(1-AD3) -> 1588.8889
B6: Giá bán hòa vốn đơn vị | C6: =+C4/(1-C3) -> 14444.444 | K6: Giá bán hòa vốn đơn vị | L6: =+L4/(1-L3) -> 14444.444 | T6: Giá bán hòa vốn đơn vị | U6: =+U4/(1-U3) -> 14444.444 | AC6: Giá bán hòa vốn đơn vị | AD6: =+AD4/(1-AD3) -> 15888.889
A7: STT | B7: Tên vật tư | C7: Cơ cấu thành phẩm thực tế | D7: Giá bán 3 trạm về DTR | J7: STT | K7: Tên vật tư | L7: Cơ cấu thành phẩm thực tế | M7: Giá bán 3 trạm về DTR | S7: STT | T7: Tên vật tư | U7: Cơ cấu thành phẩm thực tế | V7: Giá bán 3 trạm về DTR | AB7: STT | AC7: Tên vật tư | AD7: Cơ cấu thành phẩm thực tế | AE7: Giá bán 3 trạm về DTR
A8: 1 | B8: Chai PET B1 | C8: ='[3]4. 3 Trạm'!$S334 -> 0.51133536 | D8: =$C$1+GAP!$K$9 -> 15000 | J8: 1 | K8: Chai PET B1 | L8: ='[3]4. 3 Trạm'!$T334 -> 0.49706416 | M8: =$L$1+GAP!$K$9 -> 15000 | S8: 1 | T8: Chai PET B1 | U8: ='[3]4. 3 Trạm'!$U334 -> 0.50434739 | V8: =$U$1+GAP!$K$9 -> 15000 | AB8: 1 | AC8: Chai PET B1 | AD8: ='[3]4. 3 Trạm'!$V334 -> 0.51736865 | AE8: =$AD$1+GAP!$K$9 -> 16300
A9: 5 | B9: Chai PET B2.2 | C9: ='[3]4. 3 Trạm'!$S335 -> 0.064970641 | D9: =$C$1+GAP!$K$11 -> 13500 | J9: 5 | K9: Chai PET B2.2 | L9: ='[3]4. 3 Trạm'!$T335 -> 0.058399137 | M9: =$L$1+GAP!$K$11 -> 13500 | S9: 5 | T9: Chai PET B2.2 | U9: ='[3]4. 3 Trạm'!$U335 -> 0.055507957 | V9: =$U$1+GAP!$K$11 -> 13500 | AB9: 5 | AC9: Chai PET B2.2 | AD9: ='[3]4. 3 Trạm'!$V335 -> 0.044495104 | AE9: =$AD$1+GAP!$K$11 -> 14800
A10: 7 | B10: Chai PET B4 | C10: ='[3]4. 3 Trạm'!$S337 -> 0.015890206 | D10: =$C$1+GAP!$K$10 -> 12000 | J10: 7 | K10: Chai PET B4 | L10: ='[3]4. 3 Trạm'!$T337 -> 0.016398176 | M10: =$L$1+GAP!$K$10 -> 12000 | S10: 7 | T10: Chai PET B4 | U10: ='[3]4. 3 Trạm'!$U337 -> 0.01571854 | V10: =$U$1+GAP!$K$10 -> 12000 | AB10: 7 | AC10: Chai PET B4 | AD10: ='[3]4. 3 Trạm'!$V337 -> 0.015093888 | AE10: =$AD$1+GAP!$K$10 -> 13300
A11: 8 | B11: Chai PET B5 | C11: ='[3]4. 3 Trạm'!$S338 -> 0.016100854 | D11: =$C$1+GAP!$K$10 -> 12000 | J11: 8 | K11: Chai PET B5 | L11: ='[3]4. 3 Trạm'!$T338 -> 0.015470359 | M11: =$L$1+GAP!$K$10 -> 12000 | S11: 8 | T11: Chai PET B5 | U11: ='[3]4. 3 Trạm'!$U338 -> 0.01547887 | V11: =$U$1+GAP!$K$10 -> 12000 | AB11: 8 | AC11: Chai PET B5 | AD11: ='[3]4. 3 Trạm'!$V338 -> 0.015516825 | AE11: =$AD$1+GAP!$K$10 -> 13300
A12: 10 | B12: Chai PET B6.2 | C12: ='[3]4. 3 Trạm'!$S336 -> 0.26768431 | D12: =$C$1+GAP!$K$11 -> 13500 | J12: 10 | K12: Chai PET B6.2 | L12: ='[3]4. 3 Trạm'!$T336 -> 0.29014887 | M12: =$L$1+GAP!$K$11 -> 13500 | S12: 10 | T12: Chai PET B6.2 | U12: ='[3]4. 3 Trạm'!$U336 -> 0.27717466 | V12: =$U$1+GAP!$K$11 -> 13500 | AB12: 10 | AC12: Chai PET B6.2 | AD12: ='[3]4. 3 Trạm'!$V336 -> 0.27679036 | AE12: =$AD$1+GAP!$K$11 -> 14800
A13: 11 | B13: Nắp HD ép, cổ chai | C13: ='[3]4. 3 Trạm'!$S339 -> 0.015679732 | D13: =$C$1+GAP!$K$12 -> 6500 | J13: 11 | K13: Nắp HD ép, cổ chai | L13: ='[3]4. 3 Trạm'!$T339 -> 0.018909499 | M13: =$L$1+GAP!$K$12 -> 6500 | S13: 11 | T13: Nắp HD ép, cổ chai | U13: ='[3]4. 3 Trạm'!$U339 -> 0.018094122 | V13: =$U$1+GAP!$K$12 -> 6500 | AB13: 11 | AC13: Nắp HD ép, cổ chai | AD13: ='[3]4. 3 Trạm'!$V339 -> 0.023950693 | AE13: =$AD$1+GAP!$K$12 -> 7800
A14: 12 | B14: Phó sản | C14: ='[3]4. 3 Trạm'!$S341 -> 0.003848365 | D14: =$C$1+GAP!$K$15 -> 2000 | J14: 12 | K14: Phó sản | L14: ='[3]4. 3 Trạm'!$T341 -> 0.0040771834 | M14: =$L$1+GAP!$K$15 -> 2000 | S14: 12 | T14: Phó sản | U14: ='[3]4. 3 Trạm'!$U341 -> 0.0076438512 | V14: =$U$1+GAP!$K$15 -> 2000 | AB14: 12 | AC14: Phó sản | AD14: ='[3]4. 3 Trạm'!$V341 -> 0.0042130059 | AE14: =$AD$1+GAP!$K$15 -> 3300
A15: 13 | B15: Hao hụt | C15: ='[3]4. 3 Trạm'!$S$342 -> 0.10316976 | D15: =C15*$C$1 -> 1031.6976 | J15: 13 | K15: Hao hụt | L15: ='[3]4. 3 Trạm'!$S$342 -> 0.10316976 | M15: =L15*$L$1 -> 1031.6976 | S15: 13 | T15: Hao hụt | U15: ='[3]4. 3 Trạm'!$S$342 -> 0.10316976 | V15: =U15*$U$1 -> 1031.6976 | AB15: 13 | AC15: Hao hụt | AD15: ='[3]4. 3 Trạm'!$S$342 -> 0.10316976 | AE15: =AD15*$AD$1 -> 1165.8183
E17: Tháng 1 | N17: Tháng 2 | W17: Tháng 3 | AF17: Tháng 4
C18: Cơ cấu thành phẩm theo BOM | D18: CL | E18: ĐG | F18: SL | G18: TH SL | H18: GT | L18: Cơ cấu thành phẩm theo BOM | M18: CL | N18: ĐG | O18: SL | P18: TH SL | Q18: GT | U18: Cơ cấu thành phẩm theo BOM | V18: CL | W18: ĐG | X18: SL | Y18: TH SL | Z18: GT | AD18: Cơ cấu thành phẩm theo BOM | AE18: CL | AF18: ĐG | AG18: SL | AH18: TH SL | AI18: GT
A19: 1 | B19: Chai PET B1 | C19: 0.54 | D19: =C8-C19 -> -0.028664637 | E19: =D8*D19 -> -429.96956 | F19: ='[3]4. 3 Trạm'!S89 -> 467032 | G19: =F19*D19 -> -13387.303 | H19: =D8*G19 -> -2.0080954e+08 | J19: 1 | K19: Chai PET B1 | L19: 0.54 | M19: =L8-L19 -> -0.042935837 | N19: =M8*M19 -> -644.03755 | O19: ='[3]4. 3 Trạm'!T89 -> 299036 | P19: =O19*M19 -> -12839.361 | Q19: =M8*P19 -> -1.9259041e+08 | S19: 1 | T19: Chai PET B1 | U19: 0.54 | V19: =U8-U19 -> -0.035652613 | W19: =V8*V19 -> -534.78919 | X19: ='[3]4. 3 Trạm'!U89 -> 848224 | Y19: =X19*V19 -> -30241.402 | Z19: =V8*Y19 -> -4.5362103e+08 | AB19: 1 | AC19: Chai PET B1 | AD19: 0.54 | AE19: =AD8-AD19 -> -0.022631351 | AF19: =AE8*AE19 -> -368.89102 | AG19: ='[3]4. 3 Trạm'!V89 -> 446897 | AH19: =AG19*AE19 -> -10113.883 | AI19: =AE8*AH19 -> -1.6485629e+08
A20: 5 | B20: Chai PET B2.2 | C20: 0.03 | D20: =C9-C20 -> 0.034970641 | E20: =D9*D20 -> 472.10366 | F20: ='[3]4. 3 Trạm'!S90 -> 45769 | G20: =F20*D20 -> 1600.5713 | H20: =D9*G20 -> 21607712 | J20: 5 | K20: Chai PET B2.2 | L20: 0.03 | M20: =L9-L20 -> 0.028399137 | N20: =M9*M20 -> 383.38835 | O20: ='[3]4. 3 Trạm'!T90 -> 23322 | P20: =O20*M20 -> 662.32467 | Q20: =M9*P20 -> 8941383 | S20: 5 | T20: Chai PET B2.2 | U20: 0.03 | V20: =U9-U20 -> 0.025507957 | W20: =V9*V20 -> 344.35742 | X20: ='[3]4. 3 Trạm'!U90 -> 88500 | Y20: =X20*V20 -> 2257.4542 | Z20: =V9*Y20 -> 30475632 | AB20: 5 | AC20: Chai PET B2.2 | AD20: 0.03 | AE20: =AD9-AD20 -> 0.014495104 | AF20: =AE9*AE20 -> 214.52754 | AG20: ='[3]4. 3 Trạm'!V90 -> 31654 | AH20: =AG20*AE20 -> 458.82802 | AI20: =AE9*AH20 -> 6790654.6
A21: 7 | B21: Chai PET B4 | C21: 0.02 | D21: =C10-C21 -> -0.0041097939 | E21: =D10*D21 -> -49.317527 | F21: ='[3]4. 3 Trạm'!S92 -> 14995 | G21: =F21*D21 -> -61.626359 | H21: =D10*G21 -> -739516.31 | J21: 7 | K21: Chai PET B4 | L21: 0.02 | M21: =L10-L21 -> -0.0036018237 | N21: =M10*M21 -> -43.221884 | O21: ='[3]4. 3 Trạm'!T92 -> 10167 | P21: =O21*M21 -> -36.619741 | Q21: =M10*P21 -> -439436.9 | S21: 7 | T21: Chai PET B4 | U21: 0.02 | V21: =U10-U21 -> -0.0042814599 | W21: =V10*V21 -> -51.377518 | X21: ='[3]4. 3 Trạm'!U92 -> 28617 | Y21: =X21*V21 -> -122.52254 | Z21: =V10*Y21 -> -1470270.4 | AB21: 7 | AC21: Chai PET B4 | AD21: 0.02 | AE21: =AD10-AD21 -> -0.0049061125 | AF21: =AE10*AE21 -> -65.251296 | AG21: ='[3]4. 3 Trạm'!V92 -> 14779 | AH21: =AG21*AE21 -> -72.507437 | AI21: =AE10*AH21 -> -964348.91
A22: 8 | B22: Chai PET B5 | C22: 0.02 | D22: =C11-C22 -> -0.0038991456 | E22: =D11*D22 -> -46.789747 | F22: ='[3]4. 3 Trạm'!S93 -> 12807 | G22: =F22*D22 -> -49.936358 | H22: =D11*G22 -> -599236.3 | J22: 8 | K22: Chai PET B5 | L22: 0.02 | M22: =L11-L22 -> -0.0045296408 | N22: =M11*M22 -> -54.355689 | O22: ='[3]4. 3 Trạm'!T93 -> 8490 | P22: =O22*M22 -> -38.45665 | Q22: =M11*P22 -> -461479.8 | S22: 8 | T22: Chai PET B5 | U22: 0.02 | V22: =U11-U22 -> -0.0045211303 | W22: =V11*V22 -> -54.253563 | X22: ='[3]4. 3 Trạm'!U93 -> 22312 | Y22: =X22*V22 -> -100.87546 | Z22: =V11*Y22 -> -1210505.5 | AB22: 8 | AC22: Chai PET B5 | AD22: 0.02 | AE22: =AD11-AD22 -> -0.0044831751 | AF22: =AE11*AE22 -> -59.626229 | AG22: ='[3]4. 3 Trạm'!V93 -> 12733 | AH22: =AG22*AE22 -> -57.084269 | AI22: =AE11*AH22 -> -759220.78
A23: 10 | B23: Chai PET B6.2 | C23: 0.28 | D23: =C12-C23 -> -0.012315686 | E23: =D12*D23 -> -166.26176 | F23: ='[3]4. 3 Trạm'!S91 -> 275166 | G23: =F23*D23 -> -3388.8579 | H23: =D12*G23 -> -45749582 | J23: 10 | K23: Chai PET B6.2 | L23: 0.28 | M23: =L12-L23 -> 0.010148872 | N23: =M12*M23 -> 137.00977 | O23: ='[3]4. 3 Trạm'!T91 -> 202466 | P23: =O23*M23 -> 2054.8016 | Q23: =M12*P23 -> 27739821 | S23: 10 | T23: Chai PET B6.2 | U23: 0.28 | V23: =U12-U23 -> -0.0028253375 | W23: =V12*V23 -> -38.142056 | X23: ='[3]4. 3 Trạm'!U91 -> 526884 | Y23: =X23*V23 -> -1488.6251 | Z23: =V12*Y23 -> -20096439 | AB23: 10 | AC23: Chai PET B6.2 | AD23: 0.28 | AE23: =AD12-AD23 -> -0.0032096362 | AF23: =AE12*AE23 -> -47.502615 | AG23: ='[3]4. 3 Trạm'!V91 -> 278043 | AH23: =AG23*AE23 -> -892.41687 | AI23: =AE12*AH23 -> -13207770
A24: 11 | B24: Nắp HD ép, cổ chai | C24: 0.01 | D24: =C13-C24 -> 0.0056797323 | E24: =D13*D24 -> 36.91826 | F24: ='[3]4. 3 Trạm'!S94 -> 13231 | G24: =F24*D24 -> 75.148538 | H24: =D13*G24 -> 488465.5 | J24: 11 | K24: Nắp HD ép, cổ chai | L24: 0.01 | M24: =L13-L24 -> 0.0089094987 | N24: =M13*M24 -> 57.911741 | O24: ='[3]4. 3 Trạm'!T94 -> 9601 | P24: =O24*M24 -> 85.540097 | Q24: =M13*P24 -> 556010.63 | S24: 11 | T24: Nắp HD ép, cổ chai | U24: 0.01 | V24: =U13-U24 -> 0.0080941222 | W24: =V13*V24 -> 52.611794 | X24: ='[3]4. 3 Trạm'!U94 -> 28372 | Y24: =X24*V24 -> 229.64644 | Z24: =V13*Y24 -> 1492701.8 | AB24: 11 | AC24: Nắp HD ép, cổ chai | AD24: 0.01 | AE24: =AD13-AD24 -> 0.013950693 | AF24: =AE13*AE24 -> 108.81541 | AG24: ='[3]4. 3 Trạm'!V94 -> 21393 | AH24: =AG24*AE24 -> 298.44718 | AI24: =AE13*AH24 -> 2327888
A25: 12 | B25: Phó sản | C25: 0 | D25: =C14-C25 -> 0.003848365 | E25: =D14*D25 -> 7.69673 | F25: ='[3]4. 3 Trạm'!S95 -> 0 | G25: =F25*D25 -> 0 | H25: =D14*G25 -> 0 | J25: 12 | K25: Phó sản | L25: 0 | M25: =L14-L25 -> 0.0040771834 | N25: =M14*M25 -> 8.1543667 | O25: ='[3]4. 3 Trạm'!T95 -> 0 | P25: =O25*M25 -> 0 | Q25: =M14*P25 -> 0 | S25: 12 | T25: Phó sản | U25: 0 | V25: =U14-U25 -> 0.0076438512 | W25: =V14*V25 -> 15.287702 | X25: ='[3]4. 3 Trạm'!U95 -> 0 | Y25: =X25*V25 -> 0 | Z25: =V14*Y25 -> 0 | AB25: 12 | AC25: Phó sản | AD25: 0 | AE25: =AD14-AD25 -> 0.0042130059 | AF25: =AE14*AE25 -> 13.90292 | AG25: ='[3]4. 3 Trạm'!V95 -> 200.611 | AH25: =AG25*AE25 -> 0.84517533 | AI25: =AE14*AH25 -> 2789.0786
A26: 13 | B26: Hao hụt | C26: 0.1 | D26: =C15-C26 -> 0.0031697636 | E26: =D26*C1 -> 31.697636 | F26: ='[3]4. 3 Trạm'!S97 -> 117019 | G26: =-F26*D26 -> -370.92256 | H26: =$C$1*G26 -> -3709225.6 | J26: 13 | K26: Hao hụt | L26: 0.1 | M26: =L15-L26 -> 0.0031697636 | N26: =M26*L1 -> 31.697636 | O26: ='[3]4. 3 Trạm'!T97 -> 77982 | P26: =-O26*M26 -> -247.1845 | Q26: =$L$1*P26 -> -2471845 | S26: 13 | T26: Hao hụt | U26: 0.1 | V26: =U15-U26 -> 0.0031697636 | W26: =V26*U1 -> 31.697636 | X26: ='[3]4. 3 Trạm'!U97 -> 205626 | Y26: =-X26*V26 -> -651.7858 | Z26: =$U$1*Y26 -> -6517858 | AB26: 13 | AC26: Hao hụt | AD26: 0.1 | AE26: =AD15-AD26 -> 0.0031697636 | AF26: =AE26*AD1 -> 35.818328 | AG26: ='[3]4. 3 Trạm'!V97 -> 92319.389 | AH26: =-AG26*AE26 -> -292.63064 | AI26: =$AD$1*AH26 -> -3306726.2
F27: =SUM(F19:F26) -> 946019 | G27: =SUM(G19:G26) -> -15582.926 | H27: =SUM(H19:H26) -> -2.2951093e+08 | O27: =SUM(O19:O26) -> 631064 | P27: =SUM(P19:P26) -> -10358.955 | Q27: =SUM(Q19:Q26) -> -1.5872596e+08 | X27: =SUM(X19:X26) -> 1748535 | Y27: =SUM(Y19:Y26) -> -30118.11 | Z27: =SUM(Z19:Z26) -> -4.5094777e+08 | AG27: =SUM(AG19:AG26) -> 898019 | AH27: =SUM(AH19:AH26) -> -10670.402 | AI27: =SUM(AI19:AI26) -> -1.7397303e+08
H28: =H27/F27 -> -242.6071 | Q28: =Q27/O27 -> -251.52118 | Z28: =Z27/X27 -> -257.90034 | AI28: =AI27/AG27 -> -193.72978

Sheet Giá mua Chai-Vảy
A2: 2026
A3: 3
B6: Giá chai B0 | C6: 11300
B7: Chi phí phân loại | C7: 3000
B8: Tỷ lệ hao hụt thực tế | C8: 0.1
B9: Tổng chi phí | C9: =SUM(C6:C7) -> 14300
B10: Chi phí hao hụt | C10: =C9*C8/(1-C8) -> 1588.8889
B11: Giá bán hòa vốn đơn vị | C11: =+C9/(1-C8) -> 15888.889 | X11: So giá mua BO
B12: Chai | S12: Check với SAP | V12: TT | W12: BOM | X12: TT | Y12: BOM
A13: STT | B13: Tên vật tư | C13: Cơ cấu thành phẩm theo BOM | E13: Giá bán chai 3 trạm về DTR | F13: Cơ cấu nguyên vật liệu BOM (gram) | G13: Cơ cấu thành phẩm thực tế | H13: Tỷ trọng giá trị | I13: Phân bổ giá B0 | J13: Phân bổ chi phí phân loại | K13: Chi phí sau phân loại | L13: Doanh thu đơn vị | M13: Lợi nhuận đơn vị | N13: Giá thành 1kg sau phân loại | O13: Giá bán chai 4 trạm về DTR | P13: Diff | R13: Giá BO sau phân loại | S13: BOM SAP | T13: Diff | U13: %Diff | V13: Tỷ 3 cấp chất lượng | W13: Tỷ 3 cấp chất lượng | X13: Tỷ 3 cấp chất lượng | Y13: Tỷ 3 cấp chất lượng | Z13: Cơ cấu giá trừ chất lượng | AA13: GAP so BO | AC13: Giá mua theo phân loại | AD13: Chi phí Băm Vảy | AE13: Vảy
A14: 1 | B14: Chai PET B1 | C14: 0.54 | E14: 16300 | F14: =C14*1000 -> 540 | G14: =F14/1000/(1-$C$8) -> 0.6 | H14: =E14*G14/SUMPRODUCT($E$14:$E$20,$G$14:$G$20) -> 0.63543171 | I14: =$C$6*H14 -> 7180.3783 | J14: =($C$7+$C$10)*H14 -> 2915.9255 | K14: =I14+J14 -> 10096.304 | L14: =E14*G14 -> 9780 | M14: =L14-K14 -> -316.30378 | N14: =K14/(F14/(1-$C$8))*1000 -> 16827.173 | O14: 15000 | P14: =O14-N14 -> -1827.173 | Q14: =P14/E14 -> -0.1120965 | R14: =I14/F14*1000 -> 13296.997 | S14: ='[4]BOM (Long)'!$P$7 -> 11536.632 | T14: =R14-S14 -> 1760.365 | U14: =T14/S14 -> 0.15258917 | V14: =R14/R$16 -> 1.2255639 | W14: =S14/S$16 -> 1.25 | X14: =S14/C$6 -> 1.0209409 | Y14: =S14/C$6 -> 1.0209409 | Z14: 9700 | AC14: 12500 | AE14: =AC14+AD14 -> 12500
A15: 5 | B15: Chai PET B2.2 | C15: 0.03 | E15: 14800 | F15: =C15*1000 -> 30 | G15: =F15/1000/(1-$C$8) -> 0.033333333 | H15: =E15*G15/SUMPRODUCT($E$14:$E$20,$G$14:$G$20) -> 0.032053133 | I15: =$C$6*H15 -> 362.2004 | J15: =($C$7+$C$10)*H15 -> 147.08827 | K15: =I15+J15 -> 509.28867 | L15: =E15*G15 -> 493.33333 | M15: =L15-K15 -> -15.955337 | N15: =K15/(F15/(1-$C$8))*1000 -> 15278.66 | O15: 13500 | P15: =O15-N15 -> -1778.6601 | Q15: =P15/E15 -> -0.12017974 | R15: =I15/F15*1000 -> 12073.347 | S15: ='[4]BOM (Long)'!$P$9 -> 10152.236 | T15: =R15-S15 -> 1921.1108 | U15: =T15/S15 -> 0.18923032 | V15: =R15/R$16 -> 1.112782 | W15: =S15/S$16 -> 1.1 | X15: =S15/C$6 -> 0.89842796 | Y15: =S15/C$6 -> 0.89842796 | Z15: =Z14/$Y$15 -> 10796.636 | AA15: =Z15-$Z$14 -> 1096.6364 | AB15: =Z15-Z14 -> 1096.6364 | AC15: 10000
A16: 7 | B16: Chai PET B4 | C16: 0.02 | E16: 13300 | F16: =C16*1000 -> 20 | G16: =F16/1000/(1-$C$8) -> 0.022222222 | H16: =E16*G16/SUMPRODUCT($E$14:$E$20,$G$14:$G$20) -> 0.019203003 | I16: =$C$6*H16 -> 216.99394 | J16: =($C$7+$C$10)*H16 -> 88.120448 | K16: =I16+J16 -> 305.11438 | L16: =E16*G16 -> 295.55556 | M16: =L16-K16 -> -9.5588282 | N16: =K16/(F16/(1-$C$8))*1000 -> 13730.147 | O16: 12000 | P16: =O16-N16 -> -1730.1473 | Q16: =P16/E16 -> -0.13008626 | R16: =I16/F16*1000 -> 10849.697 | S16: ='[4]BOM (Long)'!$P$10 -> 9229.3054 | T16: =R16-S16 -> 1620.3914 | U16: =T16/S16 -> 0.17557024 | V16: =R16/R$16 -> 1 | W16: =S16/S$16 -> 1 | X16: =S16/C$6 -> 0.81675269 | Y16: =S16/C$6 -> 0.81675269 | Z16: =Z15/$Y$15 -> 12017.253 | AA16: =Z16-$Z$14 -> 2317.2533 | AB16: =Z16-Z15 -> 1220.6169 | AC16: 9000
A17: 8 | B17: Chai PET B5 | C17: 0.02 | E17: 13300 | F17: =C17*1000 -> 20 | G17: =F17/1000/(1-$C$8) -> 0.022222222 | H17: =E17*G17/SUMPRODUCT($E$14:$E$20,$G$14:$G$20) -> 0.019203003 | I17: =$C$6*H17 -> 216.99394 | J17: =($C$7+$C$10)*H17 -> 88.120448 | K17: =I17+J17 -> 305.11438 | L17: =E17*G17 -> 295.55556 | M17: =L17-K17 -> -9.5588282 | N17: =K17/(F17/(1-$C$8))*1000 -> 13730.147 | O17: 12000 | P17: =O17-N17 -> -1730.1473 | Q17: =P17/E17 -> -0.13008626 | R17: =I17/F17*1000 -> 10849.697 | S17: ='[4]BOM (Long)'!$P$11 -> 9229.3054 | T17: =R17-S17 -> 1620.3914 | U17: =T17/S17 -> 0.17557024 | V17: =R17/R$16 -> 1 | W17: =S17/S$16 -> 1 | X17: =S17/C$6 -> 0.81675269 | Y17: =S17/C$6 -> 0.81675269 | Z17: =Z16/$Y$15 -> 13375.867 | AA17: =Z17-$Z$14 -> 3675.8674 | AB17: =Z17-Z16 -> 1358.6141 | AC17: 9000
A18: 10 | B18: Chai PET B6.2 | C18: 0.27 | E18: 14800 | F18: =C18*1000 -> 270 | G18: =F18/1000/(1-$C$8) -> 0.3 | H18: =E18*G18/SUMPRODUCT($E$14:$E$20,$G$14:$G$20) -> 0.2884782 | I18: =$C$6*H18 -> 3259.8036 | J18: =($C$7+$C$10)*H18 -> 1323.7944 | K18: =I18+J18 -> 4583.598 | L18: =E18*G18 -> 4440 | M18: =L18-K18 -> -143.59804 | N18: =K18/(F18/(1-$C$8))*1000 -> 15278.66 | O18: 13500 | P18: =O18-N18 -> -1778.6601 | Q18: =P18/E18 -> -0.12017974 | R18: =I18/F18*1000 -> 12073.347 | S18: ='[4]BOM (Long)'!$P$13 -> 10152.236 | T18: =R18-S18 -> 1921.1108 | U18: =T18/S18 -> 0.18923032 | V18: =R18/R$16 -> 1.112782 | W18: =S18/S$16 -> 1.1 | X18: =S18/C$6 -> 0.89842796 | Y18: =S18/C$6 -> 0.89842796 | Z18: =Z17/$Y$15 -> 14888.08 | AA18: =Z18-$Z$14 -> 5188.08 | AB18: =Z18-Z17 -> 1512.2126 | AC18: 10000 | AD18: ='[5]CP Công đoạn (3)'!$CJ$6 -> 2321.031 | AE18: =AC18+AD18 -> 12321.031
A19: 11 | B19: Nắp HD ép, cổ chai | C19: 0.01 | E19: 7800 | F19: =C19*1000 -> 10 | G19: =F19/1000/(1-$C$8) -> 0.011111111 | H19: =E19*G19/SUMPRODUCT($E$14:$E$20,$G$14:$G$20) -> 0.0056309558 | I19: =$C$6*H19 -> 63.629801 | J19: =($C$7+$C$10)*H19 -> 25.839831 | K19: =I19+J19 -> 89.469631 | L19: =E19*G19 -> 86.666667 | M19: =L19-K19 -> -2.8029647 | N19: =K19/(F19/(1-$C$8))*1000 -> 8052.2668 | O19: 6500 | P19: =O19-N19 -> -1552.2668 | Q19: =P19/E19 -> -0.19900857 | R19: =I19/F19*1000 -> 6362.9801 | S19: ='[4]BOM (Long)'!$P$14 -> 5537.5833 | T19: =R19-S19 -> 825.39682 | U19: =T19/S19 -> 0.14905362 | V19: =R19/R$16 -> 0.58646617 | W19: =S19/S$16 -> 0.6 | X19: =S19/C$6 -> 0.49005162 | Y19: =S19/C$6 -> 0.49005162 | Z19: =Z18/$Y$15 -> 16571.256 | AA19: =Z19-$Z$14 -> 6871.2563 | AB19: =Z19-Z18 -> 1683.1763 | AC19: 5000
F20: =C20*1000 -> 0 | G20: =F20/1000/(1-$C$8) -> 0 | H20: =E20*G20/SUMPRODUCT($E$14:$E$20,$G$14:$G$20) -> 0 | I20: =$C$6*H20 -> 0 | J20: =($C$7+$C$10)*H20 -> 0 | K20: =I20+J20 -> 0 | L20: =E20*G20 -> 0 | M20: =L20-K20 -> 0 | N20: =K20/(F20/(1-$C$8))*1000 -> #DIV/0! | P20: =O20-N20 -> #DIV/0! | Q20: =P20/E20 -> #DIV/0!
B21: Thành phẩm thu được sau lựa | C21: =SUM(C14:C20) -> 0.89 | E21: =E14-E18 -> 1500 | F21: =SUM(F14:F20) -> 890 | G21: =SUM(G14:G20) -> 0.98888889 | H21: =SUM(H14:H20) -> 1 | I21: =SUM(I14:I20) -> 11300 | J21: =SUM(J14:J20) -> 4588.8889 | K21: =SUM(K14:K20) -> 15888.889 | L21: =SUM(L14:L20) -> 15391.111 | M21: =SUM(M14:M20) -> -497.77778 | N21: =SUMPRODUCT(C14:C19,N14:N19) -> 14300 | P21: =O21-N21 -> -14300
B22: Hao hụt (%) | C22: =100%-C21 -> 0.11 | E22: =E21/E14 -> 0.09202454 | N22: =K21-N21 -> 1588.8889 | P22: =O22-N22 -> -1588.8889
B23: Hao hụt (gram_BOM) | F23: =1000-F21 -> 110
B26: Giá chai BX mix sau phân loại | C26: =C11 -> 15888.889
B27: Chi phí rữa | C27: 1500
B28: Tỷ lệ hao hụt thực tế | C28: 0.06
B29: Tổng chi phí | C29: =SUM(C26:C27) -> 17388.889
B30: Chi phí hao hụt | C30: =C29*C28/(1-C28) -> 1109.9291
B31: Giá bán hòa vốn đơn vị | C31: =+C29/(1-C28) -> 18498.818
X32: So giá mua BO
B33: Vảy | S33: Check với SAP | V33: TT | W33: BOM | X33: TT | Y33: BOM
A34: STT | B34: Tên vật tư | C34: Cơ cấu thành phẩm theo BOM | E34: Giá bán thành chai trước băm | F34: Cơ cấu nguyên vật liệu BOM (gram) | G34: Cơ cấu thành phẩm thực tế | H34: Tỷ trọng giá trị | I34: Phân bổ giá chai băm | J34: Chi phí băm | K34: Giá thành sau băm | L34: Doanh thu đơn vị | M34: Lợi nhuận đơn vị | N34: Giá thành 1kg sau Băm | O34: Giá bán vảy 3 trạm về DTR | P34: Diff | R34: Giá BO sau phân loại | S34: BOM SAP | T34: Diff | U34: %Diff | V34: Tỷ 3 cấp chất lượng | W34: Tỷ 3 cấp chất lượng | X34: Tỷ 3 cấp chất lượng | Y34: Tỷ 3 cấp chất lượng | Z34: Cơ cấu giá trừ chất lượng | AA34: GAP so BO
A35: 1 | B35: Vảy_ Chai PET B1 | C35: 0.54 | E35: =N14 -> 16827.173 | F35: =C35*1000 -> 540 | G35: =F35/1000/(1-$C$28) -> 0.57446809 | H35: =E35*G35/SUMPRODUCT($E$35:$E$40,$G$35:$G$40) -> 0.63543171 | I35: =$C$26*H35 -> 10096.304 | J35: =($C$27+$C$30)*H35 -> 1658.4317 | K35: =I35+J35 -> 11754.735 | L35: =O35 -> 18300 | M35: =L35-N35 -> -2161.9469 | N35: =K35/(F35/(1-$C$28))*1000 -> 20461.947 | O35: 18300 | P35: =O35-N35 -> -2161.9469 | Q35: =P35/E35 -> -0.12847951 | R35: =I35/F35*1000 -> 18696.859 | S35: ='[4]BOM (Long)'!$P$7 -> 11536.632 | T35: =R35-S35 -> 7160.2271 | U35: =T35/S35 -> 0.62065144 | V35: =R35/R$16 -> 1.723261 | W35: =S35/S$16 -> 1.25 | X35: =S35/C$6 -> 1.0209409 | Y35: =S35/C$6 -> 1.0209409 | Z35: 9700
A36: 5 | B36: Vảy_Chai PET B2.2 | C36: 0.03 | E36: =N15 -> 15278.66 | F36: =C36*1000 -> 30 | G36: =F36/1000/(1-$C$28) -> 0.031914894 | H36: =E36*G36/SUMPRODUCT($E$35:$E$40,$G$35:$G$40) -> 0.032053133 | I36: =$C$26*H36 -> 509.28867 | J36: =($C$27+$C$30)*H36 -> 83.656404 | K36: =I36+J36 -> 592.94507 | L36: =O36 -> 16800 | M36: =L36-N36 -> -1778.9457 | N36: =K36/(F36/(1-$C$28))*1000 -> 18578.946 | O36: =O35-1500 -> 16800 | P36: =O36-N36 -> -1778.9457 | Q36: =P36/E36 -> -0.11643336 | R36: =I36/F36*1000 -> 16976.289 | S36: ='[4]BOM (Long)'!$P$9 -> 10152.236 | T36: =R36-S36 -> 6824.0531 | U36: =T36/S36 -> 0.67217242 | V36: =R36/R$16 -> 1.5646787 | W36: =S36/S$16 -> 1.1 | X36: =S36/C$6 -> 0.89842796 | Y36: =S36/C$6 -> 0.89842796 | Z36: =Z35/$Y$15 -> 10796.636 | AA36: =Z36-$Z$14 -> 1096.6364 | AB36: =Z36-Z35 -> 1096.6364
A37: 7 | B37: Vảy_Chai PET B4 | C37: 0.02 | E37: =N16 -> 13730.147 | F37: =C37*1000 -> 20 | G37: =F37/1000/(1-$C$28) -> 0.021276596 | H37: =E37*G37/SUMPRODUCT($E$35:$E$40,$G$35:$G$40) -> 0.019203003 | I37: =$C$26*H37 -> 305.11438 | J37: =($C$27+$C$30)*H37 -> 50.118476 | K37: =I37+J37 -> 355.23286 | L37: =O37 -> 15300 | M37: =L37-N37 -> -1395.9444 | N37: =K37/(F37/(1-$C$28))*1000 -> 16695.944 | O37: =O35-3000 -> 15300 | P37: =O37-N37 -> -1395.9444 | Q37: =P37/E37 -> -0.10167003 | R37: =I37/F37*1000 -> 15255.719 | S37: ='[4]BOM (Long)'!$P$10 -> 9229.3054 | T37: =R37-S37 -> 6026.4138 | U37: =T37/S37 -> 0.65296504 | V37: =R37/R$16 -> 1.4060964 | W37: =S37/S$16 -> 1 | X37: =S37/C$6 -> 0.81675269 | Y37: =S37/C$6 -> 0.81675269 | Z37: =Z36/$Y$15 -> 12017.253 | AA37: =Z37-$Z$14 -> 2317.2533 | AB37: =Z37-Z36 -> 1220.6169
A38: 8 | B38: Vảy_Chai PET B5 | C38: 0.02 | E38: =N17 -> 13730.147 | F38: =C38*1000 -> 20 | G38: =F38/1000/(1-$C$28) -> 0.021276596 | H38: =E38*G38/SUMPRODUCT($E$35:$E$40,$G$35:$G$40) -> 0.019203003 | I38: =$C$26*H38 -> 305.11438 | J38: =($C$27+$C$30)*H38 -> 50.118476 | K38: =I38+J38 -> 355.23286 | L38: =O38 -> 15300 | M38: =L38-N38 -> -1395.9444 | N38: =K38/(F38/(1-$C$28))*1000 -> 16695.944 | O38: =O37 -> 15300 | P38: =O38-N38 -> -1395.9444 | Q38: =P38/E38 -> -0.10167003 | R38: =I38/F38*1000 -> 15255.719 | S38: ='[4]BOM (Long)'!$P$11 -> 9229.3054 | T38: =R38-S38 -> 6026.4138 | U38: =T38/S38 -> 0.65296504 | V38: =R38/R$16 -> 1.4060964 | W38: =S38/S$16 -> 1 | X38: =S38/C$6 -> 0.81675269 | Y38: =S38/C$6 -> 0.81675269 | Z38: =Z37/$Y$15 -> 13375.867 | AA38: =Z38-$Z$14 -> 3675.8674 | AB38: =Z38-Z37 -> 1358.6141
A39: 10 | B39: Vảy_Chai PET B6.2 | C39: 0.27 | E39: =N18 -> 15278.66 | F39: =C39*1000 -> 270 | G39: =F39/1000/(1-$C$28) -> 0.28723404 | H39: =E39*G39/SUMPRODUCT($E$35:$E$40,$G$35:$G$40) -> 0.2884782 | I39: =$C$26*H39 -> 4583.598 | J39: =($C$27+$C$30)*H39 -> 752.90764 | K39: =I39+J39 -> 5336.5057 | L39: =O39 -> 17800 | M39: =L39-N39 -> -778.94568 | N39: =K39/(F39/(1-$C$28))*1000 -> 18578.946 | O39: 17800 | P39: =O39-N39 -> -778.94568 | Q39: =P39/E39 -> -0.050982591 | R39: =I39/F39*1000 -> 16976.289 | S39: ='[4]BOM (Long)'!$P$13 -> 10152.236 | T39: =R39-S39 -> 6824.0531 | U39: =T39/S39 -> 0.67217242 | V39: =R39/R$16 -> 1.5646787 | W39: =S39/S$16 -> 1.1 | X39: =S39/C$6 -> 0.89842796 | Y39: =S39/C$6 -> 0.89842796 | Z39: =Z38/$Y$15 -> 14888.08 | AA39: =Z39-$Z$14 -> 5188.08 | AB39: =Z39-Z38 -> 1512.2126
A40: 11 | B40: Vảy_Nắp HD ép, cổ chai | C40: 0.01 | E40: =N19 -> 8052.2668 | F40: =C40*1000 -> 10 | G40: =F40/1000/(1-$C$28) -> 0.010638298 | H40: =E40*G40/SUMPRODUCT($E$35:$E$40,$G$35:$G$40) -> 0.0056309558 | I40: =$C$26*H40 -> 89.469631 | J40: =($C$27+$C$30)*H40 -> 14.696395 | K40: =I40+J40 -> 104.16603 | L40: =O40 -> 12550 | M40: =L40-N40 -> 2758.3935 | N40: =K40/(F40/(1-$C$28))*1000 -> 9791.6065 | O40: =C6+1250 -> 12550 | P40: =O40-N40 -> 2758.3935 | Q40: =P40/E40 -> 0.34256111 | R40: =I40/F40*1000 -> 8946.9631 | S40: ='[4]BOM (Long)'!$P$14 -> 5537.5833 | T40: =R40-S40 -> 3409.3799 | U40: =T40/S40 -> 0.61568011 | V40: =R40/R$16 -> 0.82462794 | W40: =S40/S$16 -> 0.6 | X40: =S40/C$6 -> 0.49005162 | Y40: =S40/C$6 -> 0.49005162 | Z40: =Z39/$Y$15 -> 16571.256 | AA40: =Z40-$Z$14 -> 6871.2563 | AB40: =Z40-Z39 -> 1683.1763
F41: =C41*1000 -> 0 | G41: =F41/1000/(1-$C$8) -> 0 | H41: =E41*G41/SUMPRODUCT($E$14:$E$20,$G$14:$G$20) -> 0 | I41: =$C$6*H41 -> 0 | J41: =($C$7+$C$10)*H41 -> 0 | K41: =I41+J41 -> 0 | L41: =E41*G41 -> 0 | M41: =L41-K41 -> 0 | N41: =K41/(F41/(1-$C$8))*1000 -> #DIV/0! | P41: =O41-N41 -> #DIV/0! | Q41: =P41/E41 -> #DIV/0!
B42: Thành phẩm thu được sau lựa | C42: =SUM(C35:C41) -> 0.89 | F42: =SUM(F35:F41) -> 890 | G42: =SUM(G35:G41) -> 0.94680851 | H42: =SUM(H35:H41) -> 1 | I42: =SUM(I35:I41) -> 15888.889 | J42: =SUM(J35:J41) -> 2609.9291 | K42: =SUM(K35:K41) -> 18498.818 | L42: =SUMPRODUCT(C35:C40,L35:L40) -> 15929.5 | M42: =SUM(M35:M41) -> -4753.3337
B43: Hao hụt (%) | C43: =100%-C42 -> 0.11
B44: Hao hụt (gram_BOM) | F44: =1000-F42 -> 110

Sheet Giá mua Chai-Vảy (Giá giảm)
A2: 2026
A3: 4
B6: Giá chai B0 | C6: 11300
B7: Chi phí phân loại | C7: 3000
B8: Tỷ lệ hao hụt thực tế | C8: 0.1
B9: Tổng chi phí | C9: =SUM(C6:C7) -> 14300
B10: Chi phí hao hụt | C10: =C9*C8/(1-C8) -> 1588.8889
B11: Giá bán hòa vốn đơn vị | C11: =+C9/(1-C8) -> 15888.889 | X11: So giá mua BO
B12: Chai | E12: 0 | S12: Check với SAP | V12: TT | W12: BOM | X12: TT | Y12: BOM
A13: STT | B13: Tên vật tư | C13: Cơ cấu thành phẩm theo BOM | E13: Giá bán chai 3 trạm về DTR | F13: Cơ cấu nguyên vật liệu BOM (gram) | G13: Cơ cấu thành phẩm thực tế | H13: Tỷ trọng giá trị | I13: Phân bổ giá B0 | J13: Phân bổ chi phí phân loại | K13: Chi phí sau phân loại | L13: Doanh thu đơn vị | M13: Lợi nhuận đơn vị | N13: Giá thành 1kg sau phân loại | O13: Giá bán chai 3 trạm về DTR | P13: Diff | R13: Giá BO sau phân loại | S13: BOM SAP | T13: Diff | U13: %Diff | V13: Tỷ 3 cấp chất lượng | W13: Tỷ 3 cấp chất lượng | X13: Tỷ 3 cấp chất lượng | Y13: Tỷ 3 cấp chất lượng | Z13: Cơ cấu giá trừ chất lượng | AA13: GAP so BO | AC13: Giá mua theo phân loại | AD13: Chi phí Băm Vảy | AE13: Vảy
A14: 1 | B14: Chai PET B1 | C14: 0.53 | E14: ='Giá mua Chai-Vảy'!E14-$E$12 -> 16300 | F14: =C14*1000 -> 530 | G14: =F14/1000/(1-$C$8) -> 0.58888889 | H14: =E14*G14/SUMPRODUCT($E$14:$E$20,$G$14:$G$20) -> 0.61465671 | I14: =$C$6*H14 -> 6945.6208 | J14: =($C$7+$C$10)*H14 -> 2820.5913 | K14: =I14+J14 -> 9766.2121 | L14: =E14*G14 -> 9598.8889 | M14: =L14-K14 -> -167.32321 | N14: =K14/(F14/(1-$C$8))*1000 -> 16584.134 | O14: 16300 | P14: =O14-N14 -> -284.13376 | Q14: =P14/E14 -> -0.017431519 | R14: =I14/F14*1000 -> 13104.945 | S14: ='[4]BOM (Long)'!$P$7 -> 11536.632 | T14: =R14-S14 -> 1568.3131 | U14: =T14/S14 -> 0.13594202 | V14: =R14/R$16 -> 1.2255639 | W14: =S14/S$16 -> 1.25 | X14: =S14/C$6 -> 1.0209409 | Y14: =S14/C$6 -> 1.0209409 | Z14: 9700 | AC14: 12500 | AE14: =AC14+AD14 -> 12500
A15: 5 | B15: Chai PET B2.2 | C15: 0.03 | E15: ='Giá mua Chai-Vảy'!E15-$E$12 -> 14800 | F15: =C15*1000 -> 30 | G15: =F15/1000/(1-$C$8) -> 0.033333333 | H15: =E15*G15/SUMPRODUCT($E$14:$E$20,$G$14:$G$20) -> 0.031590181 | I15: =$C$6*H15 -> 356.96905 | J15: =($C$7+$C$10)*H15 -> 144.96383 | K15: =I15+J15 -> 501.93288 | L15: =E15*G15 -> 493.33333 | M15: =L15-K15 -> -8.5995494 | N15: =K15/(F15/(1-$C$8))*1000 -> 15057.986 | O15: 14800 | P15: =O15-N15 -> -257.98648 | Q15: =P15/E15 -> -0.017431519 | R15: =I15/F15*1000 -> 11898.968 | S15: ='[4]BOM (Long)'!$P$9 -> 10152.236 | T15: =R15-S15 -> 1746.7324 | U15: =T15/S15 -> 0.17205396 | V15: =R15/R$16 -> 1.112782 | W15: =S15/S$16 -> 1.1 | X15: =S15/C$6 -> 0.89842796 | Y15: =S15/C$6 -> 0.89842796 | Z15: =Z14/$Y$15 -> 10796.636 | AA15: =Z15-$Z$14 -> 1096.6364 | AB15: =Z15-Z14 -> 1096.6364 | AC15: 10000
A16: 7 | B16: Chai PET B4 | C16: 0.02 | E16: ='Giá mua Chai-Vảy'!E16-$E$12 -> 13300 | F16: =C16*1000 -> 20 | G16: =F16/1000/(1-$C$8) -> 0.022222222 | H16: =E16*G16/SUMPRODUCT($E$14:$E$20,$G$14:$G$20) -> 0.018925649 | I16: =$C$6*H16 -> 213.85984 | J16: =($C$7+$C$10)*H16 -> 86.847701 | K16: =I16+J16 -> 300.70754 | L16: =E16*G16 -> 295.55556 | M16: =L16-K16 -> -5.1519823 | N16: =K16/(F16/(1-$C$8))*1000 -> 13531.839 | O16: 13300 | P16: =O16-N16 -> -231.8392 | Q16: =P16/E16 -> -0.017431519 | R16: =I16/F16*1000 -> 10692.992 | S16: ='[4]BOM (Long)'!$P$10 -> 9229.3054 | T16: =R16-S16 -> 1463.6864 | U16: =T16/S16 -> 0.15859118 | V16: =R16/R$16 -> 1 | W16: =S16/S$16 -> 1 | X16: =S16/C$6 -> 0.81675269 | Y16: =S16/C$6 -> 0.81675269 | Z16: =Z15/$Y$15 -> 12017.253 | AA16: =Z16-$Z$14 -> 2317.2533 | AB16: =Z16-Z15 -> 1220.6169 | AC16: 9000
A17: 8 | B17: Chai PET B5 | C17: 0.02 | E17: ='Giá mua Chai-Vảy'!E17-$E$12 -> 13300 | F17: =C17*1000 -> 20 | G17: =F17/1000/(1-$C$8) -> 0.022222222 | H17: =E17*G17/SUMPRODUCT($E$14:$E$20,$G$14:$G$20) -> 0.018925649 | I17: =$C$6*H17 -> 213.85984 | J17: =($C$7+$C$10)*H17 -> 86.847701 | K17: =I17+J17 -> 300.70754 | L17: =E17*G17 -> 295.55556 | M17: =L17-K17 -> -5.1519823 | N17: =K17/(F17/(1-$C$8))*1000 -> 13531.839 | O17: 13300 | P17: =O17-N17 -> -231.8392 | Q17: =P17/E17 -> -0.017431519 | R17: =I17/F17*1000 -> 10692.992 | S17: ='[4]BOM (Long)'!$P$11 -> 9229.3054 | T17: =R17-S17 -> 1463.6864 | U17: =T17/S17 -> 0.15859118 | V17: =R17/R$16 -> 1 | W17: =S17/S$16 -> 1 | X17: =S17/C$6 -> 0.81675269 | Y17: =S17/C$6 -> 0.81675269 | Z17: =Z16/$Y$15 -> 13375.867 | AA17: =Z17-$Z$14 -> 3675.8674 | AB17: =Z17-Z16 -> 1358.6141 | AC17: 9000
A18: 10 | B18: Chai PET B6.2 | C18: 0.3 | E18: ='Giá mua Chai-Vảy'!E18-$E$12 -> 14800 | F18: =C18*1000 -> 300 | G18: =F18/1000/(1-$C$8) -> 0.33333333 | H18: =E18*G18/SUMPRODUCT($E$14:$E$20,$G$14:$G$20) -> 0.31590181 | I18: =$C$6*H18 -> 3569.6905 | J18: =($C$7+$C$10)*H18 -> 1449.6383 | K18: =I18+J18 -> 5019.3288 | L18: =E18*G18 -> 4933.3333 | M18: =L18-K18 -> -85.995494 | N18: =K18/(F18/(1-$C$8))*1000 -> 15057.986 | O18: 14800 | P18: =O18-N18 -> -257.98648 | Q18: =P18/E18 -> -0.017431519 | R18: =I18/F18*1000 -> 11898.968 | S18: ='[4]BOM (Long)'!$P$13 -> 10152.236 | T18: =R18-S18 -> 1746.7324 | U18: =T18/S18 -> 0.17205396 | V18: =R18/R$16 -> 1.112782 | W18: =S18/S$16 -> 1.1 | X18: =S18/C$6 -> 0.89842796 | Y18: =S18/C$6 -> 0.89842796 | Z18: =Z17/$Y$15 -> 14888.08 | AA18: =Z18-$Z$14 -> 5188.08 | AB18: =Z18-Z17 -> 1512.2126 | AC18: 10000 | AD18: ='[5]CP Công đoạn (3)'!$CJ$6 -> 2321.031 | AE18: =AC18+AD18 -> 12321.031
A19: 11 | B19: Nắp HD ép, cổ chai | E19: ='Giá mua Chai-Vảy'!E19-$E$12 -> 7800 | F19: =C19*1000 -> 0 | G19: =F19/1000/(1-$C$8) -> 0 | H19: =E19*G19/SUMPRODUCT($E$14:$E$20,$G$14:$G$20) -> 0 | I19: =$C$6*H19 -> 0 | J19: =($C$7+$C$10)*H19 -> 0 | K19: =I19+J19 -> 0 | L19: =E19*G19 -> 0 | M19: =L19-K19 -> 0 | N19: =K19/(F19/(1-$C$8))*1000 -> #DIV/0! | O19: 7800 | P19: =O19-N19 -> #DIV/0! | Q19: =P19/E19 -> #DIV/0! | R19: =I19/F19*1000 -> #DIV/0! | S19: ='[4]BOM (Long)'!$P$14 -> 5537.5833 | T19: =R19-S19 -> #DIV/0! | U19: =T19/S19 -> #DIV/0! | V19: =R19/R$16 -> #DIV/0! | W19: =S19/S$16 -> 0.6 | X19: =S19/C$6 -> 0.49005162 | Y19: =S19/C$6 -> 0.49005162 | Z19: =Z18/$Y$15 -> 16571.256 | AA19: =Z19-$Z$14 -> 6871.2563 | AB19: =Z19-Z18 -> 1683.1763 | AC19: 5000
F20: =C20*1000 -> 0 | G20: =F20/1000/(1-$C$8) -> 0 | H20: =E20*G20/SUMPRODUCT($E$14:$E$20,$G$14:$G$20) -> 0 | I20: =$C$6*H20 -> 0 | J20: =($C$7+$C$10)*H20 -> 0 | K20: =I20+J20 -> 0 | L20: =E20*G20 -> 0 | M20: =L20-K20 -> 0 | N20: =K20/(F20/(1-$C$8))*1000 -> #DIV/0! | P20: =O20-N20 -> #DIV/0! | Q20: =P20/E20 -> #DIV/0!
B21: Thành phẩm thu được sau lựa | C21: =SUM(C14:C20) -> 0.9 | F21: =SUM(F14:F20) -> 900 | G21: =SUM(G14:G20) -> 1 | H21: =SUM(H14:H20) -> 1 | I21: =SUM(I14:I20) -> 11300 | J21: =SUM(J14:J20) -> 4588.8889 | K21: =SUM(K14:K20) -> 15888.889 | L21: =SUM(L14:L20) -> 15616.667 | M21: =SUM(M14:M20) -> -272.22222 | N21: =SUMPRODUCT(C14:C18,N14:N18) -> 14300 | O21: =AVERAGE(O14:O18) -> 14500 | R21: =SUMPRODUCT(F14:F18,R14:R18) -> 11300000
B22: Hao hụt (%) | C22: =100%-C21 -> 0.1 | I22: =C10/J21 -> 0.34624697 | J22: =C7/J21 -> 0.65375303 | K22: HH B0 | L22: CF SX | N22: =K21-N21 -> 1588.8889 | O22: =SUMPRODUCT(C14:C18,O14:O18) -> 14055
B23: Hao hụt (gram_BOM) | F23: =1000-F21 -> 100 | I23: =I14/$K14 -> 0.71118881 | J23: =J14/$K14 -> 0.28881119 | K23: =J23*I22 -> 0.1 | L23: =J23*J22 -> 0.18881119 | N23: =K14/$K14 -> 1
I24: =$N14*I$23 -> 11794.45 | J24: =$N14*J$23 -> 4789.6834 | K24: =$N14*K$23 -> 1658.4134 | L24: =$N14*L$23 -> 3131.27 | N24: =$N14*N$23 -> 16584.134
I25: =$N15*I$23 -> 10709.072 | J25: =$N15*J$23 -> 4348.915 | K25: =$N15*K$23 -> 1505.7986 | L25: =$N15*L$23 -> 2843.1163 | N25: =$N15*N$23 -> 15057.986
B26: Giá chai BX mix sau phân loại | C26: =C11 -> 15888.889 | I26: =$N16*I$23 -> 9623.6926 | J26: =$N16*J$23 -> 3908.1466 | K26: =$N16*K$23 -> 1353.1839 | L26: =$N16*L$23 -> 2554.9626 | N26: =$N16*N$23 -> 13531.839
B27: Chi phí phân loại | C27: 1500 | I27: =$N17*I$23 -> 9623.6926 | J27: =$N17*J$23 -> 3908.1466 | K27: =$N17*K$23 -> 1353.1839 | L27: =$N17*L$23 -> 2554.9626 | N27: =$N17*N$23 -> 13531.839
B28: Tỷ lệ hao hụt thực tế | C28: 0.06 | I28: =$N18*I$23 -> 10709.072 | J28: =$N18*J$23 -> 4348.915 | K28: =$N18*K$23 -> 1505.7986 | L28: =$N18*L$23 -> 2843.1163 | N28: =$N18*N$23 -> 15057.986
B29: Tổng chi phí | C29: =SUM(C26:C27) -> 17388.889
B30: Chi phí hao hụt | C30: =C29*C28/(1-C28) -> 1109.9291
B31: Giá bán hòa vốn đơn vị | C31: =+C29/(1-C28) -> 18498.818
X32: So giá mua BO
B33: Vảy | S33: Check với SAP | V33: TT | W33: BOM | X33: TT | Y33: BOM
A34: STT | B34: Tên vật tư | C34: Cơ cấu thành phẩm theo BOM | E34: Giá bán thành chai trước băm | F34: Cơ cấu nguyên vật liệu BOM (gram) | G34: Cơ cấu thành phẩm thực tế | H34: Tỷ trọng giá trị | I34: Phân bổ giá chai băm | J34: Chi phí băm | K34: Giá thành sau băm | L34: Doanh thu đơn vị | M34: Lợi nhuận đơn vị | N34: Giá thành 1kg sau Băm | O34: Giá bán vảy 3 trạm về DTR | P34: Diff | R34: Giá BO sau phân loại | S34: BOM SAP | T34: Diff | U34: %Diff | V34: Tỷ 3 cấp chất lượng | W34: Tỷ 3 cấp chất lượng | X34: Tỷ 3 cấp chất lượng | Y34: Tỷ 3 cấp chất lượng | Z34: Cơ cấu giá trừ chất lượng | AA34: GAP so BO
A35: 1 | B35: Vảy_ Chai PET B1 | C35: 0.54 | E35: =N14 -> 16584.134 | F35: =C35*1000 -> 540 | G35: =F35/1000/(1-$C$28) -> 0.57446809 | H35: =E35*G35/SUMPRODUCT($E$35:$E$40,$G$35:$G$40) -> #DIV/0! | I35: =$C$26*H35 -> #DIV/0! | J35: =$C$27+$C$30 -> 2609.9291 | K35: =N14+J35 -> 19194.063 | L35: =O35 -> 19300 | M35: =L35-K35 -> 105.93716 | N35: =K35 -> 19194.063 | O35: =O14+3000 -> 19300 | P35: =O35-N35 -> 105.93716 | Q35: =P35/E35 -> 0.0063878622 | R35: =I35/F35*1000 -> #DIV/0! | S35: ='[4]BOM (Long)'!$P$7 -> 11536.632 | T35: =R35-S35 -> #DIV/0! | U35: =T35/S35 -> #DIV/0! | V35: =R35/R$16 -> #DIV/0! | W35: =S35/S$16 -> 1.25 | X35: =S35/C$6 -> 1.0209409 | Y35: =S35/C$6 -> 1.0209409 | Z35: 9700
A36: 5 | B36: Vảy_Chai PET B2.2 | C36: 0.03 | E36: =N15 -> 15057.986 | F36: =C36*1000 -> 30 | G36: =F36/1000/(1-$C$28) -> 0.031914894 | H36: =E36*G36/SUMPRODUCT($E$35:$E$40,$G$35:$G$40) -> #DIV/0! | I36: =$C$26*H36 -> #DIV/0! | J36: =$C$27+$C$30 -> 2609.9291 | K36: =N15+J36 -> 17667.916 | L36: =O36 -> 17800 | M36: =L36-K36 -> 132.08444 | N36: =K36 -> 17667.916 | O36: =O15+3000 -> 17800 | P36: =O36-N36 -> 132.08444 | Q36: =P36/E36 -> 0.0087717199 | R36: =I36/F36*1000 -> #DIV/0! | S36: ='[4]BOM (Long)'!$P$9 -> 10152.236 | T36: =R36-S36 -> #DIV/0! | U36: =T36/S36 -> #DIV/0! | V36: =R36/R$16 -> #DIV/0! | W36: =S36/S$16 -> 1.1 | X36: =S36/C$6 -> 0.89842796 | Y36: =S36/C$6 -> 0.89842796 | Z36: =Z35/$Y$15 -> 10796.636 | AA36: =Z36-$Z$14 -> 1096.6364 | AB36: =Z36-Z35 -> 1096.6364
A37: 7 | B37: Vảy_Chai PET B4 | C37: 0.02 | E37: =N16 -> 13531.839 | F37: =C37*1000 -> 20 | G37: =F37/1000/(1-$C$28) -> 0.021276596 | H37: =E37*G37/SUMPRODUCT($E$35:$E$40,$G$35:$G$40) -> #DIV/0! | I37: =$C$26*H37 -> #DIV/0! | J37: =$C$27+$C$30 -> 2609.9291 | K37: =N16+J37 -> 16141.768 | L37: =O37 -> 16300 | M37: =L37-K37 -> 158.23172 | N37: =K37 -> 16141.768 | O37: =O16+3000 -> 16300 | P37: =O37-N37 -> 158.23172 | Q37: =P37/E37 -> 0.01169329 | R37: =I37/F37*1000 -> #DIV/0! | S37: ='[4]BOM (Long)'!$P$10 -> 9229.3054 | T37: =R37-S37 -> #DIV/0! | U37: =T37/S37 -> #DIV/0! | V37: =R37/R$16 -> #DIV/0! | W37: =S37/S$16 -> 1 | X37: =S37/C$6 -> 0.81675269 | Y37: =S37/C$6 -> 0.81675269 | Z37: =Z36/$Y$15 -> 12017.253 | AA37: =Z37-$Z$14 -> 2317.2533 | AB37: =Z37-Z36 -> 1220.6169
A38: 8 | B38: Vảy_Chai PET B5 | C38: 0.02 | E38: =N17 -> 13531.839 | F38: =C38*1000 -> 20 | G38: =F38/1000/(1-$C$28) -> 0.021276596 | H38: =E38*G38/SUMPRODUCT($E$35:$E$40,$G$35:$G$40) -> #DIV/0! | I38: =$C$26*H38 -> #DIV/0! | J38: =$C$27+$C$30 -> 2609.9291 | K38: =N17+J38 -> 16141.768 | L38: =O38 -> 16300 | M38: =L38-K38 -> 158.23172 | N38: =K38 -> 16141.768 | O38: =O17+3000 -> 16300 | P38: =O38-N38 -> 158.23172 | Q38: =P38/E38 -> 0.01169329 | R38: =I38/F38*1000 -> #DIV/0! | S38: ='[4]BOM (Long)'!$P$11 -> 9229.3054 | T38: =R38-S38 -> #DIV/0! | U38: =T38/S38 -> #DIV/0! | V38: =R38/R$16 -> #DIV/0! | W38: =S38/S$16 -> 1 | X38: =S38/C$6 -> 0.81675269 | Y38: =S38/C$6 -> 0.81675269 | Z38: =Z37/$Y$15 -> 13375.867 | AA38: =Z38-$Z$14 -> 3675.8674 | AB38: =Z38-Z37 -> 1358.6141
A39: 10 | B39: Vảy_Chai PET B6.2 | C39: 0.27 | E39: =N18 -> 15057.986 | F39: =C39*1000 -> 270 | G39: =F39/1000/(1-$C$28) -> 0.28723404 | H39: =E39*G39/SUMPRODUCT($E$35:$E$40,$G$35:$G$40) -> #DIV/0! | I39: =$C$26*H39 -> #DIV/0! | J39: =$C$27+$C$30 -> 2609.9291 | K39: =N18+J39 -> 17667.916 | L39: =O39 -> 17800 | M39: =L39-K39 -> 132.08444 | N39: =K39 -> 17667.916 | O39: =O18+3000 -> 17800 | P39: =O39-N39 -> 132.08444 | Q39: =P39/E39 -> 0.0087717199 | R39: =I39/F39*1000 -> #DIV/0! | S39: ='[4]BOM (Long)'!$P$13 -> 10152.236 | T39: =R39-S39 -> #DIV/0! | U39: =T39/S39 -> #DIV/0! | V39: =R39/R$16 -> #DIV/0! | W39: =S39/S$16 -> 1.1 | X39: =S39/C$6 -> 0.89842796 | Y39: =S39/C$6 -> 0.89842796 | Z39: =Z38/$Y$15 -> 14888.08 | AA39: =Z39-$Z$14 -> 5188.08 | AB39: =Z39-Z38 -> 1512.2126
A40: 11 | B40: Vảy_Nắp HD ép, cổ chai | C40: 0.01 | E40: =N19 -> #DIV/0! | F40: =C40*1000 -> 10 | G40: =F40/1000/(1-$C$28) -> 0.010638298 | H40: =E40*G40/SUMPRODUCT($E$35:$E$40,$G$35:$G$40) -> #DIV/0! | I40: =$C$26*H40 -> #DIV/0! | J40: =$C$27+$C$30 -> 2609.9291 | K40: =N19+J40 -> #DIV/0! | L40: =O40 -> 10800 | M40: =L40-K40 -> #DIV/0! | N40: =K40 -> #DIV/0! | O40: =O19+3000 -> 10800 | P40: =O40-N40 -> #DIV/0! | Q40: =P40/E40 -> #DIV/0! | R40: =I40/F40*1000 -> #DIV/0! | S40: ='[4]BOM (Long)'!$P$14 -> 5537.5833 | T40: =R40-S40 -> #DIV/0! | U40: =T40/S40 -> #DIV/0! | V40: =R40/R$16 -> #DIV/0! | W40: =S40/S$16 -> 0.6 | X40: =S40/C$6 -> 0.49005162 | Y40: =S40/C$6 -> 0.49005162 | Z40: =Z39/$Y$15 -> 16571.256 | AA40: =Z40-$Z$14 -> 6871.2563 | AB40: =Z40-Z39 -> 1683.1763
F41: =C41*1000 -> 0 | G41: =F41/1000/(1-$C$8) -> 0 | H41: =E41*G41/SUMPRODUCT($E$14:$E$20,$G$14:$G$20) -> 0 | I41: =$C$6*H41 -> 0 | J41: =($C$7+$C$10)*H41 -> 0 | K41: =I41+J41 -> 0 | L41: =E41*G41 -> 0 | M41: =L41-K41 -> 0 | N41: =K41/(F41/(1-$C$8))*1000 -> #DIV/0! | P41: =O41-N41 -> #DIV/0! | Q41: =P41/E41 -> #DIV/0!
B42: Thành phẩm thu được sau lựa | C42: =SUM(C35:C41) -> 0.89 | F42: =SUM(F35:F41) -> 890 | G42: =SUM(G35:G41) -> 0.94680851 | H42: =SUM(H35:H41) -> #DIV/0! | I42: =SUM(I35:I41) -> #DIV/0! | J42: =SUM(J35:J41) -> 15659.574 | K42: =SUM(K35:K41) -> #DIV/0! | L42: =SUM(L35:L41) -> 98300 | M42: =SUM(M35:M41) -> #DIV/0!
B43: Hao hụt (%) | C43: =100%-C42 -> 0.11
...

Sheet Hiệu suất
B3: Giá mua chai B0 | C3: CF PL | D3: Chai Sau PL | J3: Vảy chưa rữa (HSTH và GT)-Băm | T3: Vảy sau rữa (HSTH và GT) -Rữa | AD3: Tạo hạt_CF Nhựa
B4: 11300 | C4: 3000 | D4: Tỷ lệ HH Mua B0 | E4: Chai B 1 | F4: Chai B2.2 | G4: Chai B4 | H4: Chai B5 | I4: Chai B6.2 | J4: Chai B 1 | L4: Chai B2.2 | N4: Chai B4 | P4: Chai B5 | R4: Chai B6.2 | T4: Chai B 1 | V4: Chai B2.2 | X4: Chai B4 | Z4: Chai B5 | AB4: Chai B6.2 | AD4: Công thức sản xuất | AI4: Hạt rPET iSS01084G | AK4: Hạt rPET iSS01G | AM4: Hạt rPET WSS01G | AO4: Hạt rPET WSS03G | AQ4: Hạt WSS03NC | AS4: Hạt WSS04NC | AU4: Hạt WSS04SB | AW4: Hạt WSS05SB (sợi ngắn)
