Workbook
Name EXR: EXR!$D$3
Name EXR_FC01: EXR!$B$7
Name EXR_FC02: EXR!$C$7
Name EXR_FC03: EXR!$D$7
Name EXR_FC04: EXR!$E$7
Name EXR_FC05: EXR!$F$7
Name EXR_FC06: EXR!$G$7
Name EXR_FC07: EXR!$H$7
Name EXR_FC08: EXR!$I$8
Name EXR_FC09: EXR!$J$8
Name EXR_FC10: EXR!$K$8
Name EXR_FC11: EXR!$L$8
Name EXR_FC12: EXR!$M$8

Sheet Working-T05-B2
P1: cthuc | Q1: cthuc | AJ1: cthuc | AM1: =AM2/26.2 -> 1165.5195 | AZ1: SUNTORY/NIAGARA
L2: =L3-SUM(Sales!G3:H100) -> 0 | N2: =N3-SUM(Sales!$I$3:$I$100) -> 0 | AM2: =AM3/S3 -> 30536.611 | BK2: =BK3/AM3 -> 0.14811753
K3: =SUBTOTAL(9,K8:K150) -> 2477774 | L3: =SUBTOTAL(9,L8:L150) -> 30800 | N3: =SUBTOTAL(9,N8:N150) -> 5449793.7 | P3: =SUBTOTAL(9,P8:P150) -> 0 | Q3: =SUBTOTAL(9,Q8:Q150) -> 1461441.8 | R3: =SUBTOTAL(9,R8:R150) -> 4019151.9 | S3: =SUBTOTAL(9,S8:S150) -> 5480593.7 | U3: 1.10125 | AJ3: =SUBTOTAL(9,AJ8:AJ150) -> 0 | AK3: =SUBTOTAL(9,AK8:AK150) -> 3.6353097e+10 | AL3: =SUBTOTAL(9,AL8:AL150) -> 1.3100566e+11 | AM3: =SUBTOTAL(9,AM8:AM150) -> 1.6735876e+11 | AQ3: =SUBTOTAL(9,AQ8:AQ150) -> 0 | AR3: =SUBTOTAL(9,AR8:AR150) -> 5.0898471e+08 | AS3: =SUBTOTAL(9,AS8:AS150) -> 1.6552662e+09 | AT3: =SUBTOTAL(9,AT8:AT150) -> 2.1642509e+09 | AX3: =SUBTOTAL(9,AX8:AX150) -> 0 | AY3: =SUBTOTAL(9,AY8:AY150) -> 212136320 | AZ3: =SUBTOTAL(9,AZ8:AZ150) -> 2.2469285e+09 | BA3: =SUBTOTAL(9,BA8:BA150) -> 2.4590648e+09 | BC3: =SUBTOTAL(9,BC8:BC150) -> 0 | BD3: =SUBTOTAL(9,BD8:BD150) -> 3.7989844e+10 | BE3: =SUBTOTAL(9,BE8:BE150) -> 1.0458015e+11 | BF3: =SUBTOTAL(9,BF8:BF150) -> 1.4256999e+11 | BH3: =SUBTOTAL(9,BH8:BH150) -> 0 | BI3: =SUBTOTAL(9,BI8:BI150) -> -1.6367468e+09 | BJ3: =SUBTOTAL(9,BJ8:BJ150) -> 2.6425513e+10 | BK3: =SUBTOTAL(9,BK8:BK150) -> 2.4788767e+10 | BM3: =SUBTOTAL(9,BM8:BM150) -> 1.4091985e+11 | BN3: =SUBTOTAL(9,BN8:BN150) -> 1.0085096e+11 | BO3: =SUBTOTAL(9,BO8:BO150) -> 1.3550527e+09 | BP3: =SUBTOTAL(9,BP8:BP150) -> 3.1187799e+08 | BQ3: =SUBTOTAL(9,BQ8:BQ150) -> 6.2427281e+09 | BR3: =SUBTOTAL(9,BR8:BR150) -> 8.9941607e+08 | BS3: =SUBTOTAL(9,BS8:BS150) -> 4.9100642e+09 | BT3: =SUBTOTAL(9,BT8:BT150) -> 7.3587196e+09 | ... BV3: =SUBTOTAL(9,BV8:BV150) -> 1.7193314e+10
A4: LINK | B4: SOURCE | C4: Kênh | D4: Mã khách | Mã SKU | E4: Mã khách | F4: Tên khách | G4: Mã SKU | H4: Tên SKU | K4: SỐ LƯỢNG SO CÒN GIAO ĐẦU T05 | L4: SALES | M4: CÒN LẠI | N4: SALES | P4: THÁNG 05
L5: Đã có PO | N5: Chưa có PO | P5: SẢN LƯỢNG | U5: GIÁ BÁN THEO HĐ | Z5: TỶ GIÁ | AE5: GIÁ BÁN (VND/kg) | AJ5: DOANH THU (VND) | AO5: CP VC (VND) | AV5: CP Hoa hồng (VND) | BC5: GIÁ VỐN (VND) | BH5: LÃI GỘP KẾ TOÁN (VND) | BM5: GIÁ VỐN-BREAKDOWN | BW5: Check
P6: SO+Hóa đơn | Q6: SO+Chưa hóa đơn | R6: Dự báo | S6: Tổng | T6: Check | U6: SO+Hóa đơn | V6: SO+Chưa hóa đơn | W6: Dự báo | X6: TB | Z6: SO+Hóa đơn | AA6: SO+Chưa hóa đơn | AB6: Dự báo | AC6: TB | AE6: SO+Hóa đơn | AF6: SO+Chưa hóa đơn | AG6: Dự báo | AH6: TB | AJ6: SO+Hóa đơn | AK6: SO+Chưa hóa đơn | AL6: Dự báo | AM6: TỔNG | AO6: ĐG | AQ6: SO+Hóa đơn | AR6: SO+Chưa hóa đơn | AS6: Dự báo | AT6: Tổng | AV6: ĐG | AX6: SO+Hóa đơn | AY6: SO+Chưa hóa đơn | AZ6: Dự báo | BA6: Tổng | BC6: SO+Hóa đơn | BD6: SO+Chưa hóa đơn | BE6: Dự báo | BF6: Tổng | BH6: SO+Hóa đơn | BI6: SO+Chưa hóa đơn | BJ6: Dự báo | BK6: Tổng | BM6: Tổng | BN6: Nhựa | BO6: Màu/hóa chất/phụ gia | BP6: Bao bì | BQ6: Điện | BR6: Gia công | BS6: NCTT | BT6: NCGT | BU6: Khấu hao máy | BV6: CP sx chung
A8: =_xlfn.XLOOKUP($G8,MD_SKU[Mã SKU],MD_SKU[Link vào file BCQT]) -> Phó sản | B8: TC-026 | C8: NĐ | D8: 105382 | 160012611 | E8: 105382 | F8: Văn Minh | G8: 160012611 | H8: Vảy HD Ép Hỗn Hợp ST | K8: =SUMIFS('Working-T05-B1'!L$8:L$150,'Working-T05-B1'!$C$8:$C$150,$D8) -> 60756 | L8: {=SUMPRODUCT(Sales!$G$3:$H$100*(Sales!$B$3:$B$100=$D8))} -> 0 | M8: =K8-L8 -> 60756 | N8: =SUMIFS(Sales!$I$3:$I$100,Sales!$B$3:$B$100,$D8) -> 0 | P8: =SUMIFS('Working-T05-B1'!O$8:O$150,'Working-T05-B1'!$C$8:$C$150,$D8) -> 0 | Q8: =MAX(0,MIN(K8,L8+N8)-P8) -> 0 | R8: =MAX(0,L8+N8-SUM(P8:Q8)) -> 0 | S8: =SUM(P8:R8) -> 0 | T8: =S8-(L8+N8) -> 0 | U8: =IFERROR(AE8/Z8,0) -> 0 | V8: =IFERROR(AF8/AA8,0) -> 0 | W8: =IF(AND(R8>0,V8>0),V8,0) -> 0 | X8: =IFERROR(IF($C8="XK",$AM8/$S8/$AC8,$AM8/$S8),0) -> 0 | AA8: =IF($C8="NĐ",1,EXR_FC05) -> 1 | AB8: =IF($C8="NĐ",1,EXR_FC05) -> 1 | AC8: =IFERROR(SUMPRODUCT(AJ8:AL8,Z8:AB8)/AM8,0) -> 0 | AE8: =IFERROR(AJ8/P8,0) -> 0 | AF8: =IFERROR(AK8/Q8,0) -> 0 | AG8: =W8*AB8 -> 0 | AJ8: =SUMIFS('Working-T05-B1'!AI$8:AI$150,'Working-T05-B1'!$C$8:$C$150,$D8) -> 0 | AK8: =SUMIFS('Working-T05-B1'!AJ$8:AJ$150,'Working-T05-B1'!$C$8:$C$150,$D8) -> 0 | AL8: =R8*AG8 -> 0 | AM8: =SUM(AJ8:AL8) -> 0 | AO8: =IFERROR(SUM(AQ8:AR8)/SUM(P8:Q8),0) -> 0 | AQ8: =SUMIFS('Working-T05-B1'!AP$8:AP$150,'Working-T05-B1'!$C$8:$C$150,$D8) -> 0 | AR8: =SUMIFS('Working-T05-B1'!AQ$8:AQ$150,'Working-T05-B1'!$C$8:$C$150,$D8) -> 0 | AS8: =AO8*R8 -> 0 | AT8: =SUM(AQ8:AS8) -> 0 | AV8: =IFERROR(BA8/S8,0) -> 0 | AX8: =SUMIFS('Working-T05-B1'!AW$8:AW$150,'Working-T05-B1'!$C$8:$C$150,$D8) -> 0 | AY8: =SUMIFS('Working-T05-B1'!AX$8:AX$150,'Working-T05-B1'!$C$8:$C$150,$D8) -> 0 | BA8: =SUM(AX8:AZ8) -> 0 | BC8: =_xlfn.XLOOKUP($G8,'GIÁ XUẤT KHO'!$A$4:$A$97,'GIÁ XUẤT KHO'!$AW$4:$AW$97)*P8 -> 0 | BD8: =_xlfn.XLOOKUP($G8,'GIÁ XUẤT KHO'!$A$4:$A$97,'GIÁ XUẤT KHO'!$AW$4:$AW$97)*Q8 -> 0 | BE8: =_xlfn.XLOOKUP($G8,'GIÁ XUẤT KHO'!$A$4:$A$97,'GIÁ XUẤT KHO'!$AW$4:$AW$97)*R8 -> 0 | BF8: =SUM(BC8:BE8) -> 0 | BH8: =AJ8-BC8 -> 0 | BI8: =AK8-BD8 -> 0 | BJ8: =AL8-BE8 -> 0 | BK8: =SUM(BH8:BJ8) -> 0 | BM8: =SUM(BN8:BV8) -> 0 | BN8: =SUMIFS('GIÁ XUẤT KHO'!AX$4:AX$97,'GIÁ XUẤT KHO'!$A$4:$A$97,$G8)*$S8 -> 0 | BO8: =SUMIFS('GIÁ XUẤT KHO'!AY$4:AY$97,'GIÁ XUẤT KHO'!$A$4:$A$97,$G8)*$S8 -> 0 | BP8: =SUMIFS('GIÁ XUẤT KHO'!AZ$4:AZ$97,'GIÁ XUẤT KHO'!$A$4:$A$97,$G8)*$S8 -> 0 | BQ8: =SUMIFS('GIÁ XUẤT KHO'!BA$4:BA$97,'GIÁ XUẤT KHO'!$A$4:$A$97,$G8)*$S8 -> 0 | BR8: =SUMIFS('GIÁ XUẤT KHO'!BB$4:BB$97,'GIÁ XUẤT KHO'!$A$4:$A$97,$G8)*$S8 -> 0 | BS8: =SUMIFS('GIÁ XUẤT KHO'!BC$4:BC$97,'GIÁ XUẤT KHO'!$A$4:$A$97,$G8)*$S8 -> 0 | BT8: =SUMIFS('GIÁ XUẤT KHO'!BD$4:BD$97,'GIÁ XUẤT KHO'!$A$4:$A$97,$G8)*$S8 -> 0 | BU8: =SUMIFS('GIÁ XUẤT KHO'!BE$4:BE$97,'GIÁ XUẤT KHO'!$A$4:$A$97,$G8)*$S8 -> 0 | BV8: =SUMIFS('GIÁ XUẤT KHO'!BF$4:BF$97,'GIÁ XUẤT KHO'!$A$4:$A$97,$G8)*$S8 -> 0 | BW8: =BM8-BF8 -> 0
A9: =_xlfn.XLOOKUP($G9,MD_SKU[Mã SKU],MD_SKU[Link vào file BCQT]) -> Vảy rHDPE ép | B9: TC-026 | C9: NĐ | D9: 105382 | 110000408 | E9: 105382 | F9: Văn Minh | G9: 110000408 | H9: Vảy HD Ép Trắng | K9: =SUMIFS('Working-T05-B1'!L$8:L$150,'Working-T05-B1'!$C$8:$C$150,$D9) -> 96000 | L9: {=SUMPRODUCT(Sales!$G$3:$H$100*(Sales!$B$3:$B$100=$D9))} -> 0 | M9: =K9-L9 -> 96000 | N9: =SUMIFS(Sales!$I$3:$I$100,Sales!$B$3:$B$100,$D9) -> 0 | P9: =SUMIFS('Working-T05-B1'!O$8:O$150,'Working-T05-B1'!$C$8:$C$150,$D9) -> 0 | Q9: =MAX(0,MIN(K9,L9+N9)-P9) -> 0 | R9: =MAX(0,L9+N9-SUM(P9:Q9)) -> 0 | S9: =SUM(P9:R9) -> 0 | T9: =S9-(L9+N9) -> 0 | U9: =IFERROR(AE9/Z9,0) -> 0 | V9: =IFERROR(AF9/AA9,0) -> 0 | W9: =IF(AND(R9>0,V9>0),V9,0) -> 0 | X9: =IFERROR(IF($C9="XK",$AM9/$S9/$AC9,$AM9/$S9),0) -> 0 | AA9: =IF($C9="NĐ",1,EXR_FC05) -> 1 | AB9: =IF($C9="NĐ",1,EXR_FC05) -> 1 | AC9: =IFERROR(SUMPRODUCT(AJ9:AL9,Z9:AB9)/AM9,0) -> 0 | AE9: =IFERROR(AJ9/P9,0) -> 0 | AF9: =IFERROR(AK9/Q9,0) -> 0 | AG9: =W9*AB9 -> 0 | AJ9: =SUMIFS('Working-T05-B1'!AI$8:AI$150,'Working-T05-B1'!$C$8:$C$150,$D9) -> 0 | AK9: =SUMIFS('Working-T05-B1'!AJ$8:AJ$150,'Working-T05-B1'!$C$8:$C$150,$D9) -> 0 | AL9: =R9*AG9 -> 0 | AM9: =SUM(AJ9:AL9) -> 0 | AO9: =IFERROR(SUM(AQ9:AR9)/SUM(P9:Q9),0) -> 0 | AQ9: =SUMIFS('Working-T05-B1'!AP$8:AP$150,'Working-T05-B1'!$C$8:$C$150,$D9) -> 0 | AR9: =SUMIFS('Working-T05-B1'!AQ$8:AQ$150,'Working-T05-B1'!$C$8:$C$150,$D9) -> 0 | AS9: =AO9*R9 -> 0 | AT9: =SUM(AQ9:AS9) -> 0 | AV9: =IFERROR(BA9/S9,0) -> 0 | AX9: =SUMIFS('Working-T05-B1'!AW$8:AW$150,'Working-T05-B1'!$C$8:$C$150,$D9) -> 0 | AY9: =SUMIFS('Working-T05-B1'!AX$8:AX$150,'Working-T05-B1'!$C$8:$C$150,$D9) -> 0 | BA9: =SUM(AX9:AZ9) -> 0 | BC9: =_xlfn.XLOOKUP($G9,'GIÁ XUẤT KHO'!$A$4:$A$97,'GIÁ XUẤT KHO'!$AW$4:$AW$97)*P9 -> 0 | BD9: =_xlfn.XLOOKUP($G9,'GIÁ XUẤT KHO'!$A$4:$A$97,'GIÁ XUẤT KHO'!$AW$4:$AW$97)*Q9 -> 0 | BE9: =_xlfn.XLOOKUP($G9,'GIÁ XUẤT KHO'!$A$4:$A$97,'GIÁ XUẤT KHO'!$AW$4:$AW$97)*R9 -> 0 | BF9: =SUM(BC9:BE9) -> 0 | BH9: =AJ9-BC9 -> 0 | BI9: =AK9-BD9 -> 0 | BJ9: =AL9-BE9 -> 0 | BK9: =SUM(BH9:BJ9) -> 0 | BM9: =SUM(BN9:BV9) -> 0 | BN9: =SUMIFS('GIÁ XUẤT KHO'!AX$4:AX$97,'GIÁ XUẤT KHO'!$A$4:$A$97,$G9)*$S9 -> 0 | BO9: =SUMIFS('GIÁ XUẤT KHO'!AY$4:AY$97,'GIÁ XUẤT KHO'!$A$4:$A$97,$G9)*$S9 -> 0 | BP9: =SUMIFS('GIÁ XUẤT KHO'!AZ$4:AZ$97,'GIÁ XUẤT KHO'!$A$4:$A$97,$G9)*$S9 -> 0 | BQ9: =SUMIFS('GIÁ XUẤT KHO'!BA$4:BA$97,'GIÁ XUẤT KHO'!$A$4:$A$97,$G9)*$S9 -> 0 | BR9: =SUMIFS('GIÁ XUẤT KHO'!BB$4:BB$97,'GIÁ XUẤT KHO'!$A$4:$A$97,$G9)*$S9 -> 0 | BS9: =SUMIFS('GIÁ XUẤT KHO'!BC$4:BC$97,'GIÁ XUẤT KHO'!$A$4:$A$97,$G9)*$S9 -> 0 | BT9: =SUMIFS('GIÁ XUẤT KHO'!BD$4:BD$97,'GIÁ XUẤT KHO'!$A$4:$A$97,$G9)*$S9 -> 0 | BU9: =SUMIFS('GIÁ XUẤT KHO'!BE$4:BE$97,'GIÁ XUẤT KHO'!$A$4:$A$97,$G9)*$S9 -> 0 | BV9: =SUMIFS('GIÁ XUẤT KHO'!BF$4:BF$97,'GIÁ XUẤT KHO'!$A$4:$A$97,$G9)*$S9 -> 0 | BW9: =BM9-BF9 -> 0
A10: =_xlfn.XLOOKUP($G10,MD_SKU[Mã SKU],MD_SKU[Link vào file BCQT]) -> Phó sản | B10: TC-026 | C10: NĐ | D10: 105405 | 160012801 | E10: 105405 | F10: Cường Gia Phát | G10: 160012801 | H10: Vảy PET GC Dây Đai | K10: =SUMIFS('Working-T05-B1'!L$8:L$150,'Working-T05-B1'!$C$8:$C$150,$D10) -> 80930 | L10: {=SUMPRODUCT(Sales!$G$3:$H$100*(Sales!$B$3:$B$100=$D10))} -> 0 | M10: =K10-L10 -> 80930 | N10: =SUMIFS(Sales!$I$3:$I$100,Sales!$B$3:$B$100,$D10) -> 100000 | P10: =SUMIFS('Working-T05-B1'!O$8:O$150,'Working-T05-B1'!$C$8:$C$150,$D10) -> 0 | Q10: =MAX(0,MIN(K10,L10+N10)-P10) -> 80930 | R10: =MAX(0,L10+N10-SUM(P10:Q10)) -> 19070 | S10: =SUM(P10:R10) -> 100000 | T10: =S10-(L10+N10) -> 0 | U10: =IFERROR(AE10/Z10,0) -> 0 | V10: =IFERROR(AF10/AA10,0) -> 12000 | W10: =IF(AND(R10>0,V10>0),V10,0) -> 12000 | X10: =IFERROR(IF($C10="XK",$AM10/$S10/$AC10,$AM10/$S10),0) -> 12000 | AA10: =IF($C10="NĐ",1,EXR_FC05) -> 1 | AB10: =IF($C10="NĐ",1,EXR_FC05) -> 1 | AC10: =IFERROR(SUMPRODUCT(AJ10:AL10,Z10:AB10)/AM10,0) -> 1 | AE10: =IFERROR(AJ10/P10,0) -> 0 | AF10: =IFERROR(AK10/Q10,0) -> 12000 | AG10: =W10*AB10 -> 12000 | AJ10: =SUMIFS('Working-T05-B1'!AI$8:AI$150,'Working-T05-B1'!$C$8:$C$150,$D10) -> 0 | AK10: =SUMIFS('Working-T05-B1'!AJ$8:AJ$150,'Working-T05-B1'!$C$8:$C$150,$D10) -> 971160000 | AL10: =R10*AG10 -> 228840000 | AM10: =SUM(AJ10:AL10) -> 1200000000 | AO10: =IFERROR(SUM(AQ10:AR10)/SUM(P10:Q10),0) -> 0 | AQ10: =SUMIFS('Working-T05-B1'!AP$8:AP$150,'Working-T05-B1'!$C$8:$C$150,$D10) -> 0 | AR10: =SUMIFS('Working-T05-B1'!AQ$8:AQ$150,'Working-T05-B1'!$C$8:$C$150,$D10) -> 0 | AS10: =AO10*R10 -> 0 | AT10: =SUM(AQ10:AS10) -> 0 | AV10: =IFERROR(BA10/S10,0) -> 0 | AX10: =SUMIFS('Working-T05-B1'!AW$8:AW$150,'Working-T05-B1'!$C$8:$C$150,$D10) -> 0 | AY10: =SUMIFS('Working-T05-B1'!AX$8:AX$150,'Working-T05-B1'!$C$8:$C$150,$D10) -> 0 | BA10: =SUM(AX10:AZ10) -> 0 | BC10: =_xlfn.XLOOKUP($G10,'GIÁ XUẤT KHO'!$A$4:$A$97,'GIÁ XUẤT KHO'!$AW$4:$AW$97)*P10 -> 0 | BD10: =_xlfn.XLOOKUP($G10,'GIÁ XUẤT KHO'!$A$4:$A$97,'GIÁ XUẤT KHO'!$AW$4:$AW$97)*Q10 -> 1.5574951e+09 | BE10: =_xlfn.XLOOKUP($G10,'GIÁ XUẤT KHO'!$A$4:$A$97,'GIÁ XUẤT KHO'!$AW$4:$AW$97)*R10 -> 3.6700149e+08 | BF10: =SUM(BC10:BE10) -> 1.9244965e+09 | BH10: =AJ10-BC10 -> 0 | BI10: =AK10-BD10 -> -5.8633506e+08 | BJ10: =AL10-BE10 -> -1.3816149e+08 | BK10: =SUM(BH10:BJ10) -> -7.2449655e+08 | BM10: =SUM(BN10:BV10) -> 1.9244965e+09 | BN10: =SUMIFS('GIÁ XUẤT KHO'!AX$4:AX$97,'GIÁ XUẤT KHO'!$A$4:$A$97,$G10)*$S10 -> 1.217176e+09 | BO10: =SUMIFS('GIÁ XUẤT KHO'!AY$4:AY$97,'GIÁ XUẤT KHO'!$A$4:$A$97,$G10)*$S10 -> 0.58393629 | BP10: =SUMIFS('GIÁ XUẤT KHO'!AZ$4:AZ$97,'GIÁ XUẤT KHO'!$A$4:$A$97,$G10)*$S10 -> 9.3429806 | BQ10: =SUMIFS('GIÁ XUẤT KHO'!BA$4:BA$97,'GIÁ XUẤT KHO'!$A$4:$A$97,$G10)*$S10 -> 72585904 | BR10: =SUMIFS('GIÁ XUẤT KHO'!BB$4:BB$97,'GIÁ XUẤT KHO'!$A$4:$A$97,$G10)*$S10 -> 0 | BS10: =SUMIFS('GIÁ XUẤT KHO'!BC$4:BC$97,'GIÁ XUẤT KHO'!$A$4:$A$97,$G10)*$S10 -> 1.4978174e+08 | BT10: =SUMIFS('GIÁ XUẤT KHO'!BD$4:BD$97,'GIÁ XUẤT KHO'!$A$4:$A$97,$G10)*$S10 -> 1.6243981e+08 | BU10: =SUMIFS('GIÁ XUẤT KHO'!BE$4:BE$97,'GIÁ XUẤT KHO'!$A$4:$A$97,$G10)*$S10 -> 15714904 | BV10: =SUMIFS('GIÁ XUẤT KHO'!BF$4:BF$97,'GIÁ XUẤT KHO'!$A$4:$A$97,$G10)*$S10 -> 3.0679813e+08 | BW10: =BM10-BF10 -> 0
A11: =_xlfn.XLOOKUP($G11,MD_SKU[Mã SKU],MD_SKU[Link vào file BCQT]) -> Hạt rPET | B11: TC-026 | C11: NĐ | D11: 104909 | 110000329 | E11: 104909 | F11: Công ty TNHH La Vie | G11: 110000329 | H11: Hạt nhựa rPET WSS01 | K11: =SUMIFS('Working-T05-B1'!L$8:L$150,'Working-T05-B1'!$C$8:$C$150,$D11) -> 230400 | L11: {=SUMPRODUCT(Sales!$G$3:$H$100*(Sales!$B$3:$B$100=$D11))} -> 30800 | M11: =K11-L11 -> 199600 | N11: =SUMIFS(Sales!$I$3:$I$100,Sales!$B$3:$B$100,$D11) -> 0 | P11: =SUMIFS('Working-T05-B1'!O$8:O$150,'Working-T05-B1'!$C$8:$C$150,$D11) -> 0 | Q11: =MAX(0,MIN(K11,L11+N11)-P11) -> 30800 | R11: =MAX(0,L11+N11-SUM(P11:Q11)) -> 0 | S11: =SUM(P11:R11) -> 30800 | T11: =S11-(L11+N11) -> 0 | U11: =IFERROR(AE11/Z11,0) -> 0 | V11: =IFERROR(AF11/AA11,0) -> 33832.83 | W11: =IF(AND(R11>0,V11>0),V11,0) -> 0 | X11: =IFERROR(IF($C11="XK",$AM11/$S11/$AC11,$AM11/$S11),0) -> 33832.83 | AA11: =IF($C11="NĐ",1,EXR_FC05) -> 1 | AB11: =IF($C11="NĐ",1,EXR_FC05) -> 1 | AC11: =IFERROR(SUMPRODUCT(AJ11:AL11,Z11:AB11)/AM11,0) -> 1 | AE11: =IFERROR(AJ11/P11,0) -> 0 | AF11: =IFERROR(AK11/Q11,0) -> 33832.83 | AG11: =W11*AB11 -> 0 | AJ11: =SUMIFS('Working-T05-B1'!AI$8:AI$150,'Working-T05-B1'!$C$8:$C$150,$D11) -> 0 | AK11: =SUMIFS('Working-T05-B1'!AJ$8:AJ$150,'Working-T05-B1'!$C$8:$C$150,$D11) -> 1042051164 | AL11: =R11*AG11 -> 0 | AM11: =SUM(AJ11:AL11) -> 1042051164 | AO11: =IFERROR(SUM(AQ11:AR11)/SUM(P11:Q11),0) -> 0 | AQ11: =SUMIFS('Working-T05-B1'!AP$8:AP$150,'Working-T05-B1'!$C$8:$C$150,$D11) -> 0 | AR11: =SUMIFS('Working-T05-B1'!AQ$8:AQ$150,'Working-T05-B1'!$C$8:$C$150,$D11) -> 0 | AS11: =AO11*R11 -> 0 | AT11: =SUM(AQ11:AS11) -> 0 | AV11: =IFERROR(BA11/S11,0) -> 0 | AX11: =SUMIFS('Working-T05-B1'!AW$8:AW$150,'Working-T05-B1'!$C$8:$C$150,$D11) -> 0 | AY11: =SUMIFS('Working-T05-B1'!AX$8:AX$150,'Working-T05-B1'!$C$8:$C$150,$D11) -> 0 | BA11: =SUM(AX11:AZ11) -> 0 | BC11: =_xlfn.XLOOKUP($G11,'GIÁ XUẤT KHO'!$A$4:$A$97,'GIÁ XUẤT KHO'!$AW$4:$AW$97)*P11 -> 0 | BD11: =_xlfn.XLOOKUP($G11,'GIÁ XUẤT KHO'!$A$4:$A$97,'GIÁ XUẤT KHO'!$AW$4:$AW$97)*Q11 -> 1.0002541e+09 | BE11: =_xlfn.XLOOKUP($G11,'GIÁ XUẤT KHO'!$A$4:$A$97,'GIÁ XUẤT KHO'!$AW$4:$AW$97)*R11 -> 0 | BF11: =SUM(BC11:BE11) -> 1.0002541e+09 | BH11: =AJ11-BC11 -> 0 | BI11: =AK11-BD11 -> 41797097 | BJ11: =AL11-BE11 -> 0 | BK11: =SUM(BH11:BJ11) -> 41797097 | BM11: =SUM(BN11:BV11) -> 1.0002541e+09 | BN11: =SUMIFS('GIÁ XUẤT KHO'!AX$4:AX$97,'GIÁ XUẤT KHO'!$A$4:$A$97,$G11)*$S11 -> 6.0211978e+08 | BO11: =SUMIFS('GIÁ XUẤT KHO'!AY$4:AY$97,'GIÁ XUẤT KHO'!$A$4:$A$97,$G11)*$S11 -> 2702006.6 | BP11: =SUMIFS('GIÁ XUẤT KHO'!AZ$4:AZ$97,'GIÁ XUẤT KHO'!$A$4:$A$97,$G11)*$S11 -> 8.6119702 | BQ11: =SUMIFS('GIÁ XUẤT KHO'!BA$4:BA$97,'GIÁ XUẤT KHO'!$A$4:$A$97,$G11)*$S11 -> 64998199 | BR11: =SUMIFS('GIÁ XUẤT KHO'!BB$4:BB$97,'GIÁ XUẤT KHO'!$A$4:$A$97,$G11)*$S11 -> 6081552.9 | BS11: =SUMIFS('GIÁ XUẤT KHO'!BC$4:BC$97,'GIÁ XUẤT KHO'!$A$4:$A$97,$G11)*$S11 -> 48034157 | BT11: =SUMIFS('GIÁ XUẤT KHO'!BD$4:BD$97,'GIÁ XUẤT KHO'!$A$4:$A$97,$G11)*$S11 -> 77478929 | BU11: =SUMIFS('GIÁ XUẤT KHO'!BE$4:BE$97,'GIÁ XUẤT KHO'!$A$4:$A$97,$G11)*$S11 -> 36355980 | BV11: =SUMIFS('GIÁ XUẤT KHO'!BF$4:BF$97,'GIÁ XUẤT KHO'!$A$4:$A$97,$G11)*$S11 -> 1.6248345e+08 | BW11: =BM11-BF11 -> 0
A12: =_xlfn.XLOOKUP($G12,MD_SKU[Mã SKU],MD_SKU[Link vào file BCQT]) -> Vảy rHDPE ép | B12: TC-026 | C12: NĐ | D12: 105324 | 110000409 | E12: 105324 | F12: NHỰA TRƯỜNG AN | G12: 110000409 | H12: Vảy HD Ép Vàng | K12: =SUMIFS('Working-T05-B1'!L$8:L$150,'Working-T05-B1'!$C$8:$C$150,$D12) -> 3000 | L12: {=SUMPRODUCT(Sales!$G$3:$H$100*(Sales!$B$3:$B$100=$D12))} -> 0 | M12: =K12-L12 -> 3000 | N12: =SUMIFS(Sales!$I$3:$I$100,Sales!$B$3:$B$100,$D12) -> 6000 | P12: =SUMIFS('Working-T05-B1'!O$8:O$150,'Working-T05-B1'!$C$8:$C$150,$D12) -> 0 | Q12: =MAX(0,MIN(K12,L12+N12)-P12) -> 3000 | R12: =MAX(0,L12+N12-SUM(P12:Q12)) -> 3000 | S12: =SUM(P12:R12) -> 6000 | T12: =S12-(L12+N12) -> 0 | U12: =IFERROR(AE12/Z12,0) -> 0 | V12: =IFERROR(AF12/AA12,0) -> 15740.741 | W12: =IF(AND(R12>0,V12>0),V12,0) -> 15740.741 | X12: =IFERROR(IF($C12="XK",$AM12/$S12/$AC12,$AM12/$S12),0) -> 15740.741 | AA12: =IF($C12="NĐ",1,EXR_FC05) -> 1 | AB12: =IF($C12="NĐ",1,EXR_FC05) -> 1 | AC12: =IFERROR(SUMPRODUCT(AJ12:AL12,Z12:AB12)/AM12,0) -> 1 | AE12: =IFERROR(AJ12/P12,0) -> 0 | AF12: =IFERROR(AK12/Q12,0) -> 15740.741 | AG12: =W12*AB12 -> 15740.741 | AJ12: =SUMIFS('Working-T05-B1'!AI$8:AI$150,'Working-T05-B1'!$C$8:$C$150,$D12) -> 0 | AK12: =SUMIFS('Working-T05-B1'!AJ$8:AJ$150,'Working-T05-B1'!$C$8:$C$150,$D12) -> 47222222 | AL12: =R12*AG12 -> 47222222 | AM12: =SUM(AJ12:AL12) -> 94444444 | AO12: =IFERROR(SUM(AQ12:AR12)/SUM(P12:Q12),0) -> 0 | AQ12: =SUMIFS('Working-T05-B1'!AP$8:AP$150,'Working-T05-B1'!$C$8:$C$150,$D12) -> 0 | AR12: =SUMIFS('Working-T05-B1'!AQ$8:AQ$150,'Working-T05-B1'!$C$8:$C$150,$D12) -> 0 | AS12: =AO12*R12 -> 0 | AT12: =SUM(AQ12:AS12) -> 0 | AV12: =IFERROR(BA12/S12,0) -> 0 | AX12: =SUMIFS('Working-T05-B1'!AW$8:AW$150,'Working-T05-B1'!$C$8:$C$150,$D12) -> 0 | AY12: =SUMIFS('Working-T05-B1'!AX$8:AX$150,'Working-T05-B1'!$C$8:$C$150,$D12) -> 0 | BA12: =SUM(AX12:AZ12) -> 0 | BC12: =_xlfn.XLOOKUP($G12,'GIÁ XUẤT KHO'!$A$4:$A$97,'GIÁ XUẤT KHO'!$AW$4:$AW$97)*P12 -> 0 | BD12: =_xlfn.XLOOKUP($G12,'GIÁ XUẤT KHO'!$A$4:$A$97,'GIÁ XUẤT KHO'!$AW$4:$AW$97)*Q12 -> 46759664 | BE12: =_xlfn.XLOOKUP($G12,'GIÁ XUẤT KHO'!$A$4:$A$97,'GIÁ XUẤT KHO'!$AW$4:$AW$97)*R12 -> 46759664 | BF12: =SUM(BC12:BE12) -> 93519328 | BH12: =AJ12-BC12 -> 0 | BI12: =AK12-BD12 -> 462558.33 | BJ12: =AL12-BE12 -> 462558.33 | BK12: =SUM(BH12:BJ12) -> 925116.66 | BM12: =SUM(BN12:BV12) -> 93519328 | BN12: =SUMIFS('GIÁ XUẤT KHO'!AX$4:AX$97,'GIÁ XUẤT KHO'!$A$4:$A$97,$G12)*$S12 -> 88163097 | BO12: =SUMIFS('GIÁ XUẤT KHO'!AY$4:AY$97,'GIÁ XUẤT KHO'!$A$4:$A$97,$G12)*$S12 -> 0.2640264 | BP12: =SUMIFS('GIÁ XUẤT KHO'!AZ$4:AZ$97,'GIÁ XUẤT KHO'!$A$4:$A$97,$G12)*$S12 -> 0 | BQ12: =SUMIFS('GIÁ XUẤT KHO'!BA$4:BA$97,'GIÁ XUẤT KHO'!$A$4:$A$97,$G12)*$S12 -> 748615.45 | BR12: =SUMIFS('GIÁ XUẤT KHO'!BB$4:BB$97,'GIÁ XUẤT KHO'!$A$4:$A$97,$G12)*$S12 -> 36585.347 | BS12: =SUMIFS('GIÁ XUẤT KHO'!BC$4:BC$97,'GIÁ XUẤT KHO'!$A$4:$A$97,$G12)*$S12 -> 1427976 | BT12: =SUMIFS('GIÁ XUẤT KHO'!BD$4:BD$97,'GIÁ XUẤT KHO'!$A$4:$A$97,$G12)*$S12 -> 1081458.5 | BU12: =SUMIFS('GIÁ XUẤT KHO'!BE$4:BE$97,'GIÁ XUẤT KHO'!$A$4:$A$97,$G12)*$S12 -> 666959.47 | BV12: =SUMIFS('GIÁ XUẤT KHO'!BF$4:BF$97,'GIÁ XUẤT KHO'!$A$4:$A$97,$G12)*$S12 -> 1394635.5 | BW12: =BM12-BF12 -> 0
A13: =_xlfn.XLOOKUP($G13,MD_SKU[Mã SKU],MD_SKU[Link vào file BCQT]) -> Vảy rHDPE ép | B13: TC-026 | C13: NĐ | D13: 105324 | 110000410 | E13: 105324 | F13: NHỰA TRƯỜNG AN | G13: 110000410 | H13: Vảy HD Ép Lá | K13: =SUMIFS('Working-T05-B1'!L$8:L$150,'Working-T05-B1'!$C$8:$C$150,$D13) -> 10500 | L13: {=SUMPRODUCT(Sales!$G$3:$H$100*(Sales!$B$3:$B$100=$D13))} -> 0 | M13: =K13-L13 -> 10500 | N13: =SUMIFS(Sales!$I$3:$I$100,Sales!$B$3:$B$100,$D13) -> 0 | P13: =SUMIFS('Working-T05-B1'!O$8:O$150,'Working-T05-B1'!$C$8:$C$150,$D13) -> 0 | Q13: =MAX(0,MIN(K13,L13+N13)-P13) -> 0 | R13: =MAX(0,L13+N13-SUM(P13:Q13)) -> 0 | S13: =SUM(P13:R13) -> 0 | T13: =S13-(L13+N13) -> 0 | U13: =IFERROR(AE13/Z13,0) -> 0 | V13: =IFERROR(AF13/AA13,0) -> 0 | W13: =IF(AND(R13>0,V13>0),V13,0) -> 0 | X13: =IFERROR(IF($C13="XK",$AM13/$S13/$AC13,$AM13/$S13),0) -> 0 | AA13: =IF($C13="NĐ",1,EXR_FC05) -> 1 | AB13: =IF($C13="NĐ",1,EXR_FC05) -> 1 | AC13: =IFERROR(SUMPRODUCT(AJ13:AL13,Z13:AB13)/AM13,0) -> 0 | AE13: =IFERROR(AJ13/P13,0) -> 0 | AF13: =IFERROR(AK13/Q13,0) -> 0 | AG13: =W13*AB13 -> 0 | AJ13: =SUMIFS('Working-T05-B1'!AI$8:AI$150,'Working-T05-B1'!$C$8:$C$150,$D13) -> 0 | AK13: =SUMIFS('Working-T05-B1'!AJ$8:AJ$150,'Working-T05-B1'!$C$8:$C$150,$D13) -> 0 | AL13: =R13*AG13 -> 0 | AM13: =SUM(AJ13:AL13) -> 0 | AO13: =IFERROR(SUM(AQ13:AR13)/SUM(P13:Q13),0) -> 0 | AQ13: =SUMIFS('Working-T05-B1'!AP$8:AP$150,'Working-T05-B1'!$C$8:$C$150,$D13) -> 0 | AR13: =SUMIFS('Working-T05-B1'!AQ$8:AQ$150,'Working-T05-B1'!$C$8:$C$150,$D13) -> 0 | AS13: =AO13*R13 -> 0 | AT13: =SUM(AQ13:AS13) -> 0 | AV13: =IFERROR(BA13/S13,0) -> 0 | AX13: =SUMIFS('Working-T05-B1'!AW$8:AW$150,'Working-T05-B1'!$C$8:$C$150,$D13) -> 0 | AY13: =SUMIFS('Working-T05-B1'!AX$8:AX$150,'Working-T05-B1'!$C$8:$C$150,$D13) -> 0 | BA13: =SUM(AX13:AZ13) -> 0 | BC13: =_xlfn.XLOOKUP($G13,'GIÁ XUẤT KHO'!$A$4:$A$97,'GIÁ XUẤT KHO'!$AW$4:$AW$97)*P13 -> 0 | BD13: =_xlfn.XLOOKUP($G13,'GIÁ XUẤT KHO'!$A$4:$A$97,'GIÁ XUẤT KHO'!$AW$4:$AW$97)*Q13 -> 0 | BE13: =_xlfn.XLOOKUP($G13,'GIÁ XUẤT KHO'!$A$4:$A$97,'GIÁ XUẤT KHO'!$AW$4:$AW$97)*R13 -> 0 | BF13: =SUM(BC13:BE13) -> 0 | BH13: =AJ13-BC13 -> 0 | BI13: =AK13-BD13 -> 0 | BJ13: =AL13-BE13 -> 0 | BK13: =SUM(BH13:BJ13) -> 0 | BM13: =SUM(BN13:BV13) -> 0 | BN13: =SUMIFS('GIÁ XUẤT KHO'!AX$4:AX$97,'GIÁ XUẤT KHO'!$A$4:$A$97,$G13)*$S13 -> 0 | BO13: =SUMIFS('GIÁ XUẤT KHO'!AY$4:AY$97,'GIÁ XUẤT KHO'!$A$4:$A$97,$G13)*$S13 -> 0 | BP13: =SUMIFS('GIÁ XUẤT KHO'!AZ$4:AZ$97,'GIÁ XUẤT KHO'!$A$4:$A$97,$G13)*$S13 -> 0 | BQ13: =SUMIFS('GIÁ XUẤT KHO'!BA$4:BA$97,'GIÁ XUẤT KHO'!$A$4:$A$97,$G13)*$S13 -> 0 | BR13: =SUMIFS('GIÁ XUẤT KHO'!BB$4:BB$97,'GIÁ XUẤT KHO'!$A$4:$A$97,$G13)*$S13 -> 0 | BS13: =SUMIFS('GIÁ XUẤT KHO'!BC$4:BC$97,'GIÁ XUẤT KHO'!$A$4:$A$97,$G13)*$S13 -> 0 | BT13: =SUMIFS('GIÁ XUẤT KHO'!BD$4:BD$97,'GIÁ XUẤT KHO'!$A$4:$A$97,$G13)*$S13 -> 0 | BU13: =SUMIFS('GIÁ XUẤT KHO'!BE$4:BE$97,'GIÁ XUẤT KHO'!$A$4:$A$97,$G13)*$S13 -> 0 | BV13: =SUMIFS('GIÁ XUẤT KHO'!BF$4:BF$97,'GIÁ XUẤT KHO'!$A$4:$A$97,$G13)*$S13 -> 0 | BW13: =BM13-BF13 -> 0
A14: =_xlfn.XLOOKUP($G14,MD_SKU[Mã SKU],MD_SKU[Link vào file BCQT]) -> Vảy rHDPE ép | B14: TC-026 | C14: NĐ | D14: 105324 | 110000407 | E14: 105324 | F14: NHỰA TRƯỜNG AN | G14: 110000407 | H14: Vảy HD Ép Đỏ | K14: =SUMIFS('Working-T05-B1'!L$8:L$150,'Working-T05-B1'!$C$8:$C$150,$D14) -> 24000 | L14: {=SUMPRODUCT(Sales!$G$3:$H$100*(Sales!$B$3:$B$100=$D14))} -> 0 | M14: =K14-L14 -> 24000 | N14: =SUMIFS(Sales!$I$3:$I$100,Sales!$B$3:$B$100,$D14) -> 12000 | P14: =SUMIFS('Working-T05-B1'!O$8:O$150,'Working-T05-B1'!$C$8:$C$150,$D14) -> 0 | Q14: =MAX(0,MIN(K14,L14+N14)-P14) -> 12000 | R14: =MAX(0,L14+N14-SUM(P14:Q14)) -> 0 | S14: =SUM(P14:R14) -> 12000 | T14: =S14-(L14+N14) -> 0 | U14: =IFERROR(AE14/Z14,0) -> 0 | V14: =IFERROR(AF14/AA14,0) -> 15740.741 | W14: =IF(AND(R14>0,V14>0),V14,0) -> 0 | X14: =IFERROR(IF($C14="XK",$AM14/$S14/$AC14,$AM14/$S14),0) -> 15740.741 | AA14: =IF($C14="NĐ",1,EXR_FC05) -> 1 | AB14: =IF($C14="NĐ",1,EXR_FC05) -> 1 | AC14: =IFERROR(SUMPRODUCT(AJ14:AL14,Z14:AB14)/AM14,0) -> 1 | AE14: =IFERROR(AJ14/P14,0) -> 0 | AF14: =IFERROR(AK14/Q14,0) -> 15740.741 | AG14: =W14*AB14 -> 0 | AJ14: =SUMIFS('Working-T05-B1'!AI$8:AI$150,'Working-T05-B1'!$C$8:$C$150,$D14) -> 0 | AK14: =SUMIFS('Working-T05-B1'!AJ$8:AJ$150,'Working-T05-B1'!$C$8:$C$150,$D14) -> 1.8888889e+08 | AL14: =R14*AG14 -> 0 | AM14: =SUM(AJ14:AL14) -> 1.8888889e+08 | AO14: =IFERROR(SUM(AQ14:AR14)/SUM(P14:Q14),0) -> 0 | AQ14: =SUMIFS('Working-T05-B1'!AP$8:AP$150,'Working-T05-B1'!$C$8:$C$150,$D14) -> 0 | AR14: =SUMIFS('Working-T05-B1'!AQ$8:AQ$150,'Working-T05-B1'!$C$8:$C$150,$D14) -> 0 | AS14: =AO14*R14 -> 0 | AT14: =SUM(AQ14:AS14) -> 0 | AV14: =IFERROR(BA14/S14,0) -> 0 | AX14: =SUMIFS('Working-T05-B1'!AW$8:AW$150,'Working-T05-B1'!$C$8:$C$150,$D14) -> 0 | AY14: =SUMIFS('Working-T05-B1'!AX$8:AX$150,'Working-T05-B1'!$C$8:$C$150,$D14) -> 0 | BA14: =SUM(AX14:AZ14) -> 0 | BC14: =_xlfn.XLOOKUP($G14,'GIÁ XUẤT KHO'!$A$4:$A$97,'GIÁ XUẤT KHO'!$AW$4:$AW$97)*P14 -> 0 | BD14: =_xlfn.XLOOKUP($G14,'GIÁ XUẤT KHO'!$A$4:$A$97,'GIÁ XUẤT KHO'!$AW$4:$AW$97)*Q14 -> 6.3425562e+08 | BE14: =_xlfn.XLOOKUP($G14,'GIÁ XUẤT KHO'!$A$4:$A$97,'GIÁ XUẤT KHO'!$AW$4:$AW$97)*R14 -> 0 | BF14: =SUM(BC14:BE14) -> 6.3425562e+08 | BH14: =AJ14-BC14 -> 0 | BI14: =AK14-BD14 -> -4.4536673e+08 | BJ14: =AL14-BE14 -> 0 | BK14: =SUM(BH14:BJ14) -> -4.4536673e+08 | BM14: =SUM(BN14:BV14) -> 6.3425562e+08 | BN14: =SUMIFS('GIÁ XUẤT KHO'!AX$4:AX$97,'GIÁ XUẤT KHO'!$A$4:$A$97,$G14)*$S14 -> 2.299744e+08 | BO14: =SUMIFS('GIÁ XUẤT KHO'!AY$4:AY$97,'GIÁ XUẤT KHO'!$A$4:$A$97,$G14)*$S14 -> 116210.35 | BP14: =SUMIFS('GIÁ XUẤT KHO'!AZ$4:AZ$97,'GIÁ XUẤT KHO'!$A$4:$A$97,$G14)*$S14 -> 1991055.3 | BQ14: =SUMIFS('GIÁ XUẤT KHO'!BA$4:BA$97,'GIÁ XUẤT KHO'!$A$4:$A$97,$G14)*$S14 -> 48462854 | BR14: =SUMIFS('GIÁ XUẤT KHO'!BB$4:BB$97,'GIÁ XUẤT KHO'!$A$4:$A$97,$G14)*$S14 -> 5209662.7 | BS14: =SUMIFS('GIÁ XUẤT KHO'!BC$4:BC$97,'GIÁ XUẤT KHO'!$A$4:$A$97,$G14)*$S14 -> 97711593 | BT14: =SUMIFS('GIÁ XUẤT KHO'!BD$4:BD$97,'GIÁ XUẤT KHO'!$A$4:$A$97,$G14)*$S14 -> 89153977 | BU14: =SUMIFS('GIÁ XUẤT KHO'!BE$4:BE$97,'GIÁ XUẤT KHO'!$A$4:$A$97,$G14)*$S14 -> 46994558 | BV14: =SUMIFS('GIÁ XUẤT KHO'!BF$4:BF$97,'GIÁ XUẤT KHO'!$A$4:$A$97,$G14)*$S14 -> 1.1464131e+08 | BW14: =BM14-BF14 -> 0
A15: =_xlfn.XLOOKUP($G15,MD_SKU[Mã SKU],MD_SKU[Link vào file BCQT]) -> Hạt rHDPE thổi | B15: TC-026 | C15: NĐ | D15: 105349 | 110000341 | E15: 105349 | F15: MTVN Plastic | G15: 110000341 | H15: Hạt nhựa rHDB04B01 | K15: =SUMIFS('Working-T05-B1'!L$8:L$150,'Working-T05-B1'!$C$8:$C$150,$D15) -> 30500 | L15: {=SUMPRODUCT(Sales!$G$3:$H$100*(Sales!$B$3:$B$100=$D15))} -> 0 | M15: =K15-L15 -> 30500 | N15: =SUMIFS(Sales!$I$3:$I$100,Sales!$B$3:$B$100,$D15) -> 30000 | P15: =SUMIFS('Working-T05-B1'!O$8:O$150,'Working-T05-B1'!$C$8:$C$150,$D15) -> 0 | Q15: =MAX(0,MIN(K15,L15+N15)-P15) -> 30000 | R15: =MAX(0,L15+N15-SUM(P15:Q15)) -> 0 | S15: =SUM(P15:R15) -> 30000 | T15: =S15-(L15+N15) -> 0 | U15: =IFERROR(AE15/Z15,0) -> 0 | V15: =IFERROR(AF15/AA15,0) -> 16203.704 | W15: =IF(AND(R15>0,V15>0),V15,0) -> 0 | X15: =IFERROR(IF($C15="XK",$AM15/$S15/$AC15,$AM15/$S15),0) -> 16203.704 | AA15: =IF($C15="NĐ",1,EXR_FC05) -> 1 | AB15: =IF($C15="NĐ",1,EXR_FC05) -> 1 | AC15: =IFERROR(SUMPRODUCT(AJ15:AL15,Z15:AB15)/AM15,0) -> 1 | AE15: =IFERROR(AJ15/P15,0) -> 0 | AF15: =IFERROR(AK15/Q15,0) -> 16203.704 | AG15: =W15*AB15 -> 0 | AJ15: =SUMIFS('Working-T05-B1'!AI$8:AI$150,'Working-T05-B1'!$C$8:$C$150,$D15) -> 0 | AK15: =SUMIFS('Working-T05-B1'!AJ$8:AJ$150,'Working-T05-B1'!$C$8:$C$150,$D15) -> 4.8611111e+08 | AL15: =R15*AG15 -> 0 | AM15: =SUM(AJ15:AL15) -> 4.8611111e+08 | AO15: =IFERROR(SUM(AQ15:AR15)/SUM(P15:Q15),0) -> 0 | AQ15: =SUMIFS('Working-T05-B1'!AP$8:AP$150,'Working-T05-B1'!$C$8:$C$150,$D15) -> 0 | AR15: =SUMIFS('Working-T05-B1'!AQ$8:AQ$150,'Working-T05-B1'!$C$8:$C$150,$D15) -> 0 | AS15: =AO15*R15 -> 0 | AT15: =SUM(AQ15:AS15) -> 0 | AV15: =IFERROR(BA15/S15,0) -> 0 | AX15: =SUMIFS('Working-T05-B1'!AW$8:AW$150,'Working-T05-B1'!$C$8:$C$150,$D15) -> 0 | AY15: =SUMIFS('Working-T05-B1'!AX$8:AX$150,'Working-T05-B1'!$C$8:$C$150,$D15) -> 0 | BA15: =SUM(AX15:AZ15) -> 0 | BC15: =_xlfn.XLOOKUP($G15,'GIÁ XUẤT KHO'!$A$4:$A$97,'GIÁ XUẤT KHO'!$AW$4:$AW$97)*P15 -> 0 | BD15: =_xlfn.XLOOKUP($G15,'GIÁ XUẤT KHO'!$A$4:$A$97,'GIÁ XUẤT KHO'!$AW$4:$AW$97)*Q15 -> 6.1048755e+08 | BE15: =_xlfn.XLOOKUP($G15,'GIÁ XUẤT KHO'!$A$4:$A$97,'GIÁ XUẤT KHO'!$AW$4:$AW$97)*R15 -> 0 | BF15: =SUM(BC15:BE15) -> 6.1048755e+08 | BH15: =AJ15-BC15 -> 0 | BI15: =AK15-BD15 -> -1.2437644e+08 | BJ15: =AL15-BE15 -> 0 | BK15: =SUM(BH15:BJ15) -> -1.2437644e+08 | BM15: =SUM(BN15:BV15) -> 6.1048755e+08 | BN15: =SUMIFS('GIÁ XUẤT KHO'!AX$4:AX$97,'GIÁ XUẤT KHO'!$A$4:$A$97,$G15)*$S15 -> 3.9517871e+08 | BO15: =SUMIFS('GIÁ XUẤT KHO'!AY$4:AY$97,'GIÁ XUẤT KHO'!$A$4:$A$97,$G15)*$S15 -> 10029045 | BP15: =SUMIFS('GIÁ XUẤT KHO'!AZ$4:AZ$97,'GIÁ XUẤT KHO'!$A$4:$A$97,$G15)*$S15 -> 4911419 | BQ15: =SUMIFS('GIÁ XUẤT KHO'!BA$4:BA$97,'GIÁ XUẤT KHO'!$A$4:$A$97,$G15)*$S15 -> 33250668 | BR15: =SUMIFS('GIÁ XUẤT KHO'!BB$4:BB$97,'GIÁ XUẤT KHO'!$A$4:$A$97,$G15)*$S15 -> 7139174.3 | BS15: =SUMIFS('GIÁ XUẤT KHO'!BC$4:BC$97,'GIÁ XUẤT KHO'!$A$4:$A$97,$G15)*$S15 -> 42618160 | BT15: =SUMIFS('GIÁ XUẤT KHO'!BD$4:BD$97,'GIÁ XUẤT KHO'!$A$4:$A$97,$G15)*$S15 -> 40571790 | BU15: =SUMIFS('GIÁ XUẤT KHO'!BE$4:BE$97,'GIÁ XUẤT KHO'!$A$4:$A$97,$G15)*$S15 -> 8246135.1 | BV15: =SUMIFS('GIÁ XUẤT KHO'!BF$4:BF$97,'GIÁ XUẤT KHO'!$A$4:$A$97,$G15)*$S15 -> 68542448 | BW15: =BM15-BF15 -> 0
A16: =_xlfn.XLOOKUP($G16,MD_SKU[Mã SKU],MD_SKU[Link vào file BCQT]) -> Hạt rHDPE ép | B16: TC-026 | C16: NĐ | D16: 1000 | 110000360 | E16: 1000 | F16: Duy Tân | G16: 110000360 | H16: Hạt nhựa rHDI4L01 | K16: =SUMIFS('Working-T05-B1'!L$8:L$150,'Working-T05-B1'!$C$8:$C$150,$D16) -> 11000 | L16: {=SUMPRODUCT(Sales!$G$3:$H$100*(Sales!$B$3:$B$100=$D16))} -> 0 | M16: =K16-L16 -> 11000 | N16: =SUMIFS(Sales!$I$3:$I$100,Sales!$B$3:$B$100,$D16) -> 0 | P16: =SUMIFS('Working-T05-B1'!O$8:O$150,'Working-T05-B1'!$C$8:$C$150,$D16) -> 0 | Q16: =MAX(0,MIN(K16,L16+N16)-P16) -> 0 | R16: =MAX(0,L16+N16-SUM(P16:Q16)) -> 0 | S16: =SUM(P16:R16) -> 0 | T16: =S16-(L16+N16) -> 0 | U16: =IFERROR(AE16/Z16,0) -> 0 | V16: =IFERROR(AF16/AA16,0) -> 0 | W16: =IF(AND(R16>0,V16>0),V16,0) -> 0 | X16: =IFERROR(IF($C16="XK",$AM16/$S16/$AC16,$AM16/$S16),0) -> 0 | AA16: =IF($C16="NĐ",1,EXR_FC05) -> 1 | AB16: =IF($C16="NĐ",1,EXR_FC05) -> 1 | AC16: =IFERROR(SUMPRODUCT(AJ16:AL16,Z16:AB16)/AM16,0) -> 0 | AE16: =IFERROR(AJ16/P16,0) -> 0 | AF16: =IFERROR(AK16/Q16,0) -> 0 | AG16: =W16*AB16 -> 0 | AJ16: =SUMIFS('Working-T05-B1'!AI$8:AI$150,'Working-T05-B1'!$C$8:$C$150,$D16) -> 0 | AK16: =SUMIFS('Working-T05-B1'!AJ$8:AJ$150,'Working-T05-B1'!$C$8:$C$150,$D16) -> 0 | AL16: =R16*AG16 -> 0 | AM16: =SUM(AJ16:AL16) -> 0 | AO16: =IFERROR(SUM(AQ16:AR16)/SUM(P16:Q16),0) -> 0 | AQ16: =SUMIFS('Working-T05-B1'!AP$8:AP$150,'Working-T05-B1'!$C$8:$C$150,$D16) -> 0 | AR16: =SUMIFS('Working-T05-B1'!AQ$8:AQ$150,'Working-T05-B1'!$C$8:$C$150,$D16) -> 0 | AS16: =AO16*R16 -> 0 | AT16: =SUM(AQ16:AS16) -> 0 | AV16: =IFERROR(BA16/S16,0) -> 0 | AX16: =SUMIFS('Working-T05-B1'!AW$8:AW$150,'Working-T05-B1'!$C$8:$C$150,$D16) -> 0 | AY16: =SUMIFS('Working-T05-B1'!AX$8:AX$150,'Working-T05-B1'!$C$8:$C$150,$D16) -> 0 | BA16: =SUM(AX16:AZ16) -> 0 | BC16: =_xlfn.XLOOKUP($G16,'GIÁ XUẤT KHO'!$A$4:$A$97,'GIÁ XUẤT KHO'!$AW$4:$AW$97)*P16 -> 0 | BD16: =_xlfn.XLOOKUP($G16,'GIÁ XUẤT KHO'!$A$4:$A$97,'GIÁ XUẤT KHO'!$AW$4:$AW$97)*Q16 -> 0 | BE16: =_xlfn.XLOOKUP($G16,'GIÁ XUẤT KHO'!$A$4:$A$97,'GIÁ XUẤT KHO'!$AW$4:$AW$97)*R16 -> 0 | BF16: =SUM(BC16:BE16) -> 0 | BH16: =AJ16-BC16 -> 0 | BI16: =AK16-BD16 -> 0 | BJ16: =AL16-BE16 -> 0 | BK16: =SUM(BH16:BJ16) -> 0 | BM16: =SUM(BN16:BV16) -> 0 | BN16: =SUMIFS('GIÁ XUẤT KHO'!AX$4:AX$97,'GIÁ XUẤT KHO'!$A$4:$A$97,$G16)*$S16 -> 0 | BO16: =SUMIFS('GIÁ XUẤT KHO'!AY$4:AY$97,'GIÁ XUẤT KHO'!$A$4:$A$97,$G16)*$S16 -> 0 | BP16: =SUMIFS('GIÁ XUẤT KHO'!AZ$4:AZ$97,'GIÁ XUẤT KHO'!$A$4:$A$97,$G16)*$S16 -> 0 | BQ16: =SUMIFS('GIÁ XUẤT KHO'!BA$4:BA$97,'GIÁ XUẤT KHO'!$A$4:$A$97,$G16)*$S16 -> 0 | BR16: =SUMIFS('GIÁ XUẤT KHO'!BB$4:BB$97,'GIÁ XUẤT KHO'!$A$4:$A$97,$G16)*$S16 -> 0 | BS16: =SUMIFS('GIÁ XUẤT KHO'!BC$4:BC$97,'GIÁ XUẤT KHO'!$A$4:$A$97,$G16)*$S16 -> 0 | BT16: =SUMIFS('GIÁ XUẤT KHO'!BD$4:BD$97,'GIÁ XUẤT KHO'!$A$4:$A$97,$G16)*$S16 -> 0 | BU16: =SUMIFS('GIÁ XUẤT KHO'!BE$4:BE$97,'GIÁ XUẤT KHO'!$A$4:$A$97,$G16)*$S16 -> 0 | BV16: =SUMIFS('GIÁ XUẤT KHO'!BF$4:BF$97,'GIÁ XUẤT KHO'!$A$4:$A$97,$G16)*$S16 -> 0 | BW16: =BM16-BF16 -> 0
A17: =_xlfn.XLOOKUP($G17,MD_SKU[Mã SKU],MD_SKU[Link vào file BCQT]) -> Phó sản | B17: TC-026 | C17: NĐ | D17: 105229 | 160012801 | E17: 105229 | F17: GIA TƯỜNG | G17: 160012801 | H17: Vảy PET GC Dây Đai | K17: =SUMIFS('Working-T05-B1'!L$8:L$150,'Working-T05-B1'!$C$8:$C$150,$D17) -> 5000 | L17: {=SUMPRODUCT(Sales!$G$3:$H$100*(Sales!$B$3:$B$100=$D17))} -> 0 | M17: =K17-L17 -> 5000 | N17: =SUMIFS(Sales!$I$3:$I$100,Sales!$B$3:$B$100,$D17) -> 0 | P17: =SUMIFS('Working-T05-B1'!O$8:O$150,'Working-T05-B1'!$C$8:$C$150,$D17) -> 0 | Q17: =MAX(0,MIN(K17,L17+N17)-P17) -> 0 | R17: =MAX(0,L17+N17-SUM(P17:Q17)) -> 0 | S17: =SUM(P17:R17) -> 0 | T17: =S17-(L17+N17) -> 0 | U17: =IFERROR(AE17/Z17,0) -> 0 | V17: =IFERROR(AF17/AA17,0) -> 0 | W17: =IF(AND(R17>0,V17>0),V17,0) -> 0 | X17: =IFERROR(IF($C17="XK",$AM17/$S17/$AC17,$AM17/$S17),0) -> 0 | AA17: =IF($C17="NĐ",1,EXR_FC05) -> 1 | AB17: =IF($C17="NĐ",1,EXR_FC05) -> 1 | AC17: =IFERROR(SUMPRODUCT(AJ17:AL17,Z17:AB17)/AM17,0) -> 0 | AE17: =IFERROR(AJ17/P17,0) -> 0 | AF17: =IFERROR(AK17/Q17,0) -> 0 | AG17: =W17*AB17 -> 0 | AJ17: =SUMIFS('Working-T05-B1'!AI$8:AI$150,'Working-T05-B1'!$C$8:$C$150,$D17) -> 0 | AK17: =SUMIFS('Working-T05-B1'!AJ$8:AJ$150,'Working-T05-B1'!$C$8:$C$150,$D17) -> 0 | AL17: =R17*AG17 -> 0 | AM17: =SUM(AJ17:AL17) -> 0 | AO17: =IFERROR(SUM(AQ17:AR17)/SUM(P17:Q17),0) -> 0 | AQ17: =SUMIFS('Working-T05-B1'!AP$8:AP$150,'Working-T05-B1'!$C$8:$C$150,$D17) -> 0 | AR17: =SUMIFS('Working-T05-B1'!AQ$8:AQ$150,'Working-T05-B1'!$C$8:$C$150,$D17) -> 0 | AS17: =AO17*R17 -> 0 | AT17: =SUM(AQ17:AS17) -> 0 | AV17: =IFERROR(BA17/S17,0) -> 0 | AX17: =SUMIFS('Working-T05-B1'!AW$8:AW$150,'Working-T05-B1'!$C$8:$C$150,$D17) -> 0 | AY17: =SUMIFS('Working-T05-B1'!AX$8:AX$150,'Working-T05-B1'!$C$8:$C$150,$D17) -> 0 | BA17: =SUM(AX17:AZ17) -> 0 | BC17: =_xlfn.XLOOKUP($G17,'GIÁ XUẤT KHO'!$A$4:$A$97,'GIÁ XUẤT KHO'!$AW$4:$AW$97)*P17 -> 0 | BD17: =_xlfn.XLOOKUP($G17,'GIÁ XUẤT KHO'!$A$4:$A$97,'GIÁ XUẤT KHO'!$AW$4:$AW$97)*Q17 -> 0 | BE17: =_xlfn.XLOOKUP($G17,'GIÁ XUẤT KHO'!$A$4:$A$97,'GIÁ XUẤT KHO'!$AW$4:$AW$97)*R17 -> 0 | BF17: =SUM(BC17:BE17) -> 0 | BH17: =AJ17-BC17 -> 0 | BI17: =AK17-BD17 -> 0 | BJ17: =AL17-BE17 -> 0 | BK17: =SUM(BH17:BJ17) -> 0 | BM17: =SUM(BN17:BV17) -> 0 | BN17: =SUMIFS('GIÁ XUẤT KHO'!AX$4:AX$97,'GIÁ XUẤT KHO'!$A$4:$A$97,$G17)*$S17 -> 0 | BO17: =SUMIFS('GIÁ XUẤT KHO'!AY$4:AY$97,'GIÁ XUẤT KHO'!$A$4:$A$97,$G17)*$S17 -> 0 | BP17: =SUMIFS('GIÁ XUẤT KHO'!AZ$4:AZ$97,'GIÁ XUẤT KHO'!$A$4:$A$97,$G17)*$S17 -> 0 | BQ17: =SUMIFS('GIÁ XUẤT KHO'!BA$4:BA$97,'GIÁ XUẤT KHO'!$A$4:$A$97,$G17)*$S17 -> 0 | BR17: =SUMIFS('GIÁ XUẤT KHO'!BB$4:BB$97,'GIÁ XUẤT KHO'!$A$4:$A$97,$G17)*$S17 -> 0 | BS17: =SUMIFS('GIÁ XUẤT KHO'!BC$4:BC$97,'GIÁ XUẤT KHO'!$A$4:$A$97,$G17)*$S17 -> 0 | BT17: =SUMIFS('GIÁ XUẤT KHO'!BD$4:BD$97,'GIÁ XUẤT KHO'!$A$4:$A$97,$G17)*$S17 -> 0 | BU17: =SUMIFS('GIÁ XUẤT KHO'!BE$4:BE$97,'GIÁ XUẤT KHO'!$A$4:$A$97,$G17)*$S17 -> 0 | BV17: =SUMIFS('GIÁ XUẤT KHO'!BF$4:BF$97,'GIÁ XUẤT KHO'!$A$4:$A$97,$G17)*$S17 -> 0 | BW17: =BM17-BF17 -> 0
A18: =_xlfn.XLOOKUP($G18,MD_SKU[Mã SKU],MD_SKU[Link vào file BCQT]) -> Hạt rHDPE ép | B18: TC-026 | C18: NĐ | D18: 105339 | 110000364 | E18: 105339 | F18: HUY THÀNH | G18: 110000364 | H18: Hạt nhựa rHDI3Y01 | K18: =SUMIFS('Working-T05-B1'!L$8:L$150,'Working-T05-B1'!$C$8:$C$150,$D18) -> 33000 | L18: {=SUMPRODUCT(Sales!$G$3:$H$100*(Sales!$B$3:$B$100=$D18))} -> 0 | M18: =K18-L18 -> 33000 | N18: =SUMIFS(Sales!$I$3:$I$100,Sales!$B$3:$B$100,$D18) -> 0 | P18: =SUMIFS('Working-T05-B1'!O$8:O$150,'Working-T05-B1'!$C$8:$C$150,$D18) -> 0 | Q18: =MAX(0,MIN(K18,L18+N18)-P18) -> 0 | R18: =MAX(0,L18+N18-SUM(P18:Q18)) -> 0 | S18: =SUM(P18:R18) -> 0 | T18: =S18-(L18+N18) -> 0 | U18: =IFERROR(AE18/Z18,0) -> 0 | V18: =IFERROR(AF18/AA18,0) -> 0 | W18: =IF(AND(R18>0,V18>0),V18,0) -> 0 | X18: =IFERROR(IF($C18="XK",$AM18/$S18/$AC18,$AM18/$S18),0) -> 0 | AA18: =IF($C18="NĐ",1,EXR_FC05) -> 1 | AB18: =IF($C18="NĐ",1,EXR_FC05) -> 1 | AC18: =IFERROR(SUMPRODUCT(AJ18:AL18,Z18:AB18)/AM18,0) -> 0 | AE18: =IFERROR(AJ18/P18,0) -> 0 | AF18: =IFERROR(AK18/Q18,0) -> 0 | AG18: =W18*AB18 -> 0 | AJ18: =SUMIFS('Working-T05-B1'!AI$8:AI$150,'Working-T05-B1'!$C$8:$C$150,$D18) -> 0 | AK18: =SUMIFS('Working-T05-B1'!AJ$8:AJ$150,'Working-T05-B1'!$C$8:$C$150,$D18) -> 0 | AL18: =R18*AG18 -> 0 | AM18: =SUM(AJ18:AL18) -> 0 | AO18: =IFERROR(SUM(AQ18:AR18)/SUM(P18:Q18),0) -> 0 | AQ18: =SUMIFS('Working-T05-B1'!AP$8:AP$150,'Working-T05-B1'!$C$8:$C$150,$D18) -> 0 | AR18: =SUMIFS('Working-T05-B1'!AQ$8:AQ$150,'Working-T05-B1'!$C$8:$C$150,$D18) -> 0 | AS18: =AO18*R18 -> 0 | AT18: =SUM(AQ18:AS18) -> 0 | AV18: =IFERROR(BA18/S18,0) -> 0 | AX18: =SUMIFS('Working-T05-B1'!AW$8:AW$150,'Working-T05-B1'!$C$8:$C$150,$D18) -> 0 | AY18: =SUMIFS('Working-T05-B1'!AX$8:AX$150,'Working-T05-B1'!$C$8:$C$150,$D18) -> 0 | BA18: =SUM(AX18:AZ18) -> 0 | BC18: =_xlfn.XLOOKUP($G18,'GIÁ XUẤT KHO'!$A$4:$A$97,'GIÁ XUẤT KHO'!$AW$4:$AW$97)*P18 -> 0 | BD18: =_xlfn.XLOOKUP($G18,'GIÁ XUẤT KHO'!$A$4:$A$97,'GIÁ XUẤT KHO'!$AW$4:$AW$97)*Q18 -> 0 | BE18: =_xlfn.XLOOKUP($G18,'GIÁ XUẤT KHO'!$A$4:$A$97,'GIÁ XUẤT KHO'!$AW$4:$AW$97)*R18 -> 0 | BF18: =SUM(BC18:BE18) -> 0 | BH18: =AJ18-BC18 -> 0 | BI18: =AK18-BD18 -> 0 | BJ18: =AL18-BE18 -> 0 | BK18: =SUM(BH18:BJ18) -> 0 | BM18: =SUM(BN18:BV18) -> 0 | BN18: =SUMIFS('GIÁ XUẤT KHO'!AX$4:AX$97,'GIÁ XUẤT KHO'!$A$4:$A$97,$G18)*$S18 -> 0 | BO18: =SUMIFS('GIÁ XUẤT KHO'!AY$4:AY$97,'GIÁ XUẤT KHO'!$A$4:$A$97,$G18)*$S18 -> 0 | BP18: =SUMIFS('GIÁ XUẤT KHO'!AZ$4:AZ$97,'GIÁ XUẤT KHO'!$A$4:$A$97,$G18)*$S18 -> 0 | BQ18: =SUMIFS('GIÁ XUẤT KHO'!BA$4:BA$97,'GIÁ XUẤT KHO'!$A$4:$A$97,$G18)*$S18 -> 0 | BR18: =SUMIFS('GIÁ XUẤT KHO'!BB$4:BB$97,'GIÁ XUẤT KHO'!$A$4:$A$97,$G18)*$S18 -> 0 | BS18: =SUMIFS('GIÁ XUẤT KHO'!BC$4:BC$97,'GIÁ XUẤT KHO'!$A$4:$A$97,$G18)*$S18 -> 0 | BT18: =SUMIFS('GIÁ XUẤT KHO'!BD$4:BD$97,'GIÁ XUẤT KHO'!$A$4:$A$97,$G18)*$S18 -> 0 | BU18: =SUMIFS('GIÁ XUẤT KHO'!BE$4:BE$97,'GIÁ XUẤT KHO'!$A$4:$A$97,$G18)*$S18 -> 0 | BV18: =SUMIFS('GIÁ XUẤT KHO'!BF$4:BF$97,'GIÁ XUẤT KHO'!$A$4:$A$97,$G18)*$S18 -> 0 | BW18: =BM18-BF18 -> 0
A19: =_xlfn.XLOOKUP($G19,MD_SKU[Mã SKU],MD_SKU[Link vào file BCQT]) -> Phó sản | B19: TC-026 | C19: NĐ | D19: 105371 | 160012334 | E19: 105371 | F19: VINAFIBER | G19: 160012334 | H19: Phó Sản PET Bụi Cám Sau Sàn Rung | K19: =SUMIFS('Working-T05-B1'!L$8:L$150,'Working-T05-B1'!$C$8:$C$150,$D19) -> 25876 | L19: {=SUMPRODUCT(Sales!$G$3:$H$100*(Sales!$B$3:$B$100=$D19))} -> 0 | M19: =K19-L19 -> 25876 | N19: =SUMIFS(Sales!$I$3:$I$100,Sales!$B$3:$B$100,$D19) -> 0 | P19: =SUMIFS('Working-T05-B1'!O$8:O$150,'Working-T05-B1'!$C$8:$C$150,$D19) -> 0 | Q19: =MAX(0,MIN(K19,L19+N19)-P19) -> 0 | R19: =MAX(0,L19+N19-SUM(P19:Q19)) -> 0 | S19: =SUM(P19:R19) -> 0 | T19: =S19-(L19+N19) -> 0 | U19: =IFERROR(AE19/Z19,0) -> 0 | V19: =IFERROR(AF19/AA19,0) -> 0 | W19: =IF(AND(R19>0,V19>0),V19,0) -> 0 | X19: =IFERROR(IF($C19="XK",$AM19/$S19/$AC19,$AM19/$S19),0) -> 0 | AA19: =IF($C19="NĐ",1,EXR_FC05) -> 1 | AB19: =IF($C19="NĐ",1,EXR_FC05) -> 1 | AC19: =IFERROR(SUMPRODUCT(AJ19:AL19,Z19:AB19)/AM19,0) -> 0 | AE19: =IFERROR(AJ19/P19,0) -> 0 | AF19: =IFERROR(AK19/Q19,0) -> 0 | AG19: =W19*AB19 -> 0 | AJ19: =SUMIFS('Working-T05-B1'!AI$8:AI$150,'Working-T05-B1'!$C$8:$C$150,$D19) -> 0 | AK19: =SUMIFS('Working-T05-B1'!AJ$8:AJ$150,'Working-T05-B1'!$C$8:$C$150,$D19) -> 0 | AL19: =R19*AG19 -> 0 | AM19: =SUM(AJ19:AL19) -> 0 | AO19: =IFERROR(SUM(AQ19:AR19)/SUM(P19:Q19),0) -> 0 | AQ19: =SUMIFS('Working-T05-B1'!AP$8:AP$150,'Working-T05-B1'!$C$8:$C$150,$D19) -> 0 | AR19: =SUMIFS('Working-T05-B1'!AQ$8:AQ$150,'Working-T05-B1'!$C$8:$C$150,$D19) -> 0 | AS19: =AO19*R19 -> 0 | AT19: =SUM(AQ19:AS19) -> 0 | AV19: =IFERROR(BA19/S19,0) -> 0 | AX19: =SUMIFS('Working-T05-B1'!AW$8:AW$150,'Working-T05-B1'!$C$8:$C$150,$D19) -> 0 | AY19: =SUMIFS('Working-T05-B1'!AX$8:AX$150,'Working-T05-B1'!$C$8:$C$150,$D19) -> 0 | BA19: =SUM(AX19:AZ19) -> 0 | BC19: =_xlfn.XLOOKUP($G19,'GIÁ XUẤT KHO'!$A$4:$A$97,'GIÁ XUẤT KHO'!$AW$4:$AW$97)*P19 -> 0 | BD19: =_xlfn.XLOOKUP($G19,'GIÁ XUẤT KHO'!$A$4:$A$97,'GIÁ XUẤT KHO'!$AW$4:$AW$97)*Q19 -> 0 | BE19: =_xlfn.XLOOKUP($G19,'GIÁ XUẤT KHO'!$A$4:$A$97,'GIÁ XUẤT KHO'!$AW$4:$AW$97)*R19 -> 0 | BF19: =SUM(BC19:BE19) -> 0 | BH19: =AJ19-BC19 -> 0 | BI19: =AK19-BD19 -> 0 | BJ19: =AL19-BE19 -> 0 | BK19: =SUM(BH19:BJ19) -> 0 | BM19: =SUM(BN19:BV19) -> 0 | BN19: =SUMIFS('GIÁ XUẤT KHO'!AX$4:AX$97,'GIÁ XUẤT KHO'!$A$4:$A$97,$G19)*$S19 -> 0 | BO19: =SUMIFS('GIÁ XUẤT KHO'!AY$4:AY$97,'GIÁ XUẤT KHO'!$A$4:$A$97,$G19)*$S19 -> 0 | BP19: =SUMIFS('GIÁ XUẤT KHO'!AZ$4:AZ$97,'GIÁ XUẤT KHO'!$A$4:$A$97,$G19)*$S19 -> 0 | BQ19: =SUMIFS('GIÁ XUẤT KHO'!BA$4:BA$97,'GIÁ XUẤT KHO'!$A$4:$A$97,$G19)*$S19 -> 0 | BR19: =SUMIFS('GIÁ XUẤT KHO'!BB$4:BB$97,'GIÁ XUẤT KHO'!$A$4:$A$97,$G19)*$S19 -> 0 | BS19: =SUMIFS('GIÁ XUẤT KHO'!BC$4:BC$97,'GIÁ XUẤT KHO'!$A$4:$A$97,$G19)*$S19 -> 0 | BT19: =SUMIFS('GIÁ XUẤT KHO'!BD$4:BD$97,'GIÁ XUẤT KHO'!$A$4:$A$97,$G19)*$S19 -> 0 | BU19: =SUMIFS('GIÁ XUẤT KHO'!BE$4:BE$97,'GIÁ XUẤT KHO'!$A$4:$A$97,$G19)*$S19 -> 0 | BV19: =SUMIFS('GIÁ XUẤT KHO'!BF$4:BF$97,'GIÁ XUẤT KHO'!$A$4:$A$97,$G19)*$S19 -> 0 | BW19: =BM19-BF19 -> 0
... A23: =_xlfn.XLOOKUP($G23,MD_SKU[Mã SKU],MD_SKU[Link vào file BCQT]) -> Hạt rHDPE thổi | B23: TC-026 | C23: XK | D23: 200393 | 110000341 | E23: 200393 | F23: Orient Plastic | G23: 110000341 | H23: Hạt nhựa rHDB04B01 | K23: =SUMIFS('Working-T05-B1'!L$8:L$150,'Working-T05-B1'!$C$8:$C$150,$D23) -> 81000 | L23: {=SUMPRODUCT(Sales!$G$3:$H$100*(Sales!$B$3:$B$100=$D23))} -> 0 | M23: =K23-L23 -> 81000 | N23: =SUMIFS(Sales!$I$3:$I$100,Sales!$B$3:$B$100,$D23) -> 0 | P23: =SUMIFS('Working-T05-B1'!O$8:O$150,'Working-T05-B1'!$C$8:$C$150,$D23) -> 0 | Q23: =MAX(0,MIN(K23,L23+N23)-P23) -> 0 | R23: =MAX(0,L23+N23-SUM(P23:Q23)) -> 0 | S23: =SUM(P23:R23) -> 0 | T23: =S23-(L23+N23) -> 0 | U23: =IFERROR(AE23/Z23,0) -> 0 | V23: =IFERROR(AF23/AA23,0) -> 0 | W23: =IF(AND(R23>0,V23>0),V23,0) -> 0 | X23: =IFERROR(IF($C23="XK",$AM23/$S23/$AC23,$AM23/$S23),0) -> 0 | AA23: =IF($C23="NĐ",1,EXR_FC05) -> 26300 | AB23: =IF($C23="NĐ",1,EXR_FC05) -> 26300 | AC23: =IFERROR(SUMPRODUCT(AJ23:AL23,Z23:AB23)/AM23,0) -> 0 | AE23: =IFERROR(AJ23/P23,0) -> 0 | AF23: =IFERROR(AK23/Q23,0) -> 0 | AG23: =W23*AB23 -> 0 | AJ23: =SUMIFS('Working-T05-B1'!AI$8:AI$150,'Working-T05-B1'!$C$8:$C$150,$D23) -> 0 | AK23: =SUMIFS('Working-T05-B1'!AJ$8:AJ$150,'Working-T05-B1'!$C$8:$C$150,$D23) -> 0 | AL23: =R23*AG23 -> 0 | AM23: =SUM(AJ23:AL23) -> 0 | AO23: =IFERROR(SUM(AQ23:AR23)/SUM(P23:Q23),0) -> 0 | AQ23: =SUMIFS('Working-T05-B1'!AP$8:AP$150,'Working-T05-B1'!$C$8:$C$150,$D23) -> 0 | AR23: =SUMIFS('Working-T05-B1'!AQ$8:AQ$150,'Working-T05-B1'!$C$8:$C$150,$D23) -> 0 | AS23: =AO23*R23 -> 0 | AT23: =SUM(AQ23:AS23) -> 0 | AV23: =IFERROR(BA23/S23,0) -> 0 | AX23: =SUMIFS('Working-T05-B1'!AW$8:AW$150,'Working-T05-B1'!$C$8:$C$150,$D23) -> 0 | AY23: =SUMIFS('Working-T05-B1'!AX$8:AX$150,'Working-T05-B1'!$C$8:$C$150,$D23) -> 0 | BA23: =SUM(AX23:AZ23) -> 0 | BC23: =_xlfn.XLOOKUP($G23,'GIÁ XUẤT KHO'!$A$4:$A$97,'GIÁ XUẤT KHO'!$AW$4:$AW$97)*P23 -> 0 | BD23: =_xlfn.XLOOKUP($G23,'GIÁ XUẤT KHO'!$A$4:$A$97,'GIÁ XUẤT KHO'!$AW$4:$AW$97)*Q23 -> 0 | BE23: =_xlfn.XLOOKUP($G23,'GIÁ XUẤT KHO'!$A$4:$A$97,'GIÁ XUẤT KHO'!$AW$4:$AW$97)*R23 -> 0 | BF23: =SUM(BC23:BE23) -> 0 | BH23: =AJ23-BC23 -> 0 | BI23: =AK23-BD23 -> 0 | BJ23: =AL23-BE23 -> 0 | BK23: =SUM(BH23:BJ23) -> 0 | BM23: =SUM(BN23:BV23) -> 0 | BN23: =SUMIFS('GIÁ XUẤT KHO'!AX$4:AX$97,'GIÁ XUẤT KHO'!$A$4:$A$97,$G23)*$S23 -> 0 | BO23: =SUMIFS('GIÁ XUẤT KHO'!AY$4:AY$97,'GIÁ XUẤT KHO'!$A$4:$A$97,$G23)*$S23 -> 0 | BP23: =SUMIFS('GIÁ XUẤT KHO'!AZ$4:AZ$97,'GIÁ XUẤT KHO'!$A$4:$A$97,$G23)*$S23 -> 0 | BQ23: =SUMIFS('GIÁ XUẤT KHO'!BA$4:BA$97,'GIÁ XUẤT KHO'!$A$4:$A$97,$G23)*$S23 -> 0 | BR23: =SUMIFS('GIÁ XUẤT KHO'!BB$4:BB$97,'GIÁ XUẤT KHO'!$A$4:$A$97,$G23)*$S23 -> 0 | BS23: =SUMIFS('GIÁ XUẤT KHO'!BC$4:BC$97,'GIÁ XUẤT KHO'!$A$4:$A$97,$G23)*$S23 -> 0 | BT23: =SUMIFS('GIÁ XUẤT KHO'!BD$4:BD$97,'GIÁ XUẤT KHO'!$A$4:$A$97,$G23)*$S23 -> 0 | BU23: =SUMIFS('GIÁ XUẤT KHO'!BE$4:BE$97,'GIÁ XUẤT KHO'!$A$4:$A$97,$G23)*$S23 -> 0 | BV23: =SUMIFS('GIÁ XUẤT KHO'!BF$4:BF$97,'GIÁ XUẤT KHO'!$A$4:$A$97,$G23)*$S23 -> 0 | BW23: =BM23-BF23 -> 0
A24: =_xlfn.XLOOKUP($G24,MD_SKU[Mã SKU],MD_SKU[Link vào file BCQT]) -> Hạt rPET | B24: TC-026 | C24: NĐ | D24: 105271 | 110000332 | E24: 105271 | F24: Suntory- Ngọc Nghĩa Tây Ninh | G24: 110000332 | H24: Hạt nhựa rPET iSS01084G | K24: =SUMIFS('Working-T05-B1'!L$8:L$150,'Working-T05-B1'!$C$8:$C$150,$D24) -> 88000 | L24: {=SUMPRODUCT(Sales!$G$3:$H$100*(Sales!$B$3:$B$100=$D24))} -> 0 | M24: =K24-L24 -> 88000 | N24: =SUMIFS(Sales!$I$3:$I$100,Sales!$B$3:$B$100,$D24) -> 88000 | P24: =SUMIFS('Working-T05-B1'!O$8:O$150,'Working-T05-B1'!$C$8:$C$150,$D24) -> 0 | Q24: =MAX(0,MIN(K24,L24+N24)-P24) -> 88000 | R24: =MAX(0,L24+N24-SUM(P24:Q24)) -> 0 | S24: =SUM(P24:R24) -> 88000 | T24: =S24-(L24+N24) -> 0 | U24: =IFERROR(AE24/Z24,0) -> 0 | V24: =IFERROR(AF24/AA24,0) -> 31844 | W24: =IF(AND(R24>0,V24>0),V24,0) -> 0 | X24: =IFERROR(IF($C24="XK",$AM24/$S24/$AC24,$AM24/$S24),0) -> 31844 | AA24: =IF($C24="NĐ",1,EXR_FC05) -> 1 | AB24: =IF($C24="NĐ",1,EXR_FC05) -> 1 | AC24: =IFERROR(SUMPRODUCT(AJ24:AL24,Z24:AB24)/AM24,0) -> 1 | AE24: =IFERROR(AJ24/P24,0) -> 0 | AF24: =IFERROR(AK24/Q24,0) -> 31844 | AG24: =W24*AB24 -> 0 | AJ24: =SUMIFS('Working-T05-B1'!AI$8:AI$150,'Working-T05-B1'!$C$8:$C$150,$D24) -> 0 | AK24: =SUMIFS('Working-T05-B1'!AJ$8:AJ$150,'Working-T05-B1'!$C$8:$C$150,$D24) -> 2802272000 | AL24: =R24*AG24 -> 0 | AM24: =SUM(AJ24:AL24) -> 2802272000 | AO24: =IFERROR(SUM(AQ24:AR24)/SUM(P24:Q24),0) -> 263 | AQ24: =SUMIFS('Working-T05-B1'!AP$8:AP$150,'Working-T05-B1'!$C$8:$C$150,$D24) -> 0 | AR24: =SUMIFS('Working-T05-B1'!AQ$8:AQ$150,'Working-T05-B1'!$C$8:$C$150,$D24) -> 23144000 | AS24: =AO24*R24 -> 0 | AT24: =SUM(AQ24:AS24) -> 23144000 | AV24: =IFERROR(BA24/S24,0) -> 1910.64 | AX24: =SUMIFS('Working-T05-B1'!AW$8:AW$150,'Working-T05-B1'!$C$8:$C$150,$D24) -> 0 | AY24: =SUMIFS('Working-T05-B1'!AX$8:AX$150,'Working-T05-B1'!$C$8:$C$150,$D24) -> 168136320 | BA24: =SUM(AX24:AZ24) -> 168136320 | BB24: x | BC24: =_xlfn.XLOOKUP($G24,'GIÁ XUẤT KHO'!$A$4:$A$97,'GIÁ XUẤT KHO'!$AW$4:$AW$97)*P24 -> 0 | BD24: =_xlfn.XLOOKUP($G24,'GIÁ XUẤT KHO'!$A$4:$A$97,'GIÁ XUẤT KHO'!$AW$4:$AW$97)*Q24 -> 2.4655598e+09 | BE24: =_xlfn.XLOOKUP($G24,'GIÁ XUẤT KHO'!$A$4:$A$97,'GIÁ XUẤT KHO'!$AW$4:$AW$97)*R24 -> 0 | BF24: =SUM(BC24:BE24) -> 2.4655598e+09 | BH24: =AJ24-BC24 -> 0 | BI24: =AK24-BD24 -> 3.3671221e+08 | BJ24: =AL24-BE24 -> 0 | BK24: =SUM(BH24:BJ24) -> 3.3671221e+08 | BM24: =SUM(BN24:BV24) -> 2.4655598e+09 | BN24: =SUMIFS('GIÁ XUẤT KHO'!AX$4:AX$97,'GIÁ XUẤT KHO'!$A$4:$A$97,$G24)*$S24 -> 1.4575333e+09 | BO24: =SUMIFS('GIÁ XUẤT KHO'!AY$4:AY$97,'GIÁ XUẤT KHO'!$A$4:$A$97,$G24)*$S24 -> 24217604 | BP24: =SUMIFS('GIÁ XUẤT KHO'!AZ$4:AZ$97,'GIÁ XUẤT KHO'!$A$4:$A$97,$G24)*$S24 -> 9866.9956 | BQ24: =SUMIFS('GIÁ XUẤT KHO'!BA$4:BA$97,'GIÁ XUẤT KHO'!$A$4:$A$97,$G24)*$S24 -> 1.6083751e+08 | BR24: =SUMIFS('GIÁ XUẤT KHO'!BB$4:BB$97,'GIÁ XUẤT KHO'!$A$4:$A$97,$G24)*$S24 -> 19037093 | BS24: =SUMIFS('GIÁ XUẤT KHO'!BC$4:BC$97,'GIÁ XUẤT KHO'!$A$4:$A$97,$G24)*$S24 -> 1.1509655e+08 | BT24: =SUMIFS('GIÁ XUẤT KHO'!BD$4:BD$97,'GIÁ XUẤT KHO'!$A$4:$A$97,$G24)*$S24 -> 1.8546927e+08 | BU24: =SUMIFS('GIÁ XUẤT KHO'!BE$4:BE$97,'GIÁ XUẤT KHO'!$A$4:$A$97,$G24)*$S24 -> 44526341 | BV24: =SUMIFS('GIÁ XUẤT KHO'!BF$4:BF$97,'GIÁ XUẤT KHO'!$A$4:$A$97,$G24)*$S24 -> 4.5883224e+08 | BW24: =BM24-BF24 -> 0
A25: =_xlfn.XLOOKUP($G25,MD_SKU[Mã SKU],MD_SKU[Link vào file BCQT]) -> Vảy rPET | B25: TC-026 | C25: XK | D25: 200332 | 110000507 | E25: 200332 | F25: OUTEIRINHO | G25: 110000507 | H25: Vảy FPET201 | K25: =SUMIFS('Working-T05-B1'!L$8:L$150,'Working-T05-B1'!$C$8:$C$150,$D25) -> 770000 | L25: {=SUMPRODUCT(Sales!$G$3:$H$100*(Sales!$B$3:$B$100=$D25))} -> 0 | M25: =K25-L25 -> 770000 | N25: =SUMIFS(Sales!$I$3:$I$100,Sales!$B$3:$B$100,$D25) -> 770000 | P25: =SUMIFS('Working-T05-B1'!O$8:O$150,'Working-T05-B1'!$C$8:$C$150,$D25) -> 0 | Q25: =MAX(0,MIN(K25,L25+N25)-P25) -> 770000 | R25: =MAX(0,L25+N25-SUM(P25:Q25)) -> 0 | S25: =SUM(P25:R25) -> 770000 | T25: =S25-(L25+N25) -> 0 | U25: =IFERROR(AE25/Z25,0) -> 0 | V25: =IFERROR(AF25/AA25,0) -> 0.84 | W25: =IF(AND(R25>0,V25>0),V25,0) -> 0 | X25: =IFERROR(IF($C25="XK",$AM25/$S25/$AC25,$AM25/$S25),0) -> 0.84 | AA25: =IF($C25="NĐ",1,EXR_FC05) -> 26300 | AB25: =IF($C25="NĐ",1,EXR_FC05) -> 26300 | AC25: =IFERROR(SUMPRODUCT(AJ25:AL25,Z25:AB25)/AM25,0) -> 26300 | AE25: =IFERROR(AJ25/P25,0) -> 0 | AF25: =IFERROR(AK25/Q25,0) -> 22092 | AG25: =W25*AB25 -> 0 | AJ25: =SUMIFS('Working-T05-B1'!AI$8:AI$150,'Working-T05-B1'!$C$8:$C$150,$D25) -> 0 | AK25: =SUMIFS('Working-T05-B1'!AJ$8:AJ$150,'Working-T05-B1'!$C$8:$C$150,$D25) -> 17010840000 | AL25: =R25*AG25 -> 0 | AM25: =SUM(AJ25:AL25) -> 17010840000 | AO25: =IFERROR(SUM(AQ25:AR25)/SUM(P25:Q25),0) -> 526 | AQ25: =SUMIFS('Working-T05-B1'!AP$8:AP$150,'Working-T05-B1'!$C$8:$C$150,$D25) -> 0 | AR25: =SUMIFS('Working-T05-B1'!AQ$8:AQ$150,'Working-T05-B1'!$C$8:$C$150,$D25) -> 405020000 | AS25: =AO25*R25 -> 0 | AT25: =SUM(AQ25:AS25) -> 405020000 | AV25: =IFERROR(BA25/S25,0) -> 0 | AX25: =SUMIFS('Working-T05-B1'!AW$8:AW$150,'Working-T05-B1'!$C$8:$C$150,$D25) -> 0 | AY25: =SUMIFS('Working-T05-B1'!AX$8:AX$150,'Working-T05-B1'!$C$8:$C$150,$D25) -> 0 | BA25: =SUM(AX25:AZ25) -> 0 | BC25: =_xlfn.XLOOKUP($G25,'GIÁ XUẤT KHO'!$A$4:$A$97,'GIÁ XUẤT KHO'!$AW$4:$AW$97)*P25 -> 0 | BD25: =_xlfn.XLOOKUP($G25,'GIÁ XUẤT KHO'!$A$4:$A$97,'GIÁ XUẤT KHO'!$AW$4:$AW$97)*Q25 -> 1.9788494e+10 | BE25: =_xlfn.XLOOKUP($G25,'GIÁ XUẤT KHO'!$A$4:$A$97,'GIÁ XUẤT KHO'!$AW$4:$AW$97)*R25 -> 0 | BF25: =SUM(BC25:BE25) -> 1.9788494e+10 | BH25: =AJ25-BC25 -> 0 | BI25: =AK25-BD25 -> -2.777654e+09 | BJ25: =AL25-BE25 -> 0 | BK25: =SUM(BH25:BJ25) -> -2.777654e+09 | BM25: =SUM(BN25:BV25) -> 1.9788494e+10 | BN25: =SUMIFS('GIÁ XUẤT KHO'!AX$4:AX$97,'GIÁ XUẤT KHO'!$A$4:$A$97,$G25)*$S25 -> 1.7202388e+10 | BO25: =SUMIFS('GIÁ XUẤT KHO'!AY$4:AY$97,'GIÁ XUẤT KHO'!$A$4:$A$97,$G25)*$S25 -> 27108757 | BP25: =SUMIFS('GIÁ XUẤT KHO'!AZ$4:AZ$97,'GIÁ XUẤT KHO'!$A$4:$A$97,$G25)*$S25 -> 0 | BQ25: =SUMIFS('GIÁ XUẤT KHO'!BA$4:BA$97,'GIÁ XUẤT KHO'!$A$4:$A$97,$G25)*$S25 -> 1.2277351e+08 | BR25: =SUMIFS('GIÁ XUẤT KHO'!BB$4:BB$97,'GIÁ XUẤT KHO'!$A$4:$A$97,$G25)*$S25 -> 0 | BS25: =SUMIFS('GIÁ XUẤT KHO'!BC$4:BC$97,'GIÁ XUẤT KHO'!$A$4:$A$97,$G25)*$S25 -> 4.694981e+08 | BT25: =SUMIFS('GIÁ XUẤT KHO'!BD$4:BD$97,'GIÁ XUẤT KHO'!$A$4:$A$97,$G25)*$S25 -> 670236875 | BU25: =SUMIFS('GIÁ XUẤT KHO'!BE$4:BE$97,'GIÁ XUẤT KHO'!$A$4:$A$97,$G25)*$S25 -> 73897320 | BV25: =SUMIFS('GIÁ XUẤT KHO'!BF$4:BF$97,'GIÁ XUẤT KHO'!$A$4:$A$97,$G25)*$S25 -> 1.2225918e+09 | BW25: =BM25-BF25 -> 0
A26: =_xlfn.XLOOKUP($G26,MD_SKU[Mã SKU],MD_SKU[Link vào file BCQT]) -> Hạt rPET | B26: TC-026 | C26: XK | D26: 200330 | 110000355 | E26: 200330 | F26: Fega Polymers Member | G26: 110000355 | H26: Hạt nhựa rPET iSS01G 1 | K26: =SUMIFS('Working-T05-B1'!L$8:L$150,'Working-T05-B1'!$C$8:$C$150,$D26) -> 0 | L26: {=SUMPRODUCT(Sales!$G$3:$H$100*(Sales!$B$3:$B$100=$D26))} -> 0 | M26: =K26-L26 -> 0 | N26: =SUMIFS(Sales!$I$3:$I$100,Sales!$B$3:$B$100,$D26) -> 0 | P26: =SUMIFS('Working-T05-B1'!O$8:O$150,'Working-T05-B1'!$C$8:$C$150,$D26) -> 0 | Q26: =MAX(0,MIN(K26,L26+N26)-P26) -> 0 | R26: =MAX(0,L26+N26-SUM(P26:Q26)) -> 0 | S26: =SUM(P26:R26) -> 0 | T26: =S26-(L26+N26) -> 0 | U26: =IFERROR(AE26/Z26,0) -> 0 | V26: =IFERROR(AF26/AA26,0) -> 0 | W26: =IF(AND(R26>0,V26>0),V26,0) -> 0 | X26: =IFERROR(IF($C26="XK",$AM26/$S26/$AC26,$AM26/$S26),0) -> 0 | AA26: =IF($C26="NĐ",1,EXR_FC05) -> 26300 | AB26: =IF($C26="NĐ",1,EXR_FC05) -> 26300 | AC26: =IFERROR(SUMPRODUCT(AJ26:AL26,Z26:AB26)/AM26,0) -> 0 | AE26: =IFERROR(AJ26/P26,0) -> 0 | AF26: =IFERROR(AK26/Q26,0) -> 0 | AG26: =W26*AB26 -> 0 | AJ26: =SUMIFS('Working-T05-B1'!AI$8:AI$150,'Working-T05-B1'!$C$8:$C$150,$D26) -> 0 | AK26: =SUMIFS('Working-T05-B1'!AJ$8:AJ$150,'Working-T05-B1'!$C$8:$C$150,$D26) -> 0 | AL26: =R26*AG26 -> 0 | AM26: =SUM(AJ26:AL26) -> 0 | AO26: =IFERROR(SUM(AQ26:AR26)/SUM(P26:Q26),0) -> 0 | AQ26: =SUMIFS('Working-T05-B1'!AP$8:AP$150,'Working-T05-B1'!$C$8:$C$150,$D26) -> 0 | AR26: =SUMIFS('Working-T05-B1'!AQ$8:AQ$150,'Working-T05-B1'!$C$8:$C$150,$D26) -> 0 | AS26: =AO26*R26 -> 0 | AT26: =SUM(AQ26:AS26) -> 0 | AV26: =IFERROR(BA26/S26,0) -> 0 | AX26: =SUMIFS('Working-T05-B1'!AW$8:AW$150,'Working-T05-B1'!$C$8:$C$150,$D26) -> 0 | AY26: =SUMIFS('Working-T05-B1'!AX$8:AX$150,'Working-T05-B1'!$C$8:$C$150,$D26) -> 0 | BA26: =SUM(AX26:AZ26) -> 0 | BC26: =_xlfn.XLOOKUP($G26,'GIÁ XUẤT KHO'!$A$4:$A$97,'GIÁ XUẤT KHO'!$AW$4:$AW$97)*P26 -> 0 | BD26: =_xlfn.XLOOKUP($G26,'GIÁ XUẤT KHO'!$A$4:$A$97,'GIÁ XUẤT KHO'!$AW$4:$AW$97)*Q26 -> 0 | BE26: =_xlfn.XLOOKUP($G26,'GIÁ XUẤT KHO'!$A$4:$A$97,'GIÁ XUẤT KHO'!$AW$4:$AW$97)*R26 -> 0 | BF26: =SUM(BC26:BE26) -> 0 | BH26: =AJ26-BC26 -> 0 | BI26: =AK26-BD26 -> 0 | BJ26: =AL26-BE26 -> 0 | BK26: =SUM(BH26:BJ26) -> 0 | BM26: =SUM(BN26:BV26) -> 0 | BN26: =SUMIFS('GIÁ XUẤT KHO'!AX$4:AX$97,'GIÁ XUẤT KHO'!$A$4:$A$97,$G26)*$S26 -> 0 | BO26: =SUMIFS('GIÁ XUẤT KHO'!AY$4:AY$97,'GIÁ XUẤT KHO'!$A$4:$A$97,$G26)*$S26 -> 0 | BP26: =SUMIFS('GIÁ XUẤT KHO'!AZ$4:AZ$97,'GIÁ XUẤT KHO'!$A$4:$A$97,$G26)*$S26 -> 0 | BQ26: =SUMIFS('GIÁ XUẤT KHO'!BA$4:BA$97,'GIÁ XUẤT KHO'!$A$4:$A$97,$G26)*$S26 -> 0 | BR26: =SUMIFS('GIÁ XUẤT KHO'!BB$4:BB$97,'GIÁ XUẤT KHO'!$A$4:$A$97,$G26)*$S26 -> 0 | BS26: =SUMIFS('GIÁ XUẤT KHO'!BC$4:BC$97,'GIÁ XUẤT KHO'!$A$4:$A$97,$G26)*$S26 -> 0 | BT26: =SUMIFS('GIÁ XUẤT KHO'!BD$4:BD$97,'GIÁ XUẤT KHO'!$A$4:$A$97,$G26)*$S26 -> 0 | BU26: =SUMIFS('GIÁ XUẤT KHO'!BE$4:BE$97,'GIÁ XUẤT KHO'!$A$4:$A$97,$G26)*$S26 -> 0 | BV26: =SUMIFS('GIÁ XUẤT KHO'!BF$4:BF$97,'GIÁ XUẤT KHO'!$A$4:$A$97,$G26)*$S26 -> 0 | BW26: =BM26-BF26 -> 0
A27: =_xlfn.XLOOKUP($G27,MD_SKU[Mã SKU],MD_SKU[Link vào file BCQT]) -> Phó sản | B27: TC-026 | C27: NĐ | D27: 105324 | 160012951 | E27: 105324 | F27: NHỰA TRƯỜNG AN | G27: 160012951 | H27: Vảy HD Ép Hỗn Hợp SSR | K27: =SUMIFS('Working-T05-B1'!L$8:L$150,'Working-T05-B1'!$C$8:$C$150,$D27) -> 11266 | L27: {=SUMPRODUCT(Sales!$G$3:$H$100*(Sales!$B$3:$B$100=$D27))} -> 0 | M27: =K27-L27 -> 11266 | N27: =SUMIFS(Sales!$I$3:$I$100,Sales!$B$3:$B$100,$D27) -> 0 | P27: =SUMIFS('Working-T05-B1'!O$8:O$150,'Working-T05-B1'!$C$8:$C$150,$D27) -> 0 | Q27: =MAX(0,MIN(K27,L27+N27)-P27) -> 0 | R27: =MAX(0,L27+N27-SUM(P27:Q27)) -> 0 | S27: =SUM(P27:R27) -> 0 | T27: =S27-(L27+N27) -> 0 | U27: =IFERROR(AE27/Z27,0) -> 0 | V27: =IFERROR(AF27/AA27,0) -> 0 | W27: =IF(AND(R27>0,V27>0),V27,0) -> 0 | X27: =IFERROR(IF($C27="XK",$AM27/$S27/$AC27,$AM27/$S27),0) -> 0 | AA27: =IF($C27="NĐ",1,EXR_FC05) -> 1 | AB27: =IF($C27="NĐ",1,EXR_FC05) -> 1 | AC27: =IFERROR(SUMPRODUCT(AJ27:AL27,Z27:AB27)/AM27,0) -> 0 | AE27: =IFERROR(AJ27/P27,0) -> 0 | AF27: =IFERROR(AK27/Q27,0) -> 0 | AG27: =W27*AB27 -> 0 | AJ27: =SUMIFS('Working-T05-B1'!AI$8:AI$150,'Working-T05-B1'!$C$8:$C$150,$D27) -> 0 | AK27: =SUMIFS('Working-T05-B1'!AJ$8:AJ$150,'Working-T05-B1'!$C$8:$C$150,$D27) -> 0 | AL27: =R27*AG27 -> 0 | AM27: =SUM(AJ27:AL27) -> 0 | AO27: =IFERROR(SUM(AQ27:AR27)/SUM(P27:Q27),0) -> 0 | AQ27: =SUMIFS('Working-T05-B1'!AP$8:AP$150,'Working-T05-B1'!$C$8:$C$150,$D27) -> 0 | AR27: =SUMIFS('Working-T05-B1'!AQ$8:AQ$150,'Working-T05-B1'!$C$8:$C$150,$D27) -> 0 | AS27: =AO27*R27 -> 0 | AT27: =SUM(AQ27:AS27) -> 0 | AV27: =IFERROR(BA27/S27,0) -> 0 | AX27: =SUMIFS('Working-T05-B1'!AW$8:AW$150,'Working-T05-B1'!$C$8:$C$150,$D27) -> 0 | AY27: =SUMIFS('Working-T05-B1'!AX$8:AX$150,'Working-T05-B1'!$C$8:$C$150,$D27) -> 0 | BA27: =SUM(AX27:AZ27) -> 0 | BC27: =_xlfn.XLOOKUP($G27,'GIÁ XUẤT KHO'!$A$4:$A$97,'GIÁ XUẤT KHO'!$AW$4:$AW$97)*P27 -> 0 | BD27: =_xlfn.XLOOKUP($G27,'GIÁ XUẤT KHO'!$A$4:$A$97,'GIÁ XUẤT KHO'!$AW$4:$AW$97)*Q27 -> 0 | BE27: =_xlfn.XLOOKUP($G27,'GIÁ XUẤT KHO'!$A$4:$A$97,'GIÁ XUẤT KHO'!$AW$4:$AW$97)*R27 -> 0 | BF27: =SUM(BC27:BE27) -> 0 | BH27: =AJ27-BC27 -> 0 | BI27: =AK27-BD27 -> 0 | BJ27: =AL27-BE27 -> 0 | BK27: =SUM(BH27:BJ27) -> 0 | BM27: =SUM(BN27:BV27) -> 0 | BN27: =SUMIFS('GIÁ XUẤT KHO'!AX$4:AX$97,'GIÁ XUẤT KHO'!$A$4:$A$97,$G27)*$S27 -> 0 | BO27: =SUMIFS('GIÁ XUẤT KHO'!AY$4:AY$97,'GIÁ XUẤT KHO'!$A$4:$A$97,$G27)*$S27 -> 0 | BP27: =SUMIFS('GIÁ XUẤT KHO'!AZ$4:AZ$97,'GIÁ XUẤT KHO'!$A$4:$A$97,$G27)*$S27 -> 0 | BQ27: =SUMIFS('GIÁ XUẤT KHO'!BA$4:BA$97,'GIÁ XUẤT KHO'!$A$4:$A$97,$G27)*$S27 -> 0 | BR27: =SUMIFS('GIÁ XUẤT KHO'!BB$4:BB$97,'GIÁ XUẤT KHO'!$A$4:$A$97,$G27)*$S27 -> 0 | BS27: =SUMIFS('GIÁ XUẤT KHO'!BC$4:BC$97,'GIÁ XUẤT KHO'!$A$4:$A$97,$G27)*$S27 -> 0 | BT27: =SUMIFS('GIÁ XUẤT KHO'!BD$4:BD$97,'GIÁ XUẤT KHO'!$A$4:$A$97,$G27)*$S27 -> 0 | BU27: =SUMIFS('GIÁ XUẤT KHO'!BE$4:BE$97,'GIÁ XUẤT KHO'!$A$4:$A$97,$G27)*$S27 -> 0 | BV27: =SUMIFS('GIÁ XUẤT KHO'!BF$4:BF$97,'GIÁ XUẤT KHO'!$A$4:$A$97,$G27)*$S27 -> 0 | BW27: =BM27-BF27 -> 0
A28: =_xlfn.XLOOKUP($G28,MD_SKU[Mã SKU],MD_SKU[Link vào file BCQT]) -> Phó sản | B28: TC-026 | C28: NĐ | D28: 105324 | 160012611 | E28: 105324 | F28: NHỰA TRƯỜNG AN | G28: 160012611 | H28: Vảy HD Ép Hỗn Hợp ST | K28: =SUMIFS('Working-T05-B1'!L$8:L$150,'Working-T05-B1'!$C$8:$C$150,$D28) -> 25000 | L28: {=SUMPRODUCT(Sales!$G$3:$H$100*(Sales!$B$3:$B$100=$D28))} -> 0 | M28: =K28-L28 -> 25000 | N28: =SUMIFS(Sales!$I$3:$I$100,Sales!$B$3:$B$100,$D28) -> 0 | P28: =SUMIFS('Working-T05-B1'!O$8:O$150,'Working-T05-B1'!$C$8:$C$150,$D28) -> 0 | Q28: =MAX(0,MIN(K28,L28+N28)-P28) -> 0 | R28: =MAX(0,L28+N28-SUM(P28:Q28)) -> 0 | S28: =SUM(P28:R28) -> 0 | T28: =S28-(L28+N28) -> 0 | U28: =IFERROR(AE28/Z28,0) -> 0 | V28: =IFERROR(AF28/AA28,0) -> 0 | W28: =IF(AND(R28>0,V28>0),V28,0) -> 0 | X28: =IFERROR(IF($C28="XK",$AM28/$S28/$AC28,$AM28/$S28),0) -> 0 | AA28: =IF($C28="NĐ",1,EXR_FC05) -> 1 | AB28: =IF($C28="NĐ",1,EXR_FC05) -> 1 | AC28: =IFERROR(SUMPRODUCT(AJ28:AL28,Z28:AB28)/AM28,0) -> 0 | AE28: =IFERROR(AJ28/P28,0) -> 0 | AF28: =IFERROR(AK28/Q28,0) -> 0 | AG28: =W28*AB28 -> 0 | AJ28: =SUMIFS('Working-T05-B1'!AI$8:AI$150,'Working-T05-B1'!$C$8:$C$150,$D28) -> 0 | AK28: =SUMIFS('Working-T05-B1'!AJ$8:AJ$150,'Working-T05-B1'!$C$8:$C$150,$D28) -> 0 | AL28: =R28*AG28 -> 0 | AM28: =SUM(AJ28:AL28) -> 0 | AO28: =IFERROR(SUM(AQ28:AR28)/SUM(P28:Q28),0) -> 0 | AQ28: =SUMIFS('Working-T05-B1'!AP$8:AP$150,'Working-T05-B1'!$C$8:$C$150,$D28) -> 0 | AR28: =SUMIFS('Working-T05-B1'!AQ$8:AQ$150,'Working-T05-B1'!$C$8:$C$150,$D28) -> 0 | AS28: =AO28*R28 -> 0 | AT28: =SUM(AQ28:AS28) -> 0 | AV28: =IFERROR(BA28/S28,0) -> 0 | AX28: =SUMIFS('Working-T05-B1'!AW$8:AW$150,'Working-T05-B1'!$C$8:$C$150,$D28) -> 0 | AY28: =SUMIFS('Working-T05-B1'!AX$8:AX$150,'Working-T05-B1'!$C$8:$C$150,$D28) -> 0 | BA28: =SUM(AX28:AZ28) -> 0 | BC28: =_xlfn.XLOOKUP($G28,'GIÁ XUẤT KHO'!$A$4:$A$97,'GIÁ XUẤT KHO'!$AW$4:$AW$97)*P28 -> 0 | BD28: =_xlfn.XLOOKUP($G28,'GIÁ XUẤT KHO'!$A$4:$A$97,'GIÁ XUẤT KHO'!$AW$4:$AW$97)*Q28 -> 0 | BE28: =_xlfn.XLOOKUP($G28,'GIÁ XUẤT KHO'!$A$4:$A$97,'GIÁ XUẤT KHO'!$AW$4:$AW$97)*R28 -> 0 | BF28: =SUM(BC28:BE28) -> 0 | BH28: =AJ28-BC28 -> 0 | BI28: =AK28-BD28 -> 0 | BJ28: =AL28-BE28 -> 0 | BK28: =SUM(BH28:BJ28) -> 0 | BM28: =SUM(BN28:BV28) -> 0 | BN28: =SUMIFS('GIÁ XUẤT KHO'!AX$4:AX$97,'GIÁ XUẤT KHO'!$A$4:$A$97,$G28)*$S28 -> 0 | BO28: =SUMIFS('GIÁ XUẤT KHO'!AY$4:AY$97,'GIÁ XUẤT KHO'!$A$4:$A$97,$G28)*$S28 -> 0 | BP28: =SUMIFS('GIÁ XUẤT KHO'!AZ$4:AZ$97,'GIÁ XUẤT KHO'!$A$4:$A$97,$G28)*$S28 -> 0 | BQ28: =SUMIFS('GIÁ XUẤT KHO'!BA$4:BA$97,'GIÁ XUẤT KHO'!$A$4:$A$97,$G28)*$S28 -> 0 | BR28: =SUMIFS('GIÁ XUẤT KHO'!BB$4:BB$97,'GIÁ XUẤT KHO'!$A$4:$A$97,$G28)*$S28 -> 0 | BS28: =SUMIFS('GIÁ XUẤT KHO'!BC$4:BC$97,'GIÁ XUẤT KHO'!$A$4:$A$97,$G28)*$S28 -> 0 | BT28: =SUMIFS('GIÁ XUẤT KHO'!BD$4:BD$97,'GIÁ XUẤT KHO'!$A$4:$A$97,$G28)*$S28 -> 0 | BU28: =SUMIFS('GIÁ XUẤT KHO'!BE$4:BE$97,'GIÁ XUẤT KHO'!$A$4:$A$97,$G28)*$S28 -> 0 | BV28: =SUMIFS('GIÁ XUẤT KHO'!BF$4:BF$97,'GIÁ XUẤT KHO'!$A$4:$A$97,$G28)*$S28 -> 0 | BW28: =BM28-BF28 -> 0
