Workbook

Sheet Thong tin
A1: CÔNG TY CỔ PHẦN NHỰA TÁI CHẾ DUY TÂN VĨNH LONG
A2: Địa chỉ: Thửa đất số 838, tờ bản đồ số 6, tổ 4, ấp Tân Thuận, phường Tân Hạnh, tỉnh Vĩnh Long
A3: Mã số thuế: 1501162229
A4: Deadline ngày 5 tây hàng tháng
B6: Năm tài chính hiện tại | C6: 2026
B7: Năm trước | C7: =C6-1 -> 2025
B9: Tháng báo cáo hiện tại | C9: 5
B12: KẾ TOÁN TRƯỞNG
B13: Lê Thùy Ngân
B15: GIÁM ĐỐC TÀI CHÍNH
B16: Nguyễn Bảo Quốc
B18: GIÁM ĐỐC
B19: Trần Thị Kim Thanh

Sheet BIA
B29: THÁNG 05 NĂM 2026
B50: Vĩnh Long, Ngày 31 tháng 05 năm 2026

Sheet Index
A1: ='Thong tin'!A1 -> CÔNG TY CỔ PHẦN NHỰA TÁI CHẾ DUY TÂN VĨNH LONG | I1: BÁO CÁO TÀI CHÍNH
A2: ='Thong tin'!A2 -> Địa chỉ: Thửa đất số 838, tờ bản đồ số 6, tổ 4, ấp Tân Thuận, phường Tân Hạnh, tỉnh Vĩnh Long
A10: ="BÁO CÁO TÀI CHÍNH THÁNG "&'Thong tin'!C9&" NĂM 2026" -> BÁO CÁO TÀI CHÍNH THÁNG 5 NĂM 2026 | I10: Trang
A12: BÁO CÁO CỦA BAN GIÁM ĐỐC | I12: 2 - 3
A13: BÁO CÁO KIỂM TOÁN | I13: 4 - 4
A14: - Bảng cân đối kế toán | I14: 1 - 4
A15: - Báo cáo kết quả hoạt động kinh doanh | I15: 5
A16: - Báo cáo lưu chuyển tiền tệ | I16: 6 - 7
A17: - Bản thuyết minh báo cáo tài chính | I17: 11 - 31
A30: (Báo cáo tài chính được lập và trình bày theo Quyết định số 15/2006/QĐ-BTC ngày 20/03/2006
A31: của Bộ trưởng Bộ Tài Chính)

Sheet THTC in
A1: ='Thong tin'!$A$1 -> CÔNG TY CỔ PHẦN NHỰA TÁI CHẾ DUY TÂN VĨNH LONG
A2: ='Thong tin'!$A$2 -> Địa chỉ: Thửa đất số 838, tờ bản đồ số 6, tổ 4, ấp Tân Thuận, phường Tân Hạnh, tỉnh Vĩnh Long
A4: BÁO CÁO TÌNH HÌNH TÀI CHÍNH
A5: ="Năm " & 'Thong tin'!$C$6 -> Năm 2026
C6: ='KQKD in'!G6 -> ĐVT: VNĐ
A7: TÀI SẢN | B7: ="Số cuối tháng"&" "&$D$7 -> Số cuối tháng 5 | C7: ="Số dư đầu năm " & 'Thong tin'!$C$6 -> Số dư đầu năm 2026 | D7: ='Thong tin'!C9 -> 5
A8: A . TÀI SẢN NGẮN HẠN | B8: =B10+B14+B22+B31+B40 -> 100879225044 | C8: =C10+C14+C22+C31+C40 -> 5910557105
A10: I. Tiền và các khoản tương đương tiền | B10: =SUM(B11:B12) -> 95272491003 | C10: =SUM(C11:C12) -> 403528506
A11: 1. Tiền | B11: =OFFSET('Tinh hinh tai chinh'!$BL6,0,'THTC in'!$D$7 - 1) -> 1272491003 | C11: ='Tinh hinh tai chinh'!BK6 -> 403528506
A12: 2. Các khoản tương đương tiền | B12: =OFFSET('Tinh hinh tai chinh'!$BL7,0,'THTC in'!$D$7 - 1) -> 94000000000 | C12: ='Tinh hinh tai chinh'!BK7 -> 0
A14: II. Các khoản đầu tư tài chính ngắn hạn | B14: =SUM(B15:B20) -> 5500000000 | C14: =SUM(C15:C20) -> 5500000000
A15: 1.Chứng khoán kinh doanh | B15: =OFFSET('Tinh hinh tai chinh'!$BL9,0,'THTC in'!$D$7 - 1) -> 0 | C15: ='Tinh hinh tai chinh'!BK9 -> 0
A16: 2.Dự phòng giảm giá chứng khoán kinh doanh (*) | B16: =OFFSET('Tinh hinh tai chinh'!$BL10,0,'THTC in'!$D$7 - 1) -> 0 | C16: ='Tinh hinh tai chinh'!BK10 -> 0
A17: 3.Đầu tư nắm giữ đến ngày đáo hạn ngắn hạn | B17: =OFFSET('Tinh hinh tai chinh'!$BL11,0,'THTC in'!$D$7 - 1) -> 5500000000 | C17: ='Tinh hinh tai chinh'!BK11 -> 5500000000
A18: 4.Dự phòng đầu tư nắm giữ đến ngày đáo hạn ngắn hạn (*) | B18: =OFFSET('Tinh hinh tai chinh'!$BL12,0,'THTC in'!$D$7 - 1) -> 0 | C18: ='Tinh hinh tai chinh'!BK12 -> 0
A19: 5.Đầu tư ngắn hạn khác | B19: =OFFSET('Tinh hinh tai chinh'!$BL13,0,'THTC in'!$D$7 - 1) -> 0 | C19: ='Tinh hinh tai chinh'!BK13 -> 0
A20: 6.Dự phòng tổn thất các khoản đầu tư ngắn hạn khác (*) | B20: =OFFSET('Tinh hinh tai chinh'!$BL14,0,'THTC in'!$D$7 - 1) -> 0 | C20: ='Tinh hinh tai chinh'!BK14 -> 0
A22: III. Các khoản phải thu ngắn hạn | B22: =SUM(B23:B29) -> 89087960 | C22: =SUM(C23:C29) -> 0
A23: 1.Phải thu ngắn hạn của khách hàng | B23: =OFFSET('Tinh hinh tai chinh'!$BL16,0,'THTC in'!$D$7 - 1) -> 0 | C23: ='Tinh hinh tai chinh'!BK16 -> 0
A24: 2.Trả trước cho người bán ngắn hạn | B24: =OFFSET('Tinh hinh tai chinh'!$BL17,0,'THTC in'!$D$7 - 1) -> 89087960 | C24: ='Tinh hinh tai chinh'!BK17 -> 0
A25: 3.Phải thu nội bộ ngắn hạn | B25: =OFFSET('Tinh hinh tai chinh'!$BL18,0,'THTC in'!$D$7 - 1) -> 0 | C25: ='Tinh hinh tai chinh'!BK18 -> 0
A26: 4.Phải thu theo tiến độ hợp đồng xây dựng | B26: =OFFSET('Tinh hinh tai chinh'!$BL19,0,'THTC in'!$D$7 - 1) -> 0 | C26: ='Tinh hinh tai chinh'!BK19 -> 0
A27: 5.Phải thu ngắn hạn khác | B27: =OFFSET('Tinh hinh tai chinh'!$BL20,0,'THTC in'!$D$7 - 1) -> 0 | C27: ='Tinh hinh tai chinh'!BK20 -> 0
A28: 6.Dự phòng phải thu ngắn hạn khó đòi (*) | B28: =OFFSET('Tinh hinh tai chinh'!$BL21,0,'THTC in'!$D$7 - 1) -> 0 | C28: ='Tinh hinh tai chinh'!BK21 -> 0
A29: 7.Tài sản thiếu chờ xử lý | B29: =OFFSET('Tinh hinh tai chinh'!$BL22,0,'THTC in'!$D$7 - 1) -> 0 | C29: ='Tinh hinh tai chinh'!BK22 -> 0
A31: IV. Hàng tồn kho | B31: =SUM(B32:B33) -> 0 | C31: =SUM(C32:C33) -> 0
A32: 1. Hàng tồn kho | B32: =OFFSET('Tinh hinh tai chinh'!$BL24,0,'THTC in'!$D$7 - 1) -> 0 | C32: ='Tinh hinh tai chinh'!BK24 -> 0
A33: 2. Dự phòng giảm giá hàng tồn kho (*) | B33: =OFFSET('Tinh hinh tai chinh'!$BL25,0,'THTC in'!$D$7 - 1) -> 0 | C33: ='Tinh hinh tai chinh'!BK25 -> 0
A35: V. Tài sản sinh học ngắn hạn | B35: =SUM(B36:B38) -> 0 | C35: =SUM(C36:C38) -> 0
A36: 1.Súc vật nuôi lấy sản phẩm một lần ngắn hạn | B36: =OFFSET('Tinh hinh tai chinh'!$BL27,0,'THTC in'!$D$7 - 1) -> 0 | C36: ='Tinh hinh tai chinh'!BK27 -> 0
A37: 2.Cây trồng theo mùa vụ hoặc lấy sản phẩm một lần ngắn hạn | B37: =OFFSET('Tinh hinh tai chinh'!$BL28,0,'THTC in'!$D$7 - 1) -> 0 | C37: ='Tinh hinh tai chinh'!BK28 -> 0
A38: 3.Dự phòng tổn thất tài sản sinh học ngắn hạn (*) | B38: =OFFSET('Tinh hinh tai chinh'!$BL29,0,'THTC in'!$D$7 - 1) -> 0 | C38: ='Tinh hinh tai chinh'!BK29 -> 0
A40: VI. Tài sản ngắn hạn khác | B40: =SUM(B41:B45) -> 17646081 | C40: =SUM(C41:C45) -> 7028599
A41: 1.Chi phí chờ phân bổ ngắn hạn | B41: =OFFSET('Tinh hinh tai chinh'!$BL31,0,'THTC in'!$D$7 - 1) -> 0 | C41: ='Tinh hinh tai chinh'!BK31 -> 0
A42: 2.Thuế GTGT được khấu trừ | B42: =OFFSET('Tinh hinh tai chinh'!$BL32,0,'THTC in'!$D$7 - 1) -> 17646081 | C42: ='Tinh hinh tai chinh'!BK32 -> 7028599
A43: 3.Thuế và các khoản khác phải thu Nhà nước | B43: =OFFSET('Tinh hinh tai chinh'!$BL33,0,'THTC in'!$D$7 - 1) -> 0 | C43: ='Tinh hinh tai chinh'!BK33 -> 0
A44: 4.Giao dịch mua bán lại trái phiếu Chính phủ | B44: =OFFSET('Tinh hinh tai chinh'!$BL34,0,'THTC in'!$D$7 - 1) -> 0 | C44: ='Tinh hinh tai chinh'!BK34 -> 0
A45: 5.Tài sản ngắn hạn khác | B45: =OFFSET('Tinh hinh tai chinh'!$BL35,0,'THTC in'!$D$7 - 1) -> 0 | C45: ='Tinh hinh tai chinh'!BK35 -> 0
A47: B. TÀI SẢN DÀI HẠN | B47: =B48+B58+B79+B87+B95+B83 -> 196965733 | C47: =C48+C58+C79+C87+C95+C83 -> 87557481
A48: I.Các khoản phải thu dài hạn | B48: =SUM(B49:B54) -> 0 | C48: =SUM(C49:C54) -> 0
...

Sheet KQKD in
A1: ='Thong tin'!$A$1 -> CÔNG TY CỔ PHẦN NHỰA TÁI CHẾ DUY TÂN VĨNH LONG
A2: ='Thong tin'!$A$2 -> Địa chỉ: Thửa đất số 838, tờ bản đồ số 6, tổ 4, ấp Tân Thuận, phường Tân Hạnh, tỉnh Vĩnh Long
A4: BÁO CÁO KẾT QUẢ HOẠT ĐỘNG KINH DOANH
A5: ="Năm " & 'Thong tin'!$C$6 -> Năm 2026
G6: ĐVT: VNĐ
A8: Chỉ tiêu | D8: ="Tháng "&'Thong tin'!$C$9 -> Tháng 5 | F8: ="Lũy kế"&" "&'Thong tin'!$C$9 &" "&"tháng" -> Lũy kế 5 tháng
D9: ="Năm " & 'Thong tin'!$C$6 -> Năm 2026 | E9: ="Năm " & 'Thong tin'!$C$7 -> Năm 2025 | F9: ="Năm " & 'Thong tin'!$C$6 -> Năm 2026 | G9: ="Năm " & 'Thong tin'!$C$7 -> Năm 2025
A10: 1. | B10: Doanh thu bán hàng và cung cấp dịch vụ | D10: =OFFSET('Ket qua kinh doanh'!$BL5,0,'Thong tin'!$C$9 - 1) -> 0 | E10: =OFFSET('Ket qua kinh doanh'!$AZ5,0,'Thong tin'!$C$9 - 1) -> 0 | F10: =SUM(OFFSET('Ket qua kinh doanh'!$BL5,0,0,1,'Thong tin'!$C$9)) -> 0 | G10: =SUM(OFFSET('Ket qua kinh doanh'!$AZ5,0,0,1,'Thong tin'!$C$9)) -> 0
A11: 2. | B11: Các khoản giảm trừ doanh thu | D11: =OFFSET('Ket qua kinh doanh'!$BL6,0,'Thong tin'!$C$9 - 1) -> 0 | E11: =OFFSET('Ket qua kinh doanh'!$AZ6,0,'Thong tin'!$C$9 - 1) -> 0 | F11: =SUM(OFFSET('Ket qua kinh doanh'!$BL6,0,0,1,'Thong tin'!$C$9)) -> 0 | G11: =SUM(OFFSET('Ket qua kinh doanh'!$AZ6,0,0,1,'Thong tin'!$C$9)) -> 0
A12: 3. | B12: Doanh thu thuần về bán hàng và cung cấp dịch vụ | D12: =OFFSET('Ket qua kinh doanh'!$BL7,0,'Thong tin'!$C$9 - 1) -> 0 | E12: =OFFSET('Ket qua kinh doanh'!$AZ7,0,'Thong tin'!$C$9 - 1) -> 0 | F12: =SUM(OFFSET('Ket qua kinh doanh'!$BL7,0,0,1,'Thong tin'!$C$9)) -> 0 | G12: =SUM(OFFSET('Ket qua kinh doanh'!$AZ7,0,0,1,'Thong tin'!$C$9)) -> 0
A13: 4. | B13: Giá vốn hàng bán | D13: =OFFSET('Ket qua kinh doanh'!$BL8,0,'Thong tin'!$C$9 - 1) -> 0 | E13: =OFFSET('Ket qua kinh doanh'!$AZ8,0,'Thong tin'!$C$9 - 1) -> 0 | F13: =SUM(OFFSET('Ket qua kinh doanh'!$BL8,0,0,1,'Thong tin'!$C$9)) -> 0 | G13: =SUM(OFFSET('Ket qua kinh doanh'!$AZ8,0,0,1,'Thong tin'!$C$9)) -> 0
A14: 5. | B14: Lợi nhuận gộp về bán hàng và cung cấp dịch vụ | D14: =OFFSET('Ket qua kinh doanh'!$BL9,0,'Thong tin'!$C$9 - 1) -> 0 | E14: =OFFSET('Ket qua kinh doanh'!$AZ9,0,'Thong tin'!$C$9 - 1) -> 0 | F14: =SUM(OFFSET('Ket qua kinh doanh'!$BL9,0,0,1,'Thong tin'!$C$9)) -> 0 | G14: =SUM(OFFSET('Ket qua kinh doanh'!$AZ9,0,0,1,'Thong tin'!$C$9)) -> 0
A15: 6. | B15: Lãi/lỗ của hoạt động bán, thanh lý bất động sản đầu tư | D15: =OFFSET('Ket qua kinh doanh'!$BL10,0,'Thong tin'!$C$9 - 1) -> 0 | E15: =OFFSET('Ket qua kinh doanh'!$AZ10,0,'Thong tin'!$C$9 - 1) -> 0 | F15: =SUM(OFFSET('Ket qua kinh doanh'!$BL10,0,0,1,'Thong tin'!$C$9)) -> 0 | G15: =SUM(OFFSET('Ket qua kinh doanh'!$AZ10,0,0,1,'Thong tin'!$C$9)) -> 0
A16: 7. | B16: Doanh thu hoạt động tài chính | D16: =OFFSET('Ket qua kinh doanh'!$BL11,0,'Thong tin'!$C$9 - 1) -> 10459 | E16: =OFFSET('Ket qua kinh doanh'!$AZ11,0,'Thong tin'!$C$9 - 1) -> 0 | F16: =SUM(OFFSET('Ket qua kinh doanh'!$BL11,0,0,1,'Thong tin'!$C$9)) -> 1101243809 | G16: =SUM(OFFSET('Ket qua kinh doanh'!$AZ11,0,0,1,'Thong tin'!$C$9)) -> 0
A17: 8. | B17: Chi phí tài chính | D17: =OFFSET('Ket qua kinh doanh'!$BL12,0,'Thong tin'!$C$9 - 1) -> 0 | E17: =OFFSET('Ket qua kinh doanh'!$AZ12,0,'Thong tin'!$C$9 - 1) -> 0 | F17: =SUM(OFFSET('Ket qua kinh doanh'!$BL12,0,0,1,'Thong tin'!$C$9)) -> 0 | G17: =SUM(OFFSET('Ket qua kinh doanh'!$AZ12,0,0,1,'Thong tin'!$C$9)) -> 0
B18: Trong đó: chi phí lãi vay | D18: =OFFSET('Ket qua kinh doanh'!$BL13,0,'Thong tin'!$C$9 - 1) -> 0 | E18: =OFFSET('Ket qua kinh doanh'!$AZ13,0,'Thong tin'!$C$9 - 1) -> 0 | F18: =SUM(OFFSET('Ket qua kinh doanh'!$BL13,0,0,1,'Thong tin'!$C$9)) -> 0 | G18: =SUM(OFFSET('Ket qua kinh doanh'!$AZ13,0,0,1,'Thong tin'!$C$9)) -> 0
A19: 9. | B19: Chi phí bán hàng | D19: =OFFSET('Ket qua kinh doanh'!$BL14,0,'Thong tin'!$C$9 - 1) -> 0 | E19: =OFFSET('Ket qua kinh doanh'!$AZ14,0,'Thong tin'!$C$9 - 1) -> 0 | F19: =SUM(OFFSET('Ket qua kinh doanh'!$BL14,0,0,1,'Thong tin'!$C$9)) -> 0 | G19: =SUM(OFFSET('Ket qua kinh doanh'!$AZ14,0,0,1,'Thong tin'!$C$9)) -> 0
A20: 10. | B20: Chi phí quản lý doanh nghiệp | D20: =OFFSET('Ket qua kinh doanh'!$BL15,0,'Thong tin'!$C$9 - 1) -> 90000 | E20: =OFFSET('Ket qua kinh doanh'!$AZ15,0,'Thong tin'!$C$9 - 1) -> 0 | F20: =SUM(OFFSET('Ket qua kinh doanh'!$BL15,0,0,1,'Thong tin'!$C$9)) -> 19764818 | G20: =SUM(OFFSET('Ket qua kinh doanh'!$AZ15,0,0,1,'Thong tin'!$C$9)) -> 0
A21: 11. | B21: Lợi nhuận thuần từ hoạt động kinh doanh | D21: =OFFSET('Ket qua kinh doanh'!$BL16,0,'Thong tin'!$C$9 - 1) -> -79541 | E21: =OFFSET('Ket qua kinh doanh'!$AZ16,0,'Thong tin'!$C$9 - 1) -> 0 | F21: =SUM(OFFSET('Ket qua kinh doanh'!$BL16,0,0,1,'Thong tin'!$C$9)) -> 1081478991 | G21: =SUM(OFFSET('Ket qua kinh doanh'!$AZ16,0,0,1,'Thong tin'!$C$9)) -> 0
A22: 12. | B22: Thu nhập khác | D22: =OFFSET('Ket qua kinh doanh'!$BL17,0,'Thong tin'!$C$9 - 1) -> 0 | E22: =OFFSET('Ket qua kinh doanh'!$AZ17,0,'Thong tin'!$C$9 - 1) -> 0 | F22: =SUM(OFFSET('Ket qua kinh doanh'!$BL17,0,0,1,'Thong tin'!$C$9)) -> 0 | G22: =SUM(OFFSET('Ket qua kinh doanh'!$AZ17,0,0,1,'Thong tin'!$C$9)) -> 0
A23: 13. | B23: Chi phí khác | D23: =OFFSET('Ket qua kinh doanh'!$BL18,0,'Thong tin'!$C$9 - 1) -> 0 | E23: =OFFSET('Ket qua kinh doanh'!$AZ18,0,'Thong tin'!$C$9 - 1) -> 0 | F23: =SUM(OFFSET('Ket qua kinh doanh'!$BL18,0,0,1,'Thong tin'!$C$9)) -> 3500000 | G23: =SUM(OFFSET('Ket qua kinh doanh'!$AZ18,0,0,1,'Thong tin'!$C$9)) -> 0
A24: 14. | B24: Lợi nhuận khác | D24: =OFFSET('Ket qua kinh doanh'!$BL19,0,'Thong tin'!$C$9 - 1) -> 0 | E24: =OFFSET('Ket qua kinh doanh'!$AZ19,0,'Thong tin'!$C$9 - 1) -> 0 | F24: =SUM(OFFSET('Ket qua kinh doanh'!$BL19,0,0,1,'Thong tin'!$C$9)) -> -3500000 | G24: =SUM(OFFSET('Ket qua kinh doanh'!$AZ19,0,0,1,'Thong tin'!$C$9)) -> 0
A25: 15. | B25: Tổng lợi nhuận kế toán trước thuế | D25: =OFFSET('Ket qua kinh doanh'!$BL20,0,'Thong tin'!$C$9 - 1) -> -79541 | E25: =OFFSET('Ket qua kinh doanh'!$AZ20,0,'Thong tin'!$C$9 - 1) -> 0 | F25: =SUM(OFFSET('Ket qua kinh doanh'!$BL20,0,0,1,'Thong tin'!$C$9)) -> 1077978991 | G25: =SUM(OFFSET('Ket qua kinh doanh'!$AZ20,0,0,1,'Thong tin'!$C$9)) -> 0
A26: 16. | B26: Chi phí thuế TNDN hiện hành (*) | D26: =OFFSET('Ket qua kinh doanh'!$BL21,0,'Thong tin'!$C$9 - 1) -> 0 | E26: =OFFSET('Ket qua kinh doanh'!$AZ21,0,'Thong tin'!$C$9 - 1) -> 0 | F26: =SUM(OFFSET('Ket qua kinh doanh'!$BL21,0,0,1,'Thong tin'!$C$9)) -> 0 | G26: =SUM(OFFSET('Ket qua kinh doanh'!$AZ21,0,0,1,'Thong tin'!$C$9)) -> 0
A27: 17. | B27: Chi phí thuế TNDN hoãn lại | D27: =OFFSET('Ket qua kinh doanh'!$BL22,0,'Thong tin'!$C$9 - 1) -> 0 | E27: =OFFSET('Ket qua kinh doanh'!$AZ22,0,'Thong tin'!$C$9 - 1) -> 0 | F27: =SUM(OFFSET('Ket qua kinh doanh'!$BL22,0,0,1,'Thong tin'!$C$9)) -> 0 | G27: =SUM(OFFSET('Ket qua kinh doanh'!$AZ22,0,0,1,'Thong tin'!$C$9)) -> 0
A28: 18. | B28: Lợi nhuận sau thuế | D28: =OFFSET('Ket qua kinh doanh'!$BL23,0,'Thong tin'!$C$9 - 1) -> -79541 | E28: =OFFSET('Ket qua kinh doanh'!$AZ23,0,'Thong tin'!$C$9 - 1) -> 0 | F28: =SUM(OFFSET('Ket qua kinh doanh'!$BL23,0,0,1,'Thong tin'!$C$9)) -> 1077978991 | G28: =SUM(OFFSET('Ket qua kinh doanh'!$AZ23,0,0,1,'Thong tin'!$C$9)) -> 0
A29: 19. | B29: Lãi cơ bản trên cổ phiếu | F29: =#REF!+#REF!+#REF!+#REF!+#REF!+#REF!+#REF!+#REF!+#REF!+#REF!+#REF!+D29 -> #REF! | G29: =#REF!+#REF!+#REF!+#REF!+#REF!+#REF!+#REF!+#REF!+#REF!+#REF!+#REF!+E29 -> #REF!
D31: 0 | E31: 0 | F31: 0 | G31: 0
F32: Lập, ngày 06 tháng 06 năm 2026
B34: KẾ TOÁN TRƯỞNG | F34: ='Thong tin'!B18 -> GIÁM ĐỐC
B41: ='Thong tin'!B13 -> Lê Thùy Ngân | F41: ='Thong tin'!B19 -> Trần Thị Kim Thanh

Sheet LCTT_GT in
A1: ='Thong tin'!$A$1 -> CÔNG TY CỔ PHẦN NHỰA TÁI CHẾ DUY TÂN VĨNH LONG
A2: ='Thong tin'!$A$2 -> Địa chỉ: Thửa đất số 838, tờ bản đồ số 6, tổ 4, ấp Tân Thuận, phường Tân Hạnh, tỉnh Vĩnh Long
A4: BÁO CÁO LƯU CHUYỂN TIỀN TỆ
A5: (Theo phương pháp gián tiếp)
A6: ="Năm " & 'Thong tin'!$C$6 -> Năm 2026
E7: ='KQKD in'!G6 -> ĐVT: VNĐ
A8: Chỉ tiêu | B8: ="Tháng " & 'Thong tin'!$C$9 -> Tháng 5 | D8: ="Lũy kế"&" "& 'Thong tin'!$C$9 &" "&"tháng" -> Lũy kế 5 tháng
B9: ="Năm " & 'Thong tin'!$C$6 -> Năm 2026 | C9: ="Năm " & 'Thong tin'!$C$7 -> Năm 2025 | D9: ="Năm " & 'Thong tin'!$C$6 -> Năm 2026 | E9: ="Năm " & 'Thong tin'!$C$7 -> Năm 2025
A10: I. Lưu chuyển tiền từ hoạt động kinh doanh
A11: 1. Lợi nhuận trước thuế | B11: =OFFSET('Luu chuyen tien te'!$BL5,0,'Thong tin'!$C$9 - 1) -> -79541 | C11: =OFFSET('Luu chuyen tien te'!$AZ5,0,'Thong tin'!$C$9 - 1) -> 0 | D11: =SUM(OFFSET('Luu chuyen tien te'!$BL5,0,0,1,'Thong tin'!$C$9)) -> 1077978991 | E11: =SUM(OFFSET('Luu chuyen tien te'!$AZ5,0,0,1,'Thong tin'!$C$9)) -> 0
A12: 2. Điều chỉnh cho các khoản
A13: - Khấu hao tài sản cố định và BĐSĐT | B13: =OFFSET('Luu chuyen tien te'!$BL7,0,'Thong tin'!$C$9 - 1) -> 0 | C13: =OFFSET('Luu chuyen tien te'!$AZ7,0,'Thong tin'!$C$9 - 1) -> 0 | D13: =SUM(OFFSET('Luu chuyen tien te'!$BL7,0,0,1,'Thong tin'!$C$9)) -> 0 | E13: =SUM(OFFSET('Luu chuyen tien te'!$AZ7,0,0,1,'Thong tin'!$C$9)) -> 0
A14: - Các khoản dự phòng | B14: =OFFSET('Luu chuyen tien te'!$BL8,0,'Thong tin'!$C$9 - 1) -> 0 | C14: =OFFSET('Luu chuyen tien te'!$AZ8,0,'Thong tin'!$C$9 - 1) -> 0 | D14: =SUM(OFFSET('Luu chuyen tien te'!$BL8,0,0,1,'Thong tin'!$C$9)) -> 0 | E14: =SUM(OFFSET('Luu chuyen tien te'!$AZ8,0,0,1,'Thong tin'!$C$9)) -> 0
A15: - Lãi, lỗ chênh lệch tỷ giá hối đoái do đánh giá lại các khoản mục tiền tệ có gốc ngoại tệ | B15: =OFFSET('Luu chuyen tien te'!$BL9,0,'Thong tin'!$C$9 - 1) -> 0 | C15: =OFFSET('Luu chuyen tien te'!$AZ9,0,'Thong tin'!$C$9 - 1) -> 0 | D15: =SUM(OFFSET('Luu chuyen tien te'!$BL9,0,0,1,'Thong tin'!$C$9)) -> 0 | E15: =SUM(OFFSET('Luu chuyen tien te'!$AZ9,0,0,1,'Thong tin'!$C$9)) -> 0
A16: - Lãi lỗ từ hoạt động đầu tư, tài chính | B16: =OFFSET('Luu chuyen tien te'!$BL10,0,'Thong tin'!$C$9 - 1) -> -10459 | C16: =OFFSET('Luu chuyen tien te'!$AZ10,0,'Thong tin'!$C$9 - 1) -> 0 | D16: =SUM(OFFSET('Luu chuyen tien te'!$BL10,0,0,1,'Thong tin'!$C$9)) -> -1101243809 | E16: =SUM(OFFSET('Luu chuyen tien te'!$AZ10,0,0,1,'Thong tin'!$C$9)) -> 0
A17: - Chi phí đi vay | B17: =OFFSET('Luu chuyen tien te'!$BL11,0,'Thong tin'!$C$9 - 1) -> 0 | C17: =OFFSET('Luu chuyen tien te'!$AZ11,0,'Thong tin'!$C$9 - 1) -> 0 | D17: =SUM(OFFSET('Luu chuyen tien te'!$BL11,0,0,1,'Thong tin'!$C$9)) -> 0 | E17: =SUM(OFFSET('Luu chuyen tien te'!$AZ11,0,0,1,'Thong tin'!$C$9)) -> 0
A18: - Các khoản điều chỉnh khác | B18: =OFFSET('Luu chuyen tien te'!$BL12,0,'Thong tin'!$C$9 - 1) -> 0 | C18: =OFFSET('Luu chuyen tien te'!$AZ12,0,'Thong tin'!$C$9 - 1) -> 0 | D18: =SUM(OFFSET('Luu chuyen tien te'!$BL12,0,0,1,'Thong tin'!$C$9)) -> 0 | E18: =SUM(OFFSET('Luu chuyen tien te'!$AZ12,0,0,1,'Thong tin'!$C$9)) -> 0
A19: 3. Lợi nhuận từ hoạt động kinh doanh trước thay đổi vốn lưu động | B19: =SUM(B11:B18) -> -90000 | C19: =SUM(C11:C18) -> 0 | D19: =SUM(D11:D18) -> -23264818 | E19: =SUM(E11:E18) -> 0
A20: - Tăng giảm các khoản phải thu | B20: =OFFSET('Luu chuyen tien te'!$BL14,0,'Thong tin'!$C$9 - 1) -> 0 | C20: =OFFSET('Luu chuyen tien te'!$AZ14,0,'Thong tin'!$C$9 - 1) -> 0 | D20: =SUM(OFFSET('Luu chuyen tien te'!$BL14,0,0,1,'Thong tin'!$C$9)) -> 0 | E20: =SUM(OFFSET('Luu chuyen tien te'!$AZ14,0,0,1,'Thong tin'!$C$9)) -> 0
A21: - Tăng giảm hàng tồn kho | B21: =OFFSET('Luu chuyen tien te'!$BL15,0,'Thong tin'!$C$9 - 1) -> 0 | C21: =OFFSET('Luu chuyen tien te'!$AZ15,0,'Thong tin'!$C$9 - 1) -> 0 | D21: =SUM(OFFSET('Luu chuyen tien te'!$BL15,0,0,1,'Thong tin'!$C$9)) -> 0 | E21: =SUM(OFFSET('Luu chuyen tien te'!$AZ15,0,0,1,'Thong tin'!$C$9)) -> 0
A22: - Tăng giảm các khoản phải trả (Không bao gồm lãi vay phải trả, thuế TNDN phải nộp) | B22: =OFFSET('Luu chuyen tien te'!$BL16,0,'Thong tin'!$C$9 - 1) -> 90000 | C22: =OFFSET('Luu chuyen tien te'!$AZ16,0,'Thong tin'!$C$9 - 1) -> 0 | D22: =SUM(OFFSET('Luu chuyen tien te'!$BL16,0,0,1,'Thong tin'!$C$9)) -> -107928494 | E22: =SUM(OFFSET('Luu chuyen tien te'!$AZ16,0,0,1,'Thong tin'!$C$9)) -> 0
A23: - Tăng giảm chi phí chờ phân bổ | B23: =OFFSET('Luu chuyen tien te'!$BL17,0,'Thong tin'!$C$9 - 1) -> 0 | C23: =OFFSET('Luu chuyen tien te'!$AZ17,0,'Thong tin'!$C$9 - 1) -> 0 | D23: =SUM(OFFSET('Luu chuyen tien te'!$BL17,0,0,1,'Thong tin'!$C$9)) -> 0 | E23: =SUM(OFFSET('Luu chuyen tien te'!$AZ17,0,0,1,'Thong tin'!$C$9)) -> 0
A24: - Tăng, giảm chứng khoán kinh doanh | B24: =OFFSET('Luu chuyen tien te'!$BL18,0,'Thong tin'!$C$9 - 1) -> 0 | C24: =OFFSET('Luu chuyen tien te'!$AZ18,0,'Thong tin'!$C$9 - 1) -> 0 | D24: =SUM(OFFSET('Luu chuyen tien te'!$BL18,0,0,1,'Thong tin'!$C$9)) -> 0 | E24: =SUM(OFFSET('Luu chuyen tien te'!$AZ18,0,0,1,'Thong tin'!$C$9)) -> 0
A25: - Chi phí đi vay đã trả | B25: =OFFSET('Luu chuyen tien te'!$BL19,0,'Thong tin'!$C$9 - 1) -> 0 | C25: =OFFSET('Luu chuyen tien te'!$AZ19,0,'Thong tin'!$C$9 - 1) -> 0 | D25: =SUM(OFFSET('Luu chuyen tien te'!$BL19,0,0,1,'Thong tin'!$C$9)) -> 0 | E25: =SUM(OFFSET('Luu chuyen tien te'!$AZ19,0,0,1,'Thong tin'!$C$9)) -> 0
A26: - Thuế thu nhập doanh nghiệp đã nộp | B26: =OFFSET('Luu chuyen tien te'!$BL20,0,'Thong tin'!$C$9 - 1) -> 0 | C26: =OFFSET('Luu chuyen tien te'!$AZ20,0,'Thong tin'!$C$9 - 1) -> 0 | D26: =SUM(OFFSET('Luu chuyen tien te'!$BL20,0,0,1,'Thong tin'!$C$9)) -> 0 | E26: =SUM(OFFSET('Luu chuyen tien te'!$AZ20,0,0,1,'Thong tin'!$C$9)) -> 0
A27: - Tiền thu khác từ hoạt động kinh doanh | B27: =OFFSET('Luu chuyen tien te'!$BL21,0,'Thong tin'!$C$9 - 1) -> 0 | C27: =OFFSET('Luu chuyen tien te'!$AZ21,0,'Thong tin'!$C$9 - 1) -> 0 | D27: =SUM(OFFSET('Luu chuyen tien te'!$BL21,0,0,1,'Thong tin'!$C$9)) -> 0 | E27: =SUM(OFFSET('Luu chuyen tien te'!$AZ21,0,0,1,'Thong tin'!$C$9)) -> 0
A28: - Tiền chi khác cho hoạt động kinh doanh | B28: =OFFSET('Luu chuyen tien te'!$BL22,0,'Thong tin'!$C$9 - 1) -> 0 | C28: =OFFSET('Luu chuyen tien te'!$AZ22,0,'Thong tin'!$C$9 - 1) -> 0 | D28: =SUM(OFFSET('Luu chuyen tien te'!$BL22,0,0,1,'Thong tin'!$C$9)) -> 0 | E28: =SUM(OFFSET('Luu chuyen tien te'!$AZ22,0,0,1,'Thong tin'!$C$9)) -> 0
A29: Lưu chuyển tiền thuần từ hoạt động kinh doanh | B29: =SUM(B19:B28) -> 0 | C29: =SUM(C19:C28) -> 0 | D29: =SUM(D19:D28) -> -131193312 | E29: =SUM(E19:E28) -> 0
A30: II. Lưu chuyển tiền từ hoạt động đầu tư
A31: 1. Tiền chi để mua sắm, xây dựng TSCĐ và các tài sản dài hạn khác | B31: =OFFSET('Luu chuyen tien te'!$BL25,0,'Thong tin'!$C$9 - 1) -> 0 | C31: =OFFSET('Luu chuyen tien te'!$AZ25,0,'Thong tin'!$C$9 - 1) -> 0 | D31: =SUM(OFFSET('Luu chuyen tien te'!$BL25,0,0,1,'Thong tin'!$C$9)) -> -101088000 | E31: =SUM(OFFSET('Luu chuyen tien te'!$AZ25,0,0,1,'Thong tin'!$C$9)) -> 0
A32: 2. Tiền thu từ thanh lý, nhượng bán TSCĐ và các tài sản dài hạn khác | B32: =OFFSET('Luu chuyen tien te'!$BL26,0,'Thong tin'!$C$9 - 1) -> 0 | C32: =OFFSET('Luu chuyen tien te'!$AZ26,0,'Thong tin'!$C$9 - 1) -> 0 | D32: =SUM(OFFSET('Luu chuyen tien te'!$BL26,0,0,1,'Thong tin'!$C$9)) -> 0 | E32: =SUM(OFFSET('Luu chuyen tien te'!$AZ26,0,0,1,'Thong tin'!$C$9)) -> 0
A33: 3. Tiền chi cho vay, mua các công cụ nợ của đơn vị khác | B33: =OFFSET('Luu chuyen tien te'!$BL27,0,'Thong tin'!$C$9 - 1) -> 0 | C33: =OFFSET('Luu chuyen tien te'!$AZ27,0,'Thong tin'!$C$9 - 1) -> 0 | D33: =SUM(OFFSET('Luu chuyen tien te'!$BL27,0,0,1,'Thong tin'!$C$9)) -> 0 | E33: =SUM(OFFSET('Luu chuyen tien te'!$AZ27,0,0,1,'Thong tin'!$C$9)) -> 0
A34: 4. Tiền thu hồi cho vay, bán lại các công cụ nợ của đơn vị khác | B34: =OFFSET('Luu chuyen tien te'!$BL28,0,'Thong tin'!$C$9 - 1) -> 0 | C34: =OFFSET('Luu chuyen tien te'!$AZ28,0,'Thong tin'!$C$9 - 1) -> 0 | D34: =SUM(OFFSET('Luu chuyen tien te'!$BL28,0,0,1,'Thong tin'!$C$9)) -> 0 | E34: =SUM(OFFSET('Luu chuyen tien te'!$AZ28,0,0,1,'Thong tin'!$C$9)) -> 0
A35: 5. Tiền chi đầu tư góp vốn vào đơn vị khác | B35: =OFFSET('Luu chuyen tien te'!$BL29,0,'Thong tin'!$C$9 - 1) -> 0 | C35: =OFFSET('Luu chuyen tien te'!$AZ29,0,'Thong tin'!$C$9 - 1) -> 0 | D35: =SUM(OFFSET('Luu chuyen tien te'!$BL29,0,0,1,'Thong tin'!$C$9)) -> 0 | E35: =SUM(OFFSET('Luu chuyen tien te'!$AZ29,0,0,1,'Thong tin'!$C$9)) -> 0
A36: 6. Tiền thu hồi đầu tư góp vốn vào đơn vị khác | B36: =OFFSET('Luu chuyen tien te'!$BL30,0,'Thong tin'!$C$9 - 1) -> 0 | C36: =OFFSET('Luu chuyen tien te'!$AZ30,0,'Thong tin'!$C$9 - 1) -> 0 | D36: =SUM(OFFSET('Luu chuyen tien te'!$BL30,0,0,1,'Thong tin'!$C$9)) -> 0 | E36: =SUM(OFFSET('Luu chuyen tien te'!$AZ30,0,0,1,'Thong tin'!$C$9)) -> 0
A37: 7. Tiền thu lãi cho vay, cổ tức và lợi nhuận được chia | B37: =OFFSET('Luu chuyen tien te'!$BL31,0,'Thong tin'!$C$9 - 1) -> 10459 | C37: =OFFSET('Luu chuyen tien te'!$AZ31,0,'Thong tin'!$C$9 - 1) -> 0 | D37: =SUM(OFFSET('Luu chuyen tien te'!$BL31,0,0,1,'Thong tin'!$C$9)) -> 1101243809 | E37: =SUM(OFFSET('Luu chuyen tien te'!$AZ31,0,0,1,'Thong tin'!$C$9)) -> 0
A38: Lưu chuyển tiền thuần từ hoạt động đầu tư | B38: =SUM(B31:B37) -> 10459 | C38: =SUM(C31:C37) -> 0 | D38: =SUM(D31:D37) -> 1000155809 | E38: =SUM(E31:E37) -> 0
A39: III. Lưu chuyển tiền từ hoạt động tài chính
A40: 1. Tiền thu từ phát hành cố phiếu, nhận vốn góp của chủ sở hữu | B40: =OFFSET('Luu chuyen tien te'!$BL34,0,'Thong tin'!$C$9 - 1) -> 0 | C40: =OFFSET('Luu chuyen tien te'!$AZ34,0,'Thong tin'!$C$9 - 1) -> 0 | D40: =SUM(OFFSET('Luu chuyen tien te'!$BL34,0,0,1,'Thong tin'!$C$9)) -> 94000000000 | E40: =SUM(OFFSET('Luu chuyen tien te'!$AZ34,0,0,1,'Thong tin'!$C$9)) -> 0
A41: 2. Tiền trả lại vốn góp cho các chủ sở hữu, mua lại cổ phiểu đã phát hành | B41: =OFFSET('Luu chuyen tien te'!$BL35,0,'Thong tin'!$C$9 - 1) -> 0 | C41: =OFFSET('Luu chuyen tien te'!$AZ35,0,'Thong tin'!$C$9 - 1) -> 0 | D41: =SUM(OFFSET('Luu chuyen tien te'!$BL35,0,0,1,'Thong tin'!$C$9)) -> 0 | E41: =SUM(OFFSET('Luu chuyen tien te'!$AZ35,0,0,1,'Thong tin'!$C$9)) -> 0
...

Sheet Tinh hinh tai chinh
B1: CTY CỔ PHẦN TÁI CHẾ DUY TÂN VĨNH LONG
B2: VND
A3: Index BS | B3: PHẦN I-BÁO CÁO TÌNH HÌNH TÀI CHÍNH | C3: TenCongTyID | D3: T1.2021 | E3: T02.2021 | F3: T03.2021 | G3: T04.2021 | H3: T05.2021 | I3: T06.2021 | J3: T07.2021 | K3: T08.2021 | L3: T09.2021 | M3: T10.2021 | N3: T11.2021 | O3: T12.2021 | P3: T1.2022 | Q3: T02.2022 | R3: T03.2022 | S3: T04.2022 | T3: T05.2022 | U3: T06.2022 | V3: T07.2022 | W3: T08.2022 | X3: T09.2022 | Y3: T10.2022 | Z3: T11.2022 | AA3: T12.2022 | AB3: T1.2023 | AC3: T02.2023 | AD3: T03.2023 | AE3: T04.2023 | AF3: T05.2023 | AG3: T06.2023 | AH3: T07.2023 | AI3: T08.2023 | AJ3: T09.2023 | AK3: T10.2023 | AL3: T11.2023 | AM3: T12.2023 | AN3: T01.2024 | AO3: T02.2024 | AP3: T03.2024 | AQ3: T04.2024 | AR3: T05.2024 | AS3: T06.2024 | AT3: T07.2024 | AU3: T08.2024 | AV3: T09.2024 | AW3: T10.2024 | AX3: T11.2024 | AY3: T12.2024 | AZ3: T01.2025 | BA3: T02.2025 | BB3: T03.2025 | BC3: T04.2025 | BD3: T05.2025 | BE3: T06.2025 | BF3: T07.2025 | BG3: T08.2025 | BH3: T09.2025 | BI3: T10.2025 | BJ3: T11.2025 | BK3: T12.2025 | BL3: T01.2026 | BM3: T02.2026 | BN3: T03.2026 | BO3: T04.2026 | BP3: T05.2026 | BQ3: T06.2026 | BR3: T07.2026 | BS3: T08.2026 | BT3: T09.2026 | BU3: T10.2026 | BV3: T11.2026 | BW3: T12.2026
A4: 1 | B4: A-TÀI SẢN NGẮN HẠN | C4: 27 | BJ4: 410553788 | BK4: 5910557105 | BL4: =BL5+BL8+BL15+BL23+BL26+BL30 -> 99892638707 | BM4: =BM5+BM8+BM15+BM23+BM26+BM30 -> 99876833535 | BN4: =BN5+BN8+BN15+BN23+BN26+BN30 -> 99782018348 | BO4: =BO5+BO8+BO15+BO23+BO26+BO30 -> 100879207385 | BP4: =BP5+BP8+BP15+BP23+BP26+BP30 -> 100879225044
A5: 2 | B5: I.Tiền và các khoản tương đương tiền | C5: 27 | BJ5: 403525189 | BK5: =SUM(BK6:BK7) -> 403528506 | BL5: =SUM(BL6:BL7) -> 94383791926 | BM5: =SUM(BM6:BM7) -> 94366722094 | BN5: =SUM(BN6:BN7) -> 94175313507 | BO5: =SUM(BO6:BO7) -> 95272480544 | BP5: =SUM(BP6:BP7) -> 95272491003
A6: 3 | B6: 1.Tiền | C6: 27 | BJ6: 403525189 | BK6: =5903528506-5500000000 -> 403528506 | BL6: =5883791926-5500000000 -> 383791926 | BM6: 366722094 | BN6: 175313507 | BO6: 1272480544 | BP6: 1272491003
A7: 4 | B7: 2.Các khoản tương đương tiền | C7: 27 | BL7: 94000000000 | BM7: 94000000000 | BN7: 94000000000 | BO7: 94000000000 | BP7: 94000000000
A8: 5 | B8: II.Đầu tư tài chính ngắn hạn | C8: 27 | BJ8: 0 | BK8: =SUM(BK9:BK14) -> 5500000000 | BL8: =SUM(BL9:BL14) -> 5500000000 | BM8: =SUM(BM9:BM14) -> 5500000000 | BN8: =SUM(BN9:BN14) -> 5500000000 | BO8: =SUM(BO9:BO14) -> 5500000000 | BP8: =SUM(BP9:BP14) -> 5500000000
A9: 6 | B9: 1.Chứng khoán kinh doanh | C9: 27
A10: 7 | B10: 2.Dự phòng giảm giá chứng khoán kinh doanh (*) | C10: 27
A11: 8 | B11: 3.Đầu tư nắm giữ đến ngày đáo hạn ngắn hạn | C11: 27 | BK11: 5500000000 | BL11: 5500000000 | BM11: 5500000000 | BN11: 5500000000 | BO11: 5500000000 | BP11: 5500000000
A12: 9 | B12: 4.Dự phòng đầu tư nắm giữ đến ngày đáo hạn ngắn hạn (*) | C12: 27
A13: 10 | B13: 5.Đầu tư ngắn hạn khác | C13: 27
A14: 11 | B14: 6.Dự phòng tổn thất các khoản đầu tư ngắn hạn khác (*) | C14: 27
A15: 12 | B15: III.Các khoản phải thu ngắn hạn | C15: 27 | BJ15: 0 | BN15: =BN17 -> 89087960 | BO15: =BO17 -> 89087960 | BP15: =BP17 -> 89087960
A16: 13 | B16: 1.Phải thu ngắn hạn của khách hàng | C16: 27
A17: 14 | B17: 2.Trả trước cho người bán ngắn hạn | C17: 27 | BN17: 89087960 | BO17: 89087960 | BP17: 89087960
A18: 15 | B18: 3.Phải thu nội bộ ngắn hạn | C18: 27
A19: 16 | B19: 4.Phải thu theo tiến độ hợp đồng xây dựng | C19: 27
A20: 17 | B20: 5.Phải thu ngắn hạn khác | C20: 27
A21: 18 | B21: 6.Dự phòng phải thu ngắn hạn khó đòi (*) | C21: 27
A22: 19 | B22: 7.Tài sản thiếu chờ xử lý | C22: 27
A23: 20 | B23: IV. Hàng tồn kho | C23: 27 | BJ23: 0
A24: 21 | B24: 1.Hàng tồn kho | C24: 27
A25: 22 | B25: 2.Dự phòng giảm giá hàng tồn kho (*) | C25: 27
A26: 23 | B26: V. Tài sản sinh học ngắn hạn | C26: 27
A27: 24 | B27: 1.Súc vật nuôi lấy sản phẩm một lần ngắn hạn | C27: 27
A28: 25 | B28: 2.Cây trồng theo mùa vụ hoặc lấy sản phẩm một lần ngắn hạn | C28: 27
A29: 26 | B29: 3.Dự phòng tổn thất tài sản sinh học ngắn hạn (*) | C29: 27
A30: 27 | B30: VI. Tài sản ngắn hạn khác | C30: 27 | BJ30: 7028599 | BK30: 7028599 | BL30: =BL32 -> 8846781 | BM30: =BM32 -> 10111441 | BN30: =BN32 -> 17616881 | BO30: =BO32 -> 17638881 | BP30: =BP32 -> 17646081
A31: 28 | B31: 1.Chi phí chờ phân bổ ngắn hạn | C31: 27
A32: 29 | B32: 2.Thuế GTGT được khấu trừ | C32: 27 | BJ32: 7028599 | BK32: 7028599 | BL32: =1818182+Data_BS[[#This Row],[T12.2025]] -> 8846781 | BM32: =8846781+1264660 -> 10111441 | BN32: =8846781+8770100 -> 17616881 | BO32: =8846781+8770100+22000 -> 17638881 | BP32: =8846781+8770100+22000+7200 -> 17646081
A33: 30 | B33: 3.Thuế và các khoản khác phải thu Nhà nước | C33: 27
A34: 31 | B34: 4.Giao dịch mua bán lại trái phiếu Chính phủ | C34: 27
A35: 32 | B35: 5.Tài sản ngắn hạn khác | C35: 27
A36: 33 | B36: B-TÀI SẢN DÀI HẠN | C36: 27 | BJ36: 87557481 | BK36: 87557481 | BL36: =BL37+BL44+BL54+BL63+BL66+BL76 -> 87557481 | BM36: =BM37+BM44+BM54+BM63+BM66+BM76 -> 103365733 | BN36: =BN37+BN44+BN54+BN63+BN66+BN76 -> 196965733 | BO36: =BO37+BO44+BO54+BO63+BO66+BO76 -> 196965733 | BP36: =BP37+BP44+BP54+BP63+BP66+BP76 -> 196965733
A37: 34 | B37: I.Các khoản phải thu dài hạn | C37: 27 | BJ37: 0
A38: 35 | B38: 1.Phải thu dài hạn của khách hàng | C38: 27
A39: 36 | B39: 2.Trả trước cho người bán dài hạn | C39: 27
A40: 37 | B40: 3.Vốn kinh doanh ở đơn vị trực thuộc | C40: 27
...

Sheet Ket qua kinh doanh
B1: CTY CỔ PHẦN TÁI CHẾ DUY TÂN VĨNH LONG
B2: VND
A3: Index PL | B3: PHẦN II-KẾT QUẢ HOẠT ĐỘNG KINH DOANH | C3: TenCongTyID | D3: T1.2021 | E3: T02.2021 | F3: T03.2021 | G3: T04.2021 | H3: T05.2021 | I3: T06.2021 | J3: T07.2021 | K3: T08.2021 | L3: T09.2021 | M3: T10.2021 | N3: T11.2021 | O3: T12.2021 | P3: T1.2022 | Q3: T02.2022 | R3: T03.2022 | S3: T04.2022 | T3: T05.2022 | U3: T06.2022 | V3: T07.2022 | W3: T08.2022 | X3: T09.2022 | Y3: T10.2022 | Z3: T11.2022 | AA3: T12.2022 | AB3: T1.2023 | AC3: T02.2023 | AD3: T03.2023 | AE3: T04.2023 | AF3: T05.2023 | AG3: T06.2023 | AH3: T07.2023 | AI3: T08.2023 | AJ3: T09.2023 | AK3: T10.2023 | AL3: T11.2023 | AM3: T12.2023 | AN3: T01.2024 | AO3: T02.2024 | AP3: T03.2024 | AQ3: T04.2024 | AR3: T05.2024 | AS3: T06.2024 | AT3: T07.2024 | AU3: T08.2024 | AV3: T09.2024 | AW3: T10.2024 | AX3: T11.2024 | AY3: T12.2024 | AZ3: T01.2025 | BA3: T02.2025 | BB3: T03.2025 | BC3: T04.2025 | BD3: T05.2025 | BE3: T06.2025 | BF3: T07.2025 | BG3: T08.2025 | BH3: T09.2025 | BI3: T10.2025 | BJ3: T11.2025 | BK3: T12.2025 | BL3: T01.2026 | BM3: T02.2026 | BN3: T03.2026 | BO3: T04.2026 | BP3: T05.2026 | BQ3: T06.2026 | BR3: T07.2026 | BS3: T08.2026 | BT3: T09.2026 | BU3: T10.2026 | BV3: T11.2026 | BW3: T12.2026
A4: 1 | B4: Sản lượng (kg) | C4: 27
A5: 2 | B5: 1.Doanh thu bán hàng và cung cấp dịch vụ | C5: 27
A6: 3 | B6: 2.Các khoản giảm trừ doanh thu | C6: 27
A7: 4 | B7: 3.Doanh thu thuần về bán hàng và cung cấp dịch vụ | C7: 27
A8: 5 | B8: 4.Giá vốn hàng bán | C8: 27
A9: 6 | B9: 5.Lợi nhuận gộp về bán hàng | C9: 27
A10: 7 | B10: 6.Lãi/lỗ của hoạt động bán, thanh lý bất động sản đầu tư | C10: 27
A11: 8 | B11: 7.Doanh thu hoạt động tài chính | C11: 27 | BJ11: 1669 | BK11: 3317 | BL11: 263420 | BM11: 3080 | BN11: 2813 | BO11: 1100964037 | BP11: 10459
A12: 9 | B12: 8.Chi phí tài chính | C12: 27
A13: 10 | B13: Trong đó: Chi phí lãi vay | C13: 27
A14: 11 | B14: 9.Chi phí bán hàng | C14: 27
A15: 12 | B15: 10.Chi phí quản lý doanh nghiệp | C15: 27 | BJ15: 1890400 | BL15: 18181818 | BN15: =218000+1000000 -> 1218000 | BO15: 275000 | BP15: 90000
A16: 13 | B16: 11.Lợi nhuận thuần từ hoạt động kinh doanh | C16: 27 | BJ16: -1888731 | BK16: 3317 | BL16: -17918398 | BM16: =BM11 -> 3080 | BN16: =BN11-BN15 -> -1215187 | BO16: =BO11-BO15 -> 1100689037 | BP16: =BP11-BP15 -> -79541
A17: 14 | B17: 12.Thu nhập khác | C17: 27 | BJ17: 0
A18: 15 | B18: 13.Chi phí khác | C18: 27 | BO18: 3500000
A19: 16 | B19: 14.Lợi nhuận khác | C19: 27 | BJ19: 0 | BK19: 0 | BO19: =BO17-BO18 -> -3500000 | BP19: =BP17-BP18 -> 0
A20: 17 | B20: 15.Tổng lợi nhuận kế toán trước thuế | C20: 27 | BJ20: -1888731 | BK20: 3317 | BL20: -17918398 | BM20: =BM16 -> 3080 | BN20: =BN16 -> -1215187 | BO20: =BO16+BO19 -> 1097189037 | BP20: =BP16+BP19 -> -79541
A21: 18 | B21: 16.Chi phí thuế TNDN hiện hành | C21: 27
A22: 19 | B22: 17.Chi phí thuế TNDN hoãn lại | C22: 27
A23: 20 | B23: 18.Lợi nhuận sau thuế thu nhập doanh nghiệp | C23: 27 | BJ23: -1888731 | BK23: 3317 | BL23: -17918398 | BM23: =BM20 -> 3080 | BN23: =BN20 -> -1215187 | BO23: =BO20 -> 1097189037 | BP23: =BP20 -> -79541

Sheet Luu chuyen tien te
B1: CTY CỔ PHẦN TÁI CHẾ DUY TÂN VĨNH LONG
B2: VND
A3: Index CF | B3: PHẦN III- LƯU CHUYỂN TIỀN TỆ | C3: TenCongTyID | D3: T1.2021 | E3: T02.2021 | F3: T03.2021 | G3: T04.2021 | H3: T05.2021 | I3: T06.2021 | J3: T07.2021 | K3: T08.2021 | L3: T09.2021 | M3: T10.2021 | N3: T11.2021 | O3: T12.2021 | P3: T1.2022 | Q3: T02.2022 | R3: T03.2022 | S3: T04.2022 | T3: T05.2022 | U3: T06.2022 | V3: T07.2022 | W3: T08.2022 | X3: T09.2022 | Y3: T10.2022 | Z3: T11.2022 | AA3: T12.2022 | AB3: T1.2023 | AC3: T02.2023 | AD3: T03.2023 | AE3: T04.2023 | AF3: T05.2023 | AG3: T06.2023 | AH3: T07.2023 | AI3: T08.2023 | AJ3: T09.2023 | AK3: T10.2023 | AL3: T11.2023 | AM3: T12.2023 | AN3: T01.2024 | AO3: T02.2024 | AP3: T03.2024 | AQ3: T04.2024 | AR3: T05.2024 | AS3: T06.2024 | AT3: T07.2024 | AU3: T08.2024 | AV3: T09.2024 | AW3: T10.2024 | AX3: T11.2024 | AY3: T12.2024 | AZ3: T01.2025 | BA3: T02.2025 | BB3: T03.2025 | BC3: T04.2025 | BD3: T05.2025 | BE3: T06.2025 | BF3: T07.2025 | BG3: T08.2025 | BH3: T09.2025 | BI3: T10.2025 | BJ3: T11.2025 | BK3: T12.2025 | BL3: T01.2026 | BM3: T02.2026 | BN3: T03.2026 | BO3: T04.2026 | BP3: T05.2026 | BQ3: T06.2026 | BR3: T07.2026 | BS3: T08.2026 | BT3: T09.2026 | BU3: T10.2026 | BV3: T11.2026 | BW3: T12.2026
A4: 1 | B4: I. Lưu chuyển tiền từ hoạt động kinh doanh | C4: 27
A5: 2 | B5: Lợi nhuận trước thuế | C5: 27 | BJ5: -1888731 | BK5: 3317 | BL5: ='Ket qua kinh doanh'!BL23 -> -17918398 | BM5: 3080 | BN5: -1215187 | BO5: 1097189037 | BP5: ='Ket qua kinh doanh'!BP23 -> -79541
A6: 3 | B6: Điều chỉnh cho các khoản: | C6: 27
A7: 4 | B7: Khấu hao tài sản cố định và BĐSĐT | C7: 27
A8: 5 | B8: Các khoản dự phòng | C8: 27
A9: 6 | B9: Lãi, lỗ chênh lệch tỷ giá do đánh giá lại các khoản mục tiền tệ có gốc ngoại tệ | C9: 27
A10: 7 | B10: Lãi, lỗ từ hoạt động đầu tư, tài chính | C10: 27 | BJ10: -1669 | BK10: -3317 | BL10: -263420 | BM10: -3080 | BN10: -2813 | BO10: -1100964037 | BP10: -10459
A11: 8 | B11: Chi phí đi vay | C11: 27
A12: 9 | B12: Các khoản điều chỉnh khác | C12: 27
A13: 10 | B13: Lợi nhuận từ hoạt động kinh doanh trước thay đổi vốn lưu động | C13: 27 | BJ13: -1890400 | BL13: =BL5+BL10 -> -18181818 | BM13: =BM5+BM10 -> 0 | BN13: -1218000 | BO13: -3775000 | BP13: =BP5+BP10 -> -90000
A14: 11 | B14: Tăng / giảm các khoản phải thu | C14: 27
A15: 12 | B15: Tăng / giảm hàng tồn kho | C15: 27
A16: 13 | B16: Tăng / giảm các khoản phải trả (Không bao gồm lãi vay phải trả, thuế TNDN phải nộp) | C16: 27 | BJ16: -7028599 | BL16: -1818182 | BM16: -17072912 | BN16: -89105400 | BO16: -22000 | BP16: 90000
A17: 14 | B17: Tăng / giảm chi phí chờ phân bổ | C17: 27
A18: 15 | B18: Tăng / giảm chứng khoán kinh doanh | C18: 27
A19: 16 | B19: Chi phí đi vay đã trả | C19: 27
A20: 17 | B20: Thuế thu nhập doanh nghiệp đã nộp | C20: 27
A21: 18 | B21: Tiền thu khác từ hoạt động kinh doanh | C21: 27
A22: 19 | B22: Tiền chi khác cho hoạt động kinh doanh | C22: 27
A23: 20 | B23: Lưu chuyển tiền thuần từ hoạt động kinh doanh | C23: 27 | BJ23: -8918999 | BL23: =BL13+BL16 -> -20000000 | BM23: =BM13+BM16 -> -17072912 | BN23: -90323400 | BO23: -3797000 | BP23: =BP13+BP16 -> 0
A24: 21 | B24: II. Lưu chuyển tiền từ hoạt động đầu tư | C24: 27
A25: 22 | B25: Tiền chi để mua sắm, xây dựng, TSCĐ và các tài sản dài hạn khác | C25: 27 | BJ25: -87557481 | BN25: -101088000 | BO25: 0
A26: 23 | B26: Tiền thu từ thanh lý, nhượng bán TSCĐ và các tài sản dài hạn khác | C26: 27
A27: 24 | B27: Tiền chi cho vay, mua các công cụ nợ của đơn vị khác | C27: 27 | BK27: -5500000000
A28: 25 | B28: Tiền thu hồi cho vay, bán lại các công cụ nợ của đơn vị khác | C28: 27
A29: 26 | B29: Tiền chi đầu tư góp vốn vào đơn vị khác | C29: 27
A30: 27 | B30: Tiền thu hồi đầu tư góp vốn vào đơn vị khác | C30: 27
A31: 28 | B31: Tiền thu lãi cho vay, cổ tức, và lợi nhuận được chia | C31: 27 | BJ31: 1669 | BK31: 3317 | BL31: 263420 | BM31: 3080 | BN31: 2813 | BO31: 1100964037 | BP31: 10459
A32: 29 | B32: Lưu chuyển tiền thuần từ hoạt động đầu tư | C32: 27 | BJ32: -87555812 | BK32: =3317-5500000000 -> -5499996683 | BL32: =BL31 -> 263420 | BM32: =BM31 -> 3080 | BN32: -101085187 | BO32: 1100964037 | BP32: =SUM(BP25:BP31) -> 10459
A33: 30 | B33: III. Lưu chuyển tiền từ hoạt động tài chính | C33: 27
A34: 31 | B34: Tiền thu từ phát hành cổ phiếu, nhận vốn góp của chủ sở hữu | C34: 27 | BJ34: 500000000 | BK34: 5500000000 | BL34: 94000000000
A35: 32 | B35: Tiền trả lại vốn góp cho các chủ sở hữu, mua lại cổ phiểu đã phát hành | C35: 27
A36: 33 | B36: Tiền thu từ đi vay | C36: 27
A37: 34 | B37: Tiền trả nợ gốc vay | C37: 27
A38: 35 | B38: Tiền trả nợ gốc thuê tài chính | C38: 27
A39: 36 | B39: Cổ tức, lợi nhuận đã trả cho chủ sở hữu | C39: 27
A40: 37 | B40: Lưu chuyển thuần từ hoạt động tài chính | C40: 27 | BJ40: 500000000 | BK40: 5500000000 | BL40: 94000263420 | BM40: =BM34 -> 0 | BN40: 0 | BO40: 0 | BP40: =BP34 -> 0
...

Sheet KQKD theo yeu to
B1: CTY CỔ PHẦN TÁI CHẾ DUY TÂN VĨNH LONG
B2: VND
A3: Index PL Element | B3: PHẦN IV: CHI PHÍ THEO YẾU TỐ | C3: TenCongTyID | D3: T1.2021 | E3: T02.2021 | F3: T03.2021 | G3: T04.2021 | H3: T05.2021 | I3: T06.2021 | J3: T07.2021 | K3: T08.2021 | L3: T09.2021 | M3: T10.2021 | N3: T11.2021 | O3: T12.2021 | P3: T1.2022 | Q3: T02.2022 | R3: T03.2022 | S3: T04.2022 | T3: T05.2022 | U3: T06.2022 | V3: T07.2022 | W3: T08.2022 | X3: T09.2022 | Y3: T10.2022 | Z3: T11.2022 | AA3: T12.2022 | AB3: T1.2023 | AC3: T02.2023 | AD3: T03.2023 | AE3: T04.2023 | AF3: T05.2023 | AG3: T06.2023 | AH3: T07.2023 | AI3: T08.2023 | AJ3: T09.2023 | AK3: T10.2023 | AL3: T11.2023 | AM3: T12.2023 | AN3: T01.2024 | AO3: T02.2024 | AP3: T03.2024 | AQ3: T04.2024 | AR3: T05.2024 | AS3: T06.2024 | AT3: T07.2024 | AU3: T08.2024 | AV3: T09.2024 | AW3: T10.2024 | AX3: T11.2024 | AY3: T12.2024 | AZ3: T01.2025 | BA3: T02.2025 | BB3: T03.2025 | BC3: T04.2025 | BD3: T05.2025 | BE3: T06.2025 | BF3: T07.2025 | BG3: T08.2025 | BH3: T09.2025 | BI3: T10.2025 | BJ3: T11.2025 | BK3: T12.2025 | BL3: T01.2026 | BM3: T02.2026 | BN3: T03.2026 | BO3: T04.2026 | BP3: T05.2026 | BQ3: T06.2026 | BR3: T07.2026 | BS3: T08.2026 | BT3: T09.2026 | BU3: T10.2026 | BV3: T11.2026 | BW3: T12.2026
A4: 1 | B4: Tổng nhân sự | C4: 27
A5: 2 | B5: Nhân sự nhóm sản xuất | C5: 27
A6: 3 | B6: Số ngày công (8 hrs) | C6: 27
A7: 4 | B7: Sản lượng sản xuất (Ton) | C7: 27
A8: 5 | B8: Sản lượng bán (Ton) | C8: 27 | P8: ='Ket qua kinh doanh'!P4 -> 0 | Q8: ='Ket qua kinh doanh'!Q4 -> 0 | R8: ='Ket qua kinh doanh'!R4 -> 0 | S8: ='Ket qua kinh doanh'!S4 -> 0 | T8: ='Ket qua kinh doanh'!T4 -> 0 | U8: ='Ket qua kinh doanh'!U4 -> 0 | V8: ='Ket qua kinh doanh'!V4 -> 0 | W8: ='Ket qua kinh doanh'!W4 -> 0 | ... BW8: ='Ket qua kinh doanh'!BW4 -> 0
A9: 6 | B9: Doanh thu bán hàng | C9: 27 | P9: ='Ket qua kinh doanh'!P5 -> 0 | Q9: ='Ket qua kinh doanh'!Q5 -> 0 | R9: ='Ket qua kinh doanh'!R5 -> 0 | S9: ='Ket qua kinh doanh'!S5 -> 0 | T9: ='Ket qua kinh doanh'!T5 -> 0 | U9: ='Ket qua kinh doanh'!U5 -> 0 | V9: ='Ket qua kinh doanh'!V5 -> 0 | W9: ='Ket qua kinh doanh'!W5 -> 0 | ... BW9: ='Ket qua kinh doanh'!BW5 -> 0
A10: 7 | B10: Các khoản giảm trừ doanh thu | C10: 27 | P10: ='Ket qua kinh doanh'!P6 -> 0 | Q10: ='Ket qua kinh doanh'!Q6 -> 0 | R10: ='Ket qua kinh doanh'!R6 -> 0 | S10: ='Ket qua kinh doanh'!S6 -> 0 | T10: ='Ket qua kinh doanh'!T6 -> 0 | U10: ='Ket qua kinh doanh'!U6 -> 0 | V10: ='Ket qua kinh doanh'!V6 -> 0 | W10: ='Ket qua kinh doanh'!W6 -> 0 | ... BW10: ='Ket qua kinh doanh'!BW6 -> 0
A11: 8 | B11: % Các khoản giảm trừ | C11: 27 | P11: =IFERROR(P10/P9,"") | Q11: =IFERROR(Q10/Q9,"") | R11: =IFERROR(R10/R9,"") | S11: =IFERROR(S10/S9,"") | T11: =IFERROR(T10/T9,"") | U11: =IFERROR(U10/U9,"") | V11: =IFERROR(V10/V9,"") | W11: =IFERROR(W10/W9,"") | ... BW11: =IFERROR(BW10/BW9,"")
A12: 9 | B12: Doanh thu thuần | C12: 27 | P12: ='Ket qua kinh doanh'!P7 -> 0 | Q12: ='Ket qua kinh doanh'!Q7 -> 0 | R12: ='Ket qua kinh doanh'!R7 -> 0 | S12: ='Ket qua kinh doanh'!S7 -> 0 | T12: ='Ket qua kinh doanh'!T7 -> 0 | U12: ='Ket qua kinh doanh'!U7 -> 0 | V12: ='Ket qua kinh doanh'!V7 -> 0 | W12: ='Ket qua kinh doanh'!W7 -> 0 | ... BW12: ='Ket qua kinh doanh'!BW7 -> 0
A13: 10 | B13: Xuất khẩu | C13: 27
A14: 11 | B14: Nội địa | C14: 27
A15: 12 | B15: Khác | C15: 27
A16: 13 | B16: Giá vốn hàng bán | C16: 27 | P16: ='Ket qua kinh doanh'!P8 -> 0 | Q16: ='Ket qua kinh doanh'!Q8 -> 0 | R16: ='Ket qua kinh doanh'!R8 -> 0 | S16: ='Ket qua kinh doanh'!S8 -> 0 | T16: ='Ket qua kinh doanh'!T8 -> 0 | U16: ='Ket qua kinh doanh'!U8 -> 0 | V16: ='Ket qua kinh doanh'!V8 -> 0 | W16: ='Ket qua kinh doanh'!W8 -> 0 | ... BW16: ='Ket qua kinh doanh'!BW8 -> 0
A17: 14 | B17: Chi phí nguyên vật liệu | C17: 27
A18: 15 | B18: Chi phí điện | C18: 27
A19: 16 | B19: Chi phí lương ngoài giờ sản xuất | C19: 27
A20: 17 | B20: Chi phí nhân công trực tiếp sản xuất (622) | C20: 27
A21: 18 | B21: Chi phí nhân công gián tiếp sản xuất (6271) | C21: 27
A22: 19 | B22: Phúc lợi nhân viên sản xuất (BHXH,thưởng,…) | C22: 27
A23: 20 | B23: Chi phí sửa chữa, bảo trì | C23: 27
A24: 21 | B24: Chi phí xưởng (các khoản còn lại ngoài các mục trên) | C24: 27
A25: 22 | B25: Chi phí khấu hao sản xuất (6274) | C25: 27
A26: 23 | B26: Chi phí gia công ngoài (nếu có) | C26: 27
A27: 24 | B27: Giá vốn khác | C27: 27
A28: 25 | B28: Giá vốn trong hàng tồn kho | C28: 27
A29: 26 | B29: % Giá vốn hàng bán | C29: 27 | P29: =IFERROR(P16/P12,"") | Q29: =IFERROR(Q16/Q12,"") | R29: =IFERROR(R16/R12,"") | S29: =IFERROR(S16/S12,"") | T29: =IFERROR(T16/T12,"") | U29: =IFERROR(U16/U12,"") | V29: =IFERROR(V16/V12,"") | W29: =IFERROR(W16/W12,"") | ... BW29: =IFERROR(BW16/BW12,"")
A30: 27 | B30: Lợi nhuận gộp | C30: 27 | P30: ='Ket qua kinh doanh'!P9 -> 0 | Q30: ='Ket qua kinh doanh'!Q9 -> 0 | R30: ='Ket qua kinh doanh'!R9 -> 0 | S30: ='Ket qua kinh doanh'!S9 -> 0 | T30: ='Ket qua kinh doanh'!T9 -> 0 | U30: ='Ket qua kinh doanh'!U9 -> 0 | V30: ='Ket qua kinh doanh'!V9 -> 0 | W30: ='Ket qua kinh doanh'!W9 -> 0 | ... BW30: ='Ket qua kinh doanh'!BW9 -> 0
A31: 28 | B31: % Lợi nhuận gộp | C31: 27 | P31: =IFERROR(P30/P12,"") | Q31: =IFERROR(Q30/Q12,"") | R31: =IFERROR(R30/R12,"") | S31: =IFERROR(S30/S12,"") | T31: =IFERROR(T30/T12,"") | U31: =IFERROR(U30/U12,"") | V31: =IFERROR(V30/V12,"") | W31: =IFERROR(W30/W12,"") | ... BW31: =IFERROR(BW30/BW12,"")
A32: 29 | B32: Lợi nhuận trước thuế | C32: 27 | P32: ='Ket qua kinh doanh'!P20 -> 0 | Q32: ='Ket qua kinh doanh'!Q20 -> 0 | R32: ='Ket qua kinh doanh'!R20 -> 0 | S32: ='Ket qua kinh doanh'!S20 -> 0 | T32: ='Ket qua kinh doanh'!T20 -> 0 | U32: ='Ket qua kinh doanh'!U20 -> 0 | V32: ='Ket qua kinh doanh'!V20 -> 0 | W32: ='Ket qua kinh doanh'!W20 -> 0 | ... BW32: ='Ket qua kinh doanh'!BW20 -> 0
A33: 30 | B33: % Lợi nhuận trước thuế | C33: 27 | P33: =IFERROR(P32/P12,"") | Q33: =IFERROR(Q32/Q12,"") | R33: =IFERROR(R32/R12,"") | S33: =IFERROR(S32/S12,"") | T33: =IFERROR(T32/T12,"") | U33: =IFERROR(U32/U12,"") | V33: =IFERROR(V32/V12,"") | W33: =IFERROR(W32/W12,"") | ... BW33: =IFERROR(BW32/BW12,"")
A34: 31 | B34: EBITDA | C34: 27 | P34: ='Ket qua kinh doanh'!P20+'Ket qua kinh doanh'!P13+'Luu chuyen tien te'!P7 -> 0 | Q34: ='Ket qua kinh doanh'!Q20+'Ket qua kinh doanh'!Q13+'Luu chuyen tien te'!Q7 -> 0 | R34: ='Ket qua kinh doanh'!R20+'Ket qua kinh doanh'!R13+'Luu chuyen tien te'!R7 -> 0 | S34: ='Ket qua kinh doanh'!S20+'Ket qua kinh doanh'!S13+'Luu chuyen tien te'!S7 -> 0 | T34: ='Ket qua kinh doanh'!T20+'Ket qua kinh doanh'!T13+'Luu chuyen tien te'!T7 -> 0 | U34: ='Ket qua kinh doanh'!U20+'Ket qua kinh doanh'!U13+'Luu chuyen tien te'!U7 -> 0 | V34: ='Ket qua kinh doanh'!V20+'Ket qua kinh doanh'!V13+'Luu chuyen tien te'!V7 -> 0 | W34: ='Ket qua kinh doanh'!W20+'Ket qua kinh doanh'!W13+'Luu chuyen tien te'!W7 -> 0 | ... BW34: ='Ket qua kinh doanh'!BW20+'Ket qua kinh doanh'!BW13+'Luu chuyen tien te'!BW7 -> 0
A35: 32 | B35: % EBITDA | C35: 27 | P35: =IFERROR(P34/P12,"") | Q35: =IFERROR(Q34/Q12,"") | R35: =IFERROR(R34/R12,"") | S35: =IFERROR(S34/S12,"") | T35: =IFERROR(T34/T12,"") | U35: =IFERROR(U34/U12,"") | V35: =IFERROR(V34/V12,"") | W35: =IFERROR(W34/W12,"") | ... BW35: =IFERROR(BW34/BW12,"")
A36: 33 | B36: Thuế TNDN | C36: 27 | P36: ='Ket qua kinh doanh'!P21+'Ket qua kinh doanh'!P22 -> 0 | Q36: ='Ket qua kinh doanh'!Q21+'Ket qua kinh doanh'!Q22 -> 0 | R36: ='Ket qua kinh doanh'!R21+'Ket qua kinh doanh'!R22 -> 0 | S36: ='Ket qua kinh doanh'!S21+'Ket qua kinh doanh'!S22 -> 0 | T36: ='Ket qua kinh doanh'!T21+'Ket qua kinh doanh'!T22 -> 0 | U36: ='Ket qua kinh doanh'!U21+'Ket qua kinh doanh'!U22 -> 0 | V36: ='Ket qua kinh doanh'!V21+'Ket qua kinh doanh'!V22 -> 0 | W36: ='Ket qua kinh doanh'!W21+'Ket qua kinh doanh'!W22 -> 0 | ... BW36: ='Ket qua kinh doanh'!BW21+'Ket qua kinh doanh'!BW22 -> 0
A37: 34 | B37: % Thuế TNDN | C37: 27 | P37: =IFERROR(P36/P12,"") | Q37: =IFERROR(Q36/Q12,"") | R37: =IFERROR(R36/R12,"") | S37: =IFERROR(S36/S12,"") | T37: =IFERROR(T36/T12,"") | U37: =IFERROR(U36/U12,"") | V37: =IFERROR(V36/V12,"") | W37: =IFERROR(W36/W12,"") | ... BW37: =IFERROR(BW36/BW12,"")
A38: 35 | B38: Lợi nhuận sau thuế | C38: 27 | P38: ='Ket qua kinh doanh'!P23 -> 0 | Q38: ='Ket qua kinh doanh'!Q23 -> 0 | R38: ='Ket qua kinh doanh'!R23 -> 0 | S38: ='Ket qua kinh doanh'!S23 -> 0 | T38: ='Ket qua kinh doanh'!T23 -> 0 | U38: ='Ket qua kinh doanh'!U23 -> 0 | V38: ='Ket qua kinh doanh'!V23 -> 0 | W38: ='Ket qua kinh doanh'!W23 -> 0 | ... BW38: ='Ket qua kinh doanh'!BW23 -> 0
A39: 36 | B39: % Lợi nhuận sau thuế | C39: 27 | P39: =IFERROR(P38/P12,"") | Q39: =IFERROR(Q38/Q12,"") | R39: =IFERROR(R38/R12,"") | S39: =IFERROR(S38/S12,"") | T39: =IFERROR(T38/T12,"") | U39: =IFERROR(U38/U12,"") | V39: =IFERROR(V38/V12,"") | W39: =IFERROR(W38/W12,"") | ... BW39: =IFERROR(BW38/BW12,"")
A40: 37 | B40: Chi phí bán hàng | C40: 27 | P40: ='Ket qua kinh doanh'!P14 -> 0 | Q40: ='Ket qua kinh doanh'!Q14 -> 0 | R40: ='Ket qua kinh doanh'!R14 -> 0 | S40: ='Ket qua kinh doanh'!S14 -> 0 | T40: ='Ket qua kinh doanh'!T14 -> 0 | U40: ='Ket qua kinh doanh'!U14 -> 0 | V40: ='Ket qua kinh doanh'!V14 -> 0 | W40: ='Ket qua kinh doanh'!W14 -> 0 | ... BW40: ='Ket qua kinh doanh'!BW14 -> 0
...

Sheet No vay
B1: CTY CỔ PHẦN TÁI CHẾ DUY TÂN VĨNH LONG
B2: VND
A3: Index Loan | B3: PHẦN V: CHI TIẾT NỢ VAY NGÂN HÀNG | C3: TenCongTyID | D3: T1.2021 | E3: T02.2021 | F3: T03.2021 | G3: T04.2021 | H3: T05.2021 | I3: T06.2021 | J3: T07.2021 | K3: T08.2021 | L3: T09.2021 | M3: T10.2021 | N3: T11.2021 | O3: T12.2021 | P3: T1.2022 | Q3: T02.2022 | R3: T03.2022 | S3: T04.2022 | T3: T05.2022 | U3: T06.2022 | V3: T07.2022 | W3: T08.2022 | X3: T09.2022 | Y3: T10.2022 | Z3: T11.2022 | AA3: T12.2022 | AB3: T1.2023 | AC3: T02.2023 | AD3: T03.2023 | AE3: T04.2023 | AF3: T05.2023 | AG3: T06.2023 | AH3: T07.2023 | AI3: T08.2023 | AJ3: T09.2023 | AK3: T10.2023 | AL3: T11.2023 | AM3: T12.2023 | AN3: T01.2024 | AO3: T02.2024 | AP3: T03.2024 | AQ3: T04.2024 | AR3: T05.2024 | AS3: T06.2024 | AT3: T07.2024 | AU3: T08.2024 | AV3: T09.2024 | AW3: T10.2024 | AX3: T11.2024 | AY3: T12.2024 | AZ3: T01.2025 | BA3: T02.2025 | BB3: T03.2025 | BC3: T04.2025 | BD3: T05.2025 | BE3: T06.2025 | BF3: T07.2025 | BG3: T08.2025 | BH3: T09.2025 | BI3: T10.2025 | BJ3: T11.2025 | BK3: T12.2025 | BL3: T01.2026 | BM3: T02.2026 | BN3: T03.2026 | BO3: T04.2026 | BP3: T05.2026 | BQ3: T06.2026 | BR3: T07.2026 | BS3: T08.2026 | BT3: T09.2026 | BU3: T10.2026 | BV3: T11.2026 | BW3: T12.2026
A4: 1 | B4: Hạn mức vay ngắn hạn | C4: 27
A5: 2 | B5: ACB | C5: 27
A6: 3 | B6: VietinBank | C6: 27
A7: 4 | B7: Vietcombank | C7: 27
A8: 5 | B8: BIDV | C8: 27
A9: 6 | B9: Standard Chartered | C9: 27
A10: 7 | B10: VILC | C10: 27
A11: 8 | B11: IVB | C11: 27
A12: 9 | C12: 27
A13: 10 | B13: Vay ngắn hạn ngân hàng | C13: 27
A14: 11 | B14: ACB | C14: 27
A15: 12 | B15: VietinBank | C15: 27
A16: 13 | B16: Vietcombank | C16: 27
A17: 14 | B17: BIDV | C17: 27
A18: 15 | B18: Standard Chartered | C18: 27
A19: 16 | B19: VILC | C19: 27
A20: 17 | B20: IVB | C20: 27
A21: 18 | C21: 27
A22: 19 | B22: Lãi suất vay ngắn hạn (%) | C22: 27
A23: 20 | B23: =B14 -> ACB | C23: 27
A24: 21 | B24: =B15 -> VietinBank | C24: 27
A25: 22 | B25: =B16 -> Vietcombank | C25: 27
A26: 23 | B26: =B17 -> BIDV | C26: 27
A27: 24 | B27: =B18 -> Standard Chartered | C27: 27
A28: 25 | B28: =B19 -> VILC | C28: 27
A29: 26 | B29: =B20 -> IVB | C29: 27
A30: 27 | C30: 27
A31: 28 | B31: Vay trung hạn Ngân hàng | C31: 27
A32: 29 | B32: =B14 -> ACB | C32: 27
A33: 30 | B33: =B15 -> VietinBank | C33: 27
A34: 31 | B34: =B16 -> Vietcombank | C34: 27
A35: 32 | B35: BIDV | C35: 27
A36: 33 | B36: =B18 -> Standard Chartered | C36: 27
A37: 34 | B37: VILC | C37: 27
A38: 35 | B38: IVB | C38: 27
A39: 36 | C39: 27
A40: 37 | B40: Lãi suất vay trung hạn (%) | C40: 27
...

Sheet Giao dich voi BLQ
A1: ='Thong tin'!$A$1 -> CÔNG TY CỔ PHẦN NHỰA TÁI CHẾ DUY TÂN VĨNH LONG
B2: TỔNG HỢP THÔNG TIN GIAO DỊCH VỚI CÁC BÊN LIÊN QUAN NĂM 2026
A4: A | B4: GIÁ TRỊ GIAO DỊCH VỚI CÁC BÊN LIÊN QUAN
F5: Số tiền chưa VAT
B6: Công ty thành viên | C6: Mã số thuế | D6: Diễn giải | E6: TK hạch toán | F6: Tháng 1 | G6: Tháng 2 | H6: Tháng 3 | I6: Tháng 4 | J6: Tháng 5 | K6: Tháng 6 | L6: Tháng 7 | M6: Tháng 8 | N6: Tháng 9 | O6: Tháng 10 | P6: Tháng 11 | Q6: Tháng 12 | R6: Lũy kế năm 2026
A7: I. | B7: DOANH THU BÁN HÀNG VÀ DỊCH VỤ, TÀI SẢN….
A8: 1 | B8: Công ty TNHH Nhựa Duy Tân | C8: 0301417196 | D8: Bán hàng nhựa | E8: 511 | R8: =SUM(F8:Q8) -> 0
D9: Bán vật tư | E9: 511 | R9: =SUM(F9:Q9) -> 0
D10: Bán TSCĐ | E10: 711 | R10: =SUM(F10:Q10) -> 0
D11: Lãi vay | E11: 515 | R11: =SUM(F11:Q11) -> 0
D12: Thu tiền lãi vay | E12: 112 | R12: =SUM(F12:Q12) -> 0
D13: DV TS24 | E13: 511 | R13: =SUM(F13:Q13) -> 0
D14: Bán khác | E14: 7118 | R14: =SUM(F14:Q14) -> 0
A15: 2 | B15: Công ty CP Nhựa Tái Chế Duy Tân | C15: 1100676611 | D15: Bán hàng nhựa | E15: 511 | R15: =SUM(F15:Q15) -> 0
D16: Bán nguyên vật liệu | E16: 511 | R16: =SUM(F16:Q16) -> 0
D17: Bán vật tư | E17: 511 | R17: =SUM(F17:Q17) -> 0
D18: Cho thuê máy móc | E18: 511 | R18: =SUM(F18:Q18) -> 0
D19: Bán Laptop | E19: 511 | R19: =SUM(F19:Q19) -> 0
D20: Bán TSCĐ | E20: 711 | R20: =SUM(F20:Q20) -> 0
D21: CP công tác | E21: 511 | R21: =SUM(F21:Q21) -> 0
D22: Bán khác | E22: 7118 | R22: =SUM(F22:Q22) -> 0
A23: 3 | B23: Công ty TNHH Thu mua phế liệu Đại Lộc | C23: 3603813473 | D23: Bán hàng nhựa | E23: 511 | R23: =SUM(F23:Q23) -> 0
D24: Bán nguyên vật liệu | E24: 511 | R24: =SUM(F24:Q24) -> 0
D25: Bán vật tư | E25: 511 | R25: =SUM(F25:Q25) -> 0
D26: Cho thuê nhà xưởng | E26: 511 | R26: =SUM(F26:Q26) -> 0
D27: Bán Laptop | E27: 511 | R27: =SUM(F27:Q27) -> 0
D28: Bán khác | E28: 711 | R28: =SUM(F28:Q28) -> 0
A29: 4 | B29: Công ty TNHH MTV Đồng Lâm | C29: 1501075079 | D29: Bán hàng nhựa | E29: 511 | R29: =SUM(F29:Q29) -> 0
D30: Bán nguyên vật liệu | E30: 511 | R30: =SUM(F30:Q30) -> 0
D31: Bán vật tư | E31: 511 | R31: =SUM(F31:Q31) -> 0
D32: Cho thuê máy móc | E32: 511 | R32: =SUM(F32:Q32) -> 0
D33: CP công tác | E33: 511 | R33: =SUM(F33:Q33) -> 0
D34: Bán TSCĐ | E34: 711 | R34: =SUM(F34:Q34) -> 0
D35: Bán khác | E35: 7118 | R35: =SUM(F35:Q35) -> 0
A36: 5 | B36: Công ty TNHH Thu mua phế liệu Khánh Nga | C36: 1201638316 | D36: Bán hàng nhựa | E36: 511 | R36: =SUM(F36:Q36) -> 0
D37: Bán nguyên vật liệu | E37: 511 | R37: =SUM(F37:Q37) -> 0
D38: Bán TSCĐ | E38: 711 | R38: =SUM(F38:Q38) -> 0
D39: Bán vật tư | E39: 511 | R39: =SUM(F39:Q39) -> 0
D40: CP công tác | E40: 511 | R40: =SUM(F40:Q40) -> 0
D41: Cho thuê máy móc | E41: 511 | R41: =SUM(F41:Q41) -> 0
...
