Workbook

Sheet Thong tin
A1: CÔNG TY CP NHỰA TÁI CHẾ DUY TÂN
A2: Địa chỉ: | B2: Lô D2, Cụm Công nghiệp Nhựa Đức Hoà Hạ, Xã Đức Hoà, Tỉnh Tây Ninh
A3: Mã số thuế: | B3: 1100676611
A4: Deadline ngày 5 tây hàng tháng
B6: Năm tài chính hiện tại | C6: 2026
B7: Năm trước | C7: =C6-1 -> 2025
B9: Tháng báo cáo hiện tại | C9: 1
B12: NGƯỜI LẬP BIỂU
B13: Hoàng Duy Danh
B15: KẾ TOÁN TRƯỞNG
B16: Giang Văn Lộc
B18: TỔNG GIÁM ĐỐC
B19: Trần Duy Hy

Sheet BIA
B29: THÁNG 01 NĂM 2026
B50: Thành phố Hồ Chí Minh, Ngày 31 tháng 01 năm 2026

Sheet Index
A1: ='Thong tin'!A1 -> CÔNG TY CP NHỰA TÁI CHẾ DUY TÂN | I1: BÁO CÁO TÀI CHÍNH
A2: ='Thong tin'!A2 -> Địa chỉ:
A10: ="BÁO CÁO TÀI CHÍNH THÁNG "&'Thong tin'!C9&" NĂM 2026" -> BÁO CÁO TÀI CHÍNH THÁNG 1 NĂM 2026 | I10: Trang
A12: BÁO CÁO CỦA BAN GIÁM ĐỐC | I12: 2 - 3
A13: BÁO CÁO KIỂM TOÁN | I13: 4 - 4
A14: - Bảng cân đối kế toán | I14: 1 - 4
A15: - Báo cáo kết quả hoạt động kinh doanh | I15: 5
A16: - Báo cáo lưu chuyển tiền tệ | I16: 6 - 7
A17: - Bản thuyết minh báo cáo tài chính | I17: 11 - 31
A30: (Báo cáo tài chính được lập và trình bày theo Quyết định số 15/2006/QĐ-BTC ngày 20/03/2006
A31: của Bộ trưởng Bộ Tài Chính)

Sheet THTC in
A1: ='Thong tin'!$A$1 -> CÔNG TY CP NHỰA TÁI CHẾ DUY TÂN
A2: ='Thong tin'!B2 -> Lô D2, Cụm Công nghiệp Nhựa Đức Hoà Hạ, Xã Đức Hoà, Tỉnh Tây Ninh
A4: BÁO CÁO TÌNH HÌNH TÀI CHÍNH HỢP NHẤT
A5: ="Năm " & 'Thong tin'!$C$6 -> Năm 2026
C6: ='KQKD in'!G6 -> ĐVT: VNĐ
A7: TÀI SẢN | B7: ="Số cuối tháng"&" "&$D$7 -> Số cuối tháng 1 | C7: ="Số dư đầu năm " & 'Thong tin'!$C$6 -> Số dư đầu năm 2026 | D7: ='Thong tin'!C9 -> 1
A8: A . TÀI SẢN NGẮN HẠN | B8: =B10+B14+B22+B31+B40 -> 1.0523724e+12 | C8: =C10+C14+C22+C31+C40 -> 1006445367388
A10: I. Tiền và các khoản tương đương tiền | B10: =SUM(B11:B12) -> 160064376330 | C10: =SUM(C11:C12) -> 63726156404
A11: 1. Tiền | B11: =OFFSET('Tinh hinh tai chinh'!$BL6,0,'THTC in'!$D$7 - 1) -> 50364376330 | C11: ='Tinh hinh tai chinh'!BK6 -> 48026156404
A12: 2. Các khoản tương đương tiền | B12: =OFFSET('Tinh hinh tai chinh'!$BL7,0,'THTC in'!$D$7 - 1) -> 109700000000 | C12: ='Tinh hinh tai chinh'!BK7 -> 15700000000
A14: II. Các khoản đầu tư tài chính ngắn hạn | B14: =SUM(B15:B20) -> 38542000000 | C14: =SUM(C15:C20) -> 38542000000
A15: 1.Chứng khoán kinh doanh | B15: =OFFSET('Tinh hinh tai chinh'!$BL9,0,'THTC in'!$D$7 - 1) -> 0 | C15: ='Tinh hinh tai chinh'!BK9 -> 0
A16: 2.Dự phòng giảm giá chứng khoán kinh doanh (*) | B16: =OFFSET('Tinh hinh tai chinh'!$BL10,0,'THTC in'!$D$7 - 1) -> 0 | C16: ='Tinh hinh tai chinh'!BK10 -> 0
A17: 3.Đầu tư nắm giữ đến ngày đáo hạn ngắn hạn | B17: =OFFSET('Tinh hinh tai chinh'!$BL11,0,'THTC in'!$D$7 - 1) -> 38542000000 | C17: ='Tinh hinh tai chinh'!BK11 -> 38542000000
A18: 4.Dự phòng đầu tư nắm giữ đến ngày đáo hạn ngắn hạn (*) | B18: =OFFSET('Tinh hinh tai chinh'!$BL12,0,'THTC in'!$D$7 - 1) -> 0 | C18: ='Tinh hinh tai chinh'!BK12 -> 0
A19: 5.Đầu tư ngắn hạn khác | B19: =OFFSET('Tinh hinh tai chinh'!$BL13,0,'THTC in'!$D$7 - 1) -> 0 | C19: ='Tinh hinh tai chinh'!BK13 -> 0
A20: 6.Dự phòng tổn thất các khoản đầu tư ngắn hạn khác (*) | B20: =OFFSET('Tinh hinh tai chinh'!$BL14,0,'THTC in'!$D$7 - 1) -> 0 | C20: ='Tinh hinh tai chinh'!BK14 -> 0
A22: III. Các khoản phải thu ngắn hạn | B22: =SUM(B23:B29) -> 279961205359 | C22: =SUM(C23:C29) -> 310459942750
A23: 1.Phải thu ngắn hạn của khách hàng | B23: =OFFSET('Tinh hinh tai chinh'!$BL16,0,'THTC in'!$D$7 - 1) -> 132729767167 | C23: ='Tinh hinh tai chinh'!BK16 -> 154220517132
A24: 2.Trả trước cho người bán ngắn hạn | B24: =OFFSET('Tinh hinh tai chinh'!$BL17,0,'THTC in'!$D$7 - 1) -> 68216577270 | C24: ='Tinh hinh tai chinh'!BK17 -> 60848470883
A25: 3.Phải thu nội bộ ngắn hạn | B25: =OFFSET('Tinh hinh tai chinh'!$BL18,0,'THTC in'!$D$7 - 1) -> 0 | C25: ='Tinh hinh tai chinh'!BK18 -> 0
A26: 4.Phải thu theo tiến độ hợp đồng xây dựng | B26: =OFFSET('Tinh hinh tai chinh'!$BL19,0,'THTC in'!$D$7 - 1) -> 0 | C26: ='Tinh hinh tai chinh'!BK19 -> 0
A27: 5.Phải thu ngắn hạn khác | B27: =OFFSET('Tinh hinh tai chinh'!$BL20,0,'THTC in'!$D$7 - 1) -> 78504042664 | C27: ='Tinh hinh tai chinh'!BK20 -> 96000050435
A28: 6.Dự phòng phải thu ngắn hạn khó đòi (*) | B28: =OFFSET('Tinh hinh tai chinh'!$BL21,0,'THTC in'!$D$7 - 1) -> -609095700 | C28: ='Tinh hinh tai chinh'!BK21 -> -609095700
A29: 7.Tài sản thiếu chờ xử lý | B29: =OFFSET('Tinh hinh tai chinh'!$BL22,0,'THTC in'!$D$7 - 1) -> 1119913958 | C29: ='Tinh hinh tai chinh'!BK22 -> 0
A31: IV. Hàng tồn kho | B31: =SUM(B32:B33) -> 5.489099e+11 | C31: =SUM(C32:C33) -> 570584514136
A32: 1. Hàng tồn kho | B32: =OFFSET('Tinh hinh tai chinh'!$BL24,0,'THTC in'!$D$7 - 1) -> 5.489099e+11 | C32: ='Tinh hinh tai chinh'!BK24 -> 570584514136
A33: 2. Dự phòng giảm giá hàng tồn kho (*) | B33: =OFFSET('Tinh hinh tai chinh'!$BL25,0,'THTC in'!$D$7 - 1) -> 0 | C33: ='Tinh hinh tai chinh'!BK25 -> 0
A35: V. Tài sản sinh học ngắn hạn | B35: =SUM(B36:B38) -> 0 | C35: =SUM(C36:C38) -> 0
A36: 1.Súc vật nuôi lấy sản phẩm một lần ngắn hạn | B36: =OFFSET('Tinh hinh tai chinh'!$BL27,0,'THTC in'!$D$7 - 1) -> 0 | C36: ='Tinh hinh tai chinh'!BK27 -> 0
A37: 2.Cây trồng theo mùa vụ hoặc lấy sản phẩm một lần ngắn hạn | B37: =OFFSET('Tinh hinh tai chinh'!$BL28,0,'THTC in'!$D$7 - 1) -> 0 | C37: ='Tinh hinh tai chinh'!BK28 -> 0
A38: 3.Dự phòng tổn thất tài sản sinh học ngắn hạn (*) | B38: =OFFSET('Tinh hinh tai chinh'!$BL29,0,'THTC in'!$D$7 - 1) -> 0 | C38: ='Tinh hinh tai chinh'!BK29 -> 0
A40: VI. Tài sản ngắn hạn khác | B40: =SUM(B41:B45) -> 24894891645 | C40: =SUM(C41:C45) -> 23132754098
A41: 1.Chi phí chờ phân bổ ngắn hạn | B41: =OFFSET('Tinh hinh tai chinh'!$BL31,0,'THTC in'!$D$7 - 1) -> 8760714009 | C41: ='Tinh hinh tai chinh'!BK31 -> 9528997722
A42: 2.Thuế GTGT được khấu trừ | B42: =OFFSET('Tinh hinh tai chinh'!$BL32,0,'THTC in'!$D$7 - 1) -> 15814070933 | C42: ='Tinh hinh tai chinh'!BK32 -> 13603756376
A43: 3.Thuế và các khoản khác phải thu Nhà nước | B43: =OFFSET('Tinh hinh tai chinh'!$BL33,0,'THTC in'!$D$7 - 1) -> 320106703 | C43: ='Tinh hinh tai chinh'!BK33 -> 0
A44: 4.Giao dịch mua bán lại trái phiếu Chính phủ | B44: =OFFSET('Tinh hinh tai chinh'!$BL34,0,'THTC in'!$D$7 - 1) -> 0 | C44: ='Tinh hinh tai chinh'!BK34 -> 0
A45: 5.Tài sản ngắn hạn khác | B45: =OFFSET('Tinh hinh tai chinh'!$BL35,0,'THTC in'!$D$7 - 1) -> 0 | C45: ='Tinh hinh tai chinh'!BK35 -> 0
A47: B. TÀI SẢN DÀI HẠN | B47: =B48+B58+B79+B87+B95+B83 -> 371950740747 | C47: =C48+C58+C79+C87+C95+C83 -> 370861183445
A48: I.Các khoản phải thu dài hạn | B48: =SUM(B49:B54) -> 5315314211 | C48: =SUM(C49:C54) -> 5600000000
...

Sheet KQKD in
A1: ='Thong tin'!$A$1 -> CÔNG TY CP NHỰA TÁI CHẾ DUY TÂN
A2: ='Thong tin'!B2 -> Lô D2, Cụm Công nghiệp Nhựa Đức Hoà Hạ, Xã Đức Hoà, Tỉnh Tây Ninh
A4: BÁO CÁO KẾT QUẢ HOẠT ĐỘNG KINH DOANH HỢP NHẤT
A5: ="Năm " & 'Thong tin'!$C$6 -> Năm 2026
G6: ĐVT: VNĐ
A8: Chỉ tiêu | D8: ="Tháng "&'Thong tin'!$C$9 -> Tháng 1 | F8: ="Lũy kế"&" "&'Thong tin'!$C$9 &" "&"tháng" -> Lũy kế 1 tháng
D9: ="Năm " & 'Thong tin'!$C$6 -> Năm 2026 | E9: ="Năm " & 'Thong tin'!$C$7 -> Năm 2025 | F9: ="Năm " & 'Thong tin'!$C$6 -> Năm 2026 | G9: ="Năm " & 'Thong tin'!$C$7 -> Năm 2025
A10: 1. | B10: Doanh thu bán hàng và cung cấp dịch vụ | D10: =OFFSET('Ket qua kinh doanh'!$BL5,0,'Thong tin'!$C$9 - 1) -> 126470480720 | E10: =OFFSET('Ket qua kinh doanh'!$AZ5,0,'Thong tin'!$C$9 - 1) -> 114983880947 | F10: =SUM(OFFSET('Ket qua kinh doanh'!$BL5,0,0,1,'Thong tin'!$C$9)) -> 126470480720 | G10: =SUM(OFFSET('Ket qua kinh doanh'!$AZ5,0,0,1,'Thong tin'!$C$9)) -> 114983880947
A11: 2. | B11: Các khoản giảm trừ doanh thu | D11: =OFFSET('Ket qua kinh doanh'!$BL6,0,'Thong tin'!$C$9 - 1) -> 687876997 | E11: =OFFSET('Ket qua kinh doanh'!$AZ6,0,'Thong tin'!$C$9 - 1) -> 513935495 | F11: =SUM(OFFSET('Ket qua kinh doanh'!$BL6,0,0,1,'Thong tin'!$C$9)) -> 687876997 | G11: =SUM(OFFSET('Ket qua kinh doanh'!$AZ6,0,0,1,'Thong tin'!$C$9)) -> 513935495
A12: 3. | B12: Doanh thu thuần về bán hàng và cung cấp dịch vụ | D12: =OFFSET('Ket qua kinh doanh'!$BL7,0,'Thong tin'!$C$9 - 1) -> 125782603723 | E12: =OFFSET('Ket qua kinh doanh'!$AZ7,0,'Thong tin'!$C$9 - 1) -> 114469945452 | F12: =SUM(OFFSET('Ket qua kinh doanh'!$BL7,0,0,1,'Thong tin'!$C$9)) -> 125782603723 | G12: =SUM(OFFSET('Ket qua kinh doanh'!$AZ7,0,0,1,'Thong tin'!$C$9)) -> 114469945452
A13: 4. | B13: Giá vốn hàng bán | D13: =OFFSET('Ket qua kinh doanh'!$BL8,0,'Thong tin'!$C$9 - 1) -> 1.142049e+11 | E13: =OFFSET('Ket qua kinh doanh'!$AZ8,0,'Thong tin'!$C$9 - 1) -> 97986840184 | F13: =SUM(OFFSET('Ket qua kinh doanh'!$BL8,0,0,1,'Thong tin'!$C$9)) -> 1.142049e+11 | G13: =SUM(OFFSET('Ket qua kinh doanh'!$AZ8,0,0,1,'Thong tin'!$C$9)) -> 97986840184
A14: 5. | B14: Lợi nhuận gộp về bán hàng và cung cấp dịch vụ | D14: =OFFSET('Ket qua kinh doanh'!$BL9,0,'Thong tin'!$C$9 - 1) -> 1.1577706e+10 | E14: =OFFSET('Ket qua kinh doanh'!$AZ9,0,'Thong tin'!$C$9 - 1) -> 16483105268 | F14: =SUM(OFFSET('Ket qua kinh doanh'!$BL9,0,0,1,'Thong tin'!$C$9)) -> 1.1577706e+10 | G14: =SUM(OFFSET('Ket qua kinh doanh'!$AZ9,0,0,1,'Thong tin'!$C$9)) -> 16483105268
A15: 6. | B15: Lãi/lỗ của hoạt động bán, thanh lý bất động sản đầu tư | D15: =OFFSET('Ket qua kinh doanh'!$BL10,0,'Thong tin'!$C$9 - 1) -> 0 | E15: =OFFSET('Ket qua kinh doanh'!$AZ10,0,'Thong tin'!$C$9 - 1) -> 0 | F15: =SUM(OFFSET('Ket qua kinh doanh'!$BL10,0,0,1,'Thong tin'!$C$9)) -> 0 | G15: =SUM(OFFSET('Ket qua kinh doanh'!$AZ10,0,0,1,'Thong tin'!$C$9)) -> 0
A16: 7. | B16: Doanh thu hoạt động tài chính | D16: =OFFSET('Ket qua kinh doanh'!$BL11,0,'Thong tin'!$C$9 - 1) -> 1119033075 | E16: =OFFSET('Ket qua kinh doanh'!$AZ11,0,'Thong tin'!$C$9 - 1) -> 830662240 | F16: =SUM(OFFSET('Ket qua kinh doanh'!$BL11,0,0,1,'Thong tin'!$C$9)) -> 1119033075 | G16: =SUM(OFFSET('Ket qua kinh doanh'!$AZ11,0,0,1,'Thong tin'!$C$9)) -> 830662240
A17: 8. | B17: Chi phí tài chính | D17: =OFFSET('Ket qua kinh doanh'!$BL12,0,'Thong tin'!$C$9 - 1) -> 1532817392 | E17: =OFFSET('Ket qua kinh doanh'!$AZ12,0,'Thong tin'!$C$9 - 1) -> 1529745602 | F17: =SUM(OFFSET('Ket qua kinh doanh'!$BL12,0,0,1,'Thong tin'!$C$9)) -> 1532817392 | G17: =SUM(OFFSET('Ket qua kinh doanh'!$AZ12,0,0,1,'Thong tin'!$C$9)) -> 1529745602
B18: Trong đó: chi phí lãi vay | D18: =OFFSET('Ket qua kinh doanh'!$BL13,0,'Thong tin'!$C$9 - 1) -> 1240115065 | E18: =OFFSET('Ket qua kinh doanh'!$AZ13,0,'Thong tin'!$C$9 - 1) -> 1114824276 | F18: =SUM(OFFSET('Ket qua kinh doanh'!$BL13,0,0,1,'Thong tin'!$C$9)) -> 1240115065 | G18: =SUM(OFFSET('Ket qua kinh doanh'!$AZ13,0,0,1,'Thong tin'!$C$9)) -> 1114824276
A19: 9. | B19: Chi phí bán hàng | D19: =OFFSET('Ket qua kinh doanh'!$BL14,0,'Thong tin'!$C$9 - 1) -> 4308598004 | E19: =OFFSET('Ket qua kinh doanh'!$AZ14,0,'Thong tin'!$C$9 - 1) -> 4181224849 | F19: =SUM(OFFSET('Ket qua kinh doanh'!$BL14,0,0,1,'Thong tin'!$C$9)) -> 4308598004 | G19: =SUM(OFFSET('Ket qua kinh doanh'!$AZ14,0,0,1,'Thong tin'!$C$9)) -> 4181224849
A20: 10. | B20: Chi phí quản lý doanh nghiệp | D20: =OFFSET('Ket qua kinh doanh'!$BL15,0,'Thong tin'!$C$9 - 1) -> 9741945070 | E20: =OFFSET('Ket qua kinh doanh'!$AZ15,0,'Thong tin'!$C$9 - 1) -> 8548199037 | F20: =SUM(OFFSET('Ket qua kinh doanh'!$BL15,0,0,1,'Thong tin'!$C$9)) -> 9741945070 | G20: =SUM(OFFSET('Ket qua kinh doanh'!$AZ15,0,0,1,'Thong tin'!$C$9)) -> 8548199037
A21: 11. | B21: Lợi nhuận thuần từ hoạt động kinh doanh | D21: =OFFSET('Ket qua kinh doanh'!$BL16,0,'Thong tin'!$C$9 - 1) -> -2.8866209e+09 | E21: =OFFSET('Ket qua kinh doanh'!$AZ16,0,'Thong tin'!$C$9 - 1) -> 3054598020 | F21: =SUM(OFFSET('Ket qua kinh doanh'!$BL16,0,0,1,'Thong tin'!$C$9)) -> -2.8866209e+09 | G21: =SUM(OFFSET('Ket qua kinh doanh'!$AZ16,0,0,1,'Thong tin'!$C$9)) -> 3054598020
A22: 12. | B22: Thu nhập khác | D22: =OFFSET('Ket qua kinh doanh'!$BL17,0,'Thong tin'!$C$9 - 1) -> 62317597 | E22: =OFFSET('Ket qua kinh doanh'!$AZ17,0,'Thong tin'!$C$9 - 1) -> 105489733 | F22: =SUM(OFFSET('Ket qua kinh doanh'!$BL17,0,0,1,'Thong tin'!$C$9)) -> 62317597 | G22: =SUM(OFFSET('Ket qua kinh doanh'!$AZ17,0,0,1,'Thong tin'!$C$9)) -> 105489733
A23: 13. | B23: Chi phí khác | D23: =OFFSET('Ket qua kinh doanh'!$BL18,0,'Thong tin'!$C$9 - 1) -> 243870060 | E23: =OFFSET('Ket qua kinh doanh'!$AZ18,0,'Thong tin'!$C$9 - 1) -> 60241342 | F23: =SUM(OFFSET('Ket qua kinh doanh'!$BL18,0,0,1,'Thong tin'!$C$9)) -> 243870060 | G23: =SUM(OFFSET('Ket qua kinh doanh'!$AZ18,0,0,1,'Thong tin'!$C$9)) -> 60241342
A24: 14. | B24: Lợi nhuận khác | D24: =OFFSET('Ket qua kinh doanh'!$BL19,0,'Thong tin'!$C$9 - 1) -> -181552463 | E24: =OFFSET('Ket qua kinh doanh'!$AZ19,0,'Thong tin'!$C$9 - 1) -> 45248391 | F24: =SUM(OFFSET('Ket qua kinh doanh'!$BL19,0,0,1,'Thong tin'!$C$9)) -> -181552463 | G24: =SUM(OFFSET('Ket qua kinh doanh'!$AZ19,0,0,1,'Thong tin'!$C$9)) -> 45248391
A25: 15. | B25: Tổng lợi nhuận kế toán trước thuế | D25: =OFFSET('Ket qua kinh doanh'!$BL20,0,'Thong tin'!$C$9 - 1) -> -3.0681734e+09 | E25: =OFFSET('Ket qua kinh doanh'!$AZ20,0,'Thong tin'!$C$9 - 1) -> 3099846411 | F25: =SUM(OFFSET('Ket qua kinh doanh'!$BL20,0,0,1,'Thong tin'!$C$9)) -> -3.0681734e+09 | G25: =SUM(OFFSET('Ket qua kinh doanh'!$AZ20,0,0,1,'Thong tin'!$C$9)) -> 3099846411
A26: 16. | B26: Chi phí thuế TNDN hiện hành (*) | D26: =OFFSET('Ket qua kinh doanh'!$BL22,0,'Thong tin'!$C$9 - 1) -> 0 | E26: =OFFSET('Ket qua kinh doanh'!$AZ21,0,'Thong tin'!$C$9 - 1) -> 864190686 | F26: =SUM(OFFSET('Ket qua kinh doanh'!$BL22,0,0,1,'Thong tin'!$C$9)) -> 0 | G26: =SUM(OFFSET('Ket qua kinh doanh'!$AZ21,0,0,1,'Thong tin'!$C$9)) -> 864190686
A27: 17. | B27: Chi phí thuế TNDN hoãn lại | D27: =OFFSET('Ket qua kinh doanh'!BL22,0,'Thong tin'!$C$9 - 1) -> 0 | E27: =OFFSET('Ket qua kinh doanh'!$AZ22,0,'Thong tin'!$C$9 - 1) -> 0 | F27: =SUM(OFFSET('Ket qua kinh doanh'!BL22,0,0,1,'Thong tin'!$C$9)) -> 0 | G27: =SUM(OFFSET('Ket qua kinh doanh'!$AZ22,0,0,1,'Thong tin'!$C$9)) -> 0
A28: 18. | B28: Lợi nhuận sau thuế | D28: =OFFSET('Ket qua kinh doanh'!$BL23,0,'Thong tin'!$C$9 - 1) -> -3.0681734e+09 | E28: =OFFSET('Ket qua kinh doanh'!$AZ23,0,'Thong tin'!$C$9 - 1) -> 2235655725 | F28: =SUM(OFFSET('Ket qua kinh doanh'!$BL23,0,0,1,'Thong tin'!$C$9)) -> -3.0681734e+09 | G28: =SUM(OFFSET('Ket qua kinh doanh'!$AZ23,0,0,1,'Thong tin'!$C$9)) -> 2235655725
A29: 19. | B29: Lãi cơ bản trên cổ phiếu | F29: =#REF!+#REF!+#REF!+#REF!+#REF!+#REF!+#REF!+#REF!+#REF!+#REF!+#REF!+D29 -> #REF! | G29: =#REF!+#REF!+#REF!+#REF!+#REF!+#REF!+#REF!+#REF!+#REF!+#REF!+#REF!+E29 -> #REF!
D31: 0 | E31: 0 | F31: 0 | G31: 0
F32: Lập, ngày 30 tháng 11 năm 2025
B34: KẾ TOÁN TRƯỞNG | F34: ='Thong tin'!B18 -> TỔNG GIÁM ĐỐC
B41: ='Thong tin'!B16 -> Giang Văn Lộc | F41: ='Thong tin'!B19 -> Trần Duy Hy

Sheet LCTT_GT in
A1: ='Thong tin'!$A$1 -> CÔNG TY CP NHỰA TÁI CHẾ DUY TÂN
A2: ='Thong tin'!B2 -> Lô D2, Cụm Công nghiệp Nhựa Đức Hoà Hạ, Xã Đức Hoà, Tỉnh Tây Ninh
A4: BÁO CÁO LƯU CHUYỂN TIỀN TỆ HỢP NHẤT
A5: (Theo phương pháp gián tiếp)
A6: ="Năm " & 'Thong tin'!$C$6 -> Năm 2026
E7: ='KQKD in'!G6 -> ĐVT: VNĐ
A8: Chỉ tiêu | B8: ="Tháng " & 'Thong tin'!$C$9 -> Tháng 1 | D8: ="Lũy kế"&" "& 'Thong tin'!$C$9 &" "&"tháng" -> Lũy kế 1 tháng
B9: ="Năm " & 'Thong tin'!$C$6 -> Năm 2026 | C9: ="Năm " & 'Thong tin'!$C$7 -> Năm 2025 | D9: ="Năm " & 'Thong tin'!$C$6 -> Năm 2026 | E9: ="Năm " & 'Thong tin'!$C$7 -> Năm 2025
A10: I. Lưu chuyển tiền từ hoạt động kinh doanh
A11: 1. Lợi nhuận trước thuế | B11: =OFFSET('Luu chuyen tien te'!$BL5,0,'Thong tin'!$C$9 - 1) -> -3.0681734e+09 | C11: =OFFSET('Luu chuyen tien te'!$AZ5,0,'Thong tin'!$C$9 - 1) -> 3099846411 | D11: =SUM(OFFSET('Luu chuyen tien te'!$BL5,0,0,1,'Thong tin'!$C$9)) -> -3.0681734e+09 | E11: =SUM(OFFSET('Luu chuyen tien te'!$AZ5,0,0,1,'Thong tin'!$C$9)) -> 3099846411
A12: 2. Điều chỉnh cho các khoản
A13: - Khấu hao tài sản cố định và BĐSĐT | B13: =OFFSET('Luu chuyen tien te'!$BL7,0,'Thong tin'!$C$9 - 1) -> 2875404568 | C13: =OFFSET('Luu chuyen tien te'!$AZ7,0,'Thong tin'!$C$9 - 1) -> 4869731514 | D13: =SUM(OFFSET('Luu chuyen tien te'!$BL7,0,0,1,'Thong tin'!$C$9)) -> 2875404568 | E13: =SUM(OFFSET('Luu chuyen tien te'!$AZ7,0,0,1,'Thong tin'!$C$9)) -> 4869731514
A14: - Các khoản dự phòng | B14: =OFFSET('Luu chuyen tien te'!$BL8,0,'Thong tin'!$C$9 - 1) -> 0 | C14: =OFFSET('Luu chuyen tien te'!$AZ8,0,'Thong tin'!$C$9 - 1) -> 0 | D14: =SUM(OFFSET('Luu chuyen tien te'!$BL8,0,0,1,'Thong tin'!$C$9)) -> 0 | E14: =SUM(OFFSET('Luu chuyen tien te'!$AZ8,0,0,1,'Thong tin'!$C$9)) -> 0
A15: - Lãi, lỗ chênh lệch tỷ giá hối đoái do đánh giá lại các khoản mục tiền tệ có gốc ngoại tệ | B15: =OFFSET('Luu chuyen tien te'!$BL9,0,'Thong tin'!$C$9 - 1) -> -282378363 | C15: =OFFSET('Luu chuyen tien te'!$AZ9,0,'Thong tin'!$C$9 - 1) -> -357780096 | D15: =SUM(OFFSET('Luu chuyen tien te'!$BL9,0,0,1,'Thong tin'!$C$9)) -> -282378363 | E15: =SUM(OFFSET('Luu chuyen tien te'!$AZ9,0,0,1,'Thong tin'!$C$9)) -> -357780096
A16: - Lãi lỗ từ hoạt động đầu tư, tài chính | B16: =OFFSET('Luu chuyen tien te'!$BL10,0,'Thong tin'!$C$9 - 1) -> -67576364 | C16: =OFFSET('Luu chuyen tien te'!$AZ10,0,'Thong tin'!$C$9 - 1) -> -454865223 | D16: =SUM(OFFSET('Luu chuyen tien te'!$BL10,0,0,1,'Thong tin'!$C$9)) -> -67576364 | E16: =SUM(OFFSET('Luu chuyen tien te'!$AZ10,0,0,1,'Thong tin'!$C$9)) -> -454865223
A17: - Chi phí đi vay | B17: =OFFSET('Luu chuyen tien te'!$BL11,0,'Thong tin'!$C$9 - 1) -> 1240115065 | C17: =OFFSET('Luu chuyen tien te'!$AZ11,0,'Thong tin'!$C$9 - 1) -> 739360517 | D17: =SUM(OFFSET('Luu chuyen tien te'!$BL11,0,0,1,'Thong tin'!$C$9)) -> 1240115065 | E17: =SUM(OFFSET('Luu chuyen tien te'!$AZ11,0,0,1,'Thong tin'!$C$9)) -> 739360517
A18: - Các khoản điều chỉnh khác | B18: =OFFSET('Luu chuyen tien te'!$BL12,0,'Thong tin'!$C$9 - 1) -> -128152205 | C18: =OFFSET('Luu chuyen tien te'!$AZ12,0,'Thong tin'!$C$9 - 1) -> 5872690 | D18: =SUM(OFFSET('Luu chuyen tien te'!$BL12,0,0,1,'Thong tin'!$C$9)) -> -128152205 | E18: =SUM(OFFSET('Luu chuyen tien te'!$AZ12,0,0,1,'Thong tin'!$C$9)) -> 5872690
A19: 3. Lợi nhuận từ hoạt động kinh doanh trước thay đổi vốn lưu động | B19: =SUM(B11:B18) -> 5.6923931e+08 | C19: =SUM(C11:C18) -> 7902165813 | D19: =SUM(D11:D18) -> 5.6923931e+08 | E19: =SUM(E11:E18) -> 7902165813
A20: - Tăng giảm các khoản phải thu | B20: =OFFSET('Luu chuyen tien te'!$BL14,0,'Thong tin'!$C$9 - 1) -> 53673466483 | C20: =OFFSET('Luu chuyen tien te'!$AZ14,0,'Thong tin'!$C$9 - 1) -> 5.6768186e+10 | D20: =SUM(OFFSET('Luu chuyen tien te'!$BL14,0,0,1,'Thong tin'!$C$9)) -> 53673466483 | E20: =SUM(OFFSET('Luu chuyen tien te'!$AZ14,0,0,1,'Thong tin'!$C$9)) -> 5.6768186e+10
A21: - Tăng giảm hàng tồn kho | B21: =OFFSET('Luu chuyen tien te'!$BL15,0,'Thong tin'!$C$9 - 1) -> 2.1674615e+10 | C21: =OFFSET('Luu chuyen tien te'!$AZ15,0,'Thong tin'!$C$9 - 1) -> 34011025895 | D21: =SUM(OFFSET('Luu chuyen tien te'!$BL15,0,0,1,'Thong tin'!$C$9)) -> 2.1674615e+10 | E21: =SUM(OFFSET('Luu chuyen tien te'!$AZ15,0,0,1,'Thong tin'!$C$9)) -> 34011025895
A22: - Tăng giảm các khoản phải trả (Không bao gồm lãi vay phải trả, thuế TNDN phải nộp) | B22: =OFFSET('Luu chuyen tien te'!$BL16,0,'Thong tin'!$C$9 - 1) -> -10264950362 | C22: =OFFSET('Luu chuyen tien te'!$AZ16,0,'Thong tin'!$C$9 - 1) -> -2.1447247e+10 | D22: =SUM(OFFSET('Luu chuyen tien te'!$BL16,0,0,1,'Thong tin'!$C$9)) -> -10264950362 | E22: =SUM(OFFSET('Luu chuyen tien te'!$AZ16,0,0,1,'Thong tin'!$C$9)) -> -2.1447247e+10
A23: - Tăng giảm chi phí chờ phân bổ | B23: =OFFSET('Luu chuyen tien te'!$BL17,0,'Thong tin'!$C$9 - 1) -> 2029033267 | C23: =OFFSET('Luu chuyen tien te'!$AZ17,0,'Thong tin'!$C$9 - 1) -> -594058884 | D23: =SUM(OFFSET('Luu chuyen tien te'!$BL17,0,0,1,'Thong tin'!$C$9)) -> 2029033267 | E23: =SUM(OFFSET('Luu chuyen tien te'!$AZ17,0,0,1,'Thong tin'!$C$9)) -> -594058884
A24: - Tăng, giảm chứng khoán kinh doanh | B24: =OFFSET('Luu chuyen tien te'!$BL18,0,'Thong tin'!$C$9 - 1) -> 0 | C24: =OFFSET('Luu chuyen tien te'!$AZ18,0,'Thong tin'!$C$9 - 1) -> 0 | D24: =SUM(OFFSET('Luu chuyen tien te'!$BL18,0,0,1,'Thong tin'!$C$9)) -> 0 | E24: =SUM(OFFSET('Luu chuyen tien te'!$AZ18,0,0,1,'Thong tin'!$C$9)) -> 0
A25: - Chi phí đi vay đã trả | B25: =OFFSET('Luu chuyen tien te'!$BL19,0,'Thong tin'!$C$9 - 1) -> -1240115065 | C25: =OFFSET('Luu chuyen tien te'!$AZ19,0,'Thong tin'!$C$9 - 1) -> -739360517 | D25: =SUM(OFFSET('Luu chuyen tien te'!$BL19,0,0,1,'Thong tin'!$C$9)) -> -1240115065 | E25: =SUM(OFFSET('Luu chuyen tien te'!$AZ19,0,0,1,'Thong tin'!$C$9)) -> -739360517
A26: - Thuế thu nhập doanh nghiệp đã nộp | B26: =OFFSET('Luu chuyen tien te'!$BL20,0,'Thong tin'!$C$9 - 1) -> 0 | C26: =OFFSET('Luu chuyen tien te'!$AZ20,0,'Thong tin'!$C$9 - 1) -> 0 | D26: =SUM(OFFSET('Luu chuyen tien te'!$BL20,0,0,1,'Thong tin'!$C$9)) -> 0 | E26: =SUM(OFFSET('Luu chuyen tien te'!$AZ20,0,0,1,'Thong tin'!$C$9)) -> 0
A27: - Tiền thu khác từ hoạt động kinh doanh | B27: =OFFSET('Luu chuyen tien te'!$BL21,0,'Thong tin'!$C$9 - 1) -> 0 | C27: =OFFSET('Luu chuyen tien te'!$AZ21,0,'Thong tin'!$C$9 - 1) -> 0 | D27: =SUM(OFFSET('Luu chuyen tien te'!$BL21,0,0,1,'Thong tin'!$C$9)) -> 0 | E27: =SUM(OFFSET('Luu chuyen tien te'!$AZ21,0,0,1,'Thong tin'!$C$9)) -> 0
A28: - Tiền chi khác cho hoạt động kinh doanh | B28: =OFFSET('Luu chuyen tien te'!$BL22,0,'Thong tin'!$C$9 - 1) -> -8060010807 | C28: =OFFSET('Luu chuyen tien te'!$AZ22,0,'Thong tin'!$C$9 - 1) -> -2457877506 | D28: =SUM(OFFSET('Luu chuyen tien te'!$BL22,0,0,1,'Thong tin'!$C$9)) -> -8060010807 | E28: =SUM(OFFSET('Luu chuyen tien te'!$AZ22,0,0,1,'Thong tin'!$C$9)) -> -2457877506
A29: Lưu chuyển tiền thuần từ hoạt động kinh doanh | B29: =SUM(B19:B28) -> 58381278265 | C29: =SUM(C19:C28) -> 7.3442834e+10 | D29: =SUM(D19:D28) -> 58381278265 | E29: =SUM(E19:E28) -> 7.3442834e+10
A30: II. Lưu chuyển tiền từ hoạt động đầu tư
A31: 1. Tiền chi để mua sắm, xây dựng TSCĐ và các tài sản dài hạn khác | B31: =OFFSET('Luu chuyen tien te'!$BL25,0,'Thong tin'!$C$9 - 1) -> -10076408181 | C31: =OFFSET('Luu chuyen tien te'!$AZ25,0,'Thong tin'!$C$9 - 1) -> -9821622713 | D31: =SUM(OFFSET('Luu chuyen tien te'!$BL25,0,0,1,'Thong tin'!$C$9)) -> -10076408181 | E31: =SUM(OFFSET('Luu chuyen tien te'!$AZ25,0,0,1,'Thong tin'!$C$9)) -> -9821622713
A32: 2. Tiền thu từ thanh lý, nhượng bán TSCĐ và các tài sản dài hạn khác | B32: =OFFSET('Luu chuyen tien te'!$BL26,0,'Thong tin'!$C$9 - 1) -> 0 | C32: =OFFSET('Luu chuyen tien te'!$AZ26,0,'Thong tin'!$C$9 - 1) -> 0 | D32: =SUM(OFFSET('Luu chuyen tien te'!$BL26,0,0,1,'Thong tin'!$C$9)) -> 0 | E32: =SUM(OFFSET('Luu chuyen tien te'!$AZ26,0,0,1,'Thong tin'!$C$9)) -> 0
A33: 3. Tiền chi cho vay, mua các công cụ nợ của đơn vị khác | B33: =OFFSET('Luu chuyen tien te'!$BL27,0,'Thong tin'!$C$9 - 1) -> 0 | C33: =OFFSET('Luu chuyen tien te'!$AZ27,0,'Thong tin'!$C$9 - 1) -> -2000000000 | D33: =SUM(OFFSET('Luu chuyen tien te'!$BL27,0,0,1,'Thong tin'!$C$9)) -> 0 | E33: =SUM(OFFSET('Luu chuyen tien te'!$AZ27,0,0,1,'Thong tin'!$C$9)) -> -2000000000
A34: 4. Tiền thu hồi cho vay, bán lại các công cụ nợ của đơn vị khác | B34: =OFFSET('Luu chuyen tien te'!$BL28,0,'Thong tin'!$C$9 - 1) -> 0 | C34: =OFFSET('Luu chuyen tien te'!$AZ28,0,'Thong tin'!$C$9 - 1) -> 0 | D34: =SUM(OFFSET('Luu chuyen tien te'!$BL28,0,0,1,'Thong tin'!$C$9)) -> 0 | E34: =SUM(OFFSET('Luu chuyen tien te'!$AZ28,0,0,1,'Thong tin'!$C$9)) -> 0
A35: 5. Tiền chi đầu tư góp vốn vào đơn vị khác | B35: =OFFSET('Luu chuyen tien te'!$BL29,0,'Thong tin'!$C$9 - 1) -> 0 | C35: =OFFSET('Luu chuyen tien te'!$AZ29,0,'Thong tin'!$C$9 - 1) -> 0 | D35: =SUM(OFFSET('Luu chuyen tien te'!$BL29,0,0,1,'Thong tin'!$C$9)) -> 0 | E35: =SUM(OFFSET('Luu chuyen tien te'!$AZ29,0,0,1,'Thong tin'!$C$9)) -> 0
A36: 6. Tiền thu hồi đầu tư góp vốn vào đơn vị khác | B36: =OFFSET('Luu chuyen tien te'!$BL30,0,'Thong tin'!$C$9 - 1) -> 0 | C36: =OFFSET('Luu chuyen tien te'!$AZ30,0,'Thong tin'!$C$9 - 1) -> 0 | D36: =SUM(OFFSET('Luu chuyen tien te'!$BL30,0,0,1,'Thong tin'!$C$9)) -> 0 | E36: =SUM(OFFSET('Luu chuyen tien te'!$AZ30,0,0,1,'Thong tin'!$C$9)) -> 0
A37: 7. Tiền thu lãi cho vay, cổ tức và lợi nhuận được chia | B37: =OFFSET('Luu chuyen tien te'!$BL31,0,'Thong tin'!$C$9 - 1) -> 67565511 | C37: =OFFSET('Luu chuyen tien te'!$AZ31,0,'Thong tin'!$C$9 - 1) -> 454849601 | D37: =SUM(OFFSET('Luu chuyen tien te'!$BL31,0,0,1,'Thong tin'!$C$9)) -> 67565511 | E37: =SUM(OFFSET('Luu chuyen tien te'!$AZ31,0,0,1,'Thong tin'!$C$9)) -> 454849601
A38: Lưu chuyển tiền thuần từ hoạt động đầu tư | B38: =SUM(B31:B37) -> -10008842670 | C38: =SUM(C31:C37) -> -11366773112 | D38: =SUM(D31:D37) -> -10008842670 | E38: =SUM(E31:E37) -> -11366773112
A39: III. Lưu chuyển tiền từ hoạt động tài chính
A40: 1. Tiền thu từ phát hành cố phiếu, nhận vốn góp của chủ sở hữu | B40: =OFFSET('Luu chuyen tien te'!$BL34,0,'Thong tin'!$C$9 - 1) -> 94000000000 | C40: =OFFSET('Luu chuyen tien te'!$AZ34,0,'Thong tin'!$C$9 - 1) -> 0 | D40: =SUM(OFFSET('Luu chuyen tien te'!$BL34,0,0,1,'Thong tin'!$C$9)) -> 94000000000 | E40: =SUM(OFFSET('Luu chuyen tien te'!$AZ34,0,0,1,'Thong tin'!$C$9)) -> 0
A41: 2. Tiền trả lại vốn góp cho các chủ sở hữu, mua lại cổ phiểu đã phát hành | B41: =OFFSET('Luu chuyen tien te'!$BL35,0,'Thong tin'!$C$9 - 1) -> 0 | C41: =OFFSET('Luu chuyen tien te'!$AZ35,0,'Thong tin'!$C$9 - 1) -> 0 | D41: =SUM(OFFSET('Luu chuyen tien te'!$BL35,0,0,1,'Thong tin'!$C$9)) -> 0 | E41: =SUM(OFFSET('Luu chuyen tien te'!$AZ35,0,0,1,'Thong tin'!$C$9)) -> 0
...

Sheet Tinh hinh tai chinh
B1: ='Thong tin'!A1 -> CÔNG TY CP NHỰA TÁI CHẾ DUY TÂN
B2: VND
A3: Index BS | B3: PHẦN I-BÁO CÁO TÌNH HÌNH TÀI CHÍNH | C3: TenCongTyID | D3: T1.2021 | E3: T02.2021 | F3: T03.2021 | G3: T04.2021 | H3: T05.2021 | I3: T06.2021 | J3: T07.2021 | K3: T08.2021 | L3: T09.2021 | M3: T10.2021 | N3: T11.2021 | O3: T12.2021 | P3: T1.2022 | Q3: T02.2022 | R3: T03.2022 | S3: T04.2022 | T3: T05.2022 | U3: T06.2022 | V3: T07.2022 | W3: T08.2022 | X3: T09.2022 | Y3: T10.2022 | Z3: T11.2022 | AA3: T12.2022 | AB3: T1.2023 | AC3: T02.2023 | AD3: T03.2023 | AE3: T04.2023 | AF3: T05.2023 | AG3: T06.2023 | AH3: T07.2023 | AI3: T08.2023 | AJ3: T09.2023 | AK3: T10.2023 | AL3: T11.2023 | AM3: T12.2023 | AN3: T01.2024 | AO3: T02.2024 | AP3: T03.2024 | AQ3: T04.2024 | AR3: T05.2024 | AS3: T06.2024 | AT3: T07.2024 | AU3: T08.2024 | AV3: T09.2024 | AW3: T10.2024 | AX3: T11.2024 | AY3: T12.2024 | AZ3: T01.2025 | BA3: T02.2025 | BB3: T03.2025 | BC3: T04.2025 | BD3: T05.2025 | BE3: T06.2025 | BF3: T07.2025 | BG3: T08.2025 | BH3: T09.2025 | BI3: T10.2025 | BJ3: T11.2025 | BK3: T12.2025 | BL3: T01.2026 | BM3: T02.2026 | BN3: T03.2026 | BO3: T04.2026 | BP3: T05.2026 | BQ3: T06.2026 | BR3: T07.2026 | BS3: T08.2026 | BT3: T09.2026 | BU3: T10.2026 | BV3: T11.2026 | BW3: T12.2026
A4: 1 | B4: A-TÀI SẢN NGẮN HẠN | C4: 28 | D4: =SUM(D5,D8,D15,D23,D26,D30) -> 0 | E4: =SUM(E5,E8,E15,E23,E26,E30) -> 0 | F4: =SUM(F5,F8,F15,F23,F26,F30) -> 0 | G4: =SUM(G5,G8,G15,G23,G26,G30) -> 0 | H4: =SUM(H5,H8,H15,H23,H26,H30) -> 0 | I4: =SUM(I5,I8,I15,I23,I26,I30) -> 0 | J4: =SUM(J5,J8,J15,J23,J26,J30) -> 0 | K4: =SUM(K5,K8,K15,K23,K26,K30) -> 0 | ... AY4: =SUM(AY5,AY8,AY15,AY23,AY26,AY30) -> 1.0294215e+12 | AZ4: 943346625178 | BA4: 859080481889 | BB4: 9.1202252e+11 | BC4: 976848146781 | BD4: 1029083422325 | BE4: 1.0633737e+12 | BF4: 1.0584513e+12 | BG4: 1.1198022e+12 | BH4: 1.0988051e+12 | BI4: 1.0369397e+12 | BJ4: 1.0159101e+12 | BK4: 1006445367388 | BL4: 1.0523724e+12 | BM4: 1.046079e+12 | BN4: 9.9512057e+11 | BO4: 9.5578373e+11 | BP4: 1.0354979e+12 | BQ4: 9.7165087e+11 | BR4: =SUM(BR5,BR8,BR15,BR23,BR26,BR30) -> 0 | BS4: =SUM(BS5,BS8,BS15,BS23,BS26,BS30) -> 0 | BT4: =SUM(BT5,BT8,BT15,BT23,BT26,BT30) -> 0 | BU4: =SUM(BU5,BU8,BU15,BU23,BU26,BU30) -> 0 | BV4: =SUM(BV5,BV8,BV15,BV23,BV26,BV30) -> 0 | BW4: =SUM(BW5,BW8,BW15,BW23,BW26,BW30) -> 0
A5: 2 | B5: I.Tiền và các khoản tương đương tiền | C5: 28 | D5: =SUM(D6:D7) -> 0 | E5: =SUM(E6:E7) -> 0 | F5: =SUM(F6:F7) -> 0 | G5: =SUM(G6:G7) -> 0 | H5: =SUM(H6:H7) -> 0 | I5: =SUM(I6:I7) -> 0 | J5: =SUM(J6:J7) -> 0 | K5: =SUM(K6:K7) -> 0 | ... AY5: =SUM(AY6:AY7) -> 78515947311 | AZ5: 108757458297 | BA5: 63047560922 | BB5: 57546333332 | BC5: 72781093895 | BD5: 53850392378 | BE5: 47310681042 | BF5: 46943683940 | BG5: 52760383890 | BH5: 94749581700 | BI5: 86336513720 | BJ5: 82814145673 | BK5: 63726156404 | BL5: 160064376330 | BM5: 158595220342 | BN5: 147256262964 | BO5: 165964800039 | BP5: 156543872808 | BQ5: 152981154626 | BR5: =SUM(BR6:BR7) -> 0 | BS5: =SUM(BS6:BS7) -> 0 | BT5: =SUM(BT6:BT7) -> 0 | BU5: =SUM(BU6:BU7) -> 0 | BV5: =SUM(BV6:BV7) -> 0 | BW5: =SUM(BW6:BW7) -> 0
A6: 3 | B6: 1.Tiền | C6: 28 | AN6: 39793249760 | AO6: 29011802774 | AP6: 21563055917 | AQ6: 25763153167 | AR6: 24369136312 | AS6: 14808634542 | AT6: 48441006190 | AU6: 27599490170 | AV6: 41429525475 | AW6: 71014775934 | AX6: 74105192016 | AY6: 61515947311 | AZ6: 98917458297 | BA6: 53207560922 | BB6: 49746333332 | BC6: 64981093895 | BD6: 46850392378 | BE6: 40310681042 | BF6: 40943683940 | BG6: 46060383890 | BH6: 88049581700 | BI6: 51636513720 | BJ6: 50114145673 | BK6: 48026156404 | BL6: 50364376330 | BM6: 51895220342 | BN6: 36356262964 | BO6: 42964800039 | BP6: 41543872808 | BQ6: 36525890669
A7: 4 | B7: 2.Các khoản tương đương tiền | C7: 28 | AN7: 6840000000 | AO7: 6840000000 | AP7: 4830000000 | AQ7: 8830000000 | AR7: 8830000000 | AS7: 4830000000 | AT7: 7830000000 | AU7: 7830000000 | AV7: 7000000000 | AW7: 7000000000 | AX7: 7000000000 | AY7: 17000000000 | AZ7: 9840000000 | BA7: 9840000000 | BB7: 7800000000 | BC7: 7800000000 | BD7: 7000000000 | BE7: 7000000000 | BF7: 6000000000 | BG7: 6700000000 | BH7: 6700000000 | BI7: 34700000000 | BJ7: 32700000000 | BK7: 15700000000 | BL7: 109700000000 | BM7: 106700000000 | BN7: 110900000000 | BO7: 123000000000 | BP7: 115000000000 | BQ7: 116455263957
A8: 5 | B8: II.Đầu tư tài chính ngắn hạn | C8: 28 | D8: =SUM(D9:D14) -> 0 | E8: =SUM(E9:E14) -> 0 | F8: =SUM(F9:F14) -> 0 | G8: =SUM(G9:G14) -> 0 | H8: =SUM(H9:H14) -> 0 | I8: =SUM(I9:I14) -> 0 | J8: =SUM(J9:J14) -> 0 | K8: =SUM(K9:K14) -> 0 | ... AY8: =SUM(AY9:AY14) -> 78774661921 | AZ8: 2202000000 | BA8: 202000000 | BB8: 23042000000 | BC8: 23042000000 | BD8: 23042000000 | BE8: 23042000000 | BF8: 23042000000 | BG8: 23042000000 | BH8: 23042000000 | BI8: 33042000000 | BJ8: 33042000000 | BK8: 38542000000 | BL8: 38542000000 | BM8: 38542000000 | BN8: 38542000000 | BO8: 41042000000 | BP8: 41042000000 | BQ8: 41042000000 | BR8: =SUM(BR9:BR14) -> 0 | BS8: =SUM(BS9:BS14) -> 0 | BT8: =SUM(BT9:BT14) -> 0 | BU8: =SUM(BU9:BU14) -> 0 | BV8: =SUM(BV9:BV14) -> 0 | BW8: =SUM(BW9:BW14) -> 0
A9: 6 | B9: 1.Chứng khoán kinh doanh | C9: 28 | AN9: 0 | AO9: 0 | AP9: 0 | AQ9: 0 | AR9: 0 | AS9: 0 | AT9: 0 | AU9: 0 | AV9: 0 | AW9: 0 | AX9: 0 | AY9: 0 | AZ9: 0 | BA9: 0 | BB9: 0 | BC9: 0 | BD9: 0 | BE9: 0 | BF9: 0 | BG9: 0 | BH9: 0 | BI9: 0 | BJ9: 0 | BK9: 0 | BL9: 0 | BM9: 0 | BN9: 0 | BO9: 0 | BP9: 0 | BQ9: 0
A10: 7 | B10: 2.Dự phòng giảm giá chứng khoán kinh doanh (*) | C10: 28 | AN10: 0 | AO10: 0 | AP10: 0 | AQ10: 0 | AR10: 0 | AS10: 0 | AT10: 0 | AU10: 0 | AV10: 0 | AW10: 0 | AX10: 0 | AY10: 0 | AZ10: 0 | BA10: 0 | BB10: 0 | BC10: 0 | BD10: 0 | BE10: 0 | BF10: 0 | BG10: 0 | BH10: 0 | BI10: 0 | BJ10: 0 | BK10: 0 | BL10: 0 | BM10: 0 | BN10: 0 | BO10: 0 | BP10: 0 | BQ10: 0
A11: 8 | B11: 3.Đầu tư nắm giữ đến ngày đáo hạn ngắn hạn | C11: 28 | AN11: 108051581921 | AO11: 108041861921 | AP11: 108032141921 | AQ11: 97522421921 | AR11: 97512701921 | AS11: 77502981921 | AT11: 57993261921 | AU11: 57983541921 | AV11: 58813541921 | AW11: 58794101921 | AX11: 98794101921 | AY11: 78774661921 | AZ11: 2202000000 | BA11: 202000000 | BB11: 23042000000 | BC11: 23042000000 | BD11: 23042000000 | BE11: 23042000000 | BF11: 23042000000 | BG11: 23042000000 | BH11: 23042000000 | BI11: 33042000000 | BJ11: 33042000000 | BK11: 38542000000 | BL11: 38542000000 | BM11: 38542000000 | BN11: 38542000000 | BO11: 41042000000 | BP11: 41042000000 | BQ11: 41042000000
A12: 9 | B12: 4.Dự phòng đầu tư nắm giữ đến ngày đáo hạn ngắn hạn (*) | C12: 28 | AN12: 0 | AO12: 0 | AP12: 0 | AQ12: 0 | AR12: 0 | AS12: 0 | AT12: 0 | AU12: 0 | AV12: 0 | AW12: 0 | AX12: 0 | AY12: 0 | AZ12: 0 | BA12: 0 | BB12: 0 | BC12: 0 | BD12: 0 | BE12: 0 | BF12: 0 | BG12: 0 | BH12: 0 | BI12: 0 | BJ12: 0 | BK12: 0 | BL12: 0 | BM12: 0 | BN12: 0 | BO12: 0 | BP12: 0 | BQ12: 0
A13: 10 | B13: 5.Đầu tư ngắn hạn khác | C13: 28 | AN13: 0 | AO13: 0 | AP13: 0 | AQ13: 0 | AR13: 0 | AS13: 0 | AT13: 0 | AU13: 0 | AV13: 0 | AW13: 0 | AX13: 0 | AY13: 0 | AZ13: 0 | BA13: 0 | BB13: 0 | BC13: 0 | BD13: 0 | BE13: 0 | BF13: 0 | BG13: 0 | BH13: 0 | BI13: 0 | BJ13: 0 | BK13: 0 | BL13: 0 | BM13: 0 | BN13: 0 | BO13: 0 | BP13: 0 | BQ13: 0
A14: 11 | B14: 6.Dự phòng tổn thất các khoản đầu tư ngắn hạn khác (*) | C14: 28 | AN14: 0 | AO14: 0 | AP14: 0 | AQ14: 0 | AR14: 0 | AS14: 0 | AT14: 0 | AU14: 0 | AV14: 0 | AW14: 0 | AX14: 0 | AY14: 0 | AZ14: 0 | BA14: 0 | BB14: 0 | BC14: 0 | BD14: 0 | BE14: 0 | BF14: 0 | BG14: 0 | BH14: 0 | BI14: 0 | BJ14: 0 | BK14: 0 | BL14: 0 | BM14: 0 | BN14: 0 | BO14: 0 | BP14: 0 | BQ14: 0
A15: 12 | B15: III.Các khoản phải thu ngắn hạn | C15: 28 | D15: =SUM(D16:D22) -> 0 | E15: =SUM(E16:E22) -> 0 | F15: =SUM(F16:F22) -> 0 | G15: =SUM(G16:G22) -> 0 | H15: =SUM(H16:H22) -> 0 | I15: =SUM(I16:I22) -> 0 | J15: =SUM(J16:J22) -> 0 | K15: =SUM(K16:K22) -> 0 | ... AY15: =SUM(AY16:AY22) -> 226296560348 | AZ15: 217735728888 | BA15: 2.6007532e+11 | BB15: 310288883815 | BC15: 2.9689819e+11 | BD15: 3.5420726e+11 | BE15: 365571482051 | BF15: 339058924133 | BG15: 425113236252 | BH15: 357432202896 | BI15: 315052540892 | BJ15: 297501008911 | BK15: 310459942750 | BL15: 279961205359 | BM15: 3.0321697e+11 | BN15: 343051411345 | BO15: 341187593965 | BP15: 431651334653 | BQ15: 324263549252 | BR15: =SUM(BR16:BR22) -> 0 | BS15: =SUM(BS16:BS22) -> 0 | BT15: =SUM(BT16:BT22) -> 0 | BU15: =SUM(BU16:BU22) -> 0 | BV15: =SUM(BV16:BV22) -> 0 | BW15: =SUM(BW16:BW22) -> 0
A16: 13 | B16: 1.Phải thu ngắn hạn của khách hàng | C16: 28 | AN16: 139866573147 | AO16: 145639317187 | AP16: 145029363992 | AQ16: 158990592845 | AR16: 169879811667 | AS16: 169929811366 | AT16: 102331112462 | AU16: 127587662576 | AV16: 161236707683 | AW16: 156193512518 | AX16: 158918995344 | AY16: 159389289311 | AZ16: 104710029317 | BA16: 158254405997 | BB16: 200045097235 | BC16: 155380145983 | BD16: 167509298140 | BE16: 154486175751 | BF16: 153095689903 | BG16: 190031772805 | BH16: 157982845758 | BI16: 151626732436 | BJ16: 154563122279 | BK16: 154220517132 | BL16: 132729767167 | BM16: 1.4012581e+11 | BN16: 152517322708 | BO16: 177359967457 | BP16: 177880438140 | BQ16: 169141546389
A17: 14 | B17: 2.Trả trước cho người bán ngắn hạn | C17: 28 | AN17: 19848285706 | AO17: 18001368927 | AP17: 17409185425 | AQ17: 18980934468 | AR17: 18972917626 | AS17: 16946912554 | AT17: 15624304617 | AU17: 15352055458 | AV17: 12264421488 | AW17: 10758004465 | AX17: 12010431039 | AY17: 24401454639 | AZ17: 14819388431 | BA17: 17646304860 | BB17: 20708830735 | BC17: 26192684967 | BD17: 62897284043 | BE17: 65291388780 | BF17: 54584222857 | BG17: 69767861908 | BH17: 76188674935 | BI17: 71648142604 | BJ17: 61105796375 | BK17: 60848470883 | BL17: 68216577270 | BM17: 71732450749 | BN17: 84845735477 | BO17: 66925106351 | BP17: 153006350044 | BQ17: 40413561398
A18: 15 | B18: 3.Phải thu nội bộ ngắn hạn | C18: 28 | AN18: 0 | AO18: 0 | AP18: 0 | AQ18: 0 | AR18: 0 | AS18: 0 | AT18: 0 | AU18: 0 | AV18: 0 | AW18: 0 | AX18: 0 | AY18: 0 | AZ18: 0 | BA18: 0 | BB18: 0 | BC18: 0 | BD18: 0 | BE18: 0 | BF18: 0 | BG18: 0 | BH18: 0 | BI18: 0 | BJ18: 0 | BK18: 0 | BL18: 0 | BM18: 0 | BN18: 0 | BO18: 0 | BP18: 0 | BQ18: 0
A19: 16 | B19: 4.Phải thu theo tiến độ hợp đồng xây dựng | C19: 28 | AN19: 0 | AO19: 0 | AP19: 0 | AQ19: 0 | AR19: 0 | AS19: 0 | AT19: 0 | AU19: 0 | AV19: 0 | AW19: 0 | AX19: 0 | AY19: 0 | AZ19: 0 | BA19: 0 | BB19: 0 | BC19: 0 | BD19: 0 | BE19: 0 | BF19: 0 | BG19: 0 | BH19: 0 | BI19: 0 | BJ19: 0 | BK19: 0 | BL19: 0 | BM19: 0 | BN19: 0 | BO19: 0 | BP19: 0 | BQ19: 0
A20: 17 | B20: 5.Phải thu ngắn hạn khác | C20: 28 | AN20: 4.9691048e+10 | AO20: 3.0919005e+10 | AP20: 30825313041 | AQ20: 32782410538 | AR20: 3.334478e+10 | AS20: 6.1447479e+10 | AT20: 3.5510919e+10 | AU20: 3.5511786e+10 | AV20: 3.6150353e+10 | AW20: 3.651908e+10 | AX20: 7.2633112e+10 | AY20: 42505816398 | AZ20: 98206311140 | BA20: 8.4174609e+10 | BB20: 89534955845 | BC20: 1.1532535e+11 | BD20: 1.2380067e+11 | BE20: 145793917520 | BF20: 131379011373 | BG20: 165313601539 | BH20: 123260682203 | BI20: 91777665852 | BJ20: 81832090257 | BK20: 96000050435 | BL20: 78504042664 | BM20: 90712080902 | BN20: 105041727014 | BO20: 96255894011 | BP20: 100690688471 | BQ20: 115317537165
A21: 18 | B21: 6.Dự phòng phải thu ngắn hạn khó đòi (*) | C21: 28 | AN21: -120525864 | AO21: -120525864 | AP21: -120525864 | AQ21: -120525864 | AR21: -120525864 | AS21: -120525864 | AT21: -120525864 | AU21: -120525864 | AV21: -120525864 | AW21: -120525864 | AX21: 0 | AY21: 0 | AZ21: 0 | BA21: 0 | BB21: 0 | BC21: 0 | BD21: 0 | BE21: 0 | BF21: 0 | BG21: 0 | BH21: 0 | BI21: 0 | BJ21: 0 | BK21: -609095700 | BL21: -609095700 | BM21: -609095700 | BN21: -609095700 | BO21: -609095700 | BP21: -609095700 | BQ21: -609095700
A22: 19 | B22: 7.Tài sản thiếu chờ xử lý | C22: 28 | AN22: -524609275 | AO22: -524609275 | AP22: 7901392144 | AQ22: 7901392144 | AR22: -524609275 | AS22: -524609275 | AT22: -524609275 | AU22: -524609275 | AV22: -524609275 | AW22: -524609275 | AX22: -524609275 | AY22: 0 | AZ22: 0 | BA22: 0 | BB22: 0 | BC22: 0 | BD22: 0 | BE22: 0 | BF22: 0 | BG22: 0 | BH22: 0 | BI22: 0 | BJ22: 0 | BK22: 0 | BL22: 1119913958 | BM22: 1255721846 | BN22: 1255721846 | BO22: 1255721846 | BP22: 682953698 | BQ22: 0
A23: 20 | B23: IV. Hàng tồn kho | C23: 28 | D23: =SUM(D24:D25) -> 0 | E23: =SUM(E24:E25) -> 0 | F23: =SUM(F24:F25) -> 0 | G23: =SUM(G24:G25) -> 0 | H23: =SUM(H24:H25) -> 0 | I23: =SUM(I24:I25) -> 0 | J23: =SUM(J24:J25) -> 0 | K23: =SUM(K24:K25) -> 0 | ... AY23: =SUM(AY24:AY25) -> 6.143002e+11 | AZ23: 580289170770 | BA23: 5.0050711e+11 | BB23: 4.8064156e+11 | BC23: 5.3494809e+11 | BD23: 5.4006238e+11 | BE23: 5.5977409e+11 | BF23: 5.74369e+11 | BG23: 5.7275897e+11 | BH23: 5.7610944e+11 | BI23: 5.5585695e+11 | BJ23: 5.5808593e+11 | BK23: 570584514136 | BL23: 5.489099e+11 | BM23: 5.1846389e+11 | BN23: 4.3800273e+11 | BO23: 3.7807708e+11 | BP23: 3.7110144e+11 | BQ23: 4.0460838e+11 | BR23: =SUM(BR24:BR25) -> 0 | BS23: =SUM(BS24:BS25) -> 0 | BT23: =SUM(BT24:BT25) -> 0 | BU23: =SUM(BU24:BU25) -> 0 | BV23: =SUM(BV24:BV25) -> 0 | BW23: =SUM(BW24:BW25) -> 0
A24: 21 | B24: 1.Hàng tồn kho | C24: 28 | AN24: 4.3009648e+11 | AO24: 4.3730177e+11 | AP24: 4.7716206e+11 | AQ24: 5.176144e+11 | AR24: 5.5763302e+11 | AS24: 6.1374291e+11 | AT24: 6.3087678e+11 | AU24: 5.7103508e+11 | AV24: 5.6234867e+11 | AW24: 5.581177e+11 | AX24: 5.9990299e+11 | AY24: 6.143002e+11 | AZ24: 580289170770 | BA24: 5.0050711e+11 | BB24: 4.8064156e+11 | BC24: 5.3494809e+11 | BD24: 5.4006238e+11 | BE24: 5.5977409e+11 | BF24: 5.74369e+11 | BG24: 5.7275897e+11 | BH24: 5.7610944e+11 | BI24: 5.5585695e+11 | BJ24: 5.5808593e+11 | BK24: 570584514136 | BL24: 5.489099e+11 | BM24: 5.1846389e+11 | BN24: 4.3800273e+11 | BO24: 3.7807708e+11 | BP24: 3.7110144e+11 | BQ24: 4.0460838e+11
A25: 22 | B25: 2.Dự phòng giảm giá hàng tồn kho (*) | C25: 28 | AN25: 0 | AO25: 0 | AP25: 0 | AQ25: 0 | AR25: 0 | AS25: 0 | AT25: 0 | AU25: 0 | AV25: 0 | AW25: 0 | AX25: 0 | AY25: 0 | AZ25: 0 | BA25: 0 | BB25: 0 | BC25: 0 | BD25: 0 | BE25: 0 | BF25: 0 | BG25: 0 | BH25: 0 | BI25: 0 | BJ25: 0 | BK25: 0 | BL25: 0 | BM25: 0 | BN25: 0 | BO25: 0 | BP25: 0 | BQ25: 0
A26: 23 | B26: V. Tài sản sinh học ngắn hạn | C26: 28 | D26: =SUM(D27:D29) -> 0 | E26: =SUM(E27:E29) -> 0 | F26: =SUM(F27:F29) -> 0 | G26: =SUM(G27:G29) -> 0 | H26: =SUM(H27:H29) -> 0 | I26: =SUM(I27:I29) -> 0 | J26: =SUM(J27:J29) -> 0 | K26: =SUM(K27:K29) -> 0 | ... AY26: =SUM(AY27:AY29) -> 0 | AZ26: 0 | BA26: 0 | BB26: 0 | BC26: 0 | BD26: 0 | BE26: 0 | BF26: 0 | BG26: 0 | BH26: 0 | BI26: 0 | BJ26: 0 | BK26: 0 | BL26: 0 | BM26: 0 | BN26: 0 | BO26: 0 | BP26: 0 | BQ26: 0 | BR26: =SUM(BR27:BR29) -> 0 | BS26: =SUM(BS27:BS29) -> 0 | BT26: =SUM(BT27:BT29) -> 0 | BU26: =SUM(BU27:BU29) -> 0 | BV26: =SUM(BV27:BV29) -> 0 | BW26: =SUM(BW27:BW29) -> 0
A27: 24 | B27: 1.Súc vật nuôi lấy sản phẩm một lần ngắn hạn | C27: 28 | AZ27: 0 | BA27: 0 | BB27: 0 | BC27: 0 | BD27: 0 | BE27: 0 | BF27: 0 | BG27: 0 | BH27: 0 | BI27: 0 | BJ27: 0 | BK27: 0 | BL27: 0 | BM27: 0 | BN27: 0 | BO27: 0 | BP27: 0 | BQ27: 0
A28: 25 | B28: 2.Cây trồng theo mùa vụ hoặc lấy sản phẩm một lần ngắn hạn | C28: 28 | AZ28: 0 | BA28: 0 | BB28: 0 | BC28: 0 | BD28: 0 | BE28: 0 | BF28: 0 | BG28: 0 | BH28: 0 | BI28: 0 | BJ28: 0 | BK28: 0 | BL28: 0 | BM28: 0 | BN28: 0 | BO28: 0 | BP28: 0 | BQ28: 0
A29: 26 | B29: 3.Dự phòng tổn thất tài sản sinh học ngắn hạn (*) | C29: 28 | AZ29: 0 | BA29: 0 | BB29: 0 | BC29: 0 | BD29: 0 | BE29: 0 | BF29: 0 | BG29: 0 | BH29: 0 | BI29: 0 | BJ29: 0 | BK29: 0 | BL29: 0 | BM29: 0 | BN29: 0 | BO29: 0 | BP29: 0 | BQ29: 0
A30: 27 | B30: VI. Tài sản ngắn hạn khác | C30: 28 | D30: =SUM(D31:D35) -> 0 | E30: =SUM(E31:E35) -> 0 | F30: =SUM(F31:F35) -> 0 | G30: =SUM(G31:G35) -> 0 | H30: =SUM(H31:H35) -> 0 | I30: =SUM(I31:I35) -> 0 | J30: =SUM(J31:J35) -> 0 | K30: =SUM(K31:K35) -> 0 | ... AY30: =SUM(AY31:AY35) -> 31534122458 | AZ30: 34362267223 | BA30: 35248494736 | BB30: 40503750775 | BC30: 49178776302 | BD30: 57921393429 | BE30: 67675492589 | BF30: 75037706236 | BG30: 46127608829 | BH30: 47471844315 | BI30: 46651672817 | BJ30: 44467014084 | BK30: 23132754098 | BL30: 24894891645 | BM30: 27260943738 | BN30: 28268158761 | BO30: 29512254853 | BP30: 35159235988 | BQ30: 48755784940 | BR30: =SUM(BR31:BR35) -> 0 | BS30: =SUM(BS31:BS35) -> 0 | BT30: =SUM(BT31:BT35) -> 0 | BU30: =SUM(BU31:BU35) -> 0 | BV30: =SUM(BV31:BV35) -> 0 | BW30: =SUM(BW31:BW35) -> 0
A31: 28 | B31: 1.Chi phí chờ phân bổ ngắn hạn | C31: 28 | AN31: 7035999486 | AO31: 8848304154 | AP31: 7783371139 | AQ31: 8731138492 | AR31: 8451404044 | AS31: 9556103747 | AT31: 11050173464 | AU31: 11388113648 | AV31: 12602861919 | AW31: 11727591383 | AX31: 10973880534 | AY31: 10657489774 | AZ31: 11395924021 | BA31: 11989589155 | BB31: 11598601196 | BC31: 10468261049 | BD31: 9171782469 | BE31: 14684835555 | BF31: 15885866296 | BG31: 16474015139 | BH31: 13849463748 | BI31: 11763139600 | BJ31: 9200737004 | BK31: 9528997722 | BL31: 8760714009 | BM31: 7853530050 | BN31: 8398294453 | BO31: 9369872729 | BP31: 10243788263 | BQ31: 9584774939
A32: 29 | B32: 2.Thuế GTGT được khấu trừ | C32: 28 | AN32: 41926900930 | AO32: 43981339223 | AP32: 46171681706 | AQ32: 51636650946 | AR32: 56579510013 | AS32: 32789088899 | AT32: 36250538837 | AU32: 37779643794 | AV32: 44831223018 | AW32: 48983963098 | AX32: 22259084600 | AY32: 20876632684 | AZ32: 22966343202 | BA32: 23255035548 | BB32: 28905149579 | BC32: 38710515253 | BD32: 48749610960 | BE32: 52990657034 | BF32: 59140177682 | BG32: 29653593690 | BH32: 33622380567 | BI32: 34888533217 | BJ32: 35266277080 | BK32: 13603756376 | BL32: 15814070933 | BM32: 19039790084 | BN32: 19387371189 | BO32: 19651522849 | BP32: 24397240178 | BQ32: 39171010001
A33: 30 | B33: 3.Thuế và các khoản khác phải thu Nhà nước | C33: 28 | AN33: 0 | AO33: 88589162 | AP33: 55097709 | AQ33: 31197496 | AR33: 44321343 | AS33: 68824795 | AT33: 46083769 | AU33: 95495670 | AV33: 49020929 | AW33: 51867679 | AX33: 45050425 | AY33: 0 | AZ33: 0 | BA33: 3870033 | BB33: 0 | BC33: 0 | BD33: 0 | BE33: 0 | BF33: 11662258 | BG33: 0 | BH33: 0 | BI33: 0 | BJ33: 0 | BK33: 0 | BL33: 320106703 | BM33: 367623604 | BN33: 482493119 | BO33: 490859275 | BP33: 518207547 | BQ33: 0
A34: 31 | B34: 4.Giao dịch mua bán lại trái phiếu Chính phủ | C34: 28 | AN34: 0 | AO34: 0 | AP34: 0 | AQ34: 0 | AR34: 0 | AS34: 0 | AT34: 0 | AU34: 0 | AV34: 0 | AW34: 0 | AX34: 0 | AY34: 0 | AZ34: 0 | BA34: 0 | BB34: 0 | BC34: 0 | BD34: 0 | BE34: 0 | BF34: 0 | BG34: 0 | BH34: 0 | BI34: 0 | BJ34: 0 | BK34: 0 | BL34: 0 | BM34: 0 | BN34: 0 | BO34: 0 | BP34: 0 | BQ34: 0
A35: 32 | B35: 5.Tài sản ngắn hạn khác | C35: 28 | AN35: 0 | AO35: 0 | AP35: 0 | AQ35: 0 | AR35: 0 | AS35: 0 | AT35: 0 | AU35: 0 | AV35: 0 | AW35: 0 | AX35: 0 | AY35: 0 | AZ35: 0 | BA35: 0 | BB35: 0 | BC35: 0 | BD35: 0 | BE35: 0 | BF35: 0 | BG35: 0 | BH35: 0 | BI35: 0 | BJ35: 0 | BK35: 0 | BL35: 0 | BM35: 0 | BN35: 0 | BO35: 0 | BP35: 0 | BQ35: 0
A36: 33 | B36: B-TÀI SẢN DÀI HẠN | C36: 28 | D36: =SUM(D37,D44,D54,D63,D66,D69,D76) -> 0 | E36: =SUM(E37,E44,E54,E63,E66,E69,E76) -> 0 | F36: =SUM(F37,F44,F54,F63,F66,F69,F76) -> 0 | G36: =SUM(G37,G44,G54,G63,G66,G69,G76) -> 0 | H36: =SUM(H37,H44,H54,H63,H66,H69,H76) -> 0 | I36: =SUM(I37,I44,I54,I63,I66,I69,I76) -> 0 | J36: =SUM(J37,J44,J54,J63,J66,J69,J76) -> 0 | K36: =SUM(K37,K44,K54,K63,K66,K69,K76) -> 0 | ... AY36: =SUM(AY37,AY44,AY54,AY63,AY66,AY69,AY76) -> 336474874329 | AZ36: 340380140059 | BA36: 335623957890 | BB36: 337167352653 | BC36: 345195829633 | BD36: 349130154104 | BE36: 349265800786 | BF36: 347766774950 | BG36: 347596408883 | BH36: 354522543809 | BI36: 365541010978 | BJ36: 364826588171 | BK36: 370861183445 | BL36: 371950740747 | BM36: 393184153968 | BN36: 400308290666 | BO36: 422096241613 | BP36: 423309149685 | BQ36: 554209421810 | BR36: =SUM(BR37,BR44,BR54,BR63,BR66,BR69,BR76) -> 0 | BS36: =SUM(BS37,BS44,BS54,BS63,BS66,BS69,BS76) -> 0 | BT36: =SUM(BT37,BT44,BT54,BT63,BT66,BT69,BT76) -> 0 | BU36: =SUM(BU37,BU44,BU54,BU63,BU66,BU69,BU76) -> 0 | BV36: =SUM(BV37,BV44,BV54,BV63,BV66,BV69,BV76) -> 0 | BW36: =SUM(BW37,BW44,BW54,BW63,BW66,BW69,BW76) -> 0
A37: 34 | B37: I.Các khoản phải thu dài hạn | C37: 28 | D37: =SUM(D38:D43) -> 0 | E37: =SUM(E38:E43) -> 0 | F37: =SUM(F38:F43) -> 0 | G37: =SUM(G38:G43) -> 0 | H37: =SUM(H38:H43) -> 0 | I37: =SUM(I38:I43) -> 0 | J37: =SUM(J38:J43) -> 0 | K37: =SUM(K38:K43) -> 0 | ... AY37: =SUM(AY38:AY43) -> 6530823092 | AZ37: 6530823092 | BA37: 6530823092 | BB37: 6530823092 | BC37: 6530823092 | BD37: 6530823092 | BE37: 6530823092 | BF37: 6530823092 | BG37: 6530823092 | BH37: 6530823092 | BI37: 6530823092 | BJ37: 6530823092 | BK37: 5600000000 | BL37: 5315314211 | BM37: 5315314211 | BN37: 5315314211 | BO37: 5315314210 | BP37: 5315314210 | BQ37: 5315314210 | BR37: =SUM(BR38:BR43) -> 0 | BS37: =SUM(BS38:BS43) -> 0 | BT37: =SUM(BT38:BT43) -> 0 | BU37: =SUM(BU38:BU43) -> 0 | BV37: =SUM(BV38:BV43) -> 0 | BW37: =SUM(BW38:BW43) -> 0
A38: 35 | B38: 1.Phải thu dài hạn của khách hàng | C38: 28 | AN38: 0 | AO38: 0 | AP38: 0 | AQ38: 0 | AR38: 0 | AS38: 0 | AT38: 0 | AU38: 0 | AV38: 0 | AW38: 0 | AX38: 0 | AY38: 0 | AZ38: 0 | BA38: 0 | BB38: 0 | BC38: 0 | BD38: 0 | BE38: 0 | BF38: 0 | BG38: 0 | BH38: 0 | BI38: 0 | BJ38: 0 | BK38: 0 | BL38: 0 | BM38: 0 | BN38: 0 | BO38: 0 | BP38: 0 | BQ38: 0
A39: 36 | B39: 2.Trả trước cho người bán dài hạn | C39: 28 | AN39: 0 | AO39: 0 | AP39: 0 | AQ39: 0 | AR39: 0 | AS39: 0 | AT39: 0 | AU39: 0 | AV39: 0 | AW39: 0 | AX39: 0 | AY39: 0 | AZ39: 0 | BA39: 0 | BB39: 0 | BC39: 0 | BD39: 0 | BE39: 0 | BF39: 0 | BG39: 0 | BH39: 0 | BI39: 0 | BJ39: 0 | BK39: 0 | BL39: 0 | BM39: 0 | BN39: 0 | BO39: 0 | BP39: 0 | BQ39: 0
A40: 37 | B40: 3.Vốn kinh doanh ở đơn vị trực thuộc | C40: 28 | AN40: 0 | AO40: 0 | AP40: 0 | AQ40: 0 | AR40: 0 | AS40: 0 | AT40: 0 | AU40: 0 | AV40: 0 | AW40: 0 | AX40: 0 | AY40: 0 | AZ40: 0 | BA40: 0 | BB40: 0 | BC40: 0 | BD40: 0 | BE40: 0 | BF40: 0 | BG40: 0 | BH40: 0 | BI40: 0 | BJ40: 0 | BK40: 0 | BL40: 0 | BM40: 0 | BN40: 0 | BO40: 0 | BP40: 0 | BQ40: 0
...

Sheet Ket qua kinh doanh
B1: ='Thong tin'!A1 -> CÔNG TY CP NHỰA TÁI CHẾ DUY TÂN
B2: VND
A3: Index PL | B3: PHẦN II-KẾT QUẢ HOẠT ĐỘNG KINH DOANH | C3: TenCongTyID | D3: T1.2021 | E3: T02.2021 | F3: T03.2021 | G3: T04.2021 | H3: T05.2021 | I3: T06.2021 | J3: T07.2021 | K3: T08.2021 | L3: T09.2021 | M3: T10.2021 | N3: T11.2021 | O3: T12.2021 | P3: T1.2022 | Q3: T02.2022 | R3: T03.2022 | S3: T04.2022 | T3: T05.2022 | U3: T06.2022 | V3: T07.2022 | W3: T08.2022 | X3: T09.2022 | Y3: T10.2022 | Z3: T11.2022 | AA3: T12.2022 | AB3: T1.2023 | AC3: T02.2023 | AD3: T03.2023 | AE3: T04.2023 | AF3: T05.2023 | AG3: T06.2023 | AH3: T07.2023 | AI3: T08.2023 | AJ3: T09.2023 | AK3: T10.2023 | AL3: T11.2023 | AM3: T12.2023 | AN3: T01.2024 | AO3: T02.2024 | AP3: T03.2024 | AQ3: T04.2024 | AR3: T05.2024 | AS3: T06.2024 | AT3: T07.2024 | AU3: T08.2024 | AV3: T09.2024 | AW3: T10.2024 | AX3: T11.2024 | AY3: T12.2024 | AZ3: T01.2025 | BA3: T02.2025 | BB3: T03.2025 | BC3: T04.2025 | BD3: T05.2025 | BE3: T06.2025 | BF3: T07.2025 | BG3: T08.2025 | BH3: T09.2025 | BI3: T10.2025 | BJ3: T11.2025 | BK3: T12.2025 | BL3: T01.2026 | BM3: T02.2026 | BN3: T03.2026 | BO3: T04.2026 | BP3: T05.2026 | BQ3: T06.2026 | BR3: T07.2026 | BS3: T08.2026 | BT3: T09.2026 | BU3: T10.2026 | BV3: T11.2026 | BW3: T12.2026
A4: 1 | B4: Sản lượng (kg) | C4: 28 | AZ4: 3616.4013 | BA4: 6002.038 | BB4: 4987.398 | BC4: 4085.947 | BD4: 4800.6903 | BE4: 4045.353 | BF4: 4698.9851 | BG4: 5678.89 | BH4: 3116.57 | BI4: 3435.779 | BJ4: 3062.156 | BK4: 3190.589 | BL4: 4402.052 | BM4: 3277.83 | BN4: 6446.383 | BO4: 5783.465 | BP4: 5176.4 | BQ4: 4118.6155
A5: 2 | B5: 1.Doanh thu bán hàng và cung cấp dịch vụ | C5: 28 | AN5: 130037940981 | AO5: 84645791256 | AP5: 115625416433 | AQ5: 117647266094 | AR5: 128085507494 | AS5: 95661572209 | AT5: 74679662458 | AU5: 178936926222 | AV5: 180140886766 | AW5: 143211413018 | AX5: 97197472020 | AY5: 128687104846 | AZ5: 114983880947 | BA5: 188477338235 | BB5: 150716555192 | BC5: 125691833422 | BD5: 153638670524 | BE5: 120188501523 | BF5: 138030275641 | BG5: 169482496928 | BH5: 91503288423 | BI5: 109010675108 | BJ5: 89868450986 | BK5: 100768484341 | BL5: 126470480720 | BM5: 96582496962 | BN5: 173962786425 | BO5: 159236581985 | BP5: 161004715441 | BQ5: 123197887319
A6: 3 | B6: 2.Các khoản giảm trừ doanh thu | C6: 28 | AN6: 0 | AO6: 1166125000 | AP6: 0 | AQ6: 0 | AR6: 136455000 | AS6: 0 | AT6: 0 | AU6: 6345077301 | AV6: 4671587529 | AW6: 2922205276 | AX6: 49359030 | AY6: 4680420540 | AZ6: 513935495 | BA6: 477877176 | BB6: 477350452 | BC6: 304590498 | BD6: 1607115262 | BE6: 708638196 | BF6: 26953743 | BG6: 1000293545 | BH6: 6773818500 | BI6: 0 | BJ6: 1479093000 | BK6: 1103092320 | BL6: 687876997 | BM6: 33305556 | BN6: 956126160 | BO6: 86574074 | BP6: 1221964024 | BQ6: 259219891
A7: 4 | B7: 3.Doanh thu thuần về bán hàng và cung cấp dịch vụ | C7: 28 | D7: =D5-D6 -> 0 | E7: =E5-E6 -> 0 | F7: =F5-F6 -> 0 | G7: =G5-G6 -> 0 | H7: =H5-H6 -> 0 | I7: =I5-I6 -> 0 | J7: =J5-J6 -> 0 | K7: =K5-K6 -> 0 | ... AY7: =AY5-AY6 -> 124006684306 | AZ7: 114469945452 | BA7: 187999461059 | BB7: 150239204740 | BC7: 125387242924 | BD7: 152031555262 | BE7: 119479863327 | BF7: 138003321898 | BG7: 168482203383 | BH7: 84729469923 | BI7: 109010675108 | BJ7: 88389357986 | BK7: 99665392021 | BL7: =BL5-BL6 -> 125782603723 | BM7: =BM5-BM6 -> 96549191406 | BN7: 173006660265 | BO7: 159150007911 | BP7: =BP5-BP6 -> 159782751417 | BQ7: 122938667428 | BR7: =BR5-BR6 -> 0 | BS7: =BS5-BS6 -> 0 | BT7: =BT5-BT6 -> 0 | BU7: =BU5-BU6 -> 0 | BV7: =BV5-BV6 -> 0 | BW7: =BW5-BW6 -> 0
A8: 5 | B8: 4.Giá vốn hàng bán | C8: 28 | AN8: 120065457134 | AO8: 83995360322 | AP8: 109165390822 | AQ8: 105655387173 | AR8: 125507167216 | AS8: 98477492806 | AT8: 80393606783 | AU8: 167228552558 | AV8: 152083786508 | AW8: 135696763155 | AX8: 92718574459 | AY8: -4137926966 | AZ8: 97986840184 | BA8: 155693128574 | BB8: 129053280797 | BC8: 108257691858 | BD8: 128243821985 | BE8: 104299018492 | BF8: 124260554437 | BG8: 150760754200 | BH8: 81919659396 | BI8: 98239930365 | BJ8: 80093235439 | BK8: 67988837293 | BL8: 1.142049e+11 | BM8: 8.9643992e+10 | BN8: 1.6396517e+11 | BO8: 1.3901744e+11 | BP8: 1.3457958e+11 | BQ8: 9.9754337e+10
A9: 6 | B9: 5.Lợi nhuận gộp về bán hàng | C9: 28 | D9: =D7-D8 -> 0 | E9: =E7-E8 -> 0 | F9: =F7-F8 -> 0 | G9: =G7-G8 -> 0 | H9: =H7-H8 -> 0 | I9: =I7-I8 -> 0 | J9: =J7-J8 -> 0 | K9: =K7-K8 -> 0 | ... AY9: =AY7-AY8 -> 128144611272 | AZ9: 16483105268 | BA9: 32306332485 | BB9: 21185923943 | BC9: 17129551066 | BD9: 23787733277 | BE9: 15180844835 | BF9: 13742767461 | BG9: 17721449183 | BH9: 2809810527 | BI9: 10770744743 | BJ9: 8296122547 | BK9: 31676554728 | BL9: =BL7-BL8 -> 1.1577706e+10 | BM9: =BM7-BM8 -> 6.9051991e+09 | BN9: 9.0414879e+09 | BO9: 2.0132565e+10 | BP9: =BP7-BP8 -> 2.5203171e+10 | BQ9: 2.3184331e+10 | BR9: =BR7-BR8 -> 0 | BS9: =BS7-BS8 -> 0 | BT9: =BT7-BT8 -> 0 | BU9: =BU7-BU8 -> 0 | BV9: =BV7-BV8 -> 0 | BW9: =BW7-BW8 -> 0
A10: 7 | B10: 6.Lãi/lỗ của hoạt động bán, thanh lý bất động sản đầu tư | C10: 28 | AZ10: 0 | BA10: 0 | BB10: 0 | BC10: 0 | BD10: 0 | BE10: 0 | BF10: 0 | BG10: 0 | BH10: 0 | BI10: 0 | BJ10: 0 | BK10: 0 | BM10: 0 | BN10: 0 | BO10: 0 | BQ10: 0
A11: 8 | B11: 7.Doanh thu hoạt động tài chính | C11: 28 | AN11: 712260969 | AO11: 1111471110 | AP11: 1004651784 | AQ11: 1746021208 | AR11: 1032867505 | AS11: 591086157 | AT11: 376652862 | AU11: 1253018630 | AV11: 1560156089 | AW11: 2831268643 | AX11: 886951972 | AY11: 2195155035 | AZ11: 830662240 | BA11: 1805467216 | BB11: 941747687 | BC11: 1368536357 | BD11: 2440495098 | BE11: 1651919997 | BF11: 1450067480 | BG11: 1506125345 | BH11: 1236220214 | BI11: 2769344197 | BJ11: 564107321 | BK11: 727547755 | BL11: 1119033075 | BM11: 334221183 | BN11: 895384046 | BO11: 2939826098 | BP11: 1281094644 | BQ11: 1680409032
A12: 9 | B12: 8.Chi phí tài chính | C12: 28 | AN12: 801399604 | AO12: 695500231 | AP12: 663502461 | AQ12: 1555671370 | AR12: 936492932 | AS12: 1103852896 | AT12: 1608708972 | AU12: 1489581015 | AV12: 1372261307 | AW12: 636041020 | AX12: 1257673070 | AY12: 993026233 | AZ12: 1529745602 | BA12: 1349010483 | BB12: 902730488 | BC12: 1450570894 | BD12: 858169737 | BE12: 1483876982 | BF12: 1318435167 | BG12: 1366041150 | BH12: 1603769193 | BI12: 2900732378 | BJ12: 1301741764 | BK12: 2479436989 | BL12: 1532817392 | BM12: 1578519037 | BN12: 1510605035 | BO12: 1999303711 | BP12: 1209081371 | BQ12: 1216707545
A13: 10 | B13: Trong đó: Chi phí lãi vay | C13: 28 | AN13: 460461775 | AO13: 563909516 | AP13: 587315920 | AQ13: 905708142 | AR13: 974310029 | AS13: 1115056080 | AT13: 1160823006 | AU13: 939585045 | AV13: 859444105 | AW13: 840165515 | AX13: 889159081 | AY13: 1032562923 | AZ13: 1114824276 | BA13: 928379281 | BB13: 673966789 | BC13: 888393452 | BD13: 1186588729 | BE13: 1448899822 | BF13: 1245210526 | BG13: 1303560910 | BH13: 1595764355 | BI13: 1368802426 | BJ13: 1256132292 | BK13: 1256103396 | BL13: 1240115065 | BM13: 1156279418 | BN13: 959718564 | BO13: 1062084475 | BP13: 838836791 | BQ13: 856841656
A14: 11 | B14: 9.Chi phí bán hàng | C14: 28 | AN14: 4849994610 | AO14: 1560472559 | AP14: 4219375143 | AQ14: 4926459549 | AR14: 2125110954 | AS14: 2824966874 | AT14: 2596964337 | AU14: 8480107205 | AV14: 7368729523 | AW14: 4936551194 | AX14: 2249627546 | AY14: 10540748080 | AZ14: 4181224849 | BA14: 6634982258 | BB14: 5629444776 | BC14: 4622826734 | BD14: 5242336575 | BE14: 5451129528 | BF14: 4248972349 | BG14: 5750995751 | BH14: 3513998286 | BI14: 7273403934 | BJ14: 3829549635 | BK14: 5362380917 | BL14: 4308598004 | BM14: 3594645336 | BN14: 7012095788 | BO14: 6469509126 | BP14: 6626905090 | BQ14: 4571840296
A15: 12 | B15: 10.Chi phí quản lý doanh nghiệp | C15: 28 | AN15: 5698695249 | AO15: 5090845577 | AP15: 5285019459 | AQ15: 5584474639 | AR15: 6069340865 | AS15: 5881960019 | AT15: 5698093117 | AU15: 6840474838 | AV15: 8084946891 | AW15: 8025871294 | AX15: 9126335400 | AY15: 7087963087 | AZ15: 8548199037 | BA15: 8928537962 | BB15: 8618282018 | BC15: 8518246563 | BD15: 9277438311 | BE15: 9026767632 | BF15: 8998978187 | BG15: 9320823983 | BH15: 10936858648 | BI15: 5273319876 | BJ15: 11469860627 | BK15: 17451279792 | BL15: 9741945070 | BM15: 9621802832 | BN15: 8391794513 | BO15: 9291402760 | BP15: 9149183956 | BQ15: 9341015977
A16: 13 | B16: 11.Lợi nhuận thuần từ hoạt động kinh doanh | C16: 28 | D16: =SUM(D9:D11)-D12-D14-D15 -> 0 | E16: =SUM(E9:E11)-E12-E14-E15 -> 0 | F16: =SUM(F9:F11)-F12-F14-F15 -> 0 | G16: =SUM(G9:G11)-G12-G14-G15 -> 0 | H16: =SUM(H9:H11)-H12-H14-H15 -> 0 | I16: =SUM(I9:I11)-I12-I14-I15 -> 0 | J16: =SUM(J9:J11)-J12-J14-J15 -> 0 | K16: =SUM(K9:K11)-K12-K14-K15 -> 0 | ... AY16: =SUM(AY9:AY11)-AY12-AY14-AY15 -> 111718028907 | AZ16: 3054598020 | BA16: 17199268998 | BB16: 6977214348 | BC16: 3906443232 | BD16: 10850283752 | BE16: 870990690 | BF16: 626449238 | BG16: 2789713644 | BH16: -12008595386 | BI16: -1907367248 | BJ16: -7740922158 | BK16: 7111004785 | BL16: =BL9+BL10+BL11-BL12-BL14-BL15 -> -2.8866209e+09 | BM16: =BM9+BM10+BM11-BM12-BM14-BM15 -> -7.5555469e+09 | BN16: -6.9776234e+09 | BO16: 5.3121754e+09 | BP16: =SUM(BP9:BP11)-BP12-BP14-BP15 -> 9.499095e+09 | BQ16: 9.7351761e+09 | BR16: =SUM(BR9:BR11)-BR12-BR14-BR15 -> 0 | BS16: =SUM(BS9:BS11)-BS12-BS14-BS15 -> 0 | BT16: =SUM(BT9:BT11)-BT12-BT14-BT15 -> 0 | BU16: =SUM(BU9:BU11)-BU12-BU14-BU15 -> 0 | BV16: =SUM(BV9:BV11)-BV12-BV14-BV15 -> 0 | BW16: =SUM(BW9:BW11)-BW12-BW14-BW15 -> 0
A17: 14 | B17: 12.Thu nhập khác | C17: 28 | AN17: 1945 | AO17: 1109349 | AP17: 0 | AQ17: 81700000 | AR17: 4696127 | AS17: 64937878 | AT17: 54384750 | AU17: 184242778 | AV17: 5869054 | AW17: 3145774 | AX17: 1405742798 | AY17: 7237102 | AZ17: 105489733 | BA17: 7492780 | BB17: 22177722 | BC17: 54899780 | BD17: 136977736 | BE17: 60909877 | BF17: 45395718 | BG17: 516819765 | BH17: 15045562 | BI17: 25464983 | BJ17: 8392356 | BK17: 173856388 | BL17: 62317597 | BM17: 20729933 | BN17: 83481212 | BO17: 164659578 | BP17: 182616632 | BQ17: 98404889
A18: 15 | B18: 13.Chi phí khác | C18: 28 | AN18: 54643068 | AO18: 9000870 | AP18: 40101620 | AQ18: 84654154 | AR18: 40312330 | AS18: 171972294 | AT18: 7603195 | AU18: 4413241 | AV18: 7331553 | AW18: 177107310 | AX18: 140746957 | AY18: 8816704270 | AZ18: 60241342 | BA18: 133833312 | BB18: 2500000 | BC18: 24808640 | BD18: 6500600 | BE18: 57323484 | BF18: 259624976 | BG18: 553180625 | BH18: 543708002 | BI18: 3516569246 | BJ18: 1108557251 | BK18: 1609092429 | BL18: 243870060 | BM18: 199853182 | BN18: 38712958 | BO18: 574336056 | BP18: 146865976 | BQ18: 124315595
A19: 16 | B19: 14.Lợi nhuận khác | C19: 28 | D19: =D17-D18 -> 0 | E19: =E17-E18 -> 0 | F19: =F17-F18 -> 0 | G19: =G17-G18 -> 0 | H19: =H17-H18 -> 0 | I19: =I17-I18 -> 0 | J19: =J17-J18 -> 0 | K19: =K17-K18 -> 0 | ... AY19: =AY17-AY18 -> -8809467168 | AZ19: 45248391 | BA19: -126340532 | BB19: 19677722 | BC19: 30091140 | BD19: 130477136 | BE19: 3586393 | BF19: -214229258 | BG19: -36360860 | BH19: -528662440 | BI19: -3491104263 | BJ19: -1100164895 | BK19: -1435236041 | BL19: =BL17-BL18 -> -181552463 | BM19: =BM17-BM18 -> -179123249 | BN19: 44768254 | BO19: -409676478 | BP19: =BP17-BP18 -> 35750656 | BQ19: -25910706 | BR19: =BR17-BR18 -> 0 | BS19: =BS17-BS18 -> 0 | BT19: =BT17-BT18 -> 0 | BU19: =BU17-BU18 -> 0 | BV19: =BV17-BV18 -> 0 | BW19: =BW17-BW18 -> 0
A20: 17 | B20: 15.Tổng lợi nhuận kế toán trước thuế | C20: 28 | D20: =SUM(D16,D19) -> 0 | E20: =SUM(E16,E19) -> 0 | F20: =SUM(F16,F19) -> 0 | G20: =SUM(G16,G19) -> 0 | H20: =SUM(H16,H19) -> 0 | I20: =SUM(I16,I19) -> 0 | J20: =SUM(J16,J19) -> 0 | K20: =SUM(K16,K19) -> 0 | ... AY20: =SUM(AY16,AY19) -> 102908561739 | AZ20: 3099846411 | BA20: 17072928466 | BB20: 6996892070 | BC20: 3936534372 | BD20: 10980760888 | BE20: 874577083 | BF20: 412219980 | BG20: 2753352784 | BH20: -12537257826 | BI20: -5398471511 | BJ20: -8841087053 | BK20: 5675768744 | BL20: =BL16+BL19 -> -3.0681734e+09 | BM20: =BM16+BM19 -> -7.7346702e+09 | BN20: -6.9328552e+09 | BO20: 4.9024989e+09 | BP20: =SUM(BP16,BP19) -> 9.5348456e+09 | BQ20: 9.7092654e+09 | BR20: =SUM(BR16,BR19) -> 0 | BS20: =SUM(BS16,BS19) -> 0 | BT20: =SUM(BT16,BT19) -> 0 | BU20: =SUM(BU16,BU19) -> 0 | BV20: =SUM(BV16,BV19) -> 0 | BW20: =SUM(BW16,BW19) -> 0
A21: 18 | B21: 16.Chi phí thuế TNDN hiện hành | C21: 28 | AN21: 0 | AO21: 0 | AP21: 0 | AQ21: 0 | AR21: 0 | AS21: 0 | AT21: 0 | AU21: 32927331 | AV21: 0 | AW21: 0 | AX21: 0 | AY21: 11495266455 | AZ21: 864190686 | BA21: 3020742780 | BB21: 1252632187 | BC21: 677293488 | BD21: 1681800759 | BE21: 189264839 | BF21: -1000088030 | BG21: 204199602 | BH21: -1349170846 | BI21: -516688622 | BJ21: -854033077 | BK21: 3791480158 | BN21: 153752926 | BO21: 105667873 | BP21: 150429214 | BQ21: 1157390566
