Workbook

Sheet PL DTRG
B1: CTY CP NHỰA TÁI CHẾ DUY TÂN
B2: VND
A3: Index PL | B3: PHẦN II-KẾT QUẢ HOẠT ĐỘNG KINH DOANH | C3: TenCongTyID | D3: 2021 | E3: 2022 | F3: 2023 | G3: 2024 | H3: 2025 | I3: 2026 | J3: T1.2021 | K3: T02.2021 | L3: T03.2021 | M3: T04.2021 | N3: T05.2021 | O3: T06.2021 | P3: T07.2021 | Q3: T08.2021 | R3: T09.2021 | S3: T10.2021 | T3: T11.2021 | U3: T12.2021 | V3: T1.2022 | W3: T02.2022 | X3: T03.2022 | Y3: T04.2022 | Z3: T05.2022 | AA3: T06.2022 | AB3: T07.2022 | AC3: T08.2022 | AD3: T09.2022 | AE3: T10.2022 | AF3: T11.2022 | AG3: T12.2022 | AH3: T1.2023 | AI3: T02.2023 | AJ3: T03.2023 | AK3: T04.2023 | AL3: T05.2023 | AM3: T06.2023 | AN3: T07.2023 | AO3: T08.2023 | AP3: T09.2023 | AQ3: T10.2023 | AR3: T11.2023 | AS3: T12.2023 | AT3: T01.2024 | AU3: T02.2024 | AV3: T03.2024 | AW3: T04.2024 | AX3: T05.2024 | AY3: T06.2024 | AZ3: T07.2024 | BA3: T08.2024 | BB3: T09.2024 | BC3: T10.2024 | BD3: T11.2024 | BE3: T12.2024 | BF3: T01.2025 | BG3: T02.2025 | BH3: T03.2025 | BI3: T04.2025 | BJ3: T05.2025 | BK3: T06.2025 | BL3: T07.2025 | BM3: T08.2025 | BN3: T09.2025 | BO3: T10.2025 | BP3: T11.2025 | BQ3: T12.2025 | BR3: T01.2026 | BS3: T02.2026 | BT3: T03.2026 | BU3: T04.2026 | BV3: T05.2026 | BW3: T06.2026 | BX3: T07.2026 | BY3: T08.2026 | BZ3: T09.2026 | CA3: T10.2026 | CB3: T11.2026 | CC3: T12.2026
A4: 1 | B4: Sản lượng (kg) | C4: 5 | D4: =SUM(Data_PL7[[#This Row],[T1.2021]:[T12.2021]]) -> 2131.962 | E4: =SUM(Data_PL7[[#This Row],[T1.2022]:[T12.2022]]) -> 9850.865 | F4: =SUM(Data_PL7[[#This Row],[T1.2023]:[T12.2023]]) -> 22582.09 | G4: =SUM(Data_PL7[[#This Row],[T01.2024]:[T12.2024]]) -> 40044.844 | H4: =SUM(Data_PL7[[#This Row],[T01.2025]:[T12.2025]]) -> 50376.161 | I4: =SUM(Data_PL7[[#This Row],[T01.2026]:[T12.2026]]) -> 19871.663 | J4: 76.025 | K4: 61 | L4: 303.8 | M4: 215.35 | N4: 35.93 | O4: 30.437 | P4: 87.5 | Q4: 69.2 | R4: 115.5 | S4: 262.5 | T4: 284.8 | U4: 589.92 | V4: 250.8 | W4: 242 | X4: 710 | Y4: 815.189 | Z4: 578.208 | AA4: 678.9 | AB4: 421.5 | AC4: 1104.468 | AD4: 1030.32 | AE4: 1178.275 | AF4: 981.1 | AG4: 1860.105 | AH4: 651.8 | AI4: 653.075 | AJ4: 1875.95 | AK4: 1792.575 | AL4: 1632.875 | AM4: 1573.975 | AN4: 2078.599 | AO4: 2591.943 | AP4: 2246.875 | AQ4: 3057.347 | AR4: 2111.308 | AS4: 2315.768 | AT4: 3553.2 | AU4: 2285.051 | AV4: 2972.068 | AW4: 3202.752 | AX4: 3455.89 | AY4: 2432.325 | AZ4: 1986.853 | BA4: 5184.5942 | BB4: 4932.507 | BC4: 4058.203 | BD4: 2606.253 | BE4: 3375.148 | BF4: 3612.7513 | BG4: 6002.038 | BH4: 4985.538 | BI4: 4060.361 | BJ4: 4785.7603 | BK4: 3895.695 | BL4: 4652.4191 | BM4: 5655.27 | BN4: 3106.292 | BO4: 3393.537 | BP4: 3040.82 | BQ4: 3185.679 | BR4: 4409.992 | BS4: 3267.6 | BT4: 6445.446 | BU4: 5748.625
A5: 2 | B5: 1.Doanh thu bán hàng và cung cấp dịch vụ | C5: 5 | D5: =SUM(Data_PL7[[#This Row],[T1.2021]:[T12.2021]]) -> 60562275921 | E5: =SUM(Data_PL7[[#This Row],[T1.2022]:[T12.2022]]) -> 330330688073 | F5: =SUM(Data_PL7[[#This Row],[T1.2023]:[T12.2023]]) -> 685554367311 | G5: =SUM(Data_PL7[[#This Row],[T01.2024]:[T12.2024]]) -> 1211387224737 | H5: =SUM(Data_PL7[[#This Row],[T01.2025]:[T12.2025]]) -> 1551998582223 | I5: =SUM(Data_PL7[[#This Row],[T01.2026]:[T12.2026]]) -> 556792402428 | J5: 2192940600 | K5: 1791822000 | L5: 8682084600 | M5: 6264332700 | N5: 1376973402 | O5: 904631370 | P5: 3085582842 | Q5: 2036756400 | R5: 4007834643 | S5: 8372308560 | T5: 8615033640 | U5: 13231975164 | V5: 7498036216 | W5: 6876982200 | X5: 21877405036 | Y5: 27424133378 | Z5: 18350378815 | AA5: 21902018748 | AB5: 15882148168 | AC5: 38706132850 | AD5: 36809694250 | AE5: 41577847270 | AF5: 34741567940 | AG5: 58684343202 | AH5: 24985455241 | AI5: 23042319009 | AJ5: 59212986698 | AK5: 54287237375 | AL5: 57641008821 | AM5: 50922412416 | AN5: 53533092198 | AO5: 78282463651 | AP5: 64916176630 | AQ5: 84671529098 | AR5: 62903041444 | AS5: 71156644730 | AT5: 95961616736 | AU5: 70105871996 | AV5: 92109508133 | AW5: 97489092894 | AX5: 102501453344 | AY5: 68093170109 | AZ5: 56451269692 | BA5: 160372945473 | BB5: 161501484254 | BC5: 119734804022 | BD5: 76175498864 | BE5: 110890509220 | BF5: 114976445897 | BG5: 188477338235 | BH5: 150730683132 | BI5: 125734240353 | BJ5: 153674258114 | BK5: 119843310993 | BL5: 138018360641 | BM5: 169442946928 | BN5: 91484253567 | BO5: 108928556660 | BP5: 89826973802 | BQ5: 100861213901 | BR5: 126786913920 | BS5: 96600110916 | BT5: 174261948689 | BU5: 159143428903
A6: 3 | B6: 2.Các khoản giảm trừ doanh thu | C6: 5 | D6: =SUM(Data_PL7[[#This Row],[T1.2021]:[T12.2021]]) -> 68351150 | E6: =SUM(Data_PL7[[#This Row],[T1.2022]:[T12.2022]]) -> 398631999 | F6: =SUM(Data_PL7[[#This Row],[T1.2023]:[T12.2023]]) -> 35151625 | G6: =SUM(Data_PL7[[#This Row],[T01.2024]:[T12.2024]]) -> 19971229676 | H6: =SUM(Data_PL7[[#This Row],[T01.2025]:[T12.2025]]) -> 14472758187 | I6: =SUM(Data_PL7[[#This Row],[T01.2026]:[T12.2026]]) -> 1763882787 | J6: 0 | K6: 0 | L6: 0 | M6: 0 | N6: 0 | O6: 36461250 | P6: 0 | Q6: 686000 | R6: 0 | S6: 0 | T6: 0 | U6: 31203900 | V6: 0 | W6: 765658695 | X6: -760221195 | Y6: 0 | Z6: 0 | AA6: 0 | AB6: 3076000 | AC6: 346771999 | AD6: 0 | AE6: 0 | AF6: 43346500 | AG6: 0 | AH6: 0 | AI6: 0 | AJ6: 453218 | AK6: 195177 | AL6: 9024000 | AM6: 18714230 | AN6: 6765000 | AO6: 0 | AP6: 0 | AQ6: 0 | AR6: 0 | AS6: 0 | AT6: 0 | AU6: 1166125000 | AV6: 0 | AW6: 0 | AX6: 136455000 | AY6: 0 | AZ6: 0 | BA6: 6345077301 | BB6: 4671587529 | BC6: 2922205276 | BD6: 49359030 | BE6: 4680420540 | BF6: 513935495 | BG6: 477877176 | BH6: 477350452 | BI6: 304590498 | BJ6: 1607115262 | BK6: 708638196 | BL6: 26953743 | BM6: 1000293545 | BN6: 6773818500 | BO6: 0 | BP6: 1479093000 | BQ6: 1103092320 | BR6: 687876997 | BS6: 33305556 | BT6: 956126160 | BU6: 86574074
A7: 4 | B7: 3.Doanh thu thuần về bán hàng và cung cấp dịch vụ | C7: 5 | D7: =SUM(Data_PL7[[#This Row],[T1.2021]:[T12.2021]]) -> 60493924771 | E7: =SUM(Data_PL7[[#This Row],[T1.2022]:[T12.2022]]) -> 329932056074 | F7: =SUM(Data_PL7[[#This Row],[T1.2023]:[T12.2023]]) -> 685519215686 | G7: =SUM(Data_PL7[[#This Row],[T01.2024]:[T12.2024]]) -> 1191415995061 | H7: =SUM(Data_PL7[[#This Row],[T01.2025]:[T12.2025]]) -> 1537525824036 | I7: =SUM(Data_PL7[[#This Row],[T01.2026]:[T12.2026]]) -> 555028519641 | J7: 2192940600 | K7: 1791822000 | L7: 8682084600 | M7: 6264332700 | N7: 1376973402 | O7: 868170120 | P7: 3085582842 | Q7: 2036070400 | R7: 4007834643 | S7: 8372308560 | T7: 8615033640 | U7: 13200771264 | V7: 7498036216 | W7: 6111323505 | X7: 22637626231 | Y7: 27424133378 | Z7: 18350378815 | AA7: 21902018748 | AB7: 15879072168 | AC7: 38359360851 | AD7: 36809694250 | AE7: 41577847270 | AF7: 34698221440 | AG7: 58684343202 | AH7: 24985455241 | AI7: 23042319009 | AJ7: 59212533480 | AK7: 54287042198 | AL7: 57631984821 | AM7: 50903698186 | AN7: 53526327198 | AO7: 78282463651 | AP7: 64916176630 | AQ7: 84671529098 | AR7: 62903041444 | AS7: 71156644730 | AT7: 95961616736 | AU7: 68939746996 | AV7: 92109508133 | AW7: 97489092894 | AX7: 102364998344 | AY7: 68093170109 | AZ7: 56451269692 | BA7: 154027868172 | BB7: 156829896725 | BC7: 116812598746 | BD7: 76126139834 | BE7: 106210088680 | BF7: 114462510402 | BG7: 187999461059 | BH7: 150253332680 | BI7: 125429649855 | BJ7: 152067142852 | BK7: 119134672797 | BL7: 137991406898 | BM7: 168442653383 | BN7: 84710435067 | BO7: 108928556660 | BP7: 88347880802 | BQ7: 99758121581 | BR7: 126099036923 | BS7: 96566805360 | BT7: 173305822529 | BU7: 159056854829
A8: 5 | B8: 4.Giá vốn hàng bán | C8: 5 | D8: =SUM(Data_PL7[[#This Row],[T1.2021]:[T12.2021]]) -> 55288134722 | E8: =SUM(Data_PL7[[#This Row],[T1.2022]:[T12.2022]]) -> 299901216900 | F8: =SUM(Data_PL7[[#This Row],[T1.2023]:[T12.2023]]) -> 518594542678 | G8: =SUM(Data_PL7[[#This Row],[T01.2024]:[T12.2024]]) -> 998230253982 | H8: =SUM(Data_PL7[[#This Row],[T01.2025]:[T12.2025]]) -> 1343495797036 | I8: =SUM(Data_PL7[[#This Row],[T01.2026]:[T12.2026]]) -> 512422326416 | J8: 1714389259 | K8: 1513381552 | L8: 6687623393 | M8: 4774057263 | N8: 1087102095 | O8: 807656278 | P8: 2716172489 | Q8: 4315716140 | R8: 4265960659 | S8: 7443114351 | T8: 7773986301 | U8: 12188974942 | V8: 6843552810 | W8: 6912963718 | X8: 19836366360 | Y8: 21907875072 | Z8: 15580244606 | AA8: 18312738285 | AB8: 12006617281 | AC8: 32529935445 | AD8: 32281385317 | AE8: 38377094489 | AF8: 30963456194 | AG8: 64348987323 | AH8: 20792367485 | AI8: 21918378947 | AJ8: 61251223688 | AK8: 53942190282 | AL8: 50245648463 | AM8: 7904131770 | AN8: 44797235508 | AO8: 62222051344 | AP8: 37728980820 | AQ8: 61940025172 | AR8: 49113504898 | AS8: 46738804301 | AT8: 85841765176 | AU8: 68748321616 | AV8: 86824377307 | AW8: 85475594862 | AX8: 99208228636 | AY8: 69795611979 | AZ8: 61217801757 | BA8: 147970813832 | BB8: 132769623597 | BC8: 112138441893 | BD8: 70998442117 | BE8: -22758768790 | BF8: 96299447936 | BG8: 154570631505 | BH8: 129509315823 | BI8: 109641808151 | BJ8: 129906078108 | BK8: 105463649620 | BL8: 128673842020 | BM8: 155101842643 | BN8: 83113314505 | BO8: 99966937216 | BP8: 80940600844 | BQ8: 70308328665 | BR8: 115080112871 | BS8: 90411470461 | BT8: 165844739865 | BU8: 141086003219
A9: 6 | B9: 5.Lợi nhuận gộp về bán hàng | C9: 5 | D9: =SUM(Data_PL7[[#This Row],[T1.2021]:[T12.2021]]) -> 5205790049 | E9: =SUM(Data_PL7[[#This Row],[T1.2022]:[T12.2022]]) -> 30030839174 | F9: =SUM(Data_PL7[[#This Row],[T1.2023]:[T12.2023]]) -> 166924673008 | G9: =SUM(Data_PL7[[#This Row],[T01.2024]:[T12.2024]]) -> 193185741079 | H9: =SUM(Data_PL7[[#This Row],[T01.2025]:[T12.2025]]) -> 194030027000 | I9: =SUM(Data_PL7[[#This Row],[T01.2026]:[T12.2026]]) -> 42606193225 | J9: 478551341 | K9: 278440448 | L9: 1994461207 | M9: 1490275437 | N9: 289871307 | O9: 60513842 | P9: 369410353 | Q9: -2279645740 | R9: -258126016 | S9: 929194209 | T9: 841047339 | U9: 1011796322 | V9: 654483406 | W9: -801640213 | X9: 2801259871 | Y9: 5516258306 | Z9: 2770134209 | AA9: 3589280463 | AB9: 3872454887 | AC9: 5829425406 | AD9: 4528308933 | AE9: 3200752781 | AF9: 3734765246 | AG9: -5664644121 | AH9: 4193087756 | AI9: 1123940062 | AJ9: -2038690208 | AK9: 344851916 | AL9: 7386336358 | AM9: 42999566416 | AN9: 8729091690 | AO9: 16060412307 | AP9: 27187195810 | AQ9: 22731503926 | AR9: 13789536546 | AS9: 24417840429 | AT9: 10119851560 | AU9: 191425380 | AV9: 5285130826 | AW9: 12013498032 | AX9: 3156769708 | AY9: -1702441870 | AZ9: -4766532065 | BA9: 6057054340 | BB9: 24060273128 | BC9: 4674156853 | BD9: 5127697717 | BE9: 128968857470 | BF9: 18163062466 | BG9: 33428829554 | BH9: 20744016857 | BI9: 15787841704 | BJ9: 22161064744 | BK9: 13671023177 | BL9: 9317564878 | BM9: 13340810740 | BN9: 1597120562 | BO9: 8961619444 | BP9: 7407279958 | BQ9: 29449792916 | BR9: 11018924052 | BS9: 6155334899 | BT9: 7461082664 | BU9: 17970851610
A10: 7 | B10: 6.Lãi/lỗ của hoạt động bán, thanh lý bất động sản đầu tư | C10: 5 | D10: =SUM(Data_PL7[[#This Row],[T1.2021]:[T12.2021]]) -> 0 | E10: =SUM(Data_PL7[[#This Row],[T1.2022]:[T12.2022]]) -> 0 | F10: =SUM(Data_PL7[[#This Row],[T1.2023]:[T12.2023]]) -> 0 | G10: =SUM(Data_PL7[[#This Row],[T01.2024]:[T12.2024]]) -> 0 | H10: =SUM(Data_PL7[[#This Row],[T01.2025]:[T12.2025]]) -> 0 | I10: =SUM(Data_PL7[[#This Row],[T01.2026]:[T12.2026]]) -> 0
A11: 8 | B11: 7.Doanh thu hoạt động tài chính | C11: 5 | D11: =SUM(Data_PL7[[#This Row],[T1.2021]:[T12.2021]]) -> 18328733000 | E11: =SUM(Data_PL7[[#This Row],[T1.2022]:[T12.2022]]) -> 17240601582 | F11: =SUM(Data_PL7[[#This Row],[T1.2023]:[T12.2023]]) -> 9282695737 | G11: =SUM(Data_PL7[[#This Row],[T01.2024]:[T12.2024]]) -> 15099094600 | H11: =SUM(Data_PL7[[#This Row],[T01.2025]:[T12.2025]]) -> 16906508752 | I11: =SUM(Data_PL7[[#This Row],[T01.2026]:[T12.2026]]) -> 3968224388 | J11: 1228117 | K11: 1370668 | L11: 503786 | M11: 991223 | N11: 924399 | O11: 2721429 | P11: 5630167167 | Q11: 4552274821 | R11: 4006107516 | S11: 1404451824 | T11: 1487413089 | U11: 1240578961 | V11: 1479346434 | W11: 1527456177 | X11: 1512346597 | Y11: 1655612808 | Z11: 2665641339 | AA11: 1264179580 | AB11: 1129143854 | AC11: 1236134244 | AD11: 1420307305 | AE11: 1826774837 | AF11: 1006924842 | AG11: 516733565 | AH11: 23897328 | AI11: 190776336 | AJ11: 16660712 | AK11: 967330723 | AL11: 867791673 | AM11: 866039044 | AN11: 810000497 | AO11: 1331407010 | AP11: 1045754825 | AQ11: 1146315118 | AR11: 946685267 | AS11: 1070037204 | AT11: 702840610 | AU11: 1100851130 | AV11: 994712341 | AW11: 1735368123 | AX11: 1021938222 | AY11: 578784271 | AZ11: 343643819 | BA11: 1242477440 | BB11: 1549112434 | BC11: 2779237425 | BD11: 865910053 | BE11: 2184218732 | BF11: 773999253 | BG11: 1788435256 | BH11: 931124505 | BI11: 1307926421 | BJ11: 2429341904 | BK11: 1641453607 | BL11: 1393514763 | BM11: 1498736488 | BN11: 1228780215 | BO11: 2716737103 | BP11: 515476780 | BQ11: 680982457 | BR11: 1053165322 | BS11: 307705069 | BT11: 839416558 | BU11: 1767937439
A12: 9 | B12: 8.Chi phí tài chính | C12: 5 | D12: =SUM(Data_PL7[[#This Row],[T1.2021]:[T12.2021]]) -> 3984725509 | E12: =SUM(Data_PL7[[#This Row],[T1.2022]:[T12.2022]]) -> 8892172663 | F12: =SUM(Data_PL7[[#This Row],[T1.2023]:[T12.2023]]) -> 3023468987 | G12: =SUM(Data_PL7[[#This Row],[T01.2024]:[T12.2024]]) -> 13113711111 | H12: =SUM(Data_PL7[[#This Row],[T01.2025]:[T12.2025]]) -> 18541073627 | I12: =SUM(Data_PL7[[#This Row],[T01.2026]:[T12.2026]]) -> 6611590325 | J12: 167606071 | K12: 221668883 | L12: 208008837 | M12: 262181583 | N12: 294284803 | O12: 376440316 | P12: 341383390 | Q12: 424333601 | R12: 404885911 | S12: 376140889 | T12: 457278692 | U12: 450512533 | V12: 566186825 | W12: 636770194 | X12: 622676693 | Y12: 508923847 | Z12: 611802389 | AA12: 151684906 | AB12: 632905650 | AC12: 700652271 | AD12: 1025151505 | AE12: 1107933886 | AF12: 1595489167 | AG12: 731995330 | AH12: 74107271 | AI12: 30659803 | AJ12: 220600896 | AK12: 69167924 | AL12: 49408830 | AM12: 124156445 | AN12: 311284353 | AO12: 709793834 | AP12: 328510530 | AQ12: 475535318 | AR12: 86442609 | AS12: 543801174 | AT12: 801399604 | AU12: 695500231 | AV12: 663502461 | AW12: 1555671370 | AX12: 936492932 | AY12: 1103852896 | AZ12: 1608708972 | BA12: 1489581015 | BB12: 1372261307 | BC12: 636041020 | BD12: 1257673070 | BE12: 993026233 | BF12: 1529745602 | BG12: 1349010483 | BH12: 902730488 | BI12: 1450570894 | BJ12: 858169737 | BK12: 1483876982 | BL12: 1315247967 | BM12: 1366041150 | BN12: 1603769193 | BO12: 2900732378 | BP12: 1301741764 | BQ12: 2479436989 | BR12: 1532817392 | BS12: 1569283837 | BT12: 1510605035 | BU12: 1998884061
A13: 10 | B13: Trong đó: Chi phí lãi vay | C13: 5 | D13: =SUM(Data_PL7[[#This Row],[T1.2021]:[T12.2021]]) -> 3929610603 | E13: =SUM(Data_PL7[[#This Row],[T1.2022]:[T12.2022]]) -> 7725836076 | F13: =SUM(Data_PL7[[#This Row],[T1.2023]:[T12.2023]]) -> 1165406526 | G13: =SUM(Data_PL7[[#This Row],[T01.2024]:[T12.2024]]) -> 10328501137 | H13: =SUM(Data_PL7[[#This Row],[T01.2025]:[T12.2025]]) -> 14263439054 | I13: =SUM(Data_PL7[[#This Row],[T01.2026]:[T12.2026]]) -> 4418197522 | J13: 167603935 | K13: 221659846 | L13: 208008837 | M13: 262170575 | N13: 294134531 | O13: 375347816 | P13: 340813568 | Q13: 399256526 | R13: 400979485 | S13: 368636370 | T13: 424483338 | U13: 466515776 | V13: 517655739 | W13: 651086182 | X13: 617884939 | Y13: 507919165 | Z13: 603465663 | AA13: 147007916 | AB13: 631302971 | AC13: 699695123 | AD13: 854484433 | AE13: 862022364 | AF13: 1093552795 | AG13: 539758786 | AH13: 44321388 | AI13: 0 | AJ13: 48722388 | AK13: 76187496 | AL13: 68801482 | AM13: 28249626 | AN13: 91396439 | AO13: 93845376 | AP13: 109400024 | AQ13: 129996535 | AR13: 157601782 | AS13: 316883990 | AT13: 460461775 | AU13: 563909516 | AV13: 587315920 | AW13: 905708142 | AX13: 974310029 | AY13: 1115056080 | AZ13: 1160823006 | BA13: 939585045 | BB13: 859444105 | BC13: 840165515 | BD13: 889159081 | BE13: 1032562923 | BF13: 1114824276 | BG13: 928379281 | BH13: 673966789 | BI13: 888393452 | BJ13: 1186588729 | BK13: 1448899822 | BL13: 1242023326 | BM13: 1303560910 | BN13: 1595764355 | BO13: 1368802426 | BP13: 1256132292 | BQ13: 1256103396 | BR13: 1240115065 | BS13: 1156279418 | BT13: 959718564 | BU13: 1062084475
A14: 11 | B14: 9.Chi phí bán hàng | C14: 5 | D14: =SUM(Data_PL7[[#This Row],[T1.2021]:[T12.2021]]) -> 3009092451 | E14: =SUM(Data_PL7[[#This Row],[T1.2022]:[T12.2022]]) -> 14690021152 | F14: =SUM(Data_PL7[[#This Row],[T1.2023]:[T12.2023]]) -> 19132571517 | G14: =SUM(Data_PL7[[#This Row],[T01.2024]:[T12.2024]]) -> 50836279646 | H14: =SUM(Data_PL7[[#This Row],[T01.2025]:[T12.2025]]) -> 55101745592 | I14: =SUM(Data_PL7[[#This Row],[T01.2026]:[T12.2026]]) -> 19001448254 | J14: 0 | K14: 0 | L14: 0 | M14: 0 | N14: 0 | O14: 0 | P14: 0 | Q14: 251616145 | R14: 680077987 | S14: 546329598 | T14: 967543289 | U14: 563525432 | V14: 496681104 | W14: 38696800 | X14: 1520204587 | Y14: 3287497220 | Z14: 563902784 | AA14: 802923682 | AB14: 1108487180 | AC14: 819028904 | AD14: 1282383810 | AE14: 1073636694 | AF14: 1462938929 | AG14: 2233639458 | AH14: 645459129 | AI14: 991254056 | AJ14: 1883160244 | AK14: 1145404547 | AL14: 1970368365 | AM14: 1459341885 | AN14: 1450399092 | AO14: 2363556660 | AP14: 1466584216 | AQ14: 2298997918 | AR14: 1849124450 | AS14: 1608920955 | AT14: 2846219487 | AU14: 1219456854 | AV14: 3715738043 | AW14: 4585159549 | AX14: 1693810954 | AY14: 2407466874 | AZ14: 2300964337 | BA14: 8205607205 | BB14: 7036529523 | BC14: 4608951194 | BD14: 1949627546 | BE14: 10266748080 | BF14: 4006424849 | BG14: 6313682258 | BH14: 5091544776 | BI14: 4077126734 | BJ14: 4686536575 | BK14: 4796729528 | BL14: 3449972349 | BM14: 4949095751 | BN14: 2811598286 | BO14: 6688603934 | BP14: 3413749635 | BQ14: 4816680917 | BR14: 3731798004 | BS14: 3202645336 | BT14: 6245695788 | BU14: 5821309126
A15: 12 | B15: 10.Chi phí quản lý doanh nghiệp | C15: 5 | D15: =SUM(Data_PL7[[#This Row],[T1.2021]:[T12.2021]]) -> 11203395485 | E15: =SUM(Data_PL7[[#This Row],[T1.2022]:[T12.2022]]) -> 29733399077 | F15: =SUM(Data_PL7[[#This Row],[T1.2023]:[T12.2023]]) -> 40274613810 | G15: =SUM(Data_PL7[[#This Row],[T01.2024]:[T12.2024]]) -> 70102214341 | H15: =SUM(Data_PL7[[#This Row],[T01.2025]:[T12.2025]]) -> 98715170412 | I15: =SUM(Data_PL7[[#This Row],[T01.2026]:[T12.2026]]) -> 31832287701 | J15: 457415751 | K15: 619384345 | L15: 707076077 | M15: 816715935 | N15: 827613489 | O15: 624184259 | P15: 2510720411 | Q15: 569609208 | R15: 536039299 | S15: 941857345 | T15: 3424596971 | U15: -831817605 | V15: 1435430845 | W15: 1479188151 | X15: 1624743284 | Y15: 1725353483 | Z15: 1803134313 | AA15: 1872200320 | AB15: 1882239518 | AC15: 2444716491 | AD15: 2755381317 | AE15: 3239626198 | AF15: 3143544394 | AG15: 6327840763 | AH15: 2772788125 | AI15: 2947588122 | AJ15: 3098829707 | AK15: 3036290770 | AL15: 3448026712 | AM15: 3261800788 | AN15: 3348437381 | AO15: 1910475796 | AP15: 3536419913 | AQ15: 3592592574 | AR15: 3600549435 | AS15: 5720814487 | AT15: 5241377343 | AU15: 4647980221 | AV15: 4838115306 | AW15: 5132788494 | AX15: 5665606587 | AY15: 5470797521 | AZ15: 5239042307 | BA15: 6065017937 | BB15: 7524726581 | BC15: 7016385931 | BD15: 7426888275 | BE15: 5833487838 | BF15: 7638868570 | BG15: 7013534740 | BH15: 7332584934 | BI15: 7155903324 | BJ15: 7948694673 | BK15: 7721648228 | BL15: 7616453256 | BM15: 7931593154 | BN15: 9422194647 | BO15: 3775611792 | BP15: 9875644458 | BQ15: 15282438636 | BR15: 8394130638 | BS15: 7959394332 | BT15: 7329810589 | BU15: 8148952142
A16: 13 | B16: 11.Lợi nhuận thuần từ hoạt động kinh doanh | C16: 5 | D16: =SUM(Data_PL7[[#This Row],[T1.2021]:[T12.2021]]) -> 5337309604 | E16: =SUM(Data_PL7[[#This Row],[T1.2022]:[T12.2022]]) -> -6044152136 | F16: =SUM(Data_PL7[[#This Row],[T1.2023]:[T12.2023]]) -> 113776714431 | G16: =SUM(Data_PL7[[#This Row],[T01.2024]:[T12.2024]]) -> 74232630581 | H16: =SUM(Data_PL7[[#This Row],[T01.2025]:[T12.2025]]) -> 38578546121 | I16: =SUM(Data_PL7[[#This Row],[T01.2026]:[T12.2026]]) -> -10870908667 | J16: -145242364 | K16: -561242112 | L16: 1079880079 | M16: 412369142 | N16: -831102586 | O16: -937389304 | P16: 3147473719 | Q16: 1027070127 | R16: 2126978303 | S16: 469318201 | T16: -2520958524 | U16: 2070154923 | V16: -364468934 | W16: -1428839181 | X16: 545981904 | Y16: 1650096564 | Z16: 2456936062 | AA16: 2026651135 | AB16: 1377966393 | AC16: 3101161984 | AD16: 885699606 | AE16: -393669160 | AF16: -1460282402 | AG16: -14441386107 | AH16: 724630559 | AI16: -2654785583 | AJ16: -7224620343 | AK16: -2938680602 | AL16: 2786324124 | AM16: 39020306342 | AN16: 4428971361 | AO16: 12407993027 | AP16: 22901435976 | AQ16: 17510693234 | AR16: 9200105319 | AS16: 17614341017 | AT16: 1933695736 | AU16: -5270660796 | AV16: -2937512643 | AW16: 2475246742 | AX16: -4117202543 | AY16: -10105774890 | AZ16: -13571603862 | BA16: -8460674377 | BB16: 9675868151 | BC16: -4807983867 | BD16: -4640581121 | BE16: 114059814051 | BF16: 5762022698 | BG16: 20541037329 | BH16: 8348281164 | BI16: 4412167173 | BJ16: 11097005663 | BK16: 1310222046 | BL16: -1670593931 | BM16: 592817173 | BN16: -11011661349 | BO16: -1686591557 | BP16: -6668379119 | BQ16: 7552218831 | BR16: -1586656660 | BS16: -6268283537 | BT16: -6785612190 | BU16: 3769643720
A17: 14 | B17: 12.Thu nhập khác | C17: 5 | D17: =SUM(Data_PL7[[#This Row],[T1.2021]:[T12.2021]]) -> 18771710496 | E17: =SUM(Data_PL7[[#This Row],[T1.2022]:[T12.2022]]) -> 92779904880 | F17: =SUM(Data_PL7[[#This Row],[T1.2023]:[T12.2023]]) -> 17391162 | G17: =SUM(Data_PL7[[#This Row],[T01.2024]:[T12.2024]]) -> 1503561903 | H17: =SUM(Data_PL7[[#This Row],[T01.2025]:[T12.2025]]) -> 454238633 | I17: =SUM(Data_PL7[[#This Row],[T01.2026]:[T12.2026]]) -> 11703115 | J17: 0 | K17: 299375994 | L17: 787003464 | M17: 853324557 | N17: 610174630 | O17: 1291891103 | P17: 8989972067 | Q17: 40395118 | R17: 2077248 | S17: 399581022 | T17: 2510200174 | U17: 2987715119 | V17: 5351841304 | W17: 240544660 | X17: 164167319 | Y17: 0 | Z17: 397562937 | AA17: 263298162 | AB17: 116035636 | AC17: 406946130 | AD17: 1142849269 | AE17: 973159654 | AF17: 4531212183 | AG17: 79192287626 | AH17: 332026 | AI17: 0 | AJ17: 2 | AK17: 1 | AL17: 0 | AM17: 425 | AN17: 0 | AO17: 0 | AP17: 0 | AQ17: 0 | AR17: 8116 | AS17: 17050592 | AT17: 1945 | AU17: 12000 | AV17: 0 | AW17: 0 | AX17: 203 | AY17: 58510228 | AZ17: 52918371 | BA17: 177726993 | BB17: 999 | BC17: 196700 | BD17: 1398763491 | BE17: -184569027 | BF17: 500207 | BG17: 2492480 | BH17: 2600082 | BI17: 33918440 | BJ17: 115000000 | BK17: 2020926 | BL17: 9788652 | BM17: 244500606 | BN17: 742 | BO17: 819591 | BP17: 110446 | BQ17: 42486461 | BR17: 4505 | BS17: 70001 | BT17: 1144804 | BU17: 10483805
A18: 15 | B18: 13.Chi phí khác | C18: 5 | D18: =SUM(Data_PL7[[#This Row],[T1.2021]:[T12.2021]]) -> 3720756403 | E18: =SUM(Data_PL7[[#This Row],[T1.2022]:[T12.2022]]) -> 5507730098 | F18: =SUM(Data_PL7[[#This Row],[T1.2023]:[T12.2023]]) -> 198294222 | G18: =SUM(Data_PL7[[#This Row],[T01.2024]:[T12.2024]]) -> 8884638060 | H18: =SUM(Data_PL7[[#This Row],[T01.2025]:[T12.2025]]) -> 7634668922 | I18: =SUM(Data_PL7[[#This Row],[T01.2026]:[T12.2026]]) -> 368182201 | J18: 77565 | K18: 0 | L18: 0 | M18: 0 | N18: 6136364 | O18: 0 | P18: 0 | Q18: 0 | R18: 0 | S18: 0 | T18: 0 | U18: 3714542474 | V18: 0 | W18: 274745 | X18: 2093722658 | Y18: 631668424 | Z18: 567391744 | AA18: 150706725 | AB18: 2322906 | AC18: 1880704 | AD18: 593797145 | AE18: 15441 | AF18: 441600828 | AG18: 1024348778 | AH18: 1 | AI18: 236 | AJ18: 0 | AK18: 7135172 | AL18: 3500000 | AM18: 99064 | AN18: 0 | AO18: -36000 | AP18: 0 | AQ18: 0 | AR18: 0 | AS18: 187595749 | AT18: 7958068 | AU18: 1 | AV18: 21796958 | AW18: 2 | AX18: 36200000 | AY18: 168183405 | AZ18: 6000002 | BA18: 601 | BB18: 2601033 | BC18: 170398064 | BD18: 202496 | BE18: 8471297430 | BF18: 1251667 | BG18: 130033300 | BH18: 0 | BI18: 17808640 | BJ18: 600 | BK18: 50477376 | BL18: 130663204 | BM18: 539898446 | BN18: 539664890 | BO18: 3515574706 | BP18: 1106262251 | BQ18: 1603033842 | BR18: 106808581 | BS18: 151000202 | BT18: 34000105 | BU18: 76373313
A19: 16 | B19: 14.Lợi nhuận khác | C19: 5 | D19: =SUM(Data_PL7[[#This Row],[T1.2021]:[T12.2021]]) -> 15050954093 | E19: =SUM(Data_PL7[[#This Row],[T1.2022]:[T12.2022]]) -> 87272174782 | F19: =SUM(Data_PL7[[#This Row],[T1.2023]:[T12.2023]]) -> -180903060 | G19: =SUM(Data_PL7[[#This Row],[T01.2024]:[T12.2024]]) -> -7381076157 | H19: =SUM(Data_PL7[[#This Row],[T01.2025]:[T12.2025]]) -> -7180430289 | I19: =SUM(Data_PL7[[#This Row],[T01.2026]:[T12.2026]]) -> -356479086 | J19: -77565 | K19: 299375994 | L19: 787003464 | M19: 853324557 | N19: 604038266 | O19: 1291891103 | P19: 8989972067 | Q19: 40395118 | R19: 2077248 | S19: 399581022 | T19: 2510200174 | U19: -726827355 | V19: 5351841304 | W19: 240269915 | X19: -1929555339 | Y19: -631668424 | Z19: -169828807 | AA19: 112591437 | AB19: 113712730 | AC19: 405065426 | AD19: 549052124 | AE19: 973144213 | AF19: 4089611355 | AG19: 78167938848 | AH19: 332025 | AI19: -236 | AJ19: 2 | AK19: -7135171 | AL19: -3500000 | AM19: -98639 | AN19: 0 | AO19: 36000 | AP19: 0 | AQ19: 0 | AR19: 8116 | AS19: -170545157 | AT19: -7956123 | AU19: 11999 | AV19: -21796958 | AW19: -2 | AX19: -36199797 | AY19: -109673177 | AZ19: 46918369 | BA19: 177726392 | BB19: -2600034 | BC19: -170201364 | BD19: 1398560995 | BE19: -8655866457 | BF19: -751460 | BG19: -127540820 | BH19: 2600082 | BI19: 16109800 | BJ19: 114999400 | BK19: -48456450 | BL19: -120874552 | BM19: -295397840 | BN19: -539664148 | BO19: -3514755115 | BP19: -1106151805 | BQ19: -1560547381 | BR19: -106804076 | BS19: -150930201 | BT19: -32855301 | BU19: -65889508
A20: 17 | B20: 15.Tổng lợi nhuận kế toán trước thuế | C20: 5 | D20: =SUM(Data_PL7[[#This Row],[T1.2021]:[T12.2021]]) -> 20388263697 | E20: =SUM(Data_PL7[[#This Row],[T1.2022]:[T12.2022]]) -> 81228022646 | F20: =SUM(Data_PL7[[#This Row],[T1.2023]:[T12.2023]]) -> 113595811371 | G20: =SUM(Data_PL7[[#This Row],[T01.2024]:[T12.2024]]) -> 66851554424 | H20: =SUM(Data_PL7[[#This Row],[T01.2025]:[T12.2025]]) -> 31398115832 | I20: =SUM(Data_PL7[[#This Row],[T01.2026]:[T12.2026]]) -> -11227387753 | J20: -145319929 | K20: -261866118 | L20: 1866883543 | M20: 1265693699 | N20: -227064320 | O20: 354501799 | P20: 12137445786 | Q20: 1067465245 | R20: 2129055551 | S20: 868899223 | T20: -10758350 | U20: 1343327568 | V20: 4987372370 | W20: -1188569266 | X20: -1383573435 | Y20: 1018428140 | Z20: 2287107255 | AA20: 2139242572 | AB20: 1491679123 | AC20: 3506227410 | AD20: 1434751730 | AE20: 579475053 | AF20: 2629328953 | AG20: 63726552741 | AH20: 724962584 | AI20: -2654785819 | AJ20: -7224620341 | AK20: -2945815773 | AL20: 2782824124 | AM20: 39020207703 | AN20: 4428971361 | AO20: 12408029027 | AP20: 22901435976 | AQ20: 17510693234 | AR20: 9200113435 | AS20: 17443795860 | AT20: 1925739613 | AU20: -5270648797 | AV20: -2959309601 | AW20: 2475246740 | AX20: -4153402340 | AY20: -10215448067 | AZ20: -13524685493 | BA20: -8282947985 | BB20: 9673268117 | BC20: -4978185231 | BD20: -3242020126 | BE20: 105403947594 | BF20: 5761271238 | BG20: 20413496509 | BH20: 8350881246 | BI20: 4428276973 | BJ20: 11212005063 | BK20: 1261765596 | BL20: -1791468483 | BM20: 297419333 | BN20: -11551325497 | BO20: -5201346672 | BP20: -7774530924 | BQ20: 5991671450 | BR20: -1693460736 | BS20: -6419213738 | BT20: -6818467491 | BU20: 3703754212
A21: 18 | B21: 16.Chi phí thuế TNDN hiện hành | C21: 5 | D21: =SUM(Data_PL7[[#This Row],[T1.2021]:[T12.2021]]) -> 2854356918 | E21: =SUM(Data_PL7[[#This Row],[T1.2022]:[T12.2022]]) -> 19125239788 | F21: =SUM(Data_PL7[[#This Row],[T1.2023]:[T12.2023]]) -> 11001624815 | G21: =SUM(Data_PL7[[#This Row],[T01.2024]:[T12.2024]]) -> 11495266455 | H21: =SUM(Data_PL7[[#This Row],[T01.2025]:[T12.2025]]) -> 7500302208 | I21: =SUM(Data_PL7[[#This Row],[T01.2026]:[T12.2026]]) -> -153060867 | J21: 0 | K21: 0 | L21: 373376709 | M21: 253138740 | N21: 0 | O21: 70900360 | P21: 2427489157 | Q21: 213493049 | R21: 425811110 | S21: 173779845 | T21: 0 | U21: -1083632052 | V21: 997474474 | W21: 0 | X21: 0 | Y21: 203685628 | Z21: 457567861 | AA21: 427848514 | AB21: 298494225 | AC21: 701245482 | AD21: 286950346 | AE21: 115895011 | AF21: 525865791 | AG21: 15110212456 | AH21: 144992517 | AI21: 0 | AJ21: 0 | AK21: 0 | AL21: 0 | AM21: 5795561979 | AN21: 885794272 | AO21: 2481605805 | AP21: 4580287195 | AQ21: 3502138647 | AR21: 1840022687 | AS21: -8228778287 | AT21: 0 | AU21: 0 | AV21: 0 | AW21: 0 | AX21: 0 | AY21: 0 | AZ21: 0 | BA21: 0 | BB21: 0 | BC21: 0 | BD21: 0 | BE21: 11495266455 | BF21: 864190686 | BG21: 3020742780 | BH21: 1252632187 | BI21: 677293488 | BJ21: 1681800759 | BK21: 189264839 | BL21: -1000088030 | BM21: 204199602 | BN21: -1349170846 | BO21: -516688622 | BP21: -854033077 | BQ21: 3330158442 | BS21: 0 | BT21: -153060867
A22: 19 | B22: 17.Chi phí thuế TNDN hoãn lại | C22: 5 | D22: =SUM(Data_PL7[[#This Row],[T1.2021]:[T12.2021]]) -> 0 | E22: =SUM(Data_PL7[[#This Row],[T1.2022]:[T12.2022]]) -> 0 | F22: =SUM(Data_PL7[[#This Row],[T1.2023]:[T12.2023]]) -> 0 | G22: =SUM(Data_PL7[[#This Row],[T01.2024]:[T12.2024]]) -> 1838941310 | H22: =SUM(Data_PL7[[#This Row],[T01.2025]:[T12.2025]]) -> -1838941310 | I22: =SUM(Data_PL7[[#This Row],[T01.2026]:[T12.2026]]) -> 0 | J22: 0 | K22: 0 | L22: 0 | M22: 0 | N22: 0 | O22: 0 | P22: 0 | Q22: 0 | R22: 0 | S22: 0 | T22: 0 | U22: 0 | V22: 0 | W22: 0 | X22: 0 | Y22: 0 | Z22: 0 | AA22: 0 | AB22: 0 | AC22: 0 | AD22: 0 | AE22: 0 | AF22: 0 | AG22: 0 | AH22: 0 | AI22: 0 | AJ22: 0 | AK22: 0 | AL22: 0 | AM22: 0 | AN22: 0 | AO22: 0 | AP22: 0 | AQ22: 0 | AR22: 0 | AS22: 0 | AT22: 0 | AU22: 0 | AV22: 0 | AW22: 0 | AX22: 0 | AY22: 0 | AZ22: 0 | BA22: 0 | BB22: 0 | BC22: 0 | BD22: 0 | BE22: 1838941310 | BF22: 0 | BG22: -8043000 | BH22: 0 | BI22: 0 | BK22: 0 | BL22: -1830898310 | BM22: 0 | BN22: 0 | BO22: 0 | BP22: 0 | BQ22: 0 | BS22: 0
A23: 20 | B23: 18.Lợi nhuận sau thuế thu nhập doanh nghiệp | C23: 5 | D23: =SUM(Data_PL7[[#This Row],[T1.2021]:[T12.2021]]) -> 17533906779 | E23: =SUM(Data_PL7[[#This Row],[T1.2022]:[T12.2022]]) -> 62102782858 | F23: =SUM(Data_PL7[[#This Row],[T1.2023]:[T12.2023]]) -> 102594186556 | G23: =SUM(Data_PL7[[#This Row],[T01.2024]:[T12.2024]]) -> 53517346659 | H23: =SUM(Data_PL7[[#This Row],[T01.2025]:[T12.2025]]) -> 25736754934 | I23: =SUM(Data_PL7[[#This Row],[T01.2026]:[T12.2026]]) -> -11074326886 | J23: -145319929 | K23: -261866118 | L23: 1493506834 | M23: 1012554959 | N23: -227064320 | O23: 283601439 | P23: 9709956629 | Q23: 853972196 | R23: 1703244441 | S23: 695119378 | T23: -10758350 | U23: 2426959620 | V23: 3989897896 | W23: -1188569266 | X23: -1383573435 | Y23: 814742512 | Z23: 1829539394 | AA23: 1711394058 | AB23: 1193184898 | AC23: 2804981928 | AD23: 1147801384 | AE23: 463580042 | AF23: 2103463162 | AG23: 48616340285 | AH23: 579970067 | AI23: -2654785819 | AJ23: -7224620341 | AK23: -2945815773 | AL23: 2782824124 | AM23: 33224645724 | AN23: 3543177089 | AO23: 9926423222 | AP23: 18321148781 | AQ23: 14008554587 | AR23: 7360090748 | AS23: 25672574147 | AT23: 1925739613 | AU23: -5270648797 | AV23: -2959309601 | AW23: 2475246740 | AX23: -4153402340 | AY23: -10215448067 | AZ23: -13524685493 | BA23: -8282947985 | BB23: 9673268117 | BC23: -4978185231 | BD23: -3242020126 | BE23: 92069739829 | BF23: 4897080552 | BG23: 17400796729 | BH23: 7098249059 | BI23: 3750983485 | BJ23: 9530204304 | BK23: 1072500757 | BL23: 1039517857 | BM23: 93219731 | BN23: -10202154651 | BO23: -4684658050 | BP23: -6920497847 | BQ23: 2661513008 | BR23: -1693460736 | BS23: -6419213738 | BT23: -6665406624 | BU23: 3703754212
B24: % LNST | D24: =D23/D7 -> 0.28984575 | E24: =E23/E7 -> 0.18822901 | F24: =F23/F7 -> 0.1496591 | G24: =G23/G7 -> 0.04491911 | H24: =H23/H7 -> 0.016739072 | I24: =I23/I7 -> -0.019952717

Sheet PL DTR
B1: CTY CP NHỰA TÁI CHẾ DUY TÂN
B2: VND
A3: Index PL | B3: PHẦN II-KẾT QUẢ HOẠT ĐỘNG KINH DOANH | C3: TenCongTyID | D3: 2021 | E3: 2022 | F3: 2023 | G3: 2024 | H3: 2025 | I3: 2026 | J3: T1.2021 | K3: T02.2021 | L3: T03.2021 | M3: T04.2021 | N3: T05.2021 | O3: T06.2021 | P3: T07.2021 | Q3: T08.2021 | R3: T09.2021 | S3: T10.2021 | T3: T11.2021 | U3: T12.2021 | V3: T1.2022 | W3: T02.2022 | X3: T03.2022 | Y3: T04.2022 | Z3: T05.2022 | AA3: T06.2022 | AB3: T07.2022 | AC3: T08.2022 | AD3: T09.2022 | AE3: T10.2022 | AF3: T11.2022 | AG3: T12.2022 | AH3: T1.2023 | AI3: T02.2023 | AJ3: T03.2023 | AK3: T04.2023 | AL3: T05.2023 | AM3: T06.2023 | AN3: T07.2023 | AO3: T08.2023 | AP3: T09.2023 | AQ3: T10.2023 | AR3: T11.2023 | AS3: T12.2023 | AT3: T01.2024 | AU3: T02.2024 | AV3: T03.2024 | AW3: T04.2024 | AX3: T05.2024 | AY3: T06.2024 | AZ3: T07.2024 | BA3: T08.2024 | BB3: T09.2024 | BC3: T10.2024 | BD3: T11.2024 | BE3: T12.2024 | BF3: T01.2025 | BG3: T02.2025 | BH3: T03.2025 | BI3: T04.2025 | BJ3: T05.2025 | BK3: T06.2025 | BL3: T07.2025 | BM3: T08.2025 | BN3: T09.2025 | BO3: T10.2025 | BP3: T11.2025 | BQ3: T12.2025 | BR3: T01.2026 | BS3: T02.2026 | BT3: T03.2026 | BU3: T04.2026 | BV3: T05.2026 | BW3: T06.2026 | BX3: T07.2026 | BY3: T08.2026 | BZ3: T09.2026 | CA3: T10.2026 | CB3: T11.2026 | CC3: T12.2026
A4: 1 | B4: Sản lượng (kg) | C4: 5 | D4: =SUM(Data_PL73[[#This Row],[T1.2021]:[T12.2021]]) -> 2131.962 | E4: =SUM(Data_PL73[[#This Row],[T1.2022]:[T12.2022]]) -> 9850.865 | F4: =SUM(Data_PL73[[#This Row],[T1.2023]:[T12.2023]]) -> 22582.09 | G4: =SUM(Data_PL73[[#This Row],[T01.2024]:[T12.2024]]) -> 40044.844 | H4: =SUM(Data_PL73[[#This Row],[T01.2025]:[T12.2025]]) -> 50376.161 | I4: =SUM(Data_PL73[[#This Row],[T01.2026]:[T12.2026]]) -> 19871.663 | J4: 76.025 | K4: 61 | L4: 303.8 | M4: 215.35 | N4: 35.93 | O4: 30.437 | P4: 87.5 | Q4: 69.2 | R4: 115.5 | S4: 262.5 | T4: 284.8 | U4: 589.92 | V4: 250.8 | W4: 242 | X4: 710 | Y4: 815.189 | Z4: 578.208 | AA4: 678.9 | AB4: 421.5 | AC4: 1104.468 | AD4: 1030.32 | AE4: 1178.275 | AF4: 981.1 | AG4: 1860.105 | AH4: 651.8 | AI4: 653.075 | AJ4: 1875.95 | AK4: 1792.575 | AL4: 1632.875 | AM4: 1573.975 | AN4: 2078.599 | AO4: 2591.943 | AP4: 2246.875 | AQ4: 3057.347 | AR4: 2111.308 | AS4: 2315.768 | AT4: 3553.2 | AU4: 2285.051 | AV4: 2972.068 | AW4: 3202.752 | AX4: 3455.89 | AY4: 2432.325 | AZ4: 1986.853 | BA4: 5184.5942 | BB4: 4932.507 | BC4: 4058.203 | BD4: 2606.253 | BE4: 3375.148 | BF4: 3612.7513 | BG4: 6002.038 | BH4: 4985.538 | BI4: 4060.361 | BJ4: 4785.7603 | BK4: 3895.695 | BL4: 4652.4191 | BM4: 5655.27 | BN4: 3106.292 | BO4: 3393.537 | BP4: 3040.82 | BQ4: 3185.679 | BR4: 4409.992 | BS4: 3267.6 | BT4: 6445.446 | BU4: 5748.625
A5: 2 | B5: 1.Doanh thu bán hàng và cung cấp dịch vụ | C5: 5 | D5: =SUM(Data_PL73[[#This Row],[T1.2021]:[T12.2021]]) -> 60562275921 | E5: =SUM(Data_PL73[[#This Row],[T1.2022]:[T12.2022]]) -> 330330688073 | F5: =SUM(Data_PL73[[#This Row],[T1.2023]:[T12.2023]]) -> 685554367311 | G5: =SUM(Data_PL73[[#This Row],[T01.2024]:[T12.2024]]) -> 1211387224737 | H5: =SUM(Data_PL73[[#This Row],[T01.2025]:[T12.2025]]) -> 1551998582223 | I5: =SUM(Data_PL73[[#This Row],[T01.2026]:[T12.2026]]) -> 556792402428 | J5: 2192940600 | K5: 1791822000 | L5: 8682084600 | M5: 6264332700 | N5: 1376973402 | O5: 904631370 | P5: 3085582842 | Q5: 2036756400 | R5: 4007834643 | S5: 8372308560 | T5: 8615033640 | U5: 13231975164 | V5: 7498036216 | W5: 6876982200 | X5: 21877405036 | Y5: 27424133378 | Z5: 18350378815 | AA5: 21902018748 | AB5: 15882148168 | AC5: 38706132850 | AD5: 36809694250 | AE5: 41577847270 | AF5: 34741567940 | AG5: 58684343202 | AH5: 24985455241 | AI5: 23042319009 | AJ5: 59212986698 | AK5: 54287237375 | AL5: 57641008821 | AM5: 50922412416 | AN5: 53533092198 | AO5: 78282463651 | AP5: 64916176630 | AQ5: 84671529098 | AR5: 62903041444 | AS5: 71156644730 | AT5: 95961616736 | AU5: 70105871996 | AV5: 92109508133 | AW5: 97489092894 | AX5: 102501453344 | AY5: 68093170109 | AZ5: 56451269692 | BA5: 160372945473 | BB5: 161501484254 | BC5: 119734804022 | BD5: 76175498864 | BE5: 110890509220 | BF5: 114976445897 | BG5: 188477338235 | BH5: 150730683132 | BI5: 125734240353 | BJ5: 153674258114 | BK5: 119843310993 | BL5: 138018360641 | BM5: 169442946928 | BN5: 91484253567 | BO5: 108928556660 | BP5: 89826973802 | BQ5: 100861213901 | BR5: 126786913920 | BS5: 96600110916 | BT5: 174261948689 | BU5: 159143428903
A6: 3 | B6: 2.Các khoản giảm trừ doanh thu | C6: 5 | D6: =SUM(Data_PL73[[#This Row],[T1.2021]:[T12.2021]]) -> 68351150 | E6: =SUM(Data_PL73[[#This Row],[T1.2022]:[T12.2022]]) -> 398631999 | F6: =SUM(Data_PL73[[#This Row],[T1.2023]:[T12.2023]]) -> 35151625 | G6: =SUM(Data_PL73[[#This Row],[T01.2024]:[T12.2024]]) -> 19971229676 | H6: =SUM(Data_PL73[[#This Row],[T01.2025]:[T12.2025]]) -> 14472758187 | I6: =SUM(Data_PL73[[#This Row],[T01.2026]:[T12.2026]]) -> 1763882787 | J6: 0 | K6: 0 | L6: 0 | M6: 0 | N6: 0 | O6: 36461250 | P6: 0 | Q6: 686000 | R6: 0 | S6: 0 | T6: 0 | U6: 31203900 | V6: 0 | W6: 765658695 | X6: -760221195 | Y6: 0 | Z6: 0 | AA6: 0 | AB6: 3076000 | AC6: 346771999 | AD6: 0 | AE6: 0 | AF6: 43346500 | AG6: 0 | AH6: 0 | AI6: 0 | AJ6: 453218 | AK6: 195177 | AL6: 9024000 | AM6: 18714230 | AN6: 6765000 | AO6: 0 | AP6: 0 | AQ6: 0 | AR6: 0 | AS6: 0 | AT6: 0 | AU6: 1166125000 | AV6: 0 | AW6: 0 | AX6: 136455000 | AY6: 0 | AZ6: 0 | BA6: 6345077301 | BB6: 4671587529 | BC6: 2922205276 | BD6: 49359030 | BE6: 4680420540 | BF6: 513935495 | BG6: 477877176 | BH6: 477350452 | BI6: 304590498 | BJ6: 1607115262 | BK6: 708638196 | BL6: 26953743 | BM6: 1000293545 | BN6: 6773818500 | BO6: 0 | BP6: 1479093000 | BQ6: 1103092320 | BR6: 687876997 | BS6: 33305556 | BT6: 956126160 | BU6: 86574074
A7: 4 | B7: 3.Doanh thu thuần về bán hàng và cung cấp dịch vụ | C7: 5 | D7: =SUM(Data_PL73[[#This Row],[T1.2021]:[T12.2021]]) -> 60493924771 | E7: =SUM(Data_PL73[[#This Row],[T1.2022]:[T12.2022]]) -> 329932056074 | F7: =SUM(Data_PL73[[#This Row],[T1.2023]:[T12.2023]]) -> 685519215686 | G7: =SUM(Data_PL73[[#This Row],[T01.2024]:[T12.2024]]) -> 1191415995061 | H7: =SUM(Data_PL73[[#This Row],[T01.2025]:[T12.2025]]) -> 1537525824036 | I7: =SUM(Data_PL73[[#This Row],[T01.2026]:[T12.2026]]) -> 555028519641 | J7: 2192940600 | K7: 1791822000 | L7: 8682084600 | M7: 6264332700 | N7: 1376973402 | O7: 868170120 | P7: 3085582842 | Q7: 2036070400 | R7: 4007834643 | S7: 8372308560 | T7: 8615033640 | U7: 13200771264 | V7: 7498036216 | W7: 6111323505 | X7: 22637626231 | Y7: 27424133378 | Z7: 18350378815 | AA7: 21902018748 | AB7: 15879072168 | AC7: 38359360851 | AD7: 36809694250 | AE7: 41577847270 | AF7: 34698221440 | AG7: 58684343202 | AH7: 24985455241 | AI7: 23042319009 | AJ7: 59212533480 | AK7: 54287042198 | AL7: 57631984821 | AM7: 50903698186 | AN7: 53526327198 | AO7: 78282463651 | AP7: 64916176630 | AQ7: 84671529098 | AR7: 62903041444 | AS7: 71156644730 | AT7: 95961616736 | AU7: 68939746996 | AV7: 92109508133 | AW7: 97489092894 | AX7: 102364998344 | AY7: 68093170109 | AZ7: 56451269692 | BA7: 154027868172 | BB7: 156829896725 | BC7: 116812598746 | BD7: 76126139834 | BE7: 106210088680 | BF7: 114462510402 | BG7: 187999461059 | BH7: 150253332680 | BI7: 125429649855 | BJ7: 152067142852 | BK7: 119134672797 | BL7: 137991406898 | BM7: 168442653383 | BN7: 84710435067 | BO7: 108928556660 | BP7: 88347880802 | BQ7: 99758121581 | BR7: 126099036923 | BS7: 96566805360 | BT7: 173305822529 | BU7: 159056854829
A8: 5 | B8: 4.Giá vốn hàng bán | C8: 5 | D8: =SUM(Data_PL73[[#This Row],[T1.2021]:[T12.2021]]) -> 55288134722 | E8: =SUM(Data_PL73[[#This Row],[T1.2022]:[T12.2022]]) -> 299901216900 | F8: =SUM(Data_PL73[[#This Row],[T1.2023]:[T12.2023]]) -> 518594542678 | G8: =SUM(Data_PL73[[#This Row],[T01.2024]:[T12.2024]]) -> 998230253982 | H8: =SUM(Data_PL73[[#This Row],[T01.2025]:[T12.2025]]) -> 1343495797036 | I8: =SUM(Data_PL73[[#This Row],[T01.2026]:[T12.2026]]) -> 512422326416 | J8: 1714389259 | K8: 1513381552 | L8: 6687623393 | M8: 4774057263 | N8: 1087102095 | O8: 807656278 | P8: 2716172489 | Q8: 4315716140 | R8: 4265960659 | S8: 7443114351 | T8: 7773986301 | U8: 12188974942 | V8: 6843552810 | W8: 6912963718 | X8: 19836366360 | Y8: 21907875072 | Z8: 15580244606 | AA8: 18312738285 | AB8: 12006617281 | AC8: 32529935445 | AD8: 32281385317 | AE8: 38377094489 | AF8: 30963456194 | AG8: 64348987323 | AH8: 20792367485 | AI8: 21918378947 | AJ8: 61251223688 | AK8: 53942190282 | AL8: 50245648463 | AM8: 7904131770 | AN8: 44797235508 | AO8: 62222051344 | AP8: 37728980820 | AQ8: 61940025172 | AR8: 49113504898 | AS8: 46738804301 | AT8: 85841765176 | AU8: 68748321616 | AV8: 86824377307 | AW8: 85475594862 | AX8: 99208228636 | AY8: 69795611979 | AZ8: 61217801757 | BA8: 147970813832 | BB8: 132769623597 | BC8: 112138441893 | BD8: 70998442117 | BE8: -22758768790 | BF8: 96299447936 | BG8: 154570631505 | BH8: 129509315823 | BI8: 109641808151 | BJ8: 129906078108 | BK8: 105463649620 | BL8: 128673842020 | BM8: 155101842643 | BN8: 83113314505 | BO8: 99966937216 | BP8: 80940600844 | BQ8: 70308328665 | BR8: 115080112871 | BS8: 90411470461 | BT8: 165844739865 | BU8: 141086003219
A9: 6 | B9: 5.Lợi nhuận gộp về bán hàng | C9: 5 | D9: =SUM(Data_PL73[[#This Row],[T1.2021]:[T12.2021]]) -> 5205790049 | E9: =SUM(Data_PL73[[#This Row],[T1.2022]:[T12.2022]]) -> 30030839174 | F9: =SUM(Data_PL73[[#This Row],[T1.2023]:[T12.2023]]) -> 166924673008 | G9: =SUM(Data_PL73[[#This Row],[T01.2024]:[T12.2024]]) -> 193185741079 | H9: =SUM(Data_PL73[[#This Row],[T01.2025]:[T12.2025]]) -> 194030027000 | I9: =SUM(Data_PL73[[#This Row],[T01.2026]:[T12.2026]]) -> 42606193225 | J9: 478551341 | K9: 278440448 | L9: 1994461207 | M9: 1490275437 | N9: 289871307 | O9: 60513842 | P9: 369410353 | Q9: -2279645740 | R9: -258126016 | S9: 929194209 | T9: 841047339 | U9: 1011796322 | V9: 654483406 | W9: -801640213 | X9: 2801259871 | Y9: 5516258306 | Z9: 2770134209 | AA9: 3589280463 | AB9: 3872454887 | AC9: 5829425406 | AD9: 4528308933 | AE9: 3200752781 | AF9: 3734765246 | AG9: -5664644121 | AH9: 4193087756 | AI9: 1123940062 | AJ9: -2038690208 | AK9: 344851916 | AL9: 7386336358 | AM9: 42999566416 | AN9: 8729091690 | AO9: 16060412307 | AP9: 27187195810 | AQ9: 22731503926 | AR9: 13789536546 | AS9: 24417840429 | AT9: 10119851560 | AU9: 191425380 | AV9: 5285130826 | AW9: 12013498032 | AX9: 3156769708 | AY9: -1702441870 | AZ9: -4766532065 | BA9: 6057054340 | BB9: 24060273128 | BC9: 4674156853 | BD9: 5127697717 | BE9: 128968857470 | BF9: 18163062466 | BG9: 33428829554 | BH9: 20744016857 | BI9: 15787841704 | BJ9: 22161064744 | BK9: 13671023177 | BL9: 9317564878 | BM9: 13340810740 | BN9: 1597120562 | BO9: 8961619444 | BP9: 7407279958 | BQ9: 29449792916 | BR9: 11018924052 | BS9: 6155334899 | BT9: 7461082664 | BU9: 17970851610
A10: 7 | B10: 6.Lãi/lỗ của hoạt động bán, thanh lý bất động sản đầu tư | C10: 5 | D10: =SUM(Data_PL73[[#This Row],[T1.2021]:[T12.2021]]) -> 0 | E10: =SUM(Data_PL73[[#This Row],[T1.2022]:[T12.2022]]) -> 0 | F10: =SUM(Data_PL73[[#This Row],[T1.2023]:[T12.2023]]) -> 0 | G10: =SUM(Data_PL73[[#This Row],[T01.2024]:[T12.2024]]) -> 0 | H10: =SUM(Data_PL73[[#This Row],[T01.2025]:[T12.2025]]) -> 0 | I10: =SUM(Data_PL73[[#This Row],[T01.2026]:[T12.2026]]) -> 0
A11: 8 | B11: 7.Doanh thu hoạt động tài chính | C11: 5 | D11: =SUM(Data_PL73[[#This Row],[T1.2021]:[T12.2021]]) -> 18328733000 | E11: =SUM(Data_PL73[[#This Row],[T1.2022]:[T12.2022]]) -> 17240601582 | F11: =SUM(Data_PL73[[#This Row],[T1.2023]:[T12.2023]]) -> 9282695737 | G11: =SUM(Data_PL73[[#This Row],[T01.2024]:[T12.2024]]) -> 15099094600 | H11: =SUM(Data_PL73[[#This Row],[T01.2025]:[T12.2025]]) -> 16906508752 | I11: =SUM(Data_PL73[[#This Row],[T01.2026]:[T12.2026]]) -> 3968224388 | J11: 1228117 | K11: 1370668 | L11: 503786 | M11: 991223 | N11: 924399 | O11: 2721429 | P11: 5630167167 | Q11: 4552274821 | R11: 4006107516 | S11: 1404451824 | T11: 1487413089 | U11: 1240578961 | V11: 1479346434 | W11: 1527456177 | X11: 1512346597 | Y11: 1655612808 | Z11: 2665641339 | AA11: 1264179580 | AB11: 1129143854 | AC11: 1236134244 | AD11: 1420307305 | AE11: 1826774837 | AF11: 1006924842 | AG11: 516733565 | AH11: 23897328 | AI11: 190776336 | AJ11: 16660712 | AK11: 967330723 | AL11: 867791673 | AM11: 866039044 | AN11: 810000497 | AO11: 1331407010 | AP11: 1045754825 | AQ11: 1146315118 | AR11: 946685267 | AS11: 1070037204 | AT11: 702840610 | AU11: 1100851130 | AV11: 994712341 | AW11: 1735368123 | AX11: 1021938222 | AY11: 578784271 | AZ11: 343643819 | BA11: 1242477440 | BB11: 1549112434 | BC11: 2779237425 | BD11: 865910053 | BE11: 2184218732 | BF11: 773999253 | BG11: 1788435256 | BH11: 931124505 | BI11: 1307926421 | BJ11: 2429341904 | BK11: 1641453607 | BL11: 1393514763 | BM11: 1498736488 | BN11: 1228780215 | BO11: 2716737103 | BP11: 515476780 | BQ11: 680982457 | BR11: 1053165322 | BS11: 307705069 | BT11: 839416558 | BU11: 1767937439
A12: 9 | B12: 8.Chi phí tài chính | C12: 5 | D12: =SUM(Data_PL73[[#This Row],[T1.2021]:[T12.2021]]) -> 3984725509 | E12: =SUM(Data_PL73[[#This Row],[T1.2022]:[T12.2022]]) -> 8892172663 | F12: =SUM(Data_PL73[[#This Row],[T1.2023]:[T12.2023]]) -> 3023468987 | G12: =SUM(Data_PL73[[#This Row],[T01.2024]:[T12.2024]]) -> 13113711111 | H12: =SUM(Data_PL73[[#This Row],[T01.2025]:[T12.2025]]) -> 18541073627 | I12: =SUM(Data_PL73[[#This Row],[T01.2026]:[T12.2026]]) -> 6611590325 | J12: 167606071 | K12: 221668883 | L12: 208008837 | M12: 262181583 | N12: 294284803 | O12: 376440316 | P12: 341383390 | Q12: 424333601 | R12: 404885911 | S12: 376140889 | T12: 457278692 | U12: 450512533 | V12: 566186825 | W12: 636770194 | X12: 622676693 | Y12: 508923847 | Z12: 611802389 | AA12: 151684906 | AB12: 632905650 | AC12: 700652271 | AD12: 1025151505 | AE12: 1107933886 | AF12: 1595489167 | AG12: 731995330 | AH12: 74107271 | AI12: 30659803 | AJ12: 220600896 | AK12: 69167924 | AL12: 49408830 | AM12: 124156445 | AN12: 311284353 | AO12: 709793834 | AP12: 328510530 | AQ12: 475535318 | AR12: 86442609 | AS12: 543801174 | AT12: 801399604 | AU12: 695500231 | AV12: 663502461 | AW12: 1555671370 | AX12: 936492932 | AY12: 1103852896 | AZ12: 1608708972 | BA12: 1489581015 | BB12: 1372261307 | BC12: 636041020 | BD12: 1257673070 | BE12: 993026233 | BF12: 1529745602 | BG12: 1349010483 | BH12: 902730488 | BI12: 1450570894 | BJ12: 858169737 | BK12: 1483876982 | BL12: 1315247967 | BM12: 1366041150 | BN12: 1603769193 | BO12: 2900732378 | BP12: 1301741764 | BQ12: 2479436989 | BR12: 1532817392 | BS12: 1569283837 | BT12: 1510605035 | BU12: 1998884061
A13: 10 | B13: Trong đó: Chi phí lãi vay | C13: 5 | D13: =SUM(Data_PL73[[#This Row],[T1.2021]:[T12.2021]]) -> 3929610603 | E13: =SUM(Data_PL73[[#This Row],[T1.2022]:[T12.2022]]) -> 7725836076 | F13: =SUM(Data_PL73[[#This Row],[T1.2023]:[T12.2023]]) -> 1165406526 | G13: =SUM(Data_PL73[[#This Row],[T01.2024]:[T12.2024]]) -> 10328501137 | H13: =SUM(Data_PL73[[#This Row],[T01.2025]:[T12.2025]]) -> 14263439054 | I13: =SUM(Data_PL73[[#This Row],[T01.2026]:[T12.2026]]) -> 4418197522 | J13: 167603935 | K13: 221659846 | L13: 208008837 | M13: 262170575 | N13: 294134531 | O13: 375347816 | P13: 340813568 | Q13: 399256526 | R13: 400979485 | S13: 368636370 | T13: 424483338 | U13: 466515776 | V13: 517655739 | W13: 651086182 | X13: 617884939 | Y13: 507919165 | Z13: 603465663 | AA13: 147007916 | AB13: 631302971 | AC13: 699695123 | AD13: 854484433 | AE13: 862022364 | AF13: 1093552795 | AG13: 539758786 | AH13: 44321388 | AI13: 0 | AJ13: 48722388 | AK13: 76187496 | AL13: 68801482 | AM13: 28249626 | AN13: 91396439 | AO13: 93845376 | AP13: 109400024 | AQ13: 129996535 | AR13: 157601782 | AS13: 316883990 | AT13: 460461775 | AU13: 563909516 | AV13: 587315920 | AW13: 905708142 | AX13: 974310029 | AY13: 1115056080 | AZ13: 1160823006 | BA13: 939585045 | BB13: 859444105 | BC13: 840165515 | BD13: 889159081 | BE13: 1032562923 | BF13: 1114824276 | BG13: 928379281 | BH13: 673966789 | BI13: 888393452 | BJ13: 1186588729 | BK13: 1448899822 | BL13: 1242023326 | BM13: 1303560910 | BN13: 1595764355 | BO13: 1368802426 | BP13: 1256132292 | BQ13: 1256103396 | BR13: 1240115065 | BS13: 1156279418 | BT13: 959718564 | BU13: 1062084475
A14: 11 | B14: 9.Chi phí bán hàng | C14: 5 | D14: =SUM(Data_PL73[[#This Row],[T1.2021]:[T12.2021]]) -> 3009092451 | E14: =SUM(Data_PL73[[#This Row],[T1.2022]:[T12.2022]]) -> 14690021152 | F14: =SUM(Data_PL73[[#This Row],[T1.2023]:[T12.2023]]) -> 19132571517 | G14: =SUM(Data_PL73[[#This Row],[T01.2024]:[T12.2024]]) -> 50836279646 | H14: =SUM(Data_PL73[[#This Row],[T01.2025]:[T12.2025]]) -> 55101745592 | I14: =SUM(Data_PL73[[#This Row],[T01.2026]:[T12.2026]]) -> 19001448254 | J14: 0 | K14: 0 | L14: 0 | M14: 0 | N14: 0 | O14: 0 | P14: 0 | Q14: 251616145 | R14: 680077987 | S14: 546329598 | T14: 967543289 | U14: 563525432 | V14: 496681104 | W14: 38696800 | X14: 1520204587 | Y14: 3287497220 | Z14: 563902784 | AA14: 802923682 | AB14: 1108487180 | AC14: 819028904 | AD14: 1282383810 | AE14: 1073636694 | AF14: 1462938929 | AG14: 2233639458 | AH14: 645459129 | AI14: 991254056 | AJ14: 1883160244 | AK14: 1145404547 | AL14: 1970368365 | AM14: 1459341885 | AN14: 1450399092 | AO14: 2363556660 | AP14: 1466584216 | AQ14: 2298997918 | AR14: 1849124450 | AS14: 1608920955 | AT14: 2846219487 | AU14: 1219456854 | AV14: 3715738043 | AW14: 4585159549 | AX14: 1693810954 | AY14: 2407466874 | AZ14: 2300964337 | BA14: 8205607205 | BB14: 7036529523 | BC14: 4608951194 | BD14: 1949627546 | BE14: 10266748080 | BF14: 4006424849 | BG14: 6313682258 | BH14: 5091544776 | BI14: 4077126734 | BJ14: 4686536575 | BK14: 4796729528 | BL14: 3449972349 | BM14: 4949095751 | BN14: 2811598286 | BO14: 6688603934 | BP14: 3413749635 | BQ14: 4816680917 | BR14: 3731798004 | BS14: 3202645336 | BT14: 6245695788 | BU14: 5821309126
A15: 12 | B15: 10.Chi phí quản lý doanh nghiệp | C15: 5 | D15: =SUM(Data_PL73[[#This Row],[T1.2021]:[T12.2021]]) -> 11203395485 | E15: =SUM(Data_PL73[[#This Row],[T1.2022]:[T12.2022]]) -> 29733399077 | F15: =SUM(Data_PL73[[#This Row],[T1.2023]:[T12.2023]]) -> 40274613810 | G15: =SUM(Data_PL73[[#This Row],[T01.2024]:[T12.2024]]) -> 70102214341 | H15: =SUM(Data_PL73[[#This Row],[T01.2025]:[T12.2025]]) -> 98715170412 | I15: =SUM(Data_PL73[[#This Row],[T01.2026]:[T12.2026]]) -> 31832287701 | J15: 457415751 | K15: 619384345 | L15: 707076077 | M15: 816715935 | N15: 827613489 | O15: 624184259 | P15: 2510720411 | Q15: 569609208 | R15: 536039299 | S15: 941857345 | T15: 3424596971 | U15: -831817605 | V15: 1435430845 | W15: 1479188151 | X15: 1624743284 | Y15: 1725353483 | Z15: 1803134313 | AA15: 1872200320 | AB15: 1882239518 | AC15: 2444716491 | AD15: 2755381317 | AE15: 3239626198 | AF15: 3143544394 | AG15: 6327840763 | AH15: 2772788125 | AI15: 2947588122 | AJ15: 3098829707 | AK15: 3036290770 | AL15: 3448026712 | AM15: 3261800788 | AN15: 3348437381 | AO15: 1910475796 | AP15: 3536419913 | AQ15: 3592592574 | AR15: 3600549435 | AS15: 5720814487 | AT15: 5241377343 | AU15: 4647980221 | AV15: 4838115306 | AW15: 5132788494 | AX15: 5665606587 | AY15: 5470797521 | AZ15: 5239042307 | BA15: 6065017937 | BB15: 7524726581 | BC15: 7016385931 | BD15: 7426888275 | BE15: 5833487838 | BF15: 7638868570 | BG15: 7013534740 | BH15: 7332584934 | BI15: 7155903324 | BJ15: 7948694673 | BK15: 7721648228 | BL15: 7616453256 | BM15: 7931593154 | BN15: 9422194647 | BO15: 3775611792 | BP15: 9875644458 | BQ15: 15282438636 | BR15: 8394130638 | BS15: 7959394332 | BT15: 7329810589 | BU15: 8148952142
A16: 13 | B16: 11.Lợi nhuận thuần từ hoạt động kinh doanh | C16: 5 | D16: =SUM(Data_PL73[[#This Row],[T1.2021]:[T12.2021]]) -> 5337309604 | E16: =SUM(Data_PL73[[#This Row],[T1.2022]:[T12.2022]]) -> -6044152136 | F16: =SUM(Data_PL73[[#This Row],[T1.2023]:[T12.2023]]) -> 113776714431 | G16: =SUM(Data_PL73[[#This Row],[T01.2024]:[T12.2024]]) -> 74232630581 | H16: =SUM(Data_PL73[[#This Row],[T01.2025]:[T12.2025]]) -> 38578546121 | I16: =SUM(Data_PL73[[#This Row],[T01.2026]:[T12.2026]]) -> -10870908667 | J16: -145242364 | K16: -561242112 | L16: 1079880079 | M16: 412369142 | N16: -831102586 | O16: -937389304 | P16: 3147473719 | Q16: 1027070127 | R16: 2126978303 | S16: 469318201 | T16: -2520958524 | U16: 2070154923 | V16: -364468934 | W16: -1428839181 | X16: 545981904 | Y16: 1650096564 | Z16: 2456936062 | AA16: 2026651135 | AB16: 1377966393 | AC16: 3101161984 | AD16: 885699606 | AE16: -393669160 | AF16: -1460282402 | AG16: -14441386107 | AH16: 724630559 | AI16: -2654785583 | AJ16: -7224620343 | AK16: -2938680602 | AL16: 2786324124 | AM16: 39020306342 | AN16: 4428971361 | AO16: 12407993027 | AP16: 22901435976 | AQ16: 17510693234 | AR16: 9200105319 | AS16: 17614341017 | AT16: 1933695736 | AU16: -5270660796 | AV16: -2937512643 | AW16: 2475246742 | AX16: -4117202543 | AY16: -10105774890 | AZ16: -13571603862 | BA16: -8460674377 | BB16: 9675868151 | BC16: -4807983867 | BD16: -4640581121 | BE16: 114059814051 | BF16: 5762022698 | BG16: 20541037329 | BH16: 8348281164 | BI16: 4412167173 | BJ16: 11097005663 | BK16: 1310222046 | BL16: -1670593931 | BM16: 592817173 | BN16: -11011661349 | BO16: -1686591557 | BP16: -6668379119 | BQ16: 7552218831 | BR16: -1586656660 | BS16: -6268283537 | BT16: -6785612190 | BU16: 3769643720
A17: 14 | B17: 12.Thu nhập khác | C17: 5 | D17: =SUM(Data_PL73[[#This Row],[T1.2021]:[T12.2021]]) -> 18771710496 | E17: =SUM(Data_PL73[[#This Row],[T1.2022]:[T12.2022]]) -> 92779904880 | F17: =SUM(Data_PL73[[#This Row],[T1.2023]:[T12.2023]]) -> 17391162 | G17: =SUM(Data_PL73[[#This Row],[T01.2024]:[T12.2024]]) -> 1503561903 | H17: =SUM(Data_PL73[[#This Row],[T01.2025]:[T12.2025]]) -> 454238633 | I17: =SUM(Data_PL73[[#This Row],[T01.2026]:[T12.2026]]) -> 11703115 | J17: 0 | K17: 299375994 | L17: 787003464 | M17: 853324557 | N17: 610174630 | O17: 1291891103 | P17: 8989972067 | Q17: 40395118 | R17: 2077248 | S17: 399581022 | T17: 2510200174 | U17: 2987715119 | V17: 5351841304 | W17: 240544660 | X17: 164167319 | Y17: 0 | Z17: 397562937 | AA17: 263298162 | AB17: 116035636 | AC17: 406946130 | AD17: 1142849269 | AE17: 973159654 | AF17: 4531212183 | AG17: 79192287626 | AH17: 332026 | AI17: 0 | AJ17: 2 | AK17: 1 | AL17: 0 | AM17: 425 | AN17: 0 | AO17: 0 | AP17: 0 | AQ17: 0 | AR17: 8116 | AS17: 17050592 | AT17: 1945 | AU17: 12000 | AV17: 0 | AW17: 0 | AX17: 203 | AY17: 58510228 | AZ17: 52918371 | BA17: 177726993 | BB17: 999 | BC17: 196700 | BD17: 1398763491 | BE17: -184569027 | BF17: 500207 | BG17: 2492480 | BH17: 2600082 | BI17: 33918440 | BJ17: 115000000 | BK17: 2020926 | BL17: 9788652 | BM17: 244500606 | BN17: 742 | BO17: 819591 | BP17: 110446 | BQ17: 42486461 | BR17: 4505 | BS17: 70001 | BT17: 1144804 | BU17: 10483805
A18: 15 | B18: 13.Chi phí khác | C18: 5 | D18: =SUM(Data_PL73[[#This Row],[T1.2021]:[T12.2021]]) -> 3720756403 | E18: =SUM(Data_PL73[[#This Row],[T1.2022]:[T12.2022]]) -> 5507730098 | F18: =SUM(Data_PL73[[#This Row],[T1.2023]:[T12.2023]]) -> 198294222 | G18: =SUM(Data_PL73[[#This Row],[T01.2024]:[T12.2024]]) -> 8884638060 | H18: =SUM(Data_PL73[[#This Row],[T01.2025]:[T12.2025]]) -> 7634668922 | I18: =SUM(Data_PL73[[#This Row],[T01.2026]:[T12.2026]]) -> 368182201 | J18: 77565 | K18: 0 | L18: 0 | M18: 0 | N18: 6136364 | O18: 0 | P18: 0 | Q18: 0 | R18: 0 | S18: 0 | T18: 0 | U18: 3714542474 | V18: 0 | W18: 274745 | X18: 2093722658 | Y18: 631668424 | Z18: 567391744 | AA18: 150706725 | AB18: 2322906 | AC18: 1880704 | AD18: 593797145 | AE18: 15441 | AF18: 441600828 | AG18: 1024348778 | AH18: 1 | AI18: 236 | AJ18: 0 | AK18: 7135172 | AL18: 3500000 | AM18: 99064 | AN18: 0 | AO18: -36000 | AP18: 0 | AQ18: 0 | AR18: 0 | AS18: 187595749 | AT18: 7958068 | AU18: 1 | AV18: 21796958 | AW18: 2 | AX18: 36200000 | AY18: 168183405 | AZ18: 6000002 | BA18: 601 | BB18: 2601033 | BC18: 170398064 | BD18: 202496 | BE18: 8471297430 | BF18: 1251667 | BG18: 130033300 | BH18: 0 | BI18: 17808640 | BJ18: 600 | BK18: 50477376 | BL18: 130663204 | BM18: 539898446 | BN18: 539664890 | BO18: 3515574706 | BP18: 1106262251 | BQ18: 1603033842 | BR18: 106808581 | BS18: 151000202 | BT18: 34000105 | BU18: 76373313
A19: 16 | B19: 14.Lợi nhuận khác | C19: 5 | D19: =SUM(Data_PL73[[#This Row],[T1.2021]:[T12.2021]]) -> 15050954093 | E19: =SUM(Data_PL73[[#This Row],[T1.2022]:[T12.2022]]) -> 87272174782 | F19: =SUM(Data_PL73[[#This Row],[T1.2023]:[T12.2023]]) -> -180903060 | G19: =SUM(Data_PL73[[#This Row],[T01.2024]:[T12.2024]]) -> -7381076157 | H19: =SUM(Data_PL73[[#This Row],[T01.2025]:[T12.2025]]) -> -7180430289 | I19: =SUM(Data_PL73[[#This Row],[T01.2026]:[T12.2026]]) -> -356479086 | J19: -77565 | K19: 299375994 | L19: 787003464 | M19: 853324557 | N19: 604038266 | O19: 1291891103 | P19: 8989972067 | Q19: 40395118 | R19: 2077248 | S19: 399581022 | T19: 2510200174 | U19: -726827355 | V19: 5351841304 | W19: 240269915 | X19: -1929555339 | Y19: -631668424 | Z19: -169828807 | AA19: 112591437 | AB19: 113712730 | AC19: 405065426 | AD19: 549052124 | AE19: 973144213 | AF19: 4089611355 | AG19: 78167938848 | AH19: 332025 | AI19: -236 | AJ19: 2 | AK19: -7135171 | AL19: -3500000 | AM19: -98639 | AN19: 0 | AO19: 36000 | AP19: 0 | AQ19: 0 | AR19: 8116 | AS19: -170545157 | AT19: -7956123 | AU19: 11999 | AV19: -21796958 | AW19: -2 | AX19: -36199797 | AY19: -109673177 | AZ19: 46918369 | BA19: 177726392 | BB19: -2600034 | BC19: -170201364 | BD19: 1398560995 | BE19: -8655866457 | BF19: -751460 | BG19: -127540820 | BH19: 2600082 | BI19: 16109800 | BJ19: 114999400 | BK19: -48456450 | BL19: -120874552 | BM19: -295397840 | BN19: -539664148 | BO19: -3514755115 | BP19: -1106151805 | BQ19: -1560547381 | BR19: -106804076 | BS19: -150930201 | BT19: -32855301 | BU19: -65889508
A20: 17 | B20: 15.Tổng lợi nhuận kế toán trước thuế | C20: 5 | D20: =SUM(Data_PL73[[#This Row],[T1.2021]:[T12.2021]]) -> 20388263697 | E20: =SUM(Data_PL73[[#This Row],[T1.2022]:[T12.2022]]) -> 81228022646 | F20: =SUM(Data_PL73[[#This Row],[T1.2023]:[T12.2023]]) -> 113595811371 | G20: =SUM(Data_PL73[[#This Row],[T01.2024]:[T12.2024]]) -> 66851554424 | H20: =SUM(Data_PL73[[#This Row],[T01.2025]:[T12.2025]]) -> 31398115832 | I20: =SUM(Data_PL73[[#This Row],[T01.2026]:[T12.2026]]) -> -11227387753 | J20: -145319929 | K20: -261866118 | L20: 1866883543 | M20: 1265693699 | N20: -227064320 | O20: 354501799 | P20: 12137445786 | Q20: 1067465245 | R20: 2129055551 | S20: 868899223 | T20: -10758350 | U20: 1343327568 | V20: 4987372370 | W20: -1188569266 | X20: -1383573435 | Y20: 1018428140 | Z20: 2287107255 | AA20: 2139242572 | AB20: 1491679123 | AC20: 3506227410 | AD20: 1434751730 | AE20: 579475053 | AF20: 2629328953 | AG20: 63726552741 | AH20: 724962584 | AI20: -2654785819 | AJ20: -7224620341 | AK20: -2945815773 | AL20: 2782824124 | AM20: 39020207703 | AN20: 4428971361 | AO20: 12408029027 | AP20: 22901435976 | AQ20: 17510693234 | AR20: 9200113435 | AS20: 17443795860 | AT20: 1925739613 | AU20: -5270648797 | AV20: -2959309601 | AW20: 2475246740 | AX20: -4153402340 | AY20: -10215448067 | AZ20: -13524685493 | BA20: -8282947985 | BB20: 9673268117 | BC20: -4978185231 | BD20: -3242020126 | BE20: 105403947594 | BF20: 5761271238 | BG20: 20413496509 | BH20: 8350881246 | BI20: 4428276973 | BJ20: 11212005063 | BK20: 1261765596 | BL20: -1791468483 | BM20: 297419333 | BN20: -11551325497 | BO20: -5201346672 | BP20: -7774530924 | BQ20: 5991671450 | BR20: -1693460736 | BS20: -6419213738 | BT20: -6818467491 | BU20: 3703754212
