Workbook

Sheet Thong tin
A1: CÔNG TY CP NHỰA TÁI CHẾ DUY TÂN
A2: Địa chỉ: Lô D2, Cụm CN Nhựa Đức Hòa, Xã Đức Hòa, Tỉnh Tây Ninh
A3: Mã số thuế:
A4: Deadline ngày 5 tây hàng tháng
B6: Năm tài chính hiện tại | C6: 2026
B7: Năm trước | C7: =C6-1 -> 2025
B9: Tháng báo cáo hiện tại | C9: 6
B12: NGƯỜI LẬP BIỂU
B15: KẾ TOÁN TRƯỞNG
B18: GIÁM ĐỐC TÀI CHÍNH

Sheet BIA
B29: THÁNG 06 NĂM 2026
B50: Thành phố Hồ Chí Minh, Ngày 04 tháng 07 năm 2026

Sheet Index
A1: ='Thong tin'!A1 -> CÔNG TY CP NHỰA TÁI CHẾ DUY TÂN | I1: BÁO CÁO TÀI CHÍNH
A2: ='Thong tin'!A2 -> Địa chỉ: Lô D2, Cụm CN Nhựa Đức Hòa, Xã Đức Hòa, Tỉnh Tây Ninh
A10: ="BÁO CÁO TÀI CHÍNH THÁNG "&'Thong tin'!C9&" NĂM 2026" -> BÁO CÁO TÀI CHÍNH THÁNG 6 NĂM 2026 | I10: Trang
A12: BÁO CÁO CỦA BAN GIÁM ĐỐC | I12: 2 - 3
A13: BÁO CÁO KIỂM TOÁN | I13: 4 - 4
A14: - Bảng cân đối kế toán | I14: 1 - 4
A15: - Báo cáo kết quả hoạt động kinh doanh | I15: 5
A16: - Báo cáo lưu chuyển tiền tệ | I16: 6 - 7
A17: - Bản thuyết minh báo cáo tài chính | I17: 11 - 31
A30: (Báo cáo tài chính được lập và trình bày theo Quyết định số 15/2006/QĐ-BTC ngày 20/03/2006
A31: của Bộ trưởng Bộ Tài Chính)

Sheet THTC in
A1: ='Thong tin'!$A$1 -> CÔNG TY CP NHỰA TÁI CHẾ DUY TÂN
A2: ='Thong tin'!$A$2 -> Địa chỉ: Lô D2, Cụm CN Nhựa Đức Hòa, Xã Đức Hòa, Tỉnh Tây Ninh
A4: BÁO CÁO TÌNH HÌNH TÀI CHÍNH
A5: ="Năm " & 'Thong tin'!$C$6 -> Năm 2026
C6: ='KQKD in'!G6 -> ĐVT: VNĐ
A7: TÀI SẢN | B7: ="Số cuối tháng"&" "&$D$7 -> Số cuối tháng 6 | C7: ="Số dư đầu năm " & 'Thong tin'!$C$6 -> Số dư đầu năm 2026 | D7: ='Thong tin'!C9 -> 6
A8: A . TÀI SẢN NGẮN HẠN | B8: =B10+B14+B22+B31+B40 -> 820219773119 | C8: =C10+C14+C22+C31+C40 -> 945217150933
A10: I. Tiền và các khoản tương đương tiền | B10: =SUM(B11:B12) -> 41687049619 | C10: =SUM(C11:C12) -> 36834893155
A11: 1. Tiền | B11: =OFFSET('Tinh hinh tai chinh'!$BL6,0,'THTC in'!$D$7 - 1) -> 26931785662 | C11: ='Tinh hinh tai chinh'!BK6 -> 36834893155
A12: 2. Các khoản tương đương tiền | B12: =OFFSET('Tinh hinh tai chinh'!$BL7,0,'THTC in'!$D$7 - 1) -> 14755263957 | C12: ='Tinh hinh tai chinh'!BK7 -> 0
A14: II. Các khoản đầu tư tài chính ngắn hạn | B14: =SUM(B15:B20) -> 34340000000 | C14: =SUM(C15:C20) -> 32840000000
A15: 1.Chứng khoán kinh doanh | B15: =OFFSET('Tinh hinh tai chinh'!$BL9,0,'THTC in'!$D$7 - 1) -> 0 | C15: ='Tinh hinh tai chinh'!BK9 -> 0
A16: 2.Dự phòng giảm giá chứng khoán kinh doanh (*) | B16: =OFFSET('Tinh hinh tai chinh'!$BL10,0,'THTC in'!$D$7 - 1) -> 0 | C16: ='Tinh hinh tai chinh'!BK10 -> 0
A17: 3.Đầu tư nắm giữ đến ngày đáo hạn ngắn hạn | B17: =OFFSET('Tinh hinh tai chinh'!$BL11,0,'THTC in'!$D$7 - 1) -> 34340000000 | C17: ='Tinh hinh tai chinh'!BK11 -> 32840000000
A18: 4.Dự phòng đầu tư nắm giữ đến ngày đáo hạn ngắn hạn (*) | B18: =OFFSET('Tinh hinh tai chinh'!$BL12,0,'THTC in'!$D$7 - 1) -> 0 | C18: ='Tinh hinh tai chinh'!BK12 -> 0
A19: 5.Đầu tư ngắn hạn khác | B19: =OFFSET('Tinh hinh tai chinh'!$BL13,0,'THTC in'!$D$7 - 1) -> 0 | C19: ='Tinh hinh tai chinh'!BK13 -> 0
A20: 6.Dự phòng tổn thất các khoản đầu tư ngắn hạn khác (*) | B20: =OFFSET('Tinh hinh tai chinh'!$BL14,0,'THTC in'!$D$7 - 1) -> 0 | C20: ='Tinh hinh tai chinh'!BK14 -> 0
A22: III. Các khoản phải thu ngắn hạn | B22: =SUM(B23:B29) -> 310082966155 | C22: =SUM(C23:C29) -> 293560124180
A23: 1.Phải thu ngắn hạn của khách hàng | B23: =OFFSET('Tinh hinh tai chinh'!$BL16,0,'THTC in'!$D$7 - 1) -> 169259122091 | C23: ='Tinh hinh tai chinh'!BK16 -> 154342206132
A24: 2.Trả trước cho người bán ngắn hạn | B24: =OFFSET('Tinh hinh tai chinh'!$BL17,0,'THTC in'!$D$7 - 1) -> 49662085677 | C24: ='Tinh hinh tai chinh'!BK17 -> 67613421375
A25: 3.Phải thu nội bộ ngắn hạn | B25: =OFFSET('Tinh hinh tai chinh'!$BL18,0,'THTC in'!$D$7 - 1) -> 0 | C25: ='Tinh hinh tai chinh'!BK18 -> 0
A26: 4.Phải thu theo tiến độ hợp đồng xây dựng | B26: =OFFSET('Tinh hinh tai chinh'!$BL19,0,'THTC in'!$D$7 - 1) -> 0 | C26: ='Tinh hinh tai chinh'!BK19 -> 0
A27: 5.Phải thu ngắn hạn khác | B27: =OFFSET('Tinh hinh tai chinh'!$BL20,0,'THTC in'!$D$7 - 1) -> 91770854087 | C27: ='Tinh hinh tai chinh'!BK20 -> 72213592373
A28: 6.Dự phòng phải thu ngắn hạn khó đòi (*) | B28: =OFFSET('Tinh hinh tai chinh'!$BL21,0,'THTC in'!$D$7 - 1) -> -609095700 | C28: ='Tinh hinh tai chinh'!BK21 -> -609095700
A29: 7.Tài sản thiếu chờ xử lý | B29: =OFFSET('Tinh hinh tai chinh'!$BL22,0,'THTC in'!$D$7 - 1) -> 0 | C29: ='Tinh hinh tai chinh'!BK22 -> 0
A31: IV. Hàng tồn kho | B31: =SUM(B32:B33) -> 388348343836 | C31: =SUM(C32:C33) -> 562435021579
A32: 1. Hàng tồn kho | B32: =OFFSET('Tinh hinh tai chinh'!$BL24,0,'THTC in'!$D$7 - 1) -> 388348343836 | C32: ='Tinh hinh tai chinh'!BK24 -> 562435021579
A33: 2. Dự phòng giảm giá hàng tồn kho (*) | B33: =OFFSET('Tinh hinh tai chinh'!$BL25,0,'THTC in'!$D$7 - 1) -> 0 | C33: ='Tinh hinh tai chinh'!BK25 -> 0
A35: V. Tài sản sinh học ngắn hạn | B35: =SUM(B36:B38) -> 0 | C35: =SUM(C36:C38) -> 0
A36: 1.Súc vật nuôi lấy sản phẩm một lần ngắn hạn | B36: =OFFSET('Tinh hinh tai chinh'!$BL27,0,'THTC in'!$D$7 - 1) -> 0 | C36: ='Tinh hinh tai chinh'!BK27 -> 0
A37: 2.Cây trồng theo mùa vụ hoặc lấy sản phẩm một lần ngắn hạn | B37: =OFFSET('Tinh hinh tai chinh'!$BL28,0,'THTC in'!$D$7 - 1) -> 0 | C37: ='Tinh hinh tai chinh'!BK28 -> 0
A38: 3.Dự phòng tổn thất tài sản sinh học ngắn hạn (*) | B38: =OFFSET('Tinh hinh tai chinh'!$BL29,0,'THTC in'!$D$7 - 1) -> 0 | C38: ='Tinh hinh tai chinh'!BK29 -> 0
A40: VI. Tài sản ngắn hạn khác | B40: =SUM(B41:B45) -> 45761413509 | C40: =SUM(C41:C45) -> 19547112019
A41: 1.Chi phí chờ phân bổ ngắn hạn | B41: =OFFSET('Tinh hinh tai chinh'!$BL31,0,'THTC in'!$D$7 - 1) -> 7520241462 | C41: ='Tinh hinh tai chinh'!BK31 -> 6855293515
A42: 2.Thuế GTGT được khấu trừ | B42: =OFFSET('Tinh hinh tai chinh'!$BL32,0,'THTC in'!$D$7 - 1) -> 38241172047 | C42: ='Tinh hinh tai chinh'!BK32 -> 12691818504
A43: 3.Thuế và các khoản khác phải thu Nhà nước | B43: =OFFSET('Tinh hinh tai chinh'!$BL33,0,'THTC in'!$D$7 - 1) -> 0 | C43: ='Tinh hinh tai chinh'!BK33 -> 0
A44: 4.Giao dịch mua bán lại trái phiếu Chính phủ | B44: =OFFSET('Tinh hinh tai chinh'!$BL34,0,'THTC in'!$D$7 - 1) -> 0 | C44: ='Tinh hinh tai chinh'!BK34 -> 0
A45: 5.Tài sản ngắn hạn khác | B45: =OFFSET('Tinh hinh tai chinh'!$BL35,0,'THTC in'!$D$7 - 1) -> 0 | C45: ='Tinh hinh tai chinh'!BK35 -> 0
A47: B. TÀI SẢN DÀI HẠN | B47: =B48+B58+B79+B87+B95+B83 -> 495399222088 | C47: =C48+C58+C79+C87+C95+C83 -> 320800563599
A48: I.Các khoản phải thu dài hạn | B48: =SUM(B49:B54) -> 5315314210 | C48: =SUM(C49:C54) -> 5600000000
...

Sheet KQKD in
A1: ='Thong tin'!$A$1 -> CÔNG TY CP NHỰA TÁI CHẾ DUY TÂN
A2: ='Thong tin'!$A$2 -> Địa chỉ: Lô D2, Cụm CN Nhựa Đức Hòa, Xã Đức Hòa, Tỉnh Tây Ninh
A4: BÁO CÁO KẾT QUẢ HOẠT ĐỘNG KINH DOANH
A5: ="Năm " & 'Thong tin'!$C$6 -> Năm 2026
G6: ĐVT: VNĐ
A8: Chỉ tiêu | D8: ="Tháng "&'Thong tin'!$C$9 -> Tháng 6 | F8: ="Lũy kế"&" "&'Thong tin'!$C$9 &" "&"tháng" -> Lũy kế 6 tháng
D9: ="Năm " & 'Thong tin'!$C$6 -> Năm 2026 | E9: ="Năm " & 'Thong tin'!$C$7 -> Năm 2025 | F9: ="Năm " & 'Thong tin'!$C$6 -> Năm 2026 | G9: ="Năm " & 'Thong tin'!$C$7 -> Năm 2025
A10: 1. | B10: Doanh thu bán hàng và cung cấp dịch vụ | D10: =OFFSET('Ket qua kinh doanh'!$BL5,0,'Thong tin'!$C$9 - 1) -> 123233804019 | E10: =OFFSET('Ket qua kinh doanh'!$AZ5,0,'Thong tin'!$C$9 - 1) -> 119843310993 | F10: =SUM(OFFSET('Ket qua kinh doanh'!$BL5,0,0,1,'Thong tin'!$C$9)) -> 841013479508 | G10: =SUM(OFFSET('Ket qua kinh doanh'!$AZ5,0,0,1,'Thong tin'!$C$9)) -> 853436276724
A11: 2. | B11: Các khoản giảm trừ doanh thu | D11: =OFFSET('Ket qua kinh doanh'!$BL6,0,'Thong tin'!$C$9 - 1) -> 249465491 | E11: =OFFSET('Ket qua kinh doanh'!$AZ6,0,'Thong tin'!$C$9 - 1) -> 708638196 | F11: =SUM(OFFSET('Ket qua kinh doanh'!$BL6,0,0,1,'Thong tin'!$C$9)) -> 3235312302 | G11: =SUM(OFFSET('Ket qua kinh doanh'!$AZ6,0,0,1,'Thong tin'!$C$9)) -> 4089507079
A12: 3. | B12: Doanh thu thuần về bán hàng và cung cấp dịch vụ | D12: =OFFSET('Ket qua kinh doanh'!$BL7,0,'Thong tin'!$C$9 - 1) -> 122984338528 | E12: =OFFSET('Ket qua kinh doanh'!$AZ7,0,'Thong tin'!$C$9 - 1) -> 119134672797 | F12: =SUM(OFFSET('Ket qua kinh doanh'!$BL7,0,0,1,'Thong tin'!$C$9)) -> 837778167206 | G12: =SUM(OFFSET('Ket qua kinh doanh'!$AZ7,0,0,1,'Thong tin'!$C$9)) -> 849346769645
A13: 4. | B13: Giá vốn hàng bán | D13: =OFFSET('Ket qua kinh doanh'!$BL8,0,'Thong tin'!$C$9 - 1) -> 103435583559 | E13: =OFFSET('Ket qua kinh doanh'!$AZ8,0,'Thong tin'!$C$9 - 1) -> 105463649620 | F13: =SUM(OFFSET('Ket qua kinh doanh'!$BL8,0,0,1,'Thong tin'!$C$9)) -> 753437942033 | G13: =SUM(OFFSET('Ket qua kinh doanh'!$AZ8,0,0,1,'Thong tin'!$C$9)) -> 725390931143
A14: 5. | B14: Lợi nhuận gộp về bán hàng và cung cấp dịch vụ | D14: =OFFSET('Ket qua kinh doanh'!$BL9,0,'Thong tin'!$C$9 - 1) -> 19548754969 | E14: =OFFSET('Ket qua kinh doanh'!$AZ9,0,'Thong tin'!$C$9 - 1) -> 13671023177 | F14: =SUM(OFFSET('Ket qua kinh doanh'!$BL9,0,0,1,'Thong tin'!$C$9)) -> 84340225173 | G14: =SUM(OFFSET('Ket qua kinh doanh'!$AZ9,0,0,1,'Thong tin'!$C$9)) -> 123955838502
A15: 6. | B15: Lãi/lỗ của hoạt động bán, thanh lý bất động sản đầu tư | D15: =OFFSET('Ket qua kinh doanh'!$BL10,0,'Thong tin'!$C$9 - 1) -> 0 | E15: =OFFSET('Ket qua kinh doanh'!$AZ10,0,'Thong tin'!$C$9 - 1) -> 0 | F15: =SUM(OFFSET('Ket qua kinh doanh'!$BL10,0,0,1,'Thong tin'!$C$9)) -> 0 | G15: =SUM(OFFSET('Ket qua kinh doanh'!$AZ10,0,0,1,'Thong tin'!$C$9)) -> 0
A16: 7. | B16: Doanh thu hoạt động tài chính | D16: =OFFSET('Ket qua kinh doanh'!$BL11,0,'Thong tin'!$C$9 - 1) -> 1466681763 | E16: =OFFSET('Ket qua kinh doanh'!$AZ11,0,'Thong tin'!$C$9 - 1) -> 1641453607 | F16: =SUM(OFFSET('Ket qua kinh doanh'!$BL11,0,0,1,'Thong tin'!$C$9)) -> 6696557363 | G16: =SUM(OFFSET('Ket qua kinh doanh'!$AZ11,0,0,1,'Thong tin'!$C$9)) -> 8872280946
A17: 8. | B17: Chi phí tài chính | D17: =OFFSET('Ket qua kinh doanh'!$BL12,0,'Thong tin'!$C$9 - 1) -> 1214330425 | E17: =OFFSET('Ket qua kinh doanh'!$AZ12,0,'Thong tin'!$C$9 - 1) -> 1483876982 | F17: =SUM(OFFSET('Ket qua kinh doanh'!$BL12,0,0,1,'Thong tin'!$C$9)) -> 9034656808 | G17: =SUM(OFFSET('Ket qua kinh doanh'!$AZ12,0,0,1,'Thong tin'!$C$9)) -> 7574104186
B18: Trong đó: chi phí lãi vay | D18: =OFFSET('Ket qua kinh doanh'!$BL13,0,'Thong tin'!$C$9 - 1) -> 856841656 | E18: =OFFSET('Ket qua kinh doanh'!$AZ13,0,'Thong tin'!$C$9 - 1) -> 1448899822 | F18: =SUM(OFFSET('Ket qua kinh doanh'!$BL13,0,0,1,'Thong tin'!$C$9)) -> 6113875969 | G18: =SUM(OFFSET('Ket qua kinh doanh'!$AZ13,0,0,1,'Thong tin'!$C$9)) -> 6241052349
A19: 9. | B19: Chi phí bán hàng | D19: =OFFSET('Ket qua kinh doanh'!$BL14,0,'Thong tin'!$C$9 - 1) -> 3803640296 | E19: =OFFSET('Ket qua kinh doanh'!$AZ14,0,'Thong tin'!$C$9 - 1) -> 4796729528 | F19: =SUM(OFFSET('Ket qua kinh doanh'!$BL14,0,0,1,'Thong tin'!$C$9)) -> 28720893640 | G19: =SUM(OFFSET('Ket qua kinh doanh'!$AZ14,0,0,1,'Thong tin'!$C$9)) -> 28972044720
A20: 10. | B20: Chi phí quản lý doanh nghiệp | D20: =OFFSET('Ket qua kinh doanh'!$BL15,0,'Thong tin'!$C$9 - 1) -> 8218560670 | E20: =OFFSET('Ket qua kinh doanh'!$AZ15,0,'Thong tin'!$C$9 - 1) -> 7721648228 | F20: =SUM(OFFSET('Ket qua kinh doanh'!$BL15,0,0,1,'Thong tin'!$C$9)) -> 48061650846 | G20: =SUM(OFFSET('Ket qua kinh doanh'!$AZ15,0,0,1,'Thong tin'!$C$9)) -> 44811234469
A21: 11. | B21: Lợi nhuận thuần từ hoạt động kinh doanh | D21: =OFFSET('Ket qua kinh doanh'!$BL16,0,'Thong tin'!$C$9 - 1) -> 7778905341 | E21: =OFFSET('Ket qua kinh doanh'!$AZ16,0,'Thong tin'!$C$9 - 1) -> 1310222046 | F21: =SUM(OFFSET('Ket qua kinh doanh'!$BL16,0,0,1,'Thong tin'!$C$9)) -> 5219581242 | G21: =SUM(OFFSET('Ket qua kinh doanh'!$AZ16,0,0,1,'Thong tin'!$C$9)) -> 51470736073
A22: 12. | B22: Thu nhập khác | D22: =OFFSET('Ket qua kinh doanh'!$BL17,0,'Thong tin'!$C$9 - 1) -> 371201 | E22: =OFFSET('Ket qua kinh doanh'!$AZ17,0,'Thong tin'!$C$9 - 1) -> 2020926 | F22: =SUM(OFFSET('Ket qua kinh doanh'!$BL17,0,0,1,'Thong tin'!$C$9)) -> 12074316 | G22: =SUM(OFFSET('Ket qua kinh doanh'!$AZ17,0,0,1,'Thong tin'!$C$9)) -> 156532135
A23: 13. | B23: Chi phí khác | D23: =OFFSET('Ket qua kinh doanh'!$BL18,0,'Thong tin'!$C$9 - 1) -> 100013926 | E23: =OFFSET('Ket qua kinh doanh'!$AZ18,0,'Thong tin'!$C$9 - 1) -> 50477376 | F23: =SUM(OFFSET('Ket qua kinh doanh'!$BL18,0,0,1,'Thong tin'!$C$9)) -> 598196777 | G23: =SUM(OFFSET('Ket qua kinh doanh'!$AZ18,0,0,1,'Thong tin'!$C$9)) -> 199571583
A24: 14. | B24: Lợi nhuận khác | D24: =OFFSET('Ket qua kinh doanh'!$BL19,0,'Thong tin'!$C$9 - 1) -> -99642725 | E24: =OFFSET('Ket qua kinh doanh'!$AZ19,0,'Thong tin'!$C$9 - 1) -> -48456450 | F24: =SUM(OFFSET('Ket qua kinh doanh'!$BL19,0,0,1,'Thong tin'!$C$9)) -> -586122461 | G24: =SUM(OFFSET('Ket qua kinh doanh'!$AZ19,0,0,1,'Thong tin'!$C$9)) -> -43039448
A25: 15. | B25: Tổng lợi nhuận kế toán trước thuế | D25: =OFFSET('Ket qua kinh doanh'!$BL20,0,'Thong tin'!$C$9 - 1) -> 7679262616 | E25: =OFFSET('Ket qua kinh doanh'!$AZ20,0,'Thong tin'!$C$9 - 1) -> 1261765596 | F25: =SUM(OFFSET('Ket qua kinh doanh'!$BL20,0,0,1,'Thong tin'!$C$9)) -> 4633458781 | G25: =SUM(OFFSET('Ket qua kinh doanh'!$AZ20,0,0,1,'Thong tin'!$C$9)) -> 51427696625
A26: 16. | B26: Chi phí thuế TNDN hiện hành (*) | D26: =OFFSET('Ket qua kinh doanh'!$BL21,0,'Thong tin'!$C$9 - 1) -> 926691756 | E26: =OFFSET('Ket qua kinh doanh'!$AZ21,0,'Thong tin'!$C$9 - 1) -> 189264839 | F26: =SUM(OFFSET('Ket qua kinh doanh'!$BL21,0,0,1,'Thong tin'!$C$9)) -> 727789390 | G26: =SUM(OFFSET('Ket qua kinh doanh'!$AZ21,0,0,1,'Thong tin'!$C$9)) -> 7685924739
A27: 17. | B27: Chi phí thuế TNDN hoãn lại | D27: =OFFSET('Ket qua kinh doanh'!BL22,0,'Thong tin'!$C$9 - 1) -> 0 | E27: =OFFSET('Ket qua kinh doanh'!$AZ22,0,'Thong tin'!$C$9 - 1) -> 0 | F27: =SUM(OFFSET('Ket qua kinh doanh'!BL22,0,0,1,'Thong tin'!$C$9)) -> 0 | G27: =SUM(OFFSET('Ket qua kinh doanh'!$AZ22,0,0,1,'Thong tin'!$C$9)) -> -8043000
A28: 18. | B28: Lợi nhuận sau thuế | D28: =OFFSET('Ket qua kinh doanh'!$BL23,0,'Thong tin'!$C$9 - 1) -> 6752570860 | E28: =OFFSET('Ket qua kinh doanh'!$AZ23,0,'Thong tin'!$C$9 - 1) -> 1072500757 | F28: =SUM(OFFSET('Ket qua kinh doanh'!$BL23,0,0,1,'Thong tin'!$C$9)) -> 3905669391 | G28: =SUM(OFFSET('Ket qua kinh doanh'!$AZ23,0,0,1,'Thong tin'!$C$9)) -> 43749814886
A29: 19. | B29: Lãi cơ bản trên cổ phiếu | F29: =#REF!+#REF!+#REF!+#REF!+#REF!+#REF!+#REF!+#REF!+#REF!+#REF!+#REF!+D29 -> #REF! | G29: =#REF!+#REF!+#REF!+#REF!+#REF!+#REF!+#REF!+#REF!+#REF!+#REF!+#REF!+E29 -> #REF!
D31: 0 | E31: 0 | F31: 0 | G31: 0
F32: Lập, ngày 04 tháng 07 năm 2026
B34: KẾ TOÁN TRƯỞNG | F34: ='Thong tin'!B18 -> GIÁM ĐỐC TÀI CHÍNH
B41: ='Thong tin'!B13 -> 0 | F41: Nguyễn Bảo Quốc

Sheet LCTT_GT in
A1: ='Thong tin'!$A$1 -> CÔNG TY CP NHỰA TÁI CHẾ DUY TÂN
A2: ='Thong tin'!$A$2 -> Địa chỉ: Lô D2, Cụm CN Nhựa Đức Hòa, Xã Đức Hòa, Tỉnh Tây Ninh
A4: BÁO CÁO LƯU CHUYỂN TIỀN TỆ
A5: (Theo phương pháp gián tiếp)
A6: ="Năm " & 'Thong tin'!$C$6 -> Năm 2026
E7: ='KQKD in'!G6 -> ĐVT: VNĐ
A8: Chỉ tiêu | B8: ="Tháng " & 'Thong tin'!$C$9 -> Tháng 6 | D8: ="Lũy kế"&" "& 'Thong tin'!$C$9 &" "&"tháng" -> Lũy kế 6 tháng
B9: ="Năm " & 'Thong tin'!$C$6 -> Năm 2026 | C9: ="Năm " & 'Thong tin'!$C$7 -> Năm 2025 | D9: ="Năm " & 'Thong tin'!$C$6 -> Năm 2026 | E9: ="Năm " & 'Thong tin'!$C$7 -> Năm 2025
A10: I. Lưu chuyển tiền từ hoạt động kinh doanh
A11: 1. Lợi nhuận trước thuế | B11: =OFFSET('Luu chuyen tien te'!$BL5,0,'Thong tin'!$C$9 - 1) -> 7679262616 | C11: =OFFSET('Luu chuyen tien te'!$AZ5,0,'Thong tin'!$C$9 - 1) -> 1261765596 | D11: =SUM(OFFSET('Luu chuyen tien te'!$BL5,0,0,1,'Thong tin'!$C$9)) -> 4633458781 | E11: =SUM(OFFSET('Luu chuyen tien te'!$AZ5,0,0,1,'Thong tin'!$C$9)) -> 51427696625
A12: 2. Điều chỉnh cho các khoản
A13: - Khấu hao tài sản cố định và BĐSĐT | B13: =OFFSET('Luu chuyen tien te'!$BL7,0,'Thong tin'!$C$9 - 1) -> 2329762280 | C13: =OFFSET('Luu chuyen tien te'!$AZ7,0,'Thong tin'!$C$9 - 1) -> 4087468338 | D13: =SUM(OFFSET('Luu chuyen tien te'!$BL7,0,0,1,'Thong tin'!$C$9)) -> 13293790301 | E13: =SUM(OFFSET('Luu chuyen tien te'!$AZ7,0,0,1,'Thong tin'!$C$9)) -> 23695006009
A14: - Các khoản dự phòng | B14: =OFFSET('Luu chuyen tien te'!$BL8,0,'Thong tin'!$C$9 - 1) -> 0 | C14: =OFFSET('Luu chuyen tien te'!$AZ8,0,'Thong tin'!$C$9 - 1) -> 0 | D14: =SUM(OFFSET('Luu chuyen tien te'!$BL8,0,0,1,'Thong tin'!$C$9)) -> 0 | E14: =SUM(OFFSET('Luu chuyen tien te'!$AZ8,0,0,1,'Thong tin'!$C$9)) -> 0
A15: - Lãi, lỗ chênh lệch tỷ giá hối đoái do đánh giá lại các khoản mục tiền tệ có gốc ngoại tệ | B15: =OFFSET('Luu chuyen tien te'!$BL9,0,'Thong tin'!$C$9 - 1) -> -301467078 | C15: =OFFSET('Luu chuyen tien te'!$AZ9,0,'Thong tin'!$C$9 - 1) -> -645043805 | D15: =SUM(OFFSET('Luu chuyen tien te'!$BL9,0,0,1,'Thong tin'!$C$9)) -> -2187950730 | E15: =SUM(OFFSET('Luu chuyen tien te'!$AZ9,0,0,1,'Thong tin'!$C$9)) -> -5189834305
A16: - Lãi lỗ từ hoạt động đầu tư, tài chính | B16: =OFFSET('Luu chuyen tien te'!$BL10,0,'Thong tin'!$C$9 - 1) -> -42752896 | C16: =OFFSET('Luu chuyen tien te'!$AZ10,0,'Thong tin'!$C$9 - 1) -> -989334 | D16: =SUM(OFFSET('Luu chuyen tien te'!$BL10,0,0,1,'Thong tin'!$C$9)) -> -2923290610 | E16: =SUM(OFFSET('Luu chuyen tien te'!$AZ10,0,0,1,'Thong tin'!$C$9)) -> -1680691614
A17: - Chi phí đi vay | B17: =OFFSET('Luu chuyen tien te'!$BL11,0,'Thong tin'!$C$9 - 1) -> 856841656 | C17: =OFFSET('Luu chuyen tien te'!$AZ11,0,'Thong tin'!$C$9 - 1) -> 1448899822 | D17: =SUM(OFFSET('Luu chuyen tien te'!$BL11,0,0,1,'Thong tin'!$C$9)) -> 6113875969 | E17: =SUM(OFFSET('Luu chuyen tien te'!$AZ11,0,0,1,'Thong tin'!$C$9)) -> 6241052349
A18: - Các khoản điều chỉnh khác | B18: =OFFSET('Luu chuyen tien te'!$BL12,0,'Thong tin'!$C$9 - 1) -> 0 | C18: =OFFSET('Luu chuyen tien te'!$AZ12,0,'Thong tin'!$C$9 - 1) -> 0 | D18: =SUM(OFFSET('Luu chuyen tien te'!$BL12,0,0,1,'Thong tin'!$C$9)) -> 0 | E18: =SUM(OFFSET('Luu chuyen tien te'!$AZ12,0,0,1,'Thong tin'!$C$9)) -> 0
A19: 3. Lợi nhuận từ hoạt động kinh doanh trước thay đổi vốn lưu động | B19: =SUM(B11:B18) -> 10521646578 | C19: =SUM(C11:C18) -> 6152100617 | D19: =SUM(D11:D18) -> 18929883711 | E19: =SUM(E11:E18) -> 74493229064
A20: - Tăng giảm các khoản phải thu | B20: =OFFSET('Luu chuyen tien te'!$BL14,0,'Thong tin'!$C$9 - 1) -> -11814070908 | C20: =OFFSET('Luu chuyen tien te'!$AZ14,0,'Thong tin'!$C$9 - 1) -> 720428098 | D20: =SUM(OFFSET('Luu chuyen tien te'!$BL14,0,0,1,'Thong tin'!$C$9)) -> -18056360448 | E20: =SUM(OFFSET('Luu chuyen tien te'!$AZ14,0,0,1,'Thong tin'!$C$9)) -> -59885757236
A21: - Tăng giảm hàng tồn kho | B21: =OFFSET('Luu chuyen tien te'!$BL15,0,'Thong tin'!$C$9 - 1) -> -26467578285 | C21: =OFFSET('Luu chuyen tien te'!$AZ15,0,'Thong tin'!$C$9 - 1) -> -17092818286 | D21: =SUM(OFFSET('Luu chuyen tien te'!$BL15,0,0,1,'Thong tin'!$C$9)) -> 174467761523 | E21: =SUM(OFFSET('Luu chuyen tien te'!$AZ15,0,0,1,'Thong tin'!$C$9)) -> 62229306094
A22: - Tăng giảm các khoản phải trả (Không bao gồm lãi vay phải trả, thuế TNDN phải nộp) | B22: =OFFSET('Luu chuyen tien te'!$BL16,0,'Thong tin'!$C$9 - 1) -> 32739939658 | C22: =OFFSET('Luu chuyen tien te'!$AZ16,0,'Thong tin'!$C$9 - 1) -> 14884971711 | D22: =SUM(OFFSET('Luu chuyen tien te'!$BL16,0,0,1,'Thong tin'!$C$9)) -> 63154333036 | E22: =SUM(OFFSET('Luu chuyen tien te'!$AZ16,0,0,1,'Thong tin'!$C$9)) -> -11977662415
A23: - Tăng giảm chi phí chờ phân bổ | B23: =OFFSET('Luu chuyen tien te'!$BL17,0,'Thong tin'!$C$9 - 1) -> 903849225 | C23: =OFFSET('Luu chuyen tien te'!$AZ17,0,'Thong tin'!$C$9 - 1) -> -5497715935 | D23: =SUM(OFFSET('Luu chuyen tien te'!$BL17,0,0,1,'Thong tin'!$C$9)) -> 2336527590 | E23: =SUM(OFFSET('Luu chuyen tien te'!$AZ17,0,0,1,'Thong tin'!$C$9)) -> -5798221991
A24: - Tăng, giảm chứng khoán kinh doanh | B24: =OFFSET('Luu chuyen tien te'!$BL18,0,'Thong tin'!$C$9 - 1) -> 0 | C24: =OFFSET('Luu chuyen tien te'!$AZ18,0,'Thong tin'!$C$9 - 1) -> 0 | D24: =SUM(OFFSET('Luu chuyen tien te'!$BL18,0,0,1,'Thong tin'!$C$9)) -> 0 | E24: =SUM(OFFSET('Luu chuyen tien te'!$AZ18,0,0,1,'Thong tin'!$C$9)) -> 0
A25: - Chi phí đi vay đã trả | B25: =OFFSET('Luu chuyen tien te'!$BL19,0,'Thong tin'!$C$9 - 1) -> -856841656 | C25: =OFFSET('Luu chuyen tien te'!$AZ19,0,'Thong tin'!$C$9 - 1) -> -1448899822 | D25: =SUM(OFFSET('Luu chuyen tien te'!$BL19,0,0,1,'Thong tin'!$C$9)) -> -6113875969 | E25: =SUM(OFFSET('Luu chuyen tien te'!$AZ19,0,0,1,'Thong tin'!$C$9)) -> -6241052349
A26: - Thuế thu nhập doanh nghiệp đã nộp | B26: =OFFSET('Luu chuyen tien te'!$BL20,0,'Thong tin'!$C$9 - 1) -> 0 | C26: =OFFSET('Luu chuyen tien te'!$AZ20,0,'Thong tin'!$C$9 - 1) -> 0 | D26: =SUM(OFFSET('Luu chuyen tien te'!$BL20,0,0,1,'Thong tin'!$C$9)) -> 0 | E26: =SUM(OFFSET('Luu chuyen tien te'!$AZ20,0,0,1,'Thong tin'!$C$9)) -> 0
A27: - Tiền thu khác từ hoạt động kinh doanh | B27: =OFFSET('Luu chuyen tien te'!$BL21,0,'Thong tin'!$C$9 - 1) -> 0 | C27: =OFFSET('Luu chuyen tien te'!$AZ21,0,'Thong tin'!$C$9 - 1) -> 0 | D27: =SUM(OFFSET('Luu chuyen tien te'!$BL21,0,0,1,'Thong tin'!$C$9)) -> 0 | E27: =SUM(OFFSET('Luu chuyen tien te'!$AZ21,0,0,1,'Thong tin'!$C$9)) -> 0
A28: - Tiền chi khác cho hoạt động kinh doanh | B28: =OFFSET('Luu chuyen tien te'!$BL22,0,'Thong tin'!$C$9 - 1) -> 0 | C28: =OFFSET('Luu chuyen tien te'!$AZ22,0,'Thong tin'!$C$9 - 1) -> 0 | D28: =SUM(OFFSET('Luu chuyen tien te'!$BL22,0,0,1,'Thong tin'!$C$9)) -> 0 | E28: =SUM(OFFSET('Luu chuyen tien te'!$AZ22,0,0,1,'Thong tin'!$C$9)) -> 0
A29: Lưu chuyển tiền thuần từ hoạt động kinh doanh | B29: =SUM(B19:B28) -> 5026944612 | C29: =SUM(C19:C28) -> -2281933617 | D29: =SUM(D19:D28) -> 234718269443 | E29: =SUM(E19:E28) -> 52819841167
A30: II. Lưu chuyển tiền từ hoạt động đầu tư
A31: 1. Tiền chi để mua sắm, xây dựng TSCĐ và các tài sản dài hạn khác | B31: =OFFSET('Luu chuyen tien te'!$BL25,0,'Thong tin'!$C$9 - 1) -> -3540267632 | C31: =OFFSET('Luu chuyen tien te'!$AZ25,0,'Thong tin'!$C$9 - 1) -> -4827154812 | D31: =SUM(OFFSET('Luu chuyen tien te'!$BL25,0,0,1,'Thong tin'!$C$9)) -> -156940109027 | E31: =SUM(OFFSET('Luu chuyen tien te'!$AZ25,0,0,1,'Thong tin'!$C$9)) -> -36451361520
A32: 2. Tiền thu từ thanh lý, nhượng bán TSCĐ và các tài sản dài hạn khác | B32: =OFFSET('Luu chuyen tien te'!$BL26,0,'Thong tin'!$C$9 - 1) -> 0 | C32: =OFFSET('Luu chuyen tien te'!$AZ26,0,'Thong tin'!$C$9 - 1) -> 226000000 | D32: =SUM(OFFSET('Luu chuyen tien te'!$BL26,0,0,1,'Thong tin'!$C$9)) -> 0 | E32: =SUM(OFFSET('Luu chuyen tien te'!$AZ26,0,0,1,'Thong tin'!$C$9)) -> 944633187
A33: 3. Tiền chi cho vay, mua các công cụ nợ của đơn vị khác | B33: =OFFSET('Luu chuyen tien te'!$BL27,0,'Thong tin'!$C$9 - 1) -> -34455263957 | C33: =OFFSET('Luu chuyen tien te'!$AZ27,0,'Thong tin'!$C$9 - 1) -> 0 | D33: =SUM(OFFSET('Luu chuyen tien te'!$BL27,0,0,1,'Thong tin'!$C$9)) -> -121455263957 | E33: =SUM(OFFSET('Luu chuyen tien te'!$AZ27,0,0,1,'Thong tin'!$C$9)) -> -77000000000
A34: 4. Tiền thu hồi cho vay, bán lại các công cụ nợ của đơn vị khác | B34: =OFFSET('Luu chuyen tien te'!$BL28,0,'Thong tin'!$C$9 - 1) -> 10000000000 | C34: =OFFSET('Luu chuyen tien te'!$AZ28,0,'Thong tin'!$C$9 - 1) -> 0 | D34: =SUM(OFFSET('Luu chuyen tien te'!$BL28,0,0,1,'Thong tin'!$C$9)) -> 61200000000 | E34: =SUM(OFFSET('Luu chuyen tien te'!$AZ28,0,0,1,'Thong tin'!$C$9)) -> 5500000000
A35: 5. Tiền chi đầu tư góp vốn vào đơn vị khác | B35: =OFFSET('Luu chuyen tien te'!$BL29,0,'Thong tin'!$C$9 - 1) -> 0 | C35: =OFFSET('Luu chuyen tien te'!$AZ29,0,'Thong tin'!$C$9 - 1) -> 0 | D35: =SUM(OFFSET('Luu chuyen tien te'!$BL29,0,0,1,'Thong tin'!$C$9)) -> 0 | E35: =SUM(OFFSET('Luu chuyen tien te'!$AZ29,0,0,1,'Thong tin'!$C$9)) -> 0
A36: 6. Tiền thu hồi đầu tư góp vốn vào đơn vị khác | B36: =OFFSET('Luu chuyen tien te'!$BL30,0,'Thong tin'!$C$9 - 1) -> 0 | C36: =OFFSET('Luu chuyen tien te'!$AZ30,0,'Thong tin'!$C$9 - 1) -> 0 | D36: =SUM(OFFSET('Luu chuyen tien te'!$BL30,0,0,1,'Thong tin'!$C$9)) -> 0 | E36: =SUM(OFFSET('Luu chuyen tien te'!$AZ30,0,0,1,'Thong tin'!$C$9)) -> 0
A37: 7. Tiền thu lãi cho vay, cổ tức và lợi nhuận được chia | B37: =OFFSET('Luu chuyen tien te'!$BL31,0,'Thong tin'!$C$9 - 1) -> 42752896 | C37: =OFFSET('Luu chuyen tien te'!$AZ31,0,'Thong tin'!$C$9 - 1) -> 989334 | D37: =SUM(OFFSET('Luu chuyen tien te'!$BL31,0,0,1,'Thong tin'!$C$9)) -> 2923290610 | E37: =SUM(OFFSET('Luu chuyen tien te'!$AZ31,0,0,1,'Thong tin'!$C$9)) -> 1680691614
A38: Lưu chuyển tiền thuần từ hoạt động đầu tư | B38: =SUM(B31:B37) -> -27952778693 | C38: =SUM(C31:C37) -> -4600165478 | D38: =SUM(D31:D37) -> -214272082374 | E38: =SUM(E31:E37) -> -105326036719
A39: III. Lưu chuyển tiền từ hoạt động tài chính
A40: 1. Tiền thu từ phát hành cố phiếu, nhận vốn góp của chủ sở hữu | B40: =OFFSET('Luu chuyen tien te'!$BL34,0,'Thong tin'!$C$9 - 1) -> 0 | C40: =OFFSET('Luu chuyen tien te'!$AZ34,0,'Thong tin'!$C$9 - 1) -> 0 | D40: =SUM(OFFSET('Luu chuyen tien te'!$BL34,0,0,1,'Thong tin'!$C$9)) -> 0 | E40: =SUM(OFFSET('Luu chuyen tien te'!$AZ34,0,0,1,'Thong tin'!$C$9)) -> 0
A41: 2. Tiền trả lại vốn góp cho các chủ sở hữu, mua lại cổ phiểu đã phát hành | B41: =OFFSET('Luu chuyen tien te'!$BL35,0,'Thong tin'!$C$9 - 1) -> 0 | C41: =OFFSET('Luu chuyen tien te'!$AZ35,0,'Thong tin'!$C$9 - 1) -> 0 | D41: =SUM(OFFSET('Luu chuyen tien te'!$BL35,0,0,1,'Thong tin'!$C$9)) -> 0 | E41: =SUM(OFFSET('Luu chuyen tien te'!$AZ35,0,0,1,'Thong tin'!$C$9)) -> 0
...

Sheet Tinh hinh tai chinh
B1: CTY CP NHỰA TÁI CHẾ DUY TÂN
B2: VND
A3: Index BS | B3: PHẦN I-BÁO CÁO TÌNH HÌNH TÀI CHÍNH | C3: TenCongTyID | D3: T1.2021 | E3: T02.2021 | F3: T03.2021 | G3: T04.2021 | H3: T05.2021 | I3: T06.2021 | J3: T07.2021 | K3: T08.2021 | L3: T09.2021 | M3: T10.2021 | N3: T11.2021 | O3: T12.2021 | P3: T1.2022 | Q3: T02.2022 | R3: T03.2022 | S3: T04.2022 | T3: T05.2022 | U3: T06.2022 | V3: T07.2022 | W3: T08.2022 | X3: T09.2022 | Y3: T10.2022 | Z3: T11.2022 | AA3: T12.2022 | AB3: T1.2023 | AC3: T02.2023 | AD3: T03.2023 | AE3: T04.2023 | AF3: T05.2023 | AG3: T06.2023 | AH3: T07.2023 | AI3: T08.2023 | AJ3: T09.2023 | AK3: T10.2023 | AL3: T11.2023 | AM3: T12.2023 | AN3: T01.2024 | AO3: T02.2024 | AP3: T03.2024 | AQ3: T04.2024 | AR3: T05.2024 | AS3: T06.2024 | AT3: T07.2024 | AU3: T08.2024 | AV3: T09.2024 | AW3: T10.2024 | AX3: T11.2024 | AY3: T12.2024 | AZ3: T01.2025 | BA3: T02.2025 | BB3: T03.2025 | BC3: T04.2025 | BD3: T05.2025 | BE3: T06.2025 | BF3: T07.2025 | BG3: T08.2025 | BH3: T09.2025 | BI3: T10.2025 | BJ3: T11.2025 | BK3: T12.2025 | BL3: T01.2026 | BM3: T02.2026 | BN3: T03.2026 | BO3: T04.2026 | BP3: T05.2026 | BQ3: T06.2026 | BR3: T07.2026 | BS3: T08.2026 | BT3: T09.2026 | BU3: T10.2026 | BV3: T11.2026 | BW3: T12.2026
A4: 1 | B4: A-TÀI SẢN NGẮN HẠN | C4: 5 | D4: 614493092591 | E4: 609884742147 | F4: 615298026209 | G4: 628174770356 | H4: 633634093227 | I4: 634442148116 | J4: 641465222117 | K4: 461269303491 | L4: 464335451361 | M4: 465446434421 | N4: 474566713935 | O4: 478803851536 | P4: 491203268636 | Q4: 495110335063 | R4: 506410020272 | S4: 541090328555 | T4: 557182730957 | U4: 567579171386 | V4: 553380198104 | W4: 575629704487 | X4: 581428641960 | Y4: 579326744202 | Z4: 570154808236 | AA4: 638615944603 | AB4: 630392907077 | AC4: 635811337862 | AD4: 615592156470 | AE4: 591572888711 | AF4: 576645541879 | AG4: 627637203928 | AH4: 645017740465 | AI4: 624618100412 | AJ4: 607904625059 | AK4: 655561441913 | AL4: 691663318215 | AM4: 735262711239 | AN4: 782481934423 | AO4: 768590764263 | AP4: 815465869041 | AQ4: 877414026420 | AR4: 928155716736 | AS4: 956563222023 | AT4: 906133879099 | AU4: 849218290026 | AV4: 891170346476 | AW4: 912165489717 | AX4: 989601612249 | AY4: 969587265880 | AZ4: 894788032291 | BA4: 814157821775 | BB4: 866303373135 | BC4: 929599762285 | BD4: 981599372849 | BE4: 1010794698754 | BF4: 999811801439 | BG4: 1060333071975 | BH4: 1040577598634 | BI4: 982848510813 | BJ4: 959373053576 | BK4: 945217150933 | BL4: 894150692345 | BM4: 895502322076 | BN4: 848468475952 | BO4: 807952336254 | BP4: 886588369025 | BQ4: 820219773119
A5: 2 | B5: I.Tiền và các khoản tương đương tiền | C5: 5 | D5: 3447839862 | E5: 4753297265 | F5: 3470025524 | G5: 7213551570 | H5: 6428796497 | I5: 6637859615 | J5: 6692002174 | K5: 17171442096 | L5: 20706415997 | M5: 18510700926 | N5: 9217053448 | O5: 9537238483 | P5: 7841551973 | Q5: 25742652312 | R5: 10229505276 | S5: 23153084677 | T5: 15475133505 | U5: 6070662597 | V5: 5025380377 | W5: 25956322209 | X5: 31102397335 | Y5: 12848278176 | Z5: 10250965252 | AA5: 13274374149 | AB5: 16792099757 | AC5: 15908187368 | AD5: 16078630986 | AE5: 51289665216 | AF5: 23427390962 | AG5: 21288636707 | AH5: 22472091319 | AI5: 2490582158 | AJ5: 10148364108 | AK5: 9841817259 | AL5: 4968558361 | AM5: 6353042534 | AN5: 31037848308 | AO5: 22669663716 | AP5: 6664945115 | AQ5: 15574807889 | AR5: 16007340290 | AS5: 3678057757 | AT5: 36916493026 | AU5: 16748498285 | AV5: 33251814637 | AW5: 56773964959 | AX5: 43420355696 | AY5: 39805017284 | AZ5: 76486895109 | BA5: 33258200889 | BB5: 23555271373 | BC5: 37590058839 | BD5: 21868727527 | BE5: 32470900772 | BF5: 30661632458 | BG5: 29770776625 | BH5: 64296693910 | BI5: 53646701293 | BJ5: 55165406320 | BK5: 36834893155 | BL5: 42126572011 | BM5: 45981412915 | BN5: 33613094972 | BO5: 47135211556 | BP5: 41014004605 | BQ5: 41687049619
A6: 3 | B6: 1.Tiền | C6: 5 | D6: 3447839862 | E6: 4753297265 | F6: 3470025524 | G6: 7213551570 | H6: 6428796497 | I6: 6637859615 | J6: 6692002174 | K6: 4471442096 | L6: 5006415997 | M6: 5810700926 | N6: 9217053448 | O6: 9537238483 | P6: 7841551973 | Q6: 25742652312 | R6: 10229505276 | S6: 23153084677 | T6: 15475133505 | U6: 6070662597 | V6: 5025380377 | W6: 25956322209 | X6: 31102397335 | Y6: 12848278176 | Z6: 10250965252 | AA6: 13274374149 | AB6: 16792099757 | AC6: 15908187368 | AD6: 16078630986 | AE6: 36289665216 | AF6: 23427390962 | AG6: 21288636707 | AH6: 22472091319 | AI6: 2490582158 | AJ6: 10148364108 | AK6: 7001817259 | AL6: 2128558361 | AM6: 3513042534 | AN6: 28197848308 | AO6: 19829663716 | AP6: 5834945115 | AQ6: 14744807889 | AR6: 15177340290 | AS6: 2848057757 | AT6: 36086493026 | AU6: 15918498285 | AV6: 33251814637 | AW6: 56773964959 | AX6: 43420355696 | AY6: 29805017284 | AZ6: 73646895109 | BA6: 30418200889 | BB6: 23555271373 | BC6: 37590058839 | BD6: 21868727527 | BE6: 32470900772 | BF6: 30661632458 | BG6: 29770776625 | BH6: 64296693910 | BI6: 33646701293 | BJ6: 35165406320 | BK6: 36834893155 | BL6: 42126572011 | BM6: 45981412915 | BN6: 27413094972 | BO6: 28835211556 | BP6: 30714004605 | BQ6: 26931785662
A7: 4 | B7: 2.Các khoản tương đương tiền | C7: 5 | D7: 0 | E7: 0 | F7: 0 | G7: 0 | H7: 0 | I7: 0 | J7: 0 | K7: 12700000000 | L7: 15700000000 | M7: 12700000000 | N7: 0 | O7: 0 | P7: 0 | Q7: 0 | R7: 0 | S7: 0 | T7: 0 | U7: 0 | V7: 0 | W7: 0 | X7: 0 | Y7: 0 | Z7: 0 | AA7: 0 | AB7: 0 | AC7: 0 | AD7: 0 | AE7: 15000000000 | AF7: 0 | AG7: 0 | AH7: 0 | AI7: 0 | AJ7: 0 | AK7: 2840000000 | AL7: 2840000000 | AM7: 2840000000 | AN7: 2840000000 | AO7: 2840000000 | AP7: 830000000 | AQ7: 830000000 | AR7: 830000000 | AS7: 830000000 | AT7: 830000000 | AU7: 830000000 | AV7: 0 | AW7: 0 | AX7: 0 | AY7: 10000000000 | AZ7: 2840000000 | BA7: 2840000000 | BB7: 0 | BC7: 0 | BD7: 0 | BE7: 0 | BF7: 0 | BG7: 0 | BH7: 0 | BI7: 20000000000 | BJ7: 20000000000 | BN7: 6200000000 | BO7: 18300000000 | BP7: 10300000000 | BQ7: 14755263957
A8: 5 | B8: II.Đầu tư tài chính ngắn hạn | C8: 5 | D8: 0 | E8: 0 | F8: 0 | G8: 0 | H8: 0 | I8: 0 | J8: 0 | K8: 0 | L8: 0 | M8: 0 | N8: 0 | O8: 0 | P8: 0 | Q8: 0 | R8: 0 | S8: 0 | T8: 0 | U8: 0 | V8: 0 | W8: 0 | X8: 0 | Y8: 0 | Z8: 0 | AA8: 0 | AB8: 0 | AC8: 0 | AD8: 2010000000 | AE8: 2010000000 | AF8: 2010000000 | AG8: 2010000000 | AH8: 2010000000 | AI8: 2010000000 | AJ8: 2010000000 | AK8: 2010000000 | AL8: 2010000000 | AM8: 2010000000 | AN8: 2010000000 | AO8: 2010000000 | AP8: 2010000000 | AQ8: 2010000000 | AR8: 2010000000 | AS8: 2010000000 | AT8: 2010000000 | AU8: 2010000000 | AV8: 2840000000 | AW8: 2840000000 | AX8: 2840000000 | AY8: 2840000000 | AZ8: 0 | BA8: 0 | BB8: 22840000000 | BC8: 22840000000 | BD8: 22840000000 | BE8: 22840000000 | BF8: 22840000000 | BG8: 22840000000 | BH8: 22840000000 | BI8: 32840000000 | BJ8: 32840000000 | BK8: 32840000000 | BL8: 32840000000 | BM8: 32840000000 | BN8: 32840000000 | BO8: 34340000000 | BP8: 34340000000 | BQ8: 34340000000
A9: 6 | B9: 1.Chứng khoán kinh doanh | C9: 5 | D9: 0 | E9: 0 | F9: 0 | G9: 0 | H9: 0 | I9: 0 | J9: 0 | K9: 0 | L9: 0 | M9: 0 | N9: 0 | O9: 0 | P9: 0 | Q9: 0 | R9: 0 | S9: 0 | T9: 0 | U9: 0 | V9: 0 | W9: 0 | X9: 0 | Y9: 0 | Z9: 0 | AA9: 0 | AB9: 0 | AC9: 0 | AD9: 0 | AE9: 0 | AF9: 0 | AG9: 0 | AH9: 0 | AI9: 0 | AJ9: 0 | AK9: 0 | AL9: 0 | AM9: 0 | AN9: 0 | AO9: 0 | AP9: 0 | AQ9: 0 | AR9: 0 | AS9: 0 | AT9: 0 | AU9: 0 | AV9: 0 | AW9: 0 | AX9: 0 | AY9: 0 | AZ9: 0 | BA9: 0 | BB9: 0 | BC9: 0 | BD9: 0 | BE9: 0 | BF9: 0 | BG9: 0 | BH9: 0 | BI9: 0 | BJ9: 0
A10: 7 | B10: 2.Dự phòng giảm giá chứng khoán kinh doanh (*) | C10: 5 | D10: 0 | E10: 0 | F10: 0 | G10: 0 | H10: 0 | I10: 0 | J10: 0 | K10: 0 | L10: 0 | M10: 0 | N10: 0 | O10: 0 | P10: 0 | Q10: 0 | R10: 0 | S10: 0 | T10: 0 | U10: 0 | V10: 0 | W10: 0 | X10: 0 | Y10: 0 | Z10: 0 | AA10: 0 | AB10: 0 | AC10: 0 | AD10: 0 | AE10: 0 | AF10: 0 | AG10: 0 | AH10: 0 | AI10: 0 | AJ10: 0 | AK10: 0 | AL10: 0 | AM10: 0 | AN10: 0 | AO10: 0 | AP10: 0 | AQ10: 0 | AR10: 0 | AS10: 0 | AT10: 0 | AU10: 0 | AV10: 0 | AW10: 0 | AX10: 0 | AY10: 0 | AZ10: 0 | BA10: 0 | BB10: 0 | BC10: 0 | BD10: 0 | BE10: 0 | BF10: 0 | BG10: 0 | BH10: 0 | BI10: 0 | BJ10: 0
A11: 8 | B11: 3.Đầu tư nắm giữ đến ngày đáo hạn ngắn hạn | C11: 5 | D11: 0 | E11: 0 | F11: 0 | G11: 0 | H11: 0 | I11: 0 | J11: 0 | K11: 0 | L11: 0 | M11: 0 | N11: 0 | O11: 0 | P11: 0 | Q11: 0 | R11: 0 | S11: 0 | T11: 0 | U11: 0 | V11: 0 | W11: 0 | X11: 0 | Y11: 0 | Z11: 0 | AA11: 0 | AB11: 0 | AC11: 0 | AD11: 2010000000 | AE11: 2010000000 | AF11: 2010000000 | AG11: 2010000000 | AH11: 2010000000 | AI11: 2010000000 | AJ11: 2010000000 | AK11: 2010000000 | AL11: 2010000000 | AM11: 2010000000 | AN11: 2010000000 | AO11: 2010000000 | AP11: 2010000000 | AQ11: 2010000000 | AR11: 2010000000 | AS11: 2010000000 | AT11: 2010000000 | AU11: 2010000000 | AV11: 2840000000 | AW11: 2840000000 | AX11: 2840000000 | AY11: 2840000000 | BB11: 22840000000 | BC11: 22840000000 | BD11: 22840000000 | BE11: 22840000000 | BF11: 22840000000 | BG11: 22840000000 | BH11: 22840000000 | BI11: 32840000000 | BJ11: 32840000000 | BK11: 32840000000 | BL11: 32840000000 | BM11: 32840000000 | BN11: 32840000000 | BO11: 34340000000 | BP11: 34340000000 | BQ11: 34340000000
A12: 9 | B12: 4.Dự phòng đầu tư nắm giữ đến ngày đáo hạn ngắn hạn (*) | C12: 5 | D12: 0 | E12: 0 | F12: 0 | G12: 0 | H12: 0 | I12: 0 | J12: 0 | K12: 0 | L12: 0 | M12: 0 | N12: 0 | O12: 0 | P12: 0 | Q12: 0 | R12: 0 | S12: 0 | T12: 0 | U12: 0 | V12: 0 | W12: 0 | X12: 0 | Y12: 0 | Z12: 0 | AA12: 0 | AB12: 0 | AC12: 0 | AD12: 0 | AE12: 0 | AF12: 0 | AG12: 0 | AH12: 0 | AI12: 0 | AJ12: 0 | AK12: 0 | AL12: 0 | AM12: 0 | AN12: 0 | AO12: 0 | AP12: 0 | AQ12: 0 | AR12: 0 | AS12: 0 | AT12: 0 | AU12: 0 | AV12: 0 | AW12: 0 | AX12: 0 | AY12: 0
A13: 10 | B13: 5.Đầu tư ngắn hạn khác | C13: 5 | D13: 0 | E13: 0 | F13: 0 | G13: 0 | H13: 0 | I13: 0 | J13: 0 | K13: 0 | L13: 0 | M13: 0 | N13: 0 | O13: 0 | P13: 0 | Q13: 0 | R13: 0 | S13: 0 | T13: 0 | U13: 0 | V13: 0 | W13: 0 | X13: 0 | Y13: 0 | Z13: 0 | AA13: 0 | AB13: 0 | AC13: 0 | AD13: 0 | AE13: 0 | AF13: 0 | AG13: 0 | AH13: 0 | AI13: 0 | AJ13: 0 | AK13: 0 | AL13: 0 | AM13: 0 | AN13: 0 | AO13: 0 | AP13: 0 | AQ13: 0 | AR13: 0 | AS13: 0 | AT13: 0 | AU13: 0 | AV13: 0 | AW13: 0 | AX13: 0 | AY13: 0
A14: 11 | B14: 6.Dự phòng tổn thất các khoản đầu tư ngắn hạn khác (*) | C14: 5 | D14: 0 | E14: 0 | F14: 0 | G14: 0 | H14: 0 | I14: 0 | J14: 0 | K14: 0 | L14: 0 | M14: 0 | N14: 0 | O14: 0 | P14: 0 | Q14: 0 | R14: 0 | S14: 0 | T14: 0 | U14: 0 | V14: 0 | W14: 0 | X14: 0 | Y14: 0 | Z14: 0 | AA14: 0 | AB14: 0 | AC14: 0 | AD14: 0 | AE14: 0 | AF14: 0 | AG14: 0 | AH14: 0 | AI14: 0 | AJ14: 0 | AK14: 0 | AL14: 0 | AM14: 0 | AN14: 0 | AO14: 0 | AP14: 0 | AQ14: 0 | AR14: 0 | AS14: 0 | AT14: 0 | AU14: 0 | AV14: 0 | AW14: 0 | AX14: 0 | AY14: 0
A15: 12 | B15: III.Các khoản phải thu ngắn hạn | C15: 5 | D15: 583090168909 | E15: 574635526390 | F15: 579654385119 | G15: 580152986487 | H15: 574090844955 | I15: 572033698810 | J15: 578204061657 | K15: 371354860764 | L15: 370080496191 | M15: 373899944419 | N15: 379563072845 | O15: 366657577174 | P15: 369266414406 | Q15: 347038625933 | R15: 356134424988 | S15: 351164566423 | T15: 337425900496 | U15: 332415377962 | V15: 307565424035 | W15: 308695850381 | X15: 314557732124 | Y15: 314155195386 | Z15: 285297966348 | AA15: 393325694531 | AB15: 360444652190 | AC15: 346735780052 | AD15: 314877277638 | AE15: 254854875792 | AF15: 258356225773 | AG15: 288750692005 | AH15: 295019567188 | AI15: 303397690711 | AJ15: 280722229912 | AK15: 318211148963 | AL15: 311455177330 | AM15: =SUM(AM16:AM22) -> 316868469942 | AN15: 294283662527 | AO15: 277719968888 | AP15: 297405577345 | AQ15: 303674749988 | AR15: 304477407097 | AS15: 308711681498 | AT15: 200469936704 | AU15: 222854636431 | AV15: 249167765476 | AW15: 246057656184 | AX15: 323215272934 | AY15: 292036709951 | AZ15: =SUM(AZ16:AZ22) -> 220033096514 | BA15: =SUM(BA16:BA22) -> 264758570553 | BB15: =SUM(BB16:BB22) -> 314044742217 | BC15: =SUM(BC16:BC22) -> 300175012111 | BD15: =SUM(BD16:BD22) -> 355551041672 | BE15: =SUM(BE16:BE22) -> 347420810569 | BF15: =SUM(BF16:BF22) -> 326074813439 | BG15: =SUM(BG16:BG22) -> 416521420158 | ... BJ15: =SUM(BJ16:BJ22) -> 279428206352 | BK15: 293560124180 | BL15: 263624916145 | BM15: 289980302579 | BN15: 331342767193 | BO15: 329741435832 | BP15: 417392857129 | BQ15: 310082966155
A16: 13 | B16: 1.Phải thu ngắn hạn của khách hàng | C16: 5 | D16: 571116397848 | E16: 11245292216 | F16: 15856223874 | G16: 11853022983 | H16: 4837569782 | I16: 6108714016 | J16: 18273784195 | K16: 6649601466 | L16: 6537064622 | M16: 14808496229 | N16: 23891683442 | O16: 33185427033 | P16: 42838925726 | Q16: 40209422110 | R16: 42161135861 | S16: 46509292431 | T16: 53272379708 | U16: 46733674531 | V16: 46987053150 | W16: 46192969621 | X16: 46575900326 | Y16: 51157219350 | Z16: 52837953862 | AA16: 366019034353 | AB16: 346550500356 | AC16: 331740967976 | AD16: 114960287290 | AE16: 82538799028 | AF16: 76951932726 | AG16: 75528601013 | AH16: 74743149460 | AI16: 77570626810 | AJ16: 83261973464 | AK16: 111015808616 | AL16: 116221372072 | AM16: 121096083260 | AN16: 122887480695 | AO16: 127016253433 | AP16: 139011604932 | AQ16: 152040845787 | AR16: 161172642369 | AS16: 159378679498 | AT16: 97722288447 | AU16: 120989360950 | AV16: 150031537677 | AW16: 147739603288 | AX16: 148202432891 | AY16: 152669364944 | AZ16: 108322209217 | BA16: 161139219719 | BB16: 202956915270 | BC16: 159438788675 | BD16: 170977391735 | BE16: 157629418587 | BF16: 156235244643 | BG16: 193809016663 | BH16: 162064070219 | BI16: 155463444706 | BJ16: 157631834549 | BK16: 154342206132 | BL16: 132649296167 | BM16: 140446291758 | BN16: 153248625708 | BO16: 178191270169 | BP16: 178005616424 | BQ16: 169259122091
A17: 14 | B17: 2.Trả trước cho người bán ngắn hạn | C17: 5 | D17: 6523854606 | E17: 8840317719 | F17: 9301534244 | G17: 18808203504 | H17: 19752159173 | I17: 20584484794 | J17: 13954080202 | K17: 16174952449 | L17: 16056294580 | M17: 17236756406 | N17: 12406025016 | O17: 8810297275 | P17: 12572821244 | Q17: 12985734332 | R17: 18637216896 | S17: 19362255108 | T17: 34524039024 | U17: 34861611746 | V17: 34722306504 | W17: 35591679393 | X17: 39721501993 | Y17: 33128809245 | Z17: 31174041516 | AA17: 22344097062 | AB17: 20916211061 | AC17: 21954342423 | AD17: 18757049149 | AE17: 23651627792 | AF17: 22917215700 | AG17: 22524331312 | AH17: 23699255018 | AI17: 25626123009 | AJ17: 27607049863 | AK17: 35640431515 | AL17: 18752744712 | AM17: 38776401474 | AN17: 19316587120 | AO17: 17454753549 | AP17: 16813944743 | AQ17: 18608309535 | AR17: 18405763308 | AS17: 16327636020 | AT17: 15257741813 | AU17: 14294350015 | AV17: 10832801685 | AW17: 9551925778 | AX17: 10191021053 | AY17: 23997890529 | AZ17: 17386959101 | BA17: 22390625492 | BB17: 24711414335 | BC17: 29713189366 | BD17: 63705294804 | BE17: 67384127297 | BF17: 62294223986 | BG17: 80801800470 | BH17: 83665862400 | BI17: 77870421089 | BJ17: 63335376460 | BK17: 67613421375 | BL17: 75878310145 | BM17: 82113512006 | BN17: 95312309944 | BO17: 77634941776 | BP17: 162931057926 | BQ17: 49662085677
A18: 15 | B18: 3.Phải thu nội bộ ngắn hạn | C18: 5 | D18: 0 | E18: 0 | F18: 0 | G18: 0 | H18: 0 | I18: 0 | J18: 0 | K18: 0 | L18: 0 | M18: 0 | N18: 0 | O18: 0 | P18: 0 | Q18: 0 | R18: 0 | S18: 0 | T18: 0 | U18: 0 | V18: 0 | W18: 0 | X18: 0 | Y18: 0 | Z18: 0 | AA18: 0 | AB18: 0 | AC18: 0 | AD18: 0 | AE18: 0 | AF18: 0 | AG18: 0 | AH18: 0 | AI18: 0 | AJ18: 0 | AK18: 0 | AL18: 0 | AM18: 0 | AN18: 0 | AO18: 0 | AP18: 0 | AQ18: 0 | AR18: 0 | AS18: 0 | AT18: 0 | AU18: 0 | AV18: 0 | AW18: 0 | AX18: 0 | AY18: 0 | AZ18: 0 | BA18: 0 | BB18: 0 | BC18: 0 | BD18: 0 | BE18: 0 | BF18: 0 | BG18: 0 | BH18: 0 | BI18: 0 | BJ18: 0
A19: 16 | B19: 4.Phải thu theo tiến độ hợp đồng xây dựng | C19: 5 | D19: 0 | E19: 0 | F19: 0 | G19: 0 | H19: 0 | I19: 0 | J19: 0 | K19: 0 | L19: 0 | M19: 0 | N19: 0 | O19: 0 | P19: 0 | Q19: 0 | R19: 0 | S19: 0 | T19: 0 | U19: 0 | V19: 0 | W19: 0 | X19: 0 | Y19: 0 | Z19: 0 | AA19: 0 | AB19: 0 | AC19: 0 | AD19: 0 | AE19: 0 | AF19: 0 | AG19: 0 | AH19: 0 | AI19: 0 | AJ19: 0 | AK19: 0 | AL19: 0 | AM19: 0 | AN19: 0 | AO19: 0 | AP19: 0 | AQ19: 0 | AR19: 0 | AS19: 0 | AT19: 0 | AU19: 0 | AV19: 0 | AW19: 0 | AX19: 0 | AY19: 0 | AZ19: 0 | BA19: 0 | BB19: 0 | BC19: 0 | BD19: 0 | BE19: 0 | BF19: 0 | BG19: 0 | BH19: 0 | BI19: 0 | BJ19: 0
A20: 17 | B20: 5.Phải thu ngắn hạn khác | C20: 5 | D20: 5449916455 | E20: 554549916455 | F20: 554496627001 | G20: 549491760000 | H20: 549501116000 | I20: 545340500000 | J20: 545976197260 | K20: 348530306849 | L20: 347487136989 | M20: 341854691784 | N20: 343265364387 | O20: 324394336305 | P20: 310143488382 | Q20: 290132290437 | R20: 291624893177 | S20: 281581839830 | T20: 245918302710 | U20: 247108912631 | V20: 222144885327 | W20: 223200022313 | X20: 224549150751 | Y20: 226157987737 | Z20: 197574791916 | AA20: 6706262043 | AB20: 8169517329 | AC20: 8232046209 | AD20: 196351517755 | AE20: 163856025528 | AF20: 173678653903 | AG20: 192441458607 | AH20: 198320861637 | AI20: 200200940892 | AJ20: 169853206585 | AK20: 171554908832 | AL20: 176481060546 | AM20: 156995985208 | AN20: 152604203987 | AO20: 133773571181 | AP20: 133678635526 | AQ20: 125124202522 | AR20: 125423610695 | AS20: 133529975255 | AT20: 88014515719 | AU20: 88095534741 | AV20: 88828035389 | AW20: 89290736393 | AX20: 165346428265 | AY20: 115369454478 | AZ20: 94323928196 | BA20: 81228725342 | BB20: 86376412612 | BC20: 111023034070 | BD20: 120868355133 | BE20: 122407264685 | BF20: 107545344810 | BG20: 141910603025 | BH20: 99433070224 | BI20: 68428247121 | BJ20: 58460995343 | BK20: 72213592373 | BL20: 54586491575 | BM20: 66773872669 | BN20: 82135205395 | BO20: 73268597741 | BP20: 76382324781 | BQ20: 91770854087
A21: 18 | B21: 6.Dự phòng phải thu ngắn hạn khó đòi (*) | C21: 5 | D21: 0 | E21: 0 | F21: 0 | G21: 0 | H21: 0 | I21: 0 | J21: 0 | K21: 0 | L21: 0 | M21: 0 | N21: 0 | O21: 0 | P21: 0 | Q21: 0 | R21: 0 | S21: 0 | T21: 0 | U21: 0 | V21: 0 | W21: 0 | X21: 0 | Y21: 0 | Z21: 0 | AA21: -1743698927 | AB21: -1743698927 | AC21: -1743698927 | AD21: -1743698927 | AE21: -1743698927 | AF21: -1743698927 | AG21: -1743698927 | AH21: -1743698927 | AI21: 0 | AJ21: 0 | AK21: 0 | AL21: 0 | AM21: 0 | AN21: 0 | AO21: 0 | AP21: 0 | AQ21: 0 | AR21: 0 | AS21: 0 | AT21: 0 | AU21: 0 | AV21: 0 | AW21: 0 | AX21: 0 | AY21: 0 | AZ21: 0 | BA21: 0 | BB21: 0 | BC21: 0 | BD21: 0 | BE21: 0 | BF21: 0 | BG21: 0 | BH21: 0 | BI21: 0 | BJ21: 0 | BK21: -609095700 | BL21: -609095700 | BM21: -609095700 | BN21: -609095700 | BO21: -609095700 | BP21: -609095700 | BQ21: -609095700
A22: 19 | B22: 7.Tài sản thiếu chờ xử lý | C22: 5 | D22: 0 | E22: 0 | F22: 0 | G22: 0 | H22: 0 | I22: 0 | J22: 0 | K22: 0 | L22: 0 | M22: 0 | N22: 0 | O22: 267516561 | P22: 3711179054 | Q22: 3711179054 | R22: 3711179054 | S22: 3711179054 | T22: 3711179054 | U22: 3711179054 | V22: 3711179054 | W22: 3711179054 | X22: 3711179054 | Y22: 3711179054 | Z22: 3711179054 | AA22: 0 | AB22: -13447877629 | AC22: -13447877629 | AD22: -13447877629 | AE22: -13447877629 | AF22: -13447877629 | AG22: 0 | AH22: 0 | AI22: 0 | AJ22: 0 | AK22: 0 | AL22: 0 | AN22: -524609275 | AO22: -524609275 | AP22: 7901392144 | AQ22: 7901392144 | AR22: -524609275 | AS22: -524609275 | AT22: -524609275 | AU22: -524609275 | AV22: -524609275 | AW22: -524609275 | AX22: -524609275 | AY22: 0 | AZ22: 0 | BA22: 0 | BB22: 0 | BC22: 0 | BD22: 0 | BE22: 0 | BF22: 0 | BG22: 0 | BH22: 0 | BI22: 0 | BJ22: 0 | BK22: 0 | BL22: 1119913958 | BM22: 1255721846 | BN22: 1255721846 | BO22: 1255721846 | BP22: 682953698 | BQ22: 0
A23: 20 | B23: IV. Hàng tồn kho | C23: 5 | D23: 22640840422 | E23: 24415218988 | F23: 26498172124 | G23: 34682793625 | H23: 44709711264 | I23: 47275848380 | J23: 47653018372 | K23: 46032587439 | L23: 46148656772 | M23: 45809647414 | N23: 56906779913 | O23: 71650856326 | P23: 82706082474 | Q23: 90142332135 | R23: 106212278520 | S23: 129998785280 | T23: 163378971965 | U23: 185439599732 | V23: 195978830536 | W23: 195205377630 | X23: 187734490096 | Y23: 200852894094 | Z23: 219068154486 | AA23: 193819687801 | AB23: 214379170076 | AC23: 232092273214 | AD23: 237508877159 | AE23: 241821396518 | AF23: 247116136805 | AG23: 268484485479 | AH23: 275124136485 | AI23: 264624812102 | AJ23: 265818411834 | AK23: 273657995371 | AL23: 314192815161 | AM23: 368903112653 | AN23: 406821244018 | AO23: 413788449441 | AP23: 455747162045 | AQ23: 496057122616 | AR23: 541180364701 | AS23: 600190018005 | AT23: 619776297407 | AU23: 559053982584 | AV23: 549140904407 | AW23: 546574238545 | AX23: 588008826045 | AY23: 605821152798 | AZ23: 566809475589 | BA23: 483821147048 | BB23: 468355569440 | BC23: 522665513478 | BD23: 526499028418 | BE23: 543591846704 | BF23: 548599437580 | BG23: 548273459394 | BH23: 564202481203 | BI23: 551227150950 | BJ23: 550570669746 | BK23: 562435021579 | BL23: 534105826237 | BM23: 502545827363 | BN23: 425450972162 | BO23: 370413533224 | BP23: 361880765551 | BQ23: 388348343836
A24: 21 | B24: 1.Hàng tồn kho | C24: 5 | D24: 22640840422 | E24: 24415218988 | F24: 26498172124 | G24: 34682793625 | H24: 44709711264 | I24: 47275848380 | J24: 47653018372 | K24: 46032587439 | L24: 46148656772 | M24: 45809647414 | N24: 56906779913 | O24: 71650856326 | P24: 82706082474 | Q24: 90142332135 | R24: 106212278520 | S24: 129998785280 | T24: 163378971965 | U24: 185439599732 | V24: 195978830536 | W24: 195205377630 | X24: 187734490096 | Y24: 200852894094 | Z24: 219068154486 | AA24: 193819687801 | AB24: 214379170076 | AC24: 232092273214 | AD24: 237508877159 | AE24: 241821396518 | AF24: 247116136805 | AG24: 268484485479 | AH24: 275124136485 | AI24: 264624812102 | AJ24: 265818411834 | AK24: 273657995371 | AL24: 314192815161 | AM24: 368903112653 | AN24: 406821244018 | AO24: 413788449441 | AP24: 455747162045 | AQ24: 496057122616 | AR24: 541180364701 | AS24: 600190018005 | AT24: 619776297407 | AU24: 559053982584 | AV24: 549140904407 | AW24: 546574238545 | AX24: 588008826045 | AY24: 605821152798 | AZ24: 566809475589 | BA24: 483821147048 | BB24: 468355569440 | BC24: 522665513478 | BD24: 526499028418 | BE24: 543591846704 | BF24: 548599437580 | BG24: 548273459394 | BH24: 564202481203 | BI24: 551227150950 | BJ24: 550570669746 | BK24: 562435021579 | BL24: 534105826237 | BM24: 502545827363 | BN24: 425450972162 | BO24: 370413533224 | BP24: 361880765551 | BQ24: 388348343836
A25: 22 | B25: 2.Dự phòng giảm giá hàng tồn kho (*) | C25: 5 | D25: 0 | E25: 0 | F25: 0 | G25: 0 | H25: 0 | I25: 0 | J25: 0 | K25: 0 | L25: 0 | M25: 0 | N25: 0 | O25: 0 | P25: 0 | Q25: 0 | R25: 0 | S25: 0 | T25: 0 | U25: 0 | V25: 0 | W25: 0 | X25: 0 | Y25: 0 | Z25: 0 | AA25: 0 | AB25: 0 | AC25: 0 | AD25: 0 | AE25: 0 | AF25: 0 | AG25: 0 | AH25: 0 | AI25: 0 | AJ25: 0 | AK25: 0 | AL25: 0 | AM25: 0 | AN25: 0 | AO25: 0 | AP25: 0 | AQ25: 0 | AR25: 0 | AS25: 0 | AT25: 0 | AU25: 0 | AV25: 0 | AW25: 0 | AX25: 0 | AY25: 0 | AZ25: 0 | BA25: 0 | BB25: 0 | BC25: 0 | BD25: 0 | BE25: 0 | BF25: 0 | BG25: 0 | BH25: 0 | BI25: 0 | BJ25: 0
A26: 23 | B26: V. Tài sản sinh học ngắn hạn | C26: 5 | D26: 0 | E26: 0 | F26: 0 | G26: 0 | H26: 0 | I26: 0 | J26: 0 | K26: 0 | L26: 0 | M26: 0 | N26: 0 | O26: 0 | P26: 0 | Q26: 0 | R26: 0 | S26: 0 | T26: 0 | U26: 0 | V26: 0 | W26: 0 | X26: 0 | Y26: 0 | Z26: 0 | AA26: 0 | AB26: 0 | AC26: 0 | AD26: 0 | AE26: 0 | AF26: 0 | AG26: 0 | AH26: 0 | AI26: 0 | AJ26: 0 | AK26: 0 | AL26: 0 | AM26: 0 | AN26: 0 | AO26: 0 | AP26: 0 | AQ26: 0 | AR26: 0 | AS26: 0 | AT26: 0 | AU26: 0 | AV26: 0 | AW26: 0 | AX26: 0 | AY26: 0
A27: 24 | B27: 1.Súc vật nuôi lấy sản phẩm một lần ngắn hạn | C27: 5 | D27: 0 | E27: 0 | F27: 0 | G27: 0 | H27: 0 | I27: 0 | J27: 0 | K27: 0 | L27: 0 | M27: 0 | N27: 0 | O27: 0 | P27: 0 | Q27: 0 | R27: 0 | S27: 0 | T27: 0 | U27: 0 | V27: 0 | W27: 0 | X27: 0 | Y27: 0 | Z27: 0 | AA27: 0 | AB27: 0 | AC27: 0 | AD27: 0 | AE27: 0 | AF27: 0 | AG27: 0 | AH27: 0 | AI27: 0 | AJ27: 0 | AK27: 0 | AL27: 0 | AM27: 0 | AN27: 0 | AO27: 0 | AP27: 0 | AQ27: 0 | AR27: 0 | AS27: 0 | AT27: 0 | AU27: 0 | AV27: 0 | AW27: 0 | AX27: 0 | AY27: 0
A28: 25 | B28: 2.Cây trồng theo mùa vụ hoặc lấy sản phẩm một lần ngắn hạn | C28: 5 | D28: 0 | E28: 0 | F28: 0 | G28: 0 | H28: 0 | I28: 0 | J28: 0 | K28: 0 | L28: 0 | M28: 0 | N28: 0 | O28: 0 | P28: 0 | Q28: 0 | R28: 0 | S28: 0 | T28: 0 | U28: 0 | V28: 0 | W28: 0 | X28: 0 | Y28: 0 | Z28: 0 | AA28: 0 | AB28: 0 | AC28: 0 | AD28: 0 | AE28: 0 | AF28: 0 | AG28: 0 | AH28: 0 | AI28: 0 | AJ28: 0 | AK28: 0 | AL28: 0 | AM28: 0 | AN28: 0 | AO28: 0 | AP28: 0 | AQ28: 0 | AR28: 0 | AS28: 0 | AT28: 0 | AU28: 0 | AV28: 0 | AW28: 0 | AX28: 0 | AY28: 0
A29: 26 | B29: 3.Dự phòng tổn thất tài sản sinh học ngắn hạn (*) | C29: 5 | D29: 0 | E29: 0 | F29: 0 | G29: 0 | H29: 0 | I29: 0 | J29: 0 | K29: 0 | L29: 0 | M29: 0 | N29: 0 | O29: 0 | P29: 0 | Q29: 0 | R29: 0 | S29: 0 | T29: 0 | U29: 0 | V29: 0 | W29: 0 | X29: 0 | Y29: 0 | Z29: 0 | AA29: 0 | AB29: 0 | AC29: 0 | AD29: 0 | AE29: 0 | AF29: 0 | AG29: 0 | AH29: 0 | AI29: 0 | AJ29: 0 | AK29: 0 | AL29: 0 | AM29: 0 | AN29: 0 | AO29: 0 | AP29: 0 | AQ29: 0 | AR29: 0 | AS29: 0 | AT29: 0 | AU29: 0 | AV29: 0 | AW29: 0 | AX29: 0 | AY29: 0
A30: 27 | B30: VI. Tài sản ngắn hạn khác | C30: 5 | D30: 5314243398 | E30: 6080699504 | F30: 5675443442 | G30: 6125438674 | H30: 8404740511 | I30: 8494741311 | J30: 8916139914 | K30: 26710413192 | L30: 27399882401 | M30: 27226141662 | N30: 28879807729 | O30: 30958179553 | P30: 31389219783 | Q30: 32186724683 | R30: 33833811488 | S30: 36773892175 | T30: 40902724991 | U30: 43653531095 | V30: 44810563156 | W30: 45772154267 | X30: 48034022405 | Y30: 51470376546 | Z30: 55537722150 | AA30: 38196188122 | AB30: 38776985054 | AC30: 41075097228 | AD30: 45117370687 | AE30: 41596951185 | AF30: 45735788339 | AG30: 47103389737 | AH30: 50391945473 | AI30: 52095015441 | AJ30: 49205619205 | AK30: 51840480320 | AL30: 59036767363 | AM30: 41128086110 | AN30: 48329179570 | AO30: 52402682218 | AP30: 53638184536 | AQ30: 60097345927 | AR30: 64480604648 | AS30: 41973464763 | AT30: 46961151962 | AU30: 48551172726 | AV30: 56769861956 | AW30: 59919630029 | AX30: 32117157574 | AY30: 29084385847 | AZ30: 31458565079 | BA30: 32319903285 | BB30: 37507790105 | BC30: 46329177857 | BD30: 54840575232 | BE30: 64471140709 | BF30: 71635917962 | BG30: 42927415798 | BH30: 44075420678 | BI30: 43372545654 | BJ30: 41368771158 | BK30: 19547112019 | BL30: 21453377952 | BM30: 24154779219 | BN30: 25221641625 | BO30: 26322155642 | BP30: 31960741740 | BQ30: 45761413509
A31: 28 | B31: 1.Chi phí chờ phân bổ ngắn hạn | C31: 5 | D31: 113920351 | E31: 94216760 | F31: 80384419 | G31: 60147078 | H31: 281847184 | I31: 255164290 | J31: 228481396 | K31: 201798502 | L31: 252235061 | M31: 260230306 | N31: 888993241 | O31: 907518876 | P31: 940252890 | Q31: 1040629462 | R31: 1046446719 | S31: 1010849671 | T31: 1471987794 | U31: 2225397509 | V31: 2354562379 | W31: 2407816714 | X31: 3022705182 | Y31: 2886832646 | Z31: 3574188446 | AA31: 2848864662 | AB31: 2433524948 | AC31: 2949595697 | AD31: 2636870885 | AE31: 2566632714 | AF31: 2509161957 | AG31: 2767731909 | AH31: 3160400459 | AI31: 3221096592 | AJ31: 3722160941 | AK31: 4095876199 | AL31: 5294410252 | AM31: 5769288291 | AN31: 6276274640 | AO31: 8206749833 | AP31: 7285401121 | AQ31: 8306063236 | AR31: 7856773292 | AS31: 9119226098 | AT31: 10668355095 | AU31: 10679688406 | AV31: 11891411206 | AW31: 10950384630 | AX31: 10029655608 | AY31: 8392710436 | AZ31: 8670624950 | BA31: 9360600777 | BB31: 8963443599 | BC31: 8040678677 | BD31: 6574180345 | BE31: 12024899748 | BF31: 13100177953 | BG31: 13938259781 | BH31: 11177477784 | BI31: 9268450110 | BJ31: 6953960350 | BK31: 6855293515 | BL31: 6232956370 | BM31: 5669668845 | BN31: 6281586071 | BO31: 7111878966 | BP31: 7978130611 | BQ31: 7520241462
A32: 29 | B32: 2.Thuế GTGT được khấu trừ | C32: 5 | D32: 4945420208 | E32: 5731579905 | F32: 5595059023 | G32: 6047726478 | H32: 8122893327 | I32: 8239577021 | J32: 8687658518 | K32: 26508614690 | L32: 27147647340 | M32: 26965911356 | N32: 27990814488 | O32: 29650114756 | P32: 30448966893 | Q32: 31146095221 | R32: 32787364769 | S32: 35763042504 | T32: 39429487284 | U32: 41426883673 | V32: 42456000777 | W32: 43364337553 | X32: 45011317223 | Y32: 48583543900 | Z32: 51963533704 | AA32: 35347323460 | AB32: 36343460106 | AC32: 38125501531 | AD32: 42480499802 | AE32: 37090547319 | AF32: 41231439376 | AG32: 44335657828 | AH32: 47231545014 | AI32: 48873918849 | AJ32: 45483458264 | AK32: 47744604121 | AL32: 53742357111 | AM32: 35358797819 | AN32: 42052904930 | AO32: 44107343223 | AP32: 46297685706 | AQ32: 51762654946 | AR32: 56579510013 | AS32: 32789088899 | AT32: 36250538837 | AU32: 37779613794 | AV32: 44829865745 | AW32: 48921405825 | AX32: 22042451541 | AY32: 20691675411 | AZ32: 22787940129 | BA32: 22955432475 | BB32: 28544346506 | BC32: 38288499180 | BD32: 48266394887 | BE32: 52446240961 | BF32: 58535740009 | BG32: 28989156017 | BH32: 32897942894 | BI32: 34104095544 | BJ32: 34414810808 | BK32: 12691818504 | BL32: 14900314879 | BM32: 18117486770 | BN32: 18457562435 | BO32: 18721692095 | BP32: 23467402224 | BQ32: 38241172047
A33: 30 | B33: 3.Thuế và các khoản khác phải thu Nhà nước | C33: 5 | D33: 254902839 | E33: 254902839 | F33: 0 | G33: 17565118 | H33: 0 | I33: 0 | J33: 0 | K33: 0 | L33: 0 | M33: 0 | N33: 0 | O33: 400545921 | P33: 0 | Q33: 0 | R33: 0 | S33: 0 | T33: 1249913 | U33: 1249913 | V33: 0 | W33: 0 | X33: 0 | Y33: 0 | Z33: 0 | AA33: 0 | AB33: 0 | AC33: 0 | AD33: 0 | AE33: 1939771152 | AF33: 1995187006 | AG33: 0 | AH33: 0 | AI33: 0 | AJ33: 0 | AK33: 0 | AL33: 0 | AM33: 0 | AN33: 0 | AO33: 88589162 | AP33: 55097709 | AQ33: 28627745 | AR33: 44321343 | AS33: 65149766 | AT33: 42258030 | AU33: 91870526 | AV33: 48585005 | AW33: 47839574 | AX33: 45050425 | AY33: 0 | AZ33: 0 | BA33: 3870033 | BB33: 0 | BC33: 0 | BD33: 0 | BE33: 0 | BF33: 0 | BG33: 0 | BH33: 0 | BI33: 0 | BJ33: 0 | BL33: 320106703 | BM33: 367623604 | BN33: 482493119 | BO33: 488584581 | BP33: 515208905
A34: 31 | B34: 4.Giao dịch mua bán lại trái phiếu Chính phủ | C34: 5 | D34: 0 | E34: 0 | F34: 0 | G34: 0 | H34: 0 | I34: 0 | J34: 0 | K34: 0 | L34: 0 | M34: 0 | N34: 0 | O34: 0 | P34: 0 | Q34: 0 | R34: 0 | S34: 0 | T34: 0 | U34: 0 | V34: 0 | W34: 0 | X34: 0 | Y34: 0 | Z34: 0 | AA34: 0 | AB34: 0 | AC34: 0 | AD34: 0 | AE34: 0 | AF34: 0 | AG34: 0 | AH34: 0 | AI34: 0 | AJ34: 0 | AK34: 0 | AL34: 0 | AM34: 0 | AN34: 0 | AO34: 0 | AP34: 0 | AQ34: 0 | AR34: 0 | AS34: 0 | AT34: 0 | AU34: 0 | AV34: 0 | AW34: 0 | AX34: 0 | AY34: 0 | AZ34: 0 | BA34: 0 | BB34: 0 | BC34: 0 | BD34: 0 | BE34: 0 | BF34: 0 | BG34: 0 | BH34: 0 | BI34: 0 | BJ34: 0
A35: 32 | B35: 5.Tài sản ngắn hạn khác | C35: 5 | D35: 0 | E35: 0 | F35: 0 | G35: 0 | H35: 0 | I35: 0 | J35: 0 | K35: 0 | L35: 0 | M35: 0 | N35: 0 | O35: 0 | P35: 0 | Q35: 0 | R35: 0 | S35: 0 | T35: 0 | U35: 0 | V35: 0 | W35: 0 | X35: 0 | Y35: 0 | Z35: 0 | AA35: 0 | AB35: 0 | AC35: 0 | AD35: 0 | AE35: 0 | AF35: 0 | AG35: 0 | AH35: 0 | AI35: 0 | AJ35: 0 | AK35: 0 | AL35: 0 | AM35: 0 | AN35: 0 | AO35: 0 | AP35: 0 | AQ35: 0 | AR35: 0 | AS35: 0 | AT35: 0 | AU35: 0 | AV35: 0 | AW35: 0 | AX35: 0 | AY35: 0 | AZ35: 0 | BA35: 0 | BB35: 0 | BC35: 0 | BD35: 0 | BE35: 0 | BF35: 0 | BG35: 0 | BH35: 0 | BI35: 0 | BJ35: 0
A36: 33 | B36: B-TÀI SẢN DÀI HẠN | C36: 5 | D36: 86880633442 | E36: 94747583376 | F36: 96067304286 | G36: 96848533626 | H36: 101230167312 | I36: 102383852541 | J36: 114536712032 | K36: 291833091169 | L36: 294902635908 | M36: 293648092565 | N36: 295080352755 | O36: 298129911569 | P36: 303264863543 | Q36: 303407795286 | R36: 301700774855 | S36: 308774390060 | T36: 316298750510 | U36: 323784583220 | V36: 329223426458 | W36: 334959181760 | X36: 349795170793 | Y36: 365984624129 | Z36: 378041902934 | AA36: 204283691303 | AB36: 208231581626 | AC36: 210978078121 | AD36: 216766563234 | AE36: 221271328748 | AF36: 239086746684 | AG36: 241129920093 | AH36: 246491575279 | AI36: 248549355566 | AJ36: 249202945670 | AK36: 260910890965 | AL36: 268719490169 | AM36: =AM44+AM66+AM76 -> 275488564192 | AN36: 274624562032 | AO36: 272308792463 | AP36: 271203283116 | AQ36: 270904814396 | AR36: 269907328559 | AS36: 270747087858 | AT36: 268779207254 | AU36: 274334422235 | AV36: 273134422792 | AW36: 272293558516 | AX36: 273153529742 | AY36: 285939000851 | AZ36: 289379194755 | BA36: 285515570351 | BB36: 287407502163 | BC36: 294777015341 | BD36: 299380289162 | BE36: 300166972168 | BF36: 296753996838 | BG36: 296192973827 | BH36: 304334630215 | BI36: 316482947135 | BJ36: 315796830828 | BK36: 320800563599 | BL36: 317415705891 | BM36: 337499929442 | BN36: 343594894451 | BO36: 365048803536 | BP36: 365314011891 | BQ36: 495399222088
A37: 34 | B37: I.Các khoản phải thu dài hạn | C37: 5 | D37: 0 | E37: 0 | F37: 0 | G37: 0 | H37: 0 | I37: 0 | J37: 0 | K37: 0 | L37: 0 | M37: 0 | N37: 0 | O37: 0 | P37: 0 | Q37: 0 | R37: 0 | S37: 0 | T37: 0 | U37: 0 | V37: 0 | W37: 0 | X37: 0 | Y37: 0 | Z37: 0 | AA37: 0 | AB37: 0 | AC37: 0 | AD37: 0 | AE37: 0 | AF37: 0 | AG37: 0 | AH37: 0 | AI37: 0 | AJ37: 0 | AK37: 0 | AL37: 0 | AM37: 0 | AN37: 0 | AO37: 0 | AP37: 0 | AQ37: 0 | AR37: 0 | AS37: 0 | AT37: 0 | AU37: 0 | AV37: 0 | AW37: 0 | AX37: 0 | AY37: 5600000000 | AZ37: 5600000000 | BA37: 5600000000 | BB37: 5600000000 | BC37: 5600000000 | BD37: 5600000000 | BE37: 5600000000 | BF37: 5600000000 | BG37: 5600000000 | BH37: 5600000000 | BI37: 5600000000 | BJ37: 5600000000 | BK37: 5600000000 | BL37: 5315314211 | BM37: 5315314211 | BN37: 5315314211 | BO37: 5315314210 | BP37: 5315314210 | BQ37: 5315314210
A38: 35 | B38: 1.Phải thu dài hạn của khách hàng | C38: 5 | D38: 0 | E38: 0 | F38: 0 | G38: 0 | H38: 0 | I38: 0 | J38: 0 | K38: 0 | L38: 0 | M38: 0 | N38: 0 | O38: 0 | P38: 0 | Q38: 0 | R38: 0 | S38: 0 | T38: 0 | U38: 0 | V38: 0 | W38: 0 | X38: 0 | Y38: 0 | Z38: 0 | AA38: 0 | AB38: 0 | AC38: 0 | AD38: 0 | AE38: 0 | AF38: 0 | AG38: 0 | AH38: 0 | AI38: 0 | AJ38: 0 | AK38: 0 | AL38: 0 | AM38: 0 | AN38: 0 | AO38: 0 | AP38: 0 | AQ38: 0 | AR38: 0 | AS38: 0 | AT38: 0 | AU38: 0 | AV38: 0 | AW38: 0 | AX38: 0 | AY38: 0 | AZ38: 0 | BA38: 0 | BB38: 0 | BC38: 0 | BD38: 0 | BE38: 0 | BF38: 0 | BG38: 0 | BH38: 0 | BI38: 0 | BJ38: 0
A39: 36 | B39: 2.Trả trước cho người bán dài hạn | C39: 5 | D39: 0 | E39: 0 | F39: 0 | G39: 0 | H39: 0 | I39: 0 | J39: 0 | K39: 0 | L39: 0 | M39: 0 | N39: 0 | O39: 0 | P39: 0 | Q39: 0 | R39: 0 | S39: 0 | T39: 0 | U39: 0 | V39: 0 | W39: 0 | X39: 0 | Y39: 0 | Z39: 0 | AA39: 0 | AB39: 0 | AC39: 0 | AD39: 0 | AE39: 0 | AF39: 0 | AG39: 0 | AH39: 0 | AI39: 0 | AJ39: 0 | AK39: 0 | AL39: 0 | AM39: 0 | AN39: 0 | AO39: 0 | AP39: 0 | AQ39: 0 | AR39: 0 | AS39: 0 | AT39: 0 | AU39: 0 | AV39: 0 | AW39: 0 | AX39: 0 | AY39: 0 | AZ39: 0 | BA39: 0 | BB39: 0 | BC39: 0 | BD39: 0 | BE39: 0 | BF39: 0 | BG39: 0 | BH39: 0 | BI39: 0 | BJ39: 0
