Workbook

Sheet Thong tin
A1: CÔNG TY TNHH THU MUA PHẾ LIỆU KHÁNH NGA
A2: Địa chỉ:
A3: Mã số thuế:
A4: Deadline ngày 5 tây hàng tháng
B6: Năm tài chính hiện tại | C6: 2026
B7: Năm trước | C7: =C6-1 -> 2025
B9: Tháng báo cáo hiện tại | C9: 5
B12: NGƯỜI LẬP BIỂU
B15: KẾ TOÁN TRƯỞNG
B18: GIÁM ĐỐC TÀI CHÍNH

Sheet BIA
B29: THÁNG 02 NĂM 2026
B50: Thành phố Hồ Chí Minh, Ngày 28 tháng 02 năm 2026

Sheet Index
A1: ='Thong tin'!A1 -> CÔNG TY TNHH THU MUA PHẾ LIỆU KHÁNH NGA | I1: BÁO CÁO TÀI CHÍNH
A2: ='Thong tin'!A2 -> Địa chỉ:
A10: ="BÁO CÁO TÀI CHÍNH THÁNG "&'Thong tin'!C9&" NĂM 2026" -> BÁO CÁO TÀI CHÍNH THÁNG 5 NĂM 2026 | I10: Trang
A12: BÁO CÁO CỦA BAN GIÁM ĐỐC | I12: 2 - 3
A13: BÁO CÁO KIỂM TOÁN | I13: 4 - 4
A14: - Bảng cân đối kế toán | I14: 1 - 4
A15: - Báo cáo kết quả hoạt động kinh doanh | I15: 5
A16: - Báo cáo lưu chuyển tiền tệ | I16: 6 - 7
A17: - Bản thuyết minh báo cáo tài chính | I17: 11 - 31
A30: (Báo cáo tài chính được lập và trình bày theo Quyết định số 15/2006/QĐ-BTC ngày 20/03/2006
A31: của Bộ trưởng Bộ Tài Chính)

Sheet THTC in
A1: ='Thong tin'!$A$1 -> CÔNG TY TNHH THU MUA PHẾ LIỆU KHÁNH NGA
A2: ='Thong tin'!$A$2 -> Địa chỉ:
A4: BÁO CÁO TÌNH HÌNH TÀI CHÍNH
A5: ="Năm " & 'Thong tin'!$C$6 -> Năm 2026
C6: ='KQKD in'!G6 -> ĐVT: VNĐ
A7: TÀI SẢN | B7: ="Số cuối tháng"&" "&$D$7 -> Số cuối tháng 5 | C7: ="Số dư đầu năm " & 'Thong tin'!$C$6 -> Số dư đầu năm 2026 | D7: 5
A8: A . TÀI SẢN NGẮN HẠN | B8: =B10+B14+B22+B31+B40 -> 19257599078 | C8: =C10+C14+C22+C31+C40 -> 17398509917
A10: I. Tiền và các khoản tương đương tiền | B10: =SUM(B11:B12) -> 4265994913 | C10: =SUM(C11:C12) -> 8999449324
A11: 1. Tiền | B11: =OFFSET('Tinh hinh tai chinh'!$BL6,0,'THTC in'!$D$7 - 1) -> 1265994913 | C11: ='Tinh hinh tai chinh'!BL6 -> 2999449324
A12: 2. Các khoản tương đương tiền | B12: =OFFSET('Tinh hinh tai chinh'!$BL7,0,'THTC in'!$D$7 - 1) -> 3000000000 | C12: ='Tinh hinh tai chinh'!BL7 -> 6000000000
A14: II. Các khoản đầu tư tài chính ngắn hạn | B14: =SUM(B15:B20) -> 1000000000 | C14: =SUM(C15:C20) -> 0
A15: 1.Chứng khoán kinh doanh | B15: =OFFSET('Tinh hinh tai chinh'!$BL9,0,'THTC in'!$D$7 - 1) -> 0 | C15: ='Tinh hinh tai chinh'!BK9 -> 0
A16: 2.Dự phòng giảm giá chứng khoán kinh doanh (*) | B16: =OFFSET('Tinh hinh tai chinh'!$BL10,0,'THTC in'!$D$7 - 1) -> 0 | C16: ='Tinh hinh tai chinh'!BK10 -> 0
A17: 3.Đầu tư nắm giữ đến ngày đáo hạn ngắn hạn | B17: =OFFSET('Tinh hinh tai chinh'!$BL11,0,'THTC in'!$D$7 - 1) -> 1000000000 | C17: ='Tinh hinh tai chinh'!BK11 -> 0
A18: 4.Dự phòng đầu tư nắm giữ đến ngày đáo hạn ngắn hạn (*) | B18: =OFFSET('Tinh hinh tai chinh'!$BL12,0,'THTC in'!$D$7 - 1) -> 0 | C18: ='Tinh hinh tai chinh'!BK12 -> 0
A19: 5.Đầu tư ngắn hạn khác | B19: =OFFSET('Tinh hinh tai chinh'!$BL13,0,'THTC in'!$D$7 - 1) -> 0 | C19: ='Tinh hinh tai chinh'!BK13 -> 0
A20: 6.Dự phòng tổn thất các khoản đầu tư ngắn hạn khác (*) | B20: =OFFSET('Tinh hinh tai chinh'!$BL14,0,'THTC in'!$D$7 - 1) -> 0 | C20: ='Tinh hinh tai chinh'!BK14 -> 0
A22: III. Các khoản phải thu ngắn hạn | B22: =SUM(B23:B29) -> 4109614535 | C22: =SUM(C23:C29) -> 2027514130
A23: 1.Phải thu ngắn hạn của khách hàng | B23: =OFFSET('Tinh hinh tai chinh'!$BL16,0,'THTC in'!$D$7 - 1) -> 1482666995 | C23: ='Tinh hinh tai chinh'!BL16 -> 130705920
A24: 2.Trả trước cho người bán ngắn hạn | B24: =OFFSET('Tinh hinh tai chinh'!$BL17,0,'THTC in'!$D$7 - 1) -> 284717973 | C24: ='Tinh hinh tai chinh'!BL17 -> 874147973
A25: 3.Phải thu nội bộ ngắn hạn | B25: =OFFSET('Tinh hinh tai chinh'!$BL18,0,'THTC in'!$D$7 - 1) -> 0 | C25: ='Tinh hinh tai chinh'!BK18 -> 0
A26: 4.Phải thu theo tiến độ hợp đồng xây dựng | B26: =OFFSET('Tinh hinh tai chinh'!$BL19,0,'THTC in'!$D$7 - 1) -> 0 | C26: ='Tinh hinh tai chinh'!BK19 -> 0
A27: 5.Phải thu ngắn hạn khác | B27: =OFFSET('Tinh hinh tai chinh'!$BL20,0,'THTC in'!$D$7 - 1) -> 2342229567 | C27: ='Tinh hinh tai chinh'!BL20 -> 1022660237
A28: 6.Dự phòng phải thu ngắn hạn khó đòi (*) | B28: =OFFSET('Tinh hinh tai chinh'!$BL21,0,'THTC in'!$D$7 - 1) -> 0 | C28: ='Tinh hinh tai chinh'!BK21 -> 0
A29: 7.Tài sản thiếu chờ xử lý | B29: =OFFSET('Tinh hinh tai chinh'!$BL22,0,'THTC in'!$D$7 - 1) -> 0 | C29: ='Tinh hinh tai chinh'!BK22 -> 0
A31: IV. Hàng tồn kho | B31: =SUM(B32:B33) -> 8989031026 | C31: =SUM(C32:C33) -> 5045758048
A32: 1. Hàng tồn kho | B32: =OFFSET('Tinh hinh tai chinh'!$BL24,0,'THTC in'!$D$7 - 1) -> 8989031026 | C32: ='Tinh hinh tai chinh'!BL24 -> 5045758048
A33: 2. Dự phòng giảm giá hàng tồn kho (*) | B33: =OFFSET('Tinh hinh tai chinh'!$BL25,0,'THTC in'!$D$7 - 1) -> 0 | C33: ='Tinh hinh tai chinh'!BK25 -> 0
A35: V. Tài sản sinh học ngắn hạn | B35: =SUM(B36:B38) -> 0 | C35: =SUM(C36:C38) -> 0
A36: 1.Súc vật nuôi lấy sản phẩm một lần ngắn hạn | B36: =OFFSET('Tinh hinh tai chinh'!$BL27,0,'THTC in'!$D$7 - 1) -> 0 | C36: ='Tinh hinh tai chinh'!BK27 -> 0
A37: 2.Cây trồng theo mùa vụ hoặc lấy sản phẩm một lần ngắn hạn | B37: =OFFSET('Tinh hinh tai chinh'!$BL28,0,'THTC in'!$D$7 - 1) -> 0 | C37: ='Tinh hinh tai chinh'!BK28 -> 0
A38: 3.Dự phòng tổn thất tài sản sinh học ngắn hạn (*) | B38: =OFFSET('Tinh hinh tai chinh'!$BL29,0,'THTC in'!$D$7 - 1) -> 0 | C38: ='Tinh hinh tai chinh'!BK29 -> 0
A40: VI. Tài sản ngắn hạn khác | B40: =SUM(B41:B45) -> 892958604 | C40: =SUM(C41:C45) -> 1325788415
A41: 1.Chi phí chờ phân bổ ngắn hạn | B41: =OFFSET('Tinh hinh tai chinh'!$BL31,0,'THTC in'!$D$7 - 1) -> 892958604 | C41: ='Tinh hinh tai chinh'!BL31 -> 1325788415
A42: 2.Thuế GTGT được khấu trừ | B42: =OFFSET('Tinh hinh tai chinh'!$BL32,0,'THTC in'!$D$7 - 1) -> 0 | C42: ='Tinh hinh tai chinh'!BK32 -> 0
A43: 3.Thuế và các khoản khác phải thu Nhà nước | B43: =OFFSET('Tinh hinh tai chinh'!$BL33,0,'THTC in'!$D$7 - 1) -> 0 | C43: ='Tinh hinh tai chinh'!BL33 -> 0
A44: 4.Giao dịch mua bán lại trái phiếu Chính phủ | B44: =OFFSET('Tinh hinh tai chinh'!$BL34,0,'THTC in'!$D$7 - 1) -> 0 | C44: ='Tinh hinh tai chinh'!BK34 -> 0
A45: 5.Tài sản ngắn hạn khác | B45: =OFFSET('Tinh hinh tai chinh'!$BL35,0,'THTC in'!$D$7 - 1) -> 0 | C45: ='Tinh hinh tai chinh'!BK35 -> 0
A47: B. TÀI SẢN DÀI HẠN | B47: =B48+B58+B79+B87+B95+B83 -> 6901738911 | C47: =C48+C58+C79+C87+C95+C83 -> 6404349557
A48: I.Các khoản phải thu dài hạn | B48: =SUM(B49:B54) -> 0 | C48: =SUM(C49:C54) -> 0
...

Sheet KQKD in
A1: ='Thong tin'!$A$1 -> CÔNG TY TNHH THU MUA PHẾ LIỆU KHÁNH NGA
A2: ='Thong tin'!$A$2 -> Địa chỉ:
A4: BÁO CÁO KẾT QUẢ HOẠT ĐỘNG KINH DOANH
A5: ="Năm " & 'Thong tin'!$C$6 -> Năm 2026
G6: ĐVT: VNĐ
A8: Chỉ tiêu | D8: ="Tháng "&'Thong tin'!$C$9 -> Tháng 5 | F8: ="Lũy kế"&" "&'Thong tin'!$C$9 &" "&"tháng" -> Lũy kế 5 tháng
D9: ="Năm " & 'Thong tin'!$C$6 -> Năm 2026 | E9: ="Năm " & 'Thong tin'!$C$7 -> Năm 2025 | F9: ="Năm " & 'Thong tin'!$C$6 -> Năm 2026 | G9: ="Năm " & 'Thong tin'!$C$7 -> Năm 2025
A10: 1. | B10: Doanh thu bán hàng và cung cấp dịch vụ | D10: =OFFSET('Ket qua kinh doanh'!$BL5,0,'Thong tin'!$C$9 - 1) -> 12123223250 | E10: =OFFSET('Ket qua kinh doanh'!$AZ5,0,'Thong tin'!$C$9 - 1) -> 8388349104 | F10: {=_xlfn.SWITCH(TRUE(), 'Thong tin'!$C$6=2021, SUM(OFFSET('Ket qua kinh doanh'!$D5,0,0,1,'Thong tin'!$C$9)), 'Thong tin'!$C$6=2022, SUM(OFFSET('Ket qua kinh doanh'!$P5,0,0,1,'Thong tin'!$C$9)), 'Thong tin'!$C$6=2023, SUM(OFFSET('Ket qua kinh doanh'!$AB5,0,0,1,'Thong tin'!$C$9)), 'Thong tin'!$C$6=2024, SUM(OFFSET('Ket qua kinh doanh'!$AN5,0,0,1,'Thong tin'!$C$9)), 'Thong tin'!$C$6=2025, SUM(OFFSET('Ket qua kinh doanh'!$AZ5,0,0,1,'Thong tin'!$C$9)), 'Thong tin'!$C$6=2026, SUM(OFFSET('Ket qua kinh doanh'!$BL5,0,0,1,'Thong tin'!$C$9)) )} -> 45601638252 | G10: {=_xlfn.SWITCH(TRUE(), 'Thong tin'!$C$7=2021, SUM(OFFSET('Ket qua kinh doanh'!$D5,0,0,1,'Thong tin'!$C$9)), 'Thong tin'!$C$7=2022, SUM(OFFSET('Ket qua kinh doanh'!$P5,0,0,1,'Thong tin'!$C$9)), 'Thong tin'!$C$7=2023, SUM(OFFSET('Ket qua kinh doanh'!$AB5,0,0,1,'Thong tin'!$C$9)), 'Thong tin'!$C$7=2024, SUM(OFFSET('Ket qua kinh doanh'!$AN5,0,0,1,'Thong tin'!$C$9)), 'Thong tin'!$C$7=2025, SUM(OFFSET('Ket qua kinh doanh'!$AZ5,0,0,1,'Thong tin'!$C$9)), 'Thong tin'!$C$7=2026, SUM(OFFSET('Ket qua kinh doanh'!$BL5,0,0,1,'Thong tin'!$C$9)) )} -> 34979057663
A11: 2. | B11: Các khoản giảm trừ doanh thu | D11: =OFFSET('Ket qua kinh doanh'!$BL6,0,'Thong tin'!$C$9 - 1) -> 0 | E11: =OFFSET('Ket qua kinh doanh'!$AZ6,0,'Thong tin'!$C$9 - 1) -> 0 | F11: {=_xlfn.SWITCH(TRUE(), 'Thong tin'!$C$6=2021, SUM(OFFSET('Ket qua kinh doanh'!$D6,0,0,1,'Thong tin'!$C$9)), 'Thong tin'!$C$6=2022, SUM(OFFSET('Ket qua kinh doanh'!$P6,0,0,1,'Thong tin'!$C$9)), 'Thong tin'!$C$6=2023, SUM(OFFSET('Ket qua kinh doanh'!$AB6,0,0,1,'Thong tin'!$C$9)), 'Thong tin'!$C$6=2024, SUM(OFFSET('Ket qua kinh doanh'!$AN6,0,0,1,'Thong tin'!$C$9)), 'Thong tin'!$C$6=2025, SUM(OFFSET('Ket qua kinh doanh'!$AZ6,0,0,1,'Thong tin'!$C$9)), 'Thong tin'!$C$6=2026, SUM(OFFSET('Ket qua kinh doanh'!$BL6,0,0,1,'Thong tin'!$C$9)) )} -> 0 | G11: {=_xlfn.SWITCH(TRUE(), 'Thong tin'!$C$7=2021, SUM(OFFSET('Ket qua kinh doanh'!$D6,0,0,1,'Thong tin'!$C$9)), 'Thong tin'!$C$7=2022, SUM(OFFSET('Ket qua kinh doanh'!$P6,0,0,1,'Thong tin'!$C$9)), 'Thong tin'!$C$7=2023, SUM(OFFSET('Ket qua kinh doanh'!$AB6,0,0,1,'Thong tin'!$C$9)), 'Thong tin'!$C$7=2024, SUM(OFFSET('Ket qua kinh doanh'!$AN6,0,0,1,'Thong tin'!$C$9)), 'Thong tin'!$C$7=2025, SUM(OFFSET('Ket qua kinh doanh'!$AZ6,0,0,1,'Thong tin'!$C$9)), 'Thong tin'!$C$7=2026, SUM(OFFSET('Ket qua kinh doanh'!$BL6,0,0,1,'Thong tin'!$C$9)) )} -> 0
A12: 3. | B12: Doanh thu thuần về bán hàng và cung cấp dịch vụ | D12: =OFFSET('Ket qua kinh doanh'!$BL7,0,'Thong tin'!$C$9 - 1) -> 12123223250 | E12: =OFFSET('Ket qua kinh doanh'!$AZ7,0,'Thong tin'!$C$9 - 1) -> 8388349104 | F12: {=_xlfn.SWITCH(TRUE(), 'Thong tin'!$C$6=2021, SUM(OFFSET('Ket qua kinh doanh'!$D7,0,0,1,'Thong tin'!$C$9)), 'Thong tin'!$C$6=2022, SUM(OFFSET('Ket qua kinh doanh'!$P7,0,0,1,'Thong tin'!$C$9)), 'Thong tin'!$C$6=2023, SUM(OFFSET('Ket qua kinh doanh'!$AB7,0,0,1,'Thong tin'!$C$9)), 'Thong tin'!$C$6=2024, SUM(OFFSET('Ket qua kinh doanh'!$AN7,0,0,1,'Thong tin'!$C$9)), 'Thong tin'!$C$6=2025, SUM(OFFSET('Ket qua kinh doanh'!$AZ7,0,0,1,'Thong tin'!$C$9)), 'Thong tin'!$C$6=2026, SUM(OFFSET('Ket qua kinh doanh'!$BL7,0,0,1,'Thong tin'!$C$9)) )} -> 45601638252 | G12: {=_xlfn.SWITCH(TRUE(), 'Thong tin'!$C$7=2021, SUM(OFFSET('Ket qua kinh doanh'!$D7,0,0,1,'Thong tin'!$C$9)), 'Thong tin'!$C$7=2022, SUM(OFFSET('Ket qua kinh doanh'!$P7,0,0,1,'Thong tin'!$C$9)), 'Thong tin'!$C$7=2023, SUM(OFFSET('Ket qua kinh doanh'!$AB7,0,0,1,'Thong tin'!$C$9)), 'Thong tin'!$C$7=2024, SUM(OFFSET('Ket qua kinh doanh'!$AN7,0,0,1,'Thong tin'!$C$9)), 'Thong tin'!$C$7=2025, SUM(OFFSET('Ket qua kinh doanh'!$AZ7,0,0,1,'Thong tin'!$C$9)), 'Thong tin'!$C$7=2026, SUM(OFFSET('Ket qua kinh doanh'!$BL7,0,0,1,'Thong tin'!$C$9)) )} -> 34979057663
A13: 4. | B13: Giá vốn hàng bán | D13: =OFFSET('Ket qua kinh doanh'!$BL8,0,'Thong tin'!$C$9 - 1) -> 10499325346 | E13: =OFFSET('Ket qua kinh doanh'!$AZ8,0,'Thong tin'!$C$9 - 1) -> 7739685565 | F13: {=_xlfn.SWITCH(TRUE(), 'Thong tin'!$C$6=2021, SUM(OFFSET('Ket qua kinh doanh'!$D8,0,0,1,'Thong tin'!$C$9)), 'Thong tin'!$C$6=2022, SUM(OFFSET('Ket qua kinh doanh'!$P8,0,0,1,'Thong tin'!$C$9)), 'Thong tin'!$C$6=2023, SUM(OFFSET('Ket qua kinh doanh'!$AB8,0,0,1,'Thong tin'!$C$9)), 'Thong tin'!$C$6=2024, SUM(OFFSET('Ket qua kinh doanh'!$AN8,0,0,1,'Thong tin'!$C$9)), 'Thong tin'!$C$6=2025, SUM(OFFSET('Ket qua kinh doanh'!$AZ8,0,0,1,'Thong tin'!$C$9)), 'Thong tin'!$C$6=2026, SUM(OFFSET('Ket qua kinh doanh'!$BL8,0,0,1,'Thong tin'!$C$9)) )} -> 39700166595 | G13: {=_xlfn.SWITCH(TRUE(), 'Thong tin'!$C$7=2021, SUM(OFFSET('Ket qua kinh doanh'!$D8,0,0,1,'Thong tin'!$C$9)), 'Thong tin'!$C$7=2022, SUM(OFFSET('Ket qua kinh doanh'!$P8,0,0,1,'Thong tin'!$C$9)), 'Thong tin'!$C$7=2023, SUM(OFFSET('Ket qua kinh doanh'!$AB8,0,0,1,'Thong tin'!$C$9)), 'Thong tin'!$C$7=2024, SUM(OFFSET('Ket qua kinh doanh'!$AN8,0,0,1,'Thong tin'!$C$9)), 'Thong tin'!$C$7=2025, SUM(OFFSET('Ket qua kinh doanh'!$AZ8,0,0,1,'Thong tin'!$C$9)), 'Thong tin'!$C$7=2026, SUM(OFFSET('Ket qua kinh doanh'!$BL8,0,0,1,'Thong tin'!$C$9)) )} -> 33684313417
A14: 5. | B14: Lợi nhuận gộp về bán hàng và cung cấp dịch vụ | D14: =OFFSET('Ket qua kinh doanh'!$BL9,0,'Thong tin'!$C$9 - 1) -> 1623897904 | E14: =OFFSET('Ket qua kinh doanh'!$AZ9,0,'Thong tin'!$C$9 - 1) -> 648663539 | F14: {=_xlfn.SWITCH(TRUE(), 'Thong tin'!$C$6=2021, SUM(OFFSET('Ket qua kinh doanh'!$D9,0,0,1,'Thong tin'!$C$9)), 'Thong tin'!$C$6=2022, SUM(OFFSET('Ket qua kinh doanh'!$P9,0,0,1,'Thong tin'!$C$9)), 'Thong tin'!$C$6=2023, SUM(OFFSET('Ket qua kinh doanh'!$AB9,0,0,1,'Thong tin'!$C$9)), 'Thong tin'!$C$6=2024, SUM(OFFSET('Ket qua kinh doanh'!$AN9,0,0,1,'Thong tin'!$C$9)), 'Thong tin'!$C$6=2025, SUM(OFFSET('Ket qua kinh doanh'!$AZ9,0,0,1,'Thong tin'!$C$9)), 'Thong tin'!$C$6=2026, SUM(OFFSET('Ket qua kinh doanh'!$BL9,0,0,1,'Thong tin'!$C$9)) )} -> 5901471657 | G14: {=_xlfn.SWITCH(TRUE(), 'Thong tin'!$C$7=2021, SUM(OFFSET('Ket qua kinh doanh'!$D9,0,0,1,'Thong tin'!$C$9)), 'Thong tin'!$C$7=2022, SUM(OFFSET('Ket qua kinh doanh'!$P9,0,0,1,'Thong tin'!$C$9)), 'Thong tin'!$C$7=2023, SUM(OFFSET('Ket qua kinh doanh'!$AB9,0,0,1,'Thong tin'!$C$9)), 'Thong tin'!$C$7=2024, SUM(OFFSET('Ket qua kinh doanh'!$AN9,0,0,1,'Thong tin'!$C$9)), 'Thong tin'!$C$7=2025, SUM(OFFSET('Ket qua kinh doanh'!$AZ9,0,0,1,'Thong tin'!$C$9)), 'Thong tin'!$C$7=2026, SUM(OFFSET('Ket qua kinh doanh'!$BL9,0,0,1,'Thong tin'!$C$9)) )} -> 1294744246
A15: 6. | B15: Lãi/lỗ của hoạt động bán, thanh lý bất động sản đầu tư | D15: =OFFSET('Ket qua kinh doanh'!$BL10,0,'Thong tin'!$C$9 - 1) -> 0 | E15: =OFFSET('Ket qua kinh doanh'!$AZ10,0,'Thong tin'!$C$9 - 1) -> 0 | F15: {=_xlfn.SWITCH(TRUE(), 'Thong tin'!$C$6=2021, SUM(OFFSET('Ket qua kinh doanh'!$D10,0,0,1,'Thong tin'!$C$9)), 'Thong tin'!$C$6=2022, SUM(OFFSET('Ket qua kinh doanh'!$P10,0,0,1,'Thong tin'!$C$9)), 'Thong tin'!$C$6=2023, SUM(OFFSET('Ket qua kinh doanh'!$AB10,0,0,1,'Thong tin'!$C$9)), 'Thong tin'!$C$6=2024, SUM(OFFSET('Ket qua kinh doanh'!$AN10,0,0,1,'Thong tin'!$C$9)), 'Thong tin'!$C$6=2025, SUM(OFFSET('Ket qua kinh doanh'!$AZ10,0,0,1,'Thong tin'!$C$9)), 'Thong tin'!$C$6=2026, SUM(OFFSET('Ket qua kinh doanh'!$BL10,0,0,1,'Thong tin'!$C$9)) )} -> 0 | G15: {=_xlfn.SWITCH(TRUE(), 'Thong tin'!$C$7=2021, SUM(OFFSET('Ket qua kinh doanh'!$D10,0,0,1,'Thong tin'!$C$9)), 'Thong tin'!$C$7=2022, SUM(OFFSET('Ket qua kinh doanh'!$P10,0,0,1,'Thong tin'!$C$9)), 'Thong tin'!$C$7=2023, SUM(OFFSET('Ket qua kinh doanh'!$AB10,0,0,1,'Thong tin'!$C$9)), 'Thong tin'!$C$7=2024, SUM(OFFSET('Ket qua kinh doanh'!$AN10,0,0,1,'Thong tin'!$C$9)), 'Thong tin'!$C$7=2025, SUM(OFFSET('Ket qua kinh doanh'!$AZ10,0,0,1,'Thong tin'!$C$9)), 'Thong tin'!$C$7=2026, SUM(OFFSET('Ket qua kinh doanh'!$BL10,0,0,1,'Thong tin'!$C$9)) )} -> 0
A16: 7. | B16: Doanh thu hoạt động tài chính | D16: =OFFSET('Ket qua kinh doanh'!$BL11,0,'Thong tin'!$C$9 - 1) -> 17033 | E16: =OFFSET('Ket qua kinh doanh'!$AZ11,0,'Thong tin'!$C$9 - 1) -> 29738 | F16: {=_xlfn.SWITCH(TRUE(), 'Thong tin'!$C$6=2021, SUM(OFFSET('Ket qua kinh doanh'!$D11,0,0,1,'Thong tin'!$C$9)), 'Thong tin'!$C$6=2022, SUM(OFFSET('Ket qua kinh doanh'!$P11,0,0,1,'Thong tin'!$C$9)), 'Thong tin'!$C$6=2023, SUM(OFFSET('Ket qua kinh doanh'!$AB11,0,0,1,'Thong tin'!$C$9)), 'Thong tin'!$C$6=2024, SUM(OFFSET('Ket qua kinh doanh'!$AN11,0,0,1,'Thong tin'!$C$9)), 'Thong tin'!$C$6=2025, SUM(OFFSET('Ket qua kinh doanh'!$AZ11,0,0,1,'Thong tin'!$C$9)), 'Thong tin'!$C$6=2026, SUM(OFFSET('Ket qua kinh doanh'!$BL11,0,0,1,'Thong tin'!$C$9)) )} -> 49682461 | G16: {=_xlfn.SWITCH(TRUE(), 'Thong tin'!$C$7=2021, SUM(OFFSET('Ket qua kinh doanh'!$D11,0,0,1,'Thong tin'!$C$9)), 'Thong tin'!$C$7=2022, SUM(OFFSET('Ket qua kinh doanh'!$P11,0,0,1,'Thong tin'!$C$9)), 'Thong tin'!$C$7=2023, SUM(OFFSET('Ket qua kinh doanh'!$AB11,0,0,1,'Thong tin'!$C$9)), 'Thong tin'!$C$7=2024, SUM(OFFSET('Ket qua kinh doanh'!$AN11,0,0,1,'Thong tin'!$C$9)), 'Thong tin'!$C$7=2025, SUM(OFFSET('Ket qua kinh doanh'!$AZ11,0,0,1,'Thong tin'!$C$9)), 'Thong tin'!$C$7=2026, SUM(OFFSET('Ket qua kinh doanh'!$BL11,0,0,1,'Thong tin'!$C$9)) )} -> 5638207
A17: 8. | B17: Chi phí tài chính | D17: =OFFSET('Ket qua kinh doanh'!$BL12,0,'Thong tin'!$C$9 - 1) -> 0 | E17: =OFFSET('Ket qua kinh doanh'!$AZ12,0,'Thong tin'!$C$9 - 1) -> 0 | F17: {=_xlfn.SWITCH(TRUE(), 'Thong tin'!$C$6=2021, SUM(OFFSET('Ket qua kinh doanh'!$D12,0,0,1,'Thong tin'!$C$9)), 'Thong tin'!$C$6=2022, SUM(OFFSET('Ket qua kinh doanh'!$P12,0,0,1,'Thong tin'!$C$9)), 'Thong tin'!$C$6=2023, SUM(OFFSET('Ket qua kinh doanh'!$AB12,0,0,1,'Thong tin'!$C$9)), 'Thong tin'!$C$6=2024, SUM(OFFSET('Ket qua kinh doanh'!$AN12,0,0,1,'Thong tin'!$C$9)), 'Thong tin'!$C$6=2025, SUM(OFFSET('Ket qua kinh doanh'!$AZ12,0,0,1,'Thong tin'!$C$9)), 'Thong tin'!$C$6=2026, SUM(OFFSET('Ket qua kinh doanh'!$BL12,0,0,1,'Thong tin'!$C$9)) )} -> 0 | G17: {=_xlfn.SWITCH(TRUE(), 'Thong tin'!$C$7=2021, SUM(OFFSET('Ket qua kinh doanh'!$D12,0,0,1,'Thong tin'!$C$9)), 'Thong tin'!$C$7=2022, SUM(OFFSET('Ket qua kinh doanh'!$P12,0,0,1,'Thong tin'!$C$9)), 'Thong tin'!$C$7=2023, SUM(OFFSET('Ket qua kinh doanh'!$AB12,0,0,1,'Thong tin'!$C$9)), 'Thong tin'!$C$7=2024, SUM(OFFSET('Ket qua kinh doanh'!$AN12,0,0,1,'Thong tin'!$C$9)), 'Thong tin'!$C$7=2025, SUM(OFFSET('Ket qua kinh doanh'!$AZ12,0,0,1,'Thong tin'!$C$9)), 'Thong tin'!$C$7=2026, SUM(OFFSET('Ket qua kinh doanh'!$BL12,0,0,1,'Thong tin'!$C$9)) )} -> 0
B18: Trong đó: chi phí lãi vay | D18: =OFFSET('Ket qua kinh doanh'!$BL13,0,'Thong tin'!$C$9 - 1) -> 0 | E18: =OFFSET('Ket qua kinh doanh'!$AZ13,0,'Thong tin'!$C$9 - 1) -> 0 | F18: {=_xlfn.SWITCH(TRUE(), 'Thong tin'!$C$6=2021, SUM(OFFSET('Ket qua kinh doanh'!$D13,0,0,1,'Thong tin'!$C$9)), 'Thong tin'!$C$6=2022, SUM(OFFSET('Ket qua kinh doanh'!$P13,0,0,1,'Thong tin'!$C$9)), 'Thong tin'!$C$6=2023, SUM(OFFSET('Ket qua kinh doanh'!$AB13,0,0,1,'Thong tin'!$C$9)), 'Thong tin'!$C$6=2024, SUM(OFFSET('Ket qua kinh doanh'!$AN13,0,0,1,'Thong tin'!$C$9)), 'Thong tin'!$C$6=2025, SUM(OFFSET('Ket qua kinh doanh'!$AZ13,0,0,1,'Thong tin'!$C$9)), 'Thong tin'!$C$6=2026, SUM(OFFSET('Ket qua kinh doanh'!$BL13,0,0,1,'Thong tin'!$C$9)) )} -> 0 | G18: {=_xlfn.SWITCH(TRUE(), 'Thong tin'!$C$7=2021, SUM(OFFSET('Ket qua kinh doanh'!$D13,0,0,1,'Thong tin'!$C$9)), 'Thong tin'!$C$7=2022, SUM(OFFSET('Ket qua kinh doanh'!$P13,0,0,1,'Thong tin'!$C$9)), 'Thong tin'!$C$7=2023, SUM(OFFSET('Ket qua kinh doanh'!$AB13,0,0,1,'Thong tin'!$C$9)), 'Thong tin'!$C$7=2024, SUM(OFFSET('Ket qua kinh doanh'!$AN13,0,0,1,'Thong tin'!$C$9)), 'Thong tin'!$C$7=2025, SUM(OFFSET('Ket qua kinh doanh'!$AZ13,0,0,1,'Thong tin'!$C$9)), 'Thong tin'!$C$7=2026, SUM(OFFSET('Ket qua kinh doanh'!$BL13,0,0,1,'Thong tin'!$C$9)) )} -> 0
A19: 9. | B19: Chi phí bán hàng | D19: =OFFSET('Ket qua kinh doanh'!$BL14,0,'Thong tin'!$C$9 - 1) -> 152200000 | E19: =OFFSET('Ket qua kinh doanh'!$AZ14,0,'Thong tin'!$C$9 - 1) -> 111000000 | F19: {=_xlfn.SWITCH(TRUE(), 'Thong tin'!$C$6=2021, SUM(OFFSET('Ket qua kinh doanh'!$D14,0,0,1,'Thong tin'!$C$9)), 'Thong tin'!$C$6=2022, SUM(OFFSET('Ket qua kinh doanh'!$P14,0,0,1,'Thong tin'!$C$9)), 'Thong tin'!$C$6=2023, SUM(OFFSET('Ket qua kinh doanh'!$AB14,0,0,1,'Thong tin'!$C$9)), 'Thong tin'!$C$6=2024, SUM(OFFSET('Ket qua kinh doanh'!$AN14,0,0,1,'Thong tin'!$C$9)), 'Thong tin'!$C$6=2025, SUM(OFFSET('Ket qua kinh doanh'!$AZ14,0,0,1,'Thong tin'!$C$9)), 'Thong tin'!$C$6=2026, SUM(OFFSET('Ket qua kinh doanh'!$BL14,0,0,1,'Thong tin'!$C$9)) )} -> 643600000 | G19: {=_xlfn.SWITCH(TRUE(), 'Thong tin'!$C$7=2021, SUM(OFFSET('Ket qua kinh doanh'!$D14,0,0,1,'Thong tin'!$C$9)), 'Thong tin'!$C$7=2022, SUM(OFFSET('Ket qua kinh doanh'!$P14,0,0,1,'Thong tin'!$C$9)), 'Thong tin'!$C$7=2023, SUM(OFFSET('Ket qua kinh doanh'!$AB14,0,0,1,'Thong tin'!$C$9)), 'Thong tin'!$C$7=2024, SUM(OFFSET('Ket qua kinh doanh'!$AN14,0,0,1,'Thong tin'!$C$9)), 'Thong tin'!$C$7=2025, SUM(OFFSET('Ket qua kinh doanh'!$AZ14,0,0,1,'Thong tin'!$C$9)), 'Thong tin'!$C$7=2026, SUM(OFFSET('Ket qua kinh doanh'!$BL14,0,0,1,'Thong tin'!$C$9)) )} -> 451500000
A20: 10. | B20: Chi phí quản lý doanh nghiệp | D20: =OFFSET('Ket qua kinh doanh'!$BL15,0,'Thong tin'!$C$9 - 1) -> 462618957 | E20: =OFFSET('Ket qua kinh doanh'!$AZ15,0,'Thong tin'!$C$9 - 1) -> 312964157 | F20: {=_xlfn.SWITCH(TRUE(), 'Thong tin'!$C$6=2021, SUM(OFFSET('Ket qua kinh doanh'!$D15,0,0,1,'Thong tin'!$C$9)), 'Thong tin'!$C$6=2022, SUM(OFFSET('Ket qua kinh doanh'!$P15,0,0,1,'Thong tin'!$C$9)), 'Thong tin'!$C$6=2023, SUM(OFFSET('Ket qua kinh doanh'!$AB15,0,0,1,'Thong tin'!$C$9)), 'Thong tin'!$C$6=2024, SUM(OFFSET('Ket qua kinh doanh'!$AN15,0,0,1,'Thong tin'!$C$9)), 'Thong tin'!$C$6=2025, SUM(OFFSET('Ket qua kinh doanh'!$AZ15,0,0,1,'Thong tin'!$C$9)), 'Thong tin'!$C$6=2026, SUM(OFFSET('Ket qua kinh doanh'!$BL15,0,0,1,'Thong tin'!$C$9)) )} -> 1987578782 | G20: {=_xlfn.SWITCH(TRUE(), 'Thong tin'!$C$7=2021, SUM(OFFSET('Ket qua kinh doanh'!$D15,0,0,1,'Thong tin'!$C$9)), 'Thong tin'!$C$7=2022, SUM(OFFSET('Ket qua kinh doanh'!$P15,0,0,1,'Thong tin'!$C$9)), 'Thong tin'!$C$7=2023, SUM(OFFSET('Ket qua kinh doanh'!$AB15,0,0,1,'Thong tin'!$C$9)), 'Thong tin'!$C$7=2024, SUM(OFFSET('Ket qua kinh doanh'!$AN15,0,0,1,'Thong tin'!$C$9)), 'Thong tin'!$C$7=2025, SUM(OFFSET('Ket qua kinh doanh'!$AZ15,0,0,1,'Thong tin'!$C$9)), 'Thong tin'!$C$7=2026, SUM(OFFSET('Ket qua kinh doanh'!$BL15,0,0,1,'Thong tin'!$C$9)) )} -> 1545350395
A21: 11. | B21: Lợi nhuận thuần từ hoạt động kinh doanh | D21: =OFFSET('Ket qua kinh doanh'!$BL16,0,'Thong tin'!$C$9 - 1) -> 1009095980 | E21: =OFFSET('Ket qua kinh doanh'!$AZ16,0,'Thong tin'!$C$9 - 1) -> 224729120 | F21: {=_xlfn.SWITCH(TRUE(), 'Thong tin'!$C$6=2021, SUM(OFFSET('Ket qua kinh doanh'!$D16,0,0,1,'Thong tin'!$C$9)), 'Thong tin'!$C$6=2022, SUM(OFFSET('Ket qua kinh doanh'!$P16,0,0,1,'Thong tin'!$C$9)), 'Thong tin'!$C$6=2023, SUM(OFFSET('Ket qua kinh doanh'!$AB16,0,0,1,'Thong tin'!$C$9)), 'Thong tin'!$C$6=2024, SUM(OFFSET('Ket qua kinh doanh'!$AN16,0,0,1,'Thong tin'!$C$9)), 'Thong tin'!$C$6=2025, SUM(OFFSET('Ket qua kinh doanh'!$AZ16,0,0,1,'Thong tin'!$C$9)), 'Thong tin'!$C$6=2026, SUM(OFFSET('Ket qua kinh doanh'!$BL16,0,0,1,'Thong tin'!$C$9)) )} -> 3319975336 | G21: {=_xlfn.SWITCH(TRUE(), 'Thong tin'!$C$7=2021, SUM(OFFSET('Ket qua kinh doanh'!$D16,0,0,1,'Thong tin'!$C$9)), 'Thong tin'!$C$7=2022, SUM(OFFSET('Ket qua kinh doanh'!$P16,0,0,1,'Thong tin'!$C$9)), 'Thong tin'!$C$7=2023, SUM(OFFSET('Ket qua kinh doanh'!$AB16,0,0,1,'Thong tin'!$C$9)), 'Thong tin'!$C$7=2024, SUM(OFFSET('Ket qua kinh doanh'!$AN16,0,0,1,'Thong tin'!$C$9)), 'Thong tin'!$C$7=2025, SUM(OFFSET('Ket qua kinh doanh'!$AZ16,0,0,1,'Thong tin'!$C$9)), 'Thong tin'!$C$7=2026, SUM(OFFSET('Ket qua kinh doanh'!$BL16,0,0,1,'Thong tin'!$C$9)) )} -> -696467942
A22: 12. | B22: Thu nhập khác | D22: =OFFSET('Ket qua kinh doanh'!$BL17,0,'Thong tin'!$C$9 - 1) -> 145437626 | E22: =OFFSET('Ket qua kinh doanh'!$AZ17,0,'Thong tin'!$C$9 - 1) -> 0 | F22: {=_xlfn.SWITCH(TRUE(), 'Thong tin'!$C$6=2021, SUM(OFFSET('Ket qua kinh doanh'!$D17,0,0,1,'Thong tin'!$C$9)), 'Thong tin'!$C$6=2022, SUM(OFFSET('Ket qua kinh doanh'!$P17,0,0,1,'Thong tin'!$C$9)), 'Thong tin'!$C$6=2023, SUM(OFFSET('Ket qua kinh doanh'!$AB17,0,0,1,'Thong tin'!$C$9)), 'Thong tin'!$C$6=2024, SUM(OFFSET('Ket qua kinh doanh'!$AN17,0,0,1,'Thong tin'!$C$9)), 'Thong tin'!$C$6=2025, SUM(OFFSET('Ket qua kinh doanh'!$AZ17,0,0,1,'Thong tin'!$C$9)), 'Thong tin'!$C$6=2026, SUM(OFFSET('Ket qua kinh doanh'!$BL17,0,0,1,'Thong tin'!$C$9)) )} -> 261493407 | G22: {=_xlfn.SWITCH(TRUE(), 'Thong tin'!$C$7=2021, SUM(OFFSET('Ket qua kinh doanh'!$D17,0,0,1,'Thong tin'!$C$9)), 'Thong tin'!$C$7=2022, SUM(OFFSET('Ket qua kinh doanh'!$P17,0,0,1,'Thong tin'!$C$9)), 'Thong tin'!$C$7=2023, SUM(OFFSET('Ket qua kinh doanh'!$AB17,0,0,1,'Thong tin'!$C$9)), 'Thong tin'!$C$7=2024, SUM(OFFSET('Ket qua kinh doanh'!$AN17,0,0,1,'Thong tin'!$C$9)), 'Thong tin'!$C$7=2025, SUM(OFFSET('Ket qua kinh doanh'!$AZ17,0,0,1,'Thong tin'!$C$9)), 'Thong tin'!$C$7=2026, SUM(OFFSET('Ket qua kinh doanh'!$BL17,0,0,1,'Thong tin'!$C$9)) )} -> 26584470
A23: 13. | B23: Chi phí khác | D23: =OFFSET('Ket qua kinh doanh'!$BL18,0,'Thong tin'!$C$9 - 1) -> 0 | E23: =OFFSET('Ket qua kinh doanh'!$AZ18,0,'Thong tin'!$C$9 - 1) -> 0 | F23: {=_xlfn.SWITCH(TRUE(), 'Thong tin'!$C$6=2021, SUM(OFFSET('Ket qua kinh doanh'!$D18,0,0,1,'Thong tin'!$C$9)), 'Thong tin'!$C$6=2022, SUM(OFFSET('Ket qua kinh doanh'!$P18,0,0,1,'Thong tin'!$C$9)), 'Thong tin'!$C$6=2023, SUM(OFFSET('Ket qua kinh doanh'!$AB18,0,0,1,'Thong tin'!$C$9)), 'Thong tin'!$C$6=2024, SUM(OFFSET('Ket qua kinh doanh'!$AN18,0,0,1,'Thong tin'!$C$9)), 'Thong tin'!$C$6=2025, SUM(OFFSET('Ket qua kinh doanh'!$AZ18,0,0,1,'Thong tin'!$C$9)), 'Thong tin'!$C$6=2026, SUM(OFFSET('Ket qua kinh doanh'!$BL18,0,0,1,'Thong tin'!$C$9)) )} -> 572396 | G23: {=_xlfn.SWITCH(TRUE(), 'Thong tin'!$C$7=2021, SUM(OFFSET('Ket qua kinh doanh'!$D18,0,0,1,'Thong tin'!$C$9)), 'Thong tin'!$C$7=2022, SUM(OFFSET('Ket qua kinh doanh'!$P18,0,0,1,'Thong tin'!$C$9)), 'Thong tin'!$C$7=2023, SUM(OFFSET('Ket qua kinh doanh'!$AB18,0,0,1,'Thong tin'!$C$9)), 'Thong tin'!$C$7=2024, SUM(OFFSET('Ket qua kinh doanh'!$AN18,0,0,1,'Thong tin'!$C$9)), 'Thong tin'!$C$7=2025, SUM(OFFSET('Ket qua kinh doanh'!$AZ18,0,0,1,'Thong tin'!$C$9)), 'Thong tin'!$C$7=2026, SUM(OFFSET('Ket qua kinh doanh'!$BL18,0,0,1,'Thong tin'!$C$9)) )} -> 21650012
A24: 14. | B24: Lợi nhuận khác | D24: =OFFSET('Ket qua kinh doanh'!$BL19,0,'Thong tin'!$C$9 - 1) -> 145437626 | E24: =OFFSET('Ket qua kinh doanh'!$AZ19,0,'Thong tin'!$C$9 - 1) -> 0 | F24: {=_xlfn.SWITCH(TRUE(), 'Thong tin'!$C$6=2021, SUM(OFFSET('Ket qua kinh doanh'!$D19,0,0,1,'Thong tin'!$C$9)), 'Thong tin'!$C$6=2022, SUM(OFFSET('Ket qua kinh doanh'!$P19,0,0,1,'Thong tin'!$C$9)), 'Thong tin'!$C$6=2023, SUM(OFFSET('Ket qua kinh doanh'!$AB19,0,0,1,'Thong tin'!$C$9)), 'Thong tin'!$C$6=2024, SUM(OFFSET('Ket qua kinh doanh'!$AN19,0,0,1,'Thong tin'!$C$9)), 'Thong tin'!$C$6=2025, SUM(OFFSET('Ket qua kinh doanh'!$AZ19,0,0,1,'Thong tin'!$C$9)), 'Thong tin'!$C$6=2026, SUM(OFFSET('Ket qua kinh doanh'!$BL19,0,0,1,'Thong tin'!$C$9)) )} -> 260921011 | G24: {=_xlfn.SWITCH(TRUE(), 'Thong tin'!$C$7=2021, SUM(OFFSET('Ket qua kinh doanh'!$D19,0,0,1,'Thong tin'!$C$9)), 'Thong tin'!$C$7=2022, SUM(OFFSET('Ket qua kinh doanh'!$P19,0,0,1,'Thong tin'!$C$9)), 'Thong tin'!$C$7=2023, SUM(OFFSET('Ket qua kinh doanh'!$AB19,0,0,1,'Thong tin'!$C$9)), 'Thong tin'!$C$7=2024, SUM(OFFSET('Ket qua kinh doanh'!$AN19,0,0,1,'Thong tin'!$C$9)), 'Thong tin'!$C$7=2025, SUM(OFFSET('Ket qua kinh doanh'!$AZ19,0,0,1,'Thong tin'!$C$9)), 'Thong tin'!$C$7=2026, SUM(OFFSET('Ket qua kinh doanh'!$BL19,0,0,1,'Thong tin'!$C$9)) )} -> 4934458
A25: 15. | B25: Tổng lợi nhuận kế toán trước thuế | D25: =OFFSET('Ket qua kinh doanh'!$BL20,0,'Thong tin'!$C$9 - 1) -> 1154533606 | E25: =OFFSET('Ket qua kinh doanh'!$AZ20,0,'Thong tin'!$C$9 - 1) -> 224729120 | F25: {=_xlfn.SWITCH(TRUE(), 'Thong tin'!$C$6=2021, SUM(OFFSET('Ket qua kinh doanh'!$D20,0,0,1,'Thong tin'!$C$9)), 'Thong tin'!$C$6=2022, SUM(OFFSET('Ket qua kinh doanh'!$P20,0,0,1,'Thong tin'!$C$9)), 'Thong tin'!$C$6=2023, SUM(OFFSET('Ket qua kinh doanh'!$AB20,0,0,1,'Thong tin'!$C$9)), 'Thong tin'!$C$6=2024, SUM(OFFSET('Ket qua kinh doanh'!$AN20,0,0,1,'Thong tin'!$C$9)), 'Thong tin'!$C$6=2025, SUM(OFFSET('Ket qua kinh doanh'!$AZ20,0,0,1,'Thong tin'!$C$9)), 'Thong tin'!$C$6=2026, SUM(OFFSET('Ket qua kinh doanh'!$BL20,0,0,1,'Thong tin'!$C$9)) )} -> 3580896347 | G25: {=_xlfn.SWITCH(TRUE(), 'Thong tin'!$C$7=2021, SUM(OFFSET('Ket qua kinh doanh'!$D20,0,0,1,'Thong tin'!$C$9)), 'Thong tin'!$C$7=2022, SUM(OFFSET('Ket qua kinh doanh'!$P20,0,0,1,'Thong tin'!$C$9)), 'Thong tin'!$C$7=2023, SUM(OFFSET('Ket qua kinh doanh'!$AB20,0,0,1,'Thong tin'!$C$9)), 'Thong tin'!$C$7=2024, SUM(OFFSET('Ket qua kinh doanh'!$AN20,0,0,1,'Thong tin'!$C$9)), 'Thong tin'!$C$7=2025, SUM(OFFSET('Ket qua kinh doanh'!$AZ20,0,0,1,'Thong tin'!$C$9)), 'Thong tin'!$C$7=2026, SUM(OFFSET('Ket qua kinh doanh'!$BL20,0,0,1,'Thong tin'!$C$9)) )} -> -691533484
A26: 16. | B26: Chi phí thuế TNDN hiện hành (*) | D26: =OFFSET('Ket qua kinh doanh'!$BL21,0,'Thong tin'!$C$9 - 1) -> 196270713 | E26: =OFFSET('Ket qua kinh doanh'!$AZ21,0,'Thong tin'!$C$9 - 1) -> 0 | F26: {=_xlfn.SWITCH(TRUE(), 'Thong tin'!$C$6=2021, SUM(OFFSET('Ket qua kinh doanh'!$D21,0,0,1,'Thong tin'!$C$9)), 'Thong tin'!$C$6=2022, SUM(OFFSET('Ket qua kinh doanh'!$P21,0,0,1,'Thong tin'!$C$9)), 'Thong tin'!$C$6=2023, SUM(OFFSET('Ket qua kinh doanh'!$AB21,0,0,1,'Thong tin'!$C$9)), 'Thong tin'!$C$6=2024, SUM(OFFSET('Ket qua kinh doanh'!$AN21,0,0,1,'Thong tin'!$C$9)), 'Thong tin'!$C$6=2025, SUM(OFFSET('Ket qua kinh doanh'!$AZ21,0,0,1,'Thong tin'!$C$9)), 'Thong tin'!$C$6=2026, SUM(OFFSET('Ket qua kinh doanh'!$BL21,0,0,1,'Thong tin'!$C$9)) )} -> 608752379 | G26: {=_xlfn.SWITCH(TRUE(), 'Thong tin'!$C$7=2021, SUM(OFFSET('Ket qua kinh doanh'!$D21,0,0,1,'Thong tin'!$C$9)), 'Thong tin'!$C$7=2022, SUM(OFFSET('Ket qua kinh doanh'!$P21,0,0,1,'Thong tin'!$C$9)), 'Thong tin'!$C$7=2023, SUM(OFFSET('Ket qua kinh doanh'!$AB21,0,0,1,'Thong tin'!$C$9)), 'Thong tin'!$C$7=2024, SUM(OFFSET('Ket qua kinh doanh'!$AN21,0,0,1,'Thong tin'!$C$9)), 'Thong tin'!$C$7=2025, SUM(OFFSET('Ket qua kinh doanh'!$AZ21,0,0,1,'Thong tin'!$C$9)), 'Thong tin'!$C$7=2026, SUM(OFFSET('Ket qua kinh doanh'!$BL21,0,0,1,'Thong tin'!$C$9)) )} -> 0
A27: 17. | B27: Chi phí thuế TNDN hoãn lại | D27: =OFFSET('Ket qua kinh doanh'!$BL22,0,'Thong tin'!$C$9 - 1) -> 0 | E27: =OFFSET('Ket qua kinh doanh'!$AZ22,0,'Thong tin'!$C$9 - 1) -> 0 | F27: {=_xlfn.SWITCH(TRUE(), 'Thong tin'!$C$6=2021, SUM(OFFSET('Ket qua kinh doanh'!$D22,0,0,1,'Thong tin'!$C$9)), 'Thong tin'!$C$6=2022, SUM(OFFSET('Ket qua kinh doanh'!$P22,0,0,1,'Thong tin'!$C$9)), 'Thong tin'!$C$6=2023, SUM(OFFSET('Ket qua kinh doanh'!$AB22,0,0,1,'Thong tin'!$C$9)), 'Thong tin'!$C$6=2024, SUM(OFFSET('Ket qua kinh doanh'!$AN22,0,0,1,'Thong tin'!$C$9)), 'Thong tin'!$C$6=2025, SUM(OFFSET('Ket qua kinh doanh'!$AZ22,0,0,1,'Thong tin'!$C$9)), 'Thong tin'!$C$6=2026, SUM(OFFSET('Ket qua kinh doanh'!$BL22,0,0,1,'Thong tin'!$C$9)) )} -> 0 | G27: {=_xlfn.SWITCH(TRUE(), 'Thong tin'!$C$7=2021, SUM(OFFSET('Ket qua kinh doanh'!$D22,0,0,1,'Thong tin'!$C$9)), 'Thong tin'!$C$7=2022, SUM(OFFSET('Ket qua kinh doanh'!$P22,0,0,1,'Thong tin'!$C$9)), 'Thong tin'!$C$7=2023, SUM(OFFSET('Ket qua kinh doanh'!$AB22,0,0,1,'Thong tin'!$C$9)), 'Thong tin'!$C$7=2024, SUM(OFFSET('Ket qua kinh doanh'!$AN22,0,0,1,'Thong tin'!$C$9)), 'Thong tin'!$C$7=2025, SUM(OFFSET('Ket qua kinh doanh'!$AZ22,0,0,1,'Thong tin'!$C$9)), 'Thong tin'!$C$7=2026, SUM(OFFSET('Ket qua kinh doanh'!$BL22,0,0,1,'Thong tin'!$C$9)) )} -> 0
A28: 18. | B28: Lợi nhuận sau thuế | D28: =OFFSET('Ket qua kinh doanh'!$BL23,0,'Thong tin'!$C$9 - 1) -> 958262893 | E28: =OFFSET('Ket qua kinh doanh'!$AZ23,0,'Thong tin'!$C$9 - 1) -> 224729120 | F28: {=_xlfn.SWITCH(TRUE(), 'Thong tin'!$C$6=2021, SUM(OFFSET('Ket qua kinh doanh'!$D23,0,0,1,'Thong tin'!$C$9)), 'Thong tin'!$C$6=2022, SUM(OFFSET('Ket qua kinh doanh'!$P23,0,0,1,'Thong tin'!$C$9)), 'Thong tin'!$C$6=2023, SUM(OFFSET('Ket qua kinh doanh'!$AB23,0,0,1,'Thong tin'!$C$9)), 'Thong tin'!$C$6=2024, SUM(OFFSET('Ket qua kinh doanh'!$AN23,0,0,1,'Thong tin'!$C$9)), 'Thong tin'!$C$6=2025, SUM(OFFSET('Ket qua kinh doanh'!$AZ23,0,0,1,'Thong tin'!$C$9)), 'Thong tin'!$C$6=2026, SUM(OFFSET('Ket qua kinh doanh'!$BL23,0,0,1,'Thong tin'!$C$9)) )} -> 2972143968 | G28: {=_xlfn.SWITCH(TRUE(), 'Thong tin'!$C$7=2021, SUM(OFFSET('Ket qua kinh doanh'!$D23,0,0,1,'Thong tin'!$C$9)), 'Thong tin'!$C$7=2022, SUM(OFFSET('Ket qua kinh doanh'!$P23,0,0,1,'Thong tin'!$C$9)), 'Thong tin'!$C$7=2023, SUM(OFFSET('Ket qua kinh doanh'!$AB23,0,0,1,'Thong tin'!$C$9)), 'Thong tin'!$C$7=2024, SUM(OFFSET('Ket qua kinh doanh'!$AN23,0,0,1,'Thong tin'!$C$9)), 'Thong tin'!$C$7=2025, SUM(OFFSET('Ket qua kinh doanh'!$AZ23,0,0,1,'Thong tin'!$C$9)), 'Thong tin'!$C$7=2026, SUM(OFFSET('Ket qua kinh doanh'!$BL23,0,0,1,'Thong tin'!$C$9)) )} -> -691533484
A29: 19. | B29: Lãi cơ bản trên cổ phiếu | F29: =#REF!+#REF!+#REF!+#REF!+#REF!+#REF!+#REF!+#REF!+#REF!+#REF!+#REF!+D29 -> #REF! | G29: =#REF!+#REF!+#REF!+#REF!+#REF!+#REF!+#REF!+#REF!+#REF!+#REF!+#REF!+E29 -> #REF!
D31: 0 | E31: 0 | F31: 0 | G31: 0
F32: Lập, ngày 28 tháng 02 năm 2026
B34: KẾ TOÁN TRƯỞNG | F34: ='Thong tin'!B18 -> GIÁM ĐỐC TÀI CHÍNH
B41: ='Thong tin'!B13 -> 0 | F41: Nguyễn Bảo Quốc

Sheet LCTT_GT in
A1: ='Thong tin'!$A$1 -> CÔNG TY TNHH THU MUA PHẾ LIỆU KHÁNH NGA
A2: ='Thong tin'!$A$2 -> Địa chỉ:
A4: BÁO CÁO LƯU CHUYỂN TIỀN TỆ
A5: (Theo phương pháp gián tiếp)
A6: ="Năm " & 'Thong tin'!$C$6 -> Năm 2026
E7: ='KQKD in'!G6 -> ĐVT: VNĐ
A8: Chỉ tiêu | B8: ="Tháng " & 'Thong tin'!$C$9 -> Tháng 5 | D8: ="Lũy kế"&" "& 'Thong tin'!$C$9 &" "&"tháng" -> Lũy kế 5 tháng
B9: ="Năm " & 'Thong tin'!$C$6 -> Năm 2026 | C9: ="Năm " & 'Thong tin'!$C$7 -> Năm 2025 | D9: ="Năm " & 'Thong tin'!$C$6 -> Năm 2026 | E9: ="Năm " & 'Thong tin'!$C$7 -> Năm 2025
A10: I. Lưu chuyển tiền từ hoạt động kinh doanh
A11: 1. Lợi nhuận trước thuế | B11: =OFFSET('Luu chuyen tien te'!$BL5,0,'Thong tin'!$C$9 - 1) -> 1154533606 | C11: =OFFSET('Luu chuyen tien te'!$AZ5,0,'Thong tin'!$C$9 - 1) -> 224729120 | D11: =SUM(OFFSET('Luu chuyen tien te'!$BL5,0,0,1,'Thong tin'!$C$9)) -> 3580896347 | E11: =SUM(OFFSET('Luu chuyen tien te'!$AZ5,0,0,1,'Thong tin'!$C$9)) -> -691533484
A12: 2. Điều chỉnh cho các khoản
A13: - Khấu hao tài sản cố định và BĐSĐT | B13: =OFFSET('Luu chuyen tien te'!$BL7,0,'Thong tin'!$C$9 - 1) -> 128899640 | C13: =OFFSET('Luu chuyen tien te'!$AZ7,0,'Thong tin'!$C$9 - 1) -> 161644174 | D13: =SUM(OFFSET('Luu chuyen tien te'!$BL7,0,0,1,'Thong tin'!$C$9)) -> 868937321 | E13: =SUM(OFFSET('Luu chuyen tien te'!$AZ7,0,0,1,'Thong tin'!$C$9)) -> 809475797
A14: - Các khoản dự phòng | B14: =OFFSET('Luu chuyen tien te'!$BL8,0,'Thong tin'!$C$9 - 1) -> 0 | C14: =OFFSET('Luu chuyen tien te'!$AZ8,0,'Thong tin'!$C$9 - 1) -> 0 | D14: =SUM(OFFSET('Luu chuyen tien te'!$BL8,0,0,1,'Thong tin'!$C$9)) -> 0 | E14: =SUM(OFFSET('Luu chuyen tien te'!$AZ8,0,0,1,'Thong tin'!$C$9)) -> 0
A15: - Lãi, lỗ chênh lệch tỷ giá hối đoái do đánh giá lại các khoản mục tiền tệ có gốc ngoại tệ | B15: =OFFSET('Luu chuyen tien te'!$BL9,0,'Thong tin'!$C$9 - 1) -> 0 | C15: =OFFSET('Luu chuyen tien te'!$AZ9,0,'Thong tin'!$C$9 - 1) -> 0 | D15: =SUM(OFFSET('Luu chuyen tien te'!$BL9,0,0,1,'Thong tin'!$C$9)) -> 0 | E15: =SUM(OFFSET('Luu chuyen tien te'!$AZ9,0,0,1,'Thong tin'!$C$9)) -> 0
A16: - Lãi lỗ từ hoạt động đầu tư, tài chính | B16: =OFFSET('Luu chuyen tien te'!$BL10,0,'Thong tin'!$C$9 - 1) -> -17033 | C16: =OFFSET('Luu chuyen tien te'!$AZ10,0,'Thong tin'!$C$9 - 1) -> -29738 | D16: =SUM(OFFSET('Luu chuyen tien te'!$BL10,0,0,1,'Thong tin'!$C$9)) -> -49682461 | E16: =SUM(OFFSET('Luu chuyen tien te'!$AZ10,0,0,1,'Thong tin'!$C$9)) -> -5638207
A17: - Chi phí đi vay | B17: =OFFSET('Luu chuyen tien te'!$BL11,0,'Thong tin'!$C$9 - 1) -> 0 | C17: =OFFSET('Luu chuyen tien te'!$AZ11,0,'Thong tin'!$C$9 - 1) -> 0 | D17: =SUM(OFFSET('Luu chuyen tien te'!$BL11,0,0,1,'Thong tin'!$C$9)) -> 0 | E17: =SUM(OFFSET('Luu chuyen tien te'!$AZ11,0,0,1,'Thong tin'!$C$9)) -> 0
A18: - Các khoản điều chỉnh khác | B18: =OFFSET('Luu chuyen tien te'!$BL12,0,'Thong tin'!$C$9 - 1) -> -196270713 | C18: =OFFSET('Luu chuyen tien te'!$AZ12,0,'Thong tin'!$C$9 - 1) -> 0 | D18: =SUM(OFFSET('Luu chuyen tien te'!$BL12,0,0,1,'Thong tin'!$C$9)) -> -608752379 | E18: =SUM(OFFSET('Luu chuyen tien te'!$AZ12,0,0,1,'Thong tin'!$C$9)) -> 0
A19: 3. Lợi nhuận từ hoạt động kinh doanh trước thay đổi vốn lưu động | B19: =SUM(B11:B18) -> 1087145500 | C19: =SUM(C11:C18) -> 386343556 | D19: =SUM(D11:D18) -> 3791398828 | E19: =SUM(E11:E18) -> 112304106
A20: - Tăng giảm các khoản phải thu | B20: =OFFSET('Luu chuyen tien te'!$BL14,0,'Thong tin'!$C$9 - 1) -> -768010979 | C20: =OFFSET('Luu chuyen tien te'!$AZ14,0,'Thong tin'!$C$9 - 1) -> -1364332338 | D20: =SUM(OFFSET('Luu chuyen tien te'!$BL14,0,0,1,'Thong tin'!$C$9)) -> -905171257 | E20: =SUM(OFFSET('Luu chuyen tien te'!$AZ14,0,0,1,'Thong tin'!$C$9)) -> -1.9270569e+08
A21: - Tăng giảm hàng tồn kho | B21: =OFFSET('Luu chuyen tien te'!$BL15,0,'Thong tin'!$C$9 - 1) -> -3406913583 | C21: =OFFSET('Luu chuyen tien te'!$AZ15,0,'Thong tin'!$C$9 - 1) -> 480844042 | D21: =SUM(OFFSET('Luu chuyen tien te'!$BL15,0,0,1,'Thong tin'!$C$9)) -> -6248922631 | E21: =SUM(OFFSET('Luu chuyen tien te'!$AZ15,0,0,1,'Thong tin'!$C$9)) -> -1.795106e+09
A22: - Tăng giảm các khoản phải trả (Không bao gồm lãi vay phải trả, thuế TNDN phải nộp) | B22: =OFFSET('Luu chuyen tien te'!$BL16,0,'Thong tin'!$C$9 - 1) -> 1488747957 | C22: =OFFSET('Luu chuyen tien te'!$AZ16,0,'Thong tin'!$C$9 - 1) -> -91919914 | D22: =SUM(OFFSET('Luu chuyen tien te'!$BL16,0,0,1,'Thong tin'!$C$9)) -> 812695040 | E22: =SUM(OFFSET('Luu chuyen tien te'!$AZ16,0,0,1,'Thong tin'!$C$9)) -> -2.0744709e+08
A23: - Tăng giảm chi phí chờ phân bổ | B23: =OFFSET('Luu chuyen tien te'!$BL17,0,'Thong tin'!$C$9 - 1) -> 175092383 | C23: =OFFSET('Luu chuyen tien te'!$AZ17,0,'Thong tin'!$C$9 - 1) -> -131767933 | D23: =SUM(OFFSET('Luu chuyen tien te'!$BL17,0,0,1,'Thong tin'!$C$9)) -> 387883253 | E23: =SUM(OFFSET('Luu chuyen tien te'!$AZ17,0,0,1,'Thong tin'!$C$9)) -> 237142574
A24: - Tăng, giảm chứng khoán kinh doanh | B24: =OFFSET('Luu chuyen tien te'!$BL18,0,'Thong tin'!$C$9 - 1) -> 0 | C24: =OFFSET('Luu chuyen tien te'!$AZ18,0,'Thong tin'!$C$9 - 1) -> 0 | D24: =SUM(OFFSET('Luu chuyen tien te'!$BL18,0,0,1,'Thong tin'!$C$9)) -> 0 | E24: =SUM(OFFSET('Luu chuyen tien te'!$AZ18,0,0,1,'Thong tin'!$C$9)) -> 0
A25: - Chi phí đi vay đã trả | B25: =OFFSET('Luu chuyen tien te'!$BL19,0,'Thong tin'!$C$9 - 1) -> 0 | C25: =OFFSET('Luu chuyen tien te'!$AZ19,0,'Thong tin'!$C$9 - 1) -> 0 | D25: =SUM(OFFSET('Luu chuyen tien te'!$BL19,0,0,1,'Thong tin'!$C$9)) -> 0 | E25: =SUM(OFFSET('Luu chuyen tien te'!$AZ19,0,0,1,'Thong tin'!$C$9)) -> 0
A26: - Thuế thu nhập doanh nghiệp đã nộp | B26: =OFFSET('Luu chuyen tien te'!$BL20,0,'Thong tin'!$C$9 - 1) -> 0 | C26: =OFFSET('Luu chuyen tien te'!$AZ20,0,'Thong tin'!$C$9 - 1) -> 0 | D26: =SUM(OFFSET('Luu chuyen tien te'!$BL20,0,0,1,'Thong tin'!$C$9)) -> 0 | E26: =SUM(OFFSET('Luu chuyen tien te'!$AZ20,0,0,1,'Thong tin'!$C$9)) -> 0
A27: - Tiền thu khác từ hoạt động kinh doanh | B27: =OFFSET('Luu chuyen tien te'!$BL21,0,'Thong tin'!$C$9 - 1) -> 0 | C27: =OFFSET('Luu chuyen tien te'!$AZ21,0,'Thong tin'!$C$9 - 1) -> 0 | D27: =SUM(OFFSET('Luu chuyen tien te'!$BL21,0,0,1,'Thong tin'!$C$9)) -> 0 | E27: =SUM(OFFSET('Luu chuyen tien te'!$AZ21,0,0,1,'Thong tin'!$C$9)) -> 0
A28: - Tiền chi khác cho hoạt động kinh doanh | B28: =OFFSET('Luu chuyen tien te'!$BL22,0,'Thong tin'!$C$9 - 1) -> 0 | C28: =OFFSET('Luu chuyen tien te'!$AZ22,0,'Thong tin'!$C$9 - 1) -> 0 | D28: =SUM(OFFSET('Luu chuyen tien te'!$BL22,0,0,1,'Thong tin'!$C$9)) -> 0 | E28: =SUM(OFFSET('Luu chuyen tien te'!$AZ22,0,0,1,'Thong tin'!$C$9)) -> 0
A29: Lưu chuyển tiền thuần từ hoạt động kinh doanh | B29: =SUM(B19:B28) -> -1423938722 | C29: =SUM(C19:C28) -> -720832587 | D29: =SUM(D19:D28) -> -2162116767 | E29: =SUM(E19:E28) -> -1845812086
A30: II. Lưu chuyển tiền từ hoạt động đầu tư
A31: 1. Tiền chi để mua sắm, xây dựng TSCĐ và các tài sản dài hạn khác | B31: =OFFSET('Luu chuyen tien te'!$BL25,0,'Thong tin'!$C$9 - 1) -> -85130340 | C31: =OFFSET('Luu chuyen tien te'!$AZ25,0,'Thong tin'!$C$9 - 1) -> 77500000 | D31: =SUM(OFFSET('Luu chuyen tien te'!$BL25,0,0,1,'Thong tin'!$C$9)) -> -1361625590 | E31: =SUM(OFFSET('Luu chuyen tien te'!$AZ25,0,0,1,'Thong tin'!$C$9)) -> -1273595672
A32: 2. Tiền thu từ thanh lý, nhượng bán TSCĐ và các tài sản dài hạn khác | B32: =OFFSET('Luu chuyen tien te'!$BL26,0,'Thong tin'!$C$9 - 1) -> 0 | C32: =OFFSET('Luu chuyen tien te'!$AZ26,0,'Thong tin'!$C$9 - 1) -> 0 | D32: =SUM(OFFSET('Luu chuyen tien te'!$BL26,0,0,1,'Thong tin'!$C$9)) -> 0 | E32: =SUM(OFFSET('Luu chuyen tien te'!$AZ26,0,0,1,'Thong tin'!$C$9)) -> 0
A33: 3. Tiền chi cho vay, mua các công cụ nợ của đơn vị khác | B33: =OFFSET('Luu chuyen tien te'!$BL27,0,'Thong tin'!$C$9 - 1) -> 0 | C33: =OFFSET('Luu chuyen tien te'!$AZ27,0,'Thong tin'!$C$9 - 1) -> 0 | D33: =SUM(OFFSET('Luu chuyen tien te'!$BL27,0,0,1,'Thong tin'!$C$9)) -> -1000000000 | E33: =SUM(OFFSET('Luu chuyen tien te'!$AZ27,0,0,1,'Thong tin'!$C$9)) -> 0
A34: 4. Tiền thu hồi cho vay, bán lại các công cụ nợ của đơn vị khác | B34: =OFFSET('Luu chuyen tien te'!$BL28,0,'Thong tin'!$C$9 - 1) -> 0 | C34: =OFFSET('Luu chuyen tien te'!$AZ28,0,'Thong tin'!$C$9 - 1) -> 0 | D34: =SUM(OFFSET('Luu chuyen tien te'!$BL28,0,0,1,'Thong tin'!$C$9)) -> 0 | E34: =SUM(OFFSET('Luu chuyen tien te'!$AZ28,0,0,1,'Thong tin'!$C$9)) -> 0
A35: 5. Tiền chi đầu tư góp vốn vào đơn vị khác | B35: =OFFSET('Luu chuyen tien te'!$BL29,0,'Thong tin'!$C$9 - 1) -> 0 | C35: =OFFSET('Luu chuyen tien te'!$AZ29,0,'Thong tin'!$C$9 - 1) -> 0 | D35: =SUM(OFFSET('Luu chuyen tien te'!$BL29,0,0,1,'Thong tin'!$C$9)) -> 0 | E35: =SUM(OFFSET('Luu chuyen tien te'!$AZ29,0,0,1,'Thong tin'!$C$9)) -> 0
A36: 6. Tiền thu hồi đầu tư góp vốn vào đơn vị khác | B36: =OFFSET('Luu chuyen tien te'!$BL30,0,'Thong tin'!$C$9 - 1) -> 0 | C36: =OFFSET('Luu chuyen tien te'!$AZ30,0,'Thong tin'!$C$9 - 1) -> 0 | D36: =SUM(OFFSET('Luu chuyen tien te'!$BL30,0,0,1,'Thong tin'!$C$9)) -> 0 | E36: =SUM(OFFSET('Luu chuyen tien te'!$AZ30,0,0,1,'Thong tin'!$C$9)) -> 0
A37: 7. Tiền thu lãi cho vay, cổ tức và lợi nhuận được chia | B37: =OFFSET('Luu chuyen tien te'!$BL31,0,'Thong tin'!$C$9 - 1) -> 17033 | C37: =OFFSET('Luu chuyen tien te'!$AZ31,0,'Thong tin'!$C$9 - 1) -> 29738 | D37: =SUM(OFFSET('Luu chuyen tien te'!$BL31,0,0,1,'Thong tin'!$C$9)) -> 49682461 | E37: =SUM(OFFSET('Luu chuyen tien te'!$AZ31,0,0,1,'Thong tin'!$C$9)) -> 5638207
A38: Lưu chuyển tiền thuần từ hoạt động đầu tư | B38: =SUM(B31:B37) -> -85113307 | C38: =SUM(C31:C37) -> 77529738 | D38: =SUM(D31:D37) -> -2311943129 | E38: =SUM(E31:E37) -> -1267957465
A39: III. Lưu chuyển tiền từ hoạt động tài chính
A40: 1. Tiền thu từ phát hành cố phiếu, nhận vốn góp của chủ sở hữu | B40: =OFFSET('Luu chuyen tien te'!$BL34,0,'Thong tin'!$C$9 - 1) -> 0 | C40: =OFFSET('Luu chuyen tien te'!$AZ34,0,'Thong tin'!$C$9 - 1) -> 0 | D40: =SUM(OFFSET('Luu chuyen tien te'!$BL34,0,0,1,'Thong tin'!$C$9)) -> 0 | E40: =SUM(OFFSET('Luu chuyen tien te'!$AZ34,0,0,1,'Thong tin'!$C$9)) -> 0
A41: 2. Tiền trả lại vốn góp cho các chủ sở hữu, mua lại cổ phiểu đã phát hành | B41: =OFFSET('Luu chuyen tien te'!$BL35,0,'Thong tin'!$C$9 - 1) -> 0 | C41: =OFFSET('Luu chuyen tien te'!$AZ35,0,'Thong tin'!$C$9 - 1) -> 0 | D41: =SUM(OFFSET('Luu chuyen tien te'!$BL35,0,0,1,'Thong tin'!$C$9)) -> 0 | E41: =SUM(OFFSET('Luu chuyen tien te'!$AZ35,0,0,1,'Thong tin'!$C$9)) -> 0
...

Sheet Tinh hinh tai chinh
B1: CÔNG TY TNHH THU MUA PHẾ LIỆU KHÁNH NGA
B2: VND
A3: Index BS | B3: PHẦN I-BÁO CÁO TÌNH HÌNH TÀI CHÍNH | C3: TenCongTyID | D3: T1.2021 | E3: T02.2021 | F3: T03.2021 | G3: T04.2021 | H3: T05.2021 | I3: T06.2021 | J3: T07.2021 | K3: T08.2021 | L3: T09.2021 | M3: T10.2021 | N3: T11.2021 | O3: T12.2021 | P3: T1.2022 | Q3: T02.2022 | R3: T03.2022 | S3: T04.2022 | T3: T05.2022 | U3: T06.2022 | V3: T07.2022 | W3: T08.2022 | X3: T09.2022 | Y3: T10.2022 | Z3: T11.2022 | AA3: T12.2022 | AB3: T1.2023 | AC3: T02.2023 | AD3: T03.2023 | AE3: T04.2023 | AF3: T05.2023 | AG3: T06.2023 | AH3: T07.2023 | AI3: T08.2023 | AJ3: T09.2023 | AK3: T10.2023 | AL3: T11.2023 | AM3: T12.2023 | AN3: T01.2024 | AO3: T02.2024 | AP3: T03.2024 | AQ3: T04.2024 | AR3: T05.2024 | AS3: T06.2024 | AT3: T07.2024 | AU3: T08.2024 | AV3: T09.2024 | AW3: T10.2024 | AX3: T11.2024 | AY3: T12.2024 | AZ3: T01.2025 | BA3: T02.2025 | BB3: T03.2025 | BC3: T04.2025 | BD3: T05.2025 | BE3: T06.2025 | BF3: T07.2025 | BG3: T08.2025 | BH3: T09.2025 | BI3: T10.2025 | BJ3: T11.2025 | BK3: T12.2025 | BL3: T01.2026 | BM3: T02.2026 | BN3: T03.2026 | BO3: T04.2026 | BP3: T05.2026 | BQ3: T06.2026 | BR3: T07.2026 | BS3: T08.2026 | BT3: T09.2026 | BU3: T10.2026 | BV3: T11.2026 | BW3: T12.2026
A4: 1 | B4: A-TÀI SẢN NGẮN HẠN | C4: 7 | D4: 10331196663 | E4: 10408146462 | F4: 9933109431 | G4: 9393790120 | H4: 9397232004 | I4: 9631832066 | J4: 9485676743 | K4: 9401825682 | L4: 8768034496 | M4: 8768334207 | N4: 8526023049 | O4: 7781530470 | P4: 12936730647 | Q4: 12704314802 | R4: 13104100005 | S4: 13362177273 | T4: 12480060798 | U4: 1.3837075e+10 | V4: 13365189105 | W4: 13693731095 | X4: 14259364412 | Y4: 1.3957162e+10 | Z4: 14315990601 | AA4: 12791999434 | AB4: 11516724529 | AC4: 9693441950 | AD4: 9407542517 | AE4: 10692963222 | AF4: 11998132858 | AG4: 12533847305 | AH4: 10605902581 | AI4: 8517882127 | AJ4: 8.6497339e+09 | AK4: 8.5773245e+09 | AL4: 9.9456558e+09 | AM4: 1.095654e+10 | AN4: 10103114315 | AO4: 10135163319 | AP4: 1.0184981e+10 | AQ4: 9.5553489e+09 | AR4: 9196060410 | AS4: 8684994866 | AT4: 8245968607 | AU4: 10545495550 | AV4: 11220415620 | AW4: 12143594996 | AX4: 11303945554 | AY4: 1.0918507e+10 | AZ4: 9.6224623e+09 | BA4: 10781416982 | BB4: 9.989156e+09 | BC4: 9470285625 | BD4: 9847590487 | BE4: 1.0640908e+10 | BF4: 1.2177668e+10 | BG4: 1.4816286e+10 | BH4: =+BH5+BH8+BH15+BH23+BH30 -> 1.2964527e+10 | BI4: 1.3237896e+10 | BJ4: 1.4247962e+10 | BK4: 16160112648 | BL4: 17398509917 | BM4: 17027930081 | BN4: 18865367170 | BO4: 16681174388 | BP4: 19257599078 | BQ4: 21403899174
A5: 2 | B5: I.Tiền và các khoản tương đương tiền | C5: 7 | D5: 2040300880 | E5: 1772054295 | F5: 915131285 | G5: 314235407 | H5: 469036465 | I5: 419531256 | J5: 26249780 | K5: 1152403903 | L5: 525218020 | M5: 214337661 | N5: 4074278128 | O5: 1960932082 | P5: 6316401318 | Q5: 6401164043 | R5: 7032350604 | S5: 5409143818 | T5: 4843606260 | U5: 4366742904 | V5: 1255875252 | W5: 2620787064 | X5: 3639542113 | Y5: 3359878672 | Z5: 707164873 | AA5: 3956178628 | AB5: 3421434172 | AC5: 1064642852 | AD5: 800358520 | AE5: 2573587564 | AF5: 4046655921 | AG5: 6913231953 | AH5: 5998240929 | AI5: 5522125303 | AJ5: 4466969439 | AK5: 1119051582 | AL5: 862954977 | AM5: 2116625281 | AN5: 2558802474 | AO5: 1393898918 | AP5: 4499399789 | AQ5: 4431257417 | AR5: 2753755390 | AS5: 3803839418 | AT5: 5122409452 | AU5: 6603237668 | AV5: 4901151740 | AW5: 7217320341 | AX5: 6076881148 | AY5: 6003863340 | AZ5: 1083666234 | BA5: 1893084896 | BB5: 3882973993 | BC5: 3533396638 | BD5: 2890093789 | BE5: 4170404441 | BF5: 6295754488 | BG5: 9081751086 | BH5: =+SUM(BH6:BH7) -> 8696224125 | BI5: 8789877445 | BJ5: 8971843955 | BK5: 8740054809 | BL5: 8999449324 | BM5: 6189741551 | BN5: 3726004700 | BO5: 5775046942 | BP5: 4265994913 | BQ5: 2577057383
A6: 3 | B6: 1.Tiền | C6: 7 | D6: 2040300880 | E6: 1772054295 | F6: 915131285 | G6: 314235407 | H6: 469036465 | I6: 419531256 | J6: 26249780 | K6: 1152403903 | L6: 525218020 | M6: 214337661 | N6: 4074278128 | O6: 1960932082 | P6: 6316401318 | Q6: 6401164043 | R6: 7032350604 | S6: 5409143818 | T6: 4843606260 | U6: 4366742904 | V6: 1255875252 | W6: 2620787064 | X6: 3639542113 | Y6: 3359878672 | Z6: 707164873 | AA6: 3956178628 | AB6: 3421434172 | AC6: 1064642852 | AD6: 800358520 | AE6: 2573587564 | AF6: 4046655921 | AG6: 6913231953 | AH6: 5998240929 | AI6: 5522125303 | AJ6: 4466969439 | AK6: 1119051582 | AL6: 862954977 | AM6: 2116625281 | AN6: 2558802474 | AO6: 1393898918 | AP6: 4499399789 | AQ6: 4431257417 | AR6: 2753755390 | AS6: 3803839418 | AT6: 5122409452 | AU6: 6603237668 | AV6: 4901151740 | AW6: 7217320341 | AX6: 6076881148 | AY6: 6003863340 | AZ6: 1083666234 | BA6: 1893084896 | BB6: 3882973993 | BC6: 3533396638 | BD6: 2890093789 | BE6: 4170404441 | BF6: 6295754488 | BG6: 9081751086 | BH6: 8696224125 | BI6: 8789877445 | BJ6: 8971843955 | BK6: 2740054809 | BL6: 2999449324 | BM6: 3189741551 | BN6: 726004700 | BO6: 2775046942 | BP6: 1265994913 | BQ6: 2577057383
A7: 4 | B7: 2.Các khoản tương đương tiền | C7: 7 | D7: 0 | E7: 0 | F7: 0 | G7: 0 | H7: 0 | I7: 0 | J7: 0 | K7: 0 | L7: 0 | M7: 0 | N7: 0 | O7: 0 | P7: 0 | Q7: 0 | R7: 0 | S7: 0 | T7: 0 | U7: 0 | V7: 0 | W7: 0 | X7: 0 | Z7: 0 | AA7: 0 | AB7: 0 | AC7: 0 | AD7: 0 | AE7: 0 | AF7: 0 | AG7: 0 | AH7: 0 | AI7: 0 | AJ7: 0 | AK7: 0 | AL7: 0 | AM7: 0 | AN7: 0 | AO7: 0 | AP7: 0 | AQ7: 0 | AR7: 0 | AS7: 0 | AT7: 0 | AU7: 0 | AV7: 0 | AW7: 0 | AX7: 0 | AY7: 0 | AZ7: 0 | BA7: 0 | BB7: 0 | BC7: 0 | BD7: 0 | BE7: 0 | BF7: 0 | BG7: 0 | BI7: 0 | BK7: 6000000000 | BL7: 6000000000 | BM7: 3000000000 | BN7: 3000000000 | BO7: 3000000000 | BP7: 3000000000 | BQ7: 0
A8: 5 | B8: II.Đầu tư tài chính ngắn hạn | C8: 7 | D8: 0 | E8: 0 | F8: 0 | G8: 0 | H8: 0 | I8: 0 | J8: 0 | K8: 0 | L8: 0 | M8: 0 | N8: 0 | O8: 0 | P8: 0 | Q8: 0 | R8: 0 | S8: 0 | T8: 0 | U8: 0 | V8: 0 | W8: 0 | X8: 0 | Z8: 0 | AA8: 0 | AB8: 0 | AC8: 0 | AD8: 0 | AE8: 0 | AF8: 0 | AG8: 0 | AH8: 0 | AI8: 0 | AJ8: 0 | AK8: 0 | AL8: 0 | AM8: 0 | AN8: 0 | AO8: 0 | AP8: 0 | AQ8: 0 | AR8: 0 | AS8: 0 | AT8: 0 | AU8: 0 | AV8: 0 | AW8: 0 | AX8: 0 | AZ8: 2000000000 | BA8: 0 | BB8: 0 | BC8: 0 | BD8: 0 | BE8: 0 | BF8: 0 | BG8: 0 | BH8: =SUM(BH9:BH11) -> 0 | BI8: 0 | BJ8: 0 | BL8: 0 | BM8: 0 | BN8: 0 | BO8: 1000000000 | BP8: 1000000000 | BQ8: 1000000000
A9: 6 | B9: 1.Chứng khoán kinh doanh | C9: 7 | D9: 0 | E9: 0 | F9: 0 | G9: 0 | H9: 0 | I9: 0 | J9: 0 | K9: 0 | L9: 0 | M9: 0 | N9: 0 | O9: 0 | P9: 0 | Q9: 0 | R9: 0 | S9: 0 | T9: 0 | U9: 0 | V9: 0 | W9: 0 | X9: 0 | Z9: 0 | AA9: 0 | AB9: 0 | AC9: 0 | AD9: 0 | AE9: 0 | AF9: 0 | AG9: 0 | AH9: 0 | AI9: 0 | AJ9: 0 | AK9: 0 | AL9: 0 | AM9: 0 | AN9: 0 | AO9: 0 | AP9: 0 | AQ9: 0 | AR9: 0 | AS9: 0 | AT9: 0 | AU9: 0 | AV9: 0 | AW9: 0 | AX9: 0 | AZ9: 0 | BA9: 0 | BB9: 0 | BC9: 0 | BD9: 0 | BE9: 0 | BF9: 0 | BG9: 0 | BI9: 0 | BL9: 0 | BM9: 0 | BN9: 0 | BO9: 0 | BP9: 0 | BQ9: 0
A10: 7 | B10: 2.Dự phòng giảm giá chứng khoán kinh doanh (*) | C10: 7 | D10: 0 | E10: 0 | F10: 0 | G10: 0 | H10: 0 | I10: 0 | J10: 0 | K10: 0 | L10: 0 | M10: 0 | N10: 0 | O10: 0 | P10: 0 | Q10: 0 | R10: 0 | S10: 0 | T10: 0 | U10: 0 | V10: 0 | W10: 0 | X10: 0 | Z10: 0 | AA10: 0 | AB10: 0 | AC10: 0 | AD10: 0 | AE10: 0 | AF10: 0 | AG10: 0 | AH10: 0 | AI10: 0 | AJ10: 0 | AK10: 0 | AL10: 0 | AM10: 0 | AN10: 0 | AO10: 0 | AP10: 0 | AQ10: 0 | AR10: 0 | AS10: 0 | AT10: 0 | AU10: 0 | AV10: 0 | AW10: 0 | AX10: 0 | AZ10: 0 | BA10: 0 | BB10: 0 | BC10: 0 | BD10: 0 | BE10: 0 | BF10: 0 | BG10: 0 | BI10: 0 | BL10: 0 | BM10: 0 | BN10: 0 | BO10: 0 | BP10: 0 | BQ10: 0
A11: 8 | B11: 3.Đầu tư nắm giữ đến ngày đáo hạn ngắn hạn | C11: 7 | D11: 0 | E11: 0 | F11: 0 | G11: 0 | H11: 0 | I11: 0 | J11: 0 | K11: 0 | L11: 0 | M11: 0 | N11: 0 | O11: 0 | P11: 0 | Q11: 0 | R11: 0 | S11: 0 | T11: 0 | U11: 0 | V11: 0 | W11: 0 | X11: 0 | Z11: 0 | AA11: 0 | AB11: 0 | AC11: 0 | AD11: 0 | AE11: 0 | AF11: 0 | AG11: 0 | AH11: 0 | AI11: 0 | AJ11: 0 | AK11: 0 | AL11: 0 | AM11: 0 | AN11: 0 | AO11: 0 | AP11: 0 | AQ11: 0 | AR11: 0 | AS11: 0 | AT11: 0 | AU11: 0 | AV11: 0 | AW11: 0 | AX11: 0 | AZ11: 2000000000 | BA11: 0 | BB11: 0 | BC11: 0 | BD11: 0 | BE11: 0 | BF11: 0 | BG11: 0 | BI11: 0 | BL11: 0 | BM11: 0 | BN11: 0 | BO11: 1000000000 | BP11: 1000000000 | BQ11: 1000000000
A12: 9 | B12: 4.Dự phòng đầu tư nắm giữ đến ngày đáo hạn ngắn hạn (*) | C12: 7 | BL12: 0 | BM12: 0 | BN12: 0 | BO12: 0 | BP12: 0 | BQ12: 0
A13: 10 | B13: 5.Đầu tư ngắn hạn khác | C13: 7 | BL13: 0 | BM13: 0 | BN13: 0 | BO13: 0 | BP13: 0 | BQ13: 0
A14: 11 | B14: 6.Dự phòng tổn thất các khoản đầu tư ngắn hạn khác (*) | C14: 7 | BL14: 0 | BM14: 0 | BN14: 0 | BO14: 0 | BP14: 0 | BQ14: 0
A15: 12 | B15: III.Các khoản phải thu ngắn hạn | C15: 7 | D15: 6418261360 | E15: 7085738478 | F15: 7811565598 | G15: 7728424999 | H15: 7150302539 | I15: 7268584100 | J15: 7464531500 | K15: 6261919420 | L15: 6261919420 | M15: 6272783240 | N15: 1356583240 | O15: 2405011920 | P15: 2897390721 | Q15: 2733117759 | R15: 2421717459 | S15: 5117557533 | T15: 4033482617 | U15: 5.2624238e+09 | V15: 5706417699 | W15: 3500485569 | X15: 4309771340 | Y15: 4.7476608e+09 | Z15: 7236434213 | AA15: 6025955556 | AB15: 4596579715 | AC15: 5387401759 | AD15: 4977074327 | AE15: 4238692638 | AF15: 4612410641 | AG15: 3.1928404e+09 | AH15: 3.0547165e+09 | AI15: 1.293208e+09 | AJ15: 2129814214 | AK15: 3466073332 | AL15: 3788411208 | AM15: 3875250574 | AN15: 2.2752476e+09 | AO15: 4.0669183e+09 | AP15: 2253017086 | AQ15: 1844506187 | AR15: 4.2263136e+09 | AS15: 3.1158819e+09 | AT15: 1.6497635e+09 | AU15: 2.3316789e+09 | AV15: 3.6878302e+09 | AW15: 2.5892204e+09 | AX15: 3.0609478e+09 | AY15: 1609307950 | AZ15: 1.5156008e+09 | BA15: 1.512819e+09 | BB15: 317284604 | BC15: 4.376813e+08 | BD15: 1.8020136e+09 | BE15: 382567548 | BF15: 446674724 | BG15: 290037774 | BH15: =+SUM(BH16:BH22) -> 804314929 | BI15: 1748706129 | BJ15: 1996141214 | BK15: 3204443278 | BL15: 2027514130 | BM15: 4308077225 | BN15: 7618117739 | BO15: 3341603556 | BP15: 4109614535 | BQ15: 3600631002
A16: 13 | B16: 1.Phải thu ngắn hạn của khách hàng | C16: 7 | D16: 344011360 | E16: 1011488478 | F16: 1661565598 | G16: 1637020440 | H16: 938231440 | I16: 1235584100 | J16: 1431531500 | K16: 1228919420 | L16: 1228919420 | M16: 1228919420 | N16: 1228919420 | O16: 2344852370 | P16: 2472853829 | Q16: 2348117759 | R16: 1199186719 | S16: 3801691879 | T16: 2672275521 | U16: 3.8632774e+09 | V16: 3130365079 | W16: 1716678559 | X16: 2609977880 | Y16: 2228084280 | Z16: 4863373867 | AA16: 3581636705 | AB16: 2282361831 | AC16: 2948239023 | AD16: 4217858654 | AE16: 3784872141 | AF16: 4527127000 | AG16: 3124385351 | AH16: 3053615978 | AI16: 1279974690 | AJ16: 2122982583 | AK16: 3170480400 | AL16: 3776201100 | AM16: 3868305821 | AN16: 1972488980 | AO16: 3763782920 | AP16: 1950558500 | AQ16: 1840484700 | AR16: 3956416380 | AS16: 2885016420 | AT16: 1190366820 | AU16: 1386246420 | AV16: 2371792180 | AW16: 1875305520 | AX16: 2497110264 | AY16: 1498339440 | AZ16: 1367557573 | BA16: 1270506828 | BB16: 147204 | BC16: 147204 | BD16: 874243583 | BF16: 0 | BG16: 0 | BH16: 502553255 | BI16: 1440037055 | BJ16: 1712124540 | BK16: 1967294520 | BL16: 130705920 | BM16: 2136557371 | BN16: 4506468999 | BO16: 1945280816 | BP16: 1482666995 | BQ16: 1943875984
A17: 14 | B17: 2.Trả trước cho người bán ngắn hạn | C17: 7 | D17: 74250000 | E17: 74250000 | F17: 0 | G17: 33000580 | H17: 33000580 | I17: 33000000 | J17: 33000000 | K17: 33000000 | L17: 33000000 | M17: 43863820 | N17: 127663820 | O17: 60159550 | P17: 422696450 | Q17: 385000000 | R17: 1222530740 | S17: 1309805211 | T17: 1349086211 | U17: 1399146380 | V17: 2576052620 | W17: 1783807010 | X17: 1699793460 | Y17: 1895680620 | Z17: 1389243160 | AA17: 2272134750 | AB17: 1469107250 | AC17: 1191538660 | AD17: 247971564 | AE17: 268906042 | AF17: 64090456 | AG17: 3070676 | AH17: 1100508 | AI17: 13233331 | AJ17: 6831631 | AK17: 295592932 | AL17: 12210108 | AM17: 6944753 | AN17: 302758586 | AO17: 303135378 | AP17: 302458586 | AQ17: 4021487 | AR17: 4429387 | AS17: 3351603 | AT17: 141882804 | AU17: 726490043 | AV17: 1187095603 | AW17: 713914907 | AX17: 485203444 | AY17: 25968510 | AZ17: 63043266 | BA17: 151512123 | BB17: 226337400 | BC17: 150994100 | BD17: 631128494 | BE17: 94918290 | BF17: 159925466 | BG17: 2388516 | BH17: 18112416 | BI17: 25019816 | BJ17: 367416 | BK17: 202767973 | BL17: 874147973 | BM17: 1145197973 | BN17: 2097017973 | BO17: 369817973 | BP17: 284717973 | BQ17: 263317973
A18: 15 | B18: 3.Phải thu nội bộ ngắn hạn | C18: 7 | D18: 0 | E18: 0 | F18: 150000000 | G18: 58403979 | H18: 179070519 | I18: 0 | J18: 0 | K18: 0 | L18: 0 | M18: 0 | N18: 0 | O18: 0 | P18: 1840442 | Q18: 0 | R18: 0 | S18: 6060443 | T18: 12120885 | U18: 0 | V18: 0 | W18: 0 | X18: 0 | Y18: 6.238959e+08 | Z18: 0 | AA18: 0 | AB18: 0 | AC18: 0 | AD18: 0 | AE18: 0 | AF18: 0 | AG18: 0 | AH18: 0 | AI18: 0 | AJ18: 0 | AK18: 0 | AL18: 0 | AM18: 0 | AN18: 0 | AO18: 0 | AP18: 0 | AQ18: 0 | AR18: 0 | AS18: 0 | AT18: 0 | AU18: 0 | AV18: 0 | AW18: 0 | AX18: 0 | AY18: 0 | AZ18: 0 | BA18: 0 | BB18: 0 | BC18: 0 | BD18: 0 | BE18: 0 | BF18: 0 | BG18: 0 | BH18: 0 | BI18: 0 | BL18: 0 | BM18: 0 | BN18: 0 | BO18: 0 | BP18: 0 | BQ18: 0
A19: 16 | B19: 4.Phải thu theo tiến độ hợp đồng xây dựng | C19: 7 | D19: 0 | E19: 0 | F19: 0 | G19: 0 | H19: 0 | I19: 0 | J19: 0 | K19: 0 | L19: 0 | M19: 0 | N19: 0 | O19: 0 | P19: 0 | Q19: 0 | R19: 0 | S19: 0 | T19: 0 | U19: 0 | V19: 0 | W19: 0 | X19: 0 | Z19: 0 | AA19: 0 | AB19: 0 | AC19: 0 | AD19: 0 | AE19: 0 | AF19: 0 | AG19: 0 | AH19: 0 | AI19: 0 | AJ19: 0 | AK19: 0 | AL19: 0 | AM19: 0 | AN19: 0 | AO19: 0 | AP19: 0 | AQ19: 0 | AR19: 0 | AS19: 0 | AT19: 0 | AU19: 0 | AV19: 0 | AW19: 0 | AX19: 0 | AY19: 0 | AZ19: 0 | BA19: 0 | BB19: 0 | BC19: 0 | BD19: 0 | BE19: 0 | BF19: 0 | BG19: 0 | BH19: 0 | BI19: 0 | BL19: 0 | BM19: 0 | BN19: 0 | BO19: 0 | BP19: 0 | BQ19: 0
A20: 17 | B20: 5.Phải thu ngắn hạn khác | C20: 7 | D20: 6000000000 | E20: 6000000000 | F20: 6000000000 | G20: 6000000000 | H20: 6000000000 | I20: 6000000000 | J20: 6000000000 | K20: 5000000000 | L20: 5000000000 | M20: 5000000000 | N20: 0 | O20: 0 | P20: 0 | Q20: 0 | R20: 0 | S20: 0 | T20: 0 | U20: 0 | V20: 0 | W20: 0 | X20: 0 | Z20: 983817186 | AA20: 172184101 | AB20: 845110634 | AC20: 1247624076 | AD20: 511244109 | AE20: 184914455 | AF20: 21193185 | AG20: 65384342 | AH20: 0.14 | AI20: 0.14 | AJ20: 0 | AK20: 0 | AL20: 0 | AM20: 0 | AN20: 0.14 | AO20: 0.14 | AP20: 0 | AQ20: 0 | AR20: 2.6546783e+08 | AS20: 2.2751385e+08 | AT20: 3.1751385e+08 | AU20: 2.1894241e+08 | AV20: 1.2894241e+08 | AW20: 0.518 | AX20: 78634112 | AY20: 85000000 | AZ20: 85000000 | BA20: 90800001 | BB20: 90800000 | BC20: 2.8654e+08 | BD20: 2.9664157e+08 | BE20: 287649258 | BF20: 286749258 | BG20: 287649258 | BH20: 283649258 | BI20: 283649258 | BJ20: 283649258 | BK20: 1034380785 | BL20: 1022660237 | BM20: 1026321881 | BN20: 1014630767 | BO20: 1026504767 | BP20: 2342229567 | BQ20: 1393437045
A21: 18 | B21: 6.Dự phòng phải thu ngắn hạn khó đòi (*) | C21: 7 | D21: 0 | E21: 0 | F21: 0 | G21: 0 | H21: 0 | I21: 0 | J21: 0 | K21: 0 | L21: 0 | M21: 0 | N21: 0 | O21: 0 | P21: 0 | Q21: 0 | R21: 0 | S21: 0 | T21: 0 | U21: 0 | V21: 0 | W21: 0 | X21: 0 | Z21: 0 | AA21: 0 | AB21: 0 | AC21: 0 | AD21: 0 | AE21: 0 | AF21: 0 | AG21: 0 | AH21: 0 | AI21: 0 | AJ21: 0 | AK21: 0 | AL21: 0 | AM21: 0 | AN21: 0 | AO21: 0 | AP21: 0 | AQ21: 0 | AR21: 0 | AS21: 0 | AT21: 0 | AU21: 0 | AV21: 0 | AW21: 0 | AX21: 0 | AY21: 0 | AZ21: 0 | BA21: 0 | BB21: 0 | BC21: 0 | BD21: 0 | BE21: 0 | BF21: 0 | BG21: 0 | BI21: 0 | BL21: 0 | BM21: 0 | BN21: 0 | BO21: 0 | BP21: 0 | BQ21: 0
A22: 19 | B22: 7.Tài sản thiếu chờ xử lý | C22: 7 | D22: 0 | E22: 0 | F22: 0 | G22: 0 | H22: 0 | I22: 0 | J22: 0 | K22: 0 | L22: 0 | M22: 0 | N22: 0 | O22: 0 | P22: 0 | Q22: 0 | R22: 0 | S22: 0 | T22: 0 | U22: 0 | V22: 0 | W22: 0 | X22: 0 | Z22: 0 | AA22: 0 | AB22: 0 | AC22: 0 | AD22: 0 | AE22: 0 | AF22: 0 | AG22: 0 | AH22: 0 | AI22: 0 | AJ22: 0 | AK22: 0 | AL22: 0 | AM22: 0 | AN22: 0 | AO22: 0 | AP22: 0 | AQ22: 0 | AR22: 0 | AS22: 0 | AT22: 0 | AU22: 0 | AV22: 0 | AW22: 0 | AX22: 0 | AY22: 0 | AZ22: 0 | BA22: 0 | BB22: 0 | BC22: 0 | BD22: 0 | BE22: 0 | BF22: 0 | BG22: 0 | BI22: 0 | BL22: 0 | BM22: 0 | BN22: 0 | BO22: 0 | BP22: 0 | BQ22: 0
A23: 20 | B23: IV. Hàng tồn kho | C23: 7 | D23: 1439314423 | E23: 1190057917 | F23: 952867547 | G23: 943357214 | H23: 1323737900 | I23: 1572336611 | J23: 1636087329 | K23: 1636087329 | L23: 1636087329 | M23: 1857609129 | N23: 2653243743 | O23: 2384125121 | P23: 2615356218 | Q23: 2116457578 | R23: 1788771350 | S23: 1707318288 | T23: 2378742457 | U23: 2745266923 | V23: 5140735927 | W23: 5555463714 | X23: 4847168750 | Y23: 4.7839944e+09 | Z23: 5886004288 | AA23: 2514638300 | AB23: 3244492840 | AC23: 2793559288 | AD23: 3222752503 | AE23: 3446179520 | AF23: 2994433471 | AG23: 2.1814046e+09 | AH23: 1.3066453e+09 | AI23: 1.4303281e+09 | AJ23: 1.8851828e+09 | AK23: 3.4804564e+09 | AL23: 4.7485624e+09 | AM23: 4.6043066e+09 | AN23: 4.9696708e+09 | AO23: 4.4831131e+09 | AP23: 3.3420824e+09 | AQ23: 3.2075573e+09 | AR23: 1.9381876e+09 | AS23: 1.6066631e+09 | AT23: 1.3411877e+09 | AU23: 1.1234417e+09 | AV23: 2.1623289e+09 | AW23: 1.8061644e+09 | AX23: 1.5807506e+09 | AY23: 1.5825455e+09 | AZ23: 3.3315926e+09 | BA23: 5.7772048e+09 | BB23: 4.2102498e+09 | BC23: 3.8584956e+09 | BD23: 3.3776515e+09 | BE23: 4.3001738e+09 | BF23: 3.7560301e+09 | BG23: 3.8845293e+09 | BH23: 2.0098344e+09 | BI23: 1.2843732e+09 | BJ23: 1.8962331e+09 | BK23: 2740108395 | BL23: 5045758048 | BM23: 5339692894 | BN23: 6443059216 | BO23: 5582117443 | BP23: 8989031026 | BQ23: 13491156975
