Workbook

Sheet Thong tin
A1: CÔNG TY TNHH MTV ĐỒNG LÂM
A2: Địa chỉ: Thửa đất số 838, tờ bản đồ số 6, tổ 4, ấp Tân Thuận, phường Tân Hạnh, tỉnh Vĩnh Long
A3: Mã số thuế: 1501075079
A4: Deadline ngày 5 tây hàng tháng
B6: Năm tài chính hiện tại | C6: 2026
B7: Năm trước | C7: =C6-1 -> 2025
B9: Tháng báo cáo hiện tại | C9: 5
B12: NGƯỜI LẬP BIỂU
B13: Lê Thùy Ngân
B15: KẾ TOÁN TRƯỞNG
B16: Lê Thùy Ngân
B18: TRƯỞNG TRẠM THU MUA
B19: Nguyễn Nhật Bằng

Sheet BIA
B29: THÁNG 05 NĂM 2026
B50: Vĩnh Long, Ngày 31 tháng 05 năm 2026

Sheet Index
A1: ='Thong tin'!A1 -> CÔNG TY TNHH MTV ĐỒNG LÂM | I1: BÁO CÁO TÀI CHÍNH
A2: ='Thong tin'!A2 -> Địa chỉ: Thửa đất số 838, tờ bản đồ số 6, tổ 4, ấp Tân Thuận, phường Tân Hạnh, tỉnh Vĩnh Long
A10: ="BÁO CÁO TÀI CHÍNH THÁNG "&'Thong tin'!C9&" NĂM 2026" -> BÁO CÁO TÀI CHÍNH THÁNG 5 NĂM 2026 | I10: Trang
A12: BÁO CÁO CỦA BAN GIÁM ĐỐC | I12: 2 - 3
A13: BÁO CÁO KIỂM TOÁN | I13: 4 - 4
A14: - Bảng cân đối kế toán | I14: 1 - 4
A15: - Báo cáo kết quả hoạt động kinh doanh | I15: 5
A16: - Báo cáo lưu chuyển tiền tệ | I16: 6 - 7
A17: - Bản thuyết minh báo cáo tài chính | I17: 11 - 31
A30: (Báo cáo tài chính được lập và trình bày theo Quyết định số 15/2006/QĐ-BTC ngày 20/03/2006
A31: của Bộ trưởng Bộ Tài Chính)

Sheet THTC in
A1: ='Thong tin'!$A$1 -> CÔNG TY TNHH MTV ĐỒNG LÂM
A2: ='Thong tin'!$A$2 -> Địa chỉ: Thửa đất số 838, tờ bản đồ số 6, tổ 4, ấp Tân Thuận, phường Tân Hạnh, tỉnh Vĩnh Long
A4: BÁO CÁO TÌNH HÌNH TÀI CHÍNH
A5: ="Năm " & 'Thong tin'!$C$6 -> Năm 2026
C6: ='KQKD in'!G6 -> ĐVT: VNĐ
A7: TÀI SẢN | B7: ="Số cuối tháng"&" "&$D$7 -> Số cuối tháng 5 | C7: ="Số dư đầu năm " & 'Thong tin'!$C$6 -> Số dư đầu năm 2026 | D7: ='Thong tin'!C9 -> 5
A8: A . TÀI SẢN NGẮN HẠN | B8: =B10+B14+B22+B31+B40 -> 18251786628 | C8: =C10+C14+C22+C31+C40 -> 16064654830
A10: I. Tiền và các khoản tương đương tiền | B10: =SUM(B11:B12) -> 11568161626 | C10: =SUM(C11:C12) -> 12687250516
A11: 1. Tiền | B11: =OFFSET('Tinh hinh tai chinh'!$BL6,0,'THTC in'!$D$7 - 1) -> 4568161626 | C11: ='Tinh hinh tai chinh'!BK6 -> 3687250516
A12: 2. Các khoản tương đương tiền | B12: =OFFSET('Tinh hinh tai chinh'!$BL7,0,'THTC in'!$D$7 - 1) -> 7000000000 | C12: ='Tinh hinh tai chinh'!BK7 -> 9000000000
A14: II. Các khoản đầu tư tài chính ngắn hạn | B14: =SUM(B15:B20) -> 0 | C14: =SUM(C15:C20) -> 0
A15: 1.Chứng khoán kinh doanh | B15: =OFFSET('Tinh hinh tai chinh'!$BL9,0,'THTC in'!$D$7 - 1) -> 0 | C15: ='Tinh hinh tai chinh'!BK9 -> 0
A16: 2.Dự phòng giảm giá chứng khoán kinh doanh (*) | B16: =OFFSET('Tinh hinh tai chinh'!$BL10,0,'THTC in'!$D$7 - 1) -> 0 | C16: ='Tinh hinh tai chinh'!BK10 -> 0
A17: 3.Đầu tư nắm giữ đến ngày đáo hạn ngắn hạn | B17: =OFFSET('Tinh hinh tai chinh'!$BL11,0,'THTC in'!$D$7 - 1) -> 0 | C17: ='Tinh hinh tai chinh'!BK11 -> 0
A18: 4.Dự phòng đầu tư nắm giữ đến ngày đáo hạn ngắn hạn (*) | B18: =OFFSET('Tinh hinh tai chinh'!$BL12,0,'THTC in'!$D$7 - 1) -> 0 | C18: ='Tinh hinh tai chinh'!BK12 -> 0
A19: 5.Đầu tư ngắn hạn khác | B19: =OFFSET('Tinh hinh tai chinh'!$BL13,0,'THTC in'!$D$7 - 1) -> 0 | C19: ='Tinh hinh tai chinh'!BK13 -> 0
A20: 6.Dự phòng tổn thất các khoản đầu tư ngắn hạn khác (*) | B20: =OFFSET('Tinh hinh tai chinh'!$BL14,0,'THTC in'!$D$7 - 1) -> 0 | C20: ='Tinh hinh tai chinh'!BK14 -> 0
A22: III. Các khoản phải thu ngắn hạn | B22: =SUM(B23:B29) -> 4342502789 | C22: =SUM(C23:C29) -> 1464039070
A23: 1.Phải thu ngắn hạn của khách hàng | B23: =OFFSET('Tinh hinh tai chinh'!$BL16,0,'THTC in'!$D$7 - 1) -> 3596125006 | C23: ='Tinh hinh tai chinh'!BK16 -> 1352106540
A24: 2.Trả trước cho người bán ngắn hạn | B24: =OFFSET('Tinh hinh tai chinh'!$BL17,0,'THTC in'!$D$7 - 1) -> 672134512 | C24: ='Tinh hinh tai chinh'!BK17 -> 111932530
A25: 3.Phải thu nội bộ ngắn hạn | B25: =OFFSET('Tinh hinh tai chinh'!$BL18,0,'THTC in'!$D$7 - 1) -> 0 | C25: ='Tinh hinh tai chinh'!BK18 -> 0
A26: 4.Phải thu theo tiến độ hợp đồng xây dựng | B26: =OFFSET('Tinh hinh tai chinh'!$BL19,0,'THTC in'!$D$7 - 1) -> 0 | C26: ='Tinh hinh tai chinh'!BK19 -> 0
A27: 5.Phải thu ngắn hạn khác | B27: =OFFSET('Tinh hinh tai chinh'!$BL20,0,'THTC in'!$D$7 - 1) -> 74243271 | C27: ='Tinh hinh tai chinh'!BK20 -> 0
A28: 6.Dự phòng phải thu ngắn hạn khó đòi (*) | B28: =OFFSET('Tinh hinh tai chinh'!$BL21,0,'THTC in'!$D$7 - 1) -> 0 | C28: ='Tinh hinh tai chinh'!BK21 -> 0
A29: 7.Tài sản thiếu chờ xử lý | B29: =OFFSET('Tinh hinh tai chinh'!$BL22,0,'THTC in'!$D$7 - 1) -> 0 | C29: ='Tinh hinh tai chinh'!BK22 -> 0
A31: IV. Hàng tồn kho | B31: =SUM(B32:B33) -> 1736750227 | C31: =SUM(C32:C33) -> 1493486657
A32: 1. Hàng tồn kho | B32: =OFFSET('Tinh hinh tai chinh'!$BL24,0,'THTC in'!$D$7 - 1) -> 1736750227 | C32: ='Tinh hinh tai chinh'!BK24 -> 1493486657
A33: 2. Dự phòng giảm giá hàng tồn kho (*) | B33: =OFFSET('Tinh hinh tai chinh'!$BL25,0,'THTC in'!$D$7 - 1) -> 0 | C33: ='Tinh hinh tai chinh'!BK25 -> 0
A35: V. Tài sản sinh học ngắn hạn | B35: =SUM(B36:B38) -> 0 | C35: =SUM(C36:C38) -> 0
A36: 1.Súc vật nuôi lấy sản phẩm một lần ngắn hạn | B36: =OFFSET('Tinh hinh tai chinh'!$BL27,0,'THTC in'!$D$7 - 1) -> 0 | C36: ='Tinh hinh tai chinh'!BK27 -> 0
A37: 2.Cây trồng theo mùa vụ hoặc lấy sản phẩm một lần ngắn hạn | B37: =OFFSET('Tinh hinh tai chinh'!$BL28,0,'THTC in'!$D$7 - 1) -> 0 | C37: ='Tinh hinh tai chinh'!BK28 -> 0
A38: 3.Dự phòng tổn thất tài sản sinh học ngắn hạn (*) | B38: =OFFSET('Tinh hinh tai chinh'!$BL29,0,'THTC in'!$D$7 - 1) -> 0 | C38: ='Tinh hinh tai chinh'!BK29 -> 0
A40: VI. Tài sản ngắn hạn khác | B40: =SUM(B41:B45) -> 604371986 | C40: =SUM(C41:C45) -> 419878587
A41: 1.Chi phí chờ phân bổ ngắn hạn | B41: =OFFSET('Tinh hinh tai chinh'!$BL31,0,'THTC in'!$D$7 - 1) -> 604371986 | C41: ='Tinh hinh tai chinh'!BK31 -> 419878587
A42: 2.Thuế GTGT được khấu trừ | B42: =OFFSET('Tinh hinh tai chinh'!$BL32,0,'THTC in'!$D$7 - 1) -> 0 | C42: ='Tinh hinh tai chinh'!BK32 -> 0
A43: 3.Thuế và các khoản khác phải thu Nhà nước | B43: =OFFSET('Tinh hinh tai chinh'!$BL33,0,'THTC in'!$D$7 - 1) -> 0 | C43: ='Tinh hinh tai chinh'!BK33 -> 0
A44: 4.Giao dịch mua bán lại trái phiếu Chính phủ | B44: =OFFSET('Tinh hinh tai chinh'!$BL34,0,'THTC in'!$D$7 - 1) -> 0 | C44: ='Tinh hinh tai chinh'!BK34 -> 0
A45: 5.Tài sản ngắn hạn khác | B45: =OFFSET('Tinh hinh tai chinh'!$BL35,0,'THTC in'!$D$7 - 1) -> 0 | C45: ='Tinh hinh tai chinh'!BK35 -> 0
A47: B. TÀI SẢN DÀI HẠN | B47: =B48+B58+B79+B87+B95+B83 -> 22268064535 | C47: =C48+C58+C79+C87+C95+C83 -> 20953553366
A48: I.Các khoản phải thu dài hạn | B48: =SUM(B49:B54) -> 0 | C48: =SUM(C49:C54) -> 0
...

Sheet KQKD in
A1: ='Thong tin'!$A$1 -> CÔNG TY TNHH MTV ĐỒNG LÂM
A2: ='Thong tin'!$A$2 -> Địa chỉ: Thửa đất số 838, tờ bản đồ số 6, tổ 4, ấp Tân Thuận, phường Tân Hạnh, tỉnh Vĩnh Long
A4: BÁO CÁO KẾT QUẢ HOẠT ĐỘNG KINH DOANH
A5: ="Năm " & 'Thong tin'!$C$6 -> Năm 2026
G6: ĐVT: VNĐ
A8: Chỉ tiêu | D8: ="Tháng "&'Thong tin'!$C$9 -> Tháng 5 | F8: ="Lũy kế"&" "&'Thong tin'!$C$9 &" "&"tháng" -> Lũy kế 5 tháng
D9: ="Năm " & 'Thong tin'!$C$6 -> Năm 2026 | E9: ="Năm " & 'Thong tin'!$C$7 -> Năm 2025 | F9: ="Năm " & 'Thong tin'!$C$6 -> Năm 2026 | G9: ="Năm " & 'Thong tin'!$C$7 -> Năm 2025
A10: 1. | B10: Doanh thu bán hàng và cung cấp dịch vụ | D10: =OFFSET('Ket qua kinh doanh'!$BL5,0,'Thong tin'!$C$9 - 1) -> 11024894520 | E10: =OFFSET('Ket qua kinh doanh'!$AZ5,0,'Thong tin'!$C$9 - 1) -> 7380147015 | F10: =SUM(OFFSET('Ket qua kinh doanh'!$BL5,0,0,1,'Thong tin'!$C$9)) -> 39568213997 | G10: =SUM(OFFSET('Ket qua kinh doanh'!$AZ5,0,0,1,'Thong tin'!$C$9)) -> 28611079762
A11: 2. | B11: Các khoản giảm trừ doanh thu | D11: =OFFSET('Ket qua kinh doanh'!$BL6,0,'Thong tin'!$C$9 - 1) -> 0 | E11: =OFFSET('Ket qua kinh doanh'!$AZ6,0,'Thong tin'!$C$9 - 1) -> 0 | F11: =SUM(OFFSET('Ket qua kinh doanh'!$BL6,0,0,1,'Thong tin'!$C$9)) -> 0 | G11: =SUM(OFFSET('Ket qua kinh doanh'!$AZ6,0,0,1,'Thong tin'!$C$9)) -> 0
A12: 3. | B12: Doanh thu thuần về bán hàng và cung cấp dịch vụ | D12: =OFFSET('Ket qua kinh doanh'!$BL7,0,'Thong tin'!$C$9 - 1) -> 11024894520 | E12: =OFFSET('Ket qua kinh doanh'!$AZ7,0,'Thong tin'!$C$9 - 1) -> 7380147015 | F12: =SUM(OFFSET('Ket qua kinh doanh'!$BL7,0,0,1,'Thong tin'!$C$9)) -> 39568213997 | G12: =SUM(OFFSET('Ket qua kinh doanh'!$AZ7,0,0,1,'Thong tin'!$C$9)) -> 28611079762
A13: 4. | B13: Giá vốn hàng bán | D13: =OFFSET('Ket qua kinh doanh'!$BL8,0,'Thong tin'!$C$9 - 1) -> 9397938637 | E13: =OFFSET('Ket qua kinh doanh'!$AZ8,0,'Thong tin'!$C$9 - 1) -> 7126741795 | F13: =SUM(OFFSET('Ket qua kinh doanh'!$BL8,0,0,1,'Thong tin'!$C$9)) -> 34534160005 | G13: =SUM(OFFSET('Ket qua kinh doanh'!$AZ8,0,0,1,'Thong tin'!$C$9)) -> 27645430459
A14: 5. | B14: Lợi nhuận gộp về bán hàng và cung cấp dịch vụ | D14: =OFFSET('Ket qua kinh doanh'!$BL9,0,'Thong tin'!$C$9 - 1) -> 1626955883 | E14: =OFFSET('Ket qua kinh doanh'!$AZ9,0,'Thong tin'!$C$9 - 1) -> 253405220 | F14: =SUM(OFFSET('Ket qua kinh doanh'!$BL9,0,0,1,'Thong tin'!$C$9)) -> 5034053992 | G14: =SUM(OFFSET('Ket qua kinh doanh'!$AZ9,0,0,1,'Thong tin'!$C$9)) -> 965649303
A15: 6. | B15: Lãi/lỗ của hoạt động bán, thanh lý bất động sản đầu tư | D15: =OFFSET('Ket qua kinh doanh'!$BL10,0,'Thong tin'!$C$9 - 1) -> 0 | E15: =OFFSET('Ket qua kinh doanh'!$AZ10,0,'Thong tin'!$C$9 - 1) -> 0 | F15: =SUM(OFFSET('Ket qua kinh doanh'!$BL10,0,0,1,'Thong tin'!$C$9)) -> 0 | G15: =SUM(OFFSET('Ket qua kinh doanh'!$AZ10,0,0,1,'Thong tin'!$C$9)) -> 0
A16: 7. | B16: Doanh thu hoạt động tài chính | D16: =OFFSET('Ket qua kinh doanh'!$BL11,0,'Thong tin'!$C$9 - 1) -> 11002030 | E16: =OFFSET('Ket qua kinh doanh'!$AZ11,0,'Thong tin'!$C$9 - 1) -> 11106781 | F16: =SUM(OFFSET('Ket qua kinh doanh'!$BL11,0,0,1,'Thong tin'!$C$9)) -> 173991944 | G16: =SUM(OFFSET('Ket qua kinh doanh'!$AZ11,0,0,1,'Thong tin'!$C$9)) -> 146895095
A17: 8. | B17: Chi phí tài chính | D17: =OFFSET('Ket qua kinh doanh'!$BL12,0,'Thong tin'!$C$9 - 1) -> 0 | E17: =OFFSET('Ket qua kinh doanh'!$AZ12,0,'Thong tin'!$C$9 - 1) -> 0 | F17: =SUM(OFFSET('Ket qua kinh doanh'!$BL12,0,0,1,'Thong tin'!$C$9)) -> 0 | G17: =SUM(OFFSET('Ket qua kinh doanh'!$AZ12,0,0,1,'Thong tin'!$C$9)) -> 0
B18: Trong đó: chi phí lãi vay | D18: =OFFSET('Ket qua kinh doanh'!$BL13,0,'Thong tin'!$C$9 - 1) -> 0 | E18: =OFFSET('Ket qua kinh doanh'!$AZ13,0,'Thong tin'!$C$9 - 1) -> 0 | F18: =SUM(OFFSET('Ket qua kinh doanh'!$BL13,0,0,1,'Thong tin'!$C$9)) -> 0 | G18: =SUM(OFFSET('Ket qua kinh doanh'!$AZ13,0,0,1,'Thong tin'!$C$9)) -> 0
A19: 9. | B19: Chi phí bán hàng | D19: =OFFSET('Ket qua kinh doanh'!$BL14,0,'Thong tin'!$C$9 - 1) -> 262800000 | E19: =OFFSET('Ket qua kinh doanh'!$AZ14,0,'Thong tin'!$C$9 - 1) -> 157100000 | F19: =SUM(OFFSET('Ket qua kinh doanh'!$BL14,0,0,1,'Thong tin'!$C$9)) -> 1047100000 | G19: =SUM(OFFSET('Ket qua kinh doanh'!$AZ14,0,0,1,'Thong tin'!$C$9)) -> 618500000
A20: 10. | B20: Chi phí quản lý doanh nghiệp | D20: =OFFSET('Ket qua kinh doanh'!$BL15,0,'Thong tin'!$C$9 - 1) -> 245121655 | E20: =OFFSET('Ket qua kinh doanh'!$AZ15,0,'Thong tin'!$C$9 - 1) -> 142223547 | F20: =SUM(OFFSET('Ket qua kinh doanh'!$BL15,0,0,1,'Thong tin'!$C$9)) -> 1444229086 | G20: =SUM(OFFSET('Ket qua kinh doanh'!$AZ15,0,0,1,'Thong tin'!$C$9)) -> 681764206
A21: 11. | B21: Lợi nhuận thuần từ hoạt động kinh doanh | D21: =OFFSET('Ket qua kinh doanh'!$BL16,0,'Thong tin'!$C$9 - 1) -> 1130036258 | E21: =OFFSET('Ket qua kinh doanh'!$AZ16,0,'Thong tin'!$C$9 - 1) -> -34811546 | F21: =SUM(OFFSET('Ket qua kinh doanh'!$BL16,0,0,1,'Thong tin'!$C$9)) -> 2716716850 | G21: =SUM(OFFSET('Ket qua kinh doanh'!$AZ16,0,0,1,'Thong tin'!$C$9)) -> -187719808
A22: 12. | B22: Thu nhập khác | D22: =OFFSET('Ket qua kinh doanh'!$BL17,0,'Thong tin'!$C$9 - 1) -> 26861111 | E22: =OFFSET('Ket qua kinh doanh'!$AZ17,0,'Thong tin'!$C$9 - 1) -> 0 | F22: =SUM(OFFSET('Ket qua kinh doanh'!$BL17,0,0,1,'Thong tin'!$C$9)) -> 80425162 | G22: =SUM(OFFSET('Ket qua kinh doanh'!$AZ17,0,0,1,'Thong tin'!$C$9)) -> 96212726
A23: 13. | B23: Chi phí khác | D23: =OFFSET('Ket qua kinh doanh'!$BL18,0,'Thong tin'!$C$9 - 1) -> 0 | E23: =OFFSET('Ket qua kinh doanh'!$AZ18,0,'Thong tin'!$C$9 - 1) -> 0 | F23: =SUM(OFFSET('Ket qua kinh doanh'!$BL18,0,0,1,'Thong tin'!$C$9)) -> 22020396 | G23: =SUM(OFFSET('Ket qua kinh doanh'!$AZ18,0,0,1,'Thong tin'!$C$9)) -> 42339675
A24: 14. | B24: Lợi nhuận khác | D24: =OFFSET('Ket qua kinh doanh'!$BL19,0,'Thong tin'!$C$9 - 1) -> 26861111 | E24: =OFFSET('Ket qua kinh doanh'!$AZ19,0,'Thong tin'!$C$9 - 1) -> 0 | F24: =SUM(OFFSET('Ket qua kinh doanh'!$BL19,0,0,1,'Thong tin'!$C$9)) -> 58404766 | G24: =SUM(OFFSET('Ket qua kinh doanh'!$AZ19,0,0,1,'Thong tin'!$C$9)) -> 53873051
A25: 15. | B25: Tổng lợi nhuận kế toán trước thuế | D25: =OFFSET('Ket qua kinh doanh'!$BL20,0,'Thong tin'!$C$9 - 1) -> 1156897369 | E25: =OFFSET('Ket qua kinh doanh'!$AZ20,0,'Thong tin'!$C$9 - 1) -> -34811546 | F25: =SUM(OFFSET('Ket qua kinh doanh'!$BL20,0,0,1,'Thong tin'!$C$9)) -> 2775121616 | G25: =SUM(OFFSET('Ket qua kinh doanh'!$AZ20,0,0,1,'Thong tin'!$C$9)) -> -133846757
A26: 16. | B26: Chi phí thuế TNDN hiện hành (*) | D26: =OFFSET('Ket qua kinh doanh'!$BL21,0,'Thong tin'!$C$9 - 1) -> 0 | E26: =OFFSET('Ket qua kinh doanh'!$AZ21,0,'Thong tin'!$C$9 - 1) -> 0 | F26: =SUM(OFFSET('Ket qua kinh doanh'!$BL21,0,0,1,'Thong tin'!$C$9)) -> 0 | G26: =SUM(OFFSET('Ket qua kinh doanh'!$AZ21,0,0,1,'Thong tin'!$C$9)) -> 0
A27: 17. | B27: Chi phí thuế TNDN hoãn lại | D27: =OFFSET('Ket qua kinh doanh'!$BL22,0,'Thong tin'!$C$9 - 1) -> 0 | E27: =OFFSET('Ket qua kinh doanh'!$AZ22,0,'Thong tin'!$C$9 - 1) -> 0 | F27: =SUM(OFFSET('Ket qua kinh doanh'!$BL22,0,0,1,'Thong tin'!$C$9)) -> 0 | G27: =SUM(OFFSET('Ket qua kinh doanh'!$AZ22,0,0,1,'Thong tin'!$C$9)) -> 0
A28: 18. | B28: Lợi nhuận sau thuế | D28: =OFFSET('Ket qua kinh doanh'!$BL23,0,'Thong tin'!$C$9 - 1) -> 1156897369 | E28: =OFFSET('Ket qua kinh doanh'!$AZ23,0,'Thong tin'!$C$9 - 1) -> -34811546 | F28: =SUM(OFFSET('Ket qua kinh doanh'!$BL23,0,0,1,'Thong tin'!$C$9)) -> 2775121616 | G28: =SUM(OFFSET('Ket qua kinh doanh'!$AZ23,0,0,1,'Thong tin'!$C$9)) -> -133846757
A29: 19. | B29: Lãi cơ bản trên cổ phiếu | F29: =#REF!+#REF!+#REF!+#REF!+#REF!+#REF!+#REF!+#REF!+#REF!+#REF!+#REF!+D29 -> #REF! | G29: =#REF!+#REF!+#REF!+#REF!+#REF!+#REF!+#REF!+#REF!+#REF!+#REF!+#REF!+E29 -> #REF!
D31: 0 | E31: 0 | F31: 0 | G31: 0
F32: Lập, ngày 05 tháng 06 năm 2026
B34: KẾ TOÁN TRƯỞNG | F34: ='Thong tin'!B18 -> TRƯỞNG TRẠM THU MUA
B41: ='Thong tin'!B13 -> Lê Thùy Ngân | F41: ='Thong tin'!B19 -> Nguyễn Nhật Bằng

Sheet LCTT_GT in
A1: ='Thong tin'!$A$1 -> CÔNG TY TNHH MTV ĐỒNG LÂM
A2: ='Thong tin'!$A$2 -> Địa chỉ: Thửa đất số 838, tờ bản đồ số 6, tổ 4, ấp Tân Thuận, phường Tân Hạnh, tỉnh Vĩnh Long
A4: BÁO CÁO LƯU CHUYỂN TIỀN TỆ
A5: (Theo phương pháp gián tiếp)
A6: ="Năm " & 'Thong tin'!$C$6 -> Năm 2026
E7: ='KQKD in'!G6 -> ĐVT: VNĐ
A8: Chỉ tiêu | B8: ="Tháng " & 'Thong tin'!$C$9 -> Tháng 5 | D8: ="Lũy kế"&" "& 'Thong tin'!$C$9 &" "&"tháng" -> Lũy kế 5 tháng
B9: ="Năm " & 'Thong tin'!$C$6 -> Năm 2026 | C9: ="Năm " & 'Thong tin'!$C$7 -> Năm 2025 | D9: ="Năm " & 'Thong tin'!$C$6 -> Năm 2026 | E9: ="Năm " & 'Thong tin'!$C$7 -> Năm 2025
A10: I. Lưu chuyển tiền từ hoạt động kinh doanh
A11: 1. Lợi nhuận trước thuế | B11: =OFFSET('Luu chuyen tien te'!$BL5,0,'Thong tin'!$C$9 - 1) -> 1156897369 | C11: =OFFSET('Luu chuyen tien te'!$AZ5,0,'Thong tin'!$C$9 - 1) -> -34811546 | D11: =SUM(OFFSET('Luu chuyen tien te'!$BL5,0,0,1,'Thong tin'!$C$9)) -> 2775121616 | E11: =SUM(OFFSET('Luu chuyen tien te'!$AZ5,0,0,1,'Thong tin'!$C$9)) -> -133846757
A12: 2. Điều chỉnh cho các khoản
A13: - Khấu hao tài sản cố định và BĐSĐT | B13: =OFFSET('Luu chuyen tien te'!$BL7,0,'Thong tin'!$C$9 - 1) -> 200168654 | C13: =OFFSET('Luu chuyen tien te'!$AZ7,0,'Thong tin'!$C$9 - 1) -> 329551584 | D13: =SUM(OFFSET('Luu chuyen tien te'!$BL7,0,0,1,'Thong tin'!$C$9)) -> 1009643443 | E13: =SUM(OFFSET('Luu chuyen tien te'!$AZ7,0,0,1,'Thong tin'!$C$9)) -> 1638527130
A14: - Các khoản dự phòng | B14: =OFFSET('Luu chuyen tien te'!$BL8,0,'Thong tin'!$C$9 - 1) -> 0 | C14: =OFFSET('Luu chuyen tien te'!$AZ8,0,'Thong tin'!$C$9 - 1) -> 0 | D14: =SUM(OFFSET('Luu chuyen tien te'!$BL8,0,0,1,'Thong tin'!$C$9)) -> 0 | E14: =SUM(OFFSET('Luu chuyen tien te'!$AZ8,0,0,1,'Thong tin'!$C$9)) -> 0
A15: - Lãi, lỗ chênh lệch tỷ giá hối đoái do đánh giá lại các khoản mục tiền tệ có gốc ngoại tệ | B15: =OFFSET('Luu chuyen tien te'!$BL9,0,'Thong tin'!$C$9 - 1) -> 0 | C15: =OFFSET('Luu chuyen tien te'!$AZ9,0,'Thong tin'!$C$9 - 1) -> 0 | D15: =SUM(OFFSET('Luu chuyen tien te'!$BL9,0,0,1,'Thong tin'!$C$9)) -> 0 | E15: =SUM(OFFSET('Luu chuyen tien te'!$AZ9,0,0,1,'Thong tin'!$C$9)) -> 0
A16: - Lãi lỗ từ hoạt động đầu tư, tài chính | B16: =OFFSET('Luu chuyen tien te'!$BL10,0,'Thong tin'!$C$9 - 1) -> -11002030 | C16: =OFFSET('Luu chuyen tien te'!$AZ10,0,'Thong tin'!$C$9 - 1) -> -11106781 | D16: =SUM(OFFSET('Luu chuyen tien te'!$BL10,0,0,1,'Thong tin'!$C$9)) -> -173991944 | E16: =SUM(OFFSET('Luu chuyen tien te'!$AZ10,0,0,1,'Thong tin'!$C$9)) -> -146895155
A17: - Chi phí đi vay | B17: =OFFSET('Luu chuyen tien te'!$BL11,0,'Thong tin'!$C$9 - 1) -> 0 | C17: =OFFSET('Luu chuyen tien te'!$AZ11,0,'Thong tin'!$C$9 - 1) -> 0 | D17: =SUM(OFFSET('Luu chuyen tien te'!$BL11,0,0,1,'Thong tin'!$C$9)) -> 0 | E17: =SUM(OFFSET('Luu chuyen tien te'!$AZ11,0,0,1,'Thong tin'!$C$9)) -> 0
A18: - Các khoản điều chỉnh khác | B18: =OFFSET('Luu chuyen tien te'!$BL12,0,'Thong tin'!$C$9 - 1) -> 0 | C18: =OFFSET('Luu chuyen tien te'!$AZ12,0,'Thong tin'!$C$9 - 1) -> 0 | D18: =SUM(OFFSET('Luu chuyen tien te'!$BL12,0,0,1,'Thong tin'!$C$9)) -> 0 | E18: =SUM(OFFSET('Luu chuyen tien te'!$AZ12,0,0,1,'Thong tin'!$C$9)) -> 0
A19: 3. Lợi nhuận từ hoạt động kinh doanh trước thay đổi vốn lưu động | B19: =SUM(B11:B18) -> 1346063993 | C19: =SUM(C11:C18) -> 283633257 | D19: =SUM(D11:D18) -> 3610773115 | E19: =SUM(E11:E18) -> 1357785218
A20: - Tăng giảm các khoản phải thu | B20: =OFFSET('Luu chuyen tien te'!$BL14,0,'Thong tin'!$C$9 - 1) -> -1577587338 | C20: =OFFSET('Luu chuyen tien te'!$AZ14,0,'Thong tin'!$C$9 - 1) -> 281268289 | D20: =SUM(OFFSET('Luu chuyen tien te'!$BL14,0,0,1,'Thong tin'!$C$9)) -> -2054330042 | E20: =SUM(OFFSET('Luu chuyen tien te'!$AZ14,0,0,1,'Thong tin'!$C$9)) -> 73324796
A21: - Tăng giảm hàng tồn kho | B21: =OFFSET('Luu chuyen tien te'!$BL15,0,'Thong tin'!$C$9 - 1) -> 590599954 | C21: =OFFSET('Luu chuyen tien te'!$AZ15,0,'Thong tin'!$C$9 - 1) -> -1013857236 | D21: =SUM(OFFSET('Luu chuyen tien te'!$BL15,0,0,1,'Thong tin'!$C$9)) -> -243263570 | E21: =SUM(OFFSET('Luu chuyen tien te'!$AZ15,0,0,1,'Thong tin'!$C$9)) -> -2947987348
A22: - Tăng giảm các khoản phải trả (Không bao gồm lãi vay phải trả, thuế TNDN phải nộp) | B22: =OFFSET('Luu chuyen tien te'!$BL16,0,'Thong tin'!$C$9 - 1) -> 311349763 | C22: =OFFSET('Luu chuyen tien te'!$AZ16,0,'Thong tin'!$C$9 - 1) -> 105251008 | D22: =SUM(OFFSET('Luu chuyen tien te'!$BL16,0,0,1,'Thong tin'!$C$9)) -> 48780636 | E22: =SUM(OFFSET('Luu chuyen tien te'!$AZ16,0,0,1,'Thong tin'!$C$9)) -> -153232421
A23: - Tăng giảm chi phí chờ phân bổ | B23: =OFFSET('Luu chuyen tien te'!$BL17,0,'Thong tin'!$C$9 - 1) -> -261200000 | C23: =OFFSET('Luu chuyen tien te'!$AZ17,0,'Thong tin'!$C$9 - 1) -> -537700000 | D23: =SUM(OFFSET('Luu chuyen tien te'!$BL17,0,0,1,'Thong tin'!$C$9)) -> -752647869 | E23: =SUM(OFFSET('Luu chuyen tien te'!$AZ17,0,0,1,'Thong tin'!$C$9)) -> -1008878143
A24: - Tăng, giảm chứng khoán kinh doanh | B24: =OFFSET('Luu chuyen tien te'!$BL18,0,'Thong tin'!$C$9 - 1) -> 0 | C24: =OFFSET('Luu chuyen tien te'!$AZ18,0,'Thong tin'!$C$9 - 1) -> 0 | D24: =SUM(OFFSET('Luu chuyen tien te'!$BL18,0,0,1,'Thong tin'!$C$9)) -> 0 | E24: =SUM(OFFSET('Luu chuyen tien te'!$AZ18,0,0,1,'Thong tin'!$C$9)) -> 0
A25: - Chi phí đi vay đã trả | B25: =OFFSET('Luu chuyen tien te'!$BL19,0,'Thong tin'!$C$9 - 1) -> 0 | C25: =OFFSET('Luu chuyen tien te'!$AZ19,0,'Thong tin'!$C$9 - 1) -> 0 | D25: =SUM(OFFSET('Luu chuyen tien te'!$BL19,0,0,1,'Thong tin'!$C$9)) -> 0 | E25: =SUM(OFFSET('Luu chuyen tien te'!$AZ19,0,0,1,'Thong tin'!$C$9)) -> 0
A26: - Thuế thu nhập doanh nghiệp đã nộp | B26: =OFFSET('Luu chuyen tien te'!$BL20,0,'Thong tin'!$C$9 - 1) -> 0 | C26: =OFFSET('Luu chuyen tien te'!$AZ20,0,'Thong tin'!$C$9 - 1) -> 0 | D26: =SUM(OFFSET('Luu chuyen tien te'!$BL20,0,0,1,'Thong tin'!$C$9)) -> 0 | E26: =SUM(OFFSET('Luu chuyen tien te'!$AZ20,0,0,1,'Thong tin'!$C$9)) -> 0
A27: - Tiền thu khác từ hoạt động kinh doanh | B27: =OFFSET('Luu chuyen tien te'!$BL21,0,'Thong tin'!$C$9 - 1) -> 0 | C27: =OFFSET('Luu chuyen tien te'!$AZ21,0,'Thong tin'!$C$9 - 1) -> 0 | D27: =SUM(OFFSET('Luu chuyen tien te'!$BL21,0,0,1,'Thong tin'!$C$9)) -> 0 | E27: =SUM(OFFSET('Luu chuyen tien te'!$AZ21,0,0,1,'Thong tin'!$C$9)) -> 0
A28: - Tiền chi khác cho hoạt động kinh doanh | B28: =OFFSET('Luu chuyen tien te'!$BL22,0,'Thong tin'!$C$9 - 1) -> 0 | C28: =OFFSET('Luu chuyen tien te'!$AZ22,0,'Thong tin'!$C$9 - 1) -> 0 | D28: =SUM(OFFSET('Luu chuyen tien te'!$BL22,0,0,1,'Thong tin'!$C$9)) -> 0 | E28: =SUM(OFFSET('Luu chuyen tien te'!$AZ22,0,0,1,'Thong tin'!$C$9)) -> 0
A29: Lưu chuyển tiền thuần từ hoạt động kinh doanh | B29: =SUM(B19:B28) -> 409226372 | C29: =SUM(C19:C28) -> -881404682 | D29: =SUM(D19:D28) -> 609312270 | E29: =SUM(E19:E28) -> -2678987898
A30: II. Lưu chuyển tiền từ hoạt động đầu tư
A31: 1. Tiền chi để mua sắm, xây dựng TSCĐ và các tài sản dài hạn khác | B31: =OFFSET('Luu chuyen tien te'!$BL25,0,'Thong tin'!$C$9 - 1) -> -928578104 | C31: =OFFSET('Luu chuyen tien te'!$AZ25,0,'Thong tin'!$C$9 - 1) -> 0 | D31: =SUM(OFFSET('Luu chuyen tien te'!$BL25,0,0,1,'Thong tin'!$C$9)) -> -1902393104 | E31: =SUM(OFFSET('Luu chuyen tien te'!$AZ25,0,0,1,'Thong tin'!$C$9)) -> -332455515
A32: 2. Tiền thu từ thanh lý, nhượng bán TSCĐ và các tài sản dài hạn khác | B32: =OFFSET('Luu chuyen tien te'!$BL26,0,'Thong tin'!$C$9 - 1) -> 0 | C32: =OFFSET('Luu chuyen tien te'!$AZ26,0,'Thong tin'!$C$9 - 1) -> 0 | D32: =SUM(OFFSET('Luu chuyen tien te'!$BL26,0,0,1,'Thong tin'!$C$9)) -> 0 | E32: =SUM(OFFSET('Luu chuyen tien te'!$AZ26,0,0,1,'Thong tin'!$C$9)) -> 0
A33: 3. Tiền chi cho vay, mua các công cụ nợ của đơn vị khác | B33: =OFFSET('Luu chuyen tien te'!$BL27,0,'Thong tin'!$C$9 - 1) -> 0 | C33: =OFFSET('Luu chuyen tien te'!$AZ27,0,'Thong tin'!$C$9 - 1) -> 0 | D33: =SUM(OFFSET('Luu chuyen tien te'!$BL27,0,0,1,'Thong tin'!$C$9)) -> 0 | E33: =SUM(OFFSET('Luu chuyen tien te'!$AZ27,0,0,1,'Thong tin'!$C$9)) -> 0
A34: 4. Tiền thu hồi cho vay, bán lại các công cụ nợ của đơn vị khác | B34: =OFFSET('Luu chuyen tien te'!$BL28,0,'Thong tin'!$C$9 - 1) -> 0 | C34: =OFFSET('Luu chuyen tien te'!$AZ28,0,'Thong tin'!$C$9 - 1) -> 0 | D34: =SUM(OFFSET('Luu chuyen tien te'!$BL28,0,0,1,'Thong tin'!$C$9)) -> 0 | E34: =SUM(OFFSET('Luu chuyen tien te'!$AZ28,0,0,1,'Thong tin'!$C$9)) -> 0
A35: 5. Tiền chi đầu tư góp vốn vào đơn vị khác | B35: =OFFSET('Luu chuyen tien te'!$BL29,0,'Thong tin'!$C$9 - 1) -> 0 | C35: =OFFSET('Luu chuyen tien te'!$AZ29,0,'Thong tin'!$C$9 - 1) -> 0 | D35: =SUM(OFFSET('Luu chuyen tien te'!$BL29,0,0,1,'Thong tin'!$C$9)) -> 0 | E35: =SUM(OFFSET('Luu chuyen tien te'!$AZ29,0,0,1,'Thong tin'!$C$9)) -> 0
A36: 6. Tiền thu hồi đầu tư góp vốn vào đơn vị khác | B36: =OFFSET('Luu chuyen tien te'!$BL30,0,'Thong tin'!$C$9 - 1) -> 0 | C36: =OFFSET('Luu chuyen tien te'!$AZ30,0,'Thong tin'!$C$9 - 1) -> 0 | D36: =SUM(OFFSET('Luu chuyen tien te'!$BL30,0,0,1,'Thong tin'!$C$9)) -> 0 | E36: =SUM(OFFSET('Luu chuyen tien te'!$AZ30,0,0,1,'Thong tin'!$C$9)) -> 0
A37: 7. Tiền thu lãi cho vay, cổ tức và lợi nhuận được chia | B37: =OFFSET('Luu chuyen tien te'!$BL31,0,'Thong tin'!$C$9 - 1) -> 11002030 | C37: =OFFSET('Luu chuyen tien te'!$AZ31,0,'Thong tin'!$C$9 - 1) -> 11106781 | D37: =SUM(OFFSET('Luu chuyen tien te'!$BL31,0,0,1,'Thong tin'!$C$9)) -> 173991944 | E37: =SUM(OFFSET('Luu chuyen tien te'!$AZ31,0,0,1,'Thong tin'!$C$9)) -> 146895155
A38: Lưu chuyển tiền thuần từ hoạt động đầu tư | B38: =SUM(B31:B37) -> -917576074 | C38: =SUM(C31:C37) -> 11106781 | D38: =SUM(D31:D37) -> -1728401160 | E38: =SUM(E31:E37) -> -185560360
A39: III. Lưu chuyển tiền từ hoạt động tài chính
A40: 1. Tiền thu từ phát hành cố phiếu, nhận vốn góp của chủ sở hữu | B40: =OFFSET('Luu chuyen tien te'!$BL34,0,'Thong tin'!$C$9 - 1) -> 0 | C40: =OFFSET('Luu chuyen tien te'!$AZ34,0,'Thong tin'!$C$9 - 1) -> 0 | D40: =SUM(OFFSET('Luu chuyen tien te'!$BL34,0,0,1,'Thong tin'!$C$9)) -> 0 | E40: =SUM(OFFSET('Luu chuyen tien te'!$AZ34,0,0,1,'Thong tin'!$C$9)) -> 0
A41: 2. Tiền trả lại vốn góp cho các chủ sở hữu, mua lại cổ phiểu đã phát hành | B41: =OFFSET('Luu chuyen tien te'!$BL35,0,'Thong tin'!$C$9 - 1) -> 0 | C41: =OFFSET('Luu chuyen tien te'!$AZ35,0,'Thong tin'!$C$9 - 1) -> 0 | D41: =SUM(OFFSET('Luu chuyen tien te'!$BL35,0,0,1,'Thong tin'!$C$9)) -> 0 | E41: =SUM(OFFSET('Luu chuyen tien te'!$AZ35,0,0,1,'Thong tin'!$C$9)) -> 0
...

Sheet Tinh hinh tai chinh
B1: CÔNG TY TNHH MTV ĐỒNG LÂM
B2: VND
A3: Index BS | B3: PHẦN I-BÁO CÁO TÌNH HÌNH TÀI CHÍNH | C3: TenCongTyID | D3: T1.2021 | E3: T02.2021 | F3: T03.2021 | G3: T04.2021 | H3: T05.2021 | I3: T06.2021 | J3: T07.2021 | K3: T08.2021 | L3: T09.2021 | M3: T10.2021 | N3: T11.2021 | O3: T12.2021 | P3: T1.2022 | Q3: T02.2022 | R3: T03.2022 | S3: T04.2022 | T3: T05.2022 | U3: T06.2022 | V3: T07.2022 | W3: T08.2022 | X3: T09.2022 | Y3: T10.2022 | Z3: T11.2022 | AA3: T12.2022 | AB3: T1.2023 | AC3: T02.2023 | AD3: T03.2023 | AE3: T04.2023 | AF3: T05.2023 | AG3: T06.2023 | AH3: T07.2023 | AI3: T08.2023 | AJ3: T09.2023 | AK3: T10.2023 | AL3: T11.2023 | AM3: T12.2023 | AN3: T01.2024 | AO3: T02.2024 | AP3: T03.2024 | AQ3: T04.2024 | AR3: T05.2024 | AS3: T06.2024 | AT3: T07.2024 | AU3: T08.2024 | AV3: T09.2024 | AW3: T10.2024 | AX3: T11.2024 | AY3: T12.2024 | AZ3: T01.2025 | BA3: T02.2025 | BB3: T03.2025 | BC3: T04.2025 | BD3: T05.2025 | BE3: T06.2025 | BF3: T07.2025 | BG3: T08.2025 | BH3: T09.2025 | BI3: T10.2025 | BJ3: T11.2025 | BK3: T12.2025 | BL3: T01.2026 | BM3: T02.2026 | BN3: T03.2026 | BO3: T04.2026 | BP3: T05.2026 | BQ3: T06.2026 | BR3: T07.2026 | BS3: T08.2026 | BT3: T09.2026 | BU3: T10.2026 | BV3: T11.2026 | BW3: T12.2026
A4: 1 | B4: A-TÀI SẢN NGẮN HẠN | C4: 8 | D4: 3358139575 | E4: 3953893142 | F4: 4528675513 | G4: 4640575502 | H4: 4703591381 | I4: 4530310202 | J4: 4519407013 | K4: 4509037112 | L4: 4182253135 | M4: 4167597972 | N4: 4348764088 | O4: 3976721052 | P4: 6201576506 | Q4: 6063724026 | R4: 7737636665 | S4: 12729463995 | T4: 15373589270 | U4: 14642410791 | V4: 14411380496 | W4: 18979581426 | X4: 18489393195 | Y4: 18081772557 | Z4: 20108069630 | AA4: 21430716975 | AB4: 18530493258 | AC4: 18016844387 | AD4: 16407079840 | AE4: 16621096157 | AF4: 15142789981 | AG4: 14842951388 | AH4: 13698033966 | AI4: 12815219742 | AJ4: 16417153221 | AK4: 18590520353 | AL4: 18749491220 | AM4: 19380683843 | AN4: 16655400779 | AO4: 16751161881 | AP4: 17586132451 | AQ4: 17633864126 | AR4: 15585930850 | AS4: 16387350398 | AT4: 14173712873 | AU4: 14449371716 | AV4: 14971331225 | AW4: 14580386925 | AX4: 14685617205 | AY4: 14580396486 | AZ4: 13204501927 | BA4: 13786486984 | BB4: 14537779420 | BC4: 14891446290 | BD4: 15269133452 | BE4: 16512169198 | BF4: 17559193747 | BG4: 18810005297 | BH4: =+BH5+BH8+BH15+BH23+BH30 -> 18824545028 | BI4: 18730252258 | BJ4: 19454271459 | BK4: =+BK5+BK8+BK15+BK23+BK30 -> 16064654830 | BL4: =+BL5+BL8+BL15+BL23+BL30 -> 16812894889 | BM4: =+BM5+BM8+BM15+BM23+BM30 -> 16132611614 | BN4: =+BN5+BN8+BN15+BN23+BN30 -> 16844274503 | BO4: =+BO5+BO8+BO15+BO23+BO30 -> 18289517798 | BP4: =+BP5+BP8+BP15+BP23+BP30 -> 18251786628
A5: 2 | B5: I.Tiền và các khoản tương đương tiền | C5: 8 | D5: 483768379 | E5: 720643553 | F5: 1773031343 | G5: 941288593 | H5: 1138189869 | I5: 308909807 | J5: 308359216 | K5: 835835371 | L5: 586813513 | M5: 479311301 | N5: 436629811 | O5: 212801747 | P5: 1518099189 | Q5: 717217893 | R5: 309531290 | S5: 3671852274 | T5: 4662736487 | U5: 2221627111 | V5: 1709697401 | W5: 8145220924 | X5: 7183858614 | Y5: 5627545425 | Z5: 5579005246 | AA5: 9150314701 | AB5: 8510233118 | AC5: 7792581184 | AD5: 7118800065 | AE5: 7030817990 | AF5: 7635882179 | AG5: 8088495327 | AH5: 7886638739 | AI5: 8466261018 | AJ5: 7021827102 | AK5: 6715619944 | AL5: 6638736449 | AM5: 7453392869 | AN5: 10090383500 | AO5: 9523101882 | AP5: 11009714369 | AQ5: 11029278425 | AR5: 10496124461 | AS5: 11384579309 | AT5: 11426602174 | AU5: 11746075725 | AV5: 10269138389 | AW5: 10626766582 | AX5: 9858519374 | AY5: 11072243110 | AZ5: 8834035774 | BA5: 7848966637 | BB5: 8280510070 | BC5: 9077992753 | BD5: 8207694852 | BE5: 9403068379 | BF5: 7536622429 | BG5: 10513571407 | BH5: =+SUM(BH6:BH7) -> 14815035663 | BI5: 14386677390 | BJ5: 13730084874 | BK5: =+SUM(BK6:BK7) -> 12687250516 | BL5: =+SUM(BL6:BL7) -> 12325362581 | BM5: =+SUM(BM6:BM7) -> 10597287304 | BN5: =+SUM(BN6:BN7) -> 10977840408 | BO5: =+SUM(BO6:BO7) -> 12076511328 | BP5: =+SUM(BP6:BP7) -> 11568161626
A6: 3 | B6: 1.Tiền | C6: 8 | D6: 483768379 | E6: 720643553 | F6: 1773031343 | G6: 941288593 | H6: 1138189869 | I6: 308909807 | J6: 308359216 | K6: 835835371 | L6: 586813513 | M6: 479311301 | N6: 436629811 | O6: 212801747 | P6: 1518099189 | Q6: 717217893 | R6: 309531290 | S6: 3671852274 | T6: 4662736487 | U6: 2221627111 | V6: 1709697401 | W6: 8145220924 | X6: 7183858614 | Y6: 5627545425 | Z6: 5579005246 | AA6: 9150314701 | AB6: 8510233118 | AC6: 7792581184 | AD6: 7118800065 | AE6: 7030817990 | AF6: 7635882179 | AG6: 8088495327 | AH6: 7886638739 | AI6: 8466261018 | AJ6: 7021827102 | AK6: 6715619944 | AL6: 2638736449 | AM6: 3453392869 | AN6: 6090383500 | AO6: 5523101882 | AP6: 7009714369 | AQ6: 3029278425 | AR6: 2496124461 | AS6: 7384579309 | AT6: 4426602174 | AU6: 4746075725 | AV6: 3269138389 | AW6: 3626766582 | AX6: 2858519374 | AY6: 4072243110 | AZ6: 1834035774 | BA6: 848966637 | BB6: 1280510070 | BC6: 2077992753 | BD6: 1207694852 | BE6: 2403068379 | BF6: 1536622429 | BG6: 4513571407 | BH6: 8815035663 | BI6: 5386677390 | BJ6: 4730084874 | BK6: 3687250516 | BL6: 3325362581 | BM6: 1597287304 | BN6: 3977840408 | BO6: 5076511328 | BP6: 4568161626
A7: 4 | B7: 2.Các khoản tương đương tiền | C7: 8 | D7: 0 | E7: 0 | K7: 0 | P7: 0 | Q7: 0 | R7: 0 | S7: 0 | T7: 0 | U7: 0 | V7: 0 | W7: 0 | X7: 0 | Y7: 0 | Z7: 0 | AA7: 0 | AB7: 0 | AC7: 0 | AI7: 0 | AL7: 4000000000 | AM7: 4000000000 | AN7: 4000000000 | AO7: 4000000000 | AP7: 4000000000 | AQ7: 8000000000 | AR7: 8000000000 | AS7: 4000000000 | AT7: 7000000000 | AU7: 7000000000 | AV7: 7000000000 | AW7: 7000000000 | AX7: 7000000000 | AY7: 7000000000 | AZ7: 7000000000 | BA7: 7000000000 | BB7: 7000000000 | BC7: 7000000000 | BD7: 7000000000 | BE7: 7000000000 | BF7: 6000000000 | BG7: 6000000000 | BH7: 6000000000 | BI7: 9000000000 | BJ7: 9000000000 | BK7: 9000000000 | BL7: 9000000000 | BM7: 9000000000 | BN7: 7000000000 | BO7: 7000000000 | BP7: 7000000000
A8: 5 | B8: II.Đầu tư tài chính ngắn hạn | C8: 8 | D8: 0 | E8: 0 | F8: 0 | G8: 0 | H8: 0 | I8: 0 | J8: 0 | K8: 0 | L8: 0 | M8: 0 | N8: 0 | O8: 0 | P8: 0 | Q8: 0 | R8: 0 | S8: 0 | T8: 0 | U8: 0 | V8: 0 | W8: 0 | X8: 0 | Y8: 0 | Z8: 0 | AA8: 0 | AB8: 0 | AC8: 0 | AD8: 0 | AE8: 0 | AF8: 0 | AG8: 0 | AH8: 0 | AI8: 0 | AJ8: 0 | AK8: 0 | AL8: 0 | AM8: 0 | AN8: 0 | AO8: 0 | AP8: 0 | AQ8: 0 | AR8: 0 | AS8: 0 | AT8: 0 | AU8: 0 | AV8: 0 | AW8: 0 | AX8: 0 | AY8: 0 | AZ8: 0 | BA8: 0 | BB8: 0 | BC8: 0 | BD8: 0 | BE8: 0 | BF8: 0 | BG8: 0 | BH8: =SUM(BH9:BH11) -> 0 | BI8: 0 | BJ8: 0 | BK8: =SUM(BK9:BK11) -> 0
A9: 6 | B9: 1.Chứng khoán kinh doanh | C9: 8 | P9: 0 | Q9: 0 | R9: 0 | S9: 0 | T9: 0 | U9: 0 | V9: 0 | W9: 0 | X9: 0 | Y9: 0 | Z9: 0 | AA9: 0
A10: 7 | B10: 2.Dự phòng giảm giá chứng khoán kinh doanh (*) | C10: 8 | P10: 0 | Q10: 0 | R10: 0 | S10: 0 | T10: 0 | U10: 0 | V10: 0 | W10: 0 | X10: 0 | Y10: 0 | Z10: 0 | AA10: 0
A11: 8 | B11: 3.Đầu tư nắm giữ đến ngày đáo hạn ngắn hạn | C11: 8 | P11: 0 | Q11: 0 | R11: 0 | S11: 0 | T11: 0 | U11: 0 | V11: 0 | W11: 0 | X11: 0 | Y11: 0 | Z11: 0 | AA11: 0
A12: 9 | B12: 4.Dự phòng đầu tư nắm giữ đến ngày đáo hạn ngắn hạn (*) | C12: 8
A13: 10 | B13: 5.Đầu tư ngắn hạn khác | C13: 8
A14: 11 | B14: 6.Dự phòng tổn thất các khoản đầu tư ngắn hạn khác (*) | C14: 8
A15: 12 | B15: III.Các khoản phải thu ngắn hạn | C15: 8 | D15: 1620513181 | E15: 1676539681 | F15: 371080000 | G15: 788198265 | H15: 758537475 | I15: 1420772311 | J15: 1420772311 | K15: 893331936 | L15: 794331936 | M15: 888557056 | N15: 904855060 | O15: 724170160 | P15: 1157804097 | Q15: 1764286737 | R15: 3547746882 | S15: 3457809087 | T15: 3068972654 | U15: 4106540884 | V15: 4015593184 | W15: 2386106456 | X15: 3445399070 | Y15: 4719147561 | Z15: 6167567568 | AA15: 5594151818 | AB15: 4868537401 | AC15: 5357599517 | AD15: 4805024644 | AE15: 5362894813 | AF15: 3016973436 | AG15: 3427138278 | AH15: 2681215478 | AI15: 873006738 | AJ15: 1948685648 | AK15: 1942332768 | AL15: 2270482320 | AM15: 3160096224 | AN15: 1382816904 | AO15: 2457182868 | AP15: 1724128692 | AQ15: 1980030480 | AR15: 2622074235 | AS15: 2890771785 | AT15: 1272281064 | AU15: 1255041564 | AV15: 2974642944 | AW15: 2454597412 | AX15: 3051282906 | AY15: 2434139806 | AZ15: 2320323901 | BA15: 3462927557 | BB15: 3547552868 | BC15: 2705857308 | BD15: 2949268036 | BE15: 2421836654 | BF15: 2276842655 | BG15: 2493646152 | BH15: =+SUM(BH16:BH22) -> 1854175027 | BI15: 3404777351 | BJ15: 4007416939 | BK15: =+SUM(BK16:BK22) -> 1464039070 | BL15: =+SUM(BL16:BL22) -> 1058678135 | BM15: =+SUM(BM16:BM22) -> 2036498915 | BN15: =+SUM(BN16:BN22) -> 3753577563 | BO15: =+SUM(BO16:BO22) -> 3216666112 | BP15: =+SUM(BP16:BP22) -> 4342502789
A16: 13 | B16: 1.Phải thu ngắn hạn của khách hàng | C16: 8 | G16: 405266565 | H16: 515509775 | I16: 527440375 | J16: 527440375 | K16: 0 | M16: 94225120 | N16: 204013260 | O16: 23892000 | S16: 127595180 | T16: 196037940 | U16: 683022780 | V16: 601075080 | W16: 990668388 | X16: 1394411268 | Y16: 2131276368 | Z16: 4131439608 | AA16: 4140163218 | AB16: 3685443413 | AC16: 4375012188 | AD16: 3862327288 | AE16: 3999014813 | AF16: 2359708378 | AG16: 2539128278 | AH16: 2490735478 | AI16: 807376738 | AJ16: 1883055648 | AK16: 1837302768 | AL16: 2165452320 | AM16: 3175592088 | AN16: 1398312768 | AO16: 2472678732 | AP16: 1686062460 | AQ16: 1875004248 | AR16: 2366025168 | AS16: 2622382608 | AT16: 1287776928 | AU16: 1270537428 | AV16: 2990138808 | AW16: 2460093276 | AX16: 2890298106 | AY16: 2171167146 | AZ16: 2194075101 | BA16: 3245574757 | BB16: 3302720868 | BC16: 2333761308 | BD16: 2356378858 | BE16: 1646925454 | BF16: 1921224140 | BG16: 1204904597 | BI16: 1042368852 | BJ16: 1705247640 | BK16: 1352106540 | BL16: 916040092 | BM16: 1884129790 | BN16: 2974309886 | BO16: 2369221764 | BP16: 3596125006
A17: 14 | B17: 2.Trả trước cho người bán ngắn hạn | C17: 8 | D17: 1610513181 | E17: 1666539681 | F17: 201080000 | G17: 201080000 | H17: 135080000 | I17: 785387000 | J17: 785387000 | K17: 785387000 | L17: 686387000 | M17: 686387000 | N17: 640208864 | O17: 639645224 | P17: 1105179861 | Q17: 1313060853 | R17: 3098040212 | S17: 2905076977 | T17: 2438689766 | U17: 2989273156 | V17: 2980273156 | W17: 961193120 | X17: 1588844360 | Y17: 2098527960 | Z17: 1988127960 | AA17: 1433988600 | AB17: 1163093988 | AC17: 962587329 | AD17: 922697356 | AE17: 1343880000 | AF17: 637265058 | AG17: 868010000 | AH17: 190480000 | AI17: 65630000 | AJ17: 65630000 | AK17: 105030000 | AL17: 105030000 | AM17: 105030000 | AN17: 105030000 | AO17: 105030000 | AP17: 158592096 | AQ17: 225552096 | AR17: 376574931 | AS17: 376574931 | AT17: 105030000 | AU17: 105030000 | AV17: 105030000 | AW17: 105030000 | AX17: 160984800 | AY17: 244060800 | AZ17: 124904800 | BA17: 217352800 | BB17: 244832000 | BC17: 372096000 | BD17: 592889178 | BE17: 773567200 | BF17: 355570515 | BG17: 1288693555 | BH17: 1854127027 | BI17: 2362360499 | BJ17: 2302121299 | BK17: 111932530 | BL17: 142638043 | BM17: 140569125 | BN17: 779267677 | BO17: 772967077 | BP17: 672134512
A18: 15 | B18: 3.Phải thu nội bộ ngắn hạn | C18: 8 | AZ18: 0 | BG18: 0
A19: 16 | B19: 4.Phải thu theo tiến độ hợp đồng xây dựng | C19: 8 | AZ19: 0 | BG19: 0
A20: 17 | B20: 5.Phải thu ngắn hạn khác | C20: 8 | D20: 10000000 | E20: 10000000 | F20: 170000000 | G20: 181851700 | H20: 107947700 | I20: 107944936 | J20: 107944936 | K20: 107944936 | L20: 107944936 | M20: 107944936 | N20: 60632936 | O20: 60632936 | P20: 52624236 | Q20: 451225884 | R20: 449706670 | S20: 425136930 | T20: 434244948 | U20: 434244948 | V20: 434244948 | W20: 434244948 | X20: 462143442 | Y20: 489343233 | Z20: 48000000 | AA20: 20000000 | AB20: 20000000 | AC20: 20000000 | AD20: 20000000 | AE20: 20000000 | AF20: 20000000 | AG20: 20000000 | AS20: 12340110 | AT20: 0 | AW20: 10000000 | AY20: 18911860 | AZ20: 1344000 | BE20: 1344000 | BF20: 48000 | BG20: 48000 | BH20: 48000 | BI20: 48000 | BJ20: 48000 | BM20: 11800000 | BO20: 74477271 | BP20: 74243271
A21: 18 | B21: 6.Dự phòng phải thu ngắn hạn khó đòi (*) | C21: 8 | AM21: -120525864 | AN21: -120525864 | AO21: -120525864 | AP21: -120525864 | AQ21: -120525864 | AR21: -120525864 | AS21: -120525864 | AT21: -120525864 | AU21: -120525864 | AV21: -120525864 | AW21: -120525864 | BG21: 0
A22: 19 | B22: 7.Tài sản thiếu chờ xử lý | C22: 8 | BG22: 0
A23: 20 | B23: IV. Hàng tồn kho | C23: 8 | D23: 711870500 | E23: 953822000 | F23: 1538030650 | G23: 1981940079 | H23: 1648090578 | I23: 1637240383 | J23: 1637240383 | K23: 1637240383 | L23: 1637240383 | M23: 1637240383 | N23: 1688913810 | O23: 1678041697 | P23: 1894091453 | Q23: 1916852841 | R23: 2144015083 | S23: 3320714997 | T23: 5190756285 | U23: 5961038428 | V23: 6392317595 | W23: 6090374727 | X23: 5600679519 | Y23: 5666269379 | Z23: 6665345158 | AA23: 5403066856 | AB23: 3920064141 | AC23: 3757138672 | AD23: 3689623706 | AE23: 3885652180 | AF23: 4308462957 | AG23: 3183711263 | AH23: 2984669311 | AI23: 3330147871 | AJ23: 7317099506 | AK23: 9819214405 | AL23: 9740798637 | AM23: 8670066410 | AN23: 5097334928 | AO23: 4689521975 | AP23: 4782382935 | AQ23: 4564558366 | AR23: 2418620233 | AS23: 2070065742 | AT23: 1435461347 | AU23: 1414948155 | AV23: 1662924313 | AW23: 1439296958 | AX23: 1723787677 | AY23: 1028919593 | AZ23: 2008806177 | BA23: 2407229278 | BB23: 2554142549 | BC23: 2963049705 | BD23: 3976906941 | BE23: 4554776839 | BF23: 7623270646 | BG23: 5690293381 | BH23: 2045402963 | BI23: 805983164 | BJ23: 1594635760 | BK23: 1493486657 | BL23: 3037172503 | BM23: 3123184784 | BN23: 1754219302 | BO23: =BO24 -> 2327350181 | BP23: =BP24 -> 1736750227
A24: 21 | B24: 1.Hàng tồn kho | C24: 8 | D24: 711870500 | E24: 953822000 | F24: 1538030650 | G24: 1981940079 | H24: 1648090578 | I24: 1637240383 | J24: 1637240383 | K24: 1637240383 | L24: 1637240383 | M24: 1637240383 | N24: 1688913810 | O24: 1678041697 | P24: 1894091453 | Q24: 1916852841 | R24: 2144015083 | S24: 3320714997 | T24: 5190756285 | U24: 5961038428 | V24: 6392317595 | W24: 6090374727 | X24: 5600679519 | Y24: 5666269379 | Z24: 6665345158 | AA24: 5403066856 | AB24: 3920064141 | AC24: 3757138672 | AD24: 3689623706 | AE24: 3885652180 | AF24: 4308462957 | AG24: 3183711263 | AH24: 2984669311 | AI24: 3330147871 | AJ24: 7317099506 | AK24: 9819214405 | AL24: 9740798637 | AM24: 8670066410 | AN24: 5097334928 | AO24: 4689521975 | AP24: 4782382935 | AQ24: 4564558366 | AR24: 2418620233 | AS24: 2070065742 | AT24: 1435461347 | AU24: 1414948155 | AV24: 1662924313 | AW24: 1439296958 | AX24: 1723787677 | AY24: 1028919593 | AZ24: 2008806177 | BA24: 2407229278 | BB24: 2554142549 | BC24: 2963049705 | BD24: 3976906941 | BE24: 4554776839 | BF24: 7623270646 | BG24: 5690293381 | BH24: 2045402963 | BI24: 805983164 | BJ24: 1594635760 | BK24: 1493486657 | BL24: 3037172503 | BM24: 3123184784 | BN24: 1754219302 | BO24: 2327350181 | BP24: 1736750227
A25: 22 | B25: 2.Dự phòng giảm giá hàng tồn kho (*) | C25: 8 | D25: 0 | E25: 0 | K25: 0 | P25: 0 | Q25: 0 | W25: 0 | AB25: 0 | AC25: 0 | AI25: 0 | AN25: 0 | AO25: 0 | AU25: 0
A26: 23 | B26: V. Tài sản sinh học ngắn hạn | C26: 8
A27: 24 | B27: 1.Súc vật nuôi lấy sản phẩm một lần ngắn hạn | C27: 8
A28: 25 | B28: 2.Cây trồng theo mùa vụ hoặc lấy sản phẩm một lần ngắn hạn | C28: 8
A29: 26 | B29: 3.Dự phòng tổn thất tài sản sinh học ngắn hạn (*) | C29: 8
A30: 27 | B30: VI. Tài sản ngắn hạn khác | C30: 8 | D30: 541987515 | E30: 602887908 | F30: 846533520 | G30: 929148565 | H30: 1158773459 | I30: 1163387701 | J30: 1153035103 | K30: 1142629422 | L30: 1163867303 | M30: 1162489232 | N30: 1318365407 | O30: 1361707448 | P30: 1631581767 | Q30: 1665366555 | R30: 1736343410 | S30: 2279087637 | T30: 2451123844 | U30: 2353204368 | V30: 2293772316 | W30: 2357879319 | X30: 2259455992 | Y30: 2068810192 | Z30: 1696151658 | AA30: 1283183600 | AB30: 1231658598 | AC30: 1109525014 | AD30: 793631425 | AE30: 341731174 | AF30: 181471409 | AG30: 143606520 | AH30: 145510438 | AI30: 145804115 | AJ30: 129540965 | AK30: 113353236 | AL30: 99473814 | AM30: 97128340 | AN30: 84865447 | AO30: 81355156 | AP30: 69906455 | AQ30: 59996855 | AR30: 49111921 | AS30: 41933562 | AT30: 39368288 | AU30: 33306272 | AV30: 64625579 | AW30: 59725973 | AX30: 52027248 | AY30: 45093977 | AZ30: 41336075 | BA30: 67363512 | BB30: 155573933 | BC30: 144546524 | BD30: 135263623 | BE30: 132487326 | BF30: 122458017 | BG30: 112494357 | BH30: =+SUM(BH31:BH35) -> 109931375 | BI30: 132814353 | BJ30: 122133886 | BK30: =+SUM(BK31:BK35) -> 419878587 | BL30: =+SUM(BL31:BL35) -> 391681670 | BM30: 375640611 | BN30: 358637230 | BO30: 668990177 | BP30: 604371986
A31: 28 | B31: 1.Chi phí chờ phân bổ ngắn hạn | C31: 8 | D31: 50716667 | E31: 60436223 | F31: 54587208 | G31: 48738193 | H31: 174732942 | I31: 164327261 | J31: 153921580 | K31: 143515899 | L31: 133110218 | M31: 122704537 | N31: 112298856 | O31: 133092352 | P31: 174213556 | Q31: 203230871 | R31: 199666662 | S31: 197878158 | T31: 203150030 | U31: 174973496 | V31: 176146008 | W31: 190426401 | X31: 173539941 | Y31: 225086052 | Z31: 211606193 | AA31: 187439886 | AB31: 165835550 | AC31: 159353959 | AD31: 155028734 | AE31: 144744365 | AF31: 147661856 | AG31: 143606520 | AH31: 145510438 | AI31: 145804115 | AJ31: 129540965 | AK31: 113353236 | AL31: 99473814 | AM31: 97128340 | AN31: 84865447 | AO31: 81355156 | AP31: 69906455 | AQ31: 59996855 | AR31: 49111921 | AS31: 41933562 | AT31: 39222693 | AU31: 33306272 | AV31: 64625579 | AW31: 59725973 | AX31: 52027248 | AY31: 45093977 | AZ31: 41336075 | BA31: 67363512 | BB31: 155573933 | BC31: 144546524 | BD31: 135263623 | BE31: 132487326 | BF31: 122458017 | BG31: 112494357 | BH31: 109931375 | BI31: 132814353 | BJ31: 122133886 | BK31: 419878587 | BL31: 391681670 | BM31: 375640611 | BN31: 358637230 | BO31: 668990177 | BP31: 604371986
A32: 29 | B32: 2.Thuế GTGT được khấu trừ | C32: 8 | D32: 491270848 | E32: 542451685 | F32: 791946312 | G32: 880410372 | H32: 984040517 | I32: 999060440 | J32: 999113523 | K32: 999113523 | L32: 1030757085 | M32: 1039784695 | N32: 1206066551 | O32: 1228615096 | P32: 1457368211 | Q32: 1462135684 | R32: 1536676748 | S32: 2081209479 | T32: 2247973814 | U32: 2178230872 | V32: 2117626308 | W32: 2167452918 | X32: 2085916051 | Y32: 1843724140 | Z32: 1484545465 | AA32: 1095743714 | AB32: 1065823048 | AC32: 950171055 | AD32: 638602691 | AE32: 196986809 | AF32: 33809553
A33: 30 | B33: 3.Thuế và các khoản khác phải thu Nhà nước | C33: 8 | AT33: 145595
A34: 31 | B34: 4.Giao dịch mua bán lại trái phiếu Chính phủ | C34: 8
A35: 32 | B35: 5.Tài sản ngắn hạn khác | C35: 8 | D35: 0 | E35: 0 | K35: 0 | P35: 0 | Q35: 0 | W35: 0 | AB35: 0 | AC35: 0 | AI35: 0
A36: 33 | B36: B-TÀI SẢN DÀI HẠN | C36: 8 | D36: 4179790347 | E36: 4369315410 | F36: 6452597462 | G36: 7252406264 | H36: 8043234945 | I36: 9048983532 | J36: 8986993443 | K36: 8925003354 | L36: 9156902154 | M36: 9175283322 | N36: 10760402300 | O36: 10728148450 | P36: 12816934360 | Q36: 12656822396 | R36: 13544851463 | S36: 20138783540 | T36: 21862217640 | U36: 21732650101 | V36: 21553803062 | W36: 23955581543 | X36: 24219203444 | Y36: 24024814449 | Z36: 21664052554 | AA36: 18892233961 | AB36: 20356591250 | AC36: 20376737250 | AD36: 21169533878 | AE36: 21142346060 | AF36: 22720175413 | AG36: 22560604485 | AH36: 23514574025 | AI36: 23686399540 | AJ36: 23365623530 | AK36: 23111600551 | AL36: 22830714249 | AM36: 22499311030 | AN36: 22132533800 | AO36: 21790111666 | AP36: 21512401507 | AQ36: 21227139295 | AR36: 21133588259 | AS36: 20726411945 | AT36: 20828470590 | AU36: 20410787535 | AV36: 20061663202 | AW36: 19708125425 | AX36: 19332199051 | AY36: 18990831461 | AZ36: 18815372886 | BA36: 18629807582 | BB36: 18536622943 | BC36: 18143782320 | BD36: 18284200867 | BE36: 18217638950 | BF36: 18256713289 | BG36: 18516644378 | BH36: =+BH37+BH44+BH63+BH69+BH76+BH66 -> 18100976603 | BI36: 17761288602 | BJ36: 18430227552 | BK36: =+BK37+BK44+BK63+BK69+BK76+BK66 -> 20953553366 | BL36: =+BL37+BL44+BL63+BL69+BL76+BL66 -> 21065864079 | BM36: =+BM37+BM44+BM63+BM69+BM76+BM66 -> 21432606556 | BN36: =+BN37+BN44+BN63+BN69+BN76+BN66 -> 21246677146 | BO36: =+BO37+BO44+BO63+BO69+BO76+BO66 -> 21026520918 | BP36: =+BP37+BP44+BP63+BP69+BP76+BP66 -> 22268064535
A37: 34 | B37: I.Các khoản phải thu dài hạn | C37: 8 | D37: 0 | E37: 0 | F37: 0 | G37: 0 | H37: 0 | I37: 0 | J37: 0 | K37: 0 | L37: 0 | M37: 0 | N37: 0 | O37: 0 | P37: 0 | Q37: 0 | R37: 0 | S37: 0 | T37: 0 | U37: 0 | V37: 0 | W37: 0 | X37: 0 | Y37: 0 | Z37: 0 | AA37: 0 | AB37: 0 | AC37: 0 | AD37: 0 | AE37: 0 | AF37: 0 | AG37: 0 | AH37: 0 | AI37: 0 | AJ37: 0 | AK37: 0 | AL37: 0 | AM37: 0 | AN37: 0 | AO37: 0 | AP37: 0 | AQ37: 0 | AR37: 0 | AS37: 0 | AT37: 0 | AU37: 0 | AV37: 0 | AW37: 0 | AX37: 0 | AY37: 0 | AZ37: 0 | BA37: 0 | BB37: 0 | BC37: 0 | BD37: 0 | BE37: 0 | BF37: 0 | BG37: 0 | BI37: 0 | BJ37: 0
A38: 35 | B38: 1.Phải thu dài hạn của khách hàng | C38: 8 | D38: 0 | E38: 0 | F38: 0 | G38: 0 | K38: 0 | O38: 0 | P38: 0 | Q38: 0 | R38: 0 | S38: 0 | T38: 0 | U38: 0 | V38: 0 | W38: 0 | X38: 0 | Y38: 0 | Z38: 0 | AA38: 0 | AB38: 0 | AC38: 0 | AD38: 0 | AE38: 0 | AI38: 0 | AM38: 0
A39: 36 | B39: 2.Trả trước cho người bán dài hạn | C39: 8 | D39: 0 | E39: 0 | K39: 0 | P39: 0 | Q39: 0 | R39: 0 | S39: 0 | T39: 0 | U39: 0 | V39: 0 | W39: 0 | X39: 0 | Y39: 0 | Z39: 0 | AA39: 0 | AB39: 0 | AC39: 0 | AI39: 0
A40: 37 | B40: 3.Vốn kinh doanh ở đơn vị trực thuộc | C40: 8 | D40: 0 | E40: 0 | K40: 0 | P40: 0 | Q40: 0 | R40: 0 | S40: 0 | T40: 0 | U40: 0 | V40: 0 | W40: 0 | X40: 0 | Y40: 0 | Z40: 0 | AA40: 0 | AB40: 0 | AC40: 0 | AI40: 0
...

Sheet Ket qua kinh doanh
B1: CÔNG TY TNHH MTV ĐỒNG LÂM
B2: VND
A3: Index PL | B3: PHẦN II-KẾT QUẢ HOẠT ĐỘNG KINH DOANH | C3: TenCongTyID | D3: T1.2021 | E3: T02.2021 | F3: T03.2021 | G3: T04.2021 | H3: T05.2021 | I3: T06.2021 | J3: T07.2021 | K3: T08.2021 | L3: T09.2021 | M3: T10.2021 | N3: T11.2021 | O3: T12.2021 | P3: T1.2022 | Q3: T02.2022 | R3: T03.2022 | S3: T04.2022 | T3: T05.2022 | U3: T06.2022 | V3: T07.2022 | W3: T08.2022 | X3: T09.2022 | Y3: T10.2022 | Z3: T11.2022 | AA3: T12.2022 | AB3: T1.2023 | AC3: T02.2023 | AD3: T03.2023 | AE3: T04.2023 | AF3: T05.2023 | AG3: T06.2023 | AH3: T07.2023 | AI3: T08.2023 | AJ3: T09.2023 | AK3: T10.2023 | AL3: T11.2023 | AM3: T12.2023 | AN3: T01.2024 | AO3: T02.2024 | AP3: T03.2024 | AQ3: T04.2024 | AR3: T05.2024 | AS3: T06.2024 | AT3: T07.2024 | AU3: T08.2024 | AV3: T09.2024 | AW3: T10.2024 | AX3: T11.2024 | AY3: T12.2024 | AZ3: T01.2025 | BA3: T02.2025 | BB3: T03.2025 | BC3: T04.2025 | BD3: T05.2025 | BE3: T06.2025 | BF3: T07.2025 | BG3: T08.2025 | BH3: T09.2025 | BI3: T10.2025 | BJ3: T11.2025 | BK3: T12.2025 | BL3: T01.2026 | BM3: T02.2026 | BN3: T03.2026 | BO3: T04.2026 | BP3: T05.2026 | BQ3: T06.2026 | BR3: T07.2026 | BS3: T08.2026 | BT3: T09.2026 | BU3: T10.2026 | BV3: T11.2026 | BW3: T12.2026
A4: 1 | B4: Sản lượng (Tấn) | C4: 8 | D4: 0 | E4: 0 | P4: 13.776 | Q4: 0 | R4: 21.243 | S4: 18.384 | T4: 69.306 | U4: 57.128 | V4: 45.009 | W4: 133.151 | X4: 87.34 | Y4: 200.284 | Z4: 162.7505 | AA4: 200.149 | AB4: 177.0275 | AC4: 116.397 | AD4: 313 | AE4: 367 | AF4: 260 | AG4: 320 | AH4: 273 | AI4: 241 | AJ4: 225 | AK4: 267 | AL4: 161 | AM4: 411.801 | AN4: 573 | AO4: 269 | AP4: 385 | AQ4: 393 | AR4: 627.692 | AS4: 379 | AT4: 289.909 | AU4: 249.529 | AV4: 256.07 | AW4: 285.927 | AX4: 301.603 | AY4: 231.248 | AZ4: 136.817 | BA4: 284.586 | BB4: 355.698 | BC4: 421.533 | BD4: 410.449 | BE4: 572.586 | BF4: 681.432 | BG4: 736.186 | BH4: 660.128 | BI4: 493.928 | BJ4: 419.824 | BK4: 530.27 | BL4: 513.461 | BM4: 321.709 | BN4: 698.891 | BO4: 493.24 | BP4: 710.768
A5: 2 | B5: 1.Doanh thu bán hàng và cung cấp dịch vụ | C5: 8 | G5: 368424150 | H5: 539826374 | I5: 10846000 | M5: 85659200 | N5: 502162200 | O5: 21720000 | P5: 106450910 | R5: 265207910 | S5: 235390963 | T5: 549971500 | U5: 1004388000 | V5: 811042500 | W5: 2190311943 | X5: 1430897000 | Y5: 3280888000 | Z5: 2548509050 | AA5: 2627327757 | AB5: 1822423459 | AC5: 1503889814 | AD5: 4340539454 | AE5: 5632467285 | AF5: 3711774521 | AG5: 4642198050 | AH5: 3681484099 | AI5: 3500109250 | AJ5: 3283780279 | AK5: 4161593000 | AL5: 2393981900 | AM5: 5807772500 | AN5: 8400713900 | AO5: 3931174800 | AP5: 5768669300 | AQ5: 5809292600 | AR5: 9485730900 | AS5: 6180931000 | AT5: 4176102000 | AU5: 3625752000 | AV5: 3921219000 | AW5: 4329468100 | AX5: 4671750950 | AY5: 3649641000 | AZ5: 2184030270 | BA5: 4906179695 | BB5: 6333654608 | BC5: 7807068174 | BD5: 7380147015 | BE5: 10556762949 | BF5: 12875151030 | BG5: 13763220740 | BH5: 9904916640 | BI5: 7003708500 | BJ5: 5985740000 | BK5: 7484127000 | BL5: 7320017770 | BM5: 4596489350 | BN5: 9617317135 | BO5: 7009495222 | BP5: 11024894520
A6: 3 | B6: 2.Các khoản giảm trừ doanh thu | C6: 8
A7: 4 | B7: 3.Doanh thu thuần về bán hàng và cung cấp dịch vụ | C7: 8 | D7: 0 | E7: 0 | F7: 0 | G7: 368424150 | H7: 539826374 | I7: 10846000 | J7: 0 | K7: 0 | L7: 0 | M7: 85659200 | N7: 502162200 | O7: 21720000 | P7: 106450910 | Q7: 0 | R7: 265207910 | S7: 235390963 | T7: 549971500 | U7: 1004388000 | V7: 811042500 | W7: 2190311943 | X7: 1430897000 | Y7: 3280888000 | Z7: 2548509050 | AA7: 2627327757 | AB7: 1822423459 | AC7: 1503889814 | AD7: 4340539454 | AE7: 5632467285 | AF7: 3711774521 | AG7: 4642198050 | AH7: 3681484099 | AI7: 3500109250 | AJ7: 3283780279 | AK7: 4161593000 | AL7: 2393981900 | AM7: 5807772500 | AN7: 8400713900 | AO7: 3931174800 | AP7: 5768669300 | AQ7: 5809292600 | AR7: 9485730900 | AS7: 6180931000 | AT7: 4176102000 | AU7: 3625752000 | AV7: 3921219000 | AW7: 4329468100 | AX7: 4671750950 | AY7: 3649641000 | AZ7: 2184030270 | BA7: 4906179695 | BB7: 6333654608 | BC7: 7807068174 | BD7: 7380147015 | BE7: 10556762949 | BF7: 12875151030 | BG7: 13763220740 | BH7: 9904916640 | BI7: 7003708500 | BJ7: 5985740000 | BK7: 7484127000 | BL7: 7320017770 | BM7: =BM5-BM6 -> 4596489350 | BN7: 9617317135 | BO7: 7009495222 | BP7: 11024894520
A8: 5 | B8: 4.Giá vốn hàng bán | C8: 8 | G8: 356035081 | H8: 539685001 | I8: 10850195 | M8: 84649200 | N8: 465251111 | O8: 15974935 | P8: 168407744 | Q8: 5395812 | R8: 236779308 | S8: 207650748 | T8: 435137862 | U8: 918387357 | V8: 738967733 | W8: 1857317418 | X8: 1276370111 | Y8: 2962185705 | Z8: 2312380906 | AA8: 2612701467 | AB8: 2339926056 | AC8: 1617373611 | AD8: 4386031675 | AE8: 4924018381 | AF8: 3584096913 | AG8: 4175851308 | AH8: 3523205486 | AI8: 3237017132 | AJ8: 3209996558 | AK8: 3747756710 | AL8: 2368686966 | AM8: 4587732653 | AN8: 8360095204 | AO8: 3915335812 | AP8: 5491561659 | AQ8: 5777251201 | AR8: 9281674213 | AS8: 6197150720 | AT8: 4472052819 | AU8: 3843795589 | AV8: 4098228510 | AW8: 4453562079 | AX8: 4802207565 | AY8: 3764356934 | AZ8: 2508077713 | BA8: 4740440112 | BB8: 6014198762 | BC8: 7255972077 | BD8: 7126741795 | BE8: 9609629830 | BF8: 11568387569 | BG8: 11854114403 | BH8: 9491382430 | BI8: 6472207694 | BJ8: 5524770244 | BK8: 6694289988 | BL8: 6508047485 | BM8: 4138247394 | BN8: 8386341981 | BO8: 6103584508 | BP8: 9397938637
A9: 6 | B9: 5.Lợi nhuận gộp về bán hàng | C9: 8 | D9: 0 | E9: 0 | F9: 0 | G9: 12389069 | H9: 141373 | I9: -4195 | J9: 0 | K9: 0 | L9: 0 | M9: 1010000 | N9: 36911089 | O9: 5745065 | P9: -61956834 | Q9: -5395812 | R9: 28428602 | S9: 27740215 | T9: 114833638 | U9: 86000643 | V9: 72074767 | W9: 332994525 | X9: 154526889 | Y9: 318702295 | Z9: 236128144 | AA9: 14626290 | AB9: -517502597 | AC9: -113483797 | AD9: -45492221 | AE9: 708448904 | AF9: 127677608 | AG9: 466346742 | AH9: 158278613 | AI9: 263092118 | AJ9: 73783721 | AK9: 413836290 | AL9: 25294934 | AM9: 1220039847 | AN9: 40618696 | AO9: 15838988 | AP9: 277107641 | AQ9: 32041399 | AR9: 204056687 | AS9: -16219720 | AT9: -295950819 | AU9: -218043589 | AV9: -177009510 | AW9: -124093979 | AX9: -130456615 | AY9: -114715934 | AZ9: -324047443 | BA9: 165739583 | BB9: 319455846 | BC9: 551096097 | BD9: 253405220 | BE9: 947133119 | BF9: 1306763461 | BG9: 1909106337 | BH9: 413534210 | BI9: 531500806 | BJ9: 460969756 | BK9: 789837012 | BL9: 811970285 | BM9: =BM7-BM8 -> 458241956 | BN9: =BN7-BN8 -> 1230975154 | BO9: =BO7-BO8 -> 905910714 | BP9: =BP7-BP8 -> 1626955883
A10: 7 | B10: 6.Lãi/lỗ của hoạt động bán, thanh lý bất động sản đầu tư | C10: 8
A11: 8 | B11: 7.Doanh thu hoạt động tài chính | C11: 8 | D11: 107454 | E11: 56525 | F11: 64648 | G11: 175348 | H11: 109741 | I11: 71964 | J11: 33319 | K11: 35780 | L11: 57304 | M11: 40536 | N11: 27652 | O11: 30221 | P11: 100771 | Q11: 22232 | R11: 9940 | S11: 18461 | T11: 51784 | U11: 65299 | V11: 28201 | W11: 103587 | X11: 134052 | Y11: 100634 | Z11: 1758913 | AA11: 2200453 | AB11: 3773270 | AC11: 3236864 | AD11: 2346303 | AE11: 1424265 | AF11: 777811 | AG11: 307201 | AH11: 328719 | AI11: 368024 | AJ11: 352533 | AK11: 313627 | AL11: 161478 | AM11: 13833550 | AN11: 9382459 | AO11: 10579719 | AP11: 9899400 | AQ11: 10580906 | AR11: 10872809 | AS11: 12253869 | AT11: 32961164 | AU11: 10484107 | AV11: 10990062 | AW11: 51973968 | AX11: 11239032 | AY11: 10871181 | AZ11: 56610291 | BA11: 11478700 | BB11: 10596772 | BC11: 57102551 | BD11: 11106781 | BE11: 10419655 | BF11: 56496007 | BG11: 7319275 | BH11: 7346208 | BI11: 52495236 | BJ11: 19072961 | BK11: 18946348 | BL11: 65571081 | BM11: 20192380 | BN11: 18234753 | BO11: 58991700 | BP11: 11002030
A12: 9 | B12: 8.Chi phí tài chính | C12: 8 | P12: 0 | Q12: 0 | R12: 0 | S12: 0 | T12: 0 | U12: 0 | V12: 0 | W12: 0 | X12: 0 | Y12: 0 | Z12: 0 | AA12: 0 | BF12: 3187200
A13: 10 | B13: Trong đó: Chi phí lãi vay | C13: 8 | P13: 0 | Q13: 0 | R13: 0 | S13: 0 | T13: 0 | U13: 0 | V13: 0 | W13: 0 | X13: 0 | Y13: 0 | Z13: 0 | AA13: 0 | BF13: 3187200
A14: 11 | B14: 9.Chi phí bán hàng | C14: 8 | P14: 4154275 | Q14: 111551042 | R14: 110233410 | S14: 127730395 | T14: 186833035 | U14: 196635214 | V14: 194194095 | W14: 278805851 | X14: 297860980 | Y14: 356552796 | Z14: 391895076 | AA14: 648279108 | AB14: 366527895 | AC14: 316438292 | AD14: 474659267 | AE14: 500360421 | AF14: 442222030 | AG14: 537898379 | AH14: 496904815 | AI14: 432396059 | AJ14: 375069710 | AK14: 355199519 | AL14: 319486926 | AM14: 441146680 | AN14: 80500000 | AO14: 92396800 | AP14: 121389600 | AQ14: 78000000 | AR14: 146000000 | AS14: 115500000 | AT14: 64000000 | AU14: 54000000 | AV14: 57900000 | AW14: 75900000 | AX14: 79200000 | AY14: 75900000 | AZ14: 46200000 | BA14: 111100000 | BB14: 142500000 | BC14: 161600000 | BD14: 157100000 | BE14: 207400000 | BF14: 261000000 | BG14: 278300000 | BH14: 246900000 | BI14: 175300000 | BJ14: 144200000 | BK14: 193700000 | BL14: 195900000 | BM14: 121800000 | BN14: 271300000 | BO14: 195300000 | BP14: 262800000
A15: 12 | B15: 10.Chi phí quản lý doanh nghiệp | C15: 8 | D15: 221942434 | E15: 160995395 | F15: 164451697 | G15: 178420921 | H15: 170443955 | I15: 146772545 | J15: 112926597 | K15: 92395770 | L15: 144942481 | M15: 112946309 | N15: 203715505 | O15: 162583369 | P15: 280578279 | Q15: 215624058 | R15: 219366011 | S15: 231890562 | T15: 256308230 | U15: 263761631 | V15: 256193542 | W15: 352498211 | X15: 279335970 | Y15: 316719998 | Z15: 313644325 | AA15: 314893729 | AB15: 171041154 | AC15: 106732861 | AD15: 216653690 | AE15: 175450114 | AF15: 150767254 | AG15: 113915370 | AH15: 131931037 | AI15: 141040749 | AJ15: 159030184 | AK15: 164620496 | AL15: 144231512 | AM15: 279322748 | AN15: 159221608 | AO15: 104655178 | AP15: 115295655 | AQ15: 106050997 | AR15: 66870820 | AS15: 76195851 | AT15: 68152514 | AU15: 139408411 | AV15: 83156007 | AW15: 88772319 | AX15: 552891636 | AY15: 97079504 | AZ15: 147069830 | BA15: 115999204 | BB15: 120706843 | BC15: 155764782 | BD15: 142223547 | BE15: 131398532 | BF15: 129629381 | BG15: 133594277 | BH15: 218907692 | BI15: 204745721 | BJ15: 227424354 | BK15: 505125793 | BL15: 282752757 | BM15: 375736155 | BN15: 268709308 | BO15: 271909211 | BP15: 245121655
A16: 13 | B16: 11.Lợi nhuận thuần từ hoạt động kinh doanh | C16: 8 | D16: -221834980 | E16: -160938870 | F16: -164387049 | G16: -165856504 | H16: -170192841 | I16: -146704776 | J16: -112893278 | K16: -92359990 | L16: -144885177 | M16: -111895773 | N16: -166776764 | O16: -156808083 | P16: -346588617 | Q16: -332548680 | R16: -301160879 | S16: -331862281 | T16: -328255843 | U16: -374330903 | V16: -378284669 | W16: -298205950 | X16: -422536009 | Y16: -354469865 | Z16: -467652344 | AA16: -946346094 | AB16: -1051298376 | AC16: -533418086 | AD16: -734458875 | AE16: 34062634 | AF16: -464533865 | AG16: -185159806 | AH16: -470228520 | AI16: -309976666 | AJ16: -459963640 | AK16: -105670098 | AL16: -438262026 | AM16: 513403969 | AN16: -189720453 | AO16: -170633271 | AP16: 50321786 | AQ16: -141428692 | AR16: 2058676 | AS16: -195661702 | AT16: -395142169 | AU16: -400967893 | AV16: -307075455 | AW16: -236792330 | AX16: -751309219 | AY16: -276824257 | AZ16: -460706982 | BA16: -49880921 | BB16: 66845775 | BC16: 290833866 | BD16: -34811546 | BE16: 618754242 | BF16: 969442887 | BG16: 1504531335 | BH16: -44927274 | BI16: 203950321 | BJ16: 108418363 | BK16: =+BK9+BK11-BK12-BK14-BK15 -> 109957567 | BL16: 398888609 | BM16: =SUM(BM9:BM11)-BM12-BM14-BM15 -> -19101819 | BN16: =SUM(BN9:BN11)-BN12-BN14-BN15 -> 709200599 | BO16: =SUM(BO9:BO11)-BO12-BO14-BO15 -> 497693203 | BP16: =SUM(BP9:BP11)-BP12-BP14-BP15 -> 1130036258
A17: 14 | B17: 12.Thu nhập khác | C17: 8 | P17: 500 | Q17: 500 | S17: 8003 | T17: 20000 | U17: 310 | Z17: 2683400000 | AA17: 3497668000 | AB17: 9000 | AJ17: 1 | AQ17: 81700000 | AT17: 539351 | AZ17: 76532366 | BA17: 300 | BB17: 13680000 | BC17: 6000060 | BF17: 70515 | BK17: 33444721 | BL17: 32987038 | BM17: 2504914 | BN17: 4888889 | BO17: 13183210 | BP17: 26861111
A18: 15 | B18: 13.Chi phí khác | C18: 8 | E18: 2500000 | F18: 800000 | O18: 382314178 | T18: 46 | Y18: 2428 | Z18: 3077644948 | AA18: 3724188338 | AB18: 10 | AF18: 90501 | AI18: 1 | AJ18: 1 | AO18: 4500000 | AQ18: 81718690 | AX18: 136092961 | AZ18: 36339675 | BC18: 6000000 | BK18: 48000 | BL18: 0 | BN18: 450 | BO18: 22019946
A19: 16 | B19: 14.Lợi nhuận khác | C19: 8 | D19: 0 | E19: -2500000 | F19: -800000 | G19: 0 | H19: 0 | I19: 0 | J19: 0 | K19: 0 | L19: 0 | M19: 0 | N19: 0 | O19: -382314178 | P19: 500 | Q19: 500 | R19: 0 | S19: 8003 | T19: 19954 | U19: 310 | V19: 0 | W19: 0 | X19: 0 | Y19: -2428 | Z19: -394244948 | AA19: -226520338 | AB19: 8990 | AC19: 0 | AD19: 0 | AE19: 0 | AF19: -90501 | AG19: 0 | AH19: 0 | AI19: -1 | AJ19: 0 | AK19: 0 | AL19: 0 | AM19: 0 | AN19: 0 | AO19: -4500000 | AP19: 0 | AQ19: -18690 | AR19: 0 | AS19: 0 | AT19: 539351 | AU19: 0 | AV19: 0 | AW19: 0 | AX19: -136092961 | AY19: 0 | AZ19: 40192691 | BA19: 300 | BB19: 13680000 | BC19: 60 | BD19: 0 | BE19: 0 | BF19: 70515 | BG19: 0 | BH19: 0 | BI19: 0 | BJ19: 0 | BK19: 33396721 | BL19: 32987038 | BM19: =BM17-BM18 -> 2504914 | BN19: =BN17-BN18 -> 4888439 | BO19: =BO17-BO18 -> -8836736 | BP19: =BP17-BP18 -> 26861111
