Workbook

Sheet Thong tin
A1: CÔNG TY CỔ PHẦN TÁI CHẾ TÂN ĐẠI PHÁT
A2: Địa chỉ: Số C11-C15 Cụm Công Nghiệp Nhựa Đức Hòa, Ấp Bình Tiền 2, Xã Đức Hòa, Tây Ninh
A3: Mã số thuế: 1102066435
A4: Deadline ngày 5 tây hàng tháng
B6: Năm tài chính hiện tại | C6: 2026
B7: Năm trước | C7: =C6-1 -> 2025
B9: Tháng báo cáo hiện tại | C9: 4
B12: NGƯỜI LẬP BIỂU
B13: Vũ Thị Hiên
B15: KẾ TOÁN TRƯỞNG
B16: Vũ Thị Hiên
B18: GIÁM ĐỐC TÀI CHÍNH
B19: Nguyễn Bảo Quốc

Sheet BIA
B29: THÁNG 04 NĂM 2026
B50: Thành phố Hồ Chí Minh, Ngày 30 tháng 04 năm 2026

Sheet Index
A1: ='Thong tin'!A1 -> CÔNG TY CỔ PHẦN TÁI CHẾ TÂN ĐẠI PHÁT | I1: BÁO CÁO TÀI CHÍNH
A2: ='Thong tin'!A2 -> Địa chỉ: Số C11-C15 Cụm Công Nghiệp Nhựa Đức Hòa, Ấp Bình Tiền 2, Xã Đức Hòa, Tây Ninh
A10: ="BÁO CÁO TÀI CHÍNH THÁNG "&'Thong tin'!C9&" NĂM 2026" -> BÁO CÁO TÀI CHÍNH THÁNG 4 NĂM 2026 | I10: Trang
A12: BÁO CÁO CỦA BAN GIÁM ĐỐC | I12: 2 - 3
A13: BÁO CÁO KIỂM TOÁN | I13: 4 - 4
A14: - Bảng cân đối kế toán | I14: 1 - 4
A15: - Báo cáo kết quả hoạt động kinh doanh | I15: 5
A16: - Báo cáo lưu chuyển tiền tệ | I16: 6 - 7
A17: - Bản thuyết minh báo cáo tài chính | I17: 11 - 31
A30: (Báo cáo tài chính được lập và trình bày theo Quyết định số 15/2006/QĐ-BTC ngày 20/03/2006
A31: của Bộ trưởng Bộ Tài Chính)

Sheet THTC in
A1: ='Thong tin'!$A$1 -> CÔNG TY CỔ PHẦN TÁI CHẾ TÂN ĐẠI PHÁT
A2: ='Thong tin'!$A$2 -> Địa chỉ: Số C11-C15 Cụm Công Nghiệp Nhựa Đức Hòa, Ấp Bình Tiền 2, Xã Đức Hòa, Tây Ninh
A4: BÁO CÁO TÌNH HÌNH TÀI CHÍNH
A5: ="Năm " & 'Thong tin'!$C$6 -> Năm 2026
C6: ='KQKD in'!G6 -> ĐVT: VNĐ
A7: TÀI SẢN | B7: ="Số cuối tháng"&" "&$D$7 -> Số cuối tháng 4 | C7: ="Số dư đầu năm " & 'Thong tin'!$C$6 -> Số dư đầu năm 2026 | D7: ='Thong tin'!C9 -> 4
A8: A . TÀI SẢN NGẮN HẠN | B8: =B10+B14+B22+B31+B40 -> 20740505081 | C8: =C10+C14+C22+C31+C40 -> 21734218198
A10: I. Tiền và các khoản tương đương tiền | B10: =SUM(B11:B12) -> 828313208 | C10: =SUM(C11:C12) -> 822026325
A11: 1. Tiền | B11: =OFFSET('Tinh hinh tai chinh'!$BL6,0,'THTC in'!$D$7 - 1) -> 128313208 | C11: ='Tinh hinh tai chinh'!BK6 -> 122026325
A12: 2. Các khoản tương đương tiền | B12: =OFFSET('Tinh hinh tai chinh'!$BL7,0,'THTC in'!$D$7 - 1) -> 700000000 | C12: ='Tinh hinh tai chinh'!BK7 -> 700000000
A14: II. Các khoản đầu tư tài chính ngắn hạn | B14: =SUM(B15:B20) -> 0 | C14: =SUM(C15:C20) -> 0
A15: 1.Chứng khoán kinh doanh | B15: =OFFSET('Tinh hinh tai chinh'!$BL9,0,'THTC in'!$D$7 - 1) -> 0 | C15: ='Tinh hinh tai chinh'!BK9 -> 0
A16: 2.Dự phòng giảm giá chứng khoán kinh doanh (*) | B16: =OFFSET('Tinh hinh tai chinh'!$BL10,0,'THTC in'!$D$7 - 1) -> 0 | C16: ='Tinh hinh tai chinh'!BK10 -> 0
A17: 3.Đầu tư nắm giữ đến ngày đáo hạn ngắn hạn | B17: =OFFSET('Tinh hinh tai chinh'!$BL11,0,'THTC in'!$D$7 - 1) -> 0 | C17: ='Tinh hinh tai chinh'!BK11 -> 0
A18: 4.Dự phòng đầu tư nắm giữ đến ngày đáo hạn ngắn hạn (*) | B18: =OFFSET('Tinh hinh tai chinh'!$BL12,0,'THTC in'!$D$7 - 1) -> 0 | C18: ='Tinh hinh tai chinh'!BK12 -> 0
A19: 5.Đầu tư ngắn hạn khác | B19: =OFFSET('Tinh hinh tai chinh'!$BL13,0,'THTC in'!$D$7 - 1) -> 0 | C19: ='Tinh hinh tai chinh'!BK13 -> 0
A20: 6.Dự phòng tổn thất các khoản đầu tư ngắn hạn khác (*) | B20: =OFFSET('Tinh hinh tai chinh'!$BL14,0,'THTC in'!$D$7 - 1) -> 0 | C20: ='Tinh hinh tai chinh'!BK14 -> 0
A22: III. Các khoản phải thu ngắn hạn | B22: =SUM(B23:B29) -> 19000000000 | C22: =SUM(C23:C29) -> 20000000000
A23: 1.Phải thu ngắn hạn của khách hàng | B23: =OFFSET('Tinh hinh tai chinh'!$BL16,0,'THTC in'!$D$7 - 1) -> 0 | C23: ='Tinh hinh tai chinh'!BK16 -> 0
A24: 2.Trả trước cho người bán ngắn hạn | B24: =OFFSET('Tinh hinh tai chinh'!$BL17,0,'THTC in'!$D$7 - 1) -> 0 | C24: ='Tinh hinh tai chinh'!BK17 -> 0
A25: 3.Phải thu nội bộ ngắn hạn | B25: =OFFSET('Tinh hinh tai chinh'!$BL18,0,'THTC in'!$D$7 - 1) -> 0 | C25: ='Tinh hinh tai chinh'!BK18 -> 0
A26: 4.Phải thu theo tiến độ hợp đồng xây dựng | B26: =OFFSET('Tinh hinh tai chinh'!$BL19,0,'THTC in'!$D$7 - 1) -> 0 | C26: ='Tinh hinh tai chinh'!BK19 -> 0
A27: 5.Phải thu ngắn hạn khác | B27: =OFFSET('Tinh hinh tai chinh'!$BL20,0,'THTC in'!$D$7 - 1) -> 19000000000 | C27: ='Tinh hinh tai chinh'!BK20 -> 20000000000
A28: 6.Dự phòng phải thu ngắn hạn khó đòi (*) | B28: =OFFSET('Tinh hinh tai chinh'!$BL21,0,'THTC in'!$D$7 - 1) -> 0 | C28: ='Tinh hinh tai chinh'!BK21 -> 0
A29: 7.Tài sản thiếu chờ xử lý | B29: =OFFSET('Tinh hinh tai chinh'!$BL22,0,'THTC in'!$D$7 - 1) -> 0 | C29: ='Tinh hinh tai chinh'!BK22 -> 0
A31: IV. Hàng tồn kho | B31: =SUM(B32:B33) -> 0 | C31: =SUM(C32:C33) -> 0
A32: 1. Hàng tồn kho | B32: =OFFSET('Tinh hinh tai chinh'!$BL24,0,'THTC in'!$D$7 - 1) -> 0 | C32: ='Tinh hinh tai chinh'!BK24 -> 0
A33: 2. Dự phòng giảm giá hàng tồn kho (*) | B33: =OFFSET('Tinh hinh tai chinh'!$BL25,0,'THTC in'!$D$7 - 1) -> 0 | C33: ='Tinh hinh tai chinh'!BK25 -> 0
A35: V. Tài sản sinh học ngắn hạn | B35: =SUM(B36:B38) -> 0 | C35: =SUM(C36:C38) -> 0
A36: 1.Súc vật nuôi lấy sản phẩm một lần ngắn hạn | B36: =OFFSET('Tinh hinh tai chinh'!$BL27,0,'THTC in'!$D$7 - 1) -> 0 | C36: ='Tinh hinh tai chinh'!BK27 -> 0
A37: 2.Cây trồng theo mùa vụ hoặc lấy sản phẩm một lần ngắn hạn | B37: =OFFSET('Tinh hinh tai chinh'!$BL28,0,'THTC in'!$D$7 - 1) -> 0 | C37: ='Tinh hinh tai chinh'!BK28 -> 0
A38: 3.Dự phòng tổn thất tài sản sinh học ngắn hạn (*) | B38: =OFFSET('Tinh hinh tai chinh'!$BL29,0,'THTC in'!$D$7 - 1) -> 0 | C38: ='Tinh hinh tai chinh'!BK29 -> 0
A40: VI. Tài sản ngắn hạn khác | B40: =SUM(B41:B45) -> 912191873 | C40: =SUM(C41:C45) -> 912191873
A41: 1.Chi phí chờ phân bổ ngắn hạn | B41: =OFFSET('Tinh hinh tai chinh'!$BL31,0,'THTC in'!$D$7 - 1) -> 0 | C41: ='Tinh hinh tai chinh'!BK31 -> 0
A42: 2.Thuế GTGT được khấu trừ | B42: =OFFSET('Tinh hinh tai chinh'!$BL32,0,'THTC in'!$D$7 - 1) -> 912191873 | C42: ='Tinh hinh tai chinh'!BK32 -> 912191873
A43: 3.Thuế và các khoản khác phải thu Nhà nước | B43: =OFFSET('Tinh hinh tai chinh'!$BL33,0,'THTC in'!$D$7 - 1) -> 0 | C43: ='Tinh hinh tai chinh'!BK33 -> 0
A44: 4.Giao dịch mua bán lại trái phiếu Chính phủ | B44: =OFFSET('Tinh hinh tai chinh'!$BL34,0,'THTC in'!$D$7 - 1) -> 0 | C44: ='Tinh hinh tai chinh'!BK34 -> 0
A45: 5.Tài sản ngắn hạn khác | B45: =OFFSET('Tinh hinh tai chinh'!$BL35,0,'THTC in'!$D$7 - 1) -> 0 | C45: ='Tinh hinh tai chinh'!BK35 -> 0
A47: B. TÀI SẢN DÀI HẠN | B47: =B48+B58+B79+B87+B95+B83 -> 11003914 | C47: =C48+C58+C79+C87+C95+C83 -> 13342862
A48: I.Các khoản phải thu dài hạn | B48: =SUM(B49:B54) -> 0 | C48: =SUM(C49:C54) -> 0
...

Sheet KQKD in
A1: ='Thong tin'!$A$1 -> CÔNG TY CỔ PHẦN TÁI CHẾ TÂN ĐẠI PHÁT
A2: ='Thong tin'!$A$2 -> Địa chỉ: Số C11-C15 Cụm Công Nghiệp Nhựa Đức Hòa, Ấp Bình Tiền 2, Xã Đức Hòa, Tây Ninh
A4: BÁO CÁO KẾT QUẢ HOẠT ĐỘNG KINH DOANH
A5: ="Năm " & 'Thong tin'!$C$6 -> Năm 2026
G6: ĐVT: VNĐ
A8: Chỉ tiêu | D8: ="Tháng "&'Thong tin'!$C$9 -> Tháng 4 | F8: ="Lũy kế"&" "&'Thong tin'!$C$9 &" "&"tháng" -> Lũy kế 4 tháng
D9: ="Năm " & 'Thong tin'!$C$6 -> Năm 2026 | E9: ="Năm " & 'Thong tin'!$C$7 -> Năm 2025 | F9: ="Năm " & 'Thong tin'!$C$6 -> Năm 2026 | G9: ="Năm " & 'Thong tin'!$C$7 -> Năm 2025
A10: 1. | B10: Doanh thu bán hàng và cung cấp dịch vụ | D10: =OFFSET('Ket qua kinh doanh'!$BL5,0,'Thong tin'!$C$9 - 1) -> 0 | E10: =OFFSET('Ket qua kinh doanh'!$AZ5,0,'Thong tin'!$C$9 - 1) -> 0 | F10: =SUM(OFFSET('Ket qua kinh doanh'!$BL5,0,0,1,'Thong tin'!$C$9)) -> 0 | G10: =SUM(OFFSET('Ket qua kinh doanh'!$AZ5,0,0,1,'Thong tin'!$C$9)) -> 0
A11: 2. | B11: Các khoản giảm trừ doanh thu | D11: =OFFSET('Ket qua kinh doanh'!$BL6,0,'Thong tin'!$C$9 - 1) -> 0 | E11: =OFFSET('Ket qua kinh doanh'!$AZ6,0,'Thong tin'!$C$9 - 1) -> 0 | F11: =SUM(OFFSET('Ket qua kinh doanh'!$BL6,0,0,1,'Thong tin'!$C$9)) -> 0 | G11: =SUM(OFFSET('Ket qua kinh doanh'!$AZ6,0,0,1,'Thong tin'!$C$9)) -> 0
A12: 3. | B12: Doanh thu thuần về bán hàng và cung cấp dịch vụ | D12: =OFFSET('Ket qua kinh doanh'!$BL7,0,'Thong tin'!$C$9 - 1) -> 0 | E12: =OFFSET('Ket qua kinh doanh'!$AZ7,0,'Thong tin'!$C$9 - 1) -> 0 | F12: =SUM(OFFSET('Ket qua kinh doanh'!$BL7,0,0,1,'Thong tin'!$C$9)) -> 0 | G12: =SUM(OFFSET('Ket qua kinh doanh'!$AZ7,0,0,1,'Thong tin'!$C$9)) -> 0
A13: 4. | B13: Giá vốn hàng bán | D13: =OFFSET('Ket qua kinh doanh'!$BL8,0,'Thong tin'!$C$9 - 1) -> 0 | E13: =OFFSET('Ket qua kinh doanh'!$AZ8,0,'Thong tin'!$C$9 - 1) -> 0 | F13: =SUM(OFFSET('Ket qua kinh doanh'!$BL8,0,0,1,'Thong tin'!$C$9)) -> 0 | G13: =SUM(OFFSET('Ket qua kinh doanh'!$AZ8,0,0,1,'Thong tin'!$C$9)) -> 0
A14: 5. | B14: Lợi nhuận gộp về bán hàng và cung cấp dịch vụ | D14: =OFFSET('Ket qua kinh doanh'!$BL9,0,'Thong tin'!$C$9 - 1) -> 0 | E14: =OFFSET('Ket qua kinh doanh'!$AZ9,0,'Thong tin'!$C$9 - 1) -> 0 | F14: =SUM(OFFSET('Ket qua kinh doanh'!$BL9,0,0,1,'Thong tin'!$C$9)) -> 0 | G14: =SUM(OFFSET('Ket qua kinh doanh'!$AZ9,0,0,1,'Thong tin'!$C$9)) -> 0
A15: 6. | B15: Lãi/lỗ của hoạt động bán, thanh lý bất động sản đầu tư | D15: =OFFSET('Ket qua kinh doanh'!$BL10,0,'Thong tin'!$C$9 - 1) -> 0 | E15: =OFFSET('Ket qua kinh doanh'!$AZ10,0,'Thong tin'!$C$9 - 1) -> 0 | F15: =SUM(OFFSET('Ket qua kinh doanh'!$BL10,0,0,1,'Thong tin'!$C$9)) -> 0 | G15: =SUM(OFFSET('Ket qua kinh doanh'!$AZ10,0,0,1,'Thong tin'!$C$9)) -> 0
A16: 7. | B16: Doanh thu hoạt động tài chính | D16: =OFFSET('Ket qua kinh doanh'!$BL11,0,'Thong tin'!$C$9 - 1) -> 1090 | E16: =OFFSET('Ket qua kinh doanh'!$AZ11,0,'Thong tin'!$C$9 - 1) -> 3453516 | F16: =SUM(OFFSET('Ket qua kinh doanh'!$BL11,0,0,1,'Thong tin'!$C$9)) -> 6286883 | G16: =SUM(OFFSET('Ket qua kinh doanh'!$AZ11,0,0,1,'Thong tin'!$C$9)) -> 3475152
A17: 8. | B17: Chi phí tài chính | D17: =OFFSET('Ket qua kinh doanh'!$BL12,0,'Thong tin'!$C$9 - 1) -> 0 | E17: =OFFSET('Ket qua kinh doanh'!$AZ12,0,'Thong tin'!$C$9 - 1) -> 0 | F17: =SUM(OFFSET('Ket qua kinh doanh'!$BL12,0,0,1,'Thong tin'!$C$9)) -> 0 | G17: =SUM(OFFSET('Ket qua kinh doanh'!$AZ12,0,0,1,'Thong tin'!$C$9)) -> 0
B18: Trong đó: chi phí lãi vay | D18: =OFFSET('Ket qua kinh doanh'!$BL13,0,'Thong tin'!$C$9 - 1) -> 0 | E18: =OFFSET('Ket qua kinh doanh'!$AZ13,0,'Thong tin'!$C$9 - 1) -> 0 | F18: =SUM(OFFSET('Ket qua kinh doanh'!$BL13,0,0,1,'Thong tin'!$C$9)) -> 0 | G18: =SUM(OFFSET('Ket qua kinh doanh'!$AZ13,0,0,1,'Thong tin'!$C$9)) -> 0
A19: 9. | B19: Chi phí bán hàng | D19: =OFFSET('Ket qua kinh doanh'!$BL14,0,'Thong tin'!$C$9 - 1) -> 0 | E19: =OFFSET('Ket qua kinh doanh'!$AZ14,0,'Thong tin'!$C$9 - 1) -> 0 | F19: =SUM(OFFSET('Ket qua kinh doanh'!$BL14,0,0,1,'Thong tin'!$C$9)) -> 0 | G19: =SUM(OFFSET('Ket qua kinh doanh'!$AZ14,0,0,1,'Thong tin'!$C$9)) -> 0
A20: 10. | B20: Chi phí quản lý doanh nghiệp | D20: =OFFSET('Ket qua kinh doanh'!$BL15,0,'Thong tin'!$C$9 - 1) -> 584737 | E20: =OFFSET('Ket qua kinh doanh'!$AZ15,0,'Thong tin'!$C$9 - 1) -> 616214737 | F20: =SUM(OFFSET('Ket qua kinh doanh'!$BL15,0,0,1,'Thong tin'!$C$9)) -> 2338948 | G20: =SUM(OFFSET('Ket qua kinh doanh'!$AZ15,0,0,1,'Thong tin'!$C$9)) -> 2465968948
A21: 11. | B21: Lợi nhuận thuần từ hoạt động kinh doanh | D21: =OFFSET('Ket qua kinh doanh'!$BL16,0,'Thong tin'!$C$9 - 1) -> -583647 | E21: =OFFSET('Ket qua kinh doanh'!$AZ16,0,'Thong tin'!$C$9 - 1) -> -612761221 | F21: =SUM(OFFSET('Ket qua kinh doanh'!$BL16,0,0,1,'Thong tin'!$C$9)) -> 3947935 | G21: =SUM(OFFSET('Ket qua kinh doanh'!$AZ16,0,0,1,'Thong tin'!$C$9)) -> -2462493796
A22: 12. | B22: Thu nhập khác | D22: =OFFSET('Ket qua kinh doanh'!$BL17,0,'Thong tin'!$C$9 - 1) -> 0 | E22: =OFFSET('Ket qua kinh doanh'!$AZ17,0,'Thong tin'!$C$9 - 1) -> 0 | F22: =SUM(OFFSET('Ket qua kinh doanh'!$BL17,0,0,1,'Thong tin'!$C$9)) -> 0 | G22: =SUM(OFFSET('Ket qua kinh doanh'!$AZ17,0,0,1,'Thong tin'!$C$9)) -> 0
A23: 13. | B23: Chi phí khác | D23: =OFFSET('Ket qua kinh doanh'!$BL18,0,'Thong tin'!$C$9 - 1) -> 0 | E23: =OFFSET('Ket qua kinh doanh'!$AZ18,0,'Thong tin'!$C$9 - 1) -> 0 | F23: =SUM(OFFSET('Ket qua kinh doanh'!$BL18,0,0,1,'Thong tin'!$C$9)) -> 161000 | G23: =SUM(OFFSET('Ket qua kinh doanh'!$AZ18,0,0,1,'Thong tin'!$C$9)) -> 0
A24: 14. | B24: Lợi nhuận khác | D24: =OFFSET('Ket qua kinh doanh'!$BL19,0,'Thong tin'!$C$9 - 1) -> 0 | E24: =OFFSET('Ket qua kinh doanh'!$AZ19,0,'Thong tin'!$C$9 - 1) -> 0 | F24: =SUM(OFFSET('Ket qua kinh doanh'!$BL19,0,0,1,'Thong tin'!$C$9)) -> -161000 | G24: =SUM(OFFSET('Ket qua kinh doanh'!$AZ19,0,0,1,'Thong tin'!$C$9)) -> 0
A25: 15. | B25: Tổng lợi nhuận kế toán trước thuế | D25: =OFFSET('Ket qua kinh doanh'!$BL20,0,'Thong tin'!$C$9 - 1) -> -583647 | E25: =OFFSET('Ket qua kinh doanh'!$AZ20,0,'Thong tin'!$C$9 - 1) -> -612761221 | F25: =SUM(OFFSET('Ket qua kinh doanh'!$BL20,0,0,1,'Thong tin'!$C$9)) -> 3786935 | G25: =SUM(OFFSET('Ket qua kinh doanh'!$AZ20,0,0,1,'Thong tin'!$C$9)) -> -2462493796
A26: 16. | B26: Chi phí thuế TNDN hiện hành (*) | D26: =OFFSET('Ket qua kinh doanh'!$BL21,0,'Thong tin'!$C$9 - 1) -> 0 | E26: =OFFSET('Ket qua kinh doanh'!$AZ21,0,'Thong tin'!$C$9 - 1) -> 0 | F26: =SUM(OFFSET('Ket qua kinh doanh'!$BL21,0,0,1,'Thong tin'!$C$9)) -> 0 | G26: =SUM(OFFSET('Ket qua kinh doanh'!$AZ21,0,0,1,'Thong tin'!$C$9)) -> 0
A27: 17. | B27: Chi phí thuế TNDN hoãn lại | D27: =OFFSET('Ket qua kinh doanh'!$BL22,0,'Thong tin'!$C$9 - 1) -> 0 | E27: =OFFSET('Ket qua kinh doanh'!$AZ22,0,'Thong tin'!$C$9 - 1) -> 0 | F27: =SUM(OFFSET('Ket qua kinh doanh'!$BL22,0,0,1,'Thong tin'!$C$9)) -> 0 | G27: =SUM(OFFSET('Ket qua kinh doanh'!$AZ22,0,0,1,'Thong tin'!$C$9)) -> 0
A28: 18. | B28: Lợi nhuận sau thuế | D28: =OFFSET('Ket qua kinh doanh'!$BL23,0,'Thong tin'!$C$9 - 1) -> -583647 | E28: =OFFSET('Ket qua kinh doanh'!$AZ23,0,'Thong tin'!$C$9 - 1) -> -612761221 | F28: =SUM(OFFSET('Ket qua kinh doanh'!$BL23,0,0,1,'Thong tin'!$C$9)) -> 3786935 | G28: =SUM(OFFSET('Ket qua kinh doanh'!$AZ23,0,0,1,'Thong tin'!$C$9)) -> -2462493796
A29: 19. | B29: Lãi cơ bản trên cổ phiếu | F29: =#REF!+#REF!+#REF!+#REF!+#REF!+#REF!+#REF!+#REF!+#REF!+#REF!+#REF!+D29 -> #REF! | G29: =#REF!+#REF!+#REF!+#REF!+#REF!+#REF!+#REF!+#REF!+#REF!+#REF!+#REF!+E29 -> #REF!
D31: 0 | E31: 0 | F31: 0 | G31: 0
F32: Lập ngày 30 tháng 04 năm 2026
B34: KẾ TOÁN TRƯỞNG | F34: ='Thong tin'!B18 -> GIÁM ĐỐC TÀI CHÍNH
B41: ='Thong tin'!B13 -> Vũ Thị Hiên | F41: Nguyễn Bảo Quốc

Sheet LCTT_GT in
A1: ='Thong tin'!$A$1 -> CÔNG TY CỔ PHẦN TÁI CHẾ TÂN ĐẠI PHÁT
A2: ='Thong tin'!$A$2 -> Địa chỉ: Số C11-C15 Cụm Công Nghiệp Nhựa Đức Hòa, Ấp Bình Tiền 2, Xã Đức Hòa, Tây Ninh
A4: BÁO CÁO LƯU CHUYỂN TIỀN TỆ
A5: (Theo phương pháp gián tiếp)
A6: ="Năm " & 'Thong tin'!$C$6 -> Năm 2026
E7: ='KQKD in'!G6 -> ĐVT: VNĐ
A8: Chỉ tiêu | B8: ="Tháng " & 'Thong tin'!$C$9 -> Tháng 4 | D8: ="Lũy kế"&" "& 'Thong tin'!$C$9 &" "&"tháng" -> Lũy kế 4 tháng
B9: ="Năm " & 'Thong tin'!$C$6 -> Năm 2026 | C9: ="Năm " & 'Thong tin'!$C$7 -> Năm 2025 | D9: ="Năm " & 'Thong tin'!$C$6 -> Năm 2026 | E9: ="Năm " & 'Thong tin'!$C$7 -> Năm 2025
A10: I. Lưu chuyển tiền từ hoạt động kinh doanh
A11: 1. Lợi nhuận trước thuế | B11: =OFFSET('Luu chuyen tien te'!$BL5,0,'Thong tin'!$C$9 - 1) -> -583647 | C11: =OFFSET('Luu chuyen tien te'!$AZ5,0,'Thong tin'!$C$9 - 1) -> -612761221 | D11: =SUM(OFFSET('Luu chuyen tien te'!$BL5,0,0,1,'Thong tin'!$C$9)) -> 3786935 | E11: =SUM(OFFSET('Luu chuyen tien te'!$AZ5,0,0,1,'Thong tin'!$C$9)) -> -2462493796
A12: 2. Điều chỉnh cho các khoản
A13: - Khấu hao tài sản cố định và BĐSĐT | B13: =OFFSET('Luu chuyen tien te'!$BL7,0,'Thong tin'!$C$9 - 1) -> 0 | C13: =OFFSET('Luu chuyen tien te'!$AZ7,0,'Thong tin'!$C$9 - 1) -> 0 | D13: =SUM(OFFSET('Luu chuyen tien te'!$BL7,0,0,1,'Thong tin'!$C$9)) -> 0 | E13: =SUM(OFFSET('Luu chuyen tien te'!$AZ7,0,0,1,'Thong tin'!$C$9)) -> 0
A14: - Các khoản dự phòng | B14: =OFFSET('Luu chuyen tien te'!$BL8,0,'Thong tin'!$C$9 - 1) -> 0 | C14: =OFFSET('Luu chuyen tien te'!$AZ8,0,'Thong tin'!$C$9 - 1) -> 0 | D14: =SUM(OFFSET('Luu chuyen tien te'!$BL8,0,0,1,'Thong tin'!$C$9)) -> 0 | E14: =SUM(OFFSET('Luu chuyen tien te'!$AZ8,0,0,1,'Thong tin'!$C$9)) -> 0
A15: - Lãi, lỗ chênh lệch tỷ giá hối đoái do đánh giá lại các khoản mục tiền tệ có gốc ngoại tệ | B15: =OFFSET('Luu chuyen tien te'!$BL9,0,'Thong tin'!$C$9 - 1) -> 0 | C15: =OFFSET('Luu chuyen tien te'!$AZ9,0,'Thong tin'!$C$9 - 1) -> 0 | D15: =SUM(OFFSET('Luu chuyen tien te'!$BL9,0,0,1,'Thong tin'!$C$9)) -> 0 | E15: =SUM(OFFSET('Luu chuyen tien te'!$AZ9,0,0,1,'Thong tin'!$C$9)) -> 0
A16: - Lãi lỗ từ hoạt động đầu tư, tài chính | B16: =OFFSET('Luu chuyen tien te'!$BL10,0,'Thong tin'!$C$9 - 1) -> -1090 | C16: =OFFSET('Luu chuyen tien te'!$AZ10,0,'Thong tin'!$C$9 - 1) -> -3453516 | D16: =SUM(OFFSET('Luu chuyen tien te'!$BL10,0,0,1,'Thong tin'!$C$9)) -> -6286883 | E16: =SUM(OFFSET('Luu chuyen tien te'!$AZ10,0,0,1,'Thong tin'!$C$9)) -> -3475152
A17: - Chi phí đi vay | B17: =OFFSET('Luu chuyen tien te'!$BL11,0,'Thong tin'!$C$9 - 1) -> 0 | C17: =OFFSET('Luu chuyen tien te'!$AZ11,0,'Thong tin'!$C$9 - 1) -> 0 | D17: =SUM(OFFSET('Luu chuyen tien te'!$BL11,0,0,1,'Thong tin'!$C$9)) -> 0 | E17: =SUM(OFFSET('Luu chuyen tien te'!$AZ11,0,0,1,'Thong tin'!$C$9)) -> 0
A18: - Các khoản điều chỉnh khác | B18: =OFFSET('Luu chuyen tien te'!$BL12,0,'Thong tin'!$C$9 - 1) -> 0 | C18: =OFFSET('Luu chuyen tien te'!$AZ12,0,'Thong tin'!$C$9 - 1) -> 0 | D18: =SUM(OFFSET('Luu chuyen tien te'!$BL12,0,0,1,'Thong tin'!$C$9)) -> 0 | E18: =SUM(OFFSET('Luu chuyen tien te'!$AZ12,0,0,1,'Thong tin'!$C$9)) -> 0
A19: 3. Lợi nhuận từ hoạt động kinh doanh trước thay đổi vốn lưu động | B19: =SUM(B11:B18) -> -584737 | C19: =SUM(C11:C18) -> -616214737 | D19: =SUM(D11:D18) -> -2499948 | E19: =SUM(E11:E18) -> -2465968948
A20: - Tăng giảm các khoản phải thu | B20: =OFFSET('Luu chuyen tien te'!$BL14,0,'Thong tin'!$C$9 - 1) -> 0 | C20: =OFFSET('Luu chuyen tien te'!$AZ14,0,'Thong tin'!$C$9 - 1) -> -93613000 | D20: =SUM(OFFSET('Luu chuyen tien te'!$BL14,0,0,1,'Thong tin'!$C$9)) -> 0 | E20: =SUM(OFFSET('Luu chuyen tien te'!$AZ14,0,0,1,'Thong tin'!$C$9)) -> -277213000
A21: - Tăng giảm hàng tồn kho | B21: =OFFSET('Luu chuyen tien te'!$BL15,0,'Thong tin'!$C$9 - 1) -> 0 | C21: =OFFSET('Luu chuyen tien te'!$AZ15,0,'Thong tin'!$C$9 - 1) -> 0 | D21: =SUM(OFFSET('Luu chuyen tien te'!$BL15,0,0,1,'Thong tin'!$C$9)) -> 0 | E21: =SUM(OFFSET('Luu chuyen tien te'!$AZ15,0,0,1,'Thong tin'!$C$9)) -> 0
A22: - Tăng giảm các khoản phải trả (Không bao gồm lãi vay phải trả, thuế TNDN phải nộp) | B22: =OFFSET('Luu chuyen tien te'!$BL16,0,'Thong tin'!$C$9 - 1) -> 0 | C22: =OFFSET('Luu chuyen tien te'!$AZ16,0,'Thong tin'!$C$9 - 1) -> 660000000 | D22: =SUM(OFFSET('Luu chuyen tien te'!$BL16,0,0,1,'Thong tin'!$C$9)) -> 161000 | E22: =SUM(OFFSET('Luu chuyen tien te'!$AZ16,0,0,1,'Thong tin'!$C$9)) -> 2638222222
A23: - Tăng giảm chi phí chờ phân bổ | B23: =OFFSET('Luu chuyen tien te'!$BL17,0,'Thong tin'!$C$9 - 1) -> 584737 | C23: =OFFSET('Luu chuyen tien te'!$AZ17,0,'Thong tin'!$C$9 - 1) -> 584737 | D23: =SUM(OFFSET('Luu chuyen tien te'!$BL17,0,0,1,'Thong tin'!$C$9)) -> 2338948 | E23: =SUM(OFFSET('Luu chuyen tien te'!$AZ17,0,0,1,'Thong tin'!$C$9)) -> 2338948
A24: - Tăng, giảm chứng khoán kinh doanh | B24: =OFFSET('Luu chuyen tien te'!$BL18,0,'Thong tin'!$C$9 - 1) -> 0 | C24: =OFFSET('Luu chuyen tien te'!$AZ18,0,'Thong tin'!$C$9 - 1) -> 0 | D24: =SUM(OFFSET('Luu chuyen tien te'!$BL18,0,0,1,'Thong tin'!$C$9)) -> 0 | E24: =SUM(OFFSET('Luu chuyen tien te'!$AZ18,0,0,1,'Thong tin'!$C$9)) -> 0
A25: - Chi phí đi vay đã trả | B25: =OFFSET('Luu chuyen tien te'!$BL19,0,'Thong tin'!$C$9 - 1) -> 0 | C25: =OFFSET('Luu chuyen tien te'!$AZ19,0,'Thong tin'!$C$9 - 1) -> 0 | D25: =SUM(OFFSET('Luu chuyen tien te'!$BL19,0,0,1,'Thong tin'!$C$9)) -> 0 | E25: =SUM(OFFSET('Luu chuyen tien te'!$AZ19,0,0,1,'Thong tin'!$C$9)) -> 0
A26: - Thuế thu nhập doanh nghiệp đã nộp | B26: =OFFSET('Luu chuyen tien te'!$BL20,0,'Thong tin'!$C$9 - 1) -> 0 | C26: =OFFSET('Luu chuyen tien te'!$AZ20,0,'Thong tin'!$C$9 - 1) -> 0 | D26: =SUM(OFFSET('Luu chuyen tien te'!$BL20,0,0,1,'Thong tin'!$C$9)) -> 0 | E26: =SUM(OFFSET('Luu chuyen tien te'!$AZ20,0,0,1,'Thong tin'!$C$9)) -> 0
A27: - Tiền thu khác từ hoạt động kinh doanh | B27: =OFFSET('Luu chuyen tien te'!$BL21,0,'Thong tin'!$C$9 - 1) -> 0 | C27: =OFFSET('Luu chuyen tien te'!$AZ21,0,'Thong tin'!$C$9 - 1) -> 0 | D27: =SUM(OFFSET('Luu chuyen tien te'!$BL21,0,0,1,'Thong tin'!$C$9)) -> 0 | E27: =SUM(OFFSET('Luu chuyen tien te'!$AZ21,0,0,1,'Thong tin'!$C$9)) -> 0
A28: - Tiền chi khác cho hoạt động kinh doanh | B28: =OFFSET('Luu chuyen tien te'!$BL22,0,'Thong tin'!$C$9 - 1) -> 0 | C28: =OFFSET('Luu chuyen tien te'!$AZ22,0,'Thong tin'!$C$9 - 1) -> 0 | D28: =SUM(OFFSET('Luu chuyen tien te'!$BL22,0,0,1,'Thong tin'!$C$9)) -> 0 | E28: =SUM(OFFSET('Luu chuyen tien te'!$AZ22,0,0,1,'Thong tin'!$C$9)) -> 0
A29: Lưu chuyển tiền thuần từ hoạt động kinh doanh | B29: =SUM(B19:B28) -> 0 | C29: =SUM(C19:C28) -> -49243000 | D29: =SUM(D19:D28) -> 0 | E29: =SUM(E19:E28) -> -102620778
A30: II. Lưu chuyển tiền từ hoạt động đầu tư
A31: 1. Tiền chi để mua sắm, xây dựng TSCĐ và các tài sản dài hạn khác | B31: =OFFSET('Luu chuyen tien te'!$BL25,0,'Thong tin'!$C$9 - 1) -> 0 | C31: =OFFSET('Luu chuyen tien te'!$AZ25,0,'Thong tin'!$C$9 - 1) -> 0 | D31: =SUM(OFFSET('Luu chuyen tien te'!$BL25,0,0,1,'Thong tin'!$C$9)) -> 0 | E31: =SUM(OFFSET('Luu chuyen tien te'!$AZ25,0,0,1,'Thong tin'!$C$9)) -> 0
A32: 2. Tiền thu từ thanh lý, nhượng bán TSCĐ và các tài sản dài hạn khác | B32: =OFFSET('Luu chuyen tien te'!$BL26,0,'Thong tin'!$C$9 - 1) -> 0 | C32: =OFFSET('Luu chuyen tien te'!$AZ26,0,'Thong tin'!$C$9 - 1) -> 0 | D32: =SUM(OFFSET('Luu chuyen tien te'!$BL26,0,0,1,'Thong tin'!$C$9)) -> 0 | E32: =SUM(OFFSET('Luu chuyen tien te'!$AZ26,0,0,1,'Thong tin'!$C$9)) -> 0
A33: 3. Tiền chi cho vay, mua các công cụ nợ của đơn vị khác | B33: =OFFSET('Luu chuyen tien te'!$BL27,0,'Thong tin'!$C$9 - 1) -> 0 | C33: =OFFSET('Luu chuyen tien te'!$AZ27,0,'Thong tin'!$C$9 - 1) -> 0 | D33: =SUM(OFFSET('Luu chuyen tien te'!$BL27,0,0,1,'Thong tin'!$C$9)) -> 0 | E33: =SUM(OFFSET('Luu chuyen tien te'!$AZ27,0,0,1,'Thong tin'!$C$9)) -> 0
A34: 4. Tiền thu hồi cho vay, bán lại các công cụ nợ của đơn vị khác | B34: =OFFSET('Luu chuyen tien te'!$BL28,0,'Thong tin'!$C$9 - 1) -> 0 | C34: =OFFSET('Luu chuyen tien te'!$AZ28,0,'Thong tin'!$C$9 - 1) -> 0 | D34: =SUM(OFFSET('Luu chuyen tien te'!$BL28,0,0,1,'Thong tin'!$C$9)) -> 0 | E34: =SUM(OFFSET('Luu chuyen tien te'!$AZ28,0,0,1,'Thong tin'!$C$9)) -> 0
A35: 5. Tiền chi đầu tư góp vốn vào đơn vị khác | B35: =OFFSET('Luu chuyen tien te'!$BL29,0,'Thong tin'!$C$9 - 1) -> 0 | C35: =OFFSET('Luu chuyen tien te'!$AZ29,0,'Thong tin'!$C$9 - 1) -> 0 | D35: =SUM(OFFSET('Luu chuyen tien te'!$BL29,0,0,1,'Thong tin'!$C$9)) -> 0 | E35: =SUM(OFFSET('Luu chuyen tien te'!$AZ29,0,0,1,'Thong tin'!$C$9)) -> 0
A36: 6. Tiền thu hồi đầu tư góp vốn vào đơn vị khác | B36: =OFFSET('Luu chuyen tien te'!$BL30,0,'Thong tin'!$C$9 - 1) -> 0 | C36: =OFFSET('Luu chuyen tien te'!$AZ30,0,'Thong tin'!$C$9 - 1) -> 0 | D36: =SUM(OFFSET('Luu chuyen tien te'!$BL30,0,0,1,'Thong tin'!$C$9)) -> 0 | E36: =SUM(OFFSET('Luu chuyen tien te'!$AZ30,0,0,1,'Thong tin'!$C$9)) -> 0
A37: 7. Tiền thu lãi cho vay, cổ tức và lợi nhuận được chia | B37: =OFFSET('Luu chuyen tien te'!$BL31,0,'Thong tin'!$C$9 - 1) -> 1090 | C37: =OFFSET('Luu chuyen tien te'!$AZ31,0,'Thong tin'!$C$9 - 1) -> 3453516 | D37: =SUM(OFFSET('Luu chuyen tien te'!$BL31,0,0,1,'Thong tin'!$C$9)) -> 6286883 | E37: =SUM(OFFSET('Luu chuyen tien te'!$AZ31,0,0,1,'Thong tin'!$C$9)) -> 3475152
A38: Lưu chuyển tiền thuần từ hoạt động đầu tư | B38: =SUM(B31:B37) -> 1090 | C38: =SUM(C31:C37) -> 3453516 | D38: =SUM(D31:D37) -> 6286883 | E38: =SUM(E31:E37) -> 3475152
A39: III. Lưu chuyển tiền từ hoạt động tài chính
A40: 1. Tiền thu từ phát hành cố phiếu, nhận vốn góp của chủ sở hữu | B40: =OFFSET('Luu chuyen tien te'!$BL34,0,'Thong tin'!$C$9 - 1) -> 0 | C40: =OFFSET('Luu chuyen tien te'!$AZ34,0,'Thong tin'!$C$9 - 1) -> 0 | D40: =SUM(OFFSET('Luu chuyen tien te'!$BL34,0,0,1,'Thong tin'!$C$9)) -> 0 | E40: =SUM(OFFSET('Luu chuyen tien te'!$AZ34,0,0,1,'Thong tin'!$C$9)) -> 0
A41: 2. Tiền trả lại vốn góp cho các chủ sở hữu, mua lại cổ phiểu đã phát hành | B41: =OFFSET('Luu chuyen tien te'!$BL35,0,'Thong tin'!$C$9 - 1) -> 0 | C41: =OFFSET('Luu chuyen tien te'!$AZ35,0,'Thong tin'!$C$9 - 1) -> 0 | D41: =SUM(OFFSET('Luu chuyen tien te'!$BL35,0,0,1,'Thong tin'!$C$9)) -> 0 | E41: =SUM(OFFSET('Luu chuyen tien te'!$AZ35,0,0,1,'Thong tin'!$C$9)) -> 0
...

Sheet Tinh hinh tai chinh
B1: CTY CỔ PHẦN TÁI CHẾ TÂN ĐẠI PHÁT
B2: VND
A3: Index BS | B3: PHẦN I-BÁO CÁO TÌNH HÌNH TÀI CHÍNH | C3: TenCongTyID | D3: T1.2021 | E3: T02.2021 | F3: T03.2021 | G3: T04.2021 | H3: T05.2021 | I3: T06.2021 | J3: T07.2021 | K3: T08.2021 | L3: T09.2021 | M3: T10.2021 | N3: T11.2021 | O3: T12.2021 | P3: T1.2022 | Q3: T02.2022 | R3: T03.2022 | S3: T04.2022 | T3: T05.2022 | U3: T06.2022 | V3: T07.2022 | W3: T08.2022 | X3: T09.2022 | Y3: T10.2022 | Z3: T11.2022 | AA3: T12.2022 | AB3: T1.2023 | AC3: T02.2023 | AD3: T03.2023 | AE3: T04.2023 | AF3: T05.2023 | AG3: T06.2023 | AH3: T07.2023 | AI3: T08.2023 | AJ3: T09.2023 | AK3: T10.2023 | AL3: T11.2023 | AM3: T12.2023 | AN3: T01.2024 | AO3: T02.2024 | AP3: T03.2024 | AQ3: T04.2024 | AR3: T05.2024 | AS3: T06.2024 | AT3: T07.2024 | AU3: T08.2024 | AV3: T09.2024 | AW3: T10.2024 | AX3: T11.2024 | AY3: T12.2024 | AZ3: T01.2025 | BA3: T02.2025 | BB3: T03.2025 | BC3: T04.2025 | BD3: T05.2025 | BE3: T06.2025 | BF3: T07.2025 | BG3: T08.2025 | BH3: T09.2025 | BI3: T10.2025 | BJ3: T11.2025 | BK3: T12.2025 | BL3: T01.2026 | BM3: T02.2026 | BN3: T03.2026 | BO3: T04.2026 | BP3: T05.2026 | BQ3: T06.2026 | BR3: T07.2026 | BS3: T08.2026 | BT3: T09.2026 | BU3: T10.2026 | BV3: T11.2026 | BW3: T12.2026
A4: 1 | B4: A-TÀI SẢN NGẮN HẠN | C4: 9 | AN4: =+AN5+AN8+AN15+AN23+AN30 -> 0 | AO4: =+AO5+AO8+AO15+AO23+AO30 -> 0 | AP4: =+AP5+AP8+AP15+AP23+AP30 -> 0 | AQ4: =+AQ5+AQ8+AQ15+AQ23+AQ30 -> 0 | AR4: =+AR5+AR8+AR15+AR23+AR30 -> 0 | AS4: =+AS5+AS8+AS15+AS23+AS30 -> 0 | AT4: =+AT5+AT8+AT15+AT23+AT30 -> 0 | AU4: 30000 | AV4: 1357273 | AW4: 62557273 | AX4: 20123757273 | AY4: 20100333536 | AZ4: 20080563460 | BA4: 20185570781 | BB4: 20230577394 | BC4: 20278400910 | BD4: 20323405862 | BE4: 21367412569 | BF4: 21427440870 | BG4: 21487156194 | BH4: 21547157746 | BI4: 21607158691 | BJ4: 21674217201 | BK4: =+BK5+BK8+BK15+BK23+BK30 -> 21734218198 | BL4: 21734219268 | BM4: 21740503011 | BN4: 20740503991 | BO4: 20740505081
A5: 2 | B5: I.Tiền và các khoản tương đương tiền | C5: 9 | AN5: =+SUM(AN6:AN7) -> 0 | AO5: =+SUM(AO6:AO7) -> 0 | AP5: =+SUM(AP6:AP7) -> 0 | AQ5: =+SUM(AQ6:AQ7) -> 0 | AR5: =+SUM(AR6:AR7) -> 0 | AS5: =+SUM(AS6:AS7) -> 0 | AT5: =+SUM(AT6:AT7) -> 0 | AU5: 0 | AV5: 0 | AW5: 0 | AX5: 20000000000 | AY5: 19915376263 | AZ5: 19862006187 | BA5: 19862013508 | BB5: 19862020121 | BC5: 19816230637 | BD5: 19816235589 | BE5: 815242296 | BF5: 815248997 | BG5: 814964321 | BH5: 814965873 | BI5: 814966818 | BJ5: 822025328 | BK5: =+SUM(BK6:BK7) -> 822026325 | BL5: 822027395 | BM5: 828311138 | BN5: 828312118 | BO5: 828313208
A6: 3 | B6: 1.Tiền | C6: 9 | AX6: 20000000000 | AY6: 19915376263 | AZ6: 19862006187 | BA6: 19862013508 | BB6: 19062020121 | BC6: 19016230637 | BD6: 19816235589 | BE6: 815242296 | BF6: 815248997 | BG6: 114964321 | BH6: 114965873 | BI6: 114966818 | BJ6: 122025328 | BK6: 122026325 | BL6: 122027395 | BM6: 128311138 | BN6: 128312118 | BO6: 128313208
A7: 4 | B7: 2.Các khoản tương đương tiền | C7: 9 | AS7: 0 | BB7: 800000000 | BC7: 800000000 | BE7: 0 | BF7: 0 | BG7: 700000000 | BH7: 700000000 | BI7: 700000000 | BJ7: 700000000 | BK7: 700000000 | BL7: 700000000 | BM7: 700000000 | BN7: 700000000 | BO7: 700000000
A8: 5 | B8: II.Đầu tư tài chính ngắn hạn | C8: 9 | AN8: =SUM(AN9:AN11) -> 0 | AO8: =SUM(AO9:AO11) -> 0 | AP8: =SUM(AP9:AP11) -> 0 | AQ8: =SUM(AQ9:AQ11) -> 0 | AR8: =SUM(AR9:AR11) -> 0 | AS8: 0 | AT8: =SUM(AT9:AT11) -> 0 | AU8: 0 | AV8: 0 | AW8: 0 | AX8: 0 | AY8: 0 | AZ8: 0 | BA8: 0 | BB8: 0 | BC8: 0 | BD8: 0 | BE8: 0 | BF8: 0 | BG8: 0 | BH8: 0 | BI8: 0 | BJ8: 0 | BK8: =SUM(BK9:BK11) -> 0
A9: 6 | B9: 1.Chứng khoán kinh doanh | C9: 9 | AS9: 0 | BE9: 0
A10: 7 | B10: 2.Dự phòng giảm giá chứng khoán kinh doanh (*) | C10: 9 | AS10: 0 | BE10: 0
A11: 8 | B11: 3.Đầu tư nắm giữ đến ngày đáo hạn ngắn hạn | C11: 9
A12: 9 | B12: 4.Dự phòng đầu tư nắm giữ đến ngày đáo hạn ngắn hạn (*) | C12: 9
A13: 10 | B13: 5.Đầu tư ngắn hạn khác | C13: 9
A14: 11 | B14: 6.Dự phòng tổn thất các khoản đầu tư ngắn hạn khác (*) | C14: 9
A15: 12 | B15: III.Các khoản phải thu ngắn hạn | C15: 9 | AN15: =+SUM(AN16:AN22) -> 0 | AO15: =+SUM(AO16:AO22) -> 0 | AP15: =+SUM(AP16:AP22) -> 0 | AQ15: =+SUM(AQ16:AQ22) -> 0 | AR15: =+SUM(AR16:AR22) -> 0 | AT15: =+SUM(AT16:AT22) -> 0 | AU15: 0 | AV15: 0 | AW15: 0 | AX15: 0 | AY15: 0 | AZ15: 32400000 | BA15: 16200000 | BB15: 0 | BC15: 32400000 | BD15: 16200000 | BE15: 20000000000 | BF15: 20000000000 | BG15: 20000000000 | BH15: 20000000000 | BI15: 20000000000 | BJ15: 20000000000 | BK15: =+SUM(BK16:BK22) -> 20000000000 | BL15: =+SUM(BL16:BL22) -> 20000000000 | BM15: 20000000000 | BN15: 19000000000 | BO15: 19000000000
A16: 13 | B16: 1.Phải thu ngắn hạn của khách hàng | C16: 9 | AS16: 0 | BE16: 0 | BG16: 0 | BH16: 0
A17: 14 | B17: 2.Trả trước cho người bán ngắn hạn | C17: 9 | AS17: 0 | AZ17: 32400000 | BA17: 16200000 | BC17: 32400000 | BD17: 16200000 | BE17: 0 | BH17: 0
A18: 15 | B18: 3.Phải thu nội bộ ngắn hạn | C18: 9 | AS18: 0 | BE18: 0 | BH18: 0
A19: 16 | B19: 4.Phải thu theo tiến độ hợp đồng xây dựng | C19: 9 | AS19: 0 | BE19: 0 | BH19: 0
A20: 17 | B20: 5.Phải thu ngắn hạn khác | C20: 9 | AS20: 0 | BE20: 20000000000 | BF20: 20000000000 | BG20: 20000000000 | BH20: 20000000000 | BI20: 20000000000 | BJ20: 20000000000 | BK20: 20000000000 | BL20: 20000000000 | BM20: 20000000000 | BN20: 19000000000 | BO20: 19000000000
A21: 18 | B21: 6.Dự phòng phải thu ngắn hạn khó đòi (*) | C21: 9 | AS21: 0 | BE21: 0 | BH21: 0
A22: 19 | B22: 7.Tài sản thiếu chờ xử lý | C22: 9 | AS22: 0 | BE22: 0 | BH22: 0
A23: 20 | B23: IV. Hàng tồn kho | C23: 9 | AS23: 0 | BE23: 0
A24: 21 | B24: 1.Hàng tồn kho | C24: 9 | AS24: 0 | BE24: 0
A25: 22 | B25: 2.Dự phòng giảm giá hàng tồn kho (*) | C25: 9 | AS25: 0 | BE25: 0
A26: 23 | B26: V. Tài sản sinh học ngắn hạn | C26: 9
A27: 24 | B27: 1.Súc vật nuôi lấy sản phẩm một lần ngắn hạn | C27: 9
A28: 25 | B28: 2.Cây trồng theo mùa vụ hoặc lấy sản phẩm một lần ngắn hạn | C28: 9
A29: 26 | B29: 3.Dự phòng tổn thất tài sản sinh học ngắn hạn (*) | C29: 9
A30: 27 | B30: VI. Tài sản ngắn hạn khác | C30: 9 | AN30: =+SUM(AN31:AN35) -> 0 | AO30: =+SUM(AO31:AO35) -> 0 | AP30: =+SUM(AP31:AP35) -> 0 | AQ30: =+SUM(AQ31:AQ35) -> 0 | AR30: =+SUM(AR31:AR35) -> 0 | AT30: =+SUM(AT31:AT35) -> 0 | AU30: 30000 | AV30: 1357273 | AW30: 62557273 | AX30: 123757273 | AY30: 184957273 | AZ30: 186157273 | BA30: 307357273 | BB30: 368557273 | BC30: 429770273 | BD30: 490970273 | BE30: 552170273 | BF30: 612191873 | BG30: 672191873 | BH30: 732191873 | BI30: 792191873 | BJ30: 852191873 | BK30: =+SUM(BK31:BK35) -> 912191873 | BL30: =+SUM(BL31:BL35) -> 912191873 | BM30: 912191873 | BN30: 912191873 | BO30: 912191873
A31: 28 | B31: 1.Chi phí chờ phân bổ ngắn hạn | C31: 9 | AS31: 0 | BE31: 0 | BH31: 0 | BI31: 0
A32: 29 | B32: 2.Thuế GTGT được khấu trừ | C32: 9 | AU32: 30000 | AV32: 1357273 | AW32: 62557273 | AX32: 123757273 | AY32: 184957273 | AZ32: 186157273 | BA32: 307357273 | BB32: 368557273 | BC32: 429770273 | BD32: 490970273 | BE32: 552170273 | BF32: 612191873 | BG32: 672191873 | BH32: 732191873 | BI32: 792191873 | BJ32: 852191873 | BK32: 912191873 | BL32: 912191873 | BM32: 912191873 | BN32: 912191873 | BO32: 912191873
A33: 30 | B33: 3.Thuế và các khoản khác phải thu Nhà nước | C33: 9 | BI33: 0
A34: 31 | B34: 4.Giao dịch mua bán lại trái phiếu Chính phủ | C34: 9 | AS34: 0 | BE34: 0
A35: 32 | B35: 5.Tài sản ngắn hạn khác | C35: 9 | AS35: 0 | BE35: 0
A36: 33 | B36: B-TÀI SẢN DÀI HẠN | C36: 9 | AN36: =+AN37+AN44+AN63+AN69+AN76+AN66 -> 0 | AO36: =+AO37+AO44+AO63+AO69+AO76+AO66 -> 0 | AP36: =+AP37+AP44+AP63+AP69+AP76+AP66 -> 0 | AQ36: =+AQ37+AQ44+AQ63+AQ69+AQ76+AQ66 -> 0 | AR36: =+AR37+AR44+AR63+AR69+AR76+AR66 -> 0 | AS36: 0 | AT36: =+AT37+AT44+AT63+AT69+AT76+AT66 -> 0 | AU36: 0 | AV36: 1237373 | AW36: 1202019 | AX36: 1166665 | AY36: 20359706 | AZ36: 19774969 | BA36: 19190232 | BB36: 18605495 | BC36: 18020758 | BD36: 17436021 | BE36: 16851284 | BF36: 16266547 | BG36: 15681810 | BH36: 15097073 | BI36: 14512336 | BJ36: 13927599 | BK36: 13342862 | BL36: 12758125 | BM36: 12173388 | BN36: 11588651 | BO36: 11003914
A37: 34 | B37: I.Các khoản phải thu dài hạn | C37: 9 | AS37: 0 | BE37: 0
A38: 35 | B38: 1.Phải thu dài hạn của khách hàng | C38: 9 | AS38: 0 | BE38: 0
A39: 36 | B39: 2.Trả trước cho người bán dài hạn | C39: 9 | AS39: 0 | BE39: 0
A40: 37 | B40: 3.Vốn kinh doanh ở đơn vị trực thuộc | C40: 9 | AS40: 0 | BE40: 0
...

Sheet Ket qua kinh doanh
B1: CTY CỔ PHẦN TÁI CHẾ TÂN ĐẠI PHÁT
B2: VND
A3: Index PL | B3: PHẦN II-KẾT QUẢ HOẠT ĐỘNG KINH DOANH | C3: TenCongTyID | D3: T1.2021 | E3: T02.2021 | F3: T03.2021 | G3: T04.2021 | H3: T05.2021 | I3: T06.2021 | J3: T07.2021 | K3: T08.2021 | L3: T09.2021 | M3: T10.2021 | N3: T11.2021 | O3: T12.2021 | P3: T1.2022 | Q3: T02.2022 | R3: T03.2022 | S3: T04.2022 | T3: T05.2022 | U3: T06.2022 | V3: T07.2022 | W3: T08.2022 | X3: T09.2022 | Y3: T10.2022 | Z3: T11.2022 | AA3: T12.2022 | AB3: T1.2023 | AC3: T02.2023 | AD3: T03.2023 | AE3: T04.2023 | AF3: T05.2023 | AG3: T06.2023 | AH3: T07.2023 | AI3: T08.2023 | AJ3: T09.2023 | AK3: T10.2023 | AL3: T11.2023 | AM3: T12.2023 | AN3: T01.2024 | AO3: T02.2024 | AP3: T03.2024 | AQ3: T04.2024 | AR3: T05.2024 | AS3: T06.2024 | AT3: T07.2024 | AU3: T08.2024 | AV3: T09.2024 | AW3: T10.2024 | AX3: T11.2024 | AY3: T12.2024 | AZ3: T01.2025 | BA3: T02.2025 | BB3: T03.2025 | BC3: T04.2025 | BD3: T05.2025 | BE3: T06.2025 | BF3: T07.2025 | BG3: T08.2025 | BH3: T09.2025 | BI3: T10.2025 | BJ3: T11.2025 | BK3: T12.2025 | BL3: T01.2026 | BM3: T02.2026 | BN3: T03.2026 | BO3: T04.2026 | BP3: T05.2026 | BQ3: T06.2026 | BR3: T07.2026 | BS3: T08.2026 | BT3: T09.2026 | BU3: T10.2026 | BV3: T11.2026 | BW3: T12.2026
A4: 1 | B4: Sản lượng (Tấn) | C4: 9
A5: 2 | B5: 1.Doanh thu bán hàng và cung cấp dịch vụ | C5: 9 | AU5: 0 | AV5: 0 | AW5: 0 | AX5: 0 | AY5: 0 | AZ5: 0 | BA5: 0 | BB5: 0 | BC5: 0 | BD5: 0 | BE5: 0 | BF5: 0 | BH5: 0
A6: 3 | B6: 2.Các khoản giảm trừ doanh thu | C6: 9 | AU6: 0 | AV6: 0 | AW6: 0 | AX6: 0 | AY6: 0 | AZ6: 0 | BA6: 0 | BB6: 0 | BC6: 0 | BD6: 0 | BE6: 0 | BF6: 0 | BH6: 0
A7: 4 | B7: 3.Doanh thu thuần về bán hàng và cung cấp dịch vụ | C7: 9 | AU7: 0 | AV7: 0 | AW7: 0 | AX7: 0 | AY7: 0 | AZ7: 0 | BA7: 0 | BB7: 0 | BC7: 0 | BD7: 0 | BE7: 0 | BF7: 0 | BH7: 0
A8: 5 | B8: 4.Giá vốn hàng bán | C8: 9 | AU8: 0 | AV8: 0 | AW8: 0 | AX8: 0 | AY8: 0 | AZ8: 0 | BA8: 0 | BB8: 0 | BC8: 0 | BD8: 0 | BE8: 0 | BF8: 0 | BH8: 0
A9: 6 | B9: 5.Lợi nhuận gộp về bán hàng | C9: 9 | AU9: 0 | AV9: 0 | AW9: 0 | AX9: 0 | AY9: 0 | AZ9: 0 | BA9: 0 | BB9: 0 | BC9: 0 | BD9: 0 | BE9: 0 | BF9: 0 | BH9: 0
A10: 7 | B10: 6.Lãi/lỗ của hoạt động bán, thanh lý bất động sản đầu tư | C10: 9
A11: 8 | B11: 7.Doanh thu hoạt động tài chính | C11: 9 | AU11: 0 | AV11: 0 | AW11: 0 | AX11: 0 | AY11: 6263 | AZ11: 7702 | BA11: 7321 | BB11: 6613 | BC11: 3453516 | BD11: 4952 | BE11: 6707 | BF11: 6701 | BG11: 6924 | BH11: 1552 | BI11: 945 | BJ11: 7058510 | BK11: 997 | BL11: 1070 | BM11: 6283743 | BN11: 980 | BO11: 1090
A12: 9 | B12: 8.Chi phí tài chính | C12: 9 | AU12: 0 | AV12: 0 | AW12: 0 | AX12: 0 | AY12: 0 | AZ12: 0 | BA12: 0 | BB12: 0 | BC12: 0 | BD12: 0 | BE12: 0 | BF12: 0 | BH12: 0
A13: 10 | B13: Trong đó: Chi phí lãi vay | C13: 9 | AU13: 0 | AV13: 0 | AW13: 0 | AX13: 0 | AY13: 0 | AZ13: 0 | BA13: 0 | BB13: 0 | BC13: 0 | BD13: 0 | BE13: 0 | BF13: 0 | BH13: 0
A14: 11 | B14: 9.Chi phí bán hàng | C14: 9 | AU14: 0 | AV14: 0 | AW14: 0 | AX14: 0 | AY14: 0 | AZ14: 0 | BA14: 0 | BB14: 0 | BC14: 0 | BD14: 0 | BE14: 0 | BF14: 0 | BH14: 0
A15: 12 | B15: 10.Chi phí quản lý doanh nghiệp | C15: 9 | AU15: 400000 | AV15: 15035354 | AW15: 615035354 | AX15: 615035354 | AY15: 615584737 | AZ15: 18584737 | BA15: 1215584737 | BB15: 615584737 | BC15: 616214737 | BD15: 615584737 | BE15: 615584737 | BF15: 600854737 | BG15: 600584737 | BH15: 600584737 | BI15: 600584737 | BJ15: 600584737 | BK15: 600584737 | BL15: 584737 | BM15: 584737 | BN15: 584737 | BO15: 584737
A16: 13 | B16: 11.Lợi nhuận thuần từ hoạt động kinh doanh | C16: 9 | AN16: =+AN9+AN11-AN12-AN14-AN15 -> 0 | AO16: =+AO9+AO11-AO12-AO14-AO15 -> 0 | AP16: =+AP9+AP11-AP12-AP14-AP15 -> 0 | AQ16: =+AQ9+AQ11-AQ12-AQ14-AQ15 -> 0 | AR16: =+AR9+AR11-AR12-AR14-AR15 -> 0 | AS16: =+AS9+AS11-AS12-AS14-AS15 -> 0 | AT16: =+AT9+AT11-AT12-AT14-AT15 -> 0 | AU16: -400000 | AV16: -15035354 | AW16: -615035354 | AX16: -615035354 | AY16: -615578474 | AZ16: -18577035 | BA16: -1215577416 | BB16: -615578124 | BC16: -612761221 | BD16: -615579785 | BE16: -615578030 | BF16: -600848036 | BG16: -600577813 | BH16: -600583185 | BI16: =+BI9+BI11-BI12-BI14-BI15 -> -600583792 | BJ16: -593526227 | BK16: =+BK9+BK11-BK12-BK14-BK15 -> -600583740 | BL16: -583667 | BM16: 5699006 | BN16: -583757 | BO16: -583647
A17: 14 | B17: 12.Thu nhập khác | C17: 9 | AU17: 0 | AV17: 0 | AW17: 0 | AX17: 0 | AY17: 0 | AZ17: 0 | BA17: 0 | BB17: 0 | BC17: 0 | BD17: 0 | BE17: 0 | BF17: 0 | BH17: 0
A18: 15 | B18: 13.Chi phí khác | C18: 9 | AU18: 0 | AV18: 0 | AW18: 0 | AX18: 0 | AY18: 0 | AZ18: 0 | BA18: 0 | BB18: 0 | BC18: 0 | BD18: 0 | BE18: 1000000 | BF18: 0 | BH18: 0 | BL18: 161000
A19: 16 | B19: 14.Lợi nhuận khác | C19: 9 | AO19: =AO17-AO18 -> 0 | AP19: =AP17-AP18 -> 0 | AQ19: =AQ17-AQ18 -> 0 | AR19: =AR17-AR18 -> 0 | AS19: =AS17-AS18 -> 0 | AT19: =AT17-AT18 -> 0 | AU19: 0 | AV19: 0 | AW19: 0 | AX19: 0 | AY19: 0 | AZ19: 0 | BA19: 0 | BB19: 0 | BC19: 0 | BD19: 0 | BE19: -1000000 | BF19: 0 | BH19: 0 | BL19: -161000
A20: 17 | B20: 15.Tổng lợi nhuận kế toán trước thuế | C20: 9 | AN20: =+AN16+AN19 -> 0 | AO20: =+AO16+AO19 -> 0 | AP20: =+AP16+AP19 -> 0 | AQ20: =+AQ16+AQ19 -> 0 | AR20: =+AR16+AR19 -> 0 | AS20: =+AS16+AS19 -> 0 | AT20: =+AT16+AT19 -> 0 | AU20: -400000 | AV20: -15035354 | AW20: -615035354 | AX20: -615035354 | AY20: -615578474 | AZ20: -18577035 | BA20: -1215577416 | BB20: -615578124 | BC20: -612761221 | BD20: -615579785 | BE20: -616578030 | BF20: -600848036 | BG20: -600577813 | BH20: -600583185 | BI20: =+BI16+BI19 -> -600583792 | BJ20: -593526227 | BK20: =+BK16+BK19 -> -600583740 | BL20: -744667 | BM20: 5699006 | BN20: -583757 | BO20: -583647
A21: 18 | B21: 16.Chi phí thuế TNDN hiện hành | C21: 9 | AU21: 0 | AV21: 0 | AX21: 0 | AY21: 0 | AZ21: 0 | BA21: 0 | BB21: 0 | BC21: 0 | BD21: 0 | BE21: 0 | BF21: 0 | BH21: 0
A22: 19 | B22: 17.Chi phí thuế TNDN hoãn lại | C22: 9 | AU22: 0 | AV22: 0 | AX22: 0 | AY22: 0 | AZ22: 0 | BA22: 0 | BB22: 0 | BC22: 0 | BD22: 0 | BE22: 0 | BF22: 0 | BH22: 0
A23: 20 | B23: 18.Lợi nhuận sau thuế thu nhập doanh nghiệp | C23: 9 | AN23: =+AN20-AN21-AN22 -> 0 | AO23: =+AO20-AO21-AO22 -> 0 | AP23: =+AP20-AP21-AP22 -> 0 | AQ23: =+AQ20-AQ21-AQ22 -> 0 | AR23: =+AR20-AR21-AR22 -> 0 | AS23: =+AS20-AS21-AS22 -> 0 | AT23: =+AT20-AT21-AT22 -> 0 | AU23: -400000 | AV23: -15035354 | AW23: -615035354 | AX23: -615035354 | AY23: -615578474 | AZ23: -18577035 | BA23: -1215577416 | BB23: -615578124 | BC23: -612761221 | BD23: -615579785 | BE23: -616578030 | BF23: -600848036 | BG23: -600577813 | BH23: -600583185 | BI23: =+BI20-BI21-BI22 -> -600583792 | BJ23: -593526227 | BK23: =+BK20-BK21-BK22 -> -600583740 | BL23: =+BL20-BL21-BL22 -> -744667 | BM23: 5699006 | BN23: -583757 | BO23: -583647

Sheet Luu chuyen tien te
B1: CTY CỔ PHẦN TÁI CHẾ TÂN ĐẠI PHÁT
B2: VND
A3: Index CF | B3: PHẦN III- LƯU CHUYỂN TIỀN TỆ | C3: TenCongTyID | D3: T1.2021 | E3: T02.2021 | F3: T03.2021 | G3: T04.2021 | H3: T05.2021 | I3: T06.2021 | J3: T07.2021 | K3: T08.2021 | L3: T09.2021 | M3: T10.2021 | N3: T11.2021 | O3: T12.2021 | P3: T1.2022 | Q3: T02.2022 | R3: T03.2022 | S3: T04.2022 | T3: T05.2022 | U3: T06.2022 | V3: T07.2022 | W3: T08.2022 | X3: T09.2022 | Y3: T10.2022 | Z3: T11.2022 | AA3: T12.2022 | AB3: T1.2023 | AC3: T02.2023 | AD3: T03.2023 | AE3: T04.2023 | AF3: T05.2023 | AG3: T06.2023 | AH3: T07.2023 | AI3: T08.2023 | AJ3: T09.2023 | AK3: T10.2023 | AL3: T11.2023 | AM3: T12.2023 | AN3: T01.2024 | AO3: T02.2024 | AP3: T03.2024 | AQ3: T04.2024 | AR3: T05.2024 | AS3: T06.2024 | AT3: T07.2024 | AU3: T08.2024 | AV3: T09.2024 | AW3: T10.2024 | AX3: T11.2024 | AY3: T12.2024 | AZ3: T01.2025 | BA3: T02.2025 | BB3: T03.2025 | BC3: T04.2025 | BD3: T05.2025 | BE3: T06.2025 | BF3: T07.2025 | BG3: T08.2025 | BH3: T09.2025 | BI3: T10.2025 | BJ3: T11.2025 | BK3: T12.2025 | BL3: T01.2026 | BM3: T02.2026 | BN3: T03.2026 | BO3: T04.2026 | BP3: T05.2026 | BQ3: T06.2026 | BR3: T07.2026 | BS3: T08.2026 | BT3: T09.2026 | BU3: T10.2026 | BV3: T11.2026 | BW3: T12.2026
A4: 1 | B4: I. Lưu chuyển tiền từ hoạt động kinh doanh | C4: 9
A5: 2 | B5: Lợi nhuận trước thuế | C5: 9 | AN5: ='Ket qua kinh doanh'!AN20 -> 0 | AO5: ='Ket qua kinh doanh'!AO20 -> 0 | AP5: ='Ket qua kinh doanh'!AP20 -> 0 | AQ5: ='Ket qua kinh doanh'!AQ20 -> 0 | AR5: ='Ket qua kinh doanh'!AR20 -> 0 | AS5: ='Ket qua kinh doanh'!AS20 -> 0 | AT5: ='Ket qua kinh doanh'!AT20 -> 0 | AU5: ='Ket qua kinh doanh'!AU20 -> -400000 | ... BI5: ='Ket qua kinh doanh'!BI20 -> -600583792 | BJ5: -593526227 | BK5: ='Ket qua kinh doanh'!BK20 -> -600583740 | BL5: ='Ket qua kinh doanh'!BL20 -> -744667 | BM5: 5699006 | BN5: -583757 | BO5: -583647
A6: 3 | B6: Điều chỉnh cho các khoản: | C6: 9
A7: 4 | B7: Khấu hao tài sản cố định và BĐSĐT | C7: 9
A8: 5 | B8: Các khoản dự phòng | C8: 9 | AP8: 0 | BB8: 0
A9: 6 | B9: Lãi, lỗ chênh lệch tỷ giá do đánh giá lại các khoản mục tiền tệ có gốc ngoại tệ | C9: 9 | AP9: 0 | BB9: 0
A10: 7 | B10: Lãi, lỗ từ hoạt động đầu tư, tài chính | C10: 9 | AN10: =-'Ket qua kinh doanh'!AN11 -> 0 | AO10: =-'Ket qua kinh doanh'!AO11 -> 0 | AP10: =-'Ket qua kinh doanh'!AP11 -> 0 | AQ10: =-'Ket qua kinh doanh'!AQ11 -> 0 | AR10: =-'Ket qua kinh doanh'!AR11 -> 0 | AS10: =-'Ket qua kinh doanh'!AS11 -> 0 | AT10: =-'Ket qua kinh doanh'!AT11 -> 0 | AU10: =-'Ket qua kinh doanh'!AU11 -> 0 | ... BI10: =-'Ket qua kinh doanh'!BI11 -> -945 | BJ10: -7058510 | BK10: =-'Ket qua kinh doanh'!BK11 -> -997 | BL10: =-'Ket qua kinh doanh'!BL11 -> -1070 | BM10: -6283743 | BN10: -980 | BO10: -1090
A11: 8 | B11: Chi phí đi vay | C11: 9
A12: 9 | B12: Các khoản điều chỉnh khác | C12: 9
A13: 10 | B13: Lợi nhuận từ hoạt động kinh doanh trước thay đổi vốn lưu động | C13: 9 | AN13: =+SUM(AN5:AN12) -> 0 | AO13: =+SUM(AO5:AO12) -> 0 | AP13: =+SUM(AP5:AP12) -> 0 | AQ13: =+SUM(AQ5:AQ12) -> 0 | AR13: =+SUM(AR5:AR12) -> 0 | AS13: =+SUM(AS5:AS12) -> 0 | AT13: =+SUM(AT5:AT12) -> 0 | AU13: =+SUM(AU5:AU12) -> -400000 | ... BI13: =+SUM(BI5:BI12) -> -600584737 | BJ13: -600584737 | BK13: =+SUM(BK5:BK12) -> -600584737 | BL13: =+SUM(BL5:BL12) -> -745737 | BM13: =+SUM(BM5:BM12) -> -584737 | BN13: =+SUM(BN5:BN12) -> -584737 | BO13: =+SUM(BO5:BO12) -> -584737
A14: 11 | B14: Tăng / giảm các khoản phải thu | C14: 9 | AP14: =-('Tinh hinh tai chinh'!AP32-'Tinh hinh tai chinh'!AO32) -> 0 | AQ14: =-('Tinh hinh tai chinh'!AQ32-'Tinh hinh tai chinh'!AP32) -> 0 | AR14: =-('Tinh hinh tai chinh'!AR32-'Tinh hinh tai chinh'!AQ32) -> 0 | AS14: =-('Tinh hinh tai chinh'!AS32-'Tinh hinh tai chinh'!AR32) -> 0 | AT14: =-('Tinh hinh tai chinh'!AT32-'Tinh hinh tai chinh'!AS32) -> 0 | AX14: =-('Tinh hinh tai chinh'!AX32-'Tinh hinh tai chinh'!AW32)-('Tinh hinh tai chinh'!AX17-'Tinh hinh tai chinh'!AW17)-('Tinh hinh tai chinh'!AX20-'Tinh hinh tai chinh'!AW20) -> -61200000 | AY14: =-('Tinh hinh tai chinh'!AY32-'Tinh hinh tai chinh'!AX32)-('Tinh hinh tai chinh'!AY17-'Tinh hinh tai chinh'!AX17)-('Tinh hinh tai chinh'!AY20-'Tinh hinh tai chinh'!AX20) -> -61200000 | AZ14: =-('Tinh hinh tai chinh'!AZ32-'Tinh hinh tai chinh'!AY32)-('Tinh hinh tai chinh'!AZ17-'Tinh hinh tai chinh'!AY17)-('Tinh hinh tai chinh'!AZ20-'Tinh hinh tai chinh'!AY20) -> -33600000 | BA14: =-('Tinh hinh tai chinh'!BA32-'Tinh hinh tai chinh'!AZ32)-('Tinh hinh tai chinh'!BA17-'Tinh hinh tai chinh'!AZ17)-('Tinh hinh tai chinh'!BA20-'Tinh hinh tai chinh'!AZ20) -> -105000000 | BB14: =-('Tinh hinh tai chinh'!BB32-'Tinh hinh tai chinh'!BA32)-('Tinh hinh tai chinh'!BB17-'Tinh hinh tai chinh'!BA17)-('Tinh hinh tai chinh'!BB20-'Tinh hinh tai chinh'!BA20) -> -45000000 | BC14: =-('Tinh hinh tai chinh'!BC32-'Tinh hinh tai chinh'!BB32)-('Tinh hinh tai chinh'!BC17-'Tinh hinh tai chinh'!BB17)-('Tinh hinh tai chinh'!BC20-'Tinh hinh tai chinh'!BB20) -> -93613000 | BD14: =-('Tinh hinh tai chinh'!BD32-'Tinh hinh tai chinh'!BC32)-('Tinh hinh tai chinh'!BD17-'Tinh hinh tai chinh'!BC17)-('Tinh hinh tai chinh'!BD20-'Tinh hinh tai chinh'!BC20) -> -45000000 | BE14: =-('Tinh hinh tai chinh'!BE32-'Tinh hinh tai chinh'!BD32)-('Tinh hinh tai chinh'!BE17-'Tinh hinh tai chinh'!BD17)-('Tinh hinh tai chinh'!BE20-'Tinh hinh tai chinh'!BD20) -> -20045000000 | ... BH14: =-('Tinh hinh tai chinh'!BH32-'Tinh hinh tai chinh'!BG32)-('Tinh hinh tai chinh'!BH17-'Tinh hinh tai chinh'!BG17)-('Tinh hinh tai chinh'!BH20-'Tinh hinh tai chinh'!BG20) -> -60000000 | BI14: -60000000 | BJ14: -60000000 | BK14: -60000000
A15: 12 | B15: Tăng / giảm hàng tồn kho | C15: 9 | AO15: 0 | AP15: 0 | AQ15: 0 | AR15: 0 | AS15: 0 | AT15: 0 | AU15: 0 | AV15: 0 | AW15: 0 | AX15: 0 | AY15: 0 | BA15: 0 | BB15: 0 | BC15: 0 | BD15: 0 | BE15: 0 | BF15: 0 | BG15: 0 | BH15: 0 | BI15: 0
A16: 13 | B16: Tăng / giảm các khoản phải trả (Không bao gồm lãi vay phải trả, thuế TNDN phải nộp) | C16: 9 | AU16: 400000 | AV16: =-AV5 -> 15035354 | AW16: =-AW5 -> 615035354 | AX16: =('Tinh hinh tai chinh'!AX84-'Tinh hinh tai chinh'!AW84+'Tinh hinh tai chinh'!AX87-'Tinh hinh tai chinh'!AW87+'Tinh hinh tai chinh'!AX93-'Tinh hinh tai chinh'!AW93) -> 676200000 | AY16: =('Tinh hinh tai chinh'!AY84-'Tinh hinh tai chinh'!AX84+'Tinh hinh tai chinh'!AY87-'Tinh hinh tai chinh'!AX87+'Tinh hinh tai chinh'!AY93-'Tinh hinh tai chinh'!AX93) -> 611347778 | AZ16: =('Tinh hinh tai chinh'!AZ84-'Tinh hinh tai chinh'!AY84+'Tinh hinh tai chinh'!AZ87-'Tinh hinh tai chinh'!AY87+'Tinh hinh tai chinh'!AZ93-'Tinh hinh tai chinh'!AY93) -> -1777778 | BA16: =('Tinh hinh tai chinh'!BA84-'Tinh hinh tai chinh'!AZ84+'Tinh hinh tai chinh'!BA87-'Tinh hinh tai chinh'!AZ87+'Tinh hinh tai chinh'!BA93-'Tinh hinh tai chinh'!AZ93) -> 1320000000 | BB16: =('Tinh hinh tai chinh'!BB84-'Tinh hinh tai chinh'!BA84+'Tinh hinh tai chinh'!BB87-'Tinh hinh tai chinh'!BA87+'Tinh hinh tai chinh'!BB93-'Tinh hinh tai chinh'!BA93) -> 660000000 | BC16: =('Tinh hinh tai chinh'!BC84-'Tinh hinh tai chinh'!BB84+'Tinh hinh tai chinh'!BC87-'Tinh hinh tai chinh'!BB87+'Tinh hinh tai chinh'!BC93-'Tinh hinh tai chinh'!BB93) -> 660000000 | BD16: =('Tinh hinh tai chinh'!BD84-'Tinh hinh tai chinh'!BC84+'Tinh hinh tai chinh'!BD87-'Tinh hinh tai chinh'!BC87+'Tinh hinh tai chinh'!BD93-'Tinh hinh tai chinh'!BC93) -> 660000000 | BE16: =('Tinh hinh tai chinh'!BE84-'Tinh hinh tai chinh'!BD84+'Tinh hinh tai chinh'!BE87-'Tinh hinh tai chinh'!BD87+'Tinh hinh tai chinh'!BE93-'Tinh hinh tai chinh'!BD93) -> 1660000000 | ... BH16: =('Tinh hinh tai chinh'!BH84-'Tinh hinh tai chinh'!BG84+'Tinh hinh tai chinh'!BH87-'Tinh hinh tai chinh'!BG87+'Tinh hinh tai chinh'!BH93-'Tinh hinh tai chinh'!BG93) -> 660000000 | BI16: 660000000 | BJ16: 660000000 | BK16: 660000000 | BL16: 161000
A17: 14 | B17: Tăng / giảm chi phí chờ phân bổ | C17: 9 | AN17: 0 | AP17: 0 | AQ17: 0 | AS17: 0 | AT17: 0 | AU17: 0 | AV17: 0 | AW17: 0 | AX17: =-('Tinh hinh tai chinh'!AX77-'Tinh hinh tai chinh'!AW77) -> 35354 | AY17: =-('Tinh hinh tai chinh'!AY77-'Tinh hinh tai chinh'!AX77) -> -19193041 | AZ17: =-('Tinh hinh tai chinh'!AZ77-'Tinh hinh tai chinh'!AY77) -> 584737 | BA17: =-('Tinh hinh tai chinh'!BA77-'Tinh hinh tai chinh'!AZ77) -> 584737 | BB17: =-('Tinh hinh tai chinh'!BB77-'Tinh hinh tai chinh'!BA77) -> 584737 | BC17: =-('Tinh hinh tai chinh'!BC77-'Tinh hinh tai chinh'!BB77) -> 584737 | BD17: =-('Tinh hinh tai chinh'!BD77-'Tinh hinh tai chinh'!BC77) -> 584737 | BE17: =-('Tinh hinh tai chinh'!BE77-'Tinh hinh tai chinh'!BD77) -> 584737 | ... BH17: =-('Tinh hinh tai chinh'!BH77-'Tinh hinh tai chinh'!BG77) -> 584737 | BI17: 584737 | BJ17: 584737 | BK17: 584737 | BL17: 584737 | BM17: 584737 | BN17: 584737 | BO17: 584737
A18: 15 | B18: Tăng / giảm chứng khoán kinh doanh | C18: 9 | AN18: 0 | AQ18: 0 | AS18: 0 | AT18: 0 | AU18: 0 | AW18: 0 | AY18: 0 | AZ18: 0 | BC18: 0 | BE18: 0 | BF18: 0 | BG18: 0 | BI18: 0 | BK18: 0
A19: 16 | B19: Chi phí đi vay đã trả | C19: 9 | AN19: 0 | AP19: 0 | AQ19: 0 | AS19: 0 | AT19: 0 | AU19: 0 | AW19: 0 | AY19: 0 | AZ19: 0 | BB19: 0 | BC19: 0 | BE19: 0 | BF19: 0 | BG19: 0 | BI19: 0 | BK19: 0
A20: 17 | B20: Thuế thu nhập doanh nghiệp đã nộp | C20: 9 | AN20: 0 | AP20: 0 | AQ20: 0 | AS20: 0 | AT20: 0 | AU20: 0 | AV20: 0 | AW20: 0 | AX20: 0 | AY20: 0 | AZ20: 0 | BB20: 0 | BC20: 0 | BE20: 0 | BF20: 0 | BG20: 0 | BH20: 0 | BI20: 0 | BK20: 0
A21: 18 | B21: Tiền thu khác từ hoạt động kinh doanh | C21: 9 | AS21: 0 | BE21: 0
A22: 19 | B22: Tiền chi khác cho hoạt động kinh doanh | C22: 9 | AS22: 0 | AT22: 0 | AU22: 0 | AW22: 0 | BE22: 0 | BF22: 0 | BG22: 0 | BI22: 0
A23: 20 | B23: Lưu chuyển tiền thuần từ hoạt động kinh doanh | C23: 9 | AN23: =+SUM(AN13:AN22) -> 0 | AO23: =+SUM(AO13:AO22) -> 0 | AP23: =+SUM(AP13:AP22) -> 0 | AQ23: =+SUM(AQ13:AQ22) -> 0 | AR23: =+SUM(AR13:AR22) -> 0 | AS23: =+SUM(AS13:AS22) -> 0 | AT23: =+SUM(AT13:AT22) -> 0 | AU23: =+SUM(AU13:AU22) -> 0 | ... BI23: =+SUM(BI13:BI22) -> 0 | BJ23: 0 | BK23: =+SUM(BK13:BK22) -> 0 | BL23: =+SUM(BL13:BL22) -> 0
A24: 21 | B24: II. Lưu chuyển tiền từ hoạt động đầu tư | C24: 9 | AT24: 0 | AU24: 0 | BF24: 0 | BG24: 0
A25: 22 | B25: Tiền chi để mua sắm, xây dựng, TSCĐ và các tài sản dài hạn khác | C25: 9
A26: 23 | B26: Tiền thu từ thanh lý, nhượng bán TSCĐ và các tài sản dài hạn khác | C26: 9 | AT26: 0 | AU26: 0 | BF26: 0 | BG26: 0
A27: 24 | B27: Tiền chi cho vay, mua các công cụ nợ của đơn vị khác | C27: 9 | AT27: 0 | AU27: 0 | BF27: 0 | BG27: 0
A28: 25 | B28: Tiền thu hồi cho vay, bán lại các công cụ nợ của đơn vị khác | C28: 9 | AT28: 0 | AU28: 0 | BF28: 0 | BG28: 0
A29: 26 | B29: Tiền chi đầu tư góp vốn vào đơn vị khác | C29: 9
A30: 27 | B30: Tiền thu hồi đầu tư góp vốn vào đơn vị khác | C30: 9 | AT30: 0 | AU30: 0 | BF30: 0 | BG30: 0
A31: 28 | B31: Tiền thu lãi cho vay, cổ tức, và lợi nhuận được chia | C31: 9 | AN31: =-AN10 -> 0 | AO31: =-AO10 -> 0 | AP31: =-AP10 -> 0 | AQ31: =-AQ10 -> 0 | AR31: =-AR10 -> 0 | AS31: =-AS10 -> 0 | AT31: =-AT10 -> 0 | AU31: =-AU10 -> 0 | ... BI31: =-BI10 -> 945 | BJ31: 7058510 | BK31: =-BK10 -> 997 | BL31: =-BL10 -> 1070 | BM31: 6283743 | BN31: 980 | BO31: 1090
A32: 29 | B32: Lưu chuyển tiền thuần từ hoạt động đầu tư | C32: 9 | AN32: =+SUM(AN25:AN31) -> 0 | AO32: =+SUM(AO25:AO31) -> 0 | AP32: =+SUM(AP25:AP31) -> 0 | AQ32: =+SUM(AQ25:AQ31) -> 0 | AR32: =+SUM(AR25:AR31) -> 0 | AS32: =+SUM(AS25:AS31) -> 0 | AT32: =+SUM(AT25:AT31) -> 0 | AU32: =+SUM(AU25:AU31) -> 0 | ... BI32: =+SUM(BI25:BI31) -> 945 | BJ32: 7058510 | BK32: =+SUM(BK25:BK31) -> 997 | BL32: =+SUM(BL25:BL31) -> 1070 | BM32: =+SUM(BM25:BM31) -> 6283743 | BN32: =+SUM(BN25:BN31) -> 980 | BO32: =+SUM(BO25:BO31) -> 1090
A33: 30 | B33: III. Lưu chuyển tiền từ hoạt động tài chính | C33: 9 | AT33: 0 | AU33: 0 | BF33: 0 | BG33: 0
A34: 31 | B34: Tiền thu từ phát hành cổ phiếu, nhận vốn góp của chủ sở hữu | C34: 9 | AX34: ='Tinh hinh tai chinh'!AX116-'Tinh hinh tai chinh'!AW116 -> 20000000000 | AY34: ='Tinh hinh tai chinh'!AY116-'Tinh hinh tai chinh'!AX116 -> 0 | AZ34: ='Tinh hinh tai chinh'!AZ116-'Tinh hinh tai chinh'!AY116 -> 0 | BA34: ='Tinh hinh tai chinh'!BA116-'Tinh hinh tai chinh'!AZ116 -> 0 | BB34: ='Tinh hinh tai chinh'!BB116-'Tinh hinh tai chinh'!BA116 -> 0 | BC34: ='Tinh hinh tai chinh'!BC116-'Tinh hinh tai chinh'!BB116 -> 0 | BD34: ='Tinh hinh tai chinh'!BD116-'Tinh hinh tai chinh'!BC116 -> 0 | BE34: ='Tinh hinh tai chinh'!BE116-'Tinh hinh tai chinh'!BD116 -> 0 | ... BG34: ='Tinh hinh tai chinh'!BG116-'Tinh hinh tai chinh'!BF116 -> 0
A35: 32 | B35: Tiền trả lại vốn góp cho các chủ sở hữu, mua lại cổ phiểu đã phát hành | C35: 9 | AT35: 0 | AU35: 0 | BF35: 0 | BG35: 0
A36: 33 | B36: Tiền thu từ đi vay | C36: 9 | AT36: 0 | AU36: 0 | BF36: 0 | BG36: 0
A37: 34 | B37: Tiền trả nợ gốc vay | C37: 9 | AT37: 0 | AU37: 0 | BF37: 0 | BG37: 0
A38: 35 | B38: Tiền trả nợ gốc thuê tài chính | C38: 9 | AT38: 0 | AU38: 0 | BF38: 0 | BG38: 0
A39: 36 | B39: Cổ tức, lợi nhuận đã trả cho chủ sở hữu | C39: 9 | AT39: 0 | AU39: 0 | BF39: 0 | BG39: 0
A40: 37 | B40: Lưu chuyển thuần từ hoạt động tài chính | C40: 9 | AN40: =SUM(AN34:AN39) -> 0 | AO40: =SUM(AO34:AO39) -> 0 | AP40: =SUM(AP34:AP39) -> 0 | AQ40: =SUM(AQ34:AQ39) -> 0 | AR40: =SUM(AR34:AR39) -> 0 | AS40: =SUM(AS34:AS39) -> 0 | AT40: =SUM(AT34:AT39) -> 0 | AU40: =SUM(AU34:AU39) -> 0 | ... BI40: =SUM(BI34:BI39) -> 0 | BK40: =SUM(BK34:BK39) -> 0 | BL40: =SUM(BL34:BL39) -> 0
...

Sheet KQKD theo yeu to
B1: CTY CỔ PHẦN TÁI CHẾ TÂN ĐẠI PHÁT
B2: VND
A3: Index PL Element | B3: PHẦN IV: CHI PHÍ THEO YẾU TỐ | C3: TenCongTyID | D3: T1.2021 | E3: T02.2021 | F3: T03.2021 | G3: T04.2021 | H3: T05.2021 | I3: T06.2021 | J3: T07.2021 | K3: T08.2021 | L3: T09.2021 | M3: T10.2021 | N3: T11.2021 | O3: T12.2021 | P3: T1.2022 | Q3: T02.2022 | R3: T03.2022 | S3: T04.2022 | T3: T05.2022 | U3: T06.2022 | V3: T07.2022 | W3: T08.2022 | X3: T09.2022 | Y3: T10.2022 | Z3: T11.2022 | AA3: T12.2022 | AB3: T1.2023 | AC3: T02.2023 | AD3: T03.2023 | AE3: T04.2023 | AF3: T05.2023 | AG3: T06.2023 | AH3: T07.2023 | AI3: T08.2023 | AJ3: T09.2023 | AK3: T10.2023 | AL3: T11.2023 | AM3: T12.2023 | AN3: T01.2024 | AO3: T02.2024 | AP3: T03.2024 | AQ3: T04.2024 | AR3: T05.2024 | AS3: T06.2024 | AT3: T07.2024 | AU3: T08.2024 | AV3: T09.2024 | AW3: T10.2024 | AX3: T11.2024 | AY3: T12.2024 | AZ3: T01.2025 | BA3: T02.2025 | BB3: T03.2025 | BC3: T04.2025 | BD3: T05.2025 | BE3: T06.2025 | BF3: T07.2025 | BG3: T08.2025 | BH3: T09.2025 | BI3: T10.2025 | BJ3: T11.2025 | BK3: T12.2025 | BL3: T01.2026 | BM3: T02.2026 | BN3: T03.2026 | BO3: T04.2026 | BP3: T05.2026 | BQ3: T06.2026 | BR3: T07.2026 | BS3: T08.2026 | BT3: T09.2026 | BU3: T10.2026 | BV3: T11.2026 | BW3: T12.2026
A4: 1 | B4: Tổng nhân sự | C4: 9
A5: 2 | B5: Nhân sự nhóm sản xuất | C5: 9
A6: 3 | B6: Số ngày công (8 hrs) | C6: 9
A7: 4 | B7: Sản lượng sản xuất (Ton) | C7: 9
A8: 5 | B8: Sản lượng bán (Ton) | C8: 9 | AN8: ='Ket qua kinh doanh'!AN4 -> 0 | AO8: ='Ket qua kinh doanh'!AO4 -> 0 | AP8: ='Ket qua kinh doanh'!AP4 -> 0 | AQ8: ='Ket qua kinh doanh'!AQ4 -> 0 | AR8: ='Ket qua kinh doanh'!AR4 -> 0 | AS8: ='Ket qua kinh doanh'!AS4 -> 0 | AT8: ='Ket qua kinh doanh'!AT4 -> 0 | AU8: ='Ket qua kinh doanh'!AU4 -> 0 | ... BW8: ='Ket qua kinh doanh'!BW4 -> 0
A9: 6 | B9: Doanh thu bán hàng | C9: 9 | AN9: ='Ket qua kinh doanh'!AN5 -> 0 | AO9: ='Ket qua kinh doanh'!AO5 -> 0 | AP9: ='Ket qua kinh doanh'!AP5 -> 0 | AQ9: ='Ket qua kinh doanh'!AQ5 -> 0 | AR9: ='Ket qua kinh doanh'!AR5 -> 0 | AS9: ='Ket qua kinh doanh'!AS5 -> 0 | AT9: ='Ket qua kinh doanh'!AT5 -> 0 | AU9: ='Ket qua kinh doanh'!AU5 -> 0 | ... BW9: ='Ket qua kinh doanh'!BW5 -> 0
A10: 7 | B10: Các khoản giảm trừ doanh thu | C10: 9 | AN10: ='Ket qua kinh doanh'!AN6 -> 0 | AO10: ='Ket qua kinh doanh'!AO6 -> 0 | AP10: ='Ket qua kinh doanh'!AP6 -> 0 | AQ10: ='Ket qua kinh doanh'!AQ6 -> 0 | AR10: ='Ket qua kinh doanh'!AR6 -> 0 | AS10: ='Ket qua kinh doanh'!AS6 -> 0 | AT10: ='Ket qua kinh doanh'!AT6 -> 0 | AU10: ='Ket qua kinh doanh'!AU6 -> 0 | ... BW10: ='Ket qua kinh doanh'!BW6 -> 0
A11: 8 | B11: % Các khoản giảm trừ | C11: 9 | AN11: =IFERROR(AN10/AN9,"") | AO11: =IFERROR(AO10/AO9,"") | AP11: =IFERROR(AP10/AP9,"") | AQ11: =IFERROR(AQ10/AQ9,"") | AR11: =IFERROR(AR10/AR9,"") | AS11: =IFERROR(AS10/AS9,"") | AT11: =IFERROR(AT10/AT9,"") | AU11: =IFERROR(AU10/AU9,"") | ... BW11: =IFERROR(BW10/BW9,"")
A12: 9 | B12: Doanh thu thuần | C12: 9 | AN12: ='Ket qua kinh doanh'!AN7 -> 0 | AO12: ='Ket qua kinh doanh'!AO7 -> 0 | AP12: ='Ket qua kinh doanh'!AP7 -> 0 | AQ12: ='Ket qua kinh doanh'!AQ7 -> 0 | AR12: ='Ket qua kinh doanh'!AR7 -> 0 | AS12: ='Ket qua kinh doanh'!AS7 -> 0 | AT12: ='Ket qua kinh doanh'!AT7 -> 0 | AU12: ='Ket qua kinh doanh'!AU7 -> 0 | ... BW12: ='Ket qua kinh doanh'!BW7 -> 0
A13: 10 | B13: Xuất khẩu | C13: 9
A14: 11 | B14: Nội địa | C14: 9
A15: 12 | B15: Khác | C15: 9
A16: 13 | B16: Giá vốn hàng bán | C16: 9 | AN16: ='Ket qua kinh doanh'!AN8 -> 0 | AO16: ='Ket qua kinh doanh'!AO8 -> 0 | AP16: ='Ket qua kinh doanh'!AP8 -> 0 | AQ16: ='Ket qua kinh doanh'!AQ8 -> 0 | AR16: ='Ket qua kinh doanh'!AR8 -> 0 | AS16: ='Ket qua kinh doanh'!AS8 -> 0 | AT16: ='Ket qua kinh doanh'!AT8 -> 0 | AU16: ='Ket qua kinh doanh'!AU8 -> 0 | ... BW16: ='Ket qua kinh doanh'!BW8 -> 0
A17: 14 | B17: Chi phí nguyên vật liệu | C17: 9
A18: 15 | B18: Chi phí điện | C18: 9
A19: 16 | B19: Chi phí lương ngoài giờ sản xuất | C19: 9
A20: 17 | B20: Chi phí nhân công trực tiếp sản xuất (622) | C20: 9
A21: 18 | B21: Chi phí nhân công gián tiếp sản xuất (6271) | C21: 9
A22: 19 | B22: Phúc lợi nhân viên sản xuất (BHXH,thưởng,…) | C22: 9
A23: 20 | B23: Chi phí sửa chữa, bảo trì | C23: 9
A24: 21 | B24: Chi phí xưởng (các khoản còn lại ngoài các mục trên) | C24: 9
A25: 22 | B25: Chi phí khấu hao sản xuất (6274) | C25: 9
A26: 23 | B26: Chi phí gia công ngoài (nếu có) | C26: 9
A27: 24 | B27: Giá vốn khác | C27: 9
A28: 25 | B28: Giá vốn trong hàng tồn kho | C28: 9
A29: 26 | B29: % Giá vốn hàng bán | C29: 9 | AN29: =IFERROR(AN16/AN12,"") | AO29: =IFERROR(AO16/AO12,"") | AP29: =IFERROR(AP16/AP12,"") | AQ29: =IFERROR(AQ16/AQ12,"") | AR29: =IFERROR(AR16/AR12,"") | AS29: =IFERROR(AS16/AS12,"") | AT29: =IFERROR(AT16/AT12,"") | AU29: =IFERROR(AU16/AU12,"") | ... BW29: =IFERROR(BW16/BW12,"")
A30: 27 | B30: Lợi nhuận gộp | C30: 9 | AN30: ='Ket qua kinh doanh'!AN9 -> 0 | AO30: ='Ket qua kinh doanh'!AO9 -> 0 | AP30: ='Ket qua kinh doanh'!AP9 -> 0 | AQ30: ='Ket qua kinh doanh'!AQ9 -> 0 | AR30: ='Ket qua kinh doanh'!AR9 -> 0 | AS30: ='Ket qua kinh doanh'!AS9 -> 0 | AT30: ='Ket qua kinh doanh'!AT9 -> 0 | AU30: ='Ket qua kinh doanh'!AU9 -> 0 | ... BW30: ='Ket qua kinh doanh'!BW9 -> 0
A31: 28 | B31: % Lợi nhuận gộp | C31: 9 | AN31: =IFERROR(AN30/AN12,"") | AO31: =IFERROR(AO30/AO12,"") | AP31: =IFERROR(AP30/AP12,"") | AQ31: =IFERROR(AQ30/AQ12,"") | AR31: =IFERROR(AR30/AR12,"") | AS31: =IFERROR(AS30/AS12,"") | AT31: =IFERROR(AT30/AT12,"") | AU31: =IFERROR(AU30/AU12,"") | ... BW31: =IFERROR(BW30/BW12,"")
A32: 29 | B32: Lợi nhuận trước thuế | C32: 9 | AN32: ='Ket qua kinh doanh'!AN20 -> 0 | AO32: ='Ket qua kinh doanh'!AO20 -> 0 | AP32: ='Ket qua kinh doanh'!AP20 -> 0 | AQ32: ='Ket qua kinh doanh'!AQ20 -> 0 | AR32: ='Ket qua kinh doanh'!AR20 -> 0 | AS32: ='Ket qua kinh doanh'!AS20 -> 0 | AT32: ='Ket qua kinh doanh'!AT20 -> 0 | AU32: ='Ket qua kinh doanh'!AU20 -> -400000 | ... BW32: ='Ket qua kinh doanh'!BW20 -> 0
A33: 30 | B33: % Lợi nhuận trước thuế | C33: 9 | AN33: =IFERROR(AN32/AN12,"") | AO33: =IFERROR(AO32/AO12,"") | AP33: =IFERROR(AP32/AP12,"") | AQ33: =IFERROR(AQ32/AQ12,"") | AR33: =IFERROR(AR32/AR12,"") | AS33: =IFERROR(AS32/AS12,"") | AT33: =IFERROR(AT32/AT12,"") | AU33: =IFERROR(AU32/AU12,"") | ... BW33: =IFERROR(BW32/BW12,"")
A34: 31 | B34: EBITDA | C34: 9 | AN34: ='Ket qua kinh doanh'!AN20+'Ket qua kinh doanh'!AN13+'Luu chuyen tien te'!AN7 -> 0 | AO34: ='Ket qua kinh doanh'!AO20+'Ket qua kinh doanh'!AO13+'Luu chuyen tien te'!AO7 -> 0 | AP34: ='Ket qua kinh doanh'!AP20+'Ket qua kinh doanh'!AP13+'Luu chuyen tien te'!AP7 -> 0 | AQ34: ='Ket qua kinh doanh'!AQ20+'Ket qua kinh doanh'!AQ13+'Luu chuyen tien te'!AQ7 -> 0 | AR34: ='Ket qua kinh doanh'!AR20+'Ket qua kinh doanh'!AR13+'Luu chuyen tien te'!AR7 -> 0 | AS34: ='Ket qua kinh doanh'!AS20+'Ket qua kinh doanh'!AS13+'Luu chuyen tien te'!AS7 -> 0 | AT34: ='Ket qua kinh doanh'!AT20+'Ket qua kinh doanh'!AT13+'Luu chuyen tien te'!AT7 -> 0 | AU34: ='Ket qua kinh doanh'!AU20+'Ket qua kinh doanh'!AU13+'Luu chuyen tien te'!AU7 -> -400000 | ... BW34: ='Ket qua kinh doanh'!BW20+'Ket qua kinh doanh'!BW13+'Luu chuyen tien te'!BW7 -> 0
