Workbook
Name \A: #REF!
Name \M: #REF!
Name _: #N/A
Name _____CON1: #REF!
Name _____CON2: #REF!
Name _____lai04: #REF!
Name _____NET2: #REF!
Name ____CON1: #REF!
Name ____CON2: #REF!
Name ____lai04: #REF!
Name ____NET2: #REF!
Name ____TAX3: #REF!
Name ____TAX5: #REF!
Name ____TAX8: #REF!
Name ___ATS98: #REF!
Name ___BGT02: [1]Budget!$A$1:$IV$65536
Name ___CON1: #REF!
Name ___CON2: #REF!
Name ___CHF98: #REF!
Name ___CHX2002: [2]Zellennamen!#REF!
Name ___CHX2003: [2]Zellennamen!#REF!
Name ___CHX2004: [2]Zellennamen!#REF!
Name ___CHX2005: [2]Zellennamen!#REF!
Name ___DTB2003: #REF!
Name ___DTB2004: #REF!
Name ___lai04: #REF!
Name ___LY01: '[3]Last Year'!$A$1:$IV$65536
Name ___Mkt1: '[4]Rolling F''Cast P&L'!$GQ$26:$GQ$42
Name ___NET2: #REF!
Name ___TAX3: #REF!
Name ___TAX5: #REF!
Name ___TAX8: #REF!
Name ___VAR1: #REF!
Name ___VAR2: #REF!
Name ___var22: '[5](Setup)'!$C$17
Name ___VAR3: #REF!
Name ___VAR4: #REF!
Name ___VAR5: #REF!
Name ___VAR6: #REF!
Name ___VAR7: #REF!
Name __ATS98: #REF!
Name __BGT02: [1]Budget!$A$1:$IV$65536
Name __CON1: #REF!
Name __CON2: #REF!
Name __CHF98: #REF!
Name __CHX2002: [2]Zellennamen!#REF!
Name __CHX2003: [2]Zellennamen!#REF!
Name __CHX2004: [2]Zellennamen!#REF!
Name __CHX2005: [2]Zellennamen!#REF!
Name __DAT1: #REF!
Name __DAT10: #REF!
Name __DAT11: #REF!
Name __DAT12: #REF!
Name __DAT13: #REF!
Name __DAT14: #REF!
Name __DAT15: #REF!
Name __DAT16: #REF!
Name __DAT17: #REF!
Name __DAT18: #REF!
Name __DAT19: #REF!

Sheet Chart mục tiêu
Q126: : Ước thực hiện cả năm
Q127: : Mục tiêu | S127: : thực hiện | U127: : Ước thực hiện cả năm

Sheet Data Chart
B3: 2 | T3: Không tính Lãi cho vay & Khấu hao, thuế TNDN
B4: Tháng | C4: Doanh thu | D4: Doanh thu bù các tháng trước | E4: Tổng Doanh thu + bù | F4: Sản lượng bán | G4: Sản lượng dự báo FC | H4: Sản lượng bù thêm các tháng trước thiếu | I4: Tổng sản lượng bán + bù | J4: Doanh thu | K4: Doanh thu | L4: Sản lượng bán | M4: Ước sản lượng bán thực hiện | N4: Lợi Nhuận Ròng (tỷ đồng) | P4: Lợi nhuận ròng (tỷ đồng) | R4: % Lợi nhuận/Doanh thu | T4: Ước tính lợi Nhuận ròng thực hiện (tỷ đồng) | V4: Ước % Lợi nhuận /Doanh thu | X4: EBITDA mục tiêu 2026 (tỷ đồng) | Z4: EBITDA thực hiện (tỷ) | AB4: % EBITDA thực hiện | AE4: Lũy kế EBITDA (tỷ đ) | AG4: Lũy kế EBITDA (tỷ) | AI4: LK Lợi nhuận ròng (tỷ) | AK4: LK Lợi nhuận ròng (tỷ)
C5: Mục tiêu | F5: kế hoạch | J5: Thực Hiện | K5: dự báo FC | L5: thực hiện | N5: Mục tiêu | P5: Thực hiện | R5: Thực hiện | AE5: Mục tiêu | AG5: Thực hiện | AI5: Mục tiêu | AK5: Thực hiện
C6: (Triệu đồng) | F6: Tấn | G6: Tấn | J6: (Tỷ đồng) | K6: (Tỷ đồng) | L6: (Tấn) | M6: (Tấn) | N6: Mục tiêu | O6: Mục tiêu sau loại trừ | P6: Thực hiện | Q6: Thực hiện sau loại trừ | R6: Thực hiện | S6: Sau loại trừ | T6: Thực hiện | U6: Sau loại trừ | V6: Thực hiện | W6: Sau loại trừ | X6: Mục tiêu | Y6: Sau loại trừ | Z6: Thực hiện | AA6: Sau loại trừ | AB6: Thực hiện | AC6: Sau loại trừ | AE6: Mục tiêu | AF6: Sau loại trừ | AG6: Thực hiện | AH6: Sau loại trừ | AI6: Mục tiêu | AJ6: Sau loại trừ | AK6: Thực hiện | AL6: Sau loại trừ
B7: T1.21 | J7: 2192.9406 | L7: 76.025 | P7: -145.31993 | R7: =P7/$J7 -> -0.066267152 | T7: -145.31993 | V7: =T7/$J7 -> -0.066267152 | Z7: 135.20192 | AC7: =Z7/$J7 -> 0.061653254 | AG7: =Z7 -> 135.20192
B8: T2.21 | J8: 1791.822 | L8: 61 | P8: -261.86612 | R8: =P8/$J8 -> -0.14614516 | T8: -261.86612 | V8: =T8/$J8 -> -0.14614516 | Z8: -214.83113 | AC8: =Z8/$J8 -> -0.11989535 | AG8: =AG7+Z8 -> -79.629209
B9: T3.21 | J9: 8682.0846 | L9: 303.8 | P9: 1493.5068 | R9: =P9/$J9 -> 0.17202169 | T9: 1493.5068 | V9: =T9/$J9 -> 0.17202169 | Z9: 1434.3937 | AC9: =Z9/$J9 -> 0.16521306 | AG9: =AG8+Z9 -> 1354.7645
B10: T4.21 | J10: 6264.3327 | L10: 215.35 | P10: 1012.555 | R10: =P10/$J10 -> 0.16163812 | T10: 1012.555 | V10: =T10/$J10 -> 0.16163812 | Z10: 912.27287 | AC10: =Z10/$J10 -> 0.1456297 | AG10: =AG9+Z10 -> 2267.0374
B11: T5.21 | J11: 1376.9734 | L11: 35.93 | P11: -227.06432 | R11: =P11/$J11 -> -0.16490102 | T11: -227.06432 | V11: =T11/$J11 -> -0.16490102 | Z11: -276.60379 | AC11: =Z11/$J11 -> -0.20087809 | AG11: =AG10+Z11 -> 1990.4336
B12: T6.21 | J12: 904.63137 | L12: 30.437 | P12: 283.60144 | R12: =P12/$J12 -> 0.31349945 | T12: 283.60144 | V12: =T12/$J12 -> 0.31349945 | Z12: -301.79639 | AC12: =Z12/$J12 -> -0.33361256 | AG12: =AG11+Z12 -> 1688.6372
B13: T7.21 | J13: 3085.5828 | L13: 87.5 | P13: 9709.9566 | R13: =P13/$J13 -> 3.1468793 | T13: 9709.9566 | V13: =T13/$J13 -> 3.1468793 | Z13: 175.36958 | AC13: =Z13/$J13 -> 0.056835157 | AG13: =AG12+Z13 -> 1864.0068
B14: T8.21 | J14: 2036.7564 | L14: 69.2 | P14: 853.9722 | R14: =P14/$J14 -> 0.41928048 | T14: 853.9722 | V14: =T14/$J14 -> 0.41928048 | Z14: -971.96542 | AC14: =Z14/$J14 -> -0.4772124 | AG14: =AG13+Z14 -> 892.04139
B15: T9.21 | J15: 4007.8346 | L15: 115.5 | P15: 1703.2444 | R15: =P15/$J15 -> 0.42497872 | T15: 1703.2444 | V15: =T15/$J15 -> 0.42497872 | Z15: 674.41148 | AC15: =Z15/$J15 -> 0.16827328 | AG15: =AG14+Z15 -> 1566.4529
B16: T10.21 | J16: 8372.3086 | L16: 262.5 | P16: 695.11938 | R16: =P16/$J16 -> 0.08302601 | T16: 695.11938 | V16: =T16/$J16 -> 0.08302601 | Z16: 1608.2381 | AC16: =Z16/$J16 -> 0.19209016 | AG16: =AG15+Z16 -> 3174.691
B17: T11.21 | J17: 8615.0336 | L17: 284.8 | P17: -10.75835 | R17: =P17/$J17 -> -0.0012487879 | T17: -10.75835 | V17: =T17/$J17 -> -0.0012487879 | Z17: 1137.527 | AC17: =Z17/$J17 -> 0.13203977 | AG17: =AG16+Z17 -> 4312.218
B18: T12.21 | J18: 13231.975 | L18: 589.92 | P18: 2797.121 | R18: =P18/$J18 -> 0.21139104 | T18: 2797.121 | V18: =T18/$J18 -> 0.21139104 | Z18: 1516.1379 | AC18: =Z18/$J18 -> 0.11458137 | AG18: =AG17+Z18 -> 5828.3559
B19: Tổng 2021 | C19: =SUM(C7:C18) -> 0 | J19: =SUM(J7:J18) -> 60562.276 | L19: =SUM(L7:L18) -> 2131.962 | P19: =SUM(P7:P18) -> 17904.068 | R19: =P19/$J19 -> 0.2956307 | T19: =SUM(T7:T18) -> 17904.068 | V19: =T19/$J19 -> 0.2956307 | X19: =SUM(X7:X18) -> 0 | Z19: =SUM(Z7:Z18) -> 5828.3559 | AC19: =Z19/$J19 -> 0.096237398 | AE19: =SUM(AE7:AE18) -> 0 | AG19: =AG18 -> 5828.3559 | AI19: =SUM(AI7:AI18) -> 0 | AK19: =AK18 -> 0
B20: Năm 2025
B21: 1 | C21: 127.18788 | F21: 4318.2229 | G21: 4318.2229 | J21: =IF($C56=0,#N/A,$C56) -> 126.09904 | L21: =IF($D56=0,#N/A,$D56) -> 4241.842 | N21: -1.6227981 | O21: -1.6227981 | P21: =IF($E56=0,#N/A,$E56) -> -1.6934607 | Q21: =IF($F56=0,#N/A,$F56) -> -1.6934607 | R21: =IFERROR(P21/($J21),#N/A) -> -0.013429609 | S21: =IFERROR(Q21/($J21),#N/A) -> -0.013429609 | T21: =P21 -> -1.6934607 | U21: =Q21 -> -1.6934607 | V21: =T21/$J21 -> -0.013429609 | W21: =U21/$J21 -> -0.013429609 | X21: 5.5859163 | Y21: 5.5859163 | Z21: =IF($G56=0,#N/A,$G56) -> 1.574238 | AA21: =IF($H56=0,#N/A,$H56) -> 1.574238 | AB21: =Z21/J21 -> 0.01248414 | AC21: =AA21/J21 -> 0.01248414 | AE21: =X21 -> 5.5859163 | AF21: =Y21 -> 5.5859163 | AG21: =Z21 -> 1.574238 | AH21: =AA21 -> 1.574238 | AI21: =N21 -> -1.6227981 | AJ21: =O21 -> -1.6227981 | AK21: =P21 -> -1.6934607 | AL21: =Q21 -> -1.6934607
B22: 2 | C22: 125.41159 | F22: 4253.3146 | G22: 4253.3146 | J22: =IF($C57=0,#N/A,$C57) -> 96.566805 | L22: =IF($D57=0,#N/A,$D57) -> 3245.53 | N22: 0.58682152 | O22: 0.58682152 | P22: =IF($E57=0,#N/A,$E57) -> -6.4192137 | Q22: =IF($F57=0,#N/A,$F57) -> -6.4192137 | R22: =IFERROR(P22/($J22),#N/A) -> -0.066474331 | S22: =IFERROR(Q22/($J22),#N/A) -> -0.066474331 | T22: =P22 -> -6.4192137 | U22: =Q22 -> -6.4192137 | V22: =T22/$J22 -> -0.066474331 | W22: =U22/$J22 -> -0.066474331 | X22: 8.9848388 | Y22: 8.9848388 | Z22: =IF($G57=0,#N/A,$G57) -> -3.2434715 | AA22: =IF($H57=0,#N/A,$H57) -> -3.2434715 | AB22: =Z22/J22 -> -0.033587851 | AC22: =AA22/J22 -> -0.033587851 | AE22: =AE21+X22 -> 14.570755 | AF22: =AF21+Y22 -> 14.570755 | AG22: =AG21+Z22 -> -1.6692335 | AH22: =AH21+AA22 -> -1.6692335 | AI22: =AI21+N22 -> -1.0359766 | AJ22: =AJ21+O22 -> -1.0359766 | AK22: =AK21+P22 -> -8.1126745 | AL22: =AL21+Q22 -> -8.1126745
B23: 3 | C23: 138.51989 | F23: 4678.5574 | G23: 4678.5574 | J23: =IF($C58=0,#N/A,$C58) -> 173.30582 | L23: =IF($D58=0,#N/A,$D58) -> 6165.199 | N23: 2.7456563 | O23: 2.7456563 | P23: =IF($E58=0,#N/A,$E58) -> -6.6654066 | Q23: =IF($F58=0,#N/A,$F58) -> -6.6654066 | R23: =IFERROR(P23/($J23),#N/A) -> -0.038460373 | S23: =IFERROR(Q23/($J23),#N/A) -> -0.038460373 | T23: =P23 -> -6.6654066 | U23: =Q23 -> -6.6654066 | V23: =T23/$J23 -> -0.038460373 | W23: =U23/$J23 -> -0.038460373 | X23: 11.407938 | Y23: 11.407938 | Z23: =IF($G58=0,#N/A,$G58) -> -4.054122 | AA23: =IF($H58=0,#N/A,$H58) -> -4.054122 | AB23: =Z23/J23 -> -0.023392878 | AC23: =AA23/J23 -> -0.023392878 | AE23: =AE22+X23 -> 25.978693 | AF23: =AF22+Y23 -> 25.978693 | AG23: =AG22+Z23 -> -5.7233555 | AH23: =AH22+AA23 -> -5.7233555 | AI23: =AI22+N23 -> 1.7096797 | AJ23: =AJ22+O23 -> 1.7096797 | AK23: =AK22+P23 -> -14.778081 | AL23: =AL22+Q23 -> -14.778081
B24: 4 | C24: 129.53382 | F24: 4394.2315 | G24: 4394.2315 | J24: =IF($C59=0,#N/A,$C59) -> 159.05685 | L24: =IF($D59=0,#N/A,$D59) -> 5559.431 | N24: -0.93658019 | O24: -0.93658019 | P24: =IF($E59=0,#N/A,$E59) -> 3.7037542 | Q24: =IF($F59=0,#N/A,$F59) -> 3.7037542 | R24: =IFERROR(P24/($J24),#N/A) -> 0.023285725 | S24: =IFERROR(Q24/($J24),#N/A) -> 0.023285725 | T24: =P24 -> 3.7037542 | U24: =Q24 -> 3.7037542 | V24: =T24/$J24 -> 0.023285725 | W24: =U24/$J24 -> 0.023285725 | X24: 7.4521583 | Y24: 7.4521583 | Z24: =IF($G59=0,#N/A,$G59) -> 6.7707201 | AA24: =IF($H59=0,#N/A,$H59) -> 6.7707201 | AB24: =Z24/J24 -> 0.042567924 | AC24: =AA24/J24 -> 0.042567924 | AE24: =AE23+X24 -> 33.430851 | AF24: =AF23+Y24 -> 33.430851 | AG24: =AG23+Z24 -> 1.0473646 | AH24: =AH23+AA24 -> 1.0473646 | AI24: =AI23+N24 -> 0.77309953 | AJ24: =AJ23+O24 -> 0.77309953 | AK24: =AK23+P24 -> -11.074327 | AL24: =AL23+Q24 -> -11.074327
B25: 5 | C25: 137.58723 | F25: 4663.4364 | G25: 4663.4364 | J25: =IF($C60=0,#N/A,$C60) -> 159.76531 | L25: =IF($D60=0,#N/A,$D60) -> 5019.773 | N25: 1.1280967 | O25: 1.1280967 | P25: =IF($E60=0,#N/A,$E60) -> 8.2274254 | Q25: =IF($F60=0,#N/A,$F60) -> 8.2274254 | R25: =IFERROR(P25/($J25),#N/A) -> 0.051496946 | S25: =IFERROR(Q25/($J25),#N/A) -> 0.051496946 | T25: =P25 -> 8.2274254 | U25: =Q25 -> 8.2274254 | V25: =T25/$J25 -> 0.051496946 | W25: =U25/$J25 -> 0.051496946 | X25: 9.769049 | Y25: 9.769049 | Z25: =IF($G60=0,#N/A,$G60) -> 11.229251 | AA25: =IF($H60=0,#N/A,$H60) -> 11.229251 | AB25: =Z25/J25 -> 0.070285914 | AC25: =AA25/J25 -> 0.070285914 | AE25: =AE24+X25 -> 43.1999 | AF25: =AF24+Y25 -> 43.1999 | AG25: =AG24+Z25 -> 12.276615 | AH25: =AH24+AA25 -> 12.276615 | AI25: =AI24+N25 -> 1.9011963 | AJ25: =AJ24+O25 -> 1.9011963 | AK25: =AK24+P25 -> -2.8469015 | AL25: =AL24+Q25 -> -2.8469015
B26: 6 | C26: 138.25385 | F26: 4691.9522 | G26: 4691.9522 | J26: =IF($C61=0,#N/A,$C61) -> #N/A | L26: =IF($D61=0,#N/A,$D61) -> #N/A | N26: 0.35162666 | O26: 0.35162666 | P26: =IF($E61=0,#N/A,$E61) -> #N/A | Q26: =IF($F61=0,#N/A,$F61) -> #N/A | R26: =IFERROR(P26/($J26),#N/A) -> #N/A | S26: =IFERROR(Q26/($J26),#N/A) -> #N/A | T26: =P26 -> #N/A | U26: =Q26 -> #N/A | V26: =T26/$J26 -> #N/A | W26: =U26/$J26 -> #N/A | X26: 9.1798751 | Y26: 9.1798751 | Z26: =IF($G61=0,#N/A,$G61) -> #N/A | AA26: =IF($H61=0,#N/A,$H61) -> #N/A | AB26: =Z26/J26 -> #N/A | AC26: =AA26/J26 -> #N/A | AE26: =AE25+X26 -> 52.379775 | AF26: =AF25+Y26 -> 52.379775 | AG26: =AG25+Z26 -> #N/A | AH26: =AH25+AA26 -> #N/A | AI26: =AI25+N26 -> 2.2528229 | AJ26: =AJ25+O26 -> 2.2528229 | AK26: =AK25+P26 -> #N/A | AL26: =AL25+Q26 -> #N/A
B27: 7 | C27: 137.70857 | F27: 4689.4225 | G27: 4689.4225 | J27: =IF($C62=0,#N/A,$C62) -> #N/A | L27: =IF($D62=0,#N/A,$D62) -> #N/A | N27: 5.6882325 | O27: 5.6882325 | P27: =IF($E62=0,#N/A,$E62) -> #N/A | Q27: =IF($F62=0,#N/A,$F62) -> #N/A | R27: =IFERROR(P27/($J27),#N/A) -> #N/A | S27: =IFERROR(Q27/($J27),#N/A) -> #N/A | T27: =P27 -> #N/A | U27: =Q27 -> #N/A | V27: =T27/$J27 -> #N/A | W27: =U27/$J27 -> #N/A | X27: 14.514474 | Y27: 14.514474 | Z27: =IF($G62=0,#N/A,$G62) -> #N/A | AA27: =IF($H62=0,#N/A,$H62) -> #N/A | AB27: =Z27/J27 -> #N/A | AC27: =AA27/J27 -> #N/A | AE27: =AE26+X27 -> 66.894249 | AF27: =AF26+Y27 -> 66.894249 | AG27: =AG26+Z27 -> #N/A | AH27: =AH26+AA27 -> #N/A | AI27: =AI26+N27 -> 7.9410554 | AJ27: =AJ26+O27 -> 7.9410554 | AK27: =AK26+P27 -> #N/A | AL27: =AL26+Q27 -> #N/A
B28: 8 | C28: 133.74125 | F28: 4562.8495 | G28: 4562.8495 | I28: =H28+M28 -> 0 | J28: =IF($C63=0,#N/A,$C63) -> #N/A | L28: =IF($D63=0,#N/A,$D63) -> #N/A | N28: 3.7106447 | O28: 3.7106447 | P28: =IF($E63=0,#N/A,$E63) -> #N/A | Q28: =IF($F63=0,#N/A,$F63) -> #N/A | R28: =IFERROR(P28/($J28),#N/A) -> #N/A | S28: =IFERROR(Q28/($J28),#N/A) -> #N/A | T28: =P28 -> #N/A | U28: =Q28 -> #N/A | V28: =T28/$J28 -> #N/A | W28: =U28/$J28 -> #N/A | X28: 12.693546 | Y28: 12.693546 | Z28: =IF($G63=0,#N/A,$G63) -> #N/A | AA28: =IF($H63=0,#N/A,$H63) -> #N/A | AB28: =Z28/J28 -> #N/A | AC28: =AA28/J28 -> #N/A | AE28: =AE27+X28 -> 79.587795 | AF28: =AF27+Y28 -> 79.587795 | AG28: =AG27+Z28 -> #N/A | AH28: =AH27+AA28 -> #N/A | AI28: =AI27+N28 -> 11.6517 | AJ28: =AJ27+O28 -> 11.6517 | AK28: =AK27+P28 -> #N/A | AL28: =AL27+Q28 -> #N/A
B29: 9 | C29: 139.83157 | F29: 4774.6231 | G29: 4774.6231 | I29: =H29+M29 -> 0 | J29: =IF($C64=0,#N/A,$C64) -> #N/A | L29: =IF($D64=0,#N/A,$D64) -> #N/A | N29: 4.58904 | O29: 4.58904 | P29: =IF($E64=0,#N/A,$E64) -> #N/A | Q29: =IF($F64=0,#N/A,$F64) -> #N/A | R29: =IFERROR(P29/($J29),#N/A) -> #N/A | S29: =IFERROR(Q29/($J29),#N/A) -> #N/A | T29: =P29 -> #N/A | U29: =Q29 -> #N/A | V29: =T29/$J29 -> #N/A | W29: =U29/$J29 -> #N/A | X29: 13.428733 | Y29: 13.428733 | Z29: =IF($G64=0,#N/A,$G64) -> #N/A | AA29: =IF($H64=0,#N/A,$H64) -> #N/A | AB29: =Z29/J29 -> #N/A | AC29: =AA29/J29 -> #N/A | AE29: =AE28+X29 -> 93.016529 | AF29: =AF28+Y29 -> 93.016529 | AG29: =AG28+Z29 -> #N/A | AH29: =AH28+AA29 -> #N/A | AI29: =AI28+N29 -> 16.24074 | AJ29: =AJ28+O29 -> 16.24074 | AK29: =AK28+P29 -> #N/A | AL29: =AL28+Q29 -> #N/A
B30: 10 | C30: 130.38258 | F30: 4468.6263 | G30: 4468.6263 | I30: =H30+M30 -> 0 | J30: =IF($C65=0,#N/A,$C65) -> #N/A | L30: =IF($D65=0,#N/A,$D65) -> #N/A | N30: 2.8661667 | O30: 2.8661667 | P30: =IF($E65=0,#N/A,$E65) -> #N/A | Q30: =IF($F65=0,#N/A,$F65) -> #N/A | R30: =IFERROR(P30/($J30),#N/A) -> #N/A | S30: =IFERROR(Q30/($J30),#N/A) -> #N/A | T30: =P30 -> #N/A | U30: =Q30 -> #N/A | V30: =T30/$J30 -> #N/A | W30: =U30/$J30 -> #N/A | X30: 11.690488 | Y30: 11.690488 | Z30: =IF($G65=0,#N/A,$G65) -> #N/A | AA30: =IF($H65=0,#N/A,$H65) -> #N/A | AB30: =Z30/J30 -> #N/A | AC30: =AA30/J30 -> #N/A | AE30: =AE29+X30 -> 104.70702 | AF30: =AF29+Y30 -> 104.70702 | AG30: =AG29+Z30 -> #N/A | AH30: =AH29+AA30 -> #N/A | AI30: =AI29+N30 -> 19.106907 | AJ30: =AJ29+O30 -> 19.106907 | AK30: =AK29+P30 -> #N/A | AL30: =AL29+Q30 -> #N/A
B31: 11 | C31: 138.06137 | F31: 4720.2431 | G31: 4720.2431 | I31: =H31+M31 -> 0 | J31: =IF($C66=0,#N/A,$C66) -> #N/A | L31: =IF($D66=0,#N/A,$D66) -> #N/A | N31: 5.7344809 | O31: 5.7344809 | P31: =IF($E66=0,#N/A,$E66) -> #N/A | Q31: =IF($F66=0,#N/A,$F66) -> #N/A | R31: =IFERROR(P31/($J31),#N/A) -> #N/A | S31: =IFERROR(Q31/($J31),#N/A) -> #N/A | T31: =P31 -> #N/A | U31: =Q31 -> #N/A | V31: =T31/$J31 -> #N/A | W31: =U31/$J31 -> #N/A | X31: 14.535438 | Y31: 14.535438 | Z31: =IF($G66=0,#N/A,$G66) -> #N/A | AA31: =IF($H66=0,#N/A,$H66) -> #N/A | AB31: =Z31/J31 -> #N/A | AC31: =AA31/J31 -> #N/A | AE31: =AE30+X31 -> 119.24245 | AF31: =AF30+Y31 -> 119.24245 | AG31: =AG30+Z31 -> #N/A | AH31: =AH30+AA31 -> #N/A | AI31: =AI30+N31 -> 24.841388 | AJ31: =AJ30+O31 -> 24.841388 | AK31: =AK30+P31 -> #N/A | AL31: =AL30+Q31 -> #N/A
B32: 12 | C32: 139.43048 | F32: 4784.5204 | G32: 4784.5204 | I32: =H32+M32 -> 0 | J32: =IF($C67=0,#N/A,$C67) -> #N/A | L32: =IF($D67=0,#N/A,$D67) -> #N/A | N32: 2.9676891 | O32: 2.9676891 | P32: =IF($E67=0,#N/A,$E67) -> #N/A | Q32: =IF($F67=0,#N/A,$F67) -> #N/A | R32: =IFERROR(P32/($J32),#N/A) -> #N/A | S32: =IFERROR(Q32/($J32),#N/A) -> #N/A | T32: =P32 -> #N/A | U32: =Q32 -> #N/A | V32: =T32/$J32 -> #N/A | W32: =U32/$J32 -> #N/A | X32: 11.562532 | Y32: 11.562532 | Z32: =IF($G67=0,#N/A,$G67) -> #N/A | AA32: =IF($H67=0,#N/A,$H67) -> #N/A | AB32: =Z32/J32 -> #N/A | AC32: =AA32/J32 -> #N/A | AE32: =AE31+X32 -> 130.80499 | AF32: =AF31+Y32 -> 130.80499 | AG32: =AG31+Z32 -> #N/A | AH32: =AH31+AA32 -> #N/A | AI32: =AI31+N32 -> 27.809077 | AJ32: =AJ31+O32 -> 27.809077 | AK32: =AK31+P32 -> #N/A | AL32: =AL31+Q32 -> #N/A
B33: Lũy kế 2025 | C33: =SUM(C21:C32) -> 1615.6501 | D33: =SUM(D25:D32) -> 0 | E33: =SUM(E25:E32) -> 0 | F33: =SUM(F21:F32) -> 55000 | G33: =SUM(G21:G32) -> 55000 | H33: =SUM(H21:H32) -> 0 | I33: =SUM(I21:I32) -> 0 | J33: =SUMIFS(J$21:J$32,J$21:J$32,"<>"&"#n/a") -> 714.79383 | K33: =SUMIFS(K$21:K$32,K$21:K$32,"<>"&"#n/a") -> 0 | L33: =SUMIFS(L$21:L$32,L$21:L$32,"<>"&"#n/a") -> 24231.775 | M33: =SUM(M21:M32) -> 0 | N33: =SUM(N21:N32) -> 27.809077 | O33: =SUM(O21:O32) -> 27.809077 | P33: =SUMIFS(P$21:P$32,P$21:P$32,"<>"&"#n/a") -> -2.8469015 | Q33: =SUMIFS(Q$21:Q$32,Q$21:Q$32,"<>"&"#n/a") -> -2.8469015 | R33: =IFERROR(P33/($J33),#N/A) -> -0.0039828288 | S33: =IFERROR(Q33/($J33),#N/A) -> -0.0039828288 | T33: =SUM(T21:T32) -> #N/A | U33: =SUM(U21:U32) -> #N/A | V33: =SUM(V21:V32) -> #N/A | W33: =SUM(W21:W32) -> #N/A | X33: =SUM(X21:X32) -> 130.80499 | Y33: =SUM(Y21:Y32) -> 130.80499 | Z33: =SUM(Z21:Z32) -> #N/A | AA33: =SUM(AA21:AA32) -> #N/A | ... AC33: =SUM(AC21:AC32) -> #N/A | AE33: =AE32 -> 130.80499 | AF33: =AF32 -> 130.80499 | AG33: =AG32 -> #N/A | AI33: =AI32 -> 27.809077 | AJ33: =AJ32 -> 27.809077 | AK33: =AK32 -> #N/A | AL33: =AL32 -> #N/A
B34: FC 12T | C34: 1 | D34: =C33-J33-K33 -> 900.85625 | J34: =J33/C33 -> 0.44241871 | K34: =K33/C33 -> 0 | L34: =G33 -> 55000 | M34: =F33-L33-M33 -> 30768.225 | N34: 1 | O34: 1 | P34: =P33/N33 -> -0.1023731 | Q34: =Q33/O33 -> -0.1023731 | T34: =V33 -> #N/A | X34: =X33/($C$33*10^3) -> 8.096121e-05 | Z34: =Z33/(J33*10^3) -> #N/A
B35: Mục Tiêu 2024 | F35: =F33/$F$33 -> 1 | J35: =L33/$F$33 -> 0.44057773 | K35: =M33/$F$33 -> 0 | L35: =F33 -> 55000 | M35: =M34+M33+L33 -> 55000
C36: =N33/C33 -> 0.017212314 | X36: =X33/C33 -> 0.08096121
B37: TRƯỚC LOẠI TRỪ | N37: =N33/C32 -> 0.19944762
B38: Tháng | C38: T1.26 | D38: 2 | E38: 3 | F38: 4 | G38: 5 | H38: 6 | I38: 7 | J38: 8 | K38: 9 | L38: 10 | M38: 11 | N38: 12
B39: Doanh Thu | C39: =BCTC2026!D184/10^9 -> 126.09904 | D39: =BCTC2026!E184/10^9 -> 96.566805 | E39: =BCTC2026!F184/10^9 -> 173.30582 | F39: =BCTC2026!G184/10^9 -> 159.05685 | G39: =BCTC2026!H184/10^9 -> 159.76531 | H39: =BCTC2026!I184/10^9 -> 0 | I39: =BCTC2026!J184/10^9 -> 0 | J39: =BCTC2026!K184/10^9 -> 0 | ... N39: =BCTC2026!O184/10^9 -> 0
B40: Chi Phí | C40: =(BCTC2026!D160+BCTC2026!D162+BCTC2026!D163-BCTC2026!D165+BCTC2026!D166-BCTC2026!D169+BCTC2026!D170)/10^9 -> 127.7925 | D40: =(BCTC2026!E160+BCTC2026!E162+BCTC2026!E163-BCTC2026!E165+BCTC2026!E166-BCTC2026!E169+BCTC2026!E170)/10^9 -> 102.98602 | E40: =(BCTC2026!F160+BCTC2026!F162+BCTC2026!F163-BCTC2026!F165+BCTC2026!F166-BCTC2026!F169+BCTC2026!F170)/10^9 -> 180.12429 | F40: =(BCTC2026!G160+BCTC2026!G162+BCTC2026!G163-BCTC2026!G165+BCTC2026!G166-BCTC2026!G169+BCTC2026!G170)/10^9 -> 155.3531 | G40: =(BCTC2026!H160+BCTC2026!H162+BCTC2026!H163-BCTC2026!H165+BCTC2026!H166-BCTC2026!H169+BCTC2026!H170)/10^9 -> 151.58373 | H40: =(BCTC2026!I160+BCTC2026!I162+BCTC2026!I163-BCTC2026!I165+BCTC2026!I166-BCTC2026!I169+BCTC2026!I170)/10^9 -> 0 | I40: =(BCTC2026!J160+BCTC2026!J162+BCTC2026!J163-BCTC2026!J165+BCTC2026!J166-BCTC2026!J169+BCTC2026!J170)/10^9 -> 0 | J40: =(BCTC2026!K160+BCTC2026!K162+BCTC2026!K163-BCTC2026!K165+BCTC2026!K166-BCTC2026!K169+BCTC2026!K170)/10^9 -> 0 | ... N40: =(BCTC2026!O160+BCTC2026!O162+BCTC2026!O163-BCTC2026!O165+BCTC2026!O166-BCTC2026!O169+BCTC2026!O170)/10^9 -> 0
B41: Lợi nhuận | C41: =C39-C40 -> -1.6934607 | D41: =D39-D40 -> -6.4192137 | E41: =E39-E40 -> -6.8184675 | F41: =F39-F40 -> 3.7037542 | G41: =G39-G40 -> 8.1815839 | H41: =H39-H40 -> 0 | I41: =I39-I40 -> 0 | J41: =J39-J40 -> 0 | ... N41: =N39-N40 -> 0
B43: SAU LOẠI TRỪ
...

Sheet KQKD MẪU CŨ
C1: TỔNG TÀI SẢN DTR - NGÀY 31/03/2023
C2: BÁO CÁO KẾT QUẢ KINH DOANH - NĂM 2023 | Q2: Tỷ giá
Q3: 24450 | T3: 22840
B4: Stt | C4: KẾT QUẢ KINH DOANH | D4: Tháng 01.2023 | E4: Tháng 02.2023 | F4: Tháng 03.2023 | G4: Tháng 04.2023 | H4: Tháng 05.2023 | I4: Tháng 06.2023 | J4: Tháng 07.2023 | K4: Tháng 08.2023 | L4: Tháng 09.2023 | M4: Tháng 10.2023 | N4: Tháng 11.2023 | O4: Tháng 12.2023 | P4: Lũy kế 12 tháng | Q4: $ US | R4: %/Dthu | T4: Lũy kế 2023 | U4: $ US | V4: %/Dthu
C5: Sản lượng bán (tấn) | D5: =BCTC2026!D217 -> 4241.842 | E5: =BCTC2026!E217 -> 3245.53 | F5: =BCTC2026!F217 -> 6165.199 | G5: =BCTC2026!G217 -> 5559.431 | H5: =BCTC2026!H217 -> 5019.773 | I5: =BCTC2026!I217 -> 0 | J5: =BCTC2026!J217 -> 0 | K5: =BCTC2026!K217 -> 0 | ... O5: =BCTC2026!O217 -> 0 | P5: =SUM(D5:O5) -> 24231.775 | T5: =BCTC2026!V154 -> 25012.587
B6: 1 | C6: Doanh thu | D6: =BCTC2026!D159 -> 126099036923 | E6: =BCTC2026!E159 -> 96566805360 | F6: =BCTC2026!F159 -> 173305822529 | G6: =BCTC2026!G159 -> 159056854829 | H6: =BCTC2026!H159 -> 159765309037 | I6: =BCTC2026!I159 -> 0 | J6: =BCTC2026!J159 -> 0 | K6: =BCTC2026!K159 -> 0 | ... O6: =BCTC2026!O159 -> 0 | P6: =SUM(D6:O6) -> 714793828678 | Q6: =P6/$Q$3 -> 29234921 | R6: 1 | T6: =BCTC2026!V159 -> 714793828678 | U6: =T6/$T$3 -> 31295702 | V6: =T6/$T$6 -> 1
C7: Giá vốn (chi phí sản xuất) | D7: =BCTC2026!D160 -> 115080112871 | E7: =BCTC2026!E160 -> 90411470461 | F7: =BCTC2026!F160 -> 165844739865 | G7: =BCTC2026!G160 -> 141086003219 | H7: =BCTC2026!H160 -> 137580032058 | I7: =BCTC2026!I160 -> 0 | J7: =BCTC2026!J160 -> 0 | K7: =BCTC2026!K160 -> 0 | ... O7: =BCTC2026!O160 -> 0 | P7: =SUM(D7:O7) -> 650002358474 | Q7: =P7/$Q$3 -> 26584964 | R7: =Q7/$Q$6 -> 0.90935642 | T7: =BCTC2026!V160 -> 650002358474 | U7: =T7/$T$3 -> 28458947 | V7: =T7/$T$6 -> 0.90935642
B8: 2 | C8: Lãi gộp | D8: =BCTC2026!D161 -> 11018924052 | E8: =BCTC2026!E161 -> 6155334899 | F8: =BCTC2026!F161 -> 7461082664 | G8: =BCTC2026!G161 -> 17970851610 | H8: =BCTC2026!H161 -> 22185276979 | I8: =BCTC2026!I161 -> 0 | J8: =BCTC2026!J161 -> 0 | K8: =BCTC2026!K161 -> 0 | ... O8: =BCTC2026!O161 -> 0 | P8: =SUM(D8:O8) -> 64791470204 | Q8: =P8/$Q$3 -> 2649957.9 | R8: =Q8/$Q$6 -> 0.090643578 | T8: =BCTC2026!V161 -> 64791470204 | U8: =T8/$T$3 -> 2836754.4 | V8: =T8/$T$6 -> 0.090643578
C9: Chi phí bán hàng | D9: =BCTC2026!D162 -> 3731798004 | E9: =BCTC2026!E162 -> 3202645336 | F9: =BCTC2026!F162 -> 6245695788 | G9: =BCTC2026!G162 -> 5821309126 | H9: =BCTC2026!H162 -> 5915805090 | I9: =BCTC2026!I162 -> 0 | J9: =BCTC2026!J162 -> 0 | K9: =BCTC2026!K162 -> 0 | ... O9: =BCTC2026!O162 -> 0 | P9: =SUM(D9:O9) -> 24917253344 | Q9: =P9/$Q$3 -> 1019110.6 | R9: =Q9/$Q$6 -> 0.034859357 | T9: =BCTC2026!V162 -> 24917253344 | U9: =T9/$T$3 -> 1090948 | V9: =T9/$T$6 -> 0.034859357
C10: Chi phí quản lý chung | D10: =BCTC2026!D163 -> 8394130638 | E10: =BCTC2026!E163 -> 7959394332 | F10: =BCTC2026!F163 -> 7329810589 | G10: =BCTC2026!G163 -> 8148952142 | H10: =BCTC2026!H163 -> 8010802475 | I10: =BCTC2026!I163 -> 0 | J10: =BCTC2026!J163 -> 0 | K10: =BCTC2026!K163 -> 0 | ... O10: =BCTC2026!O163 -> 0 | P10: =SUM(D10:O10) -> 39843090176 | Q10: =P10/$Q$3 -> 1629574.2 | R10: =Q10/$Q$6 -> 0.055740675 | T10: =BCTC2026!V163 -> 39843090176 | U10: =T10/$T$3 -> 1744443.5 | V10: =T10/$T$6 -> 0.055740675
B11: 3 | C11: Lợi nhuận sản xuất kinh doanh | D11: =D8-D9-D10 -> -1107004590 | E11: =E8-E9-E10 -> -5006704769 | F11: =F8-F9-F10 -> -6114423713 | G11: =G8-G9-G10 -> 4000590342 | H11: =H8-H9-H10 -> 8258669414 | I11: =I8-I9-I10 -> 0 | J11: =J8-J9-J10 -> 0 | K11: =K8-K9-K10 -> 0 | ... O11: =O8-O9-O10 -> 0 | P11: =SUM(D11:O11) -> 31126684 | Q11: =P11/$Q$3 -> 1273.075 | R11: =Q11/$Q$6 -> 4.354638e-05 | T11: =T8-T9-T10 -> 31126684 | U11: =T11/$T$3 -> 1362.8145 | V11: =T11/$T$6 -> 4.354638e-05
C12: Chi phí lãi vay ngân hàng | D12: =BCTC2026!D166 -> 1532817392 | E12: =BCTC2026!E166 -> 1569283837 | F12: =BCTC2026!F166 -> 1510605035 | G12: =BCTC2026!G166 -> 1998884061 | H12: =BCTC2026!H166 -> 1208736058 | I12: =BCTC2026!I166 -> 0 | J12: =BCTC2026!J166 -> 0 | K12: =BCTC2026!K166 -> 0 | ... O12: =BCTC2026!O166 -> 0 | P12: =SUM(D12:O12) -> 7820326383 | Q12: =P12/$Q$3 -> 319849.75 | R12: =Q12/$Q$6 -> 0.010940674 | T12: =BCTC2026!V166 -> 7820326383 | U12: =T12/$T$3 -> 342396.08 | V12: =T12/$T$6 -> 0.010940674
C13: Thu nhập lãi cho vay | D13: =BCTC2026!D165 -> 1053165322 | E13: =BCTC2026!E165 -> 307705069 | F13: =BCTC2026!F165 -> 839416558 | G13: =BCTC2026!G165 -> 1767937439 | H13: =BCTC2026!H165 -> 1261651212 | I13: =BCTC2026!I165 -> 0 | J13: =BCTC2026!J165 -> 0 | K13: =BCTC2026!K165 -> 0 | ... O13: =BCTC2026!O165 -> 0 | P13: =SUM(D13:O13) -> 5229875600 | Q13: =P13/$Q$3 -> 213900.84 | R13: =Q13/$Q$6 -> 0.0073166211 | T13: =BCTC2026!V165 -> 5229875600 | U13: =T13/$T$3 -> 228978.79 | V13: =T13/$T$6 -> 0.0073166211
C14: Thu nhập khác (tài trợ Coca, Nestle) | D14: =BCTC2026!D171 -> -106804076 | E14: =BCTC2026!E171 -> -150930201 | F14: =BCTC2026!F171 -> -32855301 | G14: =BCTC2026!G171 -> -65889508 | H14: =BCTC2026!H171 -> -130000650 | I14: =BCTC2026!I171 -> 0 | J14: =BCTC2026!J171 -> 0 | K14: =BCTC2026!K171 -> 0 | ... O14: =BCTC2026!O171 -> 0 | P14: =SUM(D14:O14) -> -486479736 | Q14: =P14/$Q$3 -> -19896.922 | R14: =Q14/$Q$6 -> -0.00068058749 | T14: =BCTC2026!V169 -> 11703115 | U14: =T14/$T$3 -> 512.39558 | V14: =T14/$T$6 -> 1.6372714e-05
B15: 4 | C15: Tổng Lợi nhuận trước thuế | D15: =D11-D12+D13+D14 -> -1693460736 | E15: =E11-E12+E13+E14 -> -6419213738 | F15: =F11-F12+F13+F14 -> -6818467491 | G15: =G11-G12+G13+G14 -> 3703754212 | H15: =H11-H12+H13+H14 -> 8181583918 | I15: =I11-I12+I13+I14 -> 0 | J15: =J11-J12+J13+J14 -> 0 | K15: =K11-K12+K13+K14 -> 0 | ... O15: =O11-O12+O13+O14 -> 0 | P15: =SUM(D15:O15) -> -3045803835 | Q15: =P15/$Q$3 -> -124572.75 | R15: =Q15/$Q$6 -> -0.0042610942 | T15: =T11-T12+T13+T14 -> -2547620984 | U15: =T15/$T$3 -> -111542.07 | V15: =T15/$T$6 -> -0.003564134
C16: Thuế thu nhập doanh nghiệp | D16: =BCTC2026!D173 -> 0 | E16: =BCTC2026!E173 -> 0 | F16: =BCTC2026!F173 -> -153060867 | G16: =BCTC2026!G173 -> 0 | H16: =BCTC2026!H173 -> -45841499 | I16: =BCTC2026!I173 -> 0 | J16: =BCTC2026!J173 -> 0 | K16: =BCTC2026!K173 -> 0 | ... O16: =BCTC2026!O173 -> 0 | P16: =SUM(D16:O16) -> -198902366 | Q16: =P16/$Q$3 -> -8135.0661 | R16: =Q16/$Q$6 -> -0.00027826537 | T16: =BCTC2026!V173 -> -198902366 | U16: =T16/$T$3 -> -8708.5099 | V16: =T16/$T$6 -> -0.00027826537
B17: 5 | C17: Lợi nhuận sau thuế | D17: =BCTC2026!D174 -> -1693460736 | E17: =BCTC2026!E174 -> -6419213738 | F17: =BCTC2026!F174 -> -6665406624 | G17: =BCTC2026!G174 -> 3703754212 | H17: =BCTC2026!H174 -> 8227425417 | I17: =BCTC2026!I174 -> 0 | J17: =BCTC2026!J174 -> 0 | K17: =BCTC2026!K174 -> 0 | ... O17: =BCTC2026!O174 -> 0 | P17: =SUM(D17:O17) -> -2846901469 | Q17: =P17/$Q$3 -> -116437.69 | R17: =Q17/$Q$6 -> -0.0039828288 | T17: =T15-T16 -> -2348718618 | U17: =T17/$T$3 -> -102833.56 | V17: =T17/$T$6 -> -0.0032858686
C18: Khấu hao | D18: =BCTC2026!D214 -> 2133968845 | E18: =BCTC2026!E214 -> 2103008488 | F18: =BCTC2026!F214 -> 2118111558 | G18: =BCTC2026!G214 -> 2277961573 | H18: =BCTC2026!H214 -> 2330977557 | I18: =BCTC2026!I214 -> 0 | J18: =BCTC2026!J214 -> 0 | K18: =BCTC2026!K214 -> 0 | ... O18: =BCTC2026!O214 -> 0 | P18: =SUM(D18:O18) -> 10964028021 | Q18: =P18/$Q$3 -> 448426.5 | R18: =Q18/$Q$6 -> 0.015338728
B19: 6 | C19: EBITDA (không gồm Lãi cho vay, Tài trợ) | D19: =BCTC2026!D176 -> 1574237997 | E19: =BCTC2026!E176 -> -3243471474 | F19: =BCTC2026!F176 -> -4054122006 | G19: =BCTC2026!G176 -> 6770720053 | H19: =BCTC2026!H176 -> 11229250758 | I19: =BCTC2026!I176 -> 0 | J19: =BCTC2026!J176 -> 0 | K19: =BCTC2026!K176 -> 0 | ... O19: =BCTC2026!O176 -> 0 | P19: =SUM(D19:O19) -> 12276615328 | Q19: =P19/$Q$3 -> 502111.06 | R19: =Q19/$Q$6 -> 0.017175044 | T19: =BCTC2026!V176 -> 12276615328 | U19: =T19/$T$3 -> 537505.05 | V19: =T19/$T$6 -> 0.017175044
B22: Stt | C22: BẢNG CÂN ĐỐI KẾ TOÁN | D22: 44957 | E22: 44985 | F22: 45016 | G22: 45046 | H22: 45077 | I22: 45107 | J22: 45138 | K22: 45169 | L22: 45199 | M22: 45230 | N22: 45260 | O22: 45291 | P22: $ US (31/12/2023) | Q22: %/TTS | W22: Stt | X22: BẢNG CÂN ĐỐI KẾ TOÁN | Y22: 44957 | Z22: 44985 | AA22: 45016 | AB22: 45046 | AC22: 45077 | AD22: 45107 | AE22: 45138 | AF22: 45169 | AG22: 45199 | AH22: 45230 | AI22: 45260 | AJ22: 45291 | AK22: $ US | AL22: %/TTS
C23: Phải thu cho vay ngắn hạn TGĐ và khác | D23: =BCTC2026!#REF! -> #REF! | E23: =BCTC2026!#REF! -> #REF! | F23: =BCTC2026!#REF! -> #REF! | G23: =BCTC2026!#REF! -> #REF! | H23: =BCTC2026!#REF! -> #REF! | I23: =BCTC2026!#REF! -> #REF! | J23: =BCTC2026!#REF! -> #REF! | K23: =BCTC2026!#REF! -> #REF! | ... O23: =BCTC2026!#REF! -> #REF! | P23: =H23/$Q$3 -> #REF! | Q23: =P23/$P$39 -> #REF!
B24: A | C24: TÀI SẢN NGẮN HẠN | D24: =SUM(D25:D30) -> #REF! | E24: =SUM(E25:E30) -> #REF! | F24: =SUM(F25:F30) -> #REF! | G24: =SUM(G25:G30) -> #REF! | H24: =SUM(H25:H30) -> #REF! | I24: =SUM(I25:I30) -> #REF! | J24: =SUM(J25:J30) -> #REF! | K24: =SUM(K25:K30) -> #REF! | ... O24: =SUM(O25:O30) -> #REF! | P24: =H24/$Q$3 -> #REF! | Q24: =P24/$P$39 -> #REF! | W24: A | X24: NỢ PHẢI TRẢ | Y24: =BCTC2026!D78-Y31 -> 332763448171 | Z24: =BCTC2026!E78-Z31 -> 360618515191 | AA24: =BCTC2026!F78-AA31 -> 326345040700 | AB24: =BCTC2026!G78-AB31 -> 303579055875 | AC24: =BCTC2026!H78-AC31 -> 374252871584 | AD24: =BCTC2026!I78-AD31 -> 0 | AE24: =BCTC2026!J78-AE31 -> 0 | AF24: =BCTC2026!K78-AF31 -> 0 | ... AJ24: =BCTC2026!O78-AJ31 -> 0 | AK24: =AC24/$Q$3 -> 15306866 | AL24: =AK24/AK$39 -> 0.29894733
B25: 1 | C25: Hàng tồn kho | D25: =BCTC2026!D20 -> 534105826237 | E25: =BCTC2026!E20 -> 502545827363 | F25: =BCTC2026!F20 -> 425450972162 | G25: =BCTC2026!G20 -> 370413533224 | H25: =BCTC2026!H20 -> 361880765551 | I25: =BCTC2026!I20 -> 0 | J25: =BCTC2026!J20 -> 0 | K25: =BCTC2026!K20 -> 0 | ... O25: =BCTC2026!O20 -> 0 | P25: =H25/$Q$3 -> 14800849 | Q25: =P25/$P$39 -> #REF! | W25: 1 | X25: Vay dài hạn ngân hàng | Y25: =BCTC2026!D95 -> 49472841415 | Z25: =BCTC2026!E95 -> 71400341415 | AA25: =BCTC2026!F95 -> 80100341415 | AB25: =BCTC2026!G95 -> 80100341415 | AC25: =BCTC2026!H95 -> 154933236415 | AD25: =BCTC2026!I95 -> 0 | AE25: =BCTC2026!J95 -> 0 | AF25: =BCTC2026!K95 -> 0 | ... AJ25: =BCTC2026!O95 -> 0 | AK25: =AC25/$Q$3 -> 6336737.7 | AL25: =AK25/AK$39 -> 0.12375824
B26: 2 | C26: Phải thu khách hàng | D26: =BCTC2026!D13 -> 132649296167 | E26: =BCTC2026!E13 -> 140446291758 | F26: =BCTC2026!F13 -> 153248625708 | G26: =BCTC2026!G13 -> 178191270169 | H26: =BCTC2026!H13 -> 178005616424 | I26: =BCTC2026!I13 -> 0 | J26: =BCTC2026!J13 -> 0 | K26: =BCTC2026!K13 -> 0 | ... O26: =BCTC2026!O13 -> 0 | P26: =H26/$Q$3 -> 7280393.3 | Q26: =P26/$P$39 -> #REF! | W26: 2 | X26: Vay ngắn hạn ngân hàng | Y26: =BCTC2026!#REF! -> #REF! | Z26: =BCTC2026!#REF! -> #REF! | AA26: =BCTC2026!#REF! -> #REF! | AB26: =BCTC2026!#REF! -> #REF! | AC26: =BCTC2026!#REF! -> #REF! | AD26: =BCTC2026!#REF! -> #REF! | AE26: =BCTC2026!#REF! -> #REF! | AF26: =BCTC2026!#REF! -> #REF! | ... AJ26: =BCTC2026!#REF! -> #REF! | AK26: =AC26/$Q$3 -> #REF! | AL26: =AK26/AK$39 -> #REF!
B27: 3 | C27: Thuế GTGT được khấu trừ | D27: =BCTC2026!D29 -> 14900314879 | E27: =BCTC2026!E29 -> 18117486770 | F27: =BCTC2026!F29 -> 18457562435 | G27: =BCTC2026!G29 -> 18721692095 | H27: =BCTC2026!H29 -> 23467402224 | I27: =BCTC2026!I29 -> 0 | J27: =BCTC2026!J29 -> 0 | K27: =BCTC2026!K29 -> 0 | ... O27: =BCTC2026!O29 -> 0 | P27: =H27/$Q$3 -> 959811.95 | Q27: =P27/$P$39 -> #REF! | W27: 3 | X27: Phải trả nhà cung cấp | Y27: =BCTC2026!D94 -> 0 | Z27: =BCTC2026!E94 -> 0 | AA27: =BCTC2026!F94 -> 0 | AB27: =BCTC2026!G94 -> 0 | AC27: =BCTC2026!H94 -> 0 | AD27: =BCTC2026!I94 -> 0 | AE27: =BCTC2026!J94 -> 0 | AF27: =BCTC2026!K94 -> 0 | ... AJ27: =BCTC2026!O94 -> 0 | AK27: =AC27/$Q$3 -> 0 | AL27: =AK27/AK$39 -> 0
B28: 4 | C28: Trả trước cho nhà cung cấp, nhà thầu | D28: =BCTC2026!D14 -> 75878310145 | E28: =BCTC2026!E14 -> 82113512006 | F28: =BCTC2026!F14 -> 95312309944 | G28: =BCTC2026!G14 -> 77634941776 | H28: =BCTC2026!H14 -> 162931057926 | I28: =BCTC2026!I14 -> 0 | J28: =BCTC2026!J14 -> 0 | K28: =BCTC2026!K14 -> 0 | ... O28: =BCTC2026!O14 -> 0 | P28: =H28/$Q$3 -> 6663846.9 | Q28: =P28/$P$39 -> #REF! | W28: 4 | X28: Thuế phải nộp Nhà nước | Y28: =BCTC2026!#REF! -> #REF! | Z28: =BCTC2026!#REF! -> #REF! | AA28: =BCTC2026!#REF! -> #REF! | AB28: =BCTC2026!#REF! -> #REF! | AC28: =BCTC2026!#REF! -> #REF! | AD28: =BCTC2026!#REF! -> #REF! | AE28: =BCTC2026!#REF! -> #REF! | AF28: =BCTC2026!#REF! -> #REF! | ... AJ28: =BCTC2026!#REF! -> #REF! | AK28: =AC28/$Q$3 -> #REF! | AL28: =AK28/AK$39 -> #REF!
B29: 5 | C29: Tiền gửi ngân hàng | D29: =BCTC2026!D5 -> 42126572011 | E29: =BCTC2026!E5 -> 45981412915 | F29: =BCTC2026!F5 -> 33613094972 | G29: =BCTC2026!G5 -> 47135211556 | H29: =BCTC2026!H5 -> 41014004605 | I29: =BCTC2026!I5 -> 0 | J29: =BCTC2026!J5 -> 0 | K29: =BCTC2026!K5 -> 0 | ... O29: =BCTC2026!O5 -> 0 | P29: =H29/$Q$3 -> 1677464.4 | Q29: =P29/$P$39 -> #REF! | W29: 5 | X29: Phải trả người lao động | Y29: =BCTC2026!#REF! -> #REF! | Z29: =BCTC2026!#REF! -> #REF! | AA29: =BCTC2026!#REF! -> #REF! | AB29: =BCTC2026!#REF! -> #REF! | AC29: =BCTC2026!#REF! -> #REF! | AD29: =BCTC2026!#REF! -> #REF! | AE29: =BCTC2026!#REF! -> #REF! | AF29: =BCTC2026!#REF! -> #REF! | ... AJ29: =BCTC2026!#REF! -> #REF! | AK29: =AC29/$Q$3 -> #REF! | AL29: =AK29/AK$39 -> #REF!
B30: 6 | C30: Tài sản ngắn hạn khác | D30: =BCTC2026!D4-D23-SUM(D25:D29) -> #REF! | E30: =BCTC2026!E4-E23-SUM(E25:E29) -> #REF! | F30: =BCTC2026!F4-F23-SUM(F25:F29) -> #REF! | G30: =BCTC2026!G4-G23-SUM(G25:G29) -> #REF! | H30: =BCTC2026!H4-H23-SUM(H25:H29) -> #REF! | I30: =BCTC2026!I4-I23-SUM(I25:I29) -> #REF! | J30: =BCTC2026!J4-J23-SUM(J25:J29) -> #REF! | K30: =BCTC2026!K4-K23-SUM(K25:K29) -> #REF! | ... O30: =BCTC2026!O4-O23-SUM(O25:O29) -> #REF! | P30: =H30/$Q$3 -> #REF! | Q30: =P30/$P$39 -> #REF! | W30: 6 | X30: Phải trả khác | Y30: =Y24-SUM(Y25:Y29) -> #REF! | Z30: =Z24-SUM(Z25:Z29) -> #REF! | AA30: =AA24-SUM(AA25:AA29) -> #REF! | AB30: =AB24-SUM(AB25:AB29) -> #REF! | AC30: =AC24-SUM(AC25:AC29) -> #REF! | AD30: =AD24-SUM(AD25:AD29) -> #REF! | AE30: =AE24-SUM(AE25:AE29) -> #REF! | AF30: =AF24-SUM(AF25:AF29) -> #REF! | ... AJ30: =AJ24-SUM(AJ25:AJ29) -> #REF! | AK30: =AC30/$Q$3 -> #REF! | AL30: =AK30/AK$39 -> #REF!
P31: =H31/$Q$3 -> 0 | AK31: =AC31/$Q$3 -> 0
B32: B | C32: TÀI SẢN DÀI HẠN | D32: =BCTC2026!D33 -> 317415705891 | E32: =BCTC2026!E33 -> 337499929442 | F32: =BCTC2026!F33 -> 343594894451 | G32: =BCTC2026!G33 -> 365048803536 | H32: =BCTC2026!H33 -> 365314011891 | I32: =BCTC2026!I33 -> 0 | J32: =BCTC2026!J33 -> 0 | K32: =BCTC2026!K33 -> 0 | ... O32: =BCTC2026!O33 -> 0 | P32: =H32/$Q$3 -> 14941268 | Q32: =P32/$P$39 -> #REF! | W32: B | X32: VỐN CHỦ SỞ HỮU | Y32: =BCTC2026!D110 -> 878802950065 | Z32: =BCTC2026!E110 -> 872383736327 | AA32: =BCTC2026!F110 -> 865718329703 | AB32: =BCTC2026!G110 -> 869422083915 | AC32: =BCTC2026!H110 -> 877649509332 | AD32: =BCTC2026!I110 -> 0 | AE32: =BCTC2026!J110 -> 0 | AF32: =BCTC2026!K110 -> 0 | ... AJ32: =BCTC2026!O110 -> 0 | AK32: =AC32/$Q$3 -> 35895685 | AL32: =AK32/AK$39 -> 0.70105267
B33: 1 | C33: Nguyên giá máy móc, hạ tầng kỹ thuật | D33: =BCTC2026!D43-D34 -> 346257196159 | E33: =BCTC2026!E43-E34 -> 349675687977 | F33: =BCTC2026!F43-F34 -> 372614337286 | G33: =BCTC2026!G43-G34 -> 379332503103 | H33: =BCTC2026!H43-H34 -> 379507503103 | I33: =BCTC2026!I43-I34 -> 0 | J33: =BCTC2026!J43-J34 -> 0 | K33: =BCTC2026!K43-K34 -> 0 | ... O33: =BCTC2026!O43-O34 -> 0 | P33: =H33/$Q$3 -> 15521779 | Q33: =P33/$P$39 -> #REF! | W33: 1 | X33: Vốn góp của chủ sở hữu | Y33: =BCTC2026!D112 -> 650000000000 | Z33: =BCTC2026!E112 -> 650000000000 | AA33: =BCTC2026!F112 -> 650000000000 | AB33: =BCTC2026!G112 -> 650000000000 | AC33: =BCTC2026!H112 -> 650000000000 | AD33: =BCTC2026!I112 -> 0 | AE33: =BCTC2026!J112 -> 0 | AF33: =BCTC2026!K112 -> 0 | ... AJ33: =BCTC2026!O112 -> 0 | AK33: =AC33/$Q$3 -> 26584867 | AL33: =AK33/AK$39 -> 0.51920981
B34: 2 | C34: Nguyên giá nhà xưởng, kho | E34: =D34 -> 0 | F34: =E34 -> 0 | G34: =F34 -> 0 | H34: =G34 -> 0 | I34: =H34 -> 0 | J34: =I34 -> 0 | K34: =J34 -> 0 | L34: =K34 -> 0 | ... O34: =N34 -> 0 | P34: =H34/$Q$3 -> 0 | Q34: =P34/$P$39 -> #REF! | W34: 2 | X34: Quỹ đầu tư phát triển | Y34: =BCTC2026!D121 -> 0 | Z34: =BCTC2026!E121 -> 0 | AA34: =BCTC2026!F121 -> 0 | AB34: =BCTC2026!G121 -> 0 | AC34: =BCTC2026!H121 -> 0 | AD34: =BCTC2026!I121 -> 0 | AE34: =BCTC2026!J121 -> 0 | AF34: =BCTC2026!K121 -> 0 | ... AJ34: =BCTC2026!O121 -> 0 | AK34: =AC34/$Q$3 -> 0 | AL34: =AK34/AK$39 -> 0
B35: 3 | C35: Xây dựng nhà xưởng, công trình dở dang | D35: =BCTC2026!D65 -> 61387421408 | E35: =BCTC2026!E65 -> 80647695075 | F35: =BCTC2026!F65 -> 66362060607 | G35: =BCTC2026!G65 -> 83813282245 | H35: =BCTC2026!H65 -> 86222726568 | I35: =BCTC2026!I65 -> 0 | J35: =BCTC2026!J65 -> 0 | K35: =BCTC2026!K65 -> 0 | ... O35: =BCTC2026!O65 -> 0 | P35: =H35/$Q$3 -> 3526491.9 | Q35: =P35/$P$39 -> #REF! | W35: 3 | X35: Lợi nhuận sau thuế | Y35: =BCTC2026!D124 -> 230496410801 | Z35: =BCTC2026!E124 -> 228802950065 | AA35: =BCTC2026!F124 -> 222383736327 | AB35: =BCTC2026!G124 -> 215718329703 | AC35: =BCTC2026!H124 -> 219422083915 | AD35: =BCTC2026!I124 -> 0 | AE35: =BCTC2026!J124 -> 0 | AF35: =BCTC2026!K124 -> 0 | ... AJ35: =BCTC2026!O124 -> 0 | AK35: =AC35/$Q$3 -> 8974318.4 | AL35: =AK35/AK$39 -> 0.17527092
B36: 4 | C36: Nguyên giá quyền sử dụng đất | D36: =BCTC2026!D49 -> 6032562739 | E36: =BCTC2026!E49 -> 6032562739 | F36: =BCTC2026!F49 -> 6032562739 | G36: =BCTC2026!G49 -> 6032562739 | H36: =BCTC2026!H49 -> 6032562739 | I36: =BCTC2026!I49 -> 0 | J36: =BCTC2026!J49 -> 0 | K36: =BCTC2026!K49 -> 0 | ... O36: =BCTC2026!O49 -> 0 | P36: =H36/$Q$3 -> 246730.58 | Q36: =P36/$P$39 -> #REF! | AK36: =AC36/$Q$3 -> 0
B37: 5 | C37: Chi phí trả trước đang phân bổ dài hạn | D37: =BCTC2026!D73 -> 7062502744 | E37: =BCTC2026!E73 -> 6570969298 | F37: =BCTC2026!F73 -> 6131031024 | G37: =BCTC2026!G73 -> 5693514228 | H37: =BCTC2026!H73 -> 5705255817 | I37: =BCTC2026!I73 -> 0 | J37: =BCTC2026!J73 -> 0 | K37: =BCTC2026!K73 -> 0 | ... O37: =BCTC2026!O73 -> 0 | P37: =H37/$Q$3 -> 233343.8 | Q37: =P37/$P$39 -> #REF! | AK37: =AC37/$Q$3 -> 0
B38: 6 | C38: Khấu hao lũy kế | D38: =BCTC2026!D44+BCTC2026!D50 -> -126324177398 | E38: =BCTC2026!E44+BCTC2026!E50 -> -128292700599 | F38: =BCTC2026!F44+BCTC2026!F50 -> -130276326863 | G38: =BCTC2026!G44+BCTC2026!G50 -> -132419803140 | H38: =BCTC2026!H44+BCTC2026!H50 -> -134616295410 | I38: =BCTC2026!I44+BCTC2026!I50 -> 0 | J38: =BCTC2026!J44+BCTC2026!J50 -> 0 | K38: =BCTC2026!K44+BCTC2026!K50 -> 0 | ... O38: =BCTC2026!O44+BCTC2026!O50 -> 0 | P38: =H38/$Q$3 -> -5505779 | Q38: =P38/$P$39 -> #REF! | AK38: =AC38/$Q$3 -> 0
C39: TỔNG TÀI SẢN | D39: =D32+D24+D23 -> #REF! | E39: =E32+E24+E23 -> #REF! | F39: =F32+F24+F23 -> #REF! | G39: =G32+G24+G23 -> #REF! | H39: =H32+H24+H23 -> #REF! | I39: =I32+I24+I23 -> #REF! | J39: =J32+J24+J23 -> #REF! | K39: =K32+K24+K23 -> #REF! | ... O39: =O32+O24+O23 -> #REF! | P39: =H39/$Q$3 -> #REF! | Q39: =P39/$P$39 -> #REF! | X39: TỔNG NGUỒN VỐN | Y39: =Y32+Y24 -> 1211566398236 | Z39: =Z32+Z24 -> 1233002251518 | AA39: =AA32+AA24 -> 1192063370403 | AB39: =AB32+AB24 -> 1173001139790 | AC39: =AC32+AC24 -> 1251902380916 | AD39: =AD32+AD24 -> 0 | AE39: =AE32+AE24 -> 0 | AF39: =AF32+AF24 -> 0 | ... AJ39: =AJ32+AJ24 -> 0 | AK39: =AC39/$Q$3 -> 51202551 | AL39: =AK39/$AK$39 -> 1
Y40: =Y39-D39 -> #REF! | Z40: =Z39-E39 -> #REF!
AK43: Người lập
C46: Tài sản ngắn hạn | D46: =P24 -> #REF! | E46: =D46/$D$49 -> #REF!
...

Sheet BCTC2026
D1: BÁO CÁO TÀI CHÍNH NĂM 2026
S2: =MONTH(TODAY())-1 -> 5 | W2: 26000
B3: BÁO CÁO TÌNH HÌNH TÀI CHÍNH | D3: T01.2026 | E3: T02.2026 | F3: T03.2026 | G3: T04.2026 | H3: T05.2026 | I3: T06.2026 | J3: T07.2026 | K3: T08.2026 | L3: T09.2026 | M3: T10.2026 | N3: T11.2026 | O3: T12.2026 | Q3: Q01.2026 | R3: Q02.2026 | S3: Q03.2026 | T3: Q04.2026 | V3: Lũy kế năm 2026 | W3: US $ | X3: %/Tổng TS
B4: A-TÀI SẢN NGẮN HẠN | D4: =D5+D8+D12+D20+D23+D27 -> 894150692345 | E4: =E5+E8+E12+E20+E23+E27 -> 895502322076 | F4: =F5+F8+F12+F20+F23+F27 -> 848468475952 | G4: =G5+G8+G12+G20+G23+G27 -> 807952336254 | H4: =H5+H8+H12+H20+H23+H27 -> 886588369025 | Q4: =F4 -> 848468475952 | R4: =H4 -> 886588369025 | S4: =L4 -> 0 | T4: =O4 -> 0 | V4: =H4 -> 886588369025 | W4: =V4/$W$2 -> 34099553 | X4: =V4/$V$77 -> 0.70819289 | Y4: =V4-H4 -> 0 | Z4: =R4-H4 -> 0
B5: I.Tiền và các khoản tương đương tiền | D5: =SUM(D6:D7) -> 42126572011 | E5: =SUM(E6:E7) -> 45981412915 | F5: =SUM(F6:F7) -> 33613094972 | G5: =SUM(G6:G7) -> 47135211556 | H5: =SUM(H6:H7) -> 41014004605 | Q5: =F5 -> 33613094972 | R5: =H5 -> 41014004605 | S5: =L5 -> 0 | T5: =O5 -> 0 | V5: =H5 -> 41014004605 | W5: =V5/$W$2 -> 1577461.7 | X5: =V5/$V$77 -> 0.032761344 | Y5: =V5-H5 -> 0 | Z5: =R5-H5 -> 0
B6: 1.Tiền | D6: =CĐKT!D4 -> 42126572011 | E6: =CĐKT!E4 -> 45981412915 | F6: =CĐKT!F4 -> 27413094972 | G6: =CĐKT!G4 -> 28835211556 | H6: =CĐKT!H4 -> 30714004605 | Q6: =F6 -> 27413094972 | R6: =H6 -> 30714004605 | S6: =L6 -> 0 | T6: =O6 -> 0 | V6: =H6 -> 30714004605 | W6: =V6/$W$2 -> 1181307.9 | X6: =V6/$V$77 -> 0.024533865 | Y6: =V6-H6 -> 0 | Z6: =R6-H6 -> 0
B7: 2.Các khoản tương đương tiền | D7: =CĐKT!D5 -> 0 | E7: =CĐKT!E5 -> 0 | F7: =CĐKT!F5 -> 6200000000 | G7: =CĐKT!G5 -> 18300000000 | H7: =CĐKT!H5 -> 10300000000 | Q7: =F7 -> 6200000000 | R7: =H7 -> 10300000000 | S7: =L7 -> 0 | T7: =O7 -> 0 | V7: =H7 -> 10300000000 | W7: =V7/$W$2 -> 396153.85 | X7: =V7/$V$77 -> 0.0082274786 | Y7: =V7-H7 -> 0 | Z7: =R7-H7 -> 0
B8: II.Các khoản đầu tư tài chính ngắn hạn | D8: =SUM(D9:D11) -> 32840000000 | E8: =SUM(E9:E11) -> 32840000000 | F8: =SUM(F9:F11) -> 32840000000 | G8: =SUM(G9:G11) -> 34340000000 | H8: =SUM(H9:H11) -> 34340000000 | Q8: =F8 -> 32840000000 | R8: =H8 -> 34340000000 | S8: =L8 -> 0 | T8: =O8 -> 0 | V8: =H8 -> 34340000000 | W8: =V8/$W$2 -> 1320769.2 | X8: =V8/$V$77 -> 0.027430254 | Y8: =V8-H8 -> 0 | Z8: =R8-H8 -> 0
B9: 1.Chứng khoán kinh doanh | Q9: =F9 -> 0 | R9: =H9 -> 0 | S9: =L9 -> 0 | T9: =O9 -> 0 | V9: =H9 -> 0 | W9: =V9/$W$2 -> 0 | X9: =V9/$V$77 -> 0 | Y9: =V9-H9 -> 0 | Z9: =R9-H9 -> 0
B10: 2.Dự phòng giảm giá chứng khoán kinh doanh (*) | Q10: =F10 -> 0 | R10: =H10 -> 0 | S10: =L10 -> 0 | T10: =O10 -> 0 | V10: =H10 -> 0 | W10: =V10/$W$2 -> 0 | X10: =V10/$V$77 -> 0 | Y10: =V10-H10 -> 0 | Z10: =R10-H10 -> 0
B11: 3.Đầu tư nắm giữ đến ngày đáo hạn | D11: =CĐKT!D9 -> 32840000000 | E11: =CĐKT!E9 -> 32840000000 | F11: =CĐKT!F9 -> 32840000000 | G11: =CĐKT!G9 -> 34340000000 | H11: =CĐKT!H9 -> 34340000000 | Q11: =F11 -> 32840000000 | R11: =H11 -> 34340000000 | S11: =L11 -> 0 | T11: =O11 -> 0 | V11: =H11 -> 34340000000 | W11: =V11/$W$2 -> 1320769.2 | X11: =V11/$V$77 -> 0.027430254 | Y11: =V11-H11 -> 0 | Z11: =R11-H11 -> 0
B12: III.Các khoản phải thu | D12: =SUM(D13:D19) -> 263624916145 | E12: =SUM(E13:E19) -> 289980302579 | F12: =SUM(F13:F19) -> 331342767193 | G12: =SUM(G13:G19) -> 329741435832 | H12: =SUM(H13:H19) -> 417392857129 | Q12: =F12 -> 331342767193 | R12: =H12 -> 417392857129 | S12: =L12 -> 0 | T12: =O12 -> 0 | V12: =H12 -> 417392857129 | W12: =V12/$W$2 -> 16053571 | X12: =V12/$V$77 -> 0.33340687 | Y12: =V12-H12 -> 0 | Z12: =R12-H12 -> 0
B13: 1.Phải thu ngắn hạn của khách hàng | D13: =CĐKT!D11 -> 132649296167 | E13: =CĐKT!E11 -> 140446291758 | F13: =CĐKT!F11 -> 153248625708 | G13: =CĐKT!G11 -> 178191270169 | H13: =CĐKT!H11 -> 178005616424 | Q13: =F13 -> 153248625708 | R13: =H13 -> 178005616424 | S13: =L13 -> 0 | T13: =O13 -> 0 | V13: =H13 -> 178005616424 | W13: =V13/$W$2 -> 6846369.9 | X13: =V13/$V$77 -> 0.1421881 | Y13: =V13-H13 -> 0 | Z13: =R13-H13 -> 0
B14: 2.Trả trước cho người bán ngắn hạn | D14: =CĐKT!D12 -> 75878310145 | E14: =CĐKT!E12 -> 82113512006 | F14: =CĐKT!F12 -> 95312309944 | G14: =CĐKT!G12 -> 77634941776 | H14: =CĐKT!H12 -> 162931057926 | Q14: =F14 -> 95312309944 | R14: =H14 -> 162931057926 | S14: =L14 -> 0 | T14: =O14 -> 0 | V14: =H14 -> 162931057926 | W14: =V14/$W$2 -> 6266579.2 | X14: =V14/$V$77 -> 0.13014678 | Y14: =V14-H14 -> 0 | Z14: =R14-H14 -> 0
B15: 3.Phải thu nội bộ ngắn hạn | Q15: =F15 -> 0 | R15: =H15 -> 0 | S15: =L15 -> 0 | T15: =O15 -> 0 | V15: =H15 -> 0 | W15: =V15/$W$2 -> 0 | X15: =V15/$V$77 -> 0 | Y15: =V15-H15 -> 0 | Z15: =R15-H15 -> 0
B16: 4.Phải thu theo tiến độ kế hoạch hợp đồng XD | Q16: =F16 -> 0 | R16: =H16 -> 0 | S16: =L16 -> 0 | T16: =O16 -> 0 | V16: =H16 -> 0 | W16: =V16/$W$2 -> 0 | X16: =V16/$V$77 -> 0 | Y16: =V16-H16 -> 0 | Z16: =R16-H16 -> 0
B17: 5.Phải thu ngắn hạn khác | D17: =CĐKT!D15+CĐKT!D16 -> 54586491575 | E17: =CĐKT!E15+CĐKT!E16 -> 66773872669 | F17: =CĐKT!F15+CĐKT!F16 -> 82135205395 | G17: =CĐKT!G15+CĐKT!G16 -> 73268597741 | H17: =CĐKT!H15+CĐKT!H16 -> 76382324781 | Q17: =F17 -> 82135205395 | R17: =H17 -> 76382324781 | S17: =L17 -> 0 | T17: =O17 -> 0 | V17: =H17 -> 76382324781 | W17: =V17/$W$2 -> 2937781.7 | X17: =V17/$V$77 -> 0.061013004 | Y17: =V17-H17 -> 0 | Z17: =R17-H17 -> 0
B18: 6.Dự phòng phải thu ngắn hạn khó đòi(*) | D18: =CĐKT!D17 -> -609095700 | E18: =CĐKT!E17 -> -609095700 | F18: =CĐKT!F17 -> -609095700 | G18: =CĐKT!G17 -> -609095700 | H18: =CĐKT!H17 -> -609095700 | Q18: =F18 -> -609095700 | R18: =H18 -> -609095700 | S18: =L18 -> 0 | T18: =O18 -> 0 | V18: =H18 -> -609095700 | W18: =V18/$W$2 -> -23426.758 | X18: =V18/$V$77 -> -0.0004865361 | Y18: =V18-H18 -> 0 | Z18: =R18-H18 -> 0
B19: 7.Tài sản thiếu chờ xử lý | D19: =CĐKT!D18 -> 1119913958 | E19: =CĐKT!E18 -> 1255721846 | F19: =CĐKT!F18 -> 1255721846 | G19: =CĐKT!G18 -> 1255721846 | H19: =CĐKT!H18 -> 682953698 | Q19: =F19 -> 1255721846 | R19: =H19 -> 682953698 | S19: =L19 -> 0 | T19: =O19 -> 0 | V19: =H19 -> 682953698 | W19: =V19/$W$2 -> 26267.45 | X19: =V19/$V$77 -> 0.00054553271 | Y19: =V19-H19 -> 0 | Z19: =R19-H19 -> 0
B20: IV. Hàng tồn kho | D20: =SUM(D21:D22) -> 534105826237 | E20: =SUM(E21:E22) -> 502545827363 | F20: =SUM(F21:F22) -> 425450972162 | G20: =SUM(G21:G22) -> 370413533224 | H20: =SUM(H21:H22) -> 361880765551 | Q20: =F20 -> 425450972162 | R20: =H20 -> 361880765551 | S20: =L20 -> 0 | T20: =O20 -> 0 | V20: =H20 -> 361880765551 | W20: =V20/$W$2 -> 13918491 | X20: =V20/$V$77 -> 0.28906468 | Y20: =V20-H20 -> 0 | Z20: =R20-H20 -> 0
B21: 1.Hàng tồn kho | D21: =CĐKT!D20 -> 534105826237 | E21: =CĐKT!E20 -> 502545827363 | F21: =CĐKT!F20 -> 425450972162 | G21: =CĐKT!G20 -> 370413533224 | H21: =CĐKT!H20 -> 361880765551 | Q21: =F21 -> 425450972162 | R21: =H21 -> 361880765551 | S21: =L21 -> 0 | T21: =O21 -> 0 | V21: =H21 -> 361880765551 | W21: =V21/$W$2 -> 13918491 | X21: =V21/$V$77 -> 0.28906468 | Y21: =V21-H21 -> 0 | Z21: =R21-H21 -> 0
B22: 2.Dự phòng giảm giá hàng tồn kho (*) | Q22: =F22 -> 0 | R22: =H22 -> 0 | S22: =L22 -> 0 | T22: =O22 -> 0 | V22: =H22 -> 0 | W22: =V22/$W$2 -> 0 | X22: =V22/$V$77 -> 0 | Y22: =V22-H22 -> 0 | Z22: =R22-H22 -> 0
B23: V. Tài sản sinh học ngắn hạn | D23: =SUM(D24:D26) -> 0 | E23: =SUM(E24:E26) -> 0 | F23: =SUM(F24:F26) -> 0 | G23: =SUM(G24:G26) -> 0 | Q23: =F23 -> 0 | R23: =H23 -> 0 | V23: =H23 -> 0 | X23: =V23/$V$77 -> 0 | Y23: =V23-H23 -> 0 | Z23: =R23-H23 -> 0
B24: 1.Súc vật nuôi lấy sản phẩm một lần ngắn hạn | Q24: =F24 -> 0 | R24: =H24 -> 0 | V24: =H24 -> 0 | X24: =V24/$V$77 -> 0 | Y24: =V24-H24 -> 0 | Z24: =R24-H24 -> 0
B25: 2.Cây trồng theo mùa vụ hoặc lấy sản phẩm một lần ngắn hạn | Q25: =F25 -> 0 | R25: =H25 -> 0 | V25: =H25 -> 0 | X25: =V25/$V$77 -> 0 | Y25: =V25-H25 -> 0 | Z25: =R25-H25 -> 0
B26: 3.Dự phòng tổn thất tài sản sinh học ngắn hạn (*) | Q26: =F26 -> 0 | R26: =H26 -> 0 | V26: =H26 -> 0 | X26: =V26/$V$77 -> 0 | Y26: =V26-H26 -> 0 | Z26: =R26-H26 -> 0
B27: VI. Tài sản ngắn hạn khác | D27: =SUM(D28:D32) -> 21453377952 | E27: =SUM(E28:E32) -> 24154779219 | F27: =SUM(F28:F32) -> 25221641625 | G27: =SUM(G28:G32) -> 26322155642 | H27: =SUM(H28:H32) -> 31960741740 | Q27: =F27 -> 25221641625 | R27: =H27 -> 31960741740 | S27: =L27 -> 0 | T27: =O27 -> 0 | V27: =H27 -> 31960741740 | W27: =V27/$W$2 -> 1229259.3 | X27: =V27/$V$77 -> 0.02552974 | Y27: =V27-H27 -> 0 | Z27: =R27-H27 -> 0
B28: 1.Chi phí chờ phân bổ ngắn hạn | D28: =CĐKT!D23 -> 6232956370 | E28: =CĐKT!E23 -> 5669668845 | F28: =CĐKT!F23 -> 6281586071 | G28: =CĐKT!G23 -> 7111878966 | H28: =CĐKT!H23 -> 7978130611 | Q28: =F28 -> 6281586071 | R28: =H28 -> 7978130611 | S28: =L28 -> 0 | T28: =O28 -> 0 | V28: =H28 -> 7978130611 | W28: =V28/$W$2 -> 306851.18 | X28: =V28/$V$77 -> 0.0063728057 | Y28: =V28-H28 -> 0 | Z28: =R28-H28 -> 0
B29: 2.Thuế GTGT được khấu trừ | D29: =CĐKT!D24 -> 14900314879 | E29: =CĐKT!E24 -> 18117486770 | F29: =CĐKT!F24 -> 18457562435 | G29: =CĐKT!G24 -> 18721692095 | H29: =CĐKT!H24 -> 23467402224 | Q29: =F29 -> 18457562435 | R29: =H29 -> 23467402224 | S29: =L29 -> 0 | T29: =O29 -> 0 | V29: =H29 -> 23467402224 | W29: =V29/$W$2 -> 902592.39 | X29: =V29/$V$77 -> 0.018745393 | Y29: =V29-H29 -> 0 | Z29: =R29-H29 -> 0
B30: 3.Thuế và các khoản khác phải thu Nhà nước | D30: =CĐKT!D25 -> 320106703 | E30: =CĐKT!E25 -> 367623604 | F30: =CĐKT!F25 -> 482493119 | G30: =CĐKT!G25 -> 488584581 | H30: =CĐKT!H25 -> 515208905 | Q30: =F30 -> 482493119 | R30: =H30 -> 515208905 | S30: =L30 -> 0 | T30: =O30 -> 0 | V30: =H30 -> 515208905 | W30: =V30/$W$2 -> 19815.727 | X30: =V30/$V$77 -> 0.0004115408 | Y30: =V30-H30 -> 0 | Z30: =R30-H30 -> 0
B31: 4.Giao dịch mua bán lại trái phiếu Nhà nước | Q31: =F31 -> 0 | R31: =H31 -> 0 | S31: =L31 -> 0 | T31: =O31 -> 0 | V31: =H31 -> 0 | W31: =V31/$W$2 -> 0 | X31: =V31/$V$77 -> 0 | Y31: =V31-H31 -> 0 | Z31: =R31-H31 -> 0
B32: 5.Tài sản ngắn hạn khác | Q32: =F32 -> 0 | R32: =H32 -> 0 | S32: =L32 -> 0 | T32: =O32 -> 0 | V32: =H32 -> 0 | W32: =V32/$W$2 -> 0 | X32: =V32/$V$77 -> 0 | Y32: =V32-H32 -> 0 | Z32: =R32-H32 -> 0
B33: B-TÀI SẢN DÀI HẠN | D33: =D34+D41+D51+D60+D63+D66+D72 -> 317415705891 | E33: =E34+E41+E51+E60+E63+E66+E72 -> 337499929442 | F33: =F34+F41+F51+F60+F63+F66+F72 -> 343594894451 | G33: =G34+G41+G51+G60+G63+G66+G72 -> 365048803536 | H33: =H34+H41+H51+H60+H63+H66+H72 -> 365314011891 | Q33: =F33 -> 343594894451 | R33: =H33 -> 365314011891 | S33: =L33 -> 0 | T33: =O33 -> 0 | V33: =H33 -> 365314011891 | W33: =V33/$W$2 -> 14050539 | X33: =V33/$V$77 -> 0.29180711 | Y33: =V33-H33 -> 0 | Z33: =R33-H33 -> 0
B34: I- Các khoản phải thu dài hạn | D34: =SUM(D35:D40) -> 5315314211 | E34: =SUM(E35:E40) -> 5315314211 | F34: =SUM(F35:F40) -> 5315314211 | G34: =SUM(G35:G40) -> 5315314210 | H34: =SUM(H35:H40) -> 5315314210 | Q34: =F34 -> 5315314211 | R34: =H34 -> 5315314210 | S34: =L34 -> 0 | T34: =O34 -> 0 | V34: =H34 -> 5315314210 | W34: =V34/$W$2 -> 204435.16 | X34: =V34/$V$77 -> 0.0042457897 | Y34: =V34-H34 -> 0 | Z34: =R34-H34 -> 0
B35: 1.Phải thu dài hạn của khách hàng | Q35: =F35 -> 0 | R35: =H35 -> 0 | S35: =L35 -> 0 | T35: =O35 -> 0 | V35: =H35 -> 0 | W35: =V35/$W$2 -> 0 | X35: =V35/$V$77 -> 0 | Y35: =V35-H35 -> 0 | Z35: =R35-H35 -> 0
B36: 2.Trả trước cho người bán dài hạn | Q36: =F36 -> 0 | R36: =H36 -> 0 | S36: =L36 -> 0 | T36: =O36 -> 0 | V36: =H36 -> 0 | W36: =V36/$W$2 -> 0 | X36: =V36/$V$77 -> 0 | Y36: =V36-H36 -> 0 | Z36: =R36-H36 -> 0
B37: 3.Vốn kinh doanh ở đơn vị trực thuộc | Q37: =F37 -> 0 | R37: =H37 -> 0 | S37: =L37 -> 0 | T37: =O37 -> 0 | V37: =H37 -> 0 | W37: =V37/$W$2 -> 0 | X37: =V37/$V$77 -> 0 | Y37: =V37-H37 -> 0 | Z37: =R37-H37 -> 0
B38: 4.Phải thu nội bộ dài hạn | Q38: =F38 -> 0 | R38: =H38 -> 0 | S38: =L38 -> 0 | T38: =O38 -> 0 | V38: =H38 -> 0 | W38: =V38/$W$2 -> 0 | X38: =V38/$V$77 -> 0 | Y38: =V38-H38 -> 0 | Z38: =R38-H38 -> 0
B39: 5.Phải thu dài hạn khác | D39: =CĐKT!D35 -> 5315314211 | E39: =CĐKT!E35 -> 5315314211 | F39: =CĐKT!F35 -> 5315314211 | G39: =CĐKT!G35 -> 5315314210 | H39: =CĐKT!H35 -> 5315314210 | Q39: =F39 -> 5315314211 | R39: =H39 -> 5315314210 | S39: =L39 -> 0 | T39: =O39 -> 0 | V39: =H39 -> 5315314210 | W39: =V39/$W$2 -> 204435.16 | X39: =V39/$V$77 -> 0.0042457897 | Y39: =V39-H39 -> 0 | Z39: =R39-H39 -> 0
B40: 6.Dự phòng phải thu dài hạn khó đòi (*) | Q40: =F40 -> 0 | R40: =H40 -> 0 | S40: =L40 -> 0 | T40: =O40 -> 0 | V40: =H40 -> 0 | W40: =V40/$W$2 -> 0 | X40: =V40/$V$77 -> 0 | Y40: =V40-H40 -> 0 | Z40: =R40-H40 -> 0
...

Sheet Tình hình tài chính
B1: CTY CP NHỰA TÁI CHẾ DUY TÂN
B2: VND
A3: Index BS | B3: PHẦN I-BÁO CÁO TÌNH HÌNH TÀI CHÍNH | C3: TenCongTyID | D3: T1.2021 | E3: T02.2021 | F3: T03.2021 | G3: T04.2021 | H3: T05.2021 | I3: T06.2021 | J3: T07.2021 | K3: T08.2021 | L3: T09.2021 | M3: T10.2021 | N3: T11.2021 | O3: T12.2021 | P3: T1.2022 | Q3: T02.2022 | R3: T03.2022 | S3: T04.2022 | T3: T05.2022 | U3: T06.2022 | V3: T07.2022 | W3: T08.2022 | X3: T09.2022 | Y3: T10.2022 | Z3: T11.2022 | AA3: T12.2022 | AB3: T1.2023 | AC3: T02.2023 | AD3: T03.2023 | AE3: T04.2023 | AF3: T05.2023 | AG3: T06.2023 | AH3: T07.2023 | AI3: T08.2023 | AJ3: T09.2023 | AK3: T10.2023 | AL3: T11.2023 | AM3: T12.2023 | AN3: T01.2024 | AO3: T02.2024 | AP3: T03.2024 | AQ3: T04.2024 | AR3: T05.2024 | AS3: T06.2024 | AT3: T07.2024 | AU3: T08.2024 | AV3: T09.2024 | AW3: T10.2024 | AX3: T11.2024 | AY3: T12.2024 | AZ3: T01.2025 | BA3: T02.2025 | BB3: T03.2025 | BC3: T04.2025 | BD3: T05.2025 | BE3: T06.2025 | BF3: T07.2025 | BG3: T08.2025 | BH3: T09.2025 | BI3: T10.2025 | BJ3: T11.2025 | BK3: T12.2025 | BL3: T01.2026 | BM3: T02.2026 | BN3: T03.2026 | BO3: T04.2026 | BP3: T05.2026 | BQ3: T06.2026 | BR3: T07.2026 | BS3: T08.2026 | BT3: T09.2026 | BU3: T10.2026 | BV3: T11.2026 | BW3: T12.2026
A4: 1 | B4: A-TÀI SẢN NGẮN HẠN | C4: 5 | D4: 614299663363 | E4: 609691312919 | F4: 615298026209 | G4: 628174770356 | H4: 633634093227 | I4: 634442148116 | J4: 641465222117 | K4: 461269303491 | L4: 464335451361 | M4: 465446434421 | N4: 474566713935 | O4: 483715466637 | P4: 491203268636 | Q4: 495110335063 | R4: 506410020272 | S4: 541090328555 | T4: 557182730957 | U4: 567579171386 | V4: 553380198104 | W4: 575629704487 | X4: 581428641960 | Y4: 579326744202 | Z4: 570154808236 | AA4: 646788980449 | AB4: 630392907077 | AC4: 635811337862 | AD4: 615592156470 | AE4: 589633117559 | AF4: 574650354873 | AG4: 627637203928 | AH4: 645144940465 | AI4: 624618100412 | AJ4: 607904625059 | AK4: 655561441656 | AL4: 691663318215 | AM4: 723466020980 | AN4: 782481934423 | AO4: 768590764263 | AP4: 815465869041 | AQ4: 877414026420 | AR4: 928155716736 | AS4: 956563222023 | AT4: 906133879099 | AU4: 849218290026 | AV4: 891170346476 | AW4: 912165489717 | AX4: 989601612249 | AY4: 969587265880 | AZ4: 894788032291 | BA4: 814157821775 | BB4: 866303373135 | BC4: 929599762285 | BD4: 981599372849 | BE4: 1010794698754 | BF4: 999811801439 | BG4: 1060333071975 | BH4: 1040577598634 | BI4: 982848510813 | BJ4: 959373053576 | BK4: 953625133537 | BL4: 897731457175
A5: 2 | B5: I.Tiền và các khoản tương đương tiền | C5: 5 | D5: 3447839862 | E5: 4753297265 | F5: 3470025524 | G5: 7213551570 | H5: 6428796497 | I5: 6637859615 | J5: 6692002174 | K5: 17171442096 | L5: 20706415997 | M5: 18510700926 | N5: 9217053448 | O5: 9537238483 | P5: 7841551973 | Q5: 25742652312 | R5: 10229505276 | S5: 23153084677 | T5: 15475133505 | U5: 6070662597 | V5: 5025380377 | W5: 25956322209 | X5: 31102397335 | Y5: 12848278176 | Z5: 10250965252 | AA5: 13274374142 | AB5: 16792099757 | AC5: 15908187368 | AD5: 16078630986 | AE5: 51289665216 | AF5: 23427390962 | AG5: 21288636707 | AH5: 22472091319 | AI5: 2490582158 | AJ5: 10148364108 | AK5: 9841817259 | AL5: 4968558361 | AM5: 6353042534 | AN5: 31037848308 | AO5: 22669663716 | AP5: 6664945115 | AQ5: 15574807889 | AR5: 16007340290 | AS5: 3678057757 | AT5: 36916493026 | AU5: 16748498285 | AV5: 33251814637 | AW5: 56773964959 | AX5: 43420355696 | AY5: 39805017284 | AZ5: 76486895109 | BA5: 33258200889 | BB5: 23555271373 | BC5: 37590058839 | BD5: 21868727527 | BE5: 32470900772 | BF5: 30661632458 | BG5: 29770776625 | BH5: 64296693910 | BI5: 53646701293 | BJ5: 55165406320 | BK5: 36834893155 | BL5: 42126572011
A6: 3 | B6: 1.Tiền | C6: 5 | D6: 3447839862 | E6: 4753297265 | F6: 3470025524 | G6: 7213551570 | H6: 6428796497 | I6: 6637859615 | J6: 6692002174 | K6: 4471442096 | L6: 5006415997 | M6: 5810700926 | N6: 9217053448 | O6: 9537238483 | P6: 7841551973 | Q6: 25742652312 | R6: 10229505276 | S6: 23153084677 | T6: 15475133505 | U6: 6070662597 | V6: 5025380377 | W6: 25956322209 | X6: 31102397335 | Y6: 12848278176 | Z6: 10250965252 | AA6: 13274374142 | AB6: 16792099757 | AC6: 15908187368 | AD6: 16078630986 | AE6: 36289665216 | AF6: 23427390962 | AG6: 21288636707 | AH6: 22472091319 | AI6: 2490582158 | AJ6: 10148364108 | AK6: 7001817259 | AL6: 2128558361 | AM6: 3513042534 | AN6: 28197848308 | AO6: 19829663716 | AP6: 5834945115 | AQ6: 14744807889 | AR6: 15177340290 | AS6: 2848057757 | AT6: 36086493026 | AU6: 15918498285 | AV6: 33251814637 | AW6: 56773964959 | AX6: 43420355696 | AY6: 29805017284 | AZ6: 73646895109 | BA6: 30418200889 | BB6: 23555271373 | BC6: 37590058839 | BD6: 21868727527 | BE6: 32470900772 | BF6: 30661632458 | BG6: 29770776625 | BH6: 64296693910 | BI6: 33646701293 | BJ6: 35165406320 | BK6: 36834893155 | BL6: 42126572011
A7: 4 | B7: 2.Các khoản tương đương tiền | C7: 5 | K7: 12700000000 | L7: 15700000000 | M7: 12700000000 | P7: 0 | Q7: 0 | R7: 0 | S7: 0 | T7: 0 | W7: 0 | X7: 0 | Y7: 0 | AA7: 0 | AE7: 15000000000 | AG7: 0 | AH7: 0 | AJ7: 0 | AK7: 2840000000 | AL7: 2840000000 | AM7: 2840000000 | AN7: 2840000000 | AO7: 2840000000 | AP7: 830000000 | AQ7: 830000000 | AR7: 830000000 | AS7: 830000000 | AT7: 830000000 | AU7: 830000000 | AV7: 0 | AW7: 0 | AX7: 0 | AY7: 10000000000 | AZ7: 2840000000 | BA7: 2840000000 | BB7: 0 | BC7: 0 | BD7: 0 | BE7: 0 | BF7: 0 | BG7: 0 | BH7: 0 | BI7: 20000000000 | BJ7: 20000000000
A8: 5 | B8: II.Đầu tư tài chính ngắn hạn | C8: 5 | D8: 1000000000 | E8: 550000000000 | F8: 550000000000 | G8: 545000000000 | H8: 545000000000 | I8: 545000000000 | J8: 545000000000 | K8: 348000000000 | L8: 347009021921 | M8: 340009021921 | N8: 340009021921 | O8: 322972364387 | P8: 305609021921 | Q8: 285609021921 | R8: 285609021921 | S8: 265812329757 | T8: 227609021921 | U8: 227609021921 | V8: 215609021921 | W8: 215609021921 | X8: 215609021921 | Y8: 215609021921 | Z8: 185609021921 | AA8: 5609021921 | AB8: 5609021921 | AC8: 5609021921 | AD8: 195619021921 | AE8: 157619021921 | AF8: 157619021921 | AG8: 157619021921 | AH8: 157619021921 | AI8: 157619021921 | AJ8: 157619021921 | AK8: 157619021921 | AL8: 157619021921 | AM8: 137869021921 | AN8: 107849581921 | AO8: 107839861921 | AP8: 107830141921 | AQ8: 97320421921 | AR8: 97310701921 | AS8: 77300981921 | AT8: 57791261921 | AU8: 57781541921 | AV8: 58611541921 | AW8: 58592101921 | AX8: 98592101921 | AY8: 78572661921 | AZ8: 75713221921 | BA8: 61213221921 | BB8: 101053221921 | BC8: 125553221921 | BD8: 135524061921 | BE8: 135504621921 | BF8: 120504621921 | BG8: 120699021921 | BH8: 108699021921 | BI8: 88699021921 | BJ8: 78699021921 | BK8: 73699021921 | BL8: 32840000000
A9: 6 | B9: 1.Chứng khoán kinh doanh | C9: 5 | D9: 0 | E9: 0 | F9: 0 | G9: 0 | H9: 0 | I9: 0 | J9: 0 | K9: 0 | L9: 0 | M9: 0 | N9: 0 | O9: 0 | P9: 0 | Q9: 0 | R9: 0 | S9: 0 | T9: 0 | W9: 0 | X9: 0 | Y9: 0 | AA9: 0 | AG9: 0 | AH9: 0 | AJ9: 0 | AN9: 0 | AO9: 0 | AP9: 0 | AQ9: 0 | AR9: 0 | AS9: 0 | AT9: 0 | AU9: 0 | AV9: 0 | AW9: 0 | AX9: 0 | AY9: 0 | AZ9: 0 | BA9: 0 | BB9: 0 | BC9: 0 | BD9: 0 | BE9: 0 | BF9: 0 | BG9: 0 | BH9: 0 | BI9: 0 | BJ9: 0
A10: 7 | B10: 2.Dự phòng giảm giá chứng khoán kinh doanh (*) | C10: 5 | D10: 0 | E10: 0 | F10: 0 | G10: 0 | H10: 0 | I10: 0 | J10: 0 | K10: 0 | L10: 0 | M10: 0 | N10: 0 | O10: 0 | P10: 0 | Q10: 0 | R10: 0 | S10: 0 | T10: 0 | W10: 0 | X10: 0 | Y10: 0 | AA10: 0 | AG10: 0 | AH10: 0 | AJ10: 0 | AN10: 0 | AO10: 0 | AP10: 0 | AQ10: 0 | AR10: 0 | AS10: 0 | AT10: 0 | AU10: 0 | AV10: 0 | AW10: 0 | AX10: 0 | AY10: 0 | AZ10: 0 | BA10: 0 | BB10: 0 | BC10: 0 | BD10: 0 | BE10: 0 | BF10: 0 | BG10: 0 | BH10: 0 | BI10: 0 | BJ10: 0
