Workbook
Name \T: #REF!
Name \T: #REF!
Name __dao1: '[1]CT Thang Mo'!$B$189:$H$189
Name __dao1: #REF!
Name __dao2: '[1]CT Thang Mo'!$B$161:$H$161
Name __dao2: #REF!
Name __dap2: '[1]CT Thang Mo'!$B$162:$H$162
Name __dap2: #REF!
Name __day1: '[2]Chiet tinh dz22'!#REF!
Name __day1: #REF!
Name __day2: '[3]Chiet tinh dz35'!$H$3
Name __day2: #REF!
Name __dbu1: '[1]CT Thang Mo'!#REF!
Name __dbu1: #REF!
Name __dbu2: '[1]CT Thang Mo'!$B$93:$F$93
Name __dbu2: #REF!
Name __doi3: '[4]truc tiep'!#REF!
Name __doi3: #REF!
Name __E99999: #REF!
Name __E99999: #REF!
Name __Jan02: '[5]FG waste'!#REF!
Name __Jan02: #REF!
Name __lap1: #REF!
Name __lap1: #REF!
Name __lap2: #REF!
Name __lap2: #REF!
Name __vc1: '[1]CT Thang Mo'!$B$34:$H$34
Name __vc1: #REF!
Name __vc2: '[1]CT Thang Mo'!$B$35:$H$35
Name __vc2: #REF!
Name __vc3: '[1]CT Thang Mo'!$B$36:$H$36
Name __vc3: #REF!
Name _01_01_99: #REF!
Name _01_01_99: #REF!
Name _01_02_99: #REF!
Name _01_02_99: #REF!
Name _01_03_99: #REF!
Name _01_03_99: #REF!
Name _01_04_99: #REF!
Name _01_05_99: #REF!
Name _01_06_99: #REF!
Name _01_07_99: #REF!
Name _01_08_1999: #REF!
Name _1CAP002: [6]MTP!#REF!
Name _1CAP002: #REF!
Name _2STREO7: [7]MTP!#REF!
Name _2STREO7: #REF!
Name _4GOIC01: [8]MTP!#REF!
Name _4GOIC01: #REF!
Name _4OSLCTT: [8]MTP!#REF!
Name _4OSLCTT: #REF!
Name _6BNTTTH: [7]MTP1!#REF!
Name _6BNTTTH: #REF!
Name _6DCTTBO: [7]MTP1!#REF!
Name _6DCTTBO: #REF!
Name _6DD24TT: [7]MTP1!#REF!
Name _6DD24TT: #REF!
Name _6FCOTBU: [7]MTP1!#REF!
Name _6FCOTBU: #REF!
Name _6LATUBU: [7]MTP1!#REF!

Sheet Điểm HV
B1: ĐIỂM HÒA VỐN
B3: rPET
C4: 1 | D4: =+C4+1 -> 2 | E4: =+D4+1 -> 3 | F4: =+E4+1 -> 4 | G4: =+F4+1 -> 5 | H4: =+G4+1 -> 6 | I4: =+H4+1 -> 7 | J4: =+I4+1 -> 8 | K4: =+J4+1 -> 9 | ... N4: =+M4+1 -> 12
B5: Từ chai nâng IV 8h | I5: 1203.2323 | J5: 1151.982 | K5: 1223.9359
B6: Từ chai nâng IV 10h | I6: 1239.4846 | J6: 1189.7421 | K6: 1267.6178
B7: Từ vảy nâng IV 8h | I7: 1162.0307 | J7: 1122.3796 | K7: 1163.5415
B8: Từ vảy nâng IV 10h | I8: 1198.283 | J8: 1160.1396 | K8: 1207.2233
B9: Hỗn hợp nâng IV 8h | I9: 1174.3911 | J9: 1131.2603 | K9: 1181.6598
B10: Hỗn hợp nâng IV 10h | I10: 1210.6435 | J10: 1169.0204 | K10: 1225.3417
B11: ISS01L | I11: 841 | J11: 841.18977 | K11: 864.64189
B15: rHDPE - PP
B16: Mã | C16: 1 | D16: 2 | E16: 3 | F16: 4 | G16: 5 | H16: 6 | I16: 7 | J16: 8 | K16: 9 | L16: 10 | M16: 11 | N16: 12
B17: MBF01 | C17: 1323 | D17: 1323 | E17: 1306 | F17: 1291 | G17: 1282 | H17: 1285 | I17: 1219 | J17: 1250.8124 | K17: 1250.9881
B18: HDPE MÀU | I18: 1099 | J18: 1129.5585 | K18: 1149.338
B19: HDPE Trắng sữa | I19: 1175 | J19: 1207.612 | K19: 1236.1786
B20: HDPE ép | I20: 867 | J20: 895.79014 | K20: 917.19481
B21: HDB03N03 | I21: 981.27765 | J21: 1003.4092 | K21: 993.90865
A22: (80% PS hạt HD thổi lẫn màu/kim loại) | B22: HDB04B01 | I22: 841 | J22: 849.89875 | K22: 853.99116
B23: HDI3Gy02 | J23: 619.75066 | K23: 629.83101
B24: Vảy HDPE ép | I24: 656 | J24: 661.16027 | K24: 664.29737
B25: Hạt PP bình quân | I25: 794 | J25: 836.80122 | K25: 856.1642
B26: PP20B01 | J26: 539.72607 | K26: 553.59194
B27: Vảy PP | I27: 738 | J27: 780.1665 | K27: 790.84737
B28: Hạt PP trắng sữa | I28: 888 | J28: 934.75986 | K28: 951.07154
B31: Xơ sợi
B32: Mã | C32: 1 | D32: =+C32+1 -> 2 | E32: =+D32+1 -> 3 | F32: =+E32+1 -> 4 | G32: =+F32+1 -> 5 | H32: =+G32+1 -> 6 | I32: =+H32+1 -> 7 | J32: =+I32+1 -> 8 | K32: =+J32+1 -> 9 | ... N32: =+M32+1 -> 12 | O32: Ghi chú
B33: WSS03SD | I33: 773.26795 | J33: 822.8214 | K33: 823.20219
B34: WSS04SD | I34: 679.34955 | J34: 728.903 | K34: 729.28379
B35: WSS04SB | I35: 613.70971 | J35: 663.26316 | K35: 663.64395
B36: WSS05SB (100% B6) | I36: 960.02539 | J36: 1005.1878 | K36: 1008.4543
B37: WSS05SB (70%B6+30%bụi) | I37: 790.60544 | J37: 840.46209 | K37: 842.58346
B38: WSS05SB (90%B8+10%B6) | I38: 731.72318 | J38: 775.18849 | K38: 779.7997
B39: WSS05SB-2 (90%B8+10%B7) | I39: 696.07927 | J39: 738.78127 | K39: 744.16977 | O39: Từ T8 hết nguyên liệu B8
B40: WSS05SB-2 (82%B8+18%B7) | I40: 687.85767 | J40: 730.09988 | K40: 735.99068 | O40: Từ T8 hết nguyên liệu B8
B41: WSS05SB-2 (82%B6+18%B7) | J41: 940 | K41: 944.32043 | O41: Từ T8 dùng nguyên liệu B6
B42: WSS05SB-3 (90%B8+10%B5) | I42: 719.17936 | J42: 761.92334 | K42: 761.38778 | O42: Từ T8 hết nguyên liệu B8
B43: WSS05SB-3 (90%B6+10%B5) | J43: 991.92267 | K43: 990.04238 | O43: Từ T8 dùng nguyên liệu B6
B44: WSS05SB-3 (100% Tomra) | I44: 501.3922 | J44: 562.20204 | K44: 562.67084 | O44: Từ T8 hết nguyên liệu Tomra
B45: WSS006SP-1 (vảy zigzag sau lựa) | I45: 395.2922 | J45: 456.10204 | K45: 455.55149 | O45: Từ T8 hết nguyên liệu Zigzag
B46: WSS006SP-1 (vảy PET tuyển nổi 2) | J46: 562.20204 | K46: 562.67084 | O46: Từ T8 dùng nguyên liệu vảy PET tuyển nổi 2
...

Sheet 1. rPET
D1: GIÁ BÁN HẠT rPET - THÁNG …. NĂM ….. HỖ TRỢ PHÁT TRIỂN KHÁCH HÀNG MỚI | O1: TC-TCH-01/ BM01
O2: V0 -
B3: STT | C3: Mã sản phẩm | D3: Sản phẩm | E3: Mức IV | F3: Giá xuất xưởng DTR (USD/tấn) | P3: Chênh lệch Giá tháng …. vs chính phẩm (….. $/ tấn)
F4: ='2. rPET- nội bộ '!F4 -> Tháng …. (đã duyệt) | J4: ='2. rPET- nội bộ '!J4 -> Tháng …. | N4: ='2. rPET- nội bộ '!N4 -> Chênh lệch tháng …. vs tháng ….
F5: Giá Bán (1) | G5: % Chiết khấu (2) | H5: Chiết Khấu (3) | I5: Giá bán sau chiết khấu (4)=(1)-(3) | J5: Giá Bán (1) | K5: % Chiết khấu (2) | L5: Chiết Khấu (3) | M5: Giá bán sau chiết khấu (4)=(1)-(3) | N5: $ | O5: % | P5: $ | Q5: %
C6: NHÓM KHÁCH HÀNG PHÁT TRIỂN BỀN VỮNG
B7: 1 | C7: 110000354 | D7: Hạt rPET WSS01G | E7: 0.78
B8: =B7+1 -> 2 | C8: 110000381 | D8: Hạt nhựa rPET WSS03SD, WSS04SD (xơ sợi) | E8: 0.63
B9: =B8+1 -> 3 | C9: 110000436 | D9: Hạt nhựa rPET WSS05SB (xơ sợi) | E9: 0.55
B11: Lưu ý:
B12: 1. Giá FOB = Giá xuất xưởng (EXW) + USD 20/tấn | G12: 20
B13: 2. Hạt sơ sợi: giá bán 1.100 usd/tấn, chào khách để bán được hàng là +/- 55usd/tấn
B14: 3. Ủy quyền cho GĐĐH duyệt theo đơn đặt hàng: biên độ +/-10% so với giá xuất xưởng DTR
B15: 4. Bảng giá áp dụng cho việc phát triển khách hàng mới, lưu hành nội bộ
O16: ='2. rPET- nội bộ '!O35 -> Ngày …. tháng ….. năm …....
B17: Chủ Tịch | D17: Giám Đốc Tài Chính | G17: Giám Đốc Điều Hành | L17: Giám Đốc Kinh Doanh | P17: Kế Toán

Sheet 2. rPET- nội bộ 
D1: GIÁ BÁN HẠT rPET - THÁNG …. NĂM ….. HỖ TRỢ PHÁT TRIỂN KHÁCH HÀNG MỚI | O1: TC-TCH-01/ BM02
O2: V0 -
B3: STT | C3: Mã sản phẩm | D3: Sản phẩm | E3: Mức IV | F3: Giá xuất xưởng DTR (USD/tấn) | P3: Chênh lệch Giá tháng …. vs chính phẩm (….. $/tấn)
F4: Tháng …. (đã duyệt) | J4: Tháng …. | N4: Chênh lệch tháng …. vs tháng ….
F5: Giá Bán (1) | G5: % Chiết khấu (2) | H5: Chiết Khấu (3) | I5: Giá bán sau chiết khấu (4)=(1)-(3) | J5: Giá Bán (1) | K5: % Chiết khấu (2) | L5: Chiết Khấu (3) | M5: Giá bán sau chiết khấu (4)=(1)-(3) | N5: $ | O5: % | P5: $ | Q5: %
B6: 1 | C6: 110000332 | D6: Hạt rPET ISS084G | E6: 0.84
B7: =+B6+1 -> 2 | C7: 110000330 | D7: Hạt rPET ISS01 | E7: 0.80
B8: =+B7+1 -> 3 | C8: 110000355 | D8: Hạt rPET ISS01G | E8: 0.80
B9: =+B8+1 -> 4 | C9: 110000378 | D9: Hạt nhựa rPET iSS01G 2 | E9: 0.80
B10: =+B9+1 -> 5 | C10: 110000354 | D10: Hạt rPET WSS01G | E10: 0.78
B11: =+B10+1 -> 6 | C11: 110000377 | D11: Hạt nhựa rPET WSS01G 2 | E11: 0.78
B12: =+B11+1 -> 7 | C12: 110000329 | D12: Hạt rPET WSS01 | E12: 0.78
B13: =+B12+1 -> 8 | C13: 110000331 | D13: Hạt rPET WSS02 | E13: 0.74
B14: =+B13+1 -> 9 | C14: 110000358 | D14: Hạt nhựa rPET WSS02G | E14: 0.74
B15: =+B14+1 -> 10 | C15: 110000333 | D15: Hạt rPET WSS03 | E15: 0.70
B16: =+B15+1 -> 11 | C16: 110000359 | D16: Hạt nhựa rPET WSS03G | E16: 0.70
B17: =+B16+1 -> 12 | C17: 110000376 | D17: Hạt nhựa rPET iSS01L | E17: 0.80
B18: =+B17+1 -> 13 | C18: 110000387 | D18: Hạt nhựa rPET WSS03SD | E18: 0.70
... B21: =+B20+1 -> 16 | C21: Hạt rPET phân lập | D21: Hạt rPET ISS084G | E21: 0.84
B22: =+B21+1 -> 17 | D22: Hạt rPET ISS01 | E22: 0.80
B23: =+B22+1 -> 18 | D23: Hạt rPET ISS01G | E23: 0.80
B24: =+B23+1 -> 19 | D24: Hạt rPET WSS01G | E24: 0.78
B25: =+B24+1 -> 20 | D25: Hạt rPET WSS01 | E25: 0.78
B26: =+B25+1 -> 21 | D26: Hạt rPET WSS02 | E26: 0.74
B27: =+B26+1 -> 22 | D27: Hạt nhựa rPET WSS02G | E27: 0.74
B28: =+B27+1 -> 23 | D28: Hạt rPET WSS03 | E28: 0.70
B29: =+B28+1 -> 24 | D29: Hạt nhựa rPET WSS03G | E29: 0.70
B31: Lưu ý:
B32: 1. Giá FOB = Giá xuất xưởng (EXW) + USD 20/tấn | G32: 20
B33: 2. Hạt xơ sợi: giá bán 1.100 usd/tấn, chào khách để bán được hàng là +/- 55usd/tấn
B34: 3. Bảng giá áp dụng cho việc phát triển khách hàng mới, lưu hành nội bộ
O35: Ngày …. tháng ….. năm …....
C36: Giám đốc Tài Chính | E36: Giám Đốc Điều Hành | J36: Giám Đốc Kinh Doanh | P36: Kế Toán

Sheet 3. rPET USA 
D2: GIÁ BÁN HẠT rPET - THÁNG …. NĂM …... - THỊ TRƯỜNG USA HỖ TRỢ PHÁT TRIỂN KHÁCH HÀNG MỚI | N2: TC-TCH-01/ BM03
N3: V0 -
C4: Hạt rPET: WSS01G (IV 0.78 ± 0.02) | H4: ISS01G (IV 0.8 ± 0.02) | M4: ISS01084G (IV 0.84 ± 0.03)
B5: TÓM TẮT:
B6: I | C6: Giá FOB | E6: =E14 -> 0 | F6: =+E6/E$8 -> 0 | H6: Giá FOB | J6: =J14 -> 0 | K6: =+J6/J$8 -> 0 | M6: Giá FOB | O6: =O14 -> 0 | P6: =+O6/O$8 -> 0
B7: II | C7: Chi phí vận chuyển từ VN sang USA | E7: =+E15+E16+E18+E19+E20 -> 6300 | F7: =+E7/E$8 -> 1 | H7: Chi phí vận chuyển từ VN sang USA | J7: =+J15+J16+J18+J19+J20 -> 6300 | K7: =+J7/J$8 -> 1 | M7: Chi phí vận chuyển từ VN sang USA | O7: =+O15+O16+O18+O19+O20 -> 6300 | P7: =+O7/O$8 -> 1
C8: Tổng cộng | D8: =+D7+D6 -> 0 | E8: =+E7+E6 -> 6300 | F8: =+E8/E$8 -> 1 | H8: Tổng cộng | I8: =+I7+I6 -> 0 | J8: =+J7+J6 -> 6300 | K8: =+J8/J$8 -> 1 | M8: Tổng cộng | N8: =+N7+N6 -> 0 | O8: =+O7+O6 -> 6300 | P8: =+O8/O$8 -> 1
C10: Số lượng (tấn/cont) | H10: Số lượng (tấn/cont) | I10: =D10 -> 0 | M10: Số lượng (tấn/cont) | N10: =I10 -> 0
B11: STT | C11: Quy cách đóng hàng (cont 20'fcl | D11: Đơn giá USD ($/tấn) | E11: Tổng giá trị USD ($/cont) | F11: Tỷ lệ % | H11: Quy cách đóng hàng (cont 20'fcl | I11: Đơn giá USD ($/tấn) | J11: Tổng giá trị USD ($/cont) | K11: Tỷ lệ % | M11: Quy cách đóng hàng (cont 20'fcl | N11: Đơn giá USD ($/tấn) | O11: Tổng giá trị USD ($/cont) | P11: Tỷ lệ %
B12: =+B10+1 -> 1 | C12: Giá Exw DTR | E12: =+D12*D$10 -> 0 | H12: Giá Ex DTR | J12: =+I12*I$10 -> 0 | M12: Giá Ex DTR | O12: =+N12*N$10 -> 0
B13: 2 | C13: Kéo cont từ DTR đến cảng HCM | E13: =+D13*D$10 -> 0 | H13: Kéo cont từ DTR đến cảng HCM | J13: =+I13*I$10 -> 0 | M13: Kéo cont từ DTR đến cảng HCM | O13: =+N13*N$10 -> 0
B14: 3 | C14: Giá FOB HCM=(1) + (2) | E14: =+D14*D$10 -> 0 | F14: =+E14/E$8 -> 0 | H14: Giá FOB HCM | J14: =+I14*I$10 -> 0 | K14: =+J14/J$8 -> 0 | M14: Giá FOB HCM | O14: =+N14*N$10 -> 0 | P14: =+O14/O$8 -> 0
B15: 4 | C15: Vận chuyển biển | E15: 4550 | F15: =+E15/E$8 -> 0.72222222 | H15: Vận chuyển biển | J15: =E15 -> 4550 | K15: =+J15/J$8 -> 0.72222222 | M15: Vận chuyển biển | O15: =E15 -> 4550 | P15: =+O15/O$8 -> 0.72222222
B16: 5 | C16: Bảo hiểm | E16: 0 | F16: =+E16/E$8 -> 0 | H16: Bảo hiểm | J16: 0 | K16: =+J16/J$8 -> 0 | M16: Bảo hiểm | O16: 0 | P16: =+O16/O$8 -> 0
B17: =+B16+1 -> 6 | C17: Giá CIF (LAX)=(3)+(4)+(5) | E17: =SUM(E14:E16) -> 4550 | F17: =+E17/E$8 -> 0.72222222 | H17: Giá CIF (LAX) | J17: =SUM(J14:J16) -> 4550 | K17: =+J17/J$8 -> 0.72222222 | M17: Giá CIF (LAX) | O17: =SUM(O14:O16) -> 4550 | P17: =+O17/O$8 -> 0.72222222
B18: =+B17+1 -> 7 | C18: Thuế nhập khẩu | E18: =7%*D14*D10 -> 0 | F18: =+E18/E$8 -> 0 | H18: Thuế nhập khẩu | J18: =7%*I14*I10 -> 0 | K18: =+J18/J$8 -> 0 | M18: Thuế nhập khẩu | O18: =7%*N14*N10 -> 0 | P18: =+O18/O$8 -> 0
B19: =+B18+1 -> 8 | C19: Kéo cont đến nhà máy | E19: 1350 | F19: =+E19/E$8 -> 0.21428571 | H19: Kéo cont đến nhà máy | J19: =E19 -> 1350 | K19: =+J19/J$8 -> 0.21428571 | M19: Kéo cont đến nhà máy | O19: =E19 -> 1350 | P19: =+O19/O$8 -> 0.21428571
B20: =+B19+1 -> 9 | C20: Phí phạt vượt tải trọng | E20: 400 | F20: =+E20/E$8 -> 0.063492063 | H20: Phí phạt vượt tải trọng | J20: =E20 -> 400 | K20: =+J20/J$8 -> 0.063492063 | M20: Phí phạt vượt tải trọng | O20: =E20 -> 400 | P20: =+O20/O$8 -> 0.063492063
B21: =+B20+1 -> 10 | C21: Giá DDP CA93033=(6)+(7)+(8)+(9) | D21: =+SUM(D17:D20) -> 0 | E21: =+SUM(E17:E20) -> 6300 | F21: =+E21/E$8 -> 1 | H21: Giá DDP CA93033 | I21: =+SUM(I17:I20) -> 0 | J21: =+SUM(J17:J20) -> 6300 | K21: =+J21/J$8 -> 1 | M21: Giá DDP CA93033 | N21: =+SUM(N17:N20) -> 0 | O21: =+SUM(O17:O20) -> 6300 | P21: =+O21/O$8 -> 1
B22: Lưu ý:
B23: 1. Bảng giá áp dụng cho việc phát triển khách hàng mới, lưu hành nội bộ
P24: ='2. rPET- nội bộ '!O35 -> Ngày …. tháng ….. năm …....
B25: Giám Đốc Tài Chính | F25: Giám Đốc Điều Hành | K25: Giám Đốc Kinh Doanh | N25: Kế Toán

Sheet 4. rHDPE 
D1: GIÁ BÁN HẠT rHDPE - THÁNG …. NĂM ….. HỖ TRỢ PHÁT TRIỂN KHÁCH HÀNG MỚI | O1: TC-TCH-01/ BM04
O2: V0 -
B3: STT | C3: Mã sản phẩm | D3: Sản phẩm | E3: Màu | F3: Giá xuất xưởng DTR (USD/tấn) | P3: Chênh lệch Giá tháng …. vs chính phẩm (….. $/tấn HD thổi & …. $/tấn HD ép)
F4: ='1. rPET'!F4 -> Tháng …. (đã duyệt) | J4: ='1. rPET'!J4 -> Tháng …. | N4: ='1. rPET'!N4 -> Chênh lệch tháng …. vs tháng ….
F5: Giá Bán (1) | G5: % Chiết khấu (2) | H5: Chiết Khấu (3) | I5: Giá bán sau chiết khấu (4)=(1)-(3) | J5: Giá Bán (1) | K5: % Chiết khấu (2) | L5: Chiết Khấu (3) | M5: Giá bán sau chiết khấu (4)=(1)-(3) | N5: $ | O5: % | P5: $ | Q5: %
B6: A | C6: NHÓM KHÁCH HÀNG PHÁT TRIỂN BỀN VỮNG
B7: I. rHDPE THỔI (PERSONAL CARE)
B8: 1 | C8: 110000429 | D8: Hạt Nhựa rHDPE A03N01 | E8: Không màu
B9: =B8+1 -> 2 | C9: 110000337 | D9: Hạt nhựa rHD Thổi màu | E9: Trắng, lá, vàng
B10: II. rHDPE THỔI (HOME CARE)
B11: 1 | C11: 110000432 | D11: Hạt nhựa rHDPE B03N01 | E11: Không màu, Trắng, lá, vàng
B12: III. rHDPE ÉP
B13: 1 | C13: 110000373 | D13: Hạt rHDI4DL01 | E13: Màu dương đậm
B14: 2 | C14: 110000365 | D14: Hạt rHD ép | E14: Màu trắng, đỏ
B15: 3 | C15: 110000361 | D15: Hạt rHDI3R01 | E15: Màu đỏ | F15: 1360 | G15: =H15/F15 -> 0.036764706 | H15: =F15-I15 -> 50 | I15: 1310 | J15: 1360 | K15: =L15/J15 -> 0.036764706 | L15: =J15-M15 -> 50 | M15: 1310 | N15: =M15-I15 -> 0 | O15: =1-(I15/M15) -> 0 | P15: =M15-#REF! -> #REF! | Q15: =P15/#REF! -> #REF!
B16: B | C16: NHÓM KHÁCH HÀNG NỘI ĐỊA
B17: 1 | C17: 110000373 | D17: Hạt rHD ép màu | E17: Màu dương đậm, trắng, đỏ
B18: 2 | C18: 110000365 | D18: Hạt rHDI3W01 | E18: Màu trắng | F18: 1000 | G18: =H18/F18 -> 0.05 | H18: =F18-I18 -> 50 | I18: 950 | J18: 1000 | K18: =L18/J18 -> 0.05 | L18: =J18-M18 -> 50 | M18: 950 | N18: =M18-I18 -> 0 | O18: =1-(I18/M18) -> 0 | P18: =M18-#REF! -> #REF! | Q18: =P18/#REF! -> #REF!
B19: 3 | C19: 110000361 | D19: Hạt rHDI3R01 | E19: Màu đỏ | F19: 1000 | G19: =H19/F19 -> 0.05 | H19: =F19-I19 -> 50 | I19: 950 | J19: 1000 | K19: =L19/J19 -> 0.05 | L19: =J19-M19 -> 50 | M19: 950 | N19: =M19-I19 -> 0 | O19: =1-(I19/M19) -> 0 | P19: =M19-#REF! -> #REF! | Q19: =P19/#REF! -> #REF!
B21: Lưu ý:
B22: 1. Giá FOB = Giá xuất xưởng (EXW) + USD 25/tấn | G22: 25
B23: 2. Giá chính phẩm HD thổi là ... usd/tấn, HD Ép là ... usd/tấn
B24: 3. Khách hàng nội địa: Long Thành, DTP, Hiệp Thành
B25: 4. Ủy quyền cho GĐĐH duyệt theo đơn đặt hàng: biên độ +/-10% so với giá xuất xưởng DTR
B26: 5. Bảng giá áp dụng cho việc phát triển khách hàng mới, lưu hành nội bộ
O27: ='2. rPET- nội bộ '!O35 -> Ngày …. tháng ….. năm …....
B28: Chủ Tịch | D28: Giám Đốc Tài Chính | G28: Giám Đốc Điều Hành | L28: Giám Đốc Kinh Doanh | P28: Kế Toán

Sheet 5.Vảy HDPE- Ép
D1: GIÁ BÁN VẢY HDPE ÉP- THÁNG …. NĂM ….. HỖ TRỢ PHÁT TRIỂN KHÁCH HÀNG MỚI | O1: TC-TCH-01/ BM05
O2: V0 -
B3: STT | C3: Mã sản phẩm | D3: Sản phẩm | E3: Màu | F3: Giá xuất xưởng DTR (USD/tấn) | P3: Chênh lệch Giá tháng ….. vs chính phẩm (….. $/tấn)
F4: ='1. rPET'!F4 -> Tháng …. (đã duyệt) | J4: ='1. rPET'!J4 -> Tháng …. | N4: ='1. rPET'!N4 -> Chênh lệch tháng …. vs tháng ….
F5: Giá Bán (1) | G5: % Chiết khấu (2) | H5: Chiết Khấu (3) | I5: Giá bán sau chiết khấu (4)=(1)-(3) | J5: Giá Bán (1) | K5: % Chiết khấu (2) | L5: Chiết Khấu (3) | M5: Giá bán sau chiết khấu (4)=(1)-(3) | N5: $ | O5: % | P5: $ | Q5: %
B6: NHÓM KHÁCH HÀNG NỘI ĐỊA
B7: 1 | C7: 110000407 | D7: Vảy HD màu | E7: Đỏ, Trắng, Vàng, Lá, Dương
B8: 2 | C8: 110000408 | D8: Vảy HD Ép Trắng | F8: 850 | G8: =H8/F8 -> 0.047058824 | H8: =F8-I8 -> 40 | I8: 810 | J8: 850 | K8: =L8/J8 -> 0.047058824 | L8: =J8-M8 -> 40 | M8: 810 | N8: =M8-I8 -> 0 | O8: =1-(I8/M8) -> 0 | P8: =M8-$R$1 -> 810 | Q8: =P8/$R$1 -> #DIV/0!
B9: 3 | C9: 110000409 | D9: Vảy HD Ép Vàng | F9: 850 | G9: =H9/F9 -> 0.047058824 | H9: =F9-I9 -> 40 | I9: 810 | J9: 850 | K9: =L9/J9 -> 0.047058824 | L9: =J9-M9 -> 40 | M9: 810 | N9: =M9-I9 -> 0 | O9: =1-(I9/M9) -> 0 | P9: =M9-$R$1 -> 810 | Q9: =P9/$R$1 -> #DIV/0!
B10: 4 | C10: 110000410 | D10: Vảy HD Ép Lá | F10: 850 | G10: =H10/F10 -> 0.047058824 | H10: =F10-I10 -> 40 | I10: 810 | J10: 850 | K10: =L10/J10 -> 0.047058824 | L10: =J10-M10 -> 40 | M10: 810 | N10: =M10-I10 -> 0 | O10: =1-(I10/M10) -> 0 | P10: =M10-$R$1 -> 810 | Q10: =P10/$R$1 -> #DIV/0!
B11: 5 | C11: 110000411 | D11: Vảy HD Ép Dương | F11: 850 | G11: =H11/F11 -> 0.047058824 | H11: =F11-I11 -> 40 | I11: 810 | J11: 850 | K11: =L11/J11 -> 0.047058824 | L11: =J11-M11 -> 40 | M11: 810 | N11: =M11-I11 -> 0 | O11: =1-(I11/M11) -> 0 | P11: =M11-$R$1 -> 810 | Q11: =P11/$R$1 -> #DIV/0!
B13: Lưu ý:
B14: 1. Giá trên là giá xuất xưởng (EXW), nếu vận chuyển đến khách hàng thì cộng thêm phí vận chuyển
B15: 2. Ủy quyền cho GĐĐH duyệt theo đơn đặt hàng: biên độ +/-10% so với giá xuất xưởng DTR
Q16: ='2. rPET- nội bộ '!O35 -> Ngày …. tháng ….. năm …....
B17: Chủ Tịch | D17: Giám Đốc Tài Chính | H17: Giám Đốc Điều Hành | L17: Giám Đốc Kinh Doanh | P17: Kế Toán

Sheet 6. rPP 
D1: GIÁ BÁN HẠT rPP - THÁNG …. NĂM …... HỖ TRỢ PHÁT TRIỂN KHÁCH HÀNG MỚI | O1: TC-TCH-01/ BM06
O2: V0 -
B3: STT | C3: Mã sản phẩm | D3: Sản phẩm | E3: Màu | F3: Giá xuất xưởng DTR (USD/tấn) | P3: Chênh lệch Giá tháng …. vs chính phẩm (…. $/tấn)
F4: ='1. rPET'!F4 -> Tháng …. (đã duyệt) | J4: ='1. rPET'!J4 -> Tháng …. | N4: ='1. rPET'!N4 -> Chênh lệch tháng …. vs tháng ….
F5: Giá Bán (1) | G5: % Chiết khấu (2) | H5: Chiết Khấu (3) | I5: Giá bán sau chiết khấu (4)=(1)-(3) | J5: Giá Bán (1) | K5: % Chiết khấu (2) | L5: Chiết Khấu (3) | M5: Giá bán sau chiết khấu (4)=(1)-(3) | N5: $ | O5: % | P5: $ | Q5: %
B6: A | C6: NHÓM KHÁCH HÀNG PHÁT TRIỂN BỀN VỮNG
B7: 1 | C7: 110000367 | D7: Hạt nhựa rPP màu | E7: Đỏ, dương, trắng, lá, đen
B8: B | C8: NHÓM KHÁCH HÀNG NỘI ĐỊA
B9: 1 | C9: 110000367 | D9: Hạt nhựa rPP màu | E9: Đỏ, dương, trắng, lá, đen
B11: Lưu ý:
B12: 1. Giá FOB = Giá xuất xưởng (EXW) + USD 25/tấn | G12: 25
B13: 2. Ủy quyền cho GĐĐH duyệt theo đơn đặt hàng: biên độ +/-10% so với giá xuất xưởng DTR
B14: 3. Bảng giá áp dụng cho việc phát triển khách hàng mới, lưu hành nội bộ
O15: ='2. rPET- nội bộ '!O35 -> Ngày …. tháng ….. năm …....
B16: Chủ Tịch | D16: Giám Đốc Tài Chính | G16: Giám Đốc Điều Hành | K16: Giám Đốc Kinh Doanh | O16: Kế Toán

Sheet 7. Vảy PP
D1: GIÁ BÁN VẢY PP - THÁNG …. NĂM …... HỖ TRỢ PHÁT TRIỂN KHÁCH HÀNG MỚI | O1: TC-TCH-01/ BM07
O2: V0 -
B3: STT | C3: Mã sản phẩm | D3: Sản phẩm | E3: Màu | F3: Giá xuất xưởng DTR (USD/tấn) | P3: Chênh lệch Giá tháng ….. vs chính phẩm (….. $/tấn)
F4: ='1. rPET'!F4 -> Tháng …. (đã duyệt) | J4: ='1. rPET'!J4 -> Tháng …. | N4: ='1. rPET'!N4 -> Chênh lệch tháng …. vs tháng ….
F5: Giá Bán (1) | G5: % Chiết khấu (2) | H5: Chiết Khấu (3) | I5: Giá bán sau chiết khấu (4)=(1)-(3) | J5: Giá Bán (1) | K5: % Chiết khấu (2) | L5: Chiết Khấu (3) | M5: Giá bán sau chiết khấu (4)=(1)-(3) | N5: $ | O5: % | P5: $ | Q5: %
B6: NHÓM KHÁCH HÀNG NỘI ĐỊA
B7: 1 | C7: 110000421 | D7: Vảy PP màu | E7: Đỏ, dương
B8: 2 | C8: 110000422 | D8: Vảy PP Đỏ Đậm | F8: 850 | G8: =H8/F8 -> 0.047058824 | H8: =F8-I8 -> 40 | I8: 810 | J8: 850 | K8: =L8/J8 -> 0.047058824 | L8: =J8-M8 -> 40 | M8: 810 | N8: =M8-I8 -> 0 | O8: =1-(I8/M8) -> 0 | P8: =M8-$R$1 -> 810 | Q8: =P8/$R$1 -> #DIV/0!
B9: 3 | C9: 110000423 | D9: Vảy PP Dương Nhạt | F9: 850 | G9: =H9/F9 -> 0.047058824 | H9: =F9-I9 -> 40 | I9: 810 | J9: 850 | K9: =L9/J9 -> 0.047058824 | L9: =J9-M9 -> 40 | M9: 810 | N9: =M9-I9 -> 0 | O9: =1-(I9/M9) -> 0 | P9: =M9-$R$1 -> 810 | Q9: =P9/$R$1 -> #DIV/0!
B10: 4 | C10: 110000424 | D10: Vảy PP Dương Đậm | F10: 850 | G10: =H10/F10 -> 0.047058824 | H10: =F10-I10 -> 40 | I10: 810 | J10: 850 | K10: =L10/J10 -> 0.047058824 | L10: =J10-M10 -> 40 | M10: 810 | N10: =M10-I10 -> 0 | O10: =1-(I10/M10) -> 0 | P10: =M10-$R$1 -> 810 | Q10: =P10/$R$1 -> #DIV/0!
B12: Lưu ý:
B13: 1. Giá trên là giá xuất xưởng (EXW), nếu vận chuyển đến khách hàng thì cộng thêm phí vận chuyển
B14: 2. Ủy quyền cho GĐĐH duyệt theo đơn đặt hàng: biên độ +/-10% so với giá xuất xưởng DTR
Q15: ='2. rPET- nội bộ '!O35 -> Ngày …. tháng ….. năm …....
B16: Chủ Tịch | D16: Giám Đốc Tài Chính | H16: Giám Đốc Điều Hành | L16: Giám Đốc Kinh Doanh | P16: Kế Toán

Sheet 8. Hạt phó sản
D1: GIÁ BÁN HẠT SẢN XUẤT TỪ PHÓ SẢN - THÁNG …. NĂM …... HỖ TRỢ PHÁT TRIỂN KHÁCH HÀNG MỚI | P1: TC-TCH-01/ BM08
P2: V0 -
B3: STT | C3: Mã sản phẩm | D3: Sản phẩm | E3: Màu | F3: IV/MI | G3: Giá xuất xưởng DTR (USD/tấn) | Q3: Chênh lệch Giá tháng …. vs chính phẩm (….. $/tấn)
G4: ='1. rPET'!F4 -> Tháng …. (đã duyệt) | K4: ='1. rPET'!J4 -> Tháng …. | O4: ='1. rPET'!N4 -> Chênh lệch tháng …. vs tháng ….
G5: Giá Bán (1) | H5: % Chiết khấu (2) | I5: Chiết Khấu (3) | J5: Giá bán sau chiết khấu (4)=(1)-(3) | K5: Giá Bán (1) | L5: % Chiết khấu (2) | M5: Chiết Khấu (3) | N5: Giá bán sau chiết khấu (4)=(1)-(3) | O5: $ | P5: % | Q5: $ | R5: %
B6: NHÓM KHÁCH HÀNG NỘI ĐỊA
B7: 1 | C7: 110000464 | D7: Hạt Nhựa rPET WSS06SP-1 | E7: Đục
B8: 2 | C8: 110000465 | D8: Hạt Nhựa rPET WSS06SP-2 | E8: Trong
B9: 3 | C9: 110000436 | D9: Hạt nhựa rPET WSS05SB | E9: Trong
B10: 4 | C10: 110000466 | D10: Hạt Nhựa rPET WSS05SB-2 | E10: Trong
B11: 5 | C11: 110000467 | D11: Hạt Nhựa rPET WSS05SB-3 | E11: Trong
B12: 6 | C12: 110000341 | D12: Hạt nhựa rHDB04B01 | E12: Đen
B13: 7 | C13: 110000433 | D13: Hạt Nhựa rHDB03N03 | E13: Trong
B14: 8 | C14: 110000431 | D14: Hạt Nhựa rHDI3Gy02 | E14: Xám
B15: 9 | C15: 110000392 | D15: Hạt nhựa rPP20B01 | E15: Đen
B17: Lưu ý:
B18: 1. Giá trên là giá xuất xưởng (EXW), nếu vận chuyển đến khách hàng thì cộng thêm phí vận chuyển
B19: 2. Ủy quyền cho GĐĐH duyệt theo đơn đặt hàng: biên độ +/-10% so với giá xuất xưởng DTR
R20: ='2. rPET- nội bộ '!O35 -> Ngày …. tháng ….. năm …....
B21: Chủ Tịch | D21: Giám Đốc Tài Chính | I21: Giám Đốc Điều Hành | M21: Giám Đốc Kinh Doanh | Q21: Kế Toán

Sheet 9. Ma trận giá bán
C1: MA TRẬN GIÁ BÁN NĂM …. | O1: TC-TCH-01/ BM09
O2: V0 -
D4: ĐVT: USD/ TẤN
A5: Stt | B5: Mã SP | C5: Tên sản phẩm | D5: Mức IV | E5: 1 | F5: 2 | G5: 3 | H5: 4 | I5: 5 | J5: 6 | K5: 7 | L5: 8 | M5: 9 | N5: 10 | O5: 11 | P5: 12
B13: ICIS | C13: ICIS - Giá trung bình
C14: +/- % Giá WSS01 của DTR vs giá ICIS
C15: Giá keo PET chính phẩm
C16: +/- % Giá WSS01 của DTR vs giá chính phẩm
C18: Ngày …./...../….....
C19: Người lập
