Workbook
Name \T: #REF!
Name \T: #REF!
Name \T: #REF!
Name \T: #REF!
Name \T: #REF!
Name \T: #REF!
Name \T: #REF!
Name \T: #REF!
Name \T: #REF!
Name \T: #REF!
Name \T: #REF!
Name __dao1: '[1]CT Thang Mo'!$B$189:$H$189
Name __dao2: '[1]CT Thang Mo'!$B$161:$H$161
Name __dap2: '[1]CT Thang Mo'!$B$162:$H$162
Name __day1: '[2]Chiet tinh dz22'!#REF!
Name __day2: '[3]Chiet tinh dz35'!$H$3
Name __dbu1: '[1]CT Thang Mo'!#REF!
Name __dbu2: '[1]CT Thang Mo'!$B$93:$F$93
Name __doi3: '[4]truc tiep'!#REF!
Name __E99999: #REF!
Name __Jan02: '[5]FG waste'!#REF!
Name __lap1: #REF!
Name __lap2: #REF!
Name __vc1: '[1]CT Thang Mo'!$B$34:$H$34
Name __vc2: '[1]CT Thang Mo'!$B$35:$H$35
Name __vc3: '[1]CT Thang Mo'!$B$36:$H$36
Name _01_01_99: #REF!
Name _01_02_99: #REF!
Name _01_03_99: #REF!
Name _01_04_99: #REF!
Name _01_05_99: #REF!
Name _01_06_99: #REF!
Name _01_07_99: #REF!
Name _01_08_1999: #REF!
Name _1CAP002: [6]MTP!#REF!
Name _2STREO7: [7]MTP!#REF!
Name _4GOIC01: [8]MTP!#REF!
Name _4OSLCTT: [8]MTP!#REF!
Name _6BNTTTH: [7]MTP1!#REF!
Name _6DCTTBO: [7]MTP1!#REF!
Name _6DD24TT: [7]MTP1!#REF!
Name _6FCOTBU: [7]MTP1!#REF!
Name _6LATUBU: [7]MTP1!#REF!
Name _6SDTT24: [7]MTP1!#REF!
Name _6TBUDTT: [7]MTP1!#REF!
Name _6TDDDTT: [7]MTP1!#REF!
Name _6TLTTTH: [7]MTP1!#REF!
Name _6TUBUTT: [7]MTP1!#REF!
Name _6UCLVIS: [7]MTP1!#REF!
Name _7DNCABC: [7]MTP1!#REF!
Name _7HDCTBU: [7]MTP1!#REF!
Name _7PKTUBU: [7]MTP1!#REF!
Name _7TBHT20: [7]MTP1!#REF!
Name _7TBHT30: [7]MTP1!#REF!
Name _7TDCABC: [7]MTP1!#REF!
Name _dao1: '[1]CT Thang Mo'!$B$189:$H$189
Name _dao2: '[1]CT Thang Mo'!$B$161:$H$161
Name _dap2: '[1]CT Thang Mo'!$B$162:$H$162
Name _day1: '[2]Chiet tinh dz22'!#REF!
Name _day2: '[3]Chiet tinh dz35'!$H$3

Sheet Nguyên tắc trình bày
A2: 1 | B2: Tiêu đề các biểu đồ font chữ size 24
A3: 2 | B3: Không để số âm vùng chênh lệch
A4: 3 | B4: font Size số, chữ đều là 14, time new roman , chữ đen
A5: 4 | B5: Zoom 90%, theo khung canh của anh Lộc, đã chỉnh làm mẫu tại sheet "vảy HDPE 2023-Tuần"
A6: 5 | B6: Kéo ngang và dọc cho nó cân xứng
A7: 6 | B7: trình bày 25 tuần gần nhất
A8: 7 | B8: Giá mua trung bình các loại vảy: (HDPE: vảy trong, PET: vảy A4 đến A6)

Sheet 01.Chai B1- Tháng
BK2: Năm 2022 | BP2: Năm 2022
BI3: Data | BJ3: 13 | BK3: 1 | BL3: 2 | BM3: 3 | BN3: 4 | BO3: 5 | BP3: T6/22 | BQ3: 7 | BR3: 8 | BS3: 9 | BT3: 10 | BU3: 11 | BV3: 12 | BW3: 1/23 | BX3: 2 | BY3: 3 | BZ3: 4 | CA3: 5 | CB3: 6 | CC3: 7 | CD3: 8 | CE3: 9 | CF3: 10 | CG3: 11 | CH3: 12 | CI3: 1.24 | CJ3: 2 | CK3: 3 | CL3: 4 | CM3: 5 | CN3: 6 | CO3: 7 | CP3: 8 | CQ3: 9 | CR3: 10 | CS3: 11 | CT3: 12 | CU3: 1.25 | CV3: 2 | CW3: 3 | CX3: 4
BI4: Tỷ giá USD | BJ4: 22920 | BK4: 23180 | BL4: 23108 | BM4: 23108 | BN4: 23108 | BO4: 23108 | BP4: 23150 | BQ4: 23150 | BR4: 23150 | BS4: 23150 | BT4: 23500 | BU4: 23500 | BV4: 23380 | BW4: 23250 | BX4: 23570 | BY4: 23260 | BZ4: 23260 | CA4: 23295 | CB4: 23330 | CC4: 23380 | CD4: 23840 | CE4: 23960 | CF4: 24280 | CG4: 24730 | CH4: 24930 | CI4: 24210 | CJ4: 24250 | CK4: 24490 | CL4: 24690 | CM4: 25475 | CN4: 25250 | CO4: 25750 | CP4: 25130 | CQ4: 24580 | CR4: 24410 | CS4: 25120 | CT4: 25140 | CU4: 25290 | CV4: 25050 | CW4: 25400 | CX4: 25460
BI5: Giá keo chính phẩm | BJ5: 1122 | BK5: 1165 | BL5: 1272.5 | BM5: 1346 | BN5: 1297.5 | BO5: 1316.6667 | BP5: =B36*BP4/1000 -> 32178.5 | BQ5: =C36*BQ4/1000 -> 28243 | BR5: =D36*BR4/1000 -> 29400.5 | BS5: =E36*BS4/1000 -> 27548.5 | BT5: =F36*BT4/1000 -> 26555 | BU5: =G36*BU4/1000 -> 24440 | BV5: =H36*BV4/1000 -> 22853.95 | BW5: =I36*BW4/1000 -> 23250 | ... CX5: =AJ36*CX4/1000 -> 20622.6
BI6: Giá duyệt mua chai B1 | BJ6: 688.17627 | BK6: =BK16/BK4*1000 -> 0 | BL6: =BL16/BL4*1000 -> 0 | BM6: =BM16/BM4*1000 -> 0 | BN6: =BN16/BN4*1000 -> 0 | BO6: =BO16/BO4*1000 -> 0 | BP6: 18000 | BQ6: 18000 | BR6: 18000 | BS6: 16500 | BT6: 16500 | BU6: 16500 | BV6: 15500 | BW6: 14500 | BX6: 14500 | BY6: 15500 | BZ6: 15500 | CA6: 15500 | CB6: 13500 | CC6: 13000 | CD6: 13000 | CE6: 13500 | CF6: 14500 | CG6: 15000 | CH6: 15000 | CI6: 16500 | CJ6: 16500 | CK6: 16500 | CL6: 17500 | CM6: 17500 | CN6: 17500 | CO6: 16500 | CP6: 17000 | CQ6: 17500 | CR6: 17400 | CS6: 17700 | CT6: 17700 | CU6: =+(16800) -> 16800 | CV6: =+(16800) -> 16800 | CW6: =+(17200) -> 17200 | CX6: 18000
BI7: Giá bale ĐNA | BP7: =BP16*BP4/1000 -> 14237.25 | BQ7: =BQ16*BQ4/1000 -> 13890 | BR7: =BR16*BR4/1000 -> 13156.917 | BS7: =BS16*BS4/1000 -> 13156.917 | BT7: =BT16*BT4/1000 -> 13351.917 | BU7: =BU16*BU4/1000 -> 12220 | BV7: =BV16*BV4/1000 -> 10918.46 | BW7: =BW16*BW4/1000 -> 10776.375 | ... CX7: =CX16*CX4/1000 -> 15461.858
BI8: Giá chai B1 thực tế mua trung bình | BJ8: 15773 | BK8: 15974 | BL8: 15997 | BM8: 16512 | BN8: 17232 | BO8: 17845 | BP8: 17949.169 | BQ8: 18008.203 | BR8: 17709.211 | BS8: 16436.763 | BT8: 16498.897 | BU8: 16968.763 | BV8: 16873.812 | BW8: 14486.456 | BX8: 14337.016 | BY8: 15026.124 | BZ8: 14967.788 | CA8: 14928.984 | CB8: 13867.306 | CC8: 12969.009 | CD8: 12977.364 | CE8: 13498.82 | CF8: 14413.011 | CG8: 15100 | CH8: 15100 | CI8: 16099.441 | CJ8: 16332.331 | CK8: =16233.8475760353+377 -> 16610.848 | CL8: 17757.505 | CM8: 17263.633 | CN8: 17209.798 | CO8: 16215.033 | CP8: 16527.439 | CQ8: 16645.01 | CR8: 16492.39 | CS8: 16673.362 | CT8: 16581.723 | CU8: 16882.91 | CV8: 17173.91 | CW8: 17802.737 | CX8: 18000
BI9: Giá chai B1 thể hiện | BJ9: 688.17627 | BK9: 689.12856 | BL9: 692.27107 | BM9: 714.55773 | BN9: 745.71577 | BO9: 772.24338 | BP9: =BP6 -> 18000 | BQ9: =BQ6 -> 18000 | BR9: =BR6 -> 18000 | BS9: =BS6 -> 16500 | BT9: =BT6 -> 16500 | BU9: =BU6 -> 16500 | BV9: =BV6 -> 15500 | BW9: =BW6 -> 14500 | ... CX9: =CX6 -> 18000
BI10: % Keo chính phẩm so với chai B1 | BJ10: 0.63039625 | BK10: 0.69054088 | BL10: 0.83815278 | BM10: 0.88368266 | BN10: 0.73993907 | BO10: 0.70498926 | BP10: =BP13/BP6 -> 0.78769444 | BQ10: =BQ13/BQ6 -> 0.56905556 | BR10: =BR13/BR6 -> 0.63336111 | BS10: =BS13/BS6 -> 0.66960606 | BT10: =BT13/BT6 -> 0.60939394 | BU10: =BU13/BU6 -> 0.48121212 | BV10: =BV13/BV6 -> 0.47444839 | BW10: =BW13/BW6 -> 0.60344828 | ... CX10: =CX13/CX6 -> 0.1457
BI11: % Giá chính phẩm tháng sau so với tháng trước | BK11: 0.038324421 | BL11: 0.092274678 | BM11: 0.057760314 | BN11: -0.036032689 | BO11: 0.014771997 | BP11: 0.055696203 | BQ11: -0.12230216 | BR11: 0.040983607 | BS11: -0.062992126 | BT11: -0.050420168 | BU11: -0.079646018 | BV11: -0.13495575 | BW11: -0.038461538 | BX11: 0.069053708 | BY11: 0.02 | BZ11: 0.009569378 | CA11: -0.045098039 | CB11: -0.14691943 | CC11: -0.14691943 | CD11: -0.14691943 | CE11: -0.14691943 | CF11: -0.14691943 | CG11: -0.14691943 | CH11: -0.14691943 | CI11: -0.14691943 | CJ11: -0.14691943 | CK11: -0.14691943 | CL11: -0.14691943 | CM11: -0.14691943 | CN11: -0.14691943 | CO11: -0.14691943 | CP11: -0.14691943 | CQ11: -0.14691943 | CR11: -0.14691943 | CS11: -0.14691943 | CT11: -0.14691943 | CU11: -0.14691943 | CV11: -0.14691943 | CW11: -0.14691943 | CX11: -0.14691943
BI12: % Giá chai B1 tháng sau so với tháng trước | BK12: 0.0013837935 | BL12: 0.00456013 | BM12: 0.032193536 | BN12: 0.043604651 | BO12: 0.035573352 | BP12: 0.0040031347 | BQ12: 0.0032870912 | BR12: -0.017658818 | BS12: -0.070830978 | BT12: -0.011177818 | BU12: 0.028486575 | BV12: -0.0059372285 | BW12: -0.16408421 | BX12: -0.14405873 | BY12: 0.037253294 | BZ12: 0.04399603 | CA12: -0.0064647859 | CB12: -0.06465806 | CC12: -0.06465806 | CD12: -0.06465806 | CE12: -0.06465806 | CF12: -0.06465806 | CG12: -0.06465806 | CH12: -0.06465806 | CI12: -0.06465806 | CJ12: -0.06465806 | CK12: -0.06465806 | CL12: -0.06465806 | CM12: -0.06465806 | CN12: -0.06465806 | CO12: -0.06465806 | CP12: -0.06465806 | CQ12: -0.06465806 | CR12: -0.06465806 | CS12: -0.06465806 | CT12: -0.06465806 | CU12: -0.06465806 | CV12: -0.06465806 | CW12: -0.06465806 | CX12: -0.06465806
BI13: Chênh lệch | BJ13: 433.82373 | BK13: 475.87144 | BL13: 580.22893 | BM13: 631.44227 | BN13: 551.78423 | BO13: 544.42329 | BP13: =BP5-BP6 -> 14178.5 | BQ13: =BQ5-BQ6 -> 10243 | BR13: =BR5-BR6 -> 11400.5 | BS13: =BS5-BS6 -> 11048.5 | BT13: =BT5-BT6 -> 10055 | BU13: =BU5-BU6 -> 7940 | BV13: =BV5-BV6 -> 7353.95 | BW13: =BW5-BW6 -> 8750 | ... CX13: =CX5-CX6 -> 2622.6
BI14: Giá bán rPET | BK14: 1300 | BL14: 1300 | BM14: 1450 | BN14: 1550 | BO14: 1550 | BP14: 1550 | BQ14: 1550 | BR14: 1480 | BS14: 1409.7447 | BT14: 1409.7447 | BU14: 1379.9766 | BV14: 1330 | BW14: 1330 | BX14: 1330 | BY14: 1380 | BZ14: 1380 | CA14: 1380 | CB14: 1350 | CC14: 1300 | CD14: 1250 | CE14: 1250 | CF14: 1250 | CG14: 1250 | CH14: 1250 | CI14: 1250 | CJ14: 1250 | CK14: 1250 | CL14: 1250 | CM14: 1300 | CN14: 1300 | CO14: 1300 | CP14: 1300 | CQ14: 1310 | CR14: 1325 | CS14: 1325 | CT14: 1325 | CU14: 1325 | CV14: 1250 | CW14: 1250 | CX14: 1250
BI15: Giá chính phẩm dự báo | BK15: 1165 | BL15: 1272.5 | BM15: 1346 | BN15: 1297.5 | BO15: 1316.6667 | BP15: 1390 | BQ15: 1220 | BR15: 1270 | BS15: 1190 | BT15: 1130 | BU15: 1040 | BV15: 977.5 | BW15: 1000 | BX15: 1045 | BY15: 1020 | BZ15: 1055 | CA15: 974 | CB15: =CB5 -> 20880.35 | CC15: =CC5 -> 21112.14 | CD15: =CD5 -> 21885.12 | CE15: =CE5 -> 22282.8 | CF15: =CF5 -> 22398.3 | CG15: =CG5 -> 22257 | CH15: =CH5 -> 22437 | CI15: =CI5 -> 22515.3 | ... CX15: =CX5 -> 20622.6
BI16: Giá bale ĐNA ( USD) | BP16: 615 | BQ16: 600 | BR16: 568.33333 | BS16: 568.33333 | BT16: 568.16667 | BU16: 520 | BV16: 467 | BW16: 463.5 | BX16: 451.5 | BY16: 471.66667 | BZ16: 501.66667 | CA16: 472.5 | CB16: 454.33333 | CC16: 453 | CD16: 433.2 | CE16: 412.7 | CF16: 419.2 | CG16: 457.4 | CH16: 474.1 | CI16: 474.1 | CJ16: 495.7 | CK16: 494.3 | CL16: 515.7 | CM16: 560 | CN16: 563.5 | CO16: 567.2 | CP16: 579.4 | CQ16: 602 | CR16: 635.5 | CS16: 630.7 | CT16: 613.3 | CU16: 588.8 | CV16: 595.2 | CW16: 595.2 | CX16: 607.3
BI17: Giá mua chai B0 | BW17: 8708.4662 | BX17: 9206.5027 | BY17: 10350.583 | BZ17: 10630.801 | CA17: 9861.484 | CB17: 9199.095 | CC17: 8896.0365 | CD17: 9246.3978 | CE17: 9607.8931 | CF17: 10586.188 | CG17: 11153.125 | CH17: 11113.72 | CI17: 11099.755 | CJ17: 11015.602 | CK17: 11145.196 | CL17: 12500 | CM17: 13000 | CN17: 13000 | CO17: 11500 | CP17: 11500 | CQ17: 12000 | CR17: 11700 | CS17: 12000 | CT17: 12000 | CU17: 12300 | CV17: 12300 | CW17: 12500 | CX17: 13500
A35: Tháng | B35: 06/22 | C35: 7 | D35: 8 | E35: 9 | F35: 10 | G35: 11 | H35: 12 | I35: 1/23 | J35: 2 | K35: 3 | L35: 4 | M35: 5 | N35: 6 | O35: 7 | P35: 8 | Q35: 9 | R35: 10 | S35: 11 | T35: 12 | U35: 1.24 | V35: 2 | W35: 3 | X35: 4 | Y35: 5 | Z35: 6 | AA35: 7 | AB35: 8 | AC35: 9 | AD35: 10 | AE35: 11 | AF35: 12 | AG35: 1.25 | AH35: 2 | AI35: 3 | AJ35: 4
A36: Giá RESIN (USD/ Tấn) | B36: 1390 | C36: 1220 | D36: 1270 | E36: 1190 | F36: 1130 | G36: 1040 | H36: 977.5 | I36: 1000 | J36: 1045 | K36: 1020 | L36: 1055 | M36: 974 | N36: 895 | O36: 903 | P36: 918 | Q36: 930 | R36: 922.5 | S36: 900 | T36: 900 | U36: 930 | V36: 943 | W36: 940 | X36: 940 | Y36: 942 | Z36: 950 | AA36: 948 | AB36: 930 | AC36: 880 | AD36: 862.5 | AE36: 852 | AF36: 840 | AG36: 828 | AH36: 840 | AI36: 823 | AJ36: 810
A45: 1. Sửa lại Tiêu đề (đã chỉnh biểu đồ bên dưới)
A46: 2. chỉnh lại size để thấy 1 màn hình
A47: 3. biểu đồ trình bày bằng VNĐ/kg, lấy tỷ giá tại ngày cuối tháng
A48: 4. Bảng số liệu chỉ trình bày 1 dòng giá keo chính phẩm bằng usd/tấn
A49: 5. Thêm 1 đường giá thực mua trung bình hàng tháng

Sheet Chart B1_Tuần
AM43: Năm 2022
AK44: Data | AL44: 33 | AM44: 34 | AN44: 35 | AO44: 36 | AP44: 37 | AQ44: 38 | AR44: 39 | AS44: 40 | AT44: 41 | AU44: 42 | AV44: 43 | AW44: 44 | AX44: 45 | AY44: 46 | AZ44: 47 | BA44: 48 | BB44: 49 | BC44: 50 | BD44: 51 | BE44: 52 | BF44: 1 | BG44: 2 | BH44: 3 | BI44: 4 | BJ44: 5 | BK44: 6 | BL44: 7 | BM44: 8 | BN44: 9 | BO44: 10 | BP44: 11 | BQ44: 12 | BR44: 13 | BS44: 14 | BT44: 15 | BU44: 16 | BV44: 17 | BW44: 18 | BX44: 19 | BY44: 20 | BZ44: 21 | CA44: 22 | CB44: 23 | CC44: 24 | CD44: 25 | CE44: 26 | CF44: 27 | CG44: 28 | CH44: 29 | CI44: 30 | CJ44: 31 | CK44: 32 | CL44: 33 | CM44: 34
AK45: Tỷ giá USD | AL45: 23150 | AM45: 23150 | AN45: 23150 | AO45: 23500 | AP45: 23500 | AQ45: 23500 | AR45: 23500 | AS45: 23500 | AT45: 23500 | AU45: 23500 | AV45: 23500 | AW45: 24600 | AX45: 24600 | AY45: 24600 | AZ45: 24600 | BA45: 24600 | BB45: 24000 | BC45: 24000 | BD45: 24000 | BE45: 24000 | BF45: 24760 | BG45: 24200 | BH45: 24330 | BI45: 24410 | BJ45: 24380 | BK45: 24220 | BL45: 24250 | BM45: 24380 | BN45: 24550 | BO45: 24530 | BP45: 24500 | BQ45: 24570 | BR45: 24620 | BS45: 24650 | BT45: 24810 | BU45: 25020 | BV45: 25240 | BW45: 25150 | BX45: 25180 | BY45: 25230 | BZ45: 25250 | CA45: 25280 | CB45: 25260 | CC45: 25250 | CD45: 25260 | CE45: 25260 | CF45: 25260 | CG45: 25220 | CH45: 25190 | CI45: 25170 | CJ45: 25120 | CK45: 24930 | CL45: 24970 | CM45: 24810
AK46: Giá bale ĐNA | AL46: 1220 | AM46: 1190 | AN46: 1160 | AO46: 1160 | AP46: 1160 | AQ46: 1130 | AR46: 1130 | AS46: 1100 | AT46: 1100 | AU46: 1070 | AV46: 1040 | AW46: 995 | AX46: 538.5 | AY46: 520.66667 | AZ46: 520.66667 | BA46: 508 | BB46: 520 | BC46: 512.83333 | BD46: 464 | BE46: 467 | BF46: =BF55*BF45/1000 -> 12273.532 | BG46: =BG55*BG45/1000 -> 11995.94 | BH46: =BH55*BH45/1000 -> 12060.381 | BI46: =BI55*BI45/1000 -> 12100.037 | BJ46: =BJ55*BJ45/1000 -> 12085.166 | BK46: =BK55*BK45/1000 -> 11970.735 | BL46: =BL55*BL45/1000 -> 11985.562 | BM46: =BM55*BM45/1000 -> 12049.815 | ... CM46: =CM55*CM45/1000 -> 14375.658
AK47: Giá duyệt mua chai B1 | AL47: 774.65803 | AM47: 773.14615 | AN47: 776.38589 | AO47: 702.12766 | AP47: 702.12766 | AQ47: 702.12766 | AR47: 702.12766 | AS47: 702.12766 | AT47: 702.12766 | AU47: 702.12766 | AV47: 702.12766 | AW47: 670.73171 | AX47: 670.73171 | AY47: 695.81402 | AZ47: 706.10846 | BA47: 719.78422 | BB47: 714.51263 | BC47: 723.60817 | BD47: 716.11607 | BE47: 658.89104 | BF47: 16500 | BG47: 16500 | BH47: 16500 | BI47: 16500 | BJ47: 16500 | BK47: 16500 | BL47: 16500 | BM47: 16500 | BN47: 16500 | BO47: 16500 | BP47: 16500 | BQ47: 16500 | BR47: 16500 | BS47: 17500 | BT47: 17500 | BU47: 17500 | BV47: 17500 | BW47: 17500 | BX47: 17500 | BY47: 17500 | BZ47: 17500 | CA47: 17500 | CB47: 17000 | CC47: 17000 | CD47: 17000 | CE47: 17000 | CF47: 16000 | CG47: 16000 | CH47: 16500 | CI47: 16500 | CJ47: 16500 | CK47: 16500 | CL47: 17000 | CM47: 17000
AK48: Giá chai B1 thực tế mua trung bình | AL48: 17933.333 | AM48: 17898.333 | AN48: 17973.333 | AO48: 16500 | AP48: 16500 | AQ48: 16500 | AR48: 16500 | AS48: 16500 | AT48: 16500 | AU48: 16500 | AV48: 16500 | AW48: 16500 | AX48: 16500 | AY48: 17117.025 | AZ48: 17370.268 | BA48: 17706.692 | BB48: 17148.303 | BC48: 17366.596 | BD48: 17186.786 | BE48: 15813.385 | BF48: 16071.933 | BG48: 16132.36 | BH48: 15988.717 | BI48: 16054.687 | BJ48: 16330.181 | BK48: 16448.82 | BM48: 16368.322 | BN48: 16350.379 | BO48: 16240.766 | BP48: 16182.893 | BQ48: 16213.85 | BR48: 16205.294 | BS48: 17370.845 | BT48: 17486.483 | BU48: 17457.58 | BV48: 17456.87 | BW48: 17193.951 | BX48: 17260.101 | BY48: 17277.914 | BZ48: 17254.469 | CA48: 17259.324 | CB48: 17143.286 | CC48: 17175.785 | CD48: 17311.471 | CE48: 17213.644 | CF48: 16000 | CG48: 15933.143 | CH48: 16357.132 | CI48: 16422.84 | CJ48: 16500 | CK48: 16471.302 | CL48: 16618.706 | CM48: 17000
AK49: Giá chai B1 thể hiện | AL49: 774.65803 | AM49: 773.14615 | AN49: 776.38589 | AO49: 702.12766 | AP49: 702.12766 | AQ49: 702.12766 | AR49: 702.12766 | AS49: 702.12766 | AT49: 702.12766 | AU49: 702.12766 | AV49: 702.12766 | AW49: 670.73171 | AX49: 670.73171 | AY49: 695.81402 | AZ49: 706.10846 | BA49: 719.78422 | BB49: 714.51263 | BC49: 723.60817 | BD49: 716.11607 | BE49: 658.89104 | BF49: =BF47 -> 16500 | BG49: =BG47 -> 16500 | BH49: =BH47 -> 16500 | BI49: =BI47 -> 16500 | BJ49: =BJ47 -> 16500 | BK49: =BK47 -> 16500 | BL49: =BL47 -> 16500 | BM49: =BM47 -> 16500 | ... CM49: =CM47 -> 17000
AK50: % Giá chính phẩm so với với chai B1 | AL50: 0.57488848 | AM50: 0.53916566 | AN50: 0.49410237 | AO50: 0.65212121 | AP50: 0.65212121 | AQ50: 0.60939394 | AR50: 0.60939394 | AS50: 0.56666667 | AT50: 0.56666667 | AU50: 0.52393939 | AV50: 0.48121212 | AW50: 0.48345455 | AX50: 0.19714545 | AY50: 0.25171576 | AZ50: 0.26262508 | BA50: 0.29423293 | BB50: 0.27223119 | BC50: 0.29128311 | BD50: 0.35206034 | BE50: 0.29123335 | BF50: =BF53/BF47 -> 0.35054545 | BG50: =BG53/BG47 -> 0.37866667 | BH50: =BH53/BH47 -> 0.38607273 | BI50: =BI53/BI47 -> 0.3906303 | BJ50: =BJ53/BJ47 -> 0.40369697 | BK50: =BK53/BK47 -> 0.37980606 | BL50: =BL53/BL47 -> 0.38151515 | BM50: =BM53/BM47 -> 0.38892121 | ... CM50: =CM53/CM47 -> 0.37184706
AK51: % Giá chính phẩm tuần sau so với tuần trước | AM51: -0.024590164 | AN51: -0.025210084 | AO51: 0 | AP51: 0 | AQ51: -0.025862069 | AR51: 0 | AS51: -0.026548673 | AT51: 0 | AU51: -0.027272727 | AV51: -0.028037383 | AW51: -0.043269231 | AX51: -0.45879397 | AY51: -0.033116682 | AZ51: 0 | BA51: -0.024327785 | BB51: 0.023622047 | BC51: -0.013782051 | BD51: -0.095222619 | BE51: 0.0064655172 | BF51: -0.021413276 | BG51: 0.014587892 | BH51: 0.0082674335 | BI51: 0.0082674335 | BJ51: -0.0085561497 | BK51: -0.016540813 | BL51: -0.058590942 | BM51: -0.029475198 | BN51: -0.034224599 | BO51: -0.023013305 | BP51: 0.024497258 | BQ51: 0.073310424 | BR51: 0.048888889 | BS51: 0.080841639 | BT51: 0.081339713 | BU51: 0.057815846 | BV51: 0.070793312 | BW51: 0.069915254 | BX51: 0.039275956 | BY51: -0.0030633084 | BZ51: -0.040148448 | CA51: -0.058139535 | CB51: -0.07029703 | CC51: -0.074268814 | CD51: -0.074268814 | CE51: -0.074268814 | CF51: -0.074268814 | CG51: -0.074268814 | CH51: -0.074268814 | CI51: -0.074268814 | CJ51: -0.074268814 | CK51: -0.074268814 | CL51: -0.074268814 | CM51: -0.074268814
AK52: % Giá chai B1 tuần sau so với tuần trước | AM52: -0.0019516729 | AN52: 0.0041903343 | AO52: -0.095646032 | AP52: 0 | AQ52: 0 | AR52: 0 | AS52: 0 | AT52: 0 | AU52: 0 | AV52: 0 | AW52: -0.044715447 | AX52: 0 | AY52: 0.037395451 | AZ52: 0.014794811 | BA52: 0.019367794 | BB52: -0.0073238572 | BC52: 0.012729718 | BD52: -0.01035381 | BE52: -0.079910267 | BF52: -0.0844465 | BG52: -0.00020721094 | BH52: 0.0060794473 | BI52: 0.0060794473 | BJ52: -0.0050127034 | BK52: -0.0053830228 | BL52: -0.013195164 | BM52: -0.011813472 | BN52: 0.02087482 | BO52: 0.036783989 | BP52: 0.044407438 | BQ52: 0.048655839 | BR52: 0.05033557 | BS52: 0.0078697787 | BT52: -0.0061905079 | BU52: -0.0041190539 | BV52: -0.00013352026 | BW52: 0.002329606 | BX52: -0.0043379605 | BY52: -0.0050234427 | BZ52: -0.009006004 | CA52: 0.04199773 | CB52: -0.045487748 | CC52: -0.063543133 | CD52: -0.063543133 | CE52: -0.063543133 | CF52: -0.063543133 | CG52: -0.063543133 | CH52: -0.063543133 | CI52: -0.063543133 | CJ52: -0.063543133 | CK52: -0.063543133 | CL52: -0.063543133 | CM52: -0.063543133
AK53: Chênh lệch | AL53: 445.34197 | AM53: 416.85385 | AN53: 383.61411 | AO53: 457.87234 | AP53: 457.87234 | AQ53: 427.87234 | AR53: 427.87234 | AS53: 397.87234 | AT53: 397.87234 | AU53: 367.87234 | AV53: 337.87234 | AW53: 324.26829 | AX53: -132.23171 | AY53: -175.14736 | AZ53: -185.44179 | BA53: -211.78422 | BB53: -194.51263 | BC53: -210.77484 | BD53: -252.11607 | BE53: -191.89104 | BF53: =BF54-BF47 -> 5784 | BG53: =BG54-BG47 -> 6248 | BH53: =BH54-BH47 -> 6370.2 | BI53: =BI54-BI47 -> 6445.4 | BJ53: =BJ54-BJ47 -> 6661 | BK53: =BK54-BK47 -> 6266.8 | BL53: =BL54-BL47 -> 6295 | BM53: =BM54-BM47 -> 6417.2 | ... CM53: =CM54-CM47 -> 6321.4
AK54: Giá chính phẩm | BF54: =BF56*BF45/1000 -> 22284 | BG54: =BG56*BG45/1000 -> 22748 | BH54: =BH56*BH45/1000 -> 22870.2 | BI54: =BI56*BI45/1000 -> 22945.4 | BJ54: =BJ56*BJ45/1000 -> 23161 | BK54: =BK56*BK45/1000 -> 22766.8 | BL54: =BL56*BL45/1000 -> 22795 | BM54: =BM56*BM45/1000 -> 22917.2 | ... CM54: =CM56*CM45/1000 -> 23321.4
AK55: Giá bale ĐNA USD | BF55: 495.7 | BG55: 495.7 | BH55: 495.7 | BI55: 495.7 | BJ55: 495.7 | BK55: 494.25 | BL55: 494.25 | BM55: 494.25 | BN55: 494.25 | BO55: 514.42 | BP55: 514.42 | BQ55: 514.42 | BR55: 514.42 | BS55: 551 | BT55: 551 | BU55: 551 | BV55: 551 | BW55: 569.88 | BX55: 569.88 | BY55: 569.88 | BZ55: 569.88 | CA55: 569.88 | CB55: 567.17 | CC55: 567.17 | CD55: 567.17 | CE55: 567.17 | CF55: 579.43 | CG55: 579.43 | CH55: 579.43 | CI55: 579.43 | CJ55: 579.43 | CK55: 579.43 | CL55: 579.43 | CM55: 579.43
AK56: Giá chính phẩm USD | BF56: 900 | BG56: 940 | BH56: 940 | BI56: 940 | BJ56: 950 | BK56: 940 | BL56: 940 | BM56: 940 | BN56: 940 | BO56: 940 | BP56: 940 | BQ56: 940 | BR56: 940 | BS56: 940 | BT56: 940 | BU56: 940 | BV56: 940 | BW56: 940 | BX56: 940 | BY56: 950 | BZ56: 950 | CA56: 950 | CB56: 950 | CC56: 950 | CD56: 950 | CE56: 950 | CF56: 950 | CG56: 940 | CH56: 940 | CI56: 940 | CJ56: 940 | CK56: 940 | CL56: 940 | CM56: 940
AK57: Giá mua chai B0 | BF57: 11099.755 | BG57: 11099.755 | BH57: 11099.755 | BI57: 11099.755 | BJ57: 11015.602 | BK57: 11015.602 | BL57: 11015.602 | BM57: 11015.602 | BN57: 11145.196 | BO57: 11145.196 | BP57: 11145.196 | BQ57: 11145.196 | BR57: 11145.196 | BS57: 11936.111 | BT57: 12163.111 | BU57: 12344.4 | BV57: 12384.111 | BW57: 12580.25 | BX57: 12764.889 | BY57: 12785.778 | BZ57: 12764.056 | CA57: 12808.067 | CB57: 12816.278 | CC57: 12793.5 | CD57: 12766.722 | CE57: 12278.111 | CF57: 11307.167 | CG57: 11044.611 | CH57: 11307.111 | CI57: 11363.81 | CJ57: 11350.278 | CK57: 11352.056 | CL57: 11366.889 | CM57: 11454.42
B69: Tháng | P69: T6 | X69: T12 | Z69: GAP giữa T6 & T12
B70: % chênh lệch giữa keo chính phẩm so với chai B1 | P70: 0.85859936 | X70: 0.49014925 | Z70: 0.36845011
E71: 1165, | F71: 1272.5, | P71: 1346, | Q71: 1297.5, | R71: 1316.66666666665,1390,1220,1270,1190,1130,1040,1040 | T71: 1270 | U71: 1190 | V71: 1130 | W71: 1040 | X71: 1040
V72: -13700
E73: 1165,1272.5,1346,1297.5,1316.66666666665,1390,1220,1270,1190,1130,1040,1040
E75: 1165 | F75: 1272.5 | P75: 1346 | Q75: 1297.5 | R75: 1316.6667 | S75: 1390 | T75: 1220 | U75: 1270 | V75: 1190 | W75: 1130 | X75: 1040 | Y75: 1040
B76: tỉ lệ | E76: 27960 | F76: 30540 | P76: 32304 | Q76: 31140 | R76: 31600 | S76: 33360 | T76: 29280 | U76: 30480 | V76: 28560 | W76: 27120 | X76: 24960 | Y76: 24960

Sheet 02. Vảy PET- Tháng
AR3: Data | AS3: 1.23 | AT3: 2 | AU3: 3 | AV3: 4 | AW3: 5 | AX3: 6 | AY3: 7 | AZ3: 8 | BA3: 9 | BB3: 10 | BC3: 11 | BD3: 12 | BE3: 1.24 | BF3: 2 | BG3: 3 | BH3: 4 | BI3: 5 | BJ3: 6 | BK3: 7 | BL3: 8 | BM3: 9 | BN3: 10 | BO3: 11 | BP3: 12 | BQ3: 1.25 | BR3: 2 | BS3: 3 | BT3: 4
AR4: Tỷ giá USD | AS4: 23250 | AT4: 23570 | AU4: 23260 | AV4: 23260 | AW4: 23295 | AX4: 23330 | AY4: 23380 | AZ4: 23840 | BA4: 23960 | BB4: 24280 | BC4: 24730 | BD4: 24930 | BE4: 24210 | BF4: 24250 | BG4: 24490 | BH4: 24690 | BI4: 25475 | BJ4: 25250 | BK4: 25270 | BL4: 25130 | BM4: ='01.Chai B1- Tháng'!CQ4 -> 24580 | BN4: ='01.Chai B1- Tháng'!CR4 -> 24410 | BO4: ='01.Chai B1- Tháng'!CS4 -> 25120 | BP4: ='01.Chai B1- Tháng'!CT4 -> 25140 | BQ4: ='01.Chai B1- Tháng'!CU4 -> 25290 | BR4: ='01.Chai B1- Tháng'!CV4 -> 25050 | BS4: ='01.Chai B1- Tháng'!CW4 -> 25400 | BT4: ='01.Chai B1- Tháng'!CX4 -> 25460
AR5: Giá keo chính phẩm | AS5: =C40*AS4/1000 -> 23250 | AT5: =D40*AT4/1000 -> 24630.65 | AU5: =E40*AU4/1000 -> 23725.2 | AV5: =F40*AV4/1000 -> 24539.3 | AW5: =G40*AW4/1000 -> 22689.33 | AX5: =H40*AX4/1000 -> 20880.35 | AY5: =I40*AY4/1000 -> 21112.14 | AZ5: =J40*AZ4/1000 -> 21885.12 | ... BT5: =AD40*BT4/1000 -> 20622.6
AR6: Giá duyệt mua vảy PET | AS6: 17500 | AT6: 17500 | AU6: 18500 | AV6: 18500 | AW6: 18500 | AX6: 17500 | AY6: 16000 | AZ6: 16000 | BA6: 16500 | BB6: 17500 | BC6: 18100 | BD6: 18100 | BE6: 18100 | BF6: =18500+100 -> 18600 | BG6: =18800+100 -> 18900 | BH6: 19300 | BI6: 19800 | BJ6: 19800 | BK6: 18300 | BL6: 18300 | BM6: =18300+350 -> 18650 | BN6: =18000+350 -> 18350 | BO6: =18000+350+200 -> 18550 | BP6: =18200+350 -> 18550 | BQ6: =18200+350 -> 18550 | BR6: =18500+350 -> 18850 | BS6: =19000+350+200 -> 19550 | BT6: =19700+350 -> 20050
AR7: Giá vảy ĐNA | AS7: =AS14*AS4/1000 -> 22227 | AT7: =AT14*AT4/1000 -> 22462.21 | AU7: =AU14*AU4/1000 -> 21980.7 | AV7: =AV14*AV4/1000 -> 21282.9 | AW7: =AW14*AW4/1000 -> 20336.535 | AX7: =AX14*AX4/1000 -> 19958.815 | AY7: =AY14*AY4/1000 -> 20001.59 | AZ7: =AZ14*AZ4/1000 -> 21587.12 | ... BT7: =BT14*BT4/1000 -> 25841.9
AR8: Giá vảy thể hiện | AS8: =AS6 -> 17500 | AT8: =AT6 -> 17500 | AU8: =AU6 -> 18500 | AV8: =AV6 -> 18500 | AW8: =AW6 -> 18500 | AX8: =AX6 -> 17500 | AY8: =AY6 -> 16000 | AZ8: =AZ6 -> 16000 | ... BT8: =BT6 -> 20050
AR9: Giá vảy PET thực tế mua trung bình | AS9: 17112 | AT9: 17235 | AU9: 17583 | AV9: 17672 | AW9: 17728 | AX9: 16972.6 | AY9: 15973.539 | AZ9: 15985.32 | BA9: 16507.339 | BB9: 16955.713 | BC9: 18100 | BD9: 18100 | BE9: 17941.908 | BF9: 18449 | BG9: 19187.723 | BH9: 19561.944 | BI9: 19772.974 | BJ9: 19648.515 | BK9: 17930.461 | BL9: 17951.517 | BM9: 18513.416 | BN9: 18183.756 | BO9: 18460.149 | BP9: 18501.388 | BQ9: 18242.041 | BR9: 19068.147 | BS9: 19530.409 | BT9: =BT6 -> 20050
AR10: % Keo chính phẩm so với vảy PET | AS10: =AS5/AS6-1 -> 0.32857143 | AT10: =AT5/AT6-1 -> 0.40746571 | AU10: =AU5/AU6-1 -> 0.28244324 | AV10: =AV5/AV6-1 -> 0.32644865 | AW10: =AW5/AW6-1 -> 0.22645027 | AX10: =AX5/AX6-1 -> 0.19316286 | AY10: =AY5/AY6-1 -> 0.31950875 | AZ10: =AZ5/AZ6-1 -> 0.36782 | ... BT10: =BT5/BT6-1 -> 0.028558603
AR11: Chênh lệch | AS11: =AS5-AS6 -> 5750 | AT11: =AT5-AT6 -> 7130.65 | AU11: =AU5-AU6 -> 5225.2 | AV11: =AV5-AV6 -> 6039.3 | AW11: =AW5-AW6 -> 4189.33 | AX11: =AX5-AX6 -> 3380.35 | AY11: =AY5-AY6 -> 5112.14 | AZ11: =AZ5-AZ6 -> 5885.12 | ... BT11: =BT5-BT6 -> 572.6
AR12: Giá bán rPET | AS12: 1330 | AT12: 1330 | AU12: 1380 | AV12: 1380 | AW12: 1380 | AX12: 1350 | AY12: 1300 | AZ12: 1250 | BA12: 1250 | BB12: 1250 | BC12: 1250 | BD12: 1250 | BE12: 1250 | BF12: 1250 | BG12: 1250 | BH12: 1250 | BI12: 1300 | BJ12: 1300 | BK12: 1300 | BL12: 1300
AR13: Giá chính phẩm dự báo | AS13: =AS5 -> 23250 | AT13: =AT5 -> 24630.65 | AU13: =AU5 -> 23725.2 | AV13: =AV5 -> 24539.3 | AW13: =AW5 -> 22689.33 | AX13: =AX5 -> 20880.35 | AY13: =AY5 -> 21112.14 | AZ13: =AZ5 -> 21885.12 | ... BT13: =BT5 -> 20622.6
AR14: Giá vảy ĐNA (usd) | AS14: 956 | AT14: 953 | AU14: 945 | AV14: 915 | AW14: 873 | AX14: =+(851+860)/2 -> 855.5 | AY14: =+(851+860)/2 -> 855.5 | AZ14: =(859+952)/2 -> 905.5 | BA14: =(825+941)/2 -> 883 | BB14: =(825+927)/2 -> 876 | BC14: =(840+945)/2 -> 892.5 | BD14: =(840+945)/2 -> 892.5 | BE14: =(840+955)/2 -> 897.5 | BF14: =(840+955)/2 -> 897.5 | BG14: =(840+955)/2 -> 897.5 | BH14: =(860+955)/2 -> 907.5 | BI14: 955 | BJ14: 1015 | BK14: 995 | BL14: 995 | BM14: 1020 | BN14: 1020 | BO14: 1020 | BP14: 1025 | BQ14: 1025 | BR14: 1010 | BS14: 1012.5 | BT14: 1015
K29: -13700
C30: 1165,1272.5,1346,1297.5,1316.66666666665,1390,1220,1270,1190,1130,1040,1040
C32: 1165 | D32: 1272.5 | E32: 1346 | F32: 1297.5 | G32: 1316.6667 | H32: 1390 | I32: 1220 | J32: 1270 | K32: 1190 | L32: 1130 | M32: 1040 | N32: 1040
B33: tỉ lệ | C33: 27960 | D33: 30540 | E33: 32304 | F33: 31140 | G33: 31600 | H33: 33360 | I33: 29280 | J33: 30480 | K33: 28560 | L33: 27120 | M33: 24960 | N33: 24960
B39: Tháng | C39: 01/23 | D39: 2 | E39: 3 | F39: 4 | G39: 5 | H39: 6 | I39: 7 | J39: 8 | K39: 9 | L39: 10 | M39: 11 | N39: 12 | O39: 1.24 | P39: 2 | Q39: 3 | R39: 4 | S39: 5 | T39: 6 | U39: 7 | V39: 8 | W39: 9 | X39: 10 | Y39: 11 | Z39: 12 | AA39: 1.25 | AB39: 2 | AC39: 3 | AD39: 4
B40: Giá Resin (USD/ Tấn) | C40: 1000 | D40: 1045 | E40: 1020 | F40: 1055 | G40: 974 | H40: 895 | I40: 903 | J40: 918 | K40: 930 | L40: 922.5 | M40: 900 | N40: 900 | O40: 930 | P40: 943 | Q40: 940 | R40: 940 | S40: 942 | T40: 950 | U40: 948 | V40: 930 | W40: 880 | X40: 862.5 | Y40: 852 | Z40: 830 | AA40: 828 | AB40: 840 | AC40: 823 | AD40: 810

Sheet Chart Vảy PET_Tuần
V45: Data | W45: 1 | X45: 2 | Y45: 3 | Z45: 4 | AA45: 5 | AB45: 6 | AC45: 7 | AD45: 8 | AE45: 9 | AF45: 10 | AG45: 11 | AH45: 12 | AI45: 13 | AJ45: 14 | AK45: 15 | AL45: 16 | AM45: 17 | AN45: 18 | AO45: 19 | AP45: 20 | AQ45: 21 | AR45: 22 | AS45: 23 | AT45: 24 | AU45: 25 | AV45: 26 | AW45: 27 | AX45: 28 | AY45: 29 | AZ45: 30 | BA45: 31 | BB45: 32 | BC45: 33 | BD45: 34
V46: Tỷ giá USD | W46: ='Chart B1_Tuần'!BF45 -> 24760 | X46: ='Chart B1_Tuần'!BG45 -> 24200 | Y46: ='Chart B1_Tuần'!BH45 -> 24330 | Z46: ='Chart B1_Tuần'!BI45 -> 24410 | AA46: ='Chart B1_Tuần'!BJ45 -> 24380 | AB46: ='Chart B1_Tuần'!BK45 -> 24220 | AC46: ='Chart B1_Tuần'!BL45 -> 24250 | AD46: ='Chart B1_Tuần'!BM45 -> 24380 | ... BE46: ='Chart B1_Tuần'!CN45 -> 0
V47: Giá keo chính phẩm | W47: =W46*W53/1000 -> 22284 | X47: =X46*X53/1000 -> 22748 | Y47: =Y46*Y53/1000 -> 22870.2 | Z47: =Z46*Z53/1000 -> 22945.4 | AA47: =AA46*AA53/1000 -> 23161 | AB47: =AB46*AB53/1000 -> 22766.8 | AC47: =AC46*AC53/1000 -> 22795 | AD47: =AD46*AD53/1000 -> 22917.2 | ... BD47: =BD46*BD53/1000 -> 23321.4
V48: Giá duyệt mua vảy PET | W48: 18000 | X48: 18000 | Y48: 18000 | Z48: 18000 | AA48: 18500 | AB48: 18500 | AC48: 18500 | AD48: 18500 | AE48: 18500 | AF48: 18500 | AG48: 18500 | AH48: 18500 | AI48: 18500 | AJ48: 19000 | AK48: 19000 | AL48: 19000 | AM48: 19000 | AN48: 19500 | AO48: 19500 | AP48: 19500 | AQ48: 19500 | AR48: 19500 | AS48: 19500 | AT48: 19500 | AU48: 19500 | AV48: 19500 | AW48: 18000 | AX48: 18000 | AY48: 18000 | AZ48: 18000 | BA48: 18000 | BB48: 18000 | BC48: 18000 | BD48: 18000
V49: Giá vảy PET thể hiện | W49: =W48 -> 18000 | X49: =X48 -> 18000 | Y49: =Y48 -> 18000 | Z49: =Z48 -> 18000 | AA49: =AA48 -> 18500 | AB49: =AB48 -> 18500 | AC49: =AC48 -> 18500 | AD49: =AD48 -> 18500 | ... BD49: =BD48 -> 18000
V50: Giá vảy PET thực tế mua trung bình | W50: 17788.268 | X50: 17828.592 | Y50: 17854.223 | Z50: 17920.599 | AA50: 17910.699 | AB50: 17862.172 | AC50: 17862.172 | AD50: 17947.186 | AE50: 18173.051 | AF50: 18673.486 | AG50: 18747.334 | AH50: 18761.632 | AI50: 18757.926 | AJ50: 19026.001 | AK50: 18925.617 | AL50: 18914.749 | AM50: 18943.065 | AN50: 19077.338 | AO50: 19443.202 | AP50: 19415.534 | AQ50: 19403.916 | AR50: 19281.645 | AS50: 19318.549 | AT50: 19421.069 | AU50: 19388.157 | AV50: 19218.54 | AW50: 17763.704 | AX50: 17851.469 | AY50: 17795.9 | AZ50: 17825.036 | BA50: 17796.164 | BB50: 17664.788 | BC50: 17690.789 | BD50: 17605.585
V51: % chính phẩm với vảy PET | W51: =W52/W48 -> 0.238 | X51: =X52/X48 -> 0.26377778 | Y51: =Y52/Y48 -> 0.27056667 | Z51: =Z52/Z48 -> 0.27474444 | AA51: =AA52/AA48 -> 0.25194595 | AB51: =AB52/AB48 -> 0.23063784 | AC51: =AC52/AC48 -> 0.23216216 | AD51: =AD52/AD48 -> 0.23876757 | ... BD51: =BD52/BD48 -> 0.29563333
V52: Chênh lệch | W52: =W47-W48 -> 4284 | X52: =X47-X48 -> 4748 | Y52: =Y47-Y48 -> 4870.2 | Z52: =Z47-Z48 -> 4945.4 | AA52: =AA47-AA48 -> 4661 | AB52: =AB47-AB48 -> 4266.8 | AC52: =AC47-AC48 -> 4295 | AD52: =AD47-AD48 -> 4417.2 | ... BD52: =BD47-BD48 -> 5321.4
V53: Giá chính phẩm USD | W53: ='Chart B1_Tuần'!BF56 -> 900 | X53: ='Chart B1_Tuần'!BG56 -> 940 | Y53: ='Chart B1_Tuần'!BH56 -> 940 | Z53: ='Chart B1_Tuần'!BI56 -> 940 | AA53: ='Chart B1_Tuần'!BJ56 -> 950 | AB53: ='Chart B1_Tuần'!BK56 -> 940 | AC53: ='Chart B1_Tuần'!BL56 -> 940 | AD53: ='Chart B1_Tuần'!BM56 -> 940 | ... BD53: ='Chart B1_Tuần'!CM56 -> 940
B67: Tháng | P67: T6
B68: % chênh lệch giữa keo chính phẩm so với chai B1 | P68: 0.85859936
C69: 1165, | O69: 1272.5, | P69: 1346, | Q69: 1297.5, | R69: 1316.66666666665,1390,1220,1270,1190,1130,1040,1040 | T69: 1270
C71: 1165,1272.5,1346,1297.5,1316.66666666665,1390,1220,1270,1190,1130,1040,1040
C73: 1165 | O73: 1272.5 | P73: 1346 | Q73: 1297.5 | R73: 1316.6667 | S73: 1390 | T73: 1220
B74: tỉ lệ | C74: 27960 | O74: 30540 | P74: 32304 | Q74: 31140 | R74: 31600 | S74: 33360 | T74: 29280

Sheet 03. HDPE- Tháng
AP3: Data | AQ3: 1.23 | AR3: 2 | AS3: 3 | AT3: 4 | AU3: 5 | AV3: 6 | AW3: 7 | AX3: 8 | AY3: 9 | AZ3: 10 | BA3: 11 | BB3: 12 | BC3: 1.24 | BD3: 2 | BE3: 3 | BF3: 4 | BG3: 5 | BH3: 6 | BI3: 7 | BJ3: 8 | BK3: 9 | BL3: 10 | BM3: 11 | BN3: 12 | BO3: 1.25 | BP3: 2 | BQ3: 3 | BR3: 4
AP4: Tỷ giá USD | AQ4: 23250 | AR4: 23570 | AS4: 23260 | AT4: 23260 | AU4: 23295 | AV4: 23330 | AW4: 23380 | AX4: 23840 | AY4: 23960 | AZ4: 24280 | BA4: 24730 | BB4: 24930 | BC4: 24210 | BD4: 24250 | BE4: 24490 | BF4: 24690 | BG4: 25475 | BH4: 25250 | BI4: 25270 | BJ4: 25130 | BK4: ='01.Chai B1- Tháng'!CQ4 -> 24580 | BL4: ='01.Chai B1- Tháng'!CR4 -> 24410 | BM4: ='01.Chai B1- Tháng'!CS4 -> 25120 | BN4: ='01.Chai B1- Tháng'!CT4 -> 25140 | BO4: ='01.Chai B1- Tháng'!CU4 -> 25290 | BP4: ='01.Chai B1- Tháng'!CV4 -> 25050 | BQ4: ='01.Chai B1- Tháng'!CW4 -> 25400 | BR4: ='01.Chai B1- Tháng'!CX4 -> 25460
AP5: Giá keo chính phẩm | AQ5: =C37*AQ4/1000 -> 23656.875 | AR5: =D37*AR4/1000 -> 25750.225 | AS5: =E37*AS4/1000 -> 24946.35 | AT5: =F37*AT4/1000 -> 24423 | AU5: =G37*AU4/1000 -> 24319.98 | AV5: =H37*AV4/1000 -> 22630.1 | AW5: =I37*AW4/1000 -> 22444.8 | AX5: =J37*AX4/1000 -> 24030.72 | ... BR5: =AD37*BR4/1000 -> 22812.16
AP6: Giá duyệt mua vảy HDPE | AQ6: 21500 | AR6: 21500 | AS6: 21500 | AT6: 21500 | AU6: 21500 | AV6: 23000 | AW6: 23000 | AX6: 22500 | AY6: 22500 | AZ6: 22500 | BA6: 22500 | BB6: 22500 | BC6: 22500 | BD6: 22500 | BE6: 22000 | BF6: 22000 | BG6: 22000 | BH6: 22000 | BI6: 22000 | BJ6: 22000 | BK6: 22000 | BL6: 22000 | BM6: 21500 | BN6: 21500 | BO6: 21500 | BP6: 21500 | BQ6: 21500 | BR6: 21500
AP7: Giá vảy thể hiện | AQ7: =AQ6 -> 21500 | AR7: =AR6 -> 21500 | AS7: =AS6 -> 21500 | AT7: =AT6 -> 21500 | AU7: =AU6 -> 21500 | AV7: =AV6 -> 23000 | AW7: =AW6 -> 23000 | AX7: =AX6 -> 22500 | ... BR7: =BR6 -> 21500
AP8: Giá vảy HDPE thực tế mua trung bình | AQ8: 21459.854 | AR8: 21913.814 | AS8: 23693.617 | AT8: 23254.478 | AU8: 21149.963 | AV8: 22556.707 | AW8: 21609.954 | AX8: 22500 | AY8: 21919.955 | AZ8: 22500 | BA8: 21972.366 | BB8: 21437.84 | BC8: 21039.935 | BD8: 20908.249 | BE8: 20865.772 | BF8: 20642.052 | BG8: 20686.277 | BH8: 21223.584 | BI8: 21243.396 | BJ8: 21527.191 | BK8: 21819.831 | BL8: 21769.364 | BM8: 21713.979 | BN8: 19595.344 | BO8: 21500 | BP8: 21500 | BQ8: 21500 | BR8: 21500
AP9: % Keo chính phẩm so với vảy HDPE | AQ9: =AQ5/AQ6-1 -> 0.10031977 | AR9: =AR5/AR6-1 -> 0.19768488 | AS9: =AS5/AS6-1 -> 0.16029535 | AT9: =AT5/AT6-1 -> 0.13595349 | AU9: =AU5/AU6-1 -> 0.13116186 | AV9: =AV5/AV6-1 -> -0.016082609 | AW9: =AW5/AW6-1 -> -0.02413913 | AX9: =AX5/AX6-1 -> 0.068032 | ... BR9: =BR5/BR6-1 -> 0.061030698
AP10: Chênh lệch | AQ10: =AQ5-AQ6 -> 2156.875 | AR10: =AR5-AR6 -> 4250.225 | AS10: =AS5-AS6 -> 3446.35 | AT10: =AT5-AT6 -> 2923 | AU10: =AU5-AU6 -> 2819.98 | AV10: =AV5-AV6 -> -369.9 | AW10: =AW5-AW6 -> -555.2 | AX10: =AX5-AX6 -> 1530.72 | ... BR10: =BR5-BR6 -> 1312.16
AP11: Giá bán rHDPE | AQ11: 1400 | AR11: 1400 | AS11: 1400 | AT11: 1530 | AU11: 1530 | AV11: 1530 | AW11: 1450 | AX11: 1400 | AY11: 1400 | AZ11: 1400 | BA11: 1400 | BB11: 1400 | BC11: 1400 | BD11: 1400 | BE11: 1400 | BF11: 1400 | BG11: 1400 | BH11: 1400 | BI11: 1400 | BJ11: 1400 | BK11: 1400 | BL11: 1400 | BM11: 1400 | BN11: 1400 | BO11: 1400 | BP11: 1400 | BQ11: 1400 | BR11: 1400
AP12: Giá chính phẩm dự báo | AQ12: =AQ5 -> 23656.875 | AR12: =AR5 -> 25750.225 | AS12: =AS5 -> 24946.35 | AT12: =AT5 -> 24423 | AU12: =AU5 -> 24319.98 | AV12: =AV5 -> 22630.1 | AW12: =AW5 -> 22444.8 | AX12: =AX5 -> 24030.72 | ... BR12: =BR5 -> 22812.16
AP13: Giá vảy ĐNA (USD) | AQ13: 779.5 | AR13: 785.25 | AS13: 763 | AT13: 802.25 | AU13: 804.38 | AV13: 749.25 | AW13: 719.94 | AX13: 714.7 | AY13: 723.13 | AZ13: 721.69 | BA13: 730.15 | BB13: 738.25 | BC13: 733.5 | BD13: 725.75 | BE13: 722.25 | BF13: 727 | BG13: 716.75
B36: Tháng | C36: 01/23 | D36: 2 | E36: 3 | F36: 4 | G36: 5 | H36: 6 | I36: 7 | J36: 8 | K36: 9 | L36: 10 | M36: 11 | N36: 12 | O36: 1.24 | P36: 2 | Q36: 3 | R36: 4 | S36: 5 | T36: 6 | U36: 7 | V36: 8 | W36: 9 | X36: 10 | Y36: 11 | Z36: 12 | AA36: 1.25 | AB36: 2 | AC36: 3 | AD36: 4
B37: Giá Resin (USD/ Tấn) | C37: 1017.5 | D37: 1092.5 | E37: 1072.5 | F37: 1050 | G37: 1044 | H37: 970 | I37: 960 | J37: 1008 | K37: 1027.5 | L37: 1020 | M37: 955 | N37: 928 | O37: 940 | P37: 990 | Q37: 985 | R37: 963 | S37: 982 | T37: 1000 | U37: 1000 | V37: 984 | W37: 968 | X37: 965 | Y37: 974 | Z37: 956 | AA37: 940 | AB37: 918 | AC37: 896 | AD37: 896

Sheet Chart HDPE_Tuần
AK48: Data | AL48: 1 | AM48: 2 | AN48: 3 | AO48: 4 | AP48: 5 | AQ48: 6 | AR48: 7 | AS48: 8 | AT48: 9 | AU48: 10 | AV48: 11 | AW48: 12 | AX48: 13 | AY48: 14 | AZ48: 15 | BA48: 16 | BB48: 17 | BC48: 18 | BD48: 19 | BE48: 20 | BF48: 21 | BG48: 22 | BH48: 23 | BI48: 24 | BJ48: 25 | BK48: 26 | BL48: 27 | BM48: 28 | BN48: 29 | BO48: 30 | BP48: 31 | BQ48: 32 | BR48: 33 | BS48: 34 | BT48: 35 | BU48: 36 | BV48: 37 | BW48: 38
AK49: Tỷ giá USD | AL49: ='Chart Vảy PET_Tuần'!W46 -> 24760 | AM49: ='Chart Vảy PET_Tuần'!X46 -> 24200 | AN49: ='Chart Vảy PET_Tuần'!Y46 -> 24330 | AO49: ='Chart Vảy PET_Tuần'!Z46 -> 24410 | AP49: ='Chart Vảy PET_Tuần'!AA46 -> 24380 | AQ49: ='Chart Vảy PET_Tuần'!AB46 -> 24220 | AR49: ='Chart Vảy PET_Tuần'!AC46 -> 24250 | AS49: ='Chart Vảy PET_Tuần'!AD46 -> 24380 | ... BW49: ='Chart Vảy PET_Tuần'!BH46 -> 0
AK50: Giá keo chính phẩm | AL50: =AL57*AL49/1000 -> 22779.2 | AM50: =AM57*AM49/1000 -> 22990 | AN50: =AN57*AN49/1000 -> 23113.5 | AO50: =AO57*AO49/1000 -> 23677.7 | AP50: =AP57*AP49/1000 -> 23892.4 | AQ50: =AQ57*AQ49/1000 -> 24220 | AR50: =AR57*AR49/1000 -> 24250 | AS50: =AS57*AS49/1000 -> 24380 | ... BS50: =BS57*BS49/1000 -> 24065.7
AK51: Giá duyệt mua vảy HDPE | AL51: 22500 | AM51: 22500 | AN51: 22500 | AO51: 22500 | AP51: 22500 | AQ51: 22500 | AR51: 22500 | AS51: 22500 | AT51: 22000 | AU51: 22000 | AV51: 22000 | AW51: 22000 | AX51: 22000 | AY51: 22000 | AZ51: 22000 | BA51: 22000 | BB51: 22000 | BC51: 22000 | BD51: 22000 | BE51: 22000 | BF51: 22000 | BG51: 22000 | BH51: 22000 | BI51: 22000 | BJ51: 22000 | BK51: 22000 | BL51: 22000 | BM51: 22000 | BN51: 22000 | BO51: 22000 | BP51: 22000 | BQ51: 22000 | BR51: 22000 | BS51: 22000
AK52: Giá chai B1 (VND) | AL52: 14478 | AM52: 14475 | AN52: 14563 | AP52: 14490 | AQ52: 14412 | AR52: 14284 | AS52: 14304 | AT52: 14867 | AU52: 15023 | AV52: 15052 | AW52: 14979 | AX52: 15024 | AY52: 14984 | AZ52: 14930 | BA52: 14990 | BB52: 14977 | BC52: 15059 | BD52: 14919 | BE52: 14855 | BF52: 14855 | BG52: 15606 | BH52: 14374 | BI52: 13971 | BJ52: 13972 | BK52: 13973
AK53: Giá vảy HDPE thể hiện | AL53: =AL51 -> 22500 | AM53: =AM51 -> 22500 | AN53: =AN51 -> 22500 | AO53: =AO51 -> 22500 | AP53: =AP51 -> 22500 | AQ53: =AQ51 -> 22500 | AR53: =AR51 -> 22500 | AS53: =AS51 -> 22500 | ... BS53: =BS51 -> 22000
AK54: Giá vảy HDPE thực tế mua trung bình | AL54: 19562.767 | AM54: 21250.051 | AN54: 21289.924 | AO54: 20703.298 | AP54: 21219.147 | AQ54: 20903.511 | AR54: 20903.511 | AS54: 21130.708 | AT54: 20482.665 | AU54: 20918.067 | AV54: 20783.794 | AW54: 20829.489 | AX54: 21098.585 | AY54: 20626.811 | AZ54: 20556.872 | BA54: 20627.343 | BB54: 20654.791 | BC54: 20800 | BD54: 20910.271 | BE54: 20428.294 | BF54: 20745.82 | BG54: 20769.394 | BH54: 21233.117 | BI54: 21200 | BJ54: 21229.627 | BK54: 21226.434 | BL54: 21200 | BM54: 21246.761 | BN54: 21243.721 | BO54: 21262.867 | BP54: 21200 | BQ54: 21517.662 | BR54: 21200 | BS54: 21863.485
AK55: % chính phẩm với vảy HDPE | AL55: =AL56/AL51 -> 0.012408889 | AM55: =AM56/AM51 -> 0.021777778 | AN55: =AN56/AN51 -> 0.027266667 | AO55: =AO56/AO51 -> 0.052342222 | AP55: =AP56/AP51 -> 0.061884444 | AQ55: =AQ56/AQ51 -> 0.076444444 | AR55: =AR56/AR51 -> 0.077777778 | AS55: =AS56/AS51 -> 0.083555556 | ... BS55: =BS56/BS51 -> 0.093895455
AK56: Chênh lệch | AL56: =AL50-AL51 -> 279.2 | AM56: =AM50-AM51 -> 490 | AN56: =AN50-AN51 -> 613.5 | AO56: =AO50-AO51 -> 1177.7 | AP56: =AP50-AP51 -> 1392.4 | AQ56: =AQ50-AQ51 -> 1720 | AR56: =AR50-AR51 -> 1750 | AS56: =AS50-AS51 -> 1880 | ... BS56: =BS50-BS51 -> 2065.7
AK57: Giá chính phẩm USD | AL57: 920 | AM57: 950 | AN57: 950 | AO57: 970 | AP57: 980 | AQ57: 1000 | AR57: 1000 | AS57: 1000 | AT57: 1000 | AU57: 1000 | AV57: 980 | AW57: 980 | AX57: 980 | AY57: 960 | AZ57: 960 | BA57: 960 | BB57: 970 | BC57: 970 | BD57: 980 | BE57: 980 | BF57: 980 | BG57: 1000 | BH57: 1000 | BI57: 1000 | BJ57: 1000 | BK57: 1000 | BL57: 1000 | BM57: 1000 | BN57: 1000 | BO57: 1000 | BP57: 1000 | BQ57: 1000 | BR57: 980 | BS57: 970
B72: Tháng | P72: T6 | X72: T12 | Z72: GAP giữa T6 & T12
B73: % chênh lệch giữa keo chính phẩm so với chai B1 | P73: 0.85859936 | X73: 0.49014925 | Z73: 0.36845011
N74: 1165, | O74: 1272.5, | P74: 1346, | Q74: 1297.5, | R74: 1316.66666666665,1390,1220,1270,1190,1130,1040,1040 | T74: 1270 | U74: 1190 | V74: 1130 | W74: 1040 | X74: 1040
V75: -13700
N76: 1165,1272.5,1346,1297.5,1316.66666666665,1390,1220,1270,1190,1130,1040,1040
N78: 1165 | O78: 1272.5 | P78: 1346 | Q78: 1297.5 | R78: 1316.6667 | S78: 1390 | T78: 1220 | U78: 1270 | V78: 1190 | W78: 1130 | X78: 1040 | Y78: 1040
B79: tỉ lệ | N79: 27960 | O79: 30540 | P79: 32304 | Q79: 31140 | R79: 31600 | S79: 33360 | T79: 29280 | U79: 30480 | V79: 28560 | W79: 27120 | X79: 24960 | Y79: 24960

Sheet 04. PP- Tháng
AP3: Data | AQ3: 1.23 | AR3: 2 | AS3: 3 | AT3: 4 | AU3: 5 | AV3: 6 | AW3: 7 | AX3: 8 | AY3: 9 | AZ3: 10 | BA3: 11 | BB3: 12 | BC3: 1.24 | BD3: 2 | BE3: 3 | BF3: 4 | BG3: 5 | BH3: 6 | BI3: 7 | BJ3: 8 | BK3: 9 | BL3: 10 | BM3: 11 | BN3: 12 | BO3: 1.25 | BP3: 2 | BQ3: 3 | BR3: 4
AP4: Tỷ giá USD | AQ4: 23250 | AR4: 23570 | AS4: 23260 | AT4: 23260 | AU4: 23295 | AV4: 23330 | AW4: 23380 | AX4: 23840 | AY4: 23960 | AZ4: 24280 | BA4: 24730 | BB4: 24930 | BC4: 24210 | BD4: 24250 | BE4: 24490 | BF4: 24690 | BG4: 25475 | BH4: 25250 | BI4: 25270 | BJ4: 25130 | BK4: ='01.Chai B1- Tháng'!CQ4 -> 24580 | BL4: ='01.Chai B1- Tháng'!CR4 -> 24410 | BM4: ='01.Chai B1- Tháng'!CS4 -> 25120 | BN4: ='01.Chai B1- Tháng'!CT4 -> 25140 | BO4: ='01.Chai B1- Tháng'!CU4 -> 25290 | BP4: ='01.Chai B1- Tháng'!CV4 -> 25050 | BQ4: ='01.Chai B1- Tháng'!CW4 -> 25400 | BR4: ='01.Chai B1- Tháng'!CX4 -> 25460
AP5: Giá keo chính phẩm | AQ5: =C37*AQ4/1000 -> 24296.25 | AR5: =D37*AR4/1000 -> 25632.375 | AS5: =E37*AS4/1000 -> 24190.4 | AT5: =F37*AT4/1000 -> 23899.65 | AU5: =G37*AU4/1000 -> 22537.912 | AV5: =H37*AV4/1000 -> 20705.375 | AW5: =I37*AW4/1000 -> 21042 | AX5: =J37*AX4/1000 -> 22838.72 | ... BR5: =AD37*BR4/1000 -> 24950.8
AP6: Giá duyệt mua PP | AQ6: 16000 | AR6: 16000 | AS6: 16000 | AT6: 16000 | AU6: 16000 | AV6: 16000 | AW6: 16000 | AX6: 16000 | AY6: 16000 | AZ6: 16000 | BA6: 16000 | BB6: 16000 | BC6: 16000 | BD6: 16000 | BE6: 16000 | BF6: 16000 | BG6: 16000 | BH6: 16000 | BI6: 16000 | BJ6: 16000 | BK6: 16000 | BL6: 16000 | BM6: 16000 | BN6: 16000 | BO6: 18500 | BP6: 19000 | BQ6: 19000 | BR6: 19000
AP7: Giá PP ĐNA | AQ7: =AQ14*AQ4/1000 -> 10776.375 | AR7: =AR14*AR4/1000 -> 10641.855 | AS7: =AS14*AS4/1000 -> 10970.967 | AT7: =AT14*AT4/1000 -> 11668.767 | AU7: =AU14*AU4/1000 -> 11006.888 | AV7: =AV14*AV4/1000 -> 10599.597 | AW7: =AW14*AW4/1000 -> 10622.313 | AX7: =AX14*AX4/1000 -> 10831.307 | AY7: =AY14*AY4/1000 -> 10885.827
AP8: Giá PP thực tế mua trung bình | AQ8: 12425.041 | AR8: 14989.244 | AS8: 14008.541 | AT8: 14615.755 | AV8: 14005.42 | AW8: 13649.971 | AX8: 14742.557 | AY8: 14761.513 | AZ8: 15600.855 | BA8: 14540.123 | BB8: 16000 | BC8: 15533.659 | BD8: 15648.437 | BE8: 15420.187 | BF8: 15972.617 | BG8: 15813.837 | BH8: 15714.946 | BI8: 15790.001 | BJ8: 15000 | BK8: 16000 | BL8: 16000 | BM8: 16000 | BN8: 16000 | BO8: =BO6 -> 18500 | BP8: 18500 | BQ8: 19000 | BR8: =BR6 -> 19000
AP9: Giá PP thể hiện | AQ9: =AQ6 -> 16000 | AR9: =AR6 -> 16000 | AS9: =AS6 -> 16000 | AT9: =AT6 -> 16000 | AU9: =AU6 -> 16000 | AV9: =AV6 -> 16000 | AW9: =AW6 -> 16000 | AX9: =AX6 -> 16000 | ... BR9: =BR6 -> 19000
AP10: % Keo chính phẩm so với PP | AQ10: =AQ11/AQ13 -> 0.34146216 | AR10: =AR11/AR13 -> 0.37578941 | AS10: =AS11/AS13 -> 0.33858059 | AT10: =AT11/AT13 -> 0.33053413 | AU10: =AU11/AU13 -> 0.2900851 | AV10: =AV11/AV13 -> 0.22725379 | AW10: =AW11/AW13 -> 0.23961601 | AX10: =AX11/AX13 -> 0.29943534 | ... BR10: =BR11/BR13 -> 0.23850137
AP11: Chênh lệch | AQ11: =AQ5-AQ6 -> 8296.25 | AR11: =AR5-AR6 -> 9632.375 | AS11: =AS5-AS6 -> 8190.4 | AT11: =AT5-AT6 -> 7899.65 | AU11: =AU5-AU6 -> 6537.9125 | AV11: =AV5-AV6 -> 4705.375 | AW11: =AW5-AW6 -> 5042 | AX11: =AX5-AX6 -> 6838.72 | ... BR11: =BR5-BR6 -> 5950.8
AP12: Giá bán rPP | AQ12: 1100 | AR12: 1100 | AS12: 1100 | AT12: 1100 | AU12: 1087.5 | AV12: 1050 | AW12: 1050 | AX12: 950 | AY12: 950 | AZ12: 950 | BA12: 950 | BB12: 950 | BC12: 930
AP13: Giá chính phẩm dự báo | AQ13: =AQ5 -> 24296.25 | AR13: =AR5 -> 25632.375 | AS13: =AS5 -> 24190.4 | AT13: =AT5 -> 23899.65 | AU13: =AU5 -> 22537.912 | AV13: =AV5 -> 20705.375 | AW13: =AW5 -> 21042 | AX13: =AX5 -> 22838.72 | ... BR13: =BR5 -> 24950.8
AP14: Giá PP ĐNA (USD) | AQ14: 463.5 | AR14: 451.5 | AS14: 471.66667 | AT14: 501.66667 | AU14: 472.5 | AV14: 454.33333 | AW14: 454.33333 | AX14: 454.33333 | AY14: 454.33333
B36: Tháng | C36: 1 | D36: 2 | E36: 3 | F36: 4 | G36: 5 | H36: 6 | I36: 7 | J36: 8 | K36: 9 | L36: 10 | M36: 11 | N36: 12 | O36: 1.24 | P36: 2 | Q36: 3 | R36: 4 | S36: 5 | T36: 6 | U36: 7 | V36: 8 | W36: 9 | X36: 10 | Y36: 11 | Z36: 12 | AA36: 1.25 | AB36: 2 | AC36: 3 | AD36: 4
B37: Giá Resin (USD/ Tấn) | C37: 1045 | D37: 1087.5 | E37: 1040 | F37: 1027.5 | G37: 967.5 | H37: 887.5 | I37: 900 | J37: 958 | K37: 980 | L37: 967.5 | M37: 927.5 | N37: 926 | O37: 962.5 | P37: 986.66667 | Q37: 990 | R37: 993 | S37: 1002 | T37: 1025 | U37: 1020 | V37: 970 | W37: 955 | X37: 957 | Y37: 968 | Z37: 960 | AA37: 970 | AB37: 985 | AC37: 980 | AD37: 980

Sheet Chart PP- Tuần
Z3: Data | AA3: 1 | AB3: 2 | AC3: 3 | AD3: 4 | AE3: 5 | AF3: 6 | AG3: 7 | AH3: 8 | AI3: 9 | AJ3: 10 | AK3: 11 | AL3: 12 | AM3: 13 | AN3: 14 | AO3: 15 | AP3: 16 | AQ3: 17 | AR3: 18 | AS3: 19 | AT3: 20 | AU3: 21 | AV3: 22 | AW3: 23 | AX3: 24 | AY3: 25 | AZ3: 26 | BA3: 27 | BB3: 28 | BC3: 29 | BD3: 30 | BE3: 31 | BF3: 32 | BG3: 33 | BH3: 34 | BI3: 35 | BJ3: 36 | BK3: 37 | BL3: 38
Z4: Tỷ giá USD | AA4: ='Chart HDPE_Tuần'!AL49 -> 24760 | AB4: ='Chart HDPE_Tuần'!AM49 -> 24200 | AC4: ='Chart HDPE_Tuần'!AN49 -> 24330 | AD4: ='Chart HDPE_Tuần'!AO49 -> 24410 | AE4: ='Chart HDPE_Tuần'!AP49 -> 24380 | AF4: ='Chart HDPE_Tuần'!AQ49 -> 24220 | AG4: ='Chart HDPE_Tuần'!AR49 -> 24250 | AH4: ='Chart HDPE_Tuần'!AS49 -> 24380 | ... BG4: ='Chart HDPE_Tuần'!BR49 -> 24970
Z5: Giá keo chính phẩm | AA5: =AA12*AA4/1000 -> 23026.8 | AB5: =AB12*AB4/1000 -> 23474 | AC5: =AC12*AC4/1000 -> 23600.1 | AD5: =AD12*AD4/1000 -> 23921.8 | AE5: =AE12*AE4/1000 -> 24380 | AF5: =AF12*AF4/1000 -> 23735.6 | AG5: =AG12*AG4/1000 -> 23765 | AH5: =AH12*AH4/1000 -> 23892.4 | ... BG5: =BG12*BG4/1000 -> 24220.9
Z6: Giá duyệt mua PP | AA6: 16000 | AB6: 16000 | AC6: 16000 | AD6: 16000 | AE6: 16000 | AF6: 16000 | AG6: 16000 | AH6: 16000 | AI6: 16000 | AJ6: 16000 | AK6: 16000 | AL6: 16000 | AM6: 16000 | AN6: 16000 | AO6: 16000 | AP6: 16000 | AQ6: 16000 | AR6: 16000 | AS6: 16000 | AT6: 16000 | AU6: 16000 | AV6: 16000 | AW6: 16000 | AX6: 16000 | AY6: 16000 | AZ6: 16000 | BA6: 16000 | BB6: 16000 | BC6: 16000 | BD6: 16000 | BE6: 16000 | BF6: 16000 | BG6: 16000
Z7: Giá PP ĐNA | AA7: =#REF!*AA4/1000 -> #REF! | AB7: =#REF!*AB4/1000 -> #REF! | AC7: =#REF!*AC4/1000 -> #REF! | AD7: =#REF!*AD4/1000 -> #REF! | AE7: =#REF!*AE4/1000 -> #REF! | AF7: =#REF!*AF4/1000 -> #REF! | AG7: =#REF!*AG4/1000 -> #REF! | AH7: =#REF!*AH4/1000 -> #REF! | AI7: =#REF!*AI4/1000 -> #REF!
Z8: Giá PP thực tế mua trung bình | AA8: 15756.954 | AB8: 15913.348 | AC8: 14862.72 | AD8: 15432.377 | AH8: 15920.135 | AI8: 15534.328 | AJ8: 15429.433 | AK8: 15715.491 | AL8: 15416.287 | AM8: 15255.335 | AN8: 15921.436 | AO8: 15754.021 | AP8: 15830.912 | AQ8: 15433.527 | AR8: 16000 | AS8: 15829.519 | AT8: 15815.815 | AU8: 15808.779 | AV8: 15725.891 | AW8: 16000 | AX8: 15717.656 | AY8: 15808.753 | AZ8: 15499.943 | BA8: 15602.37 | BB8: 15749.952 | BC8: 16000 | BE8: 16400
Z9: Giá PP thể hiện | AA9: =AA6 -> 16000 | AB9: =AB6 -> 16000 | AC9: =AC6 -> 16000 | AD9: =AD6 -> 16000 | AE9: =AE6 -> 16000 | AF9: =AF6 -> 16000 | AG9: =AG6 -> 16000 | AH9: =AH6 -> 16000 | ... BG9: =BG6 -> 16000
Z10: % Keo chính phẩm so với PP | AA10: =AA11/AA6 -> 0.439175 | AB10: =AB11/AB6 -> 0.467125 | AC10: =AC11/AC6 -> 0.47500625 | AD10: =AD11/AD6 -> 0.4951125 | AE10: =AE11/AE6 -> 0.52375 | AF10: =AF11/AF6 -> 0.483475 | AG10: =AG11/AG6 -> 0.4853125 | AH10: =AH11/AH6 -> 0.493275 | ... BG10: =BG11/BG6 -> 0.51380625
Z11: Chênh lệch | AA11: =AA5-AA6 -> 7026.8 | AB11: =AB5-AB6 -> 7474 | AC11: =AC5-AC6 -> 7600.1 | AD11: =AD5-AD6 -> 7921.8 | AE11: =AE5-AE6 -> 8380 | AF11: =AF5-AF6 -> 7735.6 | AG11: =AG5-AG6 -> 7765 | AH11: =AH5-AH6 -> 7892.4 | ... BG11: =BG5-BG6 -> 8220.9
Z12: Giá keo chính phẩm USD | AA12: 930 | AB12: 970 | AC12: 970 | AD12: 980 | AE12: 1000 | AF12: 980 | AG12: 980 | AH12: 980 | AI12: 980 | AJ12: 980 | AK12: 980 | AL12: 1000 | AM12: 1000 | AN12: 1000 | AO12: 990 | AP12: 990 | AQ12: 990 | AR12: 990 | AS12: 1000 | AT12: 1000 | AU12: 1000 | AV12: 1020 | AW12: 1020 | AX12: 1020 | AY12: 1030 | AZ12: 1030 | BA12: 1030 | BB12: 1030 | BC12: 1030 | BD12: 990 | BE12: 980 | BF12: 980 | BG12: 970

Sheet Chart mua PET
A48: Tên SP | B48: Tên thị trường | C48: T1.23 | D48: 2 | E48: 3 | F48: 4 | G48: 5 | H48: 6 | I48: 7 | J48: 8 | K48: 9 | L48: 10 | M48: 11 | N48: 12 | O48: T1.24 | P48: 2 | Q48: 3 | R48: 4 | S48: 5 | T48: 6 | U48: 7 | V48: 8 | W48: 9 | X48: 10 | Y48: 11 | Z48: 12 | AA48: T1.25 | AB48: 2 | AC48: 3 | AD48: 4
A49: B0 | B49: Chai B0 | C49: 8708.4662 | D49: 9206.5027 | E49: 10350.583 | F49: 10630.801 | G49: 9861.484 | H49: 9199.095 | I49: 8896.0365 | J49: 9246.3978 | K49: 9607.8931 | L49: 10586.188 | M49: 11153.125 | N49: 11113.72 | O49: 11099.755 | P49: 11015.602 | Q49: 11145.196 | R49: 12500 | S49: 13000 | T49: 13000 | U49: 11500 | V49: 11449.41 | W49: 11668.66 | X49: 11469.02 | Y49: 12047.76 | Z49: 11779 | AA49: 12089.892 | AB49: 12125.14 | AC49: 12552.368 | AD49: 13500
A50: B1 | B50: Chai B1 | C50: 14486.456 | D50: 14337.016 | E50: 15026.124 | F50: 14967.788 | G50: 14928.984 | H50: 13867.306 | I50: 13867.306 | J50: =14477.3636167707-1500 -> 12977.364 | K50: 13575.726 | L50: 14413.011 | M50: 14972.882 | N50: 16047.22 | O50: 16099.441 | P50: 16332.331 | Q50: =16233.8475760353+377 -> 16610.848 | R50: 17424.101 | S50: 17263.633 | T50: 17500 | U50: 16000 | V50: 16527.439 | W50: 17591.063 | X50: 16991.396 | Y50: 17312.462 | Z50: 17291.336 | AA50: 17345.811 | AB50: 17386.588 | AC50: 18223.779 | AD50: 18255.804
A51: B1 KPL | B51: Chai B1 KPL | V51: 16531.01 | W51: 15736.355 | X51: 15142.878 | Y51: 15388.66 | Z51: 15426.979 | AA51: 15758.76 | AB51: 16078.364 | AC51: 16453.863 | AD51: 16500
A52: Tuyển xô | B52: Chai tuyển xô (trạm) | AA52: 15391.18 | AB52: 15570.497 | AC52: 16077.806 | AD52: 16000
A53: B2.1 | B53: Chai B2.1 | C53: 10500 | D53: 10500 | E53: 11000 | F53: 11000 | G53: 11000.246 | H53: 9980.5578 | I53: 9000 | J53: 9000 | K53: 9394.7876 | Y53: 11000 | Z53: 11709.605 | AA53: 12300 | AB53: 16394
A54: B2.2 | B54: Chai B2.2 | M54: 12500 | N54: 12500 | O54: 13000 | P54: 13000 | Q54: 13000 | R54: 13000 | S54: 13500 | T54: 15000 | U54: 12000 | V54: 11996.6 | W54: 14000 | X54: 13700 | Y54: 13909.496 | Z54: 13991.676 | AA54: 15469.628 | AB54: 16866.232 | AC54: 17274.018 | AD54: 18147.911
A55: B3 | B55: Chai B3 | C55: 14465.461 | D55: 14509.576 | E55: 15025.379 | F55: 14910.678 | G55: 14831.036 | H55: 14808.45 | I55: =15519.2770426906-1500 -> 14019.277 | J55: =15979.3954889592-1500 -> 14479.395 | K55: 14998.539 | L55: 14535.256 | M55: 14855.148 | N55: 15392.891 | O55: 15365.226 | P55: 15345.865 | Q55: 15465.209 | R55: 16247.504 | S55: 16000 | W55: 16000 | X55: 16447.587 | Y55: 16464.667 | Z55: 16000 | AB55: 17008.322
A56: B4 | B56: Chai B4 | I56: 9000 | J56: 9000 | K56: 9594.9788 | L56: 10500 | M56: 12341.137 | N56: 12441.934 | P56: 13000 | Q56: 12851.445 | R56: 12994.024 | S56: 13500 | T56: 13500 | U56: 12000 | V56: 12000 | W56: 14000 | X56: 13700 | Y56: 14000 | Z56: 13970.906 | AA56: 14300 | AB56: 17098.762 | AC56: 17143.565 | AD56: 18161.28
A57: B5 | B57: Chai B5 | C57: 10563.825 | D57: 10507.268 | E57: 10891.883 | F57: 11017.156 | G57: 11015.531 | H57: 9991.5837 | I57: 9000 | J57: 9000 | K57: 9837.9698 | L57: 10500 | M57: 12500 | N57: 12500 | O57: 13000 | P57: 13000 | Q57: 13000 | R57: 12990.833 | S57: 13391.564 | T57: 13500 | U57: 12000 | V57: 12000 | W57: 14000 | X57: 13700 | Y57: 13943.332 | Z57: 13949.37 | AA57: 15373.679 | AB57: 17075.292 | AC57: 17383.624 | AD57: 17817.113
A58: B6.1 | B58: Chai B6.1 | Y58: 12000 | Z58: 12000 | AB58: 12300 | AC58: 12300
A59: B6.2 | B59: Chai B6.2 | P59: 12500 | Q59: 10000 | R59: 10000 | S59: 10000 | T59: 10000 | U59: 10000 | V59: 10000 | W59: 10000 | X59: 10000 | Z59: 16000 | AA59: 16000 | AB59: 17587.441 | AC59: 18055.743 | AD59: 18117.554
A60: A5.1 | B60: Vảy PET-A5.1 | C60: 17439.487 | D60: 17645.066 | E60: 17973.426 | F60: 17990.91 | G60: 18000 | H60: 17169.677 | I60: 16000 | J60: 16000 | K60: 16512.641 | L60: 16986.563 | M60: 17463.277 | N60: 17515.851 | O60: 17984.851 | P60: 18548.937 | Q60: 19187.723 | R60: 19300 | S60: 19862.191 | T60: 19800 | U60: 18300 | V60: 18000 | W60: 18300 | X60: 18002.192 | Y60: 18194.592 | Z60: 18200 | AA60: 18200 | AB60: 18746.118 | AC60: 19197.787 | AD60: 19917.065
A61: A5.2 | B61: Vảy PET-A5.2 | C61: 16955.379 | D61: 17082.559 | E61: 17500 | F61: 17500 | G61: 17500 | H61: 16603.495 | I61: 15500 | J61: 15500 | K61: 16000 | L61: 16000 | M61: 16726.574 | N61: 17000 | O61: 17476.902 | P61: 18000 | Q61: 18430.847 | R61: 18800 | S61: 19376.8 | T61: 19300 | U61: 17800 | V61: 17500 | W61: 17800 | X61: 17500 | Y61: 17700 | Z61: 17700 | AA61: 17700 | AB61: 18041.537 | AC61: 18700 | AD61: 19646.24
A62: A6 | B62: Vảy PET-A6 | C62: 16500 | D62: 16830 | E62: 16949.308 | F62: 17000 | G62: 17000 | H62: 16000 | V62: 16667.319 | W62: 16200 | AA62: 11293.478 | AD62: 20051.405
A63: A5.1.B3 | B63: Vảy PET-A5.1.B3 | I63: 17000 | K63: 17500 | L63: 18000
A64: A5.2.B3 | B64: Vảy PET-A5.2.B3
A65: A6 | B65: Vảy PET-A6.B3 | C65: 16000 | D65: 16320 | E65: 16323.886 | H65: 16000 | I65: 16000 | J65: 16000 | K65: 16344.566 | L65: 16500 | M65: 16800 | N65: 16800 | O65: 17300
A66: B2 | B66: Vảy PET B2.2_A6 | N66: 17000 | O66: 18750 | P66: 18750
A67: B6 | B67: Vảy PET B6 thử nghiệm | L67: 16000 | M67: 16000 | N67: 17000 | Q67: 18750 | R67: 18750 | S67: 18750 | T67: 18250 | U67: 18250 | V67: 18250 | W67: 18250 | X67: 18250 | Y67: 18250 | Z67: 18250 | AA67: 18250 | AB67: Không mua | AC67: 19674.73 | AD67: 19830.85
A68: B7.1 | B68: Chai B7 | C68: 9355 | D68: 9355 | E68: 9355 | F68: 9354.8387 | G68: 9354.8387 | H68: 9355 | I68: 8548 | J68: 8548 | K68: 8548.3871 | L68: 8548.3871 | M68: 8548.3871 | N68: 8548.3871 | O68: 8548.3871 | P68: 8548.3871 | Q68: 8548.3871 | R68: 8548.3871 | S68: 8548.3871 | T68: 8548.3871 | U68: 8548.3871 | V68: =5300/0.62 -> 8548.3871 | W68: =5300/0.62 -> 8548.3871 | X68: =4605.26327891469/0.66 -> 6977.6716 | Y68: =4450/0.66 -> 6742.4242 | Z68: =4450/0.66 -> 6742.4242 | AA68: =4450/0.66 -> 6742.4242 | AB68: 6742.4242 | AC68: 6742.4242 | AD68: 6742.4242

Sheet Chênh lệch B1 & B0
A49: Tên SP | B49: Tên thị trường | C49: T1.23 | D49: 2 | E49: 3 | F49: 4 | G49: 5 | H49: 6 | I49: 7 | J49: 8 | K49: 9 | L49: 10 | M49: 11 | N49: 12 | O49: T1.24 | P49: 2 | Q49: 3 | R49: 4 | S49: 5 | T49: 6 | U49: 7 | V49: 8 | W49: 9 | X49: 10 | Y49: 11 | Z49: 12 | AA49: T1.25 | AB49: 2 | AC49: 3 | AD49: 4 | AE49: 5 | AF49: 6 | AG49: 7 | AH49: 8 | AI49: 9 | AJ49: 10 | AK49: 11 | AL49: 12
A50: B0 | B50: Chai B0 | C50: 8708.4662 | D50: 9206.5027 | E50: 10350.583 | F50: 10630.801 | G50: 9861.484 | H50: 9199.095 | I50: 8896.0365 | J50: 9246.3978 | K50: 9607.8931 | L50: 10586.188 | M50: 11153.125 | N50: 11113.72 | O50: 11099.755 | P50: 11015.602 | Q50: 11145.196 | R50: 12500 | S50: 13000 | T50: 13000 | U50: 11500 | V50: 11449.41 | W50: 11668.66 | X50: 11469.02 | Y50: 12047.76 | Z50: 11779 | AA50: 12060.749 | AB50: 12125.305 | AC50: 12519.736 | AD50: 13075.123 | AE50: 12848.716 | AF50: 13370.127 | AG50: 13565.086 | AH50: 12327.306 | AI50: 9962.9823 | AJ50: 9535.2548 | AK50: 9556.9816
A51: B1.1 | B51: Chai B1.1 | C51: 14486.456 | D51: 14337.016 | E51: 15026.124 | F51: 14967.788 | G51: 14928.984 | H51: 13867.306 | I51: 14400.367 | J51: 14477.364 | K51: 14998.82 | L51: 16161.709 | M51: 15459.443 | N51: 15359.342 | O51: 15583.785 | P51: 15797.136 | Q51: 15815.178 | R51: 16623.127 | S51: 17000 | T51: 16751.644 | U51: 15000 | V51: 14000 | W51: 17591.063 | X51: 16991.396 | Y51: 17312.462 | Z51: 17285.992 | AA51: 17403.263 | AB51: 17590.561 | AC51: 18228.238 | AD51: 18384.378 | AE51: 18589.095 | AF51: 18500.484 | AG51: 18590.918 | AH51: 18034.643 | AI51: 15376.19 | AJ51: 14775.021 | AK51: 14842.864
A52: B1 KPL | B52: Chai B1.2 | V52: 16531.01 | W52: 15736.355 | X52: 15142.878 | Y52: 15388.66 | Z52: 15426.979 | AA52: 15926.472 | AB52: 16078.364 | AC52: 16453.863 | AD52: 16477.615 | AE52: 15813.538 | AF52: 19152.513 | AG52: 19335.815 | AH52: 19254.754 | AI52: 16570.656 | AJ52: 15000 | AK52: 15000
A53: Tuyển xô | B53: Chai tuyển xô (trạm) | AA53: 15391.18 | AB53: 15570.497 | AC53: 16077.806 | AD53: 16000 | AE53: 16000 | AF53: 16000
A54: B2.1 | B54: Chai B2.1 | C54: 10500 | D54: 10500 | E54: 11000 | F54: 11000 | G54: 11000.246 | H54: 9980.5578 | I54: 9000 | J54: 9000 | K54: 9394.7876 | Y54: 11000 | Z54: 11709.605 | AA54: 12300 | AB54: 16394 | AE54: 16000
A55: B2.2 | B55: Chai B2.2 | M55: 12500 | N55: 12500 | O55: 13000 | P55: 13000 | Q55: 13000 | R55: 13000 | S55: 13500 | T55: 15000 | U55: 12000 | V55: 11996.6 | W55: 14000 | X55: 13700 | Y55: 13909.496 | Z55: 13991.676 | AA55: 15469.628 | AB55: 16866.232 | AC55: 17274.018 | AD55: 18147.911 | AE55: 18398.163 | AF55: 18498.438
A56: B3 | B56: Chai B3 | C56: 14465.461 | D56: 14509.576 | E56: 15025.379 | F56: 14910.678 | G56: 14831.036 | H56: 14808.45 | I56: =15519.2770426906-1500 -> 14019.277 | J56: =15979.3954889592-1500 -> 14479.395 | K56: 14998.539 | L56: 14535.256 | M56: 14855.148 | N56: 15392.891 | O56: 15365.226 | P56: 15345.865 | Q56: 15465.209 | R56: 16247.504 | S56: 16000 | W56: 16000 | X56: 16447.587 | Y56: 16464.667 | Z56: 16000 | AB56: 17008.322 | AE56: 17500 | AF56: 17500
A57: B4 | B57: Chai B4 | I57: 9000 | J57: 9000 | K57: 9594.9788 | L57: 10500 | M57: 12341.137 | N57: 12441.934 | P57: 13000 | Q57: 12851.445 | R57: 12994.024 | S57: 13500 | T57: 13500 | U57: 12000 | V57: 12000 | W57: 14000 | X57: 13700 | Y57: 14000 | Z57: 13970.906 | AA57: 14300 | AB57: 17098.762 | AC57: 17143.565 | AD57: 18161.28 | AE57: 18565.783 | AF57: 18738.859
A58: B5 | B58: Chai B5 | C58: 10563.825 | D58: 10507.268 | E58: 10891.883 | F58: 11017.156 | G58: 11015.531 | H58: 9991.5837 | I58: 9000 | J58: 9000 | K58: 9837.9698 | L58: 10500 | M58: 12500 | N58: 12500 | O58: 13000 | P58: 13000 | Q58: 13000 | R58: 12990.833 | S58: 13391.564 | T58: 13500 | U58: 12000 | V58: 12000 | W58: 14000 | X58: 13700 | Y58: 13943.332 | Z58: 13949.37 | AA58: 15373.679 | AB58: 17075.292 | AC58: 17383.624 | AD58: 17817.113 | AE58: 18606.748 | AF58: 18588.058
A59: B6.1 | B59: Chai B6.1 | Y59: 12000 | Z59: 12000 | AB59: 12300 | AC59: 12300 | AE59: 12300 | AF59: 12300
A60: B6.2 | B60: Chai B6.2 | P60: 12500 | Q60: 10000 | R60: 10000 | S60: 10000 | T60: 10000 | U60: 10000 | V60: 10000 | W60: 10000 | X60: 10000 | Z60: 16000 | AA60: 16000 | AB60: 17587.441 | AC60: 18055.743 | AD60: 18117.554 | AE60: 18776.241 | AF60: 18836.575
A61: A5.1 | B61: Vảy PET-A5.1 | C61: 17439.487 | D61: 17645.066 | E61: 17973.426 | F61: 17990.91 | G61: 18000 | H61: 17169.677 | I61: 16000 | J61: 16000 | K61: 16512.641 | L61: 16986.563 | M61: 17463.277 | N61: 17515.851 | O61: 17984.851 | P61: 18548.937 | Q61: 19187.723 | R61: 19300 | S61: 19862.191 | T61: 19800 | U61: 18300 | V61: 18000 | W61: 18300 | X61: 18002.192 | Y61: 18194.592 | Z61: 18200 | AA61: 18380.107 | AB61: 19051.959 | AC61: 19580.029 | AD61: 20282.386 | AE61: 19546.07 | AF61: 20355.36 | AG61: 20339.853 | AH61: 19342.628 | AI61: 16728.955 | AJ61: 16041.349 | AK61: 16027.581
A62: A5.2 | B62: Vảy PET-A5.2 | C62: 16955.379 | D62: 17082.559 | E62: 17500 | F62: 17500 | G62: 17500 | H62: 16603.495 | I62: 15500 | J62: 15500 | K62: 16000 | L62: 16000 | M62: 16726.574 | N62: 17000 | O62: 17476.902 | P62: 18000 | Q62: 18430.847 | R62: 18800 | S62: 19376.8 | T62: 19300 | U62: 17800 | V62: 17500 | W62: 17800 | X62: 17500 | Y62: 17700 | Z62: 17700 | AA62: 18120.206 | AB62: 18344.625 | AC62: 18952.432 | AD62: 19780.994 | AE62: 18857.268 | AF62: 19732.977 | AG62: 19747.751 | AH62: 18919.843 | AI62: 16260.177 | AJ62: 15609.633 | AK62: 15642.643
