Workbook
Name \T: #REF!
Name __dao1: #REF!
Name __dao2: #REF!
Name __dap2: #REF!
Name __day1: #REF!
Name __day2: #REF!
Name __dbu1: #REF!
Name __dbu2: #REF!
Name __doi3: #REF!
Name __E99999: #REF!
Name __Jan02: #REF!
Name __lap1: #REF!
Name __lap2: #REF!
Name __vc1: #REF!
Name __vc2: #REF!
Name __vc3: #REF!
Name _01_01_99: #REF!
Name _01_02_99: #REF!
Name _01_03_99: #REF!
Name _01_04_99: #REF!
Name _01_05_99: #REF!
Name _01_06_99: #REF!
Name _01_07_99: #REF!
Name _01_08_1999: #REF!
Name _1CAP002: #REF!
Name _2STREO7: #REF!
Name _4GOIC01: #REF!
Name _4OSLCTT: #REF!
Name _6BNTTTH: #REF!
Name _6DCTTBO: #REF!
Name _6DD24TT: #REF!
Name _6FCOTBU: #REF!
Name _6LATUBU: #REF!
Name _6SDTT24: #REF!
Name _6TBUDTT: #REF!
Name _6TDDDTT: #REF!
Name _6TLTTTH: #REF!
Name _6TUBUTT: #REF!
Name _6UCLVIS: #REF!
Name _7DNCABC: #REF!
Name _7HDCTBU: #REF!
Name _7PKTUBU: #REF!
Name _7TBHT20: #REF!
Name _7TBHT30: #REF!
Name _7TDCABC: #REF!
Name _dao1: #REF!
Name _dao2: #REF!
Name _dap2: #REF!
Name _day1: #REF!
Name _day2: #REF!
Name _dbu1: #REF!
Name _dbu2: #REF!
Name _doi3: #REF!
Name _E99999: #REF!
Name _Jan02: #REF!
Name _lap1: #REF!
Name _lap2: #REF!
Name _vc1: #REF!
Name _vc2: #REF!
Name _vc3: #REF!

Sheet TH
A3: BẢNG TRÌNH GIÁ BÁN SẢN PHẨM DÂY ĐAI 2026
I4: Hiệu lực từ ngày | K4: tới ngày
A5: STT | B5: Mã | C5: Tên | D5: Quy cách (mm x …..) | E5: Trọng lượng (Cuộn) | F5: Đơn giá vốn (Vnđ/Kg) | G5: Giá bán EXW đề nghị (VND/Kg) | H5: Đơn giá vốn (Vnđ/Cuộn) | I5: Giá bán EXW đề nghị (VND/Cuộn) | J5: Lợi nhuận sau thuế (VND/Cuộn) | K5: % Lợi nhuận sau thuế (VND/Cuộn) | L5: Ghi chú
A6: 1 | C6: Dây đai RPE1609 | D6: 16 mm x 0.9 mm | E6: 20 | F6: =+'DĐ RPE1609'!J105 -> 23578.231 | G6: 25000 | H6: =F6*E6 -> 471564.62 | I6: =G6*E6 -> 500000 | J6: =+I6-H6 -> 28435.38 | K6: =+J6/I6 -> 0.056870761 | N6: 24000
A7: 2 | C7: Dây đai RPE1909 | D7: 19 mm x 0.9 mm | E7: 20 | F7: =+'DĐ RPE1909'!J105 -> 23578.231 | G7: 25000 | H7: =F7*E7 -> 471564.62 | I7: =G7*E7 -> 500000 | J7: =+I7-H7 -> 28435.38 | K7: =+J7/I7 -> 0.056870761 | N7: 25000
A8: 3 | C8: Dây đai RPEXXXX | D8: XX mm x XX mm | E8: 20 | F8: =+'DĐ RPE1609'!J105 -> 23578.231 | G8: 25000 | H8: =F8*E8 -> 471564.62 | I8: =G8*E8 -> 500000 | J8: =+I8-H8 -> 28435.38 | K8: =+J8/I8 -> 0.056870761 | N8: 26000
A9: 4 | J9: =+I9-H9 -> 0 | K9: =+J9/I9 -> #DIV/0!
A10: 5 | J10: =+I10-H10 -> 0 | K10: =+J10/I10 -> #DIV/0!
A11: 6 | J11: =+I11-H11 -> 0 | K11: =+J11/I11 -> #DIV/0!
C15: Phê Duyệt | D15: Xem xét | F15: Xem xét | H15: Người kiểm tra | J15: Người kiểm tra | L15: Người lập
C20: TGĐ | D20: GĐTC | F20: P.TGĐ SX | H20: GĐĐH Trạm | J20: GĐ Đại Lộc | L20: KTT Đại Lộc
C21: Huỳnh Ngọc Thạch | D21: Lê Hoành Cư | F21: Lê Xuân Huy Vũ | H21: Lê Đức Thắng | J21: Lưu Song Hùng | L21: Trần Thị Hương

Sheet Chart
C1: GIÁ SẢN PHẨM DÂY ĐAI 2026
D3: Quy cách đóng gói | E3: =+'DĐ RPE1609'!K5 -> 20 | I3: ='DĐ RPE1909'!K5 -> 20 | M3: ='DĐ RPEXXXX'!K5 -> 20 | Q3: ĐIỂM HÒA VỐN
E4: =TH!C6 -> Dây đai RPE1609 | I4: =TH!C7 -> Dây đai RPE1909 | M4: =TH!C8 -> Dây đai RPEXXXX | Q4: =D22 -> 23578.231
A5: No. | B5: SAP | C5: Chi phí Cost Items | D5: Chi phí VNĐ /Kg | E5: Đơn giá VND /Cuộn | F5: Cơ cấu % chi phí /Giá | H5: Chi phí VNĐ /Kg | I5: Đơn giá VND /Cuộn | J5: Cơ cấu % chi phí /Giá | L5: Chi phí VNĐ /Kg | M5: Đơn giá VND /Cuộn | N5: Cơ cấu % chi phí /Giá
A6: A | B6: 1521 | C6: Chi phí nguyên vật liệu | D6: =+SUM(D7:D7) -> 13296.279 | E6: =D6*E$3 -> 265925.58 | F6: =E6/$E$25 -> 0.53185116 | H6: =+SUM(H7:H7) -> 13296.279 | I6: =H6*$E$3 -> 265925.58 | J6: =I6/$E$25 -> 0.53185116 | L6: =+SUM(L7:L7) -> 13296.279 | M6: =L6*$E$3 -> 265925.58 | N6: =M6/$E$25 -> 0.53185116
A7: 1 | B7: 1521 | C7: Chi phí Vảy GCDĐ | D7: =+SUMIFS('DĐ RPE1609'!J:J,'DĐ RPE1609'!D:D,Chart!B7) -> 13296.279 | E7: =D7*E$3 -> 265925.58 | F7: =E7/$E$25 -> 0.53185116 | H7: =+SUMIFS('DĐ RPE1909'!J:J,'DĐ RPE1909'!D:D,Chart!B7) -> 13296.279 | I7: =H7*$E$3 -> 265925.58 | J7: =I7/$E$25 -> 0.53185116 | L7: =+SUMIFS('DĐ RPEXXXX'!J:J,'DĐ RPEXXXX'!D:D,Chart!B7) -> 13296.279 | M7: =L7*$E$3 -> 265925.58 | N7: =M7/$E$25 -> 0.53185116
A8: B | B8: 1522 | C8: Hao hụt về tiền | D8: =+SUMIFS('DĐ RPE1609'!J:J,'DĐ RPE1609'!D:D,Chart!B8) -> 1820 | E8: =D8*E$3 -> 36400 | F8: =E8/$E$25 -> 0.0728 | H8: =+SUMIFS('DĐ RPE1909'!J:J,'DĐ RPE1909'!D:D,Chart!B8) -> 1820 | I8: =H8*$E$3 -> 36400 | J8: =I8/$E$25 -> 0.0728 | L8: =+SUMIFS('DĐ RPEXXXX'!J:J,'DĐ RPEXXXX'!D:D,Chart!B8) -> 1820 | M8: =L8*$E$3 -> 36400 | N8: =M8/$E$25 -> 0.0728
A9: C | C9: Chi phí sản xuất | D9: =SUM(D10:D16) -> 5961.9519 | E9: =D9*E$3 -> 119239.04 | F9: =E9/$E$25 -> 0.23847808 | H9: =SUM(H10:H16) -> 5961.9519 | I9: =H9*$E$3 -> 119239.04 | J9: =I9/$E$25 -> 0.23847808 | L9: =SUM(L10:L16) -> 5961.9519 | M9: =L9*$E$3 -> 119239.04 | N9: =M9/$E$25 -> 0.23847808
A10: 2 | B10: LAB | C10: Chi phí nhân công | D10: =+SUMIFS('DĐ RPE1609'!J:J,'DĐ RPE1609'!D:D,Chart!B10) -> 901.08204 | E10: =D10*E$3 -> 18021.641 | F10: =E10/$E$25 -> 0.036043282 | H10: =+SUMIFS('DĐ RPE1909'!J:J,'DĐ RPE1909'!D:D,Chart!B10) -> 901.08204 | I10: =H10*$E$3 -> 18021.641 | J10: =I10/$E$25 -> 0.036043282 | L10: =+SUMIFS('DĐ RPEXXXX'!J:J,'DĐ RPEXXXX'!D:D,Chart!B10) -> 901.08204 | M10: =L10*$E$3 -> 18021.641 | N10: =M10/$E$25 -> 0.036043282
A11: =+A10+1 -> 3 | B11: DEP | C11: Khấu hao | D11: =+SUMIFS('DĐ RPE1609'!J:J,'DĐ RPE1609'!D:D,Chart!B11) -> 326.55786 | E11: =D11*E$3 -> 6531.1572 | F11: =E11/$E$25 -> 0.013062314 | H11: =+SUMIFS('DĐ RPE1909'!J:J,'DĐ RPE1909'!D:D,Chart!B11) -> 326.55786 | I11: =H11*$E$3 -> 6531.1572 | J11: =I11/$E$25 -> 0.013062314 | L11: =+SUMIFS('DĐ RPEXXXX'!J:J,'DĐ RPEXXXX'!D:D,Chart!B11) -> 326.55786 | M11: =L11*$E$3 -> 6531.1572 | N11: =M11/$E$25 -> 0.013062314
A12: =+A11+1 -> 4 | B12: ELEC | C12: Chi phí gián tiếp | D12: =+SUMIFS('DĐ RPE1609'!J:J,'DĐ RPE1609'!D:D,Chart!B12) -> 2569.7674 | E12: =D12*E$3 -> 51395.349 | F12: =E12/$E$25 -> 0.1027907 | H12: =+SUMIFS('DĐ RPE1909'!J:J,'DĐ RPE1909'!D:D,Chart!B12) -> 2569.7674 | I12: =H12*$E$3 -> 51395.349 | J12: =I12/$E$25 -> 0.1027907 | L12: =+SUMIFS('DĐ RPEXXXX'!J:J,'DĐ RPEXXXX'!D:D,Chart!B12) -> 2569.7674 | M12: =L12*$E$3 -> 51395.349 | N12: =M12/$E$25 -> 0.1027907
A13: =+A12+1 -> 5 | B13: OTH | C13: Điện | D13: =+SUMIFS('DĐ RPE1609'!J:J,'DĐ RPE1609'!D:D,Chart!B13) -> 2164.5446 | E13: =D13*E$3 -> 43290.891 | F13: =E13/$E$25 -> 0.086581783 | H13: =+SUMIFS('DĐ RPE1909'!J:J,'DĐ RPE1909'!D:D,Chart!B13) -> 2164.5446 | I13: =H13*$E$3 -> 43290.891 | J13: =I13/$E$25 -> 0.086581783 | L13: =+SUMIFS('DĐ RPEXXXX'!J:J,'DĐ RPEXXXX'!D:D,Chart!B13) -> 2164.5446 | M13: =L13*$E$3 -> 43290.891 | N13: =M13/$E$25 -> 0.086581783
A14: =+A13+1 -> 6 | B14: BAG | C14: Đóng gói | D14: =+SUMIFS('DĐ RPE1609'!J:J,'DĐ RPE1609'!D:D,Chart!B14) -> 0 | E14: =D14*E$3 -> 0 | F14: =E14/$E$25 -> 0 | H14: =+SUMIFS('DĐ RPE1909'!J:J,'DĐ RPE1909'!D:D,Chart!B14) -> 0 | I14: =H14*$E$3 -> 0 | J14: =I14/$E$25 -> 0 | L14: =+SUMIFS('DĐ RPEXXXX'!J:J,'DĐ RPEXXXX'!D:D,Chart!B14) -> 0 | M14: =L14*$E$3 -> 0 | N14: =M14/$E$25 -> 0
A15: =+A14+1 -> 7 | B15: CHE | C15: Hóa chất | D15: =+SUMIFS('DĐ RPE1609'!J:J,'DĐ RPE1609'!D:D,Chart!B15) -> 0 | E15: =D15*E$3 -> 0 | F15: =E15/$E$25 -> 0 | H15: =+SUMIFS('DĐ RPE1909'!J:J,'DĐ RPE1909'!D:D,Chart!B15) -> 0 | I15: =H15*$E$3 -> 0 | J15: =I15/$E$25 -> 0 | L15: =+SUMIFS('DĐ RPEXXXX'!J:J,'DĐ RPEXXXX'!D:D,Chart!B15) -> 0 | M15: =L15*$E$3 -> 0 | N15: =M15/$E$25 -> 0
A16: =+A15+1 -> 8 | B16: H2O | C16: Nước | D16: =+SUMIFS('DĐ RPE1609'!J:J,'DĐ RPE1609'!D:D,Chart!B16) -> 0 | E16: =D16*E$3 -> 0 | F16: =E16/$E$25 -> 0 | H16: =+SUMIFS('DĐ RPE1909'!J:J,'DĐ RPE1909'!D:D,Chart!B16) -> 0 | I16: =H16*$E$3 -> 0 | J16: =I16/$E$25 -> 0 | L16: =+SUMIFS('DĐ RPEXXXX'!J:J,'DĐ RPEXXXX'!D:D,Chart!B16) -> 0 | M16: =L16*$E$3 -> 0 | N16: =M16/$E$25 -> 0
A17: D | C17: Giá thành (A+B+C) | D17: =SUM(D7:D9) -> 21078.231 | E17: =D17*E$3 -> 421564.62 | F17: =E17/$E$25 -> 0.84312924 | H17: =SUM(H7:H9) -> 21078.231 | I17: =H17*$E$3 -> 421564.62 | J17: =I17/$E$25 -> 0.84312924 | L17: =SUM(L7:L9) -> 21078.231 | M17: =L17*$E$3 -> 421564.62 | N17: =M17/$E$25 -> 0.84312924
A18: E | C18: CP quản lý, bán hàng, lãi vay | D18: =+SUM(D19:D21) -> 2500 | E18: =D18*E$3 -> 50000 | F18: =E18/$E$25 -> 0.1 | H18: =+SUM(H19:H21) -> 2500 | I18: =H18*$E$3 -> 50000 | J18: =I18/$E$25 -> 0.1 | L18: =+SUM(L19:L21) -> 2500 | M18: =L18*$E$3 -> 50000 | N18: =M18/$E$25 -> 0.1
A19: 9 | B19: 641 | C19: Chi phí bán hàng | D19: =+SUMIFS('DĐ RPE1609'!J:J,'DĐ RPE1609'!D:D,Chart!B19) -> 1750 | E19: =D19*E$3 -> 35000 | F19: =E19/$E$25 -> 0.07 | H19: =+SUMIFS('DĐ RPE1909'!J:J,'DĐ RPE1909'!D:D,Chart!B19) -> 1750 | I19: =H19*$E$3 -> 35000 | J19: =I19/$E$25 -> 0.07 | L19: =+SUMIFS('DĐ RPEXXXX'!J:J,'DĐ RPEXXXX'!D:D,Chart!B19) -> 1750 | M19: =L19*$E$3 -> 35000 | N19: =M19/$E$25 -> 0.07
A20: 10 | B20: 642 | C20: Chi phí quản lý | D20: =+SUMIFS('DĐ RPE1609'!J:J,'DĐ RPE1609'!D:D,Chart!B20) -> 500 | E20: =D20*E$3 -> 10000 | F20: =E20/$E$25 -> 0.02 | H20: =+SUMIFS('DĐ RPE1909'!J:J,'DĐ RPE1909'!D:D,Chart!B20) -> 500 | I20: =H20*$E$3 -> 10000 | J20: =I20/$E$25 -> 0.02 | L20: =+SUMIFS('DĐ RPEXXXX'!J:J,'DĐ RPEXXXX'!D:D,Chart!B20) -> 500 | M20: =L20*$E$3 -> 10000 | N20: =M20/$E$25 -> 0.02
A21: 11 | B21: 635 | C21: Chi phí lãi vay | D21: =+SUMIFS('DĐ RPE1609'!J:J,'DĐ RPE1609'!D:D,Chart!B21) -> 250 | E21: =D21*E$3 -> 5000 | F21: =E21/$E$25 -> 0.01 | H21: =+SUMIFS('DĐ RPE1909'!J:J,'DĐ RPE1909'!D:D,Chart!B21) -> 250 | I21: =H21*$E$3 -> 5000 | J21: =I21/$E$25 -> 0.01 | L21: =+SUMIFS('DĐ RPEXXXX'!J:J,'DĐ RPEXXXX'!D:D,Chart!B21) -> 250 | M21: =L21*$E$3 -> 5000 | N21: =M21/$E$25 -> 0.01
A22: F | C22: Điểm hòa vốn (D+E) | D22: =+D17+D18 -> 23578.231 | E22: =D22*E$3 -> 471564.62 | F22: =E22/$E$25 -> 0.94312924 | H22: =+H17+H18 -> 23578.231 | I22: =H22*$E$3 -> 471564.62 | J22: =I22/$E$25 -> 0.94312924 | L22: =+L17+L18 -> 23578.231 | M22: =L22*$E$3 -> 471564.62 | N22: =M22/$E$25 -> 0.94312924
A23: 12 | B23: TAX | C23: Thuế thu nhập | D23: =+SUMIFS('DĐ RPE1609'!J:J,'DĐ RPE1609'!D:D,Chart!B23) -> 236.9615 | E23: =D23*E$3 -> 4739.23 | F23: =E23/$E$25 -> 0.0094784601 | H23: =+SUMIFS('DĐ RPE1909'!J:J,'DĐ RPE1909'!D:D,Chart!B23) -> 236.9615 | I23: =H23*$E$3 -> 4739.23 | J23: =I23/$E$25 -> 0.0094784601 | L23: =+SUMIFS('DĐ RPEXXXX'!J:J,'DĐ RPEXXXX'!D:D,Chart!B23) -> 236.9615 | M23: =L23*$E$3 -> 4739.23 | N23: =M23/$E$25 -> 0.0094784601
A24: G | B24: LN | C24: Lợi nhuận sau thuế | D24: =+SUMIFS('DĐ RPE1609'!J:J,'DĐ RPE1609'!D:D,Chart!B24) -> 1184.8075 | E24: =D24*E$3 -> 23696.15 | F24: =E24/$E$25 -> 0.0473923 | H24: =+SUMIFS('DĐ RPE1909'!J:J,'DĐ RPE1909'!D:D,Chart!B24) -> 1184.8075 | I24: =H24*$E$3 -> 23696.15 | J24: =I24/$E$25 -> 0.0473923 | L24: =+SUMIFS('DĐ RPEXXXX'!J:J,'DĐ RPEXXXX'!D:D,Chart!B24) -> 1184.8075 | M24: =L24*$E$3 -> 23696.15 | N24: =M24/$E$25 -> 0.0473923
A25: H | C25: Giá bán | D25: =+D22+D23+D24 -> 25000 | E25: =D25*E$3 -> 500000 | F25: =E25/$E$25 -> 1 | H25: =+H22+H23+H24 -> 25000 | I25: =H25*$E$3 -> 500000 | J25: =I25/$E$25 -> 1 | L25: =+L22+L23+L24 -> 25000 | M25: =L25*$E$3 -> 500000 | N25: =M25/$E$25 -> 1
C26: % Lãi gộp nguyên liệu/Giá bán | F26: =F25-F6-F8 -> 0.39534884 | J26: =J25-J6-J8 -> 0.39534884 | N26: =N25-N6-N8 -> 0.39534884
D27: ="ĐIỂM HÒA VỐN "&ROUND(D22,0)&" Đ" -> ĐIỂM HÒA VỐN 23578 Đ | H27: ="ĐIỂM HÒA VỐN "&ROUND(H22,0)&" Đ" -> ĐIỂM HÒA VỐN 23578 Đ | L27: ="ĐIỂM HÒA VỐN "&ROUND(L22,0)&" Đ" -> ĐIỂM HÒA VỐN 23578 Đ

Sheet DĐ RPE1609
A1: Danh mục | C1: 1
C2: PHƯƠNG ÁN SẢN XUẤT DĐ 1
C4: Nguyên liệu: | D4: NL 1
C5: Thành phẩm: | D5: =TH!C6 -> Dây đai RPE1609 | J5: Quy cách đóng gói: | K5: =TH!E6 -> 20
C6: Quy cách: | D6: =TH!D6 -> 16 mm x 0.9 mm
C7: No. | D7: Nhóm | E7: Mã SAP | F7: Chi phí Cost Items | G7: Đơn vị tính Unit | H7: Định mức Standard | I7: Đơn giá (VNĐ) | J7: Chi phí đơn vị (VNĐ /Kg) | K7: Đơn giá (VND /Cuộn) | L7: % giá bán | M7: Cơ sở tính
C8: A | D8: CÔNG ĐOẠN TẠO VẢY GCDĐ:
B9: Vảy GCDĐ | C9: I | F9: Vảy GCDĐ | G9: vnđ /Kg | H9: 1 | I9: 12000 | J9: =I9 -> 12000 | K9: =J9*$K$5 -> 240000 | L9: =J9/$J$58 -> 0.92307692
B10: Hao hụt | C10: II | F10: Hao hụt | G10: % | H10: =SUM(H11:H20) -> 0 | J10: =SUM(J11:J20) -> 0 | K10: =J10*$K$5 -> 0 | L10: =J10/$J$58 -> 0
G11: % | J11: =+($J$9-I11)*H11 -> 0 | K11: =J11*$K$5 -> 0 | L11: =J11/$J$58 -> 0
G12: % | J12: =+($J$9-I12)*H12 -> 0 | K12: =J12*$K$5 -> 0 | L12: =J12/$J$58 -> 0
G13: % | J13: =+($J$9-I13)*H13 -> 0 | K13: =J13*$K$5 -> 0 | L13: =J13/$J$58 -> 0
G14: % | J14: =+($J$9-I14)*H14 -> 0 | K14: =J14*$K$5 -> 0 | L14: =J14/$J$58 -> 0
G15: % | J15: =+($J$9-I15)*H15 -> 0 | K15: =J15*$K$5 -> 0 | L15: =J15/$J$58 -> 0
G16: % | J16: =+($J$9-I16)*H16 -> 0 | K16: =J16*$K$5 -> 0 | L16: =J16/$J$58 -> 0
G17: % | J17: =+($J$9-I17)*H17 -> 0 | K17: =J17*$K$5 -> 0 | L17: =J17/$J$58 -> 0
G18: % | J18: =+($J$9-I18)*H18 -> 0 | K18: =J18*$K$5 -> 0 | L18: =J18/$J$58 -> 0
G19: % | J19: =+($J$9-I19)*H19 -> 0 | K19: =J19*$K$5 -> 0 | L19: =J19/$J$58 -> 0
A20: Mất đi | F20: Hao hụt n | G20: % | J20: =+($J$9-I20)*H20 -> 0 | K20: =J20*$K$5 -> 0 | L20: =J20/$J$58 -> 0 | M20: Hao hụt mất đi
C21: III | F21: Chi phí VC | J21: =SUM(J22:J33) -> 0 | K21: =J21*$K$5 -> 0 | L21: =J21/$J$58 -> 0
C22: 0 | D22: REL01 | F22: Công suất máy (capacity) | G22: Kg /h | K22: =J22*$K$5 -> 0
F23: Hiệu suất máy | G23: % | K23: =J23*$K$5 -> 0
K24: =J24*$K$5 -> 0 | L24: =J24/$J$58 -> 0
K25: =J25*$K$5 -> 0 | L25: =J25/$J$58 -> 0
K26: =J26*$K$5 -> 0 | L26: =J26/$J$58 -> 0
K27: =J27*$K$5 -> 0 | L27: =J27/$J$58 -> 0
K28: =J28*$K$5 -> 0 | L28: =J28/$J$58 -> 0
K29: =J29*$K$5 -> 0 | L29: =J29/$J$58 -> 0
K30: =J30*$K$5 -> 0 | L30: =J30/$J$58 -> 0
K31: =J31*$K$5 -> 0 | L31: =J31/$J$58 -> 0
K32: =J32*$K$5 -> 0 | L32: =J32/$J$58 -> 0
C33: =+C28+1 -> 1 | D33: OTH | E33: 6277.6278 | F33: Chi phí bằng tiền khác | G33: VND | K33: =J33*$K$5 -> 0 | L33: =J33/$J$58 -> 0
D34: Cộng giá thành Vảy GCDĐ (I+II+III) | J34: =J9+J10+J21 -> 12000 | K34: =J34*$K$5 -> 240000 | L34: =J34/$J$58 -> 0.92307692
C35: B | D35: CÔNG ĐOẠN TẠO VẢY MIXED: | K35: =J35*$K$5 -> 0
C36: IV | F36: Chi phí Vảy GCDĐ | G36: Kg | H36: 1 | I36: =+J34 -> 12000 | J36: =+H36*I36 -> 12000 | K36: =J36*$K$5 -> 240000 | L36: =J36/$J$58 -> 0.92307692
C37: V | F37: Chi phí mixed màu | J37: =SUM(J40:J57) -> 1000 | K37: =J37*$K$5 -> 20000 | L37: =J37/$J$58 -> 0.076923077
C38: 0 | D38: VBAL1 | F38: Công suất máy (capacity) | G38: Kg /h | K38: =J38*$K$5 -> 0
F39: Hiệu suất máy | G39: % | K39: =J39*$K$5 -> 0
B40: Vảy GCDĐ | J40: =+($J$34-I40)*H40 -> 0 | K40: =J40*$K$5 -> 0 | L40: =J40/$J$58 -> 0
B41: Hao hụt | J41: =+($J$34-I41)*H41 -> 0 | K41: =J41*$K$5 -> 0 | L41: =J41/$J$58 -> 0
...

Sheet DĐ RPE1909
A1: Danh mục | C1: 1
C2: PHƯƠNG ÁN SẢN XUẤT DĐ 2
C4: Nguyên liệu: | D4: NL 2
C5: Thành phẩm: | D5: =TH!C7 -> Dây đai RPE1909 | J5: Quy cách đóng gói: | K5: =TH!E7 -> 20
C6: Quy cách: | D6: =TH!D7 -> 19 mm x 0.9 mm
C7: No. | D7: Nhóm | E7: Mã SAP | F7: Chi phí Cost Items | G7: Đơn vị tính Unit | H7: Định mức Standard | I7: Đơn giá (VNĐ) | J7: Chi phí đơn vị (VNĐ /Kg) | K7: Đơn giá (VND /Cuộn) | L7: % giá bán | M7: Cơ sở tính
C8: A | D8: CÔNG ĐOẠN TẠO VẢY GCDĐ:
B9: Vảy GCDĐ | C9: I | F9: Vảy GCDĐ | G9: vnđ /Kg | H9: 1 | I9: 12000 | J9: =I9 -> 12000 | K9: =J9*$K$5 -> 240000 | L9: =J9/$J$58 -> 0.92307692
B10: Hao hụt | C10: II | F10: Hao hụt | G10: % | H10: =SUM(H11:H20) -> 0 | J10: =SUM(J11:J20) -> 0 | K10: =J10*$K$5 -> 0 | L10: =J10/$J$58 -> 0
G11: % | J11: =+($J$9-I11)*H11 -> 0 | K11: =J11*$K$5 -> 0 | L11: =J11/$J$58 -> 0
G12: % | J12: =+($J$9-I12)*H12 -> 0 | K12: =J12*$K$5 -> 0 | L12: =J12/$J$58 -> 0
G13: % | J13: =+($J$9-I13)*H13 -> 0 | K13: =J13*$K$5 -> 0 | L13: =J13/$J$58 -> 0
G14: % | J14: =+($J$9-I14)*H14 -> 0 | K14: =J14*$K$5 -> 0 | L14: =J14/$J$58 -> 0
G15: % | J15: =+($J$9-I15)*H15 -> 0 | K15: =J15*$K$5 -> 0 | L15: =J15/$J$58 -> 0
G16: % | J16: =+($J$9-I16)*H16 -> 0 | K16: =J16*$K$5 -> 0 | L16: =J16/$J$58 -> 0
G17: % | J17: =+($J$9-I17)*H17 -> 0 | K17: =J17*$K$5 -> 0 | L17: =J17/$J$58 -> 0
G18: % | J18: =+($J$9-I18)*H18 -> 0 | K18: =J18*$K$5 -> 0 | L18: =J18/$J$58 -> 0
G19: % | J19: =+($J$9-I19)*H19 -> 0 | K19: =J19*$K$5 -> 0 | L19: =J19/$J$58 -> 0
A20: Mất đi | F20: Hao hụt n | G20: % | J20: =+($J$9-I20)*H20 -> 0 | K20: =J20*$K$5 -> 0 | L20: =J20/$J$58 -> 0 | M20: Hao hụt mất đi
C21: III | F21: Chi phí VC | J21: =SUM(J22:J33) -> 0 | K21: =J21*$K$5 -> 0 | L21: =J21/$J$58 -> 0
C22: 0 | D22: REL01 | F22: Công suất máy (capacity) | G22: Kg /h | K22: =J22*$K$5 -> 0
F23: Hiệu suất máy | G23: % | K23: =J23*$K$5 -> 0
K24: =J24*$K$5 -> 0 | L24: =J24/$J$58 -> 0
K25: =J25*$K$5 -> 0 | L25: =J25/$J$58 -> 0
K26: =J26*$K$5 -> 0 | L26: =J26/$J$58 -> 0
K27: =J27*$K$5 -> 0 | L27: =J27/$J$58 -> 0
K28: =J28*$K$5 -> 0 | L28: =J28/$J$58 -> 0
K29: =J29*$K$5 -> 0 | L29: =J29/$J$58 -> 0
K30: =J30*$K$5 -> 0 | L30: =J30/$J$58 -> 0
K31: =J31*$K$5 -> 0 | L31: =J31/$J$58 -> 0
K32: =J32*$K$5 -> 0 | L32: =J32/$J$58 -> 0
C33: =+C28+1 -> 1 | D33: OTH | E33: 6277.6278 | F33: Chi phí bằng tiền khác | G33: VND | K33: =J33*$K$5 -> 0 | L33: =J33/$J$58 -> 0
D34: Cộng giá thành Vảy GCDĐ (I+II+III) | J34: =J9+J10+J21 -> 12000 | K34: =J34*$K$5 -> 240000 | L34: =J34/$J$58 -> 0.92307692
C35: B | D35: CÔNG ĐOẠN TẠO VẢY MIXED: | K35: =J35*$K$5 -> 0
C36: IV | F36: Chi phí Vảy GCDĐ | G36: Kg | H36: 1 | I36: =+J34 -> 12000 | J36: =+H36*I36 -> 12000 | K36: =J36*$K$5 -> 240000 | L36: =J36/$J$58 -> 0.92307692
C37: V | F37: Chi phí mixed màu | J37: =SUM(J40:J57) -> 1000 | K37: =J37*$K$5 -> 20000 | L37: =J37/$J$58 -> 0.076923077
C38: 0 | D38: VBAL1 | F38: Công suất máy (capacity) | G38: Kg /h | K38: =J38*$K$5 -> 0
F39: Hiệu suất máy | G39: % | K39: =J39*$K$5 -> 0
B40: Vảy GCDĐ | J40: =+($J$34-I40)*H40 -> 0 | K40: =J40*$K$5 -> 0 | L40: =J40/$J$58 -> 0
B41: Hao hụt | J41: =+($J$34-I41)*H41 -> 0 | K41: =J41*$K$5 -> 0 | L41: =J41/$J$58 -> 0
...

Sheet DĐ RPEXXXX
A1: Danh mục | C1: 1
C2: PHƯƠNG ÁN SẢN XUẤT DĐ 3
C4: Nguyên liệu: | D4: NL 3 | J4: Bảng | K4: Kg
C5: Thành phẩm: | D5: =TH!C8 -> Dây đai RPEXXXX | J5: Quy cách đóng gói: | K5: =TH!E8 -> 20
C6: Quy cách: | D6: =TH!D8 -> XX mm x XX mm
C7: No. | D7: Nhóm | E7: Mã SAP | F7: Chi phí Cost Items | G7: Đơn vị tính Unit | H7: Định mức Standard | I7: Đơn giá (VNĐ) | J7: Chi phí đơn vị (VNĐ /Kg) | K7: Đơn giá (VND /Cuộn) | L7: % giá bán | M7: Cơ sở tính
C8: A | D8: CÔNG ĐOẠN TẠO VẢY GCDĐ:
B9: Vảy GCDĐ | C9: I | F9: Vảy GCDĐ | G9: vnđ /Kg | H9: 1 | I9: 12000 | J9: =I9 -> 12000 | K9: =J9*$K$5 -> 240000 | L9: =J9/$J$58 -> 0.92307692
B10: Hao hụt | C10: II | F10: Hao hụt | G10: % | H10: =SUM(H11:H20) -> 0 | J10: =SUM(J11:J20) -> 0 | K10: =J10*$K$5 -> 0 | L10: =J10/$J$58 -> 0
G11: % | J11: =+($J$9-I11)*H11 -> 0 | K11: =J11*$K$5 -> 0 | L11: =J11/$J$58 -> 0
G12: % | J12: =+($J$9-I12)*H12 -> 0 | K12: =J12*$K$5 -> 0 | L12: =J12/$J$58 -> 0
G13: % | J13: =+($J$9-I13)*H13 -> 0 | K13: =J13*$K$5 -> 0 | L13: =J13/$J$58 -> 0
G14: % | J14: =+($J$9-I14)*H14 -> 0 | K14: =J14*$K$5 -> 0 | L14: =J14/$J$58 -> 0
G15: % | J15: =+($J$9-I15)*H15 -> 0 | K15: =J15*$K$5 -> 0 | L15: =J15/$J$58 -> 0
G16: % | J16: =+($J$9-I16)*H16 -> 0 | K16: =J16*$K$5 -> 0 | L16: =J16/$J$58 -> 0
G17: % | J17: =+($J$9-I17)*H17 -> 0 | K17: =J17*$K$5 -> 0 | L17: =J17/$J$58 -> 0
G18: % | J18: =+($J$9-I18)*H18 -> 0 | K18: =J18*$K$5 -> 0 | L18: =J18/$J$58 -> 0
G19: % | J19: =+($J$9-I19)*H19 -> 0 | K19: =J19*$K$5 -> 0 | L19: =J19/$J$58 -> 0
A20: Mất đi | F20: Hao hụt n | G20: % | J20: =+($J$9-I20)*H20 -> 0 | K20: =J20*$K$5 -> 0 | L20: =J20/$J$58 -> 0 | M20: Hao hụt mất đi
C21: III | F21: Chi phí VC | J21: =SUM(J22:J33) -> 0 | K21: =J21*$K$5 -> 0 | L21: =J21/$J$58 -> 0
C22: 0 | D22: REL01 | F22: Công suất máy (capacity) | G22: Kg /h | K22: =J22*$K$5 -> 0
F23: Hiệu suất máy | G23: % | K23: =J23*$K$5 -> 0
K24: =J24*$K$5 -> 0 | L24: =J24/$J$58 -> 0
K25: =J25*$K$5 -> 0 | L25: =J25/$J$58 -> 0
K26: =J26*$K$5 -> 0 | L26: =J26/$J$58 -> 0
K27: =J27*$K$5 -> 0 | L27: =J27/$J$58 -> 0
K28: =J28*$K$5 -> 0 | L28: =J28/$J$58 -> 0
K29: =J29*$K$5 -> 0 | L29: =J29/$J$58 -> 0
K30: =J30*$K$5 -> 0 | L30: =J30/$J$58 -> 0
K31: =J31*$K$5 -> 0 | L31: =J31/$J$58 -> 0
K32: =J32*$K$5 -> 0 | L32: =J32/$J$58 -> 0
C33: =+C28+1 -> 1 | D33: OTH | E33: 6277.6278 | F33: Chi phí bằng tiền khác | G33: VND | K33: =J33*$K$5 -> 0 | L33: =J33/$J$58 -> 0
D34: Cộng giá thành Vảy GCDĐ (I+II+III) | J34: =J9+J10+J21 -> 12000 | K34: =J34*$K$5 -> 240000 | L34: =J34/$J$58 -> 0.92307692
C35: B | D35: CÔNG ĐOẠN TẠO VẢY MIXED: | K35: =J35*$K$5 -> 0
C36: IV | F36: Chi phí Vảy GCDĐ | G36: Kg | H36: 1 | I36: =+J34 -> 12000 | J36: =+H36*I36 -> 12000 | K36: =J36*$K$5 -> 240000 | L36: =J36/$J$58 -> 0.92307692
C37: V | F37: Chi phí mixed màu | J37: =SUM(J40:J57) -> 1000 | K37: =J37*$K$5 -> 20000 | L37: =J37/$J$58 -> 0.076923077
A38: Rửa | C38: 0 | D38: VBAL1 | F38: Công suất máy (capacity) | G38: Kg /h | K38: =J38*$K$5 -> 0
A39: Rửa | F39: Hiệu suất máy | G39: % | K39: =J39*$K$5 -> 0
B40: Vảy GCDĐ | J40: =+($J$34-I40)*H40 -> 0 | K40: =J40*$K$5 -> 0 | L40: =J40/$J$58 -> 0
B41: Hao hụt | J41: =+($J$34-I41)*H41 -> 0 | K41: =J41*$K$5 -> 0 | L41: =J41/$J$58 -> 0
...
