Workbook
Name _1: #REF!
Name _2: #REF!
Name _3: #REF!
Name _4: #REF!
Name _5: #REF!
Name a: #REF!
Name Accounts: #REF!
Name Activity_Reports: #REF!
Name ADM: #REF!
Name Application: #REF!
Name B: #REF!
Name back: #REF!
Name Calendar: #REF!
Name Catalogue_xls: #REF!
Name CompanyCode: #REF!
Name Contractingdiv: #REF!
Name corporate_affairs: #REF!
Name CTY: #REF!
Name Data_Values: #REF!
Name DATA13: #REF!
Name DATA14: #REF!
Name DATA15: #REF!
Name DATA16: #REF!
Name DATA17: #REF!
Name DATA18: #REF!
Name DATA19: #REF!
Name DATA20: #REF!
Name DATA21: #REF!
Name DATA22: #REF!
Name DATA23: #REF!
Name DATA24: #REF!
Name DATA25: #REF!
Name DATA26: #REF!
Name DATA27: #REF!
Name DATA28: #REF!
Name DATA29: #REF!
Name DATA30: #REF!
Name DATA31: #REF!
Name DATA32: #REF!
Name DATA33: #REF!
Name DATA34: #REF!
Name DATA35: #REF!
Name DATA36: #REF!
Name DATA37: #REF!
Name Date_of_separation: #REF!
Name DeptCode: #REF!
Name dinhbien2021: #REF!
Name DivisionCode: #REF!
Name DoCty: #REF!
Name DoDM: #REF!
Name DoMD: #REF!
Name dow: #REF!
Name DT: #REF!
Name ERP: #REF!
Name Excise: #REF!
Name Expectations: #REF!
Name EXR: #REF!
Name EXR: #REF!
Name fdg: #REF!
Name Finanacialsys: #REF!

Sheet Timeline & PIC
B1: DUY TAN GROUP
B2: =IF(B3="EN","Schedule Annual Plan 2025","Lịch lập NGÂN SÁCH năm 2026") -> #REF! | D2: =IF(B3="EN","Start:","Bắt đầu:") -> #REF! | E2: 45915
B3: =#REF! -> #REF! | D3: =IF(B3="EN","Finish:","Kết thúc:") -> #REF! | E3: =G22 -> 45990 | G3: =E3-E2 -> 75
D4: =IF(B3="en","SENDER","Đơn vị gửi") -> #REF! | E4: =IF(B3="EN","RECEIVER","Đơn vị nhận") -> #REF! | G4: Deadline | H4: THÁNG 09 | AM4: THÁNG 10 | BR4: THÁNG 11
B5: No. | C5: =IF(B3="EN","PROCESS","TRÌNH TỰ THỰC HIỆN") -> #REF! | F5: Thời gian | H5: 1 | I5: 2 | J5: 3 | K5: 4 | L5: 5 | M5: 6 | N5: 7 | O5: 8 | P5: 9 | Q5: 10 | R5: 11 | S5: 12 | T5: 13 | U5: 14 | V5: 15 | W5: 16 | X5: 17 | Y5: 18 | Z5: 19 | AA5: 20 | AB5: 21 | AC5: 22 | AD5: 23 | AE5: 24 | AF5: 25 | AG5: 26 | AH5: 27 | AI5: 28 | AJ5: 29 | AK5: 30 | AL5: 31 | AM5: 1 | AN5: 2 | AO5: 3 | AP5: 4 | AQ5: 5 | AR5: 6 | AS5: 7 | AT5: 8 | AU5: 9 | AV5: 10 | AW5: 11 | AX5: 12 | AY5: 13 | AZ5: 14 | BA5: 15 | BB5: 16 | BC5: 17 | BD5: 18 | BE5: 19 | BF5: 20 | BG5: 21 | BH5: 22 | BI5: 23 | BJ5: 24 | BK5: 25 | BL5: 26 | BM5: 27 | BN5: 28 | BO5: 29 | BP5: 30 | BQ5: 31 | BR5: 1 | BS5: =BR5+1 -> 2 | BT5: =BS5+1 -> 3 | BU5: =BT5+1 -> 4 | BV5: =BU5+1 -> 5 | BW5: =BV5+1 -> 6 | BX5: =BW5+1 -> 7 | BY5: =BX5+1 -> 8 | BZ5: =BY5+1 -> 9 | ... CT5: =CS5+1 -> 29 | CU5: 30
F6: (Ngày) | H6: M | I6: T | J6: W | K6: TH | L6: F | M6: Sa | N6: Su | O6: M | P6: T | Q6: W | R6: TH | S6: F | T6: Sa | U6: Su | V6: M | W6: T | X6: W | Y6: TH | Z6: F | AA6: Sa | AB6: Su | AC6: M | AD6: T | AE6: W | AF6: TH | AG6: F | AH6: Sa | AI6: Su | AJ6: M | AK6: T | AL6: W | AM6: TH | AN6: F | AO6: Sa | AP6: Su | AQ6: M | AR6: T | AS6: W | AT6: TH | AU6: F | AV6: Sa | AW6: Su | AX6: M | AY6: T | AZ6: W | BA6: TH | BB6: F | BC6: Sa | BD6: Su | BE6: M | BF6: T | BG6: W | BH6: TH | BI6: F | BJ6: Sa | BK6: Su | BL6: M | BM6: T | BN6: W | BO6: TH | BP6: F | BQ6: Sa | BR6: Su | BS6: M | BT6: T | BU6: W | BV6: TH | BW6: F | BX6: Sa | BY6: Su | BZ6: M | CA6: T | CB6: W | CC6: TH | CD6: F | CE6: Sa | CF6: Su | CG6: M | CH6: T | CI6: W | CJ6: TH | CK6: F | CL6: Sa | CM6: Su | CN6: M | CO6: T | CP6: W | CQ6: TH | CR6: F | CS6: Sa | CT6: Su | CU6: M
B7: 1 | C7: Khởi động | D7: GĐTC holding | E7: =IF(B3="EN","All","Tất cả") -> #REF! | G7: =E2 -> 45915
B8: 2 | C8: Kế hoạch Doanh thu / Sản lượng | D8: =IF(B3="EN","Sales team","Phòng kinh doanh") -> #REF! | E8: =IF(B3="EN","Acct.","Kế toán") -> #REF! | F8: 15 | G8: =F8+$G$7 -> 45930
B9: 3 | C9: Kế hoạch giá cả nguyên vật liệu | D9: =IF(B2="EN","Supply chain","Chuỗi cung ứng") -> #REF! | E9: =E8 -> #REF! | F9: 15 | G9: =F9+$G$7 -> 45930
B10: =B9+1 -> 4 | C10: Kế hoạch chi phí vận chuyển, cước xuất khẩu,... | D10: =IF(B3="EN","Supply chain","Chuổi cung ứng") -> #REF! | E10: =E9 -> #REF! | F10: 15 | G10: =F10+$G$7 -> 45930
B11: =B10+1 -> 5 | C11: Kế hoạch sản xuất | D11: =IF(B3="EN","Production","Bộ phận sản xuất") -> #REF! | E11: =E10 -> #REF! | F11: 20 | G11: =F11+$G$7 -> 45935
B12: =B11+1 -> 6 | C12: Kế hoạch biến phí sản xuất | D12: =E12 -> #REF! | E12: =E11 -> #REF! | F12: 20 | G12: =F12+$G$7 -> 45935
B13: =B12+1 -> 7 | C13: Kế hoạch nhân sự (số lượng nhân sự, quỹ lương, chi phí đào tạo,...) | D13: =IF(B3="EN","HR","Phòng nhân sự") -> #REF! | E13: =E12 -> #REF! | F13: 30 | G13: =F13+$G$7 -> 45945
B14: =B13+1 -> 8 | C14: Ngân sách đầu tư | D14: =E7 -> #REF! | E14: =E13 -> #REF! | F14: 30 | G14: =F14+$G$7 -> 45945
B15: =B14+1 -> 9 | C15: Ngân sách chi phí sản xuất (không bao gồm lương) | D15: =D11 -> #REF! | E15: =E14 -> #REF! | F15: 30 | G15: =F15+$G$7 -> 45945
B16: =B15+1 -> 10 | C16: Ngân sách chi phí bán hàng & chí phí quản lý (không bao gồm lương) | D16: =D14 -> #REF! | E16: =E15 -> #REF! | F16: 30 | G16: =F16+$G$7 -> 45945
B17: =B16+1 -> 11 | C17: Tổng hợp kết quả ngân sách mỗi công ty | D17: Kế toán quản trị | E17: KTT/GĐTC | F17: 45 | G17: =F17+$G$7 -> 45960
B18: 12 | C18: Trình bày kết quả ngân sách của mỗi công ty đến TGĐ (Bottom up) | D18: KTT/GĐTC | E18: TGĐ | F18: 50 | G18: =F18+$G$7 -> 45965
B19: 13 | C19: Trình bày kết quả ngân sách của mỗi công ty đến TGĐ (Top down) | D19: KTT/GĐTC | E19: TGĐ | F19: 55 | G19: =F19+$G$7 -> 45970
B20: 14 | C20: Trình bày kết quả ngân sách của mỗi công ty đến TGĐ (Chính thức) | D20: KTT/GĐTC | E20: TGĐ | F20: 62 | G20: =F20+$G$7 -> 45977
B21: 15 | C21: Hợp nhất ngân sách cho toàn bộ DT Group | D21: KTQT holding | E21: GĐTC holding | F21: 70 | G21: =F21+$G$7 -> 45985
B22: 16 | C22: Trình bày kết quả ngân sách hợp nhất cho toàn bộ DT Group | D22: GĐTC holding | E22: TGĐ | F22: 75 | G22: =F22+$G$7 -> 45990

Sheet Thongtin
B2: STT | C2: Nội dung | D2: Nguồn cung cấp dữ liệu | E2: Nguồn thông tin liên quan | F2: Thời gian cần dữ liệu | H2: STT | I2: Màu sheet | J2: Thông tin
B3: 1 | C3: Ban hành Nhóm-Loại NVL Trạm thu mua | D3: GĐĐH Trạm - DTR | E3: 1. BGĐ DTR 2. Phòng cung ứng DTR | F3: 45940 | H3: 1 | J3: Kết quả kinh doanh tổng hợp
B4: 2 | C4: Ban hành Sản lượng Trạm thu mua | D4: GĐĐH Trạm - DTR | E4: 1. BGĐ DTR 2. Phòng cung ứng DTR | F4: 45940 | H4: 2 | J4: Kết quả kinh doanh PET và HD
B5: 3 | C5: Ban hành đơn giá MUA từng loại NVL | D5: GĐĐH Trạm - DTR | E5: 1. Phòng cung ứng DTR đề xuất KH năm 2026 (Dữ liệu theo từng tháng) 2. KTT các trạm cung cấp đơn giá bình quân thực tế mua theo từng tháng ( Dữ liệu năm 2023-2024-2025) 3. Đơn giá BGĐ-DTR duyệt mua trong năm 2025 (Dữ liệu theo từng tháng) | F5: 45940 | H5: 3 | J5: Kết quả kinh doanh PET và HD
B6: 4 | C6: Ban hành đơn giá BÁN từng loại thành phẩm | D6: GĐĐH Trạm - DTR | E6: 1. BGĐ DTR 2. Phòng cung ứng DTR | F6: 45940 | H6: 4 | J6: Ban hành Định mức về Công suất MMTB - Định mức về CP phục vụ sản xuất - Định biên Nhân sự
B7: 5 | C7: Kế hoạch đầu tư CAPEX tại Trạm => Ảnh hưởng đến Sản phẩm và TCKT Trạm cung cấp đến DTR | D7: GĐĐH Trạm - DTR | E7: 1. BGĐ DTR 2. Phòng kỹ thuật DTR 3. Phòng mua hàng DTR | F7: 45940 | H7: 5 | J7: Ban hành sản lượng - đơn giá - Cơ cấu về: NVL - Thành phẩm - Hao hụt - Bán hàng
H8: 6 | J8: Nhóm Chi phí:CP Sản xuất - CP Bán hàng - CP Quản lý (Công thức từ: Định mức - Lương - PB_TSCD - PB_CPTT - nhóm NVL - Phát sinh trực tiếp)
H9: 7 | J9: Cập nhật TSCĐ - CPTT năm trước chuyển sang và Capex 2026
H10: 8 | I10: … | J10: Thông tin khác

Sheet KH hanh dong
A3: KẾ HOẠCH KINH DOANH 2026
A4: Nguồn yêu cầu: GĐTC-DTR
A5: STT | B5: Nhóm công việc | C5: Kế hoạch hành động | D5: Người thực hiện | E5: Thời gian hoàn thành tính toán và xác lập mục tiêu 2026 | F5: Hiện trạng / vướng mắt / giải pháp (tại thời điểm tháng 10/2025) | G5: Mục tiêu 2026 (rolling hàng tháng) | U5: KHNS 2026 | V5: Thực hiện 2025 | W5: Tăng/giảm vs KHNS 2026
G6: Đánh giá KQ đạt được (cập nhật đến thời điểm báo cáo) | H6: Mục tiêu T1 | I6: Mục tiêu T2 | J6: Mục tiêu T3 | K6: Mục tiêu T4 | L6: Mục tiêu T5 | M6: Mục tiêu T6 | N6: Mục tiêu T7 | O6: Mục tiêu T8 | P6: Mục tiêu T9 | Q6: Mục tiêu T10 | R6: Mục tiêu T11 | S6: Mục tiêu T12 | T6: Dự báo KQ 2026 | W6: Theo số tiền phát sinh | X6: Theo mức độ hoạt động | Y6: %
A7: A | B7: HOẠT ĐỘNG MUA HÀNG
A8: 1 | B8: Đáp ứng sản lượng mua cho Trạm | C8: Lập mục tiêu sản lượng mua để Trạm đạt hòa vốn và có lãi.
C9: Xây dựng các trạm vệ tinh để tăng lượng chai về Trạm.
C10: Phát triển thêm các NCC liên kết ở tỉnh.
C11: Đàm phán tăng sản lượng mua từ các NCC đang giao dịch.
A12: 2 | B12: Cải thiện dịch vụ khách hàng | C12: Cải thiện thời gian nhận hàng
C13: Thanh toán trong ngày và cuối tuần
A14: B | B14: HOẠT ĐỘNG BÁN HÀNG
A15: 1 | B15: Giá bán về DTR | C15: Áp dụng cơ cấu giá mới từ Tháng 9/2025
A16: 2 | B16: Kiểm soát tồn kho thành phẩm | C16: Lập KH giao hàng về DTR hàng ngày, ngày cuối tháng không để tồn kho và xuất hóa đơn 100%
A17: 3 | B17: Chi phí thuê xe vận chuyển | C17: - Đàm phán giảm giá, đề nghị NCC sử dụng phương tiện vận chuyển hiệu quả. - Tìm NCC mới cạnh tranh.
A18: C | B18: HOẠT ĐỘNG CẢI TIẾN CHI PHÍ
A19: I | B19: Chi phí nguyên vật liệu
A20: 1 | B20: Kiểm soát lượng mua, giá mua | C20: - Lập mục tiêu tồn kho tối thiểu 10 ngày sản xuất và phối hợp P.Cung ứng lập KH mua hàng theo tuần. - Kiểm soát giá mua tương ứng với từng mức chất lượng chai.
A21: 2 | B21: Kiểm soát chất lượng NVL, hao hụt | C21: Kiểm soát chất lượng chai (tỷ lệ chai nguyên liệu - Chai xá/xô tuyển, thành phần chai sau phân loại, tỷ lệ tạp chất).
A22: 3 | B22: Kiểm soát định mức vật tư sản xuất (hóa chất, dây đai, vật tư kỹ thuật …) | C22: - Thống kê và thực hiện cải tiến tiêu hao. - Mua tập trung tại P.Mua hàng DTR.
A23: 4 | B23: Xử lý phế liệu, phó sản thu hồi | C23: Phân loại phế liệu thành 2 nhóm: - Nhóm hàng hóa (nhãn, bao jumbo, kim loại,…): tìm đơn vị thu mua giá cao - Nhóm rác thải công nghiệp (bùn, hỗn hợp tạp chất): thuê thu gom
A24: II | B24: Chi phí nhân công
A25: 1 | B25: Định mức NCTT | C25: - Kiểm soát định mức NCTT theo chuyền/công đoạn. - Thực hiện tiêu chuẩn hóa/tự động hóa MMTB để giảm nhân công, tăng năng suất. - Tăng số lượng lao động thời vụ. - Tính toán phương án trả lương/ thưởng theo sản lượng.
A26: 2 | B26: Năng suất lao động | C26: - Lập mục tiêu tăng thời gian sản xuất từ 8 giờ/ngày -> 12 giờ -> 16 giờ -> 24 giờ.
A27: III | B27: Chi phí sản xuất chung
A28: 1 | B28: Chi phí điện | C28: - Phối hợp kỹ thuật bảo trì MMTB đảm bảo hoạt động liên tục -> tăng hiệu quả sử dụng điện và tăng năng suất lao động.
A29: 2 | B29: Chi phí xe nâng | C29: - Chuyển dần xe nâng dầu từ DTR về các Trạm (các xe của trạm sửa chữa nhiều sẽ thanh lý)
A30: 3 | B30: Chi phí khấu hao TSCĐ, CCDC, chi phí phân bổ khác | C30: - Thống kê, đánh giá lại hiệu quả sử dụng tất cả TS. - Tách chi phí khấu hao/phân bổ không phục vụ trực tiếp hoạt động để đánh giá hiệu quả KD thực của trạm.
A31: 4 | B31: Chi phí thuê xưởng | C31: - Tìm vị trí và đề xuất phương án di dời nhà máy để giảm tiền thu, tăng hiệu quả thu mua.
A32: IV | B32: Chi phí quản lý
A33: 1 | B33: Chi phí lương (gồm gián tiếp SX) | C33: Soát xét định biên và kế hoạch tuyển dụng, lập mục tiêu giảm định biên đến cuối 2026
A34: 2 | B34: Chi phí theo mục phí (ngoài chi phí lương) | C34: - Lập danh mục chi phí dịch vụ thuê/mua trả tiền định kỳ (nhóm dịch vụ/phòng ban quản lý, tên NCC, hợp đồng mới nhất, tiền trả định kỳ tháng/quý/năm, thời hạn công nợ) -> đàm phán từng NC giảm giá và tìm NCC mới cạnh tranh - XD định mức chi phí cho các khoản mục có thể xác lập định mức - Phân tích chi phí, nguyên nhân tăng/giảm và giải pháp cải tiến.
A35: V | B35: Mục tiêu lợi nhuận
A36: 1 | B36: Lợi nhuận kế hoạch đến cuối năm 2026 | C36: Sau khi đánh giá, xác lập các mục tiêu bên trên, tính toán lợi nhuận kế hoạch đến cuối năm 2026

Sheet KQKD Tong hop
B3: KẾ HOẠCH KINH DOANH NĂM 2026 | S3: ĐVT: Triệu đồng
B4: STT | C4: Mục phí | D4: Thực tế năm 2023 | E4: Thực tế năm 2024 | F4: Thực tế năm 2025 | G4: T1 | H4: T2 | I4: T3 | J4: T4 | K4: T5 | L4: T6 | M4: T7 | N4: T8 | O4: T9 | P4: T10 | Q4: T11 | R4: T12 | S4: 10/03/2026 DTR
C5: SẢN LƯỢNG NVL MUA VÀO (Tấn) | D5: 3173 | E5: 4044 | F5: 6481062 | G5: ='1.NVL Chai'!G16 -> 780000 | H5: ='1.NVL Chai'!H16 -> 450000 | I5: ='1.NVL Chai'!I16 -> 1040000 | J5: ='1.NVL Chai'!J16 -> 1250000 | K5: ='1.NVL Chai'!K16 -> 1250000 | L5: ='1.NVL Chai'!L16 -> 1300000 | M5: ='1.NVL Chai'!M16 -> 1350000 | N5: ='1.NVL Chai'!N16 -> 1300000 | ... S5: ='1.NVL Chai'!S16 -> 13870000 | T5: =S5/F5 -> 2.1400814
B6: 1 | C6: SẢN LƯỢNG BÁN (TẤN) | D6: 3125610.5 | E6: 4267466 | F6: 5702390 | G6: =G7+G8+G9 -> 689520 | H6: =H7+H8+H9 -> 397800 | I6: =I7+I8+I9 -> 918840 | J6: =J7+J8+J9 -> 1025362.5 | K6: =K7+K8+K9 -> 1025362.5 | L6: =L7+L8+L9 -> 1066377 | M6: =M7+M8+M9 -> 1107391.5 | N6: =N7+N8+N9 -> 1066377 | ... R6: =R7+R8+R9 -> 1107391.5 | S6: =SUM(G6:R6) -> 11521524 | T6: =S6/F6 -> 2.0204728
B7: 1.1 | C7: Chai PET | D7: 2879091.5 | E7: 3867466 | F7: 5702390 | G7: ='4.Doanh thu'!F$22 -> 689520 | H7: ='4.Doanh thu'!G$22 -> 397800 | I7: ='4.Doanh thu'!H$22 -> 918840 | J7: ='4.Doanh thu'!I$22 -> 35312.5 | K7: ='4.Doanh thu'!J$22 -> 35312.5 | L7: ='4.Doanh thu'!K$22 -> 36725 | M7: ='4.Doanh thu'!L$22 -> 38137.5 | N7: ='4.Doanh thu'!M$22 -> 36725 | ... R7: ='4.Doanh thu'!Q$22 -> 38137.5 | S7: =SUM(G7:R7) -> 2333860
B8: 1.2 | C8: Vảy PET | D8: 0 | E8: 400000 | F8: 0 | G8: ='4.Doanh thu'!F$80 -> 0 | H8: ='4.Doanh thu'!G$80 -> 0 | I8: ='4.Doanh thu'!H$80 -> 0 | J8: ='4.Doanh thu'!I$80 -> 990050 | K8: ='4.Doanh thu'!J$80 -> 990050 | L8: ='4.Doanh thu'!K$80 -> 1029652 | M8: ='4.Doanh thu'!L$80 -> 1069254 | N8: ='4.Doanh thu'!M$80 -> 1029652 | ... R8: ='4.Doanh thu'!Q$80 -> 1069254 | S8: =SUM(G8:R8) -> 9187664 | T8: =S8/S6 -> 0.79743478
B9: 1.3 | C9: Vảy HD | D9: 246519 | E9: 0 | F9: 0 | S9: =SUM(G9:R9) -> 0
B10: 2 | C10: DOANH THU | D10: 44482013609 | E10: 63950445550 | F10: 96184706621 | G10: =G11+G12+G13+G14 -> 9705618000 | H10: =H11+H12+H13+H14 -> 5599395000 | I10: =I11+I12+I13+I14 -> 12929826000 | J10: =J11+J12+J13+J14 -> 16437125000 | K10: =K11+K12+K13+K14 -> 16437125000 | L10: =L11+L12+L13+L14 -> 17094610000 | M10: =M11+M12+M13+M14 -> 17752095000 | N10: =N11+N12+N13+N14 -> 17094610000 | ... R10: =R11+R12+R13+R14 -> 17752095000 | S10: =SUM(G10:R10) -> 180771359000 | T10: =S10/F10 -> 1.8794189 | U10: =F10/F$10 -> 1 | V10: =G10/G$10 -> 1
B11: 2.1 | C11: Chai PET | D11: 39992361315 | E11: 58441845550 | F11: 96184706621 | G11: ='4.Doanh thu'!F$60 -> 9705618000 | H11: ='4.Doanh thu'!G$60 -> 5599395000 | I11: ='4.Doanh thu'!H$60 -> 12929826000 | J11: ='4.Doanh thu'!I$60 -> 367687500 | K11: ='4.Doanh thu'!J$60 -> 367687500 | L11: ='4.Doanh thu'!K$60 -> 382395000 | M11: ='4.Doanh thu'!L$60 -> 397102500 | N11: ='4.Doanh thu'!M$60 -> 382395000 | ... R11: ='4.Doanh thu'!Q$60 -> 397102500 | S11: =SUM(G11:R11) -> 31646979000 | T11: =S11/F11 -> 0.32902298 | U11: =F11/F$10 -> 1 | V11: =G11/G$10 -> 1
B12: 2.2 | C12: Vảy PET | D12: 0 | E12: 5508600000 | F12: 0 | G12: ='4.Doanh thu'!F$118 -> 0 | H12: ='4.Doanh thu'!G$118 -> 0 | I12: ='4.Doanh thu'!H$118 -> 0 | J12: ='4.Doanh thu'!I$118 -> 16069437500 | K12: ='4.Doanh thu'!J$118 -> 16069437500 | L12: ='4.Doanh thu'!K$118 -> 16712215000 | M12: ='4.Doanh thu'!L$118 -> 17354992500 | N12: ='4.Doanh thu'!M$118 -> 16712215000 | ... R12: ='4.Doanh thu'!Q$118 -> 17354992500 | S12: =SUM(G12:R12) -> 149124380000 | T12: =S12/F12 -> #DIV/0! | U12: =F12/F$10 -> 0 | V12: =G12/G$10 -> 0 | W12: =S12/S10 -> 0.82493367
B13: 2.3 | C13: Vảy HD | D13: 4489652294 | E13: 0 | F13: 0 | S13: =SUM(G13:R13) -> 0 | T13: =S13/F13 -> #DIV/0! | U13: =F13/F$10 -> 0 | V13: =G13/G$10 -> 0
B14: 2.4 | C14: Khác | D14: 0 | E14: 0 | F14: 0 | S14: =SUM(G14:R14) -> 0 | T14: =S14/F14 -> #DIV/0! | U14: =F14/F$10 -> 0 | V14: =G14/G$10 -> 0
B15: 3 | C15: BIẾN PHÍ | D15: 4.3469013e+10 | E15: 60363389060 | F15: 85223230750 | G15: =G16+G24 -> 8.5772159e+09 | H15: =H16+H24 -> 5.0796935e+09 | I15: =I16+I24 -> 1.1828102e+10 | J15: =J16+J24 -> 1.492362e+10 | K15: =K16+K24 -> 1.5012357e+10 | L15: =L16+L24 -> 1.5598926e+10 | M15: =M16+M24 -> 1.6158965e+10 | N15: =N16+N24 -> 1.5586374e+10 | ... R15: =R16+R24 -> 1.6158093e+10 | S15: =SUM(G15:R15) -> 1.6455282e+11 | T15: =S15/F15 -> 1.9308447 | U15: =F15/F$10 -> 0.88603723 | V15: =G15/G$10 -> 0.88373723
B16: 3.1 | C16: BIẾN PHÍ SẢN XUẤT | D16: 4.2103863e+10 | E16: 59322702660 | F16: 83097930750 | G16: =G17+G21+G22+G23 -> 8.3014079e+09 | H16: =H17+H21+H22+H23 -> 4.9205735e+09 | I16: =I17+I21+I22+I23 -> 1.1460566e+10 | J16: =J17+J21+J22+J23 -> 1.4592679e+10 | K16: =K17+K21+K22+K23 -> 1.4681416e+10 | L16: =L17+L21+L22+L23 -> 1.5254748e+10 | M16: =M17+M21+M22+M23 -> 1.5801549e+10 | N16: =N17+N21+N22+N23 -> 1.5242196e+10 | ... R16: =R17+R21+R22+R23 -> 1.5800677e+10 | S16: =SUM(G16:R16) -> 1.6067923e+11 | T16: =S16/F16 -> 1.9336129 | U16: =F16/F$10 -> 0.8639412 | V16: =G16/G$10 -> 0.85531987
B17: 3.1.1 | C17: Nguyên vật liệu chính (nhựa, gồm hao hụt) | D17: 38732631964 | E17: 56030510590 | F17: 78338746231 | G17: ='1.NVL Chai'!G$42 -> 7566000000 | H17: ='1.NVL Chai'!H$42 -> 4275000000 | I17: ='1.NVL Chai'!I$42 -> 10400000000 | J17: ='1.NVL Chai'!J$42 -> 12500000000 | K17: ='1.NVL Chai'!K$42 -> 12500000000 | L17: ='1.NVL Chai'!L$42 -> 13000000000 | M17: ='1.NVL Chai'!M$42 -> 13500000000 | N17: ='1.NVL Chai'!N$42 -> 13000000000 | ... R17: ='1.NVL Chai'!R$42 -> 13500000000 | S17: =SUM(G17:R17) -> 138241000000 | T17: =S17/F17 -> 1.7646568 | U17: =F17/F$10 -> 0.81446156 | V17: =G17/G$10 -> 0.7795485
B18: 3.1.2 | C18: Trong đó: i/ Hao hụt CĐ phân loại chai | D18: 2260066610 | E18: 4917236579 | F18: 8584125746 | G18: =('3.Thanh pham'!G$187+'3.Thanh pham'!G$188)*'1.NVL Chai'!G$34 -> 877656000 | H18: =('3.Thanh pham'!H$187+'3.Thanh pham'!H$188)*'1.NVL Chai'!H$34 -> 495900000 | I18: =('3.Thanh pham'!I$187+'3.Thanh pham'!I$188)*'1.NVL Chai'!I$34 -> 1211600000 | J18: =('3.Thanh pham'!J$187+'3.Thanh pham'!J$188)*'1.NVL Chai'!J$34 -> 1456250000 | K18: =('3.Thanh pham'!K$187+'3.Thanh pham'!K$188)*'1.NVL Chai'!K$34 -> 1456250000 | L18: =('3.Thanh pham'!L$187+'3.Thanh pham'!L$188)*'1.NVL Chai'!L$34 -> 1514500000 | M18: =('3.Thanh pham'!M$187+'3.Thanh pham'!M$188)*'1.NVL Chai'!M$34 -> 1572750000 | N18: =('3.Thanh pham'!N$187+'3.Thanh pham'!N$188)*'1.NVL Chai'!N$34 -> 1514500000 | ... R18: =('3.Thanh pham'!R$187+'3.Thanh pham'!R$188)*'1.NVL Chai'!R$34 -> 1572750000 | S18: =SUM(G18:R18) -> 16099156000 | T18: =S18/F18 -> 1.8754567 | U18: =F18/F$10 -> 0.089246264 | V18: =G18/G$10 -> 0.090427627
C19: ii/ Hao hụt CĐ băm vảy | D19: 0 | E19: 0 | F19: 0 | G19: =('3.Thanh pham'!G$190)*'1.NVL Chai'!G$34 -> 0 | H19: =('3.Thanh pham'!H$190)*'1.NVL Chai'!H$34 -> 0 | I19: =('3.Thanh pham'!I$190)*'1.NVL Chai'!I$34 -> 0 | J19: =('3.Thanh pham'!J$190)*'1.NVL Chai'!J$34 -> 790125000 | K19: =('3.Thanh pham'!K$190)*'1.NVL Chai'!K$34 -> 790125000 | L19: =('3.Thanh pham'!L$190)*'1.NVL Chai'!L$34 -> 821730000 | M19: =('3.Thanh pham'!M$190)*'1.NVL Chai'!M$34 -> 853335000 | N19: =('3.Thanh pham'!N$190)*'1.NVL Chai'!N$34 -> 821730000 | ... R19: =('3.Thanh pham'!R$190)*'1.NVL Chai'!R$34 -> 853335000 | S19: =SUM(G19:R19) -> 7332360000 | T19: =S19/F19 -> #DIV/0! | U19: =F19/F$10 -> 0 | V19: =G19/G$10 -> 0
B20: 3.1.3 | C20: % chi phí nguyên liệu/doanh thu | D20: 0.87074817 | E20: 0.87615512 | F20: 0.81446156 | G20: =G17/G10 -> 0.7795485 | H20: =H17/H10 -> 0.76347534 | I20: =I17/I10 -> 0.80434184 | J20: =J17/J10 -> 0.76047362 | K20: =K17/K10 -> 0.76047362 | L20: =L17/L10 -> 0.76047362 | M20: =M17/M10 -> 0.76047362 | N20: =N17/N10 -> 0.76047362 | ... S20: =S17/S10 -> 0.76472844 | T20: =S20/F20 -> 0.93893743 | U20: =F20/F$10 -> 8.4676825e-12 | V20: =G20/G$10 -> 8.0319306e-11 | W20: =F20-S20 -> 0.049733117
B21: 3.1.4 | C21: Nguyên vật liệu phụ | D21: 638275817 | E21: 511506981 | F21: 995011960 | G21: =SUM(CPSX!K$41:K$47)+SUM(CPSX!K$63:K$69) -> 1.3614546e+08 | H21: =SUM(CPSX!L$41:L$47)+SUM(CPSX!L$63:L$69) -> 1.0901108e+08 | I21: =SUM(CPSX!M$41:M$47)+SUM(CPSX!M$63:M$69) -> 2.2271629e+08 | J21: =SUM(CPSX!N$41:N$47)+SUM(CPSX!N$63:N$69) -> 8.2920734e+08 | K21: =SUM(CPSX!O$41:O$47)+SUM(CPSX!O$63:O$69) -> 9.3259777e+08 | L21: =SUM(CPSX!P$41:P$47)+SUM(CPSX!P$63:P$69) -> 9.6958168e+08 | M21: =SUM(CPSX!Q$41:Q$47)+SUM(CPSX!Q$63:Q$69) -> 1.0065656e+09 | N21: =SUM(CPSX!R$41:R$47)+SUM(CPSX!R$63:R$69) -> 9.6958168e+08 | ... R21: =SUM(CPSX!V$41:V$47)+SUM(CPSX!V$63:V$69) -> 1.0065656e+09 | S21: =SUM(G21:R21) -> 9.0167497e+09 | T21: =S21/F21 -> 9.0619511 | U21: =F21/F$10 -> 0.010344804 | V21: =G21/G$10 -> 0.01402749
B22: 3.1.5 | C22: Điện sản xuất | D22: 160219300 | E22: 225768346 | F22: 424175130 | G22: =CPSX!K$40+CPSX!K$62 -> 1.6538864e+08 | H22: =CPSX!L$40+CPSX!L$62 -> 95416522 | I22: =CPSX!M$40+CPSX!M$62 -> 2.2716263e+08 | J22: =CPSX!N$40+CPSX!N$62 -> 5.4235736e+08 | K22: =CPSX!O$40+CPSX!O$62 -> 5.4235736e+08 | L22: =CPSX!P$40+CPSX!P$62 -> 5.6405166e+08 | M22: =CPSX!Q$40+CPSX!Q$62 -> 5.8574595e+08 | N22: =CPSX!R$40+CPSX!R$62 -> 5.6405166e+08 | ... R22: =CPSX!V$40+CPSX!V$62 -> 5.8574595e+08 | S22: =SUM(G22:R22) -> 5.5210441e+09 | T22: =S22/F22 -> 13.015954 | U22: =F22/F$10 -> 0.004410006 | V22: =G22/G$10 -> 0.017040506
B23: 3.1.6 | C23: Nhân công trực tiếp | D23: 2.5727363e+09 | E23: 2554916743 | F23: 3339997429 | G23: =SUM(CPSX!K$28:K$39)+SUM(CPSX!K$50:K$61) -> 433873828 | H23: =SUM(CPSX!L$28:L$39)+SUM(CPSX!L$50:L$61) -> 441145879 | I23: =SUM(CPSX!M$28:M$39)+SUM(CPSX!M$50:M$61) -> 6.1068742e+08 | J23: =SUM(CPSX!N$28:N$39)+SUM(CPSX!N$50:N$61) -> 7.2111449e+08 | K23: =SUM(CPSX!O$28:O$39)+SUM(CPSX!O$50:O$61) -> 7.0646051e+08 | L23: =SUM(CPSX!P$28:P$39)+SUM(CPSX!P$50:P$61) -> 7.2111449e+08 | M23: =SUM(CPSX!Q$28:Q$39)+SUM(CPSX!Q$50:Q$61) -> 7.0923764e+08 | N23: =SUM(CPSX!R$28:R$39)+SUM(CPSX!R$50:R$61) -> 7.0856235e+08 | ... R23: =SUM(CPSX!V$28:V$39)+SUM(CPSX!V$50:V$61) -> 7.0836539e+08 | S23: =SUM(G23:R23) -> 7.9004329e+09 | T23: =S23/F23 -> 2.3654009 | U23: =F23/F$10 -> 0.034724828 | V23: =G23/G$10 -> 0.04470337
B24: 3.2 | C24: BIẾN PHÍ BÁN HÀNG | D24: 1365150000 | E24: 1040686400 | F24: 2125300000 | G24: =G25 -> 275808000 | H24: =H25 -> 159120000 | I24: =I25 -> 367536000 | J24: =J25 -> 330941000 | K24: =K25 -> 330941000 | L24: =L25 -> 344178640 | M24: =M25 -> 357416280 | N24: =N25 -> 344178640 | ... R24: =R25 -> 357416280 | S24: =SUM(G24:R24) -> 3873596480 | T24: =S24/F24 -> 1.8226116 | U24: =F24/F$10 -> 0.022096028 | V24: =G24/G$10 -> 0.028417356
C25: Chi phí vận chuyển | D25: 1365150000 | E25: 1040686400 | F25: 2125300000 | G25: =CPBH!K$8 -> 275808000 | H25: =CPBH!L$8 -> 159120000 | I25: =CPBH!M$8 -> 367536000 | J25: =CPBH!N$8 -> 330941000 | K25: =CPBH!O$8 -> 330941000 | L25: =CPBH!P$8 -> 344178640 | M25: =CPBH!Q$8 -> 357416280 | N25: =CPBH!R$8 -> 344178640 | ... R25: =CPBH!V$8 -> 357416280 | S25: =SUM(G25:R25) -> 3873596480 | T25: =S25/F25 -> 1.8226116 | U25: =F25/F$10 -> 0.022096028 | V25: =G25/G$10 -> 0.028417356
B26: 4 | C26: LÃI SAU BIẾN PHÍ | D26: 1.0130002e+09 | E26: 3587056490 | F26: 10961475871 | G26: =G10-G15 -> 1.1284021e+09 | H26: =H10-H15 -> 5.1970152e+08 | I26: =I10-I15 -> 1.1017237e+09 | J26: =J10-J15 -> 1.5135048e+09 | K26: =K10-K15 -> 1.4247684e+09 | L26: =L10-L15 -> 1.4956835e+09 | M26: =M10-M15 -> 1.5931295e+09 | N26: =N10-N15 -> 1.5082357e+09 | ... R26: =R10-R15 -> 1.5940018e+09 | S26: =SUM(G26:R26) -> 1.6218536e+10 | T26: =S26/F26 -> 1.4795942 | U26: =F26/F$10 -> 0.11396277 | V26: =G26/G$10 -> 0.11626277
B27: 4.1 | C27: % lãi biến phí/doanh thu | D27: 0.022773255 | E27: 0.056091188 | F27: 0.11396277 | G27: =G26/G10 -> 0.11626277 | H27: =H26/H10 -> 0.09281387 | I27: =I26/I10 -> 0.085207926 | J27: =J26/J10 -> 0.092078439 | K27: =K26/K10 -> 0.086679901 | L27: =L26/L10 -> 0.087494452 | M27: =M26/M10 -> 0.089743185 | N27: =N26/N10 -> 0.088228727 | ... S27: =S26/S10 -> 0.089718503 | T27: =S27/F27 -> 0.7872615 | U27: =F27/F$10 -> 1.1848326e-12 | V27: =G27/G$10 -> 1.1978915e-11
B28: 5 | C28: CHI PHÍ SẢN XUẤT CHUNG | D28: 5.0983022e+08 | E28: 1164487071 | F28: 1910944638 | G28: =G29+G30+G31 -> 3.2322006e+08 | H28: =H29+H30+H31 -> 3.3603316e+08 | I28: =I29+I30+I31 -> 4.0538112e+08 | J28: =J29+J30+J31 -> 8.3610333e+08 | K28: =K29+K30+K31 -> 8.8479654e+08 | L28: =L29+L30+L31 -> 9.0511612e+08 | M28: =M29+M30+M31 -> 9.4733996e+08 | N28: =N29+N30+N31 -> 9.4917077e+08 | ... R28: =R29+R30+R31 -> 9.4405953e+08 | S28: =SUM(G28:R28) -> 9.3982891e+09 | T28: =S28/F28 -> 4.9181378 | U28: =F28/F$10 -> 0.019867448 | V28: =G28/G$10 -> 0.033302367
B29: 5.1 | C29: Lương gián tiếp Sản xuất | D29: 3.9856833e+08 | E29: 530657837 | F29: 1201415069 | G29: =SUM(CPSX!K$72:K$83) -> 2.2119959e+08 | H29: =SUM(CPSX!L$72:L$83) -> 2.1904187e+08 | I29: =SUM(CPSX!M$72:M$83) -> 2.0794514e+08 | J29: =SUM(CPSX!N$72:N$83) -> 378400505 | K29: =SUM(CPSX!O$72:O$83) -> 365430740 | L29: =SUM(CPSX!P$72:P$83) -> 378400505 | M29: =SUM(CPSX!Q$72:Q$83) -> 368841683 | N29: =SUM(CPSX!R$72:R$83) -> 368646707 | ... R29: =SUM(CPSX!V$72:V$83) -> 368589849 | S29: =SUM(G29:R29) -> 3.9940596e+09 | T29: =S29/F29 -> 3.3244627 | U29: =F29/F$10 -> 0.012490708 | V29: =G29/G$10 -> 0.022790882
B30: 5.2 | C30: Chi phí thuê xưởng | G30: =CPSX!K$88 -> 0 | H30: =CPSX!L$88 -> 0 | I30: =CPSX!M$88 -> 0 | J30: =CPSX!N$88 -> 1.9260139e+08 | K30: =CPSX!O$88 -> 1.9260139e+08 | L30: =CPSX!P$88 -> 1.9260139e+08 | M30: =CPSX!Q$88 -> 1.9260139e+08 | N30: =CPSX!R$88 -> 1.9260139e+08 | ... R30: =CPSX!V$88 -> 1.9260139e+08 | S30: =SUM(G30:R30) -> 1.7334125e+09 | T30: =S30/F30 -> #DIV/0! | U30: =F30/F$10 -> 0 | V30: =G30/G$10 -> 0
B31: 5.3 | C31: Chi phí sản xuất (Ngoài lương, BOM, thuê xưởng, khấu hao) | D31: 1.1126189e+08 | E31: 633829234 | F31: 709529569 | G31: =SUM(CPSX!K$84:K$98)-CPSX!K88 -> 1.0202046e+08 | H31: =SUM(CPSX!L$84:L$98)-CPSX!L88 -> 116991288 | I31: =SUM(CPSX!M$84:M$98)-CPSX!M88 -> 1.9743597e+08 | J31: =SUM(CPSX!N$84:N$98)-CPSX!N88 -> 2.6510144e+08 | K31: =SUM(CPSX!O$84:O$98)-CPSX!O88 -> 3.2676442e+08 | L31: =SUM(CPSX!P$84:P$98)-CPSX!P88 -> 3.3411423e+08 | M31: =SUM(CPSX!Q$84:Q$98)-CPSX!Q88 -> 3.8589689e+08 | N31: =SUM(CPSX!R$84:R$98)-CPSX!R88 -> 3.8792268e+08 | ... R31: =SUM(CPSX!V$84:V$98)-CPSX!V88 -> 3.8286829e+08 | S31: =SUM(G31:R31) -> 3.6708171e+09 | T31: =S31/F31 -> 5.1735928 | U31: =F31/F$10 -> 0.00737674 | V31: =G31/G$10 -> 0.010511485
B32: 6 | C32: CHI PHÍ KHẤU HAO | D32: 2815366932 | E32: 3970082577 | F32: 3851337229 | G32: =PB_TSCD!AF$46 -> 2.0364185e+08 | H32: =PB_TSCD!AG$46 -> 2.0900296e+08 | I32: =PB_TSCD!AH$46 -> 2.1483629e+08 | J32: =PB_TSCD!AI$46 -> 2.406974e+08 | K32: =PB_TSCD!AJ$46 -> 2.406974e+08 | L32: =PB_TSCD!AK$46 -> 2.406974e+08 | M32: =PB_TSCD!AL$46 -> 2.406974e+08 | N32: =PB_TSCD!AM$46 -> 2.406974e+08 | ... R32: =PB_TSCD!AQ$46 -> 2.3458629e+08 | S32: =SUM(G32:R32) -> 2.7876466e+09 | T32: =S32/F32 -> 0.72381265 | U32: =F32/F$10 -> 0.040041056 | V32: =G32/G$10 -> 0.020981853
B33: 7 | C33: LỢI NHUẬN GỘP | D33: -2.3121969e+09 | E33: -1547513158 | F33: 5199194004 | G33: =G26-G28-G32 -> 6.0154017e+08 | H33: =H26-H28-H32 -> -25334598 | I33: =I26-I28-I32 -> 4.8150625e+08 | J33: =J26-J28-J32 -> 4.3670407e+08 | K33: =K26-K28-K32 -> 2.9927442e+08 | L33: =L26-L28-L32 -> 3.4987001e+08 | M33: =M26-M28-M32 -> 4.0509218e+08 | N33: =N26-N28-N32 -> 3.183675e+08 | ... R33: =R26-R28-R32 -> 4.1535597e+08 | S33: =SUM(G33:R33) -> 4.0326e+09 | T33: =S33/F33 -> 0.77562023 | U33: =F33/F$10 -> 0.054054269 | V33: =G33/G$10 -> 0.061978554
B34: 7.1 | C34: % lãi gộp/doanh thu | D34: -0.051980491 | E34: -0.02419863 | F34: 0.054054269 | G34: =G33/G10 -> 0.061978554 | H34: =H33/H10 -> -0.0045245242 | I34: =I33/I10 -> 0.037239964 | J34: =J33/J10 -> 0.026568154 | K34: =K33/K10 -> 0.018207224 | L34: =L33/L10 -> 0.020466685 | M34: =M33/M10 -> 0.022819401 | N34: =N33/N10 -> 0.018623853 | ... S34: =S33/S10 -> 0.022307738 | T34: =S34/F34 -> 0.41269151 | U34: =F34/F$10 -> 5.6198403e-13 | V34: =G34/G$10 -> 6.3858431e-12 | W34: ='[1]KE30-DongLam'!$BV$2 -> 0.11073334
B35: 8 | C35: CHI PHÍ BÁN HÀNG & MKT & R&D | D35: 0 | E35: 0 | F35: 0 | G35: =G36+G37+G38 -> 0 | H35: =H36+H37+H38 -> 0 | I35: =I36+I37+I38 -> 0 | J35: =J36+J37+J38 -> 0 | K35: =K36+K37+K38 -> 0 | L35: =L36+L37+L38 -> 0 | M35: =M36+M37+M38 -> 0 | N35: =N36+N37+N38 -> 0 | ... R35: =R36+R37+R38 -> 0 | S35: =SUM(G35:R35) -> 0 | T35: =S35/F35 -> #DIV/0! | U35: =F35/F$10 -> 0 | V35: =G35/G$10 -> 0
B36: 8.1 | C36: Lương | D36: 0 | E36: 0 | F36: 0 | S36: =SUM(G36:R36) -> 0 | T36: =S36/F36 -> #DIV/0! | U36: =F36/F$10 -> 0 | V36: =G36/G$10 -> 0
B37: 8.2 | C37: Chi phí bán hàng (ngoài lương, khấu hao) | D37: 0 | E37: 0 | F37: 0 | S37: =SUM(G37:R37) -> 0 | T37: =S37/F37 -> #DIV/0! | U37: =F37/F$10 -> 0 | V37: =G37/G$10 -> 0
B38: 8.3 | C38: Khấu hao tài sản | D38: 0 | E38: 0 | F38: 0 | S38: =SUM(G38:R38) -> 0 | T38: =S38/F38 -> #DIV/0! | U38: =F38/F$10 -> 0 | V38: =G38/G$10 -> 0
B39: 9 | C39: CHI PHÍ QUẢN LÝ | D39: 1920530080 | E39: 1657750500 | F39: 2232089956 | G39: =G40+G41+G42 -> 299930825 | H39: =H40+H41+H42 -> 364454832 | I39: =I40+I41+I42 -> 320241950 | J39: =J40+J41+J42 -> 351665309 | K39: =K40+K41+K42 -> 345531727 | L39: =L40+L41+L42 -> 3.5930345e+08 | M39: =M40+M41+M42 -> 3.7807215e+08 | N39: =N40+N41+N42 -> 6.5296212e+08 | ... R39: =R40+R41+R42 -> 3.771277e+08 | S39: =SUM(G39:R39) -> 4.5496361e+09 | T39: =S39/F39 -> 2.0382853 | U39: =F39/F$10 -> 0.023206288 | V39: =G39/G$10 -> 0.030902805
B40: 9.1 | C40: Lương | D40: 545455272 | E40: 507934414 | F40: 1445606425 | G40: =SUM(CPQL!K$5:K$16) -> 210647270 | H40: =SUM(CPQL!L$5:L$16) -> 213418574 | I40: =SUM(CPQL!M$5:M$16) -> 1.9799139e+08 | J40: =SUM(CPQL!N$5:N$16) -> 230329766 | K40: =SUM(CPQL!O$5:O$16) -> 221578000 | L40: =SUM(CPQL!P$5:P$16) -> 230329766 | M40: =SUM(CPQL!Q$5:Q$16) -> 224351483 | N40: =SUM(CPQL!R$5:R$16) -> 224328197 | ... R40: =SUM(CPQL!V$5:V$16) -> 223960871 | S40: =SUM(G40:R40) -> 2.6568794e+09 | T40: =S40/F40 -> 1.8378996 | U40: =F40/F$10 -> 0.015029483 | V40: =G40/G$10 -> 0.021703643
B41: 9.2 | C41: Chi phí quản lý (ngoài lương, khấu hao) | D41: 985729687 | E41: 1135468262 | F41: 599521967 | G41: =SUM(CPQL!K$17:K$62) -> 80445799 | H41: =SUM(CPQL!L$17:L$62) -> 142198502 | I41: =SUM(CPQL!M$17:M$62) -> 1.1341281e+08 | J41: =SUM(CPQL!N$17:N$62) -> 1.0999779e+08 | K41: =SUM(CPQL!O$17:O$62) -> 1.1261597e+08 | L41: =SUM(CPQL!P$17:P$62) -> 1.1763592e+08 | M41: =SUM(CPQL!Q$17:Q$62) -> 1.4238291e+08 | N41: =SUM(CPQL!R$17:R$62) -> 4.1729617e+08 | ... R41: =SUM(CPQL!V$17:V$62) -> 1.4182907e+08 | S41: =SUM(G41:R41) -> 1.7642036e+09 | T41: =S41/F41 -> 2.9426838 | U41: =F41/F$10 -> 0.006233028 | V41: =G41/G$10 -> 0.0082885808
B42: 9.3 | C42: Khấu hao tài sản | D42: 389345121 | E42: 14347824 | F42: 186961564 | G42: =PB_TSCD!AF$47 -> 8837756 | H42: =PB_TSCD!AG$47 -> 8837756 | I42: =PB_TSCD!AH$47 -> 8837756 | J42: =PB_TSCD!AI$47 -> 11337756 | K42: =PB_TSCD!AJ$47 -> 11337756 | L42: =PB_TSCD!AK$47 -> 11337756 | M42: =PB_TSCD!AL$47 -> 11337756 | N42: =PB_TSCD!AM$47 -> 11337756 | ... R42: =PB_TSCD!AQ$47 -> 11337756 | S42: =SUM(G42:R42) -> 128553072 | T42: =S42/F42 -> 0.68759091 | U42: =F42/F$10 -> 0.0019437764 | V42: =G42/G$10 -> 0.00091058148
...

Sheet Gia dinh
Q1: Định biên về nhân sự
B2: Phương án 1 | R2: =B6 -> Chuyền PL cũ | T2: =B9 -> Chuyền rework | V2: =B7 -> Chuyền AI 1 | X2: =B8 -> Chuyền AI 2 | Z2: =B10 -> Chuyền băm vảy | AC2: SXC
R3: Ca 1 | S3: Ca 2 | T3: Ca 1 | U3: Ca 2 | V3: Ca 1 | W3: Ca 2 | X3: Ca 1 | Y3: Ca 2 | Z3: Ca 1 | AA3: Ca 2 | AB3: Ca 3 | AC3: Ca 1 | AD3: Ca 2
B4: Công suất máy | O4: Tấn / giờ | Q4: Chi tiết phân bổ Công nhân trực tiếp SX
B5: Chuyền máy | C5: T1 | D5: T2 | E5: T3 | F5: T4 | G5: T5 | H5: T6 | I5: T7 | J5: T8 | K5: T9 | L5: T10 | M5: T11 | N5: T12 | O5: 2026 | Q5: Công nhân trực tiếp sản xuất - Phân loại | R5: =R6+R17+R21 -> 14 | S5: =S6+S17+S21 -> 14 | T5: =T6+T17+T21 -> 6 | U5: =U6+U17+U21 -> 6 | V5: =V6+V17+V21 -> 11 | W5: =W6+W17+W21 -> 11 | X5: =X6+X17+X21 -> 10 | Y5: =Y6+Y17+Y21 -> 10 | ... AD5: =AD6+AD17+AD21 -> 3
B6: Chuyền PL cũ | C6: 1100 | D6: 1100 | E6: 1100 | Q6: SX chai PET - Chuyền phân loại | R6: =SUM(R7:R12) -> 14 | S6: =SUM(S7:S12) -> 14 | T6: =SUM(T7:T12) -> 6 | U6: =SUM(U7:U12) -> 6 | V6: =SUM(V7:V12) -> 11 | W6: =SUM(W7:W12) -> 11 | X6: =SUM(X7:X12) -> 10 | Y6: =SUM(Y7:Y12) -> 10 | AC6: =SUM(AC7:AC12) -> 0 | AD6: =SUM(AD7:AD12) -> 0
B7: Chuyền AI 1 | C7: 1500 | D7: 1500 | E7: 1500 | F7: 1500 | G7: 1500 | H7: 1500 | I7: 1500 | J7: 1500 | K7: 1500 | L7: 1500 | M7: 1500 | N7: 1500 | Q7: Công đoạn 1: Cấp liệu | R7: 1 | S7: 1 | T7: 1 | U7: 1 | V7: 2 | W7: 2 | X7: 1 | Y7: 1
B8: Chuyền AI 2 | F8: 1500 | G8: 1500 | H8: 1500 | I8: 1500 | J8: 1500 | K8: 1500 | L8: 1500 | M8: 1500 | N8: 1500 | Q8: Công đoạn 2: Phân loại trước tách nhãn | R8: 5 | S8: 5 | T8: 2 | U8: 2 | V8: 3 | W8: 3 | X8: 3 | Y8: 3
B9: Chuyền rework | C9: =(C6+C7+C8)*40% -> 1040 | D9: =(D6+D7+D8)*40% -> 1040 | E9: =(E6+E7+E8)*40% -> 1040 | F9: =(F6+F7+F8)*40% -> 1200 | G9: =(G6+G7+G8)*40% -> 1200 | H9: =(H6+H7+H8)*40% -> 1200 | I9: =(I6+I7+I8)*40% -> 1200 | J9: =(J6+J7+J8)*40% -> 1200 | ... N9: =(N6+N7+N8)*40% -> 1200 | Q9: Công đoạn 3: Phân loại sau tách nhãn | R9: 4 | S9: 4 | T9: 1 | U9: 1 | V9: 3 | W9: 3 | X9: 3 | Y9: 3
B10: Chuyền băm vảy | C10: 2000 | D10: 2000 | E10: 2000 | F10: 2000 | G10: 2000 | H10: 2000 | I10: 2000 | J10: 2000 | K10: 2000 | L10: 2000 | M10: 2000 | N10: 2000 | Q10: Nhân viên vệ sinh kim loại nam châm - theo yêu cầu KSNB đảm bảo nam châm sạch | R10: 1 | S10: 1 | V10: 1 | W10: 1 | X10: 1 | Y10: 1
Q11: Nhân viên kéo bao, bì tạp | R11: 2 | S11: 2 | T11: 1 | U11: 1 | V11: 1 | W11: 1 | X11: 1 | Y11: 1
B12: Công suất định mức | Q12: Nhân viên Ép kiện | R12: 1 | S12: 1 | T12: 1 | U12: 1 | V12: 1 | W12: 1 | X12: 1 | Y12: 1
B13: Phân loại | C13: =C6+C7+C8 -> 2600 | D13: =D6+D7+D8 -> 2600 | E13: =E6+E7+E8 -> 2600 | F13: =F6+F7+F8 -> 3000 | G13: =G6+G7+G8 -> 3000 | H13: =H6+H7+H8 -> 3000 | I13: =I6+I7+I8 -> 3000 | J13: =J6+J7+J8 -> 3000 | ... N13: =N6+N7+N8 -> 3000 | Q13: SX băm vảy PET | Z13: =SUM(Z14:Z16) -> 4 | AA13: =SUM(AA14:AA16) -> 4 | AB13: =SUM(AB14:AB16) -> 4
B14: Băm vảy | D14: =D10 -> 2000 | E14: =E10 -> 2000 | F14: =F10 -> 2000 | G14: =G10 -> 2000 | H14: =H10 -> 2000 | I14: =I10 -> 2000 | J14: =J10 -> 2000 | K14: =K10 -> 2000 | ... N14: =N10 -> 2000 | Q14: Công đoạn 1: Cấp liệu | Z14: 1 | AA14: 1 | AB14: 1
Q15: Nhân viên PL trước băm | Z15: 2 | AA15: 2 | AB15: 2
B16: Hiệu suất máy | Q16: Nhân viên đóng gói TP | Z16: 1 | AA16: 1 | AB16: 1
B17: Phân loại | C17: 0.75 | D17: 0.75 | E17: 0.75 | F17: 0.75 | G17: 0.75 | H17: 0.75 | I17: 0.75 | J17: 0.75 | K17: 0.75 | L17: 0.75 | M17: 0.75 | N17: 0.75 | Q17: Sản xuất chung | R17: =SUM(R18:R20) -> 0 | S17: =SUM(S18:S20) -> 0 | T17: =SUM(T18:T20) -> 0 | U17: =SUM(U18:U20) -> 0 | V17: =SUM(V18:V20) -> 0 | W17: =SUM(W18:W20) -> 0 | X17: =SUM(X18:X20) -> 0 | Y17: =SUM(Y18:Y20) -> 0 | ... AD17: =SUM(AD18:AD20) -> 3
B18: Băm vảy | D18: 1 | E18: 1 | F18: 1 | G18: 1 | H18: 1 | I18: 1 | J18: 1 | K18: 1 | L18: 1 | M18: 1 | N18: 1 | Q18: Nhân viên lái xe nâng | AC18: 2 | AD18: 1
Q19: Nhân viên giao bì tạp | AC19: 1 | AD19: 1
B20: Sản lượng SX / ngày (24 giờ) x hiệu suất 75% | Q20: Nhân viên ghi số liệu | AC20: 1 | AD20: 1
B21: Phân loại | C21: =(C13*(24-2))*C17 -> 42900 | D21: =(D13*(24-2))*D17 -> 42900 | E21: =(E13*(24-2))*E17 -> 42900 | F21: =(F13*(24-2))*F17 -> 49500 | G21: =(G13*(24-2))*G17 -> 49500 | H21: =(H13*(24-2))*H17 -> 49500 | I21: =(I13*(24-2))*I17 -> 49500 | J21: =(J13*(24-2))*J17 -> 49500 | ... N21: =(N13*(24-2))*N17 -> 49500 | Q21: Xử lý phó sản - Thời vụ | AC21: =SUM(AC22:AC23) -> 5 | AD21: =SUM(AD22:AD23) -> 0
B22: Băm vảy | C22: =(C14*(24-2))*C18 -> 0 | D22: =(D14*(24-2))*D18 -> 44000 | E22: =(E14*(24-2))*E18 -> 44000 | F22: =(F14*(24-2))*F18 -> 44000 | G22: =(G14*(24-2))*G18 -> 44000 | H22: =(H14*(24-2))*H18 -> 44000 | I22: =(I14*(24-2))*I18 -> 44000 | J22: =(J14*(24-2))*J18 -> 44000 | ... N22: =(N14*(24-2))*N18 -> 44000 | Q22: Nhân viên xử lý nắp, cổ chai,… | AC22: 4
Q23: Nhân viên vệ sinh xưởng | AC23: 1
B24: Thành phẩm
B25: TP chai | C25: =C21*88% -> 37752 | D25: =D21*88% -> 37752 | E25: =E21*88% -> 37752 | F25: =F21*88% -> 43560 | G25: =G21*88% -> 43560 | H25: =H21*88% -> 43560 | I25: =I21*88% -> 43560 | J25: =J21*88% -> 43560 | ... N25: =N21*88% -> 43560
B26: TP băm | C26: =C22*88% -> 0 | D26: =D22*88% -> 38720 | E26: =E22*88% -> 38720 | F26: =F22*88% -> 38720 | G26: =G22*88% -> 38720 | H26: =H22*88% -> 38720 | I26: =I22*88% -> 38720 | J26: =J22*88% -> 38720 | ... N26: =N22*88% -> 38720
B27: TP chai bán | C27: =C21*5% -> 2145 | D27: =D21*5% -> 2145 | E27: =E21*5% -> 2145 | F27: =F21*5% -> 2475 | G27: =G21*5% -> 2475 | H27: =H21*5% -> 2475 | I27: =I21*5% -> 2475 | J27: =J21*5% -> 2475 | ... N27: =N21*5% -> 2475

Sheet Cong suat
B3: CÔNG SUẤT
B4: I - CÔNG SUẤT CHUYỀN LỰA CHAI - CHAI ÉP KIỆN - PLENMA | J4: Loại CN k đứng chuyền
B5: STT | C5: Công đoạn sản xuất | D5: Cấp liệu | E5: Lồng tách tạp chất | F5: Lựa phân loại chai | G5: Tách nhãn | H5: Lựa phân loại chai sau tách nhãn | I5: Ép kiện | J5: Công suất thành phẩm cả chuyền
B6: 1 | C6: Năng suất THIẾT KẾ (Kg NVL đầu vào / giờ) | D6: 1100 | E6: 1500 | F6: 1500 | G6: 1.100-1.500 | H6: 1100 | I6: 1400 | J6: =1200*(100%-$D$14) -> 1056
B7: 2 | C7: Năng suất ĐỊNH MỨC (Kg NVL đầu vào / giờ) | D7: 1100 | E7: =D7 -> 1100 | F7: =E7 -> 1100 | G7: =F7 -> 1100 | H7: =G7 -> 1100 | I7: 1300 | J7: =E15 -> 968
B8: 3 | C8: Định mức nhân công (Số NV / Ca8) | D8: ='Dinh bien_HCNS'!$W$60 -> 1 | F8: ='Dinh bien_HCNS'!$W$61 -> 5 | G8: ='Dinh bien_HCNS'!$W$63 -> 2 | H8: ='Dinh bien_HCNS'!$W$62 -> 5 | I8: ='Dinh bien_HCNS'!$W$64 -> 1 | J8: =SUM(D8:I8) -> 14
C9: Diễn giải
B11: STT | C11: Chỉ tiêu định mức | D11: ĐVT | E11: ĐM 1 giờ | F11: ĐM 1 Ca8 | G11: ĐM 1 Ca12 | H11: ĐM 2 Ca8 | I11: ĐM 2 Ca12
B12: 1 | C12: Tổng nhân sự: | D12: Người | E12: =J8 -> 14 | F12: =$E12 -> 14 | G12: =$F12*1.5 -> 21 | H12: =$F12*2 -> 28 | I12: =$G12*2 -> 42
B13: 2 | C13: Định mức NVL đầu vào: | D13: kg/giờ | E13: =$D$7 -> 1100 | F13: =$E13*8 -> 8800 | G13: =$F13*1.5 -> 13200 | H13: =$F13*2 -> 17600 | I13: =$G13*2 -> 26400
B14: 3 | C14: Hao hụt: | D14: ='2.Hao hut & % chai '!$M$14 -> 0.12 | E14: =E13*$D$14 -> 132 | F14: =$E14*8 -> 1056 | G14: =$E14*12 -> 1584 | H14: =$F14*2 -> 2112 | I14: =$G14*2 -> 3168
B15: 4 | C15: Định mức thành phẩm: | D15: kg/giờ | E15: =E13-E14 -> 968 | F15: =$E15*8 -> 7744 | G15: =$F15*1.5 -> 11616 | H15: =$F15*2 -> 15488 | I15: =$G15*2 -> 23232
B16: 5 | C16: Định mức thành phẩm/người: | D16: kg/giờ/người | E16: =E15/J8 -> 69.142857 | F16: =$E16*8 -> 553.14286 | G16: =$F16*1.5 -> 829.71429 | H16: =$F16*2 -> 1106.2857 | I16: =$G16*2 -> 1659.4286
B18: II - CÔNG SUẤT CHUYỀN LỰA CHAI - AI số 1
B19: STT | C19: Công đoạn sản xuất | D19: Cấp liệu | E19: Phá kiện | F19: Lựa phân loại chai | G19: Tách nhãn | H19: Lựa phân loại chai sau tách nhãn | I19: Ép kiện | J19: Công suất thành phẩm cả chuyền
B20: 1 | C20: Năng suất THIẾT KẾ (Kg NVL đầu vào / giờ) | D20: 1500-2000 | E20: 1500 | F20: 1500 | G20: 1.100-1.500 | H20: 1100 | I20: 1400 | J20: =2000*(100%-$D$14) -> 1760
B21: 2 | C21: Năng suất ĐỊNH MỨC (Kg NVL đầu vào / giờ) | D21: 1800 | E21: =D21 -> 1800 | F21: =E21 -> 1800 | G21: =F21 -> 1800 | H21: =G21 -> 1800 | I21: 1300 | J21: =$E$29 -> 1602
B22: 3 | C22: Định mức nhân công (Số NV / Ca8) | D22: ='Dinh bien_HCNS'!$U$60 -> 2 | F22: ='Dinh bien_HCNS'!$U$61 -> 3 | G22: ='Dinh bien_HCNS'!$U$63 -> 1 | H22: ='Dinh bien_HCNS'!$U$62 -> 3 | I22: ='Dinh bien_HCNS'!$U$64 -> 1 | J22: =SUM(D22:I22) -> 10
C23: Diễn giải
B25: STT | C25: Chỉ tiêu định mức | D25: ĐVT | E25: ĐM 1 giờ | F25: ĐM 1 Ca8 | G25: ĐM 1 Ca12 | H25: ĐM 2 Ca8 | I25: ĐM 2 Ca12
B26: 1 | C26: Tổng nhân sự: | D26: Người | E26: =J22 -> 10 | F26: =$E26 -> 10 | G26: =$F26*1.5 -> 15 | H26: =$F26*2 -> 20 | I26: =$G26*2 -> 30
B27: 2 | C27: Định mức NVL đầu vào: | D27: kg/giờ | E27: =G21 -> 1800 | F27: =$E27*8 -> 14400 | G27: =$F27*1.5 -> 21600 | H27: =$F27*2 -> 28800 | I27: =$G27*2 -> 43200
B28: 3 | C28: Hao hụt: | D28: ='2.Hao hut & % chai '!G8 -> 0.11 | E28: =E27*$D$28 -> 198 | F28: =$E28*8 -> 1584 | G28: =$F28*1.5 -> 2376 | H28: =$F28*2 -> 3168 | I28: =$G28*2 -> 4752
B29: 4 | C29: Định mức thành phẩm: | D29: kg/giờ | E29: =E27-E28 -> 1602 | F29: =$E29*8 -> 12816 | G29: =$F29*1.5 -> 19224 | H29: =$F29*2 -> 25632 | I29: =$G29*2 -> 38448
B30: 5 | C30: Định mức thành phẩm/người: | D30: kg/giờ/người | E30: =E29/J22 -> 160.2 | F30: =$E30*8 -> 1281.6 | G30: =$F30*1.5 -> 1922.4 | H30: =$F30*2 -> 2563.2 | I30: =$G30*2 -> 3844.8
B32: III - CÔNG SUẤT CHUYỀN LỰA CHAI - CHAI ÉP KIỆN - GIALONG
B33: STT | C33: Công đoạn sản xuất | D33: Cấp liệu | E33: Phá kiện | F33: Lựa phân loại chai | G33: Tách nhãn | H33: Lựa phân loại chai sau tách nhãn | I33: Ép kiện | J33: Công suất thành phẩm cả chuyền
B34: 1 | C34: Năng suất THIẾT KẾ (Kg NVL đầu vào / giờ) | D34: 1100 | E34: 1500 | F34: 1500 | G34: 1.100-1.500 | H34: 1100 | I34: 1400 | J34: =1200*(100%-$D$14) -> 1056
B35: 2 | C35: Năng suất ĐỊNH MỨC (Kg NVL đầu vào / giờ) | D35: 1100 | E35: =D35 -> 1100 | F35: =E35 -> 1100 | G35: =F35 -> 1100 | H35: =G35 -> 1100 | I35: 1300 | J35: =$E$43 -> 968
B36: 3 | C36: Định mức nhân công (Số NV / Ca8) | D36: ='Dinh bien_HCNS'!$W$60 -> 1 | F36: ='Dinh bien_HCNS'!$W$61 -> 5 | G36: ='Dinh bien_HCNS'!$W$63 -> 2 | H36: ='Dinh bien_HCNS'!$W$62 -> 5 | I36: ='Dinh bien_HCNS'!$W$64 -> 1 | J36: =SUM(D36:I36) -> 14
C37: Diễn giải
B39: STT | C39: Chỉ tiêu định mức | D39: ĐVT | E39: ĐM 1 giờ | F39: ĐM 1 Ca8 | G39: ĐM 1 Ca12 | H39: ĐM 2 Ca8 | I39: ĐM 2 Ca12
B40: 1 | C40: Tổng nhân sự: | D40: Người | E40: =$J$36 -> 14 | F40: =$E40 -> 14 | G40: =$F40*1.5 -> 21 | H40: =$F40*2 -> 28 | I40: =$G40*2 -> 42
B41: 2 | C41: Định mức NVL đầu vào: | D41: kg/giờ | E41: =$D$35 -> 1100 | F41: =$E41*8 -> 8800 | G41: =$F41*1.5 -> 13200 | H41: =$F41*2 -> 17600 | I41: =$G41*2 -> 26400
B42: 3 | C42: Hao hụt: | D42: ='2.Hao hut & % chai '!$M$14 -> 0.12 | E42: =E41*$D$42 -> 132 | F42: =$E42*8 -> 1056 | G42: =$E42*12 -> 1584 | H42: =$F42*2 -> 2112 | I42: =$G42*2 -> 3168
B43: 4 | C43: Định mức thành phẩm: | D43: kg/giờ | E43: =E41-E42 -> 968 | F43: =$E43*8 -> 7744 | G43: =$F43*1.5 -> 11616 | H43: =$F43*2 -> 15488 | I43: =$G43*2 -> 23232
B44: 5 | C44: Định mức thành phẩm/người: | D44: kg/giờ/người | E44: =E43/J36 -> 69.142857 | F44: =$E44*8 -> 553.14286 | G44: =$F44*1.5 -> 829.71429 | H44: =$F44*2 -> 1106.2857 | I44: =$G44*2 -> 1659.4286
B46: IV - CÔNG SUẤT CHUYỀN LỰA CHAI PET ÉP KIỆN - GIA LONG => Chạy quay đầu chai B6.6; B2.2
B47: STT | C47: Công đoạn sản xuất | D47: Cấp liệu | E47: Phá kiện | F47: Lựa phân loại chai | G47: Tách nhãn | H47: Lựa phân loại chai sau tách nhãn | I47: Ép kiện | J47: Công suất thành phẩm cả chuyền
B48: 1 | C48: Năng suất THIẾT KẾ (Kg NVL đầu vào / giờ) | D48: 1100 | E48: 1500 | F48: 1500 | G48: 1.100-1.500 | H48: 1100 | I48: 1400 | J48: =D48*(100%-$D$14) -> 968
...

Sheet Dinh muc
B3: ĐỊNH MỨC CHI PHÍ
B4: I - ĐỊNH MỨC TIÊU HAO VẬT TƯ - PHÂN LOẠI CHAI PET
B5: STT | C5: Mục phí | D5: ĐVT | E5: Định mức | F5: Đơn giá | G5: Chi phí/1kg thành phẩm | H5: Diễn giải | K5: =87*80% -> 69.6
C6: Công suất lựa chai | E6: ='Cong suat'!$H$82 -> 2570 | H6: Thành phẩm chai PET sau phân loại, tách nhãn
B7: 1 | C7: Chi phí nhân công trực tiếp (giờ công lao động)
B8: a | C8: LĐ định biên | D8: Giờ công/ca 8
B9: b | C9: LĐ thời vụ | D9: Giờ công/ca 8 | J9: Chuyền AI số 1
B10: 1 | C10: Điện sản xuất | D10: Kw/1 chuyền/1kg thành phẩm | E10: =K16+K17+K16 -> 201.9 | F10: 2300 | G10: =E10*F10/'Cong suat'!F$82 -> 239.86054 | J10: Tên MMTB sử dụng điện | K10: Số điện sử dụng kwh/ giờ
B11: 2 | C11: Điện sản xuất | D11: Kw/1 chuyền/1kg thành phẩm | E11: =$K$18 -> 276.25 | F11: 2300 | G11: =E11*F11/$E$6 -> 247.22763 | J11: Máy nén khí phân loại 80% | K11: =90*80% -> 72
B12: 3 | C12: Dao tách nhãn chai PET | D12: Bộ | E12: =1/1500000*(('Cong suat'!$E$81)/2) -> 0.00096666667 | F12: 165000000 | G12: =E12*F12/$E$6 -> 62.062257 | H12: Công suất thiết kế: 1500 tấn chai PET-B0 | J12: Tách nhãn BRT | K12: 57
B13: 4 | C13: Dây đai | E13: 0.35 | F13: 51000 | G13: =E13*F13/230 -> 77.608696 | J13: Hệ thống máy Sort + TB phụ | K13: 85
B14: 5 | C14: Bao jumbo | E14: =200/3000 -> 0.066666667 | F14: 75000 | G14: =E14*F14/$E$6 -> 1.9455253 | H14: 1 bao để được 30kg NV | J14: Định mức thiết kế HT AI | K14: =SUM(K11:K13) -> 214
B15: 6 | C15: Hóa chất | J15: Chuyền AI số 1 (thực hiện 70%) | K15: =K14*70% -> 149.8
B16: 7 | C16: Chi phí xử lý nhãn chai PET | D16: Kg | E16: 1 | F16: 300 | G16: =(('Cong suat'!$E$28+'Cong suat'!$E$14)*50%)*F16/$E$6 -> 19.2607 | H16: NCC Á Châu - TGĐ duyệt CP xử lý nhãn ở mức 300d/kg | J16: Chuyền PL TN | K16: =((87*80%)+31)*75% -> 75.45
B17: 8 | C17: Dầu xe nâng | D17: Lít/giờ hoạt động | E17: 3.2 | F17: 22000 | G17: =E17*F17/$E$6 -> 27.392996 | H17: Định mức: 1 xe nâng sử dụng 3,2 lít dầu / giờ hoạt động | J17: Chuyền rework | K17: =31+20 -> 51
B18: 9 | C18: Chi phí vận chuyển | D18: Chuyến/8 tấn | E18: 1 | F18: 3200000 | G18: =F18/8000 -> 400 | J18: Tổng | K18: =K15+K16+K17 -> 276.25
B20: II - ĐỊNH MỨC TIÊU HAO VẬT TƯ - BĂM VẢY PET GIAI ĐOẠN 1 - BĂM THÔ
B21: STT | C21: Mục phí | D21: ĐVT | E21: ĐM 1 giờ | F21: Đơn giá | G21: Chi phí/1kg thành phẩm | H21: Diễn giải
C22: Công suất băm PET | E22: ='Cong suat'!$E$110 -> 1666.9652
B23: 1 | C23: Chi phí nhân công trực tiếp
B24: a | C24: LĐ định biên | D24: Giờ công/ca 8
B25: b | C25: LĐ thời vụ | D25: Giờ công/ca 8
B26: c | C26: Tiền ăn giữa Ca | D26: Đồng/người | J26: =C27 -> Điện sản xuất | O26: =C28 -> Dao băm vảy PET | X26: =$C$32 -> Chi phí xử lý nước thải, môi trường | Y26: Tìm phương án xử lý tối ưu
B27: 2 | C27: Điện sản xuất | D27: Kw/1chuyền/1giờ hoạt động | E27: =$K$33 -> 197.16 | F27: =$F$11 -> 2300 | G27: =E27*F27/$E$22 -> 272.03207 | H27: Máy chính: 255kwh/giờ - Máy phụ: 90kwh/giờ | J27: Tên MMTB sử dụng điện | K27: Số điện sử dụng kwh/ giờ | O27: Nội dung | P27: Đơn vị tính | Q27: Số lượng | R27: Đơn giá | S27: Sản lượng SX / 1 lưỡi dao (Tấn/1 lưỡi dao) | T27: Sản lượng SX / 1 bộ dao (Tấn/1 bộ dao) | U27: Tổng CP | V27: Đồng/kg | X27: Nội dung | Y27: Đơn vị tính | Z27: Số lượng | AA27: Đơn giá | AB27: Đồng/kg
B28: 3 | C28: Dao băm vảy PET | F28: =U33 -> 72336000 | G28: =$V$33 -> 104.4295 | H28: Công suất thiết kế: 150 tấn | J28: Máy nén khí phân loại 20% | K28: =90*20% -> 18 | O28: Dao băm động - chiều dài 60cm | P28: Cái | Q28: 14 | R28: 2400000 | S28: 46 | T28: =Q28*S28 -> 644 | U28: =Q28*R28 -> 33600000 | V28: =(Q28*R28)/T28/1000 -> 52.173913 | X28: Nước thủy cục | Y28: lít/giờ | Z28: 3000 | AA28: =12000/1000 -> 12 | AB28: =(Z28*AA28)/$E$22 -> 21.596132
B29: 4 | C29: Dây đai | J29: Hệ thống băm thô | K29: 255 | O29: Dao băm tĩnh - chiều dài 120cm | P29: Cái | Q29: 6 | R29: 6000000 | S29: 324 | T29: =Q29*S29 -> 1944 | U29: =Q29*R29 -> 36000000 | V29: =(Q29*R29)/T29/1000 -> 18.518519 | X29: Vận chuyển nước thải (50/50) | Y29: lít/giờ | Z29: =Z28*50% -> 1500 | AA29: 500 | AB29: =(Z29*AA29)/$E$22 -> 449.91941
B30: 5 | C30: Bao jumbo | E30: 1 | F30: 150000 | G30: =E30*F30/450/2 -> 166.66667 | H30: 1 cái bao đựng được 450kg vảy PET băm thô => quay đầu 2 lần/tháng | J30: Thiết bị phụ trợ: Bơm nước, HT li tâm | K30: 20 | O30: Bu long M20x110 | P30: Con | Q30: 28 | R30: 23000 | T30: =2*T28 -> 1288 | U30: =Q30*R30 -> 644000 | V30: =(Q30*R30)/T30/1000 -> 0.5
B31: 6 | C31: Hóa chất | J31: Máy phá kiện | K31: 25 | O31: Bu long M20x70 | P31: Con | Q31: 28 | R31: 25000 | T31: 1288 | U31: =Q31*R31 -> 700000 | V31: =(Q31*R31)/T31/1000 -> 0.54347826
B32: 7 | C32: Chi phí xử lý nước thải, môi trường | D32: m3/h | G32: =$AB$33 -> 471.51554 | H32: PA1: Vận chuyển DTR xử lý: 500 đ/lit nước thải PA2: CTy Dịch vụ xử lý: 1.500 đ/lit nước thải | J32: Định mức thiết kế | K32: =SUM(K28:K31) -> 318 | O32: Đá mài dao | P32: Viên | Q32: 3 | R32: 464000 | T32: =(Q28*Q32)+(Q29*3) -> 60 | U32: =Q32*R32 -> 1392000 | V32: =(Q32*R32)/T32/1000 -> 23.2
B33: 8 | C33: Dầu xe nâng | E33: 3.2 | F33: 19000 | G33: =E33*F33/$E$22 -> 36.473467 | H33: Định mức: 1 xe nâng sử dụng 3,2 lít dầu / giờ hoạt động | J33: Thực hiện 62% | K33: =K32*62% -> 197.16 | O33: Tổng cộng | U33: =SUM(U28:U32) -> 72336000 | V33: =SUM(V28:V32)*110% -> 104.4295 | X33: Tổng cộng | AB33: =SUM(AB28:AB32) -> 471.51554
B34: 9 | C34: Chi phí vận chuyển | D34: Chuyến | E34: 10000 | F34: 3200000 | G34: =F34/E34 -> 320
B36: III - ĐỊNH MỨC TIÊU HAO VẬT TƯ - BĂM VẢY PET GIAI ĐOẠN 2 - RỬA NƯỚC
B37: STT | C37: Mục phí | D37: ĐVT | E37: Định mức | F37: Đơn giá | G37: Chi phí/1kg thành phẩm | H37: Diễn giải
C38: Công suất băm HD
B39: 1 | C39: Chi phí nhân công trực tiếp
B40: a | C40: LĐ định biên
B41: b | C41: LĐ thời vụ
B42: c | C42: Tiền ăn giữa Ca
B43: 2 | C43: Điện sản xuất
B44: 3 | C44: Dao băm vảy HD
...

Sheet Dinh bien_HCNS
B1: #VALUE!
B3: I - ĐINH BIÊN NHÂN SỰ - PET | D3: SLSX | E3: 6192451 | F3: ='1.NVL Chai'!G16 -> 780000 | G3: ='1.NVL Chai'!H16 -> 450000 | H3: ='1.NVL Chai'!I16 -> 1040000 | I3: ='1.NVL Chai'!J16 -> 1250000 | J3: ='1.NVL Chai'!K16 -> 1250000 | K3: ='1.NVL Chai'!L16 -> 1300000 | L3: ='1.NVL Chai'!M16 -> 1350000 | M3: ='1.NVL Chai'!N16 -> 1300000 | ... R3: ='1.NVL Chai'!S16 -> 13870000
F4: C1: Ca 8h+8h C2: Ca 8h+8h | G4: C1: Ca 8h+8h C2: Ca 8h+8h | H4: C1: Ca 8h+8h+2h C2: Ca 8h+8h C3: Ca 8h+8h | I4: C1: Ca 8h+8h+2h C2: Ca 8h+8h C3: Ca 8h+8h | J4: C1: Ca 8h+8h+2h C2: Ca 8h+8h C3: Ca 8h+8h | K4: C1: Ca 8h+8h+2h C2: Ca 8h+8h C3: Ca 8h+8h | L4: C1: Ca 8h+8h+2h C2: Ca 8h+8h C3: Ca 8h+8h | M4: C1: Ca 8h+8h+2h C2: Ca 8h+8h C3: Ca 8h+8h | N4: C1: Ca 8h+8h+2h C2: Ca 8h+8h C3: Ca 8h+8h | O4: C1: Ca 8h+8h+2h C2: Ca 8h+8h C3: Ca 8h+8h | P4: C1: Ca 8h+8h+2h C2: Ca 8h+8h C3: Ca 8h+8h | Q4: C1: Ca 8h+8h+2h C2: Ca 8h+8h C3: Ca 8h+8h
B5: STT | C5: Phòng ban | D5: Tài khoản | E5: KQKD 2025 | F5: T1 | G5: T2 | H5: T3 | I5: T4 | J5: T5 | K5: T6 | L5: T7 | M5: T8 | N5: T9 | O5: T10 | P5: T11 | Q5: T12 | R5: Mục tiêu 2026
B6: 1 | C6: Ban giám đốc | D6: 642 | E6: =E7+E8 -> 1 | F6: =F7+F8 -> 1 | G6: =G7+G8 -> 1 | H6: =H7+H8 -> 1 | I6: =I7+I8 -> 1 | J6: =J7+J8 -> 1 | K6: =K7+K8 -> 1 | L6: =L7+L8 -> 1 | ... R6: =R7+R8 -> 1
B7: 1.1 | C7: Giám đốc Trạm | R7: =Q7 -> 0
B8: 1.2 | C8: Trưởng trạm thu mua | E8: 1 | F8: 1 | G8: 1 | H8: 1 | I8: 1 | J8: 1 | K8: 1 | L8: 1 | M8: 1 | N8: 1 | O8: 1 | P8: 1 | Q8: 1 | R8: =Q8 -> 1
B9: 2 | C9: Phòng Hành chánh nhân sự | D9: 642 | E9: =SUM(E10:E16) -> 2 | F9: =SUM(F10:F16) -> 3 | G9: =SUM(G10:G16) -> 3 | H9: =SUM(H10:H16) -> 3 | I9: =SUM(I10:I16) -> 3 | J9: =SUM(J10:J16) -> 3 | K9: =SUM(K10:K16) -> 3 | L9: =SUM(L10:L16) -> 3 | ... R9: =SUM(R10:R16) -> 3
B10: 2.1 | C10: Trưởng phòng nhân sự | R10: =Q10 -> 0
B11: 2.1 | C11: Nhân viên hành chính | R11: =Q11 -> 0
B12: 2.2 | C12: Nhân viên nhân sự | E12: 1 | F12: 1 | G12: 1 | H12: 1 | I12: 1 | J12: 1 | K12: 1 | L12: 1 | M12: 1 | N12: 1 | O12: 1 | P12: 1 | Q12: 1 | R12: =Q12 -> 1
B13: 2.3 | C13: Tuyển dụng | R13: =Q13 -> 0
B14: 2.4 | C14: Nhân viên tạp vụ | E14: 1 | F14: 1 | G14: 1 | H14: 1 | I14: 1 | J14: 1 | K14: 1 | L14: 1 | M14: 1 | N14: 1 | O14: 1 | P14: 1 | Q14: 1 | R14: =Q14 -> 1
B15: 2.5 | C15: Bảo vệ | R15: =Q15 -> 0
B16: 2.6 | C16: Nhân viên chăm sóc cây xanh | F16: 1 | G16: 1 | H16: 1 | I16: 1 | J16: 1 | K16: 1 | L16: 1 | M16: 1 | N16: 1 | O16: 1 | P16: 1 | Q16: 1 | R16: =Q16 -> 1
B17: 3 | C17: Phòng Kế toán | D17: 642 | E17: =SUM(E18:E21) -> 3 | F17: =SUM(F18:F21) -> 4 | G17: =SUM(G18:G21) -> 4 | H17: =SUM(H18:H21) -> 4 | I17: =SUM(I18:I21) -> 4 | J17: =SUM(J18:J21) -> 4 | K17: =SUM(K18:K21) -> 4 | L17: =SUM(L18:L21) -> 4 | ... R17: =SUM(R18:R21) -> 4
B18: 3.1 | C18: Kế toán trưởng | E18: 1 | F18: 1 | G18: 1 | H18: 1 | I18: 1 | J18: 1 | K18: 1 | L18: 1 | M18: 1 | N18: 1 | O18: 1 | P18: 1 | Q18: 1 | R18: =Q18 -> 1
B19: 3.2 | C19: Kế toán tổng hợp | E19: 1 | F19: 2 | G19: 2 | H19: 2 | I19: 2 | J19: 2 | K19: 2 | L19: 2 | M19: 2 | N19: 2 | O19: 2 | P19: 2 | Q19: 2 | R19: =Q19 -> 2
B20: 3.3 | C20: Kế toán kho | E20: 1 | F20: 1 | G20: 1 | H20: 1 | I20: 1 | J20: 1 | K20: 1 | L20: 1 | M20: 1 | N20: 1 | O20: 1 | P20: 1 | Q20: 1 | R20: =Q20 -> 1
B21: 3.4 | C21: Kế toán viên | R21: =Q21 -> 0
B22: 4 | C22: Phòng Mua hàng (Bao gồm NVL + Vật tư) | D22: 642 | E22: =E23 -> 1 | F22: =F23 -> 1 | G22: =G23 -> 1 | H22: =H23 -> 1 | I22: =I23 -> 1 | J22: =J23 -> 1 | K22: =K23 -> 1 | L22: =L23 -> 1 | ... R22: =R23 -> 1
B23: 4.1 | C23: Nhân viên mua hàng | E23: 1 | F23: 1 | G23: 1 | H23: 1 | I23: 1 | J23: 1 | K23: 1 | L23: 1 | M23: 1 | N23: 1 | O23: 1 | P23: 1 | Q23: 1 | R23: 1
B24: 5 | C24: Ban dự án XDCB | D24: 642 | E24: =E25 -> 0 | F24: =F25 -> 0 | G24: =G25 -> 0 | H24: =H25 -> 0 | I24: =I25 -> 0 | J24: =J25 -> 0 | K24: =K25 -> 0 | L24: =L25 -> 0 | ... Q24: =Q25 -> 0
B25: 5.1 | C25: Nhân viên
B26: 6 | C26: Phòng Quản Trị Hệ Thống | D26: 642 | E26: =E27 -> 0 | F26: =F27 -> 0 | G26: =G27 -> 0 | H26: =H27 -> 0 | I26: =I27 -> 0 | J26: =J27 -> 0 | K26: =K27 -> 0 | L26: =L27 -> 0 | ... Q26: =Q27 -> 0
B27: 6.1 | C27: Nhân viên quản trị hệ thống
B28: 7 | C28: Phòng 5S & an toàn | D28: 642 | E28: =E29 -> 0 | F28: =F29 -> 1 | G28: =G29 -> 1 | H28: =H29 -> 1 | I28: =I29 -> 1 | J28: =J29 -> 1 | K28: =K29 -> 1 | L28: =L29 -> 1 | ... Q28: =Q29 -> 1 | R28: =Q28 -> 1
B29: 7.1 | C29: Nhân viên 5S & an toàn | F29: 1 | G29: 1 | H29: 1 | I29: 1 | J29: 1 | K29: 1 | L29: 1 | M29: 1 | N29: 1 | O29: 1 | P29: 1 | Q29: 1 | R29: =Q29 -> 1
B30: 8 | C30: Phòng Cung ứng | D30: 642 | E30: =E31 -> 0 | F30: =F31 -> 0 | G30: =G31 -> 0 | H30: =H31 -> 0 | I30: =I31 -> 0 | J30: =J31 -> 0 | K30: =K31 -> 0 | L30: =L31 -> 0 | ... Q30: =Q31 -> 0 | R30: =Q30 -> 0
B31: 8.1 | C31: Nhân viên | R31: =Q31 -> 0
B32: 9 | C32: Phòng mua XNK | D32: 642 | E32: =E33 -> 0 | F32: =F33 -> 0 | G32: =G33 -> 0 | H32: =H33 -> 0 | I32: =I33 -> 0 | J32: =J33 -> 0 | K32: =K33 -> 0 | L32: =L33 -> 0 | ... Q32: =Q33 -> 0 | R32: =Q32 -> 0
B33: 9.1 | C33: Nhân viên mua hàng | R33: =Q33 -> 0
B34: 10 | C34: Tư Vấn Dịch Vụ | D34: 642 | E34: =E35 -> 0 | F34: =F35 -> 0 | G34: =G35 -> 0 | H34: =H35 -> 0 | I34: =I35 -> 0 | J34: =J35 -> 0 | K34: =K35 -> 0 | L34: =L35 -> 0 | ... Q34: =Q35 -> 0 | R34: =Q34 -> 0
B35: 10.1 | C35: Nhân viên | R35: =Q35 -> 0
B36: 11 | C36: Phòng Nghiên Cứu & Phát Triển | D36: 627 | E36: =E37 -> 0 | F36: =F37 -> 0 | G36: =G37 -> 0 | H36: =H37 -> 0 | I36: =I37 -> 0 | J36: =J37 -> 0 | K36: =K37 -> 0 | L36: =L37 -> 0 | ... Q36: =Q37 -> 0 | R36: =Q36 -> 0
B37: 11.1 | C37: Nhân viên | R37: =Q37 -> 0
B38: 12 | C38: Phòng Kiểm soát chất lượng | D38: 627 | E38: =SUM(E39:E41) -> 2 | F38: =SUM(F39:F41) -> 4 | G38: =SUM(G39:G41) -> 4 | H38: =SUM(H39:H41) -> 4 | I38: =SUM(I39:I41) -> 4 | J38: =SUM(J39:J41) -> 4 | K38: =SUM(K39:K41) -> 4 | L38: =SUM(L39:L41) -> 4 | ... R38: =SUM(R39:R41) -> 4
B39: 12.1 | C39: Tổ trưởng Kiểm soát chất lượng | R39: =Q39 -> 0
B40: 12.2 | C40: Kiểm soát NVL - 1 ca Hành chánh | E40: 2 | F40: 2 | G40: 2 | H40: 2 | I40: 2 | J40: 2 | K40: 2 | L40: 2 | M40: 2 | N40: 2 | O40: 2 | P40: 2 | Q40: 2 | R40: =Q40 -> 2
B41: 12.3 | C41: Kiểm soát thành phẩm - 2 Ca | F41: 2 | G41: 2 | H41: 2 | I41: 2 | J41: 2 | K41: 2 | L41: 2 | M41: 2 | N41: 2 | O41: 2 | P41: 2 | Q41: 2 | R41: =Q41 -> 2
...

Sheet 4.Doanh thu
B3: DOANH THU
B4: I - DOANH THU CHAI PET
B5: 1. Sản lượng bán chai
B6: STT | C6: Thành phẩm (chai sau phân loại) | D6: ĐVT | E6: Tỷ lệ | F6: T1 | G6: T2 | H6: T3 | I6: T4 | J6: T5 | K6: T6 | L6: T7 | M6: T8 | N6: T9 | O6: T10 | P6: T11 | Q6: T12 | R6: KHKD 2026 | T6: T1 | U6: T2 | V6: T3 | W6: T4 | X6: T5 | Y6: T6 | Z6: T7 | AA6: T8 | AB6: T9 | AC6: T10 | AD6: T11 | AE6: T12 | AF6: KQKD 2025 | AH6: KQKD 2024 | AJ6: KQKD 2023 | AL6: +/- 2026 sv 2025 | AM6: +/- % | AX6: Thành phẩm (chai sau phân loại) | AY6: T1 | AZ6: T2 | BA6: T3 | BB6: T4 | BC6: T5 | BD6: T6 | BE6: T7 | BF6: T8 | BG6: T9 | BH6: T10 | BI6: T11 | BJ6: T12 | BK6: Mục tiêu 2026
B7: 1 | C7: Chai PET B1 | D7: Tấn | F7: ='3.Thanh pham'!G82 -> 0 | G7: ='3.Thanh pham'!H82 -> 0 | H7: ='3.Thanh pham'!I82 -> 0 | I7: ='3.Thanh pham'!J82 -> 0 | J7: ='3.Thanh pham'!K82 -> 0 | K7: ='3.Thanh pham'!L82 -> 0 | L7: ='3.Thanh pham'!M82 -> 0 | M7: ='3.Thanh pham'!N82 -> 0 | ... Q7: ='3.Thanh pham'!R82 -> 0 | R7: =SUM(F7:Q7) -> 0 | T7: 0 | U7: 19813 | V7: 50178 | W7: 69677 | X7: 35669 | Y7: 78235 | Z7: 67196 | AA7: 50812 | AB7: 6793 | AC7: 2192 | AD7: 0 | AE7: 0 | AF7: =SUM(T7:AE7) -> 380565 | AH7: 30193 | AJ7: 1038416 | AL7: =IFERROR(R7-AF7,0) -> -380565 | AM7: =IFERROR((R7/AF7)-1,0) -> -1 | AX7: Chai PET B1 | AY7: ='3.Thanh pham'!G63 -> 0 | AZ7: ='3.Thanh pham'!H63 -> 0 | BA7: ='3.Thanh pham'!I63 -> 0 | BB7: ='3.Thanh pham'!J63 -> 0 | BC7: ='3.Thanh pham'!K63 -> 0 | BD7: ='3.Thanh pham'!L63 -> 0 | BE7: ='3.Thanh pham'!M63 -> 0 | BF7: ='3.Thanh pham'!N63 -> 0 | ... BJ7: ='3.Thanh pham'!R63 -> 0 | BK7: =SUM(AY7:BJ7) -> 0
B8: 2 | C8: Chai PET B1 Không Phân Loại | D8: Tấn | F8: ='3.Thanh pham'!G83 -> 365040 | G8: ='3.Thanh pham'!H83 -> 210600 | H8: ='3.Thanh pham'!I83 -> 485680 | I8: ='3.Thanh pham'!J83 -> 0 | J8: ='3.Thanh pham'!K83 -> 0 | K8: ='3.Thanh pham'!L83 -> 0 | L8: ='3.Thanh pham'!M83 -> 0 | M8: ='3.Thanh pham'!N83 -> 0 | ... Q8: ='3.Thanh pham'!R83 -> 0 | R8: =SUM(F8:Q8) -> 1061320 | T8: 61839 | U8: 45562 | V8: 45024 | W8: 92622 | X8: 197273 | Y8: 271254 | Z8: 339955 | AA8: 389507 | AB8: 346544 | AC8: 287638 | AD8: 228800 | AE8: 246400 | AF8: =SUM(T8:AE8) -> 2552418 | AH8: 2139028 | AJ8: 504421.5 | AL8: =IFERROR(R8-AF8,0) -> -1491098 | AM8: =IFERROR((R8/AF8)-1,0) -> -0.58419036 | AX8: Chai PET B1 Không Phân Loại | AY8: ='3.Thanh pham'!G64 -> 365040 | AZ8: ='3.Thanh pham'!H64 -> 210600 | BA8: ='3.Thanh pham'!I64 -> 485680 | BB8: ='3.Thanh pham'!J64 -> 583750 | BC8: ='3.Thanh pham'!K64 -> 583750 | BD8: ='3.Thanh pham'!L64 -> 607100 | BE8: ='3.Thanh pham'!M64 -> 630450 | BF8: ='3.Thanh pham'!N64 -> 607100 | ... BJ8: ='3.Thanh pham'!R64 -> 630450 | BK8: =SUM(AY8:BJ8) -> 6478520
B9: 3 | C9: Chai PET B1.3 | D9: Tấn | F9: ='3.Thanh pham'!G84 -> 0 | G9: ='3.Thanh pham'!H84 -> 0 | H9: ='3.Thanh pham'!I84 -> 0 | I9: ='3.Thanh pham'!J84 -> 0 | J9: ='3.Thanh pham'!K84 -> 0 | K9: ='3.Thanh pham'!L84 -> 0 | L9: ='3.Thanh pham'!M84 -> 0 | M9: ='3.Thanh pham'!N84 -> 0 | ... Q9: ='3.Thanh pham'!R84 -> 0 | R9: =SUM(F9:Q9) -> 0 | T9: 5075 | U9: 82000 | V9: 96416 | W9: 83716 | X9: 5130 | Y9: 0 | Z9: 0 | AA9: 0 | AB9: 0 | AD9: 0 | AE9: 0 | AF9: =SUM(T9:AE9) -> 272337 | AL9: =IFERROR(R9-AF9,0) -> -272337 | AM9: =IFERROR((R9/AF9)-1,0) -> -1 | AX9: Chai PET B1.3 | AY9: ='3.Thanh pham'!G65 -> 0 | AZ9: ='3.Thanh pham'!H65 -> 0 | BA9: ='3.Thanh pham'!I65 -> 0 | BB9: ='3.Thanh pham'!J65 -> 0 | BC9: ='3.Thanh pham'!K65 -> 0 | BD9: ='3.Thanh pham'!L65 -> 0 | BE9: ='3.Thanh pham'!M65 -> 0 | BF9: ='3.Thanh pham'!N65 -> 0 | ... BJ9: ='3.Thanh pham'!R65 -> 0 | BK9: =SUM(AY9:BJ9) -> 0
B10: 4 | C10: Chai PET B2.1 | D10: Tấn | F10: ='3.Thanh pham'!G85 -> 0 | G10: ='3.Thanh pham'!H85 -> 0 | H10: ='3.Thanh pham'!I85 -> 0 | I10: ='3.Thanh pham'!J85 -> 0 | J10: ='3.Thanh pham'!K85 -> 0 | K10: ='3.Thanh pham'!L85 -> 0 | L10: ='3.Thanh pham'!M85 -> 0 | M10: ='3.Thanh pham'!N85 -> 0 | ... Q10: ='3.Thanh pham'!R85 -> 0 | R10: =SUM(F10:Q10) -> 0 | AF10: =SUM(T10:AE10) -> 0 | AJ10: 118971.5 | AL10: =IFERROR(R10-AF10,0) -> 0 | AM10: =IFERROR((R10/AF10)-1,0) -> 0 | AX10: Chai PET B2.1 | AY10: ='3.Thanh pham'!G66 -> 0 | AZ10: ='3.Thanh pham'!H66 -> 0 | BA10: ='3.Thanh pham'!I66 -> 0 | BB10: ='3.Thanh pham'!J66 -> 0 | BC10: ='3.Thanh pham'!K66 -> 0 | BD10: ='3.Thanh pham'!L66 -> 0 | BE10: ='3.Thanh pham'!M66 -> 0 | BF10: ='3.Thanh pham'!N66 -> 0 | ... BJ10: ='3.Thanh pham'!R66 -> 0 | BK10: =SUM(AY10:BJ10) -> 0
