Workbook

Sheet Sheet1
B2: SL bán (tấn) | C2: Nhóm hàng | D2: 1 | E2: 2 | F2: 3 | G2: 4 | H2: 5 | I2: 6 | J2: 7 | K2: 8 | L2: 9 | M2: 10 | N2: 11 | O2: 12 | P2: Tổng
B3: Unilever | C3: rPET | D3: =SUMIFS(data!$I:$I,data!$B:$B,Sheet1!$B3,data!$A:$A,Sheet1!D$2,data!$F:$F,Sheet1!$C3)/1000 -> 253 | E3: =SUMIFS(data!$I:$I,data!$B:$B,Sheet1!$B3,data!$A:$A,Sheet1!E$2,data!$F:$F,Sheet1!$C3)/1000 -> 363 | F3: =SUMIFS(data!$I:$I,data!$B:$B,Sheet1!$B3,data!$A:$A,Sheet1!F$2,data!$F:$F,Sheet1!$C3)/1000 -> 249.7 | G3: =SUMIFS(data!$I:$I,data!$B:$B,Sheet1!$B3,data!$A:$A,Sheet1!G$2,data!$F:$F,Sheet1!$C3)/1000 -> 176 | H3: =SUMIFS(data!$I:$I,data!$B:$B,Sheet1!$B3,data!$A:$A,Sheet1!H$2,data!$F:$F,Sheet1!$C3)/1000 -> 242 | I3: =SUMIFS(data!$I:$I,data!$B:$B,Sheet1!$B3,data!$A:$A,Sheet1!I$2,data!$F:$F,Sheet1!$C3)/1000 -> 341 | J3: =SUMIFS(data!$I:$I,data!$B:$B,Sheet1!$B3,data!$A:$A,Sheet1!J$2,data!$F:$F,Sheet1!$C3)/1000 -> 220 | K3: =SUMIFS(data!$I:$I,data!$B:$B,Sheet1!$B3,data!$A:$A,Sheet1!K$2,data!$F:$F,Sheet1!$C3)/1000 -> 434.5 | ... O3: =SUMIFS(data!$I:$I,data!$B:$B,Sheet1!$B3,data!$A:$A,Sheet1!O$2,data!$F:$F,Sheet1!$C3)/1000 -> 0 | P3: =SUM(D3:O3) -> 3401.2
B4: Tổng | C4: rPET | D4: =SUMIFS(data!$I:$I,data!$A:$A,Sheet1!D$2,data!$F:$F,Sheet1!$C4)/1000 -> 3296.1493 | E4: =SUMIFS(data!$I:$I,data!$A:$A,Sheet1!E$2,data!$F:$F,Sheet1!$C4)/1000 -> 5148 | F4: =SUMIFS(data!$I:$I,data!$A:$A,Sheet1!F$2,data!$F:$F,Sheet1!$C4)/1000 -> 4019.3 | G4: =SUMIFS(data!$I:$I,data!$A:$A,Sheet1!G$2,data!$F:$F,Sheet1!$C4)/1000 -> 3574.4 | H4: =SUMIFS(data!$I:$I,data!$A:$A,Sheet1!H$2,data!$F:$F,Sheet1!$C4)/1000 -> 4207.0103 | I4: =SUMIFS(data!$I:$I,data!$A:$A,Sheet1!I$2,data!$F:$F,Sheet1!$C4)/1000 -> 3103.083 | J4: =SUMIFS(data!$I:$I,data!$A:$A,Sheet1!J$2,data!$F:$F,Sheet1!$C4)/1000 -> 3670.3491 | K4: =SUMIFS(data!$I:$I,data!$A:$A,Sheet1!K$2,data!$F:$F,Sheet1!$C4)/1000 -> 4344.593 | ... O4: =SUMIFS(data!$I:$I,data!$A:$A,Sheet1!O$2,data!$F:$F,Sheet1!$C4)/1000 -> 0 | P4: =SUM(D4:O4) -> 37514.945
B5: % SL bán/ tổng SL | C5: rPET | D5: =D3/D4 -> 0.076756232 | E5: =E3/E4 -> 0.070512821 | F5: =F3/F4 -> 0.062125246 | G5: =G3/G4 -> 0.049239033 | H5: =H3/H4 -> 0.057523035 | I5: =I3/I4 -> 0.10989071 | J5: =J3/J4 -> 0.059939802 | K5: =K3/K4 -> 0.10000937 | ... P5: =P3/P4 -> 0.090662535
B7: Doanh thu (trđ) | C7: Nhóm hàng | D7: 1 | E7: 2 | F7: 3 | G7: 4 | H7: 5 | I7: 6 | J7: 7 | K7: 8 | L7: 9 | M7: 10 | N7: 11 | O7: 12 | P7: Tổng
B8: Unilever | C8: rPET | D8: =SUMIFS(data!$J:$J,data!$B:$B,Sheet1!$B8,data!$A:$A,Sheet1!D$7,data!$F:$F,Sheet1!$C8)/10^6 -> 8243.917 | E8: =SUMIFS(data!$J:$J,data!$B:$B,Sheet1!$B8,data!$A:$A,Sheet1!E$7,data!$F:$F,Sheet1!$C8)/10^6 -> 11986.26 | F8: =SUMIFS(data!$J:$J,data!$B:$B,Sheet1!$B8,data!$A:$A,Sheet1!F$7,data!$F:$F,Sheet1!$C8)/10^6 -> 8230.4563 | G8: =SUMIFS(data!$J:$J,data!$B:$B,Sheet1!$B8,data!$A:$A,Sheet1!G$7,data!$F:$F,Sheet1!$C8)/10^6 -> 5643.088 | H8: =SUMIFS(data!$J:$J,data!$B:$B,Sheet1!$B8,data!$A:$A,Sheet1!H$7,data!$F:$F,Sheet1!$C8)/10^6 -> 7759.246 | I8: =SUMIFS(data!$J:$J,data!$B:$B,Sheet1!$B8,data!$A:$A,Sheet1!I$7,data!$F:$F,Sheet1!$C8)/10^6 -> 10933.478 | J8: =SUMIFS(data!$J:$J,data!$B:$B,Sheet1!$B8,data!$A:$A,Sheet1!J$7,data!$F:$F,Sheet1!$C8)/10^6 -> 7105.868 | K8: =SUMIFS(data!$J:$J,data!$B:$B,Sheet1!$B8,data!$A:$A,Sheet1!K$7,data!$F:$F,Sheet1!$C8)/10^6 -> 14431.947 | ... O8: =SUMIFS(data!$J:$J,data!$B:$B,Sheet1!$B8,data!$A:$A,Sheet1!O$7,data!$F:$F,Sheet1!$C8)/10^6 -> 0 | P8: =SUM(D8:O8) -> 111914.41
B9: Tổng | C9: rPET | D9: =SUMIFS(data!$J:$J,data!$A:$A,Sheet1!D$7,data!$F:$F,Sheet1!$C9)/10^6 -> 104654.64 | E9: =SUMIFS(data!$J:$J,data!$A:$A,Sheet1!E$7,data!$F:$F,Sheet1!$C9)/10^6 -> 169867.35 | F9: =SUMIFS(data!$J:$J,data!$A:$A,Sheet1!F$7,data!$F:$F,Sheet1!$C9)/10^6 -> 128930.7 | G9: =SUMIFS(data!$J:$J,data!$A:$A,Sheet1!G$7,data!$F:$F,Sheet1!$C9)/10^6 -> 115777.55 | H9: =SUMIFS(data!$J:$J,data!$A:$A,Sheet1!H$7,data!$F:$F,Sheet1!$C9)/10^6 -> 139203.9 | I9: =SUMIFS(data!$J:$J,data!$A:$A,Sheet1!I$7,data!$F:$F,Sheet1!$C9)/10^6 -> 101121.31 | J9: =SUMIFS(data!$J:$J,data!$A:$A,Sheet1!J$7,data!$F:$F,Sheet1!$C9)/10^6 -> 117865.98 | K9: =SUMIFS(data!$J:$J,data!$A:$A,Sheet1!K$7,data!$F:$F,Sheet1!$C9)/10^6 -> 142817.26 | ... O9: =SUMIFS(data!$J:$J,data!$A:$A,Sheet1!O$7,data!$F:$F,Sheet1!$C9)/10^6 -> 0 | P9: =SUM(D9:O9) -> 1221433.5
B10: % doanh thu/ tổng DT | C10: rPET | D10: =D8/D9 -> 0.078772586 | E10: =E8/E9 -> 0.070562472 | F10: =F8/F9 -> 0.063836278 | G10: =G8/G9 -> 0.048740779 | H10: =H8/H9 -> 0.055740149 | I10: =I8/I9 -> 0.10812238 | J10: =J8/J9 -> 0.060287692 | K10: =K8/K9 -> 0.10105184 | ... P10: =P8/P9 -> 0.091625467
B13: SL bán (tấn) | C13: Nhóm hàng | D13: 1 | E13: 2 | F13: 3 | G13: 4 | H13: 5 | I13: 6 | J13: 7 | K13: 8 | L13: 9 | M13: 10 | N13: 11 | O13: 12 | P13: Tổng
B14: Unilever | C14: rHDPE | D14: =SUMIFS(data!$I:$I,data!$B:$B,Sheet1!$B14,data!$A:$A,Sheet1!D$2,data!$F:$F,Sheet1!$C14)/1000 -> 148.35 | E14: =SUMIFS(data!$I:$I,data!$B:$B,Sheet1!$B14,data!$A:$A,Sheet1!E$2,data!$F:$F,Sheet1!$C14)/1000 -> 178 | F14: =SUMIFS(data!$I:$I,data!$B:$B,Sheet1!$B14,data!$A:$A,Sheet1!F$2,data!$F:$F,Sheet1!$C14)/1000 -> 215.875 | G14: =SUMIFS(data!$I:$I,data!$B:$B,Sheet1!$B14,data!$A:$A,Sheet1!G$2,data!$F:$F,Sheet1!$C14)/1000 -> 90.75 | H14: =SUMIFS(data!$I:$I,data!$B:$B,Sheet1!$B14,data!$A:$A,Sheet1!H$2,data!$F:$F,Sheet1!$C14)/1000 -> 160.85 | I14: =SUMIFS(data!$I:$I,data!$B:$B,Sheet1!$B14,data!$A:$A,Sheet1!I$2,data!$F:$F,Sheet1!$C14)/1000 -> 189.75 | J14: =SUMIFS(data!$I:$I,data!$B:$B,Sheet1!$B14,data!$A:$A,Sheet1!J$2,data!$F:$F,Sheet1!$C14)/1000 -> 155.375 | K14: =SUMIFS(data!$I:$I,data!$B:$B,Sheet1!$B14,data!$A:$A,Sheet1!K$2,data!$F:$F,Sheet1!$C14)/1000 -> 178.725 | ... O14: =SUMIFS(data!$I:$I,data!$B:$B,Sheet1!$B14,data!$A:$A,Sheet1!O$2,data!$F:$F,Sheet1!$C14)/1000 -> 0 | P14: =SUM(D14:O14) -> 1815.55
B15: Tổng | C15: rHDPE | D15: =SUMIFS(data!$I:$I,data!$A:$A,Sheet1!D$2,data!$F:$F,Sheet1!$C15)/1000 -> 180.85 | E15: =SUMIFS(data!$I:$I,data!$A:$A,Sheet1!E$2,data!$F:$F,Sheet1!$C15)/1000 -> 311.5 | F15: =SUMIFS(data!$I:$I,data!$A:$A,Sheet1!F$2,data!$F:$F,Sheet1!$C15)/1000 -> 474.825 | G15: =SUMIFS(data!$I:$I,data!$A:$A,Sheet1!G$2,data!$F:$F,Sheet1!$C15)/1000 -> 268.85 | H15: =SUMIFS(data!$I:$I,data!$A:$A,Sheet1!H$2,data!$F:$F,Sheet1!$C15)/1000 -> 351.625 | I15: =SUMIFS(data!$I:$I,data!$A:$A,Sheet1!I$2,data!$F:$F,Sheet1!$C15)/1000 -> 399.225 | J15: =SUMIFS(data!$I:$I,data!$A:$A,Sheet1!J$2,data!$F:$F,Sheet1!$C15)/1000 -> 271.425 | K15: =SUMIFS(data!$I:$I,data!$A:$A,Sheet1!K$2,data!$F:$F,Sheet1!$C15)/1000 -> 506.875 | ... O15: =SUMIFS(data!$I:$I,data!$A:$A,Sheet1!O$2,data!$F:$F,Sheet1!$C15)/1000 -> 0 | P15: =SUM(D15:O15) -> 4488.1
B16: % SL bán/ tổng SL | C16: rHDPE | D16: =D14/D15 -> 0.82029306 | E16: =E14/E15 -> 0.57142857 | F16: =F14/F15 -> 0.45464118 | G16: =G14/G15 -> 0.33754882 | H16: =H14/H15 -> 0.45744756 | I16: =I14/I15 -> 0.47529589 | J16: =J14/J15 -> 0.57244174 | K16: =K14/K15 -> 0.35260173 | ... P16: =P14/P15 -> 0.4045253
B18: Doanh thu (trđ) | C18: Nhóm hàng | D18: 1 | E18: 2 | F18: 3 | G18: 4 | H18: 5 | I18: 6 | J18: 7 | K18: 8 | L18: 9 | M18: 10 | N18: 11 | O18: 12 | P18: Tổng
B19: Unilever | C19: rHDPE | D19: =SUMIFS(data!$J:$J,data!$B:$B,Sheet1!$B19,data!$A:$A,Sheet1!D$7,data!$F:$F,Sheet1!$C19)/10^6 -> 5151.0986 | E19: =SUMIFS(data!$J:$J,data!$B:$B,Sheet1!$B19,data!$A:$A,Sheet1!E$7,data!$F:$F,Sheet1!$C19)/10^6 -> 6287.385 | F19: =SUMIFS(data!$J:$J,data!$B:$B,Sheet1!$B19,data!$A:$A,Sheet1!F$7,data!$F:$F,Sheet1!$C19)/10^6 -> 7635.65 | G19: =SUMIFS(data!$J:$J,data!$B:$B,Sheet1!$B19,data!$A:$A,Sheet1!G$7,data!$F:$F,Sheet1!$C19)/10^6 -> 3157.308 | H19: =SUMIFS(data!$J:$J,data!$B:$B,Sheet1!$B19,data!$A:$A,Sheet1!H$7,data!$F:$F,Sheet1!$C19)/10^6 -> 5542.4595 | I19: =SUMIFS(data!$J:$J,data!$B:$B,Sheet1!$B19,data!$A:$A,Sheet1!I$7,data!$F:$F,Sheet1!$C19)/10^6 -> 6534.1485 | J19: =SUMIFS(data!$J:$J,data!$B:$B,Sheet1!$B19,data!$A:$A,Sheet1!J$7,data!$F:$F,Sheet1!$C19)/10^6 -> 5495.4963 | K19: =SUMIFS(data!$J:$J,data!$B:$B,Sheet1!$B19,data!$A:$A,Sheet1!K$7,data!$F:$F,Sheet1!$C19)/10^6 -> 6360.482 | ... O19: =SUMIFS(data!$J:$J,data!$B:$B,Sheet1!$B19,data!$A:$A,Sheet1!O$7,data!$F:$F,Sheet1!$C19)/10^6 -> 0 | P19: =SUM(D19:O19) -> 64047.461
B20: Tổng | C20: rHDPE | D20: =SUMIFS(data!$J:$J,data!$A:$A,Sheet1!D$7,data!$F:$F,Sheet1!$C20)/10^6 -> 6108.7015 | E20: =SUMIFS(data!$J:$J,data!$A:$A,Sheet1!E$7,data!$F:$F,Sheet1!$C20)/10^6 -> 9546.6135 | F20: =SUMIFS(data!$J:$J,data!$A:$A,Sheet1!F$7,data!$F:$F,Sheet1!$C20)/10^6 -> 14668.776 | G20: =SUMIFS(data!$J:$J,data!$A:$A,Sheet1!G$7,data!$F:$F,Sheet1!$C20)/10^6 -> 6763.9122 | H20: =SUMIFS(data!$J:$J,data!$A:$A,Sheet1!H$7,data!$F:$F,Sheet1!$C20)/10^6 -> 9389.5945 | I20: =SUMIFS(data!$J:$J,data!$A:$A,Sheet1!I$7,data!$F:$F,Sheet1!$C20)/10^6 -> 10734.442 | J20: =SUMIFS(data!$J:$J,data!$A:$A,Sheet1!J$7,data!$F:$F,Sheet1!$C20)/10^6 -> 8037.294 | K20: =SUMIFS(data!$J:$J,data!$A:$A,Sheet1!K$7,data!$F:$F,Sheet1!$C20)/10^6 -> 14841.699 | ... O20: =SUMIFS(data!$J:$J,data!$A:$A,Sheet1!O$7,data!$F:$F,Sheet1!$C20)/10^6 -> 0 | P20: =SUM(D20:O20) -> 120164.11
B21: % doanh thu/ tổng DT | C21: rHDPE | D21: =D19/D20 -> 0.84323954 | E21: =E19/E20 -> 0.65859847 | F21: =F19/F20 -> 0.52053765 | G21: =G19/G20 -> 0.46678725 | H21: =H19/H20 -> 0.59027677 | I21: =I19/I20 -> 0.60870874 | J21: =J19/J20 -> 0.68374957 | K21: =K19/K20 -> 0.42855485 | ... P21: =P19/P20 -> 0.53299991

Sheet data
I2: =SUBTOTAL(9,I4:I848) -> 1815550 | J2: =SUBTOTAL(9,J4:J848)/10^6 -> 64047.461
A3: Month | C3: Incoterm | D3: Customer | E3: Customer | F3: Material Group | G3: Product | H3: Product | I3: Số lượng h.bán T.Tế | J3: Doanh thu thuần 2 T.Tế
A4: 1 | C4: B2B | D4: 1000 | E4: CPSX Nhựa Duy Tân | F4: rPET | G4: 110000354 | H4: Hạt nhựa rPET WSS01G | I4: 11000 | J4: 371268975
A5: 1 | C5: B2B | D5: 102990 | E5: Coca-Cola Thủ Đức | F5: rPET | G5: 110000332 | H5: Hạt nhựa rPET iSS01084G | I5: 72600 | J5: 2452863600
A6: 1 | B6: Unilever | C6: B2B | D6: 104894 | E6: UNILEVER-NGỌC NGHĨA | F6: rPET | G6: 110000354 | H6: Hạt nhựa rPET WSS01G | I6: 242000 | J6: 7886494000
A7: 1 | C7: B2B | D7: 104909 | E7: Công ty TNHH La Vie | F7: rPET | G7: 110000497 | H7: Hạt Nhựa rPET WSS01G-L | I7: 2200 | J7: 68172500
A8: 1 | C8: B2B | D8: 105186 | E8: CÔNG TY TNHH HON CHU | F8: rPET | G8: 110000355 | H8: Hạt nhựa rPET iSS01G | I8: 3300 | J8: 116044500
A9: 1 | C9: B2B | D9: 105194 | E9: Suntory Việt Nam | F9: rPET | G9: 110000332 | H9: Hạt nhựa rPET iSS01084G | I9: 154000 | J9: 5761602000
A10: 1 | C10: B2B | D10: 105194 | E10: Suntory Việt Nam | F10: rPET | G10: 110000355 | H10: Hạt nhựa rPET iSS01G | I10: 4400 | J10: 165513920
A11: 1 | C11: B2B | D11: 105204 | E11: CTY NGỌC NGHĨA-TÂY N | F11: rPET | G11: 110000354 | H11: Hạt nhựa rPET WSS01G | I11: 24200 | J11: 768350000
A12: 1 | C12: B2B | D12: 105207 | E12: Sri Thái Bình Dương | F12: rPET | G12: 110000332 | H12: Hạt nhựa rPET iSS01084G | I12: -13750.7 | J12: -508671395
A13: 1 | C13: B2B | D13: 105222 | E13: CN Cty Coca - Hà Nội | F13: rPET | G13: 110000332 | H13: Hạt nhựa rPET iSS01084G | I13: 88000 | J13: 3029312000
A14: 1 | B14: Unilever | C14: B2B | D14: 105223 | E14: Dynaplast Bắc Ninh | F14: rHDPE | G14: 110000339 | H14: Hạt Nhựa rHDPE MBF01 | I14: 49500 | J14: 1777149000
A15: 1 | B15: Unilever | C15: B2B | D15: 105263 | E15: Unilever Duy Tân | F15: rHDPE | G15: 110000339 | H15: Hạt Nhựa rHDPE MBF01 | I15: -150 | J15: -5264100
A16: 1 | B16: Unilever | C16: B2B | D16: 105263 | E16: Unilever Duy Tân | F16: rHDPE | G16: 110000339 | H16: Hạt Nhựa rHDPE MBF01 | I16: 55000 | J16: 1930170000
A17: 1 | B17: Unilever | C17: B2B | D17: 105263 | E17: Unilever Duy Tân | F17: rPET | G17: 110000354 | H17: Hạt nhựa rPET WSS01G | I17: 11000 | J17: 357423000
A18: 1 | B18: Unilever | C18: B2B | D18: 105263 | E18: Unilever Duy Tân | F18: rHDPE | G18: 110000360 | H18: Hạt nhựa rHDI4L01 | I18: 5500 | J18: 122476734
A19: 1 | B19: Unilever | C19: B2B | D19: 105263 | E19: Unilever Duy Tân | F19: rHDPE | G19: 110000425 | H19: Hạt Nhựa HCBF-Whi-U | I19: 5500 | J19: 186153000
A20: 1 | B20: Unilever | C20: B2B | D20: 105263 | E20: Unilever Duy Tân | F20: rHDPE | G20: 110000426 | H20: Hạt Nhựa HCBF-Yel-U | I20: 22000 | J20: 754380000
A21: 1 | B21: Unilever | C21: B2B | D21: 105263 | E21: Unilever Duy Tân | F21: rHDPE | G21: 110000481 | H21: Hạt Nhựa rHDPE PCF01 | I21: 11000 | J21: 386034000
A22: 1 | C22: B2B | D22: 105265 | E22: Muji- DTP | F22: rPET | G22: 110000354 | H22: Hạt nhựa rPET WSS01G | I22: 5500 | J22: 185634488
A23: 1 | C23: B2B | D23: 105271 | E23: Suntory- Ngọc Nghĩa Tây Ninh | F23: rPET | G23: 110000332 | H23: Hạt nhựa rPET iSS01084G | I23: 44000 | J23: 1636624000
A24: 1 | C24: B2B | D24: 105271 | E24: Suntory- Ngọc Nghĩa Tây Ninh | F24: rPET | G24: 110000355 | H24: Hạt nhựa rPET iSS01G | I24: 3300 | J24: 118965000
A25: 1 | C25: B2B | D25: 105272 | E25: LINH CHI | F25: Xơ sợi | G25: 110000466 | H25: Hạt Nhựa rPET WSS05S | I25: 11000 | J25: 209000000
A26: 1 | C26: B2B | D26: 105281 | E26: Plascene- DTP | F26: rPET | G26: 110000329 | H26: Hạt nhựa rPET WSS01 | I26: 22000 | J26: 718440492
A27: 1 | C27: B2B | D27: 105281 | E27: Plascene- DTP | F27: rPET | G27: 110000354 | H27: Hạt nhựa rPET WSS01G | I27: 44000 | J27: 1436880984
A28: 1 | C28: B2B | D28: 105284 | E28: Motul -DTP | F28: rHDPE | G28: 110000374 | H28: Hạt Nhựa rHDB03N02 | I28: 22000 | J28: 759102300
A29: 1 | C29: B2B | D29: 105291 | E29: AN NHẬT | F29: rPET | G29: 110000354 | H29: Hạt nhựa rPET WSS01G | I29: 3300 | J29: 108043822
A30: 1 | C30: B2B | D30: 105306 | E30: MTV MILKIWAY SOLUTIO | F30: rPET | G30: 110000354 | H30: Hạt nhựa rPET WSS01G | I30: 22000 | J30: =711068380000-710357311620 -> 711068380
A31: 1 | C31: B2B | D31: 105319 | E31: PHƯƠNG VI | F31: rHDPE | G31: 110000365 | H31: Hạt nhựa rHDI3W01 | I31: 3000 | J31: 80445000
A32: 1 | C32: B2B | D32: 105324 | E32: NHỰA TRƯỜNG AN | F32: rHDPE | G32: 110000407 | H32: Vảy HD Ép Đỏ | I32: 6000 | J32: 94444445
A33: 1 | C33: B2B | D33: 105324 | E33: NHỰA TRƯỜNG AN | F33: rHDPE | G33: 110000409 | H33: Vảy HD Ép Vàng | I33: 1500 | J33: 23611111
A34: 1 | C34: XK | D34: 200319 | E34: Niagara Bottling, LL | F34: rPET | G34: 110000354 | H34: Hạt nhựa rPET WSS01G | I34: 2376000 | J34: 72787646470
A35: 1 | C35: XK | D35: 200337 | E35: Toyota Tsusho | F35: rPET | G35: 110000354 | H35: Hạt nhựa rPET WSS01G | I35: 1100 | J35: 40071295
A36: 1 | C36: XK | D36: 200367 | E36: MAS CO.LTD | F36: rPET | G36: 110000355 | H36: Hạt nhựa rPET iSS01G | I36: 132000 | J36: 4710530000
A37: 1 | C37: XK | D37: 200368 | E37: SodaStream | F37: rPET | G37: 110000332 | H37: Hạt nhựa rPET iSS01084G | I37: 44000 | J37: 1732366680
A38: 2 | C38: B2B | D38: 1000 | E38: CPSX Nhựa Duy Tân | F38: rPET | G38: 110000354 | H38: Hạt nhựa rPET WSS01G | I38: 23100 | J38: 725857440
A39: 2 | C39: B2B | D39: 1000 | E39: CPSX Nhựa Duy Tân | F39: rHDPE | G39: 110000360 | H39: Hạt nhựa rHDI4L01 | I39: 11000 | J39: 222361700
A40: 2 | C40: B2B | D40: 1000 | E40: CPSX Nhựa Duy Tân | F40: rHDPE | G40: 110000361 | H40: Hạt nhựa rHDI3R01 | I40: 16500 | J40: 333542550
A41: 2 | C41: B2B | D41: 1000 | E41: CPSX Nhựa Duy Tân | F41: rHDPE | G41: 110000363 | H41: Hạt nhựa rHDI3Gy01 | I41: 1000 | J41: 20214700
...
