Workbook

Sheet Daily
B1: VN | C1: 46203 | D1: =IF(B1="EN","AVG Estimate","BQ dự kiến") -> BQ dự kiến | E1: =IF(B1="EN","AVG Estimate","BQ dự kiến") -> BQ dự kiến | F1: =IF(B1="EN","AVG Estimate","BQ dự kiến") -> BQ dự kiến | G1: =IF(B1="EN","AVG Estimate","BQ dự kiến") -> BQ dự kiến | H1: =IF(B1="EN","AVG Estimate","BQ dự kiến") -> BQ dự kiến | I1: =IF(B1="EN","AVG Estimate","BQ dự kiến") -> BQ dự kiến | J1: =IF(B1="EN","AVG Estimate","BQ dự kiến") -> BQ dự kiến | K1: =IF(B1="EN","AVG Estimate","BQ dự kiến") -> BQ dự kiến | L1: =IF(B1="EN","AVG Estimate","BQ dự kiến") -> BQ dự kiến | M1: =IF(B1="EN","AVG Estimate","BQ dự kiến") -> BQ dự kiến | N1: =IF(A1="EN","AVG Estimate","BQ dự kiến") -> BQ dự kiến | O1: =IF(B1="EN","AVG Estimate","BQ dự kiến") -> BQ dự kiến | P1: =IF(B1="EN","AVG Actual","BQ thực tế") -> BQ thực tế | AI1: 30
B2: =IF(B1="EN","ACTUAL (DAILY)"," BÁO CÁO THỰC HIỆN KPI HÀNG NGÀY") -> BÁO CÁO THỰC HIỆN KPI HÀNG NGÀY | D2: =AI10/$AI$1 -> 4783.8358 | E2: =D2+$AI$10/$AI$1 -> 9567.6715 | F2: =E2+$AI$10/$AI$1 -> 14351.507 | G2: =F2+$AI$10/$AI$1 -> 19135.343 | H2: =G2+$AI$10/$AI$1 -> 23919.179 | I2: =H2+$AI$10/$AI$1 -> 28703.015 | J2: =I2+$AI$10/$AI$1 -> 33486.85 | K2: =J2+$AI$10/$AI$1 -> 38270.686 | L2: =K2+$AI$10/$AI$1 -> 43054.522 | ... AH2: =AG2+$AI$10/$AI$1 -> 148298.91 | AI2: =AH2 -> 148298.91
B3: =IF(B1="EN","As of","Đến ngày") -> Đến ngày | C3: =B3&" "& TEXT(C1,"dd/mm/yyyy") -> Đến ngày 30/06/2026 | D3: =$AI$2/($AI$1) -> 4943.297 | E3: =$AI$2/($AI$1) -> 4943.297 | F3: =$AI$2/($AI$1) -> 4943.297 | G3: =$AI$2/($AI$1) -> 4943.297 | H3: =$AI$2/($AI$1) -> 4943.297 | I3: =$AI$2/($AI$1) -> 4943.297 | J3: =$AI$2/($AI$1) -> 4943.297 | K3: =$AI$2/($AI$1) -> 4943.297 | ... AH3: =$AI$2/($AI$1) -> 4943.297
A4: =IF(B1="EN","MTD Volumn (ton)","Sản lượng luỹ kế từ đầu tháng (tấn)") -> Sản lượng luỹ kế từ đầu tháng (tấn) | B4: No, | C4: =IF(B1="EN","Items","Chỉ tiêu") -> Chỉ tiêu | D4: 1 | E4: 2 | F4: 3 | G4: 4 | H4: 5 | I4: 6 | J4: 7 | K4: 8 | L4: 9 | M4: 10 | N4: 11 | O4: 12 | P4: 13 | Q4: 14 | R4: 15 | S4: 16 | T4: 17 | U4: 18 | V4: 19 | W4: 20 | X4: 21 | Y4: 22 | Z4: 23 | AA4: 24 | AB4: 25 | AC4: 26 | AD4: 27 | AE4: 28 | AF4: 29 | AG4: 30 | AH4: 31 | AI4: Est | AJ4: AVG_Net sales Plan | AL4: AVG_Sales Volume Plan
B5: 1 | C5: =IF(B1="EN","Daily Net sales (mVND)","Doanh thu ngày (triệu VND)") -> Doanh thu ngày (triệu VND) | D5: =SUM(D6:D8) -> 5147.239 | E5: =SUM(E6:E8) -> 5385.719 | F5: =SUM(F6:F8) -> 8938.1 | G5: =SUM(G6:G8) -> 11380.715 | H5: =SUM(H6:H8) -> 13061.603 | I5: =SUM(I6:I8) -> 9316.684 | J5: =SUM(J6:J8) -> 0 | K5: =SUM(K6:K8) -> 2477.32 | ... AH5: =SUM(AH6:AH8) -> 0 | AI5: =SUM(D5:AH5) -> 117761.69 | AJ5: =AI5/DAY(C1) -> 3925.3896 | AL5: =AI25/AI1 -> 156.39841
C6: B2B | D6: =1210.11-62.921 -> 1147.189 | E6: =1506.43-61.921 -> 1444.509 | F6: 1196.58 | G6: =726.77-29.835 -> 696.935 | H6: =2417.27-283.997 -> 2133.273 | I6: =3580.24-125.896 -> 3454.344 | K6: 2106.98 | L6: =2418.91-191.758 -> 2227.152 | M6: =3958.68-252.622 -> 3706.058 | N6: =3126.84-296.521 -> 2830.319 | O6: =1499.73-83.306 -> 1416.424 | P6: =1808.37-30.835 -> 1777.535 | R6: =183.49-30.502 -> 152.988 | S6: =347.45-152.575 -> 194.875 | T6: =1623.13-31.002 -> 1592.128 | U6: =1375.68-115.35 -> 1260.33 | V6: =3417.52-376.875 -> 3040.645 | W6: =209.9-60.546 -> 149.354 | Y6: 1221.79 | Z6: =3562.43-84.257 -> 3478.173 | AA6: =1183.33-280.968 -> 902.362 | AB6: =5023.68-192.967 -> 4830.713 | AC6: =1137.91-83.584 -> 1054.326 | AD6: =2350.09+44.796 -> 2394.886 | AF6: 3071.39 | AG6: 1409.66 | AI6: =SUM(D6:AH6) -> 48890.918
C7: Export | D7: 3320.88 | E7: 3756.04 | F7: 7514.94 | G7: 9984.82 | H7: 10428.02 | I7: 5266.04 | T7: 3323.41 | U7: 3325.31 | W7: 2914.7 | Y7: 1943.43 | AD7: 3326.06 | AI7: =SUM(D7:AH7) -> 55103.65
C8: Other | D8: 679.17 | E8: 185.17 | F8: 226.58 | G8: 698.96 | H8: 500.31 | I8: 596.3 | K8: 370.34 | L8: 716.98 | M8: 6 | N8: 967.86 | O8: 370.34 | R8: 732.86 | S8: 740.67 | T8: 370.34 | U8: 1324.06 | W8: 400.55 | Y8: 1126.72 | Z8: 370.34 | AA8: 370.34 | AB8: 1342.1 | AF8: =833.6+107.95 -> 941.55 | AG8: =716.98+12.6 -> 729.58 | AI8: =SUM(D8:AH8) -> 13767.12
B10: 2 | C10: =IF(B1="EN","MTD Net sales (mVND)","Doanh thu luỹ kế từ đầu tháng (triệu VND)") -> Doanh thu luỹ kế từ đầu tháng (triệu VND) | D10: =SUM(D11:D13) -> 5147.239 | E10: =SUM(E11:E13) -> 10532.958 | F10: =SUM(F11:F13) -> 19471.058 | G10: =SUM(G11:G13) -> 30851.773 | H10: =SUM(H11:H13) -> 43913.376 | I10: =SUM(I11:I13) -> 53230.06 | J10: =SUM(J11:J13) -> 53230.06 | K10: =SUM(K11:K13) -> 55707.38 | ... AI10: =SUM(AI11:AI13) -> 143515.07 | AJ10: =SUM(D5:AH5) -> 117761.69 | AK10: =AJ10/AI10 -> 0.82055275 | AL10: =IF(100%-AK10>0,100%-AK10,0) -> 0.17944725 | AM10: =SUM(D6:AH6) -> 48890.918 | AN10: =AM10/AI11 -> 0.83594476 | AO10: =IF(100%-AN10>0,100%-AN10,0) -> 0.16405524 | AS10: =SUM(D7:AH7) -> 55103.65 | AT10: =AS10/AI12 -> 0.65062028 | AU10: =1-AT10 -> 0.34937972
C11: =C6 -> B2B | D11: =SUM($D6:D6) -> 1147.189 | E11: =SUM($D6:E6) -> 2591.698 | F11: =SUM($D6:F6) -> 3788.278 | G11: =SUM($D6:G6) -> 4485.213 | H11: =SUM($D6:H6) -> 6618.486 | I11: =SUM($D6:I6) -> 10072.83 | J11: =SUM($D6:J6) -> 10072.83 | K11: =SUM($D6:K6) -> 12179.81 | ... AG11: =SUM($D6:AG6) -> 48890.918 | AI11: 58485.824
C12: =C7 -> Export | D12: =SUM($D7:D7) -> 3320.88 | E12: =SUM($D7:E7) -> 7076.92 | F12: =SUM($D7:F7) -> 14591.86 | G12: =SUM($D7:G7) -> 24576.68 | H12: =SUM($D7:H7) -> 35004.7 | I12: =SUM($D7:I7) -> 40270.74 | J12: =SUM($D7:J7) -> 40270.74 | K12: =SUM($D7:K7) -> 40270.74 | ... AG12: =SUM($D7:AG7) -> 55103.65 | AI12: 84694.024
C13: =C8 -> Other | D13: =SUM($D8:D8) -> 679.17 | E13: =SUM($D8:E8) -> 864.34 | F13: =SUM($D8:F8) -> 1090.92 | G13: =SUM($D8:G8) -> 1789.88 | H13: =SUM($D8:H8) -> 2290.19 | I13: =SUM($D8:I8) -> 2886.49 | J13: =SUM($D8:J8) -> 2886.49 | K13: =SUM($D8:K8) -> 3256.83 | ... AG13: =SUM($D8:AG8) -> 13767.12 | AI13: 335.225
B15: 3 | C15: =IF(B1="EN","MTD PO from customers (mVND)","Đơn đặt hàng phát sinh luỹ kế từ đầu tháng (triệu VND)") -> Đơn đặt hàng phát sinh luỹ kế từ đầu tháng (triệu VND) | D15: =SUM(D16:D18) -> 74.35 | E15: =SUM(E16:E18) -> 3739.27 | F15: =SUM(F16:F18) -> 5010.08 | G15: =SUM(G16:G18) -> 5131.11 | H15: =SUM(H16:H18) -> 5299.33 | I15: =SUM(I16:I18) -> 5299.33 | J15: =SUM(J16:J18) -> 5299.33 | K15: =SUM(K16:K18) -> 6024.23 | ... AH15: =SUM(AH16:AH18) -> 0
C16: =C11 -> B2B | D16: 62.92 | E16: 3727.84 | F16: 4998.65 | G16: 5119.68 | H16: 5149.18 | I16: 5149.18 | J16: 5149.18 | K16: 5874.08 | L16: 22262.07 | M16: 22728.86 | N16: 23228.86 | O16: 25465.47 | P16: 25496.3 | Q16: 25496.3 | R16: 25526.8 | S16: 25794.87 | T16: 25976.71 | U16: 26008.34 | V16: 28607.44 | W16: 28667.98 | X16: 28667.98 | Y16: 44960 | Z16: 47418.9 | AA16: 47479.86 | AB16: 51029.84 | AC16: 51344.07 | AD16: 51344.07 | AE16: 51344.07 | AF16: 51344.07 | AG16: 52455.18
C17: =C12 -> Export | AA17: 841.73 | AB17: 841.73 | AC17: 841.73 | AD17: 841.73 | AE17: 841.73 | AF17: 841.73 | AG17: 36904.96
C18: Other | D18: 11.43 | E18: 11.43 | F18: 11.43 | G18: 11.43 | H18: 150.15 | I18: 150.15 | J18: 150.15 | K18: 150.15 | L18: 150.15 | M18: 150.15 | N18: 150.15 | O18: 150.15 | P18: 150.15 | Q18: 150.15 | R18: 150.15 | S18: 350.28 | T18: 350.28 | U18: 350.28 | V18: 350.28 | W18: 350.28 | X18: 13133.45 | Y18: 13133.45 | Z18: 16367.18 | AA18: 16367.18 | AB18: 16367.18 | AC18: 16383.68 | AD18: 16383.68 | AE18: 16383.68 | AF18: 16383.68 | AG18: 16390.98
B20: 4 | C20: =IF(B1="EN","Daily sales volume (Ton)","Sản lượng bán hàng ngày (Tấn)") -> Sản lượng bán hàng ngày (Tấn) | D20: =SUM(D21:D23) -> 157.49 | E20: =SUM(E21:E23) -> 167.56 | F20: =SUM(F21:F23) -> 264.28 | G20: =SUM(G21:G23) -> 327.95 | H20: =SUM(H21:H23) -> 431.751 | I20: =SUM(I21:I23) -> 322.85 | J20: =SUM(J21:J23) -> 0 | K20: =SUM(K21:K23) -> 76.98 | ... AH20: =SUM(AH21:AH23) -> 0 | AI20: =SUM(D20:AH20)/DAY(C1) -> 125.16033
C21: =C11 -> B2B | D21: =42.79-15.1 -> 27.69 | E21: =66.92-14.86 -> 52.06 | F21: 37.4 | G21: =29.16-7.16 -> 22 | H21: =99.87-33.869 -> 66.001 | I21: =111.1-9.4 -> 101.7 | K21: =65.98 -> 65.98 | L21: =103.41-34.309 -> 69.101 | M21: =146-33.747 -> 112.253 | N21: =120.35-32.347 -> 88.003 | O21: =50-5.998 -> 44.002 | P21: =60.5-7.4 -> 53.1 | R21: =11.72-7.32 -> 4.4 | S21: =32.45-26.85 -> 5.6 | T21: =56.94-7.44 -> 49.5 | U21: =52.12-13.62 -> 38.5 | V21: =113.44-16.75 -> 96.69 | W21: =18.93-14.53 -> 4.4 | Y21: 36.3 | Z21: =122.68-12.13 -> 110.55 | AA21: =60.44-32.94 -> 27.5 | AB21: =175.24-22.34 -> 152.9 | AC21: =39.02-6.02 -> 33 | AD21: =74.4+3.15 -> 77.55 | AF21: 100.1 | AG21: 43.1 | AI21: =SUM(D21:AH21) -> 1519.38
C22: =C12 -> Export | D22: 110 | E22: 110 | F22: 220 | G22: 286 | H22: 352 | I22: 198 | T22: 110 | U22: 110 | W22: 132 | Y22: 88 | AD22: 110 | AI22: =SUM(D22:AH22) -> 1826
C23: Other | D23: 19.8 | E23: 5.5 | F23: 6.88 | G23: 19.95 | H23: 13.75 | I23: 23.15 | K23: 11 | L23: 22 | M23: 0.5 | N23: 27.5 | O23: 11 | R23: 22 | S23: 22 | T23: 11 | U23: 38.5 | W23: 11 | Y23: 33 | Z23: 11 | AA23: 11 | AB23: 38.5 | AF23: =19.2+8.3 -> 27.5 | AG23: =22+0.9 -> 22.9 | AI23: =SUM(D23:AH23) -> 409.43
B25: 5 | C25: =IF(B1="EN","MTD sales volume (Ton)","Sản lượng bán luỹ kế từ đầu tháng (tấn)") -> Sản lượng bán luỹ kế từ đầu tháng (tấn) | D25: =SUM(D26:D28) -> 157.49 | E25: =SUM(E26:E28) -> 325.05 | F25: =SUM(F26:F28) -> 589.33 | G25: =SUM(G26:G28) -> 917.28 | H25: =SUM(H26:H28) -> 1349.031 | I25: =SUM(I26:I28) -> 1671.881 | J25: =SUM(J26:J28) -> 1671.881 | K25: =SUM(K26:K28) -> 1748.861 | ... AI25: =SUM(AI26:AI28) -> 4691.9522
C26: =C21 -> B2B | D26: =SUM($D21:D21) -> 27.69 | E26: =SUM($D21:E21) -> 79.75 | F26: =SUM($D21:F21) -> 117.15 | G26: =SUM($D21:G21) -> 139.15 | H26: =SUM($D21:H21) -> 205.151 | I26: =SUM($D21:I21) -> 306.851 | J26: =SUM($D21:J21) -> 306.851 | K26: =SUM($D21:K21) -> 372.831 | ... AG26: =SUM($D21:AG21) -> 1519.38 | AI26: 1935.9522
C27: =C22 -> Export | D27: =SUM($D22:D22) -> 110 | E27: =SUM($D22:E22) -> 220 | F27: =SUM($D22:F22) -> 440 | G27: =SUM($D22:G22) -> 726 | H27: =SUM($D22:H22) -> 1078 | I27: =SUM($D22:I22) -> 1276 | J27: =SUM($D22:J22) -> 1276 | K27: =SUM($D22:K22) -> 1276 | ... AG27: =SUM($D22:AG22) -> 1826 | AI27: 2745
C28: Other | D28: =SUM($D23:D23) -> 19.8 | E28: =SUM($D23:E23) -> 25.3 | F28: =SUM($D23:F23) -> 32.18 | G28: =SUM($D23:G23) -> 52.13 | H28: =SUM($D23:H23) -> 65.88 | I28: =SUM($D23:I23) -> 89.03 | J28: =SUM($D23:J23) -> 89.03 | K28: =SUM($D23:K23) -> 100.03 | ... AG28: =SUM($D23:AG23) -> 409.43 | AI28: 11
B30: 6 | C30: =IF(B1="EN","Daily production volume (Ton)","Sản lượng sản xuất hàng ngày (Tấn)") -> Sản lượng sản xuất hàng ngày (Tấn) | D30: =SUM(D31:D31) -> 146 | E30: =SUM(E31:E31) -> 125 | F30: =SUM(F31:F31) -> 76 | G30: =SUM(G31:G31) -> 126 | H30: =SUM(H31:H31) -> 154 | I30: =SUM(I31:I31) -> 100 | J30: =SUM(J31:J31) -> 94 | K30: =SUM(K31:K31) -> 151 | ... AH30: =SUM(AH31:AH31) -> 0
C31: DTR Factory | D31: 146 | E31: 125 | F31: 76 | G31: 126 | H31: 154 | I31: 100 | J31: 94 | K31: 151 | L31: 150 | M31: 131 | N31: 149 | O31: =169-27.5-26.55 -> 114.95 | P31: 123 | Q31: =166.6-22.5 -> 144.1 | R31: 145 | S31: 147 | T31: 166 | U31: 129 | V31: 113 | W31: 149 | X31: =196.675-22 -> 174.675 | Y31: 149 | Z31: 141 | AA31: 153 | AB31: 80 | AC31: 116 | AD31: =205.2167-3.3-4.5 -> 197.4167 | AE31: 0 | AF31: 198 | AG31: 80
B33: 7 | C33: =IF(B1="EN","MTD production volume (Ton)","Sản lượng sản xuất luỹ kế từ đầu tháng (tấn)") -> Sản lượng sản xuất luỹ kế từ đầu tháng (tấn) | D33: =SUM(D34:D34) -> 146 | E33: =SUM(E34:E34) -> 271 | F33: =SUM(F34:F34) -> 347 | G33: =SUM(G34:G34) -> 473 | H33: =SUM(H34:H34) -> 627 | I33: =SUM(I34:I34) -> 727 | J33: =SUM(J34:J34) -> 821 | K33: =SUM(K34:K34) -> 972 | ... AH33: =SUM(AH34:AH34) -> 0
C34: DTR Factory | D34: =SUM($D31:D31) -> 146 | E34: =SUM($D31:E31) -> 271 | F34: =SUM($D31:F31) -> 347 | G34: =SUM($D31:G31) -> 473 | H34: =SUM($D31:H31) -> 627 | I34: =SUM($D31:I31) -> 727 | J34: =SUM($D31:J31) -> 821 | K34: =SUM($D31:K31) -> 972 | ... AG34: =SUM($D31:AG31) -> 3922.1417
B36: 8 | C36: =IF(B1="EN","Finished Goods Inventory (Ton)","Thành phẩm tồn kho (Tấn)") -> Thành phẩm tồn kho (Tấn) | D36: =D37 -> 6340.74 | E36: =E37 -> 6373.01 | F36: =F37 -> 6339.54 | G36: =G37 -> 6270.97 | H36: =H37 -> 6031.74 | I36: =I37 -> 5818.72 | J36: =J37 -> 5638 | K36: =K37 -> 5762.1 | ... AG36: =AG37 -> 6842.41
C37: DTR Factory | D37: 6340.74 | E37: 6373.01 | F37: 6339.54 | G37: 6270.97 | H37: 6031.74 | I37: 5818.72 | J37: 5638 | K37: 5762.1 | L37: 5843.56 | M37: 5935.05 | N37: 5967.97 | O37: 6032.37 | P37: 6085.73 | Q37: 6124.58 | R37: 6277.43 | S37: 6346.73 | T37: 6453 | U37: 6478.27 | V37: 6437.15 | W37: 6459.33 | X37: 6402.91 | Y37: 6571.06 | Z37: 6560.78 | AA37: 6551.52 | AB37: 6652.64 | AC37: 6651.74 | AD37: 6789.09 | AE37: 6763.24 | AF37: 6763.24 | AG37: 6842.41
B39: 9 | C39: Sản lượng mua nguyên liệu [Tấn] | D39: =SUM(D40:D40) -> 0 | E39: =SUM(E40:E40) -> 230.43 | F39: =SUM(F40:F40) -> 48.01 | G39: =SUM(G40:G40) -> 170.67 | H39: =SUM(H40:H40) -> 193.93 | I39: =SUM(I40:I40) -> 179.33 | J39: =SUM(J40:J40) -> 0 | K39: =SUM(K40:K40) -> 181.05 | ... AH39: =SUM(AH40:AH40) -> 0
C40: DTR Factory | E40: 230.43 | F40: 48.01 | G40: 170.67 | H40: 193.93 | I40: 179.33 | K40: 181.05 | L40: 265.9 | M40: 155.76 | N40: 277.39 | O40: 195.1 | P40: 198.71 | R40: 209.78 | S40: 217.17 | T40: 149.48 | U40: 221.89 | V40: 242.95 | W40: 187.93 | Y40: 225.29 | Z40: 213.22 | AA40: 167.26 | AB40: 356.57 | AC40: 226.52 | AD40: 263.88 | AF40: 228.68 | AG40: 239.72
B42: 10 | C42: Lũy kế Sản lượng mua nguyên liệu [Tấn] | D42: =SUM(D43:D43) -> 0 | E42: =SUM(E43:E43) -> 230.43 | F42: =SUM(F43:F43) -> 278.44 | G42: =SUM(G43:G43) -> 449.11 | H42: =SUM(H43:H43) -> 643.04 | I42: =SUM(I43:I43) -> 822.37 | J42: =SUM(J43:J43) -> 822.37 | K42: =SUM(K43:K43) -> 1003.42 | ... AH42: =SUM(AH43:AH43) -> 0
C43: DTR Factory | D43: =SUM($D39:D39) -> 0 | E43: =SUM($D39:E39) -> 230.43 | F43: =SUM($D39:F39) -> 278.44 | G43: =SUM($D39:G39) -> 449.11 | H43: =SUM($D39:H39) -> 643.04 | I43: =SUM($D39:I39) -> 822.37 | J43: =SUM($D39:J39) -> 822.37 | K43: =SUM($D39:K39) -> 1003.42 | ... AG43: =SUM($D39:AG39) -> 5246.62
C44: AVG_Net Sales Plan | D44: =$AJ$5 -> 3925.3896 | E44: =$AJ$5 -> 3925.3896 | F44: =$AJ$5 -> 3925.3896 | G44: =$AJ$5 -> 3925.3896 | H44: =$AJ$5 -> 3925.3896 | I44: =$AJ$5 -> 3925.3896 | J44: =$AJ$5 -> 3925.3896 | K44: =$AJ$5 -> 3925.3896 | ... AH44: =$AJ$5 -> 3925.3896
C45: =IF(B1="EN","AVG Sales Volume_Plan","BQ sản lượng kế hoạch") -> BQ sản lượng kế hoạch | D45: =$AL$5 -> 156.39841 | E45: =$AL$5 -> 156.39841 | F45: =$AL$5 -> 156.39841 | G45: =$AL$5 -> 156.39841 | H45: =$AL$5 -> 156.39841 | I45: =$AL$5 -> 156.39841 | J45: =$AL$5 -> 156.39841 | K45: =$AL$5 -> 156.39841 | ... AH45: =$AL$5 -> 156.39841
C46: =IF(B1="EN","AVG Sales Volume_Actual","BQ sản lượng thực tế") -> BQ sản lượng thực tế | D46: =$AI$20 -> 125.16033 | E46: =$AI$20 -> 125.16033 | F46: =$AI$20 -> 125.16033 | G46: =$AI$20 -> 125.16033 | H46: =$AI$20 -> 125.16033 | I46: =$AI$20 -> 125.16033 | J46: =$AI$20 -> 125.16033 | K46: =$AI$20 -> 125.16033 | ... AH46: =$AI$20 -> 125.16033
C47: =IF(B1="EN","Estimated","Dự kiến cả tháng") -> Dự kiến cả tháng
C48: =IF(B1="EN","MTD Net Sales","Luỹ kế doanh thu từ đầu tháng") -> Luỹ kế doanh thu từ đầu tháng
B49: =IF(B1="EN","MTD Net Sales - B2B"," Doanh thu luỹ kế từ đầu tháng - B2B") -> Doanh thu luỹ kế từ đầu tháng - B2B | D49: =D11 -> 1147.189 | E49: =E11 -> 2591.698 | F49: =F11 -> 3788.278 | G49: =G11 -> 4485.213 | H49: =H11 -> 6618.486 | I49: =I11 -> 10072.83 | J49: =J11 -> 10072.83 | K49: =K11 -> 12179.81 | ... AI49: =AI11 -> 58485.824
...

Sheet Doanh thu và sản lượng bán
B1: Tỉ giá VND/USD | D1: 25210 | I1: 25210 | N1: 25110 | S1: 24910 | X1: 25200 | AC1: 25290 | AH1: 25320 | AM1: 25430 | AR1: 25350 | AW1: 25360 | BB1: 25460 | BG1: 25380 | BL1: 25610 | BQ1: 25650 | BV1: 25710
A2: Stt | B2: Mặt hàng | C2: TUẦN 1 | H2: TUẦN 2 | M2: TUẦN 3 | R2: TUẦN 4 | W2: TUẦN 6 | AB2: TUẦN 7 | AG2: TUẦN 8 | AL2: TUẦN 9 | AQ2: TUẦN 10 | AV2: TUẦN 11 | BA2: TUẦN 12 | BF2: TUẦN 13 | BK2: TUẦN 14 | BP2: TUẦN 15 | BU2: TUẦN 16 | BZ2: LŨY KẾ ĐẾN HIỆN TẠI
C3: Doanh thu | E3: Sản lượng bán | F3: Giá bán | H3: Doanh thu | J3: Sản lượng bán | K3: Giá bán | M3: Doanh thu | O3: Sản lượng bán | P3: Giá bán | R3: Doanh thu | T3: Sản lượng bán | U3: Giá bán | W3: Doanh thu | Y3: Sản lượng bán | Z3: Giá bán | AB3: Doanh thu | AD3: Sản lượng bán | AE3: Giá bán | AG3: Doanh thu | AI3: Sản lượng bán | AJ3: Giá bán | AL3: Doanh thu | AN3: Sản lượng bán | AO3: Giá bán | AQ3: Doanh thu | AS3: Sản lượng bán | AT3: Giá bán | AV3: Doanh thu | AX3: Sản lượng bán | AY3: Giá bán | BA3: Doanh thu | BC3: Sản lượng bán | BD3: Giá bán | BF3: Doanh thu | BH3: Sản lượng bán | BI3: Giá bán | BK3: Doanh thu | BM3: Sản lượng bán | BN3: Giá bán | BP3: Doanh thu | BR3: Sản lượng bán | BS3: Giá bán | BU3: Doanh thu | BW3: Sản lượng bán | BX3: Giá bán | BZ3: Doanh thu | CB3: Sản lượng bán | CC3: Giá bán
C4: Triệu VND | D4: USD | E4: Tấn | F4: Triệu VND | G4: USD | H4: Triệu VND | I4: USD | J4: Tấn | K4: Triệu VND | L4: USD | M4: Triệu VND | N4: USD | O4: Tấn | P4: Triệu VND | Q4: USD | R4: Triệu VND | S4: USD | T4: Tấn | U4: Triệu VND | V4: USD | W4: Triệu VND | X4: USD | Y4: Tấn | Z4: Triệu VND | AA4: USD | AB4: Triệu VND | AC4: USD | AD4: Tấn | AE4: Triệu VND | AF4: USD | AG4: Triệu VND | AH4: USD | AI4: Tấn | AJ4: Triệu VND | AK4: USD | AL4: Triệu VND | AM4: USD | AN4: Tấn | AO4: Triệu VND | AP4: USD | AQ4: Triệu VND | AR4: USD | AS4: Tấn | AT4: Triệu VND | AU4: USD | AV4: Triệu VND | AW4: USD | AX4: Tấn | AY4: Triệu VND | AZ4: USD | BA4: Triệu VND | BB4: USD | BC4: Tấn | BD4: Triệu VND | BE4: USD | BF4: Triệu VND | BG4: USD | BH4: Tấn | BI4: Triệu VND | BJ4: USD | BK4: Triệu VND | BL4: USD | BM4: Tấn | BN4: Triệu VND | BO4: USD | BP4: Triệu VND | BQ4: USD | BR4: Tấn | BS4: Triệu VND | BT4: USD | BU4: Triệu VND | BV4: USD | BW4: Tấn | BX4: Triệu VND | BY4: USD | BZ4: Triệu VND | CA4: USD | CB4: Tấn | CC4: Triệu/ Tấn | CD4: USD/ Tấn
A5: 1 | B5: Hạt rPET | C5: =10531.950414-10.164-3.388-86.98-6.16-74 -> 10351.258 | D5: =IFERROR(C5/D$1,0)*10^6 -> 410601.29 | E5: 301.4 | F5: =IFERROR(C5/E5,0) -> 34.343923 | G5: =IFERROR(D5/E5," ") -> 1362.3135 | H5: =30032.36324-30-64.4-68.5-68.5-47.6-13.5-12.32-12 -> 29715.543 | I5: =IFERROR(H5/I$1,0)*10^6 -> 1178720.5 | J5: =893.2+22 -> 915.2 | K5: =IFERROR(H5/J5,0) -> 32.468907 | L5: =IFERROR(I5/J5," ") -> 1287.9376 | M5: =54923.0063906-2.9-9.7-152.9-356.3-211.356-47.6-97.8-93.6-93.6-52.5-47.6-64.3-4 -> 53688.85 | N5: =IFERROR(M5/N$1,0)*10^6 -> 2138146.2 | O5: 1804.5493 | P5: =IFERROR(M5/O5,0) -> 29.751944 | Q5: =IFERROR(N5/O5," ") -> 1184.8644 | R5: =5394.80885-6.16-6.616-66-26 -> 5290.0329 | S5: =IFERROR(R5/S$1,0)*10^6 -> 212365.83 | T5: =286-11 -> 275 | U5: =IFERROR(R5/T5,0) -> 19.236483 | V5: =IFERROR(S5/T5," ") -> 772.23939 | W5: =25525.87796-104.412-91-71.8-130.68-16.94-108 -> 25003.046 | X5: =IFERROR(W5/X$1,0)*10^6 -> 992184.36 | Y5: 761.2 | Z5: =IFERROR(W5/Y5,0) -> 32.846881 | AA5: =IFERROR(X5/Y5," ") -> 1303.4477 | AB5: =63591.182204-236.836-59.873-161.539-25.638-22.2-22.2-116-15.4-72 -> 62859.496 | AC5: =IFERROR(AB5/AC$1,0)*10^6 -> 2485547.5 | AD5: 1951.4 | AE5: =IFERROR(AB5/AD5,0) -> 32.212512 | AF5: =IFERROR(AC5/AD5," ") -> 1273.7253 | AG5: =51732.099628-15.4-92.4-435.9-258-258-123.758-13.6-15.9-370-107.369-69.8-44.4-60 -> 49867.573 | AH5: =IFERROR(AG5/AH$1,0)*10^6 -> 1969493.4 | AI5: 1574.1 | AJ5: =IFERROR(AG5/AI5,0) -> 31.680054 | AK5: =IFERROR(AH5/AI5," ") -> 1251.187 | AL5: =29380.1992506+4917.961466-84-9.24-107.36-867-82.8-122.3-13-1.078-57.9-137.493441459-53-108 -> 32654.989 | AM5: =IFERROR(AL5/AM$1,0)*10^6 -> 1284112.8 | AN5: =861.3+150.7 -> 1012 | AO5: =IFERROR(AL5/AN5,0) -> 32.267776 | AP5: =IFERROR(AM5/AN5," ") -> 1268.8862 | AQ5: =36385.4682114-9.24-39.468-253-187.797-222.185590671-36 -> 35637.778 | AR5: =IFERROR(AQ5/AR$1,0)*10^6 -> 1405829.5 | AS5: 1127.5 | AT5: =IFERROR(AQ5/AS5,0) -> 31.607785 | AU5: =IFERROR(AR5/AS5," ") -> 1246.8554 | AV5: =15614.4428-30.3-6.16-45.54-35.36-3.08-11.649-10.56-34.947-89.26 -> 15347.587 | AW5: =IFERROR(AV5/AW$1,0)*10^6 -> 605188.75 | AX5: 473 | AY5: =IFERROR(AV5/AX5,0) -> 32.447329 | AZ5: =IFERROR(AW5/AX5," ") -> 1279.4688 | BA5: =35774.9662072-(65.649+72.5)-253-11.7-(3.5+11.649)-(14+11.788)-88.9 -> 35242.28 | BB5: =IFERROR(BA5/BB$1,0)*10^6 -> 1384221.5 | BC5: 1123.1 | BD5: =IFERROR(BA5/BC5,0) -> 31.379468 | BE5: =IFERROR(BB5/BC5," ") -> 1232.5007 | BF5: =26952.2650408-157.58-(83.4+93.5)-(59.7+29.3)-6.5-13.2-89.9-6.16-42.2 -> 26370.825 | BG5: =IFERROR(BF5/BG$1,0)*10^6 -> 1039039.6 | BH5: 850.3 | BI5: =IFERROR(BF5/BH5,0) -> 31.013554 | BJ5: =IFERROR(BG5/BH5," ") -> 1221.9682 | BK5: =9646.606568+23004.175304-3.836-(63.7+72.2)-21.7-252.339-11.798-(216.081+259)-6.16-(3.08+11.75)-(30.668+23.576) -> 31674.894 | BL5: =IFERROR(BK5/BL$1,0)*10^6 -> 1236817.4 | BM5: =294.7+720.5 -> 1015.2 | BN5: =IFERROR(BK5/BM5,0) -> 31.200644 | BO5: =IFERROR(BL5/BM5," ") -> 1218.2993 | BP5: =26654.9547-47.66-146.16-46-(76.67+58.94)-32.4 -> 26247.125 | BQ5: =IFERROR(BP5/BQ$1,0)*10^6 -> 1023279.7 | BR5: 805.2 | BS5: =IFERROR(BP5/BR5,0) -> 32.597025 | BT5: =IFERROR(BQ5/BR5," ") -> 1270.8392 | BU5: 30408.96 | BV5: =IFERROR(BU5/BV$1,0)*10^6 -> 1182767.8 | BW5: 939.4 | BX5: =IFERROR(BU5/BW5,0) -> 32.37062 | BY5: =IFERROR(BV5/BW5," ") -> 1259.0673 | BZ5: =C5+H5+M5+R5+W5+AB5+AG5+AL5+AQ5+AV5+BA5+BF5+BK5+BP5+BU5 -> 470360.24 | CA5: =D5+I5+N5+S5+X5+AC5+AH5+AM5+AR5+AW5+BB5+BG5+BL5+BQ5+BV5 -> 18548316 | CB5: =E5+J5+O5+T5+Y5+AD5+AI5+AN5+AS5+AX5+BC5+BH5+BM5+BR5+BW5 -> 14928.549 | CC5: =IFERROR(BZ5/CB5," ") -> 31.507431 | CD5: =IFERROR(CA5/CB5," ") -> 1242.4728
A7: 2 | B7: Hạt rHDPE thổi | C7: =1467.6255-18.981-193.017 -> 1255.6275 | D7: =IFERROR(C7/D$1,0)*10^6 -> 49806.724 | E7: =41.25-5.5 -> 35.75 | F7: =IFERROR(C7/E7,0) -> 35.122448 | G7: =IFERROR(D7/E7," ") -> 1393.1951 | H7: 1905.618 | I7: =IFERROR(H7/I$1,0)*10^6 -> 75589.766 | J7: 55 | K7: =IFERROR(H7/J7,0) -> 34.6476 | L7: =IFERROR(I7/J7," ") -> 1374.3594 | M7: 958.606 | N7: =IFERROR(M7/N$1,0)*10^6 -> 38176.264 | O7: 27.5 | P7: =IFERROR(M7/O7,0) -> 34.8584 | Q7: =IFERROR(N7/O7," ") -> 1388.2278 | R7: =1648.8994-18.981481 -> 1629.9179 | S7: =IFERROR(R7/S$1,0)*10^6 -> 65432.273 | T7: 46.6 | U7: =IFERROR(R7/T7,0) -> 34.976779 | V7: =IFERROR(S7/T7," ") -> 1404.126 | W7: 475.552 | X7: =IFERROR(W7/X$1,0)*10^6 -> 18871.111 | Y7: 13.75 | Z7: =IFERROR(W7/Y7,0) -> 34.5856 | AA7: =IFERROR(X7/Y7," ") -> 1372.4444 | AB7: 1183.465 | AC7: =IFERROR(AB7/AC$1,0)*10^6 -> 46795.769 | AD7: 34 | AE7: =IFERROR(AB7/AD7,0) -> 34.807794 | AF7: =IFERROR(AC7/AD7," ") -> 1376.3461 | AG7: =3247.703-19.981 -> 3227.722 | AH7: =IFERROR(AG7/AH$1,0)*10^6 -> 127477.17 | AI7: 91.75 | AJ7: =IFERROR(AG7/AI7,0) -> 35.179531 | AK7: =IFERROR(AH7/AI7," ") -> 1389.397 | AL7: 2326.775 | AM7: =IFERROR(AL7/AM$1,0)*10^6 -> 91497.247 | AN7: 71.5 | AO7: =IFERROR(AL7/AN7,0) -> 32.542308 | AP7: =IFERROR(AM7/AN7," ") -> 1279.6818 | AQ7: 1536.915 | AR7: =IFERROR(AQ7/AR$1,0)*10^6 -> 60627.811 | AS7: 44.1 | AT7: =IFERROR(AQ7/AS7,0) -> 34.85068 | AU7: =IFERROR(AR7/AS7," ") -> 1374.7803 | AV7: 2286.3921 | AW7: =IFERROR(AV7/AW$1,0)*10^6 -> 90157.417 | AX7: 70.425 | AY7: =IFERROR(AV7/AX7,0) -> 32.465632 | AZ7: =IFERROR(AW7/AX7," ") -> 1280.1905 | BA7: 3080.044 | BB7: =IFERROR(BA7/BB$1,0)*10^6 -> 120975.81 | BC7: 88 | BD7: =IFERROR(BA7/BC7,0) -> 35.0005 | BE7: =IFERROR(BB7/BC7," ") -> 1374.7251 | BF7: =5809.3915-241.5-19.444 -> 5548.4475 | BG7: =IFERROR(BF7/BG$1,0)*10^6 -> 218614.95 | BH7: 157.25 | BI7: =IFERROR(BF7/BH7,0) -> 35.284245 | BJ7: =IFERROR(BG7/BH7," ") -> 1390.2382 | BK7: =1440.901-19.4 -> 1421.501 | BL7: =IFERROR(BK7/BL$1,0)*10^6 -> 55505.701 | BM7: 46.75 | BN7: =IFERROR(BK7/BM7,0) -> 30.406439 | BO7: =IFERROR(BL7/BM7," ") -> 1187.2877 | BP7: 747.703 | BQ7: =IFERROR(BP7/BQ$1,0)*10^6 -> 29150.214 | BR7: 22 | BS7: =IFERROR(BP7/BR7,0) -> 33.9865 | BT7: =IFERROR(BQ7/BR7," ") -> 1325.0097 | BU7: 1109.1985 | BV7: =IFERROR(BU7/BV$1,0)*10^6 -> 43142.688 | BW7: 34.5 | BX7: =IFERROR(BU7/BW7,0) -> 32.150681 | BY7: =IFERROR(BV7/BW7," ") -> 1250.5127 | BZ7: =C7+H7+M7+R7+W7+AB7+AG7+AL7+AQ7+AV7+BA7+BF7+BK7+BP7+BU7 -> 28693.485 | CA7: =D7+I7+N7+S7+X7+AC7+AH7+AM7+AR7+AW7+BB7+BG7+BL7+BQ7+BV7 -> 1131820.9 | CB7: =E7+J7+O7+T7+Y7+AD7+AI7+AN7+AS7+AX7+BC7+BH7+BM7+BR7+BW7 -> 838.875 | CC7: =IFERROR(BZ7/CB7," ") -> 34.20472 | CD7: =IFERROR(CA7/CB7," ") -> 1349.2128
A9: 3 | B9: Hạt rHDPE ép | C9: 80.445 | D9: =IFERROR(C9/D$1,0)*10^6 -> 3190.9956 | E9: 3 | F9: =IFERROR(C9/E9,0) -> 26.815 | G9: =IFERROR(D9/E9," ") -> 1063.6652 | H9: 122.474 | I9: =IFERROR(H9/I$1,0)*10^6 -> 4858.1515 | J9: 5.5 | K9: =IFERROR(H9/J9,0) -> 22.268 | L9: =IFERROR(I9/J9," ") -> 883.30028 | N9: =IFERROR(M9/N$1,0)*10^6 -> 0 | P9: =IFERROR(M9/O9,0) -> 0 | Q9: =IFERROR(N9/O9," ") | S9: =IFERROR(R9/S$1,0)*10^6 -> 0 | U9: =IFERROR(R9/T9,0) -> 0 | V9: =IFERROR(S9/T9," ") | X9: =IFERROR(W9/X$1,0)*10^6 -> 0 | Z9: =IFERROR(W9/Y9,0) -> 0 | AA9: =IFERROR(X9/Y9," ") | AB9: 131.3975 | AC9: =IFERROR(AB9/AC$1,0)*10^6 -> 5195.6307 | AD9: 6.5 | AE9: =IFERROR(AB9/AD9,0) -> 20.215 | AF9: =IFERROR(AC9/AD9," ") -> 799.3278 | AG9: 1362.5625 | AH9: =IFERROR(AG9/AH$1,0)*10^6 -> 53813.685 | AI9: 50 | AJ9: =IFERROR(AG9/AI9,0) -> 27.25125 | AK9: =IFERROR(AH9/AI9," ") -> 1076.2737 | AL9: 555.9125 | AM9: =IFERROR(AL9/AM$1,0)*10^6 -> 21860.499 | AN9: 27.5 | AO9: =IFERROR(AL9/AN9,0) -> 20.215 | AP9: =IFERROR(AM9/AN9," ") -> 794.92725 | AR9: =IFERROR(AQ9/AR$1,0)*10^6 -> 0 | AT9: =IFERROR(AQ9/AS9,0) -> 0 | AU9: =IFERROR(AR9/AS9," ") | AV9: 134.875 | AW9: =IFERROR(AV9/AW$1,0)*10^6 -> 5318.4148 | AX9: 5 | AY9: =IFERROR(AV9/AX9,0) -> 26.975 | AZ9: =IFERROR(AW9/AX9," ") -> 1063.683 | BB9: =IFERROR(BA9/BB$1,0)*10^6 -> 0 | BD9: =IFERROR(BA9/BC9,0) -> 0 | BE9: =IFERROR(BB9/BC9," ") | BF9: 569.6075 | BG9: =IFERROR(BF9/BG$1,0)*10^6 -> 22443.164 | BH9: 27.5 | BI9: =IFERROR(BF9/BH9,0) -> 20.713 | BJ9: =IFERROR(BG9/BH9," ") -> 816.11505 | BL9: =IFERROR(BK9/BL$1,0)*10^6 -> 0 | BN9: =IFERROR(BK9/BM9,0) -> 0 | BO9: =IFERROR(BL9/BM9," ") | BP9: =104.808-5.5 -> 99.308 | BQ9: =IFERROR(BP9/BQ$1,0)*10^6 -> 3871.6569 | BR9: 5.5 | BS9: =IFERROR(BP9/BR9,0) -> 18.056 | BT9: =IFERROR(BQ9/BR9," ") -> 703.93762 | BU9: 606.312 | BV9: =IFERROR(BU9/BV$1,0)*10^6 -> 23582.73 | BW9: 31 | BX9: =IFERROR(BU9/BW9,0) -> 19.558452 | BY9: =IFERROR(BV9/BW9," ") -> 760.73324 | BZ9: =C9+H9+M9+R9+W9+AB9+AG9+AL9+AQ9+AV9+BA9+BF9+BK9+BP9+BU9 -> 3662.894 | CA9: =D9+I9+N9+S9+X9+AC9+AH9+AM9+AR9+AW9+BB9+BG9+BL9+BQ9+BV9 -> 144134.93 | CB9: =E9+J9+O9+T9+Y9+AD9+AI9+AN9+AS9+AX9+BC9+BH9+BM9+BR9+BW9 -> 161.5 | CC9: =IFERROR(BZ9/CB9," ") -> 22.680458 | CD9: =IFERROR(CA9/CB9," ") -> 892.47634
A11: 4 | B11: Hạt rPP | D11: =IFERROR(C11/D$1,0)*10^6 -> 0 | F11: =IFERROR(C11/E11,0) -> 0 | G11: =IFERROR(D11/E11," ") | I11: =IFERROR(H11/I$1,0)*10^6 -> 0 | K11: =IFERROR(H11/J11,0) -> 0 | L11: =IFERROR(I11/J11," ") | N11: =IFERROR(M11/N$1,0)*10^6 -> 0 | P11: =IFERROR(M11/O11,0) -> 0 | Q11: =IFERROR(N11/O11," ") | S11: =IFERROR(R11/S$1,0)*10^6 -> 0 | U11: =IFERROR(R11/T11,0) -> 0 | V11: =IFERROR(S11/T11," ") | X11: =IFERROR(W11/X$1,0)*10^6 -> 0 | Z11: =IFERROR(W11/Y11,0) -> 0 | AA11: =IFERROR(X11/Y11," ") | AC11: =IFERROR(AB11/AC$1,0)*10^6 -> 0 | AE11: =IFERROR(AB11/AD11,0) -> 0 | AF11: =IFERROR(AC11/AD11," ") | AG11: 14.6015 | AH11: =IFERROR(AG11/AH$1,0)*10^6 -> 576.67852 | AI11: 0.5 | AJ11: =IFERROR(AG11/AI11,0) -> 29.203 | AK11: =IFERROR(AH11/AI11," ") -> 1153.357 | AL11: 3.81195 | AM11: =IFERROR(AL11/AM$1,0)*10^6 -> 149.89972 | AN11: 0.175 | AO11: =IFERROR(AL11/AN11,0) -> 21.782571 | AP11: =IFERROR(AM11/AN11," ") -> 856.56986 | AR11: =IFERROR(AQ11/AR$1,0)*10^6 -> 0 | AT11: =IFERROR(AQ11/AS11,0) -> 0 | AU11: =IFERROR(AR11/AS11," ") | AW11: =IFERROR(AV11/AW$1,0)*10^6 -> 0 | AY11: =IFERROR(AV11/AX11,0) -> 0 | AZ11: =IFERROR(AW11/AX11," ") | BA11: =871.7336-15 -> 856.7336 | BB11: =IFERROR(BA11/BB$1,0)*10^6 -> 33650.181 | BC11: 35 | BD11: =IFERROR(BA11/BC11,0) -> 24.478103 | BE11: =IFERROR(BB11/BC11," ") -> 961.43373 | BF11: 130.18918 | BG11: =IFERROR(BF11/BG$1,0)*10^6 -> 5129.5973 | BH11: 6.675 | BI11: =IFERROR(BF11/BH11,0) -> 19.503997 | BJ11: =IFERROR(BG11/BH11," ") -> 768.479 | BK11: =116.664+1.9062 -> 118.5702 | BL11: =IFERROR(BK11/BL$1,0)*10^6 -> 4629.8399 | BM11: =6+0.1 -> 6.1 | BN11: =IFERROR(BK11/BM11,0) -> 19.437738 | BO11: =IFERROR(BL11/BM11," ") -> 758.99015 | BQ11: =IFERROR(BP11/BQ$1,0)*10^6 -> 0 | BS11: =IFERROR(BP11/BR11,0) -> 0 | BT11: =IFERROR(BQ11/BR11," ") | BU11: 123.9555 | BV11: =IFERROR(BU11/BV$1,0)*10^6 -> 4821.2952 | BW11: 6.375 | BX11: =IFERROR(BU11/BW11,0) -> 19.444 | BY11: =IFERROR(BV11/BW11," ") -> 756.2816 | BZ11: =C11+H11+M11+R11+W11+AB11+AG11+AL11+AQ11+AV11+BA11+BF11+BK11+BP11+BU11 -> 1247.8619 | CA11: =D11+I11+N11+S11+X11+AC11+AH11+AM11+AR11+AW11+BB11+BG11+BL11+BQ11+BV11 -> 48957.491 | CB11: =E11+J11+O11+T11+Y11+AD11+AI11+AN11+AS11+AX11+BC11+BH11+BM11+BR11+BW11 -> 54.825 | CC11: =IFERROR(BZ11/CB11," ") -> 22.76082 | CD11: =IFERROR(CA11/CB11," ") -> 892.9775
A13: 5 | B13: Vảy rHDPE ép | D13: =IFERROR(C13/D$1,0)*10^6 -> 0 | F13: =IFERROR(C13/E13,0) -> 0 | G13: =IFERROR(D13/E13," ") | I13: =IFERROR(H13/I$1,0)*10^6 -> 0 | K13: =IFERROR(H13/J13,0) -> 0 | L13: =IFERROR(I13/J13," ") | M13: 11.80575 | N13: =IFERROR(M13/N$1,0)*10^6 -> 470.16129 | O13: 0.75 | P13: =IFERROR(M13/O13,0) -> 15.741 | Q13: =IFERROR(N13/O13," ") -> 626.88172 | R13: 106.25175 | S13: =IFERROR(R13/S$1,0)*10^6 -> 4265.4255 | T13: 6.75 | U13: =IFERROR(R13/T13,0) -> 15.741 | V13: =IFERROR(S13/T13," ") -> 631.91489 | X13: =IFERROR(W13/X$1,0)*10^6 -> 0 | Z13: =IFERROR(W13/Y13,0) -> 0 | AA13: =IFERROR(X13/Y13," ") | AB13: 47.223 | AC13: =IFERROR(AB13/AC$1,0)*10^6 -> 1867.2598 | AD13: 3 | AE13: =IFERROR(AB13/AD13,0) -> 15.741 | AF13: =IFERROR(AC13/AD13," ") -> 622.41993 | AG13: 123.26625 | AH13: =IFERROR(AG13/AH$1,0)*10^6 -> 4868.3353 | AI13: 7.5 | AJ13: =IFERROR(AG13/AI13,0) -> 16.4355 | AK13: =IFERROR(AH13/AI13," ") -> 649.11137 | AL13: =175.419+35.417 -> 210.836 | AM13: =IFERROR(AL13/AM$1,0)*10^6 -> 8290.8376 | AN13: =11.25+2.25 -> 13.5 | AO13: =IFERROR(AL13/AN13,0) -> 15.617481 | AP13: =IFERROR(AM13/AN13," ") -> 614.13612 | AQ13: 539.865 | AR13: =IFERROR(AQ13/AR$1,0)*10^6 -> 21296.45 | AS13: 34.5 | AT13: =IFERROR(AQ13/AS13,0) -> 15.648261 | AU13: =IFERROR(AR13/AS13," ") -> 617.2884 | AV13: 82.64025 | AW13: =IFERROR(AV13/AW$1,0)*10^6 -> 3258.6849 | AX13: 5.25 | AY13: =IFERROR(AV13/AX13,0) -> 15.741 | AZ13: =IFERROR(AW13/AX13," ") -> 620.70189 | BA13: 77.33785 | BB13: =IFERROR(BA13/BB$1,0)*10^6 -> 3037.6218 | BC13: 6.3 | BD13: =IFERROR(BA13/BC13,0) -> 12.275849 | BE13: =IFERROR(BB13/BC13," ") -> 482.16218 | BF13: 292 | BG13: =IFERROR(BF13/BG$1,0)*10^6 -> 11505.122 | BH13: 20 | BI13: =IFERROR(BF13/BH13,0) -> 14.6 | BJ13: =IFERROR(BG13/BH13," ") -> 575.25611 | BK13: =321.534+97.071 -> 418.605 | BL13: =IFERROR(BK13/BL$1,0)*10^6 -> 16345.373 | BM13: =19.5+6.175 -> 25.675 | BN13: =IFERROR(BK13/BM13,0) -> 16.303992 | BO13: =IFERROR(BL13/BM13," ") -> 636.62601 | BP13: 151.242 | BQ13: =IFERROR(BP13/BQ$1,0)*10^6 -> 5896.3743 | BR13: 9.05 | BS13: =IFERROR(BP13/BR13,0) -> 16.711823 | BT13: =IFERROR(BQ13/BR13," ") -> 651.53307 | BU13: 104.598 | BV13: =IFERROR(BU13/BV$1,0)*10^6 -> 4068.3781 | BW13: 6.75 | BX13: =IFERROR(BU13/BW13,0) -> 15.496 | BY13: =IFERROR(BV13/BW13," ") -> 602.72268 | BZ13: =C13+H13+M13+R13+W13+AB13+AG13+AL13+AQ13+AV13+BA13+BF13+BK13+BP13+BU13 -> 2165.6708 | CA13: =D13+I13+N13+S13+X13+AC13+AH13+AM13+AR13+AW13+BB13+BG13+BL13+BQ13+BV13 -> 85170.023 | CB13: =E13+J13+O13+T13+Y13+AD13+AI13+AN13+AS13+AX13+BC13+BH13+BM13+BR13+BW13 -> 139.025 | CC13: =IFERROR(BZ13/CB13," ") -> 15.577564 | CD13: =IFERROR(CA13/CB13," ") -> 612.6238
A15: 6 | B15: Vảy PP | D15: =IFERROR(C15/D$1,0)*10^6 -> 0 | F15: =IFERROR(C15/E15,0) -> 0 | G15: =IFERROR(D15/E15," ") | I15: =IFERROR(H15/I$1,0)*10^6 -> 0 | K15: =IFERROR(H15/J15,0) -> 0 | L15: =IFERROR(I15/J15," ") | N15: =IFERROR(M15/N$1,0)*10^6 -> 0 | P15: =IFERROR(M15/O15,0) -> 0 | Q15: =IFERROR(N15/O15," ") | S15: =IFERROR(R15/S$1,0)*10^6 -> 0 | U15: =IFERROR(R15/T15,0) -> 0 | V15: =IFERROR(S15/T15," ") | X15: =IFERROR(W15/X$1,0)*10^6 -> 0 | Z15: =IFERROR(W15/Y15,0) -> 0 | AA15: =IFERROR(X15/Y15," ") | AC15: =IFERROR(AB15/AC$1,0)*10^6 -> 0 | AE15: =IFERROR(AB15/AD15,0) -> 0 | AF15: =IFERROR(AC15/AD15," ") | AH15: =IFERROR(AG15/AH$1,0)*10^6 -> 0 | AJ15: =IFERROR(AG15/AI15,0) -> 0 | AK15: =IFERROR(AH15/AI15," ") | AM15: =IFERROR(AL15/AM$1,0)*10^6 -> 0 | AO15: =IFERROR(AL15/AN15,0) -> 0 | AP15: =IFERROR(AM15/AN15," ") | AR15: =IFERROR(AQ15/AR$1,0)*10^6 -> 0 | AT15: =IFERROR(AQ15/AS15,0) -> 0 | AU15: =IFERROR(AR15/AS15," ") | AW15: =IFERROR(AV15/AW$1,0)*10^6 -> 0 | AY15: =IFERROR(AV15/AX15,0) -> 0 | AZ15: =IFERROR(AW15/AX15," ") | BB15: =IFERROR(BA15/BB$1,0)*10^6 -> 0 | BD15: =IFERROR(BA15/BC15,0) -> 0 | BE15: =IFERROR(BB15/BC15," ") | BG15: =IFERROR(BF15/BG$1,0)*10^6 -> 0 | BI15: =IFERROR(BF15/BH15,0) -> 0 | BJ15: =IFERROR(BG15/BH15," ") | BL15: =IFERROR(BK15/BL$1,0)*10^6 -> 0 | BN15: =IFERROR(BK15/BM15,0) -> 0 | BO15: =IFERROR(BL15/BM15," ") | BQ15: =IFERROR(BP15/BQ$1,0)*10^6 -> 0 | BS15: =IFERROR(BP15/BR15,0) -> 0 | BT15: =IFERROR(BQ15/BR15," ") | BV15: =IFERROR(BU15/BV$1,0)*10^6 -> 0 | BX15: =IFERROR(BU15/BW15,0) -> 0 | BY15: =IFERROR(BV15/BW15," ") | BZ15: =C15+H15+M15+R15+W15+AB15+AG15+AL15+AQ15+AV15+BA15+BF15+BK15+BP15+BU15 -> 0 | CA15: =D15+I15+N15+S15+X15+AC15+AH15+AM15+AR15+AW15+BB15+BG15+BL15+BQ15+BV15 -> 0 | CB15: =E15+J15+O15+T15+Y15+AD15+AI15+AN15+AS15+AX15+BC15+BH15+BM15+BR15+BW15 -> 0 | CC15: =IFERROR(BZ15/CB15," ") | CD15: =IFERROR(CA15/CB15," ")
A17: 7 | B17: Hạt Xơ sợi | D17: =IFERROR(C17/D$1,0)*10^6 -> 0 | F17: =IFERROR(C17/E17,0) -> 0 | G17: =IFERROR(D17/E17," ") | I17: =IFERROR(H17/I$1,0)*10^6 -> 0 | K17: =IFERROR(H17/J17,0) -> 0 | L17: =IFERROR(I17/J17," ") | M17: 209 | N17: =IFERROR(M17/N$1,0)*10^6 -> 8323.3771 | O17: 11 | P17: =IFERROR(M17/O17,0) -> 19 | Q17: =IFERROR(N17/O17," ") -> 756.67065 | S17: =IFERROR(R17/S$1,0)*10^6 -> 0 | U17: =IFERROR(R17/T17,0) -> 0 | V17: =IFERROR(S17/T17," ") | W17: 105.05 | X17: =IFERROR(W17/X$1,0)*10^6 -> 4168.6508 | Y17: 5.5 | Z17: =IFERROR(W17/Y17,0) -> 19.1 | AA17: =IFERROR(X17/Y17," ") -> 757.93651 | AB17: 209 | AC17: =IFERROR(AB17/AC$1,0)*10^6 -> 8264.136 | AD17: 11 | AE17: =IFERROR(AB17/AD17,0) -> 19 | AF17: =IFERROR(AC17/AD17," ") -> 751.28509 | AH17: =IFERROR(AG17/AH$1,0)*10^6 -> 0 | AJ17: =IFERROR(AG17/AI17,0) -> 0 | AK17: =IFERROR(AH17/AI17," ") | AL17: =209-82.64025 -> 126.35975 | AM17: =IFERROR(AL17/AM$1,0)*10^6 -> 4968.9245 | AN17: =11-5.25 -> 5.75 | AO17: =IFERROR(AL17/AN17,0) -> 21.975609 | AP17: =IFERROR(AM17/AN17," ") -> 864.16078 | AR17: =IFERROR(AQ17/AR$1,0)*10^6 -> 0 | AT17: =IFERROR(AQ17/AS17,0) -> 0 | AU17: =IFERROR(AR17/AS17," ") | AV17: 209 | AW17: =IFERROR(AV17/AW$1,0)*10^6 -> 8241.3249 | AX17: 11 | AY17: =IFERROR(AV17/AX17,0) -> 19 | AZ17: =IFERROR(AW17/AX17," ") -> 749.21136 | BB17: =IFERROR(BA17/BB$1,0)*10^6 -> 0 | BD17: =IFERROR(BA17/BC17,0) -> 0 | BE17: =IFERROR(BB17/BC17," ") | BG17: =IFERROR(BF17/BG$1,0)*10^6 -> 0 | BI17: =IFERROR(BF17/BH17,0) -> 0 | BJ17: =IFERROR(BG17/BH17," ") | BK17: 209 | BL17: =IFERROR(BK17/BL$1,0)*10^6 -> 8160.8747 | BM17: 11 | BN17: =IFERROR(BK17/BM17,0) -> 19 | BO17: =IFERROR(BL17/BM17," ") -> 741.8977 | BQ17: =IFERROR(BP17/BQ$1,0)*10^6 -> 0 | BS17: =IFERROR(BP17/BR17,0) -> 0 | BT17: =IFERROR(BQ17/BR17," ") | BV17: =IFERROR(BU17/BV$1,0)*10^6 -> 0 | BX17: =IFERROR(BU17/BW17,0) -> 0 | BY17: =IFERROR(BV17/BW17," ") | BZ17: =C17+H17+M17+R17+W17+AB17+AG17+AL17+AQ17+AV17+BA17+BF17+BK17+BP17+BU17 -> 1067.4097 | CA17: =D17+I17+N17+S17+X17+AC17+AH17+AM17+AR17+AW17+BB17+BG17+BL17+BQ17+BV17 -> 42127.288 | CB17: =E17+J17+O17+T17+Y17+AD17+AI17+AN17+AS17+AX17+BC17+BH17+BM17+BR17+BW17 -> 55.25 | CC17: =IFERROR(BZ17/CB17," ") -> 19.319633 | CD17: =IFERROR(CA17/CB17," ") -> 762.48485
A19: 8 | B19: Hạt LDPE | D19: =IFERROR(C19/D$1,0)*10^6 -> 0 | F19: =IFERROR(C19/E19,0) -> 0 | G19: =IFERROR(D19/E19," ") | I19: =IFERROR(H19/I$1,0)*10^6 -> 0 | K19: =IFERROR(H19/J19,0) -> 0 | L19: =IFERROR(I19/J19," ") | N19: =IFERROR(M19/N$1,0)*10^6 -> 0 | P19: =IFERROR(M19/O19,0) -> 0 | Q19: =IFERROR(N19/O19," ") | S19: =IFERROR(R19/S$1,0)*10^6 -> 0 | U19: =IFERROR(R19/T19,0) -> 0 | V19: =IFERROR(S19/T19," ") | X19: =IFERROR(W19/X$1,0)*10^6 -> 0 | Z19: =IFERROR(W19/Y19,0) -> 0 | AA19: =IFERROR(X19/Y19," ") | AC19: =IFERROR(AB19/AC$1,0)*10^6 -> 0 | AE19: =IFERROR(AB19/AD19,0) -> 0 | AF19: =IFERROR(AC19/AD19," ") | AH19: =IFERROR(AG19/AH$1,0)*10^6 -> 0 | AJ19: =IFERROR(AG19/AI19,0) -> 0 | AK19: =IFERROR(AH19/AI19," ") | AM19: =IFERROR(AL19/AM$1,0)*10^6 -> 0 | AO19: =IFERROR(AL19/AN19,0) -> 0 | AP19: =IFERROR(AM19/AN19," ") | AR19: =IFERROR(AQ19/AR$1,0)*10^6 -> 0 | AT19: =IFERROR(AQ19/AS19,0) -> 0 | AU19: =IFERROR(AR19/AS19," ") | AW19: =IFERROR(AV19/AW$1,0)*10^6 -> 0 | AY19: =IFERROR(AV19/AX19,0) -> 0 | AZ19: =IFERROR(AW19/AX19," ") | BB19: =IFERROR(BA19/BB$1,0)*10^6 -> 0 | BD19: =IFERROR(BA19/BC19,0) -> 0 | BE19: =IFERROR(BB19/BC19," ") | BG19: =IFERROR(BF19/BG$1,0)*10^6 -> 0 | BI19: =IFERROR(BF19/BH19,0) -> 0 | BJ19: =IFERROR(BG19/BH19," ") | BL19: =IFERROR(BK19/BL$1,0)*10^6 -> 0 | BN19: =IFERROR(BK19/BM19,0) -> 0 | BO19: =IFERROR(BL19/BM19," ") | BQ19: =IFERROR(BP19/BQ$1,0)*10^6 -> 0 | BS19: =IFERROR(BP19/BR19,0) -> 0 | BT19: =IFERROR(BQ19/BR19," ") | BV19: =IFERROR(BU19/BV$1,0)*10^6 -> 0 | BX19: =IFERROR(BU19/BW19,0) -> 0 | BY19: =IFERROR(BV19/BW19," ") | BZ19: =C19+H19+M19+R19+W19+AB19+AG19+AL19+AQ19 -> 0 | CA19: =D19+I19+N19+S19+X19+AC19+AH19+AM19+AR19 -> 0 | CB19: =E19+J19+O19+T19+Y19+AD19+AI19+AN19+AS19 -> 0 | CC19: =IFERROR(BZ19/CB19," ") | CD19: =IFERROR(CA19/CB19," ")
B21: Tổng DT (rPET + rHDPE + rPP+ xơ sợi) | C21: =C17+C15+C13+C11+C9+C7+C5+C19 -> 11687.331 | D21: =D17+D15+D13+D11+D9+D7+D5+D19 -> 463599 | E21: =E17+E15+E13+E11+E9+E7+E5+E19 -> 340.15 | F21: =C21/E21 -> 34.359344 | G21: =IFERROR(D21/E21," ") -> 1362.9252 | H21: =H17+H15+H13+H11+H9+H7+H5+H19 -> 31743.635 | I21: =I17+I15+I13+I11+I9+I7+I5+I19 -> 1259168.4 | J21: =J17+J15+J13+J11+J9+J7+J5+J19 -> 975.7 | K21: =H21/J21 -> 32.534217 | L21: =IFERROR(I21/J21," ") -> 1290.5282 | M21: =M17+M15+M13+M11+M9+M7+M5+M19 -> 54868.262 | N21: =N17+N15+N13+N11+N9+N7+N5+N19 -> 2185116 | O21: =O17+O15+O13+O11+O9+O7+O5+O19 -> 1843.7993 | P21: =M21/O21 -> 29.758262 | Q21: =IFERROR(N21/O21," ") -> 1185.116 | R21: =R17+R15+R13+R11+R9+R7+R5+R19 -> 7026.2025 | S21: =S17+S15+S13+S11+S9+S7+S5+S19 -> 282063.53 | T21: =T17+T15+T13+T11+T9+T7+T5+T19 -> 328.35 | U21: =R21/T21 -> 21.398515 | V21: =IFERROR(S21/T21," ") -> 859.03313 | W21: =W17+W15+W13+W11+W9+W7+W5+W19 -> 25583.648 | X21: =X17+X15+X13+X11+X9+X7+X5+X19 -> 1015224.1 | Y21: =Y17+Y15+Y13+Y11+Y9+Y7+Y5+Y19 -> 780.45 | Z21: =W21/Y21 -> 32.780637 | AA21: =IFERROR(X21/Y21," ") -> 1300.8189 | AB21: =AB17+AB15+AB13+AB11+AB9+AB7+AB5+AB19 -> 64430.582 | AC21: =AC17+AC15+AC13+AC11+AC9+AC7+AC5+AC19 -> 2547670.3 | AD21: =AD17+AD15+AD13+AD11+AD9+AD7+AD5+AD19 -> 2005.9 | AE21: =AB21/AD21 -> 32.120535 | AF21: =IFERROR(AC21/AD21," ") -> 1270.0884 | AG21: =AG17+AG15+AG13+AG11+AG9+AG7+AG5+AG19 -> 54595.725 | AH21: =AH17+AH15+AH13+AH11+AH9+AH7+AH5+AH19 -> 2156229.3 | AI21: =AI17+AI15+AI13+AI11+AI9+AI7+AI5+AI19 -> 1723.85 | AJ21: =AG21/AI21 -> 31.670809 | AK21: =IFERROR(AH21/AI21," ") -> 1250.8219 | AL21: =AL17+AL15+AL13+AL11+AL9+AL7+AL5+AL19 -> 35878.684 | AM21: =AM17+AM15+AM13+AM11+AM9+AM7+AM5+AM19 -> 1410880.2 | AN21: =AN17+AN15+AN13+AN11+AN9+AN7+AN5+AN19 -> 1130.425 | AO21: =AL21/AN21 -> 31.739111 | AP21: =IFERROR(AM21/AN21," ") -> 1248.0972 | AQ21: =AQ17+AQ15+AQ13+AQ11+AQ9+AQ7+AQ5+AQ19 -> 37714.558 | AR21: =AR17+AR15+AR13+AR11+AR9+AR7+AR5+AR19 -> 1487753.8 | AS21: =AS17+AS15+AS13+AS11+AS9+AS7+AS5+AS19 -> 1206.1 | AT21: =AQ21/AS21 -> 31.269843 | AU21: =IFERROR(AR21/AS21," ") -> 1233.5244 | AV21: =AV17+AV15+AV13+AV11+AV9+AV7+AV5+AV19 -> 18060.494 | AW21: =AW17+AW15+AW13+AW11+AW9+AW7+AW5+AW19 -> 712164.6 | AX21: =AX17+AX15+AX13+AX11+AX9+AX7+AX5+AX19 -> 564.675 | AY21: =AV21/AX21 -> 31.983874 | AZ21: =IFERROR(AW21/AX21," ") -> 1261.1938 | BA21: =BA17+BA15+BA13+BA11+BA9+BA7+BA5+BA19 -> 39256.396 | BB21: =BB17+BB15+BB13+BB11+BB9+BB7+BB5+BB19 -> 1541885.1 | BC21: =BC17+BC15+BC13+BC11+BC9+BC7+BC5+BC19 -> 1252.4 | BD21: =BA21/BC21 -> 31.344934 | BE21: =IFERROR(BB21/BC21," ") -> 1231.1443 | BF21: =BF17+BF15+BF13+BF11+BF9+BF7+BF5+BF19 -> 32911.069 | BG21: =BG17+BG15+BG13+BG11+BG9+BG7+BG5+BG19 -> 1296732.4 | BH21: =BH17+BH15+BH13+BH11+BH9+BH7+BH5+BH19 -> 1061.725 | BI21: =BF21/BH21 -> 30.997734 | BJ21: =IFERROR(BG21/BH21," ") -> 1221.3449 | BK21: =BK17+BK15+BK13+BK11+BK9+BK7+BK5+BK19 -> 33842.57 | BL21: =BL17+BL15+BL13+BL11+BL9+BL7+BL5+BL19 -> 1321459.2 | BM21: =BM17+BM15+BM13+BM11+BM9+BM7+BM5+BM19 -> 1104.725 | BN21: =BK21/BM21 -> 30.634384 | BO21: =IFERROR(BL21/BM21," ") -> 1196.1884 | BP21: =BP17+BP15+BP13+BP11+BP9+BP7+BP5+BP19 -> 27245.378 | BQ21: =BQ17+BQ15+BQ13+BQ11+BQ9+BQ7+BQ5+BQ19 -> 1062198 | BR21: =BR17+BR15+BR13+BR11+BR9+BR7+BR5+BR19 -> 841.75 | BS21: =BP21/BR21 -> 32.367541 | BT21: =IFERROR(BQ21/BR21," ") -> 1261.8924 | BU21: =BU17+BU15+BU13+BU11+BU9+BU7+BU5+BU19 -> 32353.024 | BV21: =BV17+BV15+BV13+BV11+BV9+BV7+BV5+BV19 -> 1258382.9 | BW21: =BW17+BW15+BW13+BW11+BW9+BW7+BW5+BW19 -> 1018.025 | BX21: =BU21/BW21 -> 31.780187 | BY21: =IFERROR(BV21/BW21," ") -> 1236.1022 | BZ21: =BZ17+BZ15+BZ13+BZ11+BZ9+BZ7+BZ5+BZ19 -> 507197.56 | CA21: =CA17+CA15+CA13+CA11+CA9+CA7+CA5+CA19 -> 20000527 | CB21: =CB17+CB15+CB13+CB11+CB9+CB7+CB5+CB19 -> 16178.024 | CC21: =BZ21/CB21 -> 31.35102 | CD21: =CA21/CB21 -> 1236.2775

Sheet Weekly
B1: =Daily!B1 -> VN | C1: ) | D1: =Monthly!$P$15/52 -> 1057.6923 | E1: =Monthly!$P$15/52 -> 1057.6923 | F1: =Monthly!$P$15/52 -> 1057.6923 | G1: =Monthly!$P$15/52 -> 1057.6923 | H1: =Monthly!$P$15/52 -> 1057.6923 | I1: =Monthly!$P$15/52 -> 1057.6923 | J1: =Monthly!$P$15/52 -> 1057.6923 | K1: =Monthly!$P$15/52 -> 1057.6923 | ... BC1: =Monthly!$P$15/52 -> 1057.6923 | BD1: =Monthly!P15 -> 55000
B2: =IF(B1="EN","ACTUAL (WEEKLY)"," BÁO CÁO THỰC HIỆN KPI HÀNG TUẦN") -> BÁO CÁO THỰC HIỆN KPI HÀNG TUẦN | D2: =Monthly!$P$8/52 -> 32202.3 | E2: =D2+Monthly!$P$8/52 -> 64404.6 | F2: =E2+Monthly!$P$8/52 -> 96606.901 | G2: =F2+Monthly!$P$8/52 -> 128809.2 | H2: =G2+Monthly!$P$8/52 -> 161011.5 | I2: =H2+Monthly!$P$8/52 -> 193213.8 | J2: =I2+Monthly!$P$8/52 -> 225416.1 | K2: =J2+Monthly!$P$8/52 -> 257618.4 | L2: =K2+Monthly!$P$8/52 -> 289820.7 | ... BC2: =BB2+Monthly!$P$8/52 -> 1674519.6
D3: Week 1 | E3: 2 | F3: 3 | G3: 4 | H3: 5 | I3: 6 | J3: 7 | K3: 8 | L3: 9 | M3: 10 | N3: 11 | O3: 12 | P3: 13 | Q3: 14 | R3: 15 | S3: 16 | T3: 17 | U3: 18 | V3: 19 | W3: 20 | X3: 21 | Y3: 22 | Z3: 23 | AA3: 24 | AB3: 25 | AC3: 26 | AD3: 27 | AE3: 28 | AF3: 29 | AG3: 30 | AH3: 31 | AI3: 32 | AJ3: 33 | AK3: 34 | AL3: 35 | AM3: 36 | AN3: 37 | AO3: 38 | AP3: 39 | AQ3: 40 | AR3: 41 | AS3: 42 | AT3: 43 | AU3: 44 | AV3: 45 | AW3: 46 | AX3: 47 | AY3: 48 | AZ3: 49 | BA3: 50 | BB3: 51 | BC3: Week 52 | BD3: Plan
B4: 1 | C4: Weekly Net sales [mVND]
C5: B2B | D5: 0 | E5: 6665.296 | F5: 12347.897 | G5: 11764.07 | H5: 7335.797 | I5: =10688.79-584.08176 -> 10104.708 | J5: 8008.23 | L5: 7140.271 | M5: 11542.277 | N5: 13035.491 | O5: 27007.339 | P5: 11778.205 | Q5: 22762.336 | R5: 17336.537 | S5: 15762.484 | T5: 17525.481 | U5: 1818.52 | V5: 8088.54 | W5: 14026.48 | X5: 11594.61 | Y5: 15091.348 | Z5: 10072.83 | AA5: 14064.468 | AB5: 6390.32 | AC5: 13882.25 | AD5: =Monthly!J5/5 -> 12103.405 | AE5: =Monthly!J5/5 -> 12103.405 | AF5: =Monthly!J5/5 -> 12103.405 | AG5: =Monthly!J5/5 -> 12103.405 | AH5: =Monthly!J5/5 -> 12103.405 | AI5: =Monthly!K5/4 -> 15926.866 | AJ5: =Monthly!K5/4 -> 15926.866 | AK5: =Monthly!K5/4 -> 15926.866 | AL5: =Monthly!K5/4 -> 15926.866 | AM5: =Monthly!L5/4 -> 13853.196 | AN5: =Monthly!L5/4 -> 13853.196 | AO5: =Monthly!L5/4 -> 13853.196 | AP5: =Monthly!L5/4 -> 13853.196 | AQ5: =Monthly!M5/5 -> 11859.033 | AR5: =Monthly!M5/5 -> 11859.033 | AS5: =Monthly!M5/5 -> 11859.033 | AT5: =Monthly!M5/5 -> 11859.033 | AU5: =Monthly!M5/5 -> 11859.033 | AV5: =Monthly!N5/4 -> 15123.858 | AW5: =Monthly!N5/4 -> 15123.858 | AX5: =Monthly!N5/4 -> 15123.858 | AY5: =Monthly!N5/4 -> 15123.858 | AZ5: =Monthly!O5/4 -> 15483.963 | BA5: =Monthly!O5/4 -> 15483.963 | BB5: =Monthly!O5/4 -> 15483.963 | BC5: =Monthly!O5/4 -> 15483.963 | BD5: 8712.594
C6: Export | D6: 0 | E6: 19483.19 | F6: 18993.54 | G6: 13093.67 | H6: 1901.69 | I6: 21434.21 | J6: 18311.3 | L6: 17117.88 | M6: 20003.51 | N6: 11793.16 | O6: 32591.71 | P6: 15105.31 | Q6: 1265.94 | R6: 9610.82 | S6: 12528.79 | T6: 22919.9 | U6: 22117.44 | V6: 0 | W6: 17700.9 | X6: 22930.48 | Y6: 46715.33 | Z6: 40270.74 | AA6: 0 | AB6: 9563.42 | AC6: 5269.49 | AD6: =Monthly!J6/5 -> 16351.038 | AE6: =Monthly!J6/5 -> 16351.038 | AF6: =Monthly!J6/5 -> 16351.038 | AG6: =Monthly!J6/5 -> 16351.038 | AH6: =Monthly!J6/5 -> 16351.038 | AI6: =Monthly!K6/4 -> 18590.316 | AJ6: =Monthly!K6/4 -> 18590.316 | AK6: =Monthly!K6/4 -> 18590.316 | AL6: =Monthly!K6/4 -> 18590.316 | AM6: =Monthly!L6/4 -> 22412.968 | AN6: =Monthly!L6/4 -> 22412.968 | AO6: =Monthly!L6/4 -> 22412.968 | AP6: =Monthly!L6/4 -> 22412.968 | AQ6: =Monthly!M6/5 -> 15096.337 | AR6: =Monthly!M6/5 -> 15096.337 | AS6: =Monthly!M6/5 -> 15096.337 | AT6: =Monthly!M6/5 -> 15096.337 | AU6: =Monthly!M6/5 -> 15096.337 | AV6: =Monthly!N6/4 -> 20576.094 | AW6: =Monthly!N6/4 -> 20576.094 | AX6: =Monthly!N6/4 -> 20576.094 | AY6: =Monthly!N6/4 -> 20576.094 | AZ6: =Monthly!O6/4 -> 20577.008 | BA6: =Monthly!O6/4 -> 20577.008 | BB6: =Monthly!O6/4 -> 20577.008 | BC6: =Monthly!O6/4 -> 20577.008 | BD6: 8386.53
C7: Other | D7: 0 | E7: 3251.4 | F7: 2663.1 | G7: 4910.25 | H7: 3919.67 | I7: 3263.23 | J7: 5226.87 | L7: 2565.46 | M7: 3982.26 | N7: 4803.52 | O7: 4052.35 | P7: 4422.76 | Q7: 2543.98 | R7: 4247.64 | S7: 4849 | T7: 3253.73 | U7: 1787.88 | V7: 3931.72 | W7: 3051.91 | X7: 4688.6 | Y7: 5662.86 | Z7: 2886.49 | AA7: 2431.52 | AB7: 3568.48 | AC7: 3209.5 | AD7: =Monthly!J7/5 -> 67.045 | AE7: =Monthly!J7/5 -> 67.045 | AF7: =Monthly!J7/5 -> 67.045 | AG7: =Monthly!J7/5 -> 67.045 | AH7: =Monthly!J7/5 -> 67.045 | AI7: =Monthly!K7/4 -> 83.80625 | AJ7: =Monthly!K7/4 -> 83.80625 | AK7: =Monthly!K7/4 -> 83.80625 | AL7: =Monthly!K7/4 -> 83.80625 | AM7: =Monthly!L7/4 -> 83.80625 | AN7: =Monthly!L7/4 -> 83.80625 | AO7: =Monthly!L7/4 -> 83.80625 | AP7: =Monthly!L7/4 -> 83.80625 | AQ7: =Monthly!M7/5 -> 67.045 | AR7: =Monthly!M7/5 -> 67.045 | AS7: =Monthly!M7/5 -> 67.045 | AT7: =Monthly!M7/5 -> 67.045 | AU7: =Monthly!M7/5 -> 67.045 | AV7: =Monthly!N7/4 -> 83.80625 | AW7: =Monthly!N7/4 -> 83.80625 | AX7: =Monthly!N7/4 -> 83.80625 | AY7: =Monthly!N7/4 -> 83.80625 | AZ7: =Monthly!O7/4 -> 83.80625 | BA7: =Monthly!O7/4 -> 83.80625 | BB7: =Monthly!O7/4 -> 83.80625 | BC7: =Monthly!O7/4 -> 83.80625 | BD7: 1943.95
C8: Total: | D8: =SUM(D5:D7) -> 0 | E8: =SUM(E5:E7) -> 29399.886 | F8: =SUM(F5:F7) -> 34004.537 | G8: =SUM(G5:G7) -> 29767.99 | H8: =SUM(H5:H7) -> 13157.157 | I8: =SUM(I5:I7) -> 34802.148 | J8: =SUM(J5:J7) -> 31546.4 | K8: =SUM(K5:K7) -> 0 | ... BC8: =SUM(BC5:BC7) -> 36144.777 | BD8: =SUM(D8:BC8) -> 1634279.9
C9: YTD Net Sales | D9: =D8 -> 0 | E9: =D9+E8 -> 29399.886 | F9: =E9+F8 -> 63404.423 | G9: =F9+G8 -> 93172.413 | H9: =G9+H8 -> 106329.57 | I9: =H9+I8 -> 141131.72 | J9: =I9+J8 -> 172678.12 | K9: =J9+K8 -> 172678.12 | L9: =K9+L8 -> 199501.73 | ... BC9: =BB9+BC8 -> 1634279.9 | BD9: =BC2 -> 1674519.6
C10: =IF(B1="EN","AVG Weekly Plan","BQ kế hoạch hàng tuần") -> BQ kế hoạch hàng tuần | D10: =Monthly!$P$8/52 -> 32202.3 | E10: =Monthly!$P$8/52 -> 32202.3 | F10: =Monthly!$P$8/52 -> 32202.3 | G10: =Monthly!$P$8/52 -> 32202.3 | H10: =Monthly!$P$8/52 -> 32202.3 | I10: =Monthly!$P$8/52 -> 32202.3 | J10: =Monthly!$P$8/52 -> 32202.3 | K10: =Monthly!$P$8/52 -> 32202.3 | ... BC10: =Monthly!$P$8/52 -> 32202.3 | BD10: =BD8/BD9 -> 0.97596938 | BE10: =1-BD10 -> 0.024030617
D11: =D3 -> Week 1 | E11: =E3 -> 2 | F11: =F3 -> 3 | G11: =G3 -> 4 | H11: =H3 -> 5 | I11: =I3 -> 6 | J11: =J3 -> 7 | K11: =K3 -> 8 | ... O11: =O3 -> 12 | P11: 13 | Q11: =Q3 -> 14 | R11: =R3 -> 15 | S11: =S3 -> 16 | T11: =T3 -> 17 | U11: =U3 -> 18 | V11: =V3 -> 19 | W11: =W3 -> 20 | X11: =X3 -> 21 | ... BA11: =BA3 -> 50 | BB11: 51 | BC11: =BC3 -> Week 52
B12: 2 | C12: Weekly Sales Volume [Ton]
C13: =C5 -> B2B | D13: 0 | E13: 207.78 | F13: 378.56 | G13: 349.48 | H13: 230.85 | I13: =387.72-51.706 -> 336.014 | J13: 254.18 | L13: 219.84 | M13: 389.349 | N13: 514.462 | O13: 980.252 | P13: 377.752 | Q13: 776.274 | R13: 590.664 | S13: 517.999 | T13: 578.644 | U13: 57.201 | V13: 251.95 | W13: 448.8 | X13: 365.348 | Y13: 475.202 | Z13: 306.851 | AA13: 432.439 | AB13: 199.09 | AC13: 437.8 | AD13: =Monthly!J12/5 -> 404.3045 | AE13: =Monthly!J12/5 -> 404.3045 | AF13: =Monthly!J12/5 -> 404.3045 | AG13: =Monthly!J12/5 -> 404.3045 | AH13: =Monthly!J12/5 -> 404.3045 | AI13: =Monthly!K12/4 -> 527.21237 | AJ13: =Monthly!K12/4 -> 527.21237 | AK13: =Monthly!K12/4 -> 527.21237 | AL13: =Monthly!K12/4 -> 527.21237 | AM13: =Monthly!L12/4 -> 465.90578 | AN13: =Monthly!L12/4 -> 465.90578 | AO13: =Monthly!L12/4 -> 465.90578 | AP13: =Monthly!L12/4 -> 465.90578 | AQ13: =Monthly!M12/5 -> 393.72526 | AR13: =Monthly!M12/5 -> 393.72526 | AS13: =Monthly!M12/5 -> 393.72526 | AT13: =Monthly!M12/5 -> 393.72526 | AU13: =Monthly!M12/5 -> 393.72526 | AV13: =Monthly!N12/4 -> 507.31078 | AW13: =Monthly!N12/4 -> 507.31078 | AX13: =Monthly!N12/4 -> 507.31078 | AY13: =Monthly!N12/4 -> 507.31078 | AZ13: =Monthly!O12/4 -> 516.6301 | BA13: =Monthly!O12/4 -> 516.6301 | BB13: =Monthly!O12/4 -> 516.6301 | BC13: =Monthly!O12/4 -> 516.6301 | BD13: 277.45
C14: Export | D14: 0 | E14: 660 | F14: 660 | G14: 505 | H14: 68 | I14: 728.35 | J14: 660 | L14: 638 | M14: 681 | N14: 418 | O14: 1142 | P14: 528 | Q14: 44 | R14: 352 | S14: 398 | T14: 770 | U14: 741 | V14: 0 | W14: 572 | X14: 902 | Y14: 1408 | Z14: 1276 | AA14: 0 | AB14: 352 | AC14: 198 | AD14: =Monthly!J13/5 -> 531.38 | AE14: =Monthly!J13/5 -> 531.38 | AF14: =Monthly!J13/5 -> 531.38 | AG14: =Monthly!J13/5 -> 531.38 | AH14: =Monthly!J13/5 -> 531.38 | AI14: =Monthly!K13/4 -> 610.75 | AJ14: =Monthly!K13/4 -> 610.75 | AK14: =Monthly!K13/4 -> 610.75 | AL14: =Monthly!K13/4 -> 610.75 | AM14: =Monthly!L13/4 -> 725 | AN14: =Monthly!L13/4 -> 725 | AO14: =Monthly!L13/4 -> 725 | AP14: =Monthly!L13/4 -> 725 | AQ14: =Monthly!M13/5 -> 497.8 | AR14: =Monthly!M13/5 -> 497.8 | AS14: =Monthly!M13/5 -> 497.8 | AT14: =Monthly!M13/5 -> 497.8 | AU14: =Monthly!M13/5 -> 497.8 | AV14: =Monthly!N13/4 -> 670 | AW14: =Monthly!N13/4 -> 670 | AX14: =Monthly!N13/4 -> 670 | AY14: =Monthly!N13/4 -> 670 | AZ14: =Monthly!O13/4 -> 676.75 | BA14: =Monthly!O13/4 -> 676.75 | BB14: =Monthly!O13/4 -> 676.75 | BC14: =Monthly!O13/4 -> 676.75 | BD14: 286
C15: Other | D15: 0 | E15: 99 | F15: 77 | G15: 152.63 | H15: 124.68 | I15: 99.4 | J15: 154 | L15: 77 | M15: =139.95-11 -> 128.95 | N15: 143 | O15: 126.5 | P15: 139.7 | Q15: 77.2 | R15: 126.5 | S15: 144.81 | T15: 99.06 | U15: 52.25 | V15: 114.4 | W15: 86.45 | X15: 140.8 | Y15: 167.2 | Z15: 89.03 | AA15: 72 | AB15: 104.5 | AC15: 93.5 | AD15: =Monthly!J14/5 -> 2.2 | AE15: =Monthly!J14/5 -> 2.2 | AF15: =Monthly!J14/5 -> 2.2 | AG15: =Monthly!J14/5 -> 2.2 | AH15: =Monthly!J14/5 -> 2.2 | AI15: =Monthly!K14/4 -> 2.75 | AJ15: =Monthly!K14/4 -> 2.75 | AK15: =Monthly!K14/4 -> 2.75 | AL15: =Monthly!K14/4 -> 2.75 | AM15: =Monthly!L14/4 -> 2.75 | AN15: =Monthly!L14/4 -> 2.75 | AO15: =Monthly!L14/4 -> 2.75 | AP15: =Monthly!L14/4 -> 2.75 | AQ15: =Monthly!M14/5 -> 2.2 | AR15: =Monthly!M14/5 -> 2.2 | AS15: =Monthly!M14/5 -> 2.2 | AT15: =Monthly!M14/5 -> 2.2 | AU15: =Monthly!M14/5 -> 2.2 | AV15: =Monthly!N14/4 -> 2.75 | AW15: =Monthly!N14/4 -> 2.75 | AX15: =Monthly!N14/4 -> 2.75 | AY15: =Monthly!N14/4 -> 2.75 | AZ15: =Monthly!O14/4 -> 2.75 | BA15: =Monthly!O14/4 -> 2.75 | BB15: =Monthly!O14/4 -> 2.75 | BC15: =Monthly!O14/4 -> 2.75 | BD15: 60.35
C16: Total: | D16: =SUM(D13:D15) -> 0 | E16: =SUM(E13:E15) -> 966.78 | F16: =SUM(F13:F15) -> 1115.56 | G16: =SUM(G13:G15) -> 1007.11 | H16: =SUM(H13:H15) -> 423.53 | I16: =SUM(I13:I15) -> 1163.764 | J16: =SUM(J13:J15) -> 1068.18 | K16: =SUM(K13:K15) -> 0 | ... BC16: =SUM(BC13:BC15) -> 1196.1301 | BD16: =SUM(D16:BC16) -> 54067.976
C17: YTD - Actual | D17: =D16 -> 0 | E17: =D17+E16 -> 966.78 | F17: =E17+F16 -> 2082.34 | G17: =F17+G16 -> 3089.45 | H17: =G17+H16 -> 3512.98 | I17: =H17+I16 -> 4676.744 | J17: =I17+J16 -> 5744.924 | K17: =J17+K16 -> 5744.924 | L17: =K17+L16 -> 6679.764 | ... BC17: =BB17+BC16 -> 54067.976 | BD17: =BD1 -> 55000 | BE17: =BD16/BD17 -> 0.98305411 | BF17: =1-BE17 -> 0.016945892
C18: YTD - Plan | D18: =D1 -> 1057.6923 | E18: =D18+E1 -> 2115.3846 | F18: =E18+F1 -> 3173.0769 | G18: =F18+G1 -> 4230.7692 | H18: =G18+H1 -> 5288.4615 | I18: =H18+I1 -> 6346.1538 | J18: =I18+J1 -> 7403.8462 | K18: =J18+K1 -> 8461.5385 | L18: =K18+L1 -> 9519.2308 | ... BC18: =BB18+BC1 -> 55000
D19: =D11 -> Week 1 | E19: =E11 -> 2 | F19: =F11 -> 3 | G19: =G11 -> 4 | H19: =H11 -> 5 | I19: =I11 -> 6 | J19: =J11 -> 7 | K19: =K11 -> 8 | ... O19: =O11 -> 12 | P19: 13 | Q19: =Q11 -> 14 | R19: =R11 -> 15 | S19: =S11 -> 16 | T19: =T11 -> 17 | U19: =U11 -> 18 | V19: =V11 -> 19 | W19: =W11 -> 20 | X19: =X11 -> 21 | ... BA19: =BA11 -> 50 | BB19: 51 | BC19: =BC11 -> Week 52
B20: 3 | C20: Weekly Net sales / Ton [m VND / Ton]
C21: =C13 -> B2B | D21: =IFERROR(D5/D13," ") | E21: =IFERROR(E5/E13," ") -> 32.078622 | F21: =IFERROR(F5/F13," ") -> 32.618071 | G21: =IFERROR(G5/G13," ") -> 33.66164 | H21: =IFERROR(H5/H13," ") -> 31.777332 | I21: =IFERROR(I5/I13," ") -> 30.072283 | J21: =IFERROR(J5/J13," ") -> 31.506137 | K21: =IFERROR(K5/K13," ") | ... BC21: =IFERROR(BC5/BC13," ") -> 29.971081
C22: Export | D22: =IFERROR(D6/D14," ") | E22: =IFERROR(E6/E14," ") -> 29.519985 | F22: =IFERROR(F6/F14," ") -> 28.778091 | G22: =IFERROR(G6/G14," ") -> 25.928059 | H22: =IFERROR(H6/H14," ") -> 27.966029 | I22: =IFERROR(I6/I14," ") -> 29.428448 | J22: =IFERROR(J6/J14," ") -> 27.744394 | K22: =IFERROR(K6/K14," ") | ... BC22: =IFERROR(BC6/BC14," ") -> 30.405627
C23: Other | D23: =IFERROR(D7/D15,"") | E23: =IFERROR(E7/E15,"") -> 32.842424 | F23: =IFERROR(F7/F15,"") -> 34.585714 | G23: =IFERROR(G7/G15,"") -> 32.170936 | H23: =IFERROR(H7/H15,"") -> 31.437841 | I23: =IFERROR(I7/I15,"") -> 32.829276 | J23: =IFERROR(J7/J15,"") -> 33.940714 | K23: =IFERROR(K7/K15,"") | ... BC23: =IFERROR(BC7/BC15,"") -> 30.475
C24: Total: | D24: =SUM(D5:D6)/SUM(D13:D14) -> #DIV/0! | E24: =SUM(E5:E6)/SUM(E13:E14) -> 30.132621 | F24: =SUM(F5:F6)/SUM(F13:F14) -> 30.177782 | G24: =IFERROR(SUM(G5:G6)/SUM(G13:G14),"") -> 29.091073 | H24: =IFERROR(SUM(H5:H6)/SUM(H13:H14),"") -> 30.910112 | I24: =SUM(I5:I6)/SUM(I13:I14) -> 29.631703 | J24: =SUM(J5:J6)/SUM(J13:J14) -> 28.790315 | K24: =SUM(K5:K6)/SUM(K13:K14) -> #DIV/0! | L24: =SUM(L5:L6)/SUM(L13:L14) -> 28.278177 | M24: =SUM(M5:M6)/SUM(M13:M14) -> 29.472431 | N24: =SUM(N5:N6)/SUM(N13:N14) -> 26.626984 | O24: =SUM(O5:O6)/SUM(O13:O14) -> 28.082927 | P24: =SUM(P5:P6)/SUM(P13:P14) -> 29.680878 | ... BC24: =SUM(BC5:BC6)/SUM(BC13:BC14) -> 30.217506
C25: =IF(B1="EN","AVG Weekly Actual","BQ Thực tế hàng tuần") -> BQ Thực tế hàng tuần | D25: =SUM($D$8:$BC$8)/$C$1 -> #VALUE! | E25: =SUM($D$8:$BC$8)/$C$1 -> #VALUE! | F25: =SUM($D$8:$BC$8)/$C$1 -> #VALUE! | G25: =SUM($D$8:$BC$8)/$C$1 -> #VALUE! | H25: =SUM($D$8:$BC$8)/$C$1 -> #VALUE! | I25: =SUM($D$8:$BC$8)/$C$1 -> #VALUE! | J25: =SUM($D$8:$BC$8)/$C$1 -> #VALUE! | K25: =SUM($D$8:$BC$8)/$C$1 -> #VALUE! | ... BC25: =SUM($D$8:$BC$8)/$C$1 -> #VALUE!

Sheet Monthly
B1: =Daily!B1 -> VN
B2: =IF(B1="EN","MONTHLY NET SALES ","DOANH THU HÀNG THÁNG") -> DOANH THU HÀNG THÁNG
C3: =IF(B1="EN","Net sales plan","Doanh thu kế hoạch") -> Doanh thu kế hoạch | D3: T01 | E3: T02 | F3: T03 | G3: T04 | H3: T05 | I3: T06 | J3: T07 | K3: T08 | L3: T09 | M3: T10 | N3: T11 | O3: T12 | P3: TOTAL
B4: 1 | C4: =IF(B1="EN","Net sales plan [mVND]","Doanh thu kế hoạch [Triệu đồng]") -> Doanh thu kế hoạch [Triệu đồng]
C5: B2B | D5: 60334.151 | E5: 56141.485 | F5: 58341.326 | G5: 60976.27 | H5: 61450.22 | I5: 58485.824 | J5: 60517.025 | K5: 63707.463 | L5: 55412.785 | M5: 59295.163 | N5: 60495.434 | O5: 61935.852 | P5: =SUM(D5:O5) -> 717093
C6: Export | D6: 70989.019 | E6: 73574.995 | F6: 85075.995 | G6: 72567.041 | H6: 80640.425 | I6: 84694.024 | J6: 81755.189 | K6: 74361.265 | L6: 89651.871 | M6: 75481.685 | N6: 82304.375 | O6: 82308.032 | P6: =SUM(D6:O6) -> 953403.91
C7: Other | D7: 335.225 | E7: 335.225 | F7: 335.225 | G7: 335.225 | H7: 335.225 | I7: 335.225 | J7: 335.225 | K7: 335.225 | L7: 335.225 | M7: 335.225 | N7: 335.225 | O7: 335.225 | P7: =SUM(D7:O7) -> 4022.7
C8: =IF(B1="EN","Total: ","Tổng cộng:") -> Tổng cộng: | D8: =SUM(D5:D7) -> 131658.4 | E8: =SUM(E5:E7) -> 130051.71 | F8: =SUM(F5:F7) -> 143752.55 | G8: =SUM(G5:G7) -> 133878.54 | H8: =SUM(H5:H7) -> 142425.87 | I8: =SUM(I5:I7) -> 143515.07 | J8: =SUM(J5:J7) -> 142607.44 | K8: =SUM(K5:K7) -> 138403.95 | ... P8: =SUM(P5:P7) -> 1674519.6
C9: YTD Net Sales (Plan) | D9: =D8 -> 131658.4 | E9: =D9+E8 -> 261710.1 | F9: =E9+F8 -> 405462.65 | G9: =F9+G8 -> 539341.18 | H9: =G9+H8 -> 681767.05 | I9: =H9+I8 -> 825282.13 | J9: =I9+J8 -> 967889.56 | K9: =J9+K8 -> 1106293.5 | L9: =K9+L8 -> 1251693.4 | ... O9: =N9+O8 -> 1674519.6
D10: =D3 -> T01 | E10: =E3 -> T02 | F10: =F3 -> T03 | G10: =G3 -> T04 | H10: =H3 -> T05 | I10: =I3 -> T06 | J10: =J3 -> T07 | K10: =K3 -> T08 | ... O10: =O3 -> T12 | P10: TOTAL
B11: 2 | C11: =IF(B1="EN","Sales Volume plan [Ton]","Sản lượng bán kế hoạch[Tấn]") -> Sản lượng bán kế hoạch[Tấn]
C12: B2B | D12: 2004.2229 | E12: 1856.3146 | F12: 1946.5574 | G12: 2014.2315 | H12: 2046.4364 | I12: 1935.9522 | J12: 2021.5225 | K12: 2108.8495 | L12: 1863.6231 | M12: 1968.6263 | N12: 2029.2431 | O12: 2066.5204 | P12: =SUM(D12:O12) -> 23862.1
C13: Export | D13: 2303 | E13: 2386 | F13: 2721 | G13: 2369 | H13: 2606 | I13: 2745 | J13: 2656.9 | K13: 2443 | L13: 2900 | M13: 2489 | N13: 2680 | O13: 2707 | P13: =SUM(D13:O13) -> 31005.9
C14: Other | D14: 11 | E14: 11 | F14: 11 | G14: 11 | H14: 11 | I14: 11 | J14: 11 | K14: 11 | L14: 11 | M14: 11 | N14: 11 | O14: 11 | P14: =SUM(D14:O14) -> 132
C15: =IF(B1="EN","Total: ","Tổng cộng:") -> Tổng cộng: | D15: =SUM(D12:D14) -> 4318.2229 | E15: =SUM(E12:E14) -> 4253.3146 | F15: =SUM(F12:F14) -> 4678.5574 | G15: =SUM(G12:G14) -> 4394.2315 | H15: =SUM(H12:H14) -> 4663.4364 | I15: =SUM(I12:I14) -> 4691.9522 | J15: =SUM(J12:J14) -> 4689.4225 | K15: =SUM(K12:K14) -> 4562.8495 | ... P15: =SUM(P12:P14) -> 55000
C17: =IF(B1="EN","Net sales","Doanh thu thực tế ") -> Doanh thu thực tế | D17: T01 | E17: T02 | F17: T03 | G17: T04 | H17: T05 | I17: T06 | J17: T07 | K17: T08 | L17: T09 | M17: T10 | N17: T11 | O17: T12 | P17: =P3 -> TOTAL
B18: 3 | C18: =IF(B1="EN","Net sales Estimate [mVND]","Doanh thu thực tế [Triệu đồng]") -> Doanh thu thực tế [Triệu đồng]
C19: B2B | D19: 38113.06 | E19: 25253.222 | F19: 66434.884 | G19: 70736.266 | H19: 50198.498 | I19: =Daily!AI6 -> 48890.918 | P19: =SUM(D19:O19) -> 299626.85
C20: Export | D20: 53472.09 | E20: 56863.39 | F20: 80759.63 | G20: 67176.95 | H20: 87346.71 | I20: =Daily!AI7 -> 55103.65 | P20: =SUM(D20:O20) -> 400722.42
C21: Other | D21: 14744.42 | E21: 11055.56 | F21: 17967.33 | G21: 15624.92 | H21: 17685.96 | I21: =Daily!AI8 -> 13767.12 | P21: =SUM(D21:O21) -> 90845.31
C22: =IF(B1="EN","Total: ","Tổng cộng:") -> Tổng cộng: | D22: =SUM(D19:D21) -> 106329.57 | E22: =SUM(E19:E21) -> 93172.172 | F22: =SUM(F19:F21) -> 165161.84 | G22: =SUM(G19:G21) -> 153538.14 | H22: =SUM(H19:H21) -> 155231.17 | I22: =SUM(I19:I21) -> 117761.69 | J22: =SUM(J19:J21) -> 0 | K22: =SUM(K19:K21) -> 0 | ... P22: =SUM(P19:P21) -> 791194.58
D24: =D17 -> T01 | E24: =E17 -> T02 | F24: =F17 -> T03 | G24: =G17 -> T04 | H24: =H17 -> T05 | I24: =I17 -> T06 | J24: =J17 -> T07 | K24: =K17 -> T08 | ... O24: =O17 -> T12 | P24: TOTAL
B25: 4 | C25: =IF(B1="EN","Sales Volume Estimate [Ton]","Sản lượng bán thực tế [Tấn]") -> Sản lượng bán thực tế [Tấn]
C26: B2B | D26: 1166.67 | E26: 810.03 | F26: 2361.088 | G26: 2377.509 | H26: 1585.3 | I26: =Daily!AI21 -> 1519.38 | P26: =SUM(D26:O26) -> 9819.977
