Workbook
Name _1: #REF!
Name _1: #REF!
Name _1: #REF!
Name _2: #REF!
Name _2: #REF!
Name _2: #REF!
Name _3: #REF!
Name _3: #REF!
Name _3: #REF!
Name _4: #REF!
Name _4: #REF!
Name _4: #REF!
Name _5: #REF!
Name _5: #REF!
Name _5: #REF!
Name a: #REF!
Name a: #REF!
Name a: #REF!
Name Accounts: #REF!
Name Accounts: #REF!
Name Accounts: #REF!
Name Activity_Reports: #REF!
Name Activity_Reports: #REF!
Name Activity_Reports: #REF!
Name ADM: #REF!
Name ADM: #REF!
Name ADM: #REF!
Name Application: [6]!Table6[Application]
Name B: #REF!
Name B: #REF!
Name B: #REF!
Name back: #REF!
Name back: #REF!
Name back: #REF!
Name Calendar: #REF!
Name Calendar: #REF!
Name Calendar: #REF!
Name Catalogue_xls: #REF!
Name Catalogue_xls: #REF!
Name Catalogue_xls: #REF!
Name CompanyCode: [11]CompanyCode!$A$2:$A$5
Name Contractingdiv: #REF!
Name Contractingdiv: #REF!
Name Contractingdiv: #REF!
Name corporate_affairs: #REF!
Name corporate_affairs: #REF!
Name corporate_affairs: #REF!
Name CTY: '[12]0.CTY'!$D:$D
Name Data_Values: '[16]Single Measure Analysis'!$B$29:$M$30
Name DATA13: '[17]2.1Raw material_details'!#REF!
Name DATA13: '[17]2.1Raw material_details'!#REF!
Name DATA13: '[17]2.1Raw material_details'!#REF!
Name DATA14: '[17]2.1Raw material_details'!#REF!
Name DATA14: '[17]2.1Raw material_details'!#REF!
Name DATA14: '[17]2.1Raw material_details'!#REF!
Name DATA15: '[17]2.1Raw material_details'!#REF!
Name DATA15: '[17]2.1Raw material_details'!#REF!
Name DATA15: '[17]2.1Raw material_details'!#REF!
Name DATA16: '[17]2.1Raw material_details'!#REF!
Name DATA16: '[17]2.1Raw material_details'!#REF!

Sheet KQKD Day Dai
B3: MỤC TIÊU KẾT QUẢ KINH DOANH NĂM 2026 | P3: ĐVT: Triệu đồng
B4: STT | C4: Mục phí | D4: T1 | E4: T2 | F4: T3 | G4: T4 | H4: T5 | I4: T6 | J4: T7 | K4: T8 | L4: T9 | M4: T10 | N4: T11 | O4: T12 | P4: KH 2026
B5: 1 | C5: SẢN LƯỢNG BÁN (TẤN) | D5: =SUM(D6:D7) -> 0 | E5: =SUM(E6:E7) -> 0 | F5: =SUM(F6:F7) -> 0 | G5: =SUM(G6:G7) -> 142416 | H5: =SUM(H6:H7) -> 142416 | I5: =SUM(I6:I7) -> 142416 | J5: =SUM(J6:J7) -> 142416 | K5: =SUM(K6:K7) -> 142416 | ... O5: =SUM(O6:O7) -> 142416 | P5: =SUM(D5:O5) -> 1281744
B6: 1.1 | C6: Dây Đai PET | D6: ='4.Doanh thu'!F7 -> 0 | E6: ='4.Doanh thu'!G7 -> 0 | F6: ='4.Doanh thu'!H7 -> 0 | G6: ='4.Doanh thu'!I7 -> 142416 | H6: ='4.Doanh thu'!J7 -> 142416 | I6: ='4.Doanh thu'!K7 -> 142416 | J6: ='4.Doanh thu'!L7 -> 142416 | K6: ='4.Doanh thu'!M7 -> 142416 | ... O6: ='4.Doanh thu'!Q7 -> 142416 | P6: =SUM(D6:O6) -> 1281744
B7: 1.2 | P7: =SUM(D7:O7) -> 0
B8: 2 | C8: DOANH THU | D8: =SUM(D9:D11) -> 0 | E8: =SUM(E9:E11) -> 0 | F8: =SUM(F9:F11) -> 0 | G8: =SUM(G9:G11) -> 2848320000 | H8: =SUM(H9:H11) -> 2848320000 | I8: =SUM(I9:I11) -> 2848320000 | J8: =SUM(J9:J11) -> 2848320000 | K8: =SUM(K9:K11) -> 2848320000 | ... O8: =SUM(O9:O11) -> 2848320000 | P8: =SUM(D8:O8) -> 25634880000
B9: 2.1 | C9: Dây Đai PET | D9: ='4.Doanh thu'!F27 -> 0 | E9: ='4.Doanh thu'!G27 -> 0 | F9: ='4.Doanh thu'!H27 -> 0 | G9: ='4.Doanh thu'!I27 -> 2848320000 | H9: ='4.Doanh thu'!J27 -> 2848320000 | I9: ='4.Doanh thu'!K27 -> 2848320000 | J9: ='4.Doanh thu'!L27 -> 2848320000 | K9: ='4.Doanh thu'!M27 -> 2848320000 | ... O9: ='4.Doanh thu'!Q27 -> 2848320000 | P9: =SUM(D9:O9) -> 25634880000
B10: 2.2
B11: 2.4 | C11: Khác | P11: =SUM(D11:O11) -> 0
B12: 3 | C12: BIẾN PHÍ | D12: =D13+D21 -> 0 | E12: =E13+E21 -> 0 | F12: =F13+F21 -> 0 | G12: =G13+G21 -> 2.9881254e+09 | H12: =H13+H21 -> 2.9881254e+09 | I12: =I13+I21 -> 2.9881254e+09 | J12: =J13+J21 -> 2.9881254e+09 | K12: =K13+K21 -> 2.9881254e+09 | ... O12: =O13+O21 -> 2.9881254e+09 | P12: =SUM(D12:O12) -> 2.6893128e+10
B13: 3.1 | C13: BIẾN PHÍ SẢN XUẤT | D13: =D14+D18+D19+D20 -> 0 | E13: =E14+E18+E19+E20 -> 0 | F13: =F14+F18+F19+F20 -> 0 | G13: =G14+G18+G19+G20 -> 2.9299722e+09 | H13: =H14+H18+H19+H20 -> 2.9299722e+09 | I13: =I14+I18+I19+I20 -> 2.9299722e+09 | J13: =J14+J18+J19+J20 -> 2.9299722e+09 | K13: =K14+K18+K19+K20 -> 2.9299722e+09 | ... O13: =O14+O18+O19+O20 -> 2.9299722e+09 | P13: =SUM(D13:O13) -> 2.6369749e+10
B14: 3.1.1 | C14: Nguyên vật liệu chính (nhựa, gồm hao hụt) | D14: ='1.NVL'!H27 -> 0 | E14: ='1.NVL'!I27 -> 0 | F14: ='1.NVL'!J27 -> 0 | G14: ='1.NVL'!K27 -> 2220420000 | H14: ='1.NVL'!L27 -> 2220420000 | I14: ='1.NVL'!M27 -> 2220420000 | J14: ='1.NVL'!N27 -> 2220420000 | K14: ='1.NVL'!O27 -> 2220420000 | ... O14: ='1.NVL'!S27 -> 2220420000 | P14: =SUM(D14:O14) -> 19983780000
B15: 3.1.2 | C15: Trong đó: i/ Hao hụt CĐ phân loại chai | D15: =SUM('[27]KH DAY DAI'!E26,'[27]KH DAY DAI'!E33) -> 0 | E15: =SUM('[27]KH DAY DAI'!F26,'[27]KH DAY DAI'!F33) -> 0 | F15: =SUM('[27]KH DAY DAI'!G26,'[27]KH DAY DAI'!G33) -> 0 | G15: =SUM('[27]KH DAY DAI'!H26,'[27]KH DAY DAI'!H33) -> 0 | H15: =SUM('[27]KH DAY DAI'!I26,'[27]KH DAY DAI'!I33) -> 0 | I15: =SUM('[27]KH DAY DAI'!J26,'[27]KH DAY DAI'!J33) -> 0 | J15: =SUM('[27]KH DAY DAI'!K26,'[27]KH DAY DAI'!K33) -> 0 | K15: =SUM('[27]KH DAY DAI'!L26,'[27]KH DAY DAI'!L33) -> 0 | ... O15: =SUM('[27]KH DAY DAI'!P26,'[27]KH DAY DAI'!P33) -> 0 | P15: =SUM(D15:O15) -> 0
C16: ii/ Hao hụt CĐ băm vảy | P16: =SUM(D16:O16) -> 0
B17: 3.1.3 | C17: % chi phí nguyên liệu/doanh thu | D17: =IFERROR(D14/D8,) -> 0 | E17: =IFERROR(E14/E8,) -> 0 | F17: =IFERROR(F14/F8,) -> 0 | G17: =IFERROR(G14/G8,) -> 0.77955426 | H17: =IFERROR(H14/H8,) -> 0.77955426 | I17: =IFERROR(I14/I8,) -> 0.77955426 | J17: =IFERROR(J14/J8,) -> 0.77955426 | K17: =IFERROR(K14/K8,) -> 0.77955426 | ... P17: =IFERROR(P14/P8,) -> 0.77955426
B18: 3.1.4 | C18: Nguyên vật liệu phụ (Lõi giấy, Màng PE, | D18: =SUM(CPSX!K19:K25) -> 0 | E18: =SUM(CPSX!L19:L25) -> 0 | F18: =SUM(CPSX!M19:M25) -> 0 | G18: =SUM(CPSX!N19:N25) -> 2.9573615e+08 | H18: =SUM(CPSX!O19:O25) -> 2.9573615e+08 | I18: =SUM(CPSX!P19:P25) -> 2.9573615e+08 | J18: =SUM(CPSX!Q19:Q25) -> 2.9573615e+08 | K18: =SUM(CPSX!R19:R25) -> 2.9573615e+08 | ... O18: =SUM(CPSX!V19:V25) -> 2.9573615e+08 | P18: =SUM(D18:O18) -> 2.6616254e+09
B19: 3.1.5 | C19: Điện sản xuất | D19: =CPSX!K18 -> 0 | E19: =CPSX!L18 -> 0 | F19: =CPSX!M18 -> 0 | G19: =CPSX!N18 -> 365976000 | H19: =CPSX!O18 -> 365976000 | I19: =CPSX!P18 -> 365976000 | J19: =CPSX!Q18 -> 365976000 | K19: =CPSX!R18 -> 365976000 | ... O19: =CPSX!V18 -> 365976000 | P19: =SUM(D19:O19) -> 3293784000
B20: 3.1.6 | C20: Nhân công trực tiếp | D20: =SUM(CPSX!K6:K17) -> 0 | E20: =SUM(CPSX!L6:L17) -> 0 | F20: =SUM(CPSX!M6:M17) -> 0 | G20: =SUM(CPSX!N6:N17) -> 47840000 | H20: =SUM(CPSX!O6:O17) -> 47840000 | I20: =SUM(CPSX!P6:P17) -> 47840000 | J20: =SUM(CPSX!Q6:Q17) -> 47840000 | K20: =SUM(CPSX!R6:R17) -> 47840000 | ... O20: =SUM(CPSX!V6:V17) -> 47840000 | P20: =SUM(D20:O20) -> 4.3056e+08
B21: 3.2 | C21: BIẾN PHÍ BÁN HÀNG | D21: =CPBH!K5 -> 0 | E21: =CPBH!L5 -> 0 | F21: =CPBH!M5 -> 0 | G21: =CPBH!N5 -> 58153200 | H21: =CPBH!O5 -> 58153200 | I21: =CPBH!P5 -> 58153200 | J21: =CPBH!Q5 -> 58153200 | K21: =CPBH!R5 -> 58153200 | ... O21: =CPBH!V5 -> 58153200 | P21: =SUM(D21:O21) -> 523378800
C22: Chi phí vận chuyển | D22: =CPSX!K27 -> 0 | E22: =CPSX!L27 -> 0 | F22: =CPSX!M27 -> 0 | G22: =CPSX!N27 -> 0 | H22: =CPSX!O27 -> 0 | I22: =CPSX!P27 -> 0 | J22: =CPSX!Q27 -> 0 | K22: =CPSX!R27 -> 0 | ... O22: =CPSX!V27 -> 0 | P22: =SUM(D22:O22) -> 0
B23: 4 | C23: LÃI SAU BIẾN PHÍ | D23: =D8-D12 -> 0 | E23: =E8-E12 -> 0 | F23: =F8-F12 -> 0 | G23: =G8-G12 -> -1.3980535e+08 | H23: =H8-H12 -> -1.3980535e+08 | I23: =I8-I12 -> -1.3980535e+08 | J23: =J8-J12 -> -1.3980535e+08 | K23: =K8-K12 -> -1.3980535e+08 | ... O23: =O8-O12 -> -1.3980535e+08 | P23: =SUM(D23:O23) -> -1.2582482e+09
B24: 4.1 | C24: % lãi biến phí/doanh thu | D24: =IFERROR(D23/D8,) -> 0 | E24: =IFERROR(E23/E8,) -> 0 | F24: =IFERROR(F23/F8,) -> 0 | G24: =IFERROR(G23/G8,) -> -0.049083443 | H24: =IFERROR(H23/H8,) -> -0.049083443 | I24: =IFERROR(I23/I8,) -> -0.049083443 | J24: =IFERROR(J23/J8,) -> -0.049083443 | K24: =IFERROR(K23/K8,) -> -0.049083443 | ... P24: =IFERROR(P23/P8,) -> -0.049083443
B25: 5 | C25: CHI PHÍ SẢN XUẤT CHUNG | D25: =D26+D27+D28 -> 0 | E25: =E26+E27+E28 -> 0 | F25: =F26+F27+F28 -> 0 | G25: =G26+G27+G28 -> 80488500 | H25: =H26+H27+H28 -> 80488500 | I25: =I26+I27+I28 -> 80488500 | J25: =J26+J27+J28 -> 80488500 | K25: =K26+K27+K28 -> 80488500 | ... O25: =O26+O27+O28 -> 80488500 | P25: =SUM(D25:O25) -> 724396500
B26: 5.1 | C26: Lương gián tiếp Sản xuất | D26: =SUM(CPSX!K29:K40) -> 0 | E26: =SUM(CPSX!L29:L40) -> 0 | F26: =SUM(CPSX!M29:M40) -> 0 | G26: =SUM(CPSX!N29:N40) -> 80488500 | H26: =SUM(CPSX!O29:O40) -> 80488500 | I26: =SUM(CPSX!P29:P40) -> 80488500 | J26: =SUM(CPSX!Q29:Q40) -> 80488500 | K26: =SUM(CPSX!R29:R40) -> 80488500 | ... O26: =SUM(CPSX!V29:V40) -> 80488500 | P26: =SUM(D26:O26) -> 724396500
B27: 5.2 | C27: Chi phí thuê xưởng | P27: =SUM(D27:O27) -> 0
B28: 5.3 | C28: Chi phí sản xuất (Ngoài lương, BOM, thuê xưởng, khấu hao) | D28: =SUM('[27]KH DAY DAI'!E30) -> 0 | E28: =SUM('[27]KH DAY DAI'!F30) -> 0 | F28: =SUM('[27]KH DAY DAI'!G30) -> 0 | G28: =SUM('[27]KH DAY DAI'!H30) -> 0 | H28: =SUM('[27]KH DAY DAI'!I30) -> 0 | I28: =SUM('[27]KH DAY DAI'!J30) -> 0 | J28: =SUM('[27]KH DAY DAI'!K30) -> 0 | K28: =SUM('[27]KH DAY DAI'!L30) -> 0 | ... O28: =SUM('[27]KH DAY DAI'!P30) -> 0 | P28: =SUM(D28:O28) -> 0
B29: 6 | C29: CHI PHÍ KHẤU HAO, CCDC | D29: =CPSX!K56 -> 0 | E29: =CPSX!L56 -> 0 | F29: =CPSX!M56 -> 0 | G29: =CPSX!N56 -> 46507064 | H29: =CPSX!O56 -> 46507064 | I29: =CPSX!P56 -> 46507064 | J29: =CPSX!Q56 -> 46507064 | K29: =CPSX!R56 -> 46507064 | ... O29: =CPSX!V56 -> 46507064 | P29: =SUM(D29:O29) -> 4.1856358e+08
B30: 7 | C30: LỢI NHUẬN GỘP | D30: =D23-D25-D29 -> 0 | E30: =E23-E25-E29 -> 0 | F30: =F23-F25-F29 -> 0 | G30: =G23-G25-G29 -> -2.6680092e+08 | H30: =H23-H25-H29 -> -2.6680092e+08 | I30: =I23-I25-I29 -> -2.6680092e+08 | J30: =J23-J25-J29 -> -2.6680092e+08 | K30: =K23-K25-K29 -> -2.6680092e+08 | ... O30: =O23-O25-O29 -> -2.6680092e+08 | P30: =SUM(D30:O30) -> -2.4012082e+09
B31: 7.1 | C31: % lãi gộp/doanh thu | D31: =IFERROR(D30/D8,) -> 0 | E31: =IFERROR(E30/E8,) -> 0 | F31: =IFERROR(F30/F8,) -> 0 | G31: =IFERROR(G30/G8,) -> -0.093669572 | H31: =IFERROR(H30/H8,) -> -0.093669572 | I31: =IFERROR(I30/I8,) -> -0.093669572 | J31: =IFERROR(J30/J8,) -> -0.093669572 | K31: =IFERROR(K30/K8,) -> -0.093669572 | ... P31: =IFERROR(P30/P8,) -> -0.093669572
B32: 8 | C32: CHI PHÍ BÁN HÀNG & MKT & R&D | D32: =D34+D35+D36 -> 0 | E32: =E34+E35+E36 -> 0 | F32: =F34+F35+F36 -> 0 | G32: =G34+G35+G36 -> 854496000 | H32: =H34+H35+H36 -> 854496000 | I32: =I34+I35+I36 -> 854496000 | J32: =J34+J35+J36 -> 854496000 | K32: =K34+K35+K36 -> 854496000 | ... O32: =O34+O35+O36 -> 854496000 | P32: =SUM(D32:O32) -> 7690464000
B33: 8.1 | C33: % CPBH/doanh thu | D33: =IFERROR(D32/D$8,) -> 0 | E33: =IFERROR(E32/E$8,) -> 0 | F33: =IFERROR(F32/F$8,) -> 0 | G33: =IFERROR(G32/G$8,) -> 0.3 | H33: =IFERROR(H32/H$8,) -> 0.3 | I33: =IFERROR(I32/I$8,) -> 0.3 | J33: =IFERROR(J32/J$8,) -> 0.3 | K33: =IFERROR(K32/K$8,) -> 0.3 | ... P33: =IFERROR(P32/P$8,) -> 0.3
B34: 8.1 | C34: Lương | D34: =CPBH!K7 -> 0 | E34: =CPBH!L7 -> 0 | F34: =CPBH!M7 -> 0 | G34: =CPBH!N7 -> 284832000 | H34: =CPBH!O7 -> 284832000 | I34: =CPBH!P7 -> 284832000 | J34: =CPBH!Q7 -> 284832000 | K34: =CPBH!R7 -> 284832000 | ... O34: =CPBH!V7 -> 284832000 | P34: =SUM(D34:O34) -> 2563488000
B35: 8.2 | C35: Chi phí bán hàng (ngoài lương, khấu hao) | D35: =SUM(CPBH!K8:K10) -> 0 | E35: =SUM(CPBH!L8:L10) -> 0 | F35: =SUM(CPBH!M8:M10) -> 0 | G35: =SUM(CPBH!N8:N10) -> 569664000 | H35: =SUM(CPBH!O8:O10) -> 569664000 | I35: =SUM(CPBH!P8:P10) -> 569664000 | J35: =SUM(CPBH!Q8:Q10) -> 569664000 | K35: =SUM(CPBH!R8:R10) -> 569664000 | ... O35: =SUM(CPBH!V8:V10) -> 569664000 | P35: =SUM(D35:O35) -> 5126976000
B36: 8.3 | C36: Khấu hao tài sản | P36: =SUM(D36:O36) -> 0
B37: 9 | C37: CHI PHÍ QUẢN LÝ | D37: =D39+D40+D41 -> 0 | E37: =E39+E40+E41 -> 0 | F37: =F39+F40+F41 -> 0 | G37: =G39+G40+G41 -> 0 | H37: =H39+H40+H41 -> 0 | I37: =I39+I40+I41 -> 0 | J37: =J39+J40+J41 -> 0 | K37: =K39+K40+K41 -> 0 | ... O37: =O39+O40+O41 -> 0 | P37: =SUM(D37:O37) -> 0
B38: 9.1 | C38: % CPQL/doanh thu | D38: =IFERROR(D37/D$8,) -> 0 | E38: =IFERROR(E37/E$8,) -> 0 | F38: =IFERROR(F37/F$8,) -> 0 | G38: =IFERROR(G37/G$8,) -> 0 | H38: =IFERROR(H37/H$8,) -> 0 | I38: =IFERROR(I37/I$8,) -> 0 | J38: =IFERROR(J37/J$8,) -> 0 | K38: =IFERROR(K37/K$8,) -> 0 | ... P38: =IFERROR(P37/P$8,) -> 0
B39: 9.1 | C39: Lương | P39: =SUM(D39:O39) -> 0
B40: 9.2 | C40: Chi phí quản lý (ngoài lương, khấu hao) | P40: =SUM(D40:O40) -> 0
B41: 9.3 | C41: Khấu hao tài sản | P41: =SUM(D41:O41) -> 0
B42: 10 | C42: DOANH THU/CHI PHÍ KHÁC | P42: =SUM(D42:O42) -> 0
...

Sheet Cong suat
B3: CÔNG SUẤT
B4: I - CÔNG SUẤT CHUYỀN SẢN XUẤT DÂY ĐAI
B5: STT | C5: Công đoạn sản xuất | D5: Cấp liệu | J5: Công suất thành phẩm cả chuyền | K5: Công suất thành phẩm cả chuyền
B6: 1 | C6: Năng suất THIẾT KẾ (Kg NVL đầu vào / giờ) | D6: 300 | J6: =D6 -> 300 | K6: =D6*(100%-$D$15) -> 258
B7: 2 | C7: Năng suất ĐỊNH MỨC (Kg NVL đầu vào / giờ) | D7: 300
B8: 3 | C8: Định mức nhân công (Số NV / Ca12) | D8: 3 | J8: =SUM(C8:I8) -> 3 | K8: =SUM(D8:J8) -> 6
C9: Định mức kỹ thuật vận hành (Số NV / Ca12) | D9: 1.5 | J9: =SUM(C9:I9) -> 1.5 | K9: =SUM(D9:J9) -> 3
C10: Diễn giải
B12: STT | C12: Chỉ tiêu định mức | D12: ĐVT | E12: ĐM 1 giờ | F12: ĐM 1 Ca8 | G12: ĐM 1 Ca12 | H12: ĐM 2 Ca8 | I12: ĐM 2 Ca12
B13: 1 | C13: Tổng nhân sự: | D13: Người | E13: =K8 -> 6 | F13: =$E13 -> 6 | G13: 5 | H13: 9 | I13: 9
B14: 2 | C14: Định mức NVL đầu vào: | D14: kg/giờ | E14: =D7 -> 300 | F14: =$E14*8 -> 2400 | G14: =$F14*1.5 -> 3600 | H14: =$F14*2 -> 4800 | I14: =$G14*2 -> 7200
B15: 3 | C15: Hao hụt: | D15: ='2.Hao hut'!$E$11 -> 0.14 | E15: =E14*$D$15 -> 42 | F15: =$E15*8 -> 336 | G15: =$E15*12 -> 504 | H15: =$F15*2 -> 672 | I15: =$G15*2 -> 1008
B16: 4 | C16: Định mức thành phẩm: | D16: kg/giờ | E16: =E14-E15 -> 258 | F16: =$E16*8 -> 2064 | G16: =$F16*1.5 -> 3096 | H16: =$F16*2 -> 4128 | I16: =$G16*2 -> 6192
B17: 5 | C17: Định mức thành phẩm/người: | D17: kg/giờ/người | E17: =E16/K8 -> 43 | F17: =$E17*8 -> 344 | G17: =$F17*1.5 -> 516 | H17: =$F17*2 -> 688 | I17: =$G17*2 -> 1032
B19: VI - CÔNG SUẤT MÁY VÀ NĂNG SUẤT LAO ĐỘNG MỤC TIÊU
B20: 1 | C20: CHUYỀN DÂY ĐAI | E20: Định mức | F20: T1 | G20: T2 | H20: T3 | I20: T4 | J20: T5 | K20: T6 | L20: T7 | M20: T8 | N20: T9 | O20: T10 | P20: T11 | Q20: T12 | R20: Mục tiêu 2026
B21: a | C21: Số nhân sự/ chuyền/ ca | D21: Người | E21: =G13 -> 5 | I21: =$E21 -> 5 | J21: =$E21 -> 5 | K21: =$E21 -> 5 | L21: =$E21 -> 5 | M21: =$E21 -> 5 | N21: =$E21 -> 5 | O21: =$E21 -> 5 | P21: =$E21 -> 5 | Q21: =$E21 -> 5
B22: b | C22: Công suất/ chuyền | D22: kg/giờ | E22: =G14 -> 3600 | I22: =$E22 -> 3600 | J22: =$E22 -> 3600 | K22: =$E22 -> 3600 | L22: =$E22 -> 3600 | M22: =$E22 -> 3600 | N22: =$E22 -> 3600 | O22: =$E22 -> 3600 | P22: =$E22 -> 3600 | Q22: =$E22 -> 3600
B23: c | C23: Năng suất lao động | D23: kg/giờ/người | E23: =E22/E21 -> 720 | I23: =$E23 -> 720 | J23: =$E23 -> 720 | K23: =$E23 -> 720 | L23: =$E23 -> 720 | M23: =$E23 -> 720 | N23: =$E23 -> 720 | O23: =$E23 -> 720 | P23: =$E23 -> 720 | Q23: =$E23 -> 720
B27: VII - TỔNG CÔNG SUẤT MÁY PET và NĂNG SUẤT LAO ĐỘNG
B28: i | C28: Tổng công suất PET/giờ | D28: kg/giờ | E28: Định mức | F28: T1 | G28: T2 | H28: T3 | I28: T4 | J28: T5 | K28: T6 | L28: T7 | M28: T8 | N28: T9 | O28: T10 | P28: T11 | Q28: T12 | R28: Mục tiêu 2026
B29: 1 | C29: Công suất máy - Tính trên NVL đầu vào | D29: Tấn/giờ | E29: =E14 -> 300 | I29: =$E29 -> 300 | J29: =$E29 -> 300 | K29: =$E29 -> 300 | L29: =$E29 -> 300 | M29: =$E29 -> 300 | N29: =$E29 -> 300 | O29: =$E29 -> 300 | P29: =$E29 -> 300 | Q29: =$E29 -> 300 | R29: =AVERAGE(F29:Q29) -> 300
B30: 2 | C30: Công suất máy - Tính trên Thành phẩm SX | D30: Tấn/giờ | E30: =E16 -> 258 | I30: =$E30 -> 258 | J30: =$E30 -> 258 | K30: =$E30 -> 258 | L30: =$E30 -> 258 | M30: =$E30 -> 258 | N30: =$E30 -> 258 | O30: =$E30 -> 258 | P30: =$E30 -> 258 | Q30: =$E30 -> 258 | R30: =AVERAGE(F30:Q30) -> 258
B31: ii | C31: Tổng công suất PET/tháng (8hx2cax30 ngày) | D31: kg/tháng | E31: Định mức | J31: T5 | K31: T6 | L31: T7 | M31: T8 | N31: T9 | O31: T10 | P31: T11 | Q31: T12
B32: 1 | C32: Công suất máy - Tính trên NVL đầu vào | D32: Tấn/tháng | E32: =G14*2*30 -> 216000 | F32: =F29*7*2*30 -> 0 | G32: =G29*7*2*30 -> 0 | H32: =H29*7*2*30 -> 0 | I32: =$E32 -> 216000 | J32: =$E32 -> 216000 | K32: =$E32 -> 216000 | L32: =$E32 -> 216000 | M32: =$E32 -> 216000 | N32: =$E32 -> 216000 | O32: =$E32 -> 216000 | P32: =$E32 -> 216000 | Q32: =$E32 -> 216000 | R32: =AVERAGE(F32:Q32) -> 162000
B33: 2 | C33: Công suất máy - Tính trên Thành phẩm SX | D33: Tấn/tháng | E33: =G16*2*30 -> 185760 | F33: =F30*7*2*30 -> 0 | G33: =G30*7*2*30 -> 0 | H33: =H30*7*2*30 -> 0 | I33: =$E33 -> 185760 | J33: =$E33 -> 185760 | K33: =$E33 -> 185760 | L33: =$E33 -> 185760 | M33: =$E33 -> 185760 | N33: =$E33 -> 185760 | O33: =$E33 -> 185760 | P33: =$E33 -> 185760 | Q33: =$E33 -> 185760 | R33: =AVERAGE(F33:Q33) -> 139320
B34: iii | C34: Năng suất lao động (CNTT) | E34: Định mức | J34: T5 | K34: T6 | L34: T7 | M34: T8 | N34: T9 | O34: T10 | P34: T11 | Q34: T12
B35: 1 | C35: Năng suất lao động - Tấn/người/ngày | D35: Tấn/người/ngày | E35: =E36/30 -> 619.2 | I35: =I36/30 -> 619.2 | J35: =J36/30 -> 619.2 | K35: =K36/30 -> 619.2 | L35: =L36/30 -> 619.2 | M35: =M36/30 -> 619.2 | N35: =N36/30 -> 619.2 | O35: =O36/30 -> 619.2 | P35: =P36/30 -> 619.2 | Q35: =Q36/30 -> 619.2 | R35: =AVERAGE(F35:Q35) -> 619.2
B36: 2 | C36: Năng suất lao động - Tấn/người/tháng | D36: Tấn/người/tháng | E36: =E33/E21/2 -> 18576 | I36: =I33/I21/2 -> 18576 | J36: =J33/J21/2 -> 18576 | K36: =K33/K21/2 -> 18576 | L36: =L33/L21/2 -> 18576 | M36: =M33/M21/2 -> 18576 | N36: =N33/N21/2 -> 18576 | O36: =O33/O21/2 -> 18576 | P36: =P33/P21/2 -> 18576 | Q36: =Q33/Q21/2 -> 18576 | R36: =AVERAGE(F36:Q36) -> 18576

Sheet Dinh muc
B3: ĐỊNH MỨC CHI PHÍ
B4: I - ĐỊNH MỨC SẢN XUẤT DÂY ĐAI | G4: =SUM(G6:G22) -> 6206.3755
B5: STT | C5: Mục phí | D5: ĐVT | E5: Định mức | F5: Đơn giá | G5: Chi phí/1kg thành phẩm | H5: Diễn giải
B6: 1 | C6: Nhân sự trực tiếp (CNSX) | I6: =SUM(G8:G9) -> 335.91731
B7: a | C7: LĐ định biên | D7: Giờ công/ca 12
B8: b | C8: LĐ thời vụ | D8: Giờ công/ca 12 | E8: 2 | F8: 470000 | G8: =E8*F8/'Cong suat'!$G$16 -> 303.61757
B9: c | C9: Tiền ăn giữa Ca | D9: Đồng/người/ngày công | E9: =E8 -> 2 | F9: 50000 | G9: =E9*F9/'Cong suat'!$G$16 -> 32.299742
B10: 2 | C10: Nhân sự gián tiếp sản xuất | I10: =SUM(G11:G13) -> 565.16473
B11: a | C11: LĐ định biên - Kỹ Thuật | D11: Giờ công/ca 12 | E11: 1.5 | F11: 712700 | G11: =E11*F11/'Cong suat'!$G$16 -> 345.30039 | H11: Tăng thêm 1 nhân sự: để vệ sinh lõi lọc so với ban đầu
B12: b | C12: LĐ định biên - QC | D12: Giờ công/ca 12 | E12: 1 | F12: 555700 | G12: =E12*F12/'Cong suat'!$G$16 -> 179.48966
B13: c | C13: Tiền ăn giữa Ca | D13: Đồng/người/ngày công | E13: 2.5 | F13: 50000 | G13: =E13*F13/'Cong suat'!$G$16 -> 40.374677
B14: 3 | C14: Điện sản xuất | D14: Kw/1chuyền/1giờ hoạt động | E14: =500*60% -> 300 | F14: =ROUND(2100*1.05,-1) -> 2210 | G14: =E14*F14/'Cong suat'!$E$16 -> 2569.7674 | H14: Hiệu suất: 60% | K14: CP SX
B15: 4 | C15: Nước đầu vào | D15: m3/h | E15: 2 | F15: 11500 | G15: =E15*F15/'Cong suat'!$E$16 -> 89.147287 | I15: =G15+G16 -> 162.64806 | K15: =SUM(G17,G19,G20,G21) -> 1997.8779
B16: 5 | C16: Nước đầu ra | D16: m3/h | E16: =E15*80% -> 1.6 | F16: 11852 | G16: =E16*F16/'Cong suat'!$E$16 -> 73.500775
C17: VTTH: Ron | D17: Cái | E17: 2 | F17: =2*26500 -> 53000 | G17: =(E17*F17)/(1600*86%) -> 77.034884 | H17: 4h thay 1 bộ
B18: 6 | C18: Cuộn màng PE/PVC (3kg) | E18: 1 | F18: 250000 | G18: =(E18*F18)/1500 -> 166.66667 | H18: 1 cuộn SX 2.5 tấn
B19: 7 | C19: Lõi giấy Æ406 | E19: 1 | F19: 20000 | G19: =E19*F19/20 -> 1000 | H19: 1 Cuộn sử dụng 1 lõi
B20: 8 | C20: Pallet rHD D4-0986 DTR | D20: Cái | E20: 1 | F20: 539000 | G20: =E20*F20/(40*20) -> 673.75 | H20: 1 pallet chứa 40 cuộn
B21: 9 | C21: Dầu xe nâng | D21: Lít/giờ hoạt động | E21: =2.5*85% -> 2.125 | F21: 30000 | G21: =E21*F21/'Cong suat'!$E$16 -> 247.09302
B22: 10 | C22: Chi phí vận chuyển | D22: Chuyến/9 tấn | E22: 1 | F22: 4900000 | G22: =F22/12000 -> 408.33333 | H22: Cơ sở tính: tham chiếu CP chở chai tại trạm
B23: 11 | C23: Chi phí chiết khấu bán hàng: 10% doanh thu
B24: 13 | C24: Chi phí hoa hồng bán hàng 5% doanh thu
B25: 14 | C25: Cp đội ngũ sale bán hàng: 10% Doanh thu | H25: Lương KD, adm, nv giao hàng
B26: 15 | C26: Cp Maketing: 5% doanh thu | H26: Bộ nhận diện thương hiệu, tem nhãn, sale kit, TDS, dây mẫu
H28: Ngày …
C29: Duyệt | D29: Xem xét | E29: Xem xét | G29: Xem xét | H29: Người lập
C30: GĐĐH DTR | D30: GĐTC DTR | E30: GĐ các trạm | G30: Trưởng Trạm | H30: Kế toán trưởng

Sheet CPSX
B3: I - CHI PHÍ SẢN XUẤT PET | W3: ĐVT: Triệu đồng
B4: STT | C4: Dự phòng | D4: Mã tài khoản (Mã Chi phí_L4) | E4: Tên tài khoản (Cost elements 2) | F4: Chi Phí_L5 (Cost Group 2) | G4: Chi tiết | H4: Phòng ban | I4: Tham chiếu | J4: % CP/DT 2026 | K4: T1 | L4: T2 | M4: T3 | N4: T4 | O4: T5 | P4: T6 | Q4: T7 | R4: T8 | S4: T9 | T4: T10 | U4: T11 | V4: T12 | W4: KH 2026
B5: 1.1 | E5: BIẾN PHÍ | J5: =SUM(J6:J27) -> 0 | K5: =SUM(K6:K27) -> 0 | L5: =SUM(L6:L27) -> 0 | M5: =SUM(M6:M27) -> 0 | N5: =SUM(N6:N27) -> 7.4474215e+08 | O5: =SUM(O6:O27) -> 7.4474215e+08 | P5: =SUM(P6:P27) -> 7.4474215e+08 | Q5: =SUM(Q6:Q27) -> 7.4474215e+08 | ... W5: =SUM(W6:W27) -> 6.7026794e+09
B6: 1 | D6: 6220002601 | E6: Chi phí lương chính - Trực tiếp | F6: Salary and Wages - Direct | G6: Chi phí lương chính - Trực tiếp | H6: Phòng Hành chánh nhân sự | I6: LUONG | K6: ='Dinh muc'!$G$8*'3.Thanh pham'!F$10 -> 0 | L6: ='Dinh muc'!$G$8*'3.Thanh pham'!G$10 -> 0 | M6: ='Dinh muc'!$G$8*'3.Thanh pham'!H$10 -> 0 | N6: ='Dinh muc'!$G$8*'3.Thanh pham'!I$10 -> 43240000 | O6: ='Dinh muc'!$G$8*'3.Thanh pham'!J$10 -> 43240000 | P6: ='Dinh muc'!$G$8*'3.Thanh pham'!K$10 -> 43240000 | Q6: ='Dinh muc'!$G$8*'3.Thanh pham'!L$10 -> 43240000 | R6: ='Dinh muc'!$G$8*'3.Thanh pham'!M$10 -> 43240000 | ... V6: ='Dinh muc'!$G$8*'3.Thanh pham'!Q$10 -> 43240000 | W6: =SUM(K6:V6) -> 3.8916e+08
B7: 2 | D7: 6220002602 | E7: Chi phí lương T13, phép năm - Trực tiếp | F7: Salary and Wages - Direct | G7: Chi phí lương T13, phép năm - Trực tiếp | H7: Phòng Hành chánh nhân sự | I7: LUONG | W7: =SUM(K7:V7) -> 0
B8: 3 | D8: 6220002802 | E8: Chi phí khen thưởng - Trực tiếp | F8: Employee Welfare | G8: Chi phí khen thưởng - Trực tiếp | H8: Phòng Hành chánh nhân sự | I8: LUONG | W8: =SUM(K8:V8) -> 0
B9: 4 | D9: 6220002806 | E9: Thưởng danh hiệu - Trực tiếp | F9: Salary and Wages - Direct | G9: Thưởng danh hiệu - Trực tiếp | H9: Phòng Hành chánh nhân sự | I9: LUONG | W9: =SUM(K9:V9) -> 0
B10: 5 | D10: 6220007202 | E10: Chi phí khen thưởng, bồi dưỡng khác | F10: Employee Welfare | G10: Chi phí khen thưởng, bồi dưỡng khác | H10: Phòng Hành chánh nhân sự | I10: LUONG | W10: =SUM(K10:V10) -> 0
B11: 6 | D11: 6220003201 | E11: Tiền ăn giữa ca - Trực tiếp | F11: Employee Welfare | G11: Tiền ăn giữa ca - Trực tiếp | H11: Phòng Hành chánh nhân sự | I11: LUONG | K11: ='Dinh muc'!$G$9*'3.Thanh pham'!F$10 -> 0 | L11: ='Dinh muc'!$G$9*'3.Thanh pham'!G$10 -> 0 | M11: ='Dinh muc'!$G$9*'3.Thanh pham'!H$10 -> 0 | N11: ='Dinh muc'!$G$9*'3.Thanh pham'!I$10 -> 4600000 | O11: ='Dinh muc'!$G$9*'3.Thanh pham'!J$10 -> 4600000 | P11: ='Dinh muc'!$G$9*'3.Thanh pham'!K$10 -> 4600000 | Q11: ='Dinh muc'!$G$9*'3.Thanh pham'!L$10 -> 4600000 | R11: ='Dinh muc'!$G$9*'3.Thanh pham'!M$10 -> 4600000 | ... V11: ='Dinh muc'!$G$9*'3.Thanh pham'!Q$10 -> 4600000 | W11: =SUM(K11:V11) -> 41400000
B12: 7 | D12: 6220002603 | E12: Phụ cấp ca đêm - Trực tiếp | F12: Salary and Wages - Direct | G12: Phụ cấp ca đêm - Trực tiếp | H12: Phòng Hành chánh nhân sự | I12: LUONG | W12: =SUM(K12:V12) -> 0
B13: 8 | D13: 6220003401 | E13: BHXH, BHYT, KPCĐ, BHTN - Trực tiếp | F13: Employee Welfare | G13: BHXH, BHYT, KPCĐ, BHTN - Trực tiếp | H13: Phòng Hành chánh nhân sự | I13: LUONG | W13: =SUM(K13:V13) -> 0
B14: 9 | D14: 6220002701 | E14: Chi phí lương ngoài giờ - Trực tiếp | F14: Salary and Wages - Direct | G14: Chi phí lương ngoài giờ - Trực tiếp | H14: Phòng Hành chánh nhân sự | I14: LUONG | W14: =SUM(K14:V14) -> 0
B15: 10 | D15: 6220002901 | E15: Chi phí trợ cấp thôi việc - Trực tiếp | F15: Employee Benefits Expenses | G15: Chi phí trợ cấp thôi việc - Trực tiếp | H15: Phòng Hành chánh nhân sự | I15: LUONG | W15: =SUM(K15:V15) -> 0
B16: 11 | D16: 6220003001 | E16: Chi phí đồng phục | F16: Employee Welfare | G16: Chi phí đồng phục | H16: Phòng Hành chánh nhân sự | I16: Phan bo | W16: =SUM(K16:V16) -> 0
B17: 12 | E17: Chi phí y tế, BH sức khỏe | F17: Employee Welfare | G17: Chi Phí Y Tế, BH Sức Khỏe, BH 24/24 | H17: Phòng Hành chánh nhân sự | I17: Phan bo | W17: =SUM(K17:V17) -> 0
B18: 13 | D18: 6275001801 | E18: Chi phí điện sản xuất | F18: Direct Cost of Goods sold | G18: Chi phí điện sản xuất | H18: Phòng Kỹ thuật | I18: Dinh muc | K18: ='Dinh muc'!$G$14*'3.Thanh pham'!F$10 -> 0 | L18: ='Dinh muc'!$G$14*'3.Thanh pham'!G$10 -> 0 | M18: ='Dinh muc'!$G$14*'3.Thanh pham'!H$10 -> 0 | N18: ='Dinh muc'!$G$14*'3.Thanh pham'!I$10 -> 365976000 | O18: ='Dinh muc'!$G$14*'3.Thanh pham'!J$10 -> 365976000 | P18: ='Dinh muc'!$G$14*'3.Thanh pham'!K$10 -> 365976000 | Q18: ='Dinh muc'!$G$14*'3.Thanh pham'!L$10 -> 365976000 | R18: ='Dinh muc'!$G$14*'3.Thanh pham'!M$10 -> 365976000 | ... V18: ='Dinh muc'!$G$14*'3.Thanh pham'!Q$10 -> 365976000 | W18: =SUM(K18:V18) -> 3293784000
B19: 14 | D19: 6272000100 | E19: Chi phí vật liệu phục vụ SX | F19: Operating Supplies | H19: Phòng Kỹ thuật | I19: Dinh muc | W19: =SUM(K19:V19) -> 0
B20: 15 | D20: 6272000100 | E20: Chi phí vật liệu phục vụ SX | F20: Operating Supplies | G20: Lõi lọc - Màng … | H20: Phòng Sản xuất | I20: Dinh muc | W20: =SUM(K20:V20) -> 0 | X20: Trường hợp sản xuất 2 công đoạn: Phân loại chai và băm vảy thì chỉ tính sản lượng chai dùng dây đai
B21: 16 | D21: 6272000100 | E21: Chi phí vật liệu phục vụ SX | F21: Operating Supplies | G21: Cuộn Màng PE | H21: Phòng Sản xuất | I21: Dinh muc | K21: ='Dinh muc'!$G$18*'3.Thanh pham'!F$10 -> 0 | L21: ='Dinh muc'!$G$18*'3.Thanh pham'!G$10 -> 0 | M21: ='Dinh muc'!$G$18*'3.Thanh pham'!H$10 -> 0 | N21: ='Dinh muc'!$G$18*'3.Thanh pham'!I$10 -> 23736000 | O21: ='Dinh muc'!$G$18*'3.Thanh pham'!J$10 -> 23736000 | P21: ='Dinh muc'!$G$18*'3.Thanh pham'!K$10 -> 23736000 | Q21: ='Dinh muc'!$G$18*'3.Thanh pham'!L$10 -> 23736000 | R21: ='Dinh muc'!$G$18*'3.Thanh pham'!M$10 -> 23736000 | ... V21: ='Dinh muc'!$G$18*'3.Thanh pham'!Q$10 -> 23736000 | W21: =SUM(K21:V21) -> 213624000
B22: 17 | D22: 6272000100 | E22: Chi phí vật liệu phục vụ SX | F22: Operating Supplies | G22: Lõi giấy | H22: Phòng Sản xuất | I22: Dinh muc | K22: ='Dinh muc'!$G$19*'3.Thanh pham'!F$10 -> 0 | L22: ='Dinh muc'!$G$19*'3.Thanh pham'!G$10 -> 0 | M22: ='Dinh muc'!$G$19*'3.Thanh pham'!H$10 -> 0 | N22: ='Dinh muc'!$G$19*'3.Thanh pham'!I$10 -> 142416000 | O22: ='Dinh muc'!$G$19*'3.Thanh pham'!J$10 -> 142416000 | P22: ='Dinh muc'!$G$19*'3.Thanh pham'!K$10 -> 142416000 | Q22: ='Dinh muc'!$G$19*'3.Thanh pham'!L$10 -> 142416000 | R22: ='Dinh muc'!$G$19*'3.Thanh pham'!M$10 -> 142416000 | ... V22: ='Dinh muc'!$G$19*'3.Thanh pham'!Q$10 -> 142416000 | W22: =SUM(K22:V22) -> 1281744000
B23: 18 | D23: 6272000100 | E23: Chi phí vật liệu phục vụ SX | F23: Operating Supplies | G23: Pallet rHD D4-0986 DTR | H23: Phòng Sản xuất | I23: Dinh muc | K23: ='Dinh muc'!$G$20*'3.Thanh pham'!F$10 -> 0 | L23: ='Dinh muc'!$G$20*'3.Thanh pham'!G$10 -> 0 | M23: ='Dinh muc'!$G$20*'3.Thanh pham'!H$10 -> 0 | N23: ='Dinh muc'!$G$20*'3.Thanh pham'!I$10 -> 95952780 | O23: ='Dinh muc'!$G$20*'3.Thanh pham'!J$10 -> 95952780 | P23: ='Dinh muc'!$G$20*'3.Thanh pham'!K$10 -> 95952780 | Q23: ='Dinh muc'!$G$20*'3.Thanh pham'!L$10 -> 95952780 | R23: ='Dinh muc'!$G$20*'3.Thanh pham'!M$10 -> 95952780 | ... V23: ='Dinh muc'!$G$20*'3.Thanh pham'!Q$10 -> 95952780 | W23: =SUM(K23:V23) -> 863575020
B24: 19 | D24: 6272002101 | E24: Chi phí vật tư phân xưởng | F24: Operating Supplies | G24: Chi phí vật tư phân xưởng (ron) | K24: =SUM('Dinh muc'!$G$17:$G$20)*'3.Thanh pham'!F10 -> 0 | L24: =SUM('Dinh muc'!$G$17:$G$20)*'3.Thanh pham'!G10 -> 0 | M24: =SUM('Dinh muc'!$G$17:$G$20)*'3.Thanh pham'!H10 -> 0 | N24: =ROUND('Dinh muc'!$G$16*'3.Thanh pham'!I$10,0) -> 10467686 | O24: =ROUND('Dinh muc'!$G$16*'3.Thanh pham'!J$10,0) -> 10467686 | P24: =ROUND('Dinh muc'!$G$16*'3.Thanh pham'!K$10,0) -> 10467686 | Q24: =ROUND('Dinh muc'!$G$16*'3.Thanh pham'!L$10,0) -> 10467686 | R24: =ROUND('Dinh muc'!$G$16*'3.Thanh pham'!M$10,0) -> 10467686 | S24: =ROUND('Dinh muc'!$G$16*'3.Thanh pham'!N$10,0) -> 10467686 | T24: =ROUND('Dinh muc'!$G$16*'3.Thanh pham'!O$10,0) -> 10467686 | U24: =ROUND('Dinh muc'!$G$16*'3.Thanh pham'!P$10,0) -> 10467686 | V24: =ROUND('Dinh muc'!$G$16*'3.Thanh pham'!Q$10,0) -> 10467686 | W24: =SUM(K24:V24) -> 94209174
B25: 19 | D25: 6272002101 | E25: Chi phí vật tư phân xưởng | F25: Operating Supplies | G25: Cp nước | K25: =SUM('Dinh muc'!$G$15:$G$16)*'3.Thanh pham'!F$10 -> 0 | L25: =SUM('Dinh muc'!$G$15:$G$16)*'3.Thanh pham'!G$10 -> 0 | M25: =SUM('Dinh muc'!$G$15:$G$16)*'3.Thanh pham'!H$10 -> 0 | N25: =SUM('Dinh muc'!$G$15:$G$16)*'3.Thanh pham'!I$10 -> 23163686 | O25: =SUM('Dinh muc'!$G$15:$G$16)*'3.Thanh pham'!J$10 -> 23163686 | P25: =SUM('Dinh muc'!$G$15:$G$16)*'3.Thanh pham'!K$10 -> 23163686 | Q25: =SUM('Dinh muc'!$G$15:$G$16)*'3.Thanh pham'!L$10 -> 23163686 | R25: =SUM('Dinh muc'!$G$15:$G$16)*'3.Thanh pham'!M$10 -> 23163686 | ... V25: =SUM('Dinh muc'!$G$15:$G$16)*'3.Thanh pham'!Q$10 -> 23163686 | W25: =SUM(K25:V25) -> 2.0847318e+08
B26: 20 | D26: 6272003502 | E26: Chi phí xăng dầu xe du lịch, xe gắn máy, xe nâng | F26: Energy Expenses | G26: Xăng dầu xe nâng | H26: Phòng Kho vận | I26: Dinh muc | K26: ='Dinh muc'!$G$21*'3.Thanh pham'!F$10 -> 0 | L26: ='Dinh muc'!$G$21*'3.Thanh pham'!G$10 -> 0 | M26: ='Dinh muc'!$G$21*'3.Thanh pham'!H$10 -> 0 | N26: ='Dinh muc'!$G$21*'3.Thanh pham'!I$10 -> 35190000 | O26: ='Dinh muc'!$G$21*'3.Thanh pham'!J$10 -> 35190000 | P26: ='Dinh muc'!$G$21*'3.Thanh pham'!K$10 -> 35190000 | Q26: ='Dinh muc'!$G$21*'3.Thanh pham'!L$10 -> 35190000 | R26: ='Dinh muc'!$G$21*'3.Thanh pham'!M$10 -> 35190000 | ... V26: ='Dinh muc'!$G$21*'3.Thanh pham'!Q$10 -> 35190000 | W26: =SUM(K26:V26) -> 316710000
B28: II | E28: ĐỊNH PHÍ | J28: =SUM(J29:J57) -> 0 | K28: =SUM(K29:K57) -> 0 | L28: =SUM(L29:L57) -> 0 | M28: =SUM(M29:M57) -> 0 | N28: =SUM(N29:N57) -> 1.3030806e+08 | O28: =SUM(O29:O57) -> 1.3030806e+08 | P28: =SUM(P29:P57) -> 1.3030806e+08 | Q28: =SUM(Q29:Q57) -> 1.3030806e+08 | ... W28: =SUM(W29:W57) -> 1.1727726e+09
B29: 1 | D29: 6271002604 | E29: Chi phí lương chính - Gián tiếp | F29: Salary and Wages - Support | G29: Chi phí lương chính - Gián tiếp | H29: Phòng Hành chánh nhân sự | I29: LUONG | K29: =SUM('Dinh muc'!$G$11:$G$12)*'3.Thanh pham'!F$10 -> 0 | L29: =SUM('Dinh muc'!$G$11:$G$12)*'3.Thanh pham'!G$10 -> 0 | M29: =SUM('Dinh muc'!$G$11:$G$12)*'3.Thanh pham'!H$10 -> 0 | N29: =SUM('Dinh muc'!$G$11:$G$12)*'3.Thanh pham'!I$10 -> 74738500 | O29: =SUM('Dinh muc'!$G$11:$G$12)*'3.Thanh pham'!J$10 -> 74738500 | P29: =SUM('Dinh muc'!$G$11:$G$12)*'3.Thanh pham'!K$10 -> 74738500 | Q29: =SUM('Dinh muc'!$G$11:$G$12)*'3.Thanh pham'!L$10 -> 74738500 | R29: =SUM('Dinh muc'!$G$11:$G$12)*'3.Thanh pham'!M$10 -> 74738500 | ... V29: =SUM('Dinh muc'!$G$11:$G$12)*'3.Thanh pham'!Q$10 -> 74738500 | W29: =SUM(K29:V29) -> 672646500
B30: 2 | D30: 6271002605 | E30: Chi phí lương T13, phép năm - Gián tiếp | F30: Salary and Wages - Support | G30: Chi phí lương T13, phép năm - Gián tiếp | H30: Phòng Hành chánh nhân sự | I30: LUONG | W30: =SUM(K30:V30) -> 0
B31: 3 | D31: 6271002802 | E31: Chi phí khen thưởng - Gián tiếp | F31: Employee Welfare | G31: Chi phí khen thưởng - Gián tiếp | H31: Phòng Hành chánh nhân sự | I31: LUONG | W31: =SUM(K31:V31) -> 0
B32: 4 | D32: 6271002806 | E32: Thưởng danh hiệu - Gián tiếp | F32: Salary and Wages - Support | G32: Thưởng danh hiệu - Gián tiếp | H32: Phòng Hành chánh nhân sự | I32: LUONG | W32: =SUM(K32:V32) -> 0
B33: 5 | D33: 6271007202 | E33: Chi phí khen thưởng, bồi dưỡng khác | F33: Employee Welfare | G33: Chi phí khen thưởng, bồi dưỡng khác | H33: Phòng Hành chánh nhân sự | I33: LUONG | W33: =SUM(K33:V33) -> 0
B34: 6 | D34: 6271003202 | E34: Tiền ăn giữa ca - Gián tiếp | F34: Employee Welfare | G34: Tiền ăn giữa ca - Gián tiếp | H34: Phòng Hành chánh nhân sự | I34: LUONG | K34: ='Dinh muc'!$G$13*'3.Thanh pham'!F$10 -> 0 | L34: ='Dinh muc'!$G$13*'3.Thanh pham'!G$10 -> 0 | M34: ='Dinh muc'!$G$13*'3.Thanh pham'!H$10 -> 0 | N34: ='Dinh muc'!$G$13*'3.Thanh pham'!I$10 -> 5750000 | O34: ='Dinh muc'!$G$13*'3.Thanh pham'!J$10 -> 5750000 | P34: ='Dinh muc'!$G$13*'3.Thanh pham'!K$10 -> 5750000 | Q34: ='Dinh muc'!$G$13*'3.Thanh pham'!L$10 -> 5750000 | R34: ='Dinh muc'!$G$13*'3.Thanh pham'!M$10 -> 5750000 | ... V34: ='Dinh muc'!$G$13*'3.Thanh pham'!Q$10 -> 5750000 | W34: =SUM(K34:V34) -> 51750000
B35: 7 | D35: 6271002603 | E35: Phụ cấp ca đêm - Gián tiếp | F35: Salary and Wages - Support | G35: Phụ cấp ca đêm - Gián tiếp | H35: Phòng Hành chánh nhân sự | I35: LUONG | W35: =SUM(K35:V35) -> 0
B36: 8 | D36: 6271003401 | E36: BHXH, BHYT, KPCĐ, BHTN - Gián tiếp | F36: Employee Welfare | G36: BHXH, BHYT, KPCĐ, BHTN - Gián tiếp | H36: Phòng Hành chánh nhân sự | I36: LUONG | W36: =SUM(K36:V36) -> 0
B37: 9 | D37: 6271002703 | E37: Chi phí lương ngoài giờ - Gián tiếp | F37: Salary and Wages - Support | G37: Chi phí lương ngoài giờ - Gián tiếp | H37: Phòng Hành chánh nhân sự | I37: LUONG | W37: =SUM(K37:V37) -> 0
B38: 10 | D38: 6220002901 | E38: Chi phí trợ cấp thôi việc - Trực tiếp | F38: Employee Benefits Expenses | G38: Chi phí trợ cấp thôi việc - Trực tiếp | H38: Phòng Hành chánh nhân sự | I38: BP Phat sinh | W38: =SUM(K38:V38) -> 0
B39: 11 | D39: 6271003001 | E39: Chi phí đồng phục | F39: Employee Welfare | G39: Chi phí đồng phục | H39: Phòng Hành chánh nhân sự | I39: Phan bo | W39: =SUM(K39:V39) -> 0
B40: 12 | D40: 6277003101 | E40: Chi phí y tế, BH sức khỏe | F40: Employee Welfare | G40: Chi Phí Y Tế, BH Sức Khỏe, BH 24/24 | H40: Phòng Hành chánh nhân sự | I40: Phan bo | W40: =SUM(K40:V40) -> 0
B41: 13 | D41: 6273000100 | E41: Chi phí công cụ dụng cụ phục vụ SX | F41: Tools and Equipments | G41: Chi phí công cụ dụng cụ phục vụ SX | H41: Phòng Sản xuất | I41: BP Phat sinh | N41: =2*750*26500/12 -> 3312500 | O41: =2*750*26500/12 -> 3312500 | P41: =2*750*26500/12 -> 3312500 | Q41: =2*750*26500/12 -> 3312500 | R41: =2*750*26500/12 -> 3312500 | S41: =2*750*26500/12 -> 3312500 | T41: =2*750*26500/12 -> 3312500 | U41: =2*750*26500/12 -> 3312500 | V41: =2*750*26500/12 -> 3312500 | W41: =SUM(K41:V41) -> 29812500
B42: 14 | D42: 6275001803 | E42: Chi phí nước sinh hoạt | F42: Energy Expenses | G42: Chi phí nước sinh hoạt | H42: Phòng Sản xuất | I42: BP Phat sinh | W42: =SUM(K42:V42) -> 0
B43: 15 | D43: 6277002804 | E43: Tiền nước uống | F43: Miscellaneous Expenses | G43: Tiền nước uống | H43: Phòng Hành chánh nhân sự | I43: BP Phat sinh | W43: =SUM(K43:V43) -> 0
...

Sheet CPSX Kg
B3: I - CHI PHÍ SẢN XUẤT PET | W3: ĐVT: Đồng/kg
B4: STT | C4: Dự phòng | D4: Mã tài khoản (Mã Chi phí_L4) | E4: Tên tài khoản (Cost elements 2) | F4: Chi Phí_L5 (Cost Group 2) | G4: Chi tiết | H4: Phòng ban | I4: Tham chiếu | J4: % CP/DT 2026 | K4: T1 | L4: T2 | M4: T3 | N4: T4 | O4: T5 | P4: T6 | Q4: T7 | R4: T8 | S4: T9 | T4: T10 | U4: T11 | V4: T12 | W4: KH 2026
B5: 1.1 | E5: BIẾN PHÍ | J5: =SUM(J6:J27) -> 0 | K5: =SUM(K6:K27) -> 0 | L5: =SUM(L6:L27) -> 0 | M5: =SUM(M6:M27) -> 0 | N5: =SUM(N6:N27) -> 5231 | O5: =SUM(O6:O27) -> 5231 | P5: =SUM(P6:P27) -> 5231 | Q5: =SUM(Q6:Q27) -> 5231 | ... W5: =SUM(W6:W27) -> 5231
B6: 1 | D6: 6220002601 | E6: Chi phí lương chính - Trực tiếp | F6: Salary and Wages - Direct | G6: Chi phí lương chính - Trực tiếp | H6: Phòng Hành chánh nhân sự | I6: LUONG | K6: ='Dinh muc'!$G$8*'3.Thanh pham'!F$10 -> 0 | L6: ='Dinh muc'!$G$8*'3.Thanh pham'!G$10 -> 0 | M6: ='Dinh muc'!$G$8*'3.Thanh pham'!H$10 -> 0 | N6: =ROUND(CPSX!N6/'4.Doanh thu'!I$11,0) -> 304 | O6: =ROUND(CPSX!O6/'4.Doanh thu'!J$11,0) -> 304 | P6: =ROUND(CPSX!P6/'4.Doanh thu'!K$11,0) -> 304 | Q6: =ROUND(CPSX!Q6/'4.Doanh thu'!L$11,0) -> 304 | R6: =ROUND(CPSX!R6/'4.Doanh thu'!M$11,0) -> 304 | S6: =ROUND(CPSX!S6/'4.Doanh thu'!N$11,0) -> 304 | T6: =ROUND(CPSX!T6/'4.Doanh thu'!O$11,0) -> 304 | U6: =ROUND(CPSX!U6/'4.Doanh thu'!P$11,0) -> 304 | V6: =ROUND(CPSX!V6/'4.Doanh thu'!Q$11,0) -> 304 | W6: =AVERAGE(N6:V6) -> 304
B7: 2 | D7: 6220002602 | E7: Chi phí lương T13, phép năm - Trực tiếp | F7: Salary and Wages - Direct | G7: Chi phí lương T13, phép năm - Trực tiếp | H7: Phòng Hành chánh nhân sự | I7: LUONG | N7: =ROUND(CPSX!N7/'4.Doanh thu'!I$11,0) -> 0 | O7: =ROUND(CPSX!O7/'4.Doanh thu'!J$11,0) -> 0 | P7: =ROUND(CPSX!P7/'4.Doanh thu'!K$11,0) -> 0 | Q7: =ROUND(CPSX!Q7/'4.Doanh thu'!L$11,0) -> 0 | R7: =ROUND(CPSX!R7/'4.Doanh thu'!M$11,0) -> 0 | S7: =ROUND(CPSX!S7/'4.Doanh thu'!N$11,0) -> 0 | T7: =ROUND(CPSX!T7/'4.Doanh thu'!O$11,0) -> 0 | U7: =ROUND(CPSX!U7/'4.Doanh thu'!P$11,0) -> 0 | V7: =ROUND(CPSX!V7/'4.Doanh thu'!Q$11,0) -> 0 | W7: =AVERAGE(N7:V7) -> 0
B8: 3 | D8: 6220002802 | E8: Chi phí khen thưởng - Trực tiếp | F8: Employee Welfare | G8: Chi phí khen thưởng - Trực tiếp | H8: Phòng Hành chánh nhân sự | I8: LUONG | N8: =ROUND(CPSX!N8/'4.Doanh thu'!I$11,0) -> 0 | O8: =ROUND(CPSX!O8/'4.Doanh thu'!J$11,0) -> 0 | P8: =ROUND(CPSX!P8/'4.Doanh thu'!K$11,0) -> 0 | Q8: =ROUND(CPSX!Q8/'4.Doanh thu'!L$11,0) -> 0 | R8: =ROUND(CPSX!R8/'4.Doanh thu'!M$11,0) -> 0 | S8: =ROUND(CPSX!S8/'4.Doanh thu'!N$11,0) -> 0 | T8: =ROUND(CPSX!T8/'4.Doanh thu'!O$11,0) -> 0 | U8: =ROUND(CPSX!U8/'4.Doanh thu'!P$11,0) -> 0 | V8: =ROUND(CPSX!V8/'4.Doanh thu'!Q$11,0) -> 0 | W8: =AVERAGE(N8:V8) -> 0
B9: 4 | D9: 6220002806 | E9: Thưởng danh hiệu - Trực tiếp | F9: Salary and Wages - Direct | G9: Thưởng danh hiệu - Trực tiếp | H9: Phòng Hành chánh nhân sự | I9: LUONG | N9: =ROUND(CPSX!N9/'4.Doanh thu'!I$11,0) -> 0 | O9: =ROUND(CPSX!O9/'4.Doanh thu'!J$11,0) -> 0 | P9: =ROUND(CPSX!P9/'4.Doanh thu'!K$11,0) -> 0 | Q9: =ROUND(CPSX!Q9/'4.Doanh thu'!L$11,0) -> 0 | R9: =ROUND(CPSX!R9/'4.Doanh thu'!M$11,0) -> 0 | S9: =ROUND(CPSX!S9/'4.Doanh thu'!N$11,0) -> 0 | T9: =ROUND(CPSX!T9/'4.Doanh thu'!O$11,0) -> 0 | U9: =ROUND(CPSX!U9/'4.Doanh thu'!P$11,0) -> 0 | V9: =ROUND(CPSX!V9/'4.Doanh thu'!Q$11,0) -> 0 | W9: =AVERAGE(N9:V9) -> 0
B10: 5 | D10: 6220007202 | E10: Chi phí khen thưởng, bồi dưỡng khác | F10: Employee Welfare | G10: Chi phí khen thưởng, bồi dưỡng khác | H10: Phòng Hành chánh nhân sự | I10: LUONG | N10: =ROUND(CPSX!N10/'4.Doanh thu'!I$11,0) -> 0 | O10: =ROUND(CPSX!O10/'4.Doanh thu'!J$11,0) -> 0 | P10: =ROUND(CPSX!P10/'4.Doanh thu'!K$11,0) -> 0 | Q10: =ROUND(CPSX!Q10/'4.Doanh thu'!L$11,0) -> 0 | R10: =ROUND(CPSX!R10/'4.Doanh thu'!M$11,0) -> 0 | S10: =ROUND(CPSX!S10/'4.Doanh thu'!N$11,0) -> 0 | T10: =ROUND(CPSX!T10/'4.Doanh thu'!O$11,0) -> 0 | U10: =ROUND(CPSX!U10/'4.Doanh thu'!P$11,0) -> 0 | V10: =ROUND(CPSX!V10/'4.Doanh thu'!Q$11,0) -> 0 | W10: =AVERAGE(N10:V10) -> 0
B11: 6 | D11: 6220003201 | E11: Tiền ăn giữa ca - Trực tiếp | F11: Employee Welfare | G11: Tiền ăn giữa ca - Trực tiếp | H11: Phòng Hành chánh nhân sự | I11: LUONG | K11: ='Dinh muc'!$G$9*'3.Thanh pham'!F$10 -> 0 | L11: ='Dinh muc'!$G$9*'3.Thanh pham'!G$10 -> 0 | M11: ='Dinh muc'!$G$9*'3.Thanh pham'!H$10 -> 0 | N11: =ROUND(CPSX!N11/'4.Doanh thu'!I$11,0) -> 32 | O11: =ROUND(CPSX!O11/'4.Doanh thu'!J$11,0) -> 32 | P11: =ROUND(CPSX!P11/'4.Doanh thu'!K$11,0) -> 32 | Q11: =ROUND(CPSX!Q11/'4.Doanh thu'!L$11,0) -> 32 | R11: =ROUND(CPSX!R11/'4.Doanh thu'!M$11,0) -> 32 | S11: =ROUND(CPSX!S11/'4.Doanh thu'!N$11,0) -> 32 | T11: =ROUND(CPSX!T11/'4.Doanh thu'!O$11,0) -> 32 | U11: =ROUND(CPSX!U11/'4.Doanh thu'!P$11,0) -> 32 | V11: =ROUND(CPSX!V11/'4.Doanh thu'!Q$11,0) -> 32 | W11: =AVERAGE(N11:V11) -> 32
B12: 7 | D12: 6220002603 | E12: Phụ cấp ca đêm - Trực tiếp | F12: Salary and Wages - Direct | G12: Phụ cấp ca đêm - Trực tiếp | H12: Phòng Hành chánh nhân sự | I12: LUONG | N12: =ROUND(CPSX!N12/'4.Doanh thu'!I$11,0) -> 0 | O12: =ROUND(CPSX!O12/'4.Doanh thu'!J$11,0) -> 0 | P12: =ROUND(CPSX!P12/'4.Doanh thu'!K$11,0) -> 0 | Q12: =ROUND(CPSX!Q12/'4.Doanh thu'!L$11,0) -> 0 | R12: =ROUND(CPSX!R12/'4.Doanh thu'!M$11,0) -> 0 | S12: =ROUND(CPSX!S12/'4.Doanh thu'!N$11,0) -> 0 | T12: =ROUND(CPSX!T12/'4.Doanh thu'!O$11,0) -> 0 | U12: =ROUND(CPSX!U12/'4.Doanh thu'!P$11,0) -> 0 | V12: =ROUND(CPSX!V12/'4.Doanh thu'!Q$11,0) -> 0 | W12: =AVERAGE(N12:V12) -> 0
B13: 8 | D13: 6220003401 | E13: BHXH, BHYT, KPCĐ, BHTN - Trực tiếp | F13: Employee Welfare | G13: BHXH, BHYT, KPCĐ, BHTN - Trực tiếp | H13: Phòng Hành chánh nhân sự | I13: LUONG | N13: =ROUND(CPSX!N13/'4.Doanh thu'!I$11,0) -> 0 | O13: =ROUND(CPSX!O13/'4.Doanh thu'!J$11,0) -> 0 | P13: =ROUND(CPSX!P13/'4.Doanh thu'!K$11,0) -> 0 | Q13: =ROUND(CPSX!Q13/'4.Doanh thu'!L$11,0) -> 0 | R13: =ROUND(CPSX!R13/'4.Doanh thu'!M$11,0) -> 0 | S13: =ROUND(CPSX!S13/'4.Doanh thu'!N$11,0) -> 0 | T13: =ROUND(CPSX!T13/'4.Doanh thu'!O$11,0) -> 0 | U13: =ROUND(CPSX!U13/'4.Doanh thu'!P$11,0) -> 0 | V13: =ROUND(CPSX!V13/'4.Doanh thu'!Q$11,0) -> 0 | W13: =AVERAGE(N13:V13) -> 0
B14: 9 | D14: 6220002701 | E14: Chi phí lương ngoài giờ - Trực tiếp | F14: Salary and Wages - Direct | G14: Chi phí lương ngoài giờ - Trực tiếp | H14: Phòng Hành chánh nhân sự | I14: LUONG | N14: =ROUND(CPSX!N14/'4.Doanh thu'!I$11,0) -> 0 | O14: =ROUND(CPSX!O14/'4.Doanh thu'!J$11,0) -> 0 | P14: =ROUND(CPSX!P14/'4.Doanh thu'!K$11,0) -> 0 | Q14: =ROUND(CPSX!Q14/'4.Doanh thu'!L$11,0) -> 0 | R14: =ROUND(CPSX!R14/'4.Doanh thu'!M$11,0) -> 0 | S14: =ROUND(CPSX!S14/'4.Doanh thu'!N$11,0) -> 0 | T14: =ROUND(CPSX!T14/'4.Doanh thu'!O$11,0) -> 0 | U14: =ROUND(CPSX!U14/'4.Doanh thu'!P$11,0) -> 0 | V14: =ROUND(CPSX!V14/'4.Doanh thu'!Q$11,0) -> 0 | W14: =AVERAGE(N14:V14) -> 0
B15: 10 | D15: 6220002901 | E15: Chi phí trợ cấp thôi việc - Trực tiếp | F15: Employee Benefits Expenses | G15: Chi phí trợ cấp thôi việc - Trực tiếp | H15: Phòng Hành chánh nhân sự | I15: LUONG | N15: =ROUND(CPSX!N15/'4.Doanh thu'!I$11,0) -> 0 | O15: =ROUND(CPSX!O15/'4.Doanh thu'!J$11,0) -> 0 | P15: =ROUND(CPSX!P15/'4.Doanh thu'!K$11,0) -> 0 | Q15: =ROUND(CPSX!Q15/'4.Doanh thu'!L$11,0) -> 0 | R15: =ROUND(CPSX!R15/'4.Doanh thu'!M$11,0) -> 0 | S15: =ROUND(CPSX!S15/'4.Doanh thu'!N$11,0) -> 0 | T15: =ROUND(CPSX!T15/'4.Doanh thu'!O$11,0) -> 0 | U15: =ROUND(CPSX!U15/'4.Doanh thu'!P$11,0) -> 0 | V15: =ROUND(CPSX!V15/'4.Doanh thu'!Q$11,0) -> 0 | W15: =AVERAGE(N15:V15) -> 0
B16: 11 | D16: 6220003001 | E16: Chi phí đồng phục | F16: Employee Welfare | G16: Chi phí đồng phục | H16: Phòng Hành chánh nhân sự | I16: Phan bo | N16: =ROUND(CPSX!N16/'4.Doanh thu'!I$11,0) -> 0 | O16: =ROUND(CPSX!O16/'4.Doanh thu'!J$11,0) -> 0 | P16: =ROUND(CPSX!P16/'4.Doanh thu'!K$11,0) -> 0 | Q16: =ROUND(CPSX!Q16/'4.Doanh thu'!L$11,0) -> 0 | R16: =ROUND(CPSX!R16/'4.Doanh thu'!M$11,0) -> 0 | S16: =ROUND(CPSX!S16/'4.Doanh thu'!N$11,0) -> 0 | T16: =ROUND(CPSX!T16/'4.Doanh thu'!O$11,0) -> 0 | U16: =ROUND(CPSX!U16/'4.Doanh thu'!P$11,0) -> 0 | V16: =ROUND(CPSX!V16/'4.Doanh thu'!Q$11,0) -> 0 | W16: =AVERAGE(N16:V16) -> 0
B17: 12 | E17: Chi phí y tế, BH sức khỏe | F17: Employee Welfare | G17: Chi Phí Y Tế, BH Sức Khỏe, BH 24/24 | H17: Phòng Hành chánh nhân sự | I17: Phan bo | N17: =ROUND(CPSX!N17/'4.Doanh thu'!I$11,0) -> 0 | O17: =ROUND(CPSX!O17/'4.Doanh thu'!J$11,0) -> 0 | P17: =ROUND(CPSX!P17/'4.Doanh thu'!K$11,0) -> 0 | Q17: =ROUND(CPSX!Q17/'4.Doanh thu'!L$11,0) -> 0 | R17: =ROUND(CPSX!R17/'4.Doanh thu'!M$11,0) -> 0 | S17: =ROUND(CPSX!S17/'4.Doanh thu'!N$11,0) -> 0 | T17: =ROUND(CPSX!T17/'4.Doanh thu'!O$11,0) -> 0 | U17: =ROUND(CPSX!U17/'4.Doanh thu'!P$11,0) -> 0 | V17: =ROUND(CPSX!V17/'4.Doanh thu'!Q$11,0) -> 0 | W17: =AVERAGE(N17:V17) -> 0
B18: 13 | D18: 6275001801 | E18: Chi phí điện sản xuất | F18: Direct Cost of Goods sold | G18: Chi phí điện sản xuất | H18: Phòng Kỹ thuật | I18: Dinh muc | K18: ='Dinh muc'!$G$14*'3.Thanh pham'!F$10 -> 0 | L18: ='Dinh muc'!$G$14*'3.Thanh pham'!G$10 -> 0 | M18: ='Dinh muc'!$G$14*'3.Thanh pham'!H$10 -> 0 | N18: =ROUND(CPSX!N18/'4.Doanh thu'!I$11,0) -> 2570 | O18: =ROUND(CPSX!O18/'4.Doanh thu'!J$11,0) -> 2570 | P18: =ROUND(CPSX!P18/'4.Doanh thu'!K$11,0) -> 2570 | Q18: =ROUND(CPSX!Q18/'4.Doanh thu'!L$11,0) -> 2570 | R18: =ROUND(CPSX!R18/'4.Doanh thu'!M$11,0) -> 2570 | S18: =ROUND(CPSX!S18/'4.Doanh thu'!N$11,0) -> 2570 | T18: =ROUND(CPSX!T18/'4.Doanh thu'!O$11,0) -> 2570 | U18: =ROUND(CPSX!U18/'4.Doanh thu'!P$11,0) -> 2570 | V18: =ROUND(CPSX!V18/'4.Doanh thu'!Q$11,0) -> 2570 | W18: =AVERAGE(N18:V18) -> 2570
B19: 14 | D19: 6272000100 | E19: Chi phí vật liệu phục vụ SX | F19: Operating Supplies | H19: Phòng Kỹ thuật | I19: Dinh muc | N19: =ROUND(CPSX!N19/'4.Doanh thu'!I$11,0) -> 0 | O19: =ROUND(CPSX!O19/'4.Doanh thu'!J$11,0) -> 0 | P19: =ROUND(CPSX!P19/'4.Doanh thu'!K$11,0) -> 0 | Q19: =ROUND(CPSX!Q19/'4.Doanh thu'!L$11,0) -> 0 | R19: =ROUND(CPSX!R19/'4.Doanh thu'!M$11,0) -> 0 | S19: =ROUND(CPSX!S19/'4.Doanh thu'!N$11,0) -> 0 | T19: =ROUND(CPSX!T19/'4.Doanh thu'!O$11,0) -> 0 | U19: =ROUND(CPSX!U19/'4.Doanh thu'!P$11,0) -> 0 | V19: =ROUND(CPSX!V19/'4.Doanh thu'!Q$11,0) -> 0 | W19: =AVERAGE(N19:V19) -> 0
B20: 15 | D20: 6272000100 | E20: Chi phí vật liệu phục vụ SX | F20: Operating Supplies | G20: Lõi lọc - Màng … | H20: Phòng Sản xuất | I20: Dinh muc | N20: =ROUND(CPSX!N20/'4.Doanh thu'!I$11,0) -> 0 | O20: =ROUND(CPSX!O20/'4.Doanh thu'!J$11,0) -> 0 | P20: =ROUND(CPSX!P20/'4.Doanh thu'!K$11,0) -> 0 | Q20: =ROUND(CPSX!Q20/'4.Doanh thu'!L$11,0) -> 0 | R20: =ROUND(CPSX!R20/'4.Doanh thu'!M$11,0) -> 0 | S20: =ROUND(CPSX!S20/'4.Doanh thu'!N$11,0) -> 0 | T20: =ROUND(CPSX!T20/'4.Doanh thu'!O$11,0) -> 0 | U20: =ROUND(CPSX!U20/'4.Doanh thu'!P$11,0) -> 0 | V20: =ROUND(CPSX!V20/'4.Doanh thu'!Q$11,0) -> 0 | W20: =AVERAGE(N20:V20) -> 0 | X20: Trường hợp sản xuất 2 công đoạn: Phân loại chai và băm vảy thì chỉ tính sản lượng chai dùng dây đai
B21: 16 | D21: 6272000100 | E21: Chi phí vật liệu phục vụ SX | F21: Operating Supplies | G21: Cuộn Màng PE | H21: Phòng Sản xuất | I21: Dinh muc | K21: ='Dinh muc'!$G$18*'3.Thanh pham'!F$10 -> 0 | L21: ='Dinh muc'!$G$18*'3.Thanh pham'!G$10 -> 0 | M21: ='Dinh muc'!$G$18*'3.Thanh pham'!H$10 -> 0 | N21: =ROUND(CPSX!N21/'4.Doanh thu'!I$11,0) -> 167 | O21: =ROUND(CPSX!O21/'4.Doanh thu'!J$11,0) -> 167 | P21: =ROUND(CPSX!P21/'4.Doanh thu'!K$11,0) -> 167 | Q21: =ROUND(CPSX!Q21/'4.Doanh thu'!L$11,0) -> 167 | R21: =ROUND(CPSX!R21/'4.Doanh thu'!M$11,0) -> 167 | S21: =ROUND(CPSX!S21/'4.Doanh thu'!N$11,0) -> 167 | T21: =ROUND(CPSX!T21/'4.Doanh thu'!O$11,0) -> 167 | U21: =ROUND(CPSX!U21/'4.Doanh thu'!P$11,0) -> 167 | V21: =ROUND(CPSX!V21/'4.Doanh thu'!Q$11,0) -> 167 | W21: =AVERAGE(N21:V21) -> 167
B22: 17 | D22: 6272000100 | E22: Chi phí vật liệu phục vụ SX | F22: Operating Supplies | G22: Lõi giấy | H22: Phòng Sản xuất | I22: Dinh muc | K22: ='Dinh muc'!$G$19*'3.Thanh pham'!F$10 -> 0 | L22: ='Dinh muc'!$G$19*'3.Thanh pham'!G$10 -> 0 | M22: ='Dinh muc'!$G$19*'3.Thanh pham'!H$10 -> 0 | N22: =ROUND(CPSX!N22/'4.Doanh thu'!I$11,0) -> 1000 | O22: =ROUND(CPSX!O22/'4.Doanh thu'!J$11,0) -> 1000 | P22: =ROUND(CPSX!P22/'4.Doanh thu'!K$11,0) -> 1000 | Q22: =ROUND(CPSX!Q22/'4.Doanh thu'!L$11,0) -> 1000 | R22: =ROUND(CPSX!R22/'4.Doanh thu'!M$11,0) -> 1000 | S22: =ROUND(CPSX!S22/'4.Doanh thu'!N$11,0) -> 1000 | T22: =ROUND(CPSX!T22/'4.Doanh thu'!O$11,0) -> 1000 | U22: =ROUND(CPSX!U22/'4.Doanh thu'!P$11,0) -> 1000 | V22: =ROUND(CPSX!V22/'4.Doanh thu'!Q$11,0) -> 1000 | W22: =AVERAGE(N22:V22) -> 1000
B23: 18 | D23: 6272000100 | E23: Chi phí vật liệu phục vụ SX | F23: Operating Supplies | G23: Pallet rHD D4-0986 DTR | H23: Phòng Sản xuất | I23: Dinh muc | K23: ='Dinh muc'!$G$20*'3.Thanh pham'!F$10 -> 0 | L23: ='Dinh muc'!$G$20*'3.Thanh pham'!G$10 -> 0 | M23: ='Dinh muc'!$G$20*'3.Thanh pham'!H$10 -> 0 | N23: =ROUND(CPSX!N23/'4.Doanh thu'!I$11,0) -> 674 | O23: =ROUND(CPSX!O23/'4.Doanh thu'!J$11,0) -> 674 | P23: =ROUND(CPSX!P23/'4.Doanh thu'!K$11,0) -> 674 | Q23: =ROUND(CPSX!Q23/'4.Doanh thu'!L$11,0) -> 674 | R23: =ROUND(CPSX!R23/'4.Doanh thu'!M$11,0) -> 674 | S23: =ROUND(CPSX!S23/'4.Doanh thu'!N$11,0) -> 674 | T23: =ROUND(CPSX!T23/'4.Doanh thu'!O$11,0) -> 674 | U23: =ROUND(CPSX!U23/'4.Doanh thu'!P$11,0) -> 674 | V23: =ROUND(CPSX!V23/'4.Doanh thu'!Q$11,0) -> 674 | W23: =AVERAGE(N23:V23) -> 674
B24: 19 | D24: 6272002101 | E24: Chi phí vật tư phân xưởng | F24: Operating Supplies | G24: Chi phí vật tư phân xưởng (ron) | K24: =SUM('Dinh muc'!$G$17:$G$20)*'3.Thanh pham'!F10 -> 0 | L24: =SUM('Dinh muc'!$G$17:$G$20)*'3.Thanh pham'!G10 -> 0 | M24: =SUM('Dinh muc'!$G$17:$G$20)*'3.Thanh pham'!H10 -> 0 | N24: =ROUND(CPSX!N24/'4.Doanh thu'!I$11,0) -> 74 | O24: =ROUND(CPSX!O24/'4.Doanh thu'!J$11,0) -> 74 | P24: =ROUND(CPSX!P24/'4.Doanh thu'!K$11,0) -> 74 | Q24: =ROUND(CPSX!Q24/'4.Doanh thu'!L$11,0) -> 74 | R24: =ROUND(CPSX!R24/'4.Doanh thu'!M$11,0) -> 74 | S24: =ROUND(CPSX!S24/'4.Doanh thu'!N$11,0) -> 74 | T24: =ROUND(CPSX!T24/'4.Doanh thu'!O$11,0) -> 74 | U24: =ROUND(CPSX!U24/'4.Doanh thu'!P$11,0) -> 74 | V24: =ROUND(CPSX!V24/'4.Doanh thu'!Q$11,0) -> 74 | W24: =AVERAGE(N24:V24) -> 74
B25: 19 | D25: 6272002101 | E25: Chi phí vật tư phân xưởng | F25: Operating Supplies | G25: Cp nước | K25: =SUM('Dinh muc'!$G$15:$G$16)*'3.Thanh pham'!F$10 -> 0 | L25: =SUM('Dinh muc'!$G$15:$G$16)*'3.Thanh pham'!G$10 -> 0 | M25: =SUM('Dinh muc'!$G$15:$G$16)*'3.Thanh pham'!H$10 -> 0 | N25: =ROUND(CPSX!N25/'4.Doanh thu'!I$11,0) -> 163 | O25: =ROUND(CPSX!O25/'4.Doanh thu'!J$11,0) -> 163 | P25: =ROUND(CPSX!P25/'4.Doanh thu'!K$11,0) -> 163 | Q25: =ROUND(CPSX!Q25/'4.Doanh thu'!L$11,0) -> 163 | R25: =ROUND(CPSX!R25/'4.Doanh thu'!M$11,0) -> 163 | S25: =ROUND(CPSX!S25/'4.Doanh thu'!N$11,0) -> 163 | T25: =ROUND(CPSX!T25/'4.Doanh thu'!O$11,0) -> 163 | U25: =ROUND(CPSX!U25/'4.Doanh thu'!P$11,0) -> 163 | V25: =ROUND(CPSX!V25/'4.Doanh thu'!Q$11,0) -> 163 | W25: =AVERAGE(N25:V25) -> 163
B26: 20 | D26: 6272003502 | E26: Chi phí xăng dầu xe du lịch, xe gắn máy, xe nâng | F26: Energy Expenses | G26: Xăng dầu xe nâng | H26: Phòng Kho vận | I26: Dinh muc | K26: ='Dinh muc'!$G$21*'3.Thanh pham'!F$10 -> 0 | L26: ='Dinh muc'!$G$21*'3.Thanh pham'!G$10 -> 0 | M26: ='Dinh muc'!$G$21*'3.Thanh pham'!H$10 -> 0 | N26: =ROUND(CPSX!N26/'4.Doanh thu'!I$11,0) -> 247 | O26: =ROUND(CPSX!O26/'4.Doanh thu'!J$11,0) -> 247 | P26: =ROUND(CPSX!P26/'4.Doanh thu'!K$11,0) -> 247 | Q26: =ROUND(CPSX!Q26/'4.Doanh thu'!L$11,0) -> 247 | R26: =ROUND(CPSX!R26/'4.Doanh thu'!M$11,0) -> 247 | S26: =ROUND(CPSX!S26/'4.Doanh thu'!N$11,0) -> 247 | T26: =ROUND(CPSX!T26/'4.Doanh thu'!O$11,0) -> 247 | U26: =ROUND(CPSX!U26/'4.Doanh thu'!P$11,0) -> 247 | V26: =ROUND(CPSX!V26/'4.Doanh thu'!Q$11,0) -> 247 | W26: =AVERAGE(N26:V26) -> 247
B28: II | E28: ĐỊNH PHÍ | J28: =SUM(J29:J57) -> 0 | K28: =SUM(K29:K57) -> 0 | L28: =SUM(L29:L57) -> 0 | M28: =SUM(M29:M57) -> 0 | N28: =SUM(N29:N57) -> 915 | O28: =SUM(O29:O57) -> 915 | P28: =SUM(P29:P57) -> 915 | Q28: =SUM(Q29:Q57) -> 915 | ... W28: =SUM(W29:W57) -> 915
B29: 1 | D29: 6271002604 | E29: Chi phí lương chính - Gián tiếp | F29: Salary and Wages - Support | G29: Chi phí lương chính - Gián tiếp | H29: Phòng Hành chánh nhân sự | I29: LUONG | K29: =SUM('Dinh muc'!$G$11:$G$12)*'3.Thanh pham'!F$10 -> 0 | L29: =SUM('Dinh muc'!$G$11:$G$12)*'3.Thanh pham'!G$10 -> 0 | M29: =SUM('Dinh muc'!$G$11:$G$12)*'3.Thanh pham'!H$10 -> 0 | N29: =ROUND(CPSX!N29/'4.Doanh thu'!I$11,0) -> 525 | O29: =ROUND(CPSX!O29/'4.Doanh thu'!J$11,0) -> 525 | P29: =ROUND(CPSX!P29/'4.Doanh thu'!K$11,0) -> 525 | Q29: =ROUND(CPSX!Q29/'4.Doanh thu'!L$11,0) -> 525 | R29: =ROUND(CPSX!R29/'4.Doanh thu'!M$11,0) -> 525 | S29: =ROUND(CPSX!S29/'4.Doanh thu'!N$11,0) -> 525 | T29: =ROUND(CPSX!T29/'4.Doanh thu'!O$11,0) -> 525 | U29: =ROUND(CPSX!U29/'4.Doanh thu'!P$11,0) -> 525 | V29: =ROUND(CPSX!V29/'4.Doanh thu'!Q$11,0) -> 525 | W29: =AVERAGE(N29:V29) -> 525
B30: 2 | D30: 6271002605 | E30: Chi phí lương T13, phép năm - Gián tiếp | F30: Salary and Wages - Support | G30: Chi phí lương T13, phép năm - Gián tiếp | H30: Phòng Hành chánh nhân sự | I30: LUONG | N30: =ROUND(CPSX!N30/'4.Doanh thu'!I$11,0) -> 0 | O30: =ROUND(CPSX!O30/'4.Doanh thu'!J$11,0) -> 0 | P30: =ROUND(CPSX!P30/'4.Doanh thu'!K$11,0) -> 0 | Q30: =ROUND(CPSX!Q30/'4.Doanh thu'!L$11,0) -> 0 | R30: =ROUND(CPSX!R30/'4.Doanh thu'!M$11,0) -> 0 | S30: =ROUND(CPSX!S30/'4.Doanh thu'!N$11,0) -> 0 | T30: =ROUND(CPSX!T30/'4.Doanh thu'!O$11,0) -> 0 | U30: =ROUND(CPSX!U30/'4.Doanh thu'!P$11,0) -> 0 | V30: =ROUND(CPSX!V30/'4.Doanh thu'!Q$11,0) -> 0 | W30: =AVERAGE(N30:V30) -> 0
B31: 3 | D31: 6271002802 | E31: Chi phí khen thưởng - Gián tiếp | F31: Employee Welfare | G31: Chi phí khen thưởng - Gián tiếp | H31: Phòng Hành chánh nhân sự | I31: LUONG | N31: =ROUND(CPSX!N31/'4.Doanh thu'!I$11,0) -> 0 | O31: =ROUND(CPSX!O31/'4.Doanh thu'!J$11,0) -> 0 | P31: =ROUND(CPSX!P31/'4.Doanh thu'!K$11,0) -> 0 | Q31: =ROUND(CPSX!Q31/'4.Doanh thu'!L$11,0) -> 0 | R31: =ROUND(CPSX!R31/'4.Doanh thu'!M$11,0) -> 0 | S31: =ROUND(CPSX!S31/'4.Doanh thu'!N$11,0) -> 0 | T31: =ROUND(CPSX!T31/'4.Doanh thu'!O$11,0) -> 0 | U31: =ROUND(CPSX!U31/'4.Doanh thu'!P$11,0) -> 0 | V31: =ROUND(CPSX!V31/'4.Doanh thu'!Q$11,0) -> 0 | W31: =AVERAGE(N31:V31) -> 0
B32: 4 | D32: 6271002806 | E32: Thưởng danh hiệu - Gián tiếp | F32: Salary and Wages - Support | G32: Thưởng danh hiệu - Gián tiếp | H32: Phòng Hành chánh nhân sự | I32: LUONG | N32: =ROUND(CPSX!N32/'4.Doanh thu'!I$11,0) -> 0 | O32: =ROUND(CPSX!O32/'4.Doanh thu'!J$11,0) -> 0 | P32: =ROUND(CPSX!P32/'4.Doanh thu'!K$11,0) -> 0 | Q32: =ROUND(CPSX!Q32/'4.Doanh thu'!L$11,0) -> 0 | R32: =ROUND(CPSX!R32/'4.Doanh thu'!M$11,0) -> 0 | S32: =ROUND(CPSX!S32/'4.Doanh thu'!N$11,0) -> 0 | T32: =ROUND(CPSX!T32/'4.Doanh thu'!O$11,0) -> 0 | U32: =ROUND(CPSX!U32/'4.Doanh thu'!P$11,0) -> 0 | V32: =ROUND(CPSX!V32/'4.Doanh thu'!Q$11,0) -> 0 | W32: =AVERAGE(N32:V32) -> 0
B33: 5 | D33: 6271007202 | E33: Chi phí khen thưởng, bồi dưỡng khác | F33: Employee Welfare | G33: Chi phí khen thưởng, bồi dưỡng khác | H33: Phòng Hành chánh nhân sự | I33: LUONG | N33: =ROUND(CPSX!N33/'4.Doanh thu'!I$11,0) -> 0 | O33: =ROUND(CPSX!O33/'4.Doanh thu'!J$11,0) -> 0 | P33: =ROUND(CPSX!P33/'4.Doanh thu'!K$11,0) -> 0 | Q33: =ROUND(CPSX!Q33/'4.Doanh thu'!L$11,0) -> 0 | R33: =ROUND(CPSX!R33/'4.Doanh thu'!M$11,0) -> 0 | S33: =ROUND(CPSX!S33/'4.Doanh thu'!N$11,0) -> 0 | T33: =ROUND(CPSX!T33/'4.Doanh thu'!O$11,0) -> 0 | U33: =ROUND(CPSX!U33/'4.Doanh thu'!P$11,0) -> 0 | V33: =ROUND(CPSX!V33/'4.Doanh thu'!Q$11,0) -> 0 | W33: =AVERAGE(N33:V33) -> 0
B34: 6 | D34: 6271003202 | E34: Tiền ăn giữa ca - Gián tiếp | F34: Employee Welfare | G34: Tiền ăn giữa ca - Gián tiếp | H34: Phòng Hành chánh nhân sự | I34: LUONG | K34: ='Dinh muc'!$G$13*'3.Thanh pham'!F$10 -> 0 | L34: ='Dinh muc'!$G$13*'3.Thanh pham'!G$10 -> 0 | M34: ='Dinh muc'!$G$13*'3.Thanh pham'!H$10 -> 0 | N34: =ROUND(CPSX!N34/'4.Doanh thu'!I$11,0) -> 40 | O34: =ROUND(CPSX!O34/'4.Doanh thu'!J$11,0) -> 40 | P34: =ROUND(CPSX!P34/'4.Doanh thu'!K$11,0) -> 40 | Q34: =ROUND(CPSX!Q34/'4.Doanh thu'!L$11,0) -> 40 | R34: =ROUND(CPSX!R34/'4.Doanh thu'!M$11,0) -> 40 | S34: =ROUND(CPSX!S34/'4.Doanh thu'!N$11,0) -> 40 | T34: =ROUND(CPSX!T34/'4.Doanh thu'!O$11,0) -> 40 | U34: =ROUND(CPSX!U34/'4.Doanh thu'!P$11,0) -> 40 | V34: =ROUND(CPSX!V34/'4.Doanh thu'!Q$11,0) -> 40 | W34: =AVERAGE(N34:V34) -> 40
B35: 7 | D35: 6271002603 | E35: Phụ cấp ca đêm - Gián tiếp | F35: Salary and Wages - Support | G35: Phụ cấp ca đêm - Gián tiếp | H35: Phòng Hành chánh nhân sự | I35: LUONG | N35: =ROUND(CPSX!N35/'4.Doanh thu'!I$11,0) -> 0 | O35: =ROUND(CPSX!O35/'4.Doanh thu'!J$11,0) -> 0 | P35: =ROUND(CPSX!P35/'4.Doanh thu'!K$11,0) -> 0 | Q35: =ROUND(CPSX!Q35/'4.Doanh thu'!L$11,0) -> 0 | R35: =ROUND(CPSX!R35/'4.Doanh thu'!M$11,0) -> 0 | S35: =ROUND(CPSX!S35/'4.Doanh thu'!N$11,0) -> 0 | T35: =ROUND(CPSX!T35/'4.Doanh thu'!O$11,0) -> 0 | U35: =ROUND(CPSX!U35/'4.Doanh thu'!P$11,0) -> 0 | V35: =ROUND(CPSX!V35/'4.Doanh thu'!Q$11,0) -> 0 | W35: =AVERAGE(N35:V35) -> 0
B36: 8 | D36: 6271003401 | E36: BHXH, BHYT, KPCĐ, BHTN - Gián tiếp | F36: Employee Welfare | G36: BHXH, BHYT, KPCĐ, BHTN - Gián tiếp | H36: Phòng Hành chánh nhân sự | I36: LUONG | N36: =ROUND(CPSX!N36/'4.Doanh thu'!I$11,0) -> 0 | O36: =ROUND(CPSX!O36/'4.Doanh thu'!J$11,0) -> 0 | P36: =ROUND(CPSX!P36/'4.Doanh thu'!K$11,0) -> 0 | Q36: =ROUND(CPSX!Q36/'4.Doanh thu'!L$11,0) -> 0 | R36: =ROUND(CPSX!R36/'4.Doanh thu'!M$11,0) -> 0 | S36: =ROUND(CPSX!S36/'4.Doanh thu'!N$11,0) -> 0 | T36: =ROUND(CPSX!T36/'4.Doanh thu'!O$11,0) -> 0 | U36: =ROUND(CPSX!U36/'4.Doanh thu'!P$11,0) -> 0 | V36: =ROUND(CPSX!V36/'4.Doanh thu'!Q$11,0) -> 0 | W36: =AVERAGE(N36:V36) -> 0
B37: 9 | D37: 6271002703 | E37: Chi phí lương ngoài giờ - Gián tiếp | F37: Salary and Wages - Support | G37: Chi phí lương ngoài giờ - Gián tiếp | H37: Phòng Hành chánh nhân sự | I37: LUONG | N37: =ROUND(CPSX!N37/'4.Doanh thu'!I$11,0) -> 0 | O37: =ROUND(CPSX!O37/'4.Doanh thu'!J$11,0) -> 0 | P37: =ROUND(CPSX!P37/'4.Doanh thu'!K$11,0) -> 0 | Q37: =ROUND(CPSX!Q37/'4.Doanh thu'!L$11,0) -> 0 | R37: =ROUND(CPSX!R37/'4.Doanh thu'!M$11,0) -> 0 | S37: =ROUND(CPSX!S37/'4.Doanh thu'!N$11,0) -> 0 | T37: =ROUND(CPSX!T37/'4.Doanh thu'!O$11,0) -> 0 | U37: =ROUND(CPSX!U37/'4.Doanh thu'!P$11,0) -> 0 | V37: =ROUND(CPSX!V37/'4.Doanh thu'!Q$11,0) -> 0 | W37: =AVERAGE(N37:V37) -> 0
B38: 10 | D38: 6220002901 | E38: Chi phí trợ cấp thôi việc - Trực tiếp | F38: Employee Benefits Expenses | G38: Chi phí trợ cấp thôi việc - Trực tiếp | H38: Phòng Hành chánh nhân sự | I38: BP Phat sinh | N38: =ROUND(CPSX!N38/'4.Doanh thu'!I$11,0) -> 0 | O38: =ROUND(CPSX!O38/'4.Doanh thu'!J$11,0) -> 0 | P38: =ROUND(CPSX!P38/'4.Doanh thu'!K$11,0) -> 0 | Q38: =ROUND(CPSX!Q38/'4.Doanh thu'!L$11,0) -> 0 | R38: =ROUND(CPSX!R38/'4.Doanh thu'!M$11,0) -> 0 | S38: =ROUND(CPSX!S38/'4.Doanh thu'!N$11,0) -> 0 | T38: =ROUND(CPSX!T38/'4.Doanh thu'!O$11,0) -> 0 | U38: =ROUND(CPSX!U38/'4.Doanh thu'!P$11,0) -> 0 | V38: =ROUND(CPSX!V38/'4.Doanh thu'!Q$11,0) -> 0 | W38: =AVERAGE(N38:V38) -> 0
B39: 11 | D39: 6271003001 | E39: Chi phí đồng phục | F39: Employee Welfare | G39: Chi phí đồng phục | H39: Phòng Hành chánh nhân sự | I39: Phan bo | N39: =ROUND(CPSX!N39/'4.Doanh thu'!I$11,0) -> 0 | O39: =ROUND(CPSX!O39/'4.Doanh thu'!J$11,0) -> 0 | P39: =ROUND(CPSX!P39/'4.Doanh thu'!K$11,0) -> 0 | Q39: =ROUND(CPSX!Q39/'4.Doanh thu'!L$11,0) -> 0 | R39: =ROUND(CPSX!R39/'4.Doanh thu'!M$11,0) -> 0 | S39: =ROUND(CPSX!S39/'4.Doanh thu'!N$11,0) -> 0 | T39: =ROUND(CPSX!T39/'4.Doanh thu'!O$11,0) -> 0 | U39: =ROUND(CPSX!U39/'4.Doanh thu'!P$11,0) -> 0 | V39: =ROUND(CPSX!V39/'4.Doanh thu'!Q$11,0) -> 0 | W39: =AVERAGE(N39:V39) -> 0
B40: 12 | D40: 6277003101 | E40: Chi phí y tế, BH sức khỏe | F40: Employee Welfare | G40: Chi Phí Y Tế, BH Sức Khỏe, BH 24/24 | H40: Phòng Hành chánh nhân sự | I40: Phan bo | N40: =ROUND(CPSX!N40/'4.Doanh thu'!I$11,0) -> 0 | O40: =ROUND(CPSX!O40/'4.Doanh thu'!J$11,0) -> 0 | P40: =ROUND(CPSX!P40/'4.Doanh thu'!K$11,0) -> 0 | Q40: =ROUND(CPSX!Q40/'4.Doanh thu'!L$11,0) -> 0 | R40: =ROUND(CPSX!R40/'4.Doanh thu'!M$11,0) -> 0 | S40: =ROUND(CPSX!S40/'4.Doanh thu'!N$11,0) -> 0 | T40: =ROUND(CPSX!T40/'4.Doanh thu'!O$11,0) -> 0 | U40: =ROUND(CPSX!U40/'4.Doanh thu'!P$11,0) -> 0 | V40: =ROUND(CPSX!V40/'4.Doanh thu'!Q$11,0) -> 0 | W40: =AVERAGE(N40:V40) -> 0
B41: 13 | D41: 6273000100 | E41: Chi phí công cụ dụng cụ phục vụ SX | F41: Tools and Equipments | G41: Chi phí công cụ dụng cụ phục vụ SX | H41: Phòng Sản xuất | I41: BP Phat sinh | N41: =ROUND(CPSX!N41/'4.Doanh thu'!I$11,0) -> 23 | O41: =ROUND(CPSX!O41/'4.Doanh thu'!J$11,0) -> 23 | P41: =ROUND(CPSX!P41/'4.Doanh thu'!K$11,0) -> 23 | Q41: =ROUND(CPSX!Q41/'4.Doanh thu'!L$11,0) -> 23 | R41: =ROUND(CPSX!R41/'4.Doanh thu'!M$11,0) -> 23 | S41: =ROUND(CPSX!S41/'4.Doanh thu'!N$11,0) -> 23 | T41: =ROUND(CPSX!T41/'4.Doanh thu'!O$11,0) -> 23 | U41: =ROUND(CPSX!U41/'4.Doanh thu'!P$11,0) -> 23 | V41: =ROUND(CPSX!V41/'4.Doanh thu'!Q$11,0) -> 23 | W41: =AVERAGE(N41:V41) -> 23
