Workbook
Name Capacity: 'Cover Page'!$F$28
Name Currency: 'Cover Page'!$A$33
Name EXR: 'Cover Page'!$F$10
Name Inflation: 'Cover Page'!$F$9
Name Opt1_WACC: 'Cover Page'!$H$23
Name Opt2_CAPEX: 'Cover Page'!$K$6
Name Opt2_CPSX: 'Cover Page'!$K$7
Name Opt2_EXW: 'Cover Page'!$K$10
Name Opt2_WACC: 'Cover Page'!$K$23
Name Opt3_CAPEX: 'Cover Page'!$N$6
Name Opt3_CPSX: 'Cover Page'!$N$7
Name Opt3_WACC: 'Cover Page'!$W$23
Name Opt4_CAPEX: 'Cover Page'!$Q$6
Name Opt4_CPSX: 'Cover Page'!$Q$7
Name Opt5_CAPEX: 'Cover Page'!$T$6
Name Opt5_CPSX: 'Cover Page'!$T$7
Name Opt6_CAPEX: 'Cover Page'!$W$6
Name Opt6_CPSX: 'Cover Page'!$W$7
Name PHOI_KG: 'Cover Page'!$F$30
Name Slicer_Currency: #N/A
Name Tax_rate: 'Cover Page'!$F$11
Name WACC: 'Cover Page'!$F$23

Sheet Timeline

Sheet >>PowerPoint

Sheet Trình bày giả định
A2: CÁC GIẢ ĐỊNH CỦA DỰ ÁN
A4: STT | B4: GIẢ ĐỊNH | C4: GIÁ TRỊ | D4: ĐVT/Ghi chú | F4: STT | G4: GIẢ ĐỊNH | H4: GIÁ TRỊ | I4: ĐVT/Ghi chú
A5: 1 | B5: Thông tin chung | F5: 4 | G5: Hiệu suất sử dụng máy | H5: ='W3'!$L$23 -> 0.88
A6: 1.1 | B6: Chủ đầu tư | C6: DTR
A7: 1.2 | B7: Thời gian khai thác | C7: 25 | D7: Năm | F7: 5 | G7: Sản lượng sản xuất tối đa | H7: ='W3'!U27/10^3 -> 6194.175 | I7: tấn/năm
A8: 1.3 | B8: Tổng dự toán đầu tư máy móc thiết bị (VND) | C8: =IF(Currency="VND",'W1'!$I$60,'W1'!$I$60*EXR) -> 300749800000 | D8: VND | H8: ='W3'!U28 -> 4.12945e+08 | I8: phôi/năm
A9: 1.4 | B9: Tổng dự toán đầu tư máy móc thiết bị (USD) | C9: =IF(Currency="VND",'W1'!$I$60/EXR,'W1'!$I$60) -> 11567300 | D9: USD
A10: 1.5 | B10: Thời gian khấu hao (PP đường thẳng) | C10: ='W1'!G13 -> 12 | D10: Năm | F10: 6 | G10: Sản lượng bán | H10: (tấn)
A11: 1.6 | B11: Tỷ giá | C11: =EXR -> 26000 | F11: 6.1 | G11: Sản lượng bán năm 1 | H11: ='W3'!L27/10^3 -> 3097.0875 | I11: 50.0% Sản lượng sản xuất tối đa
A12: 1.7 | B12: Lạm phát | C12: =Inflation -> 0.05 | F12: 6.2 | G12: Sản lượng bán năm 2 | H12: ='W3'!M27/10^3 -> 4335.9225 | I12: 70.0% Sản lượng sản xuất tối đa
F13: 6.3 | G13: Sản lượng bán năm 3 | H13: ='W3'!N27/10^3 -> 6194.175 | I13: 100.0% Sản lượng sản xuất tối đa
A14: 2 | B14: Nguồn nguyên vật liệu: Vảy sạch từ chai B1 | F14: 6.4 | G14: Từ năm thứ 4 trở đi bằng với năm 3
A15: 2.1 | B15: Đơn giá chai B1 | C15: 16600 | D15: đ/kg
A16: 2.2 | B16: Đơn giá vảy sạch cho dự án | C16: =IF(Currency="VND",'W2'!$M$56,'W2'!$M$56*EXR) -> 24960 | D16: đ/kg
A17: 2.3 | B17: Tỷ lệ hao hụt FtoP | C17: ='W2'!M41 -> 0.07 | F17: 7 | G17: Giá bán | H17: ='Cover Page'!H13 -> 45.333333 | I17: tr.đ/tấn
A18: 2.4 | B18: Liều lượng phụ gia | C18: ='W2'!M60 -> 0.0002 | H18: ='Cover Page'!H15 -> 1743.5897 | I18: USD/tấn
A19: 2.5 | B19: Đơn giá phụ gia | C19: ='W2'!M64 -> 949542 | D19: VND/kg | H19: ='Cover Page'!H14 -> 680 | I19: VND/phôi
F20: 8 | G20: Tỷ lệ chiết khấu/cơ cấu vay
A21: 3 | B21: Chi phí sản xuất | F21: 8.1 | G21: Vốn vay | H21: ='Cover Page'!H21 -> 0.7
A22: 3.1 | B22: Nhân công trực tiếp (2 người x 3 ca) | C22: =IF(Currency="VND",'W2'!$M$13,'W2'!$M$13*EXR) -> 982800000 | D22: VND/năm | F22: 8.2 | G22: Vốn tự có | H22: =1-H21 -> 0.3
A23: 3.2 | B23: Nhân viên kỹ thuật, QC, kho | C23: =IF(Currency="VND",'W2'!$M$17,'W2'!$M$17*EXR) -> 5028660000 | D23: VND/năm | F23: 8.3 | G23: Lãi vay trung dài hạn | H23: ='Cover Page'!H19 -> 0.07
A24: 3.3 | B24: Chi phí điện | C24: ='W2'!M45 -> 765 | D24: kwh | F24: 8.4 | G24: Thuế suất thuế TNDN | H24: =Tax_rate -> 0.2
A25: 3.4 | B25: Đơn giá điện | C25: =IF(Currency="VND",'W2'!$M$46,'W2'!$M$46*EXR) -> 1950 | D25: đ/kwh | F25: 8.5 | G25: Tỷ lệ chiết khấu = WACC | H25: =Opt1_WACC -> 0.07266
A26: 3.5 | B26: Chi phí sửa chữa bảo trì | C26: =IF(Currency="VND",'W2'!$M$28,'W2'!$M$28*EXR) -> 9022494000 | D26: VND/năm
A27: 3.6 | B27: Chi phí vận hành xe điện | C27: =IF(Currency="VND",'W2'!$M$37,'W2'!$M$37*EXR) -> 552000000 | D27: VND/năm
B28: (Số xe thuê: 2 với đơn giá thuê 20 triệu/tháng, chi phí điện 3 triệu/xe/tháng) | G28: Dự án chưa tính giá trị đầu tư xưởng (khoảng 150 tỷ đồng ~ 6 triệu USD)
A29: 3.7 | B29: Chi phí bao bì | C29: =IF(Currency="VND",'W2'!$M$48,'W2'!$M$48*EXR) -> 314.81481 | D29: đ/kg thành phẩm
A30: 3.8 | B30: Chi phí thuê xưởng | C30: =IF(Currency="VND",'W2'!$M$33,'W2'!$M$33*EXR) -> 2400000000 | D30: VND/năm
A31: 3.9 | B31: Chi phí bảo hiểm | C31: ='W2'!L73 -> 0.002 | D31: /tổng tài sản
A32: 3.10 | B32: Chi phí vận chuyển | C32: ='W2'!$M$77 -> 4000000 | D32: VND/chuyến

Sheet W1-Trình bày
A2: STT | B2: HẠNG MỤC | C2: Số lượng | E2: Đơn giá | F2: Giá trị đầu tư | G2: Giá trị đầu tư | M2: Thời gian khấu hao | N2: Khấu hao
C3: (cái,m2) | E3: (VND) | F3: (VND) | G3: (USD) | M3: (Năm) | N3: (VND/năm)
A5: 1 | B5: MÁY MÓC THIẾT BỊ | F5: 284499800000 | G5: =F5/26000 -> 10942300 | N5: 2.3708317e+10
A7: 1.1 | B7: Máy móc thiết bị chính | F7: 2.46389e+11 | G7: =F7/26000 -> 9476500 | N7: 2.0532417e+10
A8: 1.1.01 | B8: NGR : LSP 1200 | C8: 1 | E8: 128180000000 | F8: 128180000000 | G8: =F8/26000 -> 4930000 | M8: 12 | N8: 1.0681667e+10
A9: 1.1.02 | B9: HyPET400 HPP5e rMtP P120/120 | C9: 1 | E9: 6.727793e+10 | F9: 6.727793e+10 | G9: =F9/26000 -> 2587612.7 | M9: 12 | N9: 5.6064942e+09
A10: 1.1.03 | B10: Khuôn 15g PCO 1881 128 cavtiy | C10: 1 | E10: 3.932207e+10 | F10: 3.932207e+10 | G10: =F10/26000 -> 1512387.3 | M10: 12 | N10: 3.2768391e+09
A11: 1.1.04 | B11: Chi phí vận chuyển | C11: 1 | E11: 2600000000 | F11: 2600000000 | G11: =F11/26000 -> 100000 | M11: 12 | N11: 2.1666667e+08
A12: 1.1.05 | B12: Chi phí lắp đặt | C12: 1 | E12: 8580000000 | F12: 8580000000 | G12: =F12/26000 -> 330000 | M12: 12 | N12: 715000000
A13: 1.1.06 | B13: Thuế nhà thầu | C13: 1 | E13: 429000000 | F13: 429000000 | G13: =F13/26000 -> 16500 | M13: 12 | N13: 35750000
A15: 1.2 | B15: Máy móc thiết bị phụ | F15: 38110800000 | G15: =F15/26000 -> 1465800 | N15: 3175900000
A16: 1.2.06 | B16: Hệ thống nước, khí nén | C16: 1 | E16: 7800000000 | F16: 7800000000 | G16: =F16/26000 -> 300000 | M16: 12 | N16: 650000000
A17: 1.2.07 | B17: Hệ thống điện | C17: 1 | E17: 7800000000 | F17: 7800000000 | G17: =F17/26000 -> 300000 | M17: 12 | N17: 650000000
A18: 1.2.08 | B18: Pump system | C18: 1 | E18: 3900000000 | F18: 3900000000 | G18: =F18/26000 -> 150000 | M18: 12 | N18: 325000000
A19: 1.2.09 | B19: Camera online check | C19: 1 | E19: 3250000000 | F19: 3250000000 | G19: =F19/26000 -> 125000 | M19: 12 | N19: 2.7083333e+08
A20: 1.2.10 | B20: Chiller | C20: 1 | E20: 2600000000 | F20: 2600000000 | G20: =F20/26000 -> 100000 | M20: 12 | N20: 2.1666667e+08
A21: 1.2.11 | B21: Trạm điện | C21: 1 | E21: 2600000000 | F21: 2600000000 | G21: =F21/26000 -> 100000 | M21: 12 | N21: 2.1666667e+08
A22: 1.2.12 | B22: Overhead crane | C22: 1 | E22: 2600000000 | F22: 2600000000 | G22: =F22/26000 -> 100000 | M22: 12 | N22: 2.1666667e+08
A23: 1.2.13 | B23: Hệ thống điện dự phòng | C23: 1 | E23: 2080000000 | F23: 2080000000 | G23: =F23/26000 -> 80000 | M23: 12 | N23: 1.7333333e+08
A24: 1.2.14 | B24: Hệ thống IT | C24: 1 | E24: 2080000000 | F24: 2080000000 | G24: =F24/26000 -> 80000 | M24: 12 | N24: 1.7333333e+08
A25: 1.2.15 | B25: Lock unloading preform | C25: 1 | E25: 1352000000 | F25: 1352000000 | G25: =F25/26000 -> 52000 | M25: 12 | N25: 1.1266667e+08
A26: 1.2.16 | B26: Máy nén khí | C26: 1 | E26: 1248000000 | F26: 1248000000 | G26: =F26/26000 -> 48000 | M26: 12 | N26: 104000000
A27: 1.2.17 | B27: Cooling tower | C27: 1 | E27: 780000000 | F27: 780000000 | G27: =F27/26000 -> 30000 | M27: 12 | N27: 65000000
A28: 1.2.18 | B28: Máy scan | C28: 1 | E28: 20800000 | F28: 20800000 | G28: =F28/26000 -> 800 | M28: 12 | N28: 1733333.3
B30: CHI PHÍ XÂY DỰNG XƯỞNG SẢN XUẤT | C30: 2000 | F30: 0 | N30: 0
B31: Xưởng sản xuất | C31: 1900 | E31: 75000000 | F31: 0 | M31: 25 | N31: 0
B32: Phòng QC | C32: 100 | E32: 75000000 | F32: 0 | M32: 25 | N32: 0
A34: 2. | B34: MÁY MÓC THIẾT BỊ PHÒNG LAB | F34: 16250000000 | G34: =F34/26000 -> 625000 | N34: 1.3541667e+09
A35: 2.01 | B35: Máy đo IV PSL IV 4603 | C35: 1 | E35: 5200000000 | F35: 5200000000 | G35: =F35/26000 -> 200000 | M35: 12 | N35: 4.3333333e+08
A36: 2.02 | B36: Máy đo kích thước tự động Gawis 4D | C36: 1 | E36: 5200000000 | F36: 5200000000 | G36: =F36/26000 -> 200000 | M36: 12 | N36: 4.3333333e+08
A37: 2.03 | B37: Máy đo AA Piovan Inspecta | C37: 1 | E37: 3042000000 | F37: 3042000000 | G37: =F37/26000 -> 117000 | M37: 12 | N37: 253500000
A38: 2.04 | B38: Colorimeter/Spectrophotometer | C38: 1 | E38: 650000000 | F38: 650000000 | G38: =F38/26000 -> 25000 | M38: 12 | N38: 54166667
A39: 2.05 | B39: Melt Flow Index Tester | C39: 1 | E39: 442000000 | F39: 442000000 | G39: =F39/26000 -> 17000 | M39: 12 | N39: 36833333
A40: 2.06 | B40: Light Polarizer | C40: 1 | E40: 260000000 | F40: 260000000 | G40: =F40/26000 -> 10000 | M40: 12 | N40: 21666667
A41: 2.07 | B41: Moisture analyzer | C41: 1 | E41: 143000000 | F41: 143000000 | G41: =F41/26000 -> 5500 | M41: 12 | N41: 11916667
A42: 2.08 | B42: Perpendicular Prefrom Thickness Gauge | C42: 1 | E42: 130000000 | F42: 130000000 | G42: =F42/26000 -> 5000 | M42: 12 | N42: 10833333
A43: 2.09 | B43: Calipers with data output | C43: 1 | E43: 130000000 | F43: 130000000 | G43: =F43/26000 -> 5000 | M43: 12 | N43: 10833333
A44: 2.10 | B44: Radius gauges | C44: 1 | E44: 130000000 | F44: 130000000 | G44: =F44/26000 -> 5000 | M44: 12 | N44: 10833333
A45: 2.11 | B45: Torque tester | C45: 1 | E45: 130000000 | F45: 130000000 | G45: =F45/26000 -> 5000 | M45: 12 | N45: 10833333
A46: 2.12 | B46: Pitch gauges | C46: 1 | E46: 130000000 | F46: 130000000 | G46: =F46/26000 -> 5000 | M46: 12 | N46: 10833333
...

Sheet USD.Tấn
A3: No. | B3: SAP | C3: Chi phí Cost Items | D3: Chi phí USD/tấn | E3: Cơ cấu % chi phí /Giá
A4: A | B4: 1521 | C4: Chi phí nguyên vật liệu | D4: 979.2 | E4: 0.5616
C5: Vảy sạch | D5: 979.2 | E5: 0.5616
A6: B | B6: 1522 | C6: Hao hụt về tiền | D6: 73.703226 | E6: 0.042270968
A7: C | C7: Chi phí biến đổi | D7: 512.52452 | E7: 0.29394789
A8: 1 | B8: LAB | C8: Chi phí nhân công | D8: 39.193355 | E8: 0.022478542
A9: 2 | B9: DEP | C9: Khấu hao | D9: 155.62067 | E9: 0.089253032
A10: 3 | B10: OTH | C10: Chi phí gián tiếp | D10: 89.499728 | E10: 0.051330727
A11: 4 | B11: ELEC | C11: Điện | D11: 132.27565 | E11: 0.075863976
A12: 5 | B12: QLC | C12: Chi phí quản lý | D12: 74.974798 | E12: 0.043000252
A13: 6 | B13: BAG | C13: Đóng gói | D13: 12.713675 | E13: 0.0072916667
A14: 7 | B14: CHE | C14: Hóa chất | D14: 8.2466427 | E14: 0.0047296921
A15: 8 | B15: H2O | C15: Nước | D15: 0 | E15: 0
A16: 9 | C16: Giá thành | D16: 1565.4277 | E16: 0.89781886
A17: 10 | B17: TAX | C17: Thuế thu nhập | D17: 35.632399 | E17: 0.020436229
A18: D | B18: LN | C18: Lợi nhuận | D18: 142.5296 | E18: 0.081744916
A19: A+B+C+D | C19: Giá bán | D19: 1743.5897 | E19: 1
C20: % Lãi gộp nguyên liệu/Giá bán | E20: 0.4384

Sheet VND.Phôi
A3: No. | B3: SAP | C3: Chi phí Cost Items | D3: Chi phí VNĐ / Phôi | E3: Cơ cấu % chi phí /Giá
A4: A | B4: 1521 | C4: Chi phí nguyên vật liệu | D4: 381.888 | E4: 0.5616
B5: 1521 | C5: Vảy sạch | D5: 381.888 | E5: 0.5616
A6: B | B6: 1522 | C6: Hao hụt về tiền | D6: 28.744258 | E6: 0.042270968
A7: C | C7: Chi phí biến đổi | D7: 199.88456 | E7: 0.29394789
A8: 1 | B8: LAB | C8: Chi phí nhân công | D8: 15.285409 | E8: 0.022478542
A9: 2 | B9: DEP | C9: Khấu hao | D9: 60.692062 | E9: 0.089253032
A10: 3 | B10: QLC | C10: Chi phí quản lý | D10: 34.904894 | E10: 0.051330727
A11: 4 | B11: OTH | C11: Chi phí gián tiếp | D11: 51.587504 | E11: 0.075863976
A12: 5 | B12: ELEC | C12: Điện | D12: 29.240171 | E12: 0.043000252
A13: 6 | B13: BAG | C13: Đóng gói | D13: 4.9583333 | E13: 0.0072916667
A14: 7 | B14: CHE | C14: Hóa chất | D14: 3.2161906 | E14: 0.0047296921
A15: 8 | B15: H2O | C15: Nước | D15: 0 | E15: 0
A16: 9 | C16: Giá thành | D16: 610.51682 | E16: 0.89781886
A17: 10 | B17: TAX | C17: Thuế thu nhập | D17: 13.896636 | E17: 0.020436229
A18: D | B18: LN | C18: Lợi nhuận | D18: 55.586543 | E18: 0.081744916
A19: A+B+C+D | C19: Giá bán | D19: 680 | E19: 1
C20: % Lãi gộp nguyên liệu/Giá bán | E20: 0.4384

Sheet Sheet3
B2: STT | C2: Hạng mục | D2: Đvt | E2: 2026 | F2: 2027 | G2: 2028 | H2: 2029 | I2: 2030 | J2: 2031 | K2: 2032 | L2: 2033 | M2: 2034 | N2: 2035 | O2: 2036 | P2: 2037 | Q2: 2038 | R2: 2039 | S2: 2040 | T2: 2041 | U2: 2042 | V2: 2043 | W2: 2044 | X2: 2045 | Y2: 2046 | Z2: 2047 | AA2: 2048 | AB2: 2049 | AC2: 2050 | AD2: 2051
B4: =IF(C4<>"",SUBTOTAL(3,C$4:C4),"") -> 1 | C4: SỐ LƯỢNG SẢN XUẤT/BÁN
B5: =IF(C5<>"",SUBTOTAL(3,C$4:C5),"") -> 2 | C5: Sản lượng công suất máy | D5: kg/năm | F5: 7568640 | G5: 7568640 | H5: 7568640 | I5: 7568640 | J5: 7568640 | K5: 7568640 | L5: 7568640 | M5: 7568640 | N5: 7568640 | O5: 7568640 | P5: 7568640 | Q5: 7568640 | R5: 7568640 | S5: 7568640 | T5: 7568640 | U5: 7568640 | V5: 7568640 | W5: 7568640 | X5: 7568640 | Y5: 7568640 | Z5: 7568640 | AA5: 7568640 | AB5: 7568640 | AC5: 7568640 | AD5: 7568640
B6: =IF(C6<>"",SUBTOTAL(3,C$4:C6),"") -> 3 | C6: Sản lượng công suất máy | D6: phôi/năm | F6: 7568640 | G6: 7568640 | H6: 7568640 | I6: 7568640 | J6: 7568640 | K6: 7568640 | L6: 7568640 | M6: 7568640 | N6: 7568640 | O6: 7568640 | P6: 7568640 | Q6: 7568640 | R6: 7568640 | S6: 7568640 | T6: 7568640 | U6: 7568640 | V6: 7568640 | W6: 7568640 | X6: 7568640 | Y6: 7568640 | Z6: 7568640 | AA6: 7568640 | AB6: 7568640 | AC6: 7568640 | AD6: 7568640
B7: =IF(C7<>"",SUBTOTAL(3,C$4:C7),"") -> 4 | C7: Hiệu suất sử dụng tối đa | F7: 0.88 | G7: 0.88 | H7: 0.88 | I7: 0.88 | J7: 0.88 | K7: 0.88 | L7: 0.88 | M7: 0.88 | N7: 0.88 | O7: 0.88 | P7: 0.88 | Q7: 0.88 | R7: 0.88 | S7: 0.88 | T7: 0.88 | U7: 0.88 | V7: 0.88 | W7: 0.88 | X7: 0.88 | Y7: 0.88 | Z7: 0.88 | AA7: 0.88 | AB7: 0.88 | AC7: 0.88 | AD7: 0.88
B8: =IF(C8<>"",SUBTOTAL(3,C$4:C8),"") -> 5 | C8: Hệ số điều chỉnh sản xuất | F8: 0.5 | G8: 0.7 | H8: 1 | I8: 1 | J8: 1 | K8: 1 | L8: 1 | M8: 1 | N8: 1 | O8: 1 | P8: 1 | Q8: 1 | R8: 1 | S8: 1 | T8: 1 | U8: 1 | V8: 1 | W8: 1 | X8: 1 | Y8: 1 | Z8: 1 | AA8: 1 | AB8: 1 | AC8: 1 | AD8: 1
B9: =IF(C9<>"",SUBTOTAL(3,C$4:C9),"") -> 6 | C9: Tỷ lệ hao hụt | F9: 0.07 | G9: 0.07 | H9: 0.07 | I9: 0.07 | J9: 0.07 | K9: 0.07 | L9: 0.07 | M9: 0.07 | N9: 0.07 | O9: 0.07 | P9: 0.07 | Q9: 0.07 | R9: 0.07 | S9: 0.07 | T9: 0.07 | U9: 0.07 | V9: 0.07 | W9: 0.07 | X9: 0.07 | Y9: 0.07 | Z9: 0.07 | AA9: 0.07 | AB9: 0.07 | AC9: 0.07 | AD9: 0.07
B10: =IF(C10<>"",SUBTOTAL(3,C$4:C10),"") -> 7 | C10: Số ngày hoạt động | F10: 160.6 | G10: 224.84 | H10: 321.2 | I10: 321.2 | J10: 321.2 | K10: 321.2 | L10: 321.2 | M10: 321.2 | N10: 321.2 | O10: 321.2 | P10: 321.2 | Q10: 321.2 | R10: 321.2 | S10: 321.2 | T10: 321.2 | U10: 321.2 | V10: 321.2 | W10: 321.2 | X10: 321.2 | Y10: 321.2 | Z10: 321.2 | AA10: 321.2 | AB10: 321.2 | AC10: 321.2 | AD10: 321.2
B11: =IF(C11<>"",SUBTOTAL(3,C$4:C11),"") -> 8 | C11: Sản lượng sản xuất | D11: kg/năm | F11: 3097087.5 | G11: 4335922.5 | H11: 6194175 | I11: 6194175 | J11: 6194175 | K11: 6194175 | L11: 6194175 | M11: 6194175 | N11: 6194175 | O11: 6194175 | P11: 6194175 | Q11: 6194175 | R11: 6194175 | S11: 6194175 | T11: 6194175 | U11: 6194175 | V11: 6194175 | W11: 6194175 | X11: 6194175 | Y11: 6194175 | Z11: 6194175 | AA11: 6194175 | AB11: 6194175 | AC11: 6194175 | AD11: 6194175
B12: =IF(C12<>"",SUBTOTAL(3,C$4:C12),"") -> 9 | C12: Sản lượng sản xuất | D12: phôi/năm | F12: 2.064725e+08 | G12: 2.890615e+08 | H12: 4.12945e+08 | I12: 4.12945e+08 | J12: 4.12945e+08 | K12: 4.12945e+08 | L12: 4.12945e+08 | M12: 4.12945e+08 | N12: 4.12945e+08 | O12: 4.12945e+08 | P12: 4.12945e+08 | Q12: 4.12945e+08 | R12: 4.12945e+08 | S12: 4.12945e+08 | T12: 4.12945e+08 | U12: 4.12945e+08 | V12: 4.12945e+08 | W12: 4.12945e+08 | X12: 4.12945e+08 | Y12: 4.12945e+08 | Z12: 4.12945e+08 | AA12: 4.12945e+08 | AB12: 4.12945e+08 | AC12: 4.12945e+08 | AD12: 4.12945e+08
B13: =IF(C13<>"",SUBTOTAL(3,C$4:C13),"")
B14: =IF(C14<>"",SUBTOTAL(3,C$4:C14),"") -> 10 | C14: DOANH THU | D14: tr. VND | F14: 140401.3 | G14: 200493.06 | H14: 292147.02 | I14: 297989.96 | J14: 303949.76 | K14: 310028.76 | L14: 316229.33 | M14: 322553.92 | N14: 329005 | O14: 335585.1 | P14: 342296.8 | Q14: 349142.74 | R14: 356125.59 | S14: 363248.1 | T14: 370513.07 | U14: 377923.33 | V14: 385481.79 | W14: 393191.43 | X14: 401055.26 | Y14: 409076.36 | Z14: 417257.89 | AA14: 425603.05 | AB14: 434115.11 | AC14: 442797.41 | AD14: 451653.36
B15: =IF(C15<>"",SUBTOTAL(3,C$4:C15),"")
B16: =IF(C16<>"",SUBTOTAL(3,C$4:C16),"") -> 11 | C16: Định phí sản xuất | D16: tr. VND | E16: 0 | F16: -43649.937 | G16: -43649.937 | H16: -44549.235 | I16: -45493.497 | J16: -46484.973 | K16: -47526.022 | L16: -48619.124 | M16: -49766.881 | N16: -50972.026 | O16: -52237.429 | P16: -53566.101 | Q16: -54961.207 | R16: -31363.585 | S16: -32901.689 | T16: -34516.698 | U16: -36212.458 | V16: -37993.006 | W16: -39862.582 | X16: -41825.636 | Y16: -43886.842 | Z16: -46051.11 | AA16: -48323.59 | AB16: -50709.695 | AC16: -53215.104 | AD16: -55845.785
B17: =IF(C17<>"",SUBTOTAL(3,C$4:C17),"") -> 12 | C17: Khấu hao | D17: tr. VND | F17: -25062.483 | G17: -25062.483 | H17: -25062.483 | I17: -25062.483 | J17: -25062.483 | K17: -25062.483 | L17: -25062.483 | M17: -25062.483 | N17: -25062.483 | O17: -25062.483 | P17: -25062.483 | Q17: -25062.483 | R17: 0 | S17: 0 | T17: 0 | U17: 0 | V17: 0 | W17: 0 | X17: 0 | Y17: 0 | Z17: 0 | AA17: 0 | AB17: 0 | AC17: 0 | AD17: 0
B18: =IF(C18<>"",SUBTOTAL(3,C$4:C18),"") -> 13 | C18: Lương | D18: tr. VND | E18: 0 | F18: -6011.46 | G18: -6011.46 | H18: -6312.033 | I18: -6627.6346 | J18: -6959.0164 | K18: -7306.9672 | L18: -7672.3156 | M18: -8055.9313 | N18: -8458.7279 | O18: -8881.6643 | P18: -9325.7475 | Q18: -9792.0349 | R18: -10281.637 | S18: -10795.718 | T18: -11335.504 | U18: -11902.28 | V18: -12497.394 | W18: -13122.263 | X18: -13778.376 | Y18: -14467.295 | Z18: -15190.66 | AA18: -15950.193 | AB18: -16747.703 | AC18: -17585.088 | AD18: -18464.342
B19: =IF(C19<>"",SUBTOTAL(3,C$4:C19),"") -> 14 | C19: - Nhân công trực tiếp | D19: tr. VND | F19: -982.8 | G19: -982.8 | H19: -1031.94 | I19: -1083.537 | J19: -1137.7139 | K19: -1194.5995 | L19: -1254.3295 | M19: -1317.046 | N19: -1382.8983 | O19: -1452.0432 | P19: -1524.6454 | Q19: -1600.8776 | R19: -1680.9215 | S19: -1764.9676 | T19: -1853.216 | U19: -1945.8768 | V19: -2043.1706 | W19: -2145.3291 | X19: -2252.5956 | Y19: -2365.2254 | Z19: -2483.4867 | AA19: -2607.661 | AB19: -2738.044 | AC19: -2874.9462 | AD19: -3018.6935
B20: =IF(C20<>"",SUBTOTAL(3,C$4:C20),"") -> 15 | C20: - Nhân công gián tiếp | D20: tr. VND | F20: -5028.66 | G20: -5028.66 | H20: -5280.093 | I20: -5544.0976 | J20: -5821.3025 | K20: -6112.3677 | L20: -6417.986 | M20: -6738.8853 | N20: -7075.8296 | O20: -7429.6211 | P20: -7801.1021 | Q20: -8191.1573 | R20: -8600.7151 | S20: -9030.7509 | T20: -9482.2884 | U20: -9956.4028 | V20: -10454.223 | W20: -10976.934 | X20: -11525.781 | Y20: -12102.07 | Z20: -12707.173 | AA20: -13342.532 | AB20: -14009.659 | AC20: -14710.142 | AD20: -15445.649
B21: =IF(C21<>"",SUBTOTAL(3,C$4:C21),"") -> 16 | C21: Thuê kho,xưởng | D21: tr. VND | F21: -2400 | G21: -2400 | H21: -2520 | I21: -2646 | J21: -2778.3 | K21: -2917.215 | L21: -3063.0758 | M21: -3216.2295 | N21: -3377.041 | O21: -3545.8931 | P21: -3723.1877 | Q21: -3909.3471 | R21: -4104.8145 | S21: -4310.0552 | T21: -4525.5579 | U21: -4751.8358 | V21: -4989.4276 | W21: -5238.899 | X21: -5500.844 | Y21: -5775.8862 | Z21: -6064.6805 | AA21: -6367.9145 | AB21: -6686.3102 | AC21: -7020.6257 | AD21: -7371.657
B22: =IF(C22<>"",SUBTOTAL(3,C$4:C22),"") -> 17 | C22: Bảo trì | D22: tr. VND | F22: -9022.494 | G22: -9022.494 | H22: -9473.6187 | I22: -9947.2996 | J22: -10444.665 | K22: -10966.898 | L22: -11515.243 | M22: -12091.005 | N22: -12695.555 | O22: -13330.333 | P22: -13996.85 | Q22: -14696.692 | R22: -15431.527 | S22: -16203.103 | T22: -17013.258 | U22: -17863.921 | V22: -18757.117 | W22: -19694.973 | X22: -20679.722 | Y22: -21713.708 | Z22: -22799.393 | AA22: -23939.363 | AB22: -25136.331 | AC22: -26393.147 | AD22: -27712.805
B23: =IF(C23<>"",SUBTOTAL(3,C$4:C23),"") -> 18 | C23: Vận hành xe điện | D23: tr. VND | F23: -552 | G23: -552 | H23: -579.6 | I23: -608.58 | J23: -639.009 | K23: -670.95945 | L23: -704.50742 | M23: -739.73279 | N23: -776.71943 | O23: -815.5554 | P23: -856.33318 | Q23: -899.14983 | R23: -944.10733 | S23: -991.31269 | T23: -1040.8783 | U23: -1092.9222 | V23: -1147.5684 | W23: -1204.9468 | X23: -1265.1941 | Y23: -1328.4538 | Z23: -1394.8765 | AA23: -1464.6203 | AB23: -1537.8513 | AC23: -1614.7439 | AD23: -1695.4811
B24: =IF(C24<>"",SUBTOTAL(3,C$4:C24),"") -> 19 | C24: Bảo hiểm tài sản | D24: tr. VND | F24: -601.4996 | G24: -601.4996 | H24: -601.4996 | I24: -601.4996 | J24: -601.4996 | K24: -601.4996 | L24: -601.4996 | M24: -601.4996 | N24: -601.4996 | O24: -601.4996 | P24: -601.4996 | Q24: -601.4996 | R24: -601.4996 | S24: -601.4996 | T24: -601.4996 | U24: -601.4996 | V24: -601.4996 | W24: -601.4996 | X24: -601.4996 | Y24: -601.4996 | Z24: -601.4996 | AA24: -601.4996 | AB24: -601.4996 | AC24: -601.4996 | AD24: -601.4996
B25: =IF(C25<>"",SUBTOTAL(3,C$4:C25),"")
B26: =IF(C26<>"",SUBTOTAL(3,C$4:C26),"") -> 20 | C26: Biến phí sản xuất | D26: tr. VND | E26: 0 | F26: -92494.065 | G26: -128793.29 | H26: -187365.6 | I26: -191595.5 | J26: -195935.15 | K26: -200388 | L26: -204957.65 | M26: -209647.81 | N26: -214462.35 | O26: -219405.29 | P26: -224480.8 | Q26: -229693.22 | R26: -234044.55 | S26: -239544.48 | T26: -245195.38 | U26: -251002.33 | V26: -256970.6 | W26: -263105.66 | X26: -269413.23 | Y26: -275899.25 | Z26: -282569.91 | AA26: -289431.63 | AB26: -296491.13 | AC26: -303755.39 | AD26: -311231.67
B27: =IF(C27<>"",SUBTOTAL(3,C$4:C27),"") -> 21 | C27: Nguyên vật liệu | D27: tr. VND | E27: 0 | F27: -83121.832 | G27: -116370.56 | H27: -169568.54 | I27: -172959.91 | J27: -176419.11 | K27: -179947.49 | L27: -183546.44 | M27: -187217.37 | N27: -190961.71 | O27: -194780.95 | P27: -198676.57 | Q27: -202650.1 | R27: -206703.1 | S27: -210837.16 | T27: -215053.91 | U27: -219354.98 | V27: -223742.08 | W27: -228216.93 | X27: -232781.26 | Y27: -237436.89 | Z27: -242185.63 | AA27: -247029.34 | AB27: -251969.93 | AC27: -257009.32 | AD27: -262149.51
B28: =IF(C28<>"",SUBTOTAL(3,C$4:C28),"") -> 22 | C28: Vảy sạch | D28: tr. VND | F28: -77303.304 | G28: -108224.63 | H28: -157698.74 | I28: -160852.71 | J28: -164069.77 | K28: -167351.16 | L28: -170698.19 | M28: -174112.15 | N28: -177594.39 | O28: -181146.28 | P28: -184769.21 | Q28: -188464.59 | R28: -192233.88 | S28: -196078.56 | T28: -200000.13 | U28: -204000.14 | V28: -208080.14 | W28: -212241.74 | X28: -216486.58 | Y28: -220816.31 | Z28: -225232.63 | AA28: -229737.29 | AB28: -234332.03 | AC28: -239018.67 | AD28: -243799.05
B29: =IF(C29<>"",SUBTOTAL(3,C$4:C29),"") -> 23 | C29: Hao hụt | D29: tr. VND | F29: -5818.5282 | G29: -8145.9395 | H29: -11869.798 | I29: -12107.194 | J29: -12349.337 | K29: -12596.324 | L29: -12848.251 | M29: -13105.216 | N29: -13367.32 | O29: -13634.666 | P29: -13907.36 | Q29: -14185.507 | R29: -14469.217 | S29: -14758.601 | T29: -15053.773 | U29: -15354.849 | V29: -15661.946 | W29: -15975.185 | X29: -16294.688 | Y29: -16620.582 | Z29: -16952.994 | AA29: -17292.054 | AB29: -17637.895 | AC29: -17990.653 | AD29: -18350.466
B30: =IF(C30<>"",SUBTOTAL(3,C$4:C30),"") -> 24 | C30: Màu, phụ gia | D30: tr. VND | E30: 0 | F30: -632.43326 | G30: -885.40656 | H30: -1328.1098 | I30: -1394.5153 | J30: -1464.2411 | K30: -1537.4532 | L30: -1614.3258 | M30: -1695.0421 | N30: -1779.7942 | O30: -1868.7839 | P30: -1962.2231 | Q30: -2060.3343 | R30: -2163.351 | S30: -2271.5185 | T30: -2385.0945 | U30: -2504.3492 | V30: -2629.5666 | W30: -2761.045 | X30: -2899.0972 | Y30: -3044.0521 | Z30: -3196.2547 | AA30: -3356.0674 | AB30: -3523.8708 | AC30: -3700.0643 | AD30: -3885.0675
B31: =IF(C31<>"",SUBTOTAL(3,C$4:C31),"") -> 25 | C31: Màu Toner AY090 | D31: tr. VND | F31: -632.43326 | G31: -885.40656 | H31: -1328.1098 | I31: -1394.5153 | J31: -1464.2411 | K31: -1537.4532 | L31: -1614.3258 | M31: -1695.0421 | N31: -1779.7942 | O31: -1868.7839 | P31: -1962.2231 | Q31: -2060.3343 | R31: -2163.351 | S31: -2271.5185 | T31: -2385.0945 | U31: -2504.3492 | V31: -2629.5666 | W31: -2761.045 | X31: -2899.0972 | Y31: -3044.0521 | Z31: -3196.2547 | AA31: -3356.0674 | AB31: -3523.8708 | AC31: -3700.0643 | AD31: -3885.0675
B32: =IF(C32<>"",SUBTOTAL(3,C$4:C32),"") -> 26 | C32: Phụ gia AA Scavenger | D32: tr. VND | F32: 0 | G32: 0 | H32: 0 | I32: 0 | J32: 0 | K32: 0 | L32: 0 | M32: 0 | N32: 0 | O32: 0 | P32: 0 | Q32: 0 | R32: 0 | S32: 0 | T32: 0 | U32: 0 | V32: 0 | W32: 0 | X32: 0 | Y32: 0 | Z32: 0 | AA32: 0 | AB32: 0 | AC32: 0 | AD32: 0
B33: =IF(C33<>"",SUBTOTAL(3,C$4:C33),"") -> 27 | C33: Chi phí tạo phôi | D33: tr. VND | E33: 0 | F33: -8739.8001 | G33: -11537.321 | H33: -16468.955 | I33: -17241.075 | J33: -18051.8 | K33: -18903.063 | L33: -19796.888 | M33: -20735.404 | N33: -21720.846 | O33: -22755.561 | P33: -23842.011 | Q33: -24982.783 | R33: -25178.095 | S33: -26435.797 | T33: -27756.384 | U33: -29143 | V33: -30598.947 | W33: -32127.691 | X33: -33732.873 | Y33: -35418.314 | Z33: -37188.026 | AA33: -39046.225 | AB33: -40997.333 | AC33: -43045.996 | AD33: -45197.093
B34: =IF(C34<>"",SUBTOTAL(3,C$4:C34),"") -> 28 | C34: Chi phí điện | D34: tr. VND | F34: -5749.8012 | G34: -8049.7217 | H34: -12074.583 | I34: -12678.312 | J34: -13312.227 | K34: -13977.839 | L34: -14676.731 | M34: -15410.567 | N34: -16181.095 | O34: -16990.15 | P34: -17839.658 | Q34: -18731.641 | R34: -19668.223 | S34: -20651.634 | T34: -21684.215 | U34: -22768.426 | V34: -23906.847 | W34: -25102.19 | X34: -26357.299 | Y34: -27675.164 | Z34: -29058.923 | AA34: -30511.869 | AB34: -32037.462 | AC34: -33639.335 | AD34: -35321.302
B35: =IF(C35<>"",SUBTOTAL(3,C$4:C35),"") -> 29 | C35: Chi phí đóng bao bì | D35: tr. VND | F35: -975.00902 | G35: -1365.0126 | H35: -2047.519 | I35: -2149.8949 | J35: -2257.3896 | K35: -2370.2591 | L35: -2488.7721 | M35: -2613.2107 | N35: -2743.8712 | O35: -2881.0648 | P35: -3025.118 | Q35: -3176.3739 | R35: -3335.1926 | S35: -3501.9522 | T35: -3677.0499 | U35: -3860.9024 | V35: -4053.9475 | W35: -4256.6448 | X35: -4469.4771 | Y35: -4692.9509 | Z35: -4927.5985 | AA35: -5173.9784 | AB35: -5432.6773 | AC35: -5704.3112 | AD35: -5989.5268
B36: =IF(C36<>"",SUBTOTAL(3,C$4:C36),"") -> 30 | C36: Chi phí bằng tiền khác | D36: tr. VND | F36: -2014.9899 | G36: -2122.5868 | H36: -2346.8534 | I36: -2412.8682 | J36: -2482.1836 | K36: -2554.9648 | L36: -2631.3851 | M36: -2711.6264 | N36: -2795.8797 | O36: -2884.3457 | P36: -2977.2351 | Q36: -3074.7688 | R36: -2174.68 | S36: -2282.211 | T36: -2395.1185 | U36: -2513.6715 | V36: -2638.152 | W36: -2768.8566 | X36: -2906.0965 | Y36: -3050.1983 | Z36: -3201.5052 | AA36: -3360.3775 | AB36: -3527.1934 | AC36: -3702.35 | AD36: -3886.2645
B37: =IF(C37<>"",SUBTOTAL(3,C$4:C37),"")
B38: =IF(C38<>"",SUBTOTAL(3,C$4:C38),"") -> 31 | C38: TỔNG CHI PHÍ SẢN XUẤT | D38: tr. VND | E38: 0 | F38: -136144 | G38: -172443.23 | H38: -231914.84 | I38: -237089 | J38: -242420.12 | K38: -247914.03 | L38: -253576.78 | M38: -259414.69 | N38: -265434.38 | O38: -271642.72 | P38: -278046.9 | Q38: -284654.42 | R38: -265408.13 | S38: -272446.17 | T38: -279712.08 | U38: -287214.79 | V38: -294963.6 | W38: -302968.24 | X38: -311238.87 | Y38: -319786.1 | Z38: -328621.02 | AA38: -337755.22 | AB38: -347200.82 | AC38: -356970.49 | AD38: -367077.46
B39: =IF(C39<>"",SUBTOTAL(3,C$4:C39),"")
B40: =IF(C40<>"",SUBTOTAL(3,C$4:C40),"") -> 32 | C40: Chi phí vận chuyển | D40: tr. VND | F40: -2752.9667 | G40: -3854.1533 | H40: -5781.23 | I40: -6070.2915 | J40: -6373.8061 | K40: -6692.4964 | L40: -7027.1212 | M40: -7378.4772 | N40: -7747.4011 | O40: -8134.7711 | P40: -8541.5097 | Q40: -8968.5852 | R40: -9417.0144 | S40: -9887.8652 | T40: -10382.258 | U40: -10901.371 | V40: -11446.44 | W40: -12018.762 | X40: -12619.7 | Y40: -13250.685 | Z40: -13913.219 | AA40: -14608.88 | AB40: -15339.324 | AC40: -16106.29 | AD40: -16911.605
B41: =IF(C41<>"",SUBTOTAL(3,C$4:C41),"") -> 33 | C41: Chi phí nhân sự BH,QLDN | D41: tr. VND | F41: 0 | G41: 0 | H41: 0 | I41: 0 | J41: 0 | K41: 0 | L41: 0 | M41: 0 | N41: 0 | O41: 0 | P41: 0 | Q41: 0 | R41: 0 | S41: 0 | T41: 0 | U41: 0 | V41: 0 | W41: 0 | X41: 0 | Y41: 0 | Z41: 0 | AA41: 0 | AB41: 0 | AC41: 0 | AD41: 0
B42: =IF(C42<>"",SUBTOTAL(3,C$4:C42),"") -> 34 | C42: Chi phí quản lý chung | D42: tr. VND | F42: 0 | G42: 0 | H42: 0 | I42: 0 | J42: 0 | K42: 0 | L42: 0 | M42: 0 | N42: 0 | O42: 0 | P42: 0 | Q42: 0 | R42: 0 | S42: 0 | T42: 0 | U42: 0 | V42: 0 | W42: 0 | X42: 0 | Y42: 0 | Z42: 0 | AA42: 0 | AB42: 0 | AC42: 0 | AD42: 0
...

Sheet Sheet4
A3: Năm | B3: Dòng tiền | C3: Dòng tiền chiết khấu | D3: Dòng tiền chiết khấu Lũy kế
A4: 2026 | B4: {=TRANSPOSE('W3'!K168:AJ168)} -> -300749.8 | C4: {=TRANSPOSE('W3'!K170:AJ170)} -> -300749.8 | D4: =SUM(C$4:C4) -> -300749.8
A5: =A4+1 -> 2027 | B5: 26265.948 | C5: 24486.741 | D5: =SUM(C$4:C5) -> -276263.06
A6: =A5+1 -> 2028 | B6: 44419.022 | C6: 38605.112 | D6: =SUM(C$4:C6) -> -237657.95
A7: =A6+1 -> 2029 | B7: 68623.249 | C7: 55601.309 | D7: =SUM(C$4:C7) -> -182056.64
A8: =A7+1 -> 2030 | B8: 68927.026 | C8: 52064.439 | D8: =SUM(C$4:C8) -> -129992.2
A9: =A8+1 -> 2031 | B9: 69187.153 | C9: 48720.87 | D9: =SUM(C$4:C9) -> -81271.329
A10: =A9+1 -> 2032 | B10: 69400.272 | C10: 45560.519 | D10: =SUM(C$4:C10) -> -35710.81
A11: =A10+1 -> 2033 | B11: 69562.833 | C11: 42573.824 | D11: =SUM(C$4:C11) -> 6863.014
A12: =A11+1 -> 2034 | B12: 69671.083 | C12: 39751.715 | D12: =SUM(C$4:C12) -> 46614.729
A13: =A12+1 -> 2035 | B13: 69721.057 | C13: 37085.59 | D13: =SUM(C$4:C13) -> 83700.319
A14: =A13+1 -> 2036 | B14: 69708.569 | C14: 34567.288 | D14: =SUM(C$4:C14) -> 118267.61
A15: =A14+1 -> 2037 | B15: 69629.195 | C15: 32189.07 | D15: =SUM(C$4:C15) -> 150456.68
A16: =A15+1 -> 2038 | B16: 69478.267 | C16: 29943.595 | D16: =SUM(C$4:C16) -> 180400.27
... A29: =A28+1 -> 2051 | B29: 54131.439 | C29: 9373.4059 | D29: =SUM(C$4:C29) -> 399543.43

Sheet ||

Sheet Summary-cũ
B1: Công ty CP Nhựa tái chế Duy Tân
B2: Đơn vị: Kế toán quản trị
B3: DỰ ÁN FLAKES TO PREFORM SUNTORY - PEPSICO
B4: MỘT SỐ CHỈ TIÊU TRỌNG YẾU
B5: 15gr Hotfill | H5: GIÁ ĐỀ XUẤT - THÁNG 12/2025 : | I5: 680
A7: STT | B7: CHỈ TIÊU | C7: Đvt | E7: BÁO GIÁ LẦN 1-CÓ TÍNH ĐẦU TƯ XƯỞNG | F7: BÁO GIÁ LẦN 2 - CÓ TÍNH ĐẦU TƯ XƯỞNG | H7: CẬP NHẬT THÁNG 12 / 2025 | K7: CƠ SỞ
H8: TÍNH ĐẦU TƯ XƯỞNG | I8: KHÔNG TÍNH ĐẦU TƯ XƯỞNG | K8: KHÔNG TÍNH ĐẦU TƯ XƯỞNG
E9: Tháng 10/2024 | F9: Tháng 02/2025
A10: 1 | B10: Đơn giá bán phôi | C10: USD/tấn | E10: =E11*(1000000/'Cover Page'!$F$25)/EXR -> 1893.5897 | F10: =F11*(1000000/'Cover Page'!$F$25)/EXR -> 1843.5897 | H10: =H11*(1000000/'Cover Page'!$F$25)/EXR -> 1743.5897 | I10: =I11*(1000000/'Cover Page'!$F$25)/EXR -> 1743.5897 | K10: =K11*(1000000/'Cover Page'!$F$25)/EXR -> 1743.5897
A11: 2 | B11: Đơn giá bán phôi | C11: VND/phôi | E11: ='W5'!G4 -> 738.5 | F11: ='W5'!I4 -> 719 | H11: =I5 -> 680 | I11: =H11 -> 680 | K11: =I5 -> 680
A12: 3 | B12: Giá thành phôi | C12: USD/tấn | E12: =E13*(1000000/'Cover Page'!$F$25)/EXR -> 1777.0703 | F12: =F13*(1000000/'Cover Page'!$F$25)/EXR -> 1777.0703 | H12: =H13*(1000000/'Cover Page'!$F$25)/EXR -> 1722.3214 | I12: =I13*(1000000/'Cover Page'!$F$25)/EXR -> 1630.4375 | K12: =K13*(1000000/'Cover Page'!$F$25)/EXR -> 1565.4277
A13: 4 | B13: Giá thành phôi | C13: VND/phôi | E13: ='W5'!G6 -> 693.05742 | F13: ='W5'!I6 -> 693.05742 | H13: ='W5'!M6 -> 671.70535 | I13: ='W5'!O6 -> 635.87063 | K13: ='W5'!E6 -> 610.51682
A14: 5 | B14: Lợi nhuận sau thuế | C14: USD/tấn | E14: =E15*(1000000/'Cover Page'!$F$25)/EXR -> 93.215542 | F14: =F15*(1000000/'Cover Page'!$F$25)/EXR -> 53.215542 | H14: =H15*(1000000/'Cover Page'!$F$25)/EXR -> 17.014676 | I14: =I15*(1000000/'Cover Page'!$F$25)/EXR -> 90.521787 | K14: =K15*(1000000/'Cover Page'!$F$25)/EXR -> 142.5296
A15: 6 | B15: Lợi nhuận sau thuế | C15: VND/phôi | E15: ='W5'!G8 -> 36.354061 | F15: ='W5'!I8 -> 20.754061 | H15: ='W5'!M8 -> 6.6357236 | I15: ='W5'!O8 -> 35.303497 | K15: ='W5'!E8 -> 55.586543
B16: %LN sau thuế | E16: ='W5'!G10 -> 0.049226894 | F16: ='W5'!I10 -> 0.028865176 | H16: ='W5'!M10 -> 0.0097584171 | I16: ='W5'!O10 -> 0.051916907 | K16: ='W5'!E10 -> 0.081744916
A17: 7 | B17: Chi phí đầu tư | C17: USD | E17: =IF(Currency="USD",'W1'!$N$60,'W1'!$N$60/EXR) -> 18708231 | F17: =IF(Currency="USD",'W1'!$S$60,'W1'!$S$60/EXR) -> 18708231 | H17: =IF(Currency="USD",'W1'!$AC$60,'W1'!$AC$60/EXR) -> 17884231 | I17: =IF(Currency="USD",'W1'!$AH$60,'W1'!$AH$60/EXR) -> 12115000 | K17: =IF(Currency="USD",'W1'!$I$60,'W1'!$I$60/EXR) -> 11567300
A18: 8 | B18: Đầu tư | C18: tỷ VND | E18: =E17*EXR/10^9 -> 486.414 | F18: =F17*EXR/10^9 -> 486.414 | H18: =H17*EXR/10^9 -> 464.99 | I18: =I17*EXR/10^9 -> 314.99 | K18: =K17*EXR/10^9 -> 300.7498
A19: 9 | B19: NPV | C19: tỷ VND | E19: ='W5'!G15/10^3 -> 293.02276 | F19: ='W5'!I15/10^3 -> 214.92889 | H19: ='W5'!M15/10^3 -> 258.1737 | I19: ='W5'!O15/10^3 -> 131.84102 | K19: ='W5'!E15/10^3 -> 399.54343
A20: 10 | B20: Thời gian hoàn vốn | C20: năm | E20: ='W5'!G13 -> 10 năm 04 tháng | F20: ='W5'!I13 -> 11 năm 08 tháng | H20: ='W5'!M13 -> 13 năm 08 tháng | I20: ='W5'!O13 -> 8 năm 02 tháng | K20: ='W5'!E13 -> 6 năm 11 tháng
A21: 11 | B21: % Lãi gộp nguyên liệu/Giá bán | C21: % | E21: ='W5'!H108 -> 0.4648998 | F21: ='W5'!J108 -> 0.45038734 | H21: ='W5'!N108 -> 0.4384 | I21: ='W5'!P108 -> 0.4384 | K21: ='W5'!F108 -> 0.4384
B23: Ghi chú: Tất cả trường hợp đều có khuôn

Sheet Summary
B1: Công ty CP Nhựa tái chế Duy Tân
B2: Đơn vị: Kế toán quản trị
B3: DỰ ÁN FLAKES TO PREFORM SUNTORY - PEPSICO
B4: MỘT SỐ CHỈ TIÊU TRỌNG YẾU
B5: 15gr Hotfill | H5: GIÁ ĐỀ XUẤT - THÁNG 12/2025 :
I6: 680
E7: Paste chết | F7: Paste chết | N7: Paste chết | O7: Paste chết
A8: STT | B8: CHỈ TIÊU | C8: Đvt | E8: BÁO GIÁ LẦN 1-CÓ TÍNH ĐẦU TƯ XƯỞNG | F8: BÁO GIÁ LẦN 2 - CÓ TÍNH ĐẦU TƯ XƯỞNG | H8: CƠ SỞ | K8: CẬP NHẬT THÁNG 12 / 2025 - BÁO GIÁ | N8: CƠ SỞ-BÁO GIÁ L1- KHÔNG TÍNH ĐẦU TƯ XƯỞNG | O8: CƠ SỞ-BÁO GIÁ L2- KHÔNG TÍNH ĐẦU TƯ XƯỞNG
H9: KHÔNG TÍNH ĐẦU TƯ XƯỞNG | I9: CÓ TÍNH ĐẦU TƯ XƯỞNG | K9: KHÔNG TÍNH ĐẦU TƯ XƯỞNG | L9: TÍNH ĐẦU TƯ XƯỞNG
E10: Tháng 10/2024 | F10: Tháng 02/2025 | N10: Tháng 10/2024 | O10: Tháng 02/2025
A11: 1 | B11: Đơn giá bán phôi | C11: USD/tấn | E11: 1969.3333 | F11: 1916 | H11: =H12*(1000000/'Cover Page'!$F$25)/EXR -> 1743.5897 | I11: =I12*(1000000/'Cover Page'!$F$25)/EXR -> 1743.5897 | K11: =K12*(1000000/'Cover Page'!$F$25)/EXR -> 1743.5897 | L11: =L12*(1000000/'Cover Page'!$F$25)/EXR -> 1743.5897 | N11: 1941.3333 | O11: 1941.3333
A12: 2 | B12: Đơn giá bán phôi | C12: VND/phôi | E12: 738.5 | F12: 718.5 | H12: =I6 -> 680 | I12: =I6 -> 680 | K12: =L12 -> 680 | L12: =I6 -> 680 | N12: 728 | O12: 728
A13: 3 | B13: Giá thành phôi | C13: USD/tấn | E13: 1860.577 | F13: 1793.6349 | H13: =H14*(1000000/'Cover Page'!$F$25)/EXR -> 1565.4277 | I13: =I14*(1000000/'Cover Page'!$F$25)/EXR -> 1650.7494 | K13: =K14*(1000000/'Cover Page'!$F$25)/EXR -> 1630.4375 | L13: =L14*(1000000/'Cover Page'!$F$25)/EXR -> 1722.3214 | N13: 1669.9635 | O13: 1609.1598
A14: 4 | B14: Giá thành phôi | C14: VND/phôi | E14: 697.71636 | F14: 672.61307 | H14: ='W5'!E6 -> 610.51682 | I14: ='W5'!K6 -> 643.79228 | K14: ='W5'!O6 -> 635.87063 | L14: ='W5'!M6 -> 671.70535 | N14: 626.2363 | O14: 603.43491
A15: 5 | B15: Lợi nhuận sau thuế | C15: USD/tấn | E15: 87.005099 | F15: 97.892107 | H15: =H16*(1000000/'Cover Page'!$F$25)/EXR -> 142.5296 | I15: =I16*(1000000/'Cover Page'!$F$25)/EXR -> 74.272251 | K15: =K16*(1000000/'Cover Page'!$F$25)/EXR -> 90.521787 | L15: =L16*(1000000/'Cover Page'!$F$25)/EXR -> 17.014676 | N15: 199.32165 | O15: 247.96461
A16: 6 | B16: Lợi nhuận sau thuế | C16: VND/phôi | E16: 32.626912 | F16: 36.70954 | H16: ='W5'!E8 -> 55.586543 | I16: ='W5'!K8 -> 28.966178 | K16: ='W5'!O8 -> 35.303497 | L16: ='W5'!M8 -> 6.6357236 | N16: 74.745621 | O16: 92.986729
B17: %LN sau thuế | E17: 0.044179976 | F17: 0.051091914 | H17: ='W5'!E10 -> 0.081744916 | I17: ='W5'!K10 -> 0.04259732 | K17: ='W5'!O10 -> 0.051916907 | L17: ='W5'!M10 -> 0.0097584171 | N17: 0.11182825 | O17: 0.12772902
A18: 7 | B18: Chi phí đầu tư | C18: USD | E18: 17070000 | F18: 17070000 | H18: =IF(Currency="USD",'W1'!$I$60,'W1'!$I$60/EXR) -> 11567300 | I18: =IF(Currency="USD",'W1'!$X$60,'W1'!$X$60/EXR) -> 17336531 | K18: =IF(Currency="USD",'W1'!$AH$60,'W1'!$AH$60/EXR) -> 12115000 | L18: =IF(Currency="USD",'W1'!$AC$60,'W1'!$AC$60/EXR) -> 17884231 | N18: 10054913 | O18: 10054913
A19: 8 | B19: Đầu tư | C19: tỷ VND | E19: 426.75 | F19: 426.75 | H19: =H18*EXR/10^9 -> 300.7498 | I19: =I18*EXR/10^9 -> 450.7498 | K19: =K18*EXR/10^9 -> 314.99 | L19: =L18*EXR/10^9 -> 464.99 | N19: 251.37282 | O19: 251.37282
A20: 9 | B20: NPV | C20: tỷ VND | E20: 284.37183 | F20: 240.81878 | H20: ='W5'!E15/10^3 -> 399.54343 | I20: ='W5'!K15/10^3 -> 258.1737 | K20: ='W5'!O15/10^3 -> 131.84102 | L20: ='W5'!M15/10^3 -> 258.1737 | N20: 491.97502 | O20: 487.89218
A21: 10 | B21: Thời gian hoàn vốn | C21: năm | E21: 9 năm 08 tháng | F21: 10 năm 08 tháng | H21: ='W5'!E13 -> 6 năm 11 tháng | I21: ='W5'!K13 -> 10 năm 11 tháng | K21: ='W5'!O13 -> 8 năm 02 tháng | L21: ='W5'!M13 -> 13 năm 08 tháng | N21: 5 năm 05 tháng | O21: 5 năm 07 tháng
A22: 11 | B22: % Lãi gộp nguyên liệu/Giá bán | C22: % | E22: 0.4648998 | F22: 0.45000487 | H22: ='W5'!F108 -> 0.4384 | I22: ='W5'!L108 -> 0.4384 | K22: ='W5'!P108 -> 0.4384 | L22: ='W5'!N108 -> 0.4384 | N22: 0.45718201 | O22: 0.45718201
B26: Đầu tư khuôn | H26: x | I26: x | K26: x | L26: x
B27: Đầu tư xưởng | E27: x | F27: x | I27: x | L27: x
B29: Vảy sạch | E29: 1033 | F29: 1033

Sheet Cover Page
D3: COVER PAGE
D4: CHỈ TIÊU | H4: Base | K4: BÁO GIÁ L1 | N4: BÁO GIÁ L2 | Q4: Base-CÓ XƯỞNG | T4: UPDATED T12.25 | W4: UPDATED T12.25-KHÔNG CÓ THUÊ XƯỜNG | Z4: Công suất máy
C5: STT | D5: GIẢ ĐỊNH | E5: Đvt | F5: CHUNG | H5: OPTION 1 | K5: OPTION 2 | N5: OPTION 3 | Q5: OPTION 4 | T5: OPTION 5 | W5: OPTION 6 | Z5: Công suất máy
C6: 1 | D6: CAPEX | H6: Thực tế | K6: 0.07 | N6: 0.07 | Q6: 0 | T6: 0 | W6: 0
C7: 2 | D7: Chi phí sản xuất | H7: Thực tế | K7: 0.05 | N7: 0.05 | Q7: 0 | T7: 0.05 | W7: 0.05
D8: Chi phí vảy tăng | H8: 0.02 | K8: 0.02 | N8: 0.02 | Q8: 0.02 | T8: 0.02 | W8: 0.02
C9: 3 | D9: Lạm Phát | F9: 0.05
C10: 4 | D10: Tỷ giá | F10: 26000
C11: 5 | D11: Thuế suất TNDN: | F11: 0.2
C12: 6 | D12: Mark-up giá bán | H12: =5%/(1-Tax_rate-5%) -> 0.066666667 | K12: =5%/(1-Tax_rate-5%) -> 0.066666667 | N12: =5%/(1-Tax_rate-5%) -> 0.066666667 | Q12: =5%/(1-Tax_rate-5%) -> 0.066666667 | T12: =5%/(1-Tax_rate-5%) -> 0.066666667 | W12: =5%/(1-Tax_rate-5%) -> 0.066666667
C13: 7.1 | D13: Đơn giá ban đầu | E13: tr. VND/tấn | H13: =H14*PHOI_KG*10^3/10^6 -> 45.333333 | K13: =K14*PHOI_KG*10^3/10^6 -> 49.233333 | N13: =N14*PHOI_KG*10^3/10^6 -> 47.933333 | Q13: =Q14*PHOI_KG*10^3/10^6 -> 45.333333 | T13: =T14*PHOI_KG*10^3/10^6 -> 45.333333 | W13: =W14*PHOI_KG*10^3/10^6 -> 45.333333
C14: 7.2 | D14: Đơn giá ban đầu | E14: VND/phôi | H14: ='W5'!U2 -> 680 | K14: ='W5'!V2 -> 738.5 | N14: ='W5'!W2 -> 719 | Q14: ='W5'!X2 -> 680 | T14: ='W5'!Y2 -> 680 | W14: ='W5'!Z2 -> 680 | Y14: Lấy số từ W5
C15: 7.3 | D15: Đơn giá ban đầu | E15: USD/tấn | H15: =H13/EXR*10^6 -> 1743.5897 | K15: =K13/EXR*10^6 -> 1893.5897 | N15: =N13/EXR*10^6 -> 1843.5897 | Q15: =Q13/EXR*10^6 -> 1743.5897 | T15: =T13/EXR*10^6 -> 1743.5897 | W15: =W13/EXR*10^6 -> 1743.5897
C16: 7.4 | D16: Đơn giá ban đầu | E16: USD/1.000 phôi | H16: =H15/PHOI_KG -> 26.153846 | K16: =K15/PHOI_KG -> 28.403846 | W16: =W15/PHOI_KG -> 26.153846
C17: 8 | D17: Tỷ lệ tăng đơn giá | H17: 0.02 | K17: 0.02 | N17: 0.02 | Q17: 0.02 | T17: 0.02 | W17: 0.02 | Y17: tăng mỗi năm
C19: 9.1 | D19: Lãi suất đi vay: | H19: 0.07 | K19: 0.08 | N19: 0.08 | Q19: 0.07 | T19: 0.08 | W19: 0.08
C20: 9.2 | D20: Lợi nhuận mong muốn cổ đông: | H20: 0.1 | K20: 0.1 | N20: 0.1 | Q20: 0.1 | T20: 0.1 | W20: 0.1
C21: 9.3 | D21: Cơ cấu vay mong muốn: | H21: 0.7 | K21: 0.7 | N21: 0.7 | Q21: 0.7 | T21: 0.7 | W21: 0.7
C22: 9.4 | D22: Cơ cấu VCSH: | H22: =1-H21 -> 0.3 | K22: =1-K21 -> 0.3 | N22: =1-N21 -> 0.3 | Q22: =1-Q21 -> 0.3 | T22: =1-T21 -> 0.3 | W22: =1-W21 -> 0.3
C23: 9.5 | D23: WACC: | H23: =(H19*H21*(1-Tax_rate)+H20*H22)*(1+Inflation) -> 0.07266 | K23: =(K19*K21*(1-Tax_rate)+K20*K22)*(1+Inflation) -> 0.07854 | N23: =(N19*N21*(1-Tax_rate)+N20*N22)*(1+Inflation) -> 0.07854 | Q23: =(Q19*Q21*(1-Tax_rate)+Q20*Q22)*(1+Inflation) -> 0.07266 | T23: =(T19*T21*(1-Tax_rate)+T20*T22)*(1+Inflation) -> 0.07854 | W23: =(W19*W21*(1-Tax_rate)+W20*W22)*(1+Inflation) -> 0.07854
C25: 10.1 | D25: Khuôn phôi | E25: gram | F25: 15
C26: 10.2 | D26: Số lượng phôi/chu kỳ: | E26: phôi/chu kỳ | F26: 128
C27: 10.3 | D27: Chu kỳ | E27: giây | F27: 8
C28: 10.4 | D28: Công suất | E28: kg/giờ | F28: =60*60/F27*F26*F25/10^3 -> 864
C29: 10.5 | D29: Công suất | E29: phôi/giờ | F29: =Capacity/F25*10^3 -> 57600
C30: 10.6 | D30: Số phôi/kg | E30: phôi/kg | F30: =1000/F25 -> 66.666667
A33: =MD!A7 -> VND | D33: KẾT QUẢ
A34: =IF(Currency="USD",1,0.000001) -> 1e-06 | C34: 11 | D34: Tổng mức đầu tư | E34: =IF(Currency="USD","USD","triệu VND") -> triệu VND | H34: ='W1'!I60*$A$34 -> 300749.8 | K34: ='W1'!N60*$A$34 -> 486414 | N34: ='W1'!S60*$A$34 -> 486414 | Q34: ='W1'!X60*$A$34 -> 450749.8 | T34: ='W1'!AC60*$A$34 -> 464990 | W34: ='W1'!AH60*$A$34 -> 314990
B35: DPP | C35: 12 | D35: Thời gian thu hồi vốn | E35: năm | H35: =SUMIFS('W3'!$K$18:$K$1018,'W3'!$A$18:$A$1018,H$5,'W3'!$D$18:$D$1018,$B$35) -> 6.9 | K35: =SUMIFS('W3'!$K$18:$K$1018,'W3'!$A$18:$A$1018,K$5,'W3'!$D$18:$D$1018,$B$35) -> 10.3 | N35: =SUMIFS('W3'!$K$18:$K$1018,'W3'!$A$18:$A$1018,N$5,'W3'!$D$18:$D$1018,$B$35) -> 11.7 | Q35: =SUMIFS('W3'!$K$18:$K$1018,'W3'!$A$18:$A$1018,Q$5,'W3'!$D$18:$D$1018,$B$35) -> 10.9 | T35: =SUMIFS('W3'!$K$18:$K$1018,'W3'!$A$18:$A$1018,T$5,'W3'!$D$18:$D$1018,$B$35) -> 13.7 | W35: =SUMIFS('W3'!$K$18:$K$1018,'W3'!$A$18:$A$1018,W$5,'W3'!$D$18:$D$1018,$B$35) -> 8.2
H36: =INT(H35)&" năm "&IF(MOD(H35,1)*12=0,,TEXT(MOD(H35,1)*12,"00")&" tháng") -> 6 năm 11 tháng | K36: =INT(K35)&" năm "&IF(MOD(K35,1)*12=0,,TEXT(MOD(K35,1)*12,"00")&" tháng") -> 10 năm 04 tháng | N36: =INT(N35)&" năm "&IF(MOD(N35,1)*12=0,,TEXT(MOD(N35,1)*12,"00")&" tháng") -> 11 năm 08 tháng | Q36: =INT(Q35)&" năm "&IF(MOD(Q35,1)*12=0,,TEXT(MOD(Q35,1)*12,"00")&" tháng") -> 10 năm 11 tháng | T36: =INT(T35)&" năm "&IF(MOD(T35,1)*12=0,,TEXT(MOD(T35,1)*12,"00")&" tháng") -> 13 năm 08 tháng | W36: =INT(W35)&" năm "&IF(MOD(W35,1)*12=0,,TEXT(MOD(W35,1)*12,"00")&" tháng") -> 8 năm 02 tháng
B37: IRR | C37: 13 | D37: Tỷ suất hoàn vốn nội bộ (IRR) | E37: % | H37: =SUMIFS('W3'!$K$18:$K$1018,'W3'!$A$18:$A$1018,H$5,'W3'!$D$18:$D$1018,$B$37) -> 0.19092375 | K37: =SUMIFS('W3'!$K$18:$K$1018,'W3'!$A$18:$A$1018,K$5,'W3'!$D$18:$D$1018,$B$37) -> 0.13870388 | N37: =SUMIFS('W3'!$K$18:$K$1018,'W3'!$A$18:$A$1018,N$5,'W3'!$D$18:$D$1018,$B$37) -> 0.12432694 | Q37: =SUMIFS('W3'!$K$18:$K$1018,'W3'!$A$18:$A$1018,Q$5,'W3'!$D$18:$D$1018,$B$37) -> 0.1285189 | T37: =SUMIFS('W3'!$K$18:$K$1018,'W3'!$A$18:$A$1018,T$5,'W3'!$D$18:$D$1018,$B$37) -> 0.10937322 | W37: =SUMIFS('W3'!$K$18:$K$1018,'W3'!$A$18:$A$1018,W$5,'W3'!$D$18:$D$1018,$B$37) -> 0.16522194
D39: Đơn giá năm đầu | E39: VND/phôi | H39: =H14 -> 680 | K39: =K14 -> 738.5 | N39: =N14 -> 719 | Q39: =Q14 -> 680 | T39: =T14 -> 680 | W39: =W14 -> 680
D40: Đơn giá năm đầu | E40: USD/tấn | H40: =H15 -> 1743.5897 | K40: =K15 -> 1893.5897 | N40: =N15 -> 1843.5897 | Q40: =Q15 -> 1743.5897 | T40: =T15 -> 1743.5897 | W40: =W15 -> 1743.5897
B42: NPV | C42: 14 | D42: Dòng tiền chiết khẩu | E42: =IF(Currency="USD","USD","triệu VND") -> triệu VND | H42: =SUM(H43:H68) -> 399543.43 | K42: =SUM(K43:K68) -> 293022.76 | N42: =SUM(N43:N68) -> 214928.89 | Q42: =SUM(Q43:Q68) -> 258173.7 | T42: =SUM(T43:T68) -> 131841.02 | W42: =SUM(W43:W68) -> 273643.27
D43: 0 | E43: =IF(Currency="USD","USD","triệu VND") -> triệu VND | H43: {=SUMPRODUCT('W3'!$K$18:$AJ$1018*('W3'!$A$18:$A$1018=H$5)*('W3'!$D$18:$D$1018=$B$42)*('W3'!$K$14:$AJ$14='Cover Page'!$D43))} -> -300749.8 | K43: {=SUMPRODUCT('W3'!$K$18:$AJ$1018*('W3'!$A$18:$A$1018=K$5)*('W3'!$D$18:$D$1018=$B$42)*('W3'!$K$14:$AJ$14='Cover Page'!$D43))} -> -486414 | N43: {=SUMPRODUCT('W3'!$K$18:$AJ$1018*('W3'!$A$18:$A$1018=N$5)*('W3'!$D$18:$D$1018=$B$42)*('W3'!$K$14:$AJ$14='Cover Page'!$D43))} -> -486414 | Q43: {=SUMPRODUCT('W3'!$K$18:$AJ$1018*('W3'!$A$18:$A$1018=Q$5)*('W3'!$D$18:$D$1018=$B$42)*('W3'!$K$14:$AJ$14='Cover Page'!$D43))} -> -450749.8 | T43: {=SUMPRODUCT('W3'!$K$18:$AJ$1018*('W3'!$A$18:$A$1018=T$5)*('W3'!$D$18:$D$1018=$B$42)*('W3'!$K$14:$AJ$14='Cover Page'!$D43))} -> -464990 | W43: {=SUMPRODUCT('W3'!$K$18:$AJ$1018*('W3'!$A$18:$A$1018=W$5)*('W3'!$D$18:$D$1018=$B$42)*('W3'!$K$14:$AJ$14='Cover Page'!$D43))} -> -314990 | AH43: Giả định: sau 25 năm thì giá trị các tài sản còn lại =0
D44: 1 | E44: =IF(Currency="USD","USD","triệu VND") -> triệu VND | H44: {=SUMPRODUCT('W3'!$K$18:$AJ$1018*('W3'!$A$18:$A$1018=H$5)*('W3'!$D$18:$D$1018=$B$42)*('W3'!$K$14:$AJ$14='Cover Page'!$D44))} -> 24486.741 | K44: {=SUMPRODUCT('W3'!$K$18:$AJ$1018*('W3'!$A$18:$A$1018=K$5)*('W3'!$D$18:$D$1018=$B$42)*('W3'!$K$14:$AJ$14='Cover Page'!$D44))} -> 28874.473 | N44: {=SUMPRODUCT('W3'!$K$18:$AJ$1018*('W3'!$A$18:$A$1018=N$5)*('W3'!$D$18:$D$1018=$B$42)*('W3'!$K$14:$AJ$14='Cover Page'!$D44))} -> 25888.055 | Q44: {=SUMPRODUCT('W3'!$K$18:$AJ$1018*('W3'!$A$18:$A$1018=Q$5)*('W3'!$D$18:$D$1018=$B$42)*('W3'!$K$14:$AJ$14='Cover Page'!$D44))} -> 25193.769 | T44: {=SUMPRODUCT('W3'!$K$18:$AJ$1018*('W3'!$A$18:$A$1018=T$5)*('W3'!$D$18:$D$1018=$B$42)*('W3'!$K$14:$AJ$14='Cover Page'!$D44))} -> 22047.471 | W44: {=SUMPRODUCT('W3'!$K$18:$AJ$1018*('W3'!$A$18:$A$1018=W$5)*('W3'!$D$18:$D$1018=$B$42)*('W3'!$K$14:$AJ$14='Cover Page'!$D44))} -> 21344.298
D45: 2 | E45: =IF(Currency="USD","USD","triệu VND") -> triệu VND | H45: {=SUMPRODUCT('W3'!$K$18:$AJ$1018*('W3'!$A$18:$A$1018=H$5)*('W3'!$D$18:$D$1018=$B$42)*('W3'!$K$14:$AJ$14='Cover Page'!$D45))} -> 38605.112 | K45: {=SUMPRODUCT('W3'!$K$18:$AJ$1018*('W3'!$A$18:$A$1018=K$5)*('W3'!$D$18:$D$1018=$B$42)*('W3'!$K$14:$AJ$14='Cover Page'!$D45))} -> 44790.183 | N45: {=SUMPRODUCT('W3'!$K$18:$AJ$1018*('W3'!$A$18:$A$1018=N$5)*('W3'!$D$18:$D$1018=$B$42)*('W3'!$K$14:$AJ$14='Cover Page'!$D45))} -> 40836.129 | Q45: {=SUMPRODUCT('W3'!$K$18:$AJ$1018*('W3'!$A$18:$A$1018=Q$5)*('W3'!$D$18:$D$1018=$B$42)*('W3'!$K$14:$AJ$14='Cover Page'!$D45))} -> 39264.247 | T45: {=SUMPRODUCT('W3'!$K$18:$AJ$1018*('W3'!$A$18:$A$1018=T$5)*('W3'!$D$18:$D$1018=$B$42)*('W3'!$K$14:$AJ$14='Cover Page'!$D45))} -> 35572.147 | W45: {=SUMPRODUCT('W3'!$K$18:$AJ$1018*('W3'!$A$18:$A$1018=W$5)*('W3'!$D$18:$D$1018=$B$42)*('W3'!$K$14:$AJ$14='Cover Page'!$D45))} -> 34920.18
D46: 3 | E46: =IF(Currency="USD","USD","triệu VND") -> triệu VND | H46: {=SUMPRODUCT('W3'!$K$18:$AJ$1018*('W3'!$A$18:$A$1018=H$5)*('W3'!$D$18:$D$1018=$B$42)*('W3'!$K$14:$AJ$14='Cover Page'!$D46))} -> 55601.309 | K46: {=SUMPRODUCT('W3'!$K$18:$AJ$1018*('W3'!$A$18:$A$1018=K$5)*('W3'!$D$18:$D$1018=$B$42)*('W3'!$K$14:$AJ$14='Cover Page'!$D46))} -> 63999.38 | N46: {=SUMPRODUCT('W3'!$K$18:$AJ$1018*('W3'!$A$18:$A$1018=N$5)*('W3'!$D$18:$D$1018=$B$42)*('W3'!$K$14:$AJ$14='Cover Page'!$D46))} -> 58657.324 | Q46: {=SUMPRODUCT('W3'!$K$18:$AJ$1018*('W3'!$A$18:$A$1018=Q$5)*('W3'!$D$18:$D$1018=$B$42)*('W3'!$K$14:$AJ$14='Cover Page'!$D46))} -> 56215.796 | T46: {=SUMPRODUCT('W3'!$K$18:$AJ$1018*('W3'!$A$18:$A$1018=T$5)*('W3'!$D$18:$D$1018=$B$42)*('W3'!$K$14:$AJ$14='Cover Page'!$D46))} -> 51421.521 | W46: {=SUMPRODUCT('W3'!$K$18:$AJ$1018*('W3'!$A$18:$A$1018=W$5)*('W3'!$D$18:$D$1018=$B$42)*('W3'!$K$14:$AJ$14='Cover Page'!$D46))} -> 50817.03
D47: 4 | E47: =IF(Currency="USD","USD","triệu VND") -> triệu VND | H47: {=SUMPRODUCT('W3'!$K$18:$AJ$1018*('W3'!$A$18:$A$1018=H$5)*('W3'!$D$18:$D$1018=$B$42)*('W3'!$K$14:$AJ$14='Cover Page'!$D47))} -> 52064.439 | K47: {=SUMPRODUCT('W3'!$K$18:$AJ$1018*('W3'!$A$18:$A$1018=K$5)*('W3'!$D$18:$D$1018=$B$42)*('W3'!$K$14:$AJ$14='Cover Page'!$D47))} -> 59609.212 | N47: {=SUMPRODUCT('W3'!$K$18:$AJ$1018*('W3'!$A$18:$A$1018=N$5)*('W3'!$D$18:$D$1018=$B$42)*('W3'!$K$14:$AJ$14='Cover Page'!$D47))} -> 54557.108 | Q47: {=SUMPRODUCT('W3'!$K$18:$AJ$1018*('W3'!$A$18:$A$1018=Q$5)*('W3'!$D$18:$D$1018=$B$42)*('W3'!$K$14:$AJ$14='Cover Page'!$D47))} -> 52637.301 | T47: {=SUMPRODUCT('W3'!$K$18:$AJ$1018*('W3'!$A$18:$A$1018=T$5)*('W3'!$D$18:$D$1018=$B$42)*('W3'!$K$14:$AJ$14='Cover Page'!$D47))} -> 47715.111 | W47: {=SUMPRODUCT('W3'!$K$18:$AJ$1018*('W3'!$A$18:$A$1018=W$5)*('W3'!$D$18:$D$1018=$B$42)*('W3'!$K$14:$AJ$14='Cover Page'!$D47))} -> 47154.64
D48: 5 | E48: =IF(Currency="USD","USD","triệu VND") -> triệu VND | H48: {=SUMPRODUCT('W3'!$K$18:$AJ$1018*('W3'!$A$18:$A$1018=H$5)*('W3'!$D$18:$D$1018=$B$42)*('W3'!$K$14:$AJ$14='Cover Page'!$D48))} -> 48720.87 | K48: {=SUMPRODUCT('W3'!$K$18:$AJ$1018*('W3'!$A$18:$A$1018=K$5)*('W3'!$D$18:$D$1018=$B$42)*('W3'!$K$14:$AJ$14='Cover Page'!$D48))} -> 55484.945 | N48: {=SUMPRODUCT('W3'!$K$18:$AJ$1018*('W3'!$A$18:$A$1018=N$5)*('W3'!$D$18:$D$1018=$B$42)*('W3'!$K$14:$AJ$14='Cover Page'!$D48))} -> 50707.054 | Q48: {=SUMPRODUCT('W3'!$K$18:$AJ$1018*('W3'!$A$18:$A$1018=Q$5)*('W3'!$D$18:$D$1018=$B$42)*('W3'!$K$14:$AJ$14='Cover Page'!$D48))} -> 49254.927 | T48: {=SUMPRODUCT('W3'!$K$18:$AJ$1018*('W3'!$A$18:$A$1018=T$5)*('W3'!$D$18:$D$1018=$B$42)*('W3'!$K$14:$AJ$14='Cover Page'!$D48))} -> 44237.28 | W48: {=SUMPRODUCT('W3'!$K$18:$AJ$1018*('W3'!$A$18:$A$1018=W$5)*('W3'!$D$18:$D$1018=$B$42)*('W3'!$K$14:$AJ$14='Cover Page'!$D48))} -> 43717.622
...

Sheet W1
D1: Công ty CP Nhựa tái chế Duy Tân
D2: Đơn vị: Kế toán quản trị
D3: DỰ ÁN FLAKES TO PREFORM SUNTORY - PEPSICO
D4: TỔNG CHI PHÍ ĐẦU TƯ
D5: =Currency -> VND | N5: (không tăng chi phí xây dựng nhà xưởng) - Roundup | S5: (không tăng chi phí xây dựng nhà xưởng) | X5: (không tăng chi phí xây dựng nhà xưởng) | AC5: (không tăng chi phí xây dựng nhà xưởng) | AH5: (không tăng chi phí xây dựng nhà xưởng)
D6: =IF(D5="VND",1,EXR) -> 1 | I6: Option 1 | J6: BASE | N6: Option 2 | O6: =Opt2_CAPEX -> 0.07 | S6: Option 3 | T6: =Opt3_CAPEX -> 0.07 | X6: Option 4 | Y6: =Opt4_CAPEX -> 0 | AC6: Option 5 | AD6: =Opt5_CAPEX -> 0 | AH6: Option 6 | AI6: =Opt6_CAPEX -> 0
C7: STT | D7: HẠNG MỤC | E7: Số lượng | G7: Thời gian khấu hao | H7: Đơn giá | I7: Giá trị đầu tư | J7: Khấu hao | L7: Thời gian khấu hao | M7: Đơn giá | N7: Giá trị đầu tư | O7: Khấu hao | Q7: Thời gian khấu hao | R7: Đơn giá | S7: Giá trị đầu tư | T7: Khấu hao | V7: Thời gian khấu hao | W7: Đơn giá | X7: Giá trị đầu tư | Y7: Khấu hao | AA7: Thời gian khấu hao | AB7: Đơn giá | AC7: Giá trị đầu tư | AD7: Khấu hao | AF7: Thời gian khấu hao | AG7: Đơn giá | AH7: Giá trị đầu tư | AI7: Khấu hao | AK7: NHẬP KHẨU TỪ | AL7: Nguồn: | AM7: Ghi chú - Nếu dừng dự án thì Suntory mua lại | AO7: Option 1 | AP7: =AO7 -> Option 1 | AQ7: =AP7 -> Option 1 | AR7: =AQ7 -> Option 1 | AS7: =AR7 -> Option 1 | AT7: =AS7 -> Option 1 | AU7: =AT7 -> Option 1 | AV7: =AU7 -> Option 1 | AW7: =AV7 -> Option 1 | ... BR7: =BQ7 -> Option 1 | BT7: Option 2 | BU7: =BT7 -> Option 2 | BV7: =BU7 -> Option 2 | BW7: =BV7 -> Option 2 | BX7: =BW7 -> Option 2 | BY7: =BX7 -> Option 2 | BZ7: =BY7 -> Option 2 | CA7: =BZ7 -> Option 2 | CB7: =CA7 -> Option 2 | ... CW7: =CV7 -> Option 2 | CY7: Option 3 | CZ7: Option 3 | DA7: Option 3 | DB7: Option 3 | DC7: Option 3 | DD7: Option 3 | DE7: Option 3 | DF7: Option 3 | DG7: Option 3 | DH7: Option 3 | DI7: Option 3 | DJ7: Option 3 | DK7: Option 3 | DL7: Option 3 | DM7: Option 3 | DN7: Option 3 | DO7: Option 3 | DP7: Option 3 | DQ7: Option 3 | DR7: Option 3 | DS7: Option 3 | DT7: Option 3 | DU7: Option 3 | DV7: Option 3 | DW7: Option 3 | DX7: Option 3 | DY7: Option 3 | DZ7: Option 3 | EA7: Option 3 | EB7: Option 3 | ED7: Option 4 | EE7: Option 4 | EF7: Option 4 | EG7: Option 4 | EH7: Option 4 | EI7: Option 4 | EJ7: Option 4 | EK7: Option 4 | EL7: Option 4 | EM7: Option 4 | EN7: Option 4 | EO7: Option 4 | EP7: Option 4 | EQ7: Option 4 | ER7: Option 4 | ES7: Option 4 | ET7: Option 4 | EU7: Option 4 | EV7: Option 4 | EW7: Option 4 | EX7: Option 4 | EY7: Option 4 | EZ7: Option 4 | FA7: Option 4 | FB7: Option 4 | FC7: Option 4 | FD7: Option 4 | FE7: Option 4 | FF7: Option 4 | FG7: Option 4 | FI7: Option 5 | FJ7: Option 5 | FK7: Option 5 | FL7: Option 5 | FM7: Option 5 | FN7: Option 5 | FO7: Option 5 | FP7: Option 5 | FQ7: Option 5 | FR7: Option 5 | FS7: Option 5 | FT7: Option 5 | FU7: Option 5 | FV7: Option 5 | FW7: Option 5 | FX7: Option 5 | FY7: Option 5 | FZ7: Option 5 | GA7: Option 5 | GB7: Option 5 | GC7: Option 5 | GD7: Option 5 | GE7: Option 5 | GF7: Option 5 | GG7: Option 5 | GH7: Option 5 | GI7: Option 5 | GJ7: Option 5 | GK7: Option 5 | GL7: Option 5 | GN7: Option 6 | GO7: Option 6 | GP7: Option 6 | GQ7: Option 6 | GR7: Option 6 | GS7: Option 6 | GT7: Option 6 | GU7: Option 6 | GV7: Option 6 | GW7: Option 6 | GX7: Option 6 | GY7: Option 6 | GZ7: Option 6 | HA7: Option 6 | HB7: Option 6 | HC7: Option 6 | HD7: Option 6 | HE7: Option 6 | HF7: Option 6 | HG7: Option 6 | HH7: Option 6 | HI7: Option 6 | HJ7: Option 6 | HK7: Option 6 | HL7: Option 6 | HM7: Option 6 | HN7: Option 6 | HO7: Option 6 | HP7: Option 6 | HQ7: Option 6
A8: Link qua W3 | B8: Link qua Sun-W6 | E8: (cái,m2) | G8: (Năm) | H8: ="("&$D$5&")" -> (VND) | I8: ="("&$D$5&")" -> (VND) | J8: ="("&$D$5&"/năm)" -> (VND/năm) | L8: (Năm) | M8: ="("&$D$5&")" -> (VND) | N8: ="("&$D$5&")" -> (VND) | O8: ="("&$D$5&"/năm)" -> (VND/năm) | Q8: (Năm) | R8: ="("&$D$5&")" -> (VND) | S8: ="("&$D$5&")" -> (VND) | T8: ="("&$D$5&"/năm)" -> (VND/năm) | V8: (Năm) | W8: ="("&$D$5&")" -> (VND) | X8: ="("&$D$5&")" -> (VND) | Y8: ="("&$D$5&"/năm)" -> (VND/năm) | AA8: (Năm) | AB8: ="("&$D$5&")" -> (VND) | AC8: ="("&$D$5&")" -> (VND) | AD8: ="("&$D$5&"/năm)" -> (VND/năm) | AF8: (Năm) | AG8: ="("&$D$5&")" -> (VND) | AH8: ="("&$D$5&")" -> (VND) | AI8: ="("&$D$5&"/năm)" -> (VND/năm) | AO8: 1 | AP8: 2 | AQ8: 3 | AR8: 4 | AS8: 5 | AT8: 6 | AU8: 7 | AV8: 8 | AW8: 9 | AX8: 10 | AY8: 11 | AZ8: 12 | BA8: 13 | BB8: 14 | BC8: 15 | BD8: 16 | BE8: 17 | BF8: 18 | BG8: 19 | BH8: 20 | BI8: 21 | BJ8: 22 | BK8: 23 | BL8: 24 | BM8: 25 | BN8: 26 | BO8: 27 | BP8: 28 | BQ8: 29 | BR8: 30 | BT8: 1 | BU8: 2 | BV8: 3 | BW8: 4 | BX8: 5 | BY8: 6 | BZ8: 7 | CA8: 8 | CB8: 9 | CC8: 10 | CD8: 11 | CE8: 12 | CF8: 13 | CG8: 14 | CH8: 15 | CI8: 16 | CJ8: 17 | CK8: 18 | CL8: 19 | CM8: 20 | CN8: 21 | CO8: 22 | CP8: 23 | CQ8: 24 | CR8: 25 | CS8: 26 | CT8: 27 | CU8: 28 | CV8: 29 | CW8: 30 | CY8: 1 | CZ8: 2 | DA8: 3 | DB8: 4 | DC8: 5 | DD8: 6 | DE8: 7 | DF8: 8 | DG8: 9 | DH8: 10 | DI8: 11 | DJ8: 12 | DK8: 13 | DL8: 14 | DM8: 15 | DN8: 16 | DO8: 17 | DP8: 18 | DQ8: 19 | DR8: 20 | DS8: 21 | DT8: 22 | DU8: 23 | DV8: 24 | DW8: 25 | DX8: 26 | DY8: 27 | DZ8: 28 | EA8: 29 | EB8: 30 | ED8: 1 | EE8: 2 | EF8: 3 | EG8: 4 | EH8: 5 | EI8: 6 | EJ8: 7 | EK8: 8 | EL8: 9 | EM8: 10 | EN8: 11 | EO8: 12 | EP8: 13 | EQ8: 14 | ER8: 15 | ES8: 16 | ET8: 17 | EU8: 18 | EV8: 19 | EW8: 20 | EX8: 21 | EY8: 22 | EZ8: 23 | FA8: 24 | FB8: 25 | FC8: 26 | FD8: 27 | FE8: 28 | FF8: 29 | FG8: 30 | FI8: 1 | FJ8: 2 | FK8: 3 | FL8: 4 | FM8: 5 | FN8: 6 | FO8: 7 | FP8: 8 | FQ8: 9 | FR8: 10 | FS8: 11 | FT8: 12 | FU8: 13 | FV8: 14 | FW8: 15 | FX8: 16 | FY8: 17 | FZ8: 18 | GA8: 19 | GB8: 20 | GC8: 21 | GD8: 22 | GE8: 23 | GF8: 24 | GG8: 25 | GH8: 26 | GI8: 27 | GJ8: 28 | GK8: 29 | GL8: 30 | GN8: 1 | GO8: 2 | GP8: 3 | GQ8: 4 | GR8: 5 | GS8: 6 | GT8: 7 | GU8: 8 | GV8: 9 | GW8: 10 | GX8: 11 | GY8: 12 | GZ8: 13 | HA8: 14 | HB8: 15 | HC8: 16 | HD8: 17 | HE8: 18 | HF8: 19 | HG8: 20 | HH8: 21 | HI8: 22 | HJ8: 23 | HK8: 24 | HL8: 25 | HM8: 26 | HN8: 27 | HO8: 28 | HP8: 29 | HQ8: 30
C10: 1 | D10: MÁY MÓC THIẾT BỊ | I10: =I12+I20 -> 284499800000 | J10: =J12+J20 -> 2.3708317e+10 | N10: =N12+N20 -> 318760000000 | O10: =O12+O20 -> 2.6563333e+10 | S10: =S12+S20 -> 318760000000 | T10: =T12+T20 -> 2.6563333e+10 | X10: =X12+X20 -> 284499800000 | Y10: =Y12+Y20 -> 2.3708317e+10 | AC10: =AC12+AC20 -> 298714000000 | AD10: =AD12+AD20 -> 2.4892833e+10 | AH10: =AH12+AH20 -> 298714000000 | AI10: =AI12+AI20 -> 2.4892833e+10 | AO10: =AO12+AO20 -> 2.3708317e+10 | AP10: =AP12+AP20 -> 2.3708317e+10 | AQ10: =AQ12+AQ20 -> 2.3708317e+10 | AR10: =AR12+AR20 -> 2.3708317e+10 | AS10: =AS12+AS20 -> 2.3708317e+10 | AT10: =AT12+AT20 -> 2.3708317e+10 | AU10: =AU12+AU20 -> 2.3708317e+10 | AV10: =AV12+AV20 -> 2.3708317e+10 | ... BR10: =BR12+BR20 -> 0 | BT10: =BT12+BT20 -> 2.6563333e+10 | BU10: =BU12+BU20 -> 2.6563333e+10 | BV10: =BV12+BV20 -> 2.6563333e+10 | BW10: =BW12+BW20 -> 2.6563333e+10 | BX10: =BX12+BX20 -> 2.6563333e+10 | BY10: =BY12+BY20 -> 2.6563333e+10 | BZ10: =BZ12+BZ20 -> 2.6563333e+10 | CA10: =CA12+CA20 -> 2.6563333e+10 | ... CW10: =CW12+CW20 -> 0 | CY10: =CY12+CY20 -> 2.6563333e+10 | CZ10: =CZ12+CZ20 -> 2.6563333e+10 | DA10: =DA12+DA20 -> 2.6563333e+10 | DB10: =DB12+DB20 -> 2.6563333e+10 | DC10: =DC12+DC20 -> 2.6563333e+10 | DD10: =DD12+DD20 -> 2.6563333e+10 | DE10: =DE12+DE20 -> 2.6563333e+10 | DF10: =DF12+DF20 -> 2.6563333e+10 | ... EB10: =EB12+EB20 -> 0 | ED10: =ED12+ED20 -> 2.3708317e+10 | EE10: =EE12+EE20 -> 2.3708317e+10 | EF10: =EF12+EF20 -> 2.3708317e+10 | EG10: =EG12+EG20 -> 2.3708317e+10 | EH10: =EH12+EH20 -> 2.3708317e+10 | EI10: =EI12+EI20 -> 2.3708317e+10 | EJ10: =EJ12+EJ20 -> 2.3708317e+10 | EK10: =EK12+EK20 -> 2.3708317e+10 | ... FG10: =FG12+FG20 -> 0 | FI10: =FI12+FI20 -> 2.4892833e+10 | FJ10: =FJ12+FJ20 -> 2.4892833e+10 | FK10: =FK12+FK20 -> 2.4892833e+10 | FL10: =FL12+FL20 -> 2.4892833e+10 | FM10: =FM12+FM20 -> 2.4892833e+10 | FN10: =FN12+FN20 -> 2.4892833e+10 | FO10: =FO12+FO20 -> 2.4892833e+10 | FP10: =FP12+FP20 -> 2.4892833e+10 | ... GL10: =GL12+GL20 -> 0 | GN10: =GN12+GN20 -> 2.4892833e+10 | GO10: =GO12+GO20 -> 2.4892833e+10 | GP10: =GP12+GP20 -> 2.4892833e+10 | GQ10: =GQ12+GQ20 -> 2.4892833e+10 | GR10: =GR12+GR20 -> 2.4892833e+10 | GS10: =GS12+GS20 -> 2.4892833e+10 | GT10: =GT12+GT20 -> 2.4892833e+10 | GU10: =GU12+GU20 -> 2.4892833e+10 | ... HQ10: =HQ12+HQ20 -> 0
