Workbook
Name Capacity: 'Cover Page'!$F$28
Name Currency: 'Cover Page'!$A$33
Name EXR: 'Cover Page'!$F$10
Name Inflation: 'Cover Page'!$F$9
Name Opt1_WACC: 'Cover Page'!$H$23
Name Opt10_CAPEX: 'Cover Page'!$AI$6
Name Opt10_CPSX: 'Cover Page'!$AI$7
Name Opt2_CAPEX: 'Cover Page'!$K$6
Name Opt2_CPSX: 'Cover Page'!$K$7
Name Opt2_EXW: 'Cover Page'!$K$10
Name Opt2_WACC: 'Cover Page'!$K$23
Name Opt3_CAPEX: 'Cover Page'!$N$6
Name Opt3_CPSX: 'Cover Page'!$N$7
Name Opt3_WACC: 'Cover Page'!$W$23
Name Opt4_CAPEX: 'Cover Page'!$Q$6
Name Opt4_CPSX: 'Cover Page'!$Q$7
Name Opt5_CAPEX: 'Cover Page'!$T$6
Name Opt5_CPSX: 'Cover Page'!$T$7
Name Opt6_CAPEX: 'Cover Page'!$W$6
Name Opt6_CPSX: 'Cover Page'!$W$7
Name Opt7_CAPEX: 'Cover Page'!$Z$6
Name Opt7_CPSX: 'Cover Page'!$Z$7
Name Opt8_CAPEX: 'Cover Page'!$AC$6
Name Opt8_CPSX: 'Cover Page'!$AC$7
Name Opt9_CAPEX: 'Cover Page'!$AF$6
Name Opt9_CPSX: 'Cover Page'!$AF$7
Name PHOI_KG: 'Cover Page'!$F$30
Name Slicer_Currency: #N/A
Name Tax_rate: 'Cover Page'!$F$11
Name WACC: 'Cover Page'!$F$23

Sheet Timeline

Sheet >>PowerPoint

Sheet Trình bày giả định
A2: CÁC GIẢ ĐỊNH CỦA DỰ ÁN
A4: STT | B4: GIẢ ĐỊNH | C4: GIÁ TRỊ | D4: ĐVT/Ghi chú | F4: STT | G4: GIẢ ĐỊNH | H4: GIÁ TRỊ | I4: ĐVT/Ghi chú
A5: 1 | B5: Thông tin chung | F5: 4 | G5: Hiệu suất sử dụng máy | H5: ='W3'!$L$23 -> 0.88
A6: 1.1 | B6: Chủ đầu tư | C6: DTR
A7: 1.2 | B7: Thời gian khai thác | C7: 15 | D7: Năm | F7: 5 | G7: Sản lượng sản xuất tối đa | H7: ='W3'!U27/10^3 -> 6194.175 | I7: tấn/năm
A8: 1.3 | B8: Tổng dự toán đầu tư máy móc thiết bị (VND) | C8: =IF(Currency="VND",'W1'!$I$60,'W1'!$I$60*EXR) -> 300749800000 | D8: VND | H8: ='W3'!U28 -> 4.12945e+08 | I8: phôi/năm
A9: 1.4 | B9: Tổng dự toán đầu tư máy móc thiết bị (USD) | C9: =IF(Currency="VND",'W1'!$I$60/EXR,'W1'!$I$60) -> 11567300 | D9: USD
A10: 1.5 | B10: Thời gian khấu hao (PP đường thẳng) | C10: ='W1'!G13 -> 12 | D10: Năm | F10: 6 | G10: Sản lượng bán | H10: (tấn)
A11: 1.6 | B11: Tỷ giá | C11: =EXR -> 26000 | F11: 6.1 | G11: Sản lượng bán năm 1 | H11: ='W3'!L27/10^3 -> 3097.0875 | I11: 50.0% Sản lượng sản xuất tối đa
A12: 1.7 | B12: Lạm phát | C12: =Inflation -> 0.05 | F12: 6.2 | G12: Sản lượng bán năm 2 | H12: ='W3'!M27/10^3 -> 4335.9225 | I12: 70.0% Sản lượng sản xuất tối đa
F13: 6.3 | G13: Sản lượng bán năm 3 | H13: ='W3'!N27/10^3 -> 6194.175 | I13: 100.0% Sản lượng sản xuất tối đa
A14: 2 | B14: Nguồn nguyên vật liệu: Vảy sạch từ chai B1 | F14: 6.4 | G14: Từ năm thứ 4 trở đi bằng với năm 3
A15: 2.1 | B15: Đơn giá chai B1 | C15: 16600 | D15: đ/kg
A16: 2.2 | B16: Đơn giá vảy sạch cho dự án | C16: =IF(Currency="VND",'W2'!$M$56,'W2'!$M$56*EXR) -> 24960 | D16: đ/kg | F16: 7 | G16: Giá bán | H16: ='Cover Page'!H14 -> 680 | I16: VND/phôi
C17: =C16/EXR*10^3 -> 960 | D17: USD/tấn | H17: ='Cover Page'!H15 -> 1743.5897 | I17: USD/tấn
B18: Đơn giá vảy sạch tăng | C18: ='Cover Page'!H17 -> 0.02 | D18: /năm | G18: Đơn giá bán tăng | H18: ='Cover Page'!H17 -> 0.02 | I18: /năm
A19: 2.3 | B19: Tỷ lệ hao hụt FtoP | C19: ='W2'!M41 -> 0.07
A20: 2.4 | B20: Liều lượng phụ gia | C20: ='W2'!M60 -> 0.0002
A21: 2.5 | B21: Đơn giá phụ gia | C21: ='W2'!M64 -> 949542 | D21: VND/kg | F21: 8 | G21: Tỷ lệ chiết khấu/cơ cấu vay
F22: 8.1 | G22: Vốn vay | H22: ='Cover Page'!H21 -> 0.7
A23: 3 | B23: Chi phí sản xuất | F23: 8.2 | G23: Vốn tự có | H23: =1-H22 -> 0.3
A24: 3.1 | B24: Nhân công trực tiếp (2 người x 3 ca) | C24: =IF(Currency="VND",'W2'!$M$13,'W2'!$M$13*EXR) -> 982800000 | D24: VND/năm | F24: 8.3 | G24: Lãi vay trung dài hạn | H24: ='Cover Page'!H19 -> 0.07
A25: 3.2 | B25: Nhân viên kỹ thuật, QC, kho | C25: =IF(Currency="VND",'W2'!$M$17,'W2'!$M$17*EXR) -> 5028660000 | D25: VND/năm | F25: 8.4 | G25: Thuế suất thuế TNDN | H25: =Tax_rate -> 0.2
A26: 3.3 | B26: Chi phí điện | C26: ='W2'!M45 -> 765 | D26: kwh | F26: 8.5 | G26: Tỷ lệ chiết khấu = WACC | H26: =Opt1_WACC -> 0.07266
A27: 3.4 | B27: Đơn giá điện | C27: =IF(Currency="VND",'W2'!$M$46,'W2'!$M$46*EXR) -> 1950 | D27: đ/kwh
A28: 3.5 | B28: Chi phí sửa chữa bảo trì (3%*giá trị đầu tư) | C28: =IF(Currency="VND",'W2'!$M$28,'W2'!$M$28*EXR) -> 9022494000 | D28: VND/năm
A29: 3.6 | B29: Chi phí vận hành xe điện | C29: =IF(Currency="VND",'W2'!$M$37,'W2'!$M$37*EXR) -> 552000000 | D29: VND/năm | G29: Dự án chưa tính giá trị đầu tư xưởng (khoảng 150 tỷ đồng ~ 6 triệu USD)
B30: (Số xe thuê: 2 với đơn giá thuê 20 triệu/tháng, chi phí điện 3 triệu/xe/tháng)
A31: 3.7 | B31: Chi phí bao bì | C31: =IF(Currency="VND",'W2'!$M$48,'W2'!$M$48*EXR) -> 314.81481 | D31: đ/kg thành phẩm
A32: 3.8 | B32: Chi phí thuê xưởng (2.000 m2 * 100.000đ/m2/tháng) | C32: =IF(Currency="VND",'W2'!$M$33,'W2'!$M$33*EXR) -> 2400000000 | D32: VND/năm
A33: 3.9 | B33: Chi phí bảo hiểm | C33: ='W2'!L73 -> 0.002 | D33: /tổng tài sản
A34: 3.10 | B34: Chi phí vận chuyển | C34: ='W2'!$M$77 -> 4000000 | D34: VND/chuyến

Sheet W1-Trình bày
A2: STT | B2: HẠNG MỤC | C2: Số lượng | E2: Đơn giá | F2: Giá trị đầu tư | G2: Giá trị đầu tư | M2: Thời gian khấu hao | N2: Khấu hao
C3: (cái,m2) | E3: (VND) | F3: (VND) | G3: (USD) | M3: (Năm) | N3: (VND/năm)
A5: 1 | B5: MÁY MÓC THIẾT BỊ | F5: 284499800000 | G5: =F5/26000 -> 10942300 | N5: 2.3708317e+10
A7: 1.1 | B7: Máy móc thiết bị chính | F7: 2.46389e+11 | G7: =F7/26000 -> 9476500 | N7: 2.0532417e+10
A8: 1.1.01 | B8: NGR : LSP 1200 | C8: 1 | E8: 128180000000 | F8: 128180000000 | G8: =F8/26000 -> 4930000 | M8: 12 | N8: 1.0681667e+10
A9: 1.1.02 | B9: HyPET400 HPP5e rMtP P120/120 | C9: 1 | E9: 6.727793e+10 | F9: 6.727793e+10 | G9: =F9/26000 -> 2587612.7 | M9: 12 | N9: 5.6064942e+09
A10: 1.1.03 | B10: Khuôn 15g PCO 1881 128 cavtiy | C10: 1 | E10: 3.932207e+10 | F10: 3.932207e+10 | G10: =F10/26000 -> 1512387.3 | M10: 12 | N10: 3.2768391e+09
A11: 1.1.04 | B11: Chi phí vận chuyển | C11: 1 | E11: 2600000000 | F11: 2600000000 | G11: =F11/26000 -> 100000 | M11: 12 | N11: 2.1666667e+08
A12: 1.1.05 | B12: Chi phí lắp đặt | C12: 1 | E12: 8580000000 | F12: 8580000000 | G12: =F12/26000 -> 330000 | M12: 12 | N12: 715000000
A13: 1.1.06 | B13: Thuế nhà thầu | C13: 1 | E13: 429000000 | F13: 429000000 | G13: =F13/26000 -> 16500 | M13: 12 | N13: 35750000
A15: 1.2 | B15: Máy móc thiết bị phụ | F15: 38110800000 | G15: =F15/26000 -> 1465800 | N15: 3175900000
A16: 1.2.06 | B16: Hệ thống nước, khí nén | C16: 1 | E16: 7800000000 | F16: 7800000000 | G16: =F16/26000 -> 300000 | M16: 12 | N16: 650000000
A17: 1.2.07 | B17: Hệ thống điện | C17: 1 | E17: 7800000000 | F17: 7800000000 | G17: =F17/26000 -> 300000 | M17: 12 | N17: 650000000
A18: 1.2.08 | B18: Pump system | C18: 1 | E18: 3900000000 | F18: 3900000000 | G18: =F18/26000 -> 150000 | M18: 12 | N18: 325000000
A19: 1.2.09 | B19: Camera online check | C19: 1 | E19: 3250000000 | F19: 3250000000 | G19: =F19/26000 -> 125000 | M19: 12 | N19: 2.7083333e+08
A20: 1.2.10 | B20: Chiller | C20: 1 | E20: 2600000000 | F20: 2600000000 | G20: =F20/26000 -> 100000 | M20: 12 | N20: 2.1666667e+08
A21: 1.2.11 | B21: Trạm điện | C21: 1 | E21: 2600000000 | F21: 2600000000 | G21: =F21/26000 -> 100000 | M21: 12 | N21: 2.1666667e+08
A22: 1.2.12 | B22: Overhead crane | C22: 1 | E22: 2600000000 | F22: 2600000000 | G22: =F22/26000 -> 100000 | M22: 12 | N22: 2.1666667e+08
A23: 1.2.13 | B23: Hệ thống điện dự phòng | C23: 1 | E23: 2080000000 | F23: 2080000000 | G23: =F23/26000 -> 80000 | M23: 12 | N23: 1.7333333e+08
A24: 1.2.14 | B24: Hệ thống IT | C24: 1 | E24: 2080000000 | F24: 2080000000 | G24: =F24/26000 -> 80000 | M24: 12 | N24: 1.7333333e+08
A25: 1.2.15 | B25: Lock unloading preform | C25: 1 | E25: 1352000000 | F25: 1352000000 | G25: =F25/26000 -> 52000 | M25: 12 | N25: 1.1266667e+08
A26: 1.2.16 | B26: Máy nén khí | C26: 1 | E26: 1248000000 | F26: 1248000000 | G26: =F26/26000 -> 48000 | M26: 12 | N26: 104000000
A27: 1.2.17 | B27: Cooling tower | C27: 1 | E27: 780000000 | F27: 780000000 | G27: =F27/26000 -> 30000 | M27: 12 | N27: 65000000
A28: 1.2.18 | B28: Máy scan | C28: 1 | E28: 20800000 | F28: 20800000 | G28: =F28/26000 -> 800 | M28: 12 | N28: 1733333.3
B30: CHI PHÍ XÂY DỰNG XƯỞNG SẢN XUẤT | C30: 2000 | F30: 0 | N30: 0
B31: Xưởng sản xuất | C31: 1900 | E31: 75000000 | F31: 0 | M31: 25 | N31: 0
B32: Phòng QC | C32: 100 | E32: 75000000 | F32: 0 | M32: 25 | N32: 0
A34: 2. | B34: MÁY MÓC THIẾT BỊ PHÒNG LAB | F34: 16250000000 | G34: =F34/26000 -> 625000 | N34: 1.3541667e+09
A35: 2.01 | B35: Máy đo IV PSL IV 4603 | C35: 1 | E35: 5200000000 | F35: 5200000000 | G35: =F35/26000 -> 200000 | M35: 12 | N35: 4.3333333e+08
A36: 2.02 | B36: Máy đo kích thước tự động Gawis 4D | C36: 1 | E36: 5200000000 | F36: 5200000000 | G36: =F36/26000 -> 200000 | M36: 12 | N36: 4.3333333e+08
A37: 2.03 | B37: Máy đo AA Piovan Inspecta | C37: 1 | E37: 3042000000 | F37: 3042000000 | G37: =F37/26000 -> 117000 | M37: 12 | N37: 253500000
A38: 2.04 | B38: Colorimeter/Spectrophotometer | C38: 1 | E38: 650000000 | F38: 650000000 | G38: =F38/26000 -> 25000 | M38: 12 | N38: 54166667
A39: 2.05 | B39: Melt Flow Index Tester | C39: 1 | E39: 442000000 | F39: 442000000 | G39: =F39/26000 -> 17000 | M39: 12 | N39: 36833333
A40: 2.06 | B40: Light Polarizer | C40: 1 | E40: 260000000 | F40: 260000000 | G40: =F40/26000 -> 10000 | M40: 12 | N40: 21666667
A41: 2.07 | B41: Moisture analyzer | C41: 1 | E41: 143000000 | F41: 143000000 | G41: =F41/26000 -> 5500 | M41: 12 | N41: 11916667
A42: 2.08 | B42: Perpendicular Prefrom Thickness Gauge | C42: 1 | E42: 130000000 | F42: 130000000 | G42: =F42/26000 -> 5000 | M42: 12 | N42: 10833333
A43: 2.09 | B43: Calipers with data output | C43: 1 | E43: 130000000 | F43: 130000000 | G43: =F43/26000 -> 5000 | M43: 12 | N43: 10833333
A44: 2.10 | B44: Radius gauges | C44: 1 | E44: 130000000 | F44: 130000000 | G44: =F44/26000 -> 5000 | M44: 12 | N44: 10833333
A45: 2.11 | B45: Torque tester | C45: 1 | E45: 130000000 | F45: 130000000 | G45: =F45/26000 -> 5000 | M45: 12 | N45: 10833333
A46: 2.12 | B46: Pitch gauges | C46: 1 | E46: 130000000 | F46: 130000000 | G46: =F46/26000 -> 5000 | M46: 12 | N46: 10833333
...

Sheet USD.Tấn
A3: No. | B3: SAP | C3: Chi phí Cost Items | D3: Chi phí USD/tấn | E3: Cơ cấu % chi phí /Giá
A4: A | B4: 1521 | C4: Chi phí nguyên vật liệu | D4: 979.2 | E4: 0.5616
C5: Vảy sạch | D5: 979.2 | E5: 0.5616
A6: B | B6: 1522 | C6: Hao hụt về tiền | D6: 73.703226 | E6: 0.042270968
A7: C | C7: Chi phí biến đổi | D7: 506.99204 | E7: 0.29077485
A8: 1 | B8: LAB | C8: Chi phí nhân công | D8: 39.193355 | E8: 0.022478542
A9: 2 | B9: DEP | C9: Khấu hao | D9: 155.62067 | E9: 0.089253032
A10: 3 | B10: OTH | C10: Chi phí quản lý | D10: 83.967246 | E10: 0.048157685
A11: 4 | B11: ELEC | C11: Chi phí gián tiếp | D11: 132.27565 | E11: 0.075863976
A12: 5 | B12: QLC | C12: Điện | D12: 74.974798 | E12: 0.043000252
A13: 6 | B13: BAG | C13: Đóng gói | D13: 12.713675 | E13: 0.0072916667
A14: 7 | B14: CHE | C14: Hóa chất | D14: 8.2466427 | E14: 0.0047296921
A15: 8 | B15: H2O | C15: Nước | D15: 0 | E15: 0
A16: 9 | C16: Giá thành | D16: 1559.8953 | E16: 0.89464581
A17: 10 | B17: TAX | C17: Thuế thu nhập | D17: 36.738896 | E17: 0.021070837
A18: D | B18: LN | C18: Lợi nhuận | D18: 146.95558 | E18: 0.084283349
A19: A+B+C+D | C19: Giá bán | D19: 1743.5897 | E19: 1
C20: % Lãi gộp nguyên liệu/Giá bán | E20: 0.4384

Sheet VND.Phôi
A3: No. | B3: SAP | C3: Chi phí Cost Items | D3: Chi phí VNĐ / Phôi | E3: Cơ cấu % chi phí /Giá
A4: A | B4: 1521 | C4: Chi phí nguyên vật liệu | D4: 381.888 | E4: 0.5616
C5: Vảy sạch | D5: 381.888 | E5: 0.5616
A6: B | B6: 1522 | C6: Hao hụt về tiền | D6: 28.744258 | E6: 0.042270968
A7: C | C7: Chi phí biến đổi | D7: 197.7269 | E7: 0.29077485
A8: 1 | B8: LAB | C8: Chi phí nhân công | D8: 15.285409 | E8: 0.022478542
A9: 2 | B9: DEP | C9: Khấu hao | D9: 60.692062 | E9: 0.089253032
A10: 3 | B10: QLC | C10: Chi phí quản lý | D10: 32.747226 | E10: 0.048157685
A11: 4 | B11: OTH | C11: Chi phí gián tiếp | D11: 51.587504 | E11: 0.075863976
A12: 5 | B12: ELEC | C12: Điện | D12: 29.240171 | E12: 0.043000252
A13: 6 | B13: BAG | C13: Đóng gói | D13: 4.9583333 | E13: 0.0072916667
A14: 7 | B14: CHE | C14: Hóa chất | D14: 3.2161906 | E14: 0.0047296921
A15: 8 | B15: H2O | C15: Nước | D15: 0 | E15: 0
A16: 9 | C16: Giá thành | D16: 608.35915 | E16: 0.89464581
A17: 10 | B17: TAX | C17: Thuế thu nhập | D17: 14.328169 | E17: 0.021070837
A18: D | B18: LN | C18: Lợi nhuận | D18: 57.312677 | E18: 0.084283349
A19: A+B+C+D | C19: Giá bán | D19: 680 | E19: 1
C20: % Lãi gộp nguyên liệu/Giá bán | E20: 0.4384

Sheet Sheet3
B2: STT | C2: Hạng mục | D2: Đvt | E2: 2026 | F2: 2027 | G2: 2028 | H2: 2029 | I2: 2030 | J2: 2031 | K2: 2032 | L2: 2033 | M2: 2034 | N2: 2035 | O2: 2036 | P2: 2037 | Q2: 2038 | R2: 2039 | S2: 2040 | T2: 2041
B4: =IF(C4<>"",SUBTOTAL(3,C$4:C4),"") -> 1 | C4: SỐ LƯỢNG SẢN XUẤT/BÁN
B5: =IF(C5<>"",SUBTOTAL(3,C$4:C5),"") -> 2 | C5: Sản lượng công suất máy | D5: kg/năm | F5: 7568640 | G5: 7568640 | H5: 7568640 | I5: 7568640 | J5: 7568640 | K5: 7568640 | L5: 7568640 | M5: 7568640 | N5: 7568640 | O5: 7568640 | P5: 7568640 | Q5: 7568640 | R5: 7568640 | S5: 7568640 | T5: 7568640
B6: =IF(C6<>"",SUBTOTAL(3,C$4:C6),"") -> 3 | C6: Sản lượng công suất máy | D6: phôi/năm | F6: 7568640 | G6: 7568640 | H6: 7568640 | I6: 7568640 | J6: 7568640 | K6: 7568640 | L6: 7568640 | M6: 7568640 | N6: 7568640 | O6: 7568640 | P6: 7568640 | Q6: 7568640 | R6: 7568640 | S6: 7568640 | T6: 7568640
B7: =IF(C7<>"",SUBTOTAL(3,C$4:C7),"") -> 4 | C7: Hiệu suất sử dụng tối đa | F7: 0.88 | G7: 0.88 | H7: 0.88 | I7: 0.88 | J7: 0.88 | K7: 0.88 | L7: 0.88 | M7: 0.88 | N7: 0.88 | O7: 0.88 | P7: 0.88 | Q7: 0.88 | R7: 0.88 | S7: 0.88 | T7: 0.88
B8: =IF(C8<>"",SUBTOTAL(3,C$4:C8),"") -> 5 | C8: Hệ số điều chỉnh sản xuất | F8: 0.5 | G8: 0.7 | H8: 1 | I8: 1 | J8: 1 | K8: 1 | L8: 1 | M8: 1 | N8: 1 | O8: 1 | P8: 1 | Q8: 1 | R8: 1 | S8: 1 | T8: 1
B9: =IF(C9<>"",SUBTOTAL(3,C$4:C9),"") -> 6 | C9: Tỷ lệ hao hụt | F9: 0.07 | G9: 0.07 | H9: 0.07 | I9: 0.07 | J9: 0.07 | K9: 0.07 | L9: 0.07 | M9: 0.07 | N9: 0.07 | O9: 0.07 | P9: 0.07 | Q9: 0.07 | R9: 0.07 | S9: 0.07 | T9: 0.07
B10: =IF(C10<>"",SUBTOTAL(3,C$4:C10),"") -> 7 | C10: Số ngày hoạt động | F10: 160.6 | G10: 224.84 | H10: 321.2 | I10: 321.2 | J10: 321.2 | K10: 321.2 | L10: 321.2 | M10: 321.2 | N10: 321.2 | O10: 321.2 | P10: 321.2 | Q10: 321.2 | R10: 321.2 | S10: 321.2 | T10: 321.2
B11: =IF(C11<>"",SUBTOTAL(3,C$4:C11),"") -> 8 | C11: Sản lượng sản xuất | D11: kg/năm | F11: 3097087.5 | G11: 4335922.5 | H11: 6194175 | I11: 6194175 | J11: 6194175 | K11: 6194175 | L11: 6194175 | M11: 6194175 | N11: 6194175 | O11: 6194175 | P11: 6194175 | Q11: 6194175 | R11: 6194175 | S11: 6194175 | T11: 6194175
B12: =IF(C12<>"",SUBTOTAL(3,C$4:C12),"") -> 9 | C12: Sản lượng sản xuất | D12: phôi/năm | F12: 2.064725e+08 | G12: 2.890615e+08 | H12: 4.12945e+08 | I12: 4.12945e+08 | J12: 4.12945e+08 | K12: 4.12945e+08 | L12: 4.12945e+08 | M12: 4.12945e+08 | N12: 4.12945e+08 | O12: 4.12945e+08 | P12: 4.12945e+08 | Q12: 4.12945e+08 | R12: 4.12945e+08 | S12: 4.12945e+08 | T12: 4.12945e+08
B13: =IF(C13<>"",SUBTOTAL(3,C$4:C13),"")
B14: =IF(C14<>"",SUBTOTAL(3,C$4:C14),"") -> 10 | C14: DOANH THU | D14: tr. VND | F14: 140401.3 | G14: 200493.06 | H14: 292147.02 | I14: 297989.96 | J14: 303949.76 | K14: 310028.76 | L14: 316229.33 | M14: 322553.92 | N14: 329005 | O14: 335585.1 | P14: 342296.8 | Q14: 349142.74 | R14: 356125.59 | S14: 363248.1 | T14: 370513.07
B15: =IF(C15<>"",SUBTOTAL(3,C$4:C15),"")
B16: =IF(C16<>"",SUBTOTAL(3,C$4:C16),"") -> 11 | C16: Định phí sản xuất | D16: tr. VND | E16: 0 | F16: -43649.937 | G16: -43649.937 | H16: -44549.235 | I16: -45493.497 | J16: -46484.973 | K16: -47526.022 | L16: -48619.124 | M16: -49766.881 | N16: -50972.026 | O16: -52237.429 | P16: -53566.101 | Q16: -54961.207 | R16: -31363.585 | S16: -32901.689 | T16: -34516.698
B17: =IF(C17<>"",SUBTOTAL(3,C$4:C17),"") -> 12 | C17: Khấu hao | D17: tr. VND | F17: -25062.483 | G17: -25062.483 | H17: -25062.483 | I17: -25062.483 | J17: -25062.483 | K17: -25062.483 | L17: -25062.483 | M17: -25062.483 | N17: -25062.483 | O17: -25062.483 | P17: -25062.483 | Q17: -25062.483 | R17: 0 | S17: 0 | T17: 0
B18: =IF(C18<>"",SUBTOTAL(3,C$4:C18),"") -> 13 | C18: Lương | D18: tr. VND | E18: 0 | F18: -6011.46 | G18: -6011.46 | H18: -6312.033 | I18: -6627.6346 | J18: -6959.0164 | K18: -7306.9672 | L18: -7672.3156 | M18: -8055.9313 | N18: -8458.7279 | O18: -8881.6643 | P18: -9325.7475 | Q18: -9792.0349 | R18: -10281.637 | S18: -10795.718 | T18: -11335.504
B19: =IF(C19<>"",SUBTOTAL(3,C$4:C19),"") -> 14 | C19: - Nhân công trực tiếp | D19: tr. VND | F19: -982.8 | G19: -982.8 | H19: -1031.94 | I19: -1083.537 | J19: -1137.7139 | K19: -1194.5995 | L19: -1254.3295 | M19: -1317.046 | N19: -1382.8983 | O19: -1452.0432 | P19: -1524.6454 | Q19: -1600.8776 | R19: -1680.9215 | S19: -1764.9676 | T19: -1853.216
B20: =IF(C20<>"",SUBTOTAL(3,C$4:C20),"") -> 15 | C20: - Nhân công gián tiếp | D20: tr. VND | F20: -5028.66 | G20: -5028.66 | H20: -5280.093 | I20: -5544.0976 | J20: -5821.3025 | K20: -6112.3677 | L20: -6417.986 | M20: -6738.8853 | N20: -7075.8296 | O20: -7429.6211 | P20: -7801.1021 | Q20: -8191.1573 | R20: -8600.7151 | S20: -9030.7509 | T20: -9482.2884
B21: =IF(C21<>"",SUBTOTAL(3,C$4:C21),"") -> 16 | C21: Thuê kho,xưởng | D21: tr. VND | F21: -2400 | G21: -2400 | H21: -2520 | I21: -2646 | J21: -2778.3 | K21: -2917.215 | L21: -3063.0758 | M21: -3216.2295 | N21: -3377.041 | O21: -3545.8931 | P21: -3723.1877 | Q21: -3909.3471 | R21: -4104.8145 | S21: -4310.0552 | T21: -4525.5579
B22: =IF(C22<>"",SUBTOTAL(3,C$4:C22),"") -> 17 | C22: Bảo trì | D22: tr. VND | F22: -9022.494 | G22: -9022.494 | H22: -9473.6187 | I22: -9947.2996 | J22: -10444.665 | K22: -10966.898 | L22: -11515.243 | M22: -12091.005 | N22: -12695.555 | O22: -13330.333 | P22: -13996.85 | Q22: -14696.692 | R22: -15431.527 | S22: -16203.103 | T22: -17013.258
B23: =IF(C23<>"",SUBTOTAL(3,C$4:C23),"") -> 18 | C23: Vận hành xe điện | D23: tr. VND | F23: -552 | G23: -552 | H23: -579.6 | I23: -608.58 | J23: -639.009 | K23: -670.95945 | L23: -704.50742 | M23: -739.73279 | N23: -776.71943 | O23: -815.5554 | P23: -856.33318 | Q23: -899.14983 | R23: -944.10733 | S23: -991.31269 | T23: -1040.8783
B24: =IF(C24<>"",SUBTOTAL(3,C$4:C24),"") -> 19 | C24: Bảo hiểm tài sản | D24: tr. VND | F24: -601.4996 | G24: -601.4996 | H24: -601.4996 | I24: -601.4996 | J24: -601.4996 | K24: -601.4996 | L24: -601.4996 | M24: -601.4996 | N24: -601.4996 | O24: -601.4996 | P24: -601.4996 | Q24: -601.4996 | R24: -601.4996 | S24: -601.4996 | T24: -601.4996
B25: =IF(C25<>"",SUBTOTAL(3,C$4:C25),"")
B26: =IF(C26<>"",SUBTOTAL(3,C$4:C26),"") -> 20 | C26: Biến phí sản xuất | D26: tr. VND | E26: 0 | F26: -92494.065 | G26: -128793.29 | H26: -187365.6 | I26: -191595.5 | J26: -195935.15 | K26: -200388 | L26: -204957.65 | M26: -209647.81 | N26: -214462.35 | O26: -219405.29 | P26: -224480.8 | Q26: -229693.22 | R26: -234044.55 | S26: -239544.48 | T26: -245195.38
B27: =IF(C27<>"",SUBTOTAL(3,C$4:C27),"") -> 21 | C27: Nguyên vật liệu | D27: tr. VND | E27: 0 | F27: -83121.832 | G27: -116370.56 | H27: -169568.54 | I27: -172959.91 | J27: -176419.11 | K27: -179947.49 | L27: -183546.44 | M27: -187217.37 | N27: -190961.71 | O27: -194780.95 | P27: -198676.57 | Q27: -202650.1 | R27: -206703.1 | S27: -210837.16 | T27: -215053.91
B28: =IF(C28<>"",SUBTOTAL(3,C$4:C28),"") -> 22 | C28: Vảy sạch | D28: tr. VND | F28: -77303.304 | G28: -108224.63 | H28: -157698.74 | I28: -160852.71 | J28: -164069.77 | K28: -167351.16 | L28: -170698.19 | M28: -174112.15 | N28: -177594.39 | O28: -181146.28 | P28: -184769.21 | Q28: -188464.59 | R28: -192233.88 | S28: -196078.56 | T28: -200000.13
B29: =IF(C29<>"",SUBTOTAL(3,C$4:C29),"") -> 23 | C29: Hao hụt | D29: tr. VND | F29: -5818.5282 | G29: -8145.9395 | H29: -11869.798 | I29: -12107.194 | J29: -12349.337 | K29: -12596.324 | L29: -12848.251 | M29: -13105.216 | N29: -13367.32 | O29: -13634.666 | P29: -13907.36 | Q29: -14185.507 | R29: -14469.217 | S29: -14758.601 | T29: -15053.773
B30: =IF(C30<>"",SUBTOTAL(3,C$4:C30),"") -> 24 | C30: Màu, phụ gia | D30: tr. VND | E30: 0 | F30: -632.43326 | G30: -885.40656 | H30: -1328.1098 | I30: -1394.5153 | J30: -1464.2411 | K30: -1537.4532 | L30: -1614.3258 | M30: -1695.0421 | N30: -1779.7942 | O30: -1868.7839 | P30: -1962.2231 | Q30: -2060.3343 | R30: -2163.351 | S30: -2271.5185 | T30: -2385.0945
B31: =IF(C31<>"",SUBTOTAL(3,C$4:C31),"") -> 25 | C31: Màu Toner AY090 | D31: tr. VND | F31: -632.43326 | G31: -885.40656 | H31: -1328.1098 | I31: -1394.5153 | J31: -1464.2411 | K31: -1537.4532 | L31: -1614.3258 | M31: -1695.0421 | N31: -1779.7942 | O31: -1868.7839 | P31: -1962.2231 | Q31: -2060.3343 | R31: -2163.351 | S31: -2271.5185 | T31: -2385.0945
B32: =IF(C32<>"",SUBTOTAL(3,C$4:C32),"") -> 26 | C32: Phụ gia AA Scavenger | D32: tr. VND | F32: 0 | G32: 0 | H32: 0 | I32: 0 | J32: 0 | K32: 0 | L32: 0 | M32: 0 | N32: 0 | O32: 0 | P32: 0 | Q32: 0 | R32: 0 | S32: 0 | T32: 0
B33: =IF(C33<>"",SUBTOTAL(3,C$4:C33),"") -> 27 | C33: Chi phí tạo phôi | D33: tr. VND | E33: 0 | F33: -8739.8001 | G33: -11537.321 | H33: -16468.955 | I33: -17241.075 | J33: -18051.8 | K33: -18903.063 | L33: -19796.888 | M33: -20735.404 | N33: -21720.846 | O33: -22755.561 | P33: -23842.011 | Q33: -24982.783 | R33: -25178.095 | S33: -26435.797 | T33: -27756.384
B34: =IF(C34<>"",SUBTOTAL(3,C$4:C34),"") -> 28 | C34: Chi phí điện | D34: tr. VND | F34: -5749.8012 | G34: -8049.7217 | H34: -12074.583 | I34: -12678.312 | J34: -13312.227 | K34: -13977.839 | L34: -14676.731 | M34: -15410.567 | N34: -16181.095 | O34: -16990.15 | P34: -17839.658 | Q34: -18731.641 | R34: -19668.223 | S34: -20651.634 | T34: -21684.215
B35: =IF(C35<>"",SUBTOTAL(3,C$4:C35),"") -> 29 | C35: Chi phí đóng bao bì | D35: tr. VND | F35: -975.00902 | G35: -1365.0126 | H35: -2047.519 | I35: -2149.8949 | J35: -2257.3896 | K35: -2370.2591 | L35: -2488.7721 | M35: -2613.2107 | N35: -2743.8712 | O35: -2881.0648 | P35: -3025.118 | Q35: -3176.3739 | R35: -3335.1926 | S35: -3501.9522 | T35: -3677.0499
B36: =IF(C36<>"",SUBTOTAL(3,C$4:C36),"") -> 30 | C36: Chi phí bằng tiền khác | D36: tr. VND | F36: -2014.9899 | G36: -2122.5868 | H36: -2346.8534 | I36: -2412.8682 | J36: -2482.1836 | K36: -2554.9648 | L36: -2631.3851 | M36: -2711.6264 | N36: -2795.8797 | O36: -2884.3457 | P36: -2977.2351 | Q36: -3074.7688 | R36: -2174.68 | S36: -2282.211 | T36: -2395.1185
B37: =IF(C37<>"",SUBTOTAL(3,C$4:C37),"")
B38: =IF(C38<>"",SUBTOTAL(3,C$4:C38),"") -> 31 | C38: TỔNG CHI PHÍ SẢN XUẤT | D38: tr. VND | E38: 0 | F38: -136144 | G38: -172443.23 | H38: -231914.84 | I38: -237089 | J38: -242420.12 | K38: -247914.03 | L38: -253576.78 | M38: -259414.69 | N38: -265434.38 | O38: -271642.72 | P38: -278046.9 | Q38: -284654.42 | R38: -265408.13 | S38: -272446.17 | T38: -279712.08
B39: =IF(C39<>"",SUBTOTAL(3,C$4:C39),"")
B40: =IF(C40<>"",SUBTOTAL(3,C$4:C40),"") -> 32 | C40: Chi phí vận chuyển | D40: tr. VND | F40: -2752.9667 | G40: -3854.1533 | H40: -5781.23 | I40: -6070.2915 | J40: -6373.8061 | K40: -6692.4964 | L40: -7027.1212 | M40: -7378.4772 | N40: -7747.4011 | O40: -8134.7711 | P40: -8541.5097 | Q40: -8968.5852 | R40: -9417.0144 | S40: -9887.8652 | T40: -10382.258
B41: =IF(C41<>"",SUBTOTAL(3,C$4:C41),"") -> 33 | C41: Chi phí nhân sự BH,QLDN | D41: tr. VND | F41: 0 | G41: 0 | H41: 0 | I41: 0 | J41: 0 | K41: 0 | L41: 0 | M41: 0 | N41: 0 | O41: 0 | P41: 0 | Q41: 0 | R41: 0 | S41: 0 | T41: 0
B42: =IF(C42<>"",SUBTOTAL(3,C$4:C42),"") -> 34 | C42: Chi phí quản lý chung | D42: tr. VND | F42: 0 | G42: 0 | H42: 0 | I42: 0 | J42: 0 | K42: 0 | L42: 0 | M42: 0 | N42: 0 | O42: 0 | P42: 0 | Q42: 0 | R42: 0 | S42: 0 | T42: 0
...

Sheet Sheet4
A3: Năm | B3: Dòng tiền | C3: Dòng tiền chiết khấu | D3: Dòng tiền chiết khấu Lũy kế
A4: 2026 | B4: {=TRANSPOSE('W3'!K168:AJ168)} -> -300749.8 | C4: {=TRANSPOSE('W3'!K170:AJ170)} -> -300749.8 | D4: =SUM(C$4:C4) -> -300749.8
A5: =A4+1 -> 2027 | B5: 26265.948 | C5: 24486.741 | D5: =SUM(C$4:C5) -> -276263.06
A6: =A5+1 -> 2028 | B6: 44419.022 | C6: 38605.112 | D6: =SUM(C$4:C6) -> -237657.95
A7: =A6+1 -> 2029 | B7: 68623.249 | C7: 55601.309 | D7: =SUM(C$4:C7) -> -182056.64
A8: =A7+1 -> 2030 | B8: 68927.026 | C8: 52064.439 | D8: =SUM(C$4:C8) -> -129992.2
A9: =A8+1 -> 2031 | B9: 69187.153 | C9: 48720.87 | D9: =SUM(C$4:C9) -> -81271.329
A10: =A9+1 -> 2032 | B10: 69400.272 | C10: 45560.519 | D10: =SUM(C$4:C10) -> -35710.81
A11: =A10+1 -> 2033 | B11: 69562.833 | C11: 42573.824 | D11: =SUM(C$4:C11) -> 6863.014
A12: =A11+1 -> 2034 | B12: 69671.083 | C12: 39751.715 | D12: =SUM(C$4:C12) -> 46614.729
A13: =A12+1 -> 2035 | B13: 69721.057 | C13: 37085.59 | D13: =SUM(C$4:C13) -> 83700.319
A14: =A13+1 -> 2036 | B14: 69708.569 | C14: 34567.288 | D14: =SUM(C$4:C14) -> 118267.61
A15: =A14+1 -> 2037 | B15: 69629.195 | C15: 32189.07 | D15: =SUM(C$4:C15) -> 150456.68
A16: =A15+1 -> 2038 | B16: 69478.267 | C16: 29943.595 | D16: =SUM(C$4:C16) -> 180400.27
... A29: =A28+1 -> 2051 | B29: 0 | C29: 0 | D29: =SUM(C$4:C29) -> 253244.22

Sheet Sheet2
A3: STT | B3: CHỈ TIÊU | C3: Đvt | E3: KẾ TOÁN ĐỀ XUẤT 680 VND/PHÔI | H3: GIÁ TRUNG BÌNH 650 VND/PHÔI | K3: THEO GIÁ SUNTORY YÊU CẦU 610 VND/phôi
E4: KHÔNG TÍNH ĐẦU TƯ XƯỞNG | F4: CÓ TÍNH ĐẦU TƯ XƯỞNG | H4: KHÔNG TÍNH ĐẦU TƯ XƯỞNG | I4: CÓ TÍNH ĐẦU TƯ XƯỞNG | K4: KHÔNG TÍNH ĐẦU TƯ XƯỞNG | L4: CÓ TÍNH ĐẦU TƯ XƯỞNG
A6: 1 | B6: Đơn giá bán phôi | C6: USD/tấn | E6: 1743.5897 | F6: 1743.5897 | H6: 1666.6667 | I6: 1666.6667 | K6: 1564.1026 | L6: 1564.1026
A7: 2 | B7: Đơn giá bán phôi | C7: VND/phôi | E7: 680 | F7: 680 | H7: 650 | I7: 650 | K7: 610 | L7: 610
A8: 3 | B8: Giá thành phôi | C8: USD/tấn | E8: 1559.8953 | F8: 1642.4576 | H8: 1559.8953 | I8: 1642.4576 | K8: 1559.8953 | L8: 1642.4576
A9: 4 | B9: Giá thành phôi | C9: VND/phôi | E9: 608.35915 | F9: 640.55846 | H9: 608.35915 | I9: 640.55846 | K9: 608.35915 | L9: 640.55846
A10: 5 | B10: Lợi nhuận sau thuế | C10: USD/tấn | E10: 146.95558 | F10: 80.905713 | H10: 85.417121 | I10: 19.367251 | K10: 3.3658393 | L10: -62.684031
A11: 6 | B11: Lợi nhuận sau thuế | C11: VND/phôi | E11: 57.312677 | F11: 31.553228 | H11: 33.312677 | I11: 7.553228 | K11: 1.3126773 | L11: -24.446772
B12: %LN sau thuế | E12: 0.084283349 | F12: 0.046401806 | H12: 0.051250273 | I12: 0.011620351 | K12: 0.00215193 | L12: -0.040076675
A13: 7 | B13: Chi phí đầu tư | C13: USD | E13: 11567300 | F13: 17336531 | H13: 11567300 | I13: 17336531 | K13: 11567300 | L13: 17336531
A14: 8 | B14: Chi phí đầu tư | C14: tỷ VND | E14: 300.7498 | F14: 450.7498 | H14: 300.7498 | I14: 450.7498 | K14: 300.7498 | L14: 450.7498
A15: 9 | B15: NPV | C15: tỷ VND | E15: 253.24422 | F15: 110.03709 | H15: 160.74752 | I15: 17.540395 | K15: 37.4186 | L15: -105.78853
A16: 10 | B16: Thời gian hoàn vốn | C16: năm | E16: 6 năm 11 tháng | F16: 10 năm 11 tháng | H16: 8 năm 04 tháng | I16: 14 năm 01 tháng | K16: 12 năm 02 tháng | L16: Không đạt hoàn vốn
A17: 11 | B17: % Lãi gộp nguyên liệu/Giá bán | C17: % | E17: 0.4384 | F17: 0.4384 | H17: 0.41248 | I17: 0.41248 | K17: 0.3739541 | L17: 0.3739541
B20: Đầu tư khuôn | E20: Có | F20: Có | H20: Có | I20: Có | K20: Có | L20: Có
B21: Đầu tư xưởng | F21: Có | I21: Có | L21: Có

Sheet ||

Sheet Summary
C1: Công ty CP Nhựa tái chế Duy Tân
C2: Đơn vị: Kế toán quản trị
C3: DỰ ÁN FLAKES TO PREFORM SUNTORY - PEPSICO
C4: MỘT SỐ CHỈ TIÊU TRỌNG YẾU
C5: 15gr Hotfill | L5: GIÁ ĐỀ XUẤT - THÁNG 12/2025 : | O5: GIÁ TRUNG BÌNH | R5: GIÁ ĐỀ XUẤT SUNTORY
M6: 680 | P6: 650 | S6: 610
F8: Paste chết | G8: Paste chết | I8: Paste chết | J8: Paste chết | U8: Paste chết | V8: Paste chết
B9: STT | C9: CHỈ TIÊU | D9: Đvt | F9: BÁO GIÁ LẦN 1-KHÔNG TÍNH ĐẦU TƯ XƯỞNG | G9: BÁO GIÁ LẦN 1-CÓ TÍNH ĐẦU TƯ XƯỞNG | I9: BÁO GIÁ LẦN 2 - KHÔNG TÍNH ĐẦU TƯ XƯỞNG | J9: BÁO GIÁ LẦN 2 - CÓ TÍNH ĐẦU TƯ XƯỞNG | L9: KẾ TOÁN ĐỀ XUẤT 680 VND/PHÔI | O9: GIÁ TRUNG BÌNH 650 VND/PHÔI | R9: ="SUNTORY YÊU CẦU "&$S$6&" VND/phôi" -> SUNTORY YÊU CẦU 610 VND/phôi | U9: CƠ SỞ-BÁO GIÁ L1- KHÔNG TÍNH ĐẦU TƯ XƯỞNG | V9: CƠ SỞ-BÁO GIÁ L2- KHÔNG TÍNH ĐẦU TƯ XƯỞNG
L10: KHÔNG TÍNH ĐẦU TƯ XƯỞNG | M10: CÓ TÍNH ĐẦU TƯ XƯỞNG | O10: KHÔNG TÍNH ĐẦU TƯ XƯỞNG | P10: CÓ TÍNH ĐẦU TƯ XƯỞNG | R10: KHÔNG TÍNH ĐẦU TƯ XƯỞNG | S10: CÓ TÍNH ĐẦU TƯ XƯỞNG
F11: Tháng 10/2024 | G11: Tháng 10/2024 | I11: Tháng 02/2025 | J11: Tháng 02/2025 | U11: Tháng 10/2024 | V11: Tháng 02/2025
B12: 1 | C12: Đơn giá bán phôi | D12: USD/tấn | F12: 1969.3333 | G12: 1969.3333 | I12: 1916 | J12: 1916 | L12: =L13*(1000000/'Cover Page'!$F$25)/EXR -> 1743.5897 | M12: =M13*(1000000/'Cover Page'!$F$25)/EXR -> 1743.5897 | O12: =O13*(1000000/'Cover Page'!$F$25)/EXR -> 1666.6667 | P12: =P13*(1000000/'Cover Page'!$F$25)/EXR -> 1666.6667 | R12: =R13*(1000000/'Cover Page'!$F$25)/EXR -> 1564.1026 | S12: =S13*(1000000/'Cover Page'!$F$25)/EXR -> 1564.1026 | U12: 1941.3333 | V12: 1941.3333
B13: 2 | C13: Đơn giá bán phôi | D13: VND/phôi | F13: 738.5 | G13: 738.5 | I13: 718.5 | J13: 718.5 | L13: =M6 -> 680 | M13: =M6 -> 680 | O13: =P6 -> 650 | P13: =P6 -> 650 | R13: =S6 -> 610 | S13: =S6 -> 610 | U13: 728 | V13: 728
B14: 3 | C14: Giá thành phôi | D14: USD/tấn | F14: 1757.3256 | G14: 1860.577 | I14: 1690.3835 | J14: 1793.6349 | L14: =L15*(1000000/'Cover Page'!$F$25)/EXR -> 1559.8953 | M14: =M15*(1000000/'Cover Page'!$F$25)/EXR -> 1642.4576 | O14: =O15*(1000000/'Cover Page'!$F$25)/EXR -> 1559.8953 | P14: =P15*(1000000/'Cover Page'!$F$25)/EXR -> 1642.4576 | R14: =R15*(1000000/'Cover Page'!$F$25)/EXR -> 1559.8953 | S14: =S15*(1000000/'Cover Page'!$F$25)/EXR -> 1642.4576 | U14: 1692.1813 | V14: 1631.3776
B15: 4 | C15: Giá thành phôi | D15: VND/phôi | F15: 658.9971 | G15: 697.71636 | I15: 633.89382 | J15: 672.61307 | L15: ='W5'!E6 -> 608.35915 | M15: ='W5'!G6 -> 640.55846 | O15: ='W5'!I6 -> 608.35915 | P15: ='W5'!K6 -> 640.55846 | R15: ='W5'!M6 -> 608.35915 | S15: ='W5'!O6 -> 640.55846 | U15: 634.56797 | V15: 611.76659
B16: 5 | C16: Lợi nhuận sau thuế | D16: USD/tấn | F16: 169.60618 | G16: 87.005099 | I16: 180.49319 | J16: 97.892107 | L16: =L17*(1000000/'Cover Page'!$F$25)/EXR -> 146.95558 | M16: =M17*(1000000/'Cover Page'!$F$25)/EXR -> 80.905713 | O16: =O17*(1000000/'Cover Page'!$F$25)/EXR -> 85.417121 | P16: =P17*(1000000/'Cover Page'!$F$25)/EXR -> 19.367251 | R16: =R17*(1000000/'Cover Page'!$F$25)/EXR -> 3.3658393 | S16: =S17*(1000000/'Cover Page'!$F$25)/EXR -> -62.684031 | U16: 199.32165 | V16: 247.96461
B17: 6 | C17: Lợi nhuận sau thuế | D17: VND/phôi | F17: 63.602319 | G17: 32.626912 | I17: 67.684947 | J17: 36.70954 | L17: ='W5'!E8 -> 57.312677 | M17: ='W5'!G8 -> 31.553228 | O17: ='W5'!I8 -> 33.312677 | P17: ='W5'!K8 -> 7.553228 | R17: ='W5'!M8 -> 1.3126773 | S17: ='W5'!O8 -> -24.446772 | U17: 74.745621 | V17: 92.986729
C18: %LN sau thuế | F18: 0.086123655 | G18: 0.044179976 | I18: 0.094203128 | J18: 0.051091914 | L18: ='W5'!E10 -> 0.084283349 | M18: ='W5'!G10 -> 0.046401806 | O18: ='W5'!I10 -> 0.051250273 | P18: ='W5'!K10 -> 0.011620351 | R18: ='W5'!M10 -> 0.00215193 | S18: ='W5'!O10 -> -0.040076675 | U18: 0.10267256 | V18: 0.12772902
B19: 7 | C19: Chi phí đầu tư | D19: USD | F19: 11070000 | G19: 17070000 | I19: 11070000 | J19: 17070000 | L19: =IF(Currency="USD",'W1'!$I$60,'W1'!$I$60/EXR) -> 11567300 | M19: =IF(Currency="USD",'W1'!$N$60,'W1'!$N$60/EXR) -> 17336531 | O19: =IF(Currency="USD",'W1'!$S$60,'W1'!$S$60/EXR) -> 11567300 | P19: =IF(Currency="USD",'W1'!$X$60,'W1'!$X$60/EXR) -> 17336531 | R19: =IF(Currency="USD",'W1'!$AC$60,'W1'!$AC$60/EXR) -> 11567300 | S19: =IF(Currency="USD",'W1'!$AH$60,'W1'!$AH$60/EXR) -> 17336531 | U19: 10054913 | V19: 10054913
B20: 8 | C20: Chi phí đầu tư | D20: tỷ VND | F20: 276.75 | G20: 426.75 | I20: 276.75 | J20: 426.75 | L20: =L19*EXR/10^9 -> 300.7498 | M20: =M19*EXR/10^9 -> 450.7498 | O20: =O19*EXR/10^9 -> 300.7498 | P20: =P19*EXR/10^9 -> 450.7498 | R20: =R19*EXR/10^9 -> 300.7498 | S20: =S19*EXR/10^9 -> 450.7498 | U20: 251.37282 | V20: 251.37282
B21: 9 | C21: NPV | D21: tỷ VND | F21: 426.17409 | G21: 284.37183 | I21: 382.62104 | J21: 240.81878 | L21: =IF(Currency="VND",'W5'!E15/10^3,'W5'!E15*EXR/10^9) -> 253.24422 | M21: =IF(Currency="VND",'W5'!G15/10^3,'W5'!G15*EXR/10^9) -> 110.03709 | O21: =IF(Currency="VND",'W5'!I15/10^3,'W5'!I15/10^9) -> 160.74752 | P21: =IF(Currency="VND",'W5'!K15/10^3,'W5'!K15*EXR/10^9) -> 17.540395 | R21: =IF(Currency="VND",'W5'!M15/10^3,'W5'!M15*EXR/10^9) -> 37.4186 | S21: =IF(Currency="VND",'W5'!O15/10^3,'W5'!O15*EXR/10^9) -> -105.78853 | U21: 491.97502 | V21: 487.89218
B22: 10 | C22: Thời gian hoàn vốn | D22: năm | F22: 6 năm | G22: 9 năm 08 tháng | I22: 6 năm 06 tháng | J22: 10 năm 08 tháng | L22: ='W5'!E13 -> 6 năm 11 tháng | M22: ='W5'!G13 -> 10 năm 11 tháng | O22: ='W5'!I13 -> 8 năm 04 tháng | P22: ='W5'!K13 -> 14 năm 01 tháng | R22: ='W5'!M13 -> 12 năm 02 tháng | S22: =IF('W5'!O13="0 năm","Không đạt hoàn vốn",'W5'!O13) -> Không đạt hoàn vốn | U22: 5 năm 05 tháng | V22: 5 năm 07 tháng
B23: 11 | C23: % Lãi gộp nguyên liệu/Giá bán | D23: % | F23: 0.4648998 | G23: 0.4648998 | I23: 0.45000487 | J23: 0.45000487 | L23: ='W5'!F108 -> 0.4384 | M23: ='W5'!H108 -> 0.4384 | O23: ='W5'!J108 -> 0.41248 | P23: ='W5'!L108 -> 0.41248 | R23: ='W5'!N108 -> 0.3739541 | S23: ='W5'!P108 -> 0.3739541 | U23: 0.45718201 | V23: 0.45718201
C26: DTR-Đầu tư khuôn | L26: Có | M26: Có | O26: Có | P26: Có | R26: Có | S26: Có
C27: DTR-Đầu tư xưởng | G27: Có | J27: Có | M27: Có | P27: Có | S27: Có
C29: Vảy sạch | G29: 1033 | J29: 1033

Sheet Cover Page
D3: COVER PAGE
D4: CHỈ TIÊU | H4: BASE-KHÔNG XƯỞNG | K4: BASE-CÓ XƯỞNG | N4: 650 VND/Phôi-KHÔNG XƯỞNG | Q4: 650 VND/Phôi-CÓ XƯỞNG | T4: SUNTORY-KHÔNG XƯỞNG | W4: SUNTORY-CÓ XƯỞNG | Z4: NPV=0 - KHÔNG XƯỞNG | AC4: NPV=0 - CÓ XƯỞNG | AF4: THỦ | AI4: THỦ | AL4: Công suất máy
C5: STT | D5: GIẢ ĐỊNH | E5: Đvt | F5: CHUNG | H5: OPTION 1 | K5: OPTION 2 | N5: OPTION 3 | Q5: OPTION 4 | T5: OPTION 5 | W5: OPTION 6 | Z5: OPTION 7 | AC5: OPTION 8 | AF5: OPTION 9 | AI5: OPTION 10 | AL5: Công suất máy
C6: 1 | D6: CAPEX | H6: Thực tế | Q6: 0 | T6: 0 | W6: 0 | Z6: 0 | AC6: 0 | AF6: 0 | AI6: 0
C7: 2 | D7: Chi phí sản xuất | H7: Thực tế | Q7: 0 | T7: 0 | W7: 0 | Z7: 0 | AC7: 0 | AF7: 0 | AI7: 0
D8: Chi phí vảy tăng | H8: 0.02 | K8: 0.02 | N8: 0.02 | Q8: 0.02 | T8: 0.02 | W8: 0.02 | Z8: 0.02 | AC8: 0.02 | AF8: 0.02 | AI8: 0.02
C9: 3 | D9: Lạm Phát | F9: 0.05
C10: 4 | D10: Tỷ giá | F10: 26000
C11: 5 | D11: Thuế suất TNDN: | F11: 0.2
C12: 6 | D12: Mark-up giá bán | H12: =5%/(1-Tax_rate-5%) -> 0.066666667 | K12: =5%/(1-Tax_rate-5%) -> 0.066666667 | N12: =5%/(1-Tax_rate-5%) -> 0.066666667 | Q12: =5%/(1-Tax_rate-5%) -> 0.066666667 | T12: =5%/(1-Tax_rate-5%) -> 0.066666667 | W12: =5%/(1-Tax_rate-5%) -> 0.066666667 | Z12: =5%/(1-Tax_rate-5%) -> 0.066666667 | AC12: =5%/(1-Tax_rate-5%) -> 0.066666667 | AF12: =5%/(1-Tax_rate-5%) -> 0.066666667 | AI12: =5%/(1-Tax_rate-5%) -> 0.066666667
C13: 7.1 | D13: Đơn giá ban đầu | E13: tr. VND/tấn | H13: =H14*PHOI_KG*10^3/10^6 -> 45.333333 | K13: =K14*PHOI_KG*10^3/10^6 -> 45.333333 | N13: =N14*PHOI_KG*10^3/10^6 -> 43.333333 | Q13: =Q14*PHOI_KG*10^3/10^6 -> 43.333333 | T13: =T14*PHOI_KG*10^3/10^6 -> 40.666667 | W13: =W14*PHOI_KG*10^3/10^6 -> 40.666667 | Z13: =Z14*PHOI_KG*10^3/10^6 -> 39.065014 | AC13: =AC14*PHOI_KG*10^3/10^6 -> 41.282922 | AF13: =AF14*PHOI_KG*10^3/10^6 -> 45.333333 | AI13: =AI14*PHOI_KG*10^3/10^6 -> 45.333333
C14: 7.2 | D14: Đơn giá ban đầu | E14: VND/phôi | H14: ='W5'!AC2 -> 680 | K14: ='W5'!AD2 -> 680 | N14: ='W5'!AE2 -> 650 | Q14: ='W5'!AF2 -> 650 | T14: ='W5'!AG2 -> 610 | W14: ='W5'!AH2 -> 610 | Z14: ='W5'!AI2 -> 585.97522 | AC14: ='W5'!AJ2 -> 619.24384 | AF14: ='W5'!AK2 -> 680 | AI14: ='W5'!AL2 -> 680 | AL14: Lấy số từ W5
C15: 7.3 | D15: Đơn giá ban đầu | E15: USD/tấn | H15: =H13/EXR*10^6 -> 1743.5897 | K15: =K13/EXR*10^6 -> 1743.5897 | N15: =N13/EXR*10^6 -> 1666.6667 | Q15: =Q13/EXR*10^6 -> 1666.6667 | T15: =T13/EXR*10^6 -> 1564.1026 | W15: =W13/EXR*10^6 -> 1564.1026 | Z15: =Z13/EXR*10^6 -> 1502.5006 | AC15: =AC13/EXR*10^6 -> 1587.8047 | AF15: =AF13/EXR*10^6 -> 1743.5897 | AI15: =AI13/EXR*10^6 -> 1743.5897
C16: 7.4 | D16: Đơn giá ban đầu | E16: USD/1.000 phôi | H16: =H15/PHOI_KG -> 26.153846 | K16: =K15/PHOI_KG -> 26.153846 | W16: =W15/PHOI_KG -> 23.461538 | Z16: =Z15/PHOI_KG -> 22.537508 | AC16: =AC15/PHOI_KG -> 23.817071 | AF16: =AF15/PHOI_KG -> 26.153846 | AI16: =AI15/PHOI_KG -> 26.153846
C17: 8 | D17: Tỷ lệ tăng đơn giá | H17: 0.02 | K17: 0.02 | N17: 0.02 | Q17: 0.02 | T17: 0.02 | W17: 0.02 | Z17: 0.02 | AC17: 0.02 | AF17: 0.02 | AI17: 0.02 | AL17: tăng mỗi năm
C19: 9.1 | D19: Lãi suất đi vay: | H19: 0.07 | K19: 0.07 | N19: 0.07 | Q19: 0.07 | T19: 0.07 | W19: 0.07 | Z19: 0.07 | AC19: 0.07 | AF19: 0.07 | AI19: 0.07
C20: 9.2 | D20: Lợi nhuận mong muốn cổ đông: | H20: 0.1 | K20: 0.1 | N20: 0.1 | Q20: 0.1 | T20: 0.1 | W20: 0.1 | Z20: 0.1 | AC20: 0.1 | AF20: 0.1 | AI20: 0.1
C21: 9.3 | D21: Cơ cấu vay mong muốn: | H21: 0.7 | K21: 0.7 | N21: 0.7 | Q21: 0.7 | T21: 0.7 | W21: 0.7 | Z21: 0.7 | AC21: 0.7 | AF21: 0.7 | AI21: 0.7
C22: 9.4 | D22: Cơ cấu VCSH: | H22: =1-H21 -> 0.3 | K22: =1-K21 -> 0.3 | N22: =1-N21 -> 0.3 | Q22: =1-Q21 -> 0.3 | T22: =1-T21 -> 0.3 | W22: =1-W21 -> 0.3 | Z22: =1-Z21 -> 0.3 | AC22: =1-AC21 -> 0.3 | AF22: =1-AF21 -> 0.3 | AI22: =1-AI21 -> 0.3
C23: 9.5 | D23: WACC: | H23: =(H19*H21*(1-Tax_rate)+H20*H22)*(1+Inflation) -> 0.07266 | K23: =(K19*K21*(1-Tax_rate)+K20*K22)*(1+Inflation) -> 0.07266 | N23: =(N19*N21*(1-Tax_rate)+N20*N22)*(1+Inflation) -> 0.07266 | Q23: =(Q19*Q21*(1-Tax_rate)+Q20*Q22)*(1+Inflation) -> 0.07266 | T23: =(T19*T21*(1-Tax_rate)+T20*T22)*(1+Inflation) -> 0.07266 | W23: =(W19*W21*(1-Tax_rate)+W20*W22)*(1+Inflation) -> 0.07266 | Z23: =(Z19*Z21*(1-Tax_rate)+Z20*Z22)*(1+Inflation) -> 0.07266 | AC23: =(AC19*AC21*(1-Tax_rate)+AC20*AC22)*(1+Inflation) -> 0.07266 | AF23: =(AF19*AF21*(1-Tax_rate)+AF20*AF22)*(1+Inflation) -> 0.07266 | AI23: =(AI19*AI21*(1-Tax_rate)+AI20*AI22)*(1+Inflation) -> 0.07266
C25: 10.1 | D25: Khuôn phôi | E25: gram | F25: 15
C26: 10.2 | D26: Số lượng phôi/chu kỳ: | E26: phôi/chu kỳ | F26: 128
C27: 10.3 | D27: Chu kỳ | E27: giây | F27: 8
C28: 10.4 | D28: Công suất | E28: kg/giờ | F28: =60*60/F27*F26*F25/10^3 -> 864
C29: 10.5 | D29: Công suất | E29: phôi/giờ | F29: =Capacity/F25*10^3 -> 57600
C30: 10.6 | D30: Số phôi/kg | E30: phôi/kg | F30: =1000/F25 -> 66.666667
A33: =MD!A7 -> VND | D33: KẾT QUẢ
A34: =IF(Currency="USD",1,0.000001) -> 1e-06 | C34: 11 | D34: Tổng mức đầu tư | E34: =IF(Currency="USD","USD","triệu VND") -> triệu VND | H34: ='W1'!I60*$A$34 -> 300749.8 | K34: ='W1'!N60*$A$34 -> 450749.8 | N34: ='W1'!S60*$A$34 -> 300749.8 | Q34: ='W1'!X60*$A$34 -> 450749.8 | T34: ='W1'!AC60*$A$34 -> 300749.8 | W34: ='W1'!AH60*$A$34 -> 450749.8 | Z34: ='W1'!AM60*$A$34 -> 300749.8 | AC34: ='W1'!AR60*$A$34 -> 450749.8 | AF34: ='W1'!AW60*$A$34 -> 300749.8 | AI34: ='W1'!BB60*$A$34 -> 450749.8
B35: DPP | C35: 12 | D35: Thời gian thu hồi vốn | E35: năm | H35: =SUMIFS('W3'!$K$18:$K$1670,'W3'!$A$18:$A$1670,H$5,'W3'!$D$18:$D$1670,$B$35) -> 6.9 | K35: =SUMIFS('W3'!$K$18:$K$1670,'W3'!$A$18:$A$1670,K$5,'W3'!$D$18:$D$1670,$B$35) -> 10.9 | N35: =SUMIFS('W3'!$K$18:$K$1670,'W3'!$A$18:$A$1670,N$5,'W3'!$D$18:$D$1670,$B$35) -> 8.3 | Q35: =SUMIFS('W3'!$K$18:$K$1670,'W3'!$A$18:$A$1670,Q$5,'W3'!$D$18:$D$1670,$B$35) -> 14.1 | T35: =SUMIFS('W3'!$K$18:$K$1670,'W3'!$A$18:$A$1670,T$5,'W3'!$D$18:$D$1670,$B$35) -> 12.2 | W35: =SUMIFS('W3'!$K$18:$K$1670,'W3'!$A$18:$A$1670,W$5,'W3'!$D$18:$D$1670,$B$35) -> 0 | Z35: =SUMIFS('W3'!$K$18:$K$1670,'W3'!$A$18:$A$1670,Z$5,'W3'!$D$18:$D$1670,$B$35) -> 0 | AC35: =SUMIFS('W3'!$K$18:$K$1670,'W3'!$A$18:$A$1670,AC$5,'W3'!$D$18:$D$1670,$B$35) -> 0 | AF35: =SUMIFS('W3'!$K$18:$K$1670,'W3'!$A$18:$A$1670,AF$5,'W3'!$D$18:$D$1670,$B$35) -> 6.9 | AI35: =SUMIFS('W3'!$K$18:$K$1670,'W3'!$A$18:$A$1670,AI$5,'W3'!$D$18:$D$1670,$B$35) -> 10.9
H36: =INT(H35)&" năm"&IF(MOD(H35,1)*12=0,," "&TEXT(MOD(H35,1)*12,"00")&" tháng") -> 6 năm 11 tháng | K36: =INT(K35)&" năm"&IF(MOD(K35,1)*12=0,," "&TEXT(MOD(K35,1)*12,"00")&" tháng") -> 10 năm 11 tháng | N36: =INT(N35)&" năm"&IF(MOD(N35,1)*12=0,," "&TEXT(MOD(N35,1)*12,"00")&" tháng") -> 8 năm 04 tháng | Q36: =INT(Q35)&" năm"&IF(MOD(Q35,1)*12=0,," "&TEXT(MOD(Q35,1)*12,"00")&" tháng") -> 14 năm 01 tháng | T36: =INT(T35)&" năm"&IF(MOD(T35,1)*12=0,," "&TEXT(MOD(T35,1)*12,"00")&" tháng") -> 12 năm 02 tháng | W36: =INT(W35)&" năm"&IF(MOD(W35,1)*12=0,," "&TEXT(MOD(W35,1)*12,"00")&" tháng") -> 0 năm | Z36: =INT(Z35)&" năm"&IF(MOD(Z35,1)*12=0,," "&TEXT(MOD(Z35,1)*12,"00")&" tháng") -> 0 năm | AC36: =INT(AC35)&" năm"&IF(MOD(AC35,1)*12=0,," "&TEXT(MOD(AC35,1)*12,"00")&" tháng") -> 0 năm | AF36: =INT(AF35)&" năm"&IF(MOD(AF35,1)*12=0,," "&TEXT(MOD(AF35,1)*12,"00")&" tháng") -> 6 năm 11 tháng | AI36: =INT(AI35)&" năm"&IF(MOD(AI35,1)*12=0,," "&TEXT(MOD(AI35,1)*12,"00")&" tháng") -> 10 năm 11 tháng
B37: IRR | C37: 13 | D37: Tỷ suất hoàn vốn nội bộ (IRR) | E37: % | H37: =SUMIFS('W3'!$K$18:$K$1670,'W3'!$A$18:$A$1670,H$5,'W3'!$D$18:$D$1670,$B$37) -> 0.1774592 | K37: =SUMIFS('W3'!$K$18:$K$1670,'W3'!$A$18:$A$1670,K$5,'W3'!$D$18:$D$1670,$B$37) -> 0.10663649 | N37: =SUMIFS('W3'!$K$18:$K$1670,'W3'!$A$18:$A$1670,N$5,'W3'!$D$18:$D$1670,$B$37) -> 0.14321796 | Q37: =SUMIFS('W3'!$K$18:$K$1670,'W3'!$A$18:$A$1670,Q$5,'W3'!$D$18:$D$1670,$B$37) -> 0.07840017 | T37: =SUMIFS('W3'!$K$18:$K$1670,'W3'!$A$18:$A$1670,T$5,'W3'!$D$18:$D$1670,$B$37) -> 0.090883732 | W37: =SUMIFS('W3'!$K$18:$K$1670,'W3'!$A$18:$A$1670,W$5,'W3'!$D$18:$D$1670,$B$37) -> 0.034366044 | Z37: =SUMIFS('W3'!$K$18:$K$1670,'W3'!$A$18:$A$1670,Z$5,'W3'!$D$18:$D$1670,$B$37) -> 0.053201942 | AC37: =SUMIFS('W3'!$K$18:$K$1670,'W3'!$A$18:$A$1670,AC$5,'W3'!$D$18:$D$1670,$B$37) -> 0.045414211 | AF37: =SUMIFS('W3'!$K$18:$K$1670,'W3'!$A$18:$A$1670,AF$5,'W3'!$D$18:$D$1670,$B$37) -> 0.1774592 | AI37: =SUMIFS('W3'!$K$18:$K$1670,'W3'!$A$18:$A$1670,AI$5,'W3'!$D$18:$D$1670,$B$37) -> 0.10663649
D39: Đơn giá năm đầu | E39: VND/phôi | H39: =H14 -> 680 | K39: =K14 -> 680 | N39: =N14 -> 650 | Q39: =Q14 -> 650 | T39: =T14 -> 610 | W39: =W14 -> 610 | Z39: =Z14 -> 585.97522 | AC39: =AC14 -> 619.24384 | AF39: =AF14 -> 680 | AI39: =AI14 -> 680
D40: Đơn giá năm đầu | E40: USD/tấn | H40: =H15 -> 1743.5897 | K40: =K15 -> 1743.5897 | N40: =N15 -> 1666.6667 | Q40: =Q15 -> 1666.6667 | T40: =T15 -> 1564.1026 | W40: =W15 -> 1564.1026 | Z40: =Z15 -> 1502.5006 | AC40: =AC15 -> 1587.8047 | AF40: =AF15 -> 1743.5897 | AI40: =AI15 -> 1743.5897
B42: NPV | C42: 14 | D42: Dòng tiền chiết khẩu | E42: =IF(Currency="USD","USD","triệu VND") -> triệu VND | H42: =SUM(H43:H68) -> 253244.22 | K42: =SUM(K43:K68) -> 110037.09 | N42: =SUM(N43:N68) -> 160747.52 | Q42: =SUM(Q43:Q68) -> 17540.395 | T42: =SUM(T43:T68) -> 37418.6 | W42: =SUM(W43:W68) -> -105788.53 | Z42: =SUM(Z43:Z68) -> -36655.167 | AC42: =SUM(AC43:AC68) -> -77287.721 | AF42: =SUM(AF43:AF68) -> 253244.22 | AI42: =SUM(AI43:AI68) -> 110037.09
D43: 0 | E43: =IF(Currency="USD","USD","triệu VND") -> triệu VND | H43: {=SUMPRODUCT('W3'!$K$18:$AJ$1670*('W3'!$A$18:$A$1670=H$5)*('W3'!$D$18:$D$1670=$B$42)*('W3'!$K$14:$AJ$14='Cover Page'!$D43))} -> -300749.8 | K43: {=SUMPRODUCT('W3'!$K$18:$AJ$1670*('W3'!$A$18:$A$1670=K$5)*('W3'!$D$18:$D$1670=$B$42)*('W3'!$K$14:$AJ$14='Cover Page'!$D43))} -> -450749.8 | N43: {=SUMPRODUCT('W3'!$K$18:$AJ$1670*('W3'!$A$18:$A$1670=N$5)*('W3'!$D$18:$D$1670=$B$42)*('W3'!$K$14:$AJ$14='Cover Page'!$D43))} -> -300749.8 | Q43: {=SUMPRODUCT('W3'!$K$18:$AJ$1670*('W3'!$A$18:$A$1670=Q$5)*('W3'!$D$18:$D$1670=$B$42)*('W3'!$K$14:$AJ$14='Cover Page'!$D43))} -> -450749.8 | T43: {=SUMPRODUCT('W3'!$K$18:$AJ$1670*('W3'!$A$18:$A$1670=T$5)*('W3'!$D$18:$D$1670=$B$42)*('W3'!$K$14:$AJ$14='Cover Page'!$D43))} -> -300749.8 | W43: {=SUMPRODUCT('W3'!$K$18:$AJ$1670*('W3'!$A$18:$A$1670=W$5)*('W3'!$D$18:$D$1670=$B$42)*('W3'!$K$14:$AJ$14='Cover Page'!$D43))} -> -450749.8 | Z43: {=SUMPRODUCT('W3'!$K$18:$AJ$1670*('W3'!$A$18:$A$1670=Z$5)*('W3'!$D$18:$D$1670=$B$42)*('W3'!$K$14:$AJ$14='Cover Page'!$D43))} -> -300749.8 | AC43: {=SUMPRODUCT('W3'!$K$18:$AJ$1670*('W3'!$A$18:$A$1670=AC$5)*('W3'!$D$18:$D$1670=$B$42)*('W3'!$K$14:$AJ$14='Cover Page'!$D43))} -> -450749.8 | AF43: {=SUMPRODUCT('W3'!$K$18:$AJ$1670*('W3'!$A$18:$A$1670=AF$5)*('W3'!$D$18:$D$1670=$B$42)*('W3'!$K$14:$AJ$14='Cover Page'!$D43))} -> -300749.8 | AI43: {=SUMPRODUCT('W3'!$K$18:$AJ$1670*('W3'!$A$18:$A$1670=AI$5)*('W3'!$D$18:$D$1670=$B$42)*('W3'!$K$14:$AJ$14='Cover Page'!$D43))} -> -450749.8 | AT43: Giả định: sau 25 năm thì giá trị các tài sản còn lại =0
D44: 1 | E44: =IF(Currency="USD","USD","triệu VND") -> triệu VND | H44: {=SUMPRODUCT('W3'!$K$18:$AJ$1670*('W3'!$A$18:$A$1670=H$5)*('W3'!$D$18:$D$1670=$B$42)*('W3'!$K$14:$AJ$14='Cover Page'!$D44))} -> 24486.741 | K44: {=SUMPRODUCT('W3'!$K$18:$AJ$1670*('W3'!$A$18:$A$1670=K$5)*('W3'!$D$18:$D$1670=$B$42)*('W3'!$K$14:$AJ$14='Cover Page'!$D44))} -> 25193.769 | N44: {=SUMPRODUCT('W3'!$K$18:$AJ$1670*('W3'!$A$18:$A$1670=N$5)*('W3'!$D$18:$D$1670=$B$42)*('W3'!$K$14:$AJ$14='Cover Page'!$D44))} -> 19867.067 | Q44: {=SUMPRODUCT('W3'!$K$18:$AJ$1670*('W3'!$A$18:$A$1670=Q$5)*('W3'!$D$18:$D$1670=$B$42)*('W3'!$K$14:$AJ$14='Cover Page'!$D44))} -> 20574.094 | T44: {=SUMPRODUCT('W3'!$K$18:$AJ$1670*('W3'!$A$18:$A$1670=T$5)*('W3'!$D$18:$D$1670=$B$42)*('W3'!$K$14:$AJ$14='Cover Page'!$D44))} -> 13707.501 | W44: {=SUMPRODUCT('W3'!$K$18:$AJ$1670*('W3'!$A$18:$A$1670=W$5)*('W3'!$D$18:$D$1670=$B$42)*('W3'!$K$14:$AJ$14='Cover Page'!$D44))} -> 14414.528 | Z44: {=SUMPRODUCT('W3'!$K$18:$AJ$1670*('W3'!$A$18:$A$1670=Z$5)*('W3'!$D$18:$D$1670=$B$42)*('W3'!$K$14:$AJ$14='Cover Page'!$D44))} -> 10007.945 | AC44: {=SUMPRODUCT('W3'!$K$18:$AJ$1670*('W3'!$A$18:$A$1670=AC$5)*('W3'!$D$18:$D$1670=$B$42)*('W3'!$K$14:$AJ$14='Cover Page'!$D44))} -> 15837.979 | AF44: {=SUMPRODUCT('W3'!$K$18:$AJ$1670*('W3'!$A$18:$A$1670=AF$5)*('W3'!$D$18:$D$1670=$B$42)*('W3'!$K$14:$AJ$14='Cover Page'!$D44))} -> 24486.741 | AI44: {=SUMPRODUCT('W3'!$K$18:$AJ$1670*('W3'!$A$18:$A$1670=AI$5)*('W3'!$D$18:$D$1670=$B$42)*('W3'!$K$14:$AJ$14='Cover Page'!$D44))} -> 25193.769
D45: 2 | E45: =IF(Currency="USD","USD","triệu VND") -> triệu VND | H45: {=SUMPRODUCT('W3'!$K$18:$AJ$1670*('W3'!$A$18:$A$1670=H$5)*('W3'!$D$18:$D$1670=$B$42)*('W3'!$K$14:$AJ$14='Cover Page'!$D45))} -> 38605.112 | K45: {=SUMPRODUCT('W3'!$K$18:$AJ$1670*('W3'!$A$18:$A$1670=K$5)*('W3'!$D$18:$D$1670=$B$42)*('W3'!$K$14:$AJ$14='Cover Page'!$D45))} -> 39264.247 | N45: {=SUMPRODUCT('W3'!$K$18:$AJ$1670*('W3'!$A$18:$A$1670=N$5)*('W3'!$D$18:$D$1670=$B$42)*('W3'!$K$14:$AJ$14='Cover Page'!$D45))} -> 32455.078 | Q45: {=SUMPRODUCT('W3'!$K$18:$AJ$1670*('W3'!$A$18:$A$1670=Q$5)*('W3'!$D$18:$D$1670=$B$42)*('W3'!$K$14:$AJ$14='Cover Page'!$D45))} -> 33114.213 | T45: {=SUMPRODUCT('W3'!$K$18:$AJ$1670*('W3'!$A$18:$A$1670=T$5)*('W3'!$D$18:$D$1670=$B$42)*('W3'!$K$14:$AJ$14='Cover Page'!$D45))} -> 24255.034 | W45: {=SUMPRODUCT('W3'!$K$18:$AJ$1670*('W3'!$A$18:$A$1670=W$5)*('W3'!$D$18:$D$1670=$B$42)*('W3'!$K$14:$AJ$14='Cover Page'!$D45))} -> 24914.168 | Z45: {=SUMPRODUCT('W3'!$K$18:$AJ$1670*('W3'!$A$18:$A$1670=Z$5)*('W3'!$D$18:$D$1670=$B$42)*('W3'!$K$14:$AJ$14='Cover Page'!$D45))} -> 19329.926 | AC45: {=SUMPRODUCT('W3'!$K$18:$AJ$1670*('W3'!$A$18:$A$1670=AC$5)*('W3'!$D$18:$D$1670=$B$42)*('W3'!$K$14:$AJ$14='Cover Page'!$D45))} -> 26809.165 | AF45: {=SUMPRODUCT('W3'!$K$18:$AJ$1670*('W3'!$A$18:$A$1670=AF$5)*('W3'!$D$18:$D$1670=$B$42)*('W3'!$K$14:$AJ$14='Cover Page'!$D45))} -> 38605.112 | AI45: {=SUMPRODUCT('W3'!$K$18:$AJ$1670*('W3'!$A$18:$A$1670=AI$5)*('W3'!$D$18:$D$1670=$B$42)*('W3'!$K$14:$AJ$14='Cover Page'!$D45))} -> 39264.247
D46: 3 | E46: =IF(Currency="USD","USD","triệu VND") -> triệu VND | H46: {=SUMPRODUCT('W3'!$K$18:$AJ$1670*('W3'!$A$18:$A$1670=H$5)*('W3'!$D$18:$D$1670=$B$42)*('W3'!$K$14:$AJ$14='Cover Page'!$D46))} -> 55601.309 | K46: {=SUMPRODUCT('W3'!$K$18:$AJ$1670*('W3'!$A$18:$A$1670=K$5)*('W3'!$D$18:$D$1670=$B$42)*('W3'!$K$14:$AJ$14='Cover Page'!$D46))} -> 56215.796 | N46: {=SUMPRODUCT('W3'!$K$18:$AJ$1670*('W3'!$A$18:$A$1670=N$5)*('W3'!$D$18:$D$1670=$B$42)*('W3'!$K$14:$AJ$14='Cover Page'!$D46))} -> 47246.866 | Q46: {=SUMPRODUCT('W3'!$K$18:$AJ$1670*('W3'!$A$18:$A$1670=Q$5)*('W3'!$D$18:$D$1670=$B$42)*('W3'!$K$14:$AJ$14='Cover Page'!$D46))} -> 47861.352 | T46: {=SUMPRODUCT('W3'!$K$18:$AJ$1670*('W3'!$A$18:$A$1670=T$5)*('W3'!$D$18:$D$1670=$B$42)*('W3'!$K$14:$AJ$14='Cover Page'!$D46))} -> 36107.607 | W46: {=SUMPRODUCT('W3'!$K$18:$AJ$1670*('W3'!$A$18:$A$1670=W$5)*('W3'!$D$18:$D$1670=$B$42)*('W3'!$K$14:$AJ$14='Cover Page'!$D46))} -> 36722.094 | Z46: {=SUMPRODUCT('W3'!$K$18:$AJ$1670*('W3'!$A$18:$A$1670=Z$5)*('W3'!$D$18:$D$1670=$B$42)*('W3'!$K$14:$AJ$14='Cover Page'!$D46))} -> 29417.151 | AC46: {=SUMPRODUCT('W3'!$K$18:$AJ$1670*('W3'!$A$18:$A$1670=AC$5)*('W3'!$D$18:$D$1670=$B$42)*('W3'!$K$14:$AJ$14='Cover Page'!$D46))} -> 39296.33 | AF46: {=SUMPRODUCT('W3'!$K$18:$AJ$1670*('W3'!$A$18:$A$1670=AF$5)*('W3'!$D$18:$D$1670=$B$42)*('W3'!$K$14:$AJ$14='Cover Page'!$D46))} -> 55601.309 | AI46: {=SUMPRODUCT('W3'!$K$18:$AJ$1670*('W3'!$A$18:$A$1670=AI$5)*('W3'!$D$18:$D$1670=$B$42)*('W3'!$K$14:$AJ$14='Cover Page'!$D46))} -> 56215.796
D47: 4 | E47: =IF(Currency="USD","USD","triệu VND") -> triệu VND | H47: {=SUMPRODUCT('W3'!$K$18:$AJ$1670*('W3'!$A$18:$A$1670=H$5)*('W3'!$D$18:$D$1670=$B$42)*('W3'!$K$14:$AJ$14='Cover Page'!$D47))} -> 52064.439 | K47: {=SUMPRODUCT('W3'!$K$18:$AJ$1670*('W3'!$A$18:$A$1670=K$5)*('W3'!$D$18:$D$1670=$B$42)*('W3'!$K$14:$AJ$14='Cover Page'!$D47))} -> 52637.301 | N47: {=SUMPRODUCT('W3'!$K$18:$AJ$1670*('W3'!$A$18:$A$1670=N$5)*('W3'!$D$18:$D$1670=$B$42)*('W3'!$K$14:$AJ$14='Cover Page'!$D47))} -> 44120.139 | Q47: {=SUMPRODUCT('W3'!$K$18:$AJ$1670*('W3'!$A$18:$A$1670=Q$5)*('W3'!$D$18:$D$1670=$B$42)*('W3'!$K$14:$AJ$14='Cover Page'!$D47))} -> 44693.001 | T47: {=SUMPRODUCT('W3'!$K$18:$AJ$1670*('W3'!$A$18:$A$1670=T$5)*('W3'!$D$18:$D$1670=$B$42)*('W3'!$K$14:$AJ$14='Cover Page'!$D47))} -> 33527.74 | W47: {=SUMPRODUCT('W3'!$K$18:$AJ$1670*('W3'!$A$18:$A$1670=W$5)*('W3'!$D$18:$D$1670=$B$42)*('W3'!$K$14:$AJ$14='Cover Page'!$D47))} -> 34100.602 | Z47: {=SUMPRODUCT('W3'!$K$18:$AJ$1670*('W3'!$A$18:$A$1670=Z$5)*('W3'!$D$18:$D$1670=$B$42)*('W3'!$K$14:$AJ$14='Cover Page'!$D47))} -> 27165.737 | AC47: {=SUMPRODUCT('W3'!$K$18:$AJ$1670*('W3'!$A$18:$A$1670=AC$5)*('W3'!$D$18:$D$1670=$B$42)*('W3'!$K$14:$AJ$14='Cover Page'!$D47))} -> 36548.462 | AF47: {=SUMPRODUCT('W3'!$K$18:$AJ$1670*('W3'!$A$18:$A$1670=AF$5)*('W3'!$D$18:$D$1670=$B$42)*('W3'!$K$14:$AJ$14='Cover Page'!$D47))} -> 52064.439 | AI47: {=SUMPRODUCT('W3'!$K$18:$AJ$1670*('W3'!$A$18:$A$1670=AI$5)*('W3'!$D$18:$D$1670=$B$42)*('W3'!$K$14:$AJ$14='Cover Page'!$D47))} -> 52637.301
D48: 5 | E48: =IF(Currency="USD","USD","triệu VND") -> triệu VND | H48: {=SUMPRODUCT('W3'!$K$18:$AJ$1670*('W3'!$A$18:$A$1670=H$5)*('W3'!$D$18:$D$1670=$B$42)*('W3'!$K$14:$AJ$14='Cover Page'!$D48))} -> 48720.87 | K48: {=SUMPRODUCT('W3'!$K$18:$AJ$1670*('W3'!$A$18:$A$1670=K$5)*('W3'!$D$18:$D$1670=$B$42)*('W3'!$K$14:$AJ$14='Cover Page'!$D48))} -> 49254.927 | N48: {=SUMPRODUCT('W3'!$K$18:$AJ$1670*('W3'!$A$18:$A$1670=N$5)*('W3'!$D$18:$D$1670=$B$42)*('W3'!$K$14:$AJ$14='Cover Page'!$D48))} -> 41166.579 | Q48: {=SUMPRODUCT('W3'!$K$18:$AJ$1670*('W3'!$A$18:$A$1670=Q$5)*('W3'!$D$18:$D$1670=$B$42)*('W3'!$K$14:$AJ$14='Cover Page'!$D48))} -> 41700.636 | T48: {=SUMPRODUCT('W3'!$K$18:$AJ$1670*('W3'!$A$18:$A$1670=T$5)*('W3'!$D$18:$D$1670=$B$42)*('W3'!$K$14:$AJ$14='Cover Page'!$D48))} -> 31094.191 | W48: {=SUMPRODUCT('W3'!$K$18:$AJ$1670*('W3'!$A$18:$A$1670=W$5)*('W3'!$D$18:$D$1670=$B$42)*('W3'!$K$14:$AJ$14='Cover Page'!$D48))} -> 31628.248 | Z48: {=SUMPRODUCT('W3'!$K$18:$AJ$1670*('W3'!$A$18:$A$1670=Z$5)*('W3'!$D$18:$D$1670=$B$42)*('W3'!$K$14:$AJ$14='Cover Page'!$D48))} -> 25044.517 | AC48: {=SUMPRODUCT('W3'!$K$18:$AJ$1670*('W3'!$A$18:$A$1670=AC$5)*('W3'!$D$18:$D$1670=$B$42)*('W3'!$K$14:$AJ$14='Cover Page'!$D48))} -> 33955.935 | AF48: {=SUMPRODUCT('W3'!$K$18:$AJ$1670*('W3'!$A$18:$A$1670=AF$5)*('W3'!$D$18:$D$1670=$B$42)*('W3'!$K$14:$AJ$14='Cover Page'!$D48))} -> 48720.87 | AI48: {=SUMPRODUCT('W3'!$K$18:$AJ$1670*('W3'!$A$18:$A$1670=AI$5)*('W3'!$D$18:$D$1670=$B$42)*('W3'!$K$14:$AJ$14='Cover Page'!$D48))} -> 49254.927
...

Sheet W1
D1: Công ty CP Nhựa tái chế Duy Tân
D2: Đơn vị: Kế toán quản trị
D3: DỰ ÁN FLAKES TO PREFORM SUNTORY - PEPSICO
D4: TỔNG CHI PHÍ ĐẦU TƯ
D5: =Currency -> VND | N5: (không tăng chi phí xây dựng nhà xưởng) - Roundup | S5: (không tăng chi phí xây dựng nhà xưởng) | X5: (không tăng chi phí xây dựng nhà xưởng) | AC5: (không tăng chi phí xây dựng nhà xưởng) | AH5: (không tăng chi phí xây dựng nhà xưởng)
D6: =IF(D5="VND",1,EXR) -> 1 | I6: Option 1 | J6: BASE | N6: Option 2 | O6: =Opt2_CAPEX -> 0 | S6: Option 3 | T6: =Opt3_CAPEX -> 0 | X6: Option 4 | Y6: =Opt4_CAPEX -> 0 | AC6: Option 5 | AD6: =Opt5_CAPEX -> 0 | AH6: Option 6 | AI6: =Opt6_CAPEX -> 0 | AM6: Option 7 | AN6: =Opt7_CAPEX -> 0 | AR6: Option 8 | AS6: =Opt8_CAPEX -> 0 | AW6: Option 9 | AX6: =Opt9_CAPEX -> 0 | BB6: Option 10 | BC6: =Opt10_CAPEX -> 0
C7: STT | D7: HẠNG MỤC | E7: Số lượng | G7: Thời gian khấu hao | H7: Đơn giá | I7: Giá trị đầu tư | J7: Khấu hao | L7: Thời gian khấu hao | M7: Đơn giá | N7: Giá trị đầu tư | O7: Khấu hao | Q7: Thời gian khấu hao | R7: Đơn giá | S7: Giá trị đầu tư | T7: Khấu hao | V7: Thời gian khấu hao | W7: Đơn giá | X7: Giá trị đầu tư | Y7: Khấu hao | AA7: Thời gian khấu hao | AB7: Đơn giá | AC7: Giá trị đầu tư | AD7: Khấu hao | AF7: Thời gian khấu hao | AG7: Đơn giá | AH7: Giá trị đầu tư | AI7: Khấu hao | AK7: Thời gian khấu hao | AL7: Đơn giá | AM7: Giá trị đầu tư | AN7: Khấu hao | AP7: Thời gian khấu hao | AQ7: Đơn giá | AR7: Giá trị đầu tư | AS7: Khấu hao | AU7: Thời gian khấu hao | AV7: Đơn giá | AW7: Giá trị đầu tư | AX7: Khấu hao | AZ7: Thời gian khấu hao | BA7: Đơn giá | BB7: Giá trị đầu tư | BC7: Khấu hao | BE7: NHẬP KHẨU TỪ | BF7: Nguồn: | BG7: Ghi chú - Nếu dừng dự án thì Suntory mua lại | BI7: Option 1 | BJ7: =BI7 -> Option 1 | BK7: =BJ7 -> Option 1 | BL7: =BK7 -> Option 1 | BM7: =BL7 -> Option 1 | BN7: =BM7 -> Option 1 | BO7: =BN7 -> Option 1 | BP7: =BO7 -> Option 1 | BQ7: =BP7 -> Option 1 | ... CL7: =CK7 -> Option 1 | CN7: Option 2 | CO7: =CN7 -> Option 2 | CP7: =CO7 -> Option 2 | CQ7: =CP7 -> Option 2 | CR7: =CQ7 -> Option 2 | CS7: =CR7 -> Option 2 | CT7: =CS7 -> Option 2 | CU7: =CT7 -> Option 2 | CV7: =CU7 -> Option 2 | ... DQ7: =DP7 -> Option 2 | DS7: Option 3 | DT7: Option 3 | DU7: Option 3 | DV7: Option 3 | DW7: Option 3 | DX7: Option 3 | DY7: Option 3 | DZ7: Option 3 | EA7: Option 3 | EB7: Option 3 | EC7: Option 3 | ED7: Option 3 | EE7: Option 3 | EF7: Option 3 | EG7: Option 3 | EH7: Option 3 | EI7: Option 3 | EJ7: Option 3 | EK7: Option 3 | EL7: Option 3 | EM7: Option 3 | EN7: Option 3 | EO7: Option 3 | EP7: Option 3 | EQ7: Option 3 | ER7: Option 3 | ES7: Option 3 | ET7: Option 3 | EU7: Option 3 | EV7: Option 3 | EX7: Option 4 | EY7: Option 4 | EZ7: Option 4 | FA7: Option 4 | FB7: Option 4 | FC7: Option 4 | FD7: Option 4 | FE7: Option 4 | FF7: Option 4 | FG7: Option 4 | FH7: Option 4 | FI7: Option 4 | FJ7: Option 4 | FK7: Option 4 | FL7: Option 4 | FM7: Option 4 | FN7: Option 4 | FO7: Option 4 | FP7: Option 4 | FQ7: Option 4 | FR7: Option 4 | FS7: Option 4 | FT7: Option 4 | FU7: Option 4 | FV7: Option 4 | FW7: Option 4 | FX7: Option 4 | FY7: Option 4 | FZ7: Option 4 | GA7: Option 4 | GC7: Option 5 | GD7: Option 5 | GE7: Option 5 | GF7: Option 5 | GG7: Option 5 | GH7: Option 5 | GI7: Option 5 | GJ7: Option 5 | GK7: Option 5 | GL7: Option 5 | GM7: Option 5 | GN7: Option 5 | GO7: Option 5 | GP7: Option 5 | GQ7: Option 5 | GR7: Option 5 | GS7: Option 5 | GT7: Option 5 | GU7: Option 5 | GV7: Option 5 | GW7: Option 5 | GX7: Option 5 | GY7: Option 5 | GZ7: Option 5 | HA7: Option 5 | HB7: Option 5 | HC7: Option 5 | HD7: Option 5 | HE7: Option 5 | HF7: Option 5 | HH7: Option 6 | HI7: Option 6 | HJ7: Option 6 | HK7: Option 6 | HL7: Option 6 | HM7: Option 6 | HN7: Option 6 | HO7: Option 6 | HP7: Option 6 | HQ7: Option 6 | HR7: Option 6 | HS7: Option 6 | HT7: Option 6 | HU7: Option 6 | HV7: Option 6 | HW7: Option 6 | HX7: Option 6 | HY7: Option 6 | HZ7: Option 6 | IA7: Option 6 | IB7: Option 6 | IC7: Option 6 | ID7: Option 6 | IE7: Option 6 | IF7: Option 6 | IG7: Option 6 | IH7: Option 6 | II7: Option 6 | IJ7: Option 6 | IK7: Option 6 | IM7: Option 7 | IN7: Option 7 | IO7: Option 7 | IP7: Option 7 | IQ7: Option 7 | IR7: Option 7 | IS7: Option 7 | IT7: Option 7 | IU7: Option 7 | IV7: Option 7 | IW7: Option 7 | IX7: Option 7 | IY7: Option 7 | IZ7: Option 7 | JA7: Option 7 | JB7: Option 7 | JC7: Option 7 | JD7: Option 7 | JE7: Option 7 | JF7: Option 7 | JG7: Option 7 | JH7: Option 7 | JI7: Option 7 | JJ7: Option 7 | JK7: Option 7 | JL7: Option 7 | JM7: Option 7 | JN7: Option 7 | JO7: Option 7 | JP7: Option 7 | JR7: Option 8 | JS7: Option 8 | JT7: Option 8 | JU7: Option 8 | JV7: Option 8 | JW7: Option 8 | JX7: Option 8 | JY7: Option 8 | JZ7: Option 8 | KA7: Option 8 | KB7: Option 8 | KC7: Option 8 | KD7: Option 8 | KE7: Option 8 | KF7: Option 8 | KG7: Option 8 | KH7: Option 8 | KI7: Option 8 | KJ7: Option 8 | KK7: Option 8 | KL7: Option 8 | KM7: Option 8 | KN7: Option 8 | KO7: Option 8 | KP7: Option 8 | KQ7: Option 8 | KR7: Option 8 | KS7: Option 8 | KT7: Option 8 | KU7: Option 8 | KW7: Option 9 | KX7: Option 9 | KY7: Option 9 | KZ7: Option 9 | LA7: Option 9 | LB7: Option 9 | LC7: Option 9 | LD7: Option 9 | LE7: Option 9 | LF7: Option 9 | LG7: Option 9 | LH7: Option 9 | LI7: Option 9 | LJ7: Option 9 | LK7: Option 9 | LL7: Option 9 | LM7: Option 9 | LN7: Option 9 | LO7: Option 9 | LP7: Option 9 | LQ7: Option 9 | LR7: Option 9 | LS7: Option 9 | LT7: Option 9 | LU7: Option 9 | LV7: Option 9 | LW7: Option 9 | LX7: Option 9 | LY7: Option 9 | LZ7: Option 9 | MB7: Option 10 | MC7: Option 10 | MD7: Option 10 | ME7: Option 10 | MF7: Option 10 | MG7: Option 10 | MH7: Option 10 | MI7: Option 10 | MJ7: Option 10 | MK7: Option 10 | ML7: Option 10 | MM7: Option 10 | MN7: Option 10 | MO7: Option 10 | MP7: Option 10 | MQ7: Option 10 | MR7: Option 10 | MS7: Option 10 | MT7: Option 10 | MU7: Option 10 | MV7: Option 10 | MW7: Option 10 | MX7: Option 10 | MY7: Option 10 | MZ7: Option 10 | NA7: Option 10 | NB7: Option 10 | NC7: Option 10 | ND7: Option 10 | NE7: Option 10
