Workbook
Name \T: #REF!
Name \T: #REF!
Name __dao1: #REF!
Name __dao1: #REF!
Name __dao2: #REF!
Name __dao2: #REF!
Name __dap2: #REF!
Name __day1: #REF!
Name __day2: #REF!
Name __dbu1: #REF!
Name __dbu2: #REF!
Name __doi3: #REF!
Name __E99999: #REF!
Name __Jan02: #REF!
Name __lap1: #REF!
Name __lap2: #REF!
Name __vc1: #REF!
Name __vc2: #REF!
Name __vc3: #REF!
Name _01_01_99: #REF!
Name _01_02_99: #REF!
Name _01_03_99: #REF!
Name _01_04_99: #REF!
Name _01_05_99: #REF!
Name _01_06_99: #REF!
Name _01_07_99: #REF!
Name _01_08_1999: #REF!
Name _1CAP002: #REF!
Name _2STREO7: #REF!
Name _4GOIC01: #REF!
Name _4OSLCTT: #REF!
Name _6BNTTTH: #REF!
Name _6DCTTBO: #REF!
Name _6DD24TT: #REF!
Name _6FCOTBU: #REF!
Name _6LATUBU: #REF!
Name _6SDTT24: #REF!
Name _6TBUDTT: #REF!
Name _6TDDDTT: #REF!
Name _6TLTTTH: #REF!
Name _6TUBUTT: #REF!
Name _6UCLVIS: #REF!
Name _7DNCABC: #REF!
Name _7HDCTBU: #REF!
Name _7PKTUBU: #REF!
Name _7TBHT20: #REF!
Name _7TBHT30: #REF!
Name _7TDCABC: #REF!
Name _dao1: #REF!
Name _dao2: #REF!
Name _dap2: #REF!
Name _day1: #REF!
Name _day2: #REF!
Name _dbu1: #REF!
Name _dbu2: #REF!
Name _doi3: #REF!
Name _E99999: #REF!
Name _Jan02: #REF!
Name _lap1: #REF!
Name _lap2: #REF!

Sheet Điểm HV
B1: ĐIỂM HÒA VỐN
B3: rPET | P3: 2024
C4: 1 | D4: 2 | E4: 3 | F4: 4 | G4: 5 | H4: 6 | I4: 7 | J4: 8 | K4: 9 | L4: 10 | M4: 11 | N4: 12 | P4: 1 | Q4: =+P4+1 -> 2 | R4: =+Q4+1 -> 3 | S4: =+R4+1 -> 4 | T4: =+S4+1 -> 5 | U4: =+T4+1 -> 6 | V4: =+U4+1 -> 7 | W4: =+V4+1 -> 8 | X4: =+W4+1 -> 9 | ... AA4: =+Z4+1 -> 12
B5: Từ chai nâng IV 8h | C5: 1255.3064 | D5: 1248.8001 | V5: 1203.2323 | W5: 1151.982 | X5: 1196.6937 | Y5: 1204.34 | Z5: 1235.0905 | AA5: 1246.7519
B6: Từ chai nâng IV 10h | C6: 1307.0033 | D6: 1299.7163 | V6: 1239.4846 | W6: 1189.7421 | X6: 1233.5112 | Y6: 1247.5871 | Z6: 1279.9365 | AA6: 1296.9389
B7: Từ vảy nâng IV 8h | C7: 1149.0656 | D7: 1142.8708 | V7: 1162.0307 | W7: 1122.3796 | X7: 1136.2992 | Y7: 1142.5355 | Z7: 1156.2792 | AA7: 1156.3142
B8: Từ vảy nâng IV 10h | C8: 1200.7626 | D8: 1193.787 | V8: 1198.283 | W8: 1160.1396 | X8: 1173.1168 | Y8: 1185.7826 | Z8: 1201.1252 | AA8: 1206.5013
B9: Hỗn hợp nâng IV 8h | C9: 1180.9378 | D9: 1185.2425 | V9: 1174.3911 | W9: 1131.2603 | X9: 1154.4175 | Y9: 1161.0769 | Z9: 1179.9226 | AA9: 1183.4455 | AB9: 1300 | AC9: =+AB9-AA9 -> 116.55447
B10: Hỗn hợp nâng IV 10h | C10: 1232.6348 | D10: 1236.1587 | V10: 1210.6435 | W10: 1169.0204 | X10: 1191.2351 | Y10: 1204.3239 | Z10: 1224.7686 | AA10: 1233.6326 | AB10: =+AA9*105% -> 1242.6178
B11: ISS01L | C11: 897.41261 | D11: 824.96687 | V11: 841 | W11: 841.18977 | X11: 855.18924 | Y11: 891.81591 | Z11: 917.03828 | AA11: 895.03115 | AB11: =+AB9-AB10 -> 57.382195 | AC11: =+AB11/AB10 -> 0.046178475
B15: rHDPE - PP | P15: 2024
B16: Mã | C16: 1 | D16: 2 | E16: 3 | F16: 4 | G16: 5 | H16: 6 | I16: 7 | J16: 8 | K16: 9 | L16: 10 | M16: 11 | N16: 12 | P16: 1 | Q16: 2 | R16: 3 | S16: 4 | T16: 5 | U16: 6 | V16: 7 | W16: 8 | X16: 9 | Y16: 10 | Z16: 11 | AA16: 12
B17: MBF01 | C17: 1224.4123 | D17: 1224.8944 | P17: 1323 | Q17: 1323 | R17: 1306 | S17: 1291 | T17: 1282 | U17: 1285 | V17: 1219 | W17: 1250.8124 | X17: 1250.9881 | Y17: 1260.3186 | Z17: 1260.9722 | AA17: 1214.0816
B18: HDPE MÀU | C18: 1124.6177 | D18: 1124.5211 | V18: 1099 | W18: 1129.5585 | X18: 1149.338 | Y18: 1157.5594 | Z18: 1158.0146 | AA18: 1113.6924
B19: HDPE Trắng sữa | C19: 1205.7379 | D19: 1205.486 | V19: 1175 | W19: 1207.612 | X19: 1236.1786 | Y19: 1240.4466 | Z19: 1241.502 | AA19: 1196.3921
B20: HDPE ép | C20: 892.96567 | D20: 888.18379 | V20: 867 | W20: 895.79014 | X20: 917.19481 | Y20: 929.8394 | Z20: 937.65255 | AA20: 903.25545
B21: HDB03N03 | C21: 992.71675 | D21: 984.26718 | V21: 981.27765 | W21: 1003.4092 | X21: 993.90865 | Y21: 1007.0439 | Z21: 1009.9734 | AA21: 973.71173
A22: (80% PS hạt HD thổi lẫn màu/kim loại) | B22: HDB04B01 | C22: 846.80438 | D22: 829.95119 | V22: 841 | W22: 849.89875 | X22: 853.99116 | Y22: 866.17551 | Z22: 871.97791 | AA22: 831.8526
B23: HDI3Gy02 | C23: 621.54474 | D23: 604.90389 | W23: 619.75066 | X23: 629.83101 | Y23: 641.67872 | Z23: 645.14598 | AA23: 604.75348
B24: Vảy HDPE ép | C24: 673.72307 | D24: 686.58248 | V24: 656 | W24: 661.16027 | X24: 664.29737 | Y24: 665.95976 | Z24: 662.45159 | AA24: 666.20088
B25: Hạt PP bình quân | C25: 842.58758 | D25: 835.02956 | V25: 794 | W25: 836.80122 | X25: 856.1642 | Y25: 855.93287 | Z25: 855.93287 | AA25: 827.77378
B26: PP20B01 | C26: 523.94625 | D26: 532.30046 | W26: 539.72607 | X26: 553.59194 | Y26: 554.84579 | Z26: 554.84579 | AA26: 525.70627
B27: Vảy PP | C27: 790.71343 | D27: 780.14595 | V27: 738 | W27: 780.1665 | X27: 790.84737 | Y27: 794.61882 | Z27: 794.61882 | AA27: 772.61325
B28: Hạt PP trắng sữa | C28: 927.39823 | D28: 947.4414 | V28: 888 | W28: 934.75986 | X28: 951.07154 | Y28: 949.91757 | Z28: 949.91757 | AA28: 920.09051
B31: Xơ sợi
B32: Mã | C32: 1 | D32: 2 | E32: 3 | F32: 4 | G32: 5 | H32: 6 | I32: 7 | J32: 8 | K32: 9 | L32: 10 | M32: 11 | N32: 12 | P32: 1 | Q32: =+P32+1 -> 2 | R32: =+Q32+1 -> 3 | S32: =+R32+1 -> 4 | T32: =+S32+1 -> 5 | U32: =+T32+1 -> 6 | V32: =+U32+1 -> 7 | W32: =+V32+1 -> 8 | X32: =+W32+1 -> 9 | ... AA32: =+Z32+1 -> 12 | AB32: Ghi chú
B33: WSS03SD | C33: 762.13833 | D33: 788.55356 | V33: 773.26795 | W33: 822.8214 | X33: 823.20219 | Y33: 830.28427 | Z33: 830.28427 | AA33: 773.83832
B34: WSS04SD | C34: 668.04613 | D34: 694.46136 | V34: 679.34955 | W34: 728.903 | X34: 729.28379 | Y34: 736.19207 | Z34: 736.19207 | AA34: 679.74612
B35: WSS04SB | C35: 602.40629 | D35: 628.82152 | V35: 613.70971 | W35: 663.26316 | X35: 663.64395 | Y35: 670.55223 | Z35: 670.55223 | AA35: 614.10628
B36: WSS05SB (100% B6) | C36: 966.04043 | D36: 982.68318 | V36: 960.02539 | W36: 1005.1878 | X36: 1008.4543 | Y36: 1011.0145 | Z36: 1011.0145 | AA36: 986.40401
B37: WSS05SB (70%B6+30%bụi) | C37: 792.0426 | D37: 817.12585 | V37: 790.60544 | W37: 840.46209 | X37: 842.58346 | Y37: 849.94254 | Z37: 849.94254 | AA37: 809.13443
B38: WSS05SB (90%B8+10%B6) | C38: 727.5629 | D38: 748.88114 | V38: 731.72318 | W38: 775.18849 | X38: 779.7997 | Y38: 789.91236 | Z38: 789.91236 | AA38: 746.77337
B39: WSS05SB-2 (90%B8+10%B7) | C39: 690.6964 | D39: 704.08426 | V39: 696.07927 | W39: 738.78127 | X39: 744.16977 | Y39: 756.06407 | Z39: 756.06407 | AA39: 710.33794 | AB39: Từ T8 hết nguyên liệu B8
B40: WSS05SB-2 (82%B8+18%B7) | C40: 682.4012 | D40: 689.02917 | V40: 687.85767 | W40: 730.09988 | X40: 735.99068 | Y40: 748.63895 | Z40: 748.63895 | AA40: 702.49009 | AB40: Từ T8 hết nguyên liệu B8
B41: WSS05SB-2 (82%B6+18%B7) | C41: 899.68072 | D41: 902.04881 | W41: 940 | X41: 944.32043 | Y41: 950.08755 | Z41: 950.08755 | AA41: 920.82022 | AB41: Từ T8 dùng nguyên liệu B6
B42: WSS05SB-3 (90%B8+10%B5) | C42: 710.38095 | D42: 734.68599 | V42: 719.17936 | W42: 761.92334 | X42: 761.38778 | Y42: 772.74131 | Z42: 772.74131 | AA42: 728.50157 | AB42: Từ T8 hết nguyên liệu B8
B43: WSS05SB-3 (90%B6+10%B5) | C43: 948.85848 | D43: 968.48804 | W43: 991.92267 | X43: 990.04238 | Y43: 993.84343 | Z43: 993.84343 | AA43: 968.13221 | AB43: Từ T8 dùng nguyên liệu B6
B44: WSS05SB-3 (100% Tomra) | C44: 499.25882 | D44: 539.76402 | V44: 501.3922 | W44: 562.20204 | X44: 562.67084 | Y44: 580.17221 | Z44: 580.17221 | AA44: 510.46895 | AB44: Từ T8 hết nguyên liệu Tomra
B45: WSS006SP-1 (vảy zigzag sau lựa) | C45: 386.04765 | D45: 430.82542 | V45: 395.2922 | W45: 456.10204 | X45: 455.55149 | Y45: 474.10803 | Z45: 474.10803 | AA45: 395.50541 | AB45: Từ T8 hết nguyên liệu Zigzag
B46: WSS006SP-1 (vảy PET tuyển nổi 2) | C46: 499.25882 | D46: 539.76402 | W46: 562.20204 | X46: 562.67084 | Y46: 580.17221 | Z46: 580.17221 | AA46: 510.46895 | AB46: Từ T8 dùng nguyên liệu vảy PET tuyển nổi 2
...

Sheet TH
C1: 2
C4: GIÁ BÁN HẠT rPET
B5: STT | C5: Mã sản phẩm | D5: Sản phẩm | E5: Mức IV | F5: Màu | G5: Giá bán T01 | H5: Giá bán T2 | I5: Chênh lệch T2 sv T1 | K5: Điểm hòa vốn T5 | L5: Điểm hòa vốn T2 | M5: Lợi nhuận | O5: Giá chính phẩm T01 | P5: Giá chính phẩm T2 | Q5: Chênh lệch Giá T2 vs chính phẩm
G6: USD/tấn | H6: USD/tấn | I6: USD/tấn | J6: % | K6: USD/tấn | L6: USD/tấn | M6: USD/tấn | N6: % | O6: USD/tấn | P6: USD/tấn | Q6: USD/tấn | R6: %
A7: Hỗn hợp nâng IV 8h | B7: 1 | C7: 110000354 | D7: Hạt rPET WSS01G | E7: 0.78 | G7: 1230 | H7: ='2. rPET- nội bộ '!O13 -> 1230 | I7: =H7-G7 -> 0 | J7: =I7/G7 -> 0 | K7: 1260 | L7: =+VLOOKUP(A7,'Điểm HV'!B:AA,1+TH!$C$1,0) -> 1185.2425 | M7: =H7-L7 -> 44.757468 | N7: =M7/H7 -> 0.036388186 | O7: 820 | P7: ='1. rPET'!$R$2 -> 850 | Q7: =H7-P7 -> 380 | R7: =Q7/P7 -> 0.44705882
A8: ISS01L | B8: =+B7+1 -> 2 | C8: 110000376 | D8: Hạt nhựa rPET iSS01L | E8: 0.80 | G8: 1170 | H8: ='2. rPET- nội bộ '!O20 -> 1170 | I8: =H8-G8 -> 0 | J8: =I8/G8 -> 0 | K8: 1260 | L8: =+VLOOKUP(A8,'Điểm HV'!B:AA,1+TH!$C$1,0) -> 824.96687 | M8: =H8-L8 -> 345.03313 | N8: =M8/H8 -> 0.29490011 | O8: 820 | P8: ='1. rPET'!$R$2 -> 850 | Q8: =H8-P8 -> 320 | R8: =Q8/P8 -> 0.37647059
A9: WSS03SD | B9: =+B8+1 -> 3 | C9: 110000381 | D9: Hạt nhựa rPET WSS03SD | E9: 0.70 | G9: 1100 | H9: ='2. rPET- nội bộ '!O21 -> 1100 | I9: =H9-G9 -> 0 | J9: =I9/G9 -> 0 | K9: 729 | L9: =+VLOOKUP(A9,'Điểm HV'!B:AA,1+TH!$C$1,0) -> 788.55356 | M9: =H9-L9 -> 311.44644 | N9: =M9/H9 -> 0.28313313 | O9: 820 | P9: ='1. rPET'!$R$2 -> 850 | Q9: =H9-P9 -> 250 | R9: =Q9/P9 -> 0.29411765 | T9: S13: GIÁ rPET XƠ SỢI SEMIDULE WSS04SD
A10: WSS04SD | B10: =+B9+1 -> 4 | C10: 110000381 | D10: Hạt nhựa rPET WSS04SD | E10: 0.63 | G10: 1100 | H10: ='2. rPET- nội bộ '!O22 -> 1100 | I10: =H10-G10 -> 0 | J10: =I10/G10 -> 0 | K10: 729 | L10: =+VLOOKUP(A10,'Điểm HV'!B:AA,1+TH!$C$1,0) -> 694.46136 | M10: =H10-L10 -> 405.53864 | N10: =M10/H10 -> 0.36867149 | O10: 820 | P10: ='1. rPET'!$R$2 -> 850 | Q10: =H10-P10 -> 250 | R10: =Q10/P10 -> 0.29411765
A11: WSS04SB | B11: =+B10+1 -> 5 | C11: 110000382 | D11: Hạt nhựa rPET WSS04SB | E11: 0.63 | G11: 1100 | H11: ='2. rPET- nội bộ '!O23 -> 1100 | I11: =H11-G11 -> 0 | J11: =I11/G11 -> 0 | K11: 729 | L11: =+VLOOKUP(A11,'Điểm HV'!B:AA,1+TH!$C$1,0) -> 628.82152 | M11: =H11-L11 -> 471.17848 | N11: =M11/H11 -> 0.42834407 | O11: 820 | P11: ='1. rPET'!$R$2 -> 850 | Q11: =H11-P11 -> 250 | R11: =Q11/P11 -> 0.29411765
A12: WSS05SB (100% B6) | B12: =+B11+1 -> 6 | C12: 110000436 | D12: Hạt nhựa rPET WSS05SB (xơ sợi) | E12: 0.55 | G12: 950 | H12: ='8. Hạt phó sản'!N12 -> 950 | I12: =H12-G12 -> 0 | J12: =I12/G12 -> 0 | L12: =+VLOOKUP(A12,'Điểm HV'!B:AA,1+TH!$C$1,0) -> 982.68318 | M12: =H12-L12 -> -32.683182 | N12: =M12/H12 -> -0.03440335 | O12: 820 | P12: ='1. rPET'!$R$2 -> 850 | Q12: =H12-P12 -> 100 | R12: =Q12/P12 -> 0.11764706 | T12: WSS05SB_90% B8.A2 + 10% B7.A1
T13: WSS05SB_90% B8.A2 + 10% B6.A1
T14: 70%B6.1/B6.2 + 30%bụi tank C,D | U14: 2 mã này mới trình giá, giá lấy theo giá phó sản | V14: 778
T15: 100%B6.1/B6.2
C16: GIÁ BÁN HẠT rHDPE
B17: STT | C17: Mã sản phẩm | D17: Sản phẩm | E17: Mức IV | F17: Màu | G17: =G5 -> Giá bán T01 | H17: =H5 -> Giá bán T2 | I17: =I5 -> Chênh lệch T2 sv T1 | K17: Điểm hòa vốn T5 | L17: =L5 -> Điểm hòa vốn T2 | M17: =M5 -> Lợi nhuận | O17: =O5 -> Giá chính phẩm T01 | P17: =P5 -> Giá chính phẩm T2 | Q17: =Q5 -> Chênh lệch Giá T2 vs chính phẩm
G18: USD/tấn | H18: USD/tấn | I18: USD/tấn | J18: % | K18: USD/tấn | L18: USD/tấn | M18: USD/tấn | N18: % | O18: USD/tấn | P18: USD/tấn | Q18: USD/tấn | R18: %
B19: A | C19: NHÓM KHÁCH HÀNG PHÁT TRIỂN BỀN VỮNG
B20: I. rHDPE THỔI (PERSONAL CARE)
B21: 1 | C21: 110000429 | D21: Hạt Nhựa rHDPE A03N01 | F21: Không màu | G21: ='[2]4. rHDPE '!I11 -> 1400 | H21: ='4. rHDPE '!M11 -> 1400 | I21: =H21-G21 -> 0 | J21: =I21/G21 -> 0 | K21: 1285 | L21: =+L24 -> 1224.8944 | M21: =H21-L21 -> 175.10564 | N21: =M21/H21 -> 0.12507545 | O21: 940 | P21: ='4. rHDPE '!$R$2 -> 940 | Q21: =H21-P21 -> 460 | R21: =Q21/P21 -> 0.4893617
A22: HDPE Trắng sữa | B22: =B21+1 -> 2 | C22: 110000337 | D22: Hạt nhựa rHD Thổi màu | F22: Trắng, lá, vàng | G22: ='[2]4. rHDPE '!I12 -> 1350 | H22: ='4. rHDPE '!M12 -> 1350 | I22: =H22-G22 -> 0 | J22: =I22/G22 -> 0 | L22: =+VLOOKUP(A22,'Điểm HV'!B:AA,1+TH!$C$1,0) -> 1205.486 | M22: =H22-L22 -> 144.51396 | N22: =M22/H22 -> 0.10704738 | O22: 940 | P22: ='4. rHDPE '!$R$2 -> 940 | Q22: =H22-P22 -> 410 | R22: =Q22/P22 -> 0.43617021 | T22: mastter base
B23: II. rHDPE THỔI (HOME CARE)
A24: MBF01 | B24: 1 | C24: 110000432 | D24: Hạt nhựa rHDPE B03N01 | F24: Không màu, Trắng, lá, vàng | G24: ='[2]4. rHDPE '!I14 -> 1350 | H24: ='4. rHDPE '!M14 -> 1300 | I24: =H24-G24 -> -50 | J24: =I24/G24 -> -0.037037037 | L24: =+VLOOKUP(A24,'Điểm HV'!B:AA,1+TH!$C$1,0) -> 1224.8944 | M24: =H24-L24 -> 75.105637 | N24: =M24/H24 -> 0.057773567 | O24: 940 | P24: ='4. rHDPE '!$R$2 -> 940 | Q24: =H24-P24 -> 360 | R24: =Q24/P24 -> 0.38297872
B25: III. rHDPE ÉP
A26: HDPE ép | B26: 1 | C26: 110000373 | D26: Hạt rHDI4DL01 | F26: Màu dương đậm | G26: 1250 | H26: ='4. rHDPE '!M16 -> 1250 | I26: =H26-G26 -> 0 | J26: =I26/G26 -> 0 | L26: =+VLOOKUP(A26,'Điểm HV'!B:AA,1+TH!$C$1,0) -> 888.18379 | M26: =H26-L26 -> 361.81621 | N26: =M26/H26 -> 0.28945297 | O26: 940 | P26: ='4. rHDPE '!$R$16 -> 940 | Q26: =H26-P26 -> 310 | R26: =Q26/P26 -> 0.32978723 | T26: S17
A27: HDPE ép | B27: 2 | C27: 110000365 | D27: Hạt rHD ép | F27: Màu trắng, đỏ | G27: 1310 | H27: ='4. rHDPE '!M17 -> 1310 | I27: =H27-G27 -> 0 | J27: =I27/G27 -> 0 | L27: =+VLOOKUP(A27,'Điểm HV'!B:AA,1+TH!$C$1,0) -> 888.18379 | M27: =H27-L27 -> 421.81621 | N27: =M27/H27 -> 0.32199711 | O27: 940 | P27: ='4. rHDPE '!$R$16 -> 940 | Q27: =H27-P27 -> 370 | R27: =Q27/P27 -> 0.39361702
A28: HDPE ép | B28: 3 | C28: 110000361 | D28: Hạt rHDI3R01 | F28: Màu đỏ | G28: 1310 | H28: ='4. rHDPE '!M17 -> 1310 | I28: =H28-G28 -> 0 | J28: =I28/G28 -> 0 | L28: =+VLOOKUP(A28,'Điểm HV'!B:AA,1+TH!$C$1,0) -> 888.18379 | M28: =H28-L28 -> 421.81621 | N28: =M28/H28 -> 0.32199711 | O28: 940 | P28: ='4. rHDPE '!$R$16 -> 940 | Q28: =H28-P28 -> 370 | R28: =Q28/P28 -> 0.39361702
B29: B | C29: NHÓM KHÁCH HÀNG NỘI ĐỊA
A30: HDPE ép | B30: 1 | C30: 110000373 | D30: Hạt rHD ép màu | F30: Màu dương đậm, trắng, đỏ | G30: 870 | H30: ='4. rHDPE '!M20 -> 800 | I30: =H30-G30 -> -70 | J30: =I30/G30 -> -0.08045977 | L30: =+VLOOKUP(A30,'Điểm HV'!B:AA,1+TH!$C$1,0) -> 888.18379 | M30: =H30-L30 -> -88.183786 | N30: =M30/H30 -> -0.11022973 | O30: 940 | P30: ='4. rHDPE '!$R$16 -> 940 | Q30: =H30-P30 -> -140 | R30: =Q30/P30 -> -0.14893617 | T30: S17
C32: GIÁ BÁN VẢY HDPE ÉP
B33: STT | C33: Mã sản phẩm | D33: Sản phẩm | E33: Mức IV | F33: Màu | G33: =G5 -> Giá bán T01 | H33: =H5 -> Giá bán T2 | I33: =I5 -> Chênh lệch T2 sv T1 | K33: Điểm hòa vốn T5 | L33: =L5 -> Điểm hòa vốn T2 | M33: =M5 -> Lợi nhuận | O33: =O5 -> Giá chính phẩm T01 | P33: =P5 -> Giá chính phẩm T2 | Q33: =Q5 -> Chênh lệch Giá T2 vs chính phẩm
G34: USD/tấn | H34: USD/tấn | I34: USD/tấn | J34: % | K34: USD/tấn | L34: USD/tấn | M34: USD/tấn | N34: % | O34: USD/tấn | P34: USD/tấn | Q34: USD/tấn | R34: %
A35: Vảy HDPE ép | B35: 1 | C35: 110000407 | D35: Vảy HD màu | F35: Đỏ, Trắng, Vàng, Lá, Dương | G35: 825 | H35: ='5.Vảy HDPE- Ép'!M10 -> 750 | I35: =H35-G35 -> -75 | J35: =I35/G35 -> -0.090909091 | L35: =+VLOOKUP(A35,'Điểm HV'!B:AA,1+TH!$C$1,0) -> 686.58248 | M35: =H35-L35 -> 63.417524 | N35: =M35/H35 -> 0.084556699 | O35: 940 | P35: ='5.Vảy HDPE- Ép'!$R$2 -> 940 | Q35: =H35-P35 -> -190 | R35: =Q35/P35 -> -0.20212766 | T35: s18
C38: GIÁ BÁN HẠT rPP
B39: STT | C39: Mã sản phẩm | D39: Sản phẩm | E39: Mức IV | F39: Màu | G39: =G5 -> Giá bán T01 | H39: =H5 -> Giá bán T2 | I39: =I5 -> Chênh lệch T2 sv T1 | K39: Điểm hòa vốn T5 | L39: =L5 -> Điểm hòa vốn T2 | M39: =M5 -> Lợi nhuận | O39: =O5 -> Giá chính phẩm T01 | P39: =P5 -> Giá chính phẩm T2 | Q39: =Q5 -> Chênh lệch Giá T2 vs chính phẩm
G40: USD/tấn | H40: USD/tấn | I40: USD/tấn | J40: % | K40: USD/tấn | L40: USD/tấn | M40: USD/tấn | N40: % | O40: USD/tấn | P40: USD/tấn | Q40: USD/tấn | R40: %
B41: A | C41: NHÓM KHÁCH HÀNG PHÁT TRIỂN BỀN VỮNG | T41: s18
A42: Hạt PP bình quân | B42: 1 | C42: 110000367 | D42: Hạt nhựa rPP màu | F42: Đỏ, dương, trắng, lá, đen | G42: 1140 | H42: ='6. rPP '!M10 -> 1140 | I42: =H42-G42 -> 0 | J42: =I42/G42 -> 0 | L42: =+VLOOKUP(A42,'Điểm HV'!B:AA,1+TH!$C$1,0) -> 835.02956 | M42: =H42-L42 -> 304.97044 | N42: =M42/H42 -> 0.26751793 | O42: 960 | P42: ='6. rPP '!$R$2 -> 980 | Q42: =H42-P42 -> 160 | R42: =Q42/P42 -> 0.16326531
B43: B | C43: NHÓM KHÁCH HÀNG NỘI ĐỊA
A44: Hạt PP bình quân | B44: 1 | C44: 110000367 | D44: Hạt nhựa rPP màu | F44: Đỏ, dương, trắng, lá, đen | G44: 900 | H44: ='6. rPP '!M12 -> 820 | I44: =H44-G44 -> -80 | J44: =I44/G44 -> -0.088888889 | L44: =+VLOOKUP(A44,'Điểm HV'!B:AA,1+TH!$C$1,0) -> 835.02956 | M44: =H44-L44 -> -15.02956 | N44: =M44/H44 -> -0.018328732 | O44: 960 | P44: ='6. rPP '!$R$2 -> 980 | Q44: =H44-P44 -> -160 | R44: =Q44/P44 -> -0.16326531
C46: GIÁ BÁN VẢY PP
...

Sheet Ghi chú
B2: Ghi chú:
G3: Tỷ giá: | H3: 25000
B4: Báo giá bán T2.2025:
A5: STT | B5: loại hàng | C5: Nội dung | D5: Ảnh hưởng | F5: SL bán | G5: Giá bán theo NS | H5: Giá bán T2.25 | I5: DTKH | J5: DT ước tính | K5: CL (USD) | L5: CL (trđ) | N5: Giá bán | O5: Giá chính phẩm | P5: % | R5: Giá bán | S5: Giá chính phẩm | T5: %
A6: 1 | B6: rPET | C6: Đề xuất không thay đổi giá (WSS01G: 1230 USD ) Ghi chú: - Giá ICIS giảm 50 USD (1.400 USD -> 1.350 USD) - Giá bán T12/24 đã giảm 50 USD/tấn, T1/25 đã giảm 45 USD/tấn - Giá chính phẩm tăng 30 USD (820 -> 850 USD) (T12/24: 860 USD/tấn, T1/25: 820 USD/tấn, T2: 850 USD/ tấn) - % giá bán so với giá chính phẩm: 45% | D6: - Sản lượng bán dự kiến: 1.359 tấn - Giá bán theo kế hoạch: 1.283 USD - Doanh thu giảm so với kế hoạch: 72.040 USD ~ 1,8 tỷ | F6: 1359 | G6: 1283 | H6: 1230 | I6: =F6*G6 -> 1743597 | J6: =F6*H6 -> 1671570 | K6: =J6-I6 -> -72027 | L6: =K6*$H$3/10^6 -> -1800.675 | N6: 1230 | O6: 850 | P6: =(N6-O6)/O6 -> 0.44705882
A7: 2 | B7: Hạt rHDPE | C7: - Đề xuất rHDPE thổi không thay đổi (MBF01: 1350 USD) - Đề xuất rHDPE ép nội địa không thay đổi (870 USD) (quy định thấp hơn giá chính phẩm 5%) Giá chính phẩm: + rHD thổi không thay đổi (940 USD) - % giá bán so với giá chính phẩm: 44% + rHD ép không thay đổi (940 USD) - % giá bán so với giá chính phẩm: - 7% Không mua thông tin giá ICIS rHDPE | F7: 326 | G7: 1379.2025 | H7: 1350 | I7: =F7*G7 -> 449620 | J7: =F7*H7 -> 440100 | K7: =J7-I7 -> -9520 | L7: =K7*$H$3/10^6 -> -238 | N7: 1350 | O7: 940 | P7: =(N7-O7)/O7 -> 0.43617021 | R7: 870 | S7: 940 | T7: =(R7-S7)/S7 -> -0.074468085
F8: 10 | G8: 850 | H8: 870 | I8: =F8*G8 -> 8500 | J8: =F8*H8 -> 8700 | K8: =J8-I8 -> 200 | L8: =K8*$H$3/10^6 -> 5
A9: 3 | B9: Vảy rHDPE | C9: - Đề xuất Vảy rHDPE ép nội địa không thay đổi (825 USD) - Giá chính phẩm không thay đổi (940 USD) Không mua thông tin giá ICIS rHDPE | F9: 5 | G9: 820 | H9: 825 | I9: =F9*G9 -> 4100 | J9: =F9*H9 -> 4125 | K9: =J9-I9 -> 25 | L9: =K9*$H$3/10^6 -> 0.625 | N9: 825 | O9: 940 | P9: =(N9-O9)/O9 -> -0.12234043
A10: 4 | B10: Hạt rPP | C10: - Đề xuất Hạt rPP nội địa tăng 30 USD (900 -> 930 USD) (quy định thấp hơn giá chính phẩm 5%) - Giá chính phẩm tăng 20 USD (960 -> 980 USD) Không mua thông tin giá ICIS rPP | F10: 55 | G10: 904 | H10: 930 | I10: =F10*G10 -> 49720 | J10: =F10*H10 -> 51150 | K10: =J10-I10 -> 1430 | L10: =K10*$H$3/10^6 -> 35.75 | N10: 930 | O10: 980 | P10: =(N10-O10)/O10 -> -0.051020408
A11: 5 | B11: Vảy rPP | C11: - Đề xuất Vảy rPP nội địa tăng 25 USD (855 -> 880 USD) (quy định thấp hơn giá chính phẩm 10%) - Giá chính phẩm tăng 20 USD (960 -> 980 USD) Không mua thông tin giá ICIS rPP | F11: 0 | G11: 850 | H11: 880 | I11: 0 | J11: 0 | K11: =J11-I11 -> 0 | L11: =K11*$H$3/10^6 -> 0 | N11: 880 | O11: 980 | P11: =(N11-O11)/O11 -> -0.10204082
A12: 6 | B12: Phó sản | C12: Không thay đổi giá

Sheet Sheet1
A5: rPET | B5: Đề xuất giảm 25 USD / tấn (WSS01G: 1275 USD -> 1250 USD) Do: Giá ICIS giảm 15 USD (1440 USD -> 1425 USD) (Giá chính phẩm giảm 30 USD (860 USD -> 830 USD) % giá bán so với giá chính phẩm: 51% (T12/2024 giảm 50 USD/ tấn do chênh lệch so với giá chính phẩm ~ 54%) | C5: Đề xuất giảm 45 USD / tấn (WSS01G: 1275 USD -> 1230 USD) Do: Giá ICIS giảm 40 USD (1440 USD -> 1400 USD) (Giá chính phẩm giảm 40 USD (860 USD -> 820 USD) % giá bán so với giá chính phẩm: 50% (T12/2024 giảm 50 USD/ tấn do chênh lệch so với giá chính phẩm ~ 54%)
B7: OPTION 1 (Trình giá bán vào ngày 20/12/2024) | C7: OPTION 2 (trình | D7: Ghi chú
A8: Đề xuất | B8: Đề xuất giảm 25 USD / tấn (WSS01G: 1275 USD -> 1250 USD) | C8: Đề xuất giảm 45 USD / tấn (WSS01G: 1275 USD -> 1230 USD)
A9: Giá ICIS | B9: Giá ICIS giảm 15 USD (1440 USD -> 1425 USD)
A10: Giá chính phẩm | B10: (Giá chính phẩm giảm 30 USD (860 USD -> 830 USD)
A11: % giá bán so với giá chính phẩm

Sheet giá ICIS

Sheet 1. rPET
D2: GIÁ BÁN HẠT rPET - THÁNG 02 NĂM 2025 HỖ TRỢ PHÁT TRIỂN KHÁCH HÀNG MỚI | O2: TC-TCH-01/ BM01 | R2: 850
O3: V0 -04/10/2024
O4: Ngày áp dụng: 01/02/2025
B6: STT | C6: Mã sản phẩm | D6: Sản phẩm | E6: Mức IV | F6: Giá xuất xưởng DTR (USD/tấn) | P6: Chênh lệch Giá tháng 02 vs chính phẩm (850 $/tấn)
F7: ='2. rPET- nội bộ '!H7 -> Tháng 01 (đã duyệt) | J7: ='2. rPET- nội bộ '!L7 -> Tháng 02 | N7: ='2. rPET- nội bộ '!P7 -> Chênh lệch tháng 02 vs tháng 01
F8: Giá Bán (1) | G8: % Chiết khấu (2) | H8: Chiết Khấu (3) | I8: Giá bán sau chiết khấu (4)=(1)-(3) | J8: Giá Bán (1) | K8: % Chiết khấu (2) | L8: Chiết Khấu (3) | M8: Giá bán sau chiết khấu (4)=(1)-(3) | N8: $ | O8: % | P8: $ | Q8: %
C9: NHÓM KHÁCH HÀNG PHÁT TRIỂN BỀN VỮNG
B10: 1 | C10: 110000354 | D10: Hạt rPET WSS01G | E10: 0.78 | F10: 1365 | G10: 0.098901099 | H10: 135 | I10: 1230 | J10: 1365 | K10: =L10/J10 -> 0.098901099 | L10: =J10-M10 -> 135 | M10: =1300+10+15-50-45 -> 1230 | N10: =M10-I10 -> 0 | O10: =1-(I10/M10) -> 0 | P10: =M10-$R$2 -> 380 | Q10: =P10/$R$2 -> 0.44705882
B11: =B10+1 -> 2 | C11: 110000381 | D11: Hạt nhựa rPET WSS03SD, WSS04SB, WSS04SD (xơ sợi) | E11: 0.63 | F11: 1155 | G11: =H11/F11 -> 0.047619048 | H11: =F11-I11 -> 55 | I11: 1100 | J11: 1155 | K11: =L11/J11 -> 0.047619048 | L11: =J11-M11 -> 55 | M11: 1100 | N11: =M11-I11 -> 0 | O11: =1-(I11/M11) -> 0 | P11: =M11-$R$2 -> 250 | Q11: =P11/$R$2 -> 0.29411765
B14: Lưu ý:
B15: 1. Giá FOB = Giá xuất xưởng (EXW) + USD 20/tấn | G15: 20
B16: 2. Hạt xơ sợi: giá bán 1.100 usd/tấn, chào khách để bán được hàng là +/- 55usd/tấn
B17: 3. Ủy quyền cho GĐĐH duyệt theo đơn đặt hàng: biên độ +/-10% so với giá xuất xưởng DTR
B18: 4. Bảng giá áp dụng cho việc phát triển khách hàng mới, lưu hành nội bộ | Q18: ='2. rPET- nội bộ '!S45 -> Ngày 03 tháng 02 năm 2024
B20: Chủ Tịch | D20: Giám Đốc Tài Chính | F20: Giám Đốc Điều Hành | I20: Giám Đốc Kinh Doanh | L20: Giám Đốc Tài Chính | P20: Kế Toán
B26: Trần Duy Hy | D26: Hoàng Thị Hồng Hạnh | F26: Huỳnh Ngọc Thạch | I26: Dương Từ Uyên Thảo | L26: Phạm Đình Hoàng | P26: Lưu Thị Minh Tâm

Sheet 2. rPET- nội bộ 
E2: GIÁ BÁN HẠT rPET - THÁNG 02 NĂM 2025 HỖ TRỢ PHÁT TRIỂN KHÁCH HÀNG MỚI | Q2: TC-TCH-01/ BM02 | T2: 850
Q3: V0 -04/10/2024
Q4: Ngày áp dụng: 01/02/2025
B6: STT | D6: Mã sản phẩm | E6: Sản phẩm | F6: Mức IV | H6: Giá xuất xưởng DTR (USD/tấn) | R6: Chênh lệch Giá tháng 02 vs chính phẩm (850 $/tấn)
H7: Tháng 01 (đã duyệt) | L7: Tháng 02 | P7: Chênh lệch tháng 02 vs tháng 01
H8: Giá Bán (1) | I8: % Chiết khấu (2) | J8: Chiết Khấu (3) | K8: Giá bán sau chiết khấu (4)=(1)-(3) | L8: Giá Bán (1) | M8: % Chiết khấu (2) | N8: Chiết Khấu (3) | O8: Giá bán sau chiết khấu (4)=(1)-(3) | P8: $ | Q8: % | R8: $ | S8: %
B9: 1 | D9: 110000332 | E9: Hạt nhựa rPET iSS01084G | F9: 0.84 | H9: 1381.5 | I9: 0.04451683 | J9: 61.5 | K9: 1320 | L9: =L13+90 -> 1381.5 | M9: =N9/L9 -> 0.073470865 | N9: =L9-O9 -> 101.5 | O9: =+O15+90-40 -> 1280 | P9: =O9-K9 -> -40 | Q9: =1-(K9/O9) -> -0.03125 | R9: =O9-$T$2 -> 430 | S9: =R9/$T$2 -> 0.50588235 | T9: =O9-$O$13 -> 50 | U9: =O9-O10 -> 30
B10: =+B9+1 -> 2 | D10: 110000330 | E10: Hạt nhựa rPET iSS01 | F10: 0.80 | H10: 1321.5 | I10: 0.046538025 | J10: 61.5 | K10: 1260 | L10: =L11 -> 1321.5 | M10: =N10/L10 -> 0.054105184 | N10: =L10-O10 -> 71.5 | O10: =+O15+30-10 -> 1250 | P10: =O10-K10 -> -10 | Q10: =1-(K10/O10) -> -0.008 | R10: =O10-$T$2 -> 400 | S10: =R10/$T$2 -> 0.47058824 | T10: =O10-$O$13 -> 20
B11: =+B10+1 -> 3 | D11: 110000355 | E11: Hạt nhựa rPET iSS01G 1 | F11: 0.80 | H11: 1321.5 | I11: 0.046538025 | J11: 61.5 | K11: 1260 | L11: =L13+30 -> 1321.5 | M11: =N11/L11 -> 0.046538025 | N11: =L11-O11 -> 61.5 | O11: =+O15+30 -> 1260 | P11: =O11-K11 -> 0 | Q11: =1-(K11/O11) -> 0 | R11: =O11-$T$2 -> 410 | S11: =R11/$T$2 -> 0.48235294 | T11: =O11-$O$13 -> 30
B12: =+B11+1 -> 4 | D12: 110000378 | E12: Hạt nhựa rPET iSS01G 2 | F12: 0.80 | H12: 1321.5 | I12: 0.046538025 | J12: 61.5 | K12: 1260 | L12: =L15+30 -> 1321.5 | M12: =N12/L12 -> 0.046538025 | N12: =L12-O12 -> 61.5 | O12: =+O15+30 -> 1260 | P12: =O12-K12 -> 0 | Q12: =1-(K12/O12) -> 0 | R12: =O12-$T$2 -> 410 | S12: =R12/$T$2 -> 0.48235294 | T12: =O12-$O$13 -> 30 | U12: =O12-O13 -> 30
B13: =+B12+1 -> 5 | D13: 110000354 | E13: Hạt nhựa rPET WSS01G 1 | F13: 0.78 | H13: 1291.5 | I13: 0.047619048 | J13: 61.5 | K13: 1230 | L13: =O13*1.05 -> 1291.5 | M13: =N13/L13 -> 0.047619048 | N13: =L13-O13 -> 61.5 | O13: =O15 -> 1230 | P13: =O13-K13 -> 0 | Q13: =1-(K13/O13) -> 0 | R13: =O13-$T$2 -> 380 | S13: =R13/$T$2 -> 0.44705882 | T13: =O13-$O$13 -> 0
B14: =+B13+1 -> 6 | D14: 110000377 | E14: Hạt nhựa rPET WSS01G 2 | F14: 0.78 | H14: 1291.5 | I14: 0.047619048 | J14: 61.5 | K14: 1230 | L14: =O14*1.05 -> 1291.5 | M14: =N14/L14 -> 0.047619048 | N14: =L14-O14 -> 61.5 | O14: =O13 -> 1230 | P14: =O14-K14 -> 0 | Q14: =1-(K14/O14) -> 0 | R14: =O14-$T$2 -> 380 | S14: =R14/$T$2 -> 0.44705882 | T14: =O14-$O$13 -> 0
B15: =+B14+1 -> 7 | D15: 110000329 | E15: Hạt nhựa rPET WSS01 | F15: 0.78 | H15: 1291.5 | I15: 0.047619048 | J15: 61.5 | K15: 1230 | L15: =L13 -> 1291.5 | M15: =N15/L15 -> 0.047619048 | N15: =L15-O15 -> 61.5 | O15: =1300+10+15-50-45 -> 1230 | P15: =O15-K15 -> 0 | Q15: =1-(K15/O15) -> 0 | R15: =O15-$T$2 -> 380 | S15: =R15/$T$2 -> 0.44705882 | T15: =O15-$O$13 -> 0
B16: =+B15+1 -> 8 | D16: 110000331 | E16: Hạt nhựa rPET WSS02 | F16: 0.74 | H16: 1261.5 | I16: 0.048751486 | J16: 61.5 | K16: 1200 | L16: =L15-30 -> 1261.5 | M16: =N16/L16 -> 0.048751486 | N16: =L16-O16 -> 61.5 | O16: =O15-30 -> 1200 | P16: =O16-K16 -> 0 | Q16: =1-(K16/O16) -> 0 | R16: =O16-$T$2 -> 350 | S16: =R16/$T$2 -> 0.41176471 | T16: =O16-$O$13 -> -30 | U16: =O16-O13 -> -30
B17: =+B16+1 -> 9 | D17: 110000358 | E17: Hạt nhựa rPET WSS02G | F17: 0.74 | H17: 1231.5 | I17: 0.025578563 | J17: 31.5 | K17: 1200 | L17: =L16-30 -> 1231.5 | M17: =N17/L17 -> 0.025578563 | N17: =L17-O17 -> 31.5 | O17: =O15-30 -> 1200 | P17: =O17-K17 -> 0 | Q17: =1-(K17/O17) -> 0 | R17: =O17-$T$2 -> 350 | S17: =R17/$T$2 -> 0.41176471 | T17: =O17-$O$13 -> -30
B18: =+B17+1 -> 10 | D18: 110000333 | E18: Hạt nhựa rPET WSS03 | F18: 0.70 | H18: 1221.5 | I18: 0.050347933 | J18: 61.5 | K18: 1160 | L18: =+L15-70 -> 1221.5 | M18: =N18/L18 -> 0.050347933 | N18: =L18-O18 -> 61.5 | O18: =+O15-70 -> 1160 | P18: =O18-K18 -> 0 | Q18: =1-(K18/O18) -> 0 | R18: =O18-$T$2 -> 310 | S18: =R18/$T$2 -> 0.36470588 | T18: =O18-$O$13 -> -70 | U18: =O18-O16 -> -40
B19: =+B18+1 -> 11 | D19: 110000359 | E19: Hạt nhựa rPET WSS03G | F19: 0.70 | H19: 1191.5 | I19: 0.026437264 | J19: 31.5 | K19: 1160 | L19: =+L16-70 -> 1191.5 | M19: =N19/L19 -> 0.026437264 | N19: =L19-O19 -> 31.5 | O19: =+O15-70 -> 1160 | P19: =O19-K19 -> 0 | Q19: =1-(K19/O19) -> 0 | R19: =O19-$T$2 -> 310 | S19: =R19/$T$2 -> 0.36470588 | T19: =O19-$O$13 -> -70
B20: =+B19+1 -> 12 | D20: 110000376 | E20: Hạt nhựa rPET iSS01L | F20: 0.80 | H20: 1397 | I20: 0.16249105 | J20: 227 | K20: 1170 | L20: 1397 | M20: =N20/L20 -> 0.16249105 | N20: =L20-O20 -> 227 | O20: =O15-60 -> 1170 | P20: =O20-K20 -> 0 | Q20: =1-(K20/O20) -> 0 | R20: =O20-$T$2 -> 320 | S20: =R20/$T$2 -> 0.37647059 | T20: =O20-$O$13 -> -60 | U20: =O20-O18 -> 10
B21: =+B20+1 -> 13 | D21: 110000387 | E21: Hạt nhựa rPET WSS03SD | F21: 0.70 | H21: 1155 | I21: 0.047619048 | J21: 55 | K21: 1100 | L21: =1100*1.05 -> 1155 | M21: =N21/L21 -> 0.047619048 | N21: =L21-O21 -> 55 | O21: 1100 | P21: =O21-K21 -> 0 | Q21: =1-(K21/O21) -> 0 | R21: =O21-$T$2 -> 250 | S21: =R21/$T$2 -> 0.29411765 | T21: =O21-$O$13 -> -130
B22: =+B21+1 -> 14 | D22: 110000381 | E22: Hạt nhựa rPET WSS04SD | F22: 0.63 | H22: 1155 | I22: 0.047619048 | J22: 55 | K22: 1100 | L22: =1100*1.05 -> 1155 | M22: =N22/L22 -> 0.047619048 | N22: =L22-O22 -> 55 | O22: 1100 | P22: =O22-K22 -> 0 | Q22: =1-(K22/O22) -> 0 | R22: =O22-$T$2 -> 250 | S22: =R22/$T$2 -> 0.29411765 | T22: =O22-$O$13 -> -130
B23: =+B22+1 -> 15 | D23: 110000382 | E23: Hạt nhựa rPET WSS04SB | F23: 0.63 | H23: 1155 | I23: 0.047619048 | J23: 55 | K23: 1100 | L23: =1100*1.05 -> 1155 | M23: =N23/L23 -> 0.047619048 | N23: =L23-O23 -> 55 | O23: 1100 | P23: =O23-K23 -> 0 | Q23: =1-(K23/O23) -> 0 | R23: =O23-$T$2 -> 250 | S23: =R23/$T$2 -> 0.29411765 | T23: =O23-$O$13 -> -130
B24: =+B23+1 -> 16 | D24: 110000488 | E24: Hạt Nhựa rPET iSS01084G PL | F24: 0.84 | H24: 1308 | I24: 0.044342508 | J24: 58 | K24: 1250 | L24: =L27+90 -> 1308 | M24: =N24/L24 -> 0.044342508 | N24: =L24-O24 -> 58 | O24: =+O28+90 -> 1250 | P24: =O24-K24 -> 0 | Q24: =1-(K24/O24) -> 0 | R24: =O24-$T$2 -> 400 | S24: =R24/$T$2 -> 0.47058824 | T24: =O24-$O$13 -> 20
B25: =+B24+1 -> 17 | E25: Hạt rPET ISS01 | F25: 0.80 | H25: 1248 | I25: 0.046474359 | J25: 58 | K25: 1190 | L25: =L26 -> 1248 | M25: =N25/L25 -> 0.046474359 | N25: =L25-O25 -> 58 | O25: =+O28+30 -> 1190 | P25: =O25-K25 -> 0 | Q25: =1-(K25/O25) -> 0 | R25: =O25-$T$2 -> 340 | S25: =R25/$T$2 -> 0.4 | T25: =O25-$O$13 -> -40
B26: 17 | D26: 110000486 | E26: Hạt Nhựa rPET iSS01G 1 PL | F26: 0.80 | H26: 1248 | I26: 0.046474359 | J26: 58 | K26: 1190 | L26: =L27+30 -> 1248 | M26: =N26/L26 -> 0.046474359 | N26: =L26-O26 -> 58 | O26: =+O28+30 -> 1190 | P26: =O26-K26 -> 0 | Q26: =1-(K26/O26) -> 0 | R26: =O26-$T$2 -> 340 | S26: =R26/$T$2 -> 0.4 | T26: =O26-$O$13 -> -40
B27: =+B26+1 -> 18 | D27: 110000484 | E27: Hạt Nhựa rPET WSS01G 1 PL | F27: 0.78 | H27: 1218 | I27: 0.047619048 | J27: 58 | K27: 1160 | L27: =O27*1.05 -> 1218 | M27: =N27/L27 -> 0.047619048 | N27: =L27-O27 -> 58 | O27: =O28 -> 1160 | P27: =O27-K27 -> 0 | Q27: =1-(K27/O27) -> 0 | R27: =O27-$T$2 -> 310 | S27: =R27/$T$2 -> 0.36470588 | T27: =O27-$O$13 -> -70
B28: =+B27+1 -> 19 | D28: 110000493 | E28: Hạt Nhựa rPET WSS01 PL | F28: 0.78 | H28: 1218 | I28: 0.047619048 | J28: 58 | K28: 1160 | L28: =L27 -> 1218 | M28: =N28/L28 -> 0.047619048 | N28: =L28-O28 -> 58 | O28: =O29+30 -> 1160 | P28: =O28-K28 -> 0 | Q28: =1-(K28/O28) -> 0 | R28: =O28-$T$2 -> 310 | S28: =R28/$T$2 -> 0.36470588 | T28: =O28-$O$13 -> -70
B29: =+B28+1 -> 20 | E29: Hạt rPET WSS02 | F29: 0.74 | H29: 1188 | I29: 0.048821549 | J29: 58 | K29: 1130 | L29: =L28-30 -> 1188 | M29: =N29/L29 -> 0.048821549 | N29: =L29-O29 -> 58 | O29: =O31+30 -> 1130 | P29: =O29-K29 -> 0 | Q29: =1-(K29/O29) -> 0 | R29: =O29-$T$2 -> 280 | S29: =R29/$T$2 -> 0.32941176 | T29: =O29-$O$13 -> -100
B30: =+B29+1 -> 21 | E30: Hạt nhựa rPET WSS02G | F30: 0.74 | H30: 1158 | I30: 0.02417962 | J30: 28 | K30: 1130 | L30: =L29-30 -> 1158 | M30: =N30/L30 -> 0.02417962 | N30: =L30-O30 -> 28 | O30: =O31+30 -> 1130 | P30: =O30-K30 -> 0 | Q30: =1-(K30/O30) -> 0 | R30: =O30-$T$2 -> 280 | S30: =R30/$T$2 -> 0.32941176 | T30: =O30-$O$13 -> -100
B31: =+B30+1 -> 22 | E31: Hạt rPET WSS03 | F31: 0.70 | H31: 1148 | I31: 0.041811847 | J31: 48 | K31: 1100 | L31: =+L28-70 -> 1148 | M31: =N31/L31 -> 0.041811847 | N31: =L31-O31 -> 48 | O31: 1100 | P31: =O31-K31 -> 0 | Q31: =1-(K31/O31) -> 0 | R31: =O31-$T$2 -> 250 | S31: =R31/$T$2 -> 0.29411765 | T31: =O31-$O$13 -> -130
B32: 20 | D32: 110000492 | E32: Hạt Nhựa rPET WSS03G PL | F32: 0.70 | H32: 1118 | I32: 0.016100179 | J32: 18 | K32: 1100 | L32: =+L29-70 -> 1118 | M32: =N32/L32 -> 0.016100179 | N32: =L32-O32 -> 18 | O32: 1100 | P32: =O32-K32 -> 0 | Q32: =1-(K32/O32) -> 0 | R32: =O32-$T$2 -> 250 | S32: =R32/$T$2 -> 0.29411765 | T32: =O32-$O$13 -> -130
B35: Lưu ý:
B36: 1. Giá FOB = Giá xuất xưởng (EXW) + USD 20/tấn | I36: 20
B37: 2. Hạt xơ sợi: giá bán 1.100 usd/tấn, chào khách để bán được hàng là +/- 55usd/tấn
B38: 3. Bảng giá áp dụng cho việc phát triển khách hàng mới, lưu hành nội bộ
S45: Ngày 03 tháng 02 năm 2024
D46: Giám đốc Tài Chính | F46: Giám Đốc Điều Hành | K46: Giám Đốc Kinh Doanh | N46: Giám Đốc Tài Chính | R46: Kế Toán
D53: Hoàng Thị Hồng Hạnh | F53: Huỳnh Ngọc Thạch | K53: Dương Từ Uyên Thảo | N53: Phạm Đình Hoàng | R53: Lưu Thị Minh Tâm

Sheet 3. rPET USA 
D2: GIÁ BÁN HẠT rPET - THÁNG 02 NĂM 2025 - THỊ TRƯỜNG USA HỖ TRỢ PHÁT TRIỂN KHÁCH HÀNG MỚI | N2: TC-TCH-01/ BM03
N3: V0 -04/10/2024
N4: Ngày áp dụng: 01/02/2025
C6: Hạt rPET: WSS01G (IV 0.78 ± 0.02) | H6: ISS01G (IV 0.8 ± 0.02) | M6: ISS01084G (IV 0.84 ± 0.03)
B8: TÓM TẮT:
B9: I | C9: Giá FOB | D9: =D17 -> 1250 | E9: =E17 -> 27500 | F9: =+E9/E$11 -> 0.81541883 | H9: Giá FOB | I9: =I17 -> 1280 | J9: =J17 -> 28160 | K9: =+J9/J$11 -> 0.81786287 | M9: Giá FOB | N9: =N17 -> 1300 | O9: =O17 -> 28600 | P9: =+O9/O$11 -> 0.81943728
B10: II | C10: Chi phí vận chuyển từ VN sang USA | D10: =+D18+D19+D21+D22+D23 -> 282.95455 | E10: =+E18+E19+E21+E22+E23 -> 6225 | F10: =+E10/E$11 -> 0.18458117 | H10: Chi phí vận chuyển từ VN sang USA | I10: =+I18+I19+I21+I22+I23 -> 285.05455 | J10: =+J18+J19+J21+J22+J23 -> 6271.2 | K10: =+J10/J$11 -> 0.18213713 | M10: Chi phí vận chuyển từ VN sang USA | N10: =+N18+N19+N21+N22+N23 -> 286.45455 | O10: =+O18+O19+O21+O22+O23 -> 6302 | P10: =+O10/O$11 -> 0.18056272
C11: Tổng cộng | D11: =+D10+D9 -> 1532.9545 | E11: =+E10+E9 -> 33725 | F11: =+E11/E$11 -> 1 | H11: Tổng cộng | I11: =+I10+I9 -> 1565.0545 | J11: =+J10+J9 -> 34431.2 | K11: =+J11/J$11 -> 1 | M11: Tổng cộng | N11: =+N10+N9 -> 1586.4545 | O11: =+O10+O9 -> 34902 | P11: =+O11/O$11 -> 1
C13: Số lượng (tấn/cont) | D13: 22 | H13: Số lượng (tấn/cont) | I13: =D13 -> 22 | M13: Số lượng (tấn/cont) | N13: =I13 -> 22
B14: STT | C14: Quy cách đóng hàng (cont 20'fcl | D14: Đơn giá USD ($/tấn) | E14: Tổng giá trị USD ($/cont) | F14: Tỷ lệ % | H14: Quy cách đóng hàng (cont 20'fcl | I14: Đơn giá USD ($/tấn) | J14: Tổng giá trị USD ($/cont) | K14: Tỷ lệ % | M14: Quy cách đóng hàng (cont 20'fcl | N14: Đơn giá USD ($/tấn) | O14: Tổng giá trị USD ($/cont) | P14: Tỷ lệ %
B15: =+B13+1 -> 1 | C15: Giá Exw DTR | D15: ='2. rPET- nội bộ '!O13 -> 1230 | E15: =+D15*D$13 -> 27060 | H15: Giá Ex DTR | I15: ='2. rPET- nội bộ '!O11 -> 1260 | J15: =+I15*I$13 -> 27720 | M15: Giá Ex DTR | N15: ='2. rPET- nội bộ '!O9 -> 1280 | O15: =+N15*N$13 -> 28160
B16: 2 | C16: Kéo cont từ DTR đến cảng HCM | D16: 20 | E16: =+D16*D$13 -> 440 | H16: Kéo cont từ DTR đến cảng HCM | I16: 20 | J16: =+I16*I$13 -> 440 | M16: Kéo cont từ DTR đến cảng HCM | N16: 20 | O16: =+N16*N$13 -> 440
B17: 3 | C17: Giá FOB HCM=(1) + (2) | D17: =D15+20 -> 1250 | E17: =+D17*D$13 -> 27500 | F17: =+E17/E$11 -> 0.81541883 | H17: Giá FOB HCM | I17: =I15+20 -> 1280 | J17: =+I17*I$13 -> 28160 | K17: =+J17/J$11 -> 0.81786287 | M17: Giá FOB HCM | N17: =N15+20 -> 1300 | O17: =+N17*N$13 -> 28600 | P17: =+O17/O$11 -> 0.81943728
B18: 4 | C18: Vận chuyển biển | D18: =+E18/D13 -> 113.63636 | E18: 2500 | F18: =+E18/E$11 -> 0.074128984 | H18: Vận chuyển biển | I18: =+J18/I13 -> 113.63636 | J18: =E18 -> 2500 | K18: =+J18/J$11 -> 0.072608564 | M18: Vận chuyển biển | N18: =+O18/N13 -> 113.63636 | O18: =E18 -> 2500 | P18: =+O18/O$11 -> 0.071629133
B19: 5 | C19: Bảo hiểm | D19: =+E19/D13 -> 0 | E19: 0 | F19: =+E19/E$11 -> 0 | H19: Bảo hiểm | I19: =+J19/I13 -> 0 | J19: 0 | K19: =+J19/J$11 -> 0 | M19: Bảo hiểm | N19: =+O19/N13 -> 0 | O19: 0 | P19: =+O19/O$11 -> 0
B20: =+B19+1 -> 6 | C20: Giá CIF (LAX)=(3)+(4)+(5) | D20: =SUM(D17:D19) -> 1363.6364 | E20: =SUM(E17:E19) -> 30000 | F20: =+E20/E$11 -> 0.88954781 | H20: Giá CIF (LAX) | I20: =SUM(I17:I19) -> 1393.6364 | J20: =SUM(J17:J19) -> 30660 | K20: =+J20/J$11 -> 0.89047143 | M20: Giá CIF (LAX) | N20: =SUM(N17:N19) -> 1413.6364 | O20: =SUM(O17:O19) -> 31100 | P20: =+O20/O$11 -> 0.89106641
B21: =+B20+1 -> 7 | C21: Thuế nhập khẩu | D21: =+E21/D13 -> 87.5 | E21: =7%*D17*D13 -> 1925 | F21: =+E21/E$11 -> 0.057079318 | H21: Thuế nhập khẩu | I21: =+J21/I13 -> 89.6 | J21: =7%*I17*I13 -> 1971.2 | K21: =+J21/J$11 -> 0.057250401 | M21: Thuế nhập khẩu | N21: =+O21/N13 -> 91 | O21: =7%*N17*N13 -> 2002 | P21: =+O21/O$11 -> 0.05736061
B22: =+B21+1 -> 8 | C22: Kéo cont đến nhà máy | D22: =+E22/$D$13 -> 63.636364 | E22: 1400 | F22: =+E22/E$11 -> 0.041512231 | H22: Kéo cont đến nhà máy | I22: =+J22/$D$13 -> 63.636364 | J22: =E22 -> 1400 | K22: =+J22/J$11 -> 0.040660796 | M22: Kéo cont đến nhà máy | N22: =+O22/$D$13 -> 63.636364 | O22: =E22 -> 1400 | P22: =+O22/O$11 -> 0.040112314
B23: =+B22+1 -> 9 | C23: Phí phạt vượt tải trọng | D23: =+E23/$D$13 -> 18.181818 | E23: 400 | F23: =+E23/E$11 -> 0.011860638 | H23: Phí phạt vượt tải trọng | I23: =+J23/$D$13 -> 18.181818 | J23: =E23 -> 400 | K23: =+J23/J$11 -> 0.01161737 | M23: Phí phạt vượt tải trọng | N23: =+O23/$D$13 -> 18.181818 | O23: =E23 -> 400 | P23: =+O23/O$11 -> 0.011460661
B24: =+B23+1 -> 10 | C24: Giá DDP CA93033=(6)+(7)+(8)+(9) | D24: =+SUM(D20:D23) -> 1532.9545 | E24: =+SUM(E20:E23) -> 33725 | F24: =+E24/E$11 -> 1 | H24: Giá DDP CA93033 | I24: =+SUM(I20:I23) -> 1565.0545 | J24: =+SUM(J20:J23) -> 34431.2 | K24: =+J24/J$11 -> 1 | M24: Giá DDP CA93033 | N24: =+SUM(N20:N23) -> 1586.4545 | O24: =+SUM(O20:O23) -> 34902 | P24: =+O24/O$11 -> 1
B25: Lưu ý:
B26: 1. Bảng giá áp dụng cho việc phát triển khách hàng mới, lưu hành nội bộ
P29: ='2. rPET- nội bộ '!S45 -> Ngày 03 tháng 02 năm 2024
B30: Giám Đốc Tài Chính | F30: Giám Đốc Điều Hành | I30: Giám Đốc Kinh Doanh | M30: Giám Đốc Tài Chính | N30: Kế Toán
B36: Hoàng Thị Hồng Hạnh | F36: Huỳnh Ngọc Thạch | I36: Dương Từ Uyên Thảo | M36: Phạm Đình Hoàng | N36: Lưu Thị Minh Tâm

Sheet Giới hạn 

Sheet 4. rHDPE 
D2: GIÁ BÁN HẠT rHDPE - THÁNG 02 NĂM 2025 HỖ TRỢ PHÁT TRIỂN KHÁCH HÀNG MỚI | O2: TC-TCH-01/ BM04 | R2: 940
O3: V0 -04/10/2024
O4: Ngày áp dụng: 01/02/2025
B6: STT | C6: Mã sản phẩm | D6: Sản phẩm | E6: Màu | F6: Giá xuất xưởng DTR (USD/tấn) | P6: Chênh lệch Giá tháng 02 vs chính phẩm (940 $/tấn HD thổi & 940 $/tấn HD ép )
F7: ='1. rPET'!F7 -> Tháng 01 (đã duyệt) | J7: ='1. rPET'!J7 -> Tháng 02 | N7: ='1. rPET'!N7 -> Chênh lệch tháng 02 vs tháng 01
F8: Giá Bán (1) | G8: % Chiết khấu (2) | H8: Chiết Khấu (3) | I8: Giá bán sau chiết khấu (4)=(1)-(3) | J8: Giá Bán (1) | K8: % Chiết khấu (2) | L8: Chiết Khấu (3) | M8: Giá bán sau chiết khấu (4)=(1)-(3) | N8: $ | O8: % | P8: $ | Q8: %
B9: A | C9: NHÓM KHÁCH HÀNG PHÁT TRIỂN BỀN VỮNG
B10: I. rHDPE THỔI (PERSONAL CARE - KHỬ MÙI)
B11: 1 | C11: 110000429 | D11: Hạt Nhựa rHDPE A03N01 | E11: Không màu | F11: 1530 | G11: =H11/F11 -> 0.08496732 | H11: =F11-I11 -> 130 | I11: 1400 | J11: 1530 | K11: =L11/J11 -> 0.08496732 | L11: =J11-M11 -> 130 | M11: 1400 | N11: =M11-I11 -> 0 | O11: =1-(I11/M11) -> 0 | P11: =M11-$R$2 -> 460 | Q11: =P11/$R$2 -> 0.4893617 | S11: Không mua giá ICIS HD, PP nữa
B12: =B11+1 -> 2 | C12: 110000337 | D12: Hạt nhựa rHD Thổi màu | E12: Trắng, lá, vàng | F12: =+$F$11-50 -> 1480 | G12: =H12/F12 -> 0.087837838 | H12: =F12-I12 -> 130 | I12: =$I$11-50 -> 1350 | J12: =+$J$11-50 -> 1480 | K12: =L12/J12 -> 0.087837838 | L12: =J12-M12 -> 130 | M12: =$M$11-50 -> 1350 | N12: =M12-I12 -> 0 | O12: =1-(I12/M12) -> 0 | P12: =M12-$R$2 -> 410 | Q12: =P12/$R$2 -> 0.43617021
B13: II. rHDPE THỔI (HOME CARE - KHÔNG KHỬ MÙI)
B14: 1 | C14: 110000432 | D14: Hạt nhựa rHDPE B03N01 | E14: Không màu, Trắng, lá, vàng, đen | F14: 1530 | G14: =H14/F14 -> 0.11764706 | H14: =F14-I14 -> 180 | I14: =I11-50 -> 1350 | J14: 1530 | K14: =L14/J14 -> 0.1503268 | L14: =J14-M14 -> 230 | M14: =M11-50-50 -> 1300 | N14: =M14-I14 -> -50 | O14: =1-(I14/M14) -> -0.038461538 | P14: =M14-$R$2 -> 360 | Q14: =P14/$R$2 -> 0.38297872
B15: III. rHDPE ÉP
B16: 1 | C16: 110000373 | D16: Hạt rHDI4DL01 | E16: Màu dương đậm | F16: 1300 | G16: =H16/F16 -> 0.038461538 | H16: =F16-I16 -> 50 | I16: 1250 | J16: 1300 | K16: =L16/J16 -> 0.038461538 | L16: =J16-M16 -> 50 | M16: 1250 | N16: =M16-I16 -> 0 | O16: =1-(I16/M16) -> 0 | P16: =M16-$R$16 -> 310 | Q16: =P16/$R$16 -> 0.32978723 | R16: 940
B17: 2 | C17: 110000365 | D17: Hạt rHD ép | E17: Màu trắng, đỏ | F17: 1360 | G17: =H17/F17 -> 0.036764706 | H17: =F17-I17 -> 50 | I17: 1310 | J17: 1360 | K17: =L17/J17 -> 0.036764706 | L17: =J17-M17 -> 50 | M17: 1310 | N17: =M17-I17 -> 0 | O17: =1-(I17/M17) -> 0 | P17: =M17-$R$16 -> 370 | Q17: =P17/$R$16 -> 0.39361702
B18: 3 | C18: 110000361 | D18: Hạt rHDI3R01 | E18: Màu đỏ | F18: 1360 | G18: =H18/F18 -> 0.036764706 | H18: =F18-I18 -> 50 | I18: 1310 | J18: 1360 | K18: =L18/J18 -> 0.036764706 | L18: =J18-M18 -> 50 | M18: 1310 | N18: =M18-I18 -> 0 | O18: =1-(I18/M18) -> 0 | P18: =M18-$R$2 -> 370 | Q18: =P18/$R$2 -> 0.39361702
B19: B | C19: NHÓM KHÁCH HÀNG KHÔNG CAM KẾT PHÁT TRIỂN BỀN VỮNG
B20: 1 | C20: 110000373 | D20: Hạt rHD ép màu | E20: Màu dương, trắng, đỏ, lá, xám | F20: 1000 | G20: =H20/F20 -> 0.13 | H20: =F20-I20 -> 130 | I20: 870 | J20: 1000 | K20: =L20/J20 -> 0.2 | L20: =J20-M20 -> 200 | M20: 800 | N20: =M20-I20 -> -70 | O20: =1-(I20/M20) -> -0.0875 | P20: =M20-$R$16 -> -140 | Q20: =P20/$R$2 -> -0.14893617
B21: 2 | C21: 110000362 | D21: Hạt rHD ép đen | E21: Màu đen | F21: 1000 | G21: =H21/F21 -> 0.13 | H21: =F21-I21 -> 130 | I21: 870 | J21: 1000 | K21: =L21/J21 -> 0.25 | L21: =J21-M21 -> 250 | M21: 750 | N21: =M21-I21 -> -120 | O21: =1-(I21/M21) -> -0.16 | P21: =M21-$R$2 -> -190 | Q21: =P21/$R$2 -> -0.20212766
B22: 3 | C22: 110000361 | D22: Hạt rHDI3R01 | E22: Màu đỏ | F22: 1000 | G22: =H22/F22 -> 0.05 | H22: =F22-I22 -> 50 | I22: 950 | J22: 1000 | K22: =L22/J22 -> 0.05 | L22: =J22-M22 -> 50 | M22: 950 | N22: =M22-I22 -> 0 | O22: =1-(I22/M22) -> 0 | P22: =M22-$R$2 -> 10 | Q22: =P22/$R$2 -> 0.010638298
B25: Lưu ý:
B27: 1. Giá FOB = Giá xuất xưởng (EXW) + USD 25/tấn | G27: 25
B28: 2. Giá chính phẩm HD thổi là 940 usd/tấn, HD Ép là 940 usd/tấn
B29: 3. Khách hàng nội địa: Long Thành, DTP, Hiệp Thành
B30: 4. Ủy quyền cho GĐĐH duyệt theo đơn đặt hàng: biên độ +/-10% so với giá xuất xưởng DTR
B31: 5. Bảng giá áp dụng cho việc phát triển khách hàng mới, lưu hành nội bộ
Q32: ='2. rPET- nội bộ '!S45 -> Ngày 03 tháng 02 năm 2024
B34: Chủ Tịch | D34: Giám Đốc Tài Chính | F34: Giám Đốc Điều Hành | I34: Giám Đốc Kinh Doanh | M34: Giám Đốc Tài Chính | P34: Kế Toán
B40: Trần Duy Hy | D40: Hoàng Thị Hồng Hạnh | F40: Huỳnh Ngọc Thạch | I40: Dương Từ Uyên Thảo | M40: Phạm Đình Hoàng | P40: Lưu Thị Minh Tâm

Sheet 5.Vảy HDPE- Ép
D2: GIÁ BÁN VẢY HDPE ÉP- THÁNG 02 NĂM 2025 HỖ TRỢ PHÁT TRIỂN KHÁCH HÀNG MỚI | O2: TC-TCH-01/ BM05 | R2: 940
O3: V0 -04/10/2024
O4: Ngày áp dụng: 01/02/2025
B6: STT | C6: Mã sản phẩm | D6: Sản phẩm | E6: Màu | F6: Giá xuất xưởng DTR (USD/tấn) | P6: Chênh lệch Giá tháng 02 vs chính phẩm (940 $/tấn)
F7: ='1. rPET'!F7 -> Tháng 01 (đã duyệt) | J7: ='1. rPET'!J7 -> Tháng 02 | N7: ='1. rPET'!N7 -> Chênh lệch tháng 02 vs tháng 01
F8: Giá Bán (1) | G8: % Chiết khấu (2) | H8: Chiết Khấu (3) | I8: Giá bán sau chiết khấu (4)=(1)-(3) | J8: Giá Bán (1) | K8: % Chiết khấu (2) | L8: Chiết Khấu (3) | M8: Giá bán sau chiết khấu (4)=(1)-(3) | N8: $ | O8: % | P8: $ | Q8: %
B9: NHÓM KHÁCH HÀNG NỘI ĐỊA
B10: 1 | C10: 110000407 | D10: Vảy HD màu | E10: Đỏ, Trắng, Vàng, Lá, Dương | F10: 925 | G10: =H10/F10 -> 0.10810811 | H10: =F10-I10 -> 100 | I10: 825 | J10: 925 | K10: =L10/J10 -> 0.18918919 | L10: =J10-M10 -> 175 | M10: 750 | N10: =M10-I10 -> -75 | O10: =1-(I10/M10) -> -0.1 | P10: =M10-$R$2 -> -190 | Q10: =P10/$R$2 -> -0.20212766
B11: 2 | C11: 110000412 | D11: Vảy HD Ép Đen | E11: Đen | F11: 925 | G11: =H11/F11 -> 0.10810811 | H11: =F11-I11 -> 100 | I11: 825 | J11: 925 | K11: =L11/J11 -> 0.10810811 | L11: =J11-M11 -> 100 | M11: 825 | N11: =M11-I11 -> 0 | O11: =1-(I11/M11) -> 0 | P11: =M11-$R$2 -> -115 | Q11: =P11/$R$2 -> -0.12234043
B12: 3 | C12: 110000409 | D12: Vảy HD Ép Vàng | F12: 850 | G12: =H12/F12 -> 0.047058824 | H12: =F12-I12 -> 40 | I12: 810 | J12: 850 | K12: =L12/J12 -> 0.047058824 | L12: =J12-M12 -> 40 | M12: 810 | N12: =M12-I12 -> 0 | O12: =1-(I12/M12) -> 0 | P12: =M12-$R$2 -> -130 | Q12: =P12/$R$2 -> -0.13829787
B13: 4 | C13: 110000410 | D13: Vảy HD Ép Lá | F13: 850 | G13: =H13/F13 -> 0.047058824 | H13: =F13-I13 -> 40 | I13: 810 | J13: 850 | K13: =L13/J13 -> 0.047058824 | L13: =J13-M13 -> 40 | M13: 810 | N13: =M13-I13 -> 0 | O13: =1-(I13/M13) -> 0 | P13: =M13-$R$2 -> -130 | Q13: =P13/$R$2 -> -0.13829787
B14: 5 | C14: 110000411 | D14: Vảy HD Ép Dương | F14: 850 | G14: =H14/F14 -> 0.047058824 | H14: =F14-I14 -> 40 | I14: 810 | J14: 850 | K14: =L14/J14 -> 0.047058824 | L14: =J14-M14 -> 40 | M14: 810 | N14: =M14-I14 -> 0 | O14: =1-(I14/M14) -> 0 | P14: =M14-$R$2 -> -130 | Q14: =P14/$R$2 -> -0.13829787
B17: Lưu ý:
B19: 1. Giá trên là giá xuất xưởng (EXW), nếu vận chuyển đến khách hàng thì cộng thêm phí vận chuyển
B20: 2. Ủy quyền cho GĐĐH duyệt theo đơn đặt hàng: biên độ +/-10% so với giá xuất xưởng DTR
Q24: ='2. rPET- nội bộ '!S45 -> Ngày 03 tháng 02 năm 2024
B26: Chủ Tịch | D26: Giám Đốc Tài Chính | F26: Giám Đốc Điều Hành | I26: Giám Đốc Kinh Doanh | M26: Giám Đốc Tài Chính | P26: Kế Toán
B33: Trần Duy Hy | D33: Hoàng Thị Hồng Hạnh | F33: Huỳnh Ngọc Thạch | I33: Dương Từ Uyên Thảo | M33: Phạm Đình Hoàng | P33: Lưu Thị Minh Tâm

Sheet 6. rPP 
D2: GIÁ BÁN HẠT rPP - THÁNG 02 NĂM 2025 HỖ TRỢ PHÁT TRIỂN KHÁCH HÀNG MỚI | O2: TC-TCH-01/ BM06 | R2: 980
O3: V0 -04/10/2024
O4: Ngày áp dụng: 01/02/2025
B6: STT | C6: Mã sản phẩm | D6: Sản phẩm | E6: Màu | F6: Giá xuất xưởng DTR (USD/tấn) | P6: Chênh lệch Giá tháng 02 vs chính phẩm (980 $/tấn)
F7: ='1. rPET'!F7 -> Tháng 01 (đã duyệt) | J7: ='1. rPET'!J7 -> Tháng 02 | N7: ='1. rPET'!N7 -> Chênh lệch tháng 02 vs tháng 01
F8: Giá Bán (1) | G8: % Chiết khấu (2) | H8: Chiết Khấu (3) | I8: Giá bán sau chiết khấu (4)=(1)-(3) | J8: Giá Bán (1) | K8: % Chiết khấu (2) | L8: Chiết Khấu (3) | M8: Giá bán sau chiết khấu (4)=(1)-(3) | N8: $ | O8: % | P8: $ | Q8: %
B9: A | C9: NHÓM KHÁCH HÀNG PHÁT TRIỂN BỀN VỮNG
B10: 1 | C10: 110000367 | D10: Hạt nhựa rPP màu | E10: Đỏ, dương, trắng, lá, đen | F10: 1200 | G10: =H10/F10 -> 0.05 | H10: =F10-I10 -> 60 | I10: 1140 | J10: 1200 | K10: =L10/J10 -> 0.05 | L10: =J10-M10 -> 60 | M10: 1140 | N10: =M10-I10 -> 0 | O10: =1-(I10/M10) -> 0 | P10: =M10-$R$2 -> 160 | Q10: =P10/$R$2 -> 0.16326531
C11: NHÓM KHÁCH HÀNG NỘI ĐỊA
B12: 1 | C12: 110000367 | D12: Hạt nhựa rPP màu | E12: Đỏ, dương, trắng, lá, xám | F12: 1000 | G12: 0.1 | H12: 100 | I12: 900 | J12: 1000 | K12: =L12/J12 -> 0.18 | L12: =J12-M12 -> 180 | M12: 820 | N12: =M12-I12 -> -80 | O12: =1-(I12/M12) -> -0.097560976 | P12: =M12-$R$2 -> -160 | Q12: =P12/$R$2 -> -0.16326531
B13: 2 | C13: 110000371 | D13: Hạt nhựa rPP đen | E13: Đen | F13: 1000 | G13: 0.1 | H13: 100 | I13: 900 | J13: 1000 | K13: =L13/J13 -> 0.28 | L13: =J13-M13 -> 280 | M13: 720 | N13: =M13-I13 -> -180 | O13: =1-(I13/M13) -> -0.25 | P13: =M13-$R$2 -> -260 | Q13: =P13/$R$2 -> -0.26530612
B16: Lưu ý:
B18: 1. Giá FOB = Giá xuất xưởng (EXW) + USD 25/tấn | G18: 25
B19: 2. Ủy quyền cho GĐĐH duyệt theo đơn đặt hàng: biên độ +/-10% so với giá xuất xưởng DTR
B20: 3. Bảng giá áp dụng cho việc phát triển khách hàng mới, lưu hành nội bộ | Q20: ='2. rPET- nội bộ '!S45 -> Ngày 03 tháng 02 năm 2024
B22: Chủ Tịch | D22: Giám Đốc Tài Chính | G22: Giám Đốc Điều Hành | I22: Giám Đốc Kinh Doanh | M22: Giám Đốc Tài Chính | P22: Kế Toán
B29: Trần Duy Hy | D29: Hoàng Thị Hồng Hạnh | G29: Huỳnh Ngọc Thạch | I29: Dương Từ Uyên Thảo | M29: Phạm Đình Hoàng | P29: Lưu Thị Minh Tâm

Sheet 7. Vảy PP
D2: GIÁ BÁN VẢY PP - THÁNG 02 NĂM 2025 HỖ TRỢ PHÁT TRIỂN KHÁCH HÀNG MỚI | O2: TC-TCH-01/ BM07 | R2: 980
O3: V0 -04/10/2024
O4: Ngày áp dụng: 01/01/2025
B6: STT | C6: Mã sản phẩm | D6: Sản phẩm | E6: Màu | F6: Giá xuất xưởng DTR (USD/tấn) | P6: Chênh lệch Giá tháng 02 vs chính phẩm (980 $/tấn)
F7: ='1. rPET'!F7 -> Tháng 01 (đã duyệt) | J7: ='1. rPET'!J7 -> Tháng 02 | N7: ='1. rPET'!N7 -> Chênh lệch tháng 02 vs tháng 01
F8: Giá Bán (1) | G8: % Chiết khấu (2) | H8: Chiết Khấu (3) | I8: Giá bán sau chiết khấu (4)=(1)-(3) | J8: Giá Bán (1) | K8: % Chiết khấu (2) | L8: Chiết Khấu (3) | M8: Giá bán sau chiết khấu (4)=(1)-(3) | N8: $ | O8: % | P8: $ | Q8: %
B9: NHÓM KHÁCH HÀNG NỘI ĐỊA
B10: 1 | C10: 110000421 | D10: Vảy PP màu | E10: Đỏ, dương | F10: 900 | G10: 0.05 | H10: 45 | I10: 855 | J10: 900 | K10: =L10/J10 -> 0.13333333 | L10: =J10-M10 -> 120 | M10: 780 | N10: =M10-I10 -> -75 | O10: =1-(I10/M10) -> -0.096153846 | P10: =M10-$R$2 -> -200 | Q10: =P10/$R$2 -> -0.20408163
B11: 2 | C11: 110000422 | D11: Vảy PP Đỏ Đậm | F11: 850 | G11: =H11/F11 -> 0.047058824 | H11: =F11-I11 -> 40 | I11: 810 | J11: 850 | K11: =L11/J11 -> 0.047058824 | L11: =J11-M11 -> 40 | M11: 810 | N11: =M11-I11 -> 0 | O11: =1-(I11/M11) -> 0 | P11: =M11-$R$2 -> -170 | Q11: =P11/$R$2 -> -0.17346939
B12: 3 | C12: 110000423 | D12: Vảy PP Dương Nhạt | F12: 850 | G12: =H12/F12 -> 0.047058824 | H12: =F12-I12 -> 40 | I12: 810 | J12: 850 | K12: =L12/J12 -> 0.047058824 | L12: =J12-M12 -> 40 | M12: 810 | N12: =M12-I12 -> 0 | O12: =1-(I12/M12) -> 0 | P12: =M12-$R$2 -> -170 | Q12: =P12/$R$2 -> -0.17346939
B13: 4 | C13: 110000424 | D13: Vảy PP Dương Đậm | F13: 850 | G13: =H13/F13 -> 0.047058824 | H13: =F13-I13 -> 40 | I13: 810 | J13: 850 | K13: =L13/J13 -> 0.047058824 | L13: =J13-M13 -> 40 | M13: 810 | N13: =M13-I13 -> 0 | O13: =1-(I13/M13) -> 0 | P13: =M13-$R$2 -> -170 | Q13: =P13/$R$2 -> -0.17346939
B16: Lưu ý:
B18: 1. Giá trên là giá xuất xưởng (EXW), nếu vận chuyển đến khách hàng thì cộng thêm phí vận chuyển
B19: 2. Ủy quyền cho GĐĐH duyệt theo đơn đặt hàng: biên độ +/-10% so với giá xuất xưởng DTR
Q20: ='2. rPET- nội bộ '!S45 -> Ngày 03 tháng 02 năm 2024
B22: Chủ Tịch | D22: Giám Đốc Tài Chính | G22: Giám Đốc Điều Hành | I22: Giám Đốc Kinh Doanh | M22: Giám Đốc Tài Chính | P22: Kế Toán
B29: Trần Duy Hy | D29: Hoàng Thị Hồng Hạnh | G29: Huỳnh Ngọc Thạch | I29: Dương Từ Uyên Thảo | M29: Phạm Đình Hoàng | P29: Lưu Thị Minh Tâm

Sheet 8. Hạt phó sản
D2: GIÁ BÁN HẠT SẢN XUẤT TỪ PHÓ SẢN - THÁNG 02 NĂM 2025 HỖ TRỢ PHÁT TRIỂN KHÁCH HÀNG MỚI | P2: TC-TCH-01/ BM08
P3: V0 -04/10/2024
P4: Ngày áp dụng: 01/02/2025
B6: STT | C6: Mã sản phẩm | D6: Sản phẩm | E6: Màu | F6: IV/MI | G6: Giá xuất xưởng DTR (USD/tấn) | Q6: Chênh lệch Giá tháng 02 vs chính phẩm (850 $/tấn)
G7: ='1. rPET'!F7 -> Tháng 01 (đã duyệt) | K7: ='1. rPET'!J7 -> Tháng 02 | O7: ='1. rPET'!N7 -> Chênh lệch tháng 02 vs tháng 01
G8: Giá Bán (1) | H8: % Chiết khấu (2) | I8: Chiết Khấu (3) | J8: Giá bán sau chiết khấu (4)=(1)-(3) | K8: Giá Bán (1) | L8: % Chiết khấu (2) | M8: Chiết Khấu (3) | N8: Giá bán sau chiết khấu (4)=(1)-(3) | O8: $ | P8: % | Q8: $ | R8: % | T8: Hòa vốn | U8: Công thức
B9: NHÓM KHÁCH HÀNG NỘI ĐỊA
B10: 1 | C10: 110000464 | D10: Hạt Nhựa rPET WSS06SP-1 | E10: Đục | F10: 0.40 ~ 0.50 | G10: =J10*1.05 -> 682.5 | H10: =I10/G10 -> 0.047619048 | I10: =G10-J10 -> 32.5 | J10: 650 | K10: =N10*1.05 -> 682.5 | L10: =M10/K10 -> 0.047619048 | M10: =K10-N10 -> 32.5 | N10: 650 | O10: =N10-J10 -> 0 | P10: =1-(J10/N10) -> 0 | Q10: =N10-S10 -> -200 | R10: =Q10/S10 -> -0.23529412 | S10: 850 | T10: =#REF! -> #REF! | U10: WSS006SP-1 (vảy PET tuyển nổi 2) | W10: =T10*25 -> #REF!
B11: 2 | C11: 110000465 | D11: Hạt Nhựa rPET WSS06SP-2 | E11: Trong | F11: 0.40 ~ 0.50 | G11: =J11*1.05 -> 787.5 | H11: =I11/G11 -> 0.047619048 | I11: =G11-J11 -> 37.5 | J11: 750 | K11: =N11*1.05 -> 787.5 | L11: =M11/K11 -> 0.047619048 | M11: =K11-N11 -> 37.5 | N11: 750 | O11: =N11-J11 -> 0 | P11: =1-(J11/N11) -> 0 | Q11: =N11-S11 -> -100 | R11: =Q11/S11 -> -0.11764706 | S11: 850 | T11: =#REF! -> #REF! | U11: WSS006SP-2 (bụi tank C,D đã gia công) | W11: =T11*25 -> #REF!
B12: 3 | C12: 110000436 | D12: Hạt nhựa rPET WSS05SB | E12: Trong | F12: 0.50 ~ 0.60 | G12: 1000 | H12: =I12/G12 -> 0.05 | I12: =G12-J12 -> 50 | J12: 950 | K12: 1000 | L12: =M12/K12 -> 0.05 | M12: =K12-N12 -> 50 | N12: 950 | O12: =N12-J12 -> 0 | P12: =1-(J12/N12) -> 0 | Q12: =N12-S12 -> 100 | R12: =Q12/S12 -> 0.11764706 | S12: 850 | T12: 954 | U12: 100% B6
B13: 4 | C13: 110000466 | D13: Hạt Nhựa rPET WSS05SB-2 | E13: Trong | F13: 0.50 ~ 0.60 | G13: =J13*1.05 -> 1050 | H13: 0.05 | I13: =G13-J13 -> 50 | J13: 1000 | K13: =N13*1.05 -> 1050 | L13: 0.05 | M13: =K13-N13 -> 50 | N13: 1000 | O13: =N13-J13 -> 0 | P13: =1-(J13/N13) -> 0 | Q13: =N13-S13 -> 150 | R13: =Q13/S13 -> 0.17647059 | S13: 850 | T13: ='Giải thích phó sản'!D11 -> #REF! | U13: 82%B6+18%B7 | V13: Vảy B6 mua Đại Lộc: 18.250, Bình B7 mua lavie : 8.550, Chai B5 mua trạm: 12.000:
B14: 5 | C14: 110000467 | D14: Hạt Nhựa rPET WSS05SB-3 | E14: Trong | F14: 0.50 ~ 0.60 | G14: 1050 | H14: 0.05 | I14: 50 | J14: 1050 | K14: =N14*1.05 -> 1102.5 | L14: 0.05 | M14: =K14-N14 -> 52.5 | N14: ='Giải thích phó sản'!F15 -> 1050 | O14: =N14-J14 -> 0 | P14: =1-(J14/N14) -> 0 | Q14: =N14-S14 -> 200 | R14: =Q14/S14 -> 0.23529412 | S14: 850 | T14: ='Giải thích phó sản'!D15 -> #REF! | U14: 90%B6+10%B5
B15: 6 | C15: 110000341 | D15: Hạt nhựa rHDB04B01 | E15: Đen | F15: 0.4 ± 0.1 | G15: 1102.5 | H15: 0.05 | I15: 52.5 | J15: 950 | K15: =N15*1.05 -> 997.5 | L15: 0.05 | M15: =K15-N15 -> 47.5 | N15: 950 | O15: =N15-J15 -> 0 | P15: =1-(J15/N15) -> 0 | Q15: =N15-S15 -> 10 | R15: =Q15/S15 -> 0.010638298 | S15: 940 | T15: =#REF! -> #REF! | U15: 80% PS hạt HD thổi lẫn màu/kim loại
B16: 7 | C16: 110000433 | D16: Hạt Nhựa rHDB03N03 | E16: Trong | F16: 0.3 ± 0.05 | G16: 997.5 | H16: 0.05 | I16: 47.5 | J16: 1100 | K16: =N16*1.05 -> 1155 | L16: 0.05 | M16: =K16-N16 -> 55 | N16: 1100 | O16: =N16-J16 -> 0 | P16: =1-(J16/N16) -> 0 | Q16: =N16-S16 -> 160 | R16: =Q16/S16 -> 0.17021277 | S16: 940 | T16: =#REF! -> #REF!
B17: 8 | C17: 110000431 | D17: Hạt Nhựa rHDI3Gy02 | E17: Xám | F17: 3.00 ± 2.00 | G17: 840 | H17: 0.05 | I17: 55 | J17: 800 | K17: =N17*1.05 -> 840 | L17: =M17/K17 -> 0.047619048 | M17: =K17-N17 -> 40 | N17: 800 | O17: =N17-J17 -> 0 | P17: =1-(J17/N17) -> 0 | Q17: =N17-S17 -> -140 | R17: =Q17/S17 -> -0.14893617 | S17: 940 | T17: =#REF! -> #REF!
B18: 9 | C18: 110000392 | D18: Hạt nhựa rPP20B01 | E18: Đen | F18: 20.00 ± 10.00 | G18: =J18*1.05 -> 735 | H18: =I18/G18 -> 0.047619048 | I18: =G18-J18 -> 35 | J18: 700 | K18: =N18*1.05 -> 735 | L18: =M18/K18 -> 0.047619048 | M18: =K18-N18 -> 35 | N18: 700 | O18: =N18-J18 -> 0 | P18: =1-(J18/N18) -> 0 | Q18: =N18-S18 -> -280 | R18: =Q18/S18 -> -0.28571429 | S18: 980
B21: Lưu ý:
B23: 1. Giá trên là giá xuất xưởng (EXW), nếu vận chuyển đến khách hàng thì cộng thêm phí vận chuyển
B24: 2. Ủy quyền cho GĐĐH duyệt theo đơn đặt hàng: biên độ +/-10% so với giá xuất xưởng DTR
R25: ='2. rPET- nội bộ '!S45 -> Ngày 03 tháng 02 năm 2024
B26: Chủ Tịch | D26: Giám Đốc Tài Chính | G26: Giám Đốc Điều Hành | I26: Giám Đốc Kinh Doanh | M26: Giám Đốc Tài Chính | P26: Kế Toán
B33: Trần Duy Hy | D33: Hoàng Thị Hồng Hạnh | G33: Huỳnh Ngọc Thạch | I33: Dương Từ Uyên Thảo | M33: Phạm Đình Hoàng | P33: Lưu Thị Minh Tâm

Sheet Giải thích phó sản
A2: 3. | B2: 110000436 | C2: Hạt nhựa rPET WSS05SB
C3: Công thức | D3: giá vốn | E3: Tỷ lệ lệnh SX | G3: Tỷ lệ LSX T6.24 | H3: giá BQ
C4: 100% B6 | D4: =+#REF! -> #REF! | E4: 0.7 | F4: =D4*1.05 -> #REF! | G4: 0.7 | H4: =D4*G4+D5*G5 -> #REF! | I4: Vảy B6: 18.250 đ
C5: 90% B8+ 10% B6 | D5: 740 | E5: 0.3 | G5: 0.3 | I5: Vảy B8: 12.232 đ
C6: 70% B6 + 30% bụi | D6: 689
A8: 4. | B8: 110000466 | C8: Hạt Nhựa rPET WSS05SB-2
C9: Công thức | D9: giá vốn
C10: 90%B8+ 10%B7 | D10: 738.78127 | E10: =D10*1.1 -> 812.6594 | F10: 820
B11: T8 | C11: 82%B6+18%B7 | D11: =+#REF! -> #REF! | E11: =D11*1.05 -> #REF! | F11: 980
A12: 5. | B12: 110000467 | C12: Hạt Nhựa rPET WSS05SB-3
C13: Công thức | D13: giá vốn
C14: 90%B8 + 10%B5 | D14: 761.92334 | E14: =D14*1.1 -> 838.11568 | F14: 850
B15: T8 | C15: 90%B6+10%B5 | D15: =+#REF! -> #REF! | E15: =D15*1.05 -> #REF! | F15: 1050
A16: 6. | B16: 110000341 | C16: Hạt nhựa rHDB04B01
C17: Công thức | D17: giá vốn
C18: Phó sản hạt HD thổi lẫn màu/kim loại (80%) + Vảy HD ép đen (20%) | D18: =#REF! -> #REF! | E18: =D18*1.1 -> #REF! | F18: 950
A20: 7. | B20: 110000433 | C20: Hạt Nhựa rHDB03N03
C21: Công thức | D21: giá vốn
C22: 50% HV01.4 + 50% HV-1.5 + 5% titan | D22: =#REF! -> #REF! | E22: =D22*1.1 -> #REF! | F22: 1100
C24: Nguồn gốc rHDB03N03
C25: 1. Hàng thấp cấp của MBF01
C26: 2. Xử lý PS - có Bom

Sheet Sheet2
B3: STT | C3: Mã sản phẩm | D3: Sản phẩm | E3: Màu | F3: IV/MI | G3: Gián bán đề xuất | H3: Giá vốn
B6: NHÓM KHÁCH HÀNG NỘI ĐỊA
B7: 6 | C7: 110000341 | D7: Hạt nhựa rHDB04B01 (80% Phó sản hạt HD thổi lẫn màu/kim loại + 20% Vảy HD ép đen) | E7: Đen | F7: 0.4 ± 0.1 | G7: 950 | H7: 855
B11: STT | C11: Mã sản phẩm | D11: Sản phẩm | E11: Màu | F11: IV/MI | G11: Giá Bán (1) | H11: % Chiết khấu (2) | I11: Chiết Khấu (3) | J11: Giá bán sau chiết khấu (4)=(1)-(3) | K11: Giá vốn | L11: Lời | M11: % LN | Q11: Công thức
B12: NHÓM KHÁCH HÀNG NỘI ĐỊA
B13: 1 | C13: 110000464 | D13: Hạt Nhựa rPET WSS06SP-1 | E13: Đục | F13: 0.40 ~ 0.50 | G13: =J13*1.05 -> 682.5 | H13: =I13/G13 -> 0.047619048 | I13: =G13-J13 -> 32.5 | J13: 650 | K13: =J13-#REF! -> #REF! | L13: =1-(#REF!/J13) -> #REF! | M13: =J13-O13 -> 650 | Q13: WSS006SP-1 (vảy PET tuyển nổi 2) | S13: =P13*25 -> 0
B14: 2 | C14: 110000465 | D14: Hạt Nhựa rPET WSS06SP-2 | E14: Trong | F14: 0.40 ~ 0.50 | G14: =J14*1.05 -> 787.5 | H14: =I14/G14 -> 0.047619048 | I14: =G14-J14 -> 37.5 | J14: 750 | K14: =J14-#REF! -> #REF! | L14: =1-(#REF!/J14) -> #REF! | M14: =J14-O14 -> 750 | Q14: WSS006SP-2 (bụi tank C,D đã gia công) | S14: =P14*25 -> 0
B15: 3 | C15: 110000436 | D15: Hạt nhựa rPET WSS05SB | E15: Trong | F15: 0.50 ~ 0.60 | G15: 1000 | H15: =I15/G15 -> -0.05 | I15: =G15-J15 -> -50 | J15: 1050 | K15: =J15-#REF! -> #REF! | L15: =1-(#REF!/J15) -> #REF! | M15: =J15-O15 -> 1050 | Q15: 100% B6
B16: 4 | C16: 110000466 | D16: Hạt Nhựa rPET WSS05SB-2 (82%B6+18%B7) | E16: Trong | F16: 0.50 ~ 0.60 | G16: =J16*1.05 -> 1050 | H16: 0.05 | I16: =G16-J16 -> 50 | J16: 1000 | K16: 940 | L16: =J16-K16 -> 60 | M16: =L16/K16 -> 0.063829787 | Q16: 82%B6+18%B7 | R16: Vảy B6 mua Đại Lộc: 18.250, Bình B7 mua lavie : 8.550, Chai B5 mua trạm: 12.000:
B17: 5 | C17: 110000467 | D17: Hạt Nhựa rPET WSS05SB-3 90%B6+10%B5 | E17: Trong | F17: 0.50 ~ 0.60 | G17: =J17*1.05 -> 1102.5 | H17: 0.05 | I17: =G17-J17 -> 52.5 | J17: 1050 | K17: 991.92267 | L17: =J17-K17 -> 58.077329 | M17: =L17/K17 -> 0.058550259 | Q17: 90%B6+10%B5
B18: 6 | C18: 110000341 | D18: Hạt nhựa rHDB04B01 80% PS hạt HD thổi lẫn màu/kim loại | E18: Đen | F18: 0.4 ± 0.1 | G18: =J18*1.05 -> 997.5 | H18: 0.05 | I18: =G18-J18 -> 47.5 | J18: 950 | K18: 855 | L18: =J18-K18 -> 95 | M18: =L18/K18 -> 0.11111111 | Q18: 80% PS hạt HD thổi lẫn màu/kim loại
B19: 7 | C19: 110000433 | D19: Hạt Nhựa rHDB03N03 (50% HV01.4 + 50% HV-1.5 + 5% titan) | E19: Trong | F19: 0.3 ± 0.05 | G19: =J19*1.05 -> 1155 | H19: 0.05 | I19: =G19-J19 -> 55 | J19: 1100 | K19: 1003 | L19: =J19-K19 -> 97 | M19: =L19/K19 -> 0.09670987
