Workbook
Name \T: #REF!
Name \T: #REF!
Name \T: #REF!
Name \T: #REF!
Name \T: #REF!
Name \T: #REF!
Name \T: #REF!
Name __dao1: #REF!
Name __dao2: #REF!
Name __dap2: #REF!
Name __day1: #REF!
Name __day2: #REF!
Name __dbu1: #REF!
Name __dbu2: #REF!
Name __doi3: #REF!
Name __E99999: #REF!
Name __Jan02: #REF!
Name __lap1: #REF!
Name __lap2: #REF!
Name __vc1: #REF!
Name __vc2: #REF!
Name __vc3: #REF!
Name _01_01_99: #REF!
Name _01_02_99: #REF!
Name _01_03_99: #REF!
Name _01_04_99: #REF!
Name _01_05_99: #REF!
Name _01_06_99: #REF!
Name _01_07_99: #REF!
Name _01_08_1999: #REF!
Name _1CAP002: #REF!
Name _2STREO7: #REF!
Name _4GOIC01: #REF!
Name _4OSLCTT: #REF!
Name _6BNTTTH: #REF!
Name _6DCTTBO: #REF!
Name _6DD24TT: #REF!
Name _6FCOTBU: #REF!
Name _6LATUBU: #REF!
Name _6SDTT24: #REF!
Name _6TBUDTT: #REF!
Name _6TDDDTT: #REF!
Name _6TLTTTH: #REF!
Name _6TUBUTT: #REF!
Name _6UCLVIS: #REF!
Name _7DNCABC: #REF!
Name _7HDCTBU: #REF!
Name _7PKTUBU: #REF!
Name _7TBHT20: #REF!
Name _7TBHT30: #REF!
Name _7TDCABC: #REF!
Name _dao1: #REF!
Name _dao2: #REF!
Name _dap2: #REF!
Name _day1: #REF!
Name _day2: #REF!
Name _dbu1: #REF!
Name _dbu2: #REF!
Name _doi3: #REF!
Name _E99999: #REF!

Sheet Ma trận PET
D3: MA TRẬN GIÁ BÁN rPET | AL3: 2023 | AX3: 2024 | BJ3: 2025 | ED3: 2023 | EH3: 07.02 | EI3: 14.02 | EJ3: 21.02 | EK3: 28.02 | EL3: 7.03 | EM3: 14.03 | EN3: 21.03 | EO3: 28.03 | EP3: 4.04 | EQ3: 11.04 | ER3: 18.04 | ES3: 25.04 | ET3: 2.05 | EU3: 9.05 | EV3: 16.05 | EW3: 23.05 | EX3: 30.05 | EY3: 6.06 | EZ3: 13.06 | FA3: 20.06 | GC3: 2024 | IA3: 2025
F4: Tỷ giá | I4: 23147 | J4: 23135 | K4: 23142 | L4: 23194 | M4: 23204 | N4: 23160 | O4: 23141 | P4: 23161 | Q4: 23161 | R4: 23123 | S4: 23156 | T4: 23126 | U4: 23180 | V4: 23108 | W4: =V4 -> 23108 | X4: =W4 -> 23108 | Y4: =X4 -> 23108 | Z4: 23150 | AA4: 23150 | AB4: 23150 | AC4: 23150 | AD4: 23500 | AE4: 23500 | AF4: 23500 | AG4: 23500 | AH4: 23500 | AI4: 23500 | AJ4: 24600 | AK4: 24000 | AL4: 24000 | AM4: 24000 | AN4: 24000 | AO4: 24000 | AP4: 24000 | AQ4: 24000 | AR4: 24000 | AS4: 24000 | AT4: 24000 | AU4: 24000 | AV4: 24000 | AW4: 24000 | AX4: 24000 | AY4: 24000 | AZ4: 24000 | BA4: 24000 | BB4: 24000 | BC4: 24000 | BD4: 24000 | BE4: 24000 | BF4: 24000 | BG4: 24000 | BH4: 24000 | BI4: 24000 | DA4: 23150 | DB4: 23150 | DC4: 23150 | DD4: 23150 | DE4: 23150 | DF4: 23150 | DG4: 23150 | DH4: 23150 | DI4: 23150 | DJ4: 23150 | DK4: 23150 | DL4: 23150 | DM4: 23500 | DN4: 23500 | DO4: 23500 | DP4: 23500 | DQ4: 23500 | DR4: 23500 | DS4: 23500 | DT4: 23500 | DU4: 24600 | DV4: 24600 | DW4: 24600 | DX4: 24600 | DY4: 24600 | DZ4: 24000 | EA4: 24000 | EB4: 24000 | EC4: 24000 | ED4: 24000 | EE4: 24000 | EF4: 24000 | EG4: 24000 | EH4: 24000 | EI4: 24000 | EJ4: 24000 | EK4: 24000 | EL4: 24000 | EM4: 24000 | EN4: 24000 | EO4: 24000 | EP4: 24000 | EQ4: 24000 | ER4: 24000 | ES4: 24000 | ET4: 24000 | EU4: 24000 | EV4: 24000 | EW4: 24000 | EX4: 24000 | EY4: 24000 | EZ4: 24000 | FA4: 24000 | FB4: 24000 | FC4: 24000 | FD4: 24000 | FE4: 24000 | FF4: 24000 | FG4: 24000 | FH4: 24000 | FI4: 24000 | FJ4: 24000 | FK4: 24000 | FL4: 24000 | FM4: 24000 | FN4: 24000 | FO4: 24000 | FP4: 24000 | FQ4: 24000 | FR4: 24000 | FS4: 24000 | FT4: 24000 | FU4: 24000 | FV4: 24000 | FW4: 24000 | FX4: 24000 | FY4: 24000 | FZ4: 24000 | GA4: 24000 | GB4: 24000 | GC4: 24000 | GD4: 24000 | GE4: 24000 | GF4: 24000 | GG4: 24000 | GH4: 24000 | GI4: 24000 | GJ4: 24000 | GK4: 24000 | GL4: 24000 | GM4: 24000 | GN4: 24000 | GO4: 24000 | GP4: 24000 | GQ4: 24000 | JZ4: 2026
A5: Stt | B5: Mã SAP | C5: Tên hàng hóa SAP | D5: Mã SP | E5: Tên sản phẩm | F5: Diễn giải | G5: Đơn vị tính | H5: Diễn giải | I5: T1.21 | J5: T2.21 | K5: T3.21 | L5: T4.21 | M5: T5.21 | N5: T6.21 | O5: T7.21 | P5: T8.21 | Q5: T9.21 | R5: T10.21 | S5: T11.21 | T5: T12.21 | U5: 1 | V5: 2 | W5: 3 | X5: 4 | Y5: 5 | Z5: 6 | AA5: 7 | AB5: 8 | AC5: Hiện tại 23/8 | AD5: 9 | AE5: 10 | AF5: 4/10 | AG5: 11/10 | AH5: 18/10 | AI5: 25/10 | AJ5: 11 | AK5: 12 | AL5: T1/23 | AM5: 2 | AN5: 3 | AO5: 4 | AP5: 5 | AQ5: 6 | AR5: 7 | AS5: 8 | AT5: 9 | AU5: 10 | AV5: 11 | AW5: 12 | AX5: T1.24 | AY5: 2 | AZ5: 3 | BA5: 4 | BB5: 5 | BC5: 6 | BD5: 7 | BE5: 8 | BF5: 9 | BG5: 10 | BH5: 11 | BI5: 12 | BJ5: T1.25 | BK5: 2 | BL5: 3 | BM5: 4 | BN5: 5 | BO5: 6 | BP5: 7 | BQ5: 8 | BR5: 9 | BS5: 10 | BT5: 11 | BU5: 12 | BV5: T1.26 | BW5: 2 | BX5: 3 | BY5: 4 | CA5: Mã SP | CB5: Tên sản phẩm | CC5: Diễn giải | CD5: 1 | CE5: =+CD5+1 -> 2 | CF5: =+CE5+1 -> 3 | CG5: =+CF5+1 -> 4 | CH5: =+CG5+1 -> 5 | CI5: =+CH5+1 -> 6 | CJ5: =+CI5+1 -> 7 | CK5: =+CJ5+1 -> 8 | CL5: =+CK5+1 -> 9 | ... CZ5: =+CY5+1 -> 23 | DA5: 24 | DB5: 25 | DC5: 26 | DD5: 27 | DE5: 28 | DF5: 29 | DG5: 30 | DH5: 31 | DI5: 32 | DJ5: 33 | DK5: 34 | DL5: 35 | DM5: 36 | DN5: 37 | DO5: 38 | DP5: 39 | DQ5: 40 | DR5: 41 | DS5: 42 | DT5: 43 | DU5: 44 | DV5: 45 | DW5: 46 | DX5: 47 | DY5: 48 | DZ5: 49 | EA5: 50 | EB5: 51 | EC5: 52 | ED5: 1 | EE5: 2 | EF5: 3 | EG5: 5 | EH5: 6 | EI5: 7 | EJ5: 8 | EK5: 9 | EL5: 10 | EM5: 11 | EN5: 12 | EO5: 13 | EP5: 14 | EQ5: 15 | ER5: 16 | ES5: 17 | ET5: 18 | EU5: 19 | EV5: 20 | EW5: 21 | EX5: 22 | EY5: 23 | EZ5: 24 | FA5: 25 | FB5: 26 | FC5: 27 | FD5: 28 | FE5: 29 | FF5: 30 | FG5: 31 | FH5: 32 | FI5: 33 | FJ5: 34 | FK5: 35 | FL5: 36 | FM5: 37 | FN5: 38 | FO5: 39 | FP5: 40 | FQ5: 41 | FR5: 42 | FS5: 43 | FT5: 44 | FU5: 45 | FV5: 46 | FW5: 47 | FX5: 48 | FY5: 49 | FZ5: 50 | GA5: 51 | GB5: 52 | GC5: 1/24 | GD5: 02 | GE5: 03 | GF5: 04 | GG5: 05 | GH5: 08 | GI5: 09 | GJ5: 10 | GK5: 11 | GL5: 12 | GM5: 13 | GN5: 14 | GO5: 15 | GP5: 16 | GQ5: 17 | GR5: 18 | GS5: 19 | GT5: 20 | GU5: 21 | GV5: 22 | GW5: 23 | GX5: 24 | GY5: 25 | GZ5: 26 | HA5: 27 | HB5: 28 | HC5: 29 | HD5: 30 | HE5: 31 | HF5: 32 | HG5: 33 | HH5: 34 | HI5: 35 | HJ5: 36 | HK5: 37 | HL5: 38 | HM5: 39 | HN5: 40 | HO5: 41 | HP5: 42 | HQ5: 43 | HR5: 44 | HS5: 45 | HT5: 46 | HU5: 47 | HV5: 48 | HW5: 49 | HX5: 50 | HY5: 51 | HZ5: 52 | IA5: 01 | IB5: 02 | IC5: 03 | ID5: 04 | IE5: 06 | IF5: 07 | IG5: 08 | IH5: 09 | II5: 10 | IJ5: 11 | IK5: 12 | IL5: 13 | IM5: 14 | IN5: 15 | IO5: 16 | IP5: 17 | IQ5: 18 | IR5: 19 | IS5: 20 | IT5: 21 | IU5: 22 | IV5: 23 | IW5: 24 | IX5: 25 | IY5: 26 | IZ5: 27 | JA5: 28 | JB5: 29 | JC5: 30 | JD5: 31 | JE5: 32 | JF5: 33 | JG5: 34 | JH5: 35 | JI5: 36 | JJ5: 37 | JK5: 38 | JL5: 39 | JM5: 40 | JN5: 41 | JO5: 42 | JP5: 43 | JQ5: 44 | JR5: 45 | JS5: 46 | JT5: 47 | JU5: 48 | JV5: 49 | JW5: 50 | JX5: 51 | JY5: 52 | JZ5: 01 | KA5: 02 | KB5: 03 | KC5: 04 | KD5: 05 | KE5: 06 | KF5: 07 | KG5: 08 | KH5: 09 | KI5: 10 | KJ5: 11 | KK5: 12 | KL5: 13
A6: 5 | B6: 110000329 | C6: Hạt rPET WSS01 | D6: WSS01G | E6: WSS01 - Hạt rPET (IV 0.78) | F6: DTR | G6: $ /tấn | H6: DTR | I6: =I7-20 -> 1230 | J6: =J7-20 -> 1230 | K6: =K7-20 -> 1230 | L6: =L7-20 -> 1230 | M6: =M7-20 -> 1230 | N6: =N7-20 -> 1230 | O6: =O7-20 -> 1250 | P6: =P7-20 -> 1250 | ... V6: =V7-20 -> 1300 | W6: 1450 | X6: 1550 | Y6: 1550 | Z6: 1550 | AA6: 1550 | AB6: 1480 | AC6: 1480 | AD6: =#REF!/AD4*1000 -> #REF! | AE6: =#REF!/AE4*1000 -> #REF! | AF6: =#REF!/AF4*1000 -> #REF! | AG6: =#REF!/AG4*1000 -> #REF! | AH6: =#REF!/AH4*1000 -> #REF! | AI6: =#REF!/AI4*1000 -> #REF! | AJ6: =#REF!/AJ4*1000 -> #REF! | AK6: 1330 | AL6: =+SUM(ED6:EG6)/4 -> 1330 | AM6: =+SUM(EH6:EK6)/4 -> 1330 | AN6: =+SUM(EL6:EN6)/COUNT(EL6:EN6) -> 1380 | AO6: =+SUM(EP6:ES6)/COUNT(EP6:ES6) -> 1380 | AP6: =+SUM(ET6:EX6)/COUNT(ET6:EX6) -> 1380 | AQ6: =+SUM(EY6:FB6)/COUNT(EY6:FB6) -> 1325 | AR6: =+SUM(FC6:FF6)/COUNT(FC6:FF6) -> 1275 | AS6: =FG6 -> 1250 | AT6: 1250 | AU6: 1250 | AV6: 1250 | AW6: 1250 | AX6: 1250 | AY6: 1250 | AZ6: 1250 | BA6: 1250 | BB6: 1300 | BC6: 1300 | BD6: 1300 | BE6: 1300 | BF6: 1310 | BG6: 1325 | BH6: 1325 | BI6: =1325-50 -> 1275 | BJ6: =1325-50-45 -> 1230 | BK6: =1325-50-45 -> 1230 | BL6: =1325-50-45 -> 1230 | BM6: =1325-50-45+20 -> 1250 | BN6: =1325-50-45+20 -> 1250 | BO6: =1325-50-45+20 -> 1250 | BP6: =1325-50-45+20 -> 1250 | BQ6: =1325-50-45+20-30 -> 1220 | BR6: =1325-50-45+20-30 -> 1220 | BS6: =1325-50-45+20-30-10 -> 1210 | BT6: =1325-50-45+20-30-10-10 -> 1200 | BU6: =1325-50-45+20-30-10-10 -> 1200 | BV6: =1325-50-45+20-30-10-10-40 -> 1160 | BW6: =1325-50-45+20-30-10-10-40 -> 1160 | BX6: 1160 | BY6: 1300 | CA6: WSS01/G | CB6: WSS01 - Hạt rPET (IV 0.78) | CC6: DTR | DA6: 1550 | DB6: 1550 | DC6: 1550 | DD6: 1550 | DE6: 1550 | DF6: 1550 | DG6: 1550 | DH6: 1480 | DI6: 1480 | DJ6: 1480 | DK6: 1480 | DL6: 1480 | DM6: 1410 | DN6: 1410 | DO6: 1410 | DP6: 1410 | DQ6: =#REF!/DQ4*1000 -> #REF! | DR6: =#REF!/DR4*1000 -> #REF! | DS6: =#REF!/DS4*1000 -> #REF! | DT6: =#REF!/DT4*1000 -> #REF! | DU6: 1380 | DV6: 1380 | DW6: 1380 | DX6: 1380 | DY6: 1380 | DZ6: 1380 | EA6: 1380 | EB6: 1330 | EC6: 1330 | ED6: 1330 | EE6: 1330 | EF6: 1330 | EG6: 1330 | EH6: 1330 | EI6: 1330 | EJ6: 1330 | EK6: 1330 | EL6: 1380 | EM6: 1380 | EN6: 1380 | EO6: 1380 | EP6: 1380 | EQ6: 1380 | ER6: 1380 | ES6: 1380 | ET6: 1380 | EU6: 1380 | EV6: 1380 | EW6: 1380 | EX6: 1380 | EY6: 1350 | EZ6: 1350 | FA6: 1300 | FB6: 1300 | FC6: 1300 | FD6: 1300 | FE6: 1250 | FF6: 1250 | FG6: 1250 | FH6: 1250 | FI6: 1250 | FJ6: 1250 | FK6: 1250 | FL6: 1250 | FM6: 1250 | FN6: 1250 | FO6: 1250 | FP6: 1250 | FQ6: 1250 | FR6: 1250 | FS6: 1250 | FT6: 1250 | FU6: 1250 | FV6: 1250 | FW6: 1250 | FX6: 1250 | FY6: 1250 | FZ6: 1250 | GA6: 1250 | GB6: 1250 | GC6: 1250 | GD6: 1250 | GE6: 1250 | GF6: 1250 | GG6: 1250 | GH6: 1250 | GI6: 1250 | GJ6: 1250 | GK6: 1250 | GL6: 1250 | GM6: 1250 | GN6: 1250 | GO6: 1250 | GP6: 1250 | GQ6: 1250 | GR6: 1300 | GS6: 1300 | GT6: 1300 | GU6: 1300 | GV6: 1300 | GW6: 1300 | GX6: 1300 | GY6: 1300 | GZ6: 1300 | HA6: 1300 | HB6: 1300 | HC6: 1300 | HD6: 1300 | HE6: 1300 | HF6: 1300 | HG6: 1300 | HH6: 1300 | HI6: 1300 | HJ6: 1310 | HK6: 1310 | HL6: 1310 | HM6: 1310 | HN6: 1325 | HO6: 1325 | HP6: 1325 | HQ6: 1325 | HR6: 1325 | HS6: 1325 | HT6: 1325 | HU6: 1325 | HV6: 1325 | HW6: =1325-50 -> 1275 | HX6: =HW6 -> 1275 | HY6: =HX6 -> 1275 | HZ6: =HY6 -> 1275 | IA6: 1230 | IB6: =IA6 -> 1230 | IC6: =IB6 -> 1230 | ID6: =IC6 -> 1230 | IE6: =ID6 -> 1230 | IF6: =IE6 -> 1230 | IG6: =IF6 -> 1230 | IH6: =IG6 -> 1230 | II6: =IH6 -> 1230 | ... IL6: =IK6 -> 1230 | IM6: =IL6+20 -> 1250 | IN6: =IM6 -> 1250 | IO6: =IN6 -> 1250 | IP6: =IO6 -> 1250 | IQ6: =IP6 -> 1250 | IR6: =IQ6 -> 1250 | IS6: =IR6 -> 1250 | IT6: =IS6 -> 1250 | IU6: =IT6 -> 1250 | IV6: 1223.0835 | IW6: 1225.2286 | IX6: 1219.8595 | IY6: 1219.0531 | IZ6: 1215.2889 | JA6: 1228.3131 | JB6: 1216.0902 | JC6: 1220.5682 | JD6: 1216.9073 | JE6: 1204.4734 | JF6: 1187.6814 | JG6: 1220 | JH6: =JG6 -> 1220 | JI6: =JH6 -> 1220 | JJ6: =JI6 -> 1220 | JK6: =JJ6 -> 1220 | JL6: =JK6 -> 1220 | JM6: 1210 | JN6: =JM6 -> 1210 | JO6: =JN6 -> 1210 | JP6: =JO6 -> 1210 | JQ6: 1210 | JR6: 1200 | JS6: 1200 | JT6: 1200 | JU6: 1200 | JV6: 1200 | JW6: 1200 | JX6: 1200 | JY6: 1200 | JZ6: 1160 | KA6: 1160 | KB6: 1160 | KC6: 1160 | KD6: 1160 | KE6: 1160 | KF6: 1160 | KG6: 1160 | KH6: 1160 | KI6: 1160 | KJ6: 1160 | KK6: =1160+50 -> 1210 | KL6: 1280
A7: 6 | B7: 110000329 | C7: Hạt rPET WSS01 | D7: WSS01/G | E7: WSS01 - Hạt rPET (IV 0.78) | F7: DTR-Giá WSS01 FOB-HCM (IV: 0,78+/- 0.02) | G7: $ /tấn | H7: DTR | I7: 1250 | J7: 1250 | K7: 1250 | L7: 1250 | M7: 1250 | N7: 1250 | O7: 1270 | P7: 1270 | Q7: 1270 | R7: 1270 | S7: 1320 | T7: 1320 | U7: 1320 | V7: 1320 | W7: =W6+20 -> 1470 | X7: =X6+20 -> 1570 | Y7: =Y6+20 -> 1570 | Z7: =Z6+20 -> 1570 | AA7: =AA6+20 -> 1570 | AB7: 1500 | AC7: =AC6+20 -> 1500 | AD7: =AD6+20 -> #REF! | AE7: =AE6+20 -> #REF! | AF7: =AF6+20 -> #REF! | AG7: =AG6+20 -> #REF! | AH7: =AH6+20 -> #REF! | AI7: =AI6+20 -> #REF! | AJ7: =AJ6+20 -> #REF! | AK7: =AK6+20 -> 1350 | AL7: =+SUM(ED7:EG7)/4 -> 1330 | AM7: =+SUM(EE7:EH7)/4 -> 1330 | AN7: =+SUM(EL7:EN7)/COUNT(EL7:EN7) -> 1380 | AO7: =+SUM(EP7:ES7)/COUNT(EP7:ES7) -> 1380 | AP7: =+SUM(ET7:EX7)/COUNT(ET7:EX7) -> 1380 | AQ7: =+SUM(EY7:FB7)/COUNT(EY7:FB7) -> 1325 | AR7: =+SUM(FC7:FF7)/COUNT(FC7:FF7) -> 1275 | AS7: =+SUM(FG7:FK7)/COUNT(FG7:FK7) -> 1250 | AT7: =FL7 -> 1250 | AU7: =FM7 -> 1250 | AV7: =FN7 -> 1250 | AW7: =FO7 -> 1250 | AX7: =FP7 -> 1250 | AY7: =FQ7 -> 1250 | AZ7: =FR7 -> 1250 | BA7: =FS7 -> 1250 | BB7: 1300 | BC7: 1300 | BD7: 1300 | BE7: 1300 | BF7: 1300 | BG7: 1300 | BH7: 1300 | BI7: 1300 | BJ7: 1300 | BK7: 1300 | BL7: 1300 | BM7: 1300 | BN7: 1300 | BO7: 1300 | BP7: 1300 | BQ7: 1300 | BR7: 1300 | BS7: 1300 | BT7: 1300 | BU7: 1300 | BV7: 1300 | BW7: 1300 | BX7: 1300 | BY7: 1300 | CA7: giá EXW | CB7: WSS01 - Hạt rPET (IV 0.78) | CC7: DTR | DA7: =DA6+20 -> 1570 | DB7: =DB6+20 -> 1570 | DC7: =DC6+20 -> 1570 | DD7: =DD6+20 -> 1570 | DE7: =DE6+20 -> 1570 | DF7: =DF6+20 -> 1570 | DG7: =DG6+20 -> 1570 | DH7: =DH6+20 -> 1500 | ... DT7: =DT6+20 -> #REF! | DU7: 1400 | DV7: 1400 | DW7: 1400 | DX7: 1400 | DY7: 1400 | DZ7: 1400 | EA7: 1400 | EB7: 1350 | EC7: 1350 | ED7: =ED6 -> 1330 | EE7: =EE6 -> 1330 | EF7: =EF6 -> 1330 | EG7: =EG6 -> 1330 | EH7: =EH6 -> 1330 | EI7: =EI6 -> 1330 | EJ7: =EJ6 -> 1330 | EK7: =EK6 -> 1330 | ... GA7: =GA6 -> 1250 | GB7: 1250 | GC7: 1250 | GD7: 1250 | GE7: 1250 | GF7: 1250 | GG7: 1250 | GH7: 1250 | GI7: 1250 | GJ7: 1250 | GK7: 1250 | GL7: 1250 | GM7: 1250 | GN7: 1250 | GO7: 1250 | GP7: 1250 | GQ7: 1250 | GR7: 1250 | GS7: 1250 | GT7: 1250 | GU7: 1250 | GV7: 1250 | GW7: 1250 | GX7: 1250 | GY7: 1250 | GZ7: 1250
A8: 7 | B8: 110000330 | C8: Hạt rPET SS01 | D8: ISS01/G | E8: SS01 - Hạt rPET (IV 0.82) | F8: DTR-Giá ISS01 FOB-HCM (IV: 0,82+/- 0.02) | G8: $ /tấn | H8: ISS01 (IV: 0,82+/- 0.02) | I8: =I7+30 -> 1280 | J8: =J7+30 -> 1280 | K8: =K7+30 -> 1280 | L8: =L7+30 -> 1280 | M8: =M7+30 -> 1280 | N8: =N7+30 -> 1280 | O8: =O7+30 -> 1300 | P8: =P7+30 -> 1300 | ... S8: =S7+30 -> 1350 | T8: =T7+50 -> 1370 | U8: =U7+50 -> 1370 | V8: =V7+50 -> 1370 | W8: =W7+100 -> 1570 | X8: =X7+100 -> 1670 | Y8: =Y7+100 -> 1670 | Z8: =Z7+80 -> 1650 | AA8: =AA7+80 -> 1650 | AB8: 1530 | AC8: 1530 | AD8: =#REF!/AD4*1000+20 -> #REF! | AE8: =#REF!/AE4*1000+20 -> #REF! | AF8: =#REF!/AF4*1000+20 -> #REF! | AG8: =#REF!/AG4*1000+20 -> #REF! | AH8: =#REF!/AH4*1000+20 -> #REF! | AI8: =#REF!/AI4*1000+20 -> #REF! | AJ8: =#REF!/AJ4*1000+20 -> #REF! | AK8: =#REF!/AK4*1000+20 -> #REF! | AL8: =#REF!/AL4*1000+20 -> #REF! | AM8: =+SUM(EH8:EK8)/4 -> 1397.5 | AN8: =+SUM(EL8:EN8)/COUNT(EL8:EN8) -> 1410 | AO8: =+SUM(EP8:ES8)/COUNT(EP8:ES8) -> 1410 | AP8: =+SUM(ET8:EX8)/COUNT(ET8:EX8) -> 1410 | AQ8: =+SUM(EY8:FB8)/COUNT(EY8:FB8) -> 1355 | AR8: =+SUM(FC8:FF8)/COUNT(FC8:FF8) -> 1305 | AS8: =+SUM(FG8:FK8)/COUNT(FG8:FK8) -> 1280 | AT8: =FL8 -> 1280 | AU8: =FM8 -> 1280 | AV8: =FN8 -> 1280 | AW8: =FO8 -> 1280 | AX8: =FP8 -> 1280 | AY8: =FQ8 -> 1280 | AZ8: =FR8 -> 1280 | BA8: =FS8 -> 1280 | ... BY8: =GQ8 -> 1280 | CA8: ISS01/G | CB8: SS01 - Hạt rPET (IV 0.82) | CC8: ISS01 (IV: 0,82+/- 0.02) | DA8: 1650 | DB8: 1650 | DC8: 1650 | DD8: 1650 | DE8: 1650 | DF8: 1650 | DG8: 1650 | DH8: 1530 | DI8: 1530 | DJ8: 1530 | DK8: 1530 | DL8: 1530 | DM8: 1460 | DN8: 1460 | DO8: 1460 | DP8: 1460 | DQ8: =#REF!/DQ4*1000+20 -> #REF! | DR8: =#REF!/DR4*1000+20 -> #REF! | DS8: =#REF!/DS4*1000+20 -> #REF! | DT8: =#REF!/DT4*1000+20 -> #REF! | DU8: 1410 | DV8: 1410 | DW8: 1410 | DX8: 1410 | DY8: 1410 | DZ8: 1410 | EA8: 1410 | EB8: 1410 | EC8: 1410 | ED8: 1410 | EE8: 1410 | EF8: 1410 | EG8: 1410 | EH8: 1410 | EI8: 1410 | EJ8: 1410 | EK8: =+EK7+30 -> 1360 | EL8: =+EL7+30 -> 1410 | EM8: =+EM7+30 -> 1410 | EN8: =+EN7+30 -> 1410 | EO8: =+EO7+30 -> 1410 | EP8: =+EP7+30 -> 1410 | EQ8: =+EQ7+30 -> 1410 | ER8: =+ER7+30 -> 1410 | ... GZ8: =+GZ7+30 -> 1280
D9: ẩn | F9: DTR-Giá FOB rPET ISS01 | G9: đồng /kg | H9: DTR-Giá FOB rPET ISS01 | V9: =V8*23108/1000 -> 31657.96 | W9: =W8*23108/1000 -> 36279.56 | X9: =X8*23108/1000 -> 38590.36 | Y9: =Y8*23108/1000 -> 38590.36 | Z9: =Z8*Z4/1000 -> 38197.5 | AC9: =AC8*AC4/1000 -> 35419.5 | AD9: =AD8*AD4/1000 -> #REF! | AE9: =AE8*AE4/1000 -> #REF! | AF9: =AF8*AF4/1000 -> #REF! | AG9: =AG8*AG4/1000 -> #REF! | AH9: =AH8*AH4/1000 -> #REF! | AI9: =AI8*AI4/1000 -> #REF! | AJ9: =AJ8*AJ4/1000 -> #REF! | ... AM9: =AM8*AM4/1000 -> 33540 | CA9: ẩn | CC9: DTR-Giá FOB rPET ISS01 | DQ9: =DQ8*DQ4/1000 -> #REF! | DR9: =DR8*DR4/1000 -> #REF! | DS9: =DS8*DS4/1000 -> #REF! | DT9: =DT8*DT4/1000 -> #REF! | DU9: 33135 | FA9: =+#REF!+30 -> #REF!
A11: 9 | D11: ICIS | E11: ICIS giá rPET ($ /tấn) | F11: ICIS FOB ĐNA - Giá trung bình | G11: $ /tấn | H11: ICIS | P11: 1300 | Q11: 1300 | R11: 1350 | S11: 1350 | T11: 1350 | U11: 1350 | V11: 1500 | W11: 1525 | X11: 1525 | Y11: 1550 | Z11: 1627 | AA11: 1585 | AB11: 1574 | AC11: 1485 | AD11: 1444 | AE11: 1425 | AF11: 1425 | AG11: 1425 | AH11: 1425 | AI11: =(1350+1500)/2 -> 1425 | AJ11: 1425 | AK11: 1330 | AL11: =+SUM(ED11:EG11)/4 -> 1287.5 | AM11: =+SUM(EH11:EK11)/4 -> 1313.75 | AN11: =+SUM(EL11:EN11)/COUNT(EL11:EN11) -> 1440 | AO11: =+SUM(EP11:ES11)/COUNT(EP11:ES11) -> 1440 | AP11: =+SUM(ET11:EX11)/COUNT(ET11:EX11) -> 1433 | AQ11: =+SUM(EY11:FB11)/COUNT(EY11:FB11) -> 1337.5 | AR11: =+SUM(FC11:FF11)/COUNT(FC11:FF11) -> 1317.5 | AS11: =+SUM(FG11:FK11)/COUNT(FG11:FK11) -> 1274 | AT11: =+SUM(FL11:FO11)/COUNT(FL11:FO11) -> 1288.75 | AU11: =+SUM(FP11:FS11)/COUNT(FP11:FS11) -> 1288.125 | AV11: =+SUM(FT11:FW11)/COUNT(FT11:FW11) -> 1300 | AW11: =+SUM(FX11:GB11)/COUNT(FX11:GB11) -> 1300 | AX11: =+SUM(GC11:GF11)/COUNT(GC11:GF11) -> 1312.5 | AY11: =+SUM(GG11:GI11)/COUNT(GG11:GI11) -> 1325 | AZ11: =+SUM(GJ11:GM11)/COUNT(GJ11:GM11) -> 1320 | BA11: =+SUM(GN11:GQ11)/COUNT(GN11:GQ11) -> 1323.75 | BB11: =+SUM(GR11:GV11)/COUNT(GR11:GV11) -> 1346.6 | BC11: =+SUM(GW11:GZ11)/COUNT(GW11:GZ11) -> 1365 | BD11: =+SUM(HA11:HD11)/COUNT(HA11:HD11) -> 1365 | BE11: =+SUM(HE11:HI11)/COUNT(HE11:HI11) -> 1404 | BF11: =+SUM(HJ11:HM11)/COUNT(HJ11:HM11) -> 1427.5 | BG11: =+SUM(HN11:HQ11)/COUNT(HN11:HQ11) -> 1440 | BH11: =+SUM(HR11:HV11)/COUNT(HR11:HV11) -> 1440 | BI11: =+SUM(HW11:HZ11)/COUNT(HW11:HZ11) -> 1421.25 | BJ11: =+SUM(IA11:ID11)/COUNT(IA11:ID11) -> 1368.75 | BK11: =+SUM(IE11:IH11)/COUNT(IE11:IH11) -> 1350 | BL11: =+SUM(II11:IL11)/COUNT(II11:IL11) -> 1360 | BM11: =+SUM(IM11:IP11)/COUNT(IM11:IP11) -> 1360 | BN11: =+SUM(IQ11:IU11)/COUNT(IQ11:IU11) -> 1360 | BO11: =+SUM(IV11:IY11)/COUNT(IV11:IY11) -> 1360 | BP11: =+SUM(IZ11:JD11)/COUNT(IZ11:JD11) -> 1324 | BQ11: =+SUM(JE11:JH11)/COUNT(JE11:JH11) -> 1295 | BR11: =+SUM(JI11:JL11)/COUNT(JI11:JL11) -> 1275 | BS11: =+SUM(JM11:JQ11)/COUNT(JM11:JQ11) -> 1248 | BT11: =+SUM(JR11:JU11)/COUNT(JR11:JU11) -> 1243.75 | BU11: =+SUM(JV11:JY11)/COUNT(JV11:JY11) -> 1193.75 | BV11: =+SUM(JZ11:KD11)/COUNT(JZ11:KD11) -> 1150 | BW11: =+SUM(KE11:KH11)/COUNT(KE11:KH11) -> 1150 | BX11: =+SUM(KI11:KL11)/COUNT(KI11:KL11) -> 1220 | BY11: 1300 | CA11: ICIS | CB11: ICIS giá rPET ($ /tấn) | CC11: ICIS | DA11: =+(1550+1670)/2 -> 1610 | DB11: =+(1550+1700)/2 -> 1625 | DC11: =+(1550+1650)/2 -> 1600 | DD11: =+(1550+1620)/2 -> 1585 | DE11: =+(1550+1650)/2 -> 1600 | DF11: =+(1550+1650)/2 -> 1600 | DG11: =+(1550+1650)/2 -> 1600 | DH11: =+(1550+1680)/2 -> 1615 | DI11: =+(1550+1680)/2 -> 1615 | DJ11: =+(1550+1620)/2 -> 1585 | DK11: =+(1550+1620)/2 -> 1585 | DL11: =+(1450+1520)/2 -> 1485 | DM11: =+(1350+1550)/2 -> 1450 | DN11: =+(1350+1550)/2 -> 1450 | DO11: =+(1350+1550)/2 -> 1450 | DP11: =+(1350+1550)/2 -> 1450 | DQ11: 1425 | DR11: 1425 | DS11: 1425 | DT11: =(1350+1500)/2 -> 1425 | DU11: 1350 | DV11: 1350 | DW11: =+(1250+1450)/2 -> 1350 | DX11: =+(1250+1450)/2 -> 1350 | DY11: =+(1250+1450)/2 -> 1350 | DZ11: =+(1250+1450)/2 -> 1350 | EA11: =+(1250+1450)/2 -> 1350 | EB11: =+(1250+1350)/2 -> 1300 | EC11: =+(1250+1350)/2 -> 1300 | ED11: =+(1250+1350)/2 -> 1300 | EE11: =+(1250+1350)/2 -> 1300 | EF11: =+(1250+1300)/2 -> 1275 | EG11: =+(1250+1300)/2 -> 1275 | EH11: =+(1250+1300)/2 -> 1275 | EI11: =+(1250+1300)/2 -> 1275 | EJ11: =+(1280+1350)/2 -> 1315 | EK11: =+(1350+1430)/2 -> 1390 | EL11: =+(1350+1530)/2 -> 1440 | EM11: =+(1350+1530)/2 -> 1440 | EN11: =+(1350+1530)/2 -> 1440 | EO11: =+(1350+1530)/2 -> 1440 | EP11: =+(1350+1530)/2 -> 1440 | EQ11: =+(1350+1530)/2 -> 1440 | ER11: =+(1350+1530)/2 -> 1440 | ES11: =+(1350+1530)/2 -> 1440 | ... EW11: =+(1350+1530)/2 -> 1440 | EX11: =+(1350+1460)/2 -> 1405 | EY11: =+(1350+1400)/2 -> 1375 | EZ11: =+(1300+1350)/2 -> 1325 | FA11: =+(1300+1350)/2 -> 1325 | FB11: =+(1300+1350)/2 -> 1325 | FC11: =+(1300+1350)/2 -> 1325 | FD11: =+(1300+1350)/2 -> 1325 | FE11: =+(1270+1350)/2 -> 1310 | FF11: =+(1270+1350)/2 -> 1310 | FG11: =+(1200+1300)/2 -> 1250 | FH11: =+(1200+1320)/2 -> 1260 | FI11: =+(1200+1320)/2 -> 1260 | FJ11: =+(1250+1350)/2 -> 1300 | FK11: =+(1250+1350)/2 -> 1300 | FL11: =+(1250+1330)/2 -> 1290 | FM11: =+(1250+1330)/2 -> 1290 | FN11: =+(1250+1330)/2 -> 1290 | FO11: 1285 | FP11: 1285 | FQ11: 1287.5 | FR11: 1280 | FS11: 1300 | FT11: 1300 | FU11: 1300 | FV11: 1300 | FW11: 1300 | FX11: 1300 | FY11: 1300 | FZ11: 1300 | GA11: 1300 | GB11: 1300 | GC11: 1300 | GD11: 1300 | GE11: 1325 | GF11: 1325 | GG11: 1325 | GH11: 1325 | GI11: 1325 | GJ11: 1325 | GK11: 1325 | GL11: 1315 | GM11: 1315 | GN11: 1325 | GO11: 1325 | GP11: 1325 | GQ11: 1320 | GR11: 1333 | GS11: 1350 | GT11: 1350 | GU11: 1350 | GV11: 1350 | GW11: 1365 | GX11: 1365 | GY11: 1365 | GZ11: 1365 | HA11: 1365 | HB11: 1365 | HC11: 1365 | HD11: 1365 | HE11: 1400 | HF11: 1400 | HG11: 1400 | HH11: 1410 | HI11: 1410 | HJ11: 1430 | HK11: 1430 | HL11: 1425 | HM11: 1425 | HN11: 1440 | HO11: 1440 | HP11: 1440 | HQ11: 1440 | HR11: 1440 | HS11: 1440 | HT11: 1440 | HU11: 1440 | HV11: 1440 | HW11: 1430 | HX11: 1430 | HY11: 1425 | HZ11: 1400 | IA11: 1400 | IB11: 1375 | IC11: 1350 | ID11: 1350 | IE11: 1350 | IF11: 1350 | IG11: 1350 | IH11: 1350 | II11: 1360 | IJ11: 1360 | IK11: 1360 | IL11: 1360 | IM11: 1360 | IN11: 1360 | IO11: 1360 | IP11: 1360 | IQ11: 1360 | IR11: 1360 | IS11: 1360 | IT11: 1360 | IU11: 1360 | IV11: 1360 | IW11: 1360 | IX11: 1360 | IY11: 1360 | IZ11: 1360 | JA11: 1360 | JB11: 1300 | JC11: 1300 | JD11: 1300 | JE11: 1300 | JF11: 1300 | JG11: 1290 | JH11: 1290 | JI11: 1290 | JJ11: 1290 | JK11: 1260 | JL11: 1260 | JM11: 1240 | JN11: 1250 | JO11: 1250 | JP11: 1250 | JQ11: 1250 | JR11: 1250 | JS11: 1250 | JT11: 1250 | JU11: 1225 | JV11: 1225 | JW11: 1200 | JX11: 1200 | JY11: 1150 | JZ11: 1150 | KA11: 1150 | KB11: 1150 | KC11: 1150 | KD11: 1150 | KE11: 1150 | KF11: 1150 | KG11: 1150 | KH11: 1150 | KI11: 1175 | KJ11: 1185 | KK11: 1220 | KL11: 1300
A12: 9 | D12: ICIS | E12: ICIS giá rPET ($ /tấn) | F12: ICIS FOB ĐNA - Giá Cao | G12: $ /tấn | H12: ICIS FOB ĐNA - Giá Cao | P12: 1400 | Q12: 1500 | R12: 1500 | S12: 1500 | T12: 1500 | U12: 1500 | V12: 1650 | W12: 1650 | X12: 1650 | Y12: 1650 | Z12: 1800 | AA12: 1700 | AB12: 1610 | AC12: 1520 | AD12: 1538 | AE12: 1550 | AF12: 1500 | AG12: 1500 | AH12: 1500 | AI12: 1500 | AJ12: 1500 | AK12: 1410 | AL12: =+SUM(ED12:EG12)/4 -> 1325 | AM12: =+SUM(EH12:EK12)/4 -> 1345 | AN12: =+SUM(EL12:EN12)/COUNT(EL12:EN12) -> 1530 | AO12: =+SUM(EP12:ES12)/COUNT(EP12:ES12) -> 1530 | AP12: =+SUM(ET12:EX12)/COUNT(ET12:EX12) -> 1516 | AQ12: =+SUM(EY12:FB12)/COUNT(EY12:FB12) -> 1362.5 | AR12: =+SUM(FC12:FF12)/COUNT(FC12:FF12) -> 1350 | AS12: =+SUM(FG12:FK12)/COUNT(FG12:FK12) -> 1328 | AT12: =+SUM(FL12:FO12)/COUNT(FL12:FO12) -> 1327.5 | AU12: =+SUM(FP12:FS12)/COUNT(FP12:FS12) -> 1326.25 | AV12: =+SUM(FT12:FW12)/COUNT(FT12:FW12) -> 1350 | AW12: =+SUM(FX12:GB12)/COUNT(FX12:GB12) -> 1350 | AX12: =+SUM(GC12:GF12)/COUNT(GC12:GF12) -> 1375 | AY12: =+SUM(GG12:GI12)/COUNT(GG12:GI12) -> 1400 | AZ12: =+SUM(GJ12:GM12)/COUNT(GJ12:GM12) -> 1390 | BA12: =+SUM(GN12:GQ12)/COUNT(GN12:GQ12) -> 1397.5 | BB12: =+SUM(GR12:GV12)/COUNT(GR12:GV12) -> 1399.2 | BC12: =+SUM(GW12:GZ12)/COUNT(GW12:GZ12) -> 1455 | BD12: =+SUM(HA12:HD12)/COUNT(HA12:HD12) -> 1455 | BE12: =+SUM(HE12:HI12)/COUNT(HE12:HI12) -> 1504 | BF12: =+SUM(HJ12:HM12)/COUNT(HJ12:HM12) -> 1550 | BG12: =+SUM(HN12:HQ12)/COUNT(HN12:HQ12) -> 1580 | BH12: =+SUM(HR12:HV12)/COUNT(HR12:HV12) -> 1580 | BI12: =+SUM(HW12:HZ12)/COUNT(HW12:HZ12) -> 1555 | BJ12: =+SUM(IA12:ID12)/COUNT(IA12:ID12) -> 1512.5 | BK12: =+SUM(IE12:IH12)/COUNT(IE12:IH12) -> 1500 | BL12: =+SUM(II12:IL12)/COUNT(II12:IL12) -> 1500 | BM12: =+SUM(IM12:IP12)/COUNT(IM12:IP12) -> 1500 | BN12: =+SUM(IQ12:IU12)/COUNT(IQ12:IU12) -> 1500 | BO12: =+SUM(IV12:IY12)/COUNT(IV12:IY12) -> 1500 | BP12: =+SUM(IZ12:JD12)/COUNT(IZ12:JD12) -> 1440 | BQ12: =+SUM(JE12:JH12)/COUNT(JE12:JH12) -> 1390 | BR12: =+SUM(JI12:JL12)/COUNT(JI12:JL12) -> 1350 | BS12: =+SUM(JM12:JQ12)/COUNT(JM12:JQ12) -> 1344 | BT12: =+SUM(JR12:JU12)/COUNT(JR12:JU12) -> 1350 | BU12: =+SUM(JV12:JY12)/COUNT(JV12:JY12) -> 1300 | BV12: =+SUM(JZ12:KD12)/COUNT(JZ12:KD12) -> 1250 | BW12: =+SUM(KE12:KH12)/COUNT(KE12:KH12) -> 1250 | BX12: =+SUM(KI12:KL12)/COUNT(KI12:KL12) -> 1312.5 | BY12: 1400 | CA12: ICIS | CB12: ICIS giá rPET ($ /tấn) | CC12: ICIS FOB ĐNA - Giá Cao | DA12: 1670 | DB12: 1700 | DC12: 1650 | DD12: 1620 | DE12: 1650 | DF12: 1650 | DG12: 1650 | DH12: 1680 | DI12: 1680 | DJ12: 1620 | DK12: 1620 | DL12: 1520 | DM12: 1550 | DN12: 1550 | DO12: 1550 | DP12: 1550 | DQ12: 1500 | DR12: 1500 | DS12: 1500 | DT12: 1500 | DU12: 1450 | DV12: 1450 | DW12: 1450 | DX12: 1450 | DY12: 1450 | DZ12: 1450 | EA12: 1450 | EB12: 1350 | EC12: 1350 | ED12: 1350 | EE12: 1350 | EF12: 1300 | EG12: 1300 | EH12: 1300 | EI12: 1300 | EJ12: 1350 | EK12: 1430 | EL12: 1530 | EM12: 1530 | EN12: 1530 | EO12: 1530 | EP12: 1530 | EQ12: 1530 | ER12: 1530 | ES12: 1530 | ET12: 1530 | EU12: 1530 | EV12: 1530 | EW12: 1530 | EX12: 1460 | EY12: 1400 | EZ12: 1350 | FA12: 1350 | FB12: 1350 | FC12: 1350 | FD12: 1350 | FE12: 1350 | FF12: 1350 | FG12: 1300 | FH12: 1320 | FI12: 1320 | FJ12: 1350 | FK12: 1350 | FL12: 1330 | FM12: 1330 | FN12: 1330 | FO12: 1320 | FP12: 1320 | FQ12: 1325 | FR12: 1310 | FS12: 1350 | FT12: 1350 | FU12: 1350 | FV12: 1350 | FW12: 1350 | FX12: 1350 | FY12: 1350 | FZ12: 1350 | GA12: 1350 | GB12: 1350 | GC12: 1350 | GD12: 1350 | GE12: 1400 | GF12: 1400 | GG12: 1400 | GH12: 1400 | GI12: 1400 | GJ12: 1400 | GK12: 1400 | GL12: 1380 | GM12: 1380 | GN12: 1400 | GO12: 1400 | GP12: 1400 | GQ12: 1390 | GR12: 1396 | GS12: 1400 | GT12: 1400 | GU12: 1400 | GV12: 1400 | GW12: 1455 | GX12: 1455 | GY12: 1455 | GZ12: 1455 | HA12: 1455 | HB12: 1455 | HC12: 1455 | HD12: 1455 | HE12: 1500 | HF12: 1500 | HG12: 1500 | HH12: 1510 | HI12: 1510 | HJ12: 1550 | HK12: 1550 | HL12: 1550 | HM12: 1550 | HN12: 1580 | HO12: 1580 | HP12: 1580 | HQ12: 1580 | HR12: 1580 | HS12: 1580 | HT12: 1580 | HU12: 1580 | HV12: 1580 | HW12: 1560 | HX12: 1560 | HY12: 1550 | HZ12: 1550 | IA12: 1550 | IB12: 1500 | IC12: 1500 | ID12: 1500 | IE12: 1500 | IF12: 1500 | IG12: 1500 | IH12: 1500 | II12: 1500 | IJ12: 1500 | IK12: 1500 | IL12: 1500 | IM12: 1500 | IN12: 1500 | IO12: 1500 | IP12: 1500 | IQ12: 1500 | IR12: 1500 | IS12: 1500 | IT12: 1500 | IU12: 1500 | IV12: 1500 | IW12: 1500 | IX12: 1500 | IY12: 1500 | IZ12: 1500 | JA12: 1500 | JB12: 1400 | JC12: 1400 | JD12: 1400 | JE12: 1400 | JF12: 1400 | JG12: 1380 | JH12: 1380 | JI12: 1380 | JJ12: 1380 | JK12: 1320 | JL12: 1320 | JM12: 1320 | JN12: 1350 | JO12: 1350 | JP12: 1350 | JQ12: 1350 | JR12: 1350 | JS12: 1350 | JT12: 1350 | JU12: 1350 | JV12: 1350 | JW12: 1300 | JX12: 1300 | JY12: 1250 | JZ12: 1250 | KA12: 1250 | KB12: 1250 | KC12: 1250 | KD12: 1250 | KE12: 1250 | KF12: 1250 | KG12: 1250 | KH12: 1250 | KI12: 1250 | KJ12: 1270 | KK12: 1330 | KL12: 1400
D13: Anh 12 | F13: FENC_FOB TAIWAN BÁN CHO UNILEVER | G13: $ /tấn | H13: FENC_BÁN CHO UNILEVER | R13: 1290 | S13: 1290 | T13: 1290 | U13: 1205 | V13: 1205 | W13: 1542 | X13: 1542 | Y13: 1542 | Z13: 1755 | AA13: 1755 | AB13: 1755 | AC13: 1755 | AD13: 1755 | AE13: 1718 | AF13: 1718 | AG13: 1718 | AH13: 1718 | AI13: 1718 | AJ13: 1718 | AK13: 1718 | AL13: =+SUM(ED13:EG13)/4 -> 1640.75 | AM13: =+SUM(EH13:EK13)/4 -> 1615 | AN13: =+SUM(EL13:EN13)/COUNT(EL13:EN13) -> 1615 | BO13: =+SUM(IV13:IY13)/COUNT(IV13:IY13) -> #DIV/0! | BP13: =+SUM(IZ13:JD13)/COUNT(IZ13:JD13) -> #DIV/0! | BQ13: =+SUM(JE13:JH13)/COUNT(JE13:JH13) -> #DIV/0! | BR13: =+SUM(JI13:JL13)/COUNT(JI13:JL13) -> #DIV/0! | BS13: =+SUM(JM13:JQ13)/COUNT(JM13:JQ13) -> #DIV/0! | BT13: =+SUM(JR13:JU13)/COUNT(JR13:JU13) -> #DIV/0! | BU13: =+SUM(JV13:JY13)/COUNT(JV13:JY13) -> #DIV/0! | BV13: =+SUM(JZ13:KD13)/COUNT(JZ13:KD13) -> #DIV/0! | BW13: =+SUM(KE13:KH13)/COUNT(KE13:KH13) -> #DIV/0! | BX13: =+SUM(KI13:KL13)/COUNT(KI13:KL13) -> #DIV/0! | CA13: Anh 12 | CC13: FENC_BÁN CHO UNILEVER | DA13: 1755 | DB13: 1755 | DC13: 1755 | DD13: 1755 | DE13: 1755 | DF13: 1755 | DG13: 1755 | DH13: 1755 | DI13: 1755 | DJ13: 1755 | DK13: 1755 | DL13: 1718 | DM13: 1718 | DN13: 1718 | DO13: 1718 | DP13: 1718 | DQ13: 1718 | DR13: 1718 | DS13: 1718 | DT13: 1718 | DU13: 1718 | DV13: 1718 | DW13: 1718 | DX13: 1718 | DY13: 1718 | DZ13: 1718 | EA13: 1718 | EB13: 1718 | EC13: 1718 | ED13: 1718 | EE13: 1615 | EF13: 1615 | EG13: 1615 | EH13: 1615 | EI13: 1615 | EJ13: 1615 | EK13: 1615 | EL13: 1615 | EM13: 1615 | EN13: 1615 | EO13: 1615
D14: Anh 12 | F14: RESIN | G14: $ /tấn | H14: RESIN | S14: 1190 | T14: 1150 | U14: 1165 | V14: 1272.5 | W14: 1346 | X14: 1297.5 | Y14: 1316.6667 | Z14: 1390 | AA14: 1220 | AB14: 1270 | AC14: 1190 | AD14: 1190 | AE14: 1130 | AF14: 1100 | AG14: 1100 | AH14: 1070 | AI14: 1040 | AJ14: 1040 | AK14: =+SUM(DZ14:EC14)/4 -> 977.5 | AL14: =+SUM(ED14:EG14)/4 -> 1000 | AM14: =+SUM(EH14:EK14)/4 -> 1045 | AN14: =+SUM(EL14:EN14)/COUNT(EL14:EN14) -> 1020 | AO14: =+SUM(EP14:ES14)/COUNT(EP14:ES14) -> 1055 | AP14: =+SUM(ET14:EX14)/COUNT(ET14:EX14) -> 974 | AQ14: =+SUM(EY14:FB14)/COUNT(EY14:FB14) -> 895 | AR14: =+SUM(FC14:FF14)/COUNT(FC14:FF14) -> 903 | AS14: =+SUM(FG14:FK14)/COUNT(FG14:FK14) -> 918 | AT14: =+SUM(FL14:FO14)/COUNT(FL14:FO14) -> 930 | AU14: =+SUM(FP14:FS14)/COUNT(FP14:FS14) -> 922.5 | AV14: =+SUM(FT14:FW14)/COUNT(FT14:FW14) -> 900 | AW14: =+SUM(FX14:GB14)/COUNT(FX14:GB14) -> 900 | AX14: =+SUM(GC14:GF14)/COUNT(GC14:GF14) -> 930 | AY14: =+SUM(GG14:GI14)/COUNT(GG14:GI14) -> 943.33333 | AZ14: =+SUM(GJ14:GM14)/COUNT(GJ14:GM14) -> 940 | BA14: =+SUM(GN14:GQ14)/COUNT(GN14:GQ14) -> 940 | BB14: =+SUM(GR14:GV14)/COUNT(GR14:GV14) -> 942 | BC14: =+SUM(GW14:GZ14)/COUNT(GW14:GZ14) -> 950 | BD14: =+SUM(HA14:HD14)/COUNT(HA14:HD14) -> 947.5 | BE14: =+SUM(HE14:HI14)/COUNT(HE14:HI14) -> 930 | BF14: =+SUM(HJ14:HM14)/COUNT(HJ14:HM14) -> 880 | BG14: =+SUM(HN14:HQ14)/COUNT(HN14:HQ14) -> 862.5 | BH14: =+SUM(HR14:HV14)/COUNT(HR14:HV14) -> 852 | BI14: =+SUM(HW14:HZ14)/COUNT(HW14:HZ14) -> 830 | BJ14: =+SUM(IA14:ID14)/COUNT(IA14:ID14) -> 827.5 | BK14: =+SUM(IE14:IH14)/COUNT(IE14:IH14) -> 840 | BL14: =+SUM(II14:IL14)/COUNT(II14:IL14) -> 822.5 | BM14: =+SUM(IM14:IP14)/COUNT(IM14:IP14) -> 765 | BN14: =+SUM(IQ14:IU14)/COUNT(IQ14:IU14) -> 782 | BO14: =+SUM(IV14:IY14)/COUNT(IV14:IY14) -> 807.5 | BP14: =+SUM(IZ14:JD14)/COUNT(IZ14:JD14) -> 802 | BQ14: =+SUM(JE14:JH14)/COUNT(JE14:JH14) -> 795 | BR14: =+SUM(JI14:JL14)/COUNT(JI14:JL14) -> 782.5 | BS14: =+SUM(JM14:JQ14)/COUNT(JM14:JQ14) -> 772 | BT14: =+SUM(JR14:JU14)/COUNT(JR14:JU14) -> 770 | BU14: =+SUM(JV14:JY14)/COUNT(JV14:JY14) -> 772.5 | BV14: =+SUM(JZ14:KD14)/COUNT(JZ14:KD14) -> 805 | BW14: =+SUM(KE14:KH14)/COUNT(KE14:KH14) -> 840 | BX14: =+SUM(KI14:KL14)/COUNT(KI14:KL14) -> 1108.75 | BY14: 1140 | CA14: Anh 12 | CC14: RESIN | DA14: =+(1400+1430)/2 -> 1415 | DB14: =+(1380+1410)/2 -> 1395 | DC14: =+(1360+1390)/2 -> 1375 | DD14: =+(1320+1350)/2 -> 1335 | DE14: =+(1230+1270)/2 -> 1250 | DF14: =+(1210+1250)/2 -> 1230 | DG14: =+(1200+1240)/2 -> 1220 | DH14: =+(1230+1270)/2 -> 1250 | DI14: =+(1230+1270)/2 -> 1250 | DJ14: =+(1200+1240)/2 -> 1220 | DK14: =+(1170+1210)/2 -> 1190 | DL14: =+(1140+1180)/2 -> 1160 | DM14: =+(1140+1180)/2 -> 1160 | DN14: =+(1140+1180)/2 -> 1160 | DO14: =+(1110+1150)/2 -> 1130 | DP14: =+(1110+1150)/2 -> 1130 | DQ14: 1100 | DR14: 1100 | DS14: 1070 | DT14: 1040 | DU14: 995 | DV14: 980 | DW14: =+(960+1000)/2 -> 980 | DX14: =+(960+1000)/2 -> 980 | DY14: =+(940+1000)/2 -> 970 | DZ14: =+(940+1000)/2 -> 970 | EA14: =+(940+1000)/2 -> 970 | EB14: =+(960+1000)/2 -> 980 | EC14: =+(970+1010)/2 -> 990 | ED14: 970 | EE14: 980 | EF14: 990 | EG14: 1060 | EH14: 1070 | EI14: 1070 | EJ14: 1020 | EK14: 1020 | EL14: 1020 | EM14: 1020 | EN14: 1020 | EO14: 1020 | EP14: 1050 | EQ14: 1070 | ER14: 1050 | ES14: 1050 | ET14: 1020 | EU14: 1000 | EV14: 980 | EW14: 960 | EX14: 910 | EY14: 910 | EZ14: 890 | FA14: 890 | FB14: 890 | FC14: 890 | FD14: 882 | FE14: 920 | FF14: 920 | FG14: 940 | FH14: 920 | FI14: 910 | FJ14: 910 | FK14: 910 | FL14: 910 | FM14: 930 | FN14: 940 | FO14: 940 | FP14: 940 | FQ14: 930 | FR14: 920 | FS14: 900 | FT14: 900 | FU14: 900 | FV14: 900 | FW14: 900 | FX14: 900 | FY14: 900 | FZ14: 900 | GA14: 900 | GB14: 900 | GC14: 900 | GD14: 940 | GE14: 940 | GF14: 940 | GG14: 950 | GH14: 940 | GI14: 940 | GJ14: 940 | GK14: 940 | GL14: 940 | GM14: 940 | GN14: 940 | GO14: 940 | GP14: 940 | GQ14: 940 | GR14: 940 | GS14: 940 | GT14: 940 | GU14: 940 | GV14: 950 | GW14: 950 | GX14: 950 | GY14: 950 | GZ14: 950 | HA14: 950 | HB14: 950 | HC14: 950 | HD14: 940 | HE14: 940 | HF14: 940 | HG14: 940 | HH14: 930 | HI14: 900 | HJ14: 900 | HK14: 890 | HL14: 870 | HM14: 860 | HN14: 860 | HO14: 860 | HP14: 870 | HQ14: 860 | HR14: 860 | HS14: 860 | HT14: 860 | HU14: 840 | HV14: 840 | HW14: 840 | HX14: 830 | HY14: 830 | HZ14: 820 | IA14: 820 | IB14: 820 | IC14: 820 | ID14: 850 | IE14: 840 | IF14: 840 | IG14: 840 | IH14: 840 | II14: 840 | IJ14: 830 | IK14: 810 | IL14: 810 | IM14: 800 | IN14: 750 | IO14: 750 | IP14: 760 | IQ14: 760 | IR14: 760 | IS14: 800 | IT14: 800 | IU14: 790 | IV14: 800 | IW14: 790 | IX14: 820 | IY14: 820 | IZ14: 820 | JA14: 820 | JB14: 790 | JC14: 790 | JD14: 790 | JE14: 800 | JF14: 790 | JG14: 790 | JH14: 800 | JI14: 790 | JJ14: 780 | JK14: 780 | JL14: 780 | JM14: 780 | JN14: 780 | JO14: 770 | JP14: 760 | JQ14: 770 | JR14: 770 | JS14: 770 | JT14: 770 | JU14: 770 | JV14: 770 | JW14: 770 | JX14: 770 | JY14: 780 | JZ14: 795 | KA14: 795 | KB14: 795 | KC14: 820 | KD14: 820 | KE14: 840 | KF14: 840 | KG14: 840 | KH14: 840 | KI14: =(900+970)/2 -> 935 | KJ14: 1080 | KK14: 1280 | KL14: 1140
F15: ICIS Thị trường Mỹ (FOB) | H15: x | CC15: ICIS Bờ Tây Mỹ (FOB) | DH15: 2502.24 | DI15: 2502.24 | DJ15: 2502.24 | DK15: 2259.74 | DL15: 2259.74 | DM15: 2259.74 | DN15: 1918.02 | DO15: 1918.02 | DP15: 1918.02 | DQ15: 1587.33 | DR15: 1587.33 | DS15: 1587.33 | DT15: 1587.33 | DU15: 1587.33 | DV15: 1587.33 | DW15: 1587.33 | DX15: 1587.33 | DY15: 1477.1 | DZ15: 1477.1 | EA15: 1477.1 | EB15: 1477.1 | EC15: 1477.1 | ED15: 1543.23 | EE15: 1543.234 | EF15: 1543.234 | EG15: 1543.234 | EH15: 1543.234 | EI15: 1543.234 | EJ15: 1543.234 | EK15: 1543.234 | EL15: 1543.234 | EM15: 1543.234 | EN15: 1543.234 | EO15: 1543.234 | EP15: 1543.234 | EQ15: 1543.234 | ER15: 1543.234 | ES15: 1543.234 | ET15: 1543.234 | EU15: 1543.234 | EV15: 1543.234 | EW15: 1521.188 | EX15: 1521.188 | EY15: 1521.188 | EZ15: 1521.188 | FA15: 1521.188 | FB15: 1521.188 | FC15: 1521.188 | FD15: 1521.188 | FE15: 1521.188 | FF15: 1521.188 | FG15: 1521.188 | FH15: 1521.188 | FI15: 1521.188 | FJ15: 1521.188 | FK15: 1521.188 | FL15: 1521.188 | FM15: 1521.188 | FN15: 1521.188 | FO15: 1521.188 | FP15: 1521.188 | FQ15: 1521.188 | FR15: 1521.188 | FS15: 1521.188 | FT15: 1521.188 | FU15: 1521.188 | FV15: 1521.188 | FW15: 1521.188 | FX15: 1521.188 | FY15: 1521.188 | FZ15: 1521.188 | GA15: 1521.188 | GB15: 1521.188 | GC15: 1521.188 | GD15: 1521.188 | GE15: 1521.188 | GF15: 1521.188 | GG15: 1521.188 | GH15: 1521.188 | GI15: 1521.188 | GJ15: 1521.188 | GK15: 1521.188 | GL15: 1521.188 | GM15: 1521.188 | GN15: 1521.188 | GO15: 1521.188 | GP15: 1521.188 | GQ15: 1521.188
F16: Giá keo dự báo | H16: Giá keo dự báo | U16: =U14 -> 1165 | V16: =V14 -> 1272.5 | W16: =W14 -> 1346 | X16: =X14 -> 1297.5 | Y16: =Y14 -> 1316.6667 | Z16: =Z14 -> 1390 | AA16: =AA14 -> 1220 | AB16: =AB14 -> 1270 | ... BY16: =BY14 -> 1140 | CC16: Giá tới nhà máy Plascene | DO16: =DO15+222 -> 2140.02 | DP16: =DP15-222 -> 1696.02 | DQ16: =DQ15-222 -> 1365.33 | DR16: =DR15-222 -> 1365.33 | DS16: =DS15-222 -> 1365.33 | DT16: =DT15-222 -> 1365.33 | DU16: =DU15-222 -> 1365.33 | DV16: =DV15-222 -> 1365.33 | DW16: =DW15-222 -> 1365.33 | ... KL16: =KL15-222 -> -222
H17: TTCP | X17: =X14 -> 1297.5 | Y17: =Y14 -> 1316.6667 | Z17: =Z14 -> 1390 | AA17: =AA14 -> 1220 | AB17: =AB14 -> 1270 | AC17: =AC14 -> 1190 | AD17: =AD14 -> 1190 | AE17: =AE14 -> 1130 | ... BY17: =BY14 -> 1140 | CC17: TTCP | DQ17: =DQ14 -> 1100 | DR17: =DR14 -> 1100 | DS17: =DS14 -> 1070 | DT17: =DT14 -> 1040 | DU17: =DU14 -> 995 | DV17: =DV14 -> 980 | DW17: =DW14 -> 980 | DX17: =DX14 -> 980 | ... KL17: =KL14 -> 1140
H18: CL | X18: =X7-X17 -> 272.5 | Y18: =Y7-Y17 -> 253.33333 | Z18: =Z7-Z17 -> 180 | AA18: =AA7-AA17 -> 350 | AB18: =AB7-AB17 -> 230 | AC18: =AC7-AC17 -> 310 | AD18: =AD7-AD17 -> #REF! | AE18: =AE7-AE17 -> #REF! | ... AK18: =AK7-AK17 -> 372.5 | AL18: =AL6-AL17 -> 330 | AM18: =AM6-AM17 -> 285 | AN18: =AN6-AN17 -> 360 | AO18: =AO6-AO17 -> 325 | AP18: =AP6-AP17 -> 406 | AQ18: =AQ6-AQ17 -> 430 | AR18: =AR6-AR17 -> 372 | AS18: =AS6-AS17 -> 332 | ... BY18: =BY6-BY17 -> 160 | CC18: CL | DQ18: =+DQ7-DQ17 -> #REF! | DR18: =+DR7-DR17 -> #REF! | DS18: =+DS7-DS17 -> #REF! | DT18: =+DT7-DT17 -> #REF! | DU18: =+DU7-DU17 -> 405 | DV18: =+DV7-DV17 -> 420 | DW18: =+DW7-DW17 -> 420 | DX18: =+DX7-DX17 -> 420 | ... GB18: =+GB7-GB17 -> 350 | GC18: =+GC6-GC17 -> 350 | GD18: =+GD6-GD17 -> 310 | GE18: =+GE6-GE17 -> 310 | GF18: =+GF6-GF17 -> 310 | GG18: =+GG6-GG17 -> 300 | GH18: =+GH6-GH17 -> 310 | GI18: =+GI6-GI17 -> 310 | GJ18: =+GJ6-GJ17 -> 310 | ... KL18: =+KL6-KL17 -> 140
H19: % | X19: =X18/X17 -> 0.21001927 | Y19: =Y18/Y17 -> 0.19240506 | Z19: =Z18/Z17 -> 0.1294964 | AA19: =AA18/AA17 -> 0.28688525 | AB19: =AB18/AB17 -> 0.18110236 | AC19: =AC18/AC17 -> 0.2605042 | AD19: =AD18/AD17 -> #REF! | AE19: =AE18/AE17 -> #REF! | ... BY19: =BY18/BY17 -> 0.14035088 | CC19: % | DQ19: =+DQ18/DQ17 -> #REF! | DR19: =+DR18/DR17 -> #REF! | DS19: =+DS18/DS17 -> #REF! | DT19: =+DT18/DT17 -> #REF! | DU19: =+DU18/DU17 -> 0.40703518 | DV19: =+DV18/DV17 -> 0.42857143 | DW19: =+DW18/DW17 -> 0.42857143 | DX19: =+DX18/DX17 -> 0.42857143 | ... KL19: =+KL18/KL17 -> 0.12280702
H20: Điểm hòa vốn | X20: 1225 | Y20: 1225 | Z20: 1225 | AA20: 1225 | AB20: 1225 | AC20: 1225 | AD20: 1225 | AE20: 1225 | AF20: 1225 | AG20: 1225 | AH20: 1225 | AI20: 1225 | AJ20: 1225 | AK20: 1225 | AL20: 1225 | AM20: 1225 | AN20: 1225 | AO20: 1225 | AP20: 1225 | AQ20: 1185 | AR20: 1133 | AS20: 1133 | AT20: 1151 | AU20: 1175 | AV20: 1200 | AW20: 1143 | AX20: 1162 | AY20: 1175 | AZ20: 1200 | BA20: 1230 | BB20: 1260 | BC20: 1250 | BD20: 1174 | BE20: 1131 | BF20: 1154.4175 | BG20: 1161.0769 | BH20: 1179.9226 | BI20: 1183.4455 | BJ20: 1181 | BK20: 1185.2425 | BL20: 1190.7839 | BM20: 1188.899 | BN20: 1208.4564 | BO20: 1167.8122 | BP20: 1185.3194 | BQ20: 1163.1487 | BR20: 1186.2628 | BS20: 1128 | BT20: 1070.5116 | BU20: 1092.8991 | BV20: 1096.8837 | BW20: 1056.152 | BX20: 1057.7957 | CC20: Giá keo dự báo | DQ20: =DQ14 -> 1100 | DR20: =DR14 -> 1100 | DS20: =DS14 -> 1070 | DT20: =DT14 -> 1040 | DU20: =DU14 -> 995 | DV20: =DV14 -> 980 | DW20: =DW14 -> 980 | DX20: =DX14 -> 980 | ... KL20: =KL14 -> 1140
H21: Điểm hòa vốn ( có phí hỗ trợ) | CC21: Điểm hòa vốn | DS21: 1303 | DT21: 1303 | DU21: 1225 | DV21: 1225 | DW21: 1225 | DX21: 1225 | DY21: 1225 | DZ21: 1225 | EA21: 1225 | EB21: 1225 | EC21: 1225 | ED21: 1225 | EE21: 1225 | EF21: 1225 | EG21: 1225 | EH21: 1225 | EI21: 1225 | EJ21: 1225 | EK21: 1225 | EL21: 1225 | EM21: 1225 | EN21: 1225 | EO21: 1225 | EP21: 1225 | EQ21: 1225 | ER21: 1225 | ES21: 1225 | ET21: 1225 | EU21: 1225 | EV21: 1225 | EW21: 1225 | EX21: 1225 | EY21: 1225 | EZ21: 1185 | FA21: 1185 | FB21: 1185 | FC21: 1185 | FD21: 1133 | FE21: 1133 | FF21: 1133 | FG21: 1133 | FH21: 1133 | FI21: 1133 | FJ21: 1133 | FK21: 1151 | FL21: 1151 | FM21: 1151 | FN21: 1175 | FO21: 1175 | FP21: 1175 | FQ21: 1175 | FR21: 1175 | FS21: 1175 | FT21: 1200 | FU21: 1200 | FV21: 1200 | FW21: 1200 | FX21: 1143 | FY21: 1143 | FZ21: 1143 | GA21: 1143 | GB21: 1143 | GC21: 1162 | GD21: 1162 | GE21: 1162 | GF21: 1162 | GG21: 1175 | GH21: 1175 | GI21: 1175 | GJ21: 1200 | GK21: 1200 | GL21: 1200 | GM21: 1200 | GN21: 1230 | GO21: 1230 | GP21: 1230 | GQ21: 1230 | GR21: 1260 | GS21: 1260 | GT21: 1260 | GU21: 1260 | GV21: 1260 | GW21: 1250 | GX21: 1250 | GY21: 1250 | GZ21: 1250 | HA21: 1174 | HB21: 1174 | HC21: 1174 | HD21: 1174 | HE21: 1131 | HF21: 1131 | HG21: 1131 | HH21: 1131 | HI21: 1131 | HJ21: 1154.4175 | HK21: 1154.4175 | HL21: 1154.4175 | HM21: 1154.4175 | HN21: 1161.0769 | HO21: 1161.0769 | HP21: 1161.0769 | HQ21: 1161.0769 | HR21: 1179.9226 | HS21: 1179.9226 | HT21: 1179.9226 | HU21: 1179.9226 | HV21: 1179.9226 | HW21: 1183.4455 | HX21: 1183.4455 | HY21: 1183.4455 | HZ21: 1183.4455 | IA21: 1181 | IB21: 1181 | IC21: 1181 | ID21: 1181 | IE21: 1185.2425 | IF21: 1185.2425 | IG21: 1185.2425 | IH21: 1185.2425 | II21: 1190.7839 | IJ21: 1190.7839 | IK21: 1190.7839 | IL21: 1190.7839 | IM21: 1188.899 | IN21: 1188.899 | IO21: 1188.899 | IP21: 1188.899 | IQ21: 1208.4564 | IR21: 1208.4564 | IS21: 1208.4564 | IT21: 1208.4564 | IU21: 1208.4564 | IV21: 1167.8122 | IW21: 1167.8122 | IX21: 1167.8122 | IY21: 1167.8122 | IZ21: 1185.3194 | JA21: 1185.3194 | JB21: 1185.3194 | JC21: 1185.3194 | JD21: 1185.3194 | JE21: 1163.1487 | JF21: 1163.1487 | JG21: 1163.1487 | JH21: 1163.1487 | JI21: 1186.2628 | JJ21: 1186.2628 | JK21: 1186.2628 | JL21: 1186.2628 | JM21: 1149.7077 | JN21: 1149.7077 | JO21: 1149.7077 | JP21: 1149.7077 | JQ21: 1149.7077 | JR21: 1070.5116 | JS21: 1070.5116 | JT21: 1070.5116 | JU21: 1070.5116 | JV21: 1092.8991 | JW21: 1092.8991 | JX21: 1092.8991 | JY21: 1092.8991 | JZ21: 1096.8837 | KA21: 1096.8837 | KB21: 1096.8837 | KC21: 1096.8837 | KD21: 1096.8837 | KE21: 1056.152 | KF21: 1056.152 | KG21: 1056.152 | KH21: 1056.152 | KI21: 1057.7957 | KJ21: 1057.7957 | KK21: 1057.7957 | KL21: 1057.7957
CC22: Điểm hòa vốn có 25% rewash | ED22: =ED21+35 -> 1260 | EE22: =EE21+35 -> 1260 | EF22: =EF21+35 -> 1260 | EG22: =EG21+35 -> 1260 | EH22: =EH21+35 -> 1260 | EI22: =EI21+35 -> 1260 | EJ22: =EJ21+35 -> 1260 | EK22: =EK21+35 -> 1260 | ... FX22: =FX21+35 -> 1178 | FY22: =FY21+20 -> 1163 | FZ22: =FZ21+20 -> 1163 | GA22: =GA21+20 -> 1163 | GB22: =GB21+20 -> 1163 | GC22: =GC21+20 -> 1182 | GD22: =GD21+20 -> 1182 | GE22: =GE21+20 -> 1182 | GF22: =GF21+20 -> 1182 | ... GQ22: =GQ21+20 -> 1250
H23: Giá bán đối thủ Intco | AS23: 1220 | AT23: 1220 | AU23: 1220 | CC23: Điểm hòa vốn (có phí hỗ trợ) | ED23: =ED21+34 -> 1259 | EE23: =EE21+34 -> 1259 | EF23: =EF21+34 -> 1259 | EG23: =EG21+34 -> 1259 | EH23: =EH21+34 -> 1259 | EI23: =EI21+34 -> 1259 | EJ23: =EJ21+34 -> 1259 | EK23: =EK21+34 -> 1259 | ... FJ23: =FJ21+34 -> 1167 | FK23: 1182 | FL23: 1182 | FM23: 1182 | FN23: 1182 | FO23: 1182 | FP23: 1234 | FQ23: 1234 | FR23: 1234 | FS23: 1234 | FT23: 1234 | FU23: 1234 | FV23: 1234 | FW23: 1234 | FX23: 1234 | FY23: 1234 | FZ23: 1234 | GA23: 1234 | GB23: 1234 | GC23: 1234 | GD23: 1234 | GE23: 1234 | GF23: 1234 | GG23: 1234 | GH23: 1234 | GI23: 1234 | GJ23: 1234 | GK23: 1234 | GL23: 1234 | GM23: 1234 | GN23: 1234 | GO23: 1234 | GP23: 1234 | GQ23: 1234
H24: Giá bán Unilever | X24: 1360 | Y24: 1360 | Z24: 1360 | AA24: 1550 | AB24: 1550 | AC24: 1550 | AD24: 1550 | AE24: 1534 | AF24: 1534 | AG24: 1534 | AH24: 1534 | AI24: 1534 | AJ24: 1534 | AK24: 1534 | AL24: 1445 | AM24: 1445 | AN24: 1445 | AO24: 1500 | AP24: 1500 | AQ24: 1500 | AR24: 1450 | AS24: 1450 | AT24: 1450 | AU24: 1350 | AV24: 1350 | AW24: 1350 | AX24: 1320 | AY24: 1320 | AZ24: 1320 | BA24: 1320 | BB24: 1320 | BC24: 1320 | BD24: 1300 | BE24: 1300 | BF24: 1300 | BG24: 1300 | BH24: 1300 | BI24: 1300 | BJ24: 1300 | BK24: 1300 | BL24: 1250 | BM24: 1250 | BN24: 1250 | BO24: 1250 | BP24: 1280 | BQ24: 1280 | BR24: 1280 | BS24: 1280 | BT24: 1280 | BU24: 1280 | BV24: 1250 | BW24: 1250 | BX24: 1250 | CC24: Giá bán đối thủ Intco | FD24: 1200 | FG24: 1200 | FH24: 1200 | FI24: 1200 | FJ24: 1200 | FK24: 1200 | FL24: 1200 | FM24: 1200 | FN24: 1200 | FO24: 1200 | FP24: 1200 | FQ24: 1200 | FR24: 1200 | FS24: 1100 | FT24: 1100 | FU24: 1100 | FV24: 1100 | FW24: 1100 | FX24: 1100 | FY24: 1100 | FZ24: 1100 | GA24: 1100 | GB24: 1100 | GC24: 1100 | GD24: 1100 | GE24: 1100 | GF24: 1100 | GG24: 1100 | GH24: 1100 | GI24: 1100 | GJ24: 1100 | GK24: 1100 | GL24: 1100 | GM24: 1100 | GN24: 1100 | GO24: 1100 | GP24: 1100 | GQ24: 1100 | GR24: 1100 | GS24: 1100 | GT24: 1100 | GU24: 1100 | GV24: 1100 | GW24: 1100 | GX24: 1100 | GY24: 1100 | GZ24: 1100 | HA24: 1100 | HB24: 1100 | HC24: 1100 | HD24: 1100
CC25: Unilever | ED25: 1445 | EE25: 1445 | EF25: 1445 | EG25: 1445 | EH25: 1445 | EI25: 1445 | EJ25: 1445 | EK25: 1445 | EL25: 1445 | EM25: 1445 | EN25: 1445 | EO25: 1445 | EP25: 1500 | EQ25: 1500 | ER25: 1500 | ES25: 1500 | ET25: 1500 | EU25: 1500 | EV25: 1500 | EW25: 1500 | EX25: 1500 | EY25: 1500 | EZ25: 1500 | FA25: 1500 | FB25: 1500 | FC25: 1500 | FD25: 1450 | FE25: 1450 | FF25: 1450 | FG25: 1450 | FH25: 1450 | FI25: 1450 | FJ25: 1450 | FK25: 1450 | FL25: 1450 | FM25: 1450 | FN25: 1450 | FO25: 1450 | FP25: 1350 | FQ25: 1350 | FR25: 1350 | FS25: 1350 | FT25: 1350 | FU25: 1350 | FV25: 1350 | FW25: 1350 | FX25: 1350 | FY25: 1350 | FZ25: 1350 | GA25: 1350 | GB25: 1350 | GC25: 1320 | GD25: 1320 | GE25: 1320 | GF25: 1320 | GG25: 1320 | GH25: 1320 | GI25: 1320 | GJ25: 1320 | GK25: 1320 | GL25: 1320 | GM25: 1320 | GN25: 1320 | GO25: 1320 | GP25: 1320 | GQ25: 1320 | GR25: 1320 | GS25: 1320 | GT25: 1320 | GU25: 1320 | GV25: 1320 | GW25: 1320 | GX25: 1320 | GY25: 1320 | GZ25: 1320 | HA25: 1300 | HB25: 1300 | HC25: 1300 | HD25: 1300 | HE25: 1300 | HF25: 1300 | HG25: 1300 | HH25: 1300 | HI25: 1300 | HJ25: 1300 | HK25: 1300 | HL25: 1300 | HM25: 1300 | HN25: 1300 | HO25: 1300 | HP25: 1300 | HQ25: 1300 | HR25: 1300 | HS25: 1300 | HT25: 1300 | HU25: 1300 | HV25: 1300 | HW25: 1300 | HX25: 1300 | HY25: 1300 | HZ25: 1300 | IA25: 1300 | IB25: 1300 | IC25: 1300 | ID25: 1300 | IE25: 1300 | IF25: 1300 | IG25: 1300 | IH25: 1300 | II25: 1250 | IJ25: 1250 | IK25: 1250 | IL25: 1250 | IM25: 1250 | IN25: 1250 | IO25: 1250 | IP25: 1250 | IQ25: 1250 | IR25: 1250 | IS25: 1250 | IT25: 1250 | IU25: 1250 | IV25: 1250 | IW25: 1250 | IX25: 1250 | IY25: 1250 | IZ25: 1280 | JA25: 1280 | JB25: 1280 | JC25: 1280 | JD25: 1280 | JE25: 1280 | JF25: 1280 | JG25: 1280 | JH25: 1280 | JI25: 1280 | JJ25: 1280 | JK25: 1280 | JL25: 1280 | JM25: 1280 | JN25: 1280 | JO25: 1280 | JP25: 1280 | JQ25: 1280 | JR25: 1280 | JS25: 1280 | JT25: 1280 | JU25: 1280 | JV25: 1280 | JW25: 1280 | JX25: 1280 | JY25: 1280 | JZ25: 1250 | KA25: 1250 | KB25: 1250 | KC25: 1250 | KD25: 1250 | KE25: 1250 | KF25: 1250 | KG25: 1250 | KH25: 1250 | KI25: 1250 | KJ25: 1250 | KK25: 1250 | KL25: 1250

Sheet PET-tháng

Sheet PET_tuan

Sheet Ma trận PET- Fiber
D3: MA TRẬN GIÁ BÁN rPET | F3: MA TRẬN GIÁ BÁN rPET | AS3: 2023 | BJ3: 2024
F4: Tỷ giá | I4: 24000 | J4: 24000 | K4: 24000 | L4: 24000 | AS4: 24000 | AT4: 24000 | AU4: 24000 | AV4: 24000 | AW4: 24000 | AX4: 24000 | AY4: 24000 | AZ4: 24000 | BA4: 24000 | BB4: 24000 | BC4: 24000 | BD4: 24000 | BE4: 24000 | BF4: 24000 | BG4: 24000 | BH4: 24000 | BI4: 24000 | BJ4: 24000 | BK4: 24000 | BL4: 24000 | BM4: 24000 | DH4: 2025 | FG4: 2026
A5: Stt | B5: Mã SAP | C5: Tên hàng hóa SAP | D5: Mã SP | E5: Tên sản phẩm | F5: Diễn giải | G5: Đơn vị tính | H5: Diễn giải | I5: 9 | J5: 10 | K5: 11 | L5: 12 | M5: T1.24 | N5: 2 | O5: 3 | P5: 4 | Q5: 5 | R5: 6 | S5: 7 | T5: 8 | U5: 9 | V5: 10 | W5: 11 | X5: 12 | Y5: T1.25 | Z5: 2 | AA5: 3 | AB5: 4 | AC5: 5 | AD5: 6 | AE5: 7 | AF5: 8 | AG5: 9 | AH5: 10 | AI5: 11 | AJ5: 12 | AK5: T1.26 | AL5: 2 | AM5: 3 | AN5: 4 | AP5: Mã SP | AQ5: Tên sản phẩm | AR5: Diễn giải | AS5: 36 | AT5: 37 | AU5: 38 | AV5: 39 | AW5: 40 | AX5: 41 | AY5: 42 | AZ5: 43 | BA5: 44 | BB5: 45 | BC5: 46 | BD5: 47 | BE5: 48 | BF5: 49 | BG5: 50 | BH5: 51 | BI5: 52 | BJ5: 1/24 | BK5: 02 | BL5: 03 | BM5: 04 | BN5: 05 | BO5: 08 | BP5: 09 | BQ5: 10 | BR5: 11 | BS5: 12 | BT5: 13 | BU5: 14 | BV5: 15 | BW5: 16 | BX5: 17 | BY5: 18 | BZ5: 19 | CA5: 20 | CB5: 21 | CC5: 22 | CD5: 23 | CE5: 24 | CF5: 25 | CG5: 26 | CH5: 27 | CI5: 28 | CJ5: 29 | CK5: 30 | CL5: 31 | CM5: 32 | CN5: 33 | CO5: 34 | CP5: 35 | CQ5: 36 | CR5: 37 | CS5: 38 | CT5: 39 | CU5: 40 | CV5: 41 | CW5: 42 | CX5: 43 | CY5: 44 | CZ5: 45 | DA5: 46 | DB5: 47 | DC5: 48 | DD5: 49 | DE5: 50 | DF5: 51 | DG5: 52 | DH5: 01 | DI5: 02 | DJ5: 03 | DK5: 04 | DL5: 06 | DM5: 07 | DN5: 08 | DO5: 09 | DP5: 10 | DQ5: 11 | DR5: 12 | DS5: 13 | DT5: 14 | DU5: 15 | DV5: 16 | DW5: 17 | DX5: 18 | DY5: 19 | DZ5: 20 | EA5: 21 | EB5: 22 | EC5: 23 | ED5: 24 | EE5: 25 | EF5: 26 | EG5: 27 | EH5: 28 | EI5: 29 | EJ5: 30 | EK5: 31 | EL5: 32 | EM5: 33 | EN5: 34 | EO5: 35 | EP5: 36 | EQ5: 37 | ER5: 38 | ES5: 39 | ET5: 40 | EU5: 41 | EV5: 42 | EW5: 43 | EX5: 44 | EY5: 45 | EZ5: 46 | FA5: 47 | FB5: 48 | FC5: 49 | FD5: 50 | FE5: 51 | FF5: 52 | FG5: 01 | FH5: 02 | FI5: 03 | FJ5: 04 | FK5: 05 | FL5: 06 | FM5: 07 | FN5: 08 | FO5: 09 | FP5: 10 | FQ5: 11 | FR5: 12 | FS5: 13
H6: DTR-Food grade | J6: ='Ma trận PET'!AU6 -> 1250 | K6: ='Ma trận PET'!AV6 -> 1250 | L6: ='Ma trận PET'!AW6 -> 1250 | M6: ='Ma trận PET'!AX6 -> 1250 | N6: ='Ma trận PET'!AY6 -> 1250 | O6: ='Ma trận PET'!AZ6 -> 1250 | P6: ='Ma trận PET'!BA6 -> 1250 | Q6: ='Ma trận PET'!BB6 -> 1300 | ... U6: ='Ma trận PET'!BF6 -> 1310 | V6: =U6+15 -> 1325 | W6: =V6 -> 1325 | X6: =W6-50 -> 1275 | Y6: =X6-45 -> 1230 | Z6: =Y6 -> 1230 | AA6: =Z6 -> 1230 | AB6: =AA6+20 -> 1250 | AC6: =AB6 -> 1250 | AD6: =AC6 -> 1250 | AE6: =AD6 -> 1250 | AF6: =AE6-20-10 -> 1220 | AG6: =AF6 -> 1220 | AH6: 1210 | AI6: 1200 | AJ6: 1200 | AK6: 1160 | AL6: 1160 | AM6: 1160 | AR6: DTR-Food grade | AS6: ='Ma trận PET'!FL6 -> 1250 | AT6: ='Ma trận PET'!FM6 -> 1250 | AU6: ='Ma trận PET'!FN6 -> 1250 | AV6: ='Ma trận PET'!FO6 -> 1250 | AW6: ='Ma trận PET'!FP6 -> 1250 | AX6: ='Ma trận PET'!FQ6 -> 1250 | AY6: ='Ma trận PET'!FR6 -> 1250 | AZ6: ='Ma trận PET'!FS6 -> 1250 | ... BN6: ='Ma trận PET'!GG6 -> 1250 | BO6: 1250 | BP6: 1250 | BQ6: 1250 | BR6: 1250 | BS6: 1250 | BT6: 1250 | BU6: 1250 | BV6: 1250 | BW6: 1250 | BX6: 1250 | BY6: 1300 | BZ6: 1300 | CA6: 1300 | CB6: 1300 | CC6: 1300 | CD6: 1300 | CE6: 1300 | CF6: 1300 | CG6: 1300 | CH6: 1300 | CI6: 1300 | CJ6: 1300 | CK6: 1300 | CL6: 1300 | CM6: 1300 | CN6: 1300 | CO6: 1300 | CP6: 1300 | CQ6: 1310 | CR6: 1310 | CS6: 1310 | CT6: 1310 | CU6: 1325 | CV6: 1325 | CW6: 1325 | CX6: 1325 | CY6: 1325 | CZ6: 1325 | DA6: 1325 | DB6: 1325 | DC6: 1325 | DD6: =1325-50 -> 1275 | DE6: =1325-50 -> 1275 | DF6: =1325-50 -> 1275 | DG6: =1325-50 -> 1275 | DH6: =1325-50-45 -> 1230 | DI6: =1325-50-45 -> 1230 | DJ6: =1325-50-45 -> 1230 | DK6: =1325-50-45 -> 1230 | DL6: =1325-50-45 -> 1230 | DM6: =1325-50-45 -> 1230 | DN6: =1325-50-45 -> 1230 | DO6: =1325-50-45 -> 1230 | ... DS6: =1325-50-45 -> 1230 | DT6: =1325-50-45+20 -> 1250 | DU6: =1325-50-45+20 -> 1250 | DV6: =1325-50-45+20 -> 1250 | DW6: =1325-50-45+20 -> 1250 | DX6: =1325-50-45+20 -> 1250 | DY6: =1325-50-45+20 -> 1250 | DZ6: =1325-50-45+20 -> 1250 | EA6: =1325-50-45+20 -> 1250 | ... EK6: =1325-50-45+20 -> 1250 | EL6: =1325-50-45+20-20-10 -> 1220 | EM6: =1325-50-45+20-20-10 -> 1220 | EN6: =1325-50-45+20-20-10 -> 1220 | EO6: =1325-50-45+20-20-10 -> 1220 | EP6: =1325-50-45+20-20-10 -> 1220 | EQ6: =1325-50-45+20-20-10 -> 1220 | ER6: =1325-50-45+20-20-10 -> 1220 | ES6: =1325-50-45+20-20-10 -> 1220 | ET6: =1325-50-45+20-20-10-10 -> 1210 | EU6: =1325-50-45+20-20-10-10 -> 1210 | EV6: =1325-50-45+20-20-10-10 -> 1210 | EW6: =1325-50-45+20-20-10-10 -> 1210 | EX6: =1325-50-45+20-20-10-10 -> 1210 | EY6: =1325-50-45+20-20-10-10-10 -> 1200 | EZ6: =1325-50-45+20-20-10-10-10 -> 1200 | FA6: =1325-50-45+20-20-10-10-10 -> 1200 | FB6: =1325-50-45+20-20-10-10-10 -> 1200 | FC6: =1325-50-45+20-20-10-10-10 -> 1200 | FD6: =1325-50-45+20-20-10-10-10 -> 1200 | FE6: =1325-50-45+20-20-10-10-10 -> 1200 | FF6: =1325-50-45+20-20-10-10-10 -> 1200 | FG6: =1325-50-45+20-20-10-10-10-40 -> 1160 | FH6: =1325-50-45+20-20-10-10-10-40 -> 1160 | FI6: =1325-50-45+20-20-10-10-10-40 -> 1160 | FJ6: =1325-50-45+20-20-10-10-10-40 -> 1160 | FK6: =1325-50-45+20-20-10-10-10-40 -> 1160 | FL6: =1325-50-45+20-20-10-10-10-40 -> 1160 | FM6: =1325-50-45+20-20-10-10-10-40 -> 1160 | FN6: =1325-50-45+20-20-10-10-10-40 -> 1160 | ... FQ6: =1325-50-45+20-20-10-10-10-40 -> 1160 | FR6: =1325-50-45+20-20-10-10-10-40+50 -> 1210 | FS6: 1280
A7: 5 | B7: 110000329 | C7: Hạt rPET WSS01 | E7: WSS01 - Hạt rPET (IV 0.78) | F7: Giá DTR | G7: $ /tấn | H7: DTR | I7: 1050 | J7: 1050 | K7: 1050 | L7: 1050 | M7: 1050 | N7: 1050 | O7: 1050 | P7: 1050 | Q7: 1100 | R7: 1100 | S7: 1100 | T7: 1100 | U7: 1100 | V7: 1100 | W7: 1100 | X7: 1100 | Y7: 1100 | Z7: 1100 | AA7: 1100 | AB7: 1120 | AC7: 1120 | AD7: 1120 | AE7: =+AE6-130 -> 1120 | AF7: =+AF6-130 -> 1090 | AG7: =+AG6-130 -> 1090 | AH7: =+AH6-130 -> 1080 | AI7: =+AI6-130 -> 1070 | AJ7: =+AJ6-130 -> 1070 | AK7: =+AK6-130 -> 1030 | AL7: =+AL6-130 -> 1030 | ... AN7: =+AN6-130 -> -130 | AQ7: WSS01 - Hạt rPET (IV 0.78) | AR7: DTR | AS7: 1050 | AT7: 1050 | AU7: 1050 | AV7: 1050 | AW7: 1050 | AX7: 1050 | AY7: 1050 | AZ7: 1050 | BA7: 1050 | BB7: 1050 | BC7: 1050 | BD7: 1050 | BE7: 1050 | BF7: 1050 | BG7: 1050 | BH7: 1050 | BI7: 1050 | BJ7: 1050 | BK7: 1050 | BL7: 1050 | BM7: 1050 | BN7: 1050 | BO7: 1050 | BP7: 1050 | BQ7: 1050 | BR7: 1050 | BS7: 1050 | BT7: 1050 | BU7: 1050 | BV7: 1050 | BW7: 1050 | BX7: 1050 | BY7: 1100 | BZ7: 1100 | CA7: 1100 | CB7: 1100 | CC7: 1100 | CD7: 1100 | CE7: 1100 | CF7: 1100 | CG7: 1100 | CH7: 1100 | CI7: 1100 | CJ7: 1100 | CK7: 1100 | CL7: 1100 | CM7: 1100 | CN7: 1100 | CO7: 1100 | CP7: 1100 | CQ7: 1100 | CR7: 1100 | CS7: 1100 | CT7: 1100 | CU7: 1100 | CV7: 1100 | CW7: 1100 | CX7: 1100 | CY7: 1100 | CZ7: 1100 | DA7: 1100 | DB7: 1100 | DC7: 1100 | DD7: 1100 | DE7: 1100 | DF7: 1100 | DG7: 1100 | DH7: 1100 | DI7: 1100 | DJ7: 1100 | DK7: 1100 | DL7: 1100 | DM7: 1100 | DN7: 1100 | DO7: 1100 | DP7: 1100 | DQ7: 1100 | DR7: 1100 | DS7: 1100 | DT7: 1120 | DU7: 1120 | DV7: 1120 | DW7: 1120 | DX7: 1120 | DY7: 1120 | DZ7: 1120 | EA7: 1120 | EB7: 1120 | EC7: 1120 | ED7: 1120 | EE7: 1120 | EF7: 1120 | EG7: 1120 | EH7: 1120 | EI7: 1120 | EJ7: 1120 | EK7: 1120 | EL7: =+EL6-130 -> 1090 | EM7: =+EM6-130 -> 1090 | EN7: =+EN6-130 -> 1090 | EO7: =+EO6-130 -> 1090 | EP7: =+EP6-130 -> 1090 | EQ7: =+EQ6-130 -> 1090 | ER7: =+ER6-130 -> 1090 | ES7: =+ES6-130 -> 1090 | ... FS7: =+FS6-130 -> 1150
A8: 9 | D8: ICIS | E8: ICIS giá rPET ($ /tấn) | F8: ICIS FOB ĐNA - Giá trung bình | G8: $ /tấn | H8: ICIS | I8: =SUM(AS8:AV8)/COUNT(AS8:AV8) -> 802.75 | J8: =SUM(AW8:AZ8)/COUNT(AW8:AZ8) -> 801 | K8: =SUM(BA8:BD8)/COUNT(BA8:BD8) -> 821.5 | L8: =SUM(BE8:BH8)/COUNT(BE8:BH8) -> 821.5 | M8: =SUM(BJ8:BM8)/COUNT(BJ8:BM8) -> 804.25 | N8: =SUM(BN8:BP8)/COUNT(BN8:BP8) -> 787 | O8: =SUM(BQ8:BT8)/COUNT(BQ8:BT8) -> 815.875 | P8: =SUM(BU8:BX8)/COUNT(BU8:BX8) -> 831.875 | Q8: =SUM(BY8:CC8)/COUNT(BY8:CC8) -> 894.5 | R8: =SUM(CD8:CG8)/COUNT(CD8:CG8) -> 978.5 | S8: =SUM(CH8:CK8)/COUNT(CH8:CK8) -> 978.5 | T8: =SUM(CL8:CP8)/COUNT(CL8:CP8) -> 980.5 | U8: =SUM(CQ8:CT8)/COUNT(CQ8:CT8) -> 996 | V8: =SUM(CU8:CX8)/COUNT(CU8:CX8) -> 1018.5 | W8: =SUM(CY8:DC8)/COUNT(CY8:DC8) -> 999.7 | X8: =SUM(DD8:DG8)/COUNT(DD8:DG8) -> 956.5 | Y8: =SUM(DH8:DK8)/COUNT(DH8:DK8) -> 911.5 | Z8: =SUM(DL8:DO8)/COUNT(DL8:DO8) -> 911.5 | AA8: =SUM(DP8:DS8)/COUNT(DP8:DS8) -> 919.25 | AB8: =SUM(DT8:DW8)/COUNT(DT8:DW8) -> 933.125 | AC8: =SUM(DX8:EB8)/COUNT(DX8:EB8) -> 944.7 | AD8: =SUM(EC8:EF8)/COUNT(EC8:EF8) -> 954.5 | AE8: =SUM(EG8:EK8)/COUNT(EG8:EK8) -> 918 | AF8: =SUM(EL8:EO8)/COUNT(EL8:EO8) -> 868.375 | AG8: =SUM(EP8:ES8)/COUNT(EP8:ES8) -> 803.5 | AH8: =SUM(ET8:EX8)/COUNT(ET8:EX8) -> 794.125 | AI8: =SUM(EY8:FB8)/COUNT(EY8:FB8) -> #DIV/0! | AJ8: =SUM(EZ8:FC8)/COUNT(EZ8:FC8) -> #DIV/0! | AK8: =SUM(FA8:FD8)/COUNT(FA8:FD8) -> #DIV/0! | AL8: =SUM(FB8:FE8)/COUNT(FB8:FE8) -> #DIV/0! | AM8: =SUM(FC8:FF8)/COUNT(FC8:FF8) -> #DIV/0! | AN8: =SUM(FD8:FG8)/COUNT(FD8:FG8) -> #DIV/0! | AP8: ICIS | AQ8: ICIS giá rPET ($ /tấn) | AR8: ICIS | AS8: 802.5 | AT8: 802.5 | AU8: 802.5 | AV8: 803.5 | AW8: 801 | AX8: 801 | AY8: 801 | AZ8: 801 | BA8: 821.5 | BB8: 821.5 | BC8: 821.5 | BD8: 821.5 | BE8: 821.5 | BF8: 821.5 | BG8: 821.5 | BH8: 821.5 | BI8: 821.5 | BJ8: 821.5 | BK8: 821.5 | BL8: 787 | BM8: 787 | BN8: 787 | BO8: 787 | BP8: 787 | BQ8: 788.5 | BR8: 825 | BS8: 825 | BT8: 825 | BU8: 825 | BV8: 825 | BW8: 825 | BX8: 852.5 | BY8: 873.5 | BZ8: 873.5 | CA8: 873.5 | CB8: 873.5 | CC8: 978.5 | CD8: 978.5 | CE8: 978.5 | CF8: 978.5 | CG8: 978.5 | CH8: 978.5 | CI8: 978.5 | CJ8: 978.5 | CK8: 978.5 | CL8: 978.5 | CM8: 978.5 | CN8: 978.5 | CO8: 978.5 | CP8: 988.5 | CQ8: 988.5 | CR8: 988.5 | CS8: 988.5 | CT8: 1018.5 | CU8: 1018.5 | CV8: 1018.5 | CW8: 1018.5 | CX8: 1018.5 | CY8: 1018.5 | CZ8: 1018.5 | DA8: 1018.5 | DB8: 971.5 | DC8: 971.5 | DD8: 971.5 | DE8: 971.5 | DF8: 971.5 | DG8: 911.5 | DH8: 911.5 | DI8: 911.5 | DJ8: 911.5 | DK8: 911.5 | DL8: 911.5 | DM8: 911.5 | DN8: 911.5 | DO8: 911.5 | DP8: 911.5 | DQ8: 911.5 | DR8: 911.5 | DS8: 942.5 | DT8: 942.5 | DU8: 930 | DV8: 930 | DW8: 930 | DX8: 930 | DY8: 930 | DZ8: 954.5 | EA8: 954.5 | EB8: 954.5 | EC8: 954.5 | ED8: 954.5 | EE8: 954.5 | EF8: 954.5 | EG8: 954.5 | EH8: 954.5 | EI8: 910 | EJ8: 885.5 | EK8: 885.5 | EL8: 875.5 | EM8: 875.5 | EN8: 875.5 | EO8: 847 | EP8: 807 | EQ8: 807 | ER8: 800 | ES8: 800 | ET8: 800 | EU8: 800 | EV8: 800 | EW8: 776.5
D9: Anh 12 | F9: RESIN | G9: $ /tấn | H9: RESIN | I9: =SUM(AS9:AV9)/COUNT(AS9:AV9) -> 935 | J9: =SUM(AW9:AZ9)/COUNT(AW9:AZ9) -> 922.5 | K9: =SUM(BA9:BC9)/COUNT(BA9:BC9) -> 900 | L9: =SUM(BE9:BH9)/COUNT(BE9:BH9) -> 900 | M9: =SUM(BJ9:BM9)/COUNT(BJ9:BM9) -> 930 | N9: =SUM(BN9:BP9)/COUNT(BN9:BP9) -> 943.33333 | O9: =SUM(BQ9:BT9)/COUNT(BQ9:BT9) -> 940 | P9: =SUM(BU9:BX9)/COUNT(BU9:BX9) -> 940 | Q9: =SUM(BY9:CC9)/COUNT(BY9:CC9) -> 942 | R9: =SUM(CD9:CG9)/COUNT(CD9:CG9) -> 950 | S9: =SUM(CH9:CK9)/COUNT(CH9:CK9) -> 947.5 | T9: =SUM(CL9:CP9)/COUNT(CL9:CP9) -> 930 | U9: =SUM(CQ9:CT9)/COUNT(CQ9:CT9) -> 880 | V9: =SUM(CU9:CX9)/COUNT(CU9:CX9) -> 860 | W9: =SUM(CY9:DC9)/COUNT(CY9:DC9) -> 852 | X9: =SUM(DD9:DG9)/COUNT(DD9:DG9) -> 830 | Y9: =SUM(DH9:DK9)/COUNT(DH9:DK9) -> 827.5 | Z9: =SUM(DL9:DO9)/COUNT(DL9:DO9) -> 840 | AA9: =SUM(DP9:DS9)/COUNT(DP9:DS9) -> 822.5 | AB9: =SUM(DT9:DW9)/COUNT(DT9:DW9) -> 765 | AC9: =SUM(DX9:EB9)/COUNT(DX9:EB9) -> 782 | AD9: =SUM(EC9:EF9)/COUNT(EC9:EF9) -> 807.5 | AE9: =SUM(EG9:EK9)/COUNT(EG9:EK9) -> 802 | AF9: =SUM(EL9:EO9)/COUNT(EL9:EO9) -> 795 | AG9: =SUM(EP9:ES9)/COUNT(EP9:ES9) -> 782.5 | AH9: =SUM(ET9:EX9)/COUNT(ET9:EX9) -> 772 | AI9: =SUM(EY9:FB9)/COUNT(EY9:FB9) -> 770 | AJ9: =SUM(FC9:FF9)/COUNT(FC9:FF9) -> 772.5 | AK9: =SUM(FG9:FK9)/COUNT(FG9:FK9) -> 805 | AL9: =SUM(FL9:FO9)/COUNT(FL9:FO9) -> 840 | AM9: =SUM(FP9:FS9)/COUNT(FP9:FS9) -> 1108.75 | AN9: 1140 | AP9: Anh 12 | AR9: RESIN | AS9: 930 | AT9: 930 | AU9: 940 | AV9: 940 | AW9: 940 | AX9: 930 | AY9: 920 | AZ9: 900 | BA9: 900 | BB9: 900 | BC9: 900 | BD9: 900 | BE9: 900 | BF9: 900 | BG9: 900 | BH9: 900 | BI9: 900 | BJ9: 900 | BK9: 940 | BL9: 940 | BM9: 940 | BN9: 950 | BO9: 940 | BP9: 940 | BQ9: 940 | BR9: 940 | BS9: 940 | BT9: 940 | BU9: 940 | BV9: 940 | BW9: 940 | BX9: 940 | BY9: 940 | BZ9: 940 | CA9: 940 | CB9: 940 | CC9: 950 | CD9: 950 | CE9: 950 | CF9: 950 | CG9: 950 | CH9: 950 | CI9: 950 | CJ9: 950 | CK9: 940 | CL9: 940 | CM9: 940 | CN9: 940 | CO9: 930 | CP9: 900 | CQ9: 900 | CR9: 890 | CS9: 870 | CT9: 860 | CU9: 860 | CV9: 860 | CW9: 860 | CX9: 860 | CY9: 860 | CZ9: 860 | DA9: 860 | DB9: 840 | DC9: 840 | DD9: 840 | DE9: 830 | DF9: 830 | DG9: 820 | DH9: 820 | DI9: 820 | DJ9: 820 | DK9: 850 | DL9: 840 | DM9: 840 | DN9: 840 | DO9: 840 | DP9: 840 | DQ9: 830 | DR9: 810 | DS9: 810 | DT9: 800 | DU9: 750 | DV9: 750 | DW9: 760 | DX9: 760 | DY9: 760 | DZ9: 800 | EA9: 800 | EB9: 790 | EC9: 800 | ED9: 790 | EE9: 820 | EF9: 820 | EG9: 820 | EH9: 820 | EI9: 790 | EJ9: 790 | EK9: 790 | EL9: 800 | EM9: 790 | EN9: 790 | EO9: 800 | EP9: 790 | EQ9: 780 | ER9: 780 | ES9: 780 | ET9: 780 | EU9: 780 | EV9: 770 | EW9: 760 | EX9: 770 | EY9: 770 | EZ9: 770 | FA9: 770 | FB9: 770 | FC9: 770 | FD9: 770 | FE9: 770 | FF9: 780 | FG9: 795 | FH9: 795 | FI9: 795 | FJ9: 820 | FK9: 820 | FL9: 840 | FM9: 840 | FN9: 840 | FO9: 840 | FP9: =(900+970)/2 -> 935 | FQ9: 1080 | FR9: 1280 | FS9: 1140
