Workbook
Name \T: #REF!
Name \T: #REF!
Name \T: #REF!
Name \T: #REF!
Name \T: #REF!
Name \T: #REF!
Name \T: #REF!
Name __dao1: #REF!
Name __dao2: #REF!
Name __dap2: #REF!
Name __day1: #REF!
Name __day2: #REF!
Name __dbu1: #REF!
Name __dbu2: #REF!
Name __doi3: #REF!
Name __E99999: #REF!
Name __Jan02: #REF!
Name __lap1: #REF!
Name __lap2: #REF!
Name __vc1: #REF!
Name __vc2: #REF!
Name __vc3: #REF!
Name _01_01_99: #REF!
Name _01_02_99: #REF!
Name _01_03_99: #REF!
Name _01_04_99: #REF!
Name _01_05_99: #REF!
Name _01_06_99: #REF!
Name _01_07_99: #REF!
Name _01_08_1999: #REF!
Name _1CAP002: #REF!
Name _2STREO7: #REF!
Name _4GOIC01: #REF!
Name _4OSLCTT: #REF!
Name _6BNTTTH: #REF!
Name _6DCTTBO: #REF!
Name _6DD24TT: #REF!
Name _6FCOTBU: #REF!
Name _6LATUBU: #REF!
Name _6SDTT24: #REF!
Name _6TBUDTT: #REF!
Name _6TDDDTT: #REF!
Name _6TLTTTH: #REF!
Name _6TUBUTT: #REF!
Name _6UCLVIS: #REF!
Name _7DNCABC: #REF!
Name _7HDCTBU: #REF!
Name _7PKTUBU: #REF!
Name _7TBHT20: #REF!
Name _7TBHT30: #REF!
Name _7TDCABC: #REF!
Name _dao1: #REF!
Name _dao2: #REF!
Name _dap2: #REF!
Name _day1: #REF!
Name _day2: #REF!
Name _dbu1: #REF!
Name _dbu2: #REF!
Name _doi3: #REF!
Name _E99999: #REF!

Sheet PET-tháng

Sheet PET_tuan

Sheet Ma trận PET
D3: MA TRẬN GIÁ BÁN rPET | AL3: 2023 | AX3: 2024 | BJ3: 2025 | EG3: 2023 | EK3: 07.02 | EL3: 14.02 | EM3: 21.02 | EN3: 28.02 | EO3: 7.03 | EP3: 14.03 | EQ3: 21.03 | ER3: 28.03 | ES3: 4.04 | ET3: 11.04 | EU3: 18.04 | EV3: 25.04 | EW3: 2.05 | EX3: 9.05 | EY3: 16.05 | EZ3: 23.05 | FA3: 30.05 | FB3: 6.06 | FC3: 13.06 | FD3: 20.06 | GF3: 2024 | ID3: 2025
F4: Tỷ giá | I4: 23147 | J4: 23135 | K4: 23142 | L4: 23194 | M4: 23204 | N4: 23160 | O4: 23141 | P4: 23161 | Q4: 23161 | R4: 23123 | S4: 23156 | T4: 23126 | U4: 23180 | V4: 23108 | W4: =V4 -> 23108 | X4: =W4 -> 23108 | Y4: =X4 -> 23108 | Z4: 23150 | AA4: 23150 | AB4: 23150 | AC4: 23150 | AD4: 23500 | AE4: 23500 | AF4: 23500 | AG4: 23500 | AH4: 23500 | AI4: 23500 | AJ4: 24600 | AK4: 24000 | AL4: 24000 | AM4: 24000 | AN4: 24000 | AO4: 24000 | AP4: 24000 | AQ4: 24000 | AR4: 24000 | AS4: 24000 | AT4: 24000 | AU4: 24000 | AV4: 24000 | AW4: 24000 | AX4: 24000 | AY4: 24000 | AZ4: 24000 | BA4: 24000 | BB4: 24000 | BC4: 24000 | BD4: 24000 | BE4: 24000 | BF4: 24000 | BG4: 24000 | BH4: 24000 | BI4: 24000 | DD4: 23150 | DE4: 23150 | DF4: 23150 | DG4: 23150 | DH4: 23150 | DI4: 23150 | DJ4: 23150 | DK4: 23150 | DL4: 23150 | DM4: 23150 | DN4: 23150 | DO4: 23150 | DP4: 23500 | DQ4: 23500 | DR4: 23500 | DS4: 23500 | DT4: 23500 | DU4: 23500 | DV4: 23500 | DW4: 23500 | DX4: 24600 | DY4: 24600 | DZ4: 24600 | EA4: 24600 | EB4: 24600 | EC4: 24000 | ED4: 24000 | EE4: 24000 | EF4: 24000 | EG4: 24000 | EH4: 24000 | EI4: 24000 | EJ4: 24000 | EK4: 24000 | EL4: 24000 | EM4: 24000 | EN4: 24000 | EO4: 24000 | EP4: 24000 | EQ4: 24000 | ER4: 24000 | ES4: 24000 | ET4: 24000 | EU4: 24000 | EV4: 24000 | EW4: 24000 | EX4: 24000 | EY4: 24000 | EZ4: 24000 | FA4: 24000 | FB4: 24000 | FC4: 24000 | FD4: 24000 | FE4: 24000 | FF4: 24000 | FG4: 24000 | FH4: 24000 | FI4: 24000 | FJ4: 24000 | FK4: 24000 | FL4: 24000 | FM4: 24000 | FN4: 24000 | FO4: 24000 | FP4: 24000 | FQ4: 24000 | FR4: 24000 | FS4: 24000 | FT4: 24000 | FU4: 24000 | FV4: 24000 | FW4: 24000 | FX4: 24000 | FY4: 24000 | FZ4: 24000 | GA4: 24000 | GB4: 24000 | GC4: 24000 | GD4: 24000 | GE4: 24000 | GF4: 24000 | GG4: 24000 | GH4: 24000 | GI4: 24000 | GJ4: 24000 | GK4: 24000 | GL4: 24000 | GM4: 24000 | GN4: 24000 | GO4: 24000 | GP4: 24000 | GQ4: 24000 | GR4: 24000 | GS4: 24000 | GT4: 24000 | KC4: 2026
A5: Stt | B5: Mã SAP | C5: Tên hàng hóa SAP | D5: Mã SP | E5: Tên sản phẩm | F5: Diễn giải | G5: Đơn vị tính | H5: Diễn giải | I5: T1.21 | J5: T2.21 | K5: T3.21 | L5: T4.21 | M5: T5.21 | N5: T6.21 | O5: T7.21 | P5: T8.21 | Q5: T9.21 | R5: T10.21 | S5: T11.21 | T5: T12.21 | U5: 1 | V5: 2 | W5: 3 | X5: 4 | Y5: 5 | Z5: 6 | AA5: 7 | AB5: 8 | AC5: Hiện tại 23/8 | AD5: 9 | AE5: 10 | AF5: 4/10 | AG5: 11/10 | AH5: 18/10 | AI5: 25/10 | AJ5: 11 | AK5: 12 | AL5: T1/23 | AM5: 2 | AN5: 3 | AO5: 4 | AP5: 5 | AQ5: 6 | AR5: 7 | AS5: 8 | AT5: 9 | AU5: 10 | AV5: 11 | AW5: 12 | AX5: T1.24 | AY5: 2 | AZ5: 3 | BA5: 4 | BB5: 5 | BC5: 6 | BD5: 7 | BE5: 8 | BF5: 9 | BG5: 10 | BH5: 11 | BI5: 12 | BJ5: T1.25 | BK5: 2 | BL5: 3 | BM5: 4 | BN5: 5 | BO5: 6 | BP5: 7 | BQ5: 8 | BR5: 9 | BS5: 10 | BT5: 11 | BU5: 12 | BV5: T1.26 | BW5: 2 | BX5: 3 | BY5: 4 | BZ5: 5 | CA5: 6 | CB5: 7 | CD5: Mã SP | CE5: Tên sản phẩm | CF5: Diễn giải | CG5: 1 | CH5: =+CG5+1 -> 2 | CI5: =+CH5+1 -> 3 | CJ5: =+CI5+1 -> 4 | CK5: =+CJ5+1 -> 5 | CL5: =+CK5+1 -> 6 | CM5: =+CL5+1 -> 7 | CN5: =+CM5+1 -> 8 | CO5: =+CN5+1 -> 9 | ... DC5: =+DB5+1 -> 23 | DD5: 24 | DE5: 25 | DF5: 26 | DG5: 27 | DH5: 28 | DI5: 29 | DJ5: 30 | DK5: 31 | DL5: 32 | DM5: 33 | DN5: 34 | DO5: 35 | DP5: 36 | DQ5: 37 | DR5: 38 | DS5: 39 | DT5: 40 | DU5: 41 | DV5: 42 | DW5: 43 | DX5: 44 | DY5: 45 | DZ5: 46 | EA5: 47 | EB5: 48 | EC5: 49 | ED5: 50 | EE5: 51 | EF5: 52 | EG5: 1 | EH5: 2 | EI5: 3 | EJ5: 5 | EK5: 6 | EL5: 7 | EM5: 8 | EN5: 9 | EO5: 10 | EP5: 11 | EQ5: 12 | ER5: 13 | ES5: 14 | ET5: 15 | EU5: 16 | EV5: 17 | EW5: 18 | EX5: 19 | EY5: 20 | EZ5: 21 | FA5: 22 | FB5: 23 | FC5: 24 | FD5: 25 | FE5: 26 | FF5: 27 | FG5: 28 | FH5: 29 | FI5: 30 | FJ5: 31 | FK5: 32 | FL5: 33 | FM5: 34 | FN5: 35 | FO5: 36 | FP5: 37 | FQ5: 38 | FR5: 39 | FS5: 40 | FT5: 41 | FU5: 42 | FV5: 43 | FW5: 44 | FX5: 45 | FY5: 46 | FZ5: 47 | GA5: 48 | GB5: 49 | GC5: 50 | GD5: 51 | GE5: 52 | GF5: 1/24 | GG5: 02 | GH5: 03 | GI5: 04 | GJ5: 05 | GK5: 08 | GL5: 09 | GM5: 10 | GN5: 11 | GO5: 12 | GP5: 13 | GQ5: 14 | GR5: 15 | GS5: 16 | GT5: 17 | GU5: 18 | GV5: 19 | GW5: 20 | GX5: 21 | GY5: 22 | GZ5: 23 | HA5: 24 | HB5: 25 | HC5: 26 | HD5: 27 | HE5: 28 | HF5: 29 | HG5: 30 | HH5: 31 | HI5: 32 | HJ5: 33 | HK5: 34 | HL5: 35 | HM5: 36 | HN5: 37 | HO5: 38 | HP5: 39 | HQ5: 40 | HR5: 41 | HS5: 42 | HT5: 43 | HU5: 44 | HV5: 45 | HW5: 46 | HX5: 47 | HY5: 48 | HZ5: 49 | IA5: 50 | IB5: 51 | IC5: 52 | ID5: 01 | IE5: 02 | IF5: 03 | IG5: 04 | IH5: 06 | II5: 07 | IJ5: 08 | IK5: 09 | IL5: 10 | IM5: 11 | IN5: 12 | IO5: 13 | IP5: 14 | IQ5: 15 | IR5: 16 | IS5: 17 | IT5: 18 | IU5: 19 | IV5: 20 | IW5: 21 | IX5: 22 | IY5: 23 | IZ5: 24 | JA5: 25 | JB5: 26 | JC5: 27 | JD5: 28 | JE5: 29 | JF5: 30 | JG5: 31 | JH5: 32 | JI5: 33 | JJ5: 34 | JK5: 35 | JL5: 36 | JM5: 37 | JN5: 38 | JO5: 39 | JP5: 40 | JQ5: 41 | JR5: 42 | JS5: 43 | JT5: 44 | JU5: 45 | JV5: 46 | JW5: 47 | JX5: 48 | JY5: 49 | JZ5: 50 | KA5: 51 | KB5: 52 | KC5: 01 | KD5: 02 | KE5: 03 | KF5: 04 | KG5: 05 | KH5: 06 | KI5: 07 | KJ5: 08 | KK5: 09 | KL5: 10 | KM5: 11 | KN5: 12 | KO5: 13 | KP5: 14 | KQ5: 15 | KR5: 16 | KS5: 17 | KT5: 18 | KU5: 19 | KV5: 20 | KW5: 21 | KX5: 22 | KY5: 23 | KZ5: 24 | LA5: 25 | LB5: 26 | LC5: 27 | LD5: 28 | LE5: 29 | LF5: 30 | LG5: 31
A6: 5 | B6: 110000329 | C6: Hạt rPET WSS01 | D6: WSS01G | E6: WSS01 - Hạt rPET (IV 0.78) | F6: DTR | G6: $ /tấn | H6: DTR | I6: =I7-20 -> 1230 | J6: =J7-20 -> 1230 | K6: =K7-20 -> 1230 | L6: =L7-20 -> 1230 | M6: =M7-20 -> 1230 | N6: =N7-20 -> 1230 | O6: =O7-20 -> 1250 | P6: =P7-20 -> 1250 | ... V6: =V7-20 -> 1300 | W6: 1450 | X6: 1550 | Y6: 1550 | Z6: 1550 | AA6: 1550 | AB6: 1480 | AC6: 1480 | AD6: =#REF!/AD4*1000 -> #REF! | AE6: =#REF!/AE4*1000 -> #REF! | AF6: =#REF!/AF4*1000 -> #REF! | AG6: =#REF!/AG4*1000 -> #REF! | AH6: =#REF!/AH4*1000 -> #REF! | AI6: =#REF!/AI4*1000 -> #REF! | AJ6: =#REF!/AJ4*1000 -> #REF! | AK6: 1330 | AL6: =+SUM(EG6:EJ6)/4 -> 1330 | AM6: =+SUM(EK6:EN6)/4 -> 1330 | AN6: =+SUM(EO6:EQ6)/COUNT(EO6:EQ6) -> 1380 | AO6: =+SUM(ES6:EV6)/COUNT(ES6:EV6) -> 1380 | AP6: =+SUM(EW6:FA6)/COUNT(EW6:FA6) -> 1380 | AQ6: =+SUM(FB6:FE6)/COUNT(FB6:FE6) -> 1325 | AR6: =+SUM(FF6:FI6)/COUNT(FF6:FI6) -> 1275 | AS6: =FJ6 -> 1250 | AT6: 1250 | AU6: 1250 | AV6: 1250 | AW6: 1250 | AX6: 1250 | AY6: 1250 | AZ6: 1250 | BA6: 1250 | BB6: 1300 | BC6: 1300 | BD6: 1300 | BE6: 1300 | BF6: 1310 | BG6: 1325 | BH6: 1325 | BI6: =1325-50 -> 1275 | BJ6: =1325-50-45 -> 1230 | BK6: =1325-50-45 -> 1230 | BL6: =1325-50-45 -> 1230 | BM6: =1325-50-45+20 -> 1250 | BN6: =1325-50-45+20 -> 1250 | BO6: =1325-50-45+20 -> 1250 | BP6: =1325-50-45+20 -> 1250 | BQ6: =1325-50-45+20-30 -> 1220 | BR6: =1325-50-45+20-30 -> 1220 | BS6: =1325-50-45+20-30-10 -> 1210 | BT6: =1325-50-45+20-30-10-10 -> 1200 | BU6: =1325-50-45+20-30-10-10 -> 1200 | BV6: =1325-50-45+20-30-10-10-40 -> 1160 | BW6: =1325-50-45+20-30-10-10-40 -> 1160 | BX6: 1160 | BY6: 1280 | BZ6: 1380 | CA6: 1350 | CB6: 1330 | CD6: WSS01/G | CE6: WSS01 - Hạt rPET (IV 0.78) | CF6: DTR | DD6: 1550 | DE6: 1550 | DF6: 1550 | DG6: 1550 | DH6: 1550 | DI6: 1550 | DJ6: 1550 | DK6: 1480 | DL6: 1480 | DM6: 1480 | DN6: 1480 | DO6: 1480 | DP6: 1410 | DQ6: 1410 | DR6: 1410 | DS6: 1410 | DT6: =#REF!/DT4*1000 -> #REF! | DU6: =#REF!/DU4*1000 -> #REF! | DV6: =#REF!/DV4*1000 -> #REF! | DW6: =#REF!/DW4*1000 -> #REF! | DX6: 1380 | DY6: 1380 | DZ6: 1380 | EA6: 1380 | EB6: 1380 | EC6: 1380 | ED6: 1380 | EE6: 1330 | EF6: 1330 | EG6: 1330 | EH6: 1330 | EI6: 1330 | EJ6: 1330 | EK6: 1330 | EL6: 1330 | EM6: 1330 | EN6: 1330 | EO6: 1380 | EP6: 1380 | EQ6: 1380 | ER6: 1380 | ES6: 1380 | ET6: 1380 | EU6: 1380 | EV6: 1380 | EW6: 1380 | EX6: 1380 | EY6: 1380 | EZ6: 1380 | FA6: 1380 | FB6: 1350 | FC6: 1350 | FD6: 1300 | FE6: 1300 | FF6: 1300 | FG6: 1300 | FH6: 1250 | FI6: 1250 | FJ6: 1250 | FK6: 1250 | FL6: 1250 | FM6: 1250 | FN6: 1250 | FO6: 1250 | FP6: 1250 | FQ6: 1250 | FR6: 1250 | FS6: 1250 | FT6: 1250 | FU6: 1250 | FV6: 1250 | FW6: 1250 | FX6: 1250 | FY6: 1250 | FZ6: 1250 | GA6: 1250 | GB6: 1250 | GC6: 1250 | GD6: 1250 | GE6: 1250 | GF6: 1250 | GG6: 1250 | GH6: 1250 | GI6: 1250 | GJ6: 1250 | GK6: 1250 | GL6: 1250 | GM6: 1250 | GN6: 1250 | GO6: 1250 | GP6: 1250 | GQ6: 1250 | GR6: 1250 | GS6: 1250 | GT6: 1250 | GU6: 1300 | GV6: 1300 | GW6: 1300 | GX6: 1300 | GY6: 1300 | GZ6: 1300 | HA6: 1300 | HB6: 1300 | HC6: 1300 | HD6: 1300 | HE6: 1300 | HF6: 1300 | HG6: 1300 | HH6: 1300 | HI6: 1300 | HJ6: 1300 | HK6: 1300 | HL6: 1300 | HM6: 1310 | HN6: 1310 | HO6: 1310 | HP6: 1310 | HQ6: 1325 | HR6: 1325 | HS6: 1325 | HT6: 1325 | HU6: 1325 | HV6: 1325 | HW6: 1325 | HX6: 1325 | HY6: 1325 | HZ6: =1325-50 -> 1275 | IA6: =HZ6 -> 1275 | IB6: =IA6 -> 1275 | IC6: =IB6 -> 1275 | ID6: 1230 | IE6: =ID6 -> 1230 | IF6: =IE6 -> 1230 | IG6: =IF6 -> 1230 | IH6: =IG6 -> 1230 | II6: =IH6 -> 1230 | IJ6: =II6 -> 1230 | IK6: =IJ6 -> 1230 | IL6: =IK6 -> 1230 | ... IO6: =IN6 -> 1230 | IP6: =IO6+20 -> 1250 | IQ6: =IP6 -> 1250 | IR6: =IQ6 -> 1250 | IS6: =IR6 -> 1250 | IT6: =IS6 -> 1250 | IU6: =IT6 -> 1250 | IV6: =IU6 -> 1250 | IW6: =IV6 -> 1250 | IX6: =IW6 -> 1250 | IY6: 1223.0835 | IZ6: 1225.2286 | JA6: 1219.8595 | JB6: 1219.0531 | JC6: 1215.2889 | JD6: 1228.3131 | JE6: 1216.0902 | JF6: 1220.5682 | JG6: 1216.9073 | JH6: 1204.4734 | JI6: 1187.6814 | JJ6: 1220 | JK6: =JJ6 -> 1220 | JL6: =JK6 -> 1220 | JM6: =JL6 -> 1220 | JN6: =JM6 -> 1220 | JO6: =JN6 -> 1220 | JP6: 1210 | JQ6: =JP6 -> 1210 | JR6: =JQ6 -> 1210 | JS6: =JR6 -> 1210 | JT6: 1210 | JU6: 1200 | JV6: 1200 | JW6: 1200 | JX6: 1200 | JY6: 1200 | JZ6: 1200 | KA6: 1200 | KB6: 1200 | KC6: 1160 | KD6: 1160 | KE6: 1160 | KF6: 1160 | KG6: 1160 | KH6: 1160 | KI6: 1160 | KJ6: 1160 | KK6: 1160 | KL6: 1160 | KM6: 1160 | KN6: =1160+50 -> 1210 | KO6: 1280 | KP6: 1280 | KQ6: 1280 | KR6: 1310 | KS6: 1380 | KT6: 1380 | KU6: 1380 | KV6: 1380 | KW6: 1380 | KX6: 1380 | KY6: 1350 | KZ6: 1350 | LA6: 1350 | LB6: 1350 | LC6: 1330 | LD6: 1330
A7: 6 | B7: 110000329 | C7: Hạt rPET WSS01 | D7: WSS01/G | E7: WSS01 - Hạt rPET (IV 0.78) | F7: DTR-Giá WSS01 FOB-HCM (IV: 0,78+/- 0.02) | G7: $ /tấn | H7: DTR | I7: 1250 | J7: 1250 | K7: 1250 | L7: 1250 | M7: 1250 | N7: 1250 | O7: 1270 | P7: 1270 | Q7: 1270 | R7: 1270 | S7: 1320 | T7: 1320 | U7: 1320 | V7: 1320 | W7: =W6+20 -> 1470 | X7: =X6+20 -> 1570 | Y7: =Y6+20 -> 1570 | Z7: =Z6+20 -> 1570 | AA7: =AA6+20 -> 1570 | AB7: 1500 | AC7: =AC6+20 -> 1500 | AD7: =AD6+20 -> #REF! | AE7: =AE6+20 -> #REF! | AF7: =AF6+20 -> #REF! | AG7: =AG6+20 -> #REF! | AH7: =AH6+20 -> #REF! | AI7: =AI6+20 -> #REF! | AJ7: =AJ6+20 -> #REF! | AK7: =AK6+20 -> 1350 | AL7: =+SUM(EG7:EJ7)/4 -> 1330 | AM7: =+SUM(EH7:EK7)/4 -> 1330 | AN7: =+SUM(EO7:EQ7)/COUNT(EO7:EQ7) -> 1380 | AO7: =+SUM(ES7:EV7)/COUNT(ES7:EV7) -> 1380 | AP7: =+SUM(EW7:FA7)/COUNT(EW7:FA7) -> 1380 | AQ7: =+SUM(FB7:FE7)/COUNT(FB7:FE7) -> 1325 | AR7: =+SUM(FF7:FI7)/COUNT(FF7:FI7) -> 1275 | AS7: =+SUM(FJ7:FN7)/COUNT(FJ7:FN7) -> 1250 | AT7: =FO7 -> 1250 | AU7: =FP7 -> 1250 | AV7: =FQ7 -> 1250 | AW7: =FR7 -> 1250 | AX7: =FS7 -> 1250 | AY7: =FT7 -> 1250 | AZ7: =FU7 -> 1250 | BA7: =FV7 -> 1250 | BB7: 1300 | BC7: 1300 | BD7: 1300 | BE7: 1300 | BF7: 1300 | BG7: 1300 | BH7: 1300 | BI7: 1300 | BJ7: 1300 | BK7: 1300 | BL7: 1300 | BM7: 1300 | BN7: 1300 | BO7: 1300 | BP7: 1300 | BQ7: 1300 | BR7: 1300 | BS7: 1300 | BT7: 1300 | BU7: 1300 | BV7: 1300 | BW7: 1300 | BX7: 1300 | BY7: 1300 | BZ7: 1300 | CA7: 1300 | CB7: 1300 | CD7: giá EXW | CE7: WSS01 - Hạt rPET (IV 0.78) | CF7: DTR | DD7: =DD6+20 -> 1570 | DE7: =DE6+20 -> 1570 | DF7: =DF6+20 -> 1570 | DG7: =DG6+20 -> 1570 | DH7: =DH6+20 -> 1570 | DI7: =DI6+20 -> 1570 | DJ7: =DJ6+20 -> 1570 | DK7: =DK6+20 -> 1500 | ... DW7: =DW6+20 -> #REF! | DX7: 1400 | DY7: 1400 | DZ7: 1400 | EA7: 1400 | EB7: 1400 | EC7: 1400 | ED7: 1400 | EE7: 1350 | EF7: 1350 | EG7: =EG6 -> 1330 | EH7: =EH6 -> 1330 | EI7: =EI6 -> 1330 | EJ7: =EJ6 -> 1330 | EK7: =EK6 -> 1330 | EL7: =EL6 -> 1330 | EM7: =EM6 -> 1330 | EN7: =EN6 -> 1330 | ... GD7: =GD6 -> 1250 | GE7: 1250 | GF7: 1250 | GG7: 1250 | GH7: 1250 | GI7: 1250 | GJ7: 1250 | GK7: 1250 | GL7: 1250 | GM7: 1250 | GN7: 1250 | GO7: 1250 | GP7: 1250 | GQ7: 1250 | GR7: 1250 | GS7: 1250 | GT7: 1250 | GU7: 1250 | GV7: 1250 | GW7: 1250 | GX7: 1250 | GY7: 1250 | GZ7: 1250 | HA7: 1250 | HB7: 1250 | HC7: 1250
A8: 7 | B8: 110000330 | C8: Hạt rPET SS01 | D8: ISS01/G | E8: SS01 - Hạt rPET (IV 0.82) | F8: DTR-Giá ISS01 FOB-HCM (IV: 0,82+/- 0.02) | G8: $ /tấn | H8: ISS01 (IV: 0,82+/- 0.02) | I8: =I7+30 -> 1280 | J8: =J7+30 -> 1280 | K8: =K7+30 -> 1280 | L8: =L7+30 -> 1280 | M8: =M7+30 -> 1280 | N8: =N7+30 -> 1280 | O8: =O7+30 -> 1300 | P8: =P7+30 -> 1300 | ... S8: =S7+30 -> 1350 | T8: =T7+50 -> 1370 | U8: =U7+50 -> 1370 | V8: =V7+50 -> 1370 | W8: =W7+100 -> 1570 | X8: =X7+100 -> 1670 | Y8: =Y7+100 -> 1670 | Z8: =Z7+80 -> 1650 | AA8: =AA7+80 -> 1650 | AB8: 1530 | AC8: 1530 | AD8: =#REF!/AD4*1000+20 -> #REF! | AE8: =#REF!/AE4*1000+20 -> #REF! | AF8: =#REF!/AF4*1000+20 -> #REF! | AG8: =#REF!/AG4*1000+20 -> #REF! | AH8: =#REF!/AH4*1000+20 -> #REF! | AI8: =#REF!/AI4*1000+20 -> #REF! | AJ8: =#REF!/AJ4*1000+20 -> #REF! | AK8: =#REF!/AK4*1000+20 -> #REF! | AL8: =#REF!/AL4*1000+20 -> #REF! | AM8: =+SUM(EK8:EN8)/4 -> 1397.5 | AN8: =+SUM(EO8:EQ8)/COUNT(EO8:EQ8) -> 1410 | AO8: =+SUM(ES8:EV8)/COUNT(ES8:EV8) -> 1410 | AP8: =+SUM(EW8:FA8)/COUNT(EW8:FA8) -> 1410 | AQ8: =+SUM(FB8:FE8)/COUNT(FB8:FE8) -> 1355 | AR8: =+SUM(FF8:FI8)/COUNT(FF8:FI8) -> 1305 | AS8: =+SUM(FJ8:FN8)/COUNT(FJ8:FN8) -> 1280 | AT8: =FO8 -> 1280 | AU8: =FP8 -> 1280 | AV8: =FQ8 -> 1280 | AW8: =FR8 -> 1280 | AX8: =FS8 -> 1280 | AY8: =FT8 -> 1280 | AZ8: =FU8 -> 1280 | BA8: =FV8 -> 1280 | ... CB8: =GW8 -> 1280 | CD8: ISS01/G | CE8: SS01 - Hạt rPET (IV 0.82) | CF8: ISS01 (IV: 0,82+/- 0.02) | DD8: 1650 | DE8: 1650 | DF8: 1650 | DG8: 1650 | DH8: 1650 | DI8: 1650 | DJ8: 1650 | DK8: 1530 | DL8: 1530 | DM8: 1530 | DN8: 1530 | DO8: 1530 | DP8: 1460 | DQ8: 1460 | DR8: 1460 | DS8: 1460 | DT8: =#REF!/DT4*1000+20 -> #REF! | DU8: =#REF!/DU4*1000+20 -> #REF! | DV8: =#REF!/DV4*1000+20 -> #REF! | DW8: =#REF!/DW4*1000+20 -> #REF! | DX8: 1410 | DY8: 1410 | DZ8: 1410 | EA8: 1410 | EB8: 1410 | EC8: 1410 | ED8: 1410 | EE8: 1410 | EF8: 1410 | EG8: 1410 | EH8: 1410 | EI8: 1410 | EJ8: 1410 | EK8: 1410 | EL8: 1410 | EM8: 1410 | EN8: =+EN7+30 -> 1360 | EO8: =+EO7+30 -> 1410 | EP8: =+EP7+30 -> 1410 | EQ8: =+EQ7+30 -> 1410 | ER8: =+ER7+30 -> 1410 | ES8: =+ES7+30 -> 1410 | ET8: =+ET7+30 -> 1410 | EU8: =+EU7+30 -> 1410 | ... HC8: =+HC7+30 -> 1280
D9: ẩn | F9: DTR-Giá FOB rPET ISS01 | G9: đồng /kg | H9: DTR-Giá FOB rPET ISS01 | V9: =V8*23108/1000 -> 31657.96 | W9: =W8*23108/1000 -> 36279.56 | X9: =X8*23108/1000 -> 38590.36 | Y9: =Y8*23108/1000 -> 38590.36 | Z9: =Z8*Z4/1000 -> 38197.5 | AC9: =AC8*AC4/1000 -> 35419.5 | AD9: =AD8*AD4/1000 -> #REF! | AE9: =AE8*AE4/1000 -> #REF! | AF9: =AF8*AF4/1000 -> #REF! | AG9: =AG8*AG4/1000 -> #REF! | AH9: =AH8*AH4/1000 -> #REF! | AI9: =AI8*AI4/1000 -> #REF! | AJ9: =AJ8*AJ4/1000 -> #REF! | ... AM9: =AM8*AM4/1000 -> 33540 | CD9: ẩn | CF9: DTR-Giá FOB rPET ISS01 | DT9: =DT8*DT4/1000 -> #REF! | DU9: =DU8*DU4/1000 -> #REF! | DV9: =DV8*DV4/1000 -> #REF! | DW9: =DW8*DW4/1000 -> #REF! | DX9: 33135 | FD9: =+#REF!+30 -> #REF!
A11: 9 | D11: ICIS | E11: ICIS giá rPET ($ /tấn) | F11: ICIS FOB ĐNA - Giá trung bình | G11: $ /tấn | H11: ICIS | P11: 1300 | Q11: 1300 | R11: 1350 | S11: 1350 | T11: 1350 | U11: 1350 | V11: 1500 | W11: 1525 | X11: 1525 | Y11: 1550 | Z11: 1627 | AA11: 1585 | AB11: 1574 | AC11: 1485 | AD11: 1444 | AE11: 1425 | AF11: 1425 | AG11: 1425 | AH11: 1425 | AI11: =(1350+1500)/2 -> 1425 | AJ11: 1425 | AK11: 1330 | AL11: =+SUM(EG11:EJ11)/4 -> 1287.5 | AM11: =+SUM(EK11:EN11)/4 -> 1313.75 | AN11: =+SUM(EO11:EQ11)/COUNT(EO11:EQ11) -> 1440 | AO11: =+SUM(ES11:EV11)/COUNT(ES11:EV11) -> 1440 | AP11: =+SUM(EW11:FA11)/COUNT(EW11:FA11) -> 1433 | AQ11: =+SUM(FB11:FE11)/COUNT(FB11:FE11) -> 1337.5 | AR11: =+SUM(FF11:FI11)/COUNT(FF11:FI11) -> 1317.5 | AS11: =+SUM(FJ11:FN11)/COUNT(FJ11:FN11) -> 1274 | AT11: =+SUM(FO11:FR11)/COUNT(FO11:FR11) -> 1288.75 | AU11: =+SUM(FS11:FV11)/COUNT(FS11:FV11) -> 1288.125 | AV11: =+SUM(FW11:FZ11)/COUNT(FW11:FZ11) -> 1300 | AW11: =+SUM(GA11:GE11)/COUNT(GA11:GE11) -> 1300 | AX11: =+SUM(GF11:GI11)/COUNT(GF11:GI11) -> 1312.5 | AY11: =+SUM(GJ11:GL11)/COUNT(GJ11:GL11) -> 1325 | AZ11: =+SUM(GM11:GP11)/COUNT(GM11:GP11) -> 1320 | BA11: =+SUM(GQ11:GT11)/COUNT(GQ11:GT11) -> 1323.75 | BB11: =+SUM(GU11:GY11)/COUNT(GU11:GY11) -> 1346.6 | BC11: =+SUM(GZ11:HC11)/COUNT(GZ11:HC11) -> 1365 | BD11: =+SUM(HD11:HG11)/COUNT(HD11:HG11) -> 1365 | BE11: =+SUM(HH11:HL11)/COUNT(HH11:HL11) -> 1404 | BF11: =+SUM(HM11:HP11)/COUNT(HM11:HP11) -> 1427.5 | BG11: =+SUM(HQ11:HT11)/COUNT(HQ11:HT11) -> 1440 | BH11: =+SUM(HU11:HY11)/COUNT(HU11:HY11) -> 1440 | BI11: =+SUM(HZ11:IC11)/COUNT(HZ11:IC11) -> 1421.25 | BJ11: =+SUM(ID11:IG11)/COUNT(ID11:IG11) -> 1368.75 | BK11: =+SUM(IH11:IK11)/COUNT(IH11:IK11) -> 1350 | BL11: =+SUM(IL11:IO11)/COUNT(IL11:IO11) -> 1360 | BM11: =+SUM(IP11:IS11)/COUNT(IP11:IS11) -> 1360 | BN11: =+SUM(IT11:IX11)/COUNT(IT11:IX11) -> 1360 | BO11: =+SUM(IY11:JB11)/COUNT(IY11:JB11) -> 1360 | BP11: =+SUM(JC11:JG11)/COUNT(JC11:JG11) -> 1324 | BQ11: =+SUM(JH11:JK11)/COUNT(JH11:JK11) -> 1295 | BR11: =+SUM(JL11:JO11)/COUNT(JL11:JO11) -> 1275 | BS11: =+SUM(JP11:JT11)/COUNT(JP11:JT11) -> 1248 | BT11: =+SUM(JU11:JX11)/COUNT(JU11:JX11) -> 1243.75 | BU11: =+SUM(JY11:KB11)/COUNT(JY11:KB11) -> 1193.75 | BV11: =+SUM(KC11:KG11)/COUNT(KC11:KG11) -> 1150 | BW11: =+SUM(KH11:KK11)/COUNT(KH11:KK11) -> 1150 | BX11: =+SUM(KL11:KO11)/COUNT(KL11:KO11) -> 1220 | BY11: =+SUM(KP11:KT11)/COUNT(KP11:KT11) -> 1314 | BZ11: =+SUM(KU11:KX11)/COUNT(KU11:KX11) -> 1358.75 | CA11: =+SUM(KY11:LB11)/COUNT(KY11:LB11) -> 1307.5 | CB11: =+SUM(LC11:LG11)/COUNT(LC11:LG11) -> 1277.5 | CD11: ICIS | CE11: ICIS giá rPET ($ /tấn) | CF11: ICIS | DD11: =+(1550+1670)/2 -> 1610 | DE11: =+(1550+1700)/2 -> 1625 | DF11: =+(1550+1650)/2 -> 1600 | DG11: =+(1550+1620)/2 -> 1585 | DH11: =+(1550+1650)/2 -> 1600 | DI11: =+(1550+1650)/2 -> 1600 | DJ11: =+(1550+1650)/2 -> 1600 | DK11: =+(1550+1680)/2 -> 1615 | DL11: =+(1550+1680)/2 -> 1615 | DM11: =+(1550+1620)/2 -> 1585 | DN11: =+(1550+1620)/2 -> 1585 | DO11: =+(1450+1520)/2 -> 1485 | DP11: =+(1350+1550)/2 -> 1450 | DQ11: =+(1350+1550)/2 -> 1450 | DR11: =+(1350+1550)/2 -> 1450 | DS11: =+(1350+1550)/2 -> 1450 | DT11: 1425 | DU11: 1425 | DV11: 1425 | DW11: =(1350+1500)/2 -> 1425 | DX11: 1350 | DY11: 1350 | DZ11: =+(1250+1450)/2 -> 1350 | EA11: =+(1250+1450)/2 -> 1350 | EB11: =+(1250+1450)/2 -> 1350 | EC11: =+(1250+1450)/2 -> 1350 | ED11: =+(1250+1450)/2 -> 1350 | EE11: =+(1250+1350)/2 -> 1300 | EF11: =+(1250+1350)/2 -> 1300 | EG11: =+(1250+1350)/2 -> 1300 | EH11: =+(1250+1350)/2 -> 1300 | EI11: =+(1250+1300)/2 -> 1275 | EJ11: =+(1250+1300)/2 -> 1275 | EK11: =+(1250+1300)/2 -> 1275 | EL11: =+(1250+1300)/2 -> 1275 | EM11: =+(1280+1350)/2 -> 1315 | EN11: =+(1350+1430)/2 -> 1390 | EO11: =+(1350+1530)/2 -> 1440 | EP11: =+(1350+1530)/2 -> 1440 | EQ11: =+(1350+1530)/2 -> 1440 | ER11: =+(1350+1530)/2 -> 1440 | ES11: =+(1350+1530)/2 -> 1440 | ET11: =+(1350+1530)/2 -> 1440 | EU11: =+(1350+1530)/2 -> 1440 | EV11: =+(1350+1530)/2 -> 1440 | ... EZ11: =+(1350+1530)/2 -> 1440 | FA11: =+(1350+1460)/2 -> 1405 | FB11: =+(1350+1400)/2 -> 1375 | FC11: =+(1300+1350)/2 -> 1325 | FD11: =+(1300+1350)/2 -> 1325 | FE11: =+(1300+1350)/2 -> 1325 | FF11: =+(1300+1350)/2 -> 1325 | FG11: =+(1300+1350)/2 -> 1325 | FH11: =+(1270+1350)/2 -> 1310 | FI11: =+(1270+1350)/2 -> 1310 | FJ11: =+(1200+1300)/2 -> 1250 | FK11: =+(1200+1320)/2 -> 1260 | FL11: =+(1200+1320)/2 -> 1260 | FM11: =+(1250+1350)/2 -> 1300 | FN11: =+(1250+1350)/2 -> 1300 | FO11: =+(1250+1330)/2 -> 1290 | FP11: =+(1250+1330)/2 -> 1290 | FQ11: =+(1250+1330)/2 -> 1290 | FR11: 1285 | FS11: 1285 | FT11: 1287.5 | FU11: 1280 | FV11: 1300 | FW11: 1300 | FX11: 1300 | FY11: 1300 | FZ11: 1300 | GA11: 1300 | GB11: 1300 | GC11: 1300 | GD11: 1300 | GE11: 1300 | GF11: 1300 | GG11: 1300 | GH11: 1325 | GI11: 1325 | GJ11: 1325 | GK11: 1325 | GL11: 1325 | GM11: 1325 | GN11: 1325 | GO11: 1315 | GP11: 1315 | GQ11: 1325 | GR11: 1325 | GS11: 1325 | GT11: 1320 | GU11: 1333 | GV11: 1350 | GW11: 1350 | GX11: 1350 | GY11: 1350 | GZ11: 1365 | HA11: 1365 | HB11: 1365 | HC11: 1365 | HD11: 1365 | HE11: 1365 | HF11: 1365 | HG11: 1365 | HH11: 1400 | HI11: 1400 | HJ11: 1400 | HK11: 1410 | HL11: 1410 | HM11: 1430 | HN11: 1430 | HO11: 1425 | HP11: 1425 | HQ11: 1440 | HR11: 1440 | HS11: 1440 | HT11: 1440 | HU11: 1440 | HV11: 1440 | HW11: 1440 | HX11: 1440 | HY11: 1440 | HZ11: 1430 | IA11: 1430 | IB11: 1425 | IC11: 1400 | ID11: 1400 | IE11: 1375 | IF11: 1350 | IG11: 1350 | IH11: 1350 | II11: 1350 | IJ11: 1350 | IK11: 1350 | IL11: 1360 | IM11: 1360 | IN11: 1360 | IO11: 1360 | IP11: 1360 | IQ11: 1360 | IR11: 1360 | IS11: 1360 | IT11: 1360 | IU11: 1360 | IV11: 1360 | IW11: 1360 | IX11: 1360 | IY11: 1360 | IZ11: 1360 | JA11: 1360 | JB11: 1360 | JC11: 1360 | JD11: 1360 | JE11: 1300 | JF11: 1300 | JG11: 1300 | JH11: 1300 | JI11: 1300 | JJ11: 1290 | JK11: 1290 | JL11: 1290 | JM11: 1290 | JN11: 1260 | JO11: 1260 | JP11: 1240 | JQ11: 1250 | JR11: 1250 | JS11: 1250 | JT11: 1250 | JU11: 1250 | JV11: 1250 | JW11: 1250 | JX11: 1225 | JY11: 1225 | JZ11: 1200 | KA11: 1200 | KB11: 1150 | KC11: 1150 | KD11: 1150 | KE11: 1150 | KF11: 1150 | KG11: 1150 | KH11: 1150 | KI11: 1150 | KJ11: 1150 | KK11: 1150 | KL11: 1175 | KM11: 1185 | KN11: 1220 | KO11: 1300 | KP11: 1300 | KQ11: 1300 | KR11: 1315 | KS11: 1315 | KT11: 1340 | KU11: 1350 | KV11: 1370 | KW11: 1375 | KX11: 1340 | KY11: 1340 | KZ11: 1310 | LA11: 1290 | LB11: 1290 | LC11: 1290 | LD11: 1265
A12: 9 | D12: ICIS | E12: ICIS giá rPET ($ /tấn) | F12: ICIS FOB ĐNA - Giá Cao | G12: $ /tấn | H12: ICIS FOB ĐNA - Giá Cao | P12: 1400 | Q12: 1500 | R12: 1500 | S12: 1500 | T12: 1500 | U12: 1500 | V12: 1650 | W12: 1650 | X12: 1650 | Y12: 1650 | Z12: 1800 | AA12: 1700 | AB12: 1610 | AC12: 1520 | AD12: 1538 | AE12: 1550 | AF12: 1500 | AG12: 1500 | AH12: 1500 | AI12: 1500 | AJ12: 1500 | AK12: 1410 | AL12: =+SUM(EG12:EJ12)/4 -> 1325 | AM12: =+SUM(EK12:EN12)/4 -> 1345 | AN12: =+SUM(EO12:EQ12)/COUNT(EO12:EQ12) -> 1530 | AO12: =+SUM(ES12:EV12)/COUNT(ES12:EV12) -> 1530 | AP12: =+SUM(EW12:FA12)/COUNT(EW12:FA12) -> 1516 | AQ12: =+SUM(FB12:FE12)/COUNT(FB12:FE12) -> 1362.5 | AR12: =+SUM(FF12:FI12)/COUNT(FF12:FI12) -> 1350 | AS12: =+SUM(FJ12:FN12)/COUNT(FJ12:FN12) -> 1328 | AT12: =+SUM(FO12:FR12)/COUNT(FO12:FR12) -> 1327.5 | AU12: =+SUM(FS12:FV12)/COUNT(FS12:FV12) -> 1326.25 | AV12: =+SUM(FW12:FZ12)/COUNT(FW12:FZ12) -> 1350 | AW12: =+SUM(GA12:GE12)/COUNT(GA12:GE12) -> 1350 | AX12: =+SUM(GF12:GI12)/COUNT(GF12:GI12) -> 1375 | AY12: =+SUM(GJ12:GL12)/COUNT(GJ12:GL12) -> 1400 | AZ12: =+SUM(GM12:GP12)/COUNT(GM12:GP12) -> 1390 | BA12: =+SUM(GQ12:GT12)/COUNT(GQ12:GT12) -> 1397.5 | BB12: =+SUM(GU12:GY12)/COUNT(GU12:GY12) -> 1399.2 | BC12: =+SUM(GZ12:HC12)/COUNT(GZ12:HC12) -> 1455 | BD12: =+SUM(HD12:HG12)/COUNT(HD12:HG12) -> 1455 | BE12: =+SUM(HH12:HL12)/COUNT(HH12:HL12) -> 1504 | BF12: =+SUM(HM12:HP12)/COUNT(HM12:HP12) -> 1550 | BG12: =+SUM(HQ12:HT12)/COUNT(HQ12:HT12) -> 1580 | BH12: =+SUM(HU12:HY12)/COUNT(HU12:HY12) -> 1580 | BI12: =+SUM(HZ12:IC12)/COUNT(HZ12:IC12) -> 1555 | BJ12: =+SUM(ID12:IG12)/COUNT(ID12:IG12) -> 1512.5 | BK12: =+SUM(IH12:IK12)/COUNT(IH12:IK12) -> 1500 | BL12: =+SUM(IL12:IO12)/COUNT(IL12:IO12) -> 1500 | BM12: =+SUM(IP12:IS12)/COUNT(IP12:IS12) -> 1500 | BN12: =+SUM(IT12:IX12)/COUNT(IT12:IX12) -> 1500 | BO12: =+SUM(IY12:JB12)/COUNT(IY12:JB12) -> 1500 | BP12: =+SUM(JC12:JG12)/COUNT(JC12:JG12) -> 1440 | BQ12: =+SUM(JH12:JK12)/COUNT(JH12:JK12) -> 1390 | BR12: =+SUM(JL12:JO12)/COUNT(JL12:JO12) -> 1350 | BS12: =+SUM(JP12:JT12)/COUNT(JP12:JT12) -> 1344 | BT12: =+SUM(JU12:JX12)/COUNT(JU12:JX12) -> 1350 | BU12: =+SUM(JY12:KB12)/COUNT(JY12:KB12) -> 1300 | BV12: =+SUM(KC12:KG12)/COUNT(KC12:KG12) -> 1250 | BW12: =+SUM(KH12:KK12)/COUNT(KH12:KK12) -> 1250 | BX12: =+SUM(KL12:KO12)/COUNT(KL12:KO12) -> 1312.5 | BY12: =+SUM(KP12:KT12)/COUNT(KP12:KT12) -> 1400 | BZ12: =+SUM(KU12:KX12)/COUNT(KU12:KX12) -> 1422.5 | CA12: =+SUM(KY12:LB12)/COUNT(KY12:LB12) -> 1367.5 | CB12: =+SUM(LC12:LG12)/COUNT(LC12:LG12) -> 1350 | CD12: ICIS | CE12: ICIS giá rPET ($ /tấn) | CF12: ICIS FOB ĐNA - Giá Cao | DD12: 1670 | DE12: 1700 | DF12: 1650 | DG12: 1620 | DH12: 1650 | DI12: 1650 | DJ12: 1650 | DK12: 1680 | DL12: 1680 | DM12: 1620 | DN12: 1620 | DO12: 1520 | DP12: 1550 | DQ12: 1550 | DR12: 1550 | DS12: 1550 | DT12: 1500 | DU12: 1500 | DV12: 1500 | DW12: 1500 | DX12: 1450 | DY12: 1450 | DZ12: 1450 | EA12: 1450 | EB12: 1450 | EC12: 1450 | ED12: 1450 | EE12: 1350 | EF12: 1350 | EG12: 1350 | EH12: 1350 | EI12: 1300 | EJ12: 1300 | EK12: 1300 | EL12: 1300 | EM12: 1350 | EN12: 1430 | EO12: 1530 | EP12: 1530 | EQ12: 1530 | ER12: 1530 | ES12: 1530 | ET12: 1530 | EU12: 1530 | EV12: 1530 | EW12: 1530 | EX12: 1530 | EY12: 1530 | EZ12: 1530 | FA12: 1460 | FB12: 1400 | FC12: 1350 | FD12: 1350 | FE12: 1350 | FF12: 1350 | FG12: 1350 | FH12: 1350 | FI12: 1350 | FJ12: 1300 | FK12: 1320 | FL12: 1320 | FM12: 1350 | FN12: 1350 | FO12: 1330 | FP12: 1330 | FQ12: 1330 | FR12: 1320 | FS12: 1320 | FT12: 1325 | FU12: 1310 | FV12: 1350 | FW12: 1350 | FX12: 1350 | FY12: 1350 | FZ12: 1350 | GA12: 1350 | GB12: 1350 | GC12: 1350 | GD12: 1350 | GE12: 1350 | GF12: 1350 | GG12: 1350 | GH12: 1400 | GI12: 1400 | GJ12: 1400 | GK12: 1400 | GL12: 1400 | GM12: 1400 | GN12: 1400 | GO12: 1380 | GP12: 1380 | GQ12: 1400 | GR12: 1400 | GS12: 1400 | GT12: 1390 | GU12: 1396 | GV12: 1400 | GW12: 1400 | GX12: 1400 | GY12: 1400 | GZ12: 1455 | HA12: 1455 | HB12: 1455 | HC12: 1455 | HD12: 1455 | HE12: 1455 | HF12: 1455 | HG12: 1455 | HH12: 1500 | HI12: 1500 | HJ12: 1500 | HK12: 1510 | HL12: 1510 | HM12: 1550 | HN12: 1550 | HO12: 1550 | HP12: 1550 | HQ12: 1580 | HR12: 1580 | HS12: 1580 | HT12: 1580 | HU12: 1580 | HV12: 1580 | HW12: 1580 | HX12: 1580 | HY12: 1580 | HZ12: 1560 | IA12: 1560 | IB12: 1550 | IC12: 1550 | ID12: 1550 | IE12: 1500 | IF12: 1500 | IG12: 1500 | IH12: 1500 | II12: 1500 | IJ12: 1500 | IK12: 1500 | IL12: 1500 | IM12: 1500 | IN12: 1500 | IO12: 1500 | IP12: 1500 | IQ12: 1500 | IR12: 1500 | IS12: 1500 | IT12: 1500 | IU12: 1500 | IV12: 1500 | IW12: 1500 | IX12: 1500 | IY12: 1500 | IZ12: 1500 | JA12: 1500 | JB12: 1500 | JC12: 1500 | JD12: 1500 | JE12: 1400 | JF12: 1400 | JG12: 1400 | JH12: 1400 | JI12: 1400 | JJ12: 1380 | JK12: 1380 | JL12: 1380 | JM12: 1380 | JN12: 1320 | JO12: 1320 | JP12: 1320 | JQ12: 1350 | JR12: 1350 | JS12: 1350 | JT12: 1350 | JU12: 1350 | JV12: 1350 | JW12: 1350 | JX12: 1350 | JY12: 1350 | JZ12: 1300 | KA12: 1300 | KB12: 1250 | KC12: 1250 | KD12: 1250 | KE12: 1250 | KF12: 1250 | KG12: 1250 | KH12: 1250 | KI12: 1250 | KJ12: 1250 | KK12: 1250 | KL12: 1250 | KM12: 1270 | KN12: 1330 | KO12: 1400 | KP12: 1400 | KQ12: 1400 | KR12: 1400 | KS12: 1400 | KT12: 1400 | KU12: 1400 | KV12: 1440 | KW12: 1450 | KX12: 1400 | KY12: 1400 | KZ12: 1370 | LA12: 1350 | LB12: 1350 | LC12: 1350 | LD12: 1350
D13: Anh 12 | F13: FENC_FOB TAIWAN BÁN CHO UNILEVER | G13: $ /tấn | H13: FENC_BÁN CHO UNILEVER | R13: 1290 | S13: 1290 | T13: 1290 | U13: 1205 | V13: 1205 | W13: 1542 | X13: 1542 | Y13: 1542 | Z13: 1755 | AA13: 1755 | AB13: 1755 | AC13: 1755 | AD13: 1755 | AE13: 1718 | AF13: 1718 | AG13: 1718 | AH13: 1718 | AI13: 1718 | AJ13: 1718 | AK13: 1718 | AL13: =+SUM(EG13:EJ13)/4 -> 1640.75 | AM13: =+SUM(EK13:EN13)/4 -> 1615 | AN13: =+SUM(EO13:EQ13)/COUNT(EO13:EQ13) -> 1615 | BO13: =+SUM(IY13:JB13)/COUNT(IY13:JB13) -> #DIV/0! | BP13: =+SUM(JC13:JG13)/COUNT(JC13:JG13) -> #DIV/0! | BQ13: =+SUM(JH13:JK13)/COUNT(JH13:JK13) -> #DIV/0! | BR13: =+SUM(JL13:JO13)/COUNT(JL13:JO13) -> #DIV/0! | BS13: =+SUM(JP13:JT13)/COUNT(JP13:JT13) -> #DIV/0! | BT13: =+SUM(JU13:JX13)/COUNT(JU13:JX13) -> #DIV/0! | BU13: =+SUM(JY13:KB13)/COUNT(JY13:KB13) -> #DIV/0! | BV13: =+SUM(KC13:KG13)/COUNT(KC13:KG13) -> #DIV/0! | BW13: =+SUM(KH13:KK13)/COUNT(KH13:KK13) -> #DIV/0! | BX13: =+SUM(KL13:KO13)/COUNT(KL13:KO13) -> #DIV/0! | BY13: =+SUM(KP13:KT13)/COUNT(KP13:KT13) -> #DIV/0! | BZ13: =+SUM(KU13:KX13)/COUNT(KU13:KX13) -> #DIV/0! | CA13: =+SUM(KY13:LB13)/COUNT(KY13:LB13) -> #DIV/0! | CB13: =+SUM(LC13:LG13)/COUNT(LC13:LG13) -> #DIV/0! | CD13: Anh 12 | CF13: FENC_BÁN CHO UNILEVER | DD13: 1755 | DE13: 1755 | DF13: 1755 | DG13: 1755 | DH13: 1755 | DI13: 1755 | DJ13: 1755 | DK13: 1755 | DL13: 1755 | DM13: 1755 | DN13: 1755 | DO13: 1718 | DP13: 1718 | DQ13: 1718 | DR13: 1718 | DS13: 1718 | DT13: 1718 | DU13: 1718 | DV13: 1718 | DW13: 1718 | DX13: 1718 | DY13: 1718 | DZ13: 1718 | EA13: 1718 | EB13: 1718 | EC13: 1718 | ED13: 1718 | EE13: 1718 | EF13: 1718 | EG13: 1718 | EH13: 1615 | EI13: 1615 | EJ13: 1615 | EK13: 1615 | EL13: 1615 | EM13: 1615 | EN13: 1615 | EO13: 1615 | EP13: 1615 | EQ13: 1615 | ER13: 1615
D14: Anh 12 | F14: RESIN | G14: $ /tấn | H14: RESIN | S14: 1190 | T14: 1150 | U14: 1165 | V14: 1272.5 | W14: 1346 | X14: 1297.5 | Y14: 1316.6667 | Z14: 1390 | AA14: 1220 | AB14: 1270 | AC14: 1190 | AD14: 1190 | AE14: 1130 | AF14: 1100 | AG14: 1100 | AH14: 1070 | AI14: 1040 | AJ14: 1040 | AK14: =+SUM(EC14:EF14)/4 -> 977.5 | AL14: =+SUM(EG14:EJ14)/4 -> 1000 | AM14: =+SUM(EK14:EN14)/4 -> 1045 | AN14: =+SUM(EO14:EQ14)/COUNT(EO14:EQ14) -> 1020 | AO14: =+SUM(ES14:EV14)/COUNT(ES14:EV14) -> 1055 | AP14: =+SUM(EW14:FA14)/COUNT(EW14:FA14) -> 974 | AQ14: =+SUM(FB14:FE14)/COUNT(FB14:FE14) -> 895 | AR14: =+SUM(FF14:FI14)/COUNT(FF14:FI14) -> 903 | AS14: =+SUM(FJ14:FN14)/COUNT(FJ14:FN14) -> 918 | AT14: =+SUM(FO14:FR14)/COUNT(FO14:FR14) -> 930 | AU14: =+SUM(FS14:FV14)/COUNT(FS14:FV14) -> 922.5 | AV14: =+SUM(FW14:FZ14)/COUNT(FW14:FZ14) -> 900 | AW14: =+SUM(GA14:GE14)/COUNT(GA14:GE14) -> 900 | AX14: =+SUM(GF14:GI14)/COUNT(GF14:GI14) -> 930 | AY14: =+SUM(GJ14:GL14)/COUNT(GJ14:GL14) -> 943.33333 | AZ14: =+SUM(GM14:GP14)/COUNT(GM14:GP14) -> 940 | BA14: =+SUM(GQ14:GT14)/COUNT(GQ14:GT14) -> 940 | BB14: =+SUM(GU14:GY14)/COUNT(GU14:GY14) -> 942 | BC14: =+SUM(GZ14:HC14)/COUNT(GZ14:HC14) -> 950 | BD14: =+SUM(HD14:HG14)/COUNT(HD14:HG14) -> 947.5 | BE14: =+SUM(HH14:HL14)/COUNT(HH14:HL14) -> 930 | BF14: =+SUM(HM14:HP14)/COUNT(HM14:HP14) -> 880 | BG14: =+SUM(HQ14:HT14)/COUNT(HQ14:HT14) -> 862.5 | BH14: =+SUM(HU14:HY14)/COUNT(HU14:HY14) -> 852 | BI14: =+SUM(HZ14:IC14)/COUNT(HZ14:IC14) -> 830 | BJ14: =+SUM(ID14:IG14)/COUNT(ID14:IG14) -> 827.5 | BK14: =+SUM(IH14:IK14)/COUNT(IH14:IK14) -> 840 | BL14: =+SUM(IL14:IO14)/COUNT(IL14:IO14) -> 822.5 | BM14: =+SUM(IP14:IS14)/COUNT(IP14:IS14) -> 765 | BN14: =+SUM(IT14:IX14)/COUNT(IT14:IX14) -> 782 | BO14: =+SUM(IY14:JB14)/COUNT(IY14:JB14) -> 807.5 | BP14: =+SUM(JC14:JG14)/COUNT(JC14:JG14) -> 802 | BQ14: =+SUM(JH14:JK14)/COUNT(JH14:JK14) -> 795 | BR14: =+SUM(JL14:JO14)/COUNT(JL14:JO14) -> 782.5 | BS14: =+SUM(JP14:JT14)/COUNT(JP14:JT14) -> 772 | BT14: =+SUM(JU14:JX14)/COUNT(JU14:JX14) -> 770 | BU14: =+SUM(JY14:KB14)/COUNT(JY14:KB14) -> 772.5 | BV14: =+SUM(KC14:KG14)/COUNT(KC14:KG14) -> 805 | BW14: =+SUM(KH14:KK14)/COUNT(KH14:KK14) -> 840 | BX14: =+SUM(KL14:KO14)/COUNT(KL14:KO14) -> 1108.75 | BY14: =+SUM(KP14:KT14)/COUNT(KP14:KT14) -> 1194 | BZ14: =+SUM(KU14:KX14)/COUNT(KU14:KX14) -> 1207.5 | CA14: =+SUM(KY14:LB14)/COUNT(KY14:LB14) -> 1102.5 | CB14: =+SUM(LC14:LG14)/COUNT(LC14:LG14) -> 975 | CD14: Anh 12 | CF14: RESIN | DD14: =+(1400+1430)/2 -> 1415 | DE14: =+(1380+1410)/2 -> 1395 | DF14: =+(1360+1390)/2 -> 1375 | DG14: =+(1320+1350)/2 -> 1335 | DH14: =+(1230+1270)/2 -> 1250 | DI14: =+(1210+1250)/2 -> 1230 | DJ14: =+(1200+1240)/2 -> 1220 | DK14: =+(1230+1270)/2 -> 1250 | DL14: =+(1230+1270)/2 -> 1250 | DM14: =+(1200+1240)/2 -> 1220 | DN14: =+(1170+1210)/2 -> 1190 | DO14: =+(1140+1180)/2 -> 1160 | DP14: =+(1140+1180)/2 -> 1160 | DQ14: =+(1140+1180)/2 -> 1160 | DR14: =+(1110+1150)/2 -> 1130 | DS14: =+(1110+1150)/2 -> 1130 | DT14: 1100 | DU14: 1100 | DV14: 1070 | DW14: 1040 | DX14: 995 | DY14: 980 | DZ14: =+(960+1000)/2 -> 980 | EA14: =+(960+1000)/2 -> 980 | EB14: =+(940+1000)/2 -> 970 | EC14: =+(940+1000)/2 -> 970 | ED14: =+(940+1000)/2 -> 970 | EE14: =+(960+1000)/2 -> 980 | EF14: =+(970+1010)/2 -> 990 | EG14: 970 | EH14: 980 | EI14: 990 | EJ14: 1060 | EK14: 1070 | EL14: 1070 | EM14: 1020 | EN14: 1020 | EO14: 1020 | EP14: 1020 | EQ14: 1020 | ER14: 1020 | ES14: 1050 | ET14: 1070 | EU14: 1050 | EV14: 1050 | EW14: 1020 | EX14: 1000 | EY14: 980 | EZ14: 960 | FA14: 910 | FB14: 910 | FC14: 890 | FD14: 890 | FE14: 890 | FF14: 890 | FG14: 882 | FH14: 920 | FI14: 920 | FJ14: 940 | FK14: 920 | FL14: 910 | FM14: 910 | FN14: 910 | FO14: 910 | FP14: 930 | FQ14: 940 | FR14: 940 | FS14: 940 | FT14: 930 | FU14: 920 | FV14: 900 | FW14: 900 | FX14: 900 | FY14: 900 | FZ14: 900 | GA14: 900 | GB14: 900 | GC14: 900 | GD14: 900 | GE14: 900 | GF14: 900 | GG14: 940 | GH14: 940 | GI14: 940 | GJ14: 950 | GK14: 940 | GL14: 940 | GM14: 940 | GN14: 940 | GO14: 940 | GP14: 940 | GQ14: 940 | GR14: 940 | GS14: 940 | GT14: 940 | GU14: 940 | GV14: 940 | GW14: 940 | GX14: 940 | GY14: 950 | GZ14: 950 | HA14: 950 | HB14: 950 | HC14: 950 | HD14: 950 | HE14: 950 | HF14: 950 | HG14: 940 | HH14: 940 | HI14: 940 | HJ14: 940 | HK14: 930 | HL14: 900 | HM14: 900 | HN14: 890 | HO14: 870 | HP14: 860 | HQ14: 860 | HR14: 860 | HS14: 870 | HT14: 860 | HU14: 860 | HV14: 860 | HW14: 860 | HX14: 840 | HY14: 840 | HZ14: 840 | IA14: 830 | IB14: 830 | IC14: 820 | ID14: 820 | IE14: 820 | IF14: 820 | IG14: 850 | IH14: 840 | II14: 840 | IJ14: 840 | IK14: 840 | IL14: 840 | IM14: 830 | IN14: 810 | IO14: 810 | IP14: 800 | IQ14: 750 | IR14: 750 | IS14: 760 | IT14: 760 | IU14: 760 | IV14: 800 | IW14: 800 | IX14: 790 | IY14: 800 | IZ14: 790 | JA14: 820 | JB14: 820 | JC14: 820 | JD14: 820 | JE14: 790 | JF14: 790 | JG14: 790 | JH14: 800 | JI14: 790 | JJ14: 790 | JK14: 800 | JL14: 790 | JM14: 780 | JN14: 780 | JO14: 780 | JP14: 780 | JQ14: 780 | JR14: 770 | JS14: 760 | JT14: 770 | JU14: 770 | JV14: 770 | JW14: 770 | JX14: 770 | JY14: 770 | JZ14: 770 | KA14: 770 | KB14: 780 | KC14: 795 | KD14: 795 | KE14: 795 | KF14: 820 | KG14: 820 | KH14: 840 | KI14: 840 | KJ14: 840 | KK14: 840 | KL14: =(900+970)/2 -> 935 | KM14: 1080 | KN14: 1280 | KO14: 1140 | KP14: 1140 | KQ14: 1200 | KR14: 1200 | KS14: 1200 | KT14: 1230 | KU14: 1250 | KV14: 1230 | KW14: 1190 | KX14: 1160 | KY14: 1140 | KZ14: 1140 | LA14: 1090 | LB14: 1040 | LC14: 990 | LD14: 960
F15: ICIS Thị trường Mỹ (FOB) | H15: x | CF15: ICIS Bờ Tây Mỹ (FOB) | DK15: 2502.24 | DL15: 2502.24 | DM15: 2502.24 | DN15: 2259.74 | DO15: 2259.74 | DP15: 2259.74 | DQ15: 1918.02 | DR15: 1918.02 | DS15: 1918.02 | DT15: 1587.33 | DU15: 1587.33 | DV15: 1587.33 | DW15: 1587.33 | DX15: 1587.33 | DY15: 1587.33 | DZ15: 1587.33 | EA15: 1587.33 | EB15: 1477.1 | EC15: 1477.1 | ED15: 1477.1 | EE15: 1477.1 | EF15: 1477.1 | EG15: 1543.23 | EH15: 1543.234 | EI15: 1543.234 | EJ15: 1543.234 | EK15: 1543.234 | EL15: 1543.234 | EM15: 1543.234 | EN15: 1543.234 | EO15: 1543.234 | EP15: 1543.234 | EQ15: 1543.234 | ER15: 1543.234 | ES15: 1543.234 | ET15: 1543.234 | EU15: 1543.234 | EV15: 1543.234 | EW15: 1543.234 | EX15: 1543.234 | EY15: 1543.234 | EZ15: 1521.188 | FA15: 1521.188 | FB15: 1521.188 | FC15: 1521.188 | FD15: 1521.188 | FE15: 1521.188 | FF15: 1521.188 | FG15: 1521.188 | FH15: 1521.188 | FI15: 1521.188 | FJ15: 1521.188 | FK15: 1521.188 | FL15: 1521.188 | FM15: 1521.188 | FN15: 1521.188 | FO15: 1521.188 | FP15: 1521.188 | FQ15: 1521.188 | FR15: 1521.188 | FS15: 1521.188 | FT15: 1521.188 | FU15: 1521.188 | FV15: 1521.188 | FW15: 1521.188 | FX15: 1521.188 | FY15: 1521.188 | FZ15: 1521.188 | GA15: 1521.188 | GB15: 1521.188 | GC15: 1521.188 | GD15: 1521.188 | GE15: 1521.188 | GF15: 1521.188 | GG15: 1521.188 | GH15: 1521.188 | GI15: 1521.188 | GJ15: 1521.188 | GK15: 1521.188 | GL15: 1521.188 | GM15: 1521.188 | GN15: 1521.188 | GO15: 1521.188 | GP15: 1521.188 | GQ15: 1521.188 | GR15: 1521.188 | GS15: 1521.188 | GT15: 1521.188
F16: Giá keo dự báo | H16: Giá keo dự báo | U16: =U14 -> 1165 | V16: =V14 -> 1272.5 | W16: =W14 -> 1346 | X16: =X14 -> 1297.5 | Y16: =Y14 -> 1316.6667 | Z16: =Z14 -> 1390 | AA16: =AA14 -> 1220 | AB16: =AB14 -> 1270 | ... CB16: =CB14 -> 975 | CF16: Giá tới nhà máy Plascene | DR16: =DR15+222 -> 2140.02 | DS16: =DS15-222 -> 1696.02 | DT16: =DT15-222 -> 1365.33 | DU16: =DU15-222 -> 1365.33 | DV16: =DV15-222 -> 1365.33 | DW16: =DW15-222 -> 1365.33 | DX16: =DX15-222 -> 1365.33 | DY16: =DY15-222 -> 1365.33 | DZ16: =DZ15-222 -> 1365.33 | ... LG16: =LG15-222 -> -222
H17: TTCP | X17: =X14 -> 1297.5 | Y17: =Y14 -> 1316.6667 | Z17: =Z14 -> 1390 | AA17: =AA14 -> 1220 | AB17: =AB14 -> 1270 | AC17: =AC14 -> 1190 | AD17: =AD14 -> 1190 | AE17: =AE14 -> 1130 | ... CB17: =CB14 -> 975 | CF17: TTCP | DT17: =DT14 -> 1100 | DU17: =DU14 -> 1100 | DV17: =DV14 -> 1070 | DW17: =DW14 -> 1040 | DX17: =DX14 -> 995 | DY17: =DY14 -> 980 | DZ17: =DZ14 -> 980 | EA17: =EA14 -> 980 | ... LG17: =LG14 -> 0
H18: CL | X18: =X7-X17 -> 272.5 | Y18: =Y7-Y17 -> 253.33333 | Z18: =Z7-Z17 -> 180 | AA18: =AA7-AA17 -> 350 | AB18: =AB7-AB17 -> 230 | AC18: =AC7-AC17 -> 310 | AD18: =AD7-AD17 -> #REF! | AE18: =AE7-AE17 -> #REF! | ... AK18: =AK7-AK17 -> 372.5 | AL18: =AL6-AL17 -> 330 | AM18: =AM6-AM17 -> 285 | AN18: =AN6-AN17 -> 360 | AO18: =AO6-AO17 -> 325 | AP18: =AP6-AP17 -> 406 | AQ18: =AQ6-AQ17 -> 430 | AR18: =AR6-AR17 -> 372 | AS18: =AS6-AS17 -> 332 | ... CB18: =CB6-CB17 -> 355 | CF18: CL | DT18: =+DT7-DT17 -> #REF! | DU18: =+DU7-DU17 -> #REF! | DV18: =+DV7-DV17 -> #REF! | DW18: =+DW7-DW17 -> #REF! | DX18: =+DX7-DX17 -> 405 | DY18: =+DY7-DY17 -> 420 | DZ18: =+DZ7-DZ17 -> 420 | EA18: =+EA7-EA17 -> 420 | ... GE18: =+GE7-GE17 -> 350 | GF18: =+GF6-GF17 -> 350 | GG18: =+GG6-GG17 -> 310 | GH18: =+GH6-GH17 -> 310 | GI18: =+GI6-GI17 -> 310 | GJ18: =+GJ6-GJ17 -> 300 | GK18: =+GK6-GK17 -> 310 | GL18: =+GL6-GL17 -> 310 | GM18: =+GM6-GM17 -> 310 | ... LG18: =+LG6-LG17 -> 0
H19: % | X19: =X18/X17 -> 0.21001927 | Y19: =Y18/Y17 -> 0.19240506 | Z19: =Z18/Z17 -> 0.1294964 | AA19: =AA18/AA17 -> 0.28688525 | AB19: =AB18/AB17 -> 0.18110236 | AC19: =AC18/AC17 -> 0.2605042 | AD19: =AD18/AD17 -> #REF! | AE19: =AE18/AE17 -> #REF! | ... CB19: =CB18/CB17 -> 0.36410256 | CF19: % | DT19: =+DT18/DT17 -> #REF! | DU19: =+DU18/DU17 -> #REF! | DV19: =+DV18/DV17 -> #REF! | DW19: =+DW18/DW17 -> #REF! | DX19: =+DX18/DX17 -> 0.40703518 | DY19: =+DY18/DY17 -> 0.42857143 | DZ19: =+DZ18/DZ17 -> 0.42857143 | EA19: =+EA18/EA17 -> 0.42857143 | ... LG19: =+LG18/LG17 -> #DIV/0!
H20: Điểm hòa vốn | X20: 1225 | Y20: 1225 | Z20: 1225 | AA20: 1225 | AB20: 1225 | AC20: 1225 | AD20: 1225 | AE20: 1225 | AF20: 1225 | AG20: 1225 | AH20: 1225 | AI20: 1225 | AJ20: 1225 | AK20: 1225 | AL20: 1225 | AM20: 1225 | AN20: 1225 | AO20: 1225 | AP20: 1225 | AQ20: 1185 | AR20: 1133 | AS20: 1133 | AT20: 1151 | AU20: 1175 | AV20: 1200 | AW20: 1143 | AX20: 1162 | AY20: 1175 | AZ20: 1200 | BA20: 1230 | BB20: 1260 | BC20: 1250 | BD20: 1174 | BE20: 1131 | BF20: 1154.4175 | BG20: 1161.0769 | BH20: 1179.9226 | BI20: 1183.4455 | BJ20: 1181 | BK20: 1185.2425 | BL20: 1190.7839 | BM20: 1188.899 | BN20: 1208.4564 | BO20: 1167.8122 | BP20: 1185.3194 | BQ20: 1163.1487 | BR20: 1186.2628 | BS20: 1128 | BT20: 1070.5116 | BU20: 1092.8991 | BV20: 1096.8837 | BW20: 1056.152 | BX20: 1057.7957 | BY20: 1077.9159 | BZ20: 1157.3856 | CA20: 1148.2324 | CB20: 1150.4249 | CF20: Giá keo dự báo | DT20: =DT14 -> 1100 | DU20: =DU14 -> 1100 | DV20: =DV14 -> 1070 | DW20: =DW14 -> 1040 | DX20: =DX14 -> 995 | DY20: =DY14 -> 980 | DZ20: =DZ14 -> 980 | EA20: =EA14 -> 980 | ... LG20: =LG14 -> 0
H21: Điểm hòa vốn ( có phí hỗ trợ) | CF21: Điểm hòa vốn | DV21: 1303 | DW21: 1303 | DX21: 1225 | DY21: 1225 | DZ21: 1225 | EA21: 1225 | EB21: 1225 | EC21: 1225 | ED21: 1225 | EE21: 1225 | EF21: 1225 | EG21: 1225 | EH21: 1225 | EI21: 1225 | EJ21: 1225 | EK21: 1225 | EL21: 1225 | EM21: 1225 | EN21: 1225 | EO21: 1225 | EP21: 1225 | EQ21: 1225 | ER21: 1225 | ES21: 1225 | ET21: 1225 | EU21: 1225 | EV21: 1225 | EW21: 1225 | EX21: 1225 | EY21: 1225 | EZ21: 1225 | FA21: 1225 | FB21: 1225 | FC21: 1185 | FD21: 1185 | FE21: 1185 | FF21: 1185 | FG21: 1133 | FH21: 1133 | FI21: 1133 | FJ21: 1133 | FK21: 1133 | FL21: 1133 | FM21: 1133 | FN21: 1151 | FO21: 1151 | FP21: 1151 | FQ21: 1175 | FR21: 1175 | FS21: 1175 | FT21: 1175 | FU21: 1175 | FV21: 1175 | FW21: 1200 | FX21: 1200 | FY21: 1200 | FZ21: 1200 | GA21: 1143 | GB21: 1143 | GC21: 1143 | GD21: 1143 | GE21: 1143 | GF21: 1162 | GG21: 1162 | GH21: 1162 | GI21: 1162 | GJ21: 1175 | GK21: 1175 | GL21: 1175 | GM21: 1200 | GN21: 1200 | GO21: 1200 | GP21: 1200 | GQ21: 1230 | GR21: 1230 | GS21: 1230 | GT21: 1230 | GU21: 1260 | GV21: 1260 | GW21: 1260 | GX21: 1260 | GY21: 1260 | GZ21: 1250 | HA21: 1250 | HB21: 1250 | HC21: 1250 | HD21: 1174 | HE21: 1174 | HF21: 1174 | HG21: 1174 | HH21: 1131 | HI21: 1131 | HJ21: 1131 | HK21: 1131 | HL21: 1131 | HM21: 1154.4175 | HN21: 1154.4175 | HO21: 1154.4175 | HP21: 1154.4175 | HQ21: 1161.0769 | HR21: 1161.0769 | HS21: 1161.0769 | HT21: 1161.0769 | HU21: 1179.9226 | HV21: 1179.9226 | HW21: 1179.9226 | HX21: 1179.9226 | HY21: 1179.9226 | HZ21: 1183.4455 | IA21: 1183.4455 | IB21: 1183.4455 | IC21: 1183.4455 | ID21: 1181 | IE21: 1181 | IF21: 1181 | IG21: 1181 | IH21: 1185.2425 | II21: 1185.2425 | IJ21: 1185.2425 | IK21: 1185.2425 | IL21: 1190.7839 | IM21: 1190.7839 | IN21: 1190.7839 | IO21: 1190.7839 | IP21: 1188.899 | IQ21: 1188.899 | IR21: 1188.899 | IS21: 1188.899 | IT21: 1208.4564 | IU21: 1208.4564 | IV21: 1208.4564 | IW21: 1208.4564 | IX21: 1208.4564 | IY21: 1167.8122 | IZ21: 1167.8122 | JA21: 1167.8122 | JB21: 1167.8122 | JC21: 1185.3194 | JD21: 1185.3194 | JE21: 1185.3194 | JF21: 1185.3194 | JG21: 1185.3194 | JH21: 1163.1487 | JI21: 1163.1487 | JJ21: 1163.1487 | JK21: 1163.1487 | JL21: 1186.2628 | JM21: 1186.2628 | JN21: 1186.2628 | JO21: 1186.2628 | JP21: 1149.7077 | JQ21: 1149.7077 | JR21: 1149.7077 | JS21: 1149.7077 | JT21: 1149.7077 | JU21: 1070.5116 | JV21: 1070.5116 | JW21: 1070.5116 | JX21: 1070.5116 | JY21: 1092.8991 | JZ21: 1092.8991 | KA21: 1092.8991 | KB21: 1092.8991 | KC21: 1096.8837 | KD21: 1096.8837 | KE21: 1096.8837 | KF21: 1096.8837 | KG21: 1096.8837 | KH21: 1056.152 | KI21: 1056.152 | KJ21: 1056.152 | KK21: 1056.152 | KL21: 1057.7957 | KM21: 1057.7957 | KN21: 1057.7957 | KO21: 1057.7957 | KP21: 1077.9159 | KQ21: 1077.9159 | KR21: 1077.9159 | KS21: 1077.9159 | KT21: 1077.9159 | KU21: 1157.3856 | KV21: 1157.3856 | KW21: 1157.3856 | KX21: 1157.3856 | KY21: 1148.2324 | KZ21: 1148.2324 | LA21: 1148.2324 | LB21: 1148.2324 | LC21: 1150.4249 | LD21: 1150.4249 | LE21: 1150.4249 | LF21: 1150.4249 | LG21: 1150.4249
CF22: Điểm hòa vốn có 25% rewash | EG22: =EG21+35 -> 1260 | EH22: =EH21+35 -> 1260 | EI22: =EI21+35 -> 1260 | EJ22: =EJ21+35 -> 1260 | EK22: =EK21+35 -> 1260 | EL22: =EL21+35 -> 1260 | EM22: =EM21+35 -> 1260 | EN22: =EN21+35 -> 1260 | ... GA22: =GA21+35 -> 1178 | GB22: =GB21+20 -> 1163 | GC22: =GC21+20 -> 1163 | GD22: =GD21+20 -> 1163 | GE22: =GE21+20 -> 1163 | GF22: =GF21+20 -> 1182 | GG22: =GG21+20 -> 1182 | GH22: =GH21+20 -> 1182 | GI22: =GI21+20 -> 1182 | ... GT22: =GT21+20 -> 1250
H23: Giá bán đối thủ Intco | AS23: 1220 | AT23: 1220 | AU23: 1220 | CF23: Điểm hòa vốn (có phí hỗ trợ) | EG23: =EG21+34 -> 1259 | EH23: =EH21+34 -> 1259 | EI23: =EI21+34 -> 1259 | EJ23: =EJ21+34 -> 1259 | EK23: =EK21+34 -> 1259 | EL23: =EL21+34 -> 1259 | EM23: =EM21+34 -> 1259 | EN23: =EN21+34 -> 1259 | ... FM23: =FM21+34 -> 1167 | FN23: 1182 | FO23: 1182 | FP23: 1182 | FQ23: 1182 | FR23: 1182 | FS23: 1234 | FT23: 1234 | FU23: 1234 | FV23: 1234 | FW23: 1234 | FX23: 1234 | FY23: 1234 | FZ23: 1234 | GA23: 1234 | GB23: 1234 | GC23: 1234 | GD23: 1234 | GE23: 1234 | GF23: 1234 | GG23: 1234 | GH23: 1234 | GI23: 1234 | GJ23: 1234 | GK23: 1234 | GL23: 1234 | GM23: 1234 | GN23: 1234 | GO23: 1234 | GP23: 1234 | GQ23: 1234 | GR23: 1234 | GS23: 1234 | GT23: 1234
H24: Giá bán Unilever | X24: 1360 | Y24: 1360 | Z24: 1360 | AA24: 1550 | AB24: 1550 | AC24: 1550 | AD24: 1550 | AE24: 1534 | AF24: 1534 | AG24: 1534 | AH24: 1534 | AI24: 1534 | AJ24: 1534 | AK24: 1534 | AL24: 1445 | AM24: 1445 | AN24: 1445 | AO24: 1500 | AP24: 1500 | AQ24: 1500 | AR24: 1450 | AS24: 1450 | AT24: 1450 | AU24: 1350 | AV24: 1350 | AW24: 1350 | AX24: 1320 | AY24: 1320 | AZ24: 1320 | BA24: 1320 | BB24: 1320 | BC24: 1320 | BD24: 1300 | BE24: 1300 | BF24: 1300 | BG24: 1300 | BH24: 1300 | BI24: 1300 | BJ24: 1300 | BK24: 1300 | BL24: 1250 | BM24: 1250 | BN24: 1250 | BO24: 1250 | BP24: 1280 | BQ24: 1280 | BR24: 1280 | BS24: 1280 | BT24: 1280 | BU24: 1280 | BV24: 1250 | BW24: 1250 | BX24: 1250 | BY24: =1109+75 -> 1184 | BZ24: =1109+75 -> 1184 | CA24: =1109+75 -> 1184 | CB24: 1355 | CF24: Giá bán đối thủ Intco | FG24: 1200 | FJ24: 1200 | FK24: 1200 | FL24: 1200 | FM24: 1200 | FN24: 1200 | FO24: 1200 | FP24: 1200 | FQ24: 1200 | FR24: 1200 | FS24: 1200 | FT24: 1200 | FU24: 1200 | FV24: 1100 | FW24: 1100 | FX24: 1100 | FY24: 1100 | FZ24: 1100 | GA24: 1100 | GB24: 1100 | GC24: 1100 | GD24: 1100 | GE24: 1100 | GF24: 1100 | GG24: 1100 | GH24: 1100 | GI24: 1100 | GJ24: 1100 | GK24: 1100 | GL24: 1100 | GM24: 1100 | GN24: 1100 | GO24: 1100 | GP24: 1100 | GQ24: 1100 | GR24: 1100 | GS24: 1100 | GT24: 1100 | GU24: 1100 | GV24: 1100 | GW24: 1100 | GX24: 1100 | GY24: 1100 | GZ24: 1100 | HA24: 1100 | HB24: 1100 | HC24: 1100 | HD24: 1100 | HE24: 1100 | HF24: 1100 | HG24: 1100
CF25: Unilever | EG25: 1445 | EH25: 1445 | EI25: 1445 | EJ25: 1445 | EK25: 1445 | EL25: 1445 | EM25: 1445 | EN25: 1445 | EO25: 1445 | EP25: 1445 | EQ25: 1445 | ER25: 1445 | ES25: 1500 | ET25: 1500 | EU25: 1500 | EV25: 1500 | EW25: 1500 | EX25: 1500 | EY25: 1500 | EZ25: 1500 | FA25: 1500 | FB25: 1500 | FC25: 1500 | FD25: 1500 | FE25: 1500 | FF25: 1500 | FG25: 1450 | FH25: 1450 | FI25: 1450 | FJ25: 1450 | FK25: 1450 | FL25: 1450 | FM25: 1450 | FN25: 1450 | FO25: 1450 | FP25: 1450 | FQ25: 1450 | FR25: 1450 | FS25: 1350 | FT25: 1350 | FU25: 1350 | FV25: 1350 | FW25: 1350 | FX25: 1350 | FY25: 1350 | FZ25: 1350 | GA25: 1350 | GB25: 1350 | GC25: 1350 | GD25: 1350 | GE25: 1350 | GF25: 1320 | GG25: 1320 | GH25: 1320 | GI25: 1320 | GJ25: 1320 | GK25: 1320 | GL25: 1320 | GM25: 1320 | GN25: 1320 | GO25: 1320 | GP25: 1320 | GQ25: 1320 | GR25: 1320 | GS25: 1320 | GT25: 1320 | GU25: 1320 | GV25: 1320 | GW25: 1320 | GX25: 1320 | GY25: 1320 | GZ25: 1320 | HA25: 1320 | HB25: 1320 | HC25: 1320 | HD25: 1300 | HE25: 1300 | HF25: 1300 | HG25: 1300 | HH25: 1300 | HI25: 1300 | HJ25: 1300 | HK25: 1300 | HL25: 1300 | HM25: 1300 | HN25: 1300 | HO25: 1300 | HP25: 1300 | HQ25: 1300 | HR25: 1300 | HS25: 1300 | HT25: 1300 | HU25: 1300 | HV25: 1300 | HW25: 1300 | HX25: 1300 | HY25: 1300 | HZ25: 1300 | IA25: 1300 | IB25: 1300 | IC25: 1300 | ID25: 1300 | IE25: 1300 | IF25: 1300 | IG25: 1300 | IH25: 1300 | II25: 1300 | IJ25: 1300 | IK25: 1300 | IL25: 1250 | IM25: 1250 | IN25: 1250 | IO25: 1250 | IP25: 1250 | IQ25: 1250 | IR25: 1250 | IS25: 1250 | IT25: 1250 | IU25: 1250 | IV25: 1250 | IW25: 1250 | IX25: 1250 | IY25: 1250 | IZ25: 1250 | JA25: 1250 | JB25: 1250 | JC25: 1280 | JD25: 1280 | JE25: 1280 | JF25: 1280 | JG25: 1280 | JH25: 1280 | JI25: 1280 | JJ25: 1280 | JK25: 1280 | JL25: 1280 | JM25: 1280 | JN25: 1280 | JO25: 1280 | JP25: 1280 | JQ25: 1280 | JR25: 1280 | JS25: 1280 | JT25: 1280 | JU25: 1280 | JV25: 1280 | JW25: 1280 | JX25: 1280 | JY25: 1280 | JZ25: 1280 | KA25: 1280 | KB25: 1280 | KC25: 1250 | KD25: 1250 | KE25: 1250 | KF25: 1250 | KG25: 1250 | KH25: 1250 | KI25: 1250 | KJ25: 1250 | KK25: 1250 | KL25: 1250 | KM25: 1250 | KN25: 1250 | KO25: 1250 | KP25: 1184 | KQ25: 1184 | KR25: 1184 | KS25: 1184 | KT25: 1184 | KU25: 1184 | KV25: 1184 | KW25: 1184 | KX25: 1184 | KY25: 1184 | KZ25: 1184 | LA25: 1184 | LB25: 1184 | LC25: 1355 | LD25: 1355 | LE25: 1355 | LF25: 1355 | LG25: 1355

Sheet PET Fiber_tháng

Sheet PET Fiber_tuan 

Sheet Ma trận PET- Fiber
D3: MA TRẬN GIÁ BÁN rPET | F3: MA TRẬN GIÁ BÁN rPET | AV3: 2023 | BM3: 2024
F4: Tỷ giá | I4: 24000 | J4: 24000 | K4: 24000 | L4: 24000 | AV4: 24000 | AW4: 24000 | AX4: 24000 | AY4: 24000 | AZ4: 24000 | BA4: 24000 | BB4: 24000 | BC4: 24000 | BD4: 24000 | BE4: 24000 | BF4: 24000 | BG4: 24000 | BH4: 24000 | BI4: 24000 | BJ4: 24000 | BK4: 24000 | BL4: 24000 | BM4: 24000 | BN4: 24000 | BO4: 24000 | BP4: 24000 | DK4: 2025 | FJ4: 2026
A5: Stt | B5: Mã SAP | C5: Tên hàng hóa SAP | D5: Mã SP | E5: Tên sản phẩm | F5: Diễn giải | G5: Đơn vị tính | H5: Diễn giải | I5: 9 | J5: 10 | K5: 11 | L5: 12 | M5: T1.24 | N5: 2 | O5: 3 | P5: 4 | Q5: 5 | R5: 6 | S5: 7 | T5: 8 | U5: 9 | V5: 10 | W5: 11 | X5: 12 | Y5: T1.25 | Z5: 2 | AA5: 3 | AB5: 4 | AC5: 5 | AD5: 6 | AE5: 7 | AF5: 8 | AG5: 9 | AH5: 10 | AI5: 11 | AJ5: 12 | AK5: T1.26 | AL5: 2 | AM5: 3 | AN5: 4 | AO5: 5 | AP5: 6 | AQ5: 7 | AS5: Mã SP | AT5: Tên sản phẩm | AU5: Diễn giải | AV5: 36 | AW5: 37 | AX5: 38 | AY5: 39 | AZ5: 40 | BA5: 41 | BB5: 42 | BC5: 43 | BD5: 44 | BE5: 45 | BF5: 46 | BG5: 47 | BH5: 48 | BI5: 49 | BJ5: 50 | BK5: 51 | BL5: 52 | BM5: 1/24 | BN5: 02 | BO5: 03 | BP5: 04 | BQ5: 05 | BR5: 08 | BS5: 09 | BT5: 10 | BU5: 11 | BV5: 12 | BW5: 13 | BX5: 14 | BY5: 15 | BZ5: 16 | CA5: 17 | CB5: 18 | CC5: 19 | CD5: 20 | CE5: 21 | CF5: 22 | CG5: 23 | CH5: 24 | CI5: 25 | CJ5: 26 | CK5: 27 | CL5: 28 | CM5: 29 | CN5: 30 | CO5: 31 | CP5: 32 | CQ5: 33 | CR5: 34 | CS5: 35 | CT5: 36 | CU5: 37 | CV5: 38 | CW5: 39 | CX5: 40 | CY5: 41 | CZ5: 42 | DA5: 43 | DB5: 44 | DC5: 45 | DD5: 46 | DE5: 47 | DF5: 48 | DG5: 49 | DH5: 50 | DI5: 51 | DJ5: 52 | DK5: 01 | DL5: 02 | DM5: 03 | DN5: 04 | DO5: 06 | DP5: 07 | DQ5: 08 | DR5: 09 | DS5: 10 | DT5: 11 | DU5: 12 | DV5: 13 | DW5: 14 | DX5: 15 | DY5: 16 | DZ5: 17 | EA5: 18 | EB5: 19 | EC5: 20 | ED5: 21 | EE5: 22 | EF5: 23 | EG5: 24 | EH5: 25 | EI5: 26 | EJ5: 27 | EK5: 28 | EL5: 29 | EM5: 30 | EN5: 31 | EO5: 32 | EP5: 33 | EQ5: 34 | ER5: 35 | ES5: 36 | ET5: 37 | EU5: 38 | EV5: 39 | EW5: 40 | EX5: 41 | EY5: 42 | EZ5: 43 | FA5: 44 | FB5: 45 | FC5: 46 | FD5: 47 | FE5: 48 | FF5: 49 | FG5: 50 | FH5: 51 | FI5: 52 | FJ5: 01 | FK5: 02 | FL5: 03 | FM5: 04 | FN5: 05 | FO5: 06 | FP5: 07 | FQ5: 08 | FR5: 09 | FS5: 10 | FT5: 11 | FU5: 12 | FV5: 13 | FW5: 14 | FX5: 15 | FY5: 16 | FZ5: 17 | GA5: 18 | GB5: 19 | GC5: 20 | GD5: 21 | GE5: 22 | GF5: 23 | GG5: 24 | GH5: 25 | GI5: 26 | GJ5: 27 | GK5: 28 | GL5: 29 | GM5: 30 | GN5: 31
H6: DTR-Food grade | J6: ='Ma trận PET'!AU6 -> 1250 | K6: ='Ma trận PET'!AV6 -> 1250 | L6: ='Ma trận PET'!AW6 -> 1250 | M6: ='Ma trận PET'!AX6 -> 1250 | N6: ='Ma trận PET'!AY6 -> 1250 | O6: ='Ma trận PET'!AZ6 -> 1250 | P6: ='Ma trận PET'!BA6 -> 1250 | Q6: ='Ma trận PET'!BB6 -> 1300 | ... U6: ='Ma trận PET'!BF6 -> 1310 | V6: =U6+15 -> 1325 | W6: =V6 -> 1325 | X6: =W6-50 -> 1275 | Y6: =X6-45 -> 1230 | Z6: =Y6 -> 1230 | AA6: =Z6 -> 1230 | AB6: =AA6+20 -> 1250 | AC6: =AB6 -> 1250 | AD6: =AC6 -> 1250 | AE6: =AD6 -> 1250 | AF6: =AE6-20-10 -> 1220 | AG6: =AF6 -> 1220 | AH6: 1210 | AI6: 1200 | AJ6: 1200 | AK6: 1160 | AL6: 1160 | AM6: 1160 | AN6: 1280 | AO6: 1380 | AP6: 1350 | AQ6: 1350 | AU6: DTR-Food grade | AV6: ='Ma trận PET'!FO6 -> 1250 | AW6: ='Ma trận PET'!FP6 -> 1250 | AX6: ='Ma trận PET'!FQ6 -> 1250 | AY6: ='Ma trận PET'!FR6 -> 1250 | AZ6: ='Ma trận PET'!FS6 -> 1250 | BA6: ='Ma trận PET'!FT6 -> 1250 | BB6: ='Ma trận PET'!FU6 -> 1250 | BC6: ='Ma trận PET'!FV6 -> 1250 | ... BQ6: ='Ma trận PET'!GJ6 -> 1250 | BR6: 1250 | BS6: 1250 | BT6: 1250 | BU6: 1250 | BV6: 1250 | BW6: 1250 | BX6: 1250 | BY6: 1250 | BZ6: 1250 | CA6: 1250 | CB6: 1300 | CC6: 1300 | CD6: 1300 | CE6: 1300 | CF6: 1300 | CG6: 1300 | CH6: 1300 | CI6: 1300 | CJ6: 1300 | CK6: 1300 | CL6: 1300 | CM6: 1300 | CN6: 1300 | CO6: 1300 | CP6: 1300 | CQ6: 1300 | CR6: 1300 | CS6: 1300 | CT6: 1310 | CU6: 1310 | CV6: 1310 | CW6: 1310 | CX6: 1325 | CY6: 1325 | CZ6: 1325 | DA6: 1325 | DB6: 1325 | DC6: 1325 | DD6: 1325 | DE6: 1325 | DF6: 1325 | DG6: =1325-50 -> 1275 | DH6: =1325-50 -> 1275 | DI6: =1325-50 -> 1275 | DJ6: =1325-50 -> 1275 | DK6: =1325-50-45 -> 1230 | DL6: =1325-50-45 -> 1230 | DM6: =1325-50-45 -> 1230 | DN6: =1325-50-45 -> 1230 | DO6: =1325-50-45 -> 1230 | DP6: =1325-50-45 -> 1230 | DQ6: =1325-50-45 -> 1230 | DR6: =1325-50-45 -> 1230 | ... DV6: =1325-50-45 -> 1230 | DW6: =1325-50-45+20 -> 1250 | DX6: =1325-50-45+20 -> 1250 | DY6: =1325-50-45+20 -> 1250 | DZ6: =1325-50-45+20 -> 1250 | EA6: =1325-50-45+20 -> 1250 | EB6: =1325-50-45+20 -> 1250 | EC6: =1325-50-45+20 -> 1250 | ED6: =1325-50-45+20 -> 1250 | ... EN6: =1325-50-45+20 -> 1250 | EO6: =1325-50-45+20-20-10 -> 1220 | EP6: =1325-50-45+20-20-10 -> 1220 | EQ6: =1325-50-45+20-20-10 -> 1220 | ER6: =1325-50-45+20-20-10 -> 1220 | ES6: =1325-50-45+20-20-10 -> 1220 | ET6: =1325-50-45+20-20-10 -> 1220 | EU6: =1325-50-45+20-20-10 -> 1220 | EV6: =1325-50-45+20-20-10 -> 1220 | EW6: =1325-50-45+20-20-10-10 -> 1210 | EX6: =1325-50-45+20-20-10-10 -> 1210 | EY6: =1325-50-45+20-20-10-10 -> 1210 | EZ6: =1325-50-45+20-20-10-10 -> 1210 | FA6: =1325-50-45+20-20-10-10 -> 1210 | FB6: =1325-50-45+20-20-10-10-10 -> 1200 | FC6: =1325-50-45+20-20-10-10-10 -> 1200 | FD6: =1325-50-45+20-20-10-10-10 -> 1200 | FE6: =1325-50-45+20-20-10-10-10 -> 1200 | FF6: =1325-50-45+20-20-10-10-10 -> 1200 | FG6: =1325-50-45+20-20-10-10-10 -> 1200 | FH6: =1325-50-45+20-20-10-10-10 -> 1200 | FI6: =1325-50-45+20-20-10-10-10 -> 1200 | FJ6: =1325-50-45+20-20-10-10-10-40 -> 1160 | FK6: =1325-50-45+20-20-10-10-10-40 -> 1160 | FL6: =1325-50-45+20-20-10-10-10-40 -> 1160 | FM6: =1325-50-45+20-20-10-10-10-40 -> 1160 | FN6: =1325-50-45+20-20-10-10-10-40 -> 1160 | FO6: =1325-50-45+20-20-10-10-10-40 -> 1160 | FP6: =1325-50-45+20-20-10-10-10-40 -> 1160 | FQ6: =1325-50-45+20-20-10-10-10-40 -> 1160 | ... FT6: =1325-50-45+20-20-10-10-10-40 -> 1160 | FU6: =1325-50-45+20-20-10-10-10-40+50 -> 1210 | FV6: 1280 | FW6: 1280 | FX6: 1280 | FY6: 1310 | FZ6: 1380 | GA6: 1380 | GB6: 1380 | GC6: 1380 | GD6: 1380 | GE6: 1380 | GF6: 1350 | GG6: 1350 | GH6: 1350 | GI6: 1350 | GJ6: 1330 | GK6: 1330
A7: 5 | B7: 110000329 | C7: Hạt rPET WSS01 | E7: WSS01 - Hạt rPET (IV 0.78) | F7: Giá DTR | G7: $ /tấn | H7: DTR | I7: 1050 | J7: 1050 | K7: 1050 | L7: 1050 | M7: 1050 | N7: 1050 | O7: 1050 | P7: 1050 | Q7: 1100 | R7: 1100 | S7: 1100 | T7: 1100 | U7: 1100 | V7: 1100 | W7: 1100 | X7: 1100 | Y7: 1100 | Z7: 1100 | AA7: 1100 | AB7: 1120 | AC7: 1120 | AD7: 1120 | AE7: =+AE6-130 -> 1120 | AF7: =+AF6-130 -> 1090 | AG7: =+AG6-130 -> 1090 | AH7: =+AH6-130 -> 1080 | AI7: =+AI6-130 -> 1070 | AJ7: =+AJ6-130 -> 1070 | AK7: =+AK6-130 -> 1030 | AL7: =+AL6-130 -> 1030 | ... AQ7: =+AQ6-130 -> 1220 | AT7: WSS01 - Hạt rPET (IV 0.78) | AU7: DTR | AV7: 1050 | AW7: 1050 | AX7: 1050 | AY7: 1050 | AZ7: 1050 | BA7: 1050 | BB7: 1050 | BC7: 1050 | BD7: 1050 | BE7: 1050 | BF7: 1050 | BG7: 1050 | BH7: 1050 | BI7: 1050 | BJ7: 1050 | BK7: 1050 | BL7: 1050 | BM7: 1050 | BN7: 1050 | BO7: 1050 | BP7: 1050 | BQ7: 1050 | BR7: 1050 | BS7: 1050 | BT7: 1050 | BU7: 1050 | BV7: 1050 | BW7: 1050 | BX7: 1050 | BY7: 1050 | BZ7: 1050 | CA7: 1050 | CB7: 1100 | CC7: 1100 | CD7: 1100 | CE7: 1100 | CF7: 1100 | CG7: 1100 | CH7: 1100 | CI7: 1100 | CJ7: 1100 | CK7: 1100 | CL7: 1100 | CM7: 1100 | CN7: 1100 | CO7: 1100 | CP7: 1100 | CQ7: 1100 | CR7: 1100 | CS7: 1100 | CT7: 1100 | CU7: 1100 | CV7: 1100 | CW7: 1100 | CX7: 1100 | CY7: 1100 | CZ7: 1100 | DA7: 1100 | DB7: 1100 | DC7: 1100 | DD7: 1100 | DE7: 1100 | DF7: 1100 | DG7: 1100 | DH7: 1100 | DI7: 1100 | DJ7: 1100 | DK7: 1100 | DL7: 1100 | DM7: 1100 | DN7: 1100 | DO7: 1100 | DP7: 1100 | DQ7: 1100 | DR7: 1100 | DS7: 1100 | DT7: 1100 | DU7: 1100 | DV7: 1100 | DW7: 1120 | DX7: 1120 | DY7: 1120 | DZ7: 1120 | EA7: 1120 | EB7: 1120 | EC7: 1120 | ED7: 1120 | EE7: 1120 | EF7: 1120 | EG7: 1120 | EH7: 1120 | EI7: 1120 | EJ7: 1120 | EK7: 1120 | EL7: 1120 | EM7: 1120 | EN7: 1120 | EO7: =+EO6-130 -> 1090 | EP7: =+EP6-130 -> 1090 | EQ7: =+EQ6-130 -> 1090 | ER7: =+ER6-130 -> 1090 | ES7: =+ES6-130 -> 1090 | ET7: =+ET6-130 -> 1090 | EU7: =+EU6-130 -> 1090 | EV7: =+EV6-130 -> 1090 | ... GN7: =+GN6-130 -> -130
