Workbook
Name Code_General_Data: 'General Data'!$A$9:$A$137
Name Code_General_Item: 'General Data'!$C$9:$C$137
Name General_Data: 'General Data'!$F$9:$BB$137
Name Month: 'General Data'!$F$4:$BB$4
Name Year: 'General Data'!$F$3:$BB$3

Sheet BÌA
A5: MA TRẬN KHÁCH HÀNG
C11: I. | D11: TỔNG QUAN GIÁ CÔNG THỨC THEO KHÁCH HÀNG
C14: II. | D14: CHI TIẾT GIÁ CÔNG THỨC THEO KHÁCH HÀNG
C17: III. | D17: BIỂU ĐỒ

Sheet Giá công thức
G1: =DATE(G3,G4,1) -> 45292 | H1: =DATE(H3,H4,1) -> 45323 | I1: =DATE(I3,I4,1) -> 45352 | J1: =DATE(J3,J4,1) -> 45383 | K1: =DATE(K3,K4,1) -> 45413 | L1: =DATE(L3,L4,1) -> 45444 | M1: =DATE(M3,M4,1) -> 45474 | N1: =DATE(N3,N4,1) -> 45505 | ... AP1: =DATE(AP3,AP4,1) -> 46357
G2: =EOMONTH(G1,0) -> 45322 | H2: =EOMONTH(H1,0) -> 45351 | I2: =EOMONTH(I1,0) -> 45382 | J2: =EOMONTH(J1,0) -> 45412 | K2: =EOMONTH(K1,0) -> 45443 | L2: =EOMONTH(L1,0) -> 45473 | M2: =EOMONTH(M1,0) -> 45504 | N2: =EOMONTH(N1,0) -> 45535 | ... AP2: =EOMONTH(AP1,0) -> 46387
G3: 2024 | H3: 2024 | I3: 2024 | J3: 2024 | K3: 2024 | L3: 2024 | M3: 2024 | N3: 2024 | O3: 2024 | P3: 2024 | Q3: 2024 | R3: 2024 | S3: 2025 | T3: 2025 | U3: 2025 | V3: 2025 | W3: 2025 | X3: 2025 | Y3: 2025 | Z3: 2025 | AA3: 2025 | AB3: 2025 | AC3: 2025 | AD3: 2025 | AE3: 2026 | AF3: 2026 | AG3: 2026 | AH3: 2026 | AI3: 2026 | AJ3: 2026 | AK3: 2026 | AL3: 2026 | AM3: 2026 | AN3: 2026 | AO3: 2026 | AP3: 2026
G4: 1 | H4: 2 | I4: 3 | J4: 4 | K4: 5 | L4: 6 | M4: 7 | N4: 8 | O4: 9 | P4: 10 | Q4: 11 | R4: 12 | S4: 1 | T4: 2 | U4: 3 | V4: 4 | W4: 5 | X4: 6 | Y4: 7 | Z4: 8 | AA4: 9 | AB4: 10 | AC4: 11 | AD4: 12 | AE4: 1 | AF4: 2 | AG4: 3 | AH4: 4 | AI4: 5 | AJ4: 6 | AK4: 7 | AL4: 8 | AM4: 9 | AN4: 10 | AO4: 11 | AP4: 12
G5: I. GIÁ CÔNG THỨC THEO KHÁCH HÀNG | S5: I. GIÁ CÔNG THỨC THEO KHÁCH HÀNG | AE5: I. GIÁ CÔNG THỨC THEO KHÁCH HÀNG
D8: STT | E8: KHÁCH HÀNG/SẢN PHẨM | G8: 2024 | S8: 2025 | AE8: 2026
G9: 1 | H9: 2 | I9: 3 | J9: 4 | K9: 5 | L9: 6 | M9: 7 | N9: 8 | O9: 9 | P9: 10 | Q9: 11 | R9: 12 | S9: 1 | T9: 2 | U9: 3 | V9: 4 | W9: 5 | X9: 6 | Y9: 7 | Z9: 8 | AA9: 9 | AB9: 10 | AC9: 11 | AD9: 12 | AE9: 1 | AF9: 2 | AG9: 3 | AH9: 4 | AI9: 5 | AJ9: 6 | AK9: 7 | AL9: 8 | AM9: 9 | AN9: 10 | AO9: 11 | AP9: 12
A11: 200319 | D11: 1 | E11: NIAGARA
A12: 200319 | B12: 110000354 | F12: WSS01G
A13: 200319 | B13: 110000354 | D13: 1.1 | F13: Giá bán - FOB | G13: {=INDEX(Price!$L$11:$AY$210,MATCH(1,(Price!$A$11:$A$210=$A13)*(Price!$B$11:$B$210=$B13)*(Price!$D$11:$D$210="gb"),0),MATCH(1,(Price!$L$3:$AY$3=G$3)*(Price!$L$4:$AY$4=G$4),0))} -> 1200 | H13: {=INDEX(Price!$L$11:$AY$210,MATCH(1,(Price!$A$11:$A$210=$A13)*(Price!$B$11:$B$210=$B13)*(Price!$D$11:$D$210="gb"),0),MATCH(1,(Price!$L$3:$AY$3=H$3)*(Price!$L$4:$AY$4=H$4),0))} -> 1200 | I13: {=INDEX(Price!$L$11:$AY$210,MATCH(1,(Price!$A$11:$A$210=$A13)*(Price!$B$11:$B$210=$B13)*(Price!$D$11:$D$210="gb"),0),MATCH(1,(Price!$L$3:$AY$3=I$3)*(Price!$L$4:$AY$4=I$4),0))} -> 1200 | J13: {=INDEX(Price!$L$11:$AY$210,MATCH(1,(Price!$A$11:$A$210=$A13)*(Price!$B$11:$B$210=$B13)*(Price!$D$11:$D$210="gb"),0),MATCH(1,(Price!$L$3:$AY$3=J$3)*(Price!$L$4:$AY$4=J$4),0))} -> 1200 | K13: {=INDEX(Price!$L$11:$AY$210,MATCH(1,(Price!$A$11:$A$210=$A13)*(Price!$B$11:$B$210=$B13)*(Price!$D$11:$D$210="gb"),0),MATCH(1,(Price!$L$3:$AY$3=K$3)*(Price!$L$4:$AY$4=K$4),0))} -> 1200 | L13: {=INDEX(Price!$L$11:$AY$210,MATCH(1,(Price!$A$11:$A$210=$A13)*(Price!$B$11:$B$210=$B13)*(Price!$D$11:$D$210="gb"),0),MATCH(1,(Price!$L$3:$AY$3=L$3)*(Price!$L$4:$AY$4=L$4),0))} -> 1200.9 | M13: {=INDEX(Price!$L$11:$AY$210,MATCH(1,(Price!$A$11:$A$210=$A13)*(Price!$B$11:$B$210=$B13)*(Price!$D$11:$D$210="gb"),0),MATCH(1,(Price!$L$3:$AY$3=M$3)*(Price!$L$4:$AY$4=M$4),0))} -> 1214.4 | N13: {=INDEX(Price!$L$11:$AY$210,MATCH(1,(Price!$A$11:$A$210=$A13)*(Price!$B$11:$B$210=$B13)*(Price!$D$11:$D$210="gb"),0),MATCH(1,(Price!$L$3:$AY$3=N$3)*(Price!$L$4:$AY$4=N$4),0))} -> 1226.1 | ... AJ13: {=INDEX(Price!$L$11:$AY$210,MATCH(1,(Price!$A$11:$A$210=$A13)*(Price!$B$11:$B$210=$B13)*(Price!$D$11:$D$210="gb"),0),MATCH(1,(Price!$L$3:$AY$3=AJ$3)*(Price!$L$4:$AY$4=AJ$4),0))} -> 1221
A14: 200319 | B14: 110000354 | C14: GB | D14: 1.2 | F14: Giá bán quy đổi EXW | G14: {=INDEX(Price!$L$11:$AY$210,MATCH(1,(Price!$A$11:$A$210=$A14)*(Price!$B$11:$B$210=$B14)*(Price!$D$11:$D$210="exw"),0),MATCH(1,(Price!$L$3:$AY$3=G$3)*(Price!$L$4:$AY$4=G$4),0))} -> 1162 | H14: {=INDEX(Price!$L$11:$AY$210,MATCH(1,(Price!$A$11:$A$210=$A14)*(Price!$B$11:$B$210=$B14)*(Price!$D$11:$D$210="exw"),0),MATCH(1,(Price!$L$3:$AY$3=H$3)*(Price!$L$4:$AY$4=H$4),0))} -> 1162 | I14: {=INDEX(Price!$L$11:$AY$210,MATCH(1,(Price!$A$11:$A$210=$A14)*(Price!$B$11:$B$210=$B14)*(Price!$D$11:$D$210="exw"),0),MATCH(1,(Price!$L$3:$AY$3=I$3)*(Price!$L$4:$AY$4=I$4),0))} -> 1162 | J14: {=INDEX(Price!$L$11:$AY$210,MATCH(1,(Price!$A$11:$A$210=$A14)*(Price!$B$11:$B$210=$B14)*(Price!$D$11:$D$210="exw"),0),MATCH(1,(Price!$L$3:$AY$3=J$3)*(Price!$L$4:$AY$4=J$4),0))} -> 1162 | K14: {=INDEX(Price!$L$11:$AY$210,MATCH(1,(Price!$A$11:$A$210=$A14)*(Price!$B$11:$B$210=$B14)*(Price!$D$11:$D$210="exw"),0),MATCH(1,(Price!$L$3:$AY$3=K$3)*(Price!$L$4:$AY$4=K$4),0))} -> 1162 | L14: {=INDEX(Price!$L$11:$AY$210,MATCH(1,(Price!$A$11:$A$210=$A14)*(Price!$B$11:$B$210=$B14)*(Price!$D$11:$D$210="exw"),0),MATCH(1,(Price!$L$3:$AY$3=L$3)*(Price!$L$4:$AY$4=L$4),0))} -> 1162.8865 | M14: {=INDEX(Price!$L$11:$AY$210,MATCH(1,(Price!$A$11:$A$210=$A14)*(Price!$B$11:$B$210=$B14)*(Price!$D$11:$D$210="exw"),0),MATCH(1,(Price!$L$3:$AY$3=M$3)*(Price!$L$4:$AY$4=M$4),0))} -> 1176.184 | N14: {=INDEX(Price!$L$11:$AY$210,MATCH(1,(Price!$A$11:$A$210=$A14)*(Price!$B$11:$B$210=$B14)*(Price!$D$11:$D$210="exw"),0),MATCH(1,(Price!$L$3:$AY$3=N$3)*(Price!$L$4:$AY$4=N$4),0))} -> 1187.7085 | ... AJ14: {=INDEX(Price!$L$11:$AY$210,MATCH(1,(Price!$A$11:$A$210=$A14)*(Price!$B$11:$B$210=$B14)*(Price!$D$11:$D$210="exw"),0),MATCH(1,(Price!$L$3:$AY$3=AJ$3)*(Price!$L$4:$AY$4=AJ$4),0))} -> 1182.685
A15: 200319 | B15: 110000354 | C15: PETVirgin | D15: 1.3 | F15: Giá chính phẩm | G15: {=SUMPRODUCT(General_Data*(Code_General_Data=$C15)*(Year=G$3)*(Month=G$4))} -> 930 | H15: {=SUMPRODUCT(General_Data*(Code_General_Data=$C15)*(Year=H$3)*(Month=H$4))} -> 943.33333 | I15: {=SUMPRODUCT(General_Data*(Code_General_Data=$C15)*(Year=I$3)*(Month=I$4))} -> 940 | J15: {=SUMPRODUCT(General_Data*(Code_General_Data=$C15)*(Year=J$3)*(Month=J$4))} -> 940 | K15: {=SUMPRODUCT(General_Data*(Code_General_Data=$C15)*(Year=K$3)*(Month=K$4))} -> 942 | L15: {=SUMPRODUCT(General_Data*(Code_General_Data=$C15)*(Year=L$3)*(Month=L$4))} -> 950 | M15: {=SUMPRODUCT(General_Data*(Code_General_Data=$C15)*(Year=M$3)*(Month=M$4))} -> 947.5 | N15: {=SUMPRODUCT(General_Data*(Code_General_Data=$C15)*(Year=N$3)*(Month=N$4))} -> 930 | ... AJ15: {=SUMPRODUCT(General_Data*(Code_General_Data=$C15)*(Year=AJ$3)*(Month=AJ$4))} -> 1190
A16: 200319 | B16: 110000354 | D16: 1.4 | F16: Chênh lệch giữa R sv Virgin | G16: =IF(G13*G14*G15<>0,G14-G15,0) -> 232 | H16: =IF(H13*H14*H15<>0,H14-H15,0) -> 218.66667 | I16: =IF(I13*I14*I15<>0,I14-I15,0) -> 222 | J16: =IF(J13*J14*J15<>0,J14-J15,0) -> 222 | K16: =IF(K13*K14*K15<>0,K14-K15,0) -> 220 | L16: =IF(L13*L14*L15<>0,L14-L15,0) -> 212.8865 | M16: =IF(M13*M14*M15<>0,M14-M15,0) -> 228.684 | N16: =IF(N13*N14*N15<>0,N14-N15,0) -> 257.7085 | ... AJ16: =IF(AJ13*AJ14*AJ15<>0,AJ14-AJ15,0) -> -7.315
A17: 200319 | B17: 110000354 | D17: 1.5 | F17: % +/- | G17: =IFERROR(G16/G15,0) -> 0.24946237 | H17: =IFERROR(H16/H15,0) -> 0.23180212 | I17: =IFERROR(I16/I15,0) -> 0.23617021 | J17: =IFERROR(J16/J15,0) -> 0.23617021 | K17: =IFERROR(K16/K15,0) -> 0.23354565 | L17: =IFERROR(L16/L15,0) -> 0.22409105 | M17: =IFERROR(M16/M15,0) -> 0.24135515 | N17: =IFERROR(N16/N15,0) -> 0.27710591 | ... AJ17: =IFERROR(AJ16/AJ15,0) -> -0.0061470588
A18: 200319 | B18: 110000354 | C18: 110000354 | D18: 1.6 | F18: Giá duyệt tháng | G18: {=SUMPRODUCT(General_Data*(Code_General_Data=$C18)*(Year=G$3)*(Month=G$4))} -> 1250 | H18: {=SUMPRODUCT(General_Data*(Code_General_Data=$C18)*(Year=H$3)*(Month=H$4))} -> 1250 | I18: {=SUMPRODUCT(General_Data*(Code_General_Data=$C18)*(Year=I$3)*(Month=I$4))} -> 1250 | J18: {=SUMPRODUCT(General_Data*(Code_General_Data=$C18)*(Year=J$3)*(Month=J$4))} -> 1250 | K18: {=SUMPRODUCT(General_Data*(Code_General_Data=$C18)*(Year=K$3)*(Month=K$4))} -> 1300 | L18: {=SUMPRODUCT(General_Data*(Code_General_Data=$C18)*(Year=L$3)*(Month=L$4))} -> 1300 | M18: {=SUMPRODUCT(General_Data*(Code_General_Data=$C18)*(Year=M$3)*(Month=M$4))} -> 1300 | N18: {=SUMPRODUCT(General_Data*(Code_General_Data=$C18)*(Year=N$3)*(Month=N$4))} -> 1300 | ... AJ18: {=SUMPRODUCT(General_Data*(Code_General_Data=$C18)*(Year=AJ$3)*(Month=AJ$4))} -> 1350
A20: 200400 | D20: 2 | E20: SHEPLEY (NIAGARA NON-US)
A21: 200400 | B21: 110000354 | F21: WSS01G
A22: 200400 | B22: 110000354 | D22: 2.1 | F22: Giá bán - FOB | G22: {=INDEX(Price!$L$11:$AY$210,MATCH(1,(Price!$A$11:$A$210=$A22)*(Price!$B$11:$B$210=$B22)*(Price!$D$11:$D$210="gb"),0),MATCH(1,(Price!$L$3:$AY$3=G$3)*(Price!$L$4:$AY$4=G$4),0))} -> 1200 | H22: {=INDEX(Price!$L$11:$AY$210,MATCH(1,(Price!$A$11:$A$210=$A22)*(Price!$B$11:$B$210=$B22)*(Price!$D$11:$D$210="gb"),0),MATCH(1,(Price!$L$3:$AY$3=H$3)*(Price!$L$4:$AY$4=H$4),0))} -> 1200 | I22: {=INDEX(Price!$L$11:$AY$210,MATCH(1,(Price!$A$11:$A$210=$A22)*(Price!$B$11:$B$210=$B22)*(Price!$D$11:$D$210="gb"),0),MATCH(1,(Price!$L$3:$AY$3=I$3)*(Price!$L$4:$AY$4=I$4),0))} -> 1200 | J22: {=INDEX(Price!$L$11:$AY$210,MATCH(1,(Price!$A$11:$A$210=$A22)*(Price!$B$11:$B$210=$B22)*(Price!$D$11:$D$210="gb"),0),MATCH(1,(Price!$L$3:$AY$3=J$3)*(Price!$L$4:$AY$4=J$4),0))} -> 1200 | K22: {=INDEX(Price!$L$11:$AY$210,MATCH(1,(Price!$A$11:$A$210=$A22)*(Price!$B$11:$B$210=$B22)*(Price!$D$11:$D$210="gb"),0),MATCH(1,(Price!$L$3:$AY$3=K$3)*(Price!$L$4:$AY$4=K$4),0))} -> 1200 | L22: {=INDEX(Price!$L$11:$AY$210,MATCH(1,(Price!$A$11:$A$210=$A22)*(Price!$B$11:$B$210=$B22)*(Price!$D$11:$D$210="gb"),0),MATCH(1,(Price!$L$3:$AY$3=L$3)*(Price!$L$4:$AY$4=L$4),0))} -> 1200.9 | M22: {=INDEX(Price!$L$11:$AY$210,MATCH(1,(Price!$A$11:$A$210=$A22)*(Price!$B$11:$B$210=$B22)*(Price!$D$11:$D$210="gb"),0),MATCH(1,(Price!$L$3:$AY$3=M$3)*(Price!$L$4:$AY$4=M$4),0))} -> 1214.4 | N22: {=INDEX(Price!$L$11:$AY$210,MATCH(1,(Price!$A$11:$A$210=$A22)*(Price!$B$11:$B$210=$B22)*(Price!$D$11:$D$210="gb"),0),MATCH(1,(Price!$L$3:$AY$3=N$3)*(Price!$L$4:$AY$4=N$4),0))} -> 1226.1 | ... AJ22: {=INDEX(Price!$L$11:$AY$210,MATCH(1,(Price!$A$11:$A$210=$A22)*(Price!$B$11:$B$210=$B22)*(Price!$D$11:$D$210="gb"),0),MATCH(1,(Price!$L$3:$AY$3=AJ$3)*(Price!$L$4:$AY$4=AJ$4),0))} -> 1150
A23: 200400 | B23: 110000354 | C23: GB | D23: 2.2 | F23: Giá bán quy đổi EXW | G23: {=INDEX(Price!$L$11:$AY$210,MATCH(1,(Price!$A$11:$A$210=$A23)*(Price!$B$11:$B$210=$B23)*(Price!$D$11:$D$210="exw"),0),MATCH(1,(Price!$L$3:$AY$3=G$3)*(Price!$L$4:$AY$4=G$4),0))} -> 1162 | H23: {=INDEX(Price!$L$11:$AY$210,MATCH(1,(Price!$A$11:$A$210=$A23)*(Price!$B$11:$B$210=$B23)*(Price!$D$11:$D$210="exw"),0),MATCH(1,(Price!$L$3:$AY$3=H$3)*(Price!$L$4:$AY$4=H$4),0))} -> 1162 | I23: {=INDEX(Price!$L$11:$AY$210,MATCH(1,(Price!$A$11:$A$210=$A23)*(Price!$B$11:$B$210=$B23)*(Price!$D$11:$D$210="exw"),0),MATCH(1,(Price!$L$3:$AY$3=I$3)*(Price!$L$4:$AY$4=I$4),0))} -> 1162 | J23: {=INDEX(Price!$L$11:$AY$210,MATCH(1,(Price!$A$11:$A$210=$A23)*(Price!$B$11:$B$210=$B23)*(Price!$D$11:$D$210="exw"),0),MATCH(1,(Price!$L$3:$AY$3=J$3)*(Price!$L$4:$AY$4=J$4),0))} -> 1162 | K23: {=INDEX(Price!$L$11:$AY$210,MATCH(1,(Price!$A$11:$A$210=$A23)*(Price!$B$11:$B$210=$B23)*(Price!$D$11:$D$210="exw"),0),MATCH(1,(Price!$L$3:$AY$3=K$3)*(Price!$L$4:$AY$4=K$4),0))} -> 1162 | L23: {=INDEX(Price!$L$11:$AY$210,MATCH(1,(Price!$A$11:$A$210=$A23)*(Price!$B$11:$B$210=$B23)*(Price!$D$11:$D$210="exw"),0),MATCH(1,(Price!$L$3:$AY$3=L$3)*(Price!$L$4:$AY$4=L$4),0))} -> 1162.8865 | M23: {=INDEX(Price!$L$11:$AY$210,MATCH(1,(Price!$A$11:$A$210=$A23)*(Price!$B$11:$B$210=$B23)*(Price!$D$11:$D$210="exw"),0),MATCH(1,(Price!$L$3:$AY$3=M$3)*(Price!$L$4:$AY$4=M$4),0))} -> 1176.184 | N23: {=INDEX(Price!$L$11:$AY$210,MATCH(1,(Price!$A$11:$A$210=$A23)*(Price!$B$11:$B$210=$B23)*(Price!$D$11:$D$210="exw"),0),MATCH(1,(Price!$L$3:$AY$3=N$3)*(Price!$L$4:$AY$4=N$4),0))} -> 1187.7085 | ... AJ23: {=INDEX(Price!$L$11:$AY$210,MATCH(1,(Price!$A$11:$A$210=$A23)*(Price!$B$11:$B$210=$B23)*(Price!$D$11:$D$210="exw"),0),MATCH(1,(Price!$L$3:$AY$3=AJ$3)*(Price!$L$4:$AY$4=AJ$4),0))} -> 1112.75
A24: 200400 | B24: 110000354 | C24: PETVirgin | D24: 2.3 | F24: Giá chính phẩm | G24: {=SUMPRODUCT(General_Data*(Code_General_Data=$C24)*(Year=G$3)*(Month=G$4))} -> 930 | H24: {=SUMPRODUCT(General_Data*(Code_General_Data=$C24)*(Year=H$3)*(Month=H$4))} -> 943.33333 | I24: {=SUMPRODUCT(General_Data*(Code_General_Data=$C24)*(Year=I$3)*(Month=I$4))} -> 940 | J24: {=SUMPRODUCT(General_Data*(Code_General_Data=$C24)*(Year=J$3)*(Month=J$4))} -> 940 | K24: {=SUMPRODUCT(General_Data*(Code_General_Data=$C24)*(Year=K$3)*(Month=K$4))} -> 942 | L24: {=SUMPRODUCT(General_Data*(Code_General_Data=$C24)*(Year=L$3)*(Month=L$4))} -> 950 | M24: {=SUMPRODUCT(General_Data*(Code_General_Data=$C24)*(Year=M$3)*(Month=M$4))} -> 947.5 | N24: {=SUMPRODUCT(General_Data*(Code_General_Data=$C24)*(Year=N$3)*(Month=N$4))} -> 930 | ... AJ24: {=SUMPRODUCT(General_Data*(Code_General_Data=$C24)*(Year=AJ$3)*(Month=AJ$4))} -> 1190
A25: 200400 | B25: 110000354 | D25: 2.4 | F25: Chênh lệch giữa R sv Virgin | G25: =IF(G22*G23*G24<>0,G23-G24,0) -> 232 | H25: =IF(H22*H23*H24<>0,H23-H24,0) -> 218.66667 | I25: =IF(I22*I23*I24<>0,I23-I24,0) -> 222 | J25: =IF(J22*J23*J24<>0,J23-J24,0) -> 222 | K25: =IF(K22*K23*K24<>0,K23-K24,0) -> 220 | L25: =IF(L22*L23*L24<>0,L23-L24,0) -> 212.8865 | M25: =IF(M22*M23*M24<>0,M23-M24,0) -> 228.684 | N25: =IF(N22*N23*N24<>0,N23-N24,0) -> 257.7085 | ... AJ25: =IF(AJ22*AJ23*AJ24<>0,AJ23-AJ24,0) -> -77.25
A26: 200400 | B26: 110000354 | D26: 2.5 | F26: % +/- | G26: =IFERROR(G25/G24,0) -> 0.24946237 | H26: =IFERROR(H25/H24,0) -> 0.23180212 | I26: =IFERROR(I25/I24,0) -> 0.23617021 | J26: =IFERROR(J25/J24,0) -> 0.23617021 | K26: =IFERROR(K25/K24,0) -> 0.23354565 | L26: =IFERROR(L25/L24,0) -> 0.22409105 | M26: =IFERROR(M25/M24,0) -> 0.24135515 | N26: =IFERROR(N25/N24,0) -> 0.27710591 | ... AJ26: =IFERROR(AJ25/AJ24,0) -> -0.064915966
A27: 200400 | B27: 110000354 | C27: 110000354 | D27: 2.6 | F27: Giá duyệt tháng | G27: {=SUMPRODUCT(General_Data*(Code_General_Data=$C27)*(Year=G$3)*(Month=G$4))} -> 1250 | H27: {=SUMPRODUCT(General_Data*(Code_General_Data=$C27)*(Year=H$3)*(Month=H$4))} -> 1250 | I27: {=SUMPRODUCT(General_Data*(Code_General_Data=$C27)*(Year=I$3)*(Month=I$4))} -> 1250 | J27: {=SUMPRODUCT(General_Data*(Code_General_Data=$C27)*(Year=J$3)*(Month=J$4))} -> 1250 | K27: {=SUMPRODUCT(General_Data*(Code_General_Data=$C27)*(Year=K$3)*(Month=K$4))} -> 1300 | L27: {=SUMPRODUCT(General_Data*(Code_General_Data=$C27)*(Year=L$3)*(Month=L$4))} -> 1300 | M27: {=SUMPRODUCT(General_Data*(Code_General_Data=$C27)*(Year=M$3)*(Month=M$4))} -> 1300 | N27: {=SUMPRODUCT(General_Data*(Code_General_Data=$C27)*(Year=N$3)*(Month=N$4))} -> 1300 | ... AJ27: {=SUMPRODUCT(General_Data*(Code_General_Data=$C27)*(Year=AJ$3)*(Month=AJ$4))} -> 1350
A29: 200332 | D29: 3 | E29: OUTEIRINHO
A30: 200332 | B30: 110000355 | F30: iSS01G
A31: 200332 | B31: 110000355 | D31: 3.1 | F31: Giá bán-FOB | G31: {=INDEX(Price!$L$11:$AY$210,MATCH(1,(Price!$A$11:$A$210=$A31)*(Price!$B$11:$B$210=$B31)*(Price!$D$11:$D$210="gb"),0),MATCH(1,(Price!$L$3:$AY$3=G$3)*(Price!$L$4:$AY$4=G$4),0))} -> 0 | H31: {=INDEX(Price!$L$11:$AY$210,MATCH(1,(Price!$A$11:$A$210=$A31)*(Price!$B$11:$B$210=$B31)*(Price!$D$11:$D$210="gb"),0),MATCH(1,(Price!$L$3:$AY$3=H$3)*(Price!$L$4:$AY$4=H$4),0))} -> 0 | I31: {=INDEX(Price!$L$11:$AY$210,MATCH(1,(Price!$A$11:$A$210=$A31)*(Price!$B$11:$B$210=$B31)*(Price!$D$11:$D$210="gb"),0),MATCH(1,(Price!$L$3:$AY$3=I$3)*(Price!$L$4:$AY$4=I$4),0))} -> 0 | J31: {=INDEX(Price!$L$11:$AY$210,MATCH(1,(Price!$A$11:$A$210=$A31)*(Price!$B$11:$B$210=$B31)*(Price!$D$11:$D$210="gb"),0),MATCH(1,(Price!$L$3:$AY$3=J$3)*(Price!$L$4:$AY$4=J$4),0))} -> 0 | K31: {=INDEX(Price!$L$11:$AY$210,MATCH(1,(Price!$A$11:$A$210=$A31)*(Price!$B$11:$B$210=$B31)*(Price!$D$11:$D$210="gb"),0),MATCH(1,(Price!$L$3:$AY$3=K$3)*(Price!$L$4:$AY$4=K$4),0))} -> 0 | L31: {=INDEX(Price!$L$11:$AY$210,MATCH(1,(Price!$A$11:$A$210=$A31)*(Price!$B$11:$B$210=$B31)*(Price!$D$11:$D$210="gb"),0),MATCH(1,(Price!$L$3:$AY$3=L$3)*(Price!$L$4:$AY$4=L$4),0))} -> 0 | M31: {=INDEX(Price!$L$11:$AY$210,MATCH(1,(Price!$A$11:$A$210=$A31)*(Price!$B$11:$B$210=$B31)*(Price!$D$11:$D$210="gb"),0),MATCH(1,(Price!$L$3:$AY$3=M$3)*(Price!$L$4:$AY$4=M$4),0))} -> 0 | N31: {=INDEX(Price!$L$11:$AY$210,MATCH(1,(Price!$A$11:$A$210=$A31)*(Price!$B$11:$B$210=$B31)*(Price!$D$11:$D$210="gb"),0),MATCH(1,(Price!$L$3:$AY$3=N$3)*(Price!$L$4:$AY$4=N$4),0))} -> 0 | O31: {=INDEX(Price!$L$11:$AY$210,MATCH(1,(Price!$A$11:$A$210=$A31)*(Price!$B$11:$B$210=$B31)*(Price!$D$11:$D$210="gb"),0),MATCH(1,(Price!$L$3:$AY$3=O$3)*(Price!$L$4:$AY$4=O$4),0))} -> 0 | S31: {=INDEX(Price!$L$11:$AY$210,MATCH(1,(Price!$A$11:$A$210=$A31)*(Price!$B$11:$B$210=$B31)*(Price!$D$11:$D$210="gb"),0),MATCH(1,(Price!$L$3:$AY$3=S$3)*(Price!$L$4:$AY$4=S$4),0))} -> 1250 | T31: {=INDEX(Price!$L$11:$AY$210,MATCH(1,(Price!$A$11:$A$210=$A31)*(Price!$B$11:$B$210=$B31)*(Price!$D$11:$D$210="gb"),0),MATCH(1,(Price!$L$3:$AY$3=T$3)*(Price!$L$4:$AY$4=T$4),0))} -> 1250 | U31: {=INDEX(Price!$L$11:$AY$210,MATCH(1,(Price!$A$11:$A$210=$A31)*(Price!$B$11:$B$210=$B31)*(Price!$D$11:$D$210="gb"),0),MATCH(1,(Price!$L$3:$AY$3=U$3)*(Price!$L$4:$AY$4=U$4),0))} -> 1250 | V31: {=INDEX(Price!$L$11:$AY$210,MATCH(1,(Price!$A$11:$A$210=$A31)*(Price!$B$11:$B$210=$B31)*(Price!$D$11:$D$210="gb"),0),MATCH(1,(Price!$L$3:$AY$3=V$3)*(Price!$L$4:$AY$4=V$4),0))} -> 1250 | W31: {=INDEX(Price!$L$11:$AY$210,MATCH(1,(Price!$A$11:$A$210=$A31)*(Price!$B$11:$B$210=$B31)*(Price!$D$11:$D$210="gb"),0),MATCH(1,(Price!$L$3:$AY$3=W$3)*(Price!$L$4:$AY$4=W$4),0))} -> 1250 | X31: {=INDEX(Price!$L$11:$AY$210,MATCH(1,(Price!$A$11:$A$210=$A31)*(Price!$B$11:$B$210=$B31)*(Price!$D$11:$D$210="gb"),0),MATCH(1,(Price!$L$3:$AY$3=X$3)*(Price!$L$4:$AY$4=X$4),0))} -> 1250 | Y31: {=INDEX(Price!$L$11:$AY$210,MATCH(1,(Price!$A$11:$A$210=$A31)*(Price!$B$11:$B$210=$B31)*(Price!$D$11:$D$210="gb"),0),MATCH(1,(Price!$L$3:$AY$3=Y$3)*(Price!$L$4:$AY$4=Y$4),0))} -> 1250 | Z31: {=INDEX(Price!$L$11:$AY$210,MATCH(1,(Price!$A$11:$A$210=$A31)*(Price!$B$11:$B$210=$B31)*(Price!$D$11:$D$210="gb"),0),MATCH(1,(Price!$L$3:$AY$3=Z$3)*(Price!$L$4:$AY$4=Z$4),0))} -> 1250 | ... AD31: {=INDEX(Price!$L$11:$AY$210,MATCH(1,(Price!$A$11:$A$210=$A31)*(Price!$B$11:$B$210=$B31)*(Price!$D$11:$D$210="gb"),0),MATCH(1,(Price!$L$3:$AY$3=AD$3)*(Price!$L$4:$AY$4=AD$4),0))} -> 1250
A32: 200332 | B32: 110000355 | C32: GB | D32: 3.2 | F32: Giá bán quy đổi EXW | G32: {=INDEX(Price!$L$11:$AY$210,MATCH(1,(Price!$A$11:$A$210=$A32)*(Price!$B$11:$B$210=$B32)*(Price!$D$11:$D$210="exw"),0),MATCH(1,(Price!$L$3:$AY$3=G$3)*(Price!$L$4:$AY$4=G$4),0))} -> 0 | H32: {=INDEX(Price!$L$11:$AY$210,MATCH(1,(Price!$A$11:$A$210=$A32)*(Price!$B$11:$B$210=$B32)*(Price!$D$11:$D$210="exw"),0),MATCH(1,(Price!$L$3:$AY$3=H$3)*(Price!$L$4:$AY$4=H$4),0))} -> 0 | I32: {=INDEX(Price!$L$11:$AY$210,MATCH(1,(Price!$A$11:$A$210=$A32)*(Price!$B$11:$B$210=$B32)*(Price!$D$11:$D$210="exw"),0),MATCH(1,(Price!$L$3:$AY$3=I$3)*(Price!$L$4:$AY$4=I$4),0))} -> 0 | J32: {=INDEX(Price!$L$11:$AY$210,MATCH(1,(Price!$A$11:$A$210=$A32)*(Price!$B$11:$B$210=$B32)*(Price!$D$11:$D$210="exw"),0),MATCH(1,(Price!$L$3:$AY$3=J$3)*(Price!$L$4:$AY$4=J$4),0))} -> 0 | K32: {=INDEX(Price!$L$11:$AY$210,MATCH(1,(Price!$A$11:$A$210=$A32)*(Price!$B$11:$B$210=$B32)*(Price!$D$11:$D$210="exw"),0),MATCH(1,(Price!$L$3:$AY$3=K$3)*(Price!$L$4:$AY$4=K$4),0))} -> 0 | L32: {=INDEX(Price!$L$11:$AY$210,MATCH(1,(Price!$A$11:$A$210=$A32)*(Price!$B$11:$B$210=$B32)*(Price!$D$11:$D$210="exw"),0),MATCH(1,(Price!$L$3:$AY$3=L$3)*(Price!$L$4:$AY$4=L$4),0))} -> 0 | M32: {=INDEX(Price!$L$11:$AY$210,MATCH(1,(Price!$A$11:$A$210=$A32)*(Price!$B$11:$B$210=$B32)*(Price!$D$11:$D$210="exw"),0),MATCH(1,(Price!$L$3:$AY$3=M$3)*(Price!$L$4:$AY$4=M$4),0))} -> 0 | N32: {=INDEX(Price!$L$11:$AY$210,MATCH(1,(Price!$A$11:$A$210=$A32)*(Price!$B$11:$B$210=$B32)*(Price!$D$11:$D$210="exw"),0),MATCH(1,(Price!$L$3:$AY$3=N$3)*(Price!$L$4:$AY$4=N$4),0))} -> 0 | O32: {=INDEX(Price!$L$11:$AY$210,MATCH(1,(Price!$A$11:$A$210=$A32)*(Price!$B$11:$B$210=$B32)*(Price!$D$11:$D$210="exw"),0),MATCH(1,(Price!$L$3:$AY$3=O$3)*(Price!$L$4:$AY$4=O$4),0))} -> 0 | S32: {=INDEX(Price!$L$11:$AY$210,MATCH(1,(Price!$A$11:$A$210=$A32)*(Price!$B$11:$B$210=$B32)*(Price!$D$11:$D$210="exw"),0),MATCH(1,(Price!$L$3:$AY$3=S$3)*(Price!$L$4:$AY$4=S$4),0))} -> 1230 | T32: {=INDEX(Price!$L$11:$AY$210,MATCH(1,(Price!$A$11:$A$210=$A32)*(Price!$B$11:$B$210=$B32)*(Price!$D$11:$D$210="exw"),0),MATCH(1,(Price!$L$3:$AY$3=T$3)*(Price!$L$4:$AY$4=T$4),0))} -> 1230 | U32: {=INDEX(Price!$L$11:$AY$210,MATCH(1,(Price!$A$11:$A$210=$A32)*(Price!$B$11:$B$210=$B32)*(Price!$D$11:$D$210="exw"),0),MATCH(1,(Price!$L$3:$AY$3=U$3)*(Price!$L$4:$AY$4=U$4),0))} -> 1230 | V32: {=INDEX(Price!$L$11:$AY$210,MATCH(1,(Price!$A$11:$A$210=$A32)*(Price!$B$11:$B$210=$B32)*(Price!$D$11:$D$210="exw"),0),MATCH(1,(Price!$L$3:$AY$3=V$3)*(Price!$L$4:$AY$4=V$4),0))} -> 1228 | W32: {=INDEX(Price!$L$11:$AY$210,MATCH(1,(Price!$A$11:$A$210=$A32)*(Price!$B$11:$B$210=$B32)*(Price!$D$11:$D$210="exw"),0),MATCH(1,(Price!$L$3:$AY$3=W$3)*(Price!$L$4:$AY$4=W$4),0))} -> 1228 | X32: {=INDEX(Price!$L$11:$AY$210,MATCH(1,(Price!$A$11:$A$210=$A32)*(Price!$B$11:$B$210=$B32)*(Price!$D$11:$D$210="exw"),0),MATCH(1,(Price!$L$3:$AY$3=X$3)*(Price!$L$4:$AY$4=X$4),0))} -> 1228 | Y32: {=INDEX(Price!$L$11:$AY$210,MATCH(1,(Price!$A$11:$A$210=$A32)*(Price!$B$11:$B$210=$B32)*(Price!$D$11:$D$210="exw"),0),MATCH(1,(Price!$L$3:$AY$3=Y$3)*(Price!$L$4:$AY$4=Y$4),0))} -> 1228 | Z32: {=INDEX(Price!$L$11:$AY$210,MATCH(1,(Price!$A$11:$A$210=$A32)*(Price!$B$11:$B$210=$B32)*(Price!$D$11:$D$210="exw"),0),MATCH(1,(Price!$L$3:$AY$3=Z$3)*(Price!$L$4:$AY$4=Z$4),0))} -> 1230 | ... AD32: {=INDEX(Price!$L$11:$AY$210,MATCH(1,(Price!$A$11:$A$210=$A32)*(Price!$B$11:$B$210=$B32)*(Price!$D$11:$D$210="exw"),0),MATCH(1,(Price!$L$3:$AY$3=AD$3)*(Price!$L$4:$AY$4=AD$4),0))} -> 1230
A33: 200332 | B33: 110000355 | C33: PETVirgin | D33: 3.3 | F33: Giá chính phẩm | S33: {=SUMPRODUCT(General_Data*(Code_General_Data=$C33)*(Year=S$3)*(Month=S$4))} -> 828 | T33: {=SUMPRODUCT(General_Data*(Code_General_Data=$C33)*(Year=T$3)*(Month=T$4))} -> 840 | U33: {=SUMPRODUCT(General_Data*(Code_General_Data=$C33)*(Year=U$3)*(Month=U$4))} -> 823 | V33: {=SUMPRODUCT(General_Data*(Code_General_Data=$C33)*(Year=V$3)*(Month=V$4))} -> 765 | W33: {=SUMPRODUCT(General_Data*(Code_General_Data=$C33)*(Year=W$3)*(Month=W$4))} -> 782 | X33: {=SUMPRODUCT(General_Data*(Code_General_Data=$C33)*(Year=X$3)*(Month=X$4))} -> 807.5 | Y33: {=SUMPRODUCT(General_Data*(Code_General_Data=$C33)*(Year=Y$3)*(Month=Y$4))} -> 802 | Z33: {=SUMPRODUCT(General_Data*(Code_General_Data=$C33)*(Year=Z$3)*(Month=Z$4))} -> 795 | ... AD33: {=SUMPRODUCT(General_Data*(Code_General_Data=$C33)*(Year=AD$3)*(Month=AD$4))} -> 772.5
A34: 200332 | B34: 110000355 | D34: 3.4 | F34: Chênh lệch giữa R sv Virgin | S34: =IF(S31*S32*S33<>0,S32-S33,0) -> 402 | T34: =IF(T31*T32*T33<>0,T32-T33,0) -> 390 | U34: =IF(U31*U32*U33<>0,U32-U33,0) -> 407 | V34: =IF(V31*V32*V33<>0,V32-V33,0) -> 463 | W34: =IF(W31*W32*W33<>0,W32-W33,0) -> 446 | X34: =IF(X31*X32*X33<>0,X32-X33,0) -> 420.5 | Y34: =IF(Y31*Y32*Y33<>0,Y32-Y33,0) -> 426 | Z34: =IF(Z31*Z32*Z33<>0,Z32-Z33,0) -> 435 | ... AD34: =IF(AD31*AD32*AD33<>0,AD32-AD33,0) -> 457.5
A35: 200332 | B35: 110000355 | D35: 3.5 | F35: % +/- | S35: =IFERROR(S34/S33,0) -> 0.48550725 | T35: =IFERROR(T34/T33,0) -> 0.46428571 | U35: =IFERROR(U34/U33,0) -> 0.4945322 | V35: =IFERROR(V34/V33,0) -> 0.60522876 | W35: =IFERROR(W34/W33,0) -> 0.57033248 | X35: =IFERROR(X34/X33,0) -> 0.52074303 | Y35: =IFERROR(Y34/Y33,0) -> 0.53117207 | Z35: =IFERROR(Z34/Z33,0) -> 0.54716981 | ... AD35: =IFERROR(AD34/AD33,0) -> 0.59223301
A36: 200332 | B36: 110000355 | C36: 110000355 | D36: 3.6 | F36: Giá duyệt tháng | S36: {=SUMPRODUCT(General_Data*(Code_General_Data=$C36)*(Year=S$3)*(Month=S$4))} -> 1260 | T36: {=SUMPRODUCT(General_Data*(Code_General_Data=$C36)*(Year=T$3)*(Month=T$4))} -> 1260 | U36: {=SUMPRODUCT(General_Data*(Code_General_Data=$C36)*(Year=U$3)*(Month=U$4))} -> 1260 | V36: {=SUMPRODUCT(General_Data*(Code_General_Data=$C36)*(Year=V$3)*(Month=V$4))} -> 1280 | W36: {=SUMPRODUCT(General_Data*(Code_General_Data=$C36)*(Year=W$3)*(Month=W$4))} -> 1280 | X36: {=SUMPRODUCT(General_Data*(Code_General_Data=$C36)*(Year=X$3)*(Month=X$4))} -> 1280 | Y36: {=SUMPRODUCT(General_Data*(Code_General_Data=$C36)*(Year=Y$3)*(Month=Y$4))} -> 1280 | Z36: {=SUMPRODUCT(General_Data*(Code_General_Data=$C36)*(Year=Z$3)*(Month=Z$4))} -> 1250 | ... AD36: {=SUMPRODUCT(General_Data*(Code_General_Data=$C36)*(Year=AD$3)*(Month=AD$4))} -> 1230
A38: 105263 | D38: 4 | E38: UNILEVER VIET NAM
A39: 105263 | B39: 110000354 | F39: WSS01G
A40: 105263 | B40: 110000354 | D40: 4.1 | F40: Giá bán - DDP | G40: {=INDEX(Price!$L$11:$AY$210,MATCH(1,(Price!$A$11:$A$210=$A40)*(Price!$B$11:$B$210=$B40)*(Price!$D$11:$D$210="gb"),0),MATCH(1,(Price!$L$3:$AY$3=G$3)*(Price!$L$4:$AY$4=G$4),0))} -> 1320 | H40: {=INDEX(Price!$L$11:$AY$210,MATCH(1,(Price!$A$11:$A$210=$A40)*(Price!$B$11:$B$210=$B40)*(Price!$D$11:$D$210="gb"),0),MATCH(1,(Price!$L$3:$AY$3=H$3)*(Price!$L$4:$AY$4=H$4),0))} -> 1320 | I40: {=INDEX(Price!$L$11:$AY$210,MATCH(1,(Price!$A$11:$A$210=$A40)*(Price!$B$11:$B$210=$B40)*(Price!$D$11:$D$210="gb"),0),MATCH(1,(Price!$L$3:$AY$3=I$3)*(Price!$L$4:$AY$4=I$4),0))} -> 1320 | J40: {=INDEX(Price!$L$11:$AY$210,MATCH(1,(Price!$A$11:$A$210=$A40)*(Price!$B$11:$B$210=$B40)*(Price!$D$11:$D$210="gb"),0),MATCH(1,(Price!$L$3:$AY$3=J$3)*(Price!$L$4:$AY$4=J$4),0))} -> 1320 | K40: {=INDEX(Price!$L$11:$AY$210,MATCH(1,(Price!$A$11:$A$210=$A40)*(Price!$B$11:$B$210=$B40)*(Price!$D$11:$D$210="gb"),0),MATCH(1,(Price!$L$3:$AY$3=K$3)*(Price!$L$4:$AY$4=K$4),0))} -> 1320 | L40: {=INDEX(Price!$L$11:$AY$210,MATCH(1,(Price!$A$11:$A$210=$A40)*(Price!$B$11:$B$210=$B40)*(Price!$D$11:$D$210="gb"),0),MATCH(1,(Price!$L$3:$AY$3=L$3)*(Price!$L$4:$AY$4=L$4),0))} -> 1320 | M40: {=INDEX(Price!$L$11:$AY$210,MATCH(1,(Price!$A$11:$A$210=$A40)*(Price!$B$11:$B$210=$B40)*(Price!$D$11:$D$210="gb"),0),MATCH(1,(Price!$L$3:$AY$3=M$3)*(Price!$L$4:$AY$4=M$4),0))} -> 1320 | N40: {=INDEX(Price!$L$11:$AY$210,MATCH(1,(Price!$A$11:$A$210=$A40)*(Price!$B$11:$B$210=$B40)*(Price!$D$11:$D$210="gb"),0),MATCH(1,(Price!$L$3:$AY$3=N$3)*(Price!$L$4:$AY$4=N$4),0))} -> 1320 | ... AJ40: {=INDEX(Price!$L$11:$AY$210,MATCH(1,(Price!$A$11:$A$210=$A40)*(Price!$B$11:$B$210=$B40)*(Price!$D$11:$D$210="gb"),0),MATCH(1,(Price!$L$3:$AY$3=AJ$3)*(Price!$L$4:$AY$4=AJ$4),0))} -> 1191
A41: 105263 | B41: 110000354 | C41: GB | D41: 4.2 | F41: Giá bán quy đổi EXW | G41: {=INDEX(Price!$L$11:$AY$210,MATCH(1,(Price!$A$11:$A$210=$A41)*(Price!$B$11:$B$210=$B41)*(Price!$D$11:$D$210="exw"),0),MATCH(1,(Price!$L$3:$AY$3=G$3)*(Price!$L$4:$AY$4=G$4),0))} -> 1307.7959 | H41: {=INDEX(Price!$L$11:$AY$210,MATCH(1,(Price!$A$11:$A$210=$A41)*(Price!$B$11:$B$210=$B41)*(Price!$D$11:$D$210="exw"),0),MATCH(1,(Price!$L$3:$AY$3=H$3)*(Price!$L$4:$AY$4=H$4),0))} -> 1307.7959 | I41: {=INDEX(Price!$L$11:$AY$210,MATCH(1,(Price!$A$11:$A$210=$A41)*(Price!$B$11:$B$210=$B41)*(Price!$D$11:$D$210="exw"),0),MATCH(1,(Price!$L$3:$AY$3=I$3)*(Price!$L$4:$AY$4=I$4),0))} -> 1307.7959 | J41: {=INDEX(Price!$L$11:$AY$210,MATCH(1,(Price!$A$11:$A$210=$A41)*(Price!$B$11:$B$210=$B41)*(Price!$D$11:$D$210="exw"),0),MATCH(1,(Price!$L$3:$AY$3=J$3)*(Price!$L$4:$AY$4=J$4),0))} -> 1307.7959 | K41: {=INDEX(Price!$L$11:$AY$210,MATCH(1,(Price!$A$11:$A$210=$A41)*(Price!$B$11:$B$210=$B41)*(Price!$D$11:$D$210="exw"),0),MATCH(1,(Price!$L$3:$AY$3=K$3)*(Price!$L$4:$AY$4=K$4),0))} -> 1307.7959 | L41: {=INDEX(Price!$L$11:$AY$210,MATCH(1,(Price!$A$11:$A$210=$A41)*(Price!$B$11:$B$210=$B41)*(Price!$D$11:$D$210="exw"),0),MATCH(1,(Price!$L$3:$AY$3=L$3)*(Price!$L$4:$AY$4=L$4),0))} -> 1307.7959 | M41: {=INDEX(Price!$L$11:$AY$210,MATCH(1,(Price!$A$11:$A$210=$A41)*(Price!$B$11:$B$210=$B41)*(Price!$D$11:$D$210="exw"),0),MATCH(1,(Price!$L$3:$AY$3=M$3)*(Price!$L$4:$AY$4=M$4),0))} -> 1308.04 | N41: {=INDEX(Price!$L$11:$AY$210,MATCH(1,(Price!$A$11:$A$210=$A41)*(Price!$B$11:$B$210=$B41)*(Price!$D$11:$D$210="exw"),0),MATCH(1,(Price!$L$3:$AY$3=N$3)*(Price!$L$4:$AY$4=N$4),0))} -> 1308.04 | ... AJ41: {=INDEX(Price!$L$11:$AY$210,MATCH(1,(Price!$A$11:$A$210=$A41)*(Price!$B$11:$B$210=$B41)*(Price!$D$11:$D$210="exw"),0),MATCH(1,(Price!$L$3:$AY$3=AJ$3)*(Price!$L$4:$AY$4=AJ$4),0))} -> 1185
A42: 105263 | B42: 110000354 | C42: PETVirgin | D42: 4.3 | F42: Giá chính phẩm | G42: {=SUMPRODUCT(General_Data*(Code_General_Data=$C42)*(Year=G$3)*(Month=G$4))} -> 930 | H42: {=SUMPRODUCT(General_Data*(Code_General_Data=$C42)*(Year=H$3)*(Month=H$4))} -> 943.33333 | I42: {=SUMPRODUCT(General_Data*(Code_General_Data=$C42)*(Year=I$3)*(Month=I$4))} -> 940 | J42: {=SUMPRODUCT(General_Data*(Code_General_Data=$C42)*(Year=J$3)*(Month=J$4))} -> 940 | K42: {=SUMPRODUCT(General_Data*(Code_General_Data=$C42)*(Year=K$3)*(Month=K$4))} -> 942 | L42: {=SUMPRODUCT(General_Data*(Code_General_Data=$C42)*(Year=L$3)*(Month=L$4))} -> 950 | M42: {=SUMPRODUCT(General_Data*(Code_General_Data=$C42)*(Year=M$3)*(Month=M$4))} -> 947.5 | N42: {=SUMPRODUCT(General_Data*(Code_General_Data=$C42)*(Year=N$3)*(Month=N$4))} -> 930 | ... AJ42: {=SUMPRODUCT(General_Data*(Code_General_Data=$C42)*(Year=AJ$3)*(Month=AJ$4))} -> 1190
A43: 105263 | B43: 110000354 | D43: 4.4 | F43: Chênh lệch giữa R sv Virgin | G43: =IF(G40*G41*G42<>0,G41-G42,0) -> 377.79592 | H43: =IF(H40*H41*H42<>0,H41-H42,0) -> 364.46259 | I43: =IF(I40*I41*I42<>0,I41-I42,0) -> 367.79592 | J43: =IF(J40*J41*J42<>0,J41-J42,0) -> 367.79592 | K43: =IF(K40*K41*K42<>0,K41-K42,0) -> 365.79592 | L43: =IF(L40*L41*L42<>0,L41-L42,0) -> 357.79592 | M43: =IF(M40*M41*M42<>0,M41-M42,0) -> 360.54 | N43: =IF(N40*N41*N42<>0,N41-N42,0) -> 378.04 | ... AJ43: =IF(AJ40*AJ41*AJ42<>0,AJ41-AJ42,0) -> -5
A44: 105263 | B44: 110000354 | D44: 4.5 | F44: % +/- | G44: =IFERROR(G43/G42,0) -> 0.40623217 | H44: =IFERROR(H43/H42,0) -> 0.3863561 | I44: =IFERROR(I43/I42,0) -> 0.39127225 | J44: =IFERROR(J43/J42,0) -> 0.39127225 | K44: =IFERROR(K43/K42,0) -> 0.38831838 | L44: =IFERROR(L43/L42,0) -> 0.37662728 | M44: =IFERROR(M43/M42,0) -> 0.38051715 | N44: =IFERROR(N43/N42,0) -> 0.40649462 | ... AJ44: =IFERROR(AJ43/AJ42,0) -> -0.0042016807
A45: 105263 | B45: 110000354 | C45: 110000354 | D45: 4.6 | F45: Giá duyệt tháng | G45: {=SUMPRODUCT(General_Data*(Code_General_Data=$C45)*(Year=G$3)*(Month=G$4))} -> 1250 | H45: {=SUMPRODUCT(General_Data*(Code_General_Data=$C45)*(Year=H$3)*(Month=H$4))} -> 1250 | I45: {=SUMPRODUCT(General_Data*(Code_General_Data=$C45)*(Year=I$3)*(Month=I$4))} -> 1250 | J45: {=SUMPRODUCT(General_Data*(Code_General_Data=$C45)*(Year=J$3)*(Month=J$4))} -> 1250 | K45: {=SUMPRODUCT(General_Data*(Code_General_Data=$C45)*(Year=K$3)*(Month=K$4))} -> 1300 | L45: {=SUMPRODUCT(General_Data*(Code_General_Data=$C45)*(Year=L$3)*(Month=L$4))} -> 1300 | M45: {=SUMPRODUCT(General_Data*(Code_General_Data=$C45)*(Year=M$3)*(Month=M$4))} -> 1300 | N45: {=SUMPRODUCT(General_Data*(Code_General_Data=$C45)*(Year=N$3)*(Month=N$4))} -> 1300 | ... AJ45: {=SUMPRODUCT(General_Data*(Code_General_Data=$C45)*(Year=AJ$3)*(Month=AJ$4))} -> 1350
A46: 105263
...

Sheet Price
L1: =DATE(L3,L4,1) -> 45200 | M1: =DATE(M3,M4,1) -> 45231 | N1: =DATE(N3,N4,1) -> 45261 | O1: =DATE(O3,O4,1) -> 45292 | P1: =DATE(P3,P4,1) -> 45323 | Q1: =DATE(Q3,Q4,1) -> 45352 | R1: =DATE(R3,R4,1) -> 45383 | S1: =DATE(S3,S4,1) -> 45413 | ... AX1: =DATE(AX3,AX4,1) -> 46357
L2: =EOMONTH(L1,0) -> 45230 | M2: =EOMONTH(M1,0) -> 45260 | N2: =EOMONTH(N1,0) -> 45291 | O2: =EOMONTH(O1,0) -> 45322 | P2: =EOMONTH(P1,0) -> 45351 | Q2: =EOMONTH(Q1,0) -> 45382 | R2: =EOMONTH(R1,0) -> 45412 | S2: =EOMONTH(S1,0) -> 45443 | ... AX2: =EOMONTH(AX1,0) -> 46387
L3: 2023 | M3: 2023 | N3: 2023 | O3: 2024 | P3: 2024 | Q3: 2024 | R3: 2024 | S3: 2024 | T3: 2024 | U3: 2024 | V3: 2024 | W3: 2024 | X3: 2024 | Y3: 2024 | Z3: 2024 | AA3: 2025 | AB3: 2025 | AC3: 2025 | AD3: 2025 | AE3: 2025 | AF3: 2025 | AG3: 2025 | AH3: 2025 | AI3: 2025 | AJ3: 2025 | AK3: 2025 | AL3: 2025 | AM3: 2026 | AN3: 2026 | AO3: 2026 | AP3: 2026 | AQ3: 2026 | AR3: 2026 | AS3: 2026 | AT3: 2026 | AU3: 2026 | AV3: 2026 | AW3: 2026 | AX3: 2026
L4: 10 | M4: 11 | N4: 12 | O4: 1 | P4: 2 | Q4: 3 | R4: 4 | S4: 5 | T4: 6 | U4: 7 | V4: 8 | W4: 9 | X4: 10 | Y4: 11 | Z4: 12 | AA4: 1 | AB4: 2 | AC4: 3 | AD4: 4 | AE4: 5 | AF4: 6 | AG4: 7 | AH4: 8 | AI4: 9 | AJ4: 10 | AK4: 11 | AL4: 12 | AM4: 1 | AN4: 2 | AO4: 3 | AP4: 4 | AQ4: 5 | AR4: 6 | AS4: 7 | AT4: 8 | AU4: 9 | AV4: 10 | AW4: 11 | AX4: 12
O6: II. CHI TIẾT GIÁ CÔNG THỨC THEO KHÁCH HÀNG | AA6: II. CHI TIẾT GIÁ CÔNG THỨC THEO KHÁCH HÀNG | AM6: II. CHI TIẾT GIÁ CÔNG THỨC THEO KHÁCH HÀNG
F8: STT | G8: KHÁCH HÀNG/NỘI DUNG | L8: 2023 | O8: 2024 | AA8: 2025 | AM8: 2026
A9: Khách | B9: SKU | C9: Code | D9: Link | L9: 10 | M9: 11 | N9: 12 | O9: 1 | P9: 2 | Q9: 3 | R9: 4 | S9: 5 | T9: 6 | U9: 7 | V9: 8 | W9: 9 | X9: 10 | Y9: 11 | Z9: 12 | AA9: 1 | AB9: 2 | AC9: 3 | AD9: 4 | AE9: 5 | AF9: 6 | AG9: 7 | AH9: 8 | AI9: 9 | AJ9: 10 | AK9: 11 | AL9: 12 | AM9: 1 | AN9: 2 | AO9: 3 | AP9: 4 | AQ9: 5 | AR9: 6 | AS9: 7 | AT9: 8 | AU9: 9 | AV9: 10 | AW9: 11 | AX9: 12
A11: 200319 | F11: 1 | G11: NIAGARA
A12: 200319 | B12: 110000354 | D12: GB | F12: 1.1 | H12: GIÁ BÁN WSS01G (FOB) | O12: =MIN(MAX(SUM(O13:O14),O24),O23) -> 1200 | P12: =MIN(MAX(SUM(P13:P14),P24),P23) -> 1200 | Q12: =MIN(MAX(SUM(Q13:Q14),Q24),Q23) -> 1200 | R12: =MIN(MAX(SUM(R13:R14),R24),R23) -> 1200 | S12: =MIN(MAX(SUM(S13:S14),S24),S23) -> 1200 | T12: =MIN(MAX(SUM(T13:T14),T24),T23) -> 1200.9 | U12: =MIN(MAX(SUM(U13:U14),U24),U23) -> 1214.4 | V12: =MIN(MAX(SUM(V13:V14),V24),V23) -> 1226.1 | ... AC12: =MIN(MAX(SUM(AC13:AC14),AC24),AC23) -> 1238.875 | AD12: =MIN(MAX(SUM(AD13:AD14),AD24),AD23)-0.619999999998981 -> 1219.88 | AE12: =MIN(MAX(SUM(AE13:AE14),AE24),AE23) -> 1221 | AF12: =MIN(MAX(SUM(AF13:AF14),AF24),AF23) -> 1224 | AG12: =MIN(MAX(SUM(AG13:AG14),AG24),AG23) -> 1224 | AH12: =MIN(MAX(SUM(AH13:AH14),AH24),AH23) -> 1213.2 | AI12: =MIN(MAX(SUM(AI13:AI14),AI24),AI23) -> 1200 | AJ12: =MIN(MAX(SUM(AJ13:AJ14),AJ24),AJ23) -> 1200 | AK12: =MIN(MAX(SUM(AK13:AK14),AK24),AK23) -> 1200 | AL12: 1100 | AM12: =MIN(MAX(AM24,SUM(AM13:AM16)),AM23) -> 1080 | AN12: =MIN(MAX(AN24,SUM(AN13:AN16)),AN23) -> 1050 | AO12: =MIN(MAX(AO24,SUM(AO13:AO16)),AO23) -> 1061.25 | AP12: =MIN(MAX(AP24,SUM(AP13:AP16)),AP23) -> 1221 | AQ12: =MIN(MAX(AQ24,SUM(AQ13:AQ16)),AQ23) -> 1221 | AR12: =MIN(MAX(AR24,SUM(AR13:AR16)),AR23) -> 1221
A13: 200319 | B13: 110000354 | F13: 1.1.A | H13: [+] | I13: ICIS Bales - SEA trung bình 3 tháng trước | O13: =AVERAGE(L20:N20) -> 1296.0417 | P13: =AVERAGE(M20:O20) -> 1305 | Q13: =AVERAGE(N20:P20) -> 1313.3333 | R13: =AVERAGE(O20:Q20) -> 1320 | S13: =AVERAGE(P20:R20) -> 1326 | T13: =AVERAGE(Q20:S20) -> 1334.3333 | U13: =AVERAGE(R20:T20) -> 1349.3333 | V13: =AVERAGE(S20:U20) -> 1362.3333 | ... AK13: =AVERAGE(AH20:AJ20) -> 1271
A14: 200319 | B14: 110000354 | F14: 1.1.B | H14: [+] | I14: Chiết khấu (10%) | O14: =-O13*O21 -> -129.60417 | P14: =-P13*P21 -> -130.5 | Q14: =-Q13*Q21 -> -131.33333 | R14: =-R13*R21 -> -132 | S14: =-S13*S21 -> -132.6 | T14: =-T13*T21 -> -133.43333 | U14: =-U13*U21 -> -134.93333 | V14: =-V13*V21 -> -136.23333 | ... AK14: =-AK13*AK21 -> -127.1
F15: 1.1.C | H15: [+] | I15: Giá Báse (Áp dụng 2026) | AM15: 1080 | AN15: =AM12 -> 1080 | AO15: =AN12 -> 1050 | AP15: =AO12*1.1 -> 1167.375 | AQ15: =AP12 -> 1221 | AR15: =AQ12 -> 1221
F16: 1.1.D | H16: [+] | I16: Chênh lệch ICIS 2 tháng trước (Áp dụng 2026) | AN16: =AM20-AL20 -> -43.75 | AO16: =AN20-AM20 -> 11.25 | AP16: =AO20-AN20 -> 74.75 | AQ16: =AP20-AO20 -> 81.5 | AR16: =AQ20-AP20 -> 41.25
A17: 200319 | B17: 110000354 | D17: EXW | F17: 1.1.1 | I17: Giá bán quy đổi EXW | O17: =O12-O18-O19 -> 1162 | P17: =P12-P18-P19 -> 1162 | Q17: =Q12-Q18-Q19 -> 1162 | R17: =R12-R18-R19 -> 1162 | S17: =S12-S18-S19 -> 1162 | T17: =T12-T18-T19 -> 1162.8865 | U17: =U12-U18-U19 -> 1176.184 | V17: =V12-V18-V19 -> 1187.7085 | ... AR17: =AR12-AR18-AR19 -> 1182.685
A18: 200319 | B18: 110000354 | I18: Chi phí vận chuyển | O18: 20 | P18: 20 | Q18: 20 | R18: 20 | S18: 20 | T18: 20 | U18: 20 | V18: 20 | W18: 20 | X18: 20 | Y18: 20 | Z18: 20 | AA18: 20 | AB18: 20 | AC18: 20 | AD18: 22 | AE18: 22 | AF18: 22 | AG18: 22 | AH18: 20 | AI18: 20 | AJ18: 20 | AK18: 20 | AL18: 20 | AM18: 20 | AN18: 20 | AO18: 20 | AP18: 20 | AQ18: 20 | AR18: 20
A19: 200319 | B19: 110000354 | J19: Chi phí hoa hồng | O19: =O12*O22 -> 18 | P19: =P12*P22 -> 18 | Q19: =Q12*Q22 -> 18 | R19: =R12*R22 -> 18 | S19: =S12*S22 -> 18 | T19: =T12*T22 -> 18.0135 | U19: =U12*U22 -> 18.216 | V19: =V12*V22 -> 18.3915 | ... AR19: =AR12*AR22 -> 18.315
A20: 200319 | B20: 110000354 | C20: 04 | J20: ICIS Bales - SEA | L20: {=SUMPRODUCT(General_Data*(Year=L$3)*(Month=L$4)*(Code_General_Data=$C20))} -> 1288.125 | M20: {=SUMPRODUCT(General_Data*(Year=M$3)*(Month=M$4)*(Code_General_Data=$C20))} -> 1300 | N20: {=SUMPRODUCT(General_Data*(Year=N$3)*(Month=N$4)*(Code_General_Data=$C20))} -> 1300 | O20: {=SUMPRODUCT(General_Data*(Year=O$3)*(Month=O$4)*(Code_General_Data=$C20))} -> 1315 | P20: {=SUMPRODUCT(General_Data*(Year=P$3)*(Month=P$4)*(Code_General_Data=$C20))} -> 1325 | Q20: {=SUMPRODUCT(General_Data*(Year=Q$3)*(Month=Q$4)*(Code_General_Data=$C20))} -> 1320 | R20: {=SUMPRODUCT(General_Data*(Year=R$3)*(Month=R$4)*(Code_General_Data=$C20))} -> 1333 | S20: {=SUMPRODUCT(General_Data*(Year=S$3)*(Month=S$4)*(Code_General_Data=$C20))} -> 1350 | ... AR20: {=SUMPRODUCT(General_Data*(Year=AR$3)*(Month=AR$4)*(Code_General_Data=$C20))} -> 0
A21: 200319 | B21: 110000354 | J21: %Chiết khấu | O21: 0.1 | P21: 0.1 | Q21: 0.1 | R21: 0.1 | S21: 0.1 | T21: 0.1 | U21: 0.1 | V21: 0.1 | W21: 0.1 | X21: 0.1 | Y21: 0.1 | Z21: 0.1 | AA21: 0.1 | AB21: 0.1 | AC21: 0.1 | AD21: 0.1 | AE21: 0.1 | AF21: 0.1 | AG21: 0.1 | AH21: 0.1 | AI21: 0.1 | AJ21: 0.1 | AK21: 0.1 | AL21: 0.1 | AM21: N/A | AN21: N/A | AO21: N/A | AP21: N/A | AQ21: N/A | AR21: N/A
A22: 200319 | B22: 110000354 | J22: %Hoa hồng | O22: 0.015 | P22: 0.015 | Q22: 0.015 | R22: 0.015 | S22: 0.015 | T22: 0.015 | U22: 0.015 | V22: 0.015 | W22: 0.015 | X22: 0.015 | Y22: 0.015 | Z22: 0.015 | AA22: 0.015 | AB22: 0.015 | AC22: 0.015 | AD22: 0.015 | AE22: 0.015 | AF22: 0.015 | AG22: 0.015 | AH22: 0.015 | AI22: 0.015 | AJ22: 0.015 | AK22: 0.015 | AL22: 0.015 | AM22: 0.015 | AN22: 0.015 | AO22: 0.015 | AP22: 0.015 | AQ22: 0.015 | AR22: 0.015
A23: 200319 | B23: 110000354 | F23: 1.1.2 | J23: Giá trần | O23: {=INDEX(Note!$J$3:$J$102,MATCH(1,(Note!$A$3:$A$102=$A23)*(Note!$C$3:$C$102=$B23)*(Note!$E$3:$E$102<=O$1)*(Note!$F$3:$F$102>=O$2),0))} -> 1600 | P23: {=INDEX(Note!$J$3:$J$102,MATCH(1,(Note!$A$3:$A$102=$A23)*(Note!$C$3:$C$102=$B23)*(Note!$E$3:$E$102<=P$1)*(Note!$F$3:$F$102>=P$2),0))} -> 1600 | Q23: {=INDEX(Note!$J$3:$J$102,MATCH(1,(Note!$A$3:$A$102=$A23)*(Note!$C$3:$C$102=$B23)*(Note!$E$3:$E$102<=Q$1)*(Note!$F$3:$F$102>=Q$2),0))} -> 1600 | R23: {=INDEX(Note!$J$3:$J$102,MATCH(1,(Note!$A$3:$A$102=$A23)*(Note!$C$3:$C$102=$B23)*(Note!$E$3:$E$102<=R$1)*(Note!$F$3:$F$102>=R$2),0))} -> 1600 | S23: {=INDEX(Note!$J$3:$J$102,MATCH(1,(Note!$A$3:$A$102=$A23)*(Note!$C$3:$C$102=$B23)*(Note!$E$3:$E$102<=S$1)*(Note!$F$3:$F$102>=S$2),0))} -> 1600 | T23: {=INDEX(Note!$J$3:$J$102,MATCH(1,(Note!$A$3:$A$102=$A23)*(Note!$C$3:$C$102=$B23)*(Note!$E$3:$E$102<=T$1)*(Note!$F$3:$F$102>=T$2),0))} -> 1600 | U23: {=INDEX(Note!$J$3:$J$102,MATCH(1,(Note!$A$3:$A$102=$A23)*(Note!$C$3:$C$102=$B23)*(Note!$E$3:$E$102<=U$1)*(Note!$F$3:$F$102>=U$2),0))} -> 1600 | V23: {=INDEX(Note!$J$3:$J$102,MATCH(1,(Note!$A$3:$A$102=$A23)*(Note!$C$3:$C$102=$B23)*(Note!$E$3:$E$102<=V$1)*(Note!$F$3:$F$102>=V$2),0))} -> 1600 | ... AR23: {=INDEX(Note!$J$3:$J$102,MATCH(1,(Note!$A$3:$A$102=$A23)*(Note!$C$3:$C$102=$B23)*(Note!$E$3:$E$102<=AR$1)*(Note!$F$3:$F$102>=AR$2),0))} -> 1221
A24: 200319 | B24: 110000354 | F24: 1.1.3 | J24: Giá sàn | O24: {=INDEX(Note!$K$3:$K$102,MATCH(1,(Note!$A$3:$A$102=$A24)*(Note!$C$3:$C$102=$B24)*(Note!$E$3:$E$102<=O$1)*(Note!$F$3:$F$102>=O$2),0))} -> 1200 | P24: {=INDEX(Note!$K$3:$K$102,MATCH(1,(Note!$A$3:$A$102=$A24)*(Note!$C$3:$C$102=$B24)*(Note!$E$3:$E$102<=P$1)*(Note!$F$3:$F$102>=P$2),0))} -> 1200 | Q24: {=INDEX(Note!$K$3:$K$102,MATCH(1,(Note!$A$3:$A$102=$A24)*(Note!$C$3:$C$102=$B24)*(Note!$E$3:$E$102<=Q$1)*(Note!$F$3:$F$102>=Q$2),0))} -> 1200 | R24: {=INDEX(Note!$K$3:$K$102,MATCH(1,(Note!$A$3:$A$102=$A24)*(Note!$C$3:$C$102=$B24)*(Note!$E$3:$E$102<=R$1)*(Note!$F$3:$F$102>=R$2),0))} -> 1200 | S24: {=INDEX(Note!$K$3:$K$102,MATCH(1,(Note!$A$3:$A$102=$A24)*(Note!$C$3:$C$102=$B24)*(Note!$E$3:$E$102<=S$1)*(Note!$F$3:$F$102>=S$2),0))} -> 1200 | T24: {=INDEX(Note!$K$3:$K$102,MATCH(1,(Note!$A$3:$A$102=$A24)*(Note!$C$3:$C$102=$B24)*(Note!$E$3:$E$102<=T$1)*(Note!$F$3:$F$102>=T$2),0))} -> 1200 | U24: {=INDEX(Note!$K$3:$K$102,MATCH(1,(Note!$A$3:$A$102=$A24)*(Note!$C$3:$C$102=$B24)*(Note!$E$3:$E$102<=U$1)*(Note!$F$3:$F$102>=U$2),0))} -> 1200 | V24: {=INDEX(Note!$K$3:$K$102,MATCH(1,(Note!$A$3:$A$102=$A24)*(Note!$C$3:$C$102=$B24)*(Note!$E$3:$E$102<=V$1)*(Note!$F$3:$F$102>=V$2),0))} -> 1200 | ... AR24: {=INDEX(Note!$K$3:$K$102,MATCH(1,(Note!$A$3:$A$102=$A24)*(Note!$C$3:$C$102=$B24)*(Note!$E$3:$E$102<=AR$1)*(Note!$F$3:$F$102>=AR$2),0))} -> 1155
A25: 200319 | B25: 110000354 | F25: 1.1.4 | J25: Giá duyệt tháng | O25: {=SUMPRODUCT(General_Data*(Year=O$3)*(Month=O$4)*(Code_General_Data=$B25))} -> 1250 | P25: {=SUMPRODUCT(General_Data*(Year=P$3)*(Month=P$4)*(Code_General_Data=$B25))} -> 1250 | Q25: {=SUMPRODUCT(General_Data*(Year=Q$3)*(Month=Q$4)*(Code_General_Data=$B25))} -> 1250 | R25: {=SUMPRODUCT(General_Data*(Year=R$3)*(Month=R$4)*(Code_General_Data=$B25))} -> 1250 | S25: {=SUMPRODUCT(General_Data*(Year=S$3)*(Month=S$4)*(Code_General_Data=$B25))} -> 1300 | T25: {=SUMPRODUCT(General_Data*(Year=T$3)*(Month=T$4)*(Code_General_Data=$B25))} -> 1300 | U25: {=SUMPRODUCT(General_Data*(Year=U$3)*(Month=U$4)*(Code_General_Data=$B25))} -> 1300 | V25: {=SUMPRODUCT(General_Data*(Year=V$3)*(Month=V$4)*(Code_General_Data=$B25))} -> 1300 | ... AR25: {=SUMPRODUCT(General_Data*(Year=AR$3)*(Month=AR$4)*(Code_General_Data=$B25))} -> 1350
J26: Giá trần - quy đổi EXW | O26: =O23-O18-O19 -> 1562 | P26: =P23-P18-P19 -> 1562 | Q26: =Q23-Q18-Q19 -> 1562 | R26: =R23-R18-R19 -> 1562 | S26: =S23-S18-S19 -> 1562 | T26: =T23-T18-T19 -> 1561.9865 | U26: =U23-U18-U19 -> 1561.784 | V26: =V23-V18-V19 -> 1561.6085 | ... AK26: =AK23-AK18-AK19 -> 1562 | AM26: =AM23-AM18-AM19 -> 1073.8 | AN26: =AN23-AN18-AN19 -> 1074.25 | AO26: =AO23-AO18-AO19 -> 1074.0812 | AP26: =AP23-AP18-AP19 -> 1182.685 | AQ26: =AQ23-AQ18-AQ19 -> 1182.685 | AR26: =AR23-AR18-AR19 -> 1182.685
J27: Giá sàn - quy đổi EXW | O27: =O24-O18-O19 -> 1162 | P27: =P24-P18-P19 -> 1162 | Q27: =Q24-Q18-Q19 -> 1162 | R27: =R24-R18-R19 -> 1162 | S27: =S24-S18-S19 -> 1162 | T27: =T24-T18-T19 -> 1161.9865 | U27: =U24-U18-U19 -> 1161.784 | V27: =V24-V18-V19 -> 1161.6085 | ... AK27: =AK24-AK18-AK19 -> 1162 | AM27: =AM24-AM18-AM19 -> 1013.8 | AN27: =AN24-AN18-AN19 -> 1014.25 | AO27: =AO24-AO18-AO19 -> 1014.0812 | AP27: =AP24-AP18-AP19 -> 1116.685 | AQ27: =AQ24-AQ18-AQ19 -> 1116.685 | AR27: =AR24-AR18-AR19 -> 1116.685
A29: 200400 | F29: 2 | G29: SHEPLEY (NIAGARA NON-US)
A30: 200400 | B30: 110000354 | D30: GB | F30: 2.1 | H30: GIÁ BÁN WSS01G (FOB) | O30: =MIN(MAX(SUM(O31:O32),O42),O41) -> 1200 | P30: =MIN(MAX(SUM(P31:P32),P42),P41) -> 1200 | Q30: =MIN(MAX(SUM(Q31:Q32),Q42),Q41) -> 1200 | R30: =MIN(MAX(SUM(R31:R32),R42),R41) -> 1200 | S30: =MIN(MAX(SUM(S31:S32),S42),S41) -> 1200 | T30: =MIN(MAX(SUM(T31:T32),T42),T41) -> 1200.9 | U30: =MIN(MAX(SUM(U31:U32),U42),U41) -> 1214.4 | V30: =MIN(MAX(SUM(V31:V32),V42),V41) -> 1226.1 | ... AC30: =MIN(MAX(SUM(AC31:AC32),AC42),AC41) -> 1238.875 | AD30: =MIN(MAX(SUM(AD31:AD32),AD42),AD41)-0.619999999998981 -> 1219.88 | AE30: =MIN(MAX(SUM(AE31:AE32),AE42),AE41) -> 1221 | AF30: =MIN(MAX(SUM(AF31:AF32),AF42),AF41) -> 1224 | AG30: =MIN(MAX(SUM(AG31:AG32),AG42),AG41) -> 1224 | AH30: =MIN(MAX(SUM(AH31:AH32),AH42),AH41) -> 1213.2 | AI30: =MIN(MAX(SUM(AI31:AI32),AI42),AI41) -> 1200 | AJ30: =MIN(MAX(SUM(AJ31:AJ32),AJ42),AJ41) -> 1200 | AK30: =MIN(MAX(SUM(AK31:AK32),AK42),AK41) -> 1200 | AL30: 1100 | AM30: =MIN(MAX(AM42,SUM(AM31:AM34)),AM41) -> 1120 | AN30: =MIN(MAX(AN42,SUM(AN31:AN34)),AN41) -> 1090 | AO30: =MIN(MAX(AO42,SUM(AO31:AO34)),AO41) -> 1101.25 | AP30: =MIN(MAX(AP42,SUM(AP31:AP34)),AP41) -> 1150 | AQ30: =MIN(MAX(AQ42,SUM(AQ31:AQ34)),AQ41) -> 1150 | AR30: =MIN(MAX(AR42,SUM(AR31:AR34)),AR41) -> 1150
A31: 200400 | B31: 110000354 | F31: 2.1.A | H31: [+] | I31: ICIS Bales - SEA trung bình 3 tháng trước | O31: 1296.0417 | P31: 1305 | Q31: 1313.3333 | R31: 1320 | S31: 1326 | T31: 1334.3333 | U31: 1349.3333 | V31: 1362.3333 | W31: 1380.6667 | X31: 1401.5 | Y31: 1424.1667 | Z31: 1434.1667 | AA31: 1432.0833 | AB31: 1404.8611 | AC31: 1376.5278 | AD31: 1356.1111 | AE31: 1356.6667 | AF31: 1360 | AG31: 1360 | AH31: 1348 | AI31: 1326.3333 | AJ31: 1295.6667 | AK31: 1271
A32: 200400 | B32: 110000354 | F32: 2.1.B | H32: [+] | I32: Chiết khấu (10%) | O32: -129.60417 | P32: -130.5 | Q32: -131.33333 | R32: -132 | S32: -132.6 | T32: -133.43333 | U32: -134.93333 | V32: -136.23333 | W32: -138.06667 | X32: -140.15 | Y32: -142.41667 | Z32: -143.41667 | AA32: -143.20833 | AB32: -140.48611 | AC32: -137.65278 | AD32: -135.61111 | AE32: -135.66667 | AF32: -136 | AG32: -136 | AH32: -134.8 | AI32: -132.63333 | AJ32: -129.56667 | AK32: -127.1
A33: 200400 | F33: 2.1.C | H33: [+] | I33: Giá Báse (Áp dụng 2026) | AM33: 1120 | AN33: =AM30 -> 1120 | AO33: =AN30 -> 1090 | AP33: =AO30 -> 1101.25 | AQ33: =AP30 -> 1150 | AR33: =AQ30 -> 1150
A34: 200400 | F34: 2.1.D | H34: [+] | I34: Chênh lệch ICIS 2 tháng trước (Áp dụng 2026) | AN34: =AM38-AL38 -> -43.75 | AO34: =AN38-AM38 -> 11.25 | AP34: =AO38-AN38 -> 74.75 | AQ34: =AP38-AO38 -> 81.5 | AR34: =AQ38-AP38 -> 41.25
A35: 200400 | B35: 110000354 | D35: EXW | F35: 2.1.1 | I35: Giá bán quy đổi EXW | O35: =O30-O36-O37 -> 1162 | P35: =P30-P36-P37 -> 1162 | Q35: =Q30-Q36-Q37 -> 1162 | R35: =R30-R36-R37 -> 1162 | S35: =S30-S36-S37 -> 1162 | T35: =T30-T36-T37 -> 1162.8865 | U35: =U30-U36-U37 -> 1176.184 | V35: =V30-V36-V37 -> 1187.7085 | ... AR35: =AR30-AR36-AR37 -> 1112.75
A36: 200400 | B36: 110000354 | I36: Chi phí vận chuyển | O36: 20 | P36: 20 | Q36: 20 | R36: 20 | S36: 20 | T36: 20 | U36: 20 | V36: 20 | W36: 20 | X36: 20 | Y36: 20 | Z36: 20 | AA36: 20 | AB36: 20 | AC36: 20 | AD36: 22 | AE36: 22 | AF36: 22 | AG36: 22 | AH36: 20 | AI36: 20 | AJ36: 20 | AK36: 20 | AL36: 20 | AM36: 20 | AN36: 20 | AO36: 20 | AP36: 20 | AQ36: 20 | AR36: 20
A37: 200400 | B37: 110000354 | J37: Chi phí hoa hồng | O37: =O30*O40 -> 18 | P37: =P30*P40 -> 18 | Q37: =Q30*Q40 -> 18 | R37: =R30*R40 -> 18 | S37: =S30*S40 -> 18 | T37: =T30*T40 -> 18.0135 | U37: =U30*U40 -> 18.216 | V37: =V30*V40 -> 18.3915 | ... AR37: =AR30*AR40 -> 17.25
A38: 200400 | B38: 110000354 | C38: 04 | J38: ICIS Bales - SEA | L38: 1288.125 | M38: 1300 | N38: 1300 | O38: 1315 | P38: 1325 | Q38: 1320 | R38: 1333 | S38: 1350 | T38: 1365 | U38: 1372 | V38: 1405 | W38: 1427.5 | X38: 1440 | Y38: 1435 | Z38: 1421.25 | AA38: 1358.3333 | AB38: 1350 | AC38: 1360 | AD38: 1360 | AE38: 1360 | AF38: 1360 | AG38: 1324 | AH38: 1295 | AI38: 1268 | AJ38: 1250 | AK38: 1243.75 | AL38: 1193.75 | AM38: {=SUMPRODUCT(General_Data*(Year=AM$3)*(Month=AM$4)*(Code_General_Data=$C38))} -> 1150 | AN38: {=SUMPRODUCT(General_Data*(Year=AN$3)*(Month=AN$4)*(Code_General_Data=$C38))} -> 1161.25 | AO38: {=SUMPRODUCT(General_Data*(Year=AO$3)*(Month=AO$4)*(Code_General_Data=$C38))} -> 1236 | AP38: {=SUMPRODUCT(General_Data*(Year=AP$3)*(Month=AP$4)*(Code_General_Data=$C38))} -> 1317.5 | AQ38: {=SUMPRODUCT(General_Data*(Year=AQ$3)*(Month=AQ$4)*(Code_General_Data=$C38))} -> 1358.75 | AR38: {=SUMPRODUCT(General_Data*(Year=AR$3)*(Month=AR$4)*(Code_General_Data=$C38))} -> 0
A39: 200400 | B39: 110000354 | J39: %Chiết khấu | O39: 0.1 | P39: 0.1 | Q39: 0.1 | R39: 0.1 | S39: 0.1 | T39: 0.1 | U39: 0.1 | V39: 0.1 | W39: 0.1 | X39: 0.1 | Y39: 0.1 | Z39: 0.1 | AA39: 0.1 | AB39: 0.1 | AC39: 0.1 | AD39: 0.1 | AE39: 0.1 | AF39: 0.1 | AG39: 0.1 | AH39: 0.1 | AI39: 0.1 | AJ39: 0.1 | AK39: 0.1 | AL39: 0.1 | AM39: N/A | AN39: N/A | AO39: N/A | AP39: N/A | AQ39: N/A | AR39: N/A
A40: 200319 | B40: 110000354 | J40: %Hoa hồng | O40: 0.015 | P40: 0.015 | Q40: 0.015 | R40: 0.015 | S40: 0.015 | T40: 0.015 | U40: 0.015 | V40: 0.015 | W40: 0.015 | X40: 0.015 | Y40: 0.015 | Z40: 0.015 | AA40: 0.015 | AB40: 0.015 | AC40: 0.015 | AD40: 0.015 | AE40: 0.015 | AF40: 0.015 | AG40: 0.015 | AH40: 0.015 | AI40: 0.015 | AJ40: 0.015 | AK40: 0.015 | AL40: 0.015 | AM40: 0.015 | AN40: 0.015 | AO40: 0.015 | AP40: 0.015 | AQ40: 0.015 | AR40: 0.015
A41: 200400 | B41: 110000354 | F41: 2.1.2 | J41: Giá trần | O41: 1600 | P41: 1600 | Q41: 1600 | R41: 1600 | S41: 1600 | T41: 1600 | U41: 1600 | V41: 1600 | W41: 1600 | X41: 1600 | Y41: 1600 | Z41: 1600 | AA41: 1600 | AB41: 1600 | AC41: 1600 | AD41: 1600 | AE41: 1600 | AF41: 1600 | AG41: 1600 | AH41: 1600 | AI41: 1600 | AJ41: 1600 | AK41: 1600 | AM41: {=INDEX(Note!$J$3:$J$102,MATCH(1,(Note!$A$3:$A$102=$A41)*(Note!$C$3:$C$102=$B41)*(Note!$E$3:$E$102<=AM$1)*(Note!$F$3:$F$102>=AM$2),0))} -> 1150 | AN41: {=INDEX(Note!$J$3:$J$102,MATCH(1,(Note!$A$3:$A$102=$A41)*(Note!$C$3:$C$102=$B41)*(Note!$E$3:$E$102<=AN$1)*(Note!$F$3:$F$102>=AN$2),0))} -> 1150 | AO41: {=INDEX(Note!$J$3:$J$102,MATCH(1,(Note!$A$3:$A$102=$A41)*(Note!$C$3:$C$102=$B41)*(Note!$E$3:$E$102<=AO$1)*(Note!$F$3:$F$102>=AO$2),0))} -> 1150 | AP41: {=INDEX(Note!$J$3:$J$102,MATCH(1,(Note!$A$3:$A$102=$A41)*(Note!$C$3:$C$102=$B41)*(Note!$E$3:$E$102<=AP$1)*(Note!$F$3:$F$102>=AP$2),0))} -> 1150 | AQ41: {=INDEX(Note!$J$3:$J$102,MATCH(1,(Note!$A$3:$A$102=$A41)*(Note!$C$3:$C$102=$B41)*(Note!$E$3:$E$102<=AQ$1)*(Note!$F$3:$F$102>=AQ$2),0))} -> 1150 | AR41: {=INDEX(Note!$J$3:$J$102,MATCH(1,(Note!$A$3:$A$102=$A41)*(Note!$C$3:$C$102=$B41)*(Note!$E$3:$E$102<=AR$1)*(Note!$F$3:$F$102>=AR$2),0))} -> 1150
A42: 200400 | B42: 110000354 | F42: 2.1.3 | J42: Giá sàn | O42: 1200 | P42: 1200 | Q42: 1200 | R42: 1200 | S42: 1200 | T42: 1200 | U42: 1200 | V42: 1200 | W42: 1200 | X42: 1200 | Y42: 1200 | Z42: 1200 | AA42: 1200 | AB42: 1200 | AC42: 1200 | AD42: 1200 | AE42: 1200 | AF42: 1200 | AG42: 1200 | AH42: 1200 | AI42: 1200 | AJ42: 1200 | AK42: 1200 | AM42: {=INDEX(Note!$K$3:$K$102,MATCH(1,(Note!$A$3:$A$102=$A42)*(Note!$C$3:$C$102=$B42)*(Note!$E$3:$E$102<=AM$1)*(Note!$F$3:$F$102>=AM$2),0))} -> 1090 | AN42: {=INDEX(Note!$K$3:$K$102,MATCH(1,(Note!$A$3:$A$102=$A42)*(Note!$C$3:$C$102=$B42)*(Note!$E$3:$E$102<=AN$1)*(Note!$F$3:$F$102>=AN$2),0))} -> 1090 | AO42: {=INDEX(Note!$K$3:$K$102,MATCH(1,(Note!$A$3:$A$102=$A42)*(Note!$C$3:$C$102=$B42)*(Note!$E$3:$E$102<=AO$1)*(Note!$F$3:$F$102>=AO$2),0))} -> 1090 | AP42: {=INDEX(Note!$K$3:$K$102,MATCH(1,(Note!$A$3:$A$102=$A42)*(Note!$C$3:$C$102=$B42)*(Note!$E$3:$E$102<=AP$1)*(Note!$F$3:$F$102>=AP$2),0))} -> 1090 | AQ42: {=INDEX(Note!$K$3:$K$102,MATCH(1,(Note!$A$3:$A$102=$A42)*(Note!$C$3:$C$102=$B42)*(Note!$E$3:$E$102<=AQ$1)*(Note!$F$3:$F$102>=AQ$2),0))} -> 1090 | AR42: {=INDEX(Note!$K$3:$K$102,MATCH(1,(Note!$A$3:$A$102=$A42)*(Note!$C$3:$C$102=$B42)*(Note!$E$3:$E$102<=AR$1)*(Note!$F$3:$F$102>=AR$2),0))} -> 1090
A43: 200400 | B43: 110000354 | F43: 2.1.4 | J43: Giá duyệt tháng | O43: 1250 | P43: 1250 | Q43: 1250 | R43: 1250 | S43: 1300 | T43: 1300 | U43: 1300 | V43: 1300 | W43: 1310 | X43: 1325 | Y43: 1325 | Z43: 1275 | AA43: 1230 | AB43: 1230 | AC43: 1230 | AD43: 1250 | AE43: 1250 | AF43: 1250 | AG43: 1250 | AH43: 1220 | AI43: 1220 | AJ43: 1210 | AK43: 1200 | AL43: 1200 | AM43: {=SUMPRODUCT(General_Data*(Year=AM$3)*(Month=AM$4)*(Code_General_Data=$B43))} -> 1160 | AN43: {=SUMPRODUCT(General_Data*(Year=AN$3)*(Month=AN$4)*(Code_General_Data=$B43))} -> 1160 | AO43: {=SUMPRODUCT(General_Data*(Year=AO$3)*(Month=AO$4)*(Code_General_Data=$B43))} -> 1160 | AP43: {=SUMPRODUCT(General_Data*(Year=AP$3)*(Month=AP$4)*(Code_General_Data=$B43))} -> 1280 | AQ43: {=SUMPRODUCT(General_Data*(Year=AQ$3)*(Month=AQ$4)*(Code_General_Data=$B43))} -> 1380 | AR43: {=SUMPRODUCT(General_Data*(Year=AR$3)*(Month=AR$4)*(Code_General_Data=$B43))} -> 1350
J44: Giá trần - quy đổi EXW | O44: =O41-O36-O37 -> 1562 | P44: =P41-P36-P37 -> 1562 | Q44: =Q41-Q36-Q37 -> 1562 | R44: =R41-R36-R37 -> 1562 | S44: =S41-S36-S37 -> 1562 | T44: =T41-T36-T37 -> 1561.9865 | U44: =U41-U36-U37 -> 1561.784 | V44: =V41-V36-V37 -> 1561.6085 | ... AK44: =AK41-AK36-AK37 -> 1562 | AM44: =AM41-AM36-AM37 -> 1113.2 | AN44: =AN41-AN36-AN37 -> 1113.65 | AO44: =AO41-AO36-AO37 -> 1113.4813 | AP44: =AP41-AP36-AP37 -> 1112.75 | AQ44: =AQ41-AQ36-AQ37 -> 1112.75 | AR44: =AR41-AR36-AR37 -> 1112.75
...

Sheet Biểu đồ
C1: III. BIỂU ĐỒ
C36: III. BIỂU ĐỒ
C71: III. BIỂU ĐỒ
C106: III. BIỂU ĐỒ
C141: III. BIỂU ĐỒ

Sheet Vẽ Biểu đồ
E1: 2024 | F1: 2024 | G1: 2024 | H1: 2024 | I1: 2024 | J1: 2024 | K1: 2024 | L1: 2024 | M1: 2024 | N1: 2024 | O1: 2024 | P1: 2024 | Q1: 2025 | R1: 2025 | S1: 2025 | T1: 2025 | U1: 2025 | V1: 2025 | W1: 2025 | X1: 2025 | Y1: 2025 | Z1: 2025 | AA1: 2025 | AB1: 2025 | AC1: 2026 | AD1: 2026 | AE1: 2026 | AF1: 2026 | AG1: 2026 | AH1: 2026 | AI1: 2026 | AJ1: 2026 | AK1: 2026 | AL1: 2026 | AM1: 2026 | AN1: 2026
E2: 1 | F2: 2 | G2: 3 | H2: 4 | I2: 5 | J2: 6 | K2: 7 | L2: 8 | M2: 9 | N2: 10 | O2: 11 | P2: 12 | Q2: 1 | R2: 2 | S2: 3 | T2: 4 | U2: 5 | V2: 6 | W2: 7 | X2: 8 | Y2: 9 | Z2: 10 | AA2: 11 | AB2: 12 | AC2: 1 | AD2: 2 | AE2: 3 | AF2: 4 | AG2: 5 | AH2: 6 | AI2: 7 | AJ2: 8 | AK2: 9 | AL2: 10 | AM2: 11 | AN2: 12
D3: X dòng này làm lable -> | AH3: x
A4: Genearal Data | B4: Price
C5: 110000354 | D5: WSS01G
E6: 2024 | Q6: 2025 | AC6: 2026
E7: 1 | F7: 2 | G7: 3 | H7: 4 | I7: 5 | J7: 6 | K7: 7 | L7: 8 | M7: 9 | N7: 10 | O7: 11 | P7: 12 | Q7: 1 | R7: 2 | S7: 3 | T7: 4 | U7: 5 | V7: 6 | W7: 7 | X7: 8 | Y7: 9 | Z7: 10 | AA7: 11 | AB7: 12 | AC7: 1 | AD7: 2 | AE7: 3 | AF7: 4 | AG7: 5 | AH7: 6 | AI7: 7 | AJ7: 8 | AK7: 9 | AL7: 10 | AM7: 11 | AN7: 12
B8: 200319 | C8: 110000354 | D8: Niagara | E8: {=IF(SUMPRODUCT('Giá công thức'!$G$11:$AQ$115*('Giá công thức'!$A$11:$A$115=$B8)*('Giá công thức'!$B$11:$B$115=$C8)*('Giá công thức'!$C$11:$C$115="GB")*('Giá công thức'!$G$3:$AQ$3=E$1)*('Giá công thức'!$G$4:$AQ$4=E$2))=0,NA(),SUMPRODUCT('Giá công thức'!$G$11:$AQ$115*('Giá công thức'!$A$11:$A$115=$B8)*('Giá công thức'!$B$11:$B$115=$C8)*('Giá công thức'!$C$11:$C$115="GB")*('Giá công thức'!$G$3:$AQ$3=E$1)*('Giá công thức'!$G$4:$AQ$4=E$2)))} -> 1162 | F8: {=IF(SUMPRODUCT('Giá công thức'!$G$11:$AQ$115*('Giá công thức'!$A$11:$A$115=$B8)*('Giá công thức'!$B$11:$B$115=$C8)*('Giá công thức'!$C$11:$C$115="GB")*('Giá công thức'!$G$3:$AQ$3=F$1)*('Giá công thức'!$G$4:$AQ$4=F$2))=0,NA(),SUMPRODUCT('Giá công thức'!$G$11:$AQ$115*('Giá công thức'!$A$11:$A$115=$B8)*('Giá công thức'!$B$11:$B$115=$C8)*('Giá công thức'!$C$11:$C$115="GB")*('Giá công thức'!$G$3:$AQ$3=F$1)*('Giá công thức'!$G$4:$AQ$4=F$2)))} -> 1162 | G8: {=IF(SUMPRODUCT('Giá công thức'!$G$11:$AQ$115*('Giá công thức'!$A$11:$A$115=$B8)*('Giá công thức'!$B$11:$B$115=$C8)*('Giá công thức'!$C$11:$C$115="GB")*('Giá công thức'!$G$3:$AQ$3=G$1)*('Giá công thức'!$G$4:$AQ$4=G$2))=0,NA(),SUMPRODUCT('Giá công thức'!$G$11:$AQ$115*('Giá công thức'!$A$11:$A$115=$B8)*('Giá công thức'!$B$11:$B$115=$C8)*('Giá công thức'!$C$11:$C$115="GB")*('Giá công thức'!$G$3:$AQ$3=G$1)*('Giá công thức'!$G$4:$AQ$4=G$2)))} -> 1162 | H8: {=IF(SUMPRODUCT('Giá công thức'!$G$11:$AQ$115*('Giá công thức'!$A$11:$A$115=$B8)*('Giá công thức'!$B$11:$B$115=$C8)*('Giá công thức'!$C$11:$C$115="GB")*('Giá công thức'!$G$3:$AQ$3=H$1)*('Giá công thức'!$G$4:$AQ$4=H$2))=0,NA(),SUMPRODUCT('Giá công thức'!$G$11:$AQ$115*('Giá công thức'!$A$11:$A$115=$B8)*('Giá công thức'!$B$11:$B$115=$C8)*('Giá công thức'!$C$11:$C$115="GB")*('Giá công thức'!$G$3:$AQ$3=H$1)*('Giá công thức'!$G$4:$AQ$4=H$2)))} -> 1162 | I8: {=IF(SUMPRODUCT('Giá công thức'!$G$11:$AQ$115*('Giá công thức'!$A$11:$A$115=$B8)*('Giá công thức'!$B$11:$B$115=$C8)*('Giá công thức'!$C$11:$C$115="GB")*('Giá công thức'!$G$3:$AQ$3=I$1)*('Giá công thức'!$G$4:$AQ$4=I$2))=0,NA(),SUMPRODUCT('Giá công thức'!$G$11:$AQ$115*('Giá công thức'!$A$11:$A$115=$B8)*('Giá công thức'!$B$11:$B$115=$C8)*('Giá công thức'!$C$11:$C$115="GB")*('Giá công thức'!$G$3:$AQ$3=I$1)*('Giá công thức'!$G$4:$AQ$4=I$2)))} -> 1162 | J8: {=IF(SUMPRODUCT('Giá công thức'!$G$11:$AQ$115*('Giá công thức'!$A$11:$A$115=$B8)*('Giá công thức'!$B$11:$B$115=$C8)*('Giá công thức'!$C$11:$C$115="GB")*('Giá công thức'!$G$3:$AQ$3=J$1)*('Giá công thức'!$G$4:$AQ$4=J$2))=0,NA(),SUMPRODUCT('Giá công thức'!$G$11:$AQ$115*('Giá công thức'!$A$11:$A$115=$B8)*('Giá công thức'!$B$11:$B$115=$C8)*('Giá công thức'!$C$11:$C$115="GB")*('Giá công thức'!$G$3:$AQ$3=J$1)*('Giá công thức'!$G$4:$AQ$4=J$2)))} -> 1162.8865 | K8: {=IF(SUMPRODUCT('Giá công thức'!$G$11:$AQ$115*('Giá công thức'!$A$11:$A$115=$B8)*('Giá công thức'!$B$11:$B$115=$C8)*('Giá công thức'!$C$11:$C$115="GB")*('Giá công thức'!$G$3:$AQ$3=K$1)*('Giá công thức'!$G$4:$AQ$4=K$2))=0,NA(),SUMPRODUCT('Giá công thức'!$G$11:$AQ$115*('Giá công thức'!$A$11:$A$115=$B8)*('Giá công thức'!$B$11:$B$115=$C8)*('Giá công thức'!$C$11:$C$115="GB")*('Giá công thức'!$G$3:$AQ$3=K$1)*('Giá công thức'!$G$4:$AQ$4=K$2)))} -> 1176.184 | L8: {=IF(SUMPRODUCT('Giá công thức'!$G$11:$AQ$115*('Giá công thức'!$A$11:$A$115=$B8)*('Giá công thức'!$B$11:$B$115=$C8)*('Giá công thức'!$C$11:$C$115="GB")*('Giá công thức'!$G$3:$AQ$3=L$1)*('Giá công thức'!$G$4:$AQ$4=L$2))=0,NA(),SUMPRODUCT('Giá công thức'!$G$11:$AQ$115*('Giá công thức'!$A$11:$A$115=$B8)*('Giá công thức'!$B$11:$B$115=$C8)*('Giá công thức'!$C$11:$C$115="GB")*('Giá công thức'!$G$3:$AQ$3=L$1)*('Giá công thức'!$G$4:$AQ$4=L$2)))} -> 1187.7085 | ... AH8: {=IF(SUMPRODUCT('Giá công thức'!$G$11:$AQ$115*('Giá công thức'!$A$11:$A$115=$B8)*('Giá công thức'!$B$11:$B$115=$C8)*('Giá công thức'!$C$11:$C$115="GB")*('Giá công thức'!$G$3:$AQ$3=AH$1)*('Giá công thức'!$G$4:$AQ$4=AH$2))=0,NA(),SUMPRODUCT('Giá công thức'!$G$11:$AQ$115*('Giá công thức'!$A$11:$A$115=$B8)*('Giá công thức'!$B$11:$B$115=$C8)*('Giá công thức'!$C$11:$C$115="GB")*('Giá công thức'!$G$3:$AQ$3=AH$1)*('Giá công thức'!$G$4:$AQ$4=AH$2)))} -> 1182.685 | AO8: =INDEX($E8:$AN8,MATCH("X",$E$3:$AN$3,0)) -> 1182.685
