Workbook
Name \T: #REF!
Name \T: #REF!
Name __dao1: #REF!
Name __dao2: #REF!
Name __dap2: #REF!
Name __day1: #REF!
Name __day2: #REF!
Name __dbu1: #REF!
Name __dbu2: #REF!
Name __doi3: #REF!
Name __E99999: #REF!
Name __Jan02: #REF!
Name __lap1: #REF!
Name __lap2: #REF!
Name __vc1: #REF!
Name __vc2: #REF!
Name __vc3: #REF!
Name _01_01_99: #REF!
Name _01_02_99: #REF!
Name _01_03_99: #REF!
Name _01_04_99: #REF!
Name _01_05_99: #REF!
Name _01_06_99: #REF!
Name _01_07_99: #REF!
Name _01_08_1999: #REF!
Name _1CAP002: #REF!
Name _2STREO7: #REF!
Name _4GOIC01: #REF!
Name _4OSLCTT: #REF!
Name _6BNTTTH: #REF!
Name _6DCTTBO: #REF!
Name _6DD24TT: #REF!
Name _6FCOTBU: #REF!
Name _6LATUBU: #REF!
Name _6SDTT24: #REF!
Name _6TBUDTT: #REF!
Name _6TDDDTT: #REF!
Name _6TLTTTH: #REF!
Name _6TUBUTT: #REF!
Name _6UCLVIS: #REF!
Name _7DNCABC: #REF!
Name _7HDCTBU: #REF!
Name _7PKTUBU: #REF!
Name _7TBHT20: #REF!
Name _7TBHT30: #REF!
Name _7TDCABC: #REF!
Name _dao1: #REF!
Name _dao2: #REF!
Name _dap2: #REF!
Name _day1: #REF!
Name _day2: #REF!
Name _dbu1: #REF!
Name _dbu2: #REF!
Name _doi3: #REF!
Name _E99999: #REF!
Name _Jan02: #REF!
Name _lap1: #REF!
Name _lap2: #REF!
Name _vc1: #REF!
Name _vc2: #REF!

Sheet BÌA
A5: MA TRẬN KHÁCH HÀNG
C11: I. | D11: TỔNG QUAN GIÁ CÔNG THỨC THEO KHÁCH HÀNG
C14: II. | D14: CHI TIẾT GIÁ CÔNG THỨC THEO KHÁCH HÀNG
C17: III. | D17: BIỂU ĐỒ

Sheet Giá công thức
G1: =DATE(G3,G4,1) -> 45292 | H1: =DATE(H3,H4,1) -> 45323 | I1: =DATE(I3,I4,1) -> 45352 | J1: =DATE(J3,J4,1) -> 45383 | K1: =DATE(K3,K4,1) -> 45413 | L1: =DATE(L3,L4,1) -> 45444 | M1: =DATE(M3,M4,1) -> 45474 | N1: =DATE(N3,N4,1) -> 45505 | ... AD1: =DATE(AD3,AD4,1) -> 45992
G2: =EOMONTH(G1,0) -> 45322 | H2: =EOMONTH(H1,0) -> 45351 | I2: =EOMONTH(I1,0) -> 45382 | J2: =EOMONTH(J1,0) -> 45412 | K2: =EOMONTH(K1,0) -> 45443 | L2: =EOMONTH(L1,0) -> 45473 | M2: =EOMONTH(M1,0) -> 45504 | N2: =EOMONTH(N1,0) -> 45535 | ... AD2: =EOMONTH(AD1,0) -> 46022
G3: 2024 | H3: 2024 | I3: 2024 | J3: 2024 | K3: 2024 | L3: 2024 | M3: 2024 | N3: 2024 | O3: 2024 | P3: 2024 | Q3: 2024 | R3: 2024 | S3: 2025 | T3: 2025 | U3: 2025 | V3: 2025 | W3: 2025 | X3: 2025 | Y3: 2025 | Z3: 2025 | AA3: 2025 | AB3: 2025 | AC3: 2025 | AD3: 2025
G4: 1 | H4: 2 | I4: 3 | J4: 4 | K4: 5 | L4: 6 | M4: 7 | N4: 8 | O4: 9 | P4: 10 | Q4: 11 | R4: 12 | S4: 1 | T4: 2 | U4: 3 | V4: 4 | W4: 5 | X4: 6 | Y4: 7 | Z4: 8 | AA4: 9 | AB4: 10 | AC4: 11 | AD4: 12
G5: I. GIÁ CÔNG THỨC THEO KHÁCH HÀNG | S5: I. GIÁ CÔNG THỨC THEO KHÁCH HÀNG | AE5: I. GIÁ CÔNG THỨC THEO KHÁCH HÀNG
D8: STT | E8: KHÁCH HÀNG/SẢN PHẨM | G8: 2024 | S8: 2025 | AE8: 2026
G9: 1 | H9: 2 | I9: 3 | J9: 4 | K9: 5 | L9: 6 | M9: 7 | N9: 8 | O9: 9 | P9: 10 | Q9: 11 | R9: 12 | S9: 1 | T9: 2 | U9: 3 | V9: 4 | W9: 5 | X9: 6 | Y9: 7 | Z9: 8 | AA9: 9 | AB9: 10 | AC9: 11 | AD9: 12 | AE9: 1 | AF9: 2 | AG9: 3 | AH9: 4 | AI9: 5 | AJ9: 6 | AK9: 7 | AL9: 8 | AM9: 9 | AN9: 10 | AO9: 11 | AP9: 12
A11: 200319 | D11: 1 | E11: NIAGARA
A12: 200319 | B12: 110000354 | F12: WSS01G
A13: 200319 | B13: 110000354 | D13: 1.1 | F13: Giá bán - FOB | G13: {=INDEX(Price!$L$11:$AM$182,MATCH(1,(Price!$A$11:$A$182=$A13)*(Price!$B$11:$B$182=$B13)*(Price!$D$11:$D$182="gb"),0),MATCH(1,(Price!$L$3:$AM$3=G$3)*(Price!$L$4:$AM$4=G$4),0))} -> 1200 | H13: {=INDEX(Price!$L$11:$AM$182,MATCH(1,(Price!$A$11:$A$182=$A13)*(Price!$B$11:$B$182=$B13)*(Price!$D$11:$D$182="gb"),0),MATCH(1,(Price!$L$3:$AM$3=H$3)*(Price!$L$4:$AM$4=H$4),0))} -> 1200 | I13: {=INDEX(Price!$L$11:$AM$182,MATCH(1,(Price!$A$11:$A$182=$A13)*(Price!$B$11:$B$182=$B13)*(Price!$D$11:$D$182="gb"),0),MATCH(1,(Price!$L$3:$AM$3=I$3)*(Price!$L$4:$AM$4=I$4),0))} -> 1200 | J13: {=INDEX(Price!$L$11:$AM$182,MATCH(1,(Price!$A$11:$A$182=$A13)*(Price!$B$11:$B$182=$B13)*(Price!$D$11:$D$182="gb"),0),MATCH(1,(Price!$L$3:$AM$3=J$3)*(Price!$L$4:$AM$4=J$4),0))} -> 1200 | K13: {=INDEX(Price!$L$11:$AM$182,MATCH(1,(Price!$A$11:$A$182=$A13)*(Price!$B$11:$B$182=$B13)*(Price!$D$11:$D$182="gb"),0),MATCH(1,(Price!$L$3:$AM$3=K$3)*(Price!$L$4:$AM$4=K$4),0))} -> 1200 | L13: {=INDEX(Price!$L$11:$AM$182,MATCH(1,(Price!$A$11:$A$182=$A13)*(Price!$B$11:$B$182=$B13)*(Price!$D$11:$D$182="gb"),0),MATCH(1,(Price!$L$3:$AM$3=L$3)*(Price!$L$4:$AM$4=L$4),0))} -> 1200.9 | M13: {=INDEX(Price!$L$11:$AM$182,MATCH(1,(Price!$A$11:$A$182=$A13)*(Price!$B$11:$B$182=$B13)*(Price!$D$11:$D$182="gb"),0),MATCH(1,(Price!$L$3:$AM$3=M$3)*(Price!$L$4:$AM$4=M$4),0))} -> 1214.4 | N13: {=INDEX(Price!$L$11:$AM$182,MATCH(1,(Price!$A$11:$A$182=$A13)*(Price!$B$11:$B$182=$B13)*(Price!$D$11:$D$182="gb"),0),MATCH(1,(Price!$L$3:$AM$3=N$3)*(Price!$L$4:$AM$4=N$4),0))} -> 1226.1 | ... AD13: {=INDEX(Price!$L$11:$AM$182,MATCH(1,(Price!$A$11:$A$182=$A13)*(Price!$B$11:$B$182=$B13)*(Price!$D$11:$D$182="gb"),0),MATCH(1,(Price!$L$3:$AM$3=AD$3)*(Price!$L$4:$AM$4=AD$4),0))} -> 1200
A14: 200319 | B14: 110000354 | C14: GB | D14: 1.2 | F14: Giá bán quy đổi EXW | G14: {=INDEX(Price!$L$11:$AM$182,MATCH(1,(Price!$A$11:$A$182=$A14)*(Price!$B$11:$B$182=$B14)*(Price!$D$11:$D$182="exw"),0),MATCH(1,(Price!$L$3:$AM$3=G$3)*(Price!$L$4:$AM$4=G$4),0))} -> 1180 | H14: {=INDEX(Price!$L$11:$AM$182,MATCH(1,(Price!$A$11:$A$182=$A14)*(Price!$B$11:$B$182=$B14)*(Price!$D$11:$D$182="exw"),0),MATCH(1,(Price!$L$3:$AM$3=H$3)*(Price!$L$4:$AM$4=H$4),0))} -> 1180 | I14: {=INDEX(Price!$L$11:$AM$182,MATCH(1,(Price!$A$11:$A$182=$A14)*(Price!$B$11:$B$182=$B14)*(Price!$D$11:$D$182="exw"),0),MATCH(1,(Price!$L$3:$AM$3=I$3)*(Price!$L$4:$AM$4=I$4),0))} -> 1180 | J14: {=INDEX(Price!$L$11:$AM$182,MATCH(1,(Price!$A$11:$A$182=$A14)*(Price!$B$11:$B$182=$B14)*(Price!$D$11:$D$182="exw"),0),MATCH(1,(Price!$L$3:$AM$3=J$3)*(Price!$L$4:$AM$4=J$4),0))} -> 1180 | K14: {=INDEX(Price!$L$11:$AM$182,MATCH(1,(Price!$A$11:$A$182=$A14)*(Price!$B$11:$B$182=$B14)*(Price!$D$11:$D$182="exw"),0),MATCH(1,(Price!$L$3:$AM$3=K$3)*(Price!$L$4:$AM$4=K$4),0))} -> 1180 | L14: {=INDEX(Price!$L$11:$AM$182,MATCH(1,(Price!$A$11:$A$182=$A14)*(Price!$B$11:$B$182=$B14)*(Price!$D$11:$D$182="exw"),0),MATCH(1,(Price!$L$3:$AM$3=L$3)*(Price!$L$4:$AM$4=L$4),0))} -> 1180.9 | M14: {=INDEX(Price!$L$11:$AM$182,MATCH(1,(Price!$A$11:$A$182=$A14)*(Price!$B$11:$B$182=$B14)*(Price!$D$11:$D$182="exw"),0),MATCH(1,(Price!$L$3:$AM$3=M$3)*(Price!$L$4:$AM$4=M$4),0))} -> 1194.4 | N14: {=INDEX(Price!$L$11:$AM$182,MATCH(1,(Price!$A$11:$A$182=$A14)*(Price!$B$11:$B$182=$B14)*(Price!$D$11:$D$182="exw"),0),MATCH(1,(Price!$L$3:$AM$3=N$3)*(Price!$L$4:$AM$4=N$4),0))} -> 1206.1 | ... AD14: {=INDEX(Price!$L$11:$AM$182,MATCH(1,(Price!$A$11:$A$182=$A14)*(Price!$B$11:$B$182=$B14)*(Price!$D$11:$D$182="exw"),0),MATCH(1,(Price!$L$3:$AM$3=AD$3)*(Price!$L$4:$AM$4=AD$4),0))} -> 1180
A15: 200319 | B15: 110000354 | C15: PETVirgin | D15: 1.3 | F15: Giá chính phẩm | G15: {=SUMPRODUCT(General_Data*(Code_General_Data=$C15)*(Year=G$3)*(Month=G$4))} -> 930 | H15: {=SUMPRODUCT(General_Data*(Code_General_Data=$C15)*(Year=H$3)*(Month=H$4))} -> 943.33333 | I15: {=SUMPRODUCT(General_Data*(Code_General_Data=$C15)*(Year=I$3)*(Month=I$4))} -> 940 | J15: {=SUMPRODUCT(General_Data*(Code_General_Data=$C15)*(Year=J$3)*(Month=J$4))} -> 940 | K15: {=SUMPRODUCT(General_Data*(Code_General_Data=$C15)*(Year=K$3)*(Month=K$4))} -> 942 | L15: {=SUMPRODUCT(General_Data*(Code_General_Data=$C15)*(Year=L$3)*(Month=L$4))} -> 950 | M15: {=SUMPRODUCT(General_Data*(Code_General_Data=$C15)*(Year=M$3)*(Month=M$4))} -> 947.5 | N15: {=SUMPRODUCT(General_Data*(Code_General_Data=$C15)*(Year=N$3)*(Month=N$4))} -> 930 | ... AD15: {=SUMPRODUCT(General_Data*(Code_General_Data=$C15)*(Year=AD$3)*(Month=AD$4))} -> 770
A16: 200319 | B16: 110000354 | D16: 1.4 | F16: Chênh lệch giữa R sv Virgin | G16: =IF(G13*G14*G15<>0,G14-G15,0) -> 250 | H16: =IF(H13*H14*H15<>0,H14-H15,0) -> 236.66667 | I16: =IF(I13*I14*I15<>0,I14-I15,0) -> 240 | J16: =IF(J13*J14*J15<>0,J14-J15,0) -> 240 | K16: =IF(K13*K14*K15<>0,K14-K15,0) -> 238 | L16: =IF(L13*L14*L15<>0,L14-L15,0) -> 230.9 | M16: =IF(M13*M14*M15<>0,M14-M15,0) -> 246.9 | N16: =IF(N13*N14*N15<>0,N14-N15,0) -> 276.1 | ... AD16: =IF(AD13*AD14*AD15<>0,AD14-AD15,0) -> 410
A17: 200319 | B17: 110000354 | D17: 1.5 | F17: % +/- | G17: =IFERROR(G16/G15,0) -> 0.2688172 | H17: =IFERROR(H16/H15,0) -> 0.25088339 | I17: =IFERROR(I16/I15,0) -> 0.25531915 | J17: =IFERROR(J16/J15,0) -> 0.25531915 | K17: =IFERROR(K16/K15,0) -> 0.25265393 | L17: =IFERROR(L16/L15,0) -> 0.24305263 | M17: =IFERROR(M16/M15,0) -> 0.26058047 | N17: =IFERROR(N16/N15,0) -> 0.29688172 | ... AD17: =IFERROR(AD16/AD15,0) -> 0.53246753
A18: 200319 | B18: 110000354 | C18: 110000354 | D18: 1.6 | F18: Giá duyệt tháng | G18: {=SUMPRODUCT(General_Data*(Code_General_Data=$C18)*(Year=G$3)*(Month=G$4))} -> 1250 | H18: {=SUMPRODUCT(General_Data*(Code_General_Data=$C18)*(Year=H$3)*(Month=H$4))} -> 1250 | I18: {=SUMPRODUCT(General_Data*(Code_General_Data=$C18)*(Year=I$3)*(Month=I$4))} -> 1250 | J18: {=SUMPRODUCT(General_Data*(Code_General_Data=$C18)*(Year=J$3)*(Month=J$4))} -> 1250 | K18: {=SUMPRODUCT(General_Data*(Code_General_Data=$C18)*(Year=K$3)*(Month=K$4))} -> 1300 | L18: {=SUMPRODUCT(General_Data*(Code_General_Data=$C18)*(Year=L$3)*(Month=L$4))} -> 1300 | M18: {=SUMPRODUCT(General_Data*(Code_General_Data=$C18)*(Year=M$3)*(Month=M$4))} -> 1300 | N18: {=SUMPRODUCT(General_Data*(Code_General_Data=$C18)*(Year=N$3)*(Month=N$4))} -> 1300 | ... AD18: {=SUMPRODUCT(General_Data*(Code_General_Data=$C18)*(Year=AD$3)*(Month=AD$4))} -> 1200
A20: 200332 | D20: 2 | E20: OUTEIRINHO
A21: 200332 | B21: 110000355 | F21: iSS01G
A22: 200332 | B22: 110000355 | D22: 2.1 | F22: Giá bán-FOB | G22: {=INDEX(Price!$L$11:$AM$182,MATCH(1,(Price!$A$11:$A$182=$A22)*(Price!$B$11:$B$182=$B22)*(Price!$D$11:$D$182="gb"),0),MATCH(1,(Price!$L$3:$AM$3=G$3)*(Price!$L$4:$AM$4=G$4),0))} -> 0 | H22: {=INDEX(Price!$L$11:$AM$182,MATCH(1,(Price!$A$11:$A$182=$A22)*(Price!$B$11:$B$182=$B22)*(Price!$D$11:$D$182="gb"),0),MATCH(1,(Price!$L$3:$AM$3=H$3)*(Price!$L$4:$AM$4=H$4),0))} -> 0 | I22: {=INDEX(Price!$L$11:$AM$182,MATCH(1,(Price!$A$11:$A$182=$A22)*(Price!$B$11:$B$182=$B22)*(Price!$D$11:$D$182="gb"),0),MATCH(1,(Price!$L$3:$AM$3=I$3)*(Price!$L$4:$AM$4=I$4),0))} -> 0 | J22: {=INDEX(Price!$L$11:$AM$182,MATCH(1,(Price!$A$11:$A$182=$A22)*(Price!$B$11:$B$182=$B22)*(Price!$D$11:$D$182="gb"),0),MATCH(1,(Price!$L$3:$AM$3=J$3)*(Price!$L$4:$AM$4=J$4),0))} -> 0 | K22: {=INDEX(Price!$L$11:$AM$182,MATCH(1,(Price!$A$11:$A$182=$A22)*(Price!$B$11:$B$182=$B22)*(Price!$D$11:$D$182="gb"),0),MATCH(1,(Price!$L$3:$AM$3=K$3)*(Price!$L$4:$AM$4=K$4),0))} -> 0 | L22: {=INDEX(Price!$L$11:$AM$182,MATCH(1,(Price!$A$11:$A$182=$A22)*(Price!$B$11:$B$182=$B22)*(Price!$D$11:$D$182="gb"),0),MATCH(1,(Price!$L$3:$AM$3=L$3)*(Price!$L$4:$AM$4=L$4),0))} -> 0 | M22: {=INDEX(Price!$L$11:$AM$182,MATCH(1,(Price!$A$11:$A$182=$A22)*(Price!$B$11:$B$182=$B22)*(Price!$D$11:$D$182="gb"),0),MATCH(1,(Price!$L$3:$AM$3=M$3)*(Price!$L$4:$AM$4=M$4),0))} -> 0 | N22: {=INDEX(Price!$L$11:$AM$182,MATCH(1,(Price!$A$11:$A$182=$A22)*(Price!$B$11:$B$182=$B22)*(Price!$D$11:$D$182="gb"),0),MATCH(1,(Price!$L$3:$AM$3=N$3)*(Price!$L$4:$AM$4=N$4),0))} -> 0 | O22: {=INDEX(Price!$L$11:$AM$182,MATCH(1,(Price!$A$11:$A$182=$A22)*(Price!$B$11:$B$182=$B22)*(Price!$D$11:$D$182="gb"),0),MATCH(1,(Price!$L$3:$AM$3=O$3)*(Price!$L$4:$AM$4=O$4),0))} -> 0 | S22: {=INDEX(Price!$L$11:$AM$182,MATCH(1,(Price!$A$11:$A$182=$A22)*(Price!$B$11:$B$182=$B22)*(Price!$D$11:$D$182="gb"),0),MATCH(1,(Price!$L$3:$AM$3=S$3)*(Price!$L$4:$AM$4=S$4),0))} -> 1250 | T22: {=INDEX(Price!$L$11:$AM$182,MATCH(1,(Price!$A$11:$A$182=$A22)*(Price!$B$11:$B$182=$B22)*(Price!$D$11:$D$182="gb"),0),MATCH(1,(Price!$L$3:$AM$3=T$3)*(Price!$L$4:$AM$4=T$4),0))} -> 1250 | U22: {=INDEX(Price!$L$11:$AM$182,MATCH(1,(Price!$A$11:$A$182=$A22)*(Price!$B$11:$B$182=$B22)*(Price!$D$11:$D$182="gb"),0),MATCH(1,(Price!$L$3:$AM$3=U$3)*(Price!$L$4:$AM$4=U$4),0))} -> 1250 | V22: {=INDEX(Price!$L$11:$AM$182,MATCH(1,(Price!$A$11:$A$182=$A22)*(Price!$B$11:$B$182=$B22)*(Price!$D$11:$D$182="gb"),0),MATCH(1,(Price!$L$3:$AM$3=V$3)*(Price!$L$4:$AM$4=V$4),0))} -> 1250 | W22: {=INDEX(Price!$L$11:$AM$182,MATCH(1,(Price!$A$11:$A$182=$A22)*(Price!$B$11:$B$182=$B22)*(Price!$D$11:$D$182="gb"),0),MATCH(1,(Price!$L$3:$AM$3=W$3)*(Price!$L$4:$AM$4=W$4),0))} -> 1250 | X22: {=INDEX(Price!$L$11:$AM$182,MATCH(1,(Price!$A$11:$A$182=$A22)*(Price!$B$11:$B$182=$B22)*(Price!$D$11:$D$182="gb"),0),MATCH(1,(Price!$L$3:$AM$3=X$3)*(Price!$L$4:$AM$4=X$4),0))} -> 1250 | Y22: {=INDEX(Price!$L$11:$AM$182,MATCH(1,(Price!$A$11:$A$182=$A22)*(Price!$B$11:$B$182=$B22)*(Price!$D$11:$D$182="gb"),0),MATCH(1,(Price!$L$3:$AM$3=Y$3)*(Price!$L$4:$AM$4=Y$4),0))} -> 1250 | Z22: {=INDEX(Price!$L$11:$AM$182,MATCH(1,(Price!$A$11:$A$182=$A22)*(Price!$B$11:$B$182=$B22)*(Price!$D$11:$D$182="gb"),0),MATCH(1,(Price!$L$3:$AM$3=Z$3)*(Price!$L$4:$AM$4=Z$4),0))} -> 1250 | ... AD22: {=INDEX(Price!$L$11:$AM$182,MATCH(1,(Price!$A$11:$A$182=$A22)*(Price!$B$11:$B$182=$B22)*(Price!$D$11:$D$182="gb"),0),MATCH(1,(Price!$L$3:$AM$3=AD$3)*(Price!$L$4:$AM$4=AD$4),0))} -> 1250
A23: 200332 | B23: 110000355 | C23: GB | D23: 2.2 | F23: Giá bán quy đổi EXW | G23: {=INDEX(Price!$L$11:$AM$182,MATCH(1,(Price!$A$11:$A$182=$A23)*(Price!$B$11:$B$182=$B23)*(Price!$D$11:$D$182="exw"),0),MATCH(1,(Price!$L$3:$AM$3=G$3)*(Price!$L$4:$AM$4=G$4),0))} -> 0 | H23: {=INDEX(Price!$L$11:$AM$182,MATCH(1,(Price!$A$11:$A$182=$A23)*(Price!$B$11:$B$182=$B23)*(Price!$D$11:$D$182="exw"),0),MATCH(1,(Price!$L$3:$AM$3=H$3)*(Price!$L$4:$AM$4=H$4),0))} -> 0 | I23: {=INDEX(Price!$L$11:$AM$182,MATCH(1,(Price!$A$11:$A$182=$A23)*(Price!$B$11:$B$182=$B23)*(Price!$D$11:$D$182="exw"),0),MATCH(1,(Price!$L$3:$AM$3=I$3)*(Price!$L$4:$AM$4=I$4),0))} -> 0 | J23: {=INDEX(Price!$L$11:$AM$182,MATCH(1,(Price!$A$11:$A$182=$A23)*(Price!$B$11:$B$182=$B23)*(Price!$D$11:$D$182="exw"),0),MATCH(1,(Price!$L$3:$AM$3=J$3)*(Price!$L$4:$AM$4=J$4),0))} -> 0 | K23: {=INDEX(Price!$L$11:$AM$182,MATCH(1,(Price!$A$11:$A$182=$A23)*(Price!$B$11:$B$182=$B23)*(Price!$D$11:$D$182="exw"),0),MATCH(1,(Price!$L$3:$AM$3=K$3)*(Price!$L$4:$AM$4=K$4),0))} -> 0 | L23: {=INDEX(Price!$L$11:$AM$182,MATCH(1,(Price!$A$11:$A$182=$A23)*(Price!$B$11:$B$182=$B23)*(Price!$D$11:$D$182="exw"),0),MATCH(1,(Price!$L$3:$AM$3=L$3)*(Price!$L$4:$AM$4=L$4),0))} -> 0 | M23: {=INDEX(Price!$L$11:$AM$182,MATCH(1,(Price!$A$11:$A$182=$A23)*(Price!$B$11:$B$182=$B23)*(Price!$D$11:$D$182="exw"),0),MATCH(1,(Price!$L$3:$AM$3=M$3)*(Price!$L$4:$AM$4=M$4),0))} -> 0 | N23: {=INDEX(Price!$L$11:$AM$182,MATCH(1,(Price!$A$11:$A$182=$A23)*(Price!$B$11:$B$182=$B23)*(Price!$D$11:$D$182="exw"),0),MATCH(1,(Price!$L$3:$AM$3=N$3)*(Price!$L$4:$AM$4=N$4),0))} -> 0 | O23: {=INDEX(Price!$L$11:$AM$182,MATCH(1,(Price!$A$11:$A$182=$A23)*(Price!$B$11:$B$182=$B23)*(Price!$D$11:$D$182="exw"),0),MATCH(1,(Price!$L$3:$AM$3=O$3)*(Price!$L$4:$AM$4=O$4),0))} -> 0 | S23: {=INDEX(Price!$L$11:$AM$182,MATCH(1,(Price!$A$11:$A$182=$A23)*(Price!$B$11:$B$182=$B23)*(Price!$D$11:$D$182="exw"),0),MATCH(1,(Price!$L$3:$AM$3=S$3)*(Price!$L$4:$AM$4=S$4),0))} -> 1230 | T23: {=INDEX(Price!$L$11:$AM$182,MATCH(1,(Price!$A$11:$A$182=$A23)*(Price!$B$11:$B$182=$B23)*(Price!$D$11:$D$182="exw"),0),MATCH(1,(Price!$L$3:$AM$3=T$3)*(Price!$L$4:$AM$4=T$4),0))} -> 1230 | U23: {=INDEX(Price!$L$11:$AM$182,MATCH(1,(Price!$A$11:$A$182=$A23)*(Price!$B$11:$B$182=$B23)*(Price!$D$11:$D$182="exw"),0),MATCH(1,(Price!$L$3:$AM$3=U$3)*(Price!$L$4:$AM$4=U$4),0))} -> 1230 | V23: {=INDEX(Price!$L$11:$AM$182,MATCH(1,(Price!$A$11:$A$182=$A23)*(Price!$B$11:$B$182=$B23)*(Price!$D$11:$D$182="exw"),0),MATCH(1,(Price!$L$3:$AM$3=V$3)*(Price!$L$4:$AM$4=V$4),0))} -> 1228 | W23: {=INDEX(Price!$L$11:$AM$182,MATCH(1,(Price!$A$11:$A$182=$A23)*(Price!$B$11:$B$182=$B23)*(Price!$D$11:$D$182="exw"),0),MATCH(1,(Price!$L$3:$AM$3=W$3)*(Price!$L$4:$AM$4=W$4),0))} -> 1228 | X23: {=INDEX(Price!$L$11:$AM$182,MATCH(1,(Price!$A$11:$A$182=$A23)*(Price!$B$11:$B$182=$B23)*(Price!$D$11:$D$182="exw"),0),MATCH(1,(Price!$L$3:$AM$3=X$3)*(Price!$L$4:$AM$4=X$4),0))} -> 1228 | Y23: {=INDEX(Price!$L$11:$AM$182,MATCH(1,(Price!$A$11:$A$182=$A23)*(Price!$B$11:$B$182=$B23)*(Price!$D$11:$D$182="exw"),0),MATCH(1,(Price!$L$3:$AM$3=Y$3)*(Price!$L$4:$AM$4=Y$4),0))} -> 1228 | Z23: {=INDEX(Price!$L$11:$AM$182,MATCH(1,(Price!$A$11:$A$182=$A23)*(Price!$B$11:$B$182=$B23)*(Price!$D$11:$D$182="exw"),0),MATCH(1,(Price!$L$3:$AM$3=Z$3)*(Price!$L$4:$AM$4=Z$4),0))} -> 1228 | ... AD23: {=INDEX(Price!$L$11:$AM$182,MATCH(1,(Price!$A$11:$A$182=$A23)*(Price!$B$11:$B$182=$B23)*(Price!$D$11:$D$182="exw"),0),MATCH(1,(Price!$L$3:$AM$3=AD$3)*(Price!$L$4:$AM$4=AD$4),0))} -> 1228
A24: 200332 | B24: 110000355 | C24: PETVirgin | D24: 2.3 | F24: Giá chính phẩm | S24: {=SUMPRODUCT(General_Data*(Code_General_Data=$C24)*(Year=S$3)*(Month=S$4))} -> 828 | T24: {=SUMPRODUCT(General_Data*(Code_General_Data=$C24)*(Year=T$3)*(Month=T$4))} -> 840 | U24: {=SUMPRODUCT(General_Data*(Code_General_Data=$C24)*(Year=U$3)*(Month=U$4))} -> 823 | V24: {=SUMPRODUCT(General_Data*(Code_General_Data=$C24)*(Year=V$3)*(Month=V$4))} -> 765 | W24: {=SUMPRODUCT(General_Data*(Code_General_Data=$C24)*(Year=W$3)*(Month=W$4))} -> 782 | X24: {=SUMPRODUCT(General_Data*(Code_General_Data=$C24)*(Year=X$3)*(Month=X$4))} -> 807.5 | Y24: {=SUMPRODUCT(General_Data*(Code_General_Data=$C24)*(Year=Y$3)*(Month=Y$4))} -> 802 | Z24: {=SUMPRODUCT(General_Data*(Code_General_Data=$C24)*(Year=Z$3)*(Month=Z$4))} -> 795 | ... AD24: {=SUMPRODUCT(General_Data*(Code_General_Data=$C24)*(Year=AD$3)*(Month=AD$4))} -> 770
A25: 200332 | B25: 110000355 | D25: 2.4 | F25: Chênh lệch giữa R sv Virgin | S25: =IF(S22*S23*S24<>0,S23-S24,0) -> 402 | T25: =IF(T22*T23*T24<>0,T23-T24,0) -> 390 | U25: =IF(U22*U23*U24<>0,U23-U24,0) -> 407 | V25: =IF(V22*V23*V24<>0,V23-V24,0) -> 463 | W25: =IF(W22*W23*W24<>0,W23-W24,0) -> 446 | X25: =IF(X22*X23*X24<>0,X23-X24,0) -> 420.5 | Y25: =IF(Y22*Y23*Y24<>0,Y23-Y24,0) -> 426 | Z25: =IF(Z22*Z23*Z24<>0,Z23-Z24,0) -> 433 | ... AD25: =IF(AD22*AD23*AD24<>0,AD23-AD24,0) -> 458
A26: 200332 | B26: 110000355 | D26: 2.5 | F26: % +/- | S26: =IFERROR(S25/S24,0) -> 0.48550725 | T26: =IFERROR(T25/T24,0) -> 0.46428571 | U26: =IFERROR(U25/U24,0) -> 0.4945322 | V26: =IFERROR(V25/V24,0) -> 0.60522876 | W26: =IFERROR(W25/W24,0) -> 0.57033248 | X26: =IFERROR(X25/X24,0) -> 0.52074303 | Y26: =IFERROR(Y25/Y24,0) -> 0.53117207 | Z26: =IFERROR(Z25/Z24,0) -> 0.54465409 | ... AD26: =IFERROR(AD25/AD24,0) -> 0.59480519
A27: 200332 | B27: 110000355 | C27: 110000355 | D27: 2.6 | F27: Giá duyệt tháng | S27: {=SUMPRODUCT(General_Data*(Code_General_Data=$C27)*(Year=S$3)*(Month=S$4))} -> 1260 | T27: {=SUMPRODUCT(General_Data*(Code_General_Data=$C27)*(Year=T$3)*(Month=T$4))} -> 1260 | U27: {=SUMPRODUCT(General_Data*(Code_General_Data=$C27)*(Year=U$3)*(Month=U$4))} -> 1260 | V27: {=SUMPRODUCT(General_Data*(Code_General_Data=$C27)*(Year=V$3)*(Month=V$4))} -> 1280 | W27: {=SUMPRODUCT(General_Data*(Code_General_Data=$C27)*(Year=W$3)*(Month=W$4))} -> 1280 | X27: {=SUMPRODUCT(General_Data*(Code_General_Data=$C27)*(Year=X$3)*(Month=X$4))} -> 1280 | Y27: {=SUMPRODUCT(General_Data*(Code_General_Data=$C27)*(Year=Y$3)*(Month=Y$4))} -> 1280 | Z27: {=SUMPRODUCT(General_Data*(Code_General_Data=$C27)*(Year=Z$3)*(Month=Z$4))} -> 1250 | ... AD27: {=SUMPRODUCT(General_Data*(Code_General_Data=$C27)*(Year=AD$3)*(Month=AD$4))} -> 1230
A29: 105263 | D29: 3 | E29: UNILEVER VIET NAM
A30: 105263 | B30: 110000354 | F30: WSS01G
A31: 105263 | B31: 110000354 | D31: 3.1 | F31: Giá bán - DDP | G31: {=INDEX(Price!$L$11:$AM$182,MATCH(1,(Price!$A$11:$A$182=$A31)*(Price!$B$11:$B$182=$B31)*(Price!$D$11:$D$182="gb"),0),MATCH(1,(Price!$L$3:$AM$3=G$3)*(Price!$L$4:$AM$4=G$4),0))} -> 1320 | H31: {=INDEX(Price!$L$11:$AM$182,MATCH(1,(Price!$A$11:$A$182=$A31)*(Price!$B$11:$B$182=$B31)*(Price!$D$11:$D$182="gb"),0),MATCH(1,(Price!$L$3:$AM$3=H$3)*(Price!$L$4:$AM$4=H$4),0))} -> 1320 | I31: {=INDEX(Price!$L$11:$AM$182,MATCH(1,(Price!$A$11:$A$182=$A31)*(Price!$B$11:$B$182=$B31)*(Price!$D$11:$D$182="gb"),0),MATCH(1,(Price!$L$3:$AM$3=I$3)*(Price!$L$4:$AM$4=I$4),0))} -> 1320 | J31: {=INDEX(Price!$L$11:$AM$182,MATCH(1,(Price!$A$11:$A$182=$A31)*(Price!$B$11:$B$182=$B31)*(Price!$D$11:$D$182="gb"),0),MATCH(1,(Price!$L$3:$AM$3=J$3)*(Price!$L$4:$AM$4=J$4),0))} -> 1320 | K31: {=INDEX(Price!$L$11:$AM$182,MATCH(1,(Price!$A$11:$A$182=$A31)*(Price!$B$11:$B$182=$B31)*(Price!$D$11:$D$182="gb"),0),MATCH(1,(Price!$L$3:$AM$3=K$3)*(Price!$L$4:$AM$4=K$4),0))} -> 1320 | L31: {=INDEX(Price!$L$11:$AM$182,MATCH(1,(Price!$A$11:$A$182=$A31)*(Price!$B$11:$B$182=$B31)*(Price!$D$11:$D$182="gb"),0),MATCH(1,(Price!$L$3:$AM$3=L$3)*(Price!$L$4:$AM$4=L$4),0))} -> 1320 | M31: {=INDEX(Price!$L$11:$AM$182,MATCH(1,(Price!$A$11:$A$182=$A31)*(Price!$B$11:$B$182=$B31)*(Price!$D$11:$D$182="gb"),0),MATCH(1,(Price!$L$3:$AM$3=M$3)*(Price!$L$4:$AM$4=M$4),0))} -> 1320 | N31: {=INDEX(Price!$L$11:$AM$182,MATCH(1,(Price!$A$11:$A$182=$A31)*(Price!$B$11:$B$182=$B31)*(Price!$D$11:$D$182="gb"),0),MATCH(1,(Price!$L$3:$AM$3=N$3)*(Price!$L$4:$AM$4=N$4),0))} -> 1320 | ... AD31: {=INDEX(Price!$L$11:$AM$182,MATCH(1,(Price!$A$11:$A$182=$A31)*(Price!$B$11:$B$182=$B31)*(Price!$D$11:$D$182="gb"),0),MATCH(1,(Price!$L$3:$AM$3=AD$3)*(Price!$L$4:$AM$4=AD$4),0))} -> 1280
A32: 105263 | B32: 110000354 | C32: GB | D32: 3.2 | F32: Giá bán quy đổi EXW | G32: {=INDEX(Price!$L$11:$AM$182,MATCH(1,(Price!$A$11:$A$182=$A32)*(Price!$B$11:$B$182=$B32)*(Price!$D$11:$D$182="exw"),0),MATCH(1,(Price!$L$3:$AM$3=G$3)*(Price!$L$4:$AM$4=G$4),0))} -> 1307.7959 | H32: {=INDEX(Price!$L$11:$AM$182,MATCH(1,(Price!$A$11:$A$182=$A32)*(Price!$B$11:$B$182=$B32)*(Price!$D$11:$D$182="exw"),0),MATCH(1,(Price!$L$3:$AM$3=H$3)*(Price!$L$4:$AM$4=H$4),0))} -> 1307.7959 | I32: {=INDEX(Price!$L$11:$AM$182,MATCH(1,(Price!$A$11:$A$182=$A32)*(Price!$B$11:$B$182=$B32)*(Price!$D$11:$D$182="exw"),0),MATCH(1,(Price!$L$3:$AM$3=I$3)*(Price!$L$4:$AM$4=I$4),0))} -> 1307.7959 | J32: {=INDEX(Price!$L$11:$AM$182,MATCH(1,(Price!$A$11:$A$182=$A32)*(Price!$B$11:$B$182=$B32)*(Price!$D$11:$D$182="exw"),0),MATCH(1,(Price!$L$3:$AM$3=J$3)*(Price!$L$4:$AM$4=J$4),0))} -> 1307.7959 | K32: {=INDEX(Price!$L$11:$AM$182,MATCH(1,(Price!$A$11:$A$182=$A32)*(Price!$B$11:$B$182=$B32)*(Price!$D$11:$D$182="exw"),0),MATCH(1,(Price!$L$3:$AM$3=K$3)*(Price!$L$4:$AM$4=K$4),0))} -> 1307.7959 | L32: {=INDEX(Price!$L$11:$AM$182,MATCH(1,(Price!$A$11:$A$182=$A32)*(Price!$B$11:$B$182=$B32)*(Price!$D$11:$D$182="exw"),0),MATCH(1,(Price!$L$3:$AM$3=L$3)*(Price!$L$4:$AM$4=L$4),0))} -> 1307.7959 | M32: {=INDEX(Price!$L$11:$AM$182,MATCH(1,(Price!$A$11:$A$182=$A32)*(Price!$B$11:$B$182=$B32)*(Price!$D$11:$D$182="exw"),0),MATCH(1,(Price!$L$3:$AM$3=M$3)*(Price!$L$4:$AM$4=M$4),0))} -> 1308.04 | N32: {=INDEX(Price!$L$11:$AM$182,MATCH(1,(Price!$A$11:$A$182=$A32)*(Price!$B$11:$B$182=$B32)*(Price!$D$11:$D$182="exw"),0),MATCH(1,(Price!$L$3:$AM$3=N$3)*(Price!$L$4:$AM$4=N$4),0))} -> 1308.04 | ... AD32: {=INDEX(Price!$L$11:$AM$182,MATCH(1,(Price!$A$11:$A$182=$A32)*(Price!$B$11:$B$182=$B32)*(Price!$D$11:$D$182="exw"),0),MATCH(1,(Price!$L$3:$AM$3=AD$3)*(Price!$L$4:$AM$4=AD$4),0))} -> 1268.04
A33: 105263 | B33: 110000354 | C33: PETVirgin | D33: 3.3 | F33: Giá chính phẩm | G33: {=SUMPRODUCT(General_Data*(Code_General_Data=$C33)*(Year=G$3)*(Month=G$4))} -> 930 | H33: {=SUMPRODUCT(General_Data*(Code_General_Data=$C33)*(Year=H$3)*(Month=H$4))} -> 943.33333 | I33: {=SUMPRODUCT(General_Data*(Code_General_Data=$C33)*(Year=I$3)*(Month=I$4))} -> 940 | J33: {=SUMPRODUCT(General_Data*(Code_General_Data=$C33)*(Year=J$3)*(Month=J$4))} -> 940 | K33: {=SUMPRODUCT(General_Data*(Code_General_Data=$C33)*(Year=K$3)*(Month=K$4))} -> 942 | L33: {=SUMPRODUCT(General_Data*(Code_General_Data=$C33)*(Year=L$3)*(Month=L$4))} -> 950 | M33: {=SUMPRODUCT(General_Data*(Code_General_Data=$C33)*(Year=M$3)*(Month=M$4))} -> 947.5 | N33: {=SUMPRODUCT(General_Data*(Code_General_Data=$C33)*(Year=N$3)*(Month=N$4))} -> 930 | ... AD33: {=SUMPRODUCT(General_Data*(Code_General_Data=$C33)*(Year=AD$3)*(Month=AD$4))} -> 770
A34: 105263 | B34: 110000354 | D34: 3.4 | F34: Chênh lệch giữa R sv Virgin | G34: =IF(G31*G32*G33<>0,G32-G33,0) -> 377.79592 | H34: =IF(H31*H32*H33<>0,H32-H33,0) -> 364.46259 | I34: =IF(I31*I32*I33<>0,I32-I33,0) -> 367.79592 | J34: =IF(J31*J32*J33<>0,J32-J33,0) -> 367.79592 | K34: =IF(K31*K32*K33<>0,K32-K33,0) -> 365.79592 | L34: =IF(L31*L32*L33<>0,L32-L33,0) -> 357.79592 | M34: =IF(M31*M32*M33<>0,M32-M33,0) -> 360.54 | N34: =IF(N31*N32*N33<>0,N32-N33,0) -> 378.04 | ... AD34: =IF(AD31*AD32*AD33<>0,AD32-AD33,0) -> 498.04
A35: 105263 | B35: 110000354 | D35: 3.5 | F35: % +/- | G35: =IFERROR(G34/G33,0) -> 0.40623217 | H35: =IFERROR(H34/H33,0) -> 0.3863561 | I35: =IFERROR(I34/I33,0) -> 0.39127225 | J35: =IFERROR(J34/J33,0) -> 0.39127225 | K35: =IFERROR(K34/K33,0) -> 0.38831838 | L35: =IFERROR(L34/L33,0) -> 0.37662728 | M35: =IFERROR(M34/M33,0) -> 0.38051715 | N35: =IFERROR(N34/N33,0) -> 0.40649462 | ... AD35: =IFERROR(AD34/AD33,0) -> 0.64680519
A36: 105263 | B36: 110000354 | C36: 110000354 | D36: 3.6 | F36: Giá duyệt tháng | G36: {=SUMPRODUCT(General_Data*(Code_General_Data=$C36)*(Year=G$3)*(Month=G$4))} -> 1250 | H36: {=SUMPRODUCT(General_Data*(Code_General_Data=$C36)*(Year=H$3)*(Month=H$4))} -> 1250 | I36: {=SUMPRODUCT(General_Data*(Code_General_Data=$C36)*(Year=I$3)*(Month=I$4))} -> 1250 | J36: {=SUMPRODUCT(General_Data*(Code_General_Data=$C36)*(Year=J$3)*(Month=J$4))} -> 1250 | K36: {=SUMPRODUCT(General_Data*(Code_General_Data=$C36)*(Year=K$3)*(Month=K$4))} -> 1300 | L36: {=SUMPRODUCT(General_Data*(Code_General_Data=$C36)*(Year=L$3)*(Month=L$4))} -> 1300 | M36: {=SUMPRODUCT(General_Data*(Code_General_Data=$C36)*(Year=M$3)*(Month=M$4))} -> 1300 | N36: {=SUMPRODUCT(General_Data*(Code_General_Data=$C36)*(Year=N$3)*(Month=N$4))} -> 1300 | ... AD36: {=SUMPRODUCT(General_Data*(Code_General_Data=$C36)*(Year=AD$3)*(Month=AD$4))} -> 1200
A37: 105263
A38: 105263 | B38: 110000339 | F38: MBF01
A39: 105263 | B39: 110000339 | D39: 3.7 | F39: Giá bán - DDP | G39: {=INDEX(Price!$L$11:$AM$182,MATCH(1,(Price!$A$11:$A$182=$A39)*(Price!$B$11:$B$182=$B39)*(Price!$D$11:$D$182="gb"),0),MATCH(1,(Price!$L$3:$AM$3=G$3)*(Price!$L$4:$AM$4=G$4),0))} -> 1500 | H39: {=INDEX(Price!$L$11:$AM$182,MATCH(1,(Price!$A$11:$A$182=$A39)*(Price!$B$11:$B$182=$B39)*(Price!$D$11:$D$182="gb"),0),MATCH(1,(Price!$L$3:$AM$3=H$3)*(Price!$L$4:$AM$4=H$4),0))} -> 1500 | I39: {=INDEX(Price!$L$11:$AM$182,MATCH(1,(Price!$A$11:$A$182=$A39)*(Price!$B$11:$B$182=$B39)*(Price!$D$11:$D$182="gb"),0),MATCH(1,(Price!$L$3:$AM$3=I$3)*(Price!$L$4:$AM$4=I$4),0))} -> 1500 | J39: {=INDEX(Price!$L$11:$AM$182,MATCH(1,(Price!$A$11:$A$182=$A39)*(Price!$B$11:$B$182=$B39)*(Price!$D$11:$D$182="gb"),0),MATCH(1,(Price!$L$3:$AM$3=J$3)*(Price!$L$4:$AM$4=J$4),0))} -> 1430 | K39: {=INDEX(Price!$L$11:$AM$182,MATCH(1,(Price!$A$11:$A$182=$A39)*(Price!$B$11:$B$182=$B39)*(Price!$D$11:$D$182="gb"),0),MATCH(1,(Price!$L$3:$AM$3=K$3)*(Price!$L$4:$AM$4=K$4),0))} -> 1430 | L39: {=INDEX(Price!$L$11:$AM$182,MATCH(1,(Price!$A$11:$A$182=$A39)*(Price!$B$11:$B$182=$B39)*(Price!$D$11:$D$182="gb"),0),MATCH(1,(Price!$L$3:$AM$3=L$3)*(Price!$L$4:$AM$4=L$4),0))} -> 1430 | M39: {=INDEX(Price!$L$11:$AM$182,MATCH(1,(Price!$A$11:$A$182=$A39)*(Price!$B$11:$B$182=$B39)*(Price!$D$11:$D$182="gb"),0),MATCH(1,(Price!$L$3:$AM$3=M$3)*(Price!$L$4:$AM$4=M$4),0))} -> 1430 | N39: {=INDEX(Price!$L$11:$AM$182,MATCH(1,(Price!$A$11:$A$182=$A39)*(Price!$B$11:$B$182=$B39)*(Price!$D$11:$D$182="gb"),0),MATCH(1,(Price!$L$3:$AM$3=N$3)*(Price!$L$4:$AM$4=N$4),0))} -> 1430 | ... AD39: {=INDEX(Price!$L$11:$AM$182,MATCH(1,(Price!$A$11:$A$182=$A39)*(Price!$B$11:$B$182=$B39)*(Price!$D$11:$D$182="gb"),0),MATCH(1,(Price!$L$3:$AM$3=AD$3)*(Price!$L$4:$AM$4=AD$4),0))} -> 1380
A40: 105263 | B40: 110000339 | C40: GB | D40: 3.8 | F40: Giá bán quy đổi EXW | G40: {=INDEX(Price!$L$11:$AM$182,MATCH(1,(Price!$A$11:$A$182=$A40)*(Price!$B$11:$B$182=$B40)*(Price!$D$11:$D$182="exw"),0),MATCH(1,(Price!$L$3:$AM$3=G$3)*(Price!$L$4:$AM$4=G$4),0))} -> 1487.7959 | H40: {=INDEX(Price!$L$11:$AM$182,MATCH(1,(Price!$A$11:$A$182=$A40)*(Price!$B$11:$B$182=$B40)*(Price!$D$11:$D$182="exw"),0),MATCH(1,(Price!$L$3:$AM$3=H$3)*(Price!$L$4:$AM$4=H$4),0))} -> 1487.7959 | I40: {=INDEX(Price!$L$11:$AM$182,MATCH(1,(Price!$A$11:$A$182=$A40)*(Price!$B$11:$B$182=$B40)*(Price!$D$11:$D$182="exw"),0),MATCH(1,(Price!$L$3:$AM$3=I$3)*(Price!$L$4:$AM$4=I$4),0))} -> 1487.7959 | J40: {=INDEX(Price!$L$11:$AM$182,MATCH(1,(Price!$A$11:$A$182=$A40)*(Price!$B$11:$B$182=$B40)*(Price!$D$11:$D$182="exw"),0),MATCH(1,(Price!$L$3:$AM$3=J$3)*(Price!$L$4:$AM$4=J$4),0))} -> 1417.7959 | K40: {=INDEX(Price!$L$11:$AM$182,MATCH(1,(Price!$A$11:$A$182=$A40)*(Price!$B$11:$B$182=$B40)*(Price!$D$11:$D$182="exw"),0),MATCH(1,(Price!$L$3:$AM$3=K$3)*(Price!$L$4:$AM$4=K$4),0))} -> 1417.7959 | L40: {=INDEX(Price!$L$11:$AM$182,MATCH(1,(Price!$A$11:$A$182=$A40)*(Price!$B$11:$B$182=$B40)*(Price!$D$11:$D$182="exw"),0),MATCH(1,(Price!$L$3:$AM$3=L$3)*(Price!$L$4:$AM$4=L$4),0))} -> 1417.7959 | M40: {=INDEX(Price!$L$11:$AM$182,MATCH(1,(Price!$A$11:$A$182=$A40)*(Price!$B$11:$B$182=$B40)*(Price!$D$11:$D$182="exw"),0),MATCH(1,(Price!$L$3:$AM$3=M$3)*(Price!$L$4:$AM$4=M$4),0))} -> 1418.04 | N40: {=INDEX(Price!$L$11:$AM$182,MATCH(1,(Price!$A$11:$A$182=$A40)*(Price!$B$11:$B$182=$B40)*(Price!$D$11:$D$182="exw"),0),MATCH(1,(Price!$L$3:$AM$3=N$3)*(Price!$L$4:$AM$4=N$4),0))} -> 1418.04 | ... AD40: {=INDEX(Price!$L$11:$AM$182,MATCH(1,(Price!$A$11:$A$182=$A40)*(Price!$B$11:$B$182=$B40)*(Price!$D$11:$D$182="exw"),0),MATCH(1,(Price!$L$3:$AM$3=AD$3)*(Price!$L$4:$AM$4=AD$4),0))} -> 1368.04
A41: 105263 | B41: 110000339 | C41: HDPEVirgin | D41: 3.9 | F41: Giá chính phẩm | G41: {=SUMPRODUCT(General_Data*(Code_General_Data=$C41)*(Year=G$3)*(Month=G$4))} -> 940 | H41: {=SUMPRODUCT(General_Data*(Code_General_Data=$C41)*(Year=H$3)*(Month=H$4))} -> 993.33333 | I41: {=SUMPRODUCT(General_Data*(Code_General_Data=$C41)*(Year=I$3)*(Month=I$4))} -> 985 | J41: {=SUMPRODUCT(General_Data*(Code_General_Data=$C41)*(Year=J$3)*(Month=J$4))} -> 962.5 | K41: {=SUMPRODUCT(General_Data*(Code_General_Data=$C41)*(Year=K$3)*(Month=K$4))} -> 982 | L41: {=SUMPRODUCT(General_Data*(Code_General_Data=$C41)*(Year=L$3)*(Month=L$4))} -> 1000 | M41: {=SUMPRODUCT(General_Data*(Code_General_Data=$C41)*(Year=M$3)*(Month=M$4))} -> 1000 | N41: {=SUMPRODUCT(General_Data*(Code_General_Data=$C41)*(Year=N$3)*(Month=N$4))} -> 984 | ... AD41: {=SUMPRODUCT(General_Data*(Code_General_Data=$C41)*(Year=AD$3)*(Month=AD$4))} -> 805
A42: 105263 | B42: 110000339 | D42: 3.1 | F42: Chênh lệch giữa R sv Virgin | G42: =IF(G39*G40*G41<>0,G40-G41,0) -> 547.79592 | H42: =IF(H39*H40*H41<>0,H40-H41,0) -> 494.46259 | I42: =IF(I39*I40*I41<>0,I40-I41,0) -> 502.79592 | J42: =IF(J39*J40*J41<>0,J40-J41,0) -> 455.29592 | K42: =IF(K39*K40*K41<>0,K40-K41,0) -> 435.79592 | L42: =IF(L39*L40*L41<>0,L40-L41,0) -> 417.79592 | M42: =IF(M39*M40*M41<>0,M40-M41,0) -> 418.04 | N42: =IF(N39*N40*N41<>0,N40-N41,0) -> 434.04 | ... AD42: =IF(AD39*AD40*AD41<>0,AD40-AD41,0) -> 563.04
A43: 105263 | B43: 110000339 | D43: 3.11 | F43: % +/- | G43: =IFERROR(G42/G41,0) -> 0.58276162 | H43: =IFERROR(H42/H41,0) -> 0.49778113 | I43: =IFERROR(I42/I41,0) -> 0.51045271 | J43: =IFERROR(J42/J41,0) -> 0.47303472 | K43: =IFERROR(K42/K41,0) -> 0.44378403 | L43: =IFERROR(L42/L41,0) -> 0.41779592 | M43: =IFERROR(M42/M41,0) -> 0.41804 | N43: =IFERROR(N42/N41,0) -> 0.44109756 | ... AD43: =IFERROR(AD42/AD41,0) -> 0.69942857
A44: 105263 | B44: 110000339 | C44: 110000339 | D44: 3.12 | F44: Giá duyệt tháng | G44: {=SUMPRODUCT(General_Data*(Code_General_Data=$C44)*(Year=G$3)*(Month=G$4))} -> 1350 | H44: {=SUMPRODUCT(General_Data*(Code_General_Data=$C44)*(Year=H$3)*(Month=H$4))} -> 1350 | I44: {=SUMPRODUCT(General_Data*(Code_General_Data=$C44)*(Year=I$3)*(Month=I$4))} -> 1350 | J44: {=SUMPRODUCT(General_Data*(Code_General_Data=$C44)*(Year=J$3)*(Month=J$4))} -> 1350 | K44: {=SUMPRODUCT(General_Data*(Code_General_Data=$C44)*(Year=K$3)*(Month=K$4))} -> 1350 | L44: {=SUMPRODUCT(General_Data*(Code_General_Data=$C44)*(Year=L$3)*(Month=L$4))} -> 1350 | M44: {=SUMPRODUCT(General_Data*(Code_General_Data=$C44)*(Year=M$3)*(Month=M$4))} -> 1350 | N44: {=SUMPRODUCT(General_Data*(Code_General_Data=$C44)*(Year=N$3)*(Month=N$4))} -> 1350 | ... AD44: {=SUMPRODUCT(General_Data*(Code_General_Data=$C44)*(Year=AD$3)*(Month=AD$4))} -> 1200
A45: 105263
...

Sheet Price
L1: =DATE(L3,L4,1) -> 45200 | M1: =DATE(M3,M4,1) -> 45231 | N1: =DATE(N3,N4,1) -> 45261 | O1: =DATE(O3,O4,1) -> 45292 | P1: =DATE(P3,P4,1) -> 45323 | Q1: =DATE(Q3,Q4,1) -> 45352 | R1: =DATE(R3,R4,1) -> 45383 | S1: =DATE(S3,S4,1) -> 45413 | ... AL1: =DATE(AL3,AL4,1) -> 45992
L2: =EOMONTH(L1,0) -> 45230 | M2: =EOMONTH(M1,0) -> 45260 | N2: =EOMONTH(N1,0) -> 45291 | O2: =EOMONTH(O1,0) -> 45322 | P2: =EOMONTH(P1,0) -> 45351 | Q2: =EOMONTH(Q1,0) -> 45382 | R2: =EOMONTH(R1,0) -> 45412 | S2: =EOMONTH(S1,0) -> 45443 | ... AL2: =EOMONTH(AL1,0) -> 46022
L3: 2023 | M3: 2023 | N3: 2023 | O3: 2024 | P3: 2024 | Q3: 2024 | R3: 2024 | S3: 2024 | T3: 2024 | U3: 2024 | V3: 2024 | W3: 2024 | X3: 2024 | Y3: 2024 | Z3: 2024 | AA3: 2025 | AB3: 2025 | AC3: 2025 | AD3: 2025 | AE3: 2025 | AF3: 2025 | AG3: 2025 | AH3: 2025 | AI3: 2025 | AJ3: 2025 | AK3: 2025 | AL3: 2025
L4: 10 | M4: 11 | N4: 12 | O4: 1 | P4: 2 | Q4: 3 | R4: 4 | S4: 5 | T4: 6 | U4: 7 | V4: 8 | W4: 9 | X4: 10 | Y4: 11 | Z4: 12 | AA4: 1 | AB4: 2 | AC4: 3 | AD4: 4 | AE4: 5 | AF4: 6 | AG4: 7 | AH4: 8 | AI4: 9 | AJ4: 10 | AK4: 11 | AL4: 12
O6: II. CHI TIẾT GIÁ CÔNG THỨC THEO KHÁCH HÀNG | AA6: II. CHI TIẾT GIÁ CÔNG THỨC THEO KHÁCH HÀNG | AM6: II. CHI TIẾT GIÁ CÔNG THỨC THEO KHÁCH HÀNG
F8: STT | G8: KHÁCH HÀNG/NỘI DUNG | L8: 2023 | O8: 2024 | AA8: 2025 | AM8: 2026
A9: Khách | B9: SKU | C9: Code | D9: Link | L9: 10 | M9: 11 | N9: 12 | O9: 1 | P9: 2 | Q9: 3 | R9: 4 | S9: 5 | T9: 6 | U9: 7 | V9: 8 | W9: 9 | X9: 10 | Y9: 11 | Z9: 12 | AA9: 1 | AB9: 2 | AC9: 3 | AD9: 4 | AE9: 5 | AF9: 6 | AG9: 7 | AH9: 8 | AI9: 9 | AJ9: 10 | AK9: 11 | AL9: 12 | AM9: 1 | AN9: 2 | AO9: 3 | AP9: 4 | AQ9: 5 | AR9: 6 | AS9: 7 | AT9: 8 | AU9: 9 | AV9: 10 | AW9: 11 | AX9: 12
A11: 200319 | F11: 1 | G11: NIAGARA
A12: 200319 | B12: 110000354 | D12: GB | F12: 1.1 | H12: GIÁ BÁN WSS01G (FOB) | O12: =MIN(MAX(SUM(O13:O14),O20),O19) -> 1200 | P12: =MIN(MAX(SUM(P13:P14),P20),P19) -> 1200 | Q12: =MIN(MAX(SUM(Q13:Q14),Q20),Q19) -> 1200 | R12: =MIN(MAX(SUM(R13:R14),R20),R19) -> 1200 | S12: =MIN(MAX(SUM(S13:S14),S20),S19) -> 1200 | T12: =MIN(MAX(SUM(T13:T14),T20),T19) -> 1200.9 | U12: =MIN(MAX(SUM(U13:U14),U20),U19) -> 1214.4 | V12: =MIN(MAX(SUM(V13:V14),V20),V19) -> 1226.1 | ... AC12: =MIN(MAX(SUM(AC13:AC14),AC20),AC19) -> 1238.875 | AD12: =MIN(MAX(SUM(AD13:AD14),AD20),AD19)-0.619999999998981 -> 1219.88 | AE12: =MIN(MAX(SUM(AE13:AE14),AE20),AE19) -> 1221 | AF12: =MIN(MAX(SUM(AF13:AF14),AF20),AF19) -> 1224 | AG12: =MIN(MAX(SUM(AG13:AG14),AG20),AG19) -> 1224 | AH12: =MIN(MAX(SUM(AH13:AH14),AH20),AH19) -> 1213.2 | AI12: =MIN(MAX(SUM(AI13:AI14),AI20),AI19) -> 1200 | AJ12: =MIN(MAX(SUM(AJ13:AJ14),AJ20),AJ19) -> 1200 | AK12: =MIN(MAX(SUM(AK13:AK14),AK20),AK19) -> 1200 | AL12: =MIN(MAX(SUM(AL13:AL14),AL20),AL19) -> 1200
A13: 200319 | B13: 110000354 | F13: 1.1.A | H13: [+] | I13: ICIS Bales - SEA trung bình 3 tháng trước | O13: =AVERAGE(L17:N17) -> 1296.0417 | P13: =AVERAGE(M17:O17) -> 1305 | Q13: =AVERAGE(N17:P17) -> 1313.3333 | R13: =AVERAGE(O17:Q17) -> 1320 | S13: =AVERAGE(P17:R17) -> 1326 | T13: =AVERAGE(Q17:S17) -> 1334.3333 | U13: =AVERAGE(R17:T17) -> 1349.3333 | V13: =AVERAGE(S17:U17) -> 1362.3333 | ... AL13: =AVERAGE(AI17:AK17) -> 1253.9167
A14: 200319 | B14: 110000354 | F14: 1.1.B | H14: [+] | I14: Chiết khấu (10%) | O14: =-O13*O18 -> -129.60417 | P14: =-P13*P18 -> -130.5 | Q14: =-Q13*Q18 -> -131.33333 | R14: =-R13*R18 -> -132 | S14: =-S13*S18 -> -132.6 | T14: =-T13*T18 -> -133.43333 | U14: =-U13*U18 -> -134.93333 | V14: =-V13*V18 -> -136.23333 | ... AL14: =-AL13*AL18 -> -125.39167
A15: 200319 | B15: 110000354 | D15: EXW | F15: 1.1.1 | I15: Giá bán quy đổi EXW | O15: =O12-O16 -> 1180 | P15: =P12-P16 -> 1180 | Q15: =Q12-Q16 -> 1180 | R15: =R12-R16 -> 1180 | S15: =S12-S16 -> 1180 | T15: =T12-T16 -> 1180.9 | U15: =U12-U16 -> 1194.4 | V15: =V12-V16 -> 1206.1 | ... AL15: =AL12-AL16 -> 1180
A16: 200319 | B16: 110000354 | I16: Chi phí vận chuyển | O16: 20 | P16: 20 | Q16: 20 | R16: 20 | S16: 20 | T16: 20 | U16: 20 | V16: 20 | W16: 20 | X16: 20 | Y16: 20 | Z16: 20 | AA16: 20 | AB16: 20 | AC16: 20 | AD16: 22 | AE16: 22 | AF16: 22 | AG16: 22 | AH16: 20 | AI16: 20 | AJ16: 20 | AK16: 20 | AL16: 20
A17: 200319 | B17: 110000354 | C17: 04 | J17: ICIS Bales - SEA | L17: {=SUMPRODUCT(General_Data*(Year=L$3)*(Month=L$4)*(Code_General_Data=$C17))} -> 1288.125 | M17: {=SUMPRODUCT(General_Data*(Year=M$3)*(Month=M$4)*(Code_General_Data=$C17))} -> 1300 | N17: {=SUMPRODUCT(General_Data*(Year=N$3)*(Month=N$4)*(Code_General_Data=$C17))} -> 1300 | O17: {=SUMPRODUCT(General_Data*(Year=O$3)*(Month=O$4)*(Code_General_Data=$C17))} -> 1315 | P17: {=SUMPRODUCT(General_Data*(Year=P$3)*(Month=P$4)*(Code_General_Data=$C17))} -> 1325 | Q17: {=SUMPRODUCT(General_Data*(Year=Q$3)*(Month=Q$4)*(Code_General_Data=$C17))} -> 1320 | R17: {=SUMPRODUCT(General_Data*(Year=R$3)*(Month=R$4)*(Code_General_Data=$C17))} -> 1333 | S17: {=SUMPRODUCT(General_Data*(Year=S$3)*(Month=S$4)*(Code_General_Data=$C17))} -> 1350 | ... AL17: {=SUMPRODUCT(General_Data*(Year=AL$3)*(Month=AL$4)*(Code_General_Data=$C17))} -> 0
A18: 200319 | B18: 110000354 | J18: %Chiết khấu | O18: 0.1 | P18: 0.1 | Q18: 0.1 | R18: 0.1 | S18: 0.1 | T18: 0.1 | U18: 0.1 | V18: 0.1 | W18: 0.1 | X18: 0.1 | Y18: 0.1 | Z18: 0.1 | AA18: 0.1 | AB18: 0.1 | AC18: 0.1 | AD18: 0.1 | AE18: 0.1 | AF18: 0.1 | AG18: 0.1 | AH18: 0.1 | AI18: 0.1 | AJ18: 0.1 | AK18: 0.1 | AL18: 0.1
A19: 200319 | B19: 110000354 | F19: 1.1.2 | J19: Giá trần | O19: {=INDEX(Note!$J$3:$J$101,MATCH(1,(Note!$A$3:$A$101=$A19)*(Note!$C$3:$C$101=$B19)*(Note!$E$3:$E$101<=O$1)*(Note!$F$3:$F$101>=O$2),0))} -> 1600 | P19: {=INDEX(Note!$J$3:$J$101,MATCH(1,(Note!$A$3:$A$101=$A19)*(Note!$C$3:$C$101=$B19)*(Note!$E$3:$E$101<=P$1)*(Note!$F$3:$F$101>=P$2),0))} -> 1600 | Q19: {=INDEX(Note!$J$3:$J$101,MATCH(1,(Note!$A$3:$A$101=$A19)*(Note!$C$3:$C$101=$B19)*(Note!$E$3:$E$101<=Q$1)*(Note!$F$3:$F$101>=Q$2),0))} -> 1600 | R19: {=INDEX(Note!$J$3:$J$101,MATCH(1,(Note!$A$3:$A$101=$A19)*(Note!$C$3:$C$101=$B19)*(Note!$E$3:$E$101<=R$1)*(Note!$F$3:$F$101>=R$2),0))} -> 1600 | S19: {=INDEX(Note!$J$3:$J$101,MATCH(1,(Note!$A$3:$A$101=$A19)*(Note!$C$3:$C$101=$B19)*(Note!$E$3:$E$101<=S$1)*(Note!$F$3:$F$101>=S$2),0))} -> 1600 | T19: {=INDEX(Note!$J$3:$J$101,MATCH(1,(Note!$A$3:$A$101=$A19)*(Note!$C$3:$C$101=$B19)*(Note!$E$3:$E$101<=T$1)*(Note!$F$3:$F$101>=T$2),0))} -> 1600 | U19: {=INDEX(Note!$J$3:$J$101,MATCH(1,(Note!$A$3:$A$101=$A19)*(Note!$C$3:$C$101=$B19)*(Note!$E$3:$E$101<=U$1)*(Note!$F$3:$F$101>=U$2),0))} -> 1600 | V19: {=INDEX(Note!$J$3:$J$101,MATCH(1,(Note!$A$3:$A$101=$A19)*(Note!$C$3:$C$101=$B19)*(Note!$E$3:$E$101<=V$1)*(Note!$F$3:$F$101>=V$2),0))} -> 1600 | ... AL19: {=INDEX(Note!$J$3:$J$101,MATCH(1,(Note!$A$3:$A$101=$A19)*(Note!$C$3:$C$101=$B19)*(Note!$E$3:$E$101<=AL$1)*(Note!$F$3:$F$101>=AL$2),0))} -> 1600
A20: 200319 | B20: 110000354 | F20: 1.1.3 | J20: Giá sàn | O20: {=INDEX(Note!$K$3:$K$101,MATCH(1,(Note!$A$3:$A$101=$A20)*(Note!$C$3:$C$101=$B20)*(Note!$E$3:$E$101<=O$1)*(Note!$F$3:$F$101>=O$2),0))} -> 1200 | P20: {=INDEX(Note!$K$3:$K$101,MATCH(1,(Note!$A$3:$A$101=$A20)*(Note!$C$3:$C$101=$B20)*(Note!$E$3:$E$101<=P$1)*(Note!$F$3:$F$101>=P$2),0))} -> 1200 | Q20: {=INDEX(Note!$K$3:$K$101,MATCH(1,(Note!$A$3:$A$101=$A20)*(Note!$C$3:$C$101=$B20)*(Note!$E$3:$E$101<=Q$1)*(Note!$F$3:$F$101>=Q$2),0))} -> 1200 | R20: {=INDEX(Note!$K$3:$K$101,MATCH(1,(Note!$A$3:$A$101=$A20)*(Note!$C$3:$C$101=$B20)*(Note!$E$3:$E$101<=R$1)*(Note!$F$3:$F$101>=R$2),0))} -> 1200 | S20: {=INDEX(Note!$K$3:$K$101,MATCH(1,(Note!$A$3:$A$101=$A20)*(Note!$C$3:$C$101=$B20)*(Note!$E$3:$E$101<=S$1)*(Note!$F$3:$F$101>=S$2),0))} -> 1200 | T20: {=INDEX(Note!$K$3:$K$101,MATCH(1,(Note!$A$3:$A$101=$A20)*(Note!$C$3:$C$101=$B20)*(Note!$E$3:$E$101<=T$1)*(Note!$F$3:$F$101>=T$2),0))} -> 1200 | U20: {=INDEX(Note!$K$3:$K$101,MATCH(1,(Note!$A$3:$A$101=$A20)*(Note!$C$3:$C$101=$B20)*(Note!$E$3:$E$101<=U$1)*(Note!$F$3:$F$101>=U$2),0))} -> 1200 | V20: {=INDEX(Note!$K$3:$K$101,MATCH(1,(Note!$A$3:$A$101=$A20)*(Note!$C$3:$C$101=$B20)*(Note!$E$3:$E$101<=V$1)*(Note!$F$3:$F$101>=V$2),0))} -> 1200 | ... AL20: {=INDEX(Note!$K$3:$K$101,MATCH(1,(Note!$A$3:$A$101=$A20)*(Note!$C$3:$C$101=$B20)*(Note!$E$3:$E$101<=AL$1)*(Note!$F$3:$F$101>=AL$2),0))} -> 1200
A21: 200319 | B21: 110000354 | F21: 1.1.4 | J21: Giá duyệt tháng | O21: {=SUMPRODUCT(General_Data*(Year=O$3)*(Month=O$4)*(Code_General_Data=$B21))} -> 1250 | P21: {=SUMPRODUCT(General_Data*(Year=P$3)*(Month=P$4)*(Code_General_Data=$B21))} -> 1250 | Q21: {=SUMPRODUCT(General_Data*(Year=Q$3)*(Month=Q$4)*(Code_General_Data=$B21))} -> 1250 | R21: {=SUMPRODUCT(General_Data*(Year=R$3)*(Month=R$4)*(Code_General_Data=$B21))} -> 1250 | S21: {=SUMPRODUCT(General_Data*(Year=S$3)*(Month=S$4)*(Code_General_Data=$B21))} -> 1300 | T21: {=SUMPRODUCT(General_Data*(Year=T$3)*(Month=T$4)*(Code_General_Data=$B21))} -> 1300 | U21: {=SUMPRODUCT(General_Data*(Year=U$3)*(Month=U$4)*(Code_General_Data=$B21))} -> 1300 | V21: {=SUMPRODUCT(General_Data*(Year=V$3)*(Month=V$4)*(Code_General_Data=$B21))} -> 1300 | ... AL21: {=SUMPRODUCT(General_Data*(Year=AL$3)*(Month=AL$4)*(Code_General_Data=$B21))} -> 1200
J22: Giá trần - quy đổi EXW | O22: =O19-O16 -> 1580 | P22: =P19-P16 -> 1580 | Q22: =Q19-Q16 -> 1580 | R22: =R19-R16 -> 1580 | S22: =S19-S16 -> 1580 | T22: =T19-T16 -> 1580 | U22: =U19-U16 -> 1580 | V22: =V19-V16 -> 1580 | ... AL22: =AL19-AL16 -> 1580
J23: Giá sàn - quy đổi EXW | O23: =O20-O16 -> 1180 | P23: =P20-P16 -> 1180 | Q23: =Q20-Q16 -> 1180 | R23: =R20-R16 -> 1180 | S23: =S20-S16 -> 1180 | T23: =T20-T16 -> 1180 | U23: =U20-U16 -> 1180 | V23: =V20-V16 -> 1180 | ... AL23: =AL20-AL16 -> 1180
A25: 200332 | F25: 2 | G25: OUTEIRINHO
A26: 200332 | B26: 110000355 | D26: GB | F26: 2.1 | H26: GIÁ BÁN iSS01G (FOB) | AA26: 1250 | AB26: 1250 | AC26: 1250 | AD26: 1250 | AE26: 1250 | AF26: 1250 | AG26: 1250 | AH26: 1250 | AI26: 1250 | AJ26: 1250 | AK26: 1250 | AL26: 1250
A27: 200332 | B27: 110000355 | D27: EXW | F27: 2.1.1 | I27: Giá bán quy đổi EXW | AA27: =AA26-AA28 -> 1230 | AB27: =AB26-AB28 -> 1230 | AC27: =AC26-AC28 -> 1230 | AD27: =AD26-AD28 -> 1228 | AE27: 1228 | AF27: 1228 | AG27: 1228 | AH27: 1228 | AI27: 1228 | AJ27: 1228 | AK27: 1228 | AL27: 1228
A28: 200332 | B28: 110000355 | F28: 2.1.2 | I28: Chi phí vận chuyển | AA28: 20 | AB28: 20 | AC28: 20 | AD28: 22 | AE28: 22 | AF28: 22 | AG28: 22 | AH28: 20 | AI28: 20 | AJ28: 20 | AK28: 20 | AL28: 20
A29: 200332 | B29: 110000355 | F29: 2.1.3 | J29: Giá duyệt tháng | AA29: {=SUMPRODUCT(General_Data*(Year=AA$3)*(Month=AA$4)*(Code_General_Data=$B29))} -> 1260 | AB29: {=SUMPRODUCT(General_Data*(Year=AB$3)*(Month=AB$4)*(Code_General_Data=$B29))} -> 1260 | AC29: {=SUMPRODUCT(General_Data*(Year=AC$3)*(Month=AC$4)*(Code_General_Data=$B29))} -> 1260 | AD29: {=SUMPRODUCT(General_Data*(Year=AD$3)*(Month=AD$4)*(Code_General_Data=$B29))} -> 1280 | AE29: {=SUMPRODUCT(General_Data*(Year=AE$3)*(Month=AE$4)*(Code_General_Data=$B29))} -> 1280 | AF29: {=SUMPRODUCT(General_Data*(Year=AF$3)*(Month=AF$4)*(Code_General_Data=$B29))} -> 1280 | AG29: {=SUMPRODUCT(General_Data*(Year=AG$3)*(Month=AG$4)*(Code_General_Data=$B29))} -> 1280 | AH29: {=SUMPRODUCT(General_Data*(Year=AH$3)*(Month=AH$4)*(Code_General_Data=$B29))} -> 1250 | ... AL29: {=SUMPRODUCT(General_Data*(Year=AL$3)*(Month=AL$4)*(Code_General_Data=$B29))} -> 1230
A31: 105263 | F31: 3 | G31: UNILEVER VIỆT NAM
A32: 105263 | B32: 110000354 | D32: GB | F32: 3.1 | H32: GIÁ BÁN WSS01G (DDP) | O32: =ROUND(SUM(O33:O38),-2)+O39 -> 1320 | P32: =ROUND(SUM(P33:P38),-2)+P39 -> 1320 | Q32: =ROUND(SUM(Q33:Q38),-2)+Q39 -> 1320 | R32: =ROUND(SUM(R33:R38),-2)+R39 -> 1320 | S32: =ROUND(SUM(S33:S38),-2)+S39 -> 1320 | T32: =ROUND(SUM(T33:T38),-2)+T39 -> 1320 | U32: =ROUND(SUM(U33:U38),-2)+U39 -> 1320 | V32: =ROUND(SUM(V33:V38),-2)+V39 -> 1320 | W32: =ROUND(SUM(W33:W38),-2)+W39 -> 1320 | X32: =ROUND(SUM(X33:X38),-1)+X39 -> 1300 | Y32: =ROUND(SUM(Y33:Y38),-1)+Y39 -> 1300 | Z32: =ROUND(SUM(Z33:Z38),-1)+Z39 -> 1300 | AA32: =ROUND(SUM(AA33:AA38),-1)+AA39 -> 1300 | AB32: =ROUND(SUM(AB33:AB38),-1)+AB39 -> 1300 | AC32: =ROUND(SUM(AC33:AC38),-1)+AC39 -> 1300 | AD32: =ROUND(SUM(AD33:AD38),-1)+AD39 -> 1250 | AE32: =ROUND(SUM(AE33:AE38),-1)+AE39 -> 1250 | ... AL32: =ROUND(SUM(AL33:AL38),-1)+AL39 -> 1280
A33: 105263 | B33: 110000354 | F33: 3.1.A | H33: [+] | I33: Bales DTR | O33: =16500/O$40*10^3 -> 673.46939 | P33: =16500/P$40*10^3 -> 673.46939 | Q33: =16500/Q$40*10^3 -> 673.46939 | R33: =16500/R$40*10^3 -> 673.46939 | S33: =16500/S$40*10^3 -> 673.46939 | T33: =16500/T$40*10^3 -> 673.46939 | U33: =16500/U$40*10^3 -> 660 | V33: =16500/V$40*10^3 -> 660 | ... AC33: =16500/AC$40*10^3 -> 660 | AD33: =16800/AD$40*10^3 -> 672 | AE33: =16800/AE$40*10^3 -> 672 | AF33: =16800/AF$40*10^3 -> 672 | AG33: =16800/AG$40*10^3 -> 672 | AH33: =16800/AH$40*10^3 -> 672 | AI33: =16800/AI$40*10^3 -> 672 | AJ33: =16800/AJ$40*10^3 -> 672 | AK33: =16800/AK$40*10^3 -> 672 | AL33: =16800/AL$40*10^3 -> 672
A34: 105263 | B34: 110000354 | F34: 3.1.B | H34: [+] | I34: Hao hụt (30%) | O34: =O33*O41 -> 202.04082 | P34: =P33*P41 -> 202.04082 | Q34: =Q33*Q41 -> 202.04082 | R34: =R33*R41 -> 202.04082 | S34: =S33*S41 -> 202.04082 | T34: =T33*T41 -> 202.04082 | U34: =U33*U41 -> 198 | V34: =V33*V41 -> 198 | ... AL34: =AL33*AL41 -> 201.6
A35: 105263 | B35: 110000354 | F35: 3.1.C | H35: [+] | I35: Conversion cost | O35: =9193.7/O40*10^3 -> 375.25306 | P35: =9193.7/P40*10^3 -> 375.25306 | Q35: =9193.7/Q40*10^3 -> 375.25306 | R35: =9193.7/R40*10^3 -> 375.25306 | S35: =9193.7/S40*10^3 -> 375.25306 | T35: =9193.7/T40*10^3 -> 375.25306 | U35: =9193.7/U40*10^3 -> 367.748 | V35: =9193.7/V40*10^3 -> 367.748 | ... AC35: =9193.7/AC40*10^3 -> 367.748 | AD35: =9377.55821/AD40*10^3 -> 375.10233 | AE35: =9377.55821/AE40*10^3 -> 375.10233 | AF35: =9377.55821/AF40*10^3 -> 375.10233 | AG35: =9377.55821/AG40*10^3 -> 375.10233 | AH35: =9377.55821/AH40*10^3 -> 375.10233 | AI35: =9377.55821/AI40*10^3 -> 375.10233 | AJ35: =9377.55821/AJ40*10^3 -> 375.10233 | AK35: =9377.55821/AK40*10^3 -> 375.10233 | AL35: =9377.55821/AL40*10^3 -> 375.10233
A36: 105263 | B36: 110000354 | F36: 3.1.D | H36: [+] | I36: Chi phí vận chuyển | O36: =299/O40*10^3 -> 12.204082 | P36: =299/P40*10^3 -> 12.204082 | Q36: =299/Q40*10^3 -> 12.204082 | R36: =299/R40*10^3 -> 12.204082 | S36: =299/S40*10^3 -> 12.204082 | T36: =299/T40*10^3 -> 12.204082 | U36: =299/U40*10^3 -> 11.96 | V36: =299/V40*10^3 -> 11.96 | ... AL36: =299/AL40*10^3 -> 11.96
A37: 105263 | B37: 110000354 | F37: 3.1.E | H37: [+] | I37: Lợi nhuận trước thuế (EBT) | O37: =3295/O40*10^3 -> 134.4898 | P37: =3295/P40*10^3 -> 134.4898 | Q37: =3295/Q40*10^3 -> 134.4898 | R37: =3295/R40*10^3 -> 134.4898 | S37: =3295/S40*10^3 -> 134.4898 | T37: =3295/T40*10^3 -> 134.4898 | U37: =3295/U40*10^3 -> 131.8 | V37: =3295/V40*10^3 -> 131.8 | ... AL37: =3295/AL40*10^3 -> 131.8
A38: 105263 | B38: 110000354 | F38: 3.1.F | H38: [+] | I38: Interest (lãi vay) | O38: =8%/12*SUM(O33:O37) -> 9.316381 | P38: =8%/12*SUM(P33:P37) -> 9.316381 | Q38: =8%/12*SUM(Q33:Q37) -> 9.316381 | R38: =8%/12*SUM(R33:R37) -> 9.316381 | S38: =8%/12*SUM(S33:S37) -> 9.316381 | T38: =8%/12*SUM(T33:T37) -> 9.316381 | U38: =8%/12*SUM(U33:U37) -> 9.1300533 | V38: =8%/12*SUM(V33:V37) -> 9.1300533 | ... AL38: =8%/12*SUM(AL33:AL37) -> 9.2830822
A39: 105263 | B39: 110000354 | F39: 3.1.G | H39: [+] | I39: Chiết khấu | O39: -80 | P39: -80 | Q39: -80 | R39: -80 | S39: -80 | T39: -80 | U39: -80 | V39: -80 | W39: -80 | X39: -80 | Y39: -80 | Z39: -80 | AA39: -80 | AB39: -80 | AC39: -80 | AD39: -150 | AE39: -150 | AF39: -150 | AG39: -120 | AH39: -120 | AI39: -120 | AJ39: -120 | AK39: -120 | AL39: -120
A40: 105263 | B40: 110000354 | J40: Exchange rate | O40: 24500 | P40: 24500 | Q40: 24500 | R40: 24500 | S40: 24500 | T40: 24500 | U40: 25000 | V40: 25000 | W40: 25000 | X40: 25000 | Y40: 25000 | Z40: 25000 | AA40: 25000 | AB40: 25000 | AC40: 25000 | AD40: 25000 | AE40: 25000 | AF40: 25000 | AG40: 25000 | AH40: 25000 | AI40: 25000 | AJ40: 25000 | AK40: 25000 | AL40: 25000
A41: 105263 | B41: 110000354 | J41: %Hao hụt | O41: 0.3 | P41: 0.3 | Q41: 0.3 | R41: 0.3 | S41: 0.3 | T41: 0.3 | U41: 0.3 | V41: 0.3 | W41: 0.3 | X41: 0.3 | Y41: 0.3 | Z41: 0.3 | AA41: 0.3 | AB41: 0.3 | AC41: 0.3 | AD41: 0.3 | AE41: 0.3 | AF41: 0.3 | AG41: 0.3 | AH41: 0.3 | AI41: 0.3 | AJ41: 0.3 | AK41: 0.3 | AL41: 0.3
A42: 105263 | B42: 110000354 | D42: EXW | F42: 3.1.1 | I42: Giá bán quy đổi EXW | O42: =O32-O36 -> 1307.7959 | P42: =P32-P36 -> 1307.7959 | Q42: =Q32-Q36 -> 1307.7959 | R42: =R32-R36 -> 1307.7959 | S42: =S32-S36 -> 1307.7959 | T42: =T32-T36 -> 1307.7959 | U42: =U32-U36 -> 1308.04 | V42: =V32-V36 -> 1308.04 | ... AL42: =AL32-AL36 -> 1268.04
A43: 105263 | B43: 110000354 | F43: 3.1.2 | J43: Giá duyệt tháng | O43: {=SUMPRODUCT(General_Data*(Year=O$3)*(Month=O$4)*(Code_General_Data=$B43))} -> 1250 | P43: {=SUMPRODUCT(General_Data*(Year=P$3)*(Month=P$4)*(Code_General_Data=$B43))} -> 1250 | Q43: {=SUMPRODUCT(General_Data*(Year=Q$3)*(Month=Q$4)*(Code_General_Data=$B43))} -> 1250 | R43: {=SUMPRODUCT(General_Data*(Year=R$3)*(Month=R$4)*(Code_General_Data=$B43))} -> 1250 | S43: {=SUMPRODUCT(General_Data*(Year=S$3)*(Month=S$4)*(Code_General_Data=$B43))} -> 1300 | T43: {=SUMPRODUCT(General_Data*(Year=T$3)*(Month=T$4)*(Code_General_Data=$B43))} -> 1300 | U43: {=SUMPRODUCT(General_Data*(Year=U$3)*(Month=U$4)*(Code_General_Data=$B43))} -> 1300 | V43: {=SUMPRODUCT(General_Data*(Year=V$3)*(Month=V$4)*(Code_General_Data=$B43))} -> 1300 | ... AL43: {=SUMPRODUCT(General_Data*(Year=AL$3)*(Month=AL$4)*(Code_General_Data=$B43))} -> 1200
A45: 105263 | B45: 110000339 | D45: GB | F45: 3.2 | H45: GIÁ BÁN MBF01 (DDP) | O45: =ROUND(SUM(O46:O52),-1) -> 1500 | P45: =ROUND(SUM(P46:P52),-1) -> 1500 | Q45: =ROUND(SUM(Q46:Q52),-1) -> 1500 | R45: =ROUND(SUM(R46:R52),-1) -> 1430 | S45: =ROUND(SUM(S46:S52),-1) -> 1430 | T45: =ROUND(SUM(T46:T52),-1) -> 1430 | U45: =ROUND(SUM(U46:U52),-1) -> 1430 | V45: =ROUND(SUM(V46:V52),-1) -> 1430 | ... AL45: =ROUND(SUM(AL46:AL52),-1) -> 1380
A46: 105263 | B46: 110000339 | F46: 3.2.A | H46: [+] | I46: Bales DTR | O46: =22500/O53*10^3 -> 918.36735 | P46: =22500/P53*10^3 -> 918.36735 | Q46: =22500/Q53*10^3 -> 918.36735 | R46: =21000/R53*10^3 -> 857.14286 | S46: =21000/S53*10^3 -> 857.14286 | T46: =21000/T53*10^3 -> 857.14286 | U46: =21000/U53*10^3 -> 840 | V46: =21000/V53*10^3 -> 840 | W46: =21000/W53*10^3 -> 840 | X46: =21000/X53*10^3 -> 840 | Y46: =21000/Y53*10^3 -> 840 | ... AC46: =21000/AC53*10^3 -> 840 | AD46: =(21500*75%+24500*25%)/AD53*10^3 -> 890 | AE46: =(21500*75%+24500*25%)/AE53*10^3 -> 890 | AF46: =(21500*75%+24500*25%)/AF53*10^3 -> 890 | AG46: =21000/AG53*10^3 -> 840 | AH46: =21000/AH53*10^3 -> 840 | AI46: =21000/AI53*10^3 -> 840 | AJ46: =21000/AJ53*10^3 -> 840 | AK46: =21000/AK53*10^3 -> 840 | AL46: =21000/AL53*10^3 -> 840
...

Sheet Biểu đồ
C1: III. BIỂU ĐỒ
C36: III. BIỂU ĐỒ
C71: III. BIỂU ĐỒ
C106: III. BIỂU ĐỒ
C141: III. BIỂU ĐỒ

Sheet Vẽ Biểu đồ
E1: 2024 | F1: 2024 | G1: 2024 | H1: 2024 | I1: 2024 | J1: 2024 | K1: 2024 | L1: 2024 | M1: 2024 | N1: 2024 | O1: 2024 | P1: 2024 | Q1: 2025 | R1: 2025 | S1: 2025 | T1: 2025 | U1: 2025 | V1: 2025 | W1: 2025 | X1: 2025 | Y1: 2025 | Z1: 2025 | AA1: 2025 | AB1: 2025 | AC1: 2026 | AD1: 2026 | AE1: 2026 | AF1: 2026 | AG1: 2026 | AH1: 2026 | AI1: 2026 | AJ1: 2026 | AK1: 2026 | AL1: 2026 | AM1: 2026 | AN1: 2026
E2: 1 | F2: 2 | G2: 3 | H2: 4 | I2: 5 | J2: 6 | K2: 7 | L2: 8 | M2: 9 | N2: 10 | O2: 11 | P2: 12 | Q2: 1 | R2: 2 | S2: 3 | T2: 4 | U2: 5 | V2: 6 | W2: 7 | X2: 8 | Y2: 9 | Z2: 10 | AA2: 11 | AB2: 12 | AC2: 1 | AD2: 2 | AE2: 3 | AF2: 4 | AG2: 5 | AH2: 6 | AI2: 7 | AJ2: 8 | AK2: 9 | AL2: 10 | AM2: 11 | AN2: 12
D3: X dòng này làm lable -> | AB3: x
A4: Genearal Data | B4: Price
C5: 110000354 | D5: WSS01G
E6: 2024 | Q6: 2025
E7: 1 | F7: 2 | G7: 3 | H7: 4 | I7: 5 | J7: 6 | K7: 7 | L7: 8 | M7: 9 | N7: 10 | O7: 11 | P7: 12 | Q7: 1 | R7: 2 | S7: 3 | T7: 4 | U7: 5 | V7: 6 | W7: 7 | X7: 8 | Y7: 9 | Z7: 10 | AA7: 11 | AB7: 12 | AC7: 1 | AD7: 2 | AE7: 3 | AF7: 4 | AG7: 5 | AH7: 6 | AI7: 7 | AJ7: 8 | AK7: 9 | AL7: 10 | AM7: 11 | AN7: 12
B8: 200319 | C8: 110000354 | D8: Niagara | E8: {=IF(SUMPRODUCT('Giá công thức'!$G$11:$AD$106*('Giá công thức'!$A$11:$A$106=$B8)*('Giá công thức'!$B$11:$B$106=$C8)*('Giá công thức'!$C$11:$C$106="GB")*('Giá công thức'!$G$3:$AD$3=E$1)*('Giá công thức'!$G$4:$AD$4=E$2))=0,NA(),SUMPRODUCT('Giá công thức'!$G$11:$AD$106*('Giá công thức'!$A$11:$A$106=$B8)*('Giá công thức'!$B$11:$B$106=$C8)*('Giá công thức'!$C$11:$C$106="GB")*('Giá công thức'!$G$3:$AD$3=E$1)*('Giá công thức'!$G$4:$AD$4=E$2)))} -> 1180 | F8: {=IF(SUMPRODUCT('Giá công thức'!$G$11:$AD$106*('Giá công thức'!$A$11:$A$106=$B8)*('Giá công thức'!$B$11:$B$106=$C8)*('Giá công thức'!$C$11:$C$106="GB")*('Giá công thức'!$G$3:$AD$3=F$1)*('Giá công thức'!$G$4:$AD$4=F$2))=0,NA(),SUMPRODUCT('Giá công thức'!$G$11:$AD$106*('Giá công thức'!$A$11:$A$106=$B8)*('Giá công thức'!$B$11:$B$106=$C8)*('Giá công thức'!$C$11:$C$106="GB")*('Giá công thức'!$G$3:$AD$3=F$1)*('Giá công thức'!$G$4:$AD$4=F$2)))} -> 1180 | G8: {=IF(SUMPRODUCT('Giá công thức'!$G$11:$AD$106*('Giá công thức'!$A$11:$A$106=$B8)*('Giá công thức'!$B$11:$B$106=$C8)*('Giá công thức'!$C$11:$C$106="GB")*('Giá công thức'!$G$3:$AD$3=G$1)*('Giá công thức'!$G$4:$AD$4=G$2))=0,NA(),SUMPRODUCT('Giá công thức'!$G$11:$AD$106*('Giá công thức'!$A$11:$A$106=$B8)*('Giá công thức'!$B$11:$B$106=$C8)*('Giá công thức'!$C$11:$C$106="GB")*('Giá công thức'!$G$3:$AD$3=G$1)*('Giá công thức'!$G$4:$AD$4=G$2)))} -> 1180 | H8: {=IF(SUMPRODUCT('Giá công thức'!$G$11:$AD$106*('Giá công thức'!$A$11:$A$106=$B8)*('Giá công thức'!$B$11:$B$106=$C8)*('Giá công thức'!$C$11:$C$106="GB")*('Giá công thức'!$G$3:$AD$3=H$1)*('Giá công thức'!$G$4:$AD$4=H$2))=0,NA(),SUMPRODUCT('Giá công thức'!$G$11:$AD$106*('Giá công thức'!$A$11:$A$106=$B8)*('Giá công thức'!$B$11:$B$106=$C8)*('Giá công thức'!$C$11:$C$106="GB")*('Giá công thức'!$G$3:$AD$3=H$1)*('Giá công thức'!$G$4:$AD$4=H$2)))} -> 1180 | I8: {=IF(SUMPRODUCT('Giá công thức'!$G$11:$AD$106*('Giá công thức'!$A$11:$A$106=$B8)*('Giá công thức'!$B$11:$B$106=$C8)*('Giá công thức'!$C$11:$C$106="GB")*('Giá công thức'!$G$3:$AD$3=I$1)*('Giá công thức'!$G$4:$AD$4=I$2))=0,NA(),SUMPRODUCT('Giá công thức'!$G$11:$AD$106*('Giá công thức'!$A$11:$A$106=$B8)*('Giá công thức'!$B$11:$B$106=$C8)*('Giá công thức'!$C$11:$C$106="GB")*('Giá công thức'!$G$3:$AD$3=I$1)*('Giá công thức'!$G$4:$AD$4=I$2)))} -> 1180 | J8: {=IF(SUMPRODUCT('Giá công thức'!$G$11:$AD$106*('Giá công thức'!$A$11:$A$106=$B8)*('Giá công thức'!$B$11:$B$106=$C8)*('Giá công thức'!$C$11:$C$106="GB")*('Giá công thức'!$G$3:$AD$3=J$1)*('Giá công thức'!$G$4:$AD$4=J$2))=0,NA(),SUMPRODUCT('Giá công thức'!$G$11:$AD$106*('Giá công thức'!$A$11:$A$106=$B8)*('Giá công thức'!$B$11:$B$106=$C8)*('Giá công thức'!$C$11:$C$106="GB")*('Giá công thức'!$G$3:$AD$3=J$1)*('Giá công thức'!$G$4:$AD$4=J$2)))} -> 1180.9 | K8: {=IF(SUMPRODUCT('Giá công thức'!$G$11:$AD$106*('Giá công thức'!$A$11:$A$106=$B8)*('Giá công thức'!$B$11:$B$106=$C8)*('Giá công thức'!$C$11:$C$106="GB")*('Giá công thức'!$G$3:$AD$3=K$1)*('Giá công thức'!$G$4:$AD$4=K$2))=0,NA(),SUMPRODUCT('Giá công thức'!$G$11:$AD$106*('Giá công thức'!$A$11:$A$106=$B8)*('Giá công thức'!$B$11:$B$106=$C8)*('Giá công thức'!$C$11:$C$106="GB")*('Giá công thức'!$G$3:$AD$3=K$1)*('Giá công thức'!$G$4:$AD$4=K$2)))} -> 1194.4 | L8: {=IF(SUMPRODUCT('Giá công thức'!$G$11:$AD$106*('Giá công thức'!$A$11:$A$106=$B8)*('Giá công thức'!$B$11:$B$106=$C8)*('Giá công thức'!$C$11:$C$106="GB")*('Giá công thức'!$G$3:$AD$3=L$1)*('Giá công thức'!$G$4:$AD$4=L$2))=0,NA(),SUMPRODUCT('Giá công thức'!$G$11:$AD$106*('Giá công thức'!$A$11:$A$106=$B8)*('Giá công thức'!$B$11:$B$106=$C8)*('Giá công thức'!$C$11:$C$106="GB")*('Giá công thức'!$G$3:$AD$3=L$1)*('Giá công thức'!$G$4:$AD$4=L$2)))} -> 1206.1 | ... AB8: {=IF(SUMPRODUCT('Giá công thức'!$G$11:$AD$106*('Giá công thức'!$A$11:$A$106=$B8)*('Giá công thức'!$B$11:$B$106=$C8)*('Giá công thức'!$C$11:$C$106="GB")*('Giá công thức'!$G$3:$AD$3=AB$1)*('Giá công thức'!$G$4:$AD$4=AB$2))=0,NA(),SUMPRODUCT('Giá công thức'!$G$11:$AD$106*('Giá công thức'!$A$11:$A$106=$B8)*('Giá công thức'!$B$11:$B$106=$C8)*('Giá công thức'!$C$11:$C$106="GB")*('Giá công thức'!$G$3:$AD$3=AB$1)*('Giá công thức'!$G$4:$AD$4=AB$2)))} -> 1180 | AO8: =INDEX($E8:$AB8,MATCH("X",$E$3:$AB$3,0)) -> 1180
