Workbook
Name \0: #REF!
Name \a: #REF!
Name \b: #REF!
Name \c: #REF!
Name \C_: #REF!
Name \e: #REF!
Name \f: #REF!
Name \k: #REF!
Name \m: #REF!
Name \o: #REF!
Name \p: #REF!
Name \q: #N/A
Name \r: #REF!
Name \s: #REF!
Name \t: #REF!
Name \x: #REF!
Name \z: #REF!
Name _???: #REF!
Name _????????: #REF!
Name _????????????: #REF!
Name _?????????????: #N/A
Name _?_??????: #REF!
Name _?1_HP_A: #REF!
Name _?1_HP_B: #REF!
Name _?2_HP_A: #REF!
Name _?2_HP_B: #REF!
Name _?3_HP_A: #REF!
Name _?3_HP_B: #REF!
Name _?5_HP: #REF!
Name __???: #N/A
Name __????????????: #REF!
Name __?????????????: #REF!
Name ______TAX2: #REF!
Name _____06: #REF!
Name _____CWF1: #REF!
Name _____CWF2: #REF!
Name _____DAT1: #REF!
Name _____DAT10: #REF!
Name _____DAT2: #REF!
Name _____DAT3: #REF!
Name _____DAT4: #REF!
Name _____DAT5: #REF!
Name _____DAT6: #REF!
Name _____DAT7: #REF!
Name _____DAT8: #REF!
Name _____DAT9: #REF!
Name _____UWF1: #REF!
Name _____UWF2: #REF!
Name ____06: #REF!
Name ____CWF1: #REF!
Name ____CWF2: #REF!
Name ____DAT1: #REF!
Name ____DAT10: #REF!
Name ____DAT2: #REF!
Name ____DAT3: #REF!
Name ____DAT4: #REF!
Name ____DAT5: #REF!
Name ____DAT6: #REF!
Name ____DAT7: #REF!
Name ____DAT8: #REF!

Sheet Hop nhat
A1: GROUP (CONSOLIDATED TÁI CHẾ & THU MUA) | O1: 2025
A2: VND
C3: 2024 | D3: =C3 -> 2024 | E3: =D3 -> 2024 | F3: =E3 -> 2024 | G3: =F3 -> 2024 | H3: =G3 -> 2024 | I3: =H3 -> 2024 | J3: =I3 -> 2024 | K3: =J3 -> 2024 | ... N3: =M3 -> 2024 | O3: 2025 | P3: =O3 -> 2025 | Q3: =P3 -> 2025 | R3: =Q3 -> 2025 | S3: =R3 -> 2025 | T3: =S3 -> 2025 | U3: =T3 -> 2025 | V3: =U3 -> 2025 | W3: =V3 -> 2025 | ... Z3: =Y3 -> 2025
C4: 1 | D4: 2 | E4: 3 | F4: 4 | G4: 5 | H4: 6 | I4: 7 | J4: 8 | K4: 9 | L4: 10 | M4: 11 | N4: 12 | O4: 1 | P4: 2 | Q4: 3 | R4: 4 | S4: 5 | T4: 6 | U4: 7 | V4: 8 | W4: 9 | X4: 10 | Y4: 11 | Z4: 12
A5: PHẦN I-BÁO CÁO TÌNH HÌNH TÀI CHÍNH | B5: Index BS | C5: T01.2024 | D5: T02.2024 | E5: T03.2024 | F5: T04.2024 | G5: T05.2024 | H5: T06.2024 | I5: T07.2024 | J5: T08.2024 | K5: T09.2024 | L5: T10.2024 | M5: T11.2024 | N5: T12.2024 | O5: T01.2025 | P5: T02.2025 | Q5: T03.2025 | R5: T04.2025 | S5: T05.2025 | T5: T06.2025 | U5: T07.2025 | V5: T08.2025 | W5: T09.2025 | X5: T10.2025 | Y5: T11.2025 | Z5: T12.2025
A6: A-TÀI SẢN NGẮN HẠN | B6: 1 | C6: =DTR!C6+'Dai Loc'!C6+'Dong Lam'!C6+'Khanh Nga'!C6+TDP!C6+DTRVL!C6 -> 842504987537 | D6: =DTR!D6+'Dai Loc'!D6+'Dong Lam'!D6+'Khanh Nga'!D6+TDP!D6+DTRVL!D6 -> 828028218928 | E6: =DTR!E6+'Dai Loc'!E6+'Dong Lam'!E6+'Khanh Nga'!E6+TDP!E6+DTRVL!E6 -> 8.6664214e+11 | F6: =DTR!F6+'Dai Loc'!F6+'Dong Lam'!F6+'Khanh Nga'!F6+TDP!F6+DTRVL!F6 -> 9.2866377e+11 | G6: =DTR!G6+'Dai Loc'!G6+'Dong Lam'!G6+'Khanh Nga'!G6+TDP!G6+DTRVL!G6 -> 974972463666 | H6: =DTR!H6+'Dai Loc'!H6+'Dong Lam'!H6+'Khanh Nga'!H6+TDP!H6+DTRVL!H6 -> 1000977606992 | I6: =DTR!I6+'Dai Loc'!I6+'Dong Lam'!I6+'Khanh Nga'!I6+TDP!I6+DTRVL!I6 -> 945309048746 | J6: =DTR!J6+'Dai Loc'!J6+'Dong Lam'!J6+'Khanh Nga'!J6+TDP!J6+DTRVL!J6 -> 891517737502 | ... Z6: =DTR!Z6+'Dai Loc'!Z6+'Dong Lam'!Z6+'Khanh Nga'!Z6+TDP!Z6+DTRVL!Z6 -> 1027131422218
A7: I.Tiền và các khoản tương đương tiền | B7: 2 | C7: =DTR!C7+'Dai Loc'!C7+'Dong Lam'!C7+'Khanh Nga'!C7+TDP!C7+DTRVL!C7 -> 46633249760 | D7: =DTR!D7+'Dai Loc'!D7+'Dong Lam'!D7+'Khanh Nga'!D7+TDP!D7+DTRVL!D7 -> 35851802774 | E7: =DTR!E7+'Dai Loc'!E7+'Dong Lam'!E7+'Khanh Nga'!E7+TDP!E7+DTRVL!E7 -> 26393055917 | F7: =DTR!F7+'Dai Loc'!F7+'Dong Lam'!F7+'Khanh Nga'!F7+TDP!F7+DTRVL!F7 -> 34593153167 | G7: =DTR!G7+'Dai Loc'!G7+'Dong Lam'!G7+'Khanh Nga'!G7+TDP!G7+DTRVL!G7 -> 33199136312 | H7: =DTR!H7+'Dai Loc'!H7+'Dong Lam'!H7+'Khanh Nga'!H7+TDP!H7+DTRVL!H7 -> 19638634542 | I7: =DTR!I7+'Dai Loc'!I7+'Dong Lam'!I7+'Khanh Nga'!I7+TDP!I7+DTRVL!I7 -> 56271006190 | J7: =DTR!J7+'Dai Loc'!J7+'Dong Lam'!J7+'Khanh Nga'!J7+TDP!J7+DTRVL!J7 -> 35429490170 | ... Z7: =DTR!Z7+'Dai Loc'!Z7+'Dong Lam'!Z7+'Khanh Nga'!Z7+TDP!Z7+DTRVL!Z7 -> 63226156108
A8: 1.Tiền | B8: 3 | C8: =DTR!C8+'Dai Loc'!C8+'Dong Lam'!C8+'Khanh Nga'!C8+TDP!C8+DTRVL!C8 -> 39793249760 | D8: =DTR!D8+'Dai Loc'!D8+'Dong Lam'!D8+'Khanh Nga'!D8+TDP!D8+DTRVL!D8 -> 29011802774 | E8: =DTR!E8+'Dai Loc'!E8+'Dong Lam'!E8+'Khanh Nga'!E8+TDP!E8+DTRVL!E8 -> 21563055917 | F8: =DTR!F8+'Dai Loc'!F8+'Dong Lam'!F8+'Khanh Nga'!F8+TDP!F8+DTRVL!F8 -> 25763153167 | G8: =DTR!G8+'Dai Loc'!G8+'Dong Lam'!G8+'Khanh Nga'!G8+TDP!G8+DTRVL!G8 -> 24369136312 | H8: =DTR!H8+'Dai Loc'!H8+'Dong Lam'!H8+'Khanh Nga'!H8+TDP!H8+DTRVL!H8 -> 14808634542 | I8: =DTR!I8+'Dai Loc'!I8+'Dong Lam'!I8+'Khanh Nga'!I8+TDP!I8+DTRVL!I8 -> 48441006190 | J8: =DTR!J8+'Dai Loc'!J8+'Dong Lam'!J8+'Khanh Nga'!J8+TDP!J8+DTRVL!J8 -> 27599490170 | ... Z8: =DTR!Z8+'Dai Loc'!Z8+'Dong Lam'!Z8+'Khanh Nga'!Z8+TDP!Z8+DTRVL!Z8 -> 53526156108
A9: 2.Các khoản tương đương tiền | B9: 4 | C9: =DTR!C9+'Dai Loc'!C9+'Dong Lam'!C9+'Khanh Nga'!C9+TDP!C9+DTRVL!C9 -> 6840000000 | D9: =DTR!D9+'Dai Loc'!D9+'Dong Lam'!D9+'Khanh Nga'!D9+TDP!D9+DTRVL!D9 -> 6840000000 | E9: =DTR!E9+'Dai Loc'!E9+'Dong Lam'!E9+'Khanh Nga'!E9+TDP!E9+DTRVL!E9 -> 4830000000 | F9: =DTR!F9+'Dai Loc'!F9+'Dong Lam'!F9+'Khanh Nga'!F9+TDP!F9+DTRVL!F9 -> 8830000000 | G9: =DTR!G9+'Dai Loc'!G9+'Dong Lam'!G9+'Khanh Nga'!G9+TDP!G9+DTRVL!G9 -> 8830000000 | H9: =DTR!H9+'Dai Loc'!H9+'Dong Lam'!H9+'Khanh Nga'!H9+TDP!H9+DTRVL!H9 -> 4830000000 | I9: =DTR!I9+'Dai Loc'!I9+'Dong Lam'!I9+'Khanh Nga'!I9+TDP!I9+DTRVL!I9 -> 7830000000 | J9: =DTR!J9+'Dai Loc'!J9+'Dong Lam'!J9+'Khanh Nga'!J9+TDP!J9+DTRVL!J9 -> 7830000000 | ... Z9: =DTR!Z9+'Dai Loc'!Z9+'Dong Lam'!Z9+'Khanh Nga'!Z9+TDP!Z9+DTRVL!Z9 -> 9700000000
A10: II.Đầu tư tài chính ngắn hạn | B10: 5 | C10: =DTR!C10+'Dai Loc'!C10+'Dong Lam'!C10+'Khanh Nga'!C10+TDP!C10+DTRVL!C10 -> 108051581921 | D10: =DTR!D10+'Dai Loc'!D10+'Dong Lam'!D10+'Khanh Nga'!D10+TDP!D10+DTRVL!D10 -> 108041861921 | E10: =DTR!E10+'Dai Loc'!E10+'Dong Lam'!E10+'Khanh Nga'!E10+TDP!E10+DTRVL!E10 -> 108032141921 | F10: =DTR!F10+'Dai Loc'!F10+'Dong Lam'!F10+'Khanh Nga'!F10+TDP!F10+DTRVL!F10 -> 97522421921 | G10: =DTR!G10+'Dai Loc'!G10+'Dong Lam'!G10+'Khanh Nga'!G10+TDP!G10+DTRVL!G10 -> 97512701921 | H10: =DTR!H10+'Dai Loc'!H10+'Dong Lam'!H10+'Khanh Nga'!H10+TDP!H10+DTRVL!H10 -> 77502981921 | I10: =DTR!I10+'Dai Loc'!I10+'Dong Lam'!I10+'Khanh Nga'!I10+TDP!I10+DTRVL!I10 -> 57993261921 | J10: =DTR!J10+'Dai Loc'!J10+'Dong Lam'!J10+'Khanh Nga'!J10+TDP!J10+DTRVL!J10 -> 57983541921 | ... Z10: =DTR!Z10+'Dai Loc'!Z10+'Dong Lam'!Z10+'Khanh Nga'!Z10+TDP!Z10+DTRVL!Z10 -> 79901021921
A11: 1.Chứng khoán kinh doanh | B11: 6 | C11: =DTR!C11+'Dai Loc'!C11+'Dong Lam'!C11+'Khanh Nga'!C11+TDP!C11+DTRVL!C11 -> 0 | D11: =DTR!D11+'Dai Loc'!D11+'Dong Lam'!D11+'Khanh Nga'!D11+TDP!D11+DTRVL!D11 -> 0 | E11: =DTR!E11+'Dai Loc'!E11+'Dong Lam'!E11+'Khanh Nga'!E11+TDP!E11+DTRVL!E11 -> 0 | F11: =DTR!F11+'Dai Loc'!F11+'Dong Lam'!F11+'Khanh Nga'!F11+TDP!F11+DTRVL!F11 -> 0 | G11: =DTR!G11+'Dai Loc'!G11+'Dong Lam'!G11+'Khanh Nga'!G11+TDP!G11+DTRVL!G11 -> 0 | H11: =DTR!H11+'Dai Loc'!H11+'Dong Lam'!H11+'Khanh Nga'!H11+TDP!H11+DTRVL!H11 -> 0 | I11: =DTR!I11+'Dai Loc'!I11+'Dong Lam'!I11+'Khanh Nga'!I11+TDP!I11+DTRVL!I11 -> 0 | J11: =DTR!J11+'Dai Loc'!J11+'Dong Lam'!J11+'Khanh Nga'!J11+TDP!J11+DTRVL!J11 -> 0 | ... Z11: =DTR!Z11+'Dai Loc'!Z11+'Dong Lam'!Z11+'Khanh Nga'!Z11+TDP!Z11+DTRVL!Z11 -> 0
A12: 2.Dự phòng giảm giá chứng khoán kinh doanh (*) | B12: 7 | C12: =DTR!C12+'Dai Loc'!C12+'Dong Lam'!C12+'Khanh Nga'!C12+TDP!C12+DTRVL!C12 -> 0 | D12: =DTR!D12+'Dai Loc'!D12+'Dong Lam'!D12+'Khanh Nga'!D12+TDP!D12+DTRVL!D12 -> 0 | E12: =DTR!E12+'Dai Loc'!E12+'Dong Lam'!E12+'Khanh Nga'!E12+TDP!E12+DTRVL!E12 -> 0 | F12: =DTR!F12+'Dai Loc'!F12+'Dong Lam'!F12+'Khanh Nga'!F12+TDP!F12+DTRVL!F12 -> 0 | G12: =DTR!G12+'Dai Loc'!G12+'Dong Lam'!G12+'Khanh Nga'!G12+TDP!G12+DTRVL!G12 -> 0 | H12: =DTR!H12+'Dai Loc'!H12+'Dong Lam'!H12+'Khanh Nga'!H12+TDP!H12+DTRVL!H12 -> 0 | I12: =DTR!I12+'Dai Loc'!I12+'Dong Lam'!I12+'Khanh Nga'!I12+TDP!I12+DTRVL!I12 -> 0 | J12: =DTR!J12+'Dai Loc'!J12+'Dong Lam'!J12+'Khanh Nga'!J12+TDP!J12+DTRVL!J12 -> 0 | ... Z12: =DTR!Z12+'Dai Loc'!Z12+'Dong Lam'!Z12+'Khanh Nga'!Z12+TDP!Z12+DTRVL!Z12 -> 0
A13: 3.Đầu tư nắm giữ đến ngày đáo hạn ngắn hạn | B13: 8 | C13: =DTR!C13+'Dai Loc'!C13+'Dong Lam'!C13+'Khanh Nga'!C13+TDP!C13+DTRVL!C13 -> 108051581921 | D13: =DTR!D13+'Dai Loc'!D13+'Dong Lam'!D13+'Khanh Nga'!D13+TDP!D13+DTRVL!D13 -> 108041861921 | E13: =DTR!E13+'Dai Loc'!E13+'Dong Lam'!E13+'Khanh Nga'!E13+TDP!E13+DTRVL!E13 -> 108032141921 | F13: =DTR!F13+'Dai Loc'!F13+'Dong Lam'!F13+'Khanh Nga'!F13+TDP!F13+DTRVL!F13 -> 97522421921 | G13: =DTR!G13+'Dai Loc'!G13+'Dong Lam'!G13+'Khanh Nga'!G13+TDP!G13+DTRVL!G13 -> 97512701921 | H13: =DTR!H13+'Dai Loc'!H13+'Dong Lam'!H13+'Khanh Nga'!H13+TDP!H13+DTRVL!H13 -> 77502981921 | I13: =DTR!I13+'Dai Loc'!I13+'Dong Lam'!I13+'Khanh Nga'!I13+TDP!I13+DTRVL!I13 -> 57993261921 | J13: =DTR!J13+'Dai Loc'!J13+'Dong Lam'!J13+'Khanh Nga'!J13+TDP!J13+DTRVL!J13 -> 57983541921 | ... Z13: =DTR!Z13+'Dai Loc'!Z13+'Dong Lam'!Z13+'Khanh Nga'!Z13+TDP!Z13+DTRVL!Z13 -> 79901021921
A14: 4.Dự phòng đầu tư nắm giữ đến ngày đáo hạn ngắn hạn (*) | B14: 9 | C14: =DTR!C14+'Dai Loc'!C14+'Dong Lam'!C14+'Khanh Nga'!C14+TDP!C14+DTRVL!C14 -> 0 | D14: =DTR!D14+'Dai Loc'!D14+'Dong Lam'!D14+'Khanh Nga'!D14+TDP!D14+DTRVL!D14 -> 0 | E14: =DTR!E14+'Dai Loc'!E14+'Dong Lam'!E14+'Khanh Nga'!E14+TDP!E14+DTRVL!E14 -> 0 | F14: =DTR!F14+'Dai Loc'!F14+'Dong Lam'!F14+'Khanh Nga'!F14+TDP!F14+DTRVL!F14 -> 0 | G14: =DTR!G14+'Dai Loc'!G14+'Dong Lam'!G14+'Khanh Nga'!G14+TDP!G14+DTRVL!G14 -> 0 | H14: =DTR!H14+'Dai Loc'!H14+'Dong Lam'!H14+'Khanh Nga'!H14+TDP!H14+DTRVL!H14 -> 0 | I14: =DTR!I14+'Dai Loc'!I14+'Dong Lam'!I14+'Khanh Nga'!I14+TDP!I14+DTRVL!I14 -> 0 | J14: =DTR!J14+'Dai Loc'!J14+'Dong Lam'!J14+'Khanh Nga'!J14+TDP!J14+DTRVL!J14 -> 0 | ... Z14: =DTR!Z14+'Dai Loc'!Z14+'Dong Lam'!Z14+'Khanh Nga'!Z14+TDP!Z14+DTRVL!Z14 -> 0
A15: 5.Đầu tư ngắn hạn khác | B15: 10 | C15: =DTR!C15+'Dai Loc'!C15+'Dong Lam'!C15+'Khanh Nga'!C15+TDP!C15+DTRVL!C15 -> 0 | D15: =DTR!D15+'Dai Loc'!D15+'Dong Lam'!D15+'Khanh Nga'!D15+TDP!D15+DTRVL!D15 -> 0 | E15: =DTR!E15+'Dai Loc'!E15+'Dong Lam'!E15+'Khanh Nga'!E15+TDP!E15+DTRVL!E15 -> 0 | F15: =DTR!F15+'Dai Loc'!F15+'Dong Lam'!F15+'Khanh Nga'!F15+TDP!F15+DTRVL!F15 -> 0 | G15: =DTR!G15+'Dai Loc'!G15+'Dong Lam'!G15+'Khanh Nga'!G15+TDP!G15+DTRVL!G15 -> 0 | H15: =DTR!H15+'Dai Loc'!H15+'Dong Lam'!H15+'Khanh Nga'!H15+TDP!H15+DTRVL!H15 -> 0 | I15: =DTR!I15+'Dai Loc'!I15+'Dong Lam'!I15+'Khanh Nga'!I15+TDP!I15+DTRVL!I15 -> 0 | J15: =DTR!J15+'Dai Loc'!J15+'Dong Lam'!J15+'Khanh Nga'!J15+TDP!J15+DTRVL!J15 -> 0 | ... Z15: =DTR!Z15+'Dai Loc'!Z15+'Dong Lam'!Z15+'Khanh Nga'!Z15+TDP!Z15+DTRVL!Z15 -> 0
A16: 6.Dự phòng tổn thất các khoản đầu tư ngắn hạn khác (*) | B16: 11 | C16: =DTR!C16+'Dai Loc'!C16+'Dong Lam'!C16+'Khanh Nga'!C16+TDP!C16+DTRVL!C16 -> 0 | D16: =DTR!D16+'Dai Loc'!D16+'Dong Lam'!D16+'Khanh Nga'!D16+TDP!D16+DTRVL!D16 -> 0 | E16: =DTR!E16+'Dai Loc'!E16+'Dong Lam'!E16+'Khanh Nga'!E16+TDP!E16+DTRVL!E16 -> 0 | F16: =DTR!F16+'Dai Loc'!F16+'Dong Lam'!F16+'Khanh Nga'!F16+TDP!F16+DTRVL!F16 -> 0 | G16: =DTR!G16+'Dai Loc'!G16+'Dong Lam'!G16+'Khanh Nga'!G16+TDP!G16+DTRVL!G16 -> 0 | H16: =DTR!H16+'Dai Loc'!H16+'Dong Lam'!H16+'Khanh Nga'!H16+TDP!H16+DTRVL!H16 -> 0 | I16: =DTR!I16+'Dai Loc'!I16+'Dong Lam'!I16+'Khanh Nga'!I16+TDP!I16+DTRVL!I16 -> 0 | J16: =DTR!J16+'Dai Loc'!J16+'Dong Lam'!J16+'Khanh Nga'!J16+TDP!J16+DTRVL!J16 -> 0 | ... Z16: =DTR!Z16+'Dai Loc'!Z16+'Dong Lam'!Z16+'Khanh Nga'!Z16+TDP!Z16+DTRVL!Z16 -> 0
A17: III.Các khoản phải thu ngắn hạn | B17: 12 | C17: =DTR!C17+'Dai Loc'!C17+'Dong Lam'!C17+'Khanh Nga'!C17+TDP!C17+DTRVL!C17 -> 2.0876077e+11 | D17: =DTR!D17+'Dai Loc'!D17+'Dong Lam'!D17+'Khanh Nga'!D17+TDP!D17+DTRVL!D17 -> 1.9391456e+11 | E17: =DTR!E17+'Dai Loc'!E17+'Dong Lam'!E17+'Khanh Nga'!E17+TDP!E17+DTRVL!E17 -> 201044728738 | F17: =DTR!F17+'Dai Loc'!F17+'Dong Lam'!F17+'Khanh Nga'!F17+TDP!F17+DTRVL!F17 -> 218534804131 | G17: =DTR!G17+'Dai Loc'!G17+'Dong Lam'!G17+'Khanh Nga'!G17+TDP!G17+DTRVL!G17 -> 2.2155237e+11 | H17: =DTR!H17+'Dai Loc'!H17+'Dong Lam'!H17+'Khanh Nga'!H17+TDP!H17+DTRVL!H17 -> 2.4767907e+11 | I17: =DTR!I17+'Dai Loc'!I17+'Dong Lam'!I17+'Khanh Nga'!I17+TDP!I17+DTRVL!I17 -> 1.528212e+11 | J17: =DTR!J17+'Dai Loc'!J17+'Dong Lam'!J17+'Khanh Nga'!J17+TDP!J17+DTRVL!J17 -> 1.7780637e+11 | ... Z17: =DTR!Z17+'Dai Loc'!Z17+'Dong Lam'!Z17+'Khanh Nga'!Z17+TDP!Z17+DTRVL!Z17 -> 287452852834
... A76: 5.Đầu tư nắm giữ đến ngày đáo hạn dài hạn | B76: 71 | C76: =DTR!C76+'Dai Loc'!C76+'Dong Lam'!C76+'Khanh Nga'!C76+TDP!C76+DTRVL!C76 -> 0 | D76: =DTR!D76+'Dai Loc'!D76+'Dong Lam'!D76+'Khanh Nga'!D76+TDP!D76+DTRVL!D76 -> 0 | E76: =DTR!E76+'Dai Loc'!E76+'Dong Lam'!E76+'Khanh Nga'!E76+TDP!E76+DTRVL!E76 -> 0 | F76: =DTR!F76+'Dai Loc'!F76+'Dong Lam'!F76+'Khanh Nga'!F76+TDP!F76+DTRVL!F76 -> 0 | G76: =DTR!G76+'Dai Loc'!G76+'Dong Lam'!G76+'Khanh Nga'!G76+TDP!G76+DTRVL!G76 -> 0 | H76: =DTR!H76+'Dai Loc'!H76+'Dong Lam'!H76+'Khanh Nga'!H76+TDP!H76+DTRVL!H76 -> 0 | I76: =DTR!I76+'Dai Loc'!I76+'Dong Lam'!I76+'Khanh Nga'!I76+TDP!I76+DTRVL!I76 -> 0 | J76: =DTR!J76+'Dai Loc'!J76+'Dong Lam'!J76+'Khanh Nga'!J76+TDP!J76+DTRVL!J76 -> 0 | ... Z76: =DTR!Z76+'Dai Loc'!Z76+'Dong Lam'!Z76+'Khanh Nga'!Z76+TDP!Z76+DTRVL!Z76 -> 0
A77: 6.Dự phòng đầu tư nắm giữ đến ngày đáo hạn dài hạn (*) | B77: 72
A78: VII.Tài sản dài hạn khác | B78: 73 | C78: =DTR!C78+'Dai Loc'!C78+'Dong Lam'!C78+'Khanh Nga'!C78+TDP!C78+DTRVL!C78 -> 5400042499 | D78: =DTR!D78+'Dai Loc'!D78+'Dong Lam'!D78+'Khanh Nga'!D78+TDP!D78+DTRVL!D78 -> 5122374256 | E78: =DTR!E78+'Dai Loc'!E78+'Dong Lam'!E78+'Khanh Nga'!E78+TDP!E78+DTRVL!E78 -> 6108142400 | F78: =DTR!F78+'Dai Loc'!F78+'Dong Lam'!F78+'Khanh Nga'!F78+TDP!F78+DTRVL!F78 -> 6691697581 | G78: =DTR!G78+'Dai Loc'!G78+'Dong Lam'!G78+'Khanh Nga'!G78+TDP!G78+DTRVL!G78 -> 6073217039 | H78: =DTR!H78+'Dai Loc'!H78+'Dong Lam'!H78+'Khanh Nga'!H78+TDP!H78+DTRVL!H78 -> 5922983520 | I78: =DTR!I78+'Dai Loc'!I78+'Dong Lam'!I78+'Khanh Nga'!I78+TDP!I78+DTRVL!I78 -> 6293381718 | J78: =DTR!J78+'Dai Loc'!J78+'Dong Lam'!J78+'Khanh Nga'!J78+TDP!J78+DTRVL!J78 -> 7144685884 | ... Z78: =DTR!Z78+'Dai Loc'!Z78+'Dong Lam'!Z78+'Khanh Nga'!Z78+TDP!Z78+DTRVL!Z78 -> 11383330015
A79: 1.Chi phí chờ phân bổ dài hạn | B79: 74 | C79: =DTR!C79+'Dai Loc'!C79+'Dong Lam'!C79+'Khanh Nga'!C79+TDP!C79+DTRVL!C79 -> 5400042499 | D79: =DTR!D79+'Dai Loc'!D79+'Dong Lam'!D79+'Khanh Nga'!D79+TDP!D79+DTRVL!D79 -> 5122374256 | E79: =DTR!E79+'Dai Loc'!E79+'Dong Lam'!E79+'Khanh Nga'!E79+TDP!E79+DTRVL!E79 -> 6108142400 | F79: =DTR!F79+'Dai Loc'!F79+'Dong Lam'!F79+'Khanh Nga'!F79+TDP!F79+DTRVL!F79 -> 6691697581 | G79: =DTR!G79+'Dai Loc'!G79+'Dong Lam'!G79+'Khanh Nga'!G79+TDP!G79+DTRVL!G79 -> 6073217039 | H79: =DTR!H79+'Dai Loc'!H79+'Dong Lam'!H79+'Khanh Nga'!H79+TDP!H79+DTRVL!H79 -> 5922983520 | I79: =DTR!I79+'Dai Loc'!I79+'Dong Lam'!I79+'Khanh Nga'!I79+TDP!I79+DTRVL!I79 -> 6293381718 | J79: =DTR!J79+'Dai Loc'!J79+'Dong Lam'!J79+'Khanh Nga'!J79+TDP!J79+DTRVL!J79 -> 7144685884 | ... Z79: =DTR!Z79+'Dai Loc'!Z79+'Dong Lam'!Z79+'Khanh Nga'!Z79+TDP!Z79+DTRVL!Z79 -> 11383330015
A80: 2.Tài sản thuế thu nhập hoãn lại | B80: 75 | C80: =DTR!C80+'Dai Loc'!C80+'Dong Lam'!C80+'Khanh Nga'!C80+TDP!C80+DTRVL!C80 -> 0 | D80: =DTR!D80+'Dai Loc'!D80+'Dong Lam'!D80+'Khanh Nga'!D80+TDP!D80+DTRVL!D80 -> 0 | E80: =DTR!E80+'Dai Loc'!E80+'Dong Lam'!E80+'Khanh Nga'!E80+TDP!E80+DTRVL!E80 -> 0 | F80: =DTR!F80+'Dai Loc'!F80+'Dong Lam'!F80+'Khanh Nga'!F80+TDP!F80+DTRVL!F80 -> 0 | G80: =DTR!G80+'Dai Loc'!G80+'Dong Lam'!G80+'Khanh Nga'!G80+TDP!G80+DTRVL!G80 -> 0 | H80: =DTR!H80+'Dai Loc'!H80+'Dong Lam'!H80+'Khanh Nga'!H80+TDP!H80+DTRVL!H80 -> 0 | I80: =DTR!I80+'Dai Loc'!I80+'Dong Lam'!I80+'Khanh Nga'!I80+TDP!I80+DTRVL!I80 -> 0 | J80: =DTR!J80+'Dai Loc'!J80+'Dong Lam'!J80+'Khanh Nga'!J80+TDP!J80+DTRVL!J80 -> 0 | ... Z80: =DTR!Z80+'Dai Loc'!Z80+'Dong Lam'!Z80+'Khanh Nga'!Z80+TDP!Z80+DTRVL!Z80 -> 0
A81: 3.Thiết bị, vật tư, phụ tùng thay thế dài hạn | B81: 76 | C81: =DTR!C81+'Dai Loc'!C81+'Dong Lam'!C81+'Khanh Nga'!C81+TDP!C81+DTRVL!C81 -> 0 | D81: =DTR!D81+'Dai Loc'!D81+'Dong Lam'!D81+'Khanh Nga'!D81+TDP!D81+DTRVL!D81 -> 0 | E81: =DTR!E81+'Dai Loc'!E81+'Dong Lam'!E81+'Khanh Nga'!E81+TDP!E81+DTRVL!E81 -> 0 | F81: =DTR!F81+'Dai Loc'!F81+'Dong Lam'!F81+'Khanh Nga'!F81+TDP!F81+DTRVL!F81 -> 0 | G81: =DTR!G81+'Dai Loc'!G81+'Dong Lam'!G81+'Khanh Nga'!G81+TDP!G81+DTRVL!G81 -> 0 | H81: =DTR!H81+'Dai Loc'!H81+'Dong Lam'!H81+'Khanh Nga'!H81+TDP!H81+DTRVL!H81 -> 0 | I81: =DTR!I81+'Dai Loc'!I81+'Dong Lam'!I81+'Khanh Nga'!I81+TDP!I81+DTRVL!I81 -> 0 | J81: =DTR!J81+'Dai Loc'!J81+'Dong Lam'!J81+'Khanh Nga'!J81+TDP!J81+DTRVL!J81 -> 0 | ... Z81: =DTR!Z81+'Dai Loc'!Z81+'Dong Lam'!Z81+'Khanh Nga'!Z81+TDP!Z81+DTRVL!Z81 -> 0
A82: 4.Tài sản dài hạn khác | B82: 77 | C82: =DTR!C82+'Dai Loc'!C82+'Dong Lam'!C82+'Khanh Nga'!C82+TDP!C82+DTRVL!C82 -> 0 | D82: =DTR!D82+'Dai Loc'!D82+'Dong Lam'!D82+'Khanh Nga'!D82+TDP!D82+DTRVL!D82 -> 0 | E82: =DTR!E82+'Dai Loc'!E82+'Dong Lam'!E82+'Khanh Nga'!E82+TDP!E82+DTRVL!E82 -> 0 | F82: =DTR!F82+'Dai Loc'!F82+'Dong Lam'!F82+'Khanh Nga'!F82+TDP!F82+DTRVL!F82 -> 0 | G82: =DTR!G82+'Dai Loc'!G82+'Dong Lam'!G82+'Khanh Nga'!G82+TDP!G82+DTRVL!G82 -> 0 | H82: =DTR!H82+'Dai Loc'!H82+'Dong Lam'!H82+'Khanh Nga'!H82+TDP!H82+DTRVL!H82 -> 0 | I82: =DTR!I82+'Dai Loc'!I82+'Dong Lam'!I82+'Khanh Nga'!I82+TDP!I82+DTRVL!I82 -> 0 | J82: =DTR!J82+'Dai Loc'!J82+'Dong Lam'!J82+'Khanh Nga'!J82+TDP!J82+DTRVL!J82 -> 0 | ... Z82: =DTR!Z82+'Dai Loc'!Z82+'Dong Lam'!Z82+'Khanh Nga'!Z82+TDP!Z82+DTRVL!Z82 -> 0
A83: TỔNG TÀI SẢN | B83: 78 | C83: =DTR!C83+'Dai Loc'!C83+'Dong Lam'!C83+'Khanh Nga'!C83+TDP!C83+DTRVL!C83 -> 1175130402352 | D83: =DTR!D83+'Dai Loc'!D83+'Dong Lam'!D83+'Khanh Nga'!D83+TDP!D83+DTRVL!D83 -> 1156870558457 | E83: =DTR!E83+'Dai Loc'!E83+'Dong Lam'!E83+'Khanh Nga'!E83+TDP!E83+DTRVL!E83 -> 1.1935024e+12 | F83: =DTR!F83+'Dai Loc'!F83+'Dong Lam'!F83+'Khanh Nga'!F83+TDP!F83+DTRVL!F83 -> 1.2545406e+12 | G83: =DTR!G83+'Dai Loc'!G83+'Dong Lam'!G83+'Khanh Nga'!G83+TDP!G83+DTRVL!G83 -> 1298938884161 | H83: =DTR!H83+'Dai Loc'!H83+'Dong Lam'!H83+'Khanh Nga'!H83+TDP!H83+DTRVL!H83 -> 1325603983311 | I83: =DTR!I83+'Dai Loc'!I83+'Dong Lam'!I83+'Khanh Nga'!I83+TDP!I83+DTRVL!I83 -> 1267478798902 | J83: =DTR!J83+'Dai Loc'!J83+'Dong Lam'!J83+'Khanh Nga'!J83+TDP!J83+DTRVL!J83 -> 1218289415966 | ... Z83: =DTR!Z83+'Dai Loc'!Z83+'Dong Lam'!Z83+'Khanh Nga'!Z83+TDP!Z83+DTRVL!Z83 -> 1399120322090
A84: C-NỢ PHẢI TRẢ | B84: 79 | C84: =DTR!C84+'Dai Loc'!C84+'Dong Lam'!C84+'Khanh Nga'!C84+TDP!C84+DTRVL!C84 -> 319278887594 | D84: =DTR!D84+'Dai Loc'!D84+'Dong Lam'!D84+'Khanh Nga'!D84+TDP!D84+DTRVL!D84 -> 307757355551 | E84: =DTR!E84+'Dai Loc'!E84+'Dong Lam'!E84+'Khanh Nga'!E84+TDP!E84+DTRVL!E84 -> 3.4713248e+11 | F84: =DTR!F84+'Dai Loc'!F84+'Dong Lam'!F84+'Khanh Nga'!F84+TDP!F84+DTRVL!F84 -> 4.0650239e+11 | G84: =DTR!G84+'Dai Loc'!G84+'Dong Lam'!G84+'Khanh Nga'!G84+TDP!G84+DTRVL!G84 -> 456592470300 | H84: =DTR!H84+'Dai Loc'!H84+'Dong Lam'!H84+'Khanh Nga'!H84+TDP!H84+DTRVL!H84 -> 495400218095 | I84: =DTR!I84+'Dai Loc'!I84+'Dong Lam'!I84+'Khanh Nga'!I84+TDP!I84+DTRVL!I84 -> 452469310020 | J84: =DTR!J84+'Dai Loc'!J84+'Dong Lam'!J84+'Khanh Nga'!J84+TDP!J84+DTRVL!J84 -> 413326247943 | ... Z84: =DTR!Z84+'Dai Loc'!Z84+'Dong Lam'!Z84+'Khanh Nga'!Z84+TDP!Z84+DTRVL!Z84 -> 451967241879
A85: I.Nợ ngắn hạn | B85: 80 | C85: =DTR!C85+'Dai Loc'!C85+'Dong Lam'!C85+'Khanh Nga'!C85+TDP!C85+DTRVL!C85 -> 208892476524 | D85: =DTR!D85+'Dai Loc'!D85+'Dong Lam'!D85+'Khanh Nga'!D85+TDP!D85+DTRVL!D85 -> 197465004481 | E85: =DTR!E85+'Dai Loc'!E85+'Dong Lam'!E85+'Khanh Nga'!E85+TDP!E85+DTRVL!E85 -> 2.3689912e+11 | F85: =DTR!F85+'Dai Loc'!F85+'Dong Lam'!F85+'Khanh Nga'!F85+TDP!F85+DTRVL!F85 -> 2.9656423e+11 | G85: =DTR!G85+'Dai Loc'!G85+'Dong Lam'!G85+'Khanh Nga'!G85+TDP!G85+DTRVL!G85 -> 348607602622 | H85: =DTR!H85+'Dai Loc'!H85+'Dong Lam'!H85+'Khanh Nga'!H85+TDP!H85+DTRVL!H85 -> 386086182417 | I85: =DTR!I85+'Dai Loc'!I85+'Dong Lam'!I85+'Khanh Nga'!I85+TDP!I85+DTRVL!I85 -> 343042467734 | J85: =DTR!J85+'Dai Loc'!J85+'Dong Lam'!J85+'Khanh Nga'!J85+TDP!J85+DTRVL!J85 -> 304556465657 | ... Z85: =DTR!Z85+'Dai Loc'!Z85+'Dong Lam'!Z85+'Khanh Nga'!Z85+TDP!Z85+DTRVL!Z85 -> 368814987525
A86: 1.Phải trả người bán ngắn hạn | B86: 81 | C86: =DTR!C86+'Dai Loc'!C86+'Dong Lam'!C86+'Khanh Nga'!C86+TDP!C86+DTRVL!C86 -> 82949409956 | D86: =DTR!D86+'Dai Loc'!D86+'Dong Lam'!D86+'Khanh Nga'!D86+TDP!D86+DTRVL!D86 -> 85403340041 | E86: =DTR!E86+'Dai Loc'!E86+'Dong Lam'!E86+'Khanh Nga'!E86+TDP!E86+DTRVL!E86 -> 89847500656 | F86: =DTR!F86+'Dai Loc'!F86+'Dong Lam'!F86+'Khanh Nga'!F86+TDP!F86+DTRVL!F86 -> 92084070378 | G86: =DTR!G86+'Dai Loc'!G86+'Dong Lam'!G86+'Khanh Nga'!G86+TDP!G86+DTRVL!G86 -> 97185029412 | H86: =DTR!H86+'Dai Loc'!H86+'Dong Lam'!H86+'Khanh Nga'!H86+TDP!H86+DTRVL!H86 -> 129200888383 | I86: =DTR!I86+'Dai Loc'!I86+'Dong Lam'!I86+'Khanh Nga'!I86+TDP!I86+DTRVL!I86 -> 101456785709 | J86: =DTR!J86+'Dai Loc'!J86+'Dong Lam'!J86+'Khanh Nga'!J86+TDP!J86+DTRVL!J86 -> 115528799746 | ... Z86: =DTR!Z86+'Dai Loc'!Z86+'Dong Lam'!Z86+'Khanh Nga'!Z86+TDP!Z86+DTRVL!Z86 -> 35590749044
A87: 2.Người mua trả tiền trước ngắn hạn | B87: 82 | C87: =DTR!C87+'Dai Loc'!C87+'Dong Lam'!C87+'Khanh Nga'!C87+TDP!C87+DTRVL!C87 -> 4031903040 | D87: =DTR!D87+'Dai Loc'!D87+'Dong Lam'!D87+'Khanh Nga'!D87+TDP!D87+DTRVL!D87 -> 0 | E87: =DTR!E87+'Dai Loc'!E87+'Dong Lam'!E87+'Khanh Nga'!E87+TDP!E87+DTRVL!E87 -> -540918440 | F87: =DTR!F87+'Dai Loc'!F87+'Dong Lam'!F87+'Khanh Nga'!F87+TDP!F87+DTRVL!F87 -> 4278155246 | G87: =DTR!G87+'Dai Loc'!G87+'Dong Lam'!G87+'Khanh Nga'!G87+TDP!G87+DTRVL!G87 -> 14753134850 | H87: =DTR!H87+'Dai Loc'!H87+'Dong Lam'!H87+'Khanh Nga'!H87+TDP!H87+DTRVL!H87 -> 36030101433 | I87: =DTR!I87+'Dai Loc'!I87+'Dong Lam'!I87+'Khanh Nga'!I87+TDP!I87+DTRVL!I87 -> 34757495667 | J87: =DTR!J87+'Dai Loc'!J87+'Dong Lam'!J87+'Khanh Nga'!J87+TDP!J87+DTRVL!J87 -> 16991723009 | ... Z87: =DTR!Z87+'Dai Loc'!Z87+'Dong Lam'!Z87+'Khanh Nga'!Z87+TDP!Z87+DTRVL!Z87 -> 27242108550
A88: 3.Phải trả cổ tức, lợi nhuận | B88: 83 | C88: =DTR!C88+'Dai Loc'!C88+'Dong Lam'!C88+'Khanh Nga'!C88+TDP!C88+DTRVL!C88 -> 0 | D88: =DTR!D88+'Dai Loc'!D88+'Dong Lam'!D88+'Khanh Nga'!D88+TDP!D88+DTRVL!D88 -> 0 | E88: =DTR!E88+'Dai Loc'!E88+'Dong Lam'!E88+'Khanh Nga'!E88+TDP!E88+DTRVL!E88 -> 0 | F88: =DTR!F88+'Dai Loc'!F88+'Dong Lam'!F88+'Khanh Nga'!F88+TDP!F88+DTRVL!F88 -> 0 | G88: =DTR!G88+'Dai Loc'!G88+'Dong Lam'!G88+'Khanh Nga'!G88+TDP!G88+DTRVL!G88 -> 0 | H88: =DTR!H88+'Dai Loc'!H88+'Dong Lam'!H88+'Khanh Nga'!H88+TDP!H88+DTRVL!H88 -> 0 | I88: =DTR!I88+'Dai Loc'!I88+'Dong Lam'!I88+'Khanh Nga'!I88+TDP!I88+DTRVL!I88 -> 0 | J88: =DTR!J88+'Dai Loc'!J88+'Dong Lam'!J88+'Khanh Nga'!J88+TDP!J88+DTRVL!J88 -> 0 | ... Z88: =DTR!Z88+'Dai Loc'!Z88+'Dong Lam'!Z88+'Khanh Nga'!Z88+TDP!Z88+DTRVL!Z88 -> 0
A89: 4.Thuế và các khoản phải nộp Nhà nước ngắn hạn | B89: 84 | C89: =DTR!C89+'Dai Loc'!C89+'Dong Lam'!C89+'Khanh Nga'!C89+TDP!C89+DTRVL!C89 -> 10498883610 | D89: =DTR!D89+'Dai Loc'!D89+'Dong Lam'!D89+'Khanh Nga'!D89+TDP!D89+DTRVL!D89 -> 3689814164 | E89: =DTR!E89+'Dai Loc'!E89+'Dong Lam'!E89+'Khanh Nga'!E89+TDP!E89+DTRVL!E89 -> 4062755871 | F89: =DTR!F89+'Dai Loc'!F89+'Dong Lam'!F89+'Khanh Nga'!F89+TDP!F89+DTRVL!F89 -> 1384290807 | G89: =DTR!G89+'Dai Loc'!G89+'Dong Lam'!G89+'Khanh Nga'!G89+TDP!G89+DTRVL!G89 -> 2308850961 | H89: =DTR!H89+'Dai Loc'!H89+'Dong Lam'!H89+'Khanh Nga'!H89+TDP!H89+DTRVL!H89 -> 3118570444 | I89: =DTR!I89+'Dai Loc'!I89+'Dong Lam'!I89+'Khanh Nga'!I89+TDP!I89+DTRVL!I89 -> 1058457452 | J89: =DTR!J89+'Dai Loc'!J89+'Dong Lam'!J89+'Khanh Nga'!J89+TDP!J89+DTRVL!J89 -> 1211020482 | ... Z89: =DTR!Z89+'Dai Loc'!Z89+'Dong Lam'!Z89+'Khanh Nga'!Z89+TDP!Z89+DTRVL!Z89 -> 7281246280
... A131: TỔNG NGUỒN VỐN | B131: 126 | C131: =DTR!C131+'Dai Loc'!C131+'Dong Lam'!C131+'Khanh Nga'!C131+TDP!C131+DTRVL!C131 -> 1175130402352 | D131: =DTR!D131+'Dai Loc'!D131+'Dong Lam'!D131+'Khanh Nga'!D131+TDP!D131+DTRVL!D131 -> 1156870558457 | E131: =DTR!E131+'Dai Loc'!E131+'Dong Lam'!E131+'Khanh Nga'!E131+TDP!E131+DTRVL!E131 -> 1.1935024e+12 | F131: =DTR!F131+'Dai Loc'!F131+'Dong Lam'!F131+'Khanh Nga'!F131+TDP!F131+DTRVL!F131 -> 1.2545406e+12 | G131: =DTR!G131+'Dai Loc'!G131+'Dong Lam'!G131+'Khanh Nga'!G131+TDP!G131+DTRVL!G131 -> 1298938884161 | H131: =DTR!H131+'Dai Loc'!H131+'Dong Lam'!H131+'Khanh Nga'!H131+TDP!H131+DTRVL!H131 -> 1325603983311 | I131: =DTR!I131+'Dai Loc'!I131+'Dong Lam'!I131+'Khanh Nga'!I131+TDP!I131+DTRVL!I131 -> 1267478798902 | J131: =DTR!J131+'Dai Loc'!J131+'Dong Lam'!J131+'Khanh Nga'!J131+TDP!J131+DTRVL!J131 -> 1218289415966 | ... Z131: =DTR!Z131+'Dai Loc'!Z131+'Dong Lam'!Z131+'Khanh Nga'!Z131+TDP!Z131+DTRVL!Z131 -> 1399120322090
C132: =C131-C83 -> 0 | D132: =D131-D83 -> 0 | E132: =E131-E83 -> 0 | F132: =F131-F83 -> 0 | G132: =G131-G83 -> 0 | H132: =H131-H83 -> 0 | I132: =I131-I83 -> 0 | J132: =J131-J83 -> 0 | ... Z132: =Z131-Z83 -> 0
A133: PHẦN II-KẾT QUẢ HOẠT ĐỘNG KINH DOANH | B133: Index PL | C133: =C5 -> T01.2024 | D133: =D5 -> T02.2024 | E133: =E5 -> T03.2024 | F133: =F5 -> T04.2024 | G133: =G5 -> T05.2024 | H133: =H5 -> T06.2024 | I133: =I5 -> T07.2024 | J133: =J5 -> T08.2024 | ... Z133: =Z5 -> T12.2025 | AA133: T01.2026 | AB133: T02.2026 | AC133: T03.2026 | AD133: T04.2026 | AE133: T05.2026 | AF133: T06.2026 | AG133: T07.2026 | AH133: T08.2026 | AI133: T09.2026 | AJ133: T10.2026 | AK133: T11.2026 | AL133: T12.2026 | AM133: Hợp nhất 2026
A134: Sản lượng (Tấn) | B134: 1 | C134: =DTR!C134+'Dai Loc'!C134+'Dong Lam'!C134+'Khanh Nga'!C134+TDP!C134+DTRVL!C134 -> 5108.325 | D134: =DTR!D134+'Dai Loc'!D134+'Dong Lam'!D134+'Khanh Nga'!D134+TDP!D134+DTRVL!D134 -> 3038.375 | E134: =DTR!E134+'Dai Loc'!E134+'Dong Lam'!E134+'Khanh Nga'!E134+TDP!E134+DTRVL!E134 -> 4394.4 | F134: =DTR!F134+'Dai Loc'!F134+'Dong Lam'!F134+'Khanh Nga'!F134+TDP!F134+DTRVL!F134 -> 4434.75 | G134: =DTR!G134+'Dai Loc'!G134+'Dong Lam'!G134+'Khanh Nga'!G134+TDP!G134+DTRVL!G134 -> 4827.202 | H134: =DTR!H134+'Dai Loc'!H134+'Dong Lam'!H134+'Khanh Nga'!H134+TDP!H134+DTRVL!H134 -> 3532.75 | I134: =DTR!I134+'Dai Loc'!I134+'Dong Lam'!I134+'Khanh Nga'!I134+TDP!I134+DTRVL!I134 -> 2953.134 | J134: =DTR!J134+'Dai Loc'!J134+'Dong Lam'!J134+'Khanh Nga'!J134+TDP!J134+DTRVL!J134 -> 5764.9472 | ... Z134: =DTR!Z134+'Dai Loc'!Z134+'Dong Lam'!Z134+'Khanh Nga'!Z134+TDP!Z134+DTRVL!Z134 -> 4601 | AA134: =DTR!AA134 -> 4318.2229 | AB134: =DTR!AB134 -> 4253.3146 | AC134: =DTR!AC134 -> 4678.5574 | AD134: =DTR!AD134 -> 4394.2315 | AE134: =DTR!AE134 -> 4663.4364 | AF134: =DTR!AF134 -> 4691.9522 | AG134: =DTR!AG134 -> 4689.4225 | AH134: =DTR!AH134 -> 4562.8495 | ... AL134: =DTR!AL134 -> 4784.5204 | AM134: =SUM(AA134:AL134) -> 55000
A135: 1.Doanh thu bán hàng và cung cấp dịch vụ | B135: 2 | C135: =DTR!C135+'Dai Loc'!C135+'Dong Lam'!C135+'Khanh Nga'!C135+TDP!C135+DTRVL!C135 -> 130037940981 | D135: =DTR!D135+'Dai Loc'!D135+'Dong Lam'!D135+'Khanh Nga'!D135+TDP!D135+DTRVL!D135 -> 84645791256 | E135: =DTR!E135+'Dai Loc'!E135+'Dong Lam'!E135+'Khanh Nga'!E135+TDP!E135+DTRVL!E135 -> 115625416433 | F135: =DTR!F135+'Dai Loc'!F135+'Dong Lam'!F135+'Khanh Nga'!F135+TDP!F135+DTRVL!F135 -> 117647266094 | G135: =DTR!G135+'Dai Loc'!G135+'Dong Lam'!G135+'Khanh Nga'!G135+TDP!G135+DTRVL!G135 -> 128085507494 | H135: =DTR!H135+'Dai Loc'!H135+'Dong Lam'!H135+'Khanh Nga'!H135+TDP!H135+DTRVL!H135 -> 95661572209 | I135: =DTR!I135+'Dai Loc'!I135+'Dong Lam'!I135+'Khanh Nga'!I135+TDP!I135+DTRVL!I135 -> 74679662458 | J135: =DTR!J135+'Dai Loc'!J135+'Dong Lam'!J135+'Khanh Nga'!J135+TDP!J135+DTRVL!J135 -> 178936926222 | ... Z135: =DTR!Z135+'Dai Loc'!Z135+'Dong Lam'!Z135+'Khanh Nga'!Z135+TDP!Z135+DTRVL!Z135 -> 127334240251 | AA135: =AA137 -> 1.2950534e+11 | AB135: =AB137 -> 1.2797444e+11 | AC135: =AC137 -> 1.4159949e+11 | AD135: =AD137 -> 1.3178227e+11 | AE135: =AE137 -> 1.4024431e+11 | AF135: =AF137 -> 1.414093e+11 | AG135: =AG137 -> 1.4540406e+11 | AH135: =AH137 -> 1.4127636e+11 | ... AL135: =AL137 -> 1.4744201e+11 | AM135: =SUM(AA135:AL135) -> 1.6787476e+12
A136: 2.Các khoản giảm trừ doanh thu | B136: 3 | C136: =DTR!C136+'Dai Loc'!C136+'Dong Lam'!C136+'Khanh Nga'!C136+TDP!C136+DTRVL!C136 -> 0 | D136: =DTR!D136+'Dai Loc'!D136+'Dong Lam'!D136+'Khanh Nga'!D136+TDP!D136+DTRVL!D136 -> 1166125000 | E136: =DTR!E136+'Dai Loc'!E136+'Dong Lam'!E136+'Khanh Nga'!E136+TDP!E136+DTRVL!E136 -> 0 | F136: =DTR!F136+'Dai Loc'!F136+'Dong Lam'!F136+'Khanh Nga'!F136+TDP!F136+DTRVL!F136 -> 0 | G136: =DTR!G136+'Dai Loc'!G136+'Dong Lam'!G136+'Khanh Nga'!G136+TDP!G136+DTRVL!G136 -> 136455000 | H136: =DTR!H136+'Dai Loc'!H136+'Dong Lam'!H136+'Khanh Nga'!H136+TDP!H136+DTRVL!H136 -> 0 | I136: =DTR!I136+'Dai Loc'!I136+'Dong Lam'!I136+'Khanh Nga'!I136+TDP!I136+DTRVL!I136 -> 0 | J136: =DTR!J136+'Dai Loc'!J136+'Dong Lam'!J136+'Khanh Nga'!J136+TDP!J136+DTRVL!J136 -> 6345077301 | ... Z136: =DTR!Z136+'Dai Loc'!Z136+'Dong Lam'!Z136+'Khanh Nga'!Z136+TDP!Z136+DTRVL!Z136 -> -573868680 | AA136: ='Hop cong'!AA136 -> 0 | AB136: ='Hop cong'!AB136 -> 0 | AC136: ='Hop cong'!AC136 -> 0 | AD136: ='Hop cong'!AD136 -> 0 | AE136: ='Hop cong'!AE136 -> 0 | AF136: ='Hop cong'!AF136 -> 0 | AG136: ='Hop cong'!AG136 -> 0 | AH136: ='Hop cong'!AH136 -> 0 | ... AL136: ='Hop cong'!AL136 -> 0 | AM136: =SUM(AA136:AL136) -> 0
A137: 3.Doanh thu thuần về bán hàng và cung cấp dịch vụ | B137: 4 | C137: =DTR!C137+'Dai Loc'!C137+'Dong Lam'!C137+'Khanh Nga'!C137+TDP!C137+DTRVL!C137 -> 130037940981 | D137: =DTR!D137+'Dai Loc'!D137+'Dong Lam'!D137+'Khanh Nga'!D137+TDP!D137+DTRVL!D137 -> 83479666256 | E137: =DTR!E137+'Dai Loc'!E137+'Dong Lam'!E137+'Khanh Nga'!E137+TDP!E137+DTRVL!E137 -> 115625416433 | F137: =DTR!F137+'Dai Loc'!F137+'Dong Lam'!F137+'Khanh Nga'!F137+TDP!F137+DTRVL!F137 -> 117647266094 | G137: =DTR!G137+'Dai Loc'!G137+'Dong Lam'!G137+'Khanh Nga'!G137+TDP!G137+DTRVL!G137 -> 127949052494 | H137: =DTR!H137+'Dai Loc'!H137+'Dong Lam'!H137+'Khanh Nga'!H137+TDP!H137+DTRVL!H137 -> 95661572209 | I137: =DTR!I137+'Dai Loc'!I137+'Dong Lam'!I137+'Khanh Nga'!I137+TDP!I137+DTRVL!I137 -> 74679662458 | J137: =DTR!J137+'Dai Loc'!J137+'Dong Lam'!J137+'Khanh Nga'!J137+TDP!J137+DTRVL!J137 -> 172591848921 | ... Z137: =DTR!Z137+'Dai Loc'!Z137+'Dong Lam'!Z137+'Khanh Nga'!Z137+TDP!Z137+DTRVL!Z137 -> 127908108931 | AA137: ='Hop cong'!AA137-SUM(GDNB!H9:H11) -> 1.2950534e+11 | AB137: ='Hop cong'!AB137-SUM(GDNB!I9:I11) -> 1.2797444e+11 | AC137: ='Hop cong'!AC137-SUM(GDNB!J9:J11) -> 1.4159949e+11 | AD137: ='Hop cong'!AD137-SUM(GDNB!K9:K11) -> 1.3178227e+11 | AE137: ='Hop cong'!AE137-SUM(GDNB!L9:L11) -> 1.4024431e+11 | AF137: ='Hop cong'!AF137-SUM(GDNB!M9:M11) -> 1.414093e+11 | AG137: ='Hop cong'!AG137-SUM(GDNB!N9:N11) -> 1.4540406e+11 | AH137: ='Hop cong'!AH137-SUM(GDNB!O9:O11) -> 1.4127636e+11 | ... AL137: ='Hop cong'!AL137-SUM(GDNB!S9:S11) -> 1.4744201e+11 | AM137: =SUM(AA137:AL137) -> 1.6787476e+12
A138: 4.Giá vốn hàng bán | B138: 5 | C138: =DTR!C138+'Dai Loc'!C138+'Dong Lam'!C138+'Khanh Nga'!C138+TDP!C138+DTRVL!C138 -> 120065457134 | D138: =DTR!D138+'Dai Loc'!D138+'Dong Lam'!D138+'Khanh Nga'!D138+TDP!D138+DTRVL!D138 -> 83995360322 | E138: =DTR!E138+'Dai Loc'!E138+'Dong Lam'!E138+'Khanh Nga'!E138+TDP!E138+DTRVL!E138 -> 109165390822 | F138: =DTR!F138+'Dai Loc'!F138+'Dong Lam'!F138+'Khanh Nga'!F138+TDP!F138+DTRVL!F138 -> 105655387173 | G138: =DTR!G138+'Dai Loc'!G138+'Dong Lam'!G138+'Khanh Nga'!G138+TDP!G138+DTRVL!G138 -> 125507167216 | H138: =DTR!H138+'Dai Loc'!H138+'Dong Lam'!H138+'Khanh Nga'!H138+TDP!H138+DTRVL!H138 -> 98477492806 | I138: =DTR!I138+'Dai Loc'!I138+'Dong Lam'!I138+'Khanh Nga'!I138+TDP!I138+DTRVL!I138 -> 80393606783 | J138: =DTR!J138+'Dai Loc'!J138+'Dong Lam'!J138+'Khanh Nga'!J138+TDP!J138+DTRVL!J138 -> 167228552558 | ... Z138: =DTR!Z138+'Dai Loc'!Z138+'Dong Lam'!Z138+'Khanh Nga'!Z138+TDP!Z138+DTRVL!Z138 -> 90514001561 | AA138: ='Hop cong'!AA138-SUM(GDNB!H9:H11) -> 1.1123971e+11 | AB138: ='Hop cong'!AB138-SUM(GDNB!I9:I11) -> 1.1647829e+11 | AC138: ='Hop cong'!AC138-SUM(GDNB!J9:J11) -> 1.2020251e+11 | AD138: ='Hop cong'!AD138-SUM(GDNB!K9:K11) -> 1.1256952e+11 | AE138: ='Hop cong'!AE138-SUM(GDNB!L9:L11) -> 1.1880678e+11 | AF138: ='Hop cong'!AF138-SUM(GDNB!M9:M11) -> 1.2105992e+11 | AG138: ='Hop cong'!AG138-SUM(GDNB!N9:N11) -> 1.1938279e+11 | AH138: ='Hop cong'!AH138-SUM(GDNB!O9:O11) -> 1.1588108e+11 | ... AL138: ='Hop cong'!AL138-SUM(GDNB!S9:S11) -> 1.2206924e+11 | AM138: =SUM(AA138:AL138) -> 1.4141767e+12
A139: 5.Lợi nhuận gộp về bán hàng | B139: 6 | C139: =DTR!C139+'Dai Loc'!C139+'Dong Lam'!C139+'Khanh Nga'!C139+TDP!C139+DTRVL!C139 -> 9972483847 | D139: =DTR!D139+'Dai Loc'!D139+'Dong Lam'!D139+'Khanh Nga'!D139+TDP!D139+DTRVL!D139 -> -515694066 | E139: =DTR!E139+'Dai Loc'!E139+'Dong Lam'!E139+'Khanh Nga'!E139+TDP!E139+DTRVL!E139 -> 6460025611 | F139: =DTR!F139+'Dai Loc'!F139+'Dong Lam'!F139+'Khanh Nga'!F139+TDP!F139+DTRVL!F139 -> 11991878921 | G139: =DTR!G139+'Dai Loc'!G139+'Dong Lam'!G139+'Khanh Nga'!G139+TDP!G139+DTRVL!G139 -> 2441885278 | H139: =DTR!H139+'Dai Loc'!H139+'Dong Lam'!H139+'Khanh Nga'!H139+TDP!H139+DTRVL!H139 -> -2815920597 | I139: =DTR!I139+'Dai Loc'!I139+'Dong Lam'!I139+'Khanh Nga'!I139+TDP!I139+DTRVL!I139 -> -5713944325 | J139: =DTR!J139+'Dai Loc'!J139+'Dong Lam'!J139+'Khanh Nga'!J139+TDP!J139+DTRVL!J139 -> 5363296363 | ... Z139: =DTR!Z139+'Dai Loc'!Z139+'Dong Lam'!Z139+'Khanh Nga'!Z139+TDP!Z139+DTRVL!Z139 -> 37394107370 | AA139: =AA137-AA138 -> 1.8265635e+10 | AB139: =AB137-AB138 -> 1.1496149e+10 | AC139: =AC137-AC138 -> 2.1396983e+10 | AD139: =AD137-AD138 -> 1.9212745e+10 | AE139: =AE137-AE138 -> 2.1437525e+10 | AF139: =AF137-AF138 -> 2.0349382e+10 | AG139: =AG137-AG138 -> 2.6021268e+10 | AH139: =AH137-AH138 -> 2.5395279e+10 | ... AL139: =AL137-AL138 -> 2.5372778e+10 | AM139: =SUM(AA139:AL139) -> 2.6457089e+11
...

Sheet Hop cong
A1: GROUP (CONBINE TÁI CHẾ & THU MUA) | O1: 2025
A2: VND
C3: 2024 | D3: =C3 -> 2024 | E3: =D3 -> 2024 | F3: =E3 -> 2024 | G3: =F3 -> 2024 | H3: =G3 -> 2024 | I3: =H3 -> 2024 | J3: =I3 -> 2024 | K3: =J3 -> 2024 | ... N3: =M3 -> 2024 | O3: 2025 | P3: =O3 -> 2025 | Q3: =P3 -> 2025 | R3: =Q3 -> 2025 | S3: =R3 -> 2025 | T3: =S3 -> 2025 | U3: =T3 -> 2025 | V3: =U3 -> 2025 | W3: =V3 -> 2025 | ... Z3: =Y3 -> 2025
C4: 1 | D4: 2 | E4: 3 | F4: 4 | G4: 5 | H4: 6 | I4: 7 | J4: 8 | K4: 9 | L4: 10 | M4: 11 | N4: 12 | O4: 1 | P4: 2 | Q4: 3 | R4: 4 | S4: 5 | T4: 6 | U4: 7 | V4: 8 | W4: 9 | X4: 10 | Y4: 11 | Z4: 12
A5: PHẦN I-BÁO CÁO TÌNH HÌNH TÀI CHÍNH | B5: Index BS | C5: T01.2024 | D5: T02.2024 | E5: T03.2024 | F5: T04.2024 | G5: T05.2024 | H5: T06.2024 | I5: T07.2024 | J5: T08.2024 | K5: T09.2024 | L5: T10.2024 | M5: T11.2024 | N5: T12.2024 | O5: T01.2025 | P5: T02.2025 | Q5: T03.2025 | R5: T04.2025 | S5: T05.2025 | T5: T06.2025 | U5: T07.2025 | V5: T08.2025 | W5: T09.2025 | X5: T10.2025 | Y5: T11.2025 | Z5: T12.2025
A6: A-TÀI SẢN NGẮN HẠN | B6: 1 | C6: =DTR!C6+'Dai Loc'!C6+'Dong Lam'!C6+'Khanh Nga'!C6+TDP!C6+DTRVL!C6 -> 842504987537 | D6: =DTR!D6+'Dai Loc'!D6+'Dong Lam'!D6+'Khanh Nga'!D6+TDP!D6+DTRVL!D6 -> 828028218928 | E6: =DTR!E6+'Dai Loc'!E6+'Dong Lam'!E6+'Khanh Nga'!E6+TDP!E6+DTRVL!E6 -> 8.6664214e+11 | F6: =DTR!F6+'Dai Loc'!F6+'Dong Lam'!F6+'Khanh Nga'!F6+TDP!F6+DTRVL!F6 -> 9.2866377e+11 | G6: =DTR!G6+'Dai Loc'!G6+'Dong Lam'!G6+'Khanh Nga'!G6+TDP!G6+DTRVL!G6 -> 974972463666 | H6: =DTR!H6+'Dai Loc'!H6+'Dong Lam'!H6+'Khanh Nga'!H6+TDP!H6+DTRVL!H6 -> 1000977606992 | I6: =DTR!I6+'Dai Loc'!I6+'Dong Lam'!I6+'Khanh Nga'!I6+TDP!I6+DTRVL!I6 -> 945309048746 | J6: =DTR!J6+'Dai Loc'!J6+'Dong Lam'!J6+'Khanh Nga'!J6+TDP!J6+DTRVL!J6 -> 891517737502 | ... Z6: =DTR!Z6+'Dai Loc'!Z6+'Dong Lam'!Z6+'Khanh Nga'!Z6+TDP!Z6+DTRVL!Z6 -> 1027131422218
A7: I.Tiền và các khoản tương đương tiền | B7: 2 | C7: =DTR!C7+'Dai Loc'!C7+'Dong Lam'!C7+'Khanh Nga'!C7+TDP!C7+DTRVL!C7 -> 46633249760 | D7: =DTR!D7+'Dai Loc'!D7+'Dong Lam'!D7+'Khanh Nga'!D7+TDP!D7+DTRVL!D7 -> 35851802774 | E7: =DTR!E7+'Dai Loc'!E7+'Dong Lam'!E7+'Khanh Nga'!E7+TDP!E7+DTRVL!E7 -> 26393055917 | F7: =DTR!F7+'Dai Loc'!F7+'Dong Lam'!F7+'Khanh Nga'!F7+TDP!F7+DTRVL!F7 -> 34593153167 | G7: =DTR!G7+'Dai Loc'!G7+'Dong Lam'!G7+'Khanh Nga'!G7+TDP!G7+DTRVL!G7 -> 33199136312 | H7: =DTR!H7+'Dai Loc'!H7+'Dong Lam'!H7+'Khanh Nga'!H7+TDP!H7+DTRVL!H7 -> 19638634542 | I7: =DTR!I7+'Dai Loc'!I7+'Dong Lam'!I7+'Khanh Nga'!I7+TDP!I7+DTRVL!I7 -> 56271006190 | J7: =DTR!J7+'Dai Loc'!J7+'Dong Lam'!J7+'Khanh Nga'!J7+TDP!J7+DTRVL!J7 -> 35429490170 | ... Z7: =DTR!Z7+'Dai Loc'!Z7+'Dong Lam'!Z7+'Khanh Nga'!Z7+TDP!Z7+DTRVL!Z7 -> 63226156108
A8: 1.Tiền | B8: 3 | C8: =DTR!C8+'Dai Loc'!C8+'Dong Lam'!C8+'Khanh Nga'!C8+TDP!C8+DTRVL!C8 -> 39793249760 | D8: =DTR!D8+'Dai Loc'!D8+'Dong Lam'!D8+'Khanh Nga'!D8+TDP!D8+DTRVL!D8 -> 29011802774 | E8: =DTR!E8+'Dai Loc'!E8+'Dong Lam'!E8+'Khanh Nga'!E8+TDP!E8+DTRVL!E8 -> 21563055917 | F8: =DTR!F8+'Dai Loc'!F8+'Dong Lam'!F8+'Khanh Nga'!F8+TDP!F8+DTRVL!F8 -> 25763153167 | G8: =DTR!G8+'Dai Loc'!G8+'Dong Lam'!G8+'Khanh Nga'!G8+TDP!G8+DTRVL!G8 -> 24369136312 | H8: =DTR!H8+'Dai Loc'!H8+'Dong Lam'!H8+'Khanh Nga'!H8+TDP!H8+DTRVL!H8 -> 14808634542 | I8: =DTR!I8+'Dai Loc'!I8+'Dong Lam'!I8+'Khanh Nga'!I8+TDP!I8+DTRVL!I8 -> 48441006190 | J8: =DTR!J8+'Dai Loc'!J8+'Dong Lam'!J8+'Khanh Nga'!J8+TDP!J8+DTRVL!J8 -> 27599490170 | ... Z8: =DTR!Z8+'Dai Loc'!Z8+'Dong Lam'!Z8+'Khanh Nga'!Z8+TDP!Z8+DTRVL!Z8 -> 53526156108
A9: 2.Các khoản tương đương tiền | B9: 4 | C9: =DTR!C9+'Dai Loc'!C9+'Dong Lam'!C9+'Khanh Nga'!C9+TDP!C9+DTRVL!C9 -> 6840000000 | D9: =DTR!D9+'Dai Loc'!D9+'Dong Lam'!D9+'Khanh Nga'!D9+TDP!D9+DTRVL!D9 -> 6840000000 | E9: =DTR!E9+'Dai Loc'!E9+'Dong Lam'!E9+'Khanh Nga'!E9+TDP!E9+DTRVL!E9 -> 4830000000 | F9: =DTR!F9+'Dai Loc'!F9+'Dong Lam'!F9+'Khanh Nga'!F9+TDP!F9+DTRVL!F9 -> 8830000000 | G9: =DTR!G9+'Dai Loc'!G9+'Dong Lam'!G9+'Khanh Nga'!G9+TDP!G9+DTRVL!G9 -> 8830000000 | H9: =DTR!H9+'Dai Loc'!H9+'Dong Lam'!H9+'Khanh Nga'!H9+TDP!H9+DTRVL!H9 -> 4830000000 | I9: =DTR!I9+'Dai Loc'!I9+'Dong Lam'!I9+'Khanh Nga'!I9+TDP!I9+DTRVL!I9 -> 7830000000 | J9: =DTR!J9+'Dai Loc'!J9+'Dong Lam'!J9+'Khanh Nga'!J9+TDP!J9+DTRVL!J9 -> 7830000000 | ... Z9: =DTR!Z9+'Dai Loc'!Z9+'Dong Lam'!Z9+'Khanh Nga'!Z9+TDP!Z9+DTRVL!Z9 -> 9700000000
A10: II.Đầu tư tài chính ngắn hạn | B10: 5 | C10: =DTR!C10+'Dai Loc'!C10+'Dong Lam'!C10+'Khanh Nga'!C10+TDP!C10+DTRVL!C10 -> 108051581921 | D10: =DTR!D10+'Dai Loc'!D10+'Dong Lam'!D10+'Khanh Nga'!D10+TDP!D10+DTRVL!D10 -> 108041861921 | E10: =DTR!E10+'Dai Loc'!E10+'Dong Lam'!E10+'Khanh Nga'!E10+TDP!E10+DTRVL!E10 -> 108032141921 | F10: =DTR!F10+'Dai Loc'!F10+'Dong Lam'!F10+'Khanh Nga'!F10+TDP!F10+DTRVL!F10 -> 97522421921 | G10: =DTR!G10+'Dai Loc'!G10+'Dong Lam'!G10+'Khanh Nga'!G10+TDP!G10+DTRVL!G10 -> 97512701921 | H10: =DTR!H10+'Dai Loc'!H10+'Dong Lam'!H10+'Khanh Nga'!H10+TDP!H10+DTRVL!H10 -> 77502981921 | I10: =DTR!I10+'Dai Loc'!I10+'Dong Lam'!I10+'Khanh Nga'!I10+TDP!I10+DTRVL!I10 -> 57993261921 | J10: =DTR!J10+'Dai Loc'!J10+'Dong Lam'!J10+'Khanh Nga'!J10+TDP!J10+DTRVL!J10 -> 57983541921 | ... Z10: =DTR!Z10+'Dai Loc'!Z10+'Dong Lam'!Z10+'Khanh Nga'!Z10+TDP!Z10+DTRVL!Z10 -> 79901021921
A11: 1.Chứng khoán kinh doanh | B11: 6 | C11: =DTR!C11+'Dai Loc'!C11+'Dong Lam'!C11+'Khanh Nga'!C11+TDP!C11+DTRVL!C11 -> 0 | D11: =DTR!D11+'Dai Loc'!D11+'Dong Lam'!D11+'Khanh Nga'!D11+TDP!D11+DTRVL!D11 -> 0 | E11: =DTR!E11+'Dai Loc'!E11+'Dong Lam'!E11+'Khanh Nga'!E11+TDP!E11+DTRVL!E11 -> 0 | F11: =DTR!F11+'Dai Loc'!F11+'Dong Lam'!F11+'Khanh Nga'!F11+TDP!F11+DTRVL!F11 -> 0 | G11: =DTR!G11+'Dai Loc'!G11+'Dong Lam'!G11+'Khanh Nga'!G11+TDP!G11+DTRVL!G11 -> 0 | H11: =DTR!H11+'Dai Loc'!H11+'Dong Lam'!H11+'Khanh Nga'!H11+TDP!H11+DTRVL!H11 -> 0 | I11: =DTR!I11+'Dai Loc'!I11+'Dong Lam'!I11+'Khanh Nga'!I11+TDP!I11+DTRVL!I11 -> 0 | J11: =DTR!J11+'Dai Loc'!J11+'Dong Lam'!J11+'Khanh Nga'!J11+TDP!J11+DTRVL!J11 -> 0 | ... Z11: =DTR!Z11+'Dai Loc'!Z11+'Dong Lam'!Z11+'Khanh Nga'!Z11+TDP!Z11+DTRVL!Z11 -> 0
A12: 2.Dự phòng giảm giá chứng khoán kinh doanh (*) | B12: 7 | C12: =DTR!C12+'Dai Loc'!C12+'Dong Lam'!C12+'Khanh Nga'!C12+TDP!C12+DTRVL!C12 -> 0 | D12: =DTR!D12+'Dai Loc'!D12+'Dong Lam'!D12+'Khanh Nga'!D12+TDP!D12+DTRVL!D12 -> 0 | E12: =DTR!E12+'Dai Loc'!E12+'Dong Lam'!E12+'Khanh Nga'!E12+TDP!E12+DTRVL!E12 -> 0 | F12: =DTR!F12+'Dai Loc'!F12+'Dong Lam'!F12+'Khanh Nga'!F12+TDP!F12+DTRVL!F12 -> 0 | G12: =DTR!G12+'Dai Loc'!G12+'Dong Lam'!G12+'Khanh Nga'!G12+TDP!G12+DTRVL!G12 -> 0 | H12: =DTR!H12+'Dai Loc'!H12+'Dong Lam'!H12+'Khanh Nga'!H12+TDP!H12+DTRVL!H12 -> 0 | I12: =DTR!I12+'Dai Loc'!I12+'Dong Lam'!I12+'Khanh Nga'!I12+TDP!I12+DTRVL!I12 -> 0 | J12: =DTR!J12+'Dai Loc'!J12+'Dong Lam'!J12+'Khanh Nga'!J12+TDP!J12+DTRVL!J12 -> 0 | ... Z12: =DTR!Z12+'Dai Loc'!Z12+'Dong Lam'!Z12+'Khanh Nga'!Z12+TDP!Z12+DTRVL!Z12 -> 0
A13: 3.Đầu tư nắm giữ đến ngày đáo hạn ngắn hạn | B13: 8 | C13: =DTR!C13+'Dai Loc'!C13+'Dong Lam'!C13+'Khanh Nga'!C13+TDP!C13+DTRVL!C13 -> 108051581921 | D13: =DTR!D13+'Dai Loc'!D13+'Dong Lam'!D13+'Khanh Nga'!D13+TDP!D13+DTRVL!D13 -> 108041861921 | E13: =DTR!E13+'Dai Loc'!E13+'Dong Lam'!E13+'Khanh Nga'!E13+TDP!E13+DTRVL!E13 -> 108032141921 | F13: =DTR!F13+'Dai Loc'!F13+'Dong Lam'!F13+'Khanh Nga'!F13+TDP!F13+DTRVL!F13 -> 97522421921 | G13: =DTR!G13+'Dai Loc'!G13+'Dong Lam'!G13+'Khanh Nga'!G13+TDP!G13+DTRVL!G13 -> 97512701921 | H13: =DTR!H13+'Dai Loc'!H13+'Dong Lam'!H13+'Khanh Nga'!H13+TDP!H13+DTRVL!H13 -> 77502981921 | I13: =DTR!I13+'Dai Loc'!I13+'Dong Lam'!I13+'Khanh Nga'!I13+TDP!I13+DTRVL!I13 -> 57993261921 | J13: =DTR!J13+'Dai Loc'!J13+'Dong Lam'!J13+'Khanh Nga'!J13+TDP!J13+DTRVL!J13 -> 57983541921 | ... Z13: =DTR!Z13+'Dai Loc'!Z13+'Dong Lam'!Z13+'Khanh Nga'!Z13+TDP!Z13+DTRVL!Z13 -> 79901021921
A14: 4.Dự phòng đầu tư nắm giữ đến ngày đáo hạn ngắn hạn (*) | B14: 9 | C14: =DTR!C14+'Dai Loc'!C14+'Dong Lam'!C14+'Khanh Nga'!C14+TDP!C14+DTRVL!C14 -> 0 | D14: =DTR!D14+'Dai Loc'!D14+'Dong Lam'!D14+'Khanh Nga'!D14+TDP!D14+DTRVL!D14 -> 0 | E14: =DTR!E14+'Dai Loc'!E14+'Dong Lam'!E14+'Khanh Nga'!E14+TDP!E14+DTRVL!E14 -> 0 | F14: =DTR!F14+'Dai Loc'!F14+'Dong Lam'!F14+'Khanh Nga'!F14+TDP!F14+DTRVL!F14 -> 0 | G14: =DTR!G14+'Dai Loc'!G14+'Dong Lam'!G14+'Khanh Nga'!G14+TDP!G14+DTRVL!G14 -> 0 | H14: =DTR!H14+'Dai Loc'!H14+'Dong Lam'!H14+'Khanh Nga'!H14+TDP!H14+DTRVL!H14 -> 0 | I14: =DTR!I14+'Dai Loc'!I14+'Dong Lam'!I14+'Khanh Nga'!I14+TDP!I14+DTRVL!I14 -> 0 | J14: =DTR!J14+'Dai Loc'!J14+'Dong Lam'!J14+'Khanh Nga'!J14+TDP!J14+DTRVL!J14 -> 0 | ... Z14: =DTR!Z14+'Dai Loc'!Z14+'Dong Lam'!Z14+'Khanh Nga'!Z14+TDP!Z14+DTRVL!Z14 -> 0
A15: 5.Đầu tư ngắn hạn khác | B15: 10 | C15: =DTR!C15+'Dai Loc'!C15+'Dong Lam'!C15+'Khanh Nga'!C15+TDP!C15+DTRVL!C15 -> 0 | D15: =DTR!D15+'Dai Loc'!D15+'Dong Lam'!D15+'Khanh Nga'!D15+TDP!D15+DTRVL!D15 -> 0 | E15: =DTR!E15+'Dai Loc'!E15+'Dong Lam'!E15+'Khanh Nga'!E15+TDP!E15+DTRVL!E15 -> 0 | F15: =DTR!F15+'Dai Loc'!F15+'Dong Lam'!F15+'Khanh Nga'!F15+TDP!F15+DTRVL!F15 -> 0 | G15: =DTR!G15+'Dai Loc'!G15+'Dong Lam'!G15+'Khanh Nga'!G15+TDP!G15+DTRVL!G15 -> 0 | H15: =DTR!H15+'Dai Loc'!H15+'Dong Lam'!H15+'Khanh Nga'!H15+TDP!H15+DTRVL!H15 -> 0 | I15: =DTR!I15+'Dai Loc'!I15+'Dong Lam'!I15+'Khanh Nga'!I15+TDP!I15+DTRVL!I15 -> 0 | J15: =DTR!J15+'Dai Loc'!J15+'Dong Lam'!J15+'Khanh Nga'!J15+TDP!J15+DTRVL!J15 -> 0 | ... Z15: =DTR!Z15+'Dai Loc'!Z15+'Dong Lam'!Z15+'Khanh Nga'!Z15+TDP!Z15+DTRVL!Z15 -> 0
A16: 6.Dự phòng tổn thất các khoản đầu tư ngắn hạn khác (*) | B16: 11 | C16: =DTR!C16+'Dai Loc'!C16+'Dong Lam'!C16+'Khanh Nga'!C16+TDP!C16+DTRVL!C16 -> 0 | D16: =DTR!D16+'Dai Loc'!D16+'Dong Lam'!D16+'Khanh Nga'!D16+TDP!D16+DTRVL!D16 -> 0 | E16: =DTR!E16+'Dai Loc'!E16+'Dong Lam'!E16+'Khanh Nga'!E16+TDP!E16+DTRVL!E16 -> 0 | F16: =DTR!F16+'Dai Loc'!F16+'Dong Lam'!F16+'Khanh Nga'!F16+TDP!F16+DTRVL!F16 -> 0 | G16: =DTR!G16+'Dai Loc'!G16+'Dong Lam'!G16+'Khanh Nga'!G16+TDP!G16+DTRVL!G16 -> 0 | H16: =DTR!H16+'Dai Loc'!H16+'Dong Lam'!H16+'Khanh Nga'!H16+TDP!H16+DTRVL!H16 -> 0 | I16: =DTR!I16+'Dai Loc'!I16+'Dong Lam'!I16+'Khanh Nga'!I16+TDP!I16+DTRVL!I16 -> 0 | J16: =DTR!J16+'Dai Loc'!J16+'Dong Lam'!J16+'Khanh Nga'!J16+TDP!J16+DTRVL!J16 -> 0 | ... Z16: =DTR!Z16+'Dai Loc'!Z16+'Dong Lam'!Z16+'Khanh Nga'!Z16+TDP!Z16+DTRVL!Z16 -> 0
A17: III.Các khoản phải thu ngắn hạn | B17: 12 | C17: =DTR!C17+'Dai Loc'!C17+'Dong Lam'!C17+'Khanh Nga'!C17+TDP!C17+DTRVL!C17 -> 2.0876077e+11 | D17: =DTR!D17+'Dai Loc'!D17+'Dong Lam'!D17+'Khanh Nga'!D17+TDP!D17+DTRVL!D17 -> 1.9391456e+11 | E17: =DTR!E17+'Dai Loc'!E17+'Dong Lam'!E17+'Khanh Nga'!E17+TDP!E17+DTRVL!E17 -> 201044728738 | F17: =DTR!F17+'Dai Loc'!F17+'Dong Lam'!F17+'Khanh Nga'!F17+TDP!F17+DTRVL!F17 -> 218534804131 | G17: =DTR!G17+'Dai Loc'!G17+'Dong Lam'!G17+'Khanh Nga'!G17+TDP!G17+DTRVL!G17 -> 2.2155237e+11 | H17: =DTR!H17+'Dai Loc'!H17+'Dong Lam'!H17+'Khanh Nga'!H17+TDP!H17+DTRVL!H17 -> 2.4767907e+11 | I17: =DTR!I17+'Dai Loc'!I17+'Dong Lam'!I17+'Khanh Nga'!I17+TDP!I17+DTRVL!I17 -> 1.528212e+11 | J17: =DTR!J17+'Dai Loc'!J17+'Dong Lam'!J17+'Khanh Nga'!J17+TDP!J17+DTRVL!J17 -> 1.7780637e+11 | ... Z17: =DTR!Z17+'Dai Loc'!Z17+'Dong Lam'!Z17+'Khanh Nga'!Z17+TDP!Z17+DTRVL!Z17 -> 287452852834
... A76: 5.Đầu tư nắm giữ đến ngày đáo hạn dài hạn | B76: 71 | C76: =DTR!C76+'Dai Loc'!C76+'Dong Lam'!C76+'Khanh Nga'!C76+TDP!C76+DTRVL!C76 -> 0 | D76: =DTR!D76+'Dai Loc'!D76+'Dong Lam'!D76+'Khanh Nga'!D76+TDP!D76+DTRVL!D76 -> 0 | E76: =DTR!E76+'Dai Loc'!E76+'Dong Lam'!E76+'Khanh Nga'!E76+TDP!E76+DTRVL!E76 -> 0 | F76: =DTR!F76+'Dai Loc'!F76+'Dong Lam'!F76+'Khanh Nga'!F76+TDP!F76+DTRVL!F76 -> 0 | G76: =DTR!G76+'Dai Loc'!G76+'Dong Lam'!G76+'Khanh Nga'!G76+TDP!G76+DTRVL!G76 -> 0 | H76: =DTR!H76+'Dai Loc'!H76+'Dong Lam'!H76+'Khanh Nga'!H76+TDP!H76+DTRVL!H76 -> 0 | I76: =DTR!I76+'Dai Loc'!I76+'Dong Lam'!I76+'Khanh Nga'!I76+TDP!I76+DTRVL!I76 -> 0 | J76: =DTR!J76+'Dai Loc'!J76+'Dong Lam'!J76+'Khanh Nga'!J76+TDP!J76+DTRVL!J76 -> 0 | ... Z76: =DTR!Z76+'Dai Loc'!Z76+'Dong Lam'!Z76+'Khanh Nga'!Z76+TDP!Z76+DTRVL!Z76 -> 0
A77: 6.Dự phòng đầu tư nắm giữ đến ngày đáo hạn dài hạn (*) | B77: 72
A78: VII.Tài sản dài hạn khác | B78: 73 | C78: =DTR!C78+'Dai Loc'!C78+'Dong Lam'!C78+'Khanh Nga'!C78+TDP!C78+DTRVL!C78 -> 5400042499 | D78: =DTR!D78+'Dai Loc'!D78+'Dong Lam'!D78+'Khanh Nga'!D78+TDP!D78+DTRVL!D78 -> 5122374256 | E78: =DTR!E78+'Dai Loc'!E78+'Dong Lam'!E78+'Khanh Nga'!E78+TDP!E78+DTRVL!E78 -> 6108142400 | F78: =DTR!F78+'Dai Loc'!F78+'Dong Lam'!F78+'Khanh Nga'!F78+TDP!F78+DTRVL!F78 -> 6691697581 | G78: =DTR!G78+'Dai Loc'!G78+'Dong Lam'!G78+'Khanh Nga'!G78+TDP!G78+DTRVL!G78 -> 6073217039 | H78: =DTR!H78+'Dai Loc'!H78+'Dong Lam'!H78+'Khanh Nga'!H78+TDP!H78+DTRVL!H78 -> 5922983520 | I78: =DTR!I78+'Dai Loc'!I78+'Dong Lam'!I78+'Khanh Nga'!I78+TDP!I78+DTRVL!I78 -> 6293381718 | J78: =DTR!J78+'Dai Loc'!J78+'Dong Lam'!J78+'Khanh Nga'!J78+TDP!J78+DTRVL!J78 -> 7144685884 | ... Z78: =DTR!Z78+'Dai Loc'!Z78+'Dong Lam'!Z78+'Khanh Nga'!Z78+TDP!Z78+DTRVL!Z78 -> 11383330015
A79: 1.Chi phí chờ phân bổ dài hạn | B79: 74 | C79: =DTR!C79+'Dai Loc'!C79+'Dong Lam'!C79+'Khanh Nga'!C79+TDP!C79+DTRVL!C79 -> 5400042499 | D79: =DTR!D79+'Dai Loc'!D79+'Dong Lam'!D79+'Khanh Nga'!D79+TDP!D79+DTRVL!D79 -> 5122374256 | E79: =DTR!E79+'Dai Loc'!E79+'Dong Lam'!E79+'Khanh Nga'!E79+TDP!E79+DTRVL!E79 -> 6108142400 | F79: =DTR!F79+'Dai Loc'!F79+'Dong Lam'!F79+'Khanh Nga'!F79+TDP!F79+DTRVL!F79 -> 6691697581 | G79: =DTR!G79+'Dai Loc'!G79+'Dong Lam'!G79+'Khanh Nga'!G79+TDP!G79+DTRVL!G79 -> 6073217039 | H79: =DTR!H79+'Dai Loc'!H79+'Dong Lam'!H79+'Khanh Nga'!H79+TDP!H79+DTRVL!H79 -> 5922983520 | I79: =DTR!I79+'Dai Loc'!I79+'Dong Lam'!I79+'Khanh Nga'!I79+TDP!I79+DTRVL!I79 -> 6293381718 | J79: =DTR!J79+'Dai Loc'!J79+'Dong Lam'!J79+'Khanh Nga'!J79+TDP!J79+DTRVL!J79 -> 7144685884 | ... Z79: =DTR!Z79+'Dai Loc'!Z79+'Dong Lam'!Z79+'Khanh Nga'!Z79+TDP!Z79+DTRVL!Z79 -> 11383330015
A80: 2.Tài sản thuế thu nhập hoãn lại | B80: 75 | C80: =DTR!C80+'Dai Loc'!C80+'Dong Lam'!C80+'Khanh Nga'!C80+TDP!C80+DTRVL!C80 -> 0 | D80: =DTR!D80+'Dai Loc'!D80+'Dong Lam'!D80+'Khanh Nga'!D80+TDP!D80+DTRVL!D80 -> 0 | E80: =DTR!E80+'Dai Loc'!E80+'Dong Lam'!E80+'Khanh Nga'!E80+TDP!E80+DTRVL!E80 -> 0 | F80: =DTR!F80+'Dai Loc'!F80+'Dong Lam'!F80+'Khanh Nga'!F80+TDP!F80+DTRVL!F80 -> 0 | G80: =DTR!G80+'Dai Loc'!G80+'Dong Lam'!G80+'Khanh Nga'!G80+TDP!G80+DTRVL!G80 -> 0 | H80: =DTR!H80+'Dai Loc'!H80+'Dong Lam'!H80+'Khanh Nga'!H80+TDP!H80+DTRVL!H80 -> 0 | I80: =DTR!I80+'Dai Loc'!I80+'Dong Lam'!I80+'Khanh Nga'!I80+TDP!I80+DTRVL!I80 -> 0 | J80: =DTR!J80+'Dai Loc'!J80+'Dong Lam'!J80+'Khanh Nga'!J80+TDP!J80+DTRVL!J80 -> 0 | ... Z80: =DTR!Z80+'Dai Loc'!Z80+'Dong Lam'!Z80+'Khanh Nga'!Z80+TDP!Z80+DTRVL!Z80 -> 0
A81: 3.Thiết bị, vật tư, phụ tùng thay thế dài hạn | B81: 76 | C81: =DTR!C81+'Dai Loc'!C81+'Dong Lam'!C81+'Khanh Nga'!C81+TDP!C81+DTRVL!C81 -> 0 | D81: =DTR!D81+'Dai Loc'!D81+'Dong Lam'!D81+'Khanh Nga'!D81+TDP!D81+DTRVL!D81 -> 0 | E81: =DTR!E81+'Dai Loc'!E81+'Dong Lam'!E81+'Khanh Nga'!E81+TDP!E81+DTRVL!E81 -> 0 | F81: =DTR!F81+'Dai Loc'!F81+'Dong Lam'!F81+'Khanh Nga'!F81+TDP!F81+DTRVL!F81 -> 0 | G81: =DTR!G81+'Dai Loc'!G81+'Dong Lam'!G81+'Khanh Nga'!G81+TDP!G81+DTRVL!G81 -> 0 | H81: =DTR!H81+'Dai Loc'!H81+'Dong Lam'!H81+'Khanh Nga'!H81+TDP!H81+DTRVL!H81 -> 0 | I81: =DTR!I81+'Dai Loc'!I81+'Dong Lam'!I81+'Khanh Nga'!I81+TDP!I81+DTRVL!I81 -> 0 | J81: =DTR!J81+'Dai Loc'!J81+'Dong Lam'!J81+'Khanh Nga'!J81+TDP!J81+DTRVL!J81 -> 0 | ... Z81: =DTR!Z81+'Dai Loc'!Z81+'Dong Lam'!Z81+'Khanh Nga'!Z81+TDP!Z81+DTRVL!Z81 -> 0
A82: 4.Tài sản dài hạn khác | B82: 77 | C82: =DTR!C82+'Dai Loc'!C82+'Dong Lam'!C82+'Khanh Nga'!C82+TDP!C82+DTRVL!C82 -> 0 | D82: =DTR!D82+'Dai Loc'!D82+'Dong Lam'!D82+'Khanh Nga'!D82+TDP!D82+DTRVL!D82 -> 0 | E82: =DTR!E82+'Dai Loc'!E82+'Dong Lam'!E82+'Khanh Nga'!E82+TDP!E82+DTRVL!E82 -> 0 | F82: =DTR!F82+'Dai Loc'!F82+'Dong Lam'!F82+'Khanh Nga'!F82+TDP!F82+DTRVL!F82 -> 0 | G82: =DTR!G82+'Dai Loc'!G82+'Dong Lam'!G82+'Khanh Nga'!G82+TDP!G82+DTRVL!G82 -> 0 | H82: =DTR!H82+'Dai Loc'!H82+'Dong Lam'!H82+'Khanh Nga'!H82+TDP!H82+DTRVL!H82 -> 0 | I82: =DTR!I82+'Dai Loc'!I82+'Dong Lam'!I82+'Khanh Nga'!I82+TDP!I82+DTRVL!I82 -> 0 | J82: =DTR!J82+'Dai Loc'!J82+'Dong Lam'!J82+'Khanh Nga'!J82+TDP!J82+DTRVL!J82 -> 0 | ... Z82: =DTR!Z82+'Dai Loc'!Z82+'Dong Lam'!Z82+'Khanh Nga'!Z82+TDP!Z82+DTRVL!Z82 -> 0
A83: TỔNG TÀI SẢN | B83: 78 | C83: =DTR!C83+'Dai Loc'!C83+'Dong Lam'!C83+'Khanh Nga'!C83+TDP!C83+DTRVL!C83 -> 1175130402352 | D83: =DTR!D83+'Dai Loc'!D83+'Dong Lam'!D83+'Khanh Nga'!D83+TDP!D83+DTRVL!D83 -> 1156870558457 | E83: =DTR!E83+'Dai Loc'!E83+'Dong Lam'!E83+'Khanh Nga'!E83+TDP!E83+DTRVL!E83 -> 1.1935024e+12 | F83: =DTR!F83+'Dai Loc'!F83+'Dong Lam'!F83+'Khanh Nga'!F83+TDP!F83+DTRVL!F83 -> 1.2545406e+12 | G83: =DTR!G83+'Dai Loc'!G83+'Dong Lam'!G83+'Khanh Nga'!G83+TDP!G83+DTRVL!G83 -> 1298938884161 | H83: =DTR!H83+'Dai Loc'!H83+'Dong Lam'!H83+'Khanh Nga'!H83+TDP!H83+DTRVL!H83 -> 1325603983311 | I83: =DTR!I83+'Dai Loc'!I83+'Dong Lam'!I83+'Khanh Nga'!I83+TDP!I83+DTRVL!I83 -> 1267478798902 | J83: =DTR!J83+'Dai Loc'!J83+'Dong Lam'!J83+'Khanh Nga'!J83+TDP!J83+DTRVL!J83 -> 1218289415966 | ... Z83: =DTR!Z83+'Dai Loc'!Z83+'Dong Lam'!Z83+'Khanh Nga'!Z83+TDP!Z83+DTRVL!Z83 -> 1399120322090
A84: C-NỢ PHẢI TRẢ | B84: 79 | C84: =DTR!C84+'Dai Loc'!C84+'Dong Lam'!C84+'Khanh Nga'!C84+TDP!C84+DTRVL!C84 -> 319278887594 | D84: =DTR!D84+'Dai Loc'!D84+'Dong Lam'!D84+'Khanh Nga'!D84+TDP!D84+DTRVL!D84 -> 307757355551 | E84: =DTR!E84+'Dai Loc'!E84+'Dong Lam'!E84+'Khanh Nga'!E84+TDP!E84+DTRVL!E84 -> 3.4713248e+11 | F84: =DTR!F84+'Dai Loc'!F84+'Dong Lam'!F84+'Khanh Nga'!F84+TDP!F84+DTRVL!F84 -> 4.0650239e+11 | G84: =DTR!G84+'Dai Loc'!G84+'Dong Lam'!G84+'Khanh Nga'!G84+TDP!G84+DTRVL!G84 -> 456592470300 | H84: =DTR!H84+'Dai Loc'!H84+'Dong Lam'!H84+'Khanh Nga'!H84+TDP!H84+DTRVL!H84 -> 495400218095 | I84: =DTR!I84+'Dai Loc'!I84+'Dong Lam'!I84+'Khanh Nga'!I84+TDP!I84+DTRVL!I84 -> 452469310020 | J84: =DTR!J84+'Dai Loc'!J84+'Dong Lam'!J84+'Khanh Nga'!J84+TDP!J84+DTRVL!J84 -> 413326247943 | ... Z84: =DTR!Z84+'Dai Loc'!Z84+'Dong Lam'!Z84+'Khanh Nga'!Z84+TDP!Z84+DTRVL!Z84 -> 451967241879
A85: I.Nợ ngắn hạn | B85: 80 | C85: =DTR!C85+'Dai Loc'!C85+'Dong Lam'!C85+'Khanh Nga'!C85+TDP!C85+DTRVL!C85 -> 208892476524 | D85: =DTR!D85+'Dai Loc'!D85+'Dong Lam'!D85+'Khanh Nga'!D85+TDP!D85+DTRVL!D85 -> 197465004481 | E85: =DTR!E85+'Dai Loc'!E85+'Dong Lam'!E85+'Khanh Nga'!E85+TDP!E85+DTRVL!E85 -> 2.3689912e+11 | F85: =DTR!F85+'Dai Loc'!F85+'Dong Lam'!F85+'Khanh Nga'!F85+TDP!F85+DTRVL!F85 -> 2.9656423e+11 | G85: =DTR!G85+'Dai Loc'!G85+'Dong Lam'!G85+'Khanh Nga'!G85+TDP!G85+DTRVL!G85 -> 348607602622 | H85: =DTR!H85+'Dai Loc'!H85+'Dong Lam'!H85+'Khanh Nga'!H85+TDP!H85+DTRVL!H85 -> 386086182417 | I85: =DTR!I85+'Dai Loc'!I85+'Dong Lam'!I85+'Khanh Nga'!I85+TDP!I85+DTRVL!I85 -> 343042467734 | J85: =DTR!J85+'Dai Loc'!J85+'Dong Lam'!J85+'Khanh Nga'!J85+TDP!J85+DTRVL!J85 -> 304556465657 | ... Z85: =DTR!Z85+'Dai Loc'!Z85+'Dong Lam'!Z85+'Khanh Nga'!Z85+TDP!Z85+DTRVL!Z85 -> 368814987525
A86: 1.Phải trả người bán ngắn hạn | B86: 81 | C86: =DTR!C86+'Dai Loc'!C86+'Dong Lam'!C86+'Khanh Nga'!C86+TDP!C86+DTRVL!C86 -> 82949409956 | D86: =DTR!D86+'Dai Loc'!D86+'Dong Lam'!D86+'Khanh Nga'!D86+TDP!D86+DTRVL!D86 -> 85403340041 | E86: =DTR!E86+'Dai Loc'!E86+'Dong Lam'!E86+'Khanh Nga'!E86+TDP!E86+DTRVL!E86 -> 89847500656 | F86: =DTR!F86+'Dai Loc'!F86+'Dong Lam'!F86+'Khanh Nga'!F86+TDP!F86+DTRVL!F86 -> 92084070378 | G86: =DTR!G86+'Dai Loc'!G86+'Dong Lam'!G86+'Khanh Nga'!G86+TDP!G86+DTRVL!G86 -> 97185029412 | H86: =DTR!H86+'Dai Loc'!H86+'Dong Lam'!H86+'Khanh Nga'!H86+TDP!H86+DTRVL!H86 -> 129200888383 | I86: =DTR!I86+'Dai Loc'!I86+'Dong Lam'!I86+'Khanh Nga'!I86+TDP!I86+DTRVL!I86 -> 101456785709 | J86: =DTR!J86+'Dai Loc'!J86+'Dong Lam'!J86+'Khanh Nga'!J86+TDP!J86+DTRVL!J86 -> 115528799746 | ... Z86: =DTR!Z86+'Dai Loc'!Z86+'Dong Lam'!Z86+'Khanh Nga'!Z86+TDP!Z86+DTRVL!Z86 -> 35590749044
A87: 2.Người mua trả tiền trước ngắn hạn | B87: 82 | C87: =DTR!C87+'Dai Loc'!C87+'Dong Lam'!C87+'Khanh Nga'!C87+TDP!C87+DTRVL!C87 -> 4031903040 | D87: =DTR!D87+'Dai Loc'!D87+'Dong Lam'!D87+'Khanh Nga'!D87+TDP!D87+DTRVL!D87 -> 0 | E87: =DTR!E87+'Dai Loc'!E87+'Dong Lam'!E87+'Khanh Nga'!E87+TDP!E87+DTRVL!E87 -> -540918440 | F87: =DTR!F87+'Dai Loc'!F87+'Dong Lam'!F87+'Khanh Nga'!F87+TDP!F87+DTRVL!F87 -> 4278155246 | G87: =DTR!G87+'Dai Loc'!G87+'Dong Lam'!G87+'Khanh Nga'!G87+TDP!G87+DTRVL!G87 -> 14753134850 | H87: =DTR!H87+'Dai Loc'!H87+'Dong Lam'!H87+'Khanh Nga'!H87+TDP!H87+DTRVL!H87 -> 36030101433 | I87: =DTR!I87+'Dai Loc'!I87+'Dong Lam'!I87+'Khanh Nga'!I87+TDP!I87+DTRVL!I87 -> 34757495667 | J87: =DTR!J87+'Dai Loc'!J87+'Dong Lam'!J87+'Khanh Nga'!J87+TDP!J87+DTRVL!J87 -> 16991723009 | ... Z87: =DTR!Z87+'Dai Loc'!Z87+'Dong Lam'!Z87+'Khanh Nga'!Z87+TDP!Z87+DTRVL!Z87 -> 27242108550
A88: 3.Phải trả cổ tức, lợi nhuận | B88: 83 | C88: =DTR!C88+'Dai Loc'!C88+'Dong Lam'!C88+'Khanh Nga'!C88+TDP!C88+DTRVL!C88 -> 0 | D88: =DTR!D88+'Dai Loc'!D88+'Dong Lam'!D88+'Khanh Nga'!D88+TDP!D88+DTRVL!D88 -> 0 | E88: =DTR!E88+'Dai Loc'!E88+'Dong Lam'!E88+'Khanh Nga'!E88+TDP!E88+DTRVL!E88 -> 0 | F88: =DTR!F88+'Dai Loc'!F88+'Dong Lam'!F88+'Khanh Nga'!F88+TDP!F88+DTRVL!F88 -> 0 | G88: =DTR!G88+'Dai Loc'!G88+'Dong Lam'!G88+'Khanh Nga'!G88+TDP!G88+DTRVL!G88 -> 0 | H88: =DTR!H88+'Dai Loc'!H88+'Dong Lam'!H88+'Khanh Nga'!H88+TDP!H88+DTRVL!H88 -> 0 | I88: =DTR!I88+'Dai Loc'!I88+'Dong Lam'!I88+'Khanh Nga'!I88+TDP!I88+DTRVL!I88 -> 0 | J88: =DTR!J88+'Dai Loc'!J88+'Dong Lam'!J88+'Khanh Nga'!J88+TDP!J88+DTRVL!J88 -> 0 | ... Z88: =DTR!Z88+'Dai Loc'!Z88+'Dong Lam'!Z88+'Khanh Nga'!Z88+TDP!Z88+DTRVL!Z88 -> 0
A89: 4.Thuế và các khoản phải nộp Nhà nước ngắn hạn | B89: 84 | C89: =DTR!C89+'Dai Loc'!C89+'Dong Lam'!C89+'Khanh Nga'!C89+TDP!C89+DTRVL!C89 -> 10498883610 | D89: =DTR!D89+'Dai Loc'!D89+'Dong Lam'!D89+'Khanh Nga'!D89+TDP!D89+DTRVL!D89 -> 3689814164 | E89: =DTR!E89+'Dai Loc'!E89+'Dong Lam'!E89+'Khanh Nga'!E89+TDP!E89+DTRVL!E89 -> 4062755871 | F89: =DTR!F89+'Dai Loc'!F89+'Dong Lam'!F89+'Khanh Nga'!F89+TDP!F89+DTRVL!F89 -> 1384290807 | G89: =DTR!G89+'Dai Loc'!G89+'Dong Lam'!G89+'Khanh Nga'!G89+TDP!G89+DTRVL!G89 -> 2308850961 | H89: =DTR!H89+'Dai Loc'!H89+'Dong Lam'!H89+'Khanh Nga'!H89+TDP!H89+DTRVL!H89 -> 3118570444 | I89: =DTR!I89+'Dai Loc'!I89+'Dong Lam'!I89+'Khanh Nga'!I89+TDP!I89+DTRVL!I89 -> 1058457452 | J89: =DTR!J89+'Dai Loc'!J89+'Dong Lam'!J89+'Khanh Nga'!J89+TDP!J89+DTRVL!J89 -> 1211020482 | ... Z89: =DTR!Z89+'Dai Loc'!Z89+'Dong Lam'!Z89+'Khanh Nga'!Z89+TDP!Z89+DTRVL!Z89 -> 7281246280
... A131: TỔNG NGUỒN VỐN | B131: 126 | C131: =DTR!C131+'Dai Loc'!C131+'Dong Lam'!C131+'Khanh Nga'!C131+TDP!C131+DTRVL!C131 -> 1175130402352 | D131: =DTR!D131+'Dai Loc'!D131+'Dong Lam'!D131+'Khanh Nga'!D131+TDP!D131+DTRVL!D131 -> 1156870558457 | E131: =DTR!E131+'Dai Loc'!E131+'Dong Lam'!E131+'Khanh Nga'!E131+TDP!E131+DTRVL!E131 -> 1.1935024e+12 | F131: =DTR!F131+'Dai Loc'!F131+'Dong Lam'!F131+'Khanh Nga'!F131+TDP!F131+DTRVL!F131 -> 1.2545406e+12 | G131: =DTR!G131+'Dai Loc'!G131+'Dong Lam'!G131+'Khanh Nga'!G131+TDP!G131+DTRVL!G131 -> 1298938884161 | H131: =DTR!H131+'Dai Loc'!H131+'Dong Lam'!H131+'Khanh Nga'!H131+TDP!H131+DTRVL!H131 -> 1325603983311 | I131: =DTR!I131+'Dai Loc'!I131+'Dong Lam'!I131+'Khanh Nga'!I131+TDP!I131+DTRVL!I131 -> 1267478798902 | J131: =DTR!J131+'Dai Loc'!J131+'Dong Lam'!J131+'Khanh Nga'!J131+TDP!J131+DTRVL!J131 -> 1218289415966 | ... Z131: =DTR!Z131+'Dai Loc'!Z131+'Dong Lam'!Z131+'Khanh Nga'!Z131+TDP!Z131+DTRVL!Z131 -> 1399120322090
C132: =C131-C83 -> 0 | D132: =D131-D83 -> 0 | E132: =E131-E83 -> 0 | F132: =F131-F83 -> 0 | G132: =G131-G83 -> 0 | H132: =H131-H83 -> 0 | I132: =I131-I83 -> 0 | J132: =J131-J83 -> 0 | ... Z132: =Z131-Z83 -> 0
A133: PHẦN II-KẾT QUẢ HOẠT ĐỘNG KINH DOANH | B133: Index PL | C133: =C5 -> T01.2024 | D133: =D5 -> T02.2024 | E133: =E5 -> T03.2024 | F133: =F5 -> T04.2024 | G133: =G5 -> T05.2024 | H133: =H5 -> T06.2024 | I133: =I5 -> T07.2024 | J133: =J5 -> T08.2024 | ... Z133: =Z5 -> T12.2025 | AA133: T01.2026 | AB133: T02.2026 | AC133: T03.2026 | AD133: T04.2026 | AE133: T05.2026 | AF133: T06.2026 | AG133: T07.2026 | AH133: T08.2026 | AI133: T09.2026 | AJ133: T10.2026 | AK133: T11.2026 | AL133: T12.2026 | AM133: Tổng hợp 2026 | AN133: Tổng hợp 205 | AO133: 2026 vs 2025 | AP133: %
A134: Sản lượng (Tấn) | B134: 1 | C134: =DTR!C134+'Dai Loc'!C134+'Dong Lam'!C134+'Khanh Nga'!C134+TDP!C134+DTRVL!C134 -> 5108.325 | D134: =DTR!D134+'Dai Loc'!D134+'Dong Lam'!D134+'Khanh Nga'!D134+TDP!D134+DTRVL!D134 -> 3038.375 | E134: =DTR!E134+'Dai Loc'!E134+'Dong Lam'!E134+'Khanh Nga'!E134+TDP!E134+DTRVL!E134 -> 4394.4 | F134: =DTR!F134+'Dai Loc'!F134+'Dong Lam'!F134+'Khanh Nga'!F134+TDP!F134+DTRVL!F134 -> 4434.75 | G134: =DTR!G134+'Dai Loc'!G134+'Dong Lam'!G134+'Khanh Nga'!G134+TDP!G134+DTRVL!G134 -> 4827.202 | H134: =DTR!H134+'Dai Loc'!H134+'Dong Lam'!H134+'Khanh Nga'!H134+TDP!H134+DTRVL!H134 -> 3532.75 | I134: =DTR!I134+'Dai Loc'!I134+'Dong Lam'!I134+'Khanh Nga'!I134+TDP!I134+DTRVL!I134 -> 2953.134 | J134: =DTR!J134+'Dai Loc'!J134+'Dong Lam'!J134+'Khanh Nga'!J134+TDP!J134+DTRVL!J134 -> 5764.9472 | ... AL134: =DTR!AL134+'Dai Loc'!AL134+'Dong Lam'!AL134+'Khanh Nga'!AL134+TDP!AL134+DTRVL!AL134 -> 7410.268 | AM134: =SUM(AA134:AL134) -> 84233.917 | AN134: =SUM(O134:Z134) -> 68196.753 | AO134: =AM134-AN134 -> 16037.165 | AP134: =AO134/AM134 -> 0.19038845
A135: 1.Doanh thu bán hàng và cung cấp dịch vụ | B135: 2 | C135: =DTR!C135+'Dai Loc'!C135+'Dong Lam'!C135+'Khanh Nga'!C135+TDP!C135+DTRVL!C135 -> 130037940981 | D135: =DTR!D135+'Dai Loc'!D135+'Dong Lam'!D135+'Khanh Nga'!D135+TDP!D135+DTRVL!D135 -> 84645791256 | E135: =DTR!E135+'Dai Loc'!E135+'Dong Lam'!E135+'Khanh Nga'!E135+TDP!E135+DTRVL!E135 -> 115625416433 | F135: =DTR!F135+'Dai Loc'!F135+'Dong Lam'!F135+'Khanh Nga'!F135+TDP!F135+DTRVL!F135 -> 117647266094 | G135: =DTR!G135+'Dai Loc'!G135+'Dong Lam'!G135+'Khanh Nga'!G135+TDP!G135+DTRVL!G135 -> 128085507494 | H135: =DTR!H135+'Dai Loc'!H135+'Dong Lam'!H135+'Khanh Nga'!H135+TDP!H135+DTRVL!H135 -> 95661572209 | I135: =DTR!I135+'Dai Loc'!I135+'Dong Lam'!I135+'Khanh Nga'!I135+TDP!I135+DTRVL!I135 -> 74679662458 | J135: =DTR!J135+'Dai Loc'!J135+'Dong Lam'!J135+'Khanh Nga'!J135+TDP!J135+DTRVL!J135 -> 178936926222 | ... AL135: =DTR!AL135+'Dai Loc'!AL135+'Dong Lam'!AL135+'Khanh Nga'!AL135+TDP!AL135+DTRVL!AL135 -> 1.701826e+11 | AM135: =SUM(AA135:AL135) -> 1.9373895e+12 | AN135: =SUM(O135:Z135) -> 1924391187895 | AO135: =AM135-AN135 -> 1.2998362e+10 | AP135: =AO135/AM135 -> 0.0067092143
