Workbook
Name \T: #REF!
Name __dao1: #REF!
Name __dao2: #REF!
Name __dap2: #REF!
Name __day1: #REF!
Name __day2: #REF!
Name __dbu1: #REF!
Name __dbu2: #REF!
Name __doi3: #REF!
Name __E99999: #REF!
Name __Jan02: #REF!
Name __lap1: #REF!
Name __lap2: #REF!
Name __vc1: #REF!
Name __vc2: #REF!
Name __vc3: #REF!
Name _01_01_99: #REF!
Name _01_02_99: #REF!
Name _01_03_99: #REF!
Name _01_04_99: #REF!
Name _01_05_99: #REF!
Name _01_06_99: #REF!
Name _01_07_99: #REF!
Name _01_08_1999: #REF!
Name _1CAP002: #REF!
Name _2STREO7: #REF!
Name _4GOIC01: #REF!
Name _4OSLCTT: #REF!
Name _6BNTTTH: #REF!
Name _6DCTTBO: #REF!
Name _6DD24TT: #REF!
Name _6FCOTBU: #REF!
Name _6LATUBU: #REF!
Name _6SDTT24: #REF!
Name _6TBUDTT: #REF!
Name _6TDDDTT: #REF!
Name _6TLTTTH: #REF!
Name _6TUBUTT: #REF!
Name _6UCLVIS: #REF!
Name _7DNCABC: #REF!
Name _7HDCTBU: #REF!
Name _7PKTUBU: #REF!
Name _7TBHT20: #REF!
Name _7TBHT30: #REF!
Name _7TDCABC: #REF!
Name _dao1: #REF!
Name _dao2: #REF!
Name _dap2: #REF!
Name _day1: #REF!
Name _day2: #REF!
Name _dbu1: #REF!
Name _dbu2: #REF!
Name _doi3: #REF!
Name _E99999: #REF!
Name _Jan02: #REF!
Name _lap1: #REF!
Name _lap2: #REF!
Name _vc1: #REF!
Name _vc2: #REF!
Name _vc3: #REF!

Sheet 1. rPET
D2: GIÁ BÁN HẠT rPET - THÁNG 06 NĂM 2025 HỖ TRỢ PHÁT TRIỂN KHÁCH HÀNG MỚI | O2: TC-TCH-01/ BM01 | R2: 800
O3: V0 -04/10/2024
O4: Ngày áp dụng: 01/04/2026
B6: STT | C6: Mã sản phẩm | D6: Sản phẩm | E6: Mức IV | F6: Giá xuất xưởng DTR (USD/tấn) | P6: Chênh lệch Giá tháng 04 vs chính phẩm (800 $/tấn)
F7: ='rPET- nội bộ '!F7 -> Tháng 03 (đã duyệt) | J7: ='rPET- nội bộ '!J7 -> Tháng 04 | N7: ='rPET- nội bộ '!N7 -> Chênh lệch tháng 04 vs tháng 03
F8: Giá Bán (1) | G8: % Chiết khấu (2) | H8: Chiết Khấu (3) | I8: Giá bán sau chiết khấu (4)=(1)-(3) | J8: Giá Bán (1) | K8: % Chiết khấu (2) | L8: Chiết Khấu (3) | M8: Giá bán sau chiết khấu (4)=(1)-(3) | N8: USD | O8: % | P8: USD | Q8: %
C9: HẠT FOOD GRADE
B10: 1 | C10: 110000354 | D10: Hạt nhựa rPET WSS01G | E10: 0.78 | F10: 1365 | G10: 0.098901099 | H10: 135 | I10: 1250 | J10: 1365 | K10: =L10/J10 -> 0.084249084 | L10: =J10-M10 -> 115 | M10: =1300+10+15-50-45+20 -> 1250 | N10: =M10-I10 -> 0 | O10: =1-(I10/M10) -> 0 | P10: =M10-$R$2 -> 450 | Q10: =P10/$R$2 -> 0.5625
B11: =B10+1 -> 2 | C11: 110000381 | D11: Hạt nhựa rPET WSS03SD, WSS04SB, WSS04SD (xơ sợi) | E11: 0.63 | F11: 1155 | G11: =H11/F11 -> 0.047619048 | H11: =F11-I11 -> 55 | I11: 1100 | J11: 1155 | K11: =L11/J11 -> 0.047619048 | L11: =J11-M11 -> 55 | M11: 1100 | N11: =M11-I11 -> 0 | O11: =1-(I11/M11) -> 0 | P11: =M11-$R$2 -> 300 | Q11: =P11/$R$2 -> 0.375
B14: Bảng chi tiết giá theo IV:
B15: Giá bán ± thêm so với giá gốc IV 0.78
B16: STT | C16: Mức IV | D16: Nhóm Sản Phẩm | E16: Giá bán ± theo IV ( USD )
C17: HẠT FOOD GRADE
B18: 1 | C18: 0.84 | D18: iSS01084G | E18: + 90
B19: 2 | C19: 0.8 | D19: iSS01G / iSS01 | E19: + 30
B20: 3 | C20: 0.78 | D20: WSS01G / WSS01 / WSS01L | E20: 0
B21: 4 | C21: 0.7 | D21: WSS03G/ WSS03 | E21: - 70
C22: HẠT XƠ SỢI
B23: 1 | C23: 0.7 | D23: WSS03SD/WSS03SB | E23: -130
B24: 2 | C24: 0.63 | D24: WSS04SD/WSS04SB | E24: -130
B25: Lưu ý:
B26: 1. Giá FOB = Giá xuất xưởng (EXW) + USD 22/tấn (trường hợp bán full cont, nếu bán ít hơn cont liên hệ bộ phận Logistics lấy chi phí phù hợp)
B27: 2. Ủy quyền cho GĐĐH duyệt theo đơn đặt hàng: biên độ +/-10% so với giá xuất xưởng DTR
Q28: ='rPET- nội bộ '!Q45 -> Ngày 19 tháng 03 năm 2026
B30: Chủ Tịch | D30: GĐĐH Tài Chính | F30: TGĐ | H30: GĐĐH DTR | J30: Giám Đốc Kinh Doanh | M30: Giám Đốc Tài Chính | P30: Kế Toán
B37: Trần Duy Hy | D37: Nguyễn Bảo Quốc | F37: Huỳnh Ngọc Thạch | H37: Đái Trung Quân | J37: Dương Từ Uyên Thảo | M37: Lê Hoành Cư | P37: Lưu Thị Minh Tâm

Sheet 2. rHDPE 
D2: GIÁ BÁN HẠT rHDPE - THÁNG 06 NĂM 2025 HỖ TRỢ PHÁT TRIỂN KHÁCH HÀNG MỚI | O2: TC-TCH-01/ BM04 | R2: 860
O3: V0 -04/10/2024
O4: ='1. rPET'!O4 -> Ngày áp dụng: 01/04/2026
B6: STT | C6: Mã sản phẩm | D6: Sản phẩm | E6: Màu | F6: Giá xuất xưởng DTR (USD/tấn) | P6: Chênh lệch Giá tháng 06 vs chính phẩm (860 $/tấn HD thổi & 910 $/tấn HD ép )
F7: ='1. rPET'!F7 -> Tháng 03 (đã duyệt) | J7: ='1. rPET'!J7 -> Tháng 04 | N7: ='1. rPET'!N7 -> Chênh lệch tháng 04 vs tháng 03
F8: Giá Bán (1) | G8: % Chiết khấu (2) | H8: Chiết Khấu (3) | I8: Giá bán sau chiết khấu (4)=(1)-(3) | J8: Giá Bán (1) | K8: % Chiết khấu (2) | L8: Chiết Khấu (3) | M8: Giá bán sau chiết khấu (4)=(1)-(3) | N8: USD | O8: % | P8: USD | Q8: %
B9: A | C9: NHÓM KHÁCH HÀNG PHÁT TRIỂN BỀN VỮNG
B10: I. rHDPE THỔI (PERSONAL CARE) (ĐÃ KHỬ MÙI)
B11: 1 | C11: 110000443 | D11: Hạt Nhựa rHDA03N01 | E11: Không màu | F11: 1530 | G11: =H11/F11 -> 0.11764706 | H11: =F11-I11 -> 180 | I11: 1350 | J11: 1530 | K11: =L11/J11 -> 0.11764706 | L11: =J11-M11 -> 180 | M11: 1350 | N11: =M11-I11 -> 0 | O11: =1-(I11/M11) -> 0 | P11: =M11-$R$2 -> 490 | Q11: =P11/$R$2 -> 0.56976744 | S11: Không mua giá ICIS HD, PP nữa
B12: =B11+1 -> 2 | C12: 110000337 | D12: Hạt nhựa rHD Thổi màu | E12: Trắng, lá, vàng | F12: =+$F$11-50 -> 1480 | G12: =H12/F12 -> 0.12162162 | H12: =F12-I12 -> 180 | I12: 1300 | J12: =+$J$11-50 -> 1480 | K12: =L12/J12 -> 0.12162162 | L12: =J12-M12 -> 180 | M12: 1300 | N12: =M12-I12 -> 0 | O12: =1-(I12/M12) -> 0 | P12: =M12-$R$2 -> 440 | Q12: =P12/$R$2 -> 0.51162791
B13: II. rHDPE THỔI (HOME CARE) (CHƯA KHỬ MÙI)
B14: 1 | C14: 110000432 | D14: Hạt Nhựa rHDB03N01/ rHDB03N02 | E14: Không màu, Trắng, lá, vàng, đen | F14: 1480 | G14: =H14/F14 -> 0.15540541 | H14: =F14-I14 -> 230 | I14: 1250 | J14: 1480 | K14: =L14/J14 -> 0.15540541 | L14: =J14-M14 -> 230 | M14: =M12-50 -> 1250 | N14: =M14-I14 -> 0 | O14: =1-(I14/M14) -> 0 | P14: =M14-$R$2 -> 390 | Q14: =P14/$R$2 -> 0.45348837
B15: III. rHDPE ÉP
B16: 1 | C16: 110000373 | D16: Hạt rHD ép màu | E16: Màu dương, trắng, đỏ, lá, xám | F16: 1300 | G16: =H16/F16 -> 0.23846154 | H16: =F16-I16 -> 310 | I16: 990 | J16: 1300 | K16: =L16/J16 -> 0.23076923 | L16: =J16-M16 -> 300 | M16: =$R$16*1.1-1 -> 1000 | N16: =M16-I16 -> 10 | O16: =1-(I16/M16) -> 0.01 | P16: =M16-$R$16 -> 90 | Q16: =P16/$R$16 -> 0.098901099 | R16: 910
B17: 2 | C17: 110000362 | D17: Hạt rHD ép đen | E17: Màu đen | F17: 1300 | G17: =H17/F17 -> 0.27692308 | H17: =F17-I17 -> 360 | I17: 940 | J17: 1360 | K17: =L17/J17 -> 0.30147059 | L17: =J17-M17 -> 410 | M17: =M16-50 -> 950 | N17: =M17-I17 -> 10 | O17: =1-(I17/M17) -> 0.010526316 | P17: =M17-$R$16 -> 40 | Q17: =P17/$R$16 -> 0.043956044
B18: B | C18: NHÓM KHÁCH HÀNG CHƯA CAM KẾT PHÁT TRIỂN BỀN VỮNG
B19: 1 | C19: 110000373 | D19: Hạt rHD ép màu | E19: Màu dương, trắng, đỏ, lá, xám | F19: 1000 | G19: =H19/F19 -> 0.235 | H19: =F19-I19 -> 235 | I19: 765 | J19: 1000 | K19: =L19/J19 -> 0.2255 | L19: =J19-M19 -> 225.5 | M19: =R16*85%+1 -> 774.5 | N19: =M19-I19 -> 9.5 | O19: =1-(I19/M19) -> 0.012265978 | P19: =M19-$R$16 -> -135.5 | Q19: =P19/$R$2 -> -0.15755814
B20: 2 | C20: 110000362 | D20: Hạt rHD ép đen | E20: Màu đen | F20: 1000 | G20: =H20/F20 -> 0.285 | H20: =F20-I20 -> 285 | I20: =I19-50 -> 715 | J20: 1000 | K20: =L20/J20 -> 0.2755 | L20: =J20-M20 -> 275.5 | M20: =M19-50 -> 724.5 | N20: =M20-I20 -> 9.5 | O20: =1-(I20/M20) -> 0.013112491 | P20: =M20-$R$2 -> -135.5 | Q20: =P20/$R$2 -> -0.15755814
B21: 3 | C21: 110000361 | D21: Hạt rHDI3R01 | E21: Màu đỏ | F21: 1000 | G21: =H21/F21 -> 0.05 | H21: =F21-I21 -> 50 | I21: 950 | J21: 1000 | K21: =L21/J21 -> 0.05 | L21: =J21-M21 -> 50 | M21: 950 | N21: =M21-I21 -> 0 | O21: =1-(I21/M21) -> 0 | P21: =M21-$R$2 -> 90 | Q21: =P21/$R$2 -> 0.10465116
B24: Lưu ý:
B26: 1. Giá FOB = Giá xuất xưởng (EXW) + USD 22/tấn (trường hợp bán full cont, nếu bán ít hơn cont liên hệ bộ phận Logistics lấy chi phí phù hợp)
B27: 2. Ủy quyền cho GĐĐH duyệt theo đơn đặt hàng: biên độ +/-10% so với giá xuất xưởng DTR
Q29: ='rPET- nội bộ '!Q45 -> Ngày 19 tháng 03 năm 2026
B31: Chủ Tịch | D31: GĐĐH Tài Chính | F31: TGĐ | H31: GĐĐH DTR | J31: Giám Đốc Kinh Doanh | M31: Giám Đốc Tài Chính | P31: Kế Toán
B38: Trần Duy Hy | D38: Nguyễn Bảo Quốc | F38: Huỳnh Ngọc Thạch | H38: Đái Trung Quân | J38: Dương Từ Uyên Thảo | M38: Lê Hoành Cư | P38: Lưu Thị Minh Tâm

Sheet 3.Vảy HDPE- Ép
D2: GIÁ BÁN VẢY HDPE ÉP- THÁNG 06 NĂM 2025 HỖ TRỢ PHÁT TRIỂN KHÁCH HÀNG MỚI | O2: TC-TCH-01/ BM05 | R2: 910
O3: V0 -04/10/2024
O4: ='1. rPET'!O4 -> Ngày áp dụng: 01/04/2026
B6: STT | C6: Mã sản phẩm | D6: Sản phẩm | E6: Màu | F6: Giá xuất xưởng DTR (USD/tấn) | P6: Chênh lệch Giá tháng 06 vs chính phẩm (910 $/tấn)
F7: ='1. rPET'!F7 -> Tháng 03 (đã duyệt) | J7: ='1. rPET'!J7 -> Tháng 04 | N7: ='1. rPET'!N7 -> Chênh lệch tháng 04 vs tháng 03
F8: Giá Bán (1) | G8: % Chiết khấu (2) | H8: Chiết Khấu (3) | I8: Giá bán sau chiết khấu (4)=(1)-(3) | J8: Giá Bán (1) | K8: % Chiết khấu (2) | L8: Chiết Khấu (3) | M8: Giá bán sau chiết khấu (4)=(1)-(3) | N8: USD | O8: % | P8: USD | Q8: %
B9: NHÓM KHÁCH HÀNG CHƯA CAM KẾT PHÁT TRIỂN BỀN VỮNG
B10: 1 | C10: 110000407 | D10: Vảy HD màu | E10: Đỏ, Trắng, Vàng, Lá, Dương | F10: 925 | G10: =H10/F10 -> 0.22162162 | H10: =F10-I10 -> 205 | I10: 720 | J10: 925 | K10: =L10/J10 -> 0.21621622 | L10: =J10-M10 -> 200 | M10: =R2*0.8-3 -> 725 | N10: =M10-I10 -> 5 | O10: =1-(I10/M10) -> 0.0068965517 | P10: =M10-$R$2 -> -185 | Q10: =P10/$R$2 -> -0.2032967
B11: 2 | C11: 110000412 | D11: Vảy HD Ép Đen | E11: Đen | F11: 925 | G11: =H11/F11 -> 0.10810811 | H11: =F11-I11 -> 100 | I11: 825 | J11: 925 | K11: =L11/J11 -> 0.10810811 | L11: =J11-M11 -> 100 | M11: 825 | N11: =M11-I11 -> 0 | O11: =1-(I11/M11) -> 0 | P11: =M11-$R$2 -> -85 | Q11: =P11/$R$2 -> -0.093406593
B12: 3 | C12: 110000409 | D12: Vảy HD Ép Vàng | F12: 850 | G12: =H12/F12 -> 0.047058824 | H12: =F12-I12 -> 40 | I12: 810 | J12: 850 | K12: =L12/J12 -> 0.047058824 | L12: =J12-M12 -> 40 | M12: 810 | N12: =M12-I12 -> 0 | O12: =1-(I12/M12) -> 0 | P12: =M12-$R$2 -> -100 | Q12: =P12/$R$2 -> -0.10989011
B13: 4 | C13: 110000410 | D13: Vảy HD Ép Lá | F13: 850 | G13: =H13/F13 -> 0.047058824 | H13: =F13-I13 -> 40 | I13: 810 | J13: 850 | K13: =L13/J13 -> 0.047058824 | L13: =J13-M13 -> 40 | M13: 810 | N13: =M13-I13 -> 0 | O13: =1-(I13/M13) -> 0 | P13: =M13-$R$2 -> -100 | Q13: =P13/$R$2 -> -0.10989011
B14: 5 | C14: 110000411 | D14: Vảy HD Ép Dương | F14: 850 | G14: =H14/F14 -> 0.047058824 | H14: =F14-I14 -> 40 | I14: 810 | J14: 850 | K14: =L14/J14 -> 0.047058824 | L14: =J14-M14 -> 40 | M14: 810 | N14: =M14-I14 -> 0 | O14: =1-(I14/M14) -> 0 | P14: =M14-$R$2 -> -100 | Q14: =P14/$R$2 -> -0.10989011
B17: Lưu ý:
B19: 1. Giá trên là giá xuất xưởng (EXW), nếu vận chuyển đến khách hàng thì cộng thêm phí vận chuyển.
B20: 2. Ủy quyền cho GĐĐH duyệt theo đơn đặt hàng: biên độ +/-10% so với giá xuất xưởng DTR .
Q24: ='rPET- nội bộ '!Q45 -> Ngày 19 tháng 03 năm 2026
B26: Chủ Tịch | D26: GĐĐH Tài Chính | F26: TGĐ | H26: GĐĐH DTR | J26: Giám Đốc Kinh Doanh | M26: Giám Đốc Tài Chính | P26: Kế Toán
B33: Trần Duy Hy | D33: Nguyễn Bảo Quốc | F33: Huỳnh Ngọc Thạch | H33: Đái Trung Quân | J33: Dương Từ Uyên Thảo | M33: Lê Hoành Cư | P33: Lưu Thị Minh Tâm

Sheet 4. rPP 
D2: GIÁ BÁN HẠT rPP - THÁNG 06 NĂM 2025 HỖ TRỢ PHÁT TRIỂN KHÁCH HÀNG MỚI | O2: TC-TCH-01/ BM06 | R2: 930
O3: V0 -04/10/2024
O4: ='1. rPET'!O4 -> Ngày áp dụng: 01/04/2026
B6: STT | C6: Mã sản phẩm | D6: Sản phẩm | E6: Màu | F6: Giá xuất xưởng DTR (USD/tấn) | P6: Chênh lệch Giá tháng 06 vs chính phẩm (930 $/tấn)
F7: ='1. rPET'!F7 -> Tháng 03 (đã duyệt) | J7: ='1. rPET'!J7 -> Tháng 04 | N7: ='1. rPET'!N7 -> Chênh lệch tháng 04 vs tháng 03
F8: Giá Bán (1) | G8: % Chiết khấu (2) | H8: Chiết Khấu (3) | I8: Giá bán sau chiết khấu (4)=(1)-(3) | J8: Giá Bán (1) | K8: % Chiết khấu (2) | L8: Chiết Khấu (3) | M8: Giá bán sau chiết khấu (4)=(1)-(3) | N8: USD | O8: % | P8: USD | Q8: %
B9: A | C9: NHÓM KHÁCH HÀNG PHÁT TRIỂN BỀN VỮNG
B10: 1 | C10: 110000367 | D10: Hạt nhựa rPP màu | E10: Đỏ, dương, trắng, lá | F10: 1200 | G10: =H10/F10 -> 0.12083333 | H10: =F10-I10 -> 145 | I10: 1055 | J10: 1200 | K10: =L10/J10 -> 0.14583333 | L10: =J10-M10 -> 175 | M10: =R2*1.1+2 -> 1025 | N10: =M10-I10 -> -30 | O10: =1-(I10/M10) -> -0.029268293 | P10: =M10-$R$2 -> 95 | Q10: =P10/$R$2 -> 0.10215054
B11: 2 | C11: 110000371 | D11: Hạt nhựa rPP đen | E11: Đen | F11: 1200 | G11: =H11/F11 -> 0.20416667 | H11: =F11-I11 -> 245 | I11: 955 | J11: 1200 | K11: =L11/J11 -> 0.22916667 | L11: =J11-M11 -> 275 | M11: =M10-100 -> 925 | N11: =M11-I11 -> -30 | O11: =1-(I11/M11) -> -0.032432432 | P11: =M11-$R$2 -> -5 | Q11: =P11/$R$2 -> -0.0053763441
B12: B | C12: NHÓM KHÁCH HÀNG CHƯA CAM KẾT PHÁT TRIỂN BỀN VỮNG
B13: 1 | C13: 110000367 | D13: Hạt nhựa rPP màu | E13: Đỏ, dương, trắng, lá, xám | F13: 1000 | G13: 0.1 | H13: 100 | I13: 815 | J13: 1000 | K13: =L13/J13 -> 0.2105 | L13: =J13-M13 -> 210.5 | M13: =R2*85%-1 -> 789.5 | N13: =M13-I13 -> -25.5 | O13: =1-(I13/M13) -> -0.032298923 | P13: =M13-$R$2 -> -140.5 | Q13: =P13/$R$2 -> -0.15107527
B14: 2 | C14: 110000371 | D14: Hạt nhựa rPP đen | E14: Đen | F14: 1000 | G14: 0.1 | H14: 100 | I14: 715 | J14: 1000 | K14: =L14/J14 -> 0.3105 | L14: =J14-M14 -> 310.5 | M14: =M13-100 -> 689.5 | N14: =M14-I14 -> -25.5 | O14: =1-(I14/M14) -> -0.036983321 | P14: =M14-$R$2 -> -240.5 | Q14: =P14/$R$2 -> -0.25860215
B17: Lưu ý:
B19: 1. Giá FOB = Giá xuất xưởng (EXW) + USD 22/tấn (trường hợp bán full cont, nếu bán ít hơn cont liên hệ bộ phận Logistics lấy chi phí phù hợp)
B20: 2. Ủy quyền cho GĐĐH duyệt theo đơn đặt hàng: biên độ +/-10% so với giá xuất xưởng DTR.
Q21: ='rPET- nội bộ '!Q45 -> Ngày 19 tháng 03 năm 2026
B23: Chủ Tịch | D23: GĐĐH Tài Chính | F23: TGĐ | H23: GĐĐH DTR | J23: Giám Đốc Kinh Doanh | M23: Giám Đốc Tài Chính | P23: Kế Toán
B30: Trần Duy Hy | D30: Nguyễn Bảo Quốc | F30: Huỳnh Ngọc Thạch | H30: Đái Trung Quân | J30: Dương Từ Uyên Thảo | M30: Lê Hoành Cư | P30: Lưu Thị Minh Tâm

Sheet 5. Vảy PP
D2: GIÁ BÁN VẢY PP - THÁNG 06 NĂM 2025 HỖ TRỢ PHÁT TRIỂN KHÁCH HÀNG MỚI | O2: TC-TCH-01/ BM07 | R2: 930
O3: V0 -04/10/2024
O4: ='1. rPET'!O4 -> Ngày áp dụng: 01/04/2026
B6: STT | C6: Mã sản phẩm | D6: Sản phẩm | E6: Màu | F6: Giá xuất xưởng DTR (USD/tấn) | P6: Chênh lệch Giá tháng 06 vs chính phẩm (930 $/tấn)
F7: ='1. rPET'!F7 -> Tháng 03 (đã duyệt) | J7: ='1. rPET'!J7 -> Tháng 04 | N7: ='1. rPET'!N7 -> Chênh lệch tháng 04 vs tháng 03
F8: Giá Bán (1) | G8: % Chiết khấu (2) | H8: Chiết Khấu (3) | I8: Giá bán sau chiết khấu (4)=(1)-(3) | J8: Giá Bán (1) | K8: % Chiết khấu (2) | L8: Chiết Khấu (3) | M8: Giá bán sau chiết khấu (4)=(1)-(3) | N8: $ | O8: % | P8: $ | Q8: %
B9: NHÓM KHÁCH HÀNG CHƯA CAM KẾT PHÁT TRIỂN BỀN VỮNG
B10: 1 | C10: 110000421 | D10: Vảy PP màu | E10: Đỏ, dương | F10: 900 | G10: 0.05 | H10: 45 | I10: 765 | J10: 900 | K10: =L10/J10 -> 0.17222222 | L10: =J10-M10 -> 155 | M10: =R2*80%+1 -> 745 | N10: =M10-I10 -> -20 | O10: =1-(I10/M10) -> -0.026845638 | P10: =M10-$R$2 -> -185 | Q10: =P10/$R$2 -> -0.19892473
B11: 2 | C11: 110000422 | D11: Vảy PP Đỏ Đậm | F11: 850 | G11: =H11/F11 -> 0.047058824 | H11: =F11-I11 -> 40 | I11: 810 | J11: 850 | K11: =L11/J11 -> 0.047058824 | L11: =J11-M11 -> 40 | M11: 810 | N11: =M11-I11 -> 0 | O11: =1-(I11/M11) -> 0 | P11: =M11-$R$2 -> -120 | Q11: =P11/$R$2 -> -0.12903226
B12: 3 | C12: 110000423 | D12: Vảy PP Dương Nhạt | F12: 850 | G12: =H12/F12 -> 0.047058824 | H12: =F12-I12 -> 40 | I12: 810 | J12: 850 | K12: =L12/J12 -> 0.047058824 | L12: =J12-M12 -> 40 | M12: 810 | N12: =M12-I12 -> 0 | O12: =1-(I12/M12) -> 0 | P12: =M12-$R$2 -> -120 | Q12: =P12/$R$2 -> -0.12903226
B13: 4 | C13: 110000424 | D13: Vảy PP Dương Đậm | F13: 850 | G13: =H13/F13 -> 0.047058824 | H13: =F13-I13 -> 40 | I13: 810 | J13: 850 | K13: =L13/J13 -> 0.047058824 | L13: =J13-M13 -> 40 | M13: 810 | N13: =M13-I13 -> 0 | O13: =1-(I13/M13) -> 0 | P13: =M13-$R$2 -> -120 | Q13: =P13/$R$2 -> -0.12903226
B16: Lưu ý:
B18: 1. Giá trên là giá xuất xưởng (EXW), nếu vận chuyển đến khách hàng thì cộng thêm phí vận chuyển.
B19: 2. Ủy quyền cho GĐĐH duyệt theo đơn đặt hàng: biên độ +/-10% so với giá xuất xưởng DTR .
Q21: ='rPET- nội bộ '!Q45 -> Ngày 19 tháng 03 năm 2026
B23: Chủ Tịch | D23: GĐĐH Tài Chính | F23: TGĐ | H23: GĐĐH DTR | J23: Giám Đốc Kinh Doanh | M23: Giám Đốc Tài Chính | P23: Kế Toán
B30: Trần Duy Hy | D30: Nguyễn Bảo Quốc | F30: Huỳnh Ngọc Thạch | H30: Đái Trung Quân | J30: Dương Từ Uyên Thảo | M30: Lê Hoành Cư | P30: Lưu Thị Minh Tâm

Sheet 6. Hạt phó sản
D2: GIÁ BÁN HẠT SẢN XUẤT TỪ PHÓ SẢN - THÁNG 06 NĂM 2025 HỖ TRỢ PHÁT TRIỂN KHÁCH HÀNG MỚI | P2: TC-TCH-01/ BM08
P3: V0 -04/10/2024
P4: ='1. rPET'!O4 -> Ngày áp dụng: 01/04/2026
B6: STT | C6: Mã sản phẩm | D6: Sản phẩm | E6: Màu | F6: IV/MI | G6: Giá xuất xưởng DTR (USD/tấn) | Q6: Chênh lệch Giá tháng 04 vs chính phẩm (800 $/tấn)
G7: ='1. rPET'!F7 -> Tháng 03 (đã duyệt) | K7: ='1. rPET'!J7 -> Tháng 04 | O7: ='1. rPET'!N7 -> Chênh lệch tháng 04 vs tháng 03
G8: Giá Bán (1) | H8: % Chiết khấu (2) | I8: Chiết Khấu (3) | J8: Giá bán sau chiết khấu (4)=(1)-(3) | K8: Giá Bán (1) | L8: % Chiết khấu (2) | M8: Chiết Khấu (3) | N8: Giá bán sau chiết khấu (4)=(1)-(3) | O8: USD | P8: % | Q8: USD | R8: % | T8: Hòa vốn | U8: Công thức
B9: I | C9: NHÓM XƠ SỢI
B10: 1 | C10: 110000464 | D10: Hạt Nhựa rPET WSS06SP-1 | E10: Đục | F10: 0.40 ~ 0.50 | G10: =J10*1.05 -> 682.5 | H10: =I10/G10 -> 0.047619048 | I10: =G10-J10 -> 32.5 | J10: 650 | K10: =N10*1.05 -> 682.5 | L10: =M10/K10 -> 0.047619048 | M10: =K10-N10 -> 32.5 | N10: 650 | O10: =N10-J10 -> 0 | P10: =1-(J10/N10) -> 0 | Q10: =N10-S10 -> -150 | R10: =Q10/S10 -> -0.1875 | S10: 800 | T10: =#REF! -> #REF! | U10: WSS006SP-1 (vảy PET tuyển nổi 2) | W10: =T10*25 -> #REF!
B11: 2 | C11: 110000465 | D11: Hạt Nhựa rPET WSS06SP-2 | E11: Trong | F11: 0.40 ~ 0.50 | G11: =J11*1.05 -> 787.5 | H11: =I11/G11 -> 0.047619048 | I11: =G11-J11 -> 37.5 | J11: 750 | K11: =N11*1.05 -> 787.5 | L11: =M11/K11 -> 0.047619048 | M11: =K11-N11 -> 37.5 | N11: 750 | O11: =N11-J11 -> 0 | P11: =1-(J11/N11) -> 0 | Q11: =N11-S11 -> -50 | R11: =Q11/S11 -> -0.0625 | S11: 800 | T11: =#REF! -> #REF! | U11: WSS006SP-2 (bụi tank C,D đã gia công) | W11: =T11*25 -> #REF!
B12: 3 | C12: 110000436 | D12: Hạt nhựa rPET WSS05SB | E12: Trong | F12: 0.50 ~ 0.60 | G12: 1000 | H12: =I12/G12 -> 0.2 | I12: =G12-J12 -> 200 | J12: 800 | K12: 1000 | L12: =M12/K12 -> 0.2 | M12: =K12-N12 -> 200 | N12: 800 | O12: =N12-J12 -> 0 | P12: =1-(J12/N12) -> 0 | Q12: =N12-S12 -> 0 | R12: =Q12/S12 -> 0 | S12: 800 | T12: 954 | U12: 100% B6
B13: 4 | C13: 110000466 | D13: Hạt Nhựa rPET WSS05SB-2 | E13: Trong | F13: 0.50 ~ 0.60 | G13: =J13*1.05 -> 892.5 | H13: 0.05 | I13: =G13-J13 -> 42.5 | J13: 850 | K13: =N13*1.05 -> 892.5 | L13: 0.05 | M13: =K13-N13 -> 42.5 | N13: 850 | O13: =N13-J13 -> 0 | P13: =1-(J13/N13) -> 0 | Q13: =N13-S13 -> 50 | R13: =Q13/S13 -> 0.0625 | S13: 800 | T13: =#REF! -> #REF! | U13: 82%B6+18%B7 | V13: Vảy B6 mua Đại Lộc: 18.250, Bình B7 mua lavie : 8.550, Chai B5 mua trạm: 12.000:
B14: 5 | C14: 110000467 | D14: Hạt Nhựa rPET WSS05SB-3 | E14: Trong | F14: 0.50 ~ 0.60 | G14: 1050 | H14: 0.05 | I14: 50 | J14: 900 | K14: 1102.5 | L14: 0.05 | M14: 52.5 | N14: 900 | O14: =N14-J14 -> 0 | P14: =1-(J14/N14) -> 0 | Q14: =N14-S14 -> 100 | R14: =Q14/S14 -> 0.125 | S14: 800 | T14: =#REF! -> #REF! | U14: 90%B6+10%B5
B15: II | C15: NHÓM rHDPE THỔI
B16: 6 | C16: 110000341 | D16: Hạt nhựa rHDB04B01 | E16: Đen | F16: 0.4 ± 0.1 | G16: 1102.5 | H16: 0.05 | I16: 52.5 | J16: 950 | K16: =N16*1.05 -> 997.5 | L16: 0.05 | M16: =K16-N16 -> 47.5 | N16: 950 | O16: =N16-J16 -> 0 | P16: =1-(J16/N16) -> 0 | Q16: =N16-S16 -> 90 | R16: =Q16/S16 -> 0.10465116 | S16: 860 | T16: =#REF! -> #REF! | U16: 80% PS hạt HD thổi lẫn màu/kim loại
B17: 7 | C17: 110000433 | D17: Hạt Nhựa rHDB03N03 | E17: Trong | F17: 0.3 ± 0.05 | G17: 997.5 | H17: 0.05 | I17: 47.5 | J17: 1100 | K17: =N17*1.05 -> 1155 | L17: 0.05 | M17: =K17-N17 -> 55 | N17: 1100 | O17: =N17-J17 -> 0 | P17: =1-(J17/N17) -> 0 | Q17: =N17-S17 -> 210 | R17: =Q17/S17 -> 0.23595506 | S17: 890 | T17: =#REF! -> #REF!
B18: III | C18: NHÓM rHDPE ÉP
B19: 7 | C19: 110000431 | D19: Hạt Nhựa rHDI3Gy02 | E19: Xám | F19: 3.00 ± 2.00 | G19: 840 | H19: 0.05 | I19: 55 | J19: 700 | K19: =N19*1.05 -> 735 | L19: =M19/K19 -> 0.047619048 | M19: =K19-N19 -> 35 | N19: 700 | O19: =N19-J19 -> 0 | P19: =1-(J19/N19) -> 0 | Q19: =N19-S19 -> -210 | R19: =Q19/S19 -> -0.23076923 | S19: 910 | T19: =#REF! -> #REF!
B20: IV | C20: NHÓM rPP
B21: 8 | C21: 110000392 | D21: Hạt nhựa rPP20B01 | E21: Đen | F21: 20.00 ± 10.00 | G21: =J21*1.05 -> 735 | H21: =I21/G21 -> 0.047619048 | I21: =G21-J21 -> 35 | J21: 700 | K21: =N21*1.05 -> 735 | L21: =M21/K21 -> 0.047619048 | M21: =K21-N21 -> 35 | N21: 700 | O21: =N21-J21 -> 0 | P21: =1-(J21/N21) -> 0 | Q21: =N21-S21 -> -230 | R21: =Q21/S21 -> -0.24731183 | S21: 930
B24: Lưu ý:
B26: 1. Giá trên là giá xuất xưởng (EXW), nếu vận chuyển đến khách hàng thì cộng thêm phí vận chuyển
B27: 2. Ủy quyền cho GĐĐH duyệt theo đơn đặt hàng: biên độ +/-10% so với giá xuất xưởng DTR
Q28: ='rPET- nội bộ '!Q45 -> Ngày 19 tháng 03 năm 2026
B30: Chủ Tịch | D30: GĐĐH Tài Chính | F30: TGĐ | H30: GĐĐH DTR | J30: Giám Đốc Kinh Doanh | M30: Giám Đốc Tài Chính | P30: Kế Toán
B37: Trần Duy Hy | D37: Nguyễn Bảo Quốc | F37: Huỳnh Ngọc Thạch | H37: Đái Trung Quân | J37: Dương Từ Uyên Thảo | M37: Lê Hoành Cư | P37: Lưu Thị Minh Tâm

Sheet rPET- nội bộ 
D2: GIÁ BÁN HẠT rPET - THÁNG 06 NĂM 2025 HỖ TRỢ PHÁT TRIỂN KHÁCH HÀNG MỚI | O2: TC-TCH-01/ BM02 | R2: 1280
O3: V0 -04/10/2024
O4: ='1. rPET'!O4 -> Ngày áp dụng: 01/04/2026
B6: STT | C6: Mã sản phẩm | D6: Sản phẩm | E6: Mức IV | F6: Giá xuất xưởng DTR (USD/tấn) | P6: Chênh lệch Giá tháng 04 vs chính phẩm (800 $/tấn)
F7: Tháng 03 (đã duyệt) | J7: Tháng 04 | N7: Chênh lệch tháng 04 vs tháng 03
F8: Giá Bán (1) | G8: % Chiết khấu (2) | H8: Chiết Khấu (3) | I8: Giá bán sau chiết khấu (4)=(1)-(3) | J8: Giá Bán (1) | K8: % Chiết khấu (2) | L8: Chiết Khấu (3) | M8: Giá bán sau chiết khấu (4)=(1)-(3) | N8: $ | O8: % | P8: $ | Q8: %
B9: 1 | C9: 110000332 | D9: Hạt nhựa rPET iSS01084G | E9: 0.84 | F9: 1381.5 | G9: 0.04451683 | H9: 61.5 | I9: 1340 | J9: =J13+90 -> 1402.5 | K9: =L9/J9 -> 0.04456328 | L9: =J9-M9 -> 62.5 | M9: =+M15+90 -> 1340 | N9: =M9-I9 -> 0 | O9: =1-(I9/M9) -> 0 | P9: =M9-$R$2 -> 60 | Q9: =P9/$R$2 -> 0.046875 | S9: =M9+M10+M13 -> 3870
B10: =+B9+1 -> 2 | C10: 110000330 | D10: Hạt nhựa rPET iSS01 | E10: 0.80 | F10: 1321.5 | G10: 0.046538025 | H10: 61.5 | I10: 1280 | J10: =J11 -> 1342.5 | K10: =L10/J10 -> 0.046554935 | L10: =J10-M10 -> 62.5 | M10: =+M15+30 -> 1280 | N10: =M10-I10 -> 0 | O10: =1-(I10/M10) -> 0 | P10: =M10-$R$2 -> 0 | Q10: =P10/$R$2 -> 0 | S10: =S9/3 -> 1290
B11: =+B10+1 -> 3 | C11: 110000355 | D11: Hạt nhựa rPET iSS01G 1 | E11: 0.80 | F11: 1321.5 | G11: 0.046538025 | H11: 61.5 | I11: 1280 | J11: =J13+30 -> 1342.5 | K11: =L11/J11 -> 0.046554935 | L11: =J11-M11 -> 62.5 | M11: =+M15+30 -> 1280 | N11: =M11-I11 -> 0 | O11: =1-(I11/M11) -> 0 | P11: =M11-$R$2 -> 0 | Q11: =P11/$R$2 -> 0
B12: =+B11+1 -> 4 | C12: 110000378 | D12: Hạt nhựa rPET iSS01G 2 | E12: 0.80 | F12: 1321.5 | G12: 0.046538025 | H12: 61.5 | I12: 1280 | J12: =J15+30 -> 1342.5 | K12: =L12/J12 -> 0.046554935 | L12: =J12-M12 -> 62.5 | M12: =+M15+30 -> 1280 | N12: =M12-I12 -> 0 | O12: =1-(I12/M12) -> 0 | P12: =M12-$R$2 -> 0 | Q12: =P12/$R$2 -> 0
B13: =+B12+1 -> 5 | C13: 110000354 | D13: Hạt nhựa rPET WSS01G 1 | E13: 0.78 | F13: 1291.5 | G13: 0.047619048 | H13: 61.5 | I13: 1250 | J13: =M13*1.05 -> 1312.5 | K13: =L13/J13 -> 0.047619048 | L13: =J13-M13 -> 62.5 | M13: =M15 -> 1250 | N13: =M13-I13 -> 0 | O13: =1-(I13/M13) -> 0 | P13: =M13-$R$2 -> -30 | Q13: =P13/$R$2 -> -0.0234375
B14: =+B13+1 -> 6 | C14: 110000377 | D14: Hạt nhựa rPET WSS01G 2 | E14: 0.78 | F14: 1291.5 | G14: 0.047619048 | H14: 61.5 | I14: 1250 | J14: =M14*1.05 -> 1312.5 | K14: =L14/J14 -> 0.047619048 | L14: =J14-M14 -> 62.5 | M14: =M13 -> 1250 | N14: =M14-I14 -> 0 | O14: =1-(I14/M14) -> 0 | P14: =M14-$R$2 -> -30 | Q14: =P14/$R$2 -> -0.0234375
B15: =+B14+1 -> 7 | C15: 110000329 | D15: Hạt nhựa rPET WSS01 | E15: 0.78 | F15: 1291.5 | G15: 0.047619048 | H15: 61.5 | I15: 1250 | J15: =J13 -> 1312.5 | K15: =L15/J15 -> 0.047619048 | L15: =J15-M15 -> 62.5 | M15: =1300+10+15-50-45+20 -> 1250 | N15: =M15-I15 -> 0 | O15: =1-(I15/M15) -> 0 | P15: =M15-$R$2 -> -30 | Q15: =P15/$R$2 -> -0.0234375
B16: =+B15+1 -> 8 | C16: 110000331 | D16: Hạt nhựa rPET WSS02 | E16: 0.74 | F16: 1261.5 | G16: 0.048751486 | H16: 61.5 | I16: 1220 | J16: =J15-30 -> 1282.5 | K16: =L16/J16 -> 0.048732943 | L16: =J16-M16 -> 62.5 | M16: =M15-30 -> 1220 | N16: =M16-I16 -> 0 | O16: =1-(I16/M16) -> 0 | P16: =M16-$R$2 -> -60 | Q16: =P16/$R$2 -> -0.046875
B17: =+B16+1 -> 9 | C17: 110000358 | D17: Hạt nhựa rPET WSS02G | E17: 0.74 | F17: 1231.5 | G17: 0.025578563 | H17: 31.5 | I17: 1220 | J17: =J16-30 -> 1252.5 | K17: =L17/J17 -> 0.025948104 | L17: =J17-M17 -> 32.5 | M17: =M15-30 -> 1220 | N17: =M17-I17 -> 0 | O17: =1-(I17/M17) -> 0 | P17: =M17-$R$2 -> -60 | Q17: =P17/$R$2 -> -0.046875
B18: =+B17+1 -> 10 | C18: 110000333 | D18: Hạt nhựa rPET WSS03 | E18: 0.70 | F18: 1221.5 | G18: 0.050347933 | H18: 61.5 | I18: 1180 | J18: =+J15-70 -> 1242.5 | K18: =L18/J18 -> 0.050301811 | L18: =J18-M18 -> 62.5 | M18: =+M15-70 -> 1180 | N18: =M18-I18 -> 0 | O18: =1-(I18/M18) -> 0 | P18: =M18-$R$2 -> -100 | Q18: =P18/$R$2 -> -0.078125
B19: =+B18+1 -> 11 | C19: 110000359 | D19: Hạt nhựa rPET WSS03G | E19: 0.70 | F19: 1191.5 | G19: 0.026437264 | H19: 31.5 | I19: 1180 | J19: =+J16-70 -> 1212.5 | K19: =L19/J19 -> 0.026804124 | L19: =J19-M19 -> 32.5 | M19: =+M15-70 -> 1180 | N19: =M19-I19 -> 0 | O19: =1-(I19/M19) -> 0 | P19: =M19-$R$2 -> -100 | Q19: =P19/$R$2 -> -0.078125
B20: =+B19+1 -> 12 | C20: 110000376 | D20: Hạt nhựa rPET iSS01L | E20: 0.80 | F20: 1397 | G20: 0.16249105 | H20: 227 | I20: 1190 | J20: 1397 | K20: =L20/J20 -> 0.14817466 | L20: =J20-M20 -> 207 | M20: =M15-60 -> 1190 | N20: =M20-I20 -> 0 | O20: =1-(I20/M20) -> 0 | P20: =M20-$R$2 -> -90 | Q20: =P20/$R$2 -> -0.0703125
B21: =+B20+1 -> 13 | C21: 110000387 | D21: Hạt nhựa rPET WSS03SD | E21: 0.70 | F21: 1155 | G21: 0.047619048 | H21: 55 | I21: 1100 | J21: =1100*1.05 -> 1155 | K21: =L21/J21 -> 0.047619048 | L21: =J21-M21 -> 55 | M21: 1100 | N21: =M21-I21 -> 0 | O21: =1-(I21/M21) -> 0 | P21: =M21-$R$2 -> -180 | Q21: =P21/$R$2 -> -0.140625
B22: =+B21+1 -> 14 | C22: 110000381 | D22: Hạt nhựa rPET WSS04SD | E22: 0.63 | F22: 1155 | G22: 0.047619048 | H22: 55 | I22: 1100 | J22: =1100*1.05 -> 1155 | K22: =L22/J22 -> 0.047619048 | L22: =J22-M22 -> 55 | M22: 1100 | N22: =M22-I22 -> 0 | O22: =1-(I22/M22) -> 0 | P22: =M22-$R$2 -> -180 | Q22: =P22/$R$2 -> -0.140625
B23: =+B22+1 -> 15 | C23: 110000382 | D23: Hạt nhựa rPET WSS04SB | E23: 0.63 | F23: 1155 | G23: 0.047619048 | H23: 55 | I23: 1100 | J23: =1100*1.05 -> 1155 | K23: =L23/J23 -> 0.047619048 | L23: =J23-M23 -> 55 | M23: 1100 | N23: =M23-I23 -> 0 | O23: =1-(I23/M23) -> 0 | P23: =M23-$R$2 -> -180 | Q23: =P23/$R$2 -> -0.140625
B24: =+B23+1 -> 16 | C24: 110000488 | D24: Hạt Nhựa rPET iSS01084G PL | E24: 0.84 | F24: 1308 | G24: 0.044342508 | H24: 58 | I24: 1250 | J24: =J27+90 -> 1308 | K24: =L24/J24 -> 0.044342508 | L24: =J24-M24 -> 58 | M24: =+M28+90 -> 1250 | N24: =M24-I24 -> 0 | O24: =1-(I24/M24) -> 0 | P24: =M24-$R$2 -> -30 | Q24: =P24/$R$2 -> -0.0234375
B25: =+B24+1 -> 17 | D25: Hạt rPET ISS01 | E25: 0.80 | F25: 1248 | G25: 0.046474359 | H25: 58 | I25: 1190 | J25: =J26 -> 1248 | K25: =L25/J25 -> 0.046474359 | L25: =J25-M25 -> 58 | M25: =+M28+30 -> 1190 | N25: =M25-I25 -> 0 | O25: =1-(I25/M25) -> 0 | P25: =M25-$R$2 -> -90 | Q25: =P25/$R$2 -> -0.0703125
B26: =+B25+1 -> 18 | C26: 110000486 | D26: Hạt Nhựa rPET iSS01G 1 PL | E26: 0.80 | F26: 1248 | G26: 0.046474359 | H26: 58 | I26: 1190 | J26: =J27+30 -> 1248 | K26: =L26/J26 -> 0.046474359 | L26: =J26-M26 -> 58 | M26: =+M28+30 -> 1190 | N26: =M26-I26 -> 0 | O26: =1-(I26/M26) -> 0 | P26: =M26-$R$2 -> -90 | Q26: =P26/$R$2 -> -0.0703125
B27: =+B26+1 -> 19 | C27: 110000484 | D27: Hạt Nhựa rPET WSS01G 1 PL | E27: 0.78 | F27: 1218 | G27: 0.047619048 | H27: 58 | I27: 1160 | J27: =M27*1.05 -> 1218 | K27: =L27/J27 -> 0.047619048 | L27: =J27-M27 -> 58 | M27: =M28 -> 1160 | N27: =M27-I27 -> 0 | O27: =1-(I27/M27) -> 0 | P27: =M27-$R$2 -> -120 | Q27: =P27/$R$2 -> -0.09375
B28: =+B27+1 -> 20 | C28: 110000493 | D28: Hạt Nhựa rPET WSS01 PL | E28: 0.78 | F28: 1218 | G28: 0.047619048 | H28: 58 | I28: 1160 | J28: =J27 -> 1218 | K28: =L28/J28 -> 0.047619048 | L28: =J28-M28 -> 58 | M28: =M29+30 -> 1160 | N28: =M28-I28 -> 0 | O28: =1-(I28/M28) -> 0 | P28: =M28-$R$2 -> -120 | Q28: =P28/$R$2 -> -0.09375
B29: =+B28+1 -> 21 | D29: Hạt rPET WSS02 | E29: 0.74 | F29: 1188 | G29: 0.048821549 | H29: 58 | I29: 1130 | J29: =J28-30 -> 1188 | K29: =L29/J29 -> 0.048821549 | L29: =J29-M29 -> 58 | M29: =M31+30 -> 1130 | N29: =M29-I29 -> 0 | O29: =1-(I29/M29) -> 0 | P29: =M29-$R$2 -> -150 | Q29: =P29/$R$2 -> -0.1171875
B30: =+B29+1 -> 22 | D30: Hạt nhựa rPET WSS02G | E30: 0.74 | F30: 1158 | G30: 0.02417962 | H30: 28 | I30: 1130 | J30: =J29-30 -> 1158 | K30: =L30/J30 -> 0.02417962 | L30: =J30-M30 -> 28 | M30: =M31+30 -> 1130 | N30: =M30-I30 -> 0 | O30: =1-(I30/M30) -> 0 | P30: =M30-$R$2 -> -150 | Q30: =P30/$R$2 -> -0.1171875
B31: =+B30+1 -> 23 | D31: Hạt rPET WSS03 | E31: 0.70 | F31: 1148 | G31: 0.041811847 | H31: 48 | I31: 1100 | J31: =+J28-70 -> 1148 | K31: =L31/J31 -> 0.041811847 | L31: =J31-M31 -> 48 | M31: 1100 | N31: =M31-I31 -> 0 | O31: =1-(I31/M31) -> 0 | P31: =M31-$R$2 -> -180 | Q31: =P31/$R$2 -> -0.140625
B32: 20 | C32: 110000492 | D32: Hạt Nhựa rPET WSS03G PL | E32: 0.70 | F32: 1118 | G32: 0.016100179 | H32: 18 | I32: 1100 | J32: =+J29-70 -> 1118 | K32: =L32/J32 -> 0.016100179 | L32: =J32-M32 -> 18 | M32: 1100 | N32: =M32-I32 -> 0 | O32: =1-(I32/M32) -> 0 | P32: =M32-$R$2 -> -180 | Q32: =P32/$R$2 -> -0.140625
B35: Lưu ý:
B36: 1. Giá FOB = Giá xuất xưởng (EXW) + USD 20/tấn | G36: 20
B37: 2. Hạt xơ sợi: giá bán 1.100 usd/tấn, chào khách để bán được hàng là +/- 55usd/tấn
B38: 3. Bảng giá áp dụng cho việc phát triển khách hàng mới, lưu hành nội bộ
Q45: Ngày 19 tháng 03 năm 2026
C46: GĐĐH Tài Chính | E46: TGĐ | G46: GĐĐH DTR | J46: Giám Đốc Kinh Doanh | M46: Giám Đốc Tài Chính | P46: Kế Toán
C53: Nguyễn Bảo Quốc | E53: Huỳnh Ngọc Thạch | G53: Đái Trung Quân | J53: Dương Từ Uyên Thảo | M53: Lê Hoành Cư | P53: Lưu Thị Minh Tâm

Sheet Tính giá
B1: DANH MỤC THÀNH PHẨM
P2: Giá xuất xưởng DTR (USD/tấn) | AF2: Hiện tại | AH2: T3
P3: ='rPET- nội bộ '!J7&" - PKD" -> Tháng 04 - PKD | T3: ='rPET- nội bộ '!J7 &" - GĐDH & TGĐ" -> Tháng 04 - GĐDH & TGĐ | X3: ='rPET- nội bộ '!N7 -> Chênh lệch tháng 04 vs tháng 03 | Z3: Chênh lệch Giá tháng 04 vs chính phẩm ($/tấn) | AB3: Chênh lệch Giá tháng 04 vs nhựa nguyên sinh ($/tấn) | AD3: Chính phẩm tăng | AE3: N.Sinh tăng | AF3: Giá chính phẩm | AG3: Giá Nguyên sinh | AH3: Giá chính phẩm | AI3: Giá Nguyên sinh
A4: STT | B4: Mã SAP | C4: Tên hàng hóa | D4: Màu | E4: Tồn kho 24/02/2026 (kg) | F4: Số lượng bán BQ 2026 (kg/ tháng) | G4: Giá duyệt T2 (USD/ tấn) | H4: Giá bán đề nghị T3 (USD/ tấn) | I4: CL T3 sv T2 (USD/ tấn) | J4: Giá thành | K4: CPQL | L4: Giá vốn | M4: Lợi nhuận trước thuế | N4: % lợi nhuận trước thuế | O4: Giá đề nghị của kinh doanh | P4: Giá Bán (1) | Q4: % Chiết khấu (2) | R4: Chiết Khấu (3) | S4: Giá bán sau chiết khấu (4)=(1)-(3) | T4: Giá Bán (1) | U4: % Chiết khấu (2) | V4: Chiết Khấu (3) | W4: Giá bán sau chiết khấu (4)=(1)-(3) | X4: USD | Y4: % | Z4: USD | AA4: % | AB4: USD | AC4: %
A5: A | B5: rPET
A6: I | B6: MÃ HÀNG ĐANG BÁN
A7: 1 | B7: 110000354 | C7: Hạt nhựa rPET WSS01G 1 | E7: 503605 | F7: 2663100 | G7: 1160 | H7: 1160 | I7: 0 | L7: 1057.7957 | M7: 102.20427 | N7: 0.088107133 | P7: ='KTQT_Trình bày'!Z7 -> 1197.6363 | Q7: 0.03 | R7: =P7*Q7 -> 35.92909 | S7: =P7-R7 -> 1161.7072 | T7: =P7 -> 1197.6363 | U7: 0.1 | V7: =T7*U7 -> 119.76363 | W7: =T7-V7 -> 1077.8727 | X7: =P7-G7 -> 37.636321 | Y7: =X7/G7 -> 0.032445105 | Z7: =P7-AF7 -> 57.636321 | AA7: =Z7/AF7 -> 0.050558177 | AB7: =P7-AG7 -> -102.36368 | AC7: =AB7/AG7 -> -0.078741291 | AD7: =AF7-AH7 -> 300 | AE7: =AG7-AI7 -> 150 | AF7: 1140 | AG7: 1300 | AH7: 840 | AI7: 1150
A8: 2 | B8: 110000355 | C8: Hạt nhựa rPET iSS01G 1 | E8: 154879.75 | F8: 25300 | G8: 1190 | H8: 1190 | I8: 0 | L8: 1057.7957 | M8: 132.20427 | N8: 0.11109603 | P8: ='KTQT_Trình bày'!Z8 -> 1197.6363 | Q8: 0.03 | R8: =P8*Q8 -> 35.92909 | S8: =P8-R8 -> 1161.7072 | T8: =P8 -> 1197.6363 | U8: 0.1 | V8: =T8*U8 -> 119.76363 | W8: =T8-V8 -> 1077.8727 | X8: =P8-G8 -> 7.6363213 | Y8: =X8/G8 -> 0.0064170767 | Z8: =P8-AF8 -> 57.636321 | AA8: =Z8/AF8 -> 0.050558177 | AB8: =P8-AG8 -> -102.36368 | AC8: =AB8/AG8 -> -0.078741291 | AD8: =AF8-AH8 -> 300 | AE8: =AG8-AI8 -> 150 | AF8: 1140 | AG8: 1300 | AH8: 840 | AI8: 1150
A9: 3 | B9: 110000332 | C9: Hạt nhựa rPET iSS01084G | E9: 788631.35 | F9: 616000 | G9: 1250 | H9: 1250 | I9: 0 | L9: 1113.7705 | M9: 136.22947 | N9: 0.10898358 | P9: ='KTQT_Trình bày'!Z9 -> 1261.011 | Q9: 0.03 | R9: =P9*Q9 -> 37.83033 | S9: =P9-R9 -> 1223.1807 | T9: =P9 -> 1261.011 | U9: 0.1 | V9: =T9*U9 -> 126.1011 | W9: =T9-V9 -> 1134.9099 | X9: =P9-G9 -> 11.010989 | Y9: =X9/G9 -> 0.0088087915 | Z9: =P9-AF9 -> 121.01099 | AA9: =Z9/AF9 -> 0.10614999 | AB9: =P9-AG9 -> -38.989011 | AC9: =AB9/AG9 -> -0.029991547 | AD9: =AF9-AH9 -> 300 | AE9: =AG9-AI9 -> 150 | AF9: 1140 | AG9: 1300 | AH9: 840 | AI9: 1150
A10: 4 | B10: 110000359 | C10: Hạt nhựa rPET WSS03G | E10: 1999804.7 | F10: 244200 | G10: 1090 | H10: 1090 | I10: 0 | L10: 1057.7957 | M10: 32.204274 | N10: 0.029545205 | P10: ='KTQT_Trình bày'!Z10 -> 1197.6363 | Q10: 0.03 | R10: =P10*Q10 -> 35.92909 | S10: =P10-R10 -> 1161.7072 | T10: =P10 -> 1197.6363 | U10: 0.1 | V10: =T10*U10 -> 119.76363 | W10: =T10-V10 -> 1077.8727 | X10: =P10-G10 -> 107.63632 | Y10: =X10/G10 -> 0.098748919 | Z10: =P10-AF10 -> 57.636321 | AA10: =Z10/AF10 -> 0.050558177 | AB10: =P10-AG10 -> -102.36368 | AC10: =AB10/AG10 -> -0.078741291 | AD10: =AF10-AH10 -> 300 | AE10: =AG10-AI10 -> 150 | AF10: 1140 | AG10: 1300 | AH10: 840 | AI10: 1150
A11: 5 | B11: 110000329 | C11: Hạt nhựa rPET WSS01 | E11: 378162 | F11: 0 | G11: 1320 | H11: 1320 | I11: 0 | L11: 1155.3596 | M11: 164.64035 | N11: 0.12472754 | P11: ='KTQT_Trình bày'!Z11 -> 1308.0982 | Q11: 0.03 | R11: =P11*Q11 -> 39.242946 | S11: =P11-R11 -> 1268.8552 | T11: =P11 -> 1308.0982 | U11: 0.1 | V11: =T11*U11 -> 130.80982 | W11: =T11-V11 -> 1177.2884 | X11: =P11-G11 -> -11.901805 | Y11: =X11/G11 -> -0.0090165191 | Z11: =P11-AF11 -> 168.09819 | AA11: =Z11/AF11 -> 0.14745456 | AB11: =P11-AG11 -> 8.0981948 | AC11: =AB11/AG11 -> 0.0062293806 | AD11: =AF11-AH11 -> 300 | AE11: =AG11-AI11 -> 150 | AF11: 1140 | AG11: 1300 | AH11: 840 | AI11: 1150
A12: 7 | B12: 110000499 | C12: Hạt Nhựa rPET WSS01L | E12: 34030 | F12: 0 | G12: 1160 | H12: 1160 | I12: 0 | L12: 1006.566 | M12: 153.43396 | N12: 0.13227066 | P12: ='KTQT_Trình bày'!Z12 -> 1139.6341 | Q12: 0.03 | R12: =P12*Q12 -> 34.189022 | S12: =P12-R12 -> 1105.445 | T12: =P12 -> 1139.6341 | U12: 0.1 | V12: =T12*U12 -> 113.96341 | W12: =T12-V12 -> 1025.6707 | X12: =P12-G12 -> -20.365932 | Y12: =X12/G12 -> -0.017556838 | Z12: =P12-AF12 -> -0.36593208 | AA12: =Z12/AF12 -> -0.00032099305 | AB12: =P12-AG12 -> -160.36593 | AC12: =AB12/AG12 -> -0.12335841 | AD12: =AF12-AH12 -> 300 | AE12: =AG12-AI12 -> 150 | AF12: 1140 | AG12: 1300 | AH12: 840 | AI12: 1150
A13: 9 | B13: 110000506 | C13: Hạt Nhựa rPET WSS01 & WSS01G-L | E13: 65840 | F13: 0 | G13: 1410 | H13: 690 | I13: -720 | L13: 1222.6415 | M13: -532.64151 | N13: -0.77194422 | P13: ='KTQT_Trình bày'!Z13 -> 1384.2747 | Q13: 0.03 | R13: =P13*Q13 -> 41.528242 | S13: =P13-R13 -> 1342.7465 | T13: =P13 -> 1384.2747 | U13: 0.1 | V13: =T13*U13 -> 138.42747 | W13: =T13-V13 -> 1245.8472 | X13: =P13-G13 -> -25.725283 | Y13: =X13/G13 -> -0.018244882 | Z13: =P13-AF13 -> 244.27472 | AA13: =Z13/AF13 -> 0.21427607 | AB13: =P13-AG13 -> 84.274717 | AC13: =AB13/AG13 -> 0.064826705 | AD13: =AF13-AH13 -> 300 | AE13: =AG13-AI13 -> 150 | AF13: 1140 | AG13: 1300 | AH13: 840 | AI13: 1150
A14: 10 | B14: 110000483 | C14: Hạt Nhựa rPET iSS01G-S | E14: 32405.5 | F14: 6600 | G14: 1190 | H14: 1190 | I14: 0 | L14: 1117.1698 | M14: 72.830189 | N14: 0.061201839 | P14: ='KTQT_Trình bày'!Z14 -> 1264.8597 | Q14: 0.03 | R14: =P14*Q14 -> 37.94579 | S14: =P14-R14 -> 1226.9139 | T14: =P14 -> 1264.8597 | U14: 0.1 | V14: =T14*U14 -> 126.48597 | W14: =T14-V14 -> 1138.3737 | X14: =P14-G14 -> 74.85966 | Y14: =X14/G14 -> 0.062907278 | Z14: =P14-AF14 -> 124.85966 | AA14: =Z14/AF14 -> 0.10952602 | AB14: =P14-AG14 -> -35.14034 | AC14: =AB14/AG14 -> -0.02703103 | AD14: =AF14-AH14 -> 300 | AE14: =AG14-AI14 -> 150 | AF14: 1140 | AG14: 1300 | AH14: 840 | AI14: 1150
A15: II | B15: MÃ HÀNG BÁN CHẬM
A16: 1 | B16: 110000378 | C16: Hạt nhựa rPET iSS01G 2 | E16: 1649997 | F16: 0 | G16: 1190 | H16: 1190 | I16: 0 | L16: 1057.7957 | M16: 132.20427 | N16: 0.11109603 | P16: ='KTQT_Trình bày'!Z16 -> 1197.6363 | Q16: 0.03 | R16: =P16*Q16 -> 35.92909 | S16: =P16-R16 -> 1161.7072 | T16: =P16 -> 1197.6363 | U16: 0.1 | V16: =T16*U16 -> 119.76363 | W16: =T16-V16 -> 1077.8727 | X16: =P16-G16 -> 7.6363213 | Y16: =X16/G16 -> 0.0064170767 | Z16: =P16-AF16 -> 57.636321 | AA16: =Z16/AF16 -> 0.050558177 | AB16: =P16-AG16 -> -102.36368 | AC16: =AB16/AG16 -> -0.078741291 | AD16: =AF16-AH16 -> 300 | AE16: =AG16-AI16 -> 150 | AF16: 1140 | AG16: 1300 | AH16: 840 | AI16: 1150
A17: 2 | B17: 110000377 | C17: Hạt nhựa rPET WSS01G 2 | E17: 287099.5 | F17: 11000 | G17: 1160 | H17: 1160 | I17: 0 | L17: 1057.7957 | M17: 102.20427 | N17: 0.088107133 | P17: ='KTQT_Trình bày'!Z17 -> 1197.6363 | Q17: 0.03 | R17: =P17*Q17 -> 35.92909 | S17: =P17-R17 -> 1161.7072 | T17: =P17 -> 1197.6363 | U17: 0.1 | V17: =T17*U17 -> 119.76363 | W17: =T17-V17 -> 1077.8727 | X17: =P17-G17 -> 37.636321 | Y17: =X17/G17 -> 0.032445105 | Z17: =P17-AF17 -> 57.636321 | AA17: =Z17/AF17 -> 0.050558177 | AB17: =P17-AG17 -> -102.36368 | AC17: =AB17/AG17 -> -0.078741291 | AD17: =AF17-AH17 -> 300 | AE17: =AG17-AI17 -> 150 | AF17: 1140 | AG17: 1300 | AH17: 840 | AI17: 1150
A18: 3 | B18: 110000383 | C18: Hạt Nhựa rPET iSS84G-P | E18: 52800 | F18: 0 | I18: 0 | L18: 1109.283 | P18: ='KTQT_Trình bày'!Z18 -> 1255.9302 | Q18: 0.03 | R18: =P18*Q18 -> 37.677907 | S18: =P18-R18 -> 1218.2523 | T18: =P18 -> 1255.9302 | U18: 0.1 | V18: =T18*U18 -> 125.59302 | W18: =T18-V18 -> 1130.3372 | X18: =P18-G18 -> 1255.9302 | Y18: =X18/G18 -> #DIV/0! | Z18: =P18-AF18 -> 115.93023 | AA18: =Z18/AF18 -> 0.10169319 | AB18: =P18-AG18 -> -44.069766 | AC18: =AB18/AG18 -> -0.03389982 | AD18: =AF18-AH18 -> 300 | AE18: =AG18-AI18 -> 150 | AF18: 1140 | AG18: 1300 | AH18: 840 | AI18: 1150
A19: 6 | B19: 110000468 | C19: Hạt Nhựa rPET iSS80G-P | E19: 73650 | F19: 0 | I19: 0 | L19: 1042.1887 | P19: ='KTQT_Trình bày'!Z19 -> 1179.966 | Q19: 0.03 | R19: =P19*Q19 -> 35.398981 | S19: =P19-R19 -> 1144.567 | T19: =P19 -> 1179.966 | U19: 0.1 | V19: =T19*U19 -> 117.9966 | W19: =T19-V19 -> 1061.9694 | X19: =P19-G19 -> 1179.966 | Y19: =X19/G19 -> #DIV/0! | Z19: =P19-AF19 -> 39.966023 | AA19: =Z19/AF19 -> 0.035057915 | AB19: =P19-AG19 -> -120.03398 | AC19: =AB19/AG19 -> -0.092333829 | AD19: =AF19-AH19 -> 300 | AE19: =AG19-AI19 -> 150 | AF19: 1140 | AG19: 1300 | AH19: 840 | AI19: 1150
A20: 8 | B20: 110000376 | C20: Hạt nhựa rPET iSS01L | E20: 800 | F20: 0 | I20: 0 | L20: 1176.2642 | P20: ='KTQT_Trình bày'!Z20 -> 1331.7663 | Q20: 0.03 | R20: =P20*Q20 -> 39.952988 | S20: =P20-R20 -> 1291.8133 | T20: =P20 -> 1331.7663 | U20: 0.1 | V20: =T20*U20 -> 133.17663 | W20: =T20-V20 -> 1198.5896 | X20: =P20-G20 -> 1331.7663 | Y20: =X20/G20 -> #DIV/0! | Z20: =P20-AF20 -> 191.76627 | AA20: =Z20/AF20 -> 0.16821603 | AB20: =P20-AG20 -> 31.766272 | AC20: =AB20/AG20 -> 0.024435594 | AD20: =AF20-AH20 -> 300 | AE20: =AG20-AI20 -> 150 | AF20: 1140 | AG20: 1300 | AH20: 840 | AI20: 1150
A21: III | B21: MÃ HÀNG SẢN XUẤT TỪ PHÓ SẢN NGÀNH PET
A22: 1 | B22: 110000466 | C22: Hạt Nhựa rPET WSS05SB-2 | E22: 16099 | F22: 0 | G22: 770 | H22: 770 | I22: 0 | L22: 853 | M22: -83 | N22: -0.10779221 | P22: ='KTQT_Trình bày'!Z22 -> 965.7666 | Q22: 0.03 | R22: =P22*Q22 -> 28.972998 | S22: =P22-R22 -> 936.7936 | T22: =P22 -> 965.7666 | U22: 0.1 | V22: =T22*U22 -> 96.57666 | W22: =T22-V22 -> 869.18994 | X22: =P22-G22 -> 195.7666 | Y22: =X22/G22 -> 0.25424234 | Z22: =P22-AF22 -> -174.2334 | AA22: =Z22/AF22 -> -0.15283632 | AB22: =P22-AG22 -> -334.2334 | AC22: =AB22/AG22 -> -0.25710262 | AD22: =AF22-AH22 -> 300 | AE22: =AG22-AI22 -> 150 | AF22: 1140 | AG22: 1300 | AH22: 840 | AI22: 1150
A23: 2 | B23: 110000436 | C23: Hạt nhựa rPET WSS05SB | E23: 570335.7 | F23: 23100 | G23: 720 | H23: 720 | I23: 0 | L23: 880 | M23: -160 | N23: -0.22222222 | P23: ='KTQT_Trình bày'!Z23 -> 996.336 | Q23: 0.03 | R23: =P23*Q23 -> 29.89008 | S23: =P23-R23 -> 966.44592 | T23: =P23 -> 996.336 | U23: 0.1 | V23: =T23*U23 -> 99.6336 | W23: =T23-V23 -> 896.7024 | X23: =P23-G23 -> 276.336 | Y23: =X23/G23 -> 0.3838 | Z23: =P23-AF23 -> -143.664 | AA23: =Z23/AF23 -> -0.12602105 | AB23: =P23-AG23 -> -303.664 | AC23: =AB23/AG23 -> -0.23358769 | AD23: =AF23-AH23 -> 300 | AE23: =AG23-AI23 -> 150 | AF23: 1140 | AG23: 1300 | AH23: 840 | AI23: 1150
A24: 2 | B24: 110000382 | C24: Hạt nhựa rPET WSS04SB | E24: 4514.7 | F24: 0 | G24: 1030 | H24: 1030 | I24: 0 | L24: 517 | M24: 513 | N24: 0.49805825 | P24: ='KTQT_Trình bày'!Z24 -> 585.3474 | Q24: 0.03 | R24: =P24*Q24 -> 17.560422 | S24: =P24-R24 -> 567.78698 | T24: =P24 -> 585.3474 | U24: 0.1 | V24: =T24*U24 -> 58.53474 | W24: =T24-V24 -> 526.81266 | X24: =P24-G24 -> -444.6526 | Y24: =X24/G24 -> -0.43170155 | Z24: =P24-AF24 -> -554.6526 | AA24: =Z24/AF24 -> -0.48653737 | AB24: =P24-AG24 -> -714.6526 | AC24: =AB24/AG24 -> -0.54973277 | AD24: =AF24-AH24 -> 300 | AE24: =AG24-AI24 -> 150 | AF24: 1140 | AG24: 1300 | AH24: 840 | AI24: 1150
A25: 3 | B25: 110000384 | C25: Hạt Nhựa Xơ Sợi Thử Nghiệm | E25: 171597.5 | F25: 0 | I25: 0 | P25: ='KTQT_Trình bày'!Z25 -> 0 | Q25: 0.03 | R25: =P25*Q25 -> 0 | S25: =P25-R25 -> 0 | T25: =P25 -> 0 | U25: 0.1 | V25: =T25*U25 -> 0 | W25: =T25-V25 -> 0 | X25: =P25-G25 -> 0 | Y25: =X25/G25 -> #DIV/0! | Z25: =P25-AF25 -> -1140 | AA25: =Z25/AF25 -> -1 | AB25: =P25-AG25 -> -1300 | AC25: =AB25/AG25 -> -1 | AD25: =AF25-AH25 -> 300 | AE25: =AG25-AI25 -> 150 | AF25: 1140 | AG25: 1300 | AH25: 840 | AI25: 1150
A26: 3 | B26: 110000381 | C26: Hạt nhựa rPET WSS04SD | E26: 68711.6 | F26: -17600 | G26: 1030 | H26: 1030 | I26: 0 | L26: 579 | M26: 451 | N26: 0.43786408 | P26: ='KTQT_Trình bày'!Z26 -> 655.5438 | Q26: 0.03 | R26: =P26*Q26 -> 19.666314 | S26: =P26-R26 -> 635.87749 | T26: =P26 -> 655.5438 | U26: 0.1 | V26: =T26*U26 -> 65.55438 | W26: =T26-V26 -> 589.98942 | X26: =P26-G26 -> -374.4562 | Y26: =X26/G26 -> -0.36354971 | Z26: =P26-AF26 -> -484.4562 | AA26: =Z26/AF26 -> -0.42496158 | AB26: =P26-AG26 -> -644.4562 | AC26: =AB26/AG26 -> -0.49573554 | AD26: =AF26-AH26 -> 300 | AE26: =AG26-AI26 -> 150 | AF26: 1140 | AG26: 1300 | AH26: 840 | AI26: 1150
A27: 4 | B27: 110000387 | C27: Hạt nhựa rPET WSS03SD | E27: 13179.6 | F27: 0 | G27: 1030 | H27: 1030 | I27: 0 | L27: 668 | M27: 362 | N27: 0.35145631 | P27: ='KTQT_Trình bày'!Z27 -> 756.3096 | Q27: 0.03 | R27: =P27*Q27 -> 22.689288 | S27: =P27-R27 -> 733.62031 | T27: =P27 -> 756.3096 | U27: 0.1 | V27: =T27*U27 -> 75.63096 | W27: =T27-V27 -> 680.67864 | X27: =P27-G27 -> -273.6904 | Y27: =X27/G27 -> -0.26571883 | Z27: =P27-AF27 -> -383.6904 | AA27: =Z27/AF27 -> -0.33657053 | AB27: =P27-AG27 -> -543.6904 | AC27: =AB27/AG27 -> -0.41822338 | AD27: =AF27-AH27 -> 300 | AE27: =AG27-AI27 -> 150 | AF27: 1140 | AG27: 1300 | AH27: 840 | AI27: 1150
A28: 4 | B28: 110000464 | C28: Hạt Nhựa rPET WSS06SP-1 | E28: 90593 | F28: 0 | G28: 570 | H28: 570 | I28: 0 | L28: 589 | M28: -19 | N28: -0.033333333 | P28: ='KTQT_Trình bày'!Z28 -> 666.8658 | Q28: 0.03 | R28: =P28*Q28 -> 20.005974 | S28: =P28-R28 -> 646.85983 | T28: =P28 -> 666.8658 | U28: 0.1 | V28: =T28*U28 -> 66.68658 | W28: =T28-V28 -> 600.17922 | X28: =P28-G28 -> 96.8658 | Y28: =X28/G28 -> 0.16994 | Z28: =P28-AF28 -> -473.1342 | AA28: =Z28/AF28 -> -0.41503 | AB28: =P28-AG28 -> -633.1342 | AC28: =AB28/AG28 -> -0.48702631 | AD28: =AF28-AH28 -> 300 | AE28: =AG28-AI28 -> 150 | AF28: 1140 | AG28: 1300 | AH28: 840 | AI28: 1150
A29: 5 | B29: 110000430 | C29: Hạt Nhựa rPET Bán Thành Phẩm | E29: 37399 | F29: 0 | P29: ='KTQT_Trình bày'!Z29 -> 0 | Q29: 0.03 | R29: =P29*Q29 -> 0 | S29: =P29-R29 -> 0 | T29: =P29 -> 0 | U29: 0.1 | V29: =T29*U29 -> 0 | W29: =T29-V29 -> 0 | X29: =P29-G29 -> 0 | Y29: =X29/G29 -> #DIV/0! | Z29: =P29-AF29 -> -1140 | AA29: =Z29/AF29 -> -1 | AB29: =P29-AG29 -> -1300 | AC29: =AB29/AG29 -> -1 | AD29: =AF29-AH29 -> 300 | AE29: =AG29-AI29 -> 150 | AF29: 1140 | AG29: 1300 | AH29: 840 | AI29: 1150
A30: B | B30: rHDPE THỔI | H30: 220
A31: I | B31: MÃ HÀNG ĐANG BÁN
A32: 1 | B32: 110000339 | C32: Hạt Nhựa rHDPE MBF01 | D32: Trong | E32: 404076.5 | F32: 211750 | I32: 0 | L32: 1076 | P32: ='KTQT_Trình bày'!Z32 -> 1218.2472 | Q32: 0.03 | R32: =P32*Q32 -> 36.547416 | S32: =P32-R32 -> 1181.6998 | T32: =P32 -> 1218.2472 | U32: 0.1 | V32: =T32*U32 -> 121.82472 | W32: =T32-V32 -> 1096.4225 | X32: =P32-G32 -> 1218.2472 | Y32: =X32/G32 -> #DIV/0! | Z32: =P32-AF32 -> 78.2472 | AA32: =Z32/AF32 -> 0.068637895 | AB32: =P32-AG32 -> -81.7528 | AC32: =AB32/AG32 -> -0.062886769 | AD32: =AF32-AH32 -> 300 | AE32: =AG32-AI32 -> 150 | AF32: 1140 | AG32: 1300 | AH32: 840 | AI32: 1150
A33: 2 | B33: 110000426 | C33: Hạt Nhựa HCBF-Yel-U | D33: Vàng | E33: 40547 | F33: 0 | I33: 0 | L33: 1071.1353 | P33: ='KTQT_Trình bày'!Z33 -> 1212.7394 | Q33: 0.03 | R33: =P33*Q33 -> 36.382181 | S33: =P33-R33 -> 1176.3572 | T33: =P33 -> 1212.7394 | U33: 0.1 | V33: =T33*U33 -> 121.27394 | W33: =T33-V33 -> 1091.4654 | X33: =P33-G33 -> 1212.7394 | Y33: =X33/G33 -> #DIV/0! | Z33: =P33-AF33 -> 72.739372 | AA33: =Z33/AF33 -> 0.063806467 | AB33: =P33-AG33 -> -87.260628 | AC33: =AB33/AG33 -> -0.06712356 | AD33: =AF33-AH33 -> 300 | AE33: =AG33-AI33 -> 150 | AF33: 1140 | AG33: 1300 | AH33: 840 | AI33: 1150
A34: 3 | B34: 110000374 | C34: Hạt Nhựa rHDB03N02 | D34: Trong | E34: 326364.4 | F34: 44500 | G34: 1200 | H34: 1200 | I34: 0 | L34: 1076 | M34: 124 | N34: 0.10333333 | P34: ='KTQT_Trình bày'!Z34 -> 1218.2472 | Q34: 0.03 | R34: =P34*Q34 -> 36.547416 | S34: =P34-R34 -> 1181.6998 | T34: =P34 -> 1218.2472 | U34: 0.1 | V34: =T34*U34 -> 121.82472 | W34: =T34-V34 -> 1096.4225 | X34: =P34-G34 -> 18.2472 | Y34: =X34/G34 -> 0.015206 | Z34: =P34-AF34 -> 78.2472 | AA34: =Z34/AF34 -> 0.068637895 | AB34: =P34-AG34 -> -81.7528 | AC34: =AB34/AG34 -> -0.062886769 | AD34: =AF34-AH34 -> 300 | AE34: =AG34-AI34 -> 150 | AF34: 1140 | AG34: 1300 | AH34: 840 | AI34: 1150
A35: 4 | B35: 110000443 | C35: Hạt Nhựa rHDA03N01 | D35: Trong | E35: 1749 | F35: 0 | G35: 1300 | H35: 1300 | I35: 0 | L35: 1083 | M35: 217 | N35: 0.16692308 | P35: ='KTQT_Trình bày'!Z35 -> 1226.1726 | Q35: 0.03 | R35: =P35*Q35 -> 36.785178 | S35: =P35-R35 -> 1189.3874 | T35: =P35 -> 1226.1726 | U35: 0.1 | V35: =T35*U35 -> 122.61726 | W35: =T35-V35 -> 1103.5553 | X35: =P35-G35 -> -73.8274 | Y35: =X35/G35 -> -0.056790308 | Z35: =P35-AF35 -> 86.1726 | AA35: =Z35/AF35 -> 0.07559 | AB35: =P35-AG35 -> -73.8274 | AC35: =AB35/AG35 -> -0.056790308 | AD35: =AF35-AH35 -> 300 | AE35: =AG35-AI35 -> 150 | AF35: 1140 | AG35: 1300 | AH35: 840 | AI35: 1150
A36: 5 | B36: 110000481 | C36: Hạt Nhựa rHDPE PCF01 | D36: Trong | E36: 377595 | F36: 11000 | I36: 0 | L36: 1083 | P36: ='KTQT_Trình bày'!Z36 -> 1226.1726 | Q36: 0.03 | R36: =P36*Q36 -> 36.785178 | S36: =P36-R36 -> 1189.3874 | T36: =P36 -> 1226.1726 | U36: 0.1 | V36: =T36*U36 -> 122.61726 | W36: =T36-V36 -> 1103.5553 | X36: =P36-G36 -> 1226.1726 | Y36: =X36/G36 -> #DIV/0! | Z36: =P36-AF36 -> 86.1726 | AA36: =Z36/AF36 -> 0.07559 | AB36: =P36-AG36 -> -73.8274 | AC36: =AB36/AG36 -> -0.056790308 | AD36: =AF36-AH36 -> 300 | AE36: =AG36-AI36 -> 150 | AF36: 1140 | AG36: 1300 | AH36: 840 | AI36: 1150
A37: 6 | B37: 110000425 | C37: Hạt Nhựa HCBF-Whi-U | D37: Trắng | E37: 93557.5 | F37: 60500 | I37: 0 | L37: 1101.259 | P37: ='KTQT_Trình bày'!Z37 -> 1246.8455 | Q37: 0.03 | R37: =P37*Q37 -> 37.405365 | S37: =P37-R37 -> 1209.4401 | T37: =P37 -> 1246.8455 | U37: 0.1 | V37: =T37*U37 -> 124.68455 | W37: =T37-V37 -> 1122.1609 | X37: =P37-G37 -> 1246.8455 | Y37: =X37/G37 -> #DIV/0! | Z37: =P37-AF37 -> 106.84549 | AA37: =Z37/AF37 -> 0.093724113 | AB37: =P37-AG37 -> -53.154511 | AC37: =AB37/AG37 -> -0.040888086 | AD37: =AF37-AH37 -> 300 | AE37: =AG37-AI37 -> 150 | AF37: 1140 | AG37: 1300 | AH37: 840 | AI37: 1150
A38: 7 | B38: 110000495 | C38: Hạt Nhựa rHDA03W01 | D38: Trắng | E38: 15628 | F38: 0 | G38: 1250 | H38: 1250 | I38: 0 | L38: 1101.259 | M38: 148.74096 | N38: 0.11899277 | P38: ='KTQT_Trình bày'!Z38 -> 1246.8455 | Q38: 0.03 | R38: =P38*Q38 -> 37.405365 | S38: =P38-R38 -> 1209.4401 | T38: =P38 -> 1246.8455 | U38: 0.1 | V38: =T38*U38 -> 124.68455 | W38: =T38-V38 -> 1122.1609 | X38: =P38-G38 -> -3.1545114 | Y38: =X38/G38 -> -0.0025236091 | Z38: =P38-AF38 -> 106.84549 | AA38: =Z38/AF38 -> 0.093724113 | AB38: =P38-AG38 -> -53.154511 | AC38: =AB38/AG38 -> -0.040888086 | AD38: =AF38-AH38 -> 300 | AE38: =AG38-AI38 -> 150 | AF38: 1140 | AG38: 1300 | AH38: 840 | AI38: 1150
A39: II | B39: MÃ HÀNG BÁN CHẬM
A40: 1 | B40: 110000385 | C40: Hạt Nhựa rHDB05N01 | D40: Trong | E40: 2750 | F40: 0 | G40: 1200 | H40: 1200 | I40: 0 | L40: 1189.283 | M40: 10.716981 | N40: 0.0089308176 | P40: ='KTQT_Trình bày'!Z40 -> 1346.5062 | Q40: 0.03 | R40: =P40*Q40 -> 40.395187 | S40: =P40-R40 -> 1306.111 | T40: =P40 -> 1346.5062 | U40: 0.1 | V40: =T40*U40 -> 134.65062 | W40: =T40-V40 -> 1211.8556 | X40: =P40-G40 -> 146.50623 | Y40: =X40/G40 -> 0.12208853 | Z40: =P40-AF40 -> 206.50623 | AA40: =Z40/AF40 -> 0.18114582 | AB40: =P40-AG40 -> 46.506234 | AC40: =AB40/AG40 -> 0.035774026 | AD40: =AF40-AH40 -> 300 | AE40: =AG40-AI40 -> 150 | AF40: 1140 | AG40: 1300 | AH40: 840 | AI40: 1150
...

Sheet KTQT_Trình bày
B1: DANH MỤC THÀNH PHẨM
Z3: CK KD | AD3: ='rPET- nội bộ '!T8&" - PKD" -> - PKD | AH3: ='rPET- nội bộ '!T8 &" - GĐDH & TGĐ" -> - GĐDH & TGĐ | AL3: SV KTQT
A4: STT | B4: Mã SAP | C4: Tên hàng hóa | D4: Màu | E4: Tồn kho 24/02/2026 (kg) | F4: Số lượng bán BQ 2026 (kg/ tháng) | G4: Giá duyệt T2 (USD/ tấn) | H4: Giá bán đề nghị T3 (USD/ tấn) | I4: CL T3 sv T2 (USD/ tấn) | J4: Giá thành | K4: CPQL | L4: Giá vốn | M4: Lợi nhuận trước thuế | N4: % lợi nhuận trước thuế | O4: Giá đề nghị của kinh doanh | P4: Ghi chú | Q4: Sử dụng phó sản | S4: Giá bán đảm bảo LH 20% | T4: Lợi nhuận gộp | U4: % Lợi nhuận gộp | V4: Giá bán đảm bảo LNTT 10% | W4: Lợi nhuận trước thuế | X4: % Lợi nhuận trước thuế | Z4: Giá bán đảm bảo LNTT 10% | AA4: Lợi nhuận trước thuế | AB4: % Lợi nhuận trước thuế | AD4: Giá Bán (1) | AE4: % Chiết khấu (2) | AF4: Chiết Khấu (3) | AG4: Giá bán sau chiết khấu (4)=(1)-(3) | AH4: Giá Bán (1) | AI4: % Chiết khấu (2) | AJ4: Chiết Khấu (3) | AK4: Giá bán sau chiết khấu (4)=(1)-(3) | AL4: (-) USD | AM4: (-) USD
A5: A | B5: rPET | Z5: =L7/0.9 -> 1175.3286 | AA5: =Z5-J7 -> 242.53286 | AB5: =AA5/Z5 -> 0.20635324
A6: I | B6: MÃ HÀNG ĐANG BÁN | S6: 0.25 | V6: 0.11 | Z6: 0.02 | AA6: =Z5-L7 -> 117.53286 | AB6: =AA6/Z5 -> 0.1
A7: 1 | B7: 110000354 | C7: Hạt nhựa rPET WSS01G 1 | E7: 503605 | F7: 2663100 | G7: 1160 | H7: 1160 | I7: 0 | J7: =L7-K7 -> 932.79573 | K7: 125 | L7: 1057.7957 | M7: 102.20427 | N7: 0.088107133 | S7: =J7+J7*$S$6 -> 1165.9947 | T7: =S7-J7 -> 233.19893 | U7: =T7/S7 -> 0.2 | V7: =L7+L7*$V$6 -> 1174.1533 | W7: =V7-L7 -> 116.35753 | X7: =W7/S7 -> 0.099792507 | Z7: =V7+V7*Z$6 -> 1197.6363 | AA7: =Z7-L7 -> 139.8406 | AB7: =AA7/Z7 -> 0.11676382 | AD7: =Z7 -> 1197.6363 | AE7: 0.03 | AF7: =AD7*AE7 -> 35.92909 | AG7: =AD7-AF7 -> 1161.7072 | AH7: =AD7 -> 1197.6363 | AI7: 0.05 | AJ7: =AH7*AI7 -> 59.881816 | AK7: =AH7-AJ7 -> 1137.7545 | AL7: =AG7-H7 -> 1.7072317 | AM7: =AK7-H7 -> -22.245495
A8: 2 | B8: 110000355 | C8: Hạt nhựa rPET iSS01G 1 | E8: 154879.75 | F8: 25300 | G8: 1190 | H8: 1190 | I8: 0 | J8: =L8-K8 -> 932.79573 | K8: 125 | L8: 1057.7957 | M8: 132.20427 | N8: 0.11109603 | S8: =J8+J8*$S$6 -> 1165.9947 | T8: =S8-J8 -> 233.19893 | U8: =T8/S8 -> 0.2 | V8: =L8+L8*$V$6 -> 1174.1533 | W8: =V8-L8 -> 116.35753 | X8: =W8/S8 -> 0.099792507 | Z8: =V8+V8*Z$6 -> 1197.6363 | AA8: =Z8-L8 -> 139.8406 | AB8: =AA8/Z8 -> 0.11676382 | AD8: =Z8 -> 1197.6363 | AE8: 0.03 | AF8: =AD8*AE8 -> 35.92909 | AG8: =AD8-AF8 -> 1161.7072 | AH8: =AD8 -> 1197.6363 | AI8: 0.05 | AJ8: =AH8*AI8 -> 59.881816 | AK8: =AH8-AJ8 -> 1137.7545 | AL8: =AG8-H8 -> -28.292768 | AM8: =AK8-H8 -> -52.245495
A9: 3 | B9: 110000332 | C9: Hạt nhựa rPET iSS01084G | E9: 788631.35 | F9: 616000 | G9: 1250 | H9: 1250 | I9: 0 | J9: =L9-K9 -> 988.77053 | K9: 125 | L9: 1113.7705 | M9: 136.22947 | N9: 0.10898358 | S9: =J9+J9*$S$6 -> 1235.9632 | T9: =S9-J9 -> 247.19263 | U9: =T9/S9 -> 0.2 | V9: =L9+L9*$V$6 -> 1236.2853 | W9: =V9-L9 -> 122.51476 | X9: =W9/S9 -> 0.099124927 | Z9: =V9+V9*Z$6 -> 1261.011 | AA9: =Z9-L9 -> 147.24046 | AB9: =AA9/Z9 -> 0.11676382 | AD9: =Z9 -> 1261.011 | AE9: 0.03 | AF9: =AD9*AE9 -> 37.83033 | AG9: =AD9-AF9 -> 1223.1807 | AH9: =AD9 -> 1261.011 | AI9: 0.05 | AJ9: =AH9*AI9 -> 63.050549 | AK9: =AH9-AJ9 -> 1197.9604 | AL9: =AG9-H9 -> -26.81934 | AM9: =AK9-H9 -> -52.03956
A10: 4 | B10: 110000359 | C10: Hạt nhựa rPET WSS03G | E10: 1999804.7 | F10: 244200 | G10: 1090 | H10: 1090 | I10: 0 | J10: =L10-K10 -> 932.79573 | K10: 125 | L10: 1057.7957 | M10: 32.204274 | N10: 0.029545205 | S10: =J10+J10*$S$6 -> 1165.9947 | T10: =S10-J10 -> 233.19893 | U10: =T10/S10 -> 0.2 | V10: =L10+L10*$V$6 -> 1174.1533 | W10: =V10-L10 -> 116.35753 | X10: =W10/S10 -> 0.099792507 | Z10: =V10+V10*Z$6 -> 1197.6363 | AA10: =Z10-L10 -> 139.8406 | AB10: =AA10/Z10 -> 0.11676382 | AD10: =Z10 -> 1197.6363 | AE10: 0.03 | AF10: =AD10*AE10 -> 35.92909 | AG10: =AD10-AF10 -> 1161.7072 | AH10: =AD10 -> 1197.6363 | AI10: 0.05 | AJ10: =AH10*AI10 -> 59.881816 | AK10: =AH10-AJ10 -> 1137.7545 | AL10: =AG10-H10 -> 71.707232 | AM10: =AK10-H10 -> 47.754505
A11: 5 | B11: 110000329 | C11: Hạt nhựa rPET WSS01 | E11: 378162 | F11: 0 | G11: 1320 | H11: 1320 | I11: 0 | J11: =L11-K11 -> 1030.3596 | K11: 125 | L11: 1155.3596 | M11: 164.64035 | N11: 0.12472754 | P11: Bán cho Lavie | S11: =J11+J11*$S$6 -> 1287.9496 | T11: =S11-J11 -> 257.58991 | U11: =T11/S11 -> 0.2 | V11: =L11+L11*$V$6 -> 1282.4492 | W11: =V11-L11 -> 127.08956 | X11: =W11/S11 -> 0.098675884 | Z11: =V11+V11*Z$6 -> 1308.0982 | AA11: =Z11-L11 -> 152.73855 | AB11: =AA11/Z11 -> 0.11676382 | AD11: =Z11 -> 1308.0982 | AE11: 0.03 | AF11: =AD11*AE11 -> 39.242946 | AG11: =AD11-AF11 -> 1268.8552 | AH11: =AD11 -> 1308.0982 | AI11: 0.05 | AJ11: =AH11*AI11 -> 65.40491 | AK11: =AH11-AJ11 -> 1242.6933 | AL11: =AG11-H11 -> -51.144751 | AM11: =AK11-H11 -> -77.306715
A12: 7 | B12: 110000499 | C12: Hạt Nhựa rPET WSS01L | E12: 34030 | F12: 0 | G12: 1160 | H12: 1160 | I12: 0 | J12: =L12-K12 -> 881.56604 | K12: 125 | L12: 1006.566 | M12: 153.43396 | N12: 0.13227066 | S12: =J12+J12*$S$6 -> 1101.9575 | T12: =S12-J12 -> 220.39151 | U12: =T12/S12 -> 0.2 | V12: =L12+L12*$V$6 -> 1117.2883 | W12: =V12-L12 -> 110.72226 | X12: =W12/S12 -> 0.10047779 | Z12: =V12+V12*Z$6 -> 1139.6341 | AA12: =Z12-L12 -> 133.06803 | AB12: =AA12/Z12 -> 0.11676382 | AD12: =Z12 -> 1139.6341 | AE12: 0.03 | AF12: =AD12*AE12 -> 34.189022 | AG12: =AD12-AF12 -> 1105.445 | AH12: =AD12 -> 1139.6341 | AI12: 0.05 | AJ12: =AH12*AI12 -> 56.981703 | AK12: =AH12-AJ12 -> 1082.6524 | AL12: =AG12-H12 -> -54.554954 | AM12: =AK12-H12 -> -77.347635
A13: 9 | B13: 110000506 | C13: Hạt Nhựa rPET WSS01 & WSS01G-L | E13: 65840 | F13: 0 | G13: 1410 | H13: 690 | I13: -720 | J13: =L13-K13 -> 1097.6415 | K13: 125 | L13: 1222.6415 | M13: -532.64151 | N13: -0.77194422 | P13: Bán cho Lavie | Q13: Giá tồn kho | S13: =J13+J13*$S$6 -> 1372.0519 | T13: =S13-J13 -> 274.41038 | U13: =T13/S13 -> 0.2 | V13: =L13+L13*$V$6 -> 1357.1321 | W13: =V13-L13 -> 134.49057 | X13: =W13/S13 -> 0.098021487 | Z13: =V13+V13*Z$6 -> 1384.2747 | AA13: =Z13-L13 -> 161.63321 | AB13: =AA13/Z13 -> 0.11676382 | AD13: =Z13 -> 1384.2747 | AE13: 0.03 | AF13: =AD13*AE13 -> 41.528242 | AG13: =AD13-AF13 -> 1342.7465 | AH13: =AD13 -> 1384.2747 | AI13: 0.05 | AJ13: =AH13*AI13 -> 69.213736 | AK13: =AH13-AJ13 -> 1315.061 | AL13: =AG13-H13 -> 652.74648 | AM13: =AK13-H13 -> 625.06098
A14: 10 | B14: 110000483 | C14: Hạt Nhựa rPET iSS01G-S | E14: 32405.5 | F14: 6600 | G14: 1190 | H14: 1190 | I14: 0 | J14: =L14-K14 -> 992.16981 | K14: 125 | L14: 1117.1698 | M14: 72.830189 | N14: 0.061201839 | P14: Sản phẩm mới | Q14: Giá tồn kho | S14: =J14+J14*$S$6 -> 1240.2123 | T14: =S14-J14 -> 248.04245 | U14: =T14/S14 -> 0.2 | V14: =L14+L14*$V$6 -> 1240.0585 | W14: =V14-L14 -> 122.88868 | X14: =W14/S14 -> 0.099086812 | Z14: =V14+V14*Z$6 -> 1264.8597 | AA14: =Z14-L14 -> 147.68985 | AB14: =AA14/Z14 -> 0.11676382 | AD14: =Z14 -> 1264.8597 | AE14: 0.03 | AF14: =AD14*AE14 -> 37.94579 | AG14: =AD14-AF14 -> 1226.9139 | AH14: =AD14 -> 1264.8597 | AI14: 0.05 | AJ14: =AH14*AI14 -> 63.242983 | AK14: =AH14-AJ14 -> 1201.6167 | AL14: =AG14-H14 -> 36.913871 | AM14: =AK14-H14 -> 11.616677
A15: II | B15: MÃ HÀNG BÁN CHẬM | S15: 0.25 | V15: 0.11
A16: 1 | B16: 110000378 | C16: Hạt nhựa rPET iSS01G 2 | E16: 1649997 | F16: 0 | G16: 1190 | H16: 1190 | I16: 0 | J16: =L16-K16 -> 932.79573 | K16: 125 | L16: 1057.7957 | M16: 132.20427 | N16: 0.11109603 | P16: Chuyển thành mã iSS01G 1 để bán | S16: =J16+J16*$S$15 -> 1165.9947 | T16: =S16-J16 -> 233.19893 | U16: =T16/S16 -> 0.2 | V16: =L16+L16*$V$15 -> 1174.1533 | W16: =V16-L16 -> 116.35753 | X16: =W16/S16 -> 0.099792507 | Z16: =V16+V16*Z$6 -> 1197.6363 | AA16: =Z16-L16 -> 139.8406 | AB16: =AA16/Z16 -> 0.11676382 | AD16: =Z16 -> 1197.6363 | AE16: 0.03 | AF16: =AD16*AE16 -> 35.92909 | AG16: =AD16-AF16 -> 1161.7072 | AH16: =AD16 -> 1197.6363 | AI16: 0.05 | AJ16: =AH16*AI16 -> 59.881816 | AK16: =AH16-AJ16 -> 1137.7545 | AL16: =AG16-H16 -> -28.292768 | AM16: =AK16-H16 -> -52.245495
A17: 2 | B17: 110000377 | C17: Hạt nhựa rPET WSS01G 2 | E17: 287099.5 | F17: 11000 | G17: 1160 | H17: 1160 | I17: 0 | J17: =L17-K17 -> 932.79573 | K17: 125 | L17: 1057.7957 | M17: 102.20427 | N17: 0.088107133 | P17: Chuyển thành mã wSS01G 1 để bán | S17: =J17+J17*$S$15 -> 1165.9947 | T17: =S17-J17 -> 233.19893 | U17: =T17/S17 -> 0.2 | V17: =L17+L17*$V$15 -> 1174.1533 | W17: =V17-L17 -> 116.35753 | X17: =W17/S17 -> 0.099792507 | Z17: =V17+V17*Z$6 -> 1197.6363 | AA17: =Z17-L17 -> 139.8406 | AB17: =AA17/Z17 -> 0.11676382 | AD17: =Z17 -> 1197.6363 | AE17: 0.03 | AF17: =AD17*AE17 -> 35.92909 | AG17: =AD17-AF17 -> 1161.7072 | AH17: =AD17 -> 1197.6363 | AI17: 0.05 | AJ17: =AH17*AI17 -> 59.881816 | AK17: =AH17-AJ17 -> 1137.7545 | AL17: =AG17-H17 -> 1.7072317 | AM17: =AK17-H17 -> -22.245495
A18: 3 | B18: 110000383 | C18: Hạt Nhựa rPET iSS84G-P | E18: 52800 | F18: 0 | I18: 0 | J18: =L18-K18 -> 984.28302 | K18: 125 | L18: 1109.283 | P18: Không báo giá (SP SX bán cho Amcor) | Q18: Giá tồn kho | S18: =J18+J18*$S$15 -> 1230.3538 | T18: =S18-J18 -> 246.07075 | U18: =T18/S18 -> 0.2 | V18: =L18+L18*$V$15 -> 1231.3042 | W18: =V18-L18 -> 122.02113 | X18: =W18/S18 -> 0.099175647 | Z18: =V18+V18*Z$6 -> 1255.9302 | AA18: =Z18-L18 -> 146.64722 | AB18: =AA18/Z18 -> 0.11676382 | AD18: =Z18 -> 1255.9302 | AE18: 0.03 | AF18: =AD18*AE18 -> 37.677907 | AG18: =AD18-AF18 -> 1218.2523 | AH18: =AD18 -> 1255.9302 | AI18: 0.05 | AJ18: =AH18*AI18 -> 62.796512 | AK18: =AH18-AJ18 -> 1193.1337 | AL18: =AG18-H18 -> 1218.2523 | AM18: =AK18-H18 -> 1193.1337
A19: 6 | B19: 110000468 | C19: Hạt Nhựa rPET iSS80G-P | E19: 73650 | F19: 0 | I19: 0 | J19: =L19-K19 -> 917.18868 | K19: 125 | L19: 1042.1887 | P19: Không báo giá (SP SX bán cho Amcor) | Q19: Giá tồn kho | S19: =J19+J19*$S$15 -> 1146.4858 | T19: =S19-J19 -> 229.29717 | U19: =T19/S19 -> 0.2 | V19: =L19+L19*$V$15 -> 1156.8294 | W19: =V19-L19 -> 114.64075 | X19: =W19/S19 -> 0.09999317 | Z19: =V19+V19*Z$6 -> 1179.966 | AA19: =Z19-L19 -> 137.77734 | AB19: =AA19/Z19 -> 0.11676382 | AD19: =Z19 -> 1179.966 | AE19: 0.03 | AF19: =AD19*AE19 -> 35.398981 | AG19: =AD19-AF19 -> 1144.567 | AH19: =AD19 -> 1179.966 | AI19: 0.05 | AJ19: =AH19*AI19 -> 58.998301 | AK19: =AH19-AJ19 -> 1120.9677 | AL19: =AG19-H19 -> 1144.567 | AM19: =AK19-H19 -> 1120.9677
