Workbook
Name \0: #REF!
Name \a: #REF!
Name \b: #REF!
Name \c: #REF!
Name \C_: #REF!
Name \e: #REF!
Name \f: #REF!
Name \k: #REF!
Name \m: #REF!
Name \o: #REF!
Name \p: #REF!
Name \q: #N/A
Name \r: #REF!
Name \s: #REF!
Name \t: #REF!
Name \x: #REF!
Name \z: #REF!
Name _???: #REF!
Name _????????: #REF!
Name _????????????: #REF!
Name _?????????????: #N/A
Name _?_??????: #REF!
Name _?1_HP_A: #REF!
Name _?1_HP_B: #REF!
Name _?2_HP_A: #REF!
Name _?2_HP_B: #REF!
Name _?3_HP_A: #REF!
Name _?3_HP_B: #REF!
Name _?5_HP: #REF!
Name __???: #N/A
Name __????????????: #REF!
Name __?????????????: #REF!
Name ______TAX2: #REF!
Name _____06: #REF!
Name _____CWF1: #REF!
Name _____CWF2: #REF!
Name _____DAT1: #REF!
Name _____DAT10: #REF!
Name _____DAT2: #REF!
Name _____DAT3: #REF!
Name _____DAT4: #REF!
Name _____DAT5: #REF!
Name _____DAT6: #REF!
Name _____DAT7: #REF!
Name _____DAT8: #REF!
Name _____DAT9: #REF!
Name _____UWF1: #REF!
Name _____UWF2: #REF!
Name ____06: #REF!
Name ____CWF1: #REF!
Name ____CWF2: #REF!
Name ____DAT1: #REF!
Name ____DAT10: #REF!
Name ____DAT2: #REF!
Name ____DAT3: #REF!
Name ____DAT4: #REF!
Name ____DAT5: #REF!
Name ____DAT6: #REF!
Name ____DAT7: #REF!
Name ____DAT8: #REF!

Sheet Performance
E1: PERFORMANCE | F1: =IF(K1="EN","PERFORMANCE","KẾT QUẢ KINH DOANH") -> KẾT QUẢ KINH DOANH | G1: 2024 | H1: 2025 | I1: 2026 | K1: VN | O1: 2024 | P1: 2025 | Q1: 2026
E2: =F2 -> DTR | F2: DTR | G2: 12 | H2: 5 | I2: 5 | J2: =IF(K1="EN","Unit:","Đvt:") -> Đvt: | K2: Triệu VND | O2: =G2 -> 12 | P2: =H2 -> 5 | Q2: =I2 -> 5 | X2: =H2 -> 5 | Y2: =I2 -> 5
E3: PROFIT & LOSS | F3: =IF($K$1="EN",E3,"KẾT QUẢ KINH DOANH") -> KẾT QUẢ KINH DOANH | G3: =IF(J1="EN",IF(G2=12,"FY "&G1,"YTD "&G1),IF(G2=12,"Năm "&G1,"LK "&G1)) -> Năm 2024 | H3: =IF(K1="EN",IF(H2=12,"FY "&H1,"YTD "&H1),IF(H2=12,"Năm "&H1,"LK "&H1)) -> LK 2025 | I3: =IF(K1="EN",IF(I2=12,"FY "&I1,"YTD "&I1),IF(I2=12,"Năm "&I1,"LK "&I1)) -> LK 2026 | J3: =IF($K$1="EN","Change from last year","So với năm trước") -> So với năm trước | M3: =IF(K1="EN",N3,"BẢNG CÂN ĐỐI KẾ TOÁN") -> BẢNG CÂN ĐỐI KẾ TOÁN | N3: BALANCE SHEET | O3: =IF(K1="EN"," "&O2&"/"&RIGHT(O1,4),O2&"/"&RIGHT(O1,4)) -> 12/2024 | P3: =IF(K1="EN"," "&P2&"/"&RIGHT(P1,4),P2&"/"&RIGHT(P1,4)) -> 5/2025 | Q3: =IF(K1="EN"," "&Q2&"/" &RIGHT(Q1,4),Q2&"/"&RIGHT(Q1,4)) -> 5/2026 | R3: =J3 -> So với năm trước | V3: =IF(K1="EN","Key Financial Indicators","CHỈ SỐ TÀI CHÍNH") -> CHỈ SỐ TÀI CHÍNH | W3: =G3 -> Năm 2024 | X3: =H3 -> LK 2025 | Y3: =I3 -> LK 2026 | Z3: =IF(K1="EN","Ref.","Tham chiếu") -> Tham chiếu
E4: Production volume | F4: =IF($K$1="EN",E4,"Sản lượng sản xuất (Tấn)") -> Sản lượng sản xuất (Tấn) | G4: =IFERROR(SUMIFS(Data!Q:Q,Data!B:B,Performance!$E$2,Data!D:D,Performance!E4),"") -> 21515.497 | H4: =IFERROR(SUMIFS(Data!AD:AD,Data!B:B,Performance!$E$2,Data!D:D,Performance!E4),"") -> 18536.137 | I4: =IFERROR(SUMIFS(Data!AR:AR,Data!B:B,Performance!$E$2,Data!D:D,Performance!E4),"") -> 16555.638 | J4: =IFERROR(I4-H4,"") -> -1980.4994 | K4: =IFERROR(J4/H4,"") -> -0.10684532 | M4: =IF(K1="en",N4,"Tài sản ngắn hạn") -> Tài sản ngắn hạn | N4: Current Assets | O4: =IF($K$2="USD",SUMIFS(Data!Q:Q,Data!B:B,Performance!$F$2,Data!D:D,Performance!N4)*10^6,SUMIFS(Data!Q:Q,Data!B:B,Performance!$F$2,Data!D:D,Performance!N4)) -> 928155716736 | P4: =IF($K$2="USD",SUMIFS(Data!AD:AD,Data!B:B,Performance!$E$2,Data!D:D,Performance!N4)*10^6,SUMIFS(Data!AD:AD,Data!B:B,Performance!$E$2,Data!D:D,Performance!N4)) -> 981599372849 | Q4: =IF($K$2="USD",SUMIFS(Data!AR:AR,Data!B:B,Performance!$F$2,Data!D:D,Performance!N4)*10^6,SUMIFS(Data!AR:AR,Data!B:B,Performance!$F$2,Data!D:D,Performance!N4)) -> 886588369025 | R4: =Q4-P4 -> -95011003824 | S4: =IFERROR(R4/P4,"") -> -0.096792038 | U4: 1 | V4: =IF(K1="EN","SG&A / Net sales","CP bán hàng & quản lý / Doanh thu") -> CP bán hàng & quản lý / Doanh thu | W4: =IFERROR((G24-G29)/G6,0) -> 0.068520423 | X4: =IFERROR((H24-H29)/H6,0) -> 0.068898903 | Y4: =IFERROR((I24-I29)/I6,0) -> 0.080839702 | Z4: 0.1 | AC4: =P3 -> 5/2025 | AD4: =Q3 -> 5/2026
E5: Sales volume | F5: =IF($K$1="EN",E5,"Sản lượng bán")& IF(F2="DTPM"," (molds)"," (Tấn)") -> Sản lượng bán (Tấn) | G5: =SUMIFS(Data!Q:Q,Data!B:B,Performance!$E$2,Data!D:D,Performance!E5) -> 15468.961 | H5: =SUMIFS(Data!AD:AD,Data!B:B,Performance!$E$2,Data!D:D,Performance!E5) -> 23446.449 | I5: =SUMIFS(Data!AR:AR,Data!B:B,Performance!$E$2,Data!D:D,Performance!E5) -> 25012.587 | J5: =I5-H5 -> 1566.1384 | K5: =IFERROR(J5/H5,"") -> 0.066796402 | M5: =IF($K$1="EN",N5,"Tiền") -> Tiền | N5: Cash | O5: =IF($K$2="USD",SUMIFS(Data!Q:Q,Data!B:B,Performance!$F$2,Data!D:D,Performance!N5)*10^6,SUMIFS(Data!Q:Q,Data!B:B,Performance!$F$2,Data!D:D,Performance!N5)) -> 16007340290 | P5: =IF($K$2="USD",SUMIFS(Data!AD:AD,Data!B:B,Performance!$E$2,Data!D:D,Performance!N5)*10^6,SUMIFS(Data!AD:AD,Data!B:B,Performance!$E$2,Data!D:D,Performance!N5)) -> 21868727527 | Q5: =IF($K$2="USD",SUMIFS(Data!AR:AR,Data!B:B,Performance!$F$2,Data!D:D,Performance!N5)*10^6,SUMIFS(Data!AR:AR,Data!B:B,Performance!$F$2,Data!D:D,Performance!N5)) -> 41014004605 | R5: =Q5-P5 -> 19145277078 | S5: =IFERROR(R5/P5,"") -> 0.8754637 | U5: 2 | V5: =IF(K1="EN","Gross profit margin","Tỷ suất lợi nhuận gộp") -> Tỷ suất lợi nhuận gộp | W5: =IFERROR(G23/G6,0) -> 0.06734304 | X5: =IFERROR(H23/H6,0) -> 0.15103121 | Y5: =IFERROR(I23/I6,0) -> 0.090643578 | Z5: 0.25 | AB5: Tổng nợ | AC5: =P14+P17 -> 383542692015 | AD5: =Q14+Q17 -> 374252871584 | AE5: =AD5-AC5 -> -9289820431
E6: NET SALES | F6: =IF($K$1="EN",E6,"Doanh thu thuần") -> Doanh thu thuần | G6: =IF($K$2="USD",SUMIFS(Data!Q:Q,Data!B:B,Performance!$E$2,Data!D:D,Performance!E6)*10^6,SUMIFS(Data!Q:Q,Data!B:B,Performance!$E$2,Data!D:D,Performance!E6)) -> 456864963103 | H6: =IF($K$2="USD",SUMIFS(Data!AD:AD,Data!B:B,Performance!$E$2,Data!D:D,Performance!E6)*10^6,SUMIFS(Data!AD:AD,Data!B:B,Performance!$E$2,Data!D:D,Performance!E6)) -> 730212096848 | I6: =IF($K$2="USD",SUMIFS(Data!AR:AR,Data!B:B,Performance!$E$2,Data!D:D,Performance!E6)*10^6,SUMIFS(Data!AR:AR,Data!B:B,Performance!$E$2,Data!D:D,Performance!E6)) -> 714793828678 | J6: =I6-H6 -> -15418268170 | K6: =IFERROR(I6/H6-1,0) -> -0.021114781 | M6: =IF($K$1="EN",N6,"Đầu tư tài chính ngắn hạn") -> Đầu tư tài chính ngắn hạn | N6: Financial investment | O6: =IF($K$2="USD",SUMIFS(Data!Q:Q,Data!B:B,Performance!$F$2,Data!D:D,Performance!N6)*10^6,SUMIFS(Data!Q:Q,Data!B:B,Performance!$F$2,Data!D:D,Performance!N6)) -> 2010000000 | P6: =IF($K$2="USD",SUMIFS(Data!AD:AD,Data!B:B,Performance!$E$2,Data!D:D,Performance!N6)*10^6,SUMIFS(Data!AD:AD,Data!B:B,Performance!$E$2,Data!D:D,Performance!N6)) -> 22840000000 | Q6: =IF($K$2="USD",SUMIFS(Data!AR:AR,Data!B:B,Performance!$F$2,Data!D:D,Performance!N6)*10^6,SUMIFS(Data!AR:AR,Data!B:B,Performance!$F$2,Data!D:D,Performance!N6)) -> 34340000000 | R6: =Q6-P6 -> 11500000000 | S6: =IFERROR(R6/P6,"") -> 0.50350263 | U6: 3 | V6: =IF(K1="EN","EBITDA margin","Tỷ suất EBITDA") -> Tỷ suất EBITDA | W6: =IFERROR(G35/G6,0) -> 0.023923692 | X6: =IFERROR(H35/H6,0) -> 0.10211502 | Y6: =IFERROR(I35/I6,0) -> 0.01843225 | Z6: 0.2 | AB6: Vốn điều lệ | AC6: =P19-P20 -> 650000000000 | AD6: =Q19-Q20 -> 650000000000
E7: Export | F7: Xuất khẩu | G7: =IF(J2="USD",SUMIFS(Data!Q:Q,Data!B:B,Performance!$E$2,Data!D:D,Performance!E7)*10^6,SUMIFS(Data!Q:Q,Data!B:B,Performance!$E$2,Data!D:D,Performance!E7)) -> 410615873525 | H7: =IF(K2="USD",SUMIFS(Data!AD:AD,Data!B:B,Performance!$E$2,Data!D:D,Performance!E7)*10^6,SUMIFS(Data!AD:AD,Data!B:B,Performance!$E$2,Data!D:D,Performance!E7)) -> 518069151644 | I7: =IF(K2="USD",SUMIFS(Data!AR:AR,Data!B:B,Performance!$E$2,Data!D:D,Performance!E7)*10^6,SUMIFS(Data!AR:AR,Data!B:B,Performance!$E$2,Data!D:D,Performance!E7)) -> 364524912433 | J7: =I7-H7 -> -153544239211 | K7: =IFERROR(J7/H7,"") -> -0.29637788 | M7: =IF($K$1="EN",N7,"Các khoản phải thu") -> Các khoản phải thu | N7: Account receivables | O7: =IF($K$2="USD",SUMIFS(Data!Q:Q,Data!B:B,Performance!$F$2,Data!D:D,Performance!N7)*10^6,SUMIFS(Data!Q:Q,Data!B:B,Performance!$F$2,Data!D:D,Performance!N7)) -> 304477407097 | P7: =IF($K$2="USD",SUMIFS(Data!AD:AD,Data!B:B,Performance!$E$2,Data!D:D,Performance!N7)*10^6,SUMIFS(Data!AD:AD,Data!B:B,Performance!$E$2,Data!D:D,Performance!N7)) -> 355551041672 | Q7: =IF($K$2="USD",SUMIFS(Data!AR:AR,Data!B:B,Performance!$F$2,Data!D:D,Performance!N7)*10^6,SUMIFS(Data!AR:AR,Data!B:B,Performance!$F$2,Data!D:D,Performance!N7)) -> 417392857129 | R7: =Q7-P7 -> 61841815457 | S7: =IFERROR(R7/P7,"") -> 0.17393231 | U7: 4 | V7: =IF(K1="EN","Net profit margin (ROS)","Tỷ suất lợi nhuận sau thuế (ROS)") -> Tỷ suất lợi nhuận sau thuế (ROS) | W7: =IFERROR(G38/G6,0) -> -0.017472065 | X7: =IFERROR(H38/H6,0) -> 0.058445093 | Y7: =IFERROR(I38/I6,0) -> -0.0039828288 | Z7: 0.1 | AB7: Lợi nhuận luỹ kế | AC7: =P20 -> 247436969996 | AD7: =Q20 -> 227649509332 | AE7: =AD7-AC7 -> -19787460664
E8: Domestic | F8: Nội địa | G8: =IF(J2="USD",SUMIFS(Data!Q:Q,Data!B:B,Performance!$E$2,Data!D:D,Performance!E8)*10^6,SUMIFS(Data!Q:Q,Data!B:B,Performance!$E$2,Data!D:D,Performance!E8)) -> 161696678485 | H8: =IF(K2="USD",SUMIFS(Data!AD:AD,Data!B:B,Performance!$E$2,Data!D:D,Performance!E8)*10^6,SUMIFS(Data!AD:AD,Data!B:B,Performance!$E$2,Data!D:D,Performance!E8)) -> 211963572602 | I8: =IF(K2="USD",SUMIFS(Data!AR:AR,Data!B:B,Performance!$E$2,Data!D:D,Performance!E8)*10^6,SUMIFS(Data!AR:AR,Data!B:B,Performance!$E$2,Data!D:D,Performance!E8)) -> 346764544100 | J8: =I8-H8 -> 134800971498 | K8: =IFERROR(J8/H8,"") -> 0.63596291 | M8: =IF($K$1="EN",N8,"Hàng tồn kho") -> Hàng tồn kho | N8: Inventory | O8: =IF($K$2="USD",SUMIFS(Data!Q:Q,Data!B:B,Performance!$F$2,Data!D:D,Performance!N8)*10^6,SUMIFS(Data!Q:Q,Data!B:B,Performance!$F$2,Data!D:D,Performance!N8)) -> 541180364701 | P8: =IF($K$2="USD",SUMIFS(Data!AD:AD,Data!B:B,Performance!$E$2,Data!D:D,Performance!N8)*10^6,SUMIFS(Data!AD:AD,Data!B:B,Performance!$E$2,Data!D:D,Performance!N8)) -> 526499028418 | Q8: =IF($K$2="USD",SUMIFS(Data!AR:AR,Data!B:B,Performance!$F$2,Data!D:D,Performance!N8)*10^6,SUMIFS(Data!AR:AR,Data!B:B,Performance!$F$2,Data!D:D,Performance!N8)) -> 361880765551 | R8: =Q8-P8 -> -164618262867 | S8: =IFERROR(R8/P8,"") -> -0.31266584 | U8: 5 | V8: =IF(K1="EN","Net contribution margin","Tỷ suất lãi biến phí") -> Tỷ suất lãi biến phí | W8: =IFERROR((G6-G11-G12-G13-G29-G21-G27-G28-G22)/G6,0) -> 0.35666237 | X8: =IFERROR((H6-H11-H12-H13-H29-H21-H27-H28-H22)/H6,0) -> 0.29301473 | Y8: =IFERROR((I6-I11-I12-I13-I29-I21-I28-I27-I22)/I6,0) -> 0.23303561 | Z8: 0.4 | AB8: Tổng nguồn vốn | AC8: =SUM(AC5:AC7) -> 1280979662011 | AD8: =SUM(AD5:AD7) -> 1251902380916
E9: Others | F9: Khác | G9: =IF(J2="USD",SUMIFS(Data!Q:Q,Data!B:B,Performance!$E$2,Data!D:D,Performance!E9)*10^6,SUMIFS(Data!Q:Q,Data!B:B,Performance!$E$2,Data!D:D,Performance!E9)) -> 0 | H9: =IF(K2="USD",SUMIFS(Data!AD:AD,Data!B:B,Performance!$E$2,Data!D:D,Performance!E9)*10^6,SUMIFS(Data!AD:AD,Data!B:B,Performance!$E$2,Data!D:D,Performance!E9)) -> 179372602 | I9: =IF(K2="USD",SUMIFS(Data!AR:AR,Data!B:B,Performance!$E$2,Data!D:D,Performance!E9)*10^6,SUMIFS(Data!AR:AR,Data!B:B,Performance!$E$2,Data!D:D,Performance!E9)) -> 3504372145 | J9: =I9-H9 -> 3324999543 | K9: =IFERROR(J9/H9,0) -> 18.536831 | M9: =IF($K$1="EN",N9,"Tài sản dài hạn") -> Tài sản dài hạn | N9: Long-term assets | O9: =IF($K$2="USD",SUMIFS(Data!Q:Q,Data!B:B,Performance!$F$2,Data!D:D,Performance!N9)*10^6,SUMIFS(Data!Q:Q,Data!B:B,Performance!$F$2,Data!D:D,Performance!N9)) -> 269907328559 | P9: =IF($K$2="USD",SUMIFS(Data!AD:AD,Data!B:B,Performance!$E$2,Data!D:D,Performance!N9)*10^6,SUMIFS(Data!AD:AD,Data!B:B,Performance!$E$2,Data!D:D,Performance!N9)) -> 299380289162 | Q9: =IF($K$2="USD",SUMIFS(Data!AR:AR,Data!B:B,Performance!$F$2,Data!D:D,Performance!N9)*10^6,SUMIFS(Data!AR:AR,Data!B:B,Performance!$F$2,Data!D:D,Performance!N9)) -> 365314011891 | R9: =Q9-P9 -> 65933722729 | S9: =IFERROR(R9/P9,"") -> 0.22023401 | U9: 6 | V9: =IF(K1="EN","D/E","Nợ / Vốn chủ sở hữu") -> Nợ / Vốn chủ sở hữu | W9: =(O14+O17-O6)/O19 -> 0.50776939 | X9: =(P14+P17)/P19 -> 0.42737563 | Y9: =(Q14+Q17)/Q19 -> 0.42642634 | Z9: 1
E10: Cost of Goods Sold (COGS) | F10: =IF($K$1="EN",E10,"Giá vốn hàng bán") -> Giá vốn hàng bán | G10: =IF(J2="USD",SUMIFS(Data!Q:Q,Data!B:B,Performance!$E$2,Data!D:D,Performance!E10)*10^6,SUMIFS(Data!Q:Q,Data!B:B,Performance!$E$2,Data!D:D,Performance!E10)) -> 426098287597 | H10: =IF(K2="USD",SUMIFS(Data!AD:AD,Data!B:B,Performance!$E$2,Data!D:D,Performance!E10)*10^6,SUMIFS(Data!AD:AD,Data!B:B,Performance!$E$2,Data!D:D,Performance!E10)) -> 619927281523 | I10: =IF(K2="USD",SUMIFS(Data!AR:AR,Data!B:B,Performance!$E$2,Data!D:D,Performance!E10)*10^6,SUMIFS(Data!AR:AR,Data!B:B,Performance!$E$2,Data!D:D,Performance!E10)) -> 650002358474 | J10: =I10-H10 -> 30075076951 | K10: =IFERROR(J10/H10,0) -> 0.048513879 | M10: =IF($K$1="EN",N10,"Tài sản cố định") -> Tài sản cố định | N10: Fixed Assets | O10: =IF($K$2="USD",SUMIFS(Data!Q:Q,Data!B:B,Performance!$F$2,Data!D:D,Performance!N10)*10^6,SUMIFS(Data!Q:Q,Data!B:B,Performance!$F$2,Data!D:D,Performance!N10)) -> 224673388970 | P10: =IF($K$2="USD",SUMIFS(Data!AD:AD,Data!B:B,Performance!$E$2,Data!D:D,Performance!N10)*10^6,SUMIFS(Data!AD:AD,Data!B:B,Performance!$E$2,Data!D:D,Performance!N10)) -> 237349552865 | Q10: =IF($K$2="USD",SUMIFS(Data!AR:AR,Data!B:B,Performance!$F$2,Data!D:D,Performance!N10)*10^6,SUMIFS(Data!AR:AR,Data!B:B,Performance!$F$2,Data!D:D,Performance!N10)) -> 268070715296 | R10: =Q10-P10 -> 30721162431 | S10: =IFERROR(R10/P10,"") -> 0.12943425 | U10: 7 | V10: =IF(K1="EN","Debt / EBITDA","Nợ vay / EBITDA") -> Nợ vay / EBITDA | W10: =(O15+O18)/G35 -> 23.250062 | X10: 0.58194405 | Y10: 7.9845739 | Z10: 4 | AB10: Nợ phải thu | AC10: =P7 -> 355551041672 | AD10: =Q7 -> 417392857129 | AE10: =AD10-AC10 -> 61841815457 | AF10: =SUM(AE10:AE12) -> -36842724681
D11: VC | E11: Material cost | F11: =IF($K$1="EN",E11,"Chi phí nguyên vật liệu") -> Chi phí nguyên vật liệu | G11: =IF(J2="USD",SUMIFS(Data!Q:Q,Data!B:B,Performance!$E$2,Data!D:D,Performance!E11)*10^6,SUMIFS(Data!Q:Q,Data!B:B,Performance!$E$2,Data!D:D,Performance!E11)) -> 2.8650612e+11 | H11: =IF(K2="USD",SUMIFS(Data!AD:AD,Data!B:B,Performance!$E$2,Data!D:D,Performance!E11)*10^6,SUMIFS(Data!AD:AD,Data!B:B,Performance!$E$2,Data!D:D,Performance!E11)) -> 4.5534206e+11 | I11: =IF(K2="USD",SUMIFS(Data!AR:AR,Data!B:B,Performance!$E$2,Data!D:D,Performance!E11)*10^6,SUMIFS(Data!AR:AR,Data!B:B,Performance!$E$2,Data!D:D,Performance!E11)) -> 4.6521435e+11 | J11: =I11-H11 -> 9.8722882e+09 | K11: =IFERROR(J11/H11,"") -> 0.021681037 | M11: =IF($K$1="EN",N11,"Nguyên giá") -> Nguyên giá | N11: Cost | O11: =IF($K$2="USD",SUMIFS(Data!Q:Q,Data!B:B,Performance!$F$2,Data!D:D,Performance!N11)*10^6,SUMIFS(Data!Q:Q,Data!B:B,Performance!$F$2,Data!D:D,Performance!N11)) -> 299394448651 | P11: =IF($K$2="USD",SUMIFS(Data!AD:AD,Data!B:B,Performance!$E$2,Data!D:D,Performance!N11)*10^6,SUMIFS(Data!AD:AD,Data!B:B,Performance!$E$2,Data!D:D,Performance!N11)) -> 338856847837 | Q11: =IF($K$2="USD",SUMIFS(Data!AR:AR,Data!B:B,Performance!$F$2,Data!D:D,Performance!N11)*10^6,SUMIFS(Data!AR:AR,Data!B:B,Performance!$F$2,Data!D:D,Performance!N11)) -> 409700584982 | R11: =Q11-P11 -> 70843737145 | S11: =IFERROR(R11/P11,"") -> 0.20906686 | U11: 8 | V11: =IF(K1="EN","Current liquidity","Khả năng thanh toán hiện hành") -> Khả năng thanh toán hiện hành | W11: =O4/O14 -> 2.8161069 | X11: =P4/P14 -> 3.4377216 | Y11: =Q4/Q14 -> 4.0424487 | Z11: 1.5 | AB11: Hàng tồn kho | AC11: =P8 -> 526499028418 | AD11: =Q8 -> 361880765551 | AE11: =AD11-AC11 -> -164618262867
B12: Production cost | D12: VC | E12: Electricity | F12: =IF($K$1="EN",E12,"Chi phí điện") -> Chi phí điện | G12: =IF(J2="USD",SUMIFS(Data!Q:Q,Data!B:B,Performance!$E$2,Data!D:D,Performance!E12)*10^6,SUMIFS(Data!Q:Q,Data!B:B,Performance!$E$2,Data!D:D,Performance!E12)) -> 26054054069 | H12: =IF(K2="USD",SUMIFS(Data!AD:AD,Data!B:B,Performance!$E$2,Data!D:D,Performance!E12)*10^6,SUMIFS(Data!AD:AD,Data!B:B,Performance!$E$2,Data!D:D,Performance!E12)) -> 26358956271 | I12: =IF(K2="USD",SUMIFS(Data!AR:AR,Data!B:B,Performance!$E$2,Data!D:D,Performance!E12)*10^6,SUMIFS(Data!AR:AR,Data!B:B,Performance!$E$2,Data!D:D,Performance!E12)) -> 23524568050 | J12: =I12-H12 -> -2834388221 | K12: =IFERROR(J12/H12,"") -> -0.10753037 | M12: =IF($K$1="EN",N12,"Hao mòn lũy kế") -> Hao mòn lũy kế | N12: Accumulated depreciation | O12: =IF($K$2="USD",SUMIFS(Data!Q:Q,Data!B:B,Performance!$F$2,Data!D:D,Performance!N12)*10^6,SUMIFS(Data!Q:Q,Data!B:B,Performance!$F$2,Data!D:D,Performance!N12)) -> -74721059681 | P12: =IF($K$2="USD",SUMIFS(Data!AD:AD,Data!B:B,Performance!$E$2,Data!D:D,Performance!N12)*10^6,SUMIFS(Data!AD:AD,Data!B:B,Performance!$E$2,Data!D:D,Performance!N12)) -> -101507294972 | Q12: =IF($K$2="USD",SUMIFS(Data!AR:AR,Data!B:B,Performance!$F$2,Data!D:D,Performance!N12)*10^6,SUMIFS(Data!AR:AR,Data!B:B,Performance!$F$2,Data!D:D,Performance!N12)) -> -141629869686 | R12: =Q12-P12 -> -40122574714 | S12: =IFERROR(R12/P12,"") -> 0.39526789 | U12: 9 | V12: =IF(K1="EN","Quick liquidity","Khả năng thanh toán nhanh") -> Khả năng thanh toán nhanh | W12: =(O4-O8)/O14 -> 1.1741176 | X12: =(P4-P8)/P14 -> 1.5938359 | Y12: =(Q4-Q8)/Q14 -> 2.3924333 | Z12: 1 | AB12: Tài sản cố định | AC12: =P9 -> 299380289162 | AD12: =Q9 -> 365314011891 | AE12: =AD12-AC12 -> 65933722729
B13: Production cost | D13: VC | E13: Overtime | F13: =IF($K$1="EN",E13,"Lương ngoài giờ") -> Lương ngoài giờ | G13: =IF(J2="USD",SUMIFS(Data!Q:Q,Data!B:B,Performance!$E$2,Data!D:D,Performance!E13)*10^6,SUMIFS(Data!Q:Q,Data!B:B,Performance!$E$2,Data!D:D,Performance!E13)) -> 4297992394 | H13: =IF(K2="USD",SUMIFS(Data!AD:AD,Data!B:B,Performance!$E$2,Data!D:D,Performance!E13)*10^6,SUMIFS(Data!AD:AD,Data!B:B,Performance!$E$2,Data!D:D,Performance!E13)) -> 1932148253 | I13: =IF(K2="USD",SUMIFS(Data!AR:AR,Data!B:B,Performance!$E$2,Data!D:D,Performance!E13)*10^6,SUMIFS(Data!AR:AR,Data!B:B,Performance!$E$2,Data!D:D,Performance!E13)) -> 1809482234 | J13: =I13-H13 -> -122666019 | K13: =IFERROR(J13/H13,"") -> -0.063486857 | M13: =IF($K$1="EN",N13,"Tổng tài sản") -> Tổng tài sản | N13: Total Assets | O13: =O4+O9 -> 1198063045295 | P13: =P4+P9 -> 1280979662011 | Q13: =Q4+Q9 -> 1251902380916 | R13: =Q13-P13 -> -29077281095 | S13: =IFERROR(R13/P13,"") -> -0.022699253 | U13: 10 | V13: =IF(K1="EN","DWC (days)","Ngày vốn lưu động (ngày)") -> Ngày vốn lưu động (ngày) | W13: =IFERROR((O7+O8-O16)*30*G2/G6,0) -> 589.67503 | X13: =IFERROR((P7+P8-P16)*30*H2/H6,0) -> 173.63858 | Y13: =IFERROR((Q7+Q8-Q16)*30*I2/I6,0) -> 149.74002 | Z13: 90 | AB13: Tiền | AC13: =IF(F2="MIDA",P5,P5+P6) -> 44708727527 | AD13: =IF(F2="MIDA",Q5,Q5+Q6) -> 75354004605 | AE13: =AD13-AC13 -> 30645277078
B14: Production cost | C14: FOH | D14: FC | E14: Direct labor | F14: =IF($K$1="EN",E14,"Lương nhân công trực tiếp") -> Lương nhân công trực tiếp | G14: =IF(J2="USD",SUMIFS(Data!Q:Q,Data!B:B,Performance!$E$2,Data!D:D,Performance!E14)*10^6,SUMIFS(Data!Q:Q,Data!B:B,Performance!$E$2,Data!D:D,Performance!E14)) -> 6496977417 | H14: =IF(K2="USD",SUMIFS(Data!AD:AD,Data!B:B,Performance!$E$2,Data!D:D,Performance!E14)*10^6,SUMIFS(Data!AD:AD,Data!B:B,Performance!$E$2,Data!D:D,Performance!E14)) -> 10924942546 | I14: =IF(K2="USD",SUMIFS(Data!AR:AR,Data!B:B,Performance!$E$2,Data!D:D,Performance!E14)*10^6,SUMIFS(Data!AR:AR,Data!B:B,Performance!$E$2,Data!D:D,Performance!E14)) -> 11177167097 | J14: =I14-H14 -> 252224551 | K14: =IFERROR(J14/H14,"") -> 0.023087037 | M14: =IF($K$1="EN",N14,"Nợ ngắn hạn") -> Nợ ngắn hạn | N14: Short-term Liabilities | O14: =IF($K$2="USD",SUMIFS(Data!Q:Q,Data!B:B,Performance!$F$2,Data!D:D,Performance!N14)*10^6,SUMIFS(Data!Q:Q,Data!B:B,Performance!$F$2,Data!D:D,Performance!N14)) -> 329588242794 | P14: =IF($K$2="USD",SUMIFS(Data!AD:AD,Data!B:B,Performance!$E$2,Data!D:D,Performance!N14)*10^6,SUMIFS(Data!AD:AD,Data!B:B,Performance!$E$2,Data!D:D,Performance!N14)) -> 285537774573 | Q14: =IF($K$2="USD",SUMIFS(Data!AR:AR,Data!B:B,Performance!$F$2,Data!D:D,Performance!N14)*10^6,SUMIFS(Data!AR:AR,Data!B:B,Performance!$F$2,Data!D:D,Performance!N14)) -> 219319635169 | R14: =Q14-P14 -> -66218139404 | S14: =IFERROR(R14/P14,"") -> -0.23190676 | U14: 11 | V14: =IF(K1="EN","ROE","Lợi nhuận / Vốn chủ sở hữu (ROE)") -> Lợi nhuận / Vốn chủ sở hữu (ROE) | W14: =O20/O19 -> 0.18059646 | X14: 0.11114706 | Y14: -0.02089847 | Z14: 0.2 | AB14: Khấu hao | AC14: =P12 -> -101507294972 | AD14: =Q12 -> -141629869686 | AE14: =-(AD14-AC14)/10^3 -> 40122575
B15: Production cost | C15: FOH | D15: FC | E15: Indirect labor | F15: =IF($K$1="EN",E15,"Lương nhân công gián tiếp") -> Lương nhân công gián tiếp | G15: =IF(J2="USD",SUMIFS(Data!Q:Q,Data!B:B,Performance!$E$2,Data!D:D,Performance!E15)*10^6,SUMIFS(Data!Q:Q,Data!B:B,Performance!$E$2,Data!D:D,Performance!E15)) -> 14365408991 | H15: =IF(K2="USD",SUMIFS(Data!AD:AD,Data!B:B,Performance!$E$2,Data!D:D,Performance!E15)*10^6,SUMIFS(Data!AD:AD,Data!B:B,Performance!$E$2,Data!D:D,Performance!E15)) -> 19333674244 | I15: =IF(K2="USD",SUMIFS(Data!AR:AR,Data!B:B,Performance!$E$2,Data!D:D,Performance!E15)*10^6,SUMIFS(Data!AR:AR,Data!B:B,Performance!$E$2,Data!D:D,Performance!E15)) -> 20071879576 | J15: =I15-H15 -> 738205332 | K15: =IFERROR(J15/H15,"") -> 0.038182361 | M15: =IF($K$1="EN",N15,"Vay ngắn hạn") -> Vay ngắn hạn | N15: Short-term borrowings | O15: =IF($K$2="USD",SUMIFS(Data!Q:Q,Data!B:B,Performance!$F$2,Data!D:D,Performance!N15)*10^6,SUMIFS(Data!Q:Q,Data!B:B,Performance!$F$2,Data!D:D,Performance!N15)) -> 178905916168 | P15: =IF($K$2="USD",SUMIFS(Data!AD:AD,Data!B:B,Performance!$E$2,Data!D:D,Performance!N15)*10^6,SUMIFS(Data!AD:AD,Data!B:B,Performance!$E$2,Data!D:D,Performance!N15)) -> 200666324688 | Q15: =IF($K$2="USD",SUMIFS(Data!AR:AR,Data!B:B,Performance!$F$2,Data!D:D,Performance!N15)*10^6,SUMIFS(Data!AR:AR,Data!B:B,Performance!$F$2,Data!D:D,Performance!N15)) -> 116595603825 | R15: =Q15-P15 -> -84070720863 | S15: =IFERROR(R15/P15,"") -> -0.41895779 | U15: 12 | V15: =IF(K1="EN","ROA","Lợi nhuận / Tài sản (ROA)") -> Lợi nhuận / Tài sản (ROA) | W15: =O20/O13 -> 0.11957629 | X15: 0.076189954 | Y15: -0.014554774 | Z15: 0.15
B16: Production cost | C16: FOH | D16: FC | E16: Employee welfare (FOH) | F16: =IF($K$1="EN",E16,"Phúc lợi nhân viên") -> Phúc lợi nhân viên | G16: =IF(J2="USD",SUMIFS(Data!Q:Q,Data!B:B,Performance!$E$2,Data!D:D,Performance!E16)*10^6,SUMIFS(Data!Q:Q,Data!B:B,Performance!$E$2,Data!D:D,Performance!E16)) -> 4887723770 | H16: =IF(K2="USD",SUMIFS(Data!AD:AD,Data!B:B,Performance!$E$2,Data!D:D,Performance!E16)*10^6,SUMIFS(Data!AD:AD,Data!B:B,Performance!$E$2,Data!D:D,Performance!E16)) -> 6473941109 | I16: =IF(K2="USD",SUMIFS(Data!AR:AR,Data!B:B,Performance!$E$2,Data!D:D,Performance!E16)*10^6,SUMIFS(Data!AR:AR,Data!B:B,Performance!$E$2,Data!D:D,Performance!E16)) -> 6450663123 | J16: =I16-H16 -> -23277986 | K16: =IFERROR(J16/H16,"") -> -0.0035956438 | M16: =IF($K$1="EN",N16,"Các khoản phải trả") -> Các khoản phải trả | N16: Account payables | O16: =IF($K$2="USD",SUMIFS(Data!Q:Q,Data!B:B,Performance!$F$2,Data!D:D,Performance!N16)*10^6,SUMIFS(Data!Q:Q,Data!B:B,Performance!$F$2,Data!D:D,Performance!N16)) -> 97319270425 | P16: =IF($K$2="USD",SUMIFS(Data!AD:AD,Data!B:B,Performance!$E$2,Data!D:D,Performance!N16)*10^6,SUMIFS(Data!AD:AD,Data!B:B,Performance!$E$2,Data!D:D,Performance!N16)) -> 36763462032 | Q16: =IF($K$2="USD",SUMIFS(Data!AR:AR,Data!B:B,Performance!$F$2,Data!D:D,Performance!N16)*10^6,SUMIFS(Data!AR:AR,Data!B:B,Performance!$F$2,Data!D:D,Performance!N16)) -> 65718659314 | R16: =Q16-P16 -> 28955197282 | S16: =IFERROR(R16/P16,"") -> 0.78760801 | U16: Net Cash flow | V16: =IF(K1="EN","CASH FLOW","DÒNG TIỀN") -> DÒNG TIỀN | W16: =W3 -> Năm 2024 | X16: =X3 -> LK 2025 | Y16: =Y3 -> LK 2026
B17: Production cost | C17: FOH | D17: FC | E17: Repairs and maintanance | F17: =IF($K$1="EN",E17,"Sửa chữa, bảo trì") -> Sửa chữa, bảo trì | G17: =IF(J2="USD",SUMIFS(Data!Q:Q,Data!B:B,Performance!$E$2,Data!D:D,Performance!E17)*10^6,SUMIFS(Data!Q:Q,Data!B:B,Performance!$E$2,Data!D:D,Performance!E17)) -> 2592205996 | H17: =IF(K2="USD",SUMIFS(Data!AD:AD,Data!B:B,Performance!$E$2,Data!D:D,Performance!E17)*10^6,SUMIFS(Data!AD:AD,Data!B:B,Performance!$E$2,Data!D:D,Performance!E17)) -> 3558171258 | I17: =IF(K2="USD",SUMIFS(Data!AR:AR,Data!B:B,Performance!$E$2,Data!D:D,Performance!E17)*10^6,SUMIFS(Data!AR:AR,Data!B:B,Performance!$E$2,Data!D:D,Performance!E17)) -> 3158106760 | J17: =I17-H17 -> -400064498 | K17: =IFERROR(J17/H17,"") -> -0.11243543 | M17: =IF($K$1="EN",N17,"Nợ dài hạn") -> Nợ dài hạn | N17: Long-term liabilities | O17: =IF($K$2="USD",SUMIFS(Data!Q:Q,Data!B:B,Performance!$F$2,Data!D:D,Performance!N17)*10^6,SUMIFS(Data!Q:Q,Data!B:B,Performance!$F$2,Data!D:D,Performance!N17)) -> 75214867678 | P17: =IF($K$2="USD",SUMIFS(Data!AD:AD,Data!B:B,Performance!$E$2,Data!D:D,Performance!N17)*10^6,SUMIFS(Data!AD:AD,Data!B:B,Performance!$E$2,Data!D:D,Performance!N17)) -> 98004917442 | Q17: =IF($K$2="USD",SUMIFS(Data!AR:AR,Data!B:B,Performance!$F$2,Data!D:D,Performance!N17)*10^6,SUMIFS(Data!AR:AR,Data!B:B,Performance!$F$2,Data!D:D,Performance!N17)) -> 154933236415 | R17: =Q17-P17 -> 56928318973 | S17: =IFERROR(R17/P17,"") -> 0.58087207 | U17: Net cash flow from operating activities | V17: =IF(K1="EN","Cash flow from operation","Dòng tiền hoạt động kinh doanh") -> Dòng tiền hoạt động kinh doanh | W17: =Data!AC18 -> -22475023560 | X17: =IF($K$2="USD",SUMIFS(Data!$AD:$AD,Data!$B:$B,Performance!$E$2,Data!$D:$D,Performance!$U17)*10^6,SUMIFS(Data!$AD:$AD,Data!$B:$B,Performance!$E$2,Data!$D:$D,Performance!$U17)) -> 55101774784 | Y17: =IF($K$2="USD",SUMIFS(Data!$AR:$AR,Data!$B:$B,Performance!$E$2,Data!$D:$D,Performance!$U17)*10^6,SUMIFS(Data!$AR:$AR,Data!$B:$B,Performance!$E$2,Data!$D:$D,Performance!$U17)) -> 135903187315 | Z17: =Y17-X17 -> 80801412531
B18: Production cost | C18: FOH | D18: FC | E18: Factory expenses | F18: =IF($K$1="EN",E18,"Chi phí chung phân xưởng") -> Chi phí chung phân xưởng | G18: =IF(J2="USD",SUMIFS(Data!Q:Q,Data!B:B,Performance!$E$2,Data!D:D,Performance!E18)*10^6,SUMIFS(Data!Q:Q,Data!B:B,Performance!$E$2,Data!D:D,Performance!E18)) -> 35211653392 | H18: =IF(K2="USD",SUMIFS(Data!AD:AD,Data!B:B,Performance!$E$2,Data!D:D,Performance!E18)*10^6,SUMIFS(Data!AD:AD,Data!B:B,Performance!$E$2,Data!D:D,Performance!E18)) -> 36726436636 | I18: =IF(K2="USD",SUMIFS(Data!AR:AR,Data!B:B,Performance!$E$2,Data!D:D,Performance!E18)*10^6,SUMIFS(Data!AR:AR,Data!B:B,Performance!$E$2,Data!D:D,Performance!E18)) -> 41164807588 | J18: =I18-H18 -> 4438370952 | K18: =IFERROR(J18/H18,"") -> 0.12084948 | M18: =IF($K$1="EN",N15,"Vay dài hạn") -> Vay dài hạn | N18: Long-term borrowings | O18: =IF($K$2="USD",SUMIFS(Data!Q:Q,Data!B:B,Performance!$F$2,Data!D:D,Performance!N18)*10^6,SUMIFS(Data!Q:Q,Data!B:B,Performance!$F$2,Data!D:D,Performance!N18)) -> 75214867678 | P18: =IF($K$2="USD",SUMIFS(Data!AD:AD,Data!B:B,Performance!$E$2,Data!D:D,Performance!N18)*10^6,SUMIFS(Data!AD:AD,Data!B:B,Performance!$E$2,Data!D:D,Performance!N18)) -> 98004917442 | Q18: =IF($K$2="USD",SUMIFS(Data!AR:AR,Data!B:B,Performance!$F$2,Data!D:D,Performance!N18)*10^6,SUMIFS(Data!AR:AR,Data!B:B,Performance!$F$2,Data!D:D,Performance!N18)) -> 154933236415 | R18: =Q18-P18 -> 56928318973 | S18: =IFERROR(R18/P18,"") -> 0.58087207 | U18: Net cash flow from investment activities | V18: =IF(K1="EN","Cash flow from investment","Dòng tiền hoạt động đầu tư") -> Dòng tiền hoạt động đầu tư | W18: =Data!AC21 -> 15615882426 | X18: =IF($K$2="USD",SUMIFS(Data!$AD:$AD,Data!$B:$B,Performance!$E$2,Data!$D:$D,Performance!$U18)*10^6,SUMIFS(Data!$AD:$AD,Data!$B:$B,Performance!$E$2,Data!$D:$D,Performance!$U18)) -> -100725871241 | Y18: =IF($K$2="USD",SUMIFS(Data!$AR:$AR,Data!$B:$B,Performance!$E$2,Data!$D:$D,Performance!$U18)*10^6,SUMIFS(Data!$AR:$AR,Data!$B:$B,Performance!$E$2,Data!$D:$D,Performance!$U18)) -> -92531166165
D19: FC | E19: Depreciation (FOH) | F19: =IF($K$1="EN",E19,"Khấu hao (sản xuất)") -> Khấu hao (sản xuất) | G19: =IF(J2="USD",SUMIFS(Data!Q:Q,Data!B:B,Performance!$E$2,Data!D:D,Performance!E19)*10^6,SUMIFS(Data!Q:Q,Data!B:B,Performance!$E$2,Data!D:D,Performance!E19)) -> 20052559894 | H19: =IF(K2="USD",SUMIFS(Data!AD:AD,Data!B:B,Performance!$E$2,Data!D:D,Performance!E19)*10^6,SUMIFS(Data!AD:AD,Data!B:B,Performance!$E$2,Data!D:D,Performance!E19)) -> 31961594702 | I19: =IF(K2="USD",SUMIFS(Data!AR:AR,Data!B:B,Performance!$E$2,Data!D:D,Performance!E19)*10^6,SUMIFS(Data!AR:AR,Data!B:B,Performance!$E$2,Data!D:D,Performance!E19)) -> 28122702259 | J19: =I19-H19 -> -3838892443 | K19: =IFERROR(J19/H19,"") -> -0.12010954 | M19: =IF($K$1="EN",N19,"Vốn chủ sở hữu") -> Vốn chủ sở hữu | N19: Equity | O19: =IF($K$2="USD",SUMIFS(Data!Q:Q,Data!B:B,Performance!$F$2,Data!D:D,Performance!N19)*10^6,SUMIFS(Data!Q:Q,Data!B:B,Performance!$F$2,Data!D:D,Performance!N19)) -> 793259934823 | P19: =IF($K$2="USD",SUMIFS(Data!AD:AD,Data!B:B,Performance!$E$2,Data!D:D,Performance!N19)*10^6,SUMIFS(Data!AD:AD,Data!B:B,Performance!$E$2,Data!D:D,Performance!N19)) -> 897436969996 | Q19: =IF($K$2="USD",SUMIFS(Data!AR:AR,Data!B:B,Performance!$F$2,Data!D:D,Performance!N19)*10^6,SUMIFS(Data!AR:AR,Data!B:B,Performance!$F$2,Data!D:D,Performance!N19)) -> 877649509332 | R19: =Q19-P19 -> -19787460664 | S19: =IFERROR(R19/P19,"") -> -0.022048858 | U19: Net cash flow from financial activities | V19: =IF(K1="EN","Cash flow from finance","Dòng tiền hoạt động tài chính") -> Dòng tiền hoạt động tài chính | X19: =IF($K$2="USD",SUMIFS(Data!$AD:$AD,Data!$B:$B,Performance!$E$2,Data!$D:$D,Performance!$U19)*10^6,SUMIFS(Data!$AD:$AD,Data!$B:$B,Performance!$E$2,Data!$D:$D,Performance!$U19)) -> 23143016200 | Y19: =IF($K$2="USD",SUMIFS(Data!$AR:$AR,Data!$B:$B,Performance!$E$2,Data!$D:$D,Performance!$U19)*10^6,SUMIFS(Data!$AR:$AR,Data!$B:$B,Performance!$E$2,Data!$D:$D,Performance!$U19)) -> -41079393352
D20: FC | E20: Other COGs | F20: =IF($K$1="EN",E20,"Giá vốn Khác") -> Giá vốn Khác | G20: =IF(J2="USD",SUMIFS(Data!Q:Q,Data!B:B,Performance!$E$2,Data!D:D,Performance!E20)*10^6,SUMIFS(Data!Q:Q,Data!B:B,Performance!$E$2,Data!D:D,Performance!E20)) -> 60188636051 | H20: =IF(K2="USD",SUMIFS(Data!AD:AD,Data!B:B,Performance!$E$2,Data!D:D,Performance!E20)*10^6,SUMIFS(Data!AD:AD,Data!B:B,Performance!$E$2,Data!D:D,Performance!E20)) -> 1.223123e+10 | I20: =IF(K2="USD",SUMIFS(Data!AR:AR,Data!B:B,Performance!$E$2,Data!D:D,Performance!E20)*10^6,SUMIFS(Data!AR:AR,Data!B:B,Performance!$E$2,Data!D:D,Performance!E20)) -> 9.7017706e+09 | J20: =I20-H20 -> -2.529459e+09 | K20: =IFERROR(J20/H20,"") -> -0.20680333 | M20: =IF($K$1="EN",N20,"Lợi nhuận chưa phân phối") -> Lợi nhuận chưa phân phối | N20: Retained earnings | O20: =IF($K$2="USD",SUMIFS(Data!Q:Q,Data!B:B,Performance!$F$2,Data!D:D,Performance!N20)*10^6,SUMIFS(Data!Q:Q,Data!B:B,Performance!$F$2,Data!D:D,Performance!N20)) -> 143259934823 | P20: =IF($K$2="USD",SUMIFS(Data!AD:AD,Data!B:B,Performance!$E$2,Data!D:D,Performance!N20)*10^6,SUMIFS(Data!AD:AD,Data!B:B,Performance!$E$2,Data!D:D,Performance!N20)) -> 247436969996 | Q20: =IF($K$2="USD",SUMIFS(Data!AR:AR,Data!B:B,Performance!$F$2,Data!D:D,Performance!N20)*10^6,SUMIFS(Data!AR:AR,Data!B:B,Performance!$F$2,Data!D:D,Performance!N20)) -> 227649509332 | R20: =Q20-P20 -> -19787460664 | S20: =IFERROR(R20/P20,"") -> -0.079969702 | V20: =IF(K1="EN","Productivity KPI","KPI năng suất") -> KPI năng suất | W20: =W3 -> Năm 2024 | X20: =X3 -> LK 2025 | Y20: =Y3 -> LK 2026
D21: VC | E21: Processing cost | F21: =IF($K$1="EN",E21,"Phí gia công") -> Phí gia công | G21: =IF(J2="USD",SUMIFS(Data!Q:Q,Data!B:B,Performance!$E$2,Data!D:D,Performance!E21)*10^6,SUMIFS(Data!Q:Q,Data!B:B,Performance!$E$2,Data!D:D,Performance!E21)) -> 5461823200 | H21: =IF(K2="USD",SUMIFS(Data!AD:AD,Data!B:B,Performance!$E$2,Data!D:D,Performance!E21)*10^6,SUMIFS(Data!AD:AD,Data!B:B,Performance!$E$2,Data!D:D,Performance!E21)) -> 4762024734 | I21: =IF(K2="USD",SUMIFS(Data!AR:AR,Data!B:B,Performance!$E$2,Data!D:D,Performance!E21)*10^6,SUMIFS(Data!AR:AR,Data!B:B,Performance!$E$2,Data!D:D,Performance!E21)) -> 387853873 | J21: =I21-H21 -> -4374170861 | K21: =IFERROR(J21/H21,"") -> -0.91855274 | M21: =IF($K$1="EN",N21,"Tổng nguồn vốn") -> Tổng nguồn vốn | N21: Total Resources | O21: =O14+O17+O19 -> 1198063045295 | P21: =P14+P17+P19 -> 1280979662011 | Q21: =Q14+Q17+Q19 -> 1251902380916 | R21: =Q21-P21 -> -29077281095 | S21: =IFERROR(R21/P21,"") -> -0.022699253 | V21: Doanh thu / người (Triệu/người) | W21: =IFERROR(G6/IFERROR(SUMIFS(Data!Q:Q,Data!B:B,Performance!$E$2,Data!D:D,"Total Headcount"),0)/10^6,0) -> 970.73559 | X21: =IFERROR(H6/IFERROR(SUMIFS(Data!AD:AD,Data!B:B,Performance!$E$2,Data!D:D,"Total Headcount"),0)/10^6,0) -> 1198.559 | Y21: =IFERROR(I6/IFERROR(SUMIFS(Data!AR:AR,Data!B:B,Performance!$E$2,Data!D:D,"Total Headcount"),0)/10^6,0) -> 1146.2534 | Z21: =Y21-X21 -> -52.305567
E22: COGs in inventory | F22: =IF($K$1="EN",E22,"Giá vốn trong thành phẩm & bán TP") -> Giá vốn trong thành phẩm & bán TP | G22: =IF(J2="USD",SUMIFS(Data!Q:Q,Data!B:B,Performance!$E$2,Data!D:D,Performance!E22)*10^6,SUMIFS(Data!Q:Q,Data!B:B,Performance!$E$2,Data!D:D,Performance!E22)) -> -4.0016867e+10 | H22: =IF(K2="USD",SUMIFS(Data!AD:AD,Data!B:B,Performance!$E$2,Data!D:D,Performance!E22)*10^6,SUMIFS(Data!AD:AD,Data!B:B,Performance!$E$2,Data!D:D,Performance!E22)) -> 1.0322101e+10 | I22: =IF(K2="USD",SUMIFS(Data!AR:AR,Data!B:B,Performance!$E$2,Data!D:D,Performance!E22)*10^6,SUMIFS(Data!AR:AR,Data!B:B,Performance!$E$2,Data!D:D,Performance!E22)) -> 3.9219008e+10 | J22: =I22-H22 -> 2.8896907e+10 | K22: =IFERROR(J22/H22,"") -> 2.799518 | M22: =IF($K$1="EN","Man-day (8 hrs)","Giờ công (8 giờ)") -> Giờ công (8 giờ) | N22: Man-day (8 hrs) | O22: =SUMIFS(Data!Q:Q,Data!B:B,Performance!$E$2,Data!D:D,Performance!N22) -> 41220.643 | P22: =SUMIFS(Data!AD:AD,Data!B:B,Performance!$E$2,Data!D:D,Performance!N22) -> 44236.176 | Q22: =SUMIFS(Data!AR:AR,Data!B:B,Performance!$E$2,Data!D:D,Performance!N22) -> 40735.577 | R22: =Q22-P22 -> -3500.5988 | S22: =IFERROR(R22/P22,"") -> -0.079134298 | V22: Chi phí nhân sự / Doanh thu (%) | W22: =IFERROR((G13+G14+G15+G16+G25+G26)/G6,0) -> 0.10752671 | X22: =IFERROR((H13+H14+H15+H16+H25+H26)/H6,0) -> 0.089225434 | Y22: =IFERROR((I13+I14+I15+I16+I25+I26)/I6,0) -> 0.10001718 | Z22: =Y22-X22 -> 0.010791742
E23: Gross Profit | F23: =IF($K$1="EN",E23,"Lợi nhuận gộp") -> Lợi nhuận gộp | G23: =G6-G10 -> 30766675506 | H23: =H6-H10 -> 110284815325 | I23: =I6-I10 -> 64791470204 | J23: =I23-H23 -> -45493345121 | K23: =IFERROR(J23/H23,0) -> -0.41250779 | M23: =IF($K$1="EN",N23,"Số lượng nhân sự sản xuất") -> Số lượng nhân sự sản xuất | N23: Production headcount (avg) | O23: =IFERROR(SUMIFS(Data!Q:Q,Data!B:B,Performance!$E$2,Data!D:D,Performance!N23),0) -> 259.2379 | P23: =IFERROR(SUMIFS(Data!AD:AD,Data!B:B,Performance!$E$2,Data!D:D,Performance!N23),0) -> 340.0417 | Q23: =IFERROR(SUMIFS(Data!AR:AR,Data!B:B,Performance!$E$2,Data!D:D,Performance!N23),0) -> 341.39146 | R23: =Q23-P23 -> 1.3497628 | S23: =IFERROR(R23/P23,"") -> 0.0039694038
E24: SG&A (MKT&ADM) expenses | F24: =IF($K$1="EN",E24,"Chi phí bán hàng & quản lý") -> Chi phí bán hàng & quản lý | G24: =IF(J2="USD",SUMIFS(Data!Q:Q,Data!B:B,Performance!$E$2,Data!D:D,Performance!E24)*10^6,SUMIFS(Data!Q:Q,Data!B:B,Performance!$E$2,Data!D:D,Performance!E24)) -> 39586252838 | H24: =IF(K2="USD",SUMIFS(Data!AD:AD,Data!B:B,Performance!$E$2,Data!D:D,Performance!E24)*10^6,SUMIFS(Data!AD:AD,Data!B:B,Performance!$E$2,Data!D:D,Performance!E24)) -> 61264901433 | I24: =IF(K2="USD",SUMIFS(Data!AR:AR,Data!B:B,Performance!$E$2,Data!D:D,Performance!E24)*10^6,SUMIFS(Data!AR:AR,Data!B:B,Performance!$E$2,Data!D:D,Performance!E24)) -> 64760343520 | J24: =I24-H24 -> 3495442087 | K24: =J24/H24 -> 0.057054562 | M24: =IF($K$1="EN",N24,"PHÂN TÍCH LỢI NHUẬN") -> PHÂN TÍCH LỢI NHUẬN | N24: PROFIT ANALYSIS | O24: =G3 -> Năm 2024 | P24: =H3 -> LK 2025 | Q24: =I3 -> LK 2026 | R24: =R3 -> So với năm trước
B25: MKT & ADM (SG&A) | D25: FC | E25: Salary | F25: =IF($K$1="EN",E25,"Lương quản lý") -> Lương quản lý | G25: =IF(J2="USD",SUMIFS(Data!Q:Q,Data!B:B,Performance!$E$2,Data!D:D,Performance!E25)*10^6,SUMIFS(Data!Q:Q,Data!B:B,Performance!$E$2,Data!D:D,Performance!E25)) -> 15564591994 | H25: =IF(K2="USD",SUMIFS(Data!AD:AD,Data!B:B,Performance!$E$2,Data!D:D,Performance!E25)*10^6,SUMIFS(Data!AD:AD,Data!B:B,Performance!$E$2,Data!D:D,Performance!E25)) -> 21108428439 | I25: =IF(K2="USD",SUMIFS(Data!AR:AR,Data!B:B,Performance!$E$2,Data!D:D,Performance!E25)*10^6,SUMIFS(Data!AR:AR,Data!B:B,Performance!$E$2,Data!D:D,Performance!E25)) -> 25157743581 | J25: =I25-H25 -> 4049315142 | K25: =IFERROR(J25/H25,"") -> 0.19183404 | M25: =F5 -> Sản lượng bán (Tấn) | N25: Sales volume (Ton) | O25: =G5 -> 15468.961 | P25: =H5 -> 23446.449 | Q25: =I5 -> 25012.587 | R25: =Q25-P25 -> 1566.1384 | S25: =IFERROR(R25/P25,"") -> 0.066796402 | AB25: Volume | AC25: Fixed cost | AD25: =IF(K1="EN","Total cost","Tổng chi phí") -> Tổng chi phí | AE25: =IF(K1="EN","Revenue","Doanh thu") -> Doanh thu
B26: MKT & ADM (SG&A) | D26: FC | E26: Employee welfare | F26: =IF($K$1="EN",E26,"Phúc lợi nhân viên quản lý") -> Phúc lợi nhân viên quản lý | G26: =IF(J2="USD",SUMIFS(Data!Q:Q,Data!B:B,Performance!$E$2,Data!D:D,Performance!E26)*10^6,SUMIFS(Data!Q:Q,Data!B:B,Performance!$E$2,Data!D:D,Performance!E26)) -> 3512492392 | H26: =IF(K2="USD",SUMIFS(Data!AD:AD,Data!B:B,Performance!$E$2,Data!D:D,Performance!E26)*10^6,SUMIFS(Data!AD:AD,Data!B:B,Performance!$E$2,Data!D:D,Performance!E26)) -> 5380356731 | I26: =IF(K2="USD",SUMIFS(Data!AR:AR,Data!B:B,Performance!$E$2,Data!D:D,Performance!E26)*10^6,SUMIFS(Data!AR:AR,Data!B:B,Performance!$E$2,Data!D:D,Performance!E26)) -> 6824724413 | J26: =I26-H26 -> 1444367682 | K26: =IFERROR(J26/H26,"") -> 0.26845203 | M26: =IF($K$1="EN","Variable Cost/" & IF(F2="DTPM","mold(m VND/mold)","Ton(m VND/Ton)"),"Biến phí / " & IF(F2="DTPM","Cái (triệu đồng/cái) ","Tấn (Triệu đồng /tấn)")) -> Biến phí / Tấn (Triệu đồng /tấn) | N26: Variable cost/ton (m VND/ton) | O26: =IFERROR(IF(E2="DTPM",(G11+G12+G13+G21+G27+G28+G29)/G5,(G11+G12+G13+G21)/G4+(G27+G28+G29)/G5),0) -> 15731707 | P26: =IFERROR(IF(F2="DTPM",(H11+H12+H13+H21+H27+H28+H29)/H5,(H11+H12+H13+H21)/H4+(H27+H28+H29)/H5),0) -> 27096015 | Q26: =IFERROR(IF(F2="DTPM",(I11+I12+I13+I21+I27+I28+I29)/I4,(I11+I12+I13+I21+I27+I28+I29)/I5),0) -> 20349850 | R26: =Q26-P26 -> -6746164.8 | S26: =IFERROR(R26/P26,"") -> -0.24897258 | AB26: 0 | AC26: =$Q$33/$I$2 -> 3.293197e+10 | AD26: =AC26+AB26*($Q$26+$I$22/$I$5) -> 3.293197e+10 | AE26: =AB26*($I$6/$I$5) -> 0
B27: Direct Selling | D27: VC | E27: Commission expenses | F27: =IF($K$1="EN",E27,"Hoa hồng bán hàng") -> Hoa hồng bán hàng | G27: =IF(J2="USD",SUMIFS(Data!Q:Q,Data!B:B,Performance!$E$2,Data!D:D,Performance!E27)*10^6,SUMIFS(Data!Q:Q,Data!B:B,Performance!$E$2,Data!D:D,Performance!E27)) -> 2775360992 | H27: =IF(K2="USD",SUMIFS(Data!AD:AD,Data!B:B,Performance!$E$2,Data!D:D,Performance!E27)*10^6,SUMIFS(Data!AD:AD,Data!B:B,Performance!$E$2,Data!D:D,Performance!E27)) -> 4947114404 | I27: =IF(K2="USD",SUMIFS(Data!AR:AR,Data!B:B,Performance!$E$2,Data!D:D,Performance!E27)*10^6,SUMIFS(Data!AR:AR,Data!B:B,Performance!$E$2,Data!D:D,Performance!E27)) -> 8553891209 | J27: =I27-H27 -> 3606776805 | K27: =IFERROR(J27/H27,"") -> 0.72906679 | M27: =IF($K$1="EN","Material cost /" & IF(F2="DTPM"," mold"," Ton"),"Chi phí nguyên vật liệu / " & IF(F2="DTPM","Cái","Tấn")) -> Chi phí nguyên vật liệu / Tấn | N27: Material cost per Ton | O27: =IFERROR(IF(E2="DTPM",G11/G4,G11/G4),0) -> 13316268 | P27: =IFERROR(IF(F2="DTPM",H11/H5,H11/H4),0) -> 24565100 | Q27: =IFERROR(I11/I5,0) -> 18599210 | R27: =Q27-P27 -> -5965890.5 | S27: =IFERROR(R27/P27,"") -> -0.24286042 | AB27: =I5/I2 -> 5002.5174 | AC27: =$Q$33/$I$2 -> 3.293197e+10 | AD27: =AC27+AB27*($Q$26+$I$22/$I$5) -> 1.4257625e+11 | AE27: =AB27*($I$6/$I$5) -> 1.4295877e+11
B28: Direct Selling | D28: VC | E28: Domestic Freight | F28: =IF($K$1="EN",E28,"Chi phí vận chuyển trong nước") -> Chi phí vận chuyển trong nước | G28: =IF(J2="USD",SUMIFS(Data!Q:Q,Data!B:B,Performance!$E$2,Data!D:D,Performance!E28)*10^6,SUMIFS(Data!Q:Q,Data!B:B,Performance!$E$2,Data!D:D,Performance!E28)) -> 558268174 | H28: =IF(K2="USD",SUMIFS(Data!AD:AD,Data!B:B,Performance!$E$2,Data!D:D,Performance!E28)*10^6,SUMIFS(Data!AD:AD,Data!B:B,Performance!$E$2,Data!D:D,Performance!E28)) -> 1630704741 | I28: =IF(K2="USD",SUMIFS(Data!AR:AR,Data!B:B,Performance!$E$2,Data!D:D,Performance!E28)*10^6,SUMIFS(Data!AR:AR,Data!B:B,Performance!$E$2,Data!D:D,Performance!E28)) -> 2535633671 | J28: =I28-H28 -> 904928930 | K28: =IFERROR(J28/H28,"") -> 0.55493119 | M28: =IF($K$1="EN","Electricity cost / " & IF(F2="DTPM","mold","Ton"),"Chi phí điện / " & IF(F2="DTPM","Cái","Tấn")) -> Chi phí điện / Tấn | N28: Electricity cost per Ton | O28: =IFERROR(IF(E2="DTPM",G12/G4,G12/G4),0) -> 1210943.6 | P28: =IFERROR(IF(F2="DTPM",H12/H4,H12/H4),0) -> 1422030.7 | Q28: =IFERROR(I12/I4,0) -> 1420940 | R28: =Q28-P28 -> -1090.6959 | S28: =IFERROR(R28/P28,"") -> -0.00076699882 | AB28: =AB27*(1+12%) -> 5602.8195 | AC28: =$Q$33/$I$2 -> 3.293197e+10 | AD28: =AC28+AB28*($Q$26+$I$22/$I$5) -> 1.5573357e+11 | AE28: =AB28*($I$6/$I$5) -> 1.6011382e+11
B29: Direct Selling | D29: VC | E29: Export Freight | F29: =IF($K$1="EN",E29,"Cước xuất khẩu") -> Cước xuất khẩu | G29: =IF(J2="USD",SUMIFS(Data!Q:Q,Data!B:B,Performance!$E$2,Data!D:D,Performance!E29)*10^6,SUMIFS(Data!Q:Q,Data!B:B,Performance!$E$2,Data!D:D,Performance!E29)) -> 8281672437 | H29: =IF(K2="USD",SUMIFS(Data!AD:AD,Data!B:B,Performance!$E$2,Data!D:D,Performance!E29)*10^6,SUMIFS(Data!AD:AD,Data!B:B,Performance!$E$2,Data!D:D,Performance!E29)) -> 10954088709 | I29: =IF(K2="USD",SUMIFS(Data!AR:AR,Data!B:B,Performance!$E$2,Data!D:D,Performance!E29)*10^6,SUMIFS(Data!AR:AR,Data!B:B,Performance!$E$2,Data!D:D,Performance!E29)) -> 6976623658 | J29: =I29-H29 -> -3977465051 | K29: =IFERROR(J29/H29,"") -> -0.36310324 | M29: =IF($K$1="EN","Overtime cost / " & IF(F2="DTPM","mold","Ton"),"Lương ngoài giờ / " & IF(F2="DTPM","Cái","Tấn")) -> Lương ngoài giờ / Tấn | N29: Overtime per Ton | O29: =IFERROR(IF(E2="DTPM",G13/G4,G13/G4),0) -> 199762.64 | P29: =IFERROR(IF(F2="DTPM",H13/H4,H13/H4),0) -> 104236.83 | Q29: =IFERROR(I13/I4,0) -> 109297.04 | R29: =Q29-P29 -> 5060.2083 | S29: =IFERROR(R29/P29,"") -> 0.048545299 | AB29: =AB28*(1+12%) -> 6275.1578 | AC29: =$Q$33/$I$2 -> 3.293197e+10 | AD29: =AC29+AB29*($Q$26+$I$22/$I$5) -> 1.7046976e+11 | AE29: =AB29*($I$6/$I$5) -> 1.7932748e+11
B30: MKT & ADM (SG&A) | D30: FC | E30: Depreciation | F30: =IF($K$1="EN",E30,"Khấu hao (quản lý)") -> Khấu hao (quản lý) | G30: =IF(J2="USD",SUMIFS(Data!Q:Q,Data!B:B,Performance!$E$2,Data!D:D,Performance!E30)*10^6,SUMIFS(Data!Q:Q,Data!B:B,Performance!$E$2,Data!D:D,Performance!E30)) -> 930972362 | H30: =IF(K2="USD",SUMIFS(Data!AD:AD,Data!B:B,Performance!$E$2,Data!D:D,Performance!E30)*10^6,SUMIFS(Data!AD:AD,Data!B:B,Performance!$E$2,Data!D:D,Performance!E30)) -> 2274537180 | I30: =IF(K2="USD",SUMIFS(Data!AR:AR,Data!B:B,Performance!$E$2,Data!D:D,Performance!E30)*10^6,SUMIFS(Data!AR:AR,Data!B:B,Performance!$E$2,Data!D:D,Performance!E30)) -> 424659097 | J30: =I30-H30 -> -1849878083 | K30: =IFERROR(J30/H30,"") -> -0.81329868 | M30: =IF(K1="EN","Processing cost / " & IF(F2="DTPM","mold","Ton"),"Phí gia công /" & IF(F2="DTPM"," Cái"," Tấn")) -> Phí gia công / Tấn | N30: Processing cost per Ton | O30: =IFERROR(IF(E2="DTPM",G21/G4,G21/G4),0) -> 253855.31 | P30: =IFERROR(IF(F2="DTPM",H21/H4,H21/H4),0) -> 256904.92 | Q30: =IFERROR(I21/I4,0) -> 23427.299 | R30: =Q30-P30 -> -233477.62 | S30: =IFERROR(R30/P30,"") -> -0.90880946 | AB30: =AB29*(1+12%) -> 7028.1768 | AC30: =$Q$33/$I$2 -> 3.293197e+10 | AD30: =AC30+AB30*($Q$26+$I$22/$I$5) -> 1.8697429e+11 | AE30: =AB30*($I$6/$I$5) -> 2.0084677e+11
B31: MKT & ADM (SG&A) | D31: FC | E31: Controllable expenses | F31: =IF($K$1="EN",E31,"Chi phí còn lại khác") -> Chi phí còn lại khác | G31: =IF(J2="USD",SUMIFS(Data!Q:Q,Data!B:B,Performance!$E$2,Data!D:D,Performance!E31)*10^6,SUMIFS(Data!Q:Q,Data!B:B,Performance!$E$2,Data!D:D,Performance!E31)) -> 7962894487 | H31: =IF(K2="USD",SUMIFS(Data!AD:AD,Data!B:B,Performance!$E$2,Data!D:D,Performance!E31)*10^6,SUMIFS(Data!AD:AD,Data!B:B,Performance!$E$2,Data!D:D,Performance!E31)) -> 14969671229 | I31: =IF(K2="USD",SUMIFS(Data!AR:AR,Data!B:B,Performance!$E$2,Data!D:D,Performance!E31)*10^6,SUMIFS(Data!AR:AR,Data!B:B,Performance!$E$2,Data!D:D,Performance!E31)) -> 14287067891 | J31: =I31-H31 -> -682603338 | K31: =IFERROR(J31/H31,"") -> -0.045599087 | M31: =IF(K1="EN","Direct selling / " & IF(F2="DTPM","mold","Ton"),"CP bán hàng trực tiếp /" & IF(F2="DTPM"," Cái"," Tấn")) -> CP bán hàng trực tiếp / Tấn | N31: Direct selling | O31: =IFERROR(SUM(G27:G29)/G5/10^6,0) -> 0.75087794 | P31: =IFERROR(SUM(H27:H29)/H5/10^6,0) -> 0.74774258 | Q31: =IFERROR(SUM(I27:I29)/I5/10^6,0) -> 0.72228229 | R31: =Q31-P31 -> -0.025460288 | S31: =IFERROR(R31/P31,"") -> -0.034049537 | AB31: =AB30*(1+12%) -> 7871.558 | AC31: =$Q$33/$I$2 -> 3.293197e+10 | AD31: =AC31+AB31*($Q$26+$I$22/$I$5) -> 2.0545937e+11 | AE31: =AB31*($I$6/$I$5) -> 2.2494839e+11
D32: FC | E32: Financial Expense | F32: =IF($K$1="EN",E32,"Chi phí tài chính") -> Chi phí tài chính | G32: =IF(J2="USD",SUMIFS(Data!Q:Q,Data!B:B,Performance!$E$2,Data!D:D,Performance!E32)*10^6,SUMIFS(Data!Q:Q,Data!B:B,Performance!$E$2,Data!D:D,Performance!E32)) -> 4652566598 | H32: =IF(K2="USD",SUMIFS(Data!AD:AD,Data!B:B,Performance!$E$2,Data!D:D,Performance!E32)*10^6,SUMIFS(Data!AD:AD,Data!B:B,Performance!$E$2,Data!D:D,Performance!E32)) -> 6090227204 | I32: =IF(K2="USD",SUMIFS(Data!AR:AR,Data!B:B,Performance!$E$2,Data!D:D,Performance!E32)*10^6,SUMIFS(Data!AR:AR,Data!B:B,Performance!$E$2,Data!D:D,Performance!E32)) -> 7820326383 | J32: =I32-H32 -> 1730099179 | K32: =IFERROR(J32/H32,0) -> 0.28407794 | M32: =IF(K1="EN","Others / " & IF(F2="DTPM","mold","Ton"),"CP khác /" & IF(F2="DTPM"," Cái"," Tấn")) -> CP khác / Tấn | O32: =IFERROR(G20/G5,0) -> 3890929.5 | P32: =IFERROR(H20/H5,0) -> 521666.62 | Q32: =IFERROR(I20/I5,0) -> 387875.54 | R32: =Q32-P32 -> -133791.08 | S32: =IFERROR(R32/P32,"") -> -0.25646855 | AB32: =AB31*(1+12%) -> 8816.1449 | AC32: =$Q$33/$I$2 -> 3.293197e+10 | AD32: =AC32+AB32*($Q$26+$I$22/$I$5) -> 2.2616266e+11 | AE32: =AB32*($I$6/$I$5) -> 2.5194219e+11
E33: Interest expense | F33: =IF($K$1="EN",E33,"Chi phí lãi vay") -> Chi phí lãi vay | G33: =IF(J2="USD",SUMIFS(Data!Q:Q,Data!B:B,Performance!$E$2,Data!D:D,Performance!E33)*10^6,SUMIFS(Data!Q:Q,Data!B:B,Performance!$E$2,Data!D:D,Performance!E33)) -> 3491705382 | H33: =IF(K2="USD",SUMIFS(Data!AD:AD,Data!B:B,Performance!$E$2,Data!D:D,Performance!E33)*10^6,SUMIFS(Data!AD:AD,Data!B:B,Performance!$E$2,Data!D:D,Performance!E33)) -> 4792152527 | I33: =IF(K2="USD",SUMIFS(Data!AR:AR,Data!B:B,Performance!$E$2,Data!D:D,Performance!E33)*10^6,SUMIFS(Data!AR:AR,Data!B:B,Performance!$E$2,Data!D:D,Performance!E33)) -> 5257034313 | J33: =I33-H33 -> 464881786 | K33: =IFERROR(J33/H33,"") -> 0.097008971 | M33: =IF($K$1="EN",N33,"Định phí") -> Định phí | N33: Fixed cost | O33: =SUM(G14:G18)+G26+G25+G31+G32+G30+G19 -> 116230047293 | P33: =SUM(H14:H18)+H26+H25+H31+H32+H30+H19 -> 158801981278 | Q33: =SUM(I14:I18)+I26+I25+I31+I32+I30+I19 -> 164659847768 | R33: =Q33-P33 -> 5857866490 | S33: =IFERROR(R33/P33,0) -> 0.036887868 | V33: =IF(K1="EN","Break even","SL hòa vốn") -> SL hòa vốn | X33: =I6/I2 -> 1.4295877e+11 | AB33: =AB32*(1+12%) -> 9874.0823 | AC33: =$Q$33/$I$2 -> 3.293197e+10 | AD33: =AC33+AB33*($Q$26+$I$22/$I$5) -> 2.4935034e+11 | AE33: =AB33*($I$6/$I$5) -> 2.8217525e+11
E34: Other Income | F34: =IF($K$1="EN",E34,"Thu nhập khác") -> Thu nhập khác | G34: =IF(J2="USD",SUMIFS(Data!Q:Q,Data!B:B,Performance!$E$2,Data!D:D,Performance!E34)*10^6,SUMIFS(Data!Q:Q,Data!B:B,Performance!$E$2,Data!D:D,Performance!E34)) -> 5489769545 | H34: =IF(K2="USD",SUMIFS(Data!AD:AD,Data!B:B,Performance!$E$2,Data!D:D,Performance!E34)*10^6,SUMIFS(Data!AD:AD,Data!B:B,Performance!$E$2,Data!D:D,Performance!E34)) -> 7236244341 | I34: =IF(K2="USD",SUMIFS(Data!AR:AR,Data!B:B,Performance!$E$2,Data!D:D,Performance!E34)*10^6,SUMIFS(Data!AR:AR,Data!B:B,Performance!$E$2,Data!D:D,Performance!E34)) -> 4743395864 | J34: =I34-H34 -> -2492848477 | K34: =IFERROR(J34/H34,"") -> -0.34449479 | M34: =IF(K1="EN","Operating Expense (OpEx)","Chi phí hoạt động") -> Chi phí hoạt động | O34: =O33-O36-O37 -> 90593948439 | P34: =P33-P36-P37 -> 118475622192 | Q34: =Q33-Q36-Q37 -> 128292160029 | R34: =Q34-P34 -> 9816537837 | S34: =IFERROR(R34/P34,0) -> 0.082857027 | V34: =H38 -> 42677314129 | AB34: =AB33*(1+12%) -> 11058.972 | AC34: =$Q$33/$I$2 -> 3.293197e+10 | AD34: =AC34+AB34*($Q$26+$I$22/$I$5) -> 2.7532055e+11 | AE34: =AB34*($I$6/$I$5) -> 3.1603629e+11
E35: EBITDA | F35: =IF($K$1="EN",E35,"EBITDA") -> EBITDA | G35: =IF(J2="USD",SUMIFS(Data!Q:Q,Data!B:B,Performance!$E$2,Data!D:D,Performance!E35)*10^6,SUMIFS(Data!Q:Q,Data!B:B,Performance!$E$2,Data!D:D,Performance!E35)) -> 10929896878 | H35: =IF(K2="USD",SUMIFS(Data!AD:AD,Data!B:B,Performance!$E$2,Data!D:D,Performance!E35)*10^6,SUMIFS(Data!AD:AD,Data!B:B,Performance!$E$2,Data!D:D,Performance!E35)) -> 74565621227 | I35: =IF(K2="USD",SUMIFS(Data!AR:AR,Data!B:B,Performance!$E$2,Data!D:D,Performance!E35)*10^6,SUMIFS(Data!AR:AR,Data!B:B,Performance!$E$2,Data!D:D,Performance!E35)) -> 13175258499 | J35: =I35-H35 -> -61390362728 | K35: =IFERROR(J35/H35,"") -> -0.82330653 | M35: Trong đó: chi phí nhân sự | O35: =G14+G15+G16+G25+G26 -> 44827194564 | P35: =H14+H15+H16+H25+H26 -> 63221343069 | Q35: =I14+I15+I16+I25+I26 -> 69682177790 | R35: =Q35-P35 -> 6460834721 | S35: =R35/P35 -> 0.10219389 | AB35: =AB34*(1+12%) -> 12386.049 | AC35: =$Q$33/$I$2 -> 3.293197e+10 | AD35: =AC35+AB35*($Q$26+$I$22/$I$5) -> 3.0440717e+11 | AE35: =AB35*($I$6/$I$5) -> 3.5396064e+11
E36: Profit before tax | F36: =IF($K$1="EN",E36,"Lợi nhuận trước thuế") -> Lợi nhuận trước thuế | G36: =IF(J2="USD",SUMIFS(Data!Q:Q,Data!B:B,Performance!$E$2,Data!D:D,Performance!E36)*10^6,SUMIFS(Data!Q:Q,Data!B:B,Performance!$E$2,Data!D:D,Performance!E36)) -> -7982374385 | H36: =IF(K2="USD",SUMIFS(Data!AD:AD,Data!B:B,Performance!$E$2,Data!D:D,Performance!E36)*10^6,SUMIFS(Data!AD:AD,Data!B:B,Performance!$E$2,Data!D:D,Performance!E36)) -> 50165931029 | I36: =IF(K2="USD",SUMIFS(Data!AR:AR,Data!B:B,Performance!$E$2,Data!D:D,Performance!E36)*10^6,SUMIFS(Data!AR:AR,Data!B:B,Performance!$E$2,Data!D:D,Performance!E36)) -> -3045803835 | J36: =I36-H36 -> -53211734864 | K36: =IFERROR(J36/H36,"") -> -1.0607146 | M36: =IF(K1="EN","Depreciation","Khấu hao") -> Khấu hao | O36: =G19+G30 -> 20983532256 | P36: =H19+H30 -> 34236131882 | Q36: =I19+I30 -> 28547361356 | R36: =Q36-P36 -> -5688770526 | S36: =IFERROR(R36/P36,0) -> -0.16616277 | AB36: =IF(K1="EN","Actual volume","SL thực tế") -> SL thực tế | AC36: =I5/I2 -> 5002.5174
E37: CIT | F37: =IF($K$1="EN",E37,"Thuế TNDN") -> Thuế TNDN | G37: =IF(J2="USD",SUMIFS(Data!Q:Q,Data!B:B,Performance!$E$2,Data!D:D,Performance!E37)*10^6,SUMIFS(Data!Q:Q,Data!B:B,Performance!$E$2,Data!D:D,Performance!E37)) -> 0 | H37: =IF(K2="USD",SUMIFS(Data!AD:AD,Data!B:B,Performance!$E$2,Data!D:D,Performance!E37)*10^6,SUMIFS(Data!AD:AD,Data!B:B,Performance!$E$2,Data!D:D,Performance!E37)) -> 7488616900 | I37: =IF(K2="USD",SUMIFS(Data!AR:AR,Data!B:B,Performance!$E$2,Data!D:D,Performance!E37)*10^6,SUMIFS(Data!AR:AR,Data!B:B,Performance!$E$2,Data!D:D,Performance!E37)) -> -198902366 | J37: =I37-H37 -> -7687519266 | K37: =IFERROR(J37/H37,"") -> -1.0265606 | M37: =IF(K1="EN","Financial expense","Chi phí tài chính") -> Chi phí tài chính | O37: =G32 -> 4652566598 | P37: =H32 -> 6090227204 | Q37: =I32 -> 7820326383 | R37: =Q37-P37 -> 1730099179 | S37: =IFERROR(R37/P37,0) -> 0.28407794
E38: NET PROFIT | F38: =IF($K$1="EN",E38,"Lợi nhuận sau thuế") -> Lợi nhuận sau thuế | G38: =IF(J2="USD",SUMIFS(Data!Q:Q,Data!B:B,Performance!$E$2,Data!D:D,Performance!E38)*10^6,SUMIFS(Data!Q:Q,Data!B:B,Performance!$E$2,Data!D:D,Performance!E38)) -> -7982374385 | H38: =IF(K2="USD",SUMIFS(Data!AD:AD,Data!B:B,Performance!$E$2,Data!D:D,Performance!E38)*10^6,SUMIFS(Data!AD:AD,Data!B:B,Performance!$E$2,Data!D:D,Performance!E38)) -> 42677314129 | I38: =IF(K2="USD",SUMIFS(Data!AR:AR,Data!B:B,Performance!$E$2,Data!D:D,Performance!E38)*10^6,SUMIFS(Data!AR:AR,Data!B:B,Performance!$E$2,Data!D:D,Performance!E38)) -> -2846901469 | J38: =I38-H38 -> -45524215598 | K38: =J38/H38 -> -1.0667076 | L38: =M40 -> Phân tích lợi nhuận sau thuế | M38: =IF(K1="EN","Breakeven Volume/month","Sản lượng hòa vốn/tháng ") -> Sản lượng hòa vốn/tháng | P38: =IFERROR(P33/X8/(H6/H5)/H2,0) -> 3480.3627 | Q38: =IFERROR((Q33)/Y8/(I6/I5)/I2,0) -> 4945.0789 | R38: =Q38-P38 -> 1464.7162 | S38: =IFERROR(R38/P38,"") -> 0.42085158
L39: =IF(K1="EN","Volume","Sản lượng") -> Sản lượng | M39: =IF(K1="EN","Breakeven Sales (m VND)/month","Doanh thu hòa vốn (Triệu)/tháng ") -> Doanh thu hòa vốn (Triệu)/tháng | P39: =IFERROR(P38*(H6/H5),0) -> 1.0839181e+11 | Q39: =IFERROR(Q38*(I6/I5),0) -> 1.4131732e+11 | R39: =Q39-P39 -> 3.2925516e+10 | S39: =IFERROR(R39/P39,"") -> 0.30376387 | U39: =SUM(U40:U49) -> -1.0667076
L40: =IF(K1="EN","Selling price","Giá bán") -> Giá bán | M40: =IF(K1="EN","Net profit analysis by Factors","Phân tích lợi nhuận sau thuế") -> Phân tích lợi nhuận sau thuế | O40: =O24 -> Năm 2024 | P40: =P24 -> LK 2025 | Q40: =Q24 -> LK 2026 | R40: =IF(K1="EN","Change","Thay đổi") -> Thay đổi | S40: =IF(K1="EN","Impact","Ảnh hưởng") -> Ảnh hưởng | U40: =S41*10^6/$H$38 -> 0.31574034 | AB40: =IF(K1="EN","Net profit 2025","LNST 2025") -> LNST 2025 | AD40: =H38/10^6 -> 42677.314 | AE40: 1
...

Sheet Data
D1: Check
E2: 1 | F2: 2 | G2: 3 | H2: 4 | I2: 5 | J2: 6 | K2: 7 | L2: 8 | M2: 9 | N2: 10 | O2: 11 | P2: 12 | Q2: 2024 | R2: 1 | S2: 2 | T2: 3 | U2: 4 | V2: 5 | W2: 6 | X2: 7 | Y2: 8 | Z2: 9 | AA2: 10 | AB2: 11 | AC2: 12 | AD2: 2025
A3: =Performance!$K$1 -> VN | B3: =Performance!K2 -> Triệu VND | D3: =IF(B3="USD","nghìn USD","Triệu đồng") -> Triệu đồng
B4: =Performance!F2 -> DTR | D4: Operating Expense | R4: 1 | S4: 2 | T4: 3 | U4: 4 | V4: 5 | W4: 6 | X4: 7 | Y4: 8 | Z4: 9 | AA4: 10 | AB4: 11 | AC4: 12 | AD4: =IF('FS matrix'!A1="EN","YTD","Lũy kế") -> Lũy kế
B5: =Performance!H1 -> 2025 | D5: =IF(A3="EN","Last year","Năm trước") -> Năm trước | R5: =IF($B$3="USD",SUMIFS(E$28:E$359,$B$28:$B$359,$B$4,$D$28:$D$359,$D$4),SUMIFS(E$28:E$359,$B$28:$B$359,$B$4,$D$28:$D$359,$D$4)/10^6) -> 15301.449 | S5: =IF($B$3="USD",SUMIFS(F$28:F$359,$B$28:$B$359,$B$4,$D$28:$D$359,$D$4),SUMIFS(F$28:F$359,$B$28:$B$359,$B$4,$D$28:$D$359,$D$4)/10^6) -> 13873.741 | T5: =IF($B$3="USD",SUMIFS(G$28:G$359,$B$28:$B$359,$B$4,$D$28:$D$359,$D$4),SUMIFS(G$28:G$359,$B$28:$B$359,$B$4,$D$28:$D$359,$D$4)/10^6) -> 20712.853 | U5: =IF($B$3="USD",SUMIFS(H$28:H$359,$B$28:$B$359,$B$4,$D$28:$D$359,$D$4),SUMIFS(H$28:H$359,$B$28:$B$359,$B$4,$D$28:$D$359,$D$4)/10^6) -> 19330.107 | V5: =IF($B$3="USD",SUMIFS(I$28:I$359,$B$28:$B$359,$B$4,$D$28:$D$359,$D$4),SUMIFS(I$28:I$359,$B$28:$B$359,$B$4,$D$28:$D$359,$D$4)/10^6) -> 21375.798 | W5: =IF($B$3="USD",SUMIFS(J$28:J$359,$B$28:$B$359,$B$4,$D$28:$D$359,$D$4),SUMIFS(J$28:J$359,$B$28:$B$359,$B$4,$D$28:$D$359,$D$4)/10^6) -> 20743.137 | X5: =IF($B$3="USD",SUMIFS(K$28:K$359,$B$28:$B$359,$B$4,$D$28:$D$359,$D$4),SUMIFS(K$28:K$359,$B$28:$B$359,$B$4,$D$28:$D$359,$D$4)/10^6) -> 19696.085 | Y5: =IF($B$3="USD",SUMIFS(L$28:L$359,$B$28:$B$359,$B$4,$D$28:$D$359,$D$4),SUMIFS(L$28:L$359,$B$28:$B$359,$B$4,$D$28:$D$359,$D$4)/10^6) -> 21459.303 | ... AC5: =IF($B$3="USD",SUMIFS(P$28:P$359,$B$28:$B$359,$B$4,$D$28:$D$359,$D$4),SUMIFS(P$28:P$359,$B$28:$B$359,$B$4,$D$28:$D$359,$D$4)/10^6) -> 25170.049 | AD5: =SUM(OFFSET(R5:AC5,0,0,1,Performance!H2)) -> 90593.948
B6: =Performance!I1 -> 2026 | D6: =IF(A3="EN","Current year","Năm nay") -> Năm nay | R6: =IF($B$3="USD",SUMIFS(R$28:R$359,$B$28:$B$359,$B$4,$D$28:$D$359,$D$4),SUMIFS(R$28:R$359,$B$28:$B$359,$B$4,$D$28:$D$359,$D$4)/10^6) -> 23429.032 | S6: =IF($B$3="USD",SUMIFS(S$28:S$359,$B$28:$B$359,$B$4,$D$28:$D$359,$D$4),SUMIFS(S$28:S$359,$B$28:$B$359,$B$4,$D$28:$D$359,$D$4)/10^6) -> 22438.833 | T6: =IF($B$3="USD",SUMIFS(T$28:T$359,$B$28:$B$359,$B$4,$D$28:$D$359,$D$4),SUMIFS(T$28:T$359,$B$28:$B$359,$B$4,$D$28:$D$359,$D$4)/10^6) -> 24091.469 | U6: =IF($B$3="USD",SUMIFS(U$28:U$359,$B$28:$B$359,$B$4,$D$28:$D$359,$D$4),SUMIFS(U$28:U$359,$B$28:$B$359,$B$4,$D$28:$D$359,$D$4)/10^6) -> 24143.191 | V6: =IF($B$3="USD",SUMIFS(V$28:V$359,$B$28:$B$359,$B$4,$D$28:$D$359,$D$4),SUMIFS(V$28:V$359,$B$28:$B$359,$B$4,$D$28:$D$359,$D$4)/10^6) -> 24373.097 | W6: =IF($B$3="USD",SUMIFS(W$28:W$359,$B$28:$B$359,$B$4,$D$28:$D$359,$D$4),SUMIFS(W$28:W$359,$B$28:$B$359,$B$4,$D$28:$D$359,$D$4)/10^6) -> 24531.919 | X6: =IF($B$3="USD",SUMIFS(X$28:X$359,$B$28:$B$359,$B$4,$D$28:$D$359,$D$4),SUMIFS(X$28:X$359,$B$28:$B$359,$B$4,$D$28:$D$359,$D$4)/10^6) -> 25277.268 | Y6: =IF($B$3="USD",SUMIFS(Y$28:Y$359,$B$28:$B$359,$B$4,$D$28:$D$359,$D$4),SUMIFS(Y$28:Y$359,$B$28:$B$359,$B$4,$D$28:$D$359,$D$4)/10^6) -> 25871.126 | ... AC6: =IF($B$3="USD",SUMIFS(AC$28:AC$359,$B$28:$B$359,$B$4,$D$28:$D$359,$D$4),SUMIFS(AC$28:AC$359,$B$28:$B$359,$B$4,$D$28:$D$359,$D$4)/10^6) -> 33123.812 | AD6: =SUM(OFFSET(R6:AC6,0,0,1,Performance!I2)) -> 118475.62
D7: Sales volume
B8: 2024 | D8: =D5 -> Năm trước | R8: =SUMIFS(E$28:E$359,$B$28:$B$359,$B$4,$D$28:$D$359,$D$7) -> 3553.2 | S8: =SUMIFS(F$28:F$359,$B$28:$B$359,$B$4,$D$28:$D$359,$D$7) -> 2285.051 | T8: =SUMIFS(G$28:G$359,$B$28:$B$359,$B$4,$D$28:$D$359,$D$7) -> 2972.068 | U8: =SUMIFS(H$28:H$359,$B$28:$B$359,$B$4,$D$28:$D$359,$D$7) -> 3202.752 | V8: =SUMIFS(I$28:I$359,$B$28:$B$359,$B$4,$D$28:$D$359,$D$7) -> 3455.89 | W8: =SUMIFS(J$28:J$359,$B$28:$B$359,$B$4,$D$28:$D$359,$D$7) -> 2432.325 | X8: =SUMIFS(K$28:K$359,$B$28:$B$359,$B$4,$D$28:$D$359,$D$7) -> 1986.853 | Y8: =SUMIFS(L$28:L$359,$B$28:$B$359,$B$4,$D$28:$D$359,$D$7) -> 5184.5942 | ... AC8: =SUMIFS(P$28:P$359,$B$28:$B$359,$B$4,$D$28:$D$359,$D$7) -> 3375.148 | AD8: =SUM(OFFSET(R8:AC8,0,0,1,Performance!H2)) -> 15468.961
B9: 2025 | D9: =D6 -> Năm nay | R9: =SUMIFS(R$28:R$359,$B$28:$B$359,$B$4,$D$28:$D$359,$D$7) -> 3612.7513 | S9: =SUMIFS(S$28:S$359,$B$28:$B$359,$B$4,$D$28:$D$359,$D$7) -> 6002.038 | T9: =SUMIFS(T$28:T$359,$B$28:$B$359,$B$4,$D$28:$D$359,$D$7) -> 4985.538 | U9: =SUMIFS(U$28:U$359,$B$28:$B$359,$B$4,$D$28:$D$359,$D$7) -> 4060.361 | V9: =SUMIFS(V$28:V$359,$B$28:$B$359,$B$4,$D$28:$D$359,$D$7) -> 4785.7603 | W9: =SUMIFS(W$28:W$359,$B$28:$B$359,$B$4,$D$28:$D$359,$D$7) -> 3895.695 | X9: =SUMIFS(X$28:X$359,$B$28:$B$359,$B$4,$D$28:$D$359,$D$7) -> 4652.4191 | Y9: =SUMIFS(Y$28:Y$359,$B$28:$B$359,$B$4,$D$28:$D$359,$D$7) -> 5655.27 | ... AC9: =SUMIFS(AC$28:AC$359,$B$28:$B$359,$B$4,$D$28:$D$359,$D$7) -> 3185.679 | AD9: =SUM(OFFSET(R9:AC9,0,0,1,Performance!H2)) -> 23446.449
B10: =IF(A3="EN","Net sales (B VND)","Doanh thu thuần (Tỷ)") -> Doanh thu thuần (Tỷ) | D10: Net sales
B11: =B5 -> 2025 | D11: =IF(A3="EN","Last year","Năm trước") -> Năm trước | R11: =SUMIFS(E$28:E$359,$B$28:$B$359,$B$4,$D$28:$D$359,$D$10) -> 95961616736 | S11: =SUMIFS(F$28:F$359,$B$28:$B$359,$B$4,$D$28:$D$359,$D$10) -> 68939746996 | T11: =SUMIFS(G$28:G$359,$B$28:$B$359,$B$4,$D$28:$D$359,$D$10) -> 92109508133 | U11: =SUMIFS(H$28:H$359,$B$28:$B$359,$B$4,$D$28:$D$359,$D$10) -> 97489092894 | V11: =SUMIFS(I$28:I$359,$B$28:$B$359,$B$4,$D$28:$D$359,$D$10) -> 102364998344 | W11: =SUMIFS(J$28:J$359,$B$28:$B$359,$B$4,$D$28:$D$359,$D$10) -> 68093170109 | X11: =SUMIFS(K$28:K$359,$B$28:$B$359,$B$4,$D$28:$D$359,$D$10) -> 56451269692 | Y11: =SUMIFS(L$28:L$359,$B$28:$B$359,$B$4,$D$28:$D$359,$D$10) -> 154027868172 | ... AC11: =SUMIFS(P$28:P$359,$B$28:$B$359,$B$4,$D$28:$D$359,$D$10) -> 106210088680 | AD11: =SUM(OFFSET(R11:AC11,0,0,1,Performance!$H$2)) -> 456864963103
