Workbook

Sheet Chỉ tiêu
A2: STT | B2: CHỈ TIÊU | C2: Đvt | E2: 2024 | F2: 2025 | G2: KH26-01 | H2: KH26-02 | I2: KH26-03 | J2: KH26-04 | K2: KH26-05 | L2: KH26-06 | M2: KH26-07 | N2: KH26-08 | O2: KH26-09 | P2: KH26-10 | Q2: KH26-11 | R2: KH26-12 | S2: KH26
A4: 1 | B4: Doanh thu | C4: tr.đ | E4: =SUM(PL!D16:O16) -> 1454585730121 | F4: =SUM(PL!P16:AA16) -> 1537887693083 | G4: =PL!AB16 -> 1.2950534e+11 | H4: =PL!AC16 -> 1.2797444e+11 | I4: =PL!AD16 -> 1.4159949e+11 | J4: =PL!AE16 -> 1.3178227e+11 | K4: =PL!AF16 -> 1.4024431e+11 | L4: =PL!AG16 -> 1.414093e+11 | M4: =PL!AH16 -> 1.4540406e+11 | N4: =PL!AI16 -> 1.4127636e+11 | ... R4: =PL!AM16 -> 1.4744201e+11 | S4: =SUM(G4:R4) -> 1.6787476e+12
A5: =A4+1 -> 2 | B5: Giá vốn | C5: tr.đ | E5: =SUM(PL!D20:O20) -> 1266849611970 | F5: =SUM(PL!P20:AA20) -> 1326796753020 | G5: =PL!AB20 -> 1.112126e+11 | H5: =PL!AC20 -> 1.1487344e+11 | I5: =PL!AD20 -> 1.1977663e+11 | J5: =PL!AE20 -> 1.1273471e+11 | K5: =PL!AF20 -> 1.1787345e+11 | L5: =PL!AG20 -> 1.2058265e+11 | M5: =PL!AH20 -> 1.1780873e+11 | N5: =PL!AI20 -> 1.1382363e+11 | ... R5: =PL!AM20 -> 1.2012256e+11 | S5: =SUM(G5:R5) -> 1.3991907e+12
A6: =A5+1 -> 3 | B6: Lãi gộp | C6: tr.đ | E6: =E4-E5 -> 187736118151 | F6: =F4-F5 -> 211090940063 | G6: =G4-G5 -> 1.829274e+10 | H6: =H4-H5 -> 1.3101005e+10 | I6: =I4-I5 -> 2.1822866e+10 | J6: =J4-J5 -> 1.9047554e+10 | K6: =K4-K5 -> 2.2370862e+10 | L6: =L4-L5 -> 2.0826655e+10 | ... S6: =S4-S5 -> 2.7955694e+11
A7: =A6+1 -> 4 | B7: %Lãi gộp | E7: =IFERROR(E6/E$4,0) -> 0.12906501 | F7: =IFERROR(F6/F$4,0) -> 0.13726031 | G7: =IFERROR(G6/G$4,0) -> 0.14125085 | H7: =IFERROR(H6/H$4,0) -> 0.10237204 | I7: =IFERROR(I6/I$4,0) -> 0.15411684 | J7: =IFERROR(J6/J$4,0) -> 0.14453807 | K7: =IFERROR(K6/K$4,0) -> 0.15951351 | L7: =IFERROR(L6/L$4,0) -> 0.14727925 | ... S7: =IFERROR(S6/S$4,0) -> 0.16652708
A8: =A7+1 -> 5 | B8: Lợi nhuận trước thuế | C8: tr.đ | E8: =SUM(PL!D43:O43) -> 47029317688 | F8: =SUM(PL!P43:AA43) -> 25026064408 | G8: =PL!AB43 -> 4.4747033e+08 | H8: =PL!AC43 -> -2.8767835e+09 | I8: =PL!AD43 -> 4.5395712e+09 | J8: =PL!AE43 -> 2.2796445e+09 | K8: =PL!AF43 -> 3.5450752e+09 | L8: =PL!AG43 -> 2.0947193e+09 | M8: =PL!AH43 -> 9.0031741e+09 | N8: =PL!AI43 -> 8.4046895e+09 | ... R8: =PL!AM43 -> 6.8857321e+09 | S8: =SUM(G8:R8) -> 5.9857641e+10
A9: =A8+1 -> 6 | B9: %Lãi vay | E9: =IFERROR(E8/E$4,0) -> 0.032331761 | F9: =IFERROR(F8/F$4,0) -> 0.016273012 | G9: =IFERROR(G8/G$4,0) -> 0.0034552268 | H9: =IFERROR(H8/H$4,0) -> -0.02247936 | I9: =IFERROR(I8/I$4,0) -> 0.032059234 | J9: =IFERROR(J8/J$4,0) -> 0.017298568 | K9: =IFERROR(K8/K$4,0) -> 0.025277854 | L9: =IFERROR(L8/L$4,0) -> 0.014813165 | ... S9: =IFERROR(S8/S$4,0) -> 0.035656128
A10: =A9+1 -> 7 | B10: Lợi nhuận sau thuế | C10: tr.đ | E10: =SUM(PL!D46:O46) -> 33662182592 | F10: =SUM(PL!P46:AA46) -> 19364703510 | G10: =PL!AB46 -> 67196451 | H10: =PL!AC46 -> -2.8767835e+09 | I10: =PL!AD46 -> 3.6049522e+09 | J10: =PL!AE46 -> 1.5326975e+09 | K10: =PL!AF46 -> 2.7625022e+09 | L10: =PL!AG46 -> 1.3867762e+09 | M10: =PL!AH46 -> 7.1655985e+09 | N10: =PL!AI46 -> 6.7241875e+09 | ... R10: =PL!AM46 -> 5.5628699e+09 | S10: =SUM(G10:R10) -> 4.6489947e+10
A11: =A10+1 -> 8 | B11: %LNST | E11: =IFERROR(E10/E$4,0) -> 0.02314211 | F11: =IFERROR(F10/F$4,0) -> 0.012591754 | G11: =IFERROR(G10/G$4,0) -> 0.00051887011 | H11: =IFERROR(H10/H$4,0) -> -0.02247936 | I11: =IFERROR(I10/I$4,0) -> 0.025458793 | J11: =IFERROR(J10/J$4,0) -> 0.01163053 | K11: =IFERROR(K10/K$4,0) -> 0.019697785 | L11: =IFERROR(L10/L$4,0) -> 0.0098068244 | ... S11: =IFERROR(S10/S$4,0) -> 0.027693232
A12: =A11+1 -> 9 | B12: Chi phí bán hàng | C12: tr.đ | E12: =SUM(PL!D37:O37) -> 56679107574 | F12: =SUM(PL!P37:AA37) -> 61741245592 | G12: =PL!AB37 -> 5.7151198e+09 | H12: =PL!AC37 -> 4.5328953e+09 | I12: =PL!AD37 -> 5.3549859e+09 | J12: =PL!AE37 -> 4.7672285e+09 | K12: =PL!AF37 -> 6.360624e+09 | L12: =PL!AG37 -> 5.7198861e+09 | M12: =PL!AH37 -> 5.09689e+09 | N12: =PL!AI37 -> 4.9944445e+09 | ... R12: =PL!AM37 -> 5.5406114e+09 | S12: =SUM(G12:R12) -> 6.5635224e+10
A13: =A12+1 -> 10 | B13: %Cpbh | E13: =IFERROR(E12/E$4,0) -> 0.038965808 | F13: =IFERROR(F12/F$4,0) -> 0.040146784 | G13: =IFERROR(G12/G$4,0) -> 0.044130379 | H13: =IFERROR(H12/H$4,0) -> 0.035420318 | I13: =IFERROR(I12/I$4,0) -> 0.037817833 | J13: =IFERROR(J12/J$4,0) -> 0.036175038 | K13: =IFERROR(K12/K$4,0) -> 0.045353884 | L13: =IFERROR(L12/L$4,0) -> 0.040449151 | ... S13: =IFERROR(S12/S$4,0) -> 0.039097732
A14: =A13+1 -> 11 | B14: Chi phí quản lý | C14: tr.đ | E14: =SUM(PL!D38:O38) -> 78474020435 | F14: =SUM(PL!P38:AA38) -> 116368592636 | G14: =PL!AB38 -> 1.0275861e+10 | H14: =PL!AC38 -> 8.7169324e+09 | I14: =PL!AD38 -> 8.7599047e+09 | J14: =PL!AE38 -> 8.9181475e+09 | K14: =PL!AF38 -> 9.0570395e+09 | L14: =PL!AG38 -> 9.5047244e+09 | M14: =PL!AH38 -> 9.9320859e+09 | N14: =PL!AI38 -> 1.030846e+10 | ... R14: =PL!AM38 -> 1.1367196e+10 | S14: =SUM(G14:R14) -> 1.1444546e+11
A15: =A14+1 -> 12 | B15: %Cpql | E15: =IFERROR(E14/E$4,0) -> 0.053949395 | F15: =IFERROR(F14/F$4,0) -> 0.075667809 | G15: =IFERROR(G14/G$4,0) -> 0.079347003 | H15: =IFERROR(H14/H$4,0) -> 0.068114635 | I15: =IFERROR(I14/I$4,0) -> 0.061863956 | J15: =IFERROR(J14/J$4,0) -> 0.067673351 | K15: =IFERROR(K14/K$4,0) -> 0.064580443 | L15: =IFERROR(L14/L$4,0) -> 0.06721428 | ... S15: =IFERROR(S14/S$4,0) -> 0.068173117
A16: =A15+1 -> 13 | B16: Lãi vay | C16: tr.đ | E16: =SUM(PL!D36:O36) -> 10328501137 | F16: =SUM(PL!P36:AA36) -> 14266626254 | G16: =PL!AB36 -> 1.4407292e+09 | H16: =PL!AC36 -> 2.3144015e+09 | I16: =PL!AD36 -> 2.7548451e+09 | J16: =PL!AE36 -> 2.658974e+09 | K16: =PL!AF36 -> 2.9845639e+09 | L16: =PL!AG36 -> 3.0837659e+09 | M16: =PL!AH36 -> 3.1396192e+09 | N16: =PL!AI36 -> 3.3215811e+09 | ... R16: =PL!AM36 -> 3.1023551e+09 | S16: =SUM(G16:R16) -> 3.4565904e+10
A17: =A16+1 -> 14 | B17: %Lãi vay | E17: =IFERROR(E16/E$4,0) -> 0.0071006479 | F17: =IFERROR(F16/F$4,0) -> 0.0092767673 | G17: =IFERROR(G16/G$4,0) -> 0.011124863 | H17: =IFERROR(H16/H$4,0) -> 0.018084873 | I17: =IFERROR(I16/I$4,0) -> 0.019455191 | J17: =IFERROR(J16/J$4,0) -> 0.020177024 | K17: =IFERROR(K16/K$4,0) -> 0.021281176 | L17: =IFERROR(L16/L$4,0) -> 0.021807377 | ... S17: =IFERROR(S16/S$4,0) -> 0.020590292
A18: =A17+1 -> 15 | B18: Khấu hao | C18: tr.đ | E18: =SUM(PL!D48:O48) -> 51297238188 | F18: =SUM(PL!P48:AA48) -> 62523478612 | G18: =PL!AB48 -> 5.9925726e+09 | H18: =PL!AC48 -> 6.3713e+09 | I18: =PL!AD48 -> 6.4789564e+09 | J18: =PL!AE48 -> 6.5541914e+09 | K18: =PL!AF48 -> 6.5701444e+09 | L18: =PL!AG48 -> 6.7121196e+09 | M18: =PL!AH48 -> 6.7121196e+09 | N18: =PL!AI48 -> 6.7121196e+09 | ... R18: =PL!AM48 -> 6.748464e+09 | S18: =SUM(G18:R18) -> 7.9048707e+10
A19: =A18+1 -> 16 | B19: %Khấu hao | E19: =IFERROR(E18/E$4,0) -> 0.035265875 | F19: =IFERROR(F18/F$4,0) -> 0.040655426 | G19: =IFERROR(G18/G$4,0) -> 0.046272783 | H19: =IFERROR(H18/H$4,0) -> 0.049785722 | I19: =IFERROR(I18/I$4,0) -> 0.045755506 | J19: =IFERROR(J18/J$4,0) -> 0.049735003 | K19: =IFERROR(K18/K$4,0) -> 0.046847851 | L19: =IFERROR(L18/L$4,0) -> 0.047465899 | ... S19: =IFERROR(S18/S$4,0) -> 0.047087904
A20: =A19+1 -> 17 | B20: EBITDA | E20: =E8+E16+E18 -> 108655057013 | F20: =F8+F16+F18 -> 101816169274 | G20: =G8+G16+G18 -> 7.8807721e+09 | H20: =H8+H16+H18 -> 5.808918e+09 | I20: =I8+I16+I18 -> 1.3773373e+10 | J20: =J8+J16+J18 -> 1.149281e+10 | K20: =K8+K16+K18 -> 1.3099783e+10 | L20: =L8+L16+L18 -> 1.1890605e+10 | ... S20: =S8+S16+S18 -> 1.7347225e+11
A21: =A20+1 -> 18 | B21: %EBITDA | E21: =IFERROR(E20/E$4,0) -> 0.074698283 | F21: =IFERROR(F20/F$4,0) -> 0.066205205 | G21: =IFERROR(G20/G$4,0) -> 0.060852873 | H21: =IFERROR(H20/H$4,0) -> 0.045391235 | I21: =IFERROR(I20/I$4,0) -> 0.097269931 | J21: =IFERROR(J20/J$4,0) -> 0.087210595 | K21: =IFERROR(K20/K$4,0) -> 0.093406882 | L21: =IFERROR(L20/L$4,0) -> 0.084086441 | ... S21: =IFERROR(S20/S$4,0) -> 0.10333432
A22: =A21+1 -> 19 | B22: VỐN LƯU ĐỘNG | C22: ngày | E22: =E23+E24-E25 -> 164.25862 | F22: =F23+F24-F25 -> 189.67798 | G22: =G23+G24-G25 -> 187.69697 | H22: =H23+H24-H25 -> 196.38979 | I22: =I23+I24-I25 -> 201.48846 | J22: =J23+J24-J25 -> 205.64116 | K22: =K23+K24-K25 -> 210.97934 | L22: =L23+L24-L25 -> 211.2458 | ... S22: =S23+S24-S25 -> 219.23181
A23: =A22+1 -> 20 | B23: Số ngày phải thu | C23: ngày | E23: {=AVERAGE(BS!D15:O15-BS!D84:O84)/SUM(PL!D16:O16)*365} -> 33.347739 | F23: {=AVERAGE(BS!O15:AA15-BS!O84:AA84)/SUM(PL!P16:AA16)*365} -> 33.509012 | G23: {=AVERAGE(BS!P15:AB15-BS!P84:AB84)/SUM(PL!Q16:AB16)*365} -> 33.924517 | H23: {=AVERAGE(BS!Q15:AC15-BS!Q84:AC84)/SUM(PL!R16:AC16)*365} -> 37.181786 | I23: {=AVERAGE(BS!R15:AD15-BS!R84:AD84)/SUM(PL!S16:AD16)*365} -> 37.261201 | J23: {=AVERAGE(BS!S15:AE15-BS!S84:AE84)/SUM(PL!T16:AE16)*365} -> 36.152566 | K23: {=AVERAGE(BS!T15:AF15-BS!T84:AF84)/SUM(PL!U16:AF16)*365} -> 36.133953 | L23: {=AVERAGE(BS!U15:AG15-BS!U84:AG84)/SUM(PL!V16:AG16)*365} -> 35.045839 | M23: {=AVERAGE(BS!V15:AH15-BS!V84:AH84)/SUM(PL!W16:AH16)*365} -> 35.215445 | ... R23: {=AVERAGE(BS!AA15:AM15-BS!AA84:AM84)/SUM(PL!AB16:AM16)*365} -> 31.376937 | S23: =R23 -> 31.376937
A24: =A23+1 -> 21 | B24: Số ngày tồn kho | C24: ngày | E24: =AVERAGE(BS!D22:O22)/SUM(PL!D20:O20)*365 -> 157.74683 | F24: =AVERAGE(BS!O22:AA22)/SUM(PL!P20:AA20)*365 -> 152.74932 | G24: =AVERAGE(BS!P22:AB22)/SUM(PL!Q20:AB20)*365 -> 148.98648 | H24: =AVERAGE(BS!Q22:AC22)/SUM(PL!R20:AC20)*365 -> 152.8816 | I24: =AVERAGE(BS!R22:AD22)/SUM(PL!S20:AD20)*365 -> 156.78309 | J24: =AVERAGE(BS!S22:AE22)/SUM(PL!T20:AE20)*365 -> 158.54169 | K24: =AVERAGE(BS!T22:AF22)/SUM(PL!U20:AF20)*365 -> 161.55204 | L24: =AVERAGE(BS!U22:AG22)/SUM(PL!V20:AG20)*365 -> 161.63379 | M24: =AVERAGE(BS!V22:AH22)/SUM(PL!W20:AH20)*365 -> 163.42655 | ... S24: =AVERAGE(BS!AB22:AN22)/SUM(PL!AC20:AN20)*365 -> 170.59399
A25: =A24+1 -> 22 | B25: Số ngày phải trả | C25: ngày | E25: {=AVERAGE(BS!D83:O83-BS!D16:O16)/SUM(PL!D20:O20)*365} -> 26.835954 | F25: {=AVERAGE(BS!O83:AA83-BS!O16:AA16)/SUM(PL!P20:AA20)*365} -> -3.4196471 | G25: {=AVERAGE(BS!P83:AB83-BS!P16:AB16)/SUM(PL!Q20:AB20)*365} -> -4.7859657 | H25: {=AVERAGE(BS!Q83:AC83-BS!Q16:AC16)/SUM(PL!R20:AC20)*365} -> -6.3264053 | I25: {=AVERAGE(BS!R83:AD83-BS!R16:AD16)/SUM(PL!S20:AD20)*365} -> -7.4441679 | J25: {=AVERAGE(BS!S83:AE83-BS!S16:AE16)/SUM(PL!T20:AE20)*365} -> -10.946902 | K25: {=AVERAGE(BS!T83:AF83-BS!T16:AF16)/SUM(PL!U20:AF20)*365} -> -13.293352 | L25: {=AVERAGE(BS!U83:AG83-BS!U16:AG16)/SUM(PL!V20:AG20)*365} -> -14.56617 | M25: {=AVERAGE(BS!V83:AH83-BS!V16:AH16)/SUM(PL!W20:AH20)*365} -> -16.36804 | ... R25: {=AVERAGE(BS!AA83:AM83-BS!AA16:AM16)/SUM(PL!AB20:AM20)*365} -> -17.260881 | S25: =R25 -> -17.260881
A26: =A25+1 -> 23 | B26: ROE | C26: % | E26: =E27*E28*E29 -> 0.040223061 | F26: =F27*F28*F29 -> 0.020726111 | S26: =S27*S28*S29 -> 0.049161013
A27: =A26+1 -> 24 | B27: %Lợi nhuận sau thuế | C27: % | E27: =E11 -> 0.02314211 | F27: =F11 -> 0.012591754 | S27: =S11 -> 0.027693232
A28: =A27+1 -> 25 | B28: Vòng quay tài sản | C28: lần | E28: =SUM(PL!D16:O16)/AVERAGE(BS!D80:O80) -> 1.1498401 | F28: =SUM(PL!P16:AA16)/AVERAGE(BS!O80:AA80) -> 1.1292143 | S28: =SUM(PL!AB16:AM16)/AVERAGE(BS!AA80:AM80) -> 0.8861647
A29: =A28+1 -> 26 | B29: Tổng tài sản/VCSH | C29: lần | E29: =AVERAGE(BS!D80:O80)/AVERAGE(BS!D113:O113) -> 1.5115925 | F29: =AVERAGE(BS!O80:AA80)/AVERAGE(BS!O113:AA113) -> 1.4576566 | S29: =AVERAGE(BS!AA80:AM80)/AVERAGE(BS!AA113:AM113) -> 2.0032388
A30: =A29+1 -> 27 | B30: ROA | C30: % | E30: =E27*E28 -> 0.026609726 | F30: =F27*F28 -> 0.014218789 | S30: =S27*S28 -> 0.024540765
B32: Các chỉ tiêu nợ vay
B33: Nợ vay / Doanh thu | C33: % | E33: {=AVERAGE(BS!D93:O93+BS!D107:O107)/E4} -> 0.17372574 | F33: {=AVERAGE(BS!O93:AA93+BS!O107:AA107)/F4} -> 0.21164644 | S33: {=AVERAGE(BS!AA93:AM93+BS!AA107:AM107)/S4} -> 0.40457965
B34: Nợ vay / VCSH | C34: lần | E34: {=AVERAGE(BS!D93:O93+BS!D107:O107)/AVERAGE(BS!D113:O113)} -> 0.3019509 | F34: {=AVERAGE(BS!O93:AA93+BS!O107:AA107)/AVERAGE(BS!O113:AA113)} -> 0.34837146 | S34: {=AVERAGE(BS!AA93:AM93+BS!AA107:AM107)/AVERAGE(BS!AA113:AM113)} -> 0.7182096

Sheet PL
A3: Index PL | B3: PHẦN II-KẾT QUẢ HOẠT ĐỘNG KINH DOANH | D3: T01.2024 | E3: T02.2024 | F3: T03.2024 | G3: T04.2024 | H3: T05.2024 | I3: T06.2024 | J3: T07.2024 | K3: T08.2024 | L3: T09.2024 | M3: T10.2024 | N3: T11.2024 | O3: T12.2024 | P3: T01.2025 | Q3: T02.2025 | R3: T03.2025 | S3: T04.2025 | T3: T05.2025 | U3: T06.2025 | V3: T07.2025 | W3: T08.2025 | X3: T09.2025 | Y3: T10.2025 | Z3: T11.2025 | AA3: T12.2025 | AB3: T01.2026 | AC3: T02.2026 | AD3: T03.2026 | AE3: T04.2026 | AF3: T05.2026 | AG3: T06.2026 | AH3: T07.2026 | AI3: T08.2026 | AJ3: T09.2026 | AK3: T10.2026 | AL3: T11.2026 | AM3: T12.2026
A4: 1 | B4: Sản lượng (tấn) | P4: 3616.4013 | Q4: 6002.038 | R4: 4987.398 | S4: 4085.947 | T4: 4800.6903 | U4: 4045.353 | V4: 4698.9851 | W4: 5678.89 | X4: 3116.57 | Y4: 3435.779 | Z4: 3062.156 | AA4: 3190.589 | AB4: ='Consol PL-DTRG'!C5 -> 4318.2229 | AC4: ='Consol PL-DTRG'!D5 -> 4253.3146 | AD4: ='Consol PL-DTRG'!E5 -> 4678.5574 | AE4: ='Consol PL-DTRG'!F5 -> 4394.2315 | AF4: ='Consol PL-DTRG'!G5 -> 4663.4364 | AG4: ='Consol PL-DTRG'!H5 -> 4691.9522 | AH4: ='Consol PL-DTRG'!I5 -> 4689.4225 | AI4: ='Consol PL-DTRG'!J5 -> 4562.8495 | ... AM4: ='Consol PL-DTRG'!N5 -> 4784.5204
A5: SL-BN | B5: Bán ngoài | P5: 3616.4013 | Q5: 6002.038 | R5: 4987.398 | S5: 4085.947 | T5: 4800.6903 | U5: 4045.353 | V5: 4698.9851 | W5: 5678.89 | X5: 3116.57 | Y5: 3435.779 | Z5: 3062.156 | AA5: 3190.589 | AB5: ='Consol PL-DTRG'!C6 -> 4318.2229 | AC5: ='Consol PL-DTRG'!D6 -> 4253.3146 | AD5: ='Consol PL-DTRG'!E6 -> 4678.5574 | AE5: ='Consol PL-DTRG'!F6 -> 4394.2315 | AF5: ='Consol PL-DTRG'!G6 -> 4663.4364 | AG5: ='Consol PL-DTRG'!H6 -> 4691.9522 | AH5: ='Consol PL-DTRG'!I6 -> 4689.4225 | AI5: ='Consol PL-DTRG'!J6 -> 4562.8495 | ... AM5: ='Consol PL-DTRG'!N6 -> 4784.5204
A6: SL-MC | B6: Mẹ-Con | P6: 0 | Q6: 0 | R6: 0 | S6: 0 | T6: 0 | U6: 0 | V6: 0 | W6: 0 | X6: 0 | Y6: 0 | Z6: 0 | AA6: 0 | AB6: ='Consol PL-DTRG'!C7 -> 0 | AC6: ='Consol PL-DTRG'!D7 -> 0 | AD6: ='Consol PL-DTRG'!E7 -> 0 | AE6: ='Consol PL-DTRG'!F7 -> 0 | AF6: ='Consol PL-DTRG'!G7 -> 0 | AG6: ='Consol PL-DTRG'!H7 -> 0 | AH6: ='Consol PL-DTRG'!I7 -> 0 | AI6: ='Consol PL-DTRG'!J7 -> 0 | ... AM6: ='Consol PL-DTRG'!N7 -> 0
A7: SL-CC | B7: Con-Con | P7: 0 | Q7: 0 | R7: 0 | S7: 0 | T7: 0 | U7: 0 | V7: 0 | W7: 0 | X7: 0 | Y7: 0 | Z7: 0 | AA7: 0 | AB7: ='Consol PL-DTRG'!C8 -> 0 | AC7: ='Consol PL-DTRG'!D8 -> 0 | AD7: ='Consol PL-DTRG'!E8 -> 0 | AE7: ='Consol PL-DTRG'!F8 -> 0 | AF7: ='Consol PL-DTRG'!G8 -> 0 | AG7: ='Consol PL-DTRG'!H8 -> 0 | AH7: ='Consol PL-DTRG'!I8 -> 0 | AI7: ='Consol PL-DTRG'!J8 -> 0 | ... AM7: ='Consol PL-DTRG'!N8 -> 0
A8: 2 | B8: 1.Doanh thu bán hàng và cung cấp dịch vụ | D8: 130037940981 | E8: 84645791256 | F8: 115625416433 | G8: 117647266094 | H8: 128085507494 | I8: 95661572209 | J8: 74679662458 | K8: 178936926222 | L8: 180140886766 | M8: 143211413018 | N8: 97197472020 | O8: 128687104846 | P8: 114983880947 | Q8: 188477338235 | R8: 150716555192 | S8: 125691833422 | T8: 153638670524 | U8: 120188501523 | V8: 138030275641 | W8: 169482496928 | X8: 91503288423 | Y8: 109010675108 | Z8: 89868450986 | AA8: 100768484341 | AB8: ='Consol PL-DTRG'!C9 -> 1.2950534e+11 | AC8: ='Consol PL-DTRG'!D9 -> 1.2797444e+11 | AD8: ='Consol PL-DTRG'!E9 -> 1.4159949e+11 | AE8: ='Consol PL-DTRG'!F9 -> 1.3178227e+11 | AF8: ='Consol PL-DTRG'!G9 -> 1.4024431e+11 | AG8: ='Consol PL-DTRG'!H9 -> 1.414093e+11 | AH8: ='Consol PL-DTRG'!I9 -> 1.4540406e+11 | AI8: ='Consol PL-DTRG'!J9 -> 1.4127636e+11 | ... AM8: ='Consol PL-DTRG'!N9 -> 1.4744201e+11
A9: 511-BN | B9: Bán ngoài | P9: 114983880947 | Q9: 188477338235 | R9: 150716555192 | S9: 125691833422 | T9: 153638670524 | U9: 120188501523 | V9: 138030275641 | W9: 169482496928 | X9: 91503288423 | Y9: 109010675108 | Z9: 89868450986 | AA9: 100768484341 | AB9: ='Consol PL-DTRG'!C10 -> 1.2950534e+11 | AC9: ='Consol PL-DTRG'!D10 -> 1.2797444e+11 | AD9: ='Consol PL-DTRG'!E10 -> 1.4159949e+11 | AE9: ='Consol PL-DTRG'!F10 -> 1.3178227e+11 | AF9: ='Consol PL-DTRG'!G10 -> 1.4024431e+11 | AG9: ='Consol PL-DTRG'!H10 -> 1.414093e+11 | AH9: ='Consol PL-DTRG'!I10 -> 1.4540406e+11 | AI9: ='Consol PL-DTRG'!J10 -> 1.4127636e+11 | ... AM9: ='Consol PL-DTRG'!N10 -> 1.4744201e+11
A10: 511-MC | B10: Mẹ-Con | P10: 0 | Q10: 0 | R10: 0 | S10: 0 | T10: 0 | U10: 0 | V10: 0 | W10: 0 | X10: 0 | Y10: 0 | Z10: 0 | AA10: 0 | AB10: ='Consol PL-DTRG'!C11 -> 0 | AC10: ='Consol PL-DTRG'!D11 -> 0 | AD10: ='Consol PL-DTRG'!E11 -> 0 | AE10: ='Consol PL-DTRG'!F11 -> 0 | AF10: ='Consol PL-DTRG'!G11 -> 0 | AG10: ='Consol PL-DTRG'!H11 -> 0 | AH10: ='Consol PL-DTRG'!I11 -> 0 | AI10: ='Consol PL-DTRG'!J11 -> 0 | ... AM10: ='Consol PL-DTRG'!N11 -> 0
A11: 511-CC | B11: Con-Con | P11: 0 | Q11: 0 | R11: 0 | S11: 0 | T11: 0 | U11: 0 | V11: 0 | W11: 0 | X11: 0 | Y11: 0 | Z11: 0 | AA11: 0 | AB11: ='Consol PL-DTRG'!C12 -> 0 | AC11: ='Consol PL-DTRG'!D12 -> 0 | AD11: ='Consol PL-DTRG'!E12 -> 0 | AE11: ='Consol PL-DTRG'!F12 -> 0 | AF11: ='Consol PL-DTRG'!G12 -> 0 | AG11: ='Consol PL-DTRG'!H12 -> 0 | AH11: ='Consol PL-DTRG'!I12 -> 0 | AI11: ='Consol PL-DTRG'!J12 -> 0 | ... AM11: ='Consol PL-DTRG'!N12 -> 0
A12: 3 | B12: 2.Các khoản giảm trừ doanh thu | D12: 0 | E12: 1166125000 | F12: 0 | G12: 0 | H12: 136455000 | I12: 0 | J12: 0 | K12: 6345077301 | L12: 4671587529 | M12: 2922205276 | N12: 49359030 | O12: 4680420540 | P12: 513935495 | Q12: 477877176 | R12: 477350452 | S12: 304590498 | T12: 1607115262 | U12: 708638196 | V12: 26953743 | W12: 1000293545 | X12: 6773818500 | Y12: 0 | Z12: 1479093000 | AA12: 1103092320 | AB12: ='Consol PL-DTRG'!C13 -> 0 | AC12: ='Consol PL-DTRG'!D13 -> 0 | AD12: ='Consol PL-DTRG'!E13 -> 0 | AE12: ='Consol PL-DTRG'!F13 -> 0 | AF12: ='Consol PL-DTRG'!G13 -> 0 | AG12: ='Consol PL-DTRG'!H13 -> 0 | AH12: ='Consol PL-DTRG'!I13 -> 0 | AI12: ='Consol PL-DTRG'!J13 -> 0 | ... AM12: ='Consol PL-DTRG'!N13 -> 0
A13: 521-BN | B13: Bán ngoài | P13: 513935495 | Q13: 477877176 | R13: 477350452 | S13: 304590498 | T13: 1607115262 | U13: 708638196 | V13: 26953743 | W13: 1000293545 | X13: 6773818500 | Y13: 0 | Z13: 1479093000 | AA13: 1103092320 | AB13: ='Consol PL-DTRG'!C14 -> 0 | AC13: ='Consol PL-DTRG'!D14 -> 0 | AD13: ='Consol PL-DTRG'!E14 -> 0 | AE13: ='Consol PL-DTRG'!F14 -> 0 | AF13: ='Consol PL-DTRG'!G14 -> 0 | AG13: ='Consol PL-DTRG'!H14 -> 0 | AH13: ='Consol PL-DTRG'!I14 -> 0 | AI13: ='Consol PL-DTRG'!J14 -> 0 | ... AM13: ='Consol PL-DTRG'!N14 -> 0
A14: 521-MC | B14: Mẹ-Con | P14: 0 | Q14: 0 | R14: 0 | S14: 0 | T14: 0 | U14: 0 | V14: 0 | W14: 0 | X14: 0 | Y14: 0 | Z14: 0 | AA14: 0 | AB14: ='Consol PL-DTRG'!C15 -> 0 | AC14: ='Consol PL-DTRG'!D15 -> 0 | AD14: ='Consol PL-DTRG'!E15 -> 0 | AE14: ='Consol PL-DTRG'!F15 -> 0 | AF14: ='Consol PL-DTRG'!G15 -> 0 | AG14: ='Consol PL-DTRG'!H15 -> 0 | AH14: ='Consol PL-DTRG'!I15 -> 0 | AI14: ='Consol PL-DTRG'!J15 -> 0 | ... AM14: ='Consol PL-DTRG'!N15 -> 0
A15: 521-CC | B15: Con-Con | P15: 0 | Q15: 0 | R15: 0 | S15: 0 | T15: 0 | U15: 0 | V15: 0 | W15: 0 | X15: 0 | Y15: 0 | Z15: 0 | AA15: 0 | AB15: ='Consol PL-DTRG'!C16 -> 0 | AC15: ='Consol PL-DTRG'!D16 -> 0 | AD15: ='Consol PL-DTRG'!E16 -> 0 | AE15: ='Consol PL-DTRG'!F16 -> 0 | AF15: ='Consol PL-DTRG'!G16 -> 0 | AG15: ='Consol PL-DTRG'!H16 -> 0 | AH15: ='Consol PL-DTRG'!I16 -> 0 | AI15: ='Consol PL-DTRG'!J16 -> 0 | ... AM15: ='Consol PL-DTRG'!N16 -> 0
A16: 4 | B16: 3.Doanh thu thuần về bán hàng và cung cấp dịch vụ | D16: 130037940981 | E16: 83479666256 | F16: 115625416433 | G16: 117647266094 | H16: 127949052494 | I16: 95661572209 | J16: 74679662458 | K16: 172591848921 | L16: 175469299237 | M16: 140289207742 | N16: 97148112990 | O16: 124006684306 | P16: 114469945452 | Q16: 187999461059 | R16: 150239204740 | S16: 125387242924 | T16: 152031555262 | U16: 119479863327 | V16: 138003321898 | W16: 168482203383 | X16: 84729469923 | Y16: 109010675108 | Z16: 88389357986 | AA16: 99665392021 | AB16: ='Consol PL-DTRG'!C17 -> 1.2950534e+11 | AC16: ='Consol PL-DTRG'!D17 -> 1.2797444e+11 | AD16: ='Consol PL-DTRG'!E17 -> 1.4159949e+11 | AE16: ='Consol PL-DTRG'!F17 -> 1.3178227e+11 | AF16: ='Consol PL-DTRG'!G17 -> 1.4024431e+11 | AG16: ='Consol PL-DTRG'!H17 -> 1.414093e+11 | AH16: ='Consol PL-DTRG'!I17 -> 1.4540406e+11 | AI16: ='Consol PL-DTRG'!J17 -> 1.4127636e+11 | ... AM16: ='Consol PL-DTRG'!N17 -> 1.4744201e+11
A17: DTT-BN | B17: Bán ngoài | P17: 114469945452 | Q17: 187999461059 | R17: 150239204740 | S17: 125387242924 | T17: 152031555262 | U17: 119479863327 | V17: 138003321898 | W17: 168482203383 | X17: 84729469923 | Y17: 109010675108 | Z17: 88389357986 | AA17: 99665392021 | AB17: ='Consol PL-DTRG'!C18 -> 1.2950534e+11 | AC17: ='Consol PL-DTRG'!D18 -> 1.2797444e+11 | AD17: ='Consol PL-DTRG'!E18 -> 1.4159949e+11 | AE17: ='Consol PL-DTRG'!F18 -> 1.3178227e+11 | AF17: ='Consol PL-DTRG'!G18 -> 1.4024431e+11 | AG17: ='Consol PL-DTRG'!H18 -> 1.414093e+11 | AH17: ='Consol PL-DTRG'!I18 -> 1.4540406e+11 | AI17: ='Consol PL-DTRG'!J18 -> 1.4127636e+11 | ... AM17: ='Consol PL-DTRG'!N18 -> 1.4744201e+11
A18: DTT-MC | B18: Mẹ-Con | P18: 0 | Q18: 0 | R18: 0 | S18: 0 | T18: 0 | U18: 0 | V18: 0 | W18: 0 | X18: 0 | Y18: 0 | Z18: 0 | AA18: 0 | AB18: ='Consol PL-DTRG'!C19 -> 0 | AC18: ='Consol PL-DTRG'!D19 -> 0 | AD18: ='Consol PL-DTRG'!E19 -> 0 | AE18: ='Consol PL-DTRG'!F19 -> 0 | AF18: ='Consol PL-DTRG'!G19 -> 0 | AG18: ='Consol PL-DTRG'!H19 -> 0 | AH18: ='Consol PL-DTRG'!I19 -> 0 | AI18: ='Consol PL-DTRG'!J19 -> 0 | ... AM18: ='Consol PL-DTRG'!N19 -> 0
A19: DTT-CC | B19: Con-Con | P19: 0 | Q19: 0 | R19: 0 | S19: 0 | T19: 0 | U19: 0 | V19: 0 | W19: 0 | X19: 0 | Y19: 0 | Z19: 0 | AA19: 0 | AB19: ='Consol PL-DTRG'!C20 -> 0 | AC19: ='Consol PL-DTRG'!D20 -> 0 | AD19: ='Consol PL-DTRG'!E20 -> 0 | AE19: ='Consol PL-DTRG'!F20 -> 0 | AF19: ='Consol PL-DTRG'!G20 -> 0 | AG19: ='Consol PL-DTRG'!H20 -> 0 | AH19: ='Consol PL-DTRG'!I20 -> 0 | AI19: ='Consol PL-DTRG'!J20 -> 0 | ... AM19: ='Consol PL-DTRG'!N20 -> 0
A20: 5 | B20: 4.Giá vốn hàng bán | D20: 120065457134 | E20: 83995360322 | F20: 109165390822 | G20: 105655387173 | H20: 125507167216 | I20: 98477492806 | J20: 80393606783 | K20: 167228552558 | L20: 152083786508 | M20: 135696763155 | N20: 92718574459 | O20: -4137926966 | P20: 97986840184 | Q20: 155693128574 | R20: 129053280797 | S20: 108257691858 | T20: 128243821985 | U20: 104299018492 | V20: 124260554437 | W20: 150760754200 | X20: 81919659396 | Y20: 98239930365 | Z20: 80093235439 | AA20: 67988837293 | AB20: ='Consol PL-DTRG'!C21 -> 1.112126e+11 | AC20: ='Consol PL-DTRG'!D21 -> 1.1487344e+11 | AD20: ='Consol PL-DTRG'!E21 -> 1.1977663e+11 | AE20: ='Consol PL-DTRG'!F21 -> 1.1273471e+11 | AF20: ='Consol PL-DTRG'!G21 -> 1.1787345e+11 | AG20: ='Consol PL-DTRG'!H21 -> 1.2058265e+11 | AH20: ='Consol PL-DTRG'!I21 -> 1.1780873e+11 | AI20: ='Consol PL-DTRG'!J21 -> 1.1382363e+11 | ... AM20: ='Consol PL-DTRG'!N21 -> 1.2012256e+11
A21: 632-BN | B21: Bán ngoài | P21: 96300770078 | Q21: 154570631505 | R21: 129509315823 | S21: 109525077013 | T21: 129914451733 | U21: 106614505132 | V21: 128694704995 | W21: 155128887377 | X21: 83081045429 | Y21: 99996863451 | Z21: 80689028389 | AA21: 70066064909 | AB21: ='Consol PL-DTRG'!C22 -> 1.1157315e+11 | AC21: ='Consol PL-DTRG'!D22 -> 1.1494222e+11 | AD21: ='Consol PL-DTRG'!E22 -> 1.2021369e+11 | AE21: ='Consol PL-DTRG'!F22 -> 1.1329788e+11 | AF21: ='Consol PL-DTRG'!G22 -> 1.195158e+11 | AG21: ='Consol PL-DTRG'!H22 -> 1.2132006e+11 | AH21: ='Consol PL-DTRG'!I22 -> 1.1966307e+11 | AI21: ='Consol PL-DTRG'!J22 -> 1.1606589e+11 | ... AM21: ='Consol PL-DTRG'!N22 -> 1.224094e+11
A22: 632-MC | B22: Mẹ-Con | P22: 1.2602127e+09 | Q22: 1122497069 | R22: -456035026 | S22: -1267385155 | T22: -1670629748 | U22: -2315486640 | V22: -4434150558 | W22: -4368133177 | X22: -1161386033 | Y22: -1756933086 | Z22: -595792950 | AA22: -2077227616 | AB22: ='Consol PL-DTRG'!C23 -> -1.4422047e+09 | AC22: ='Consol PL-DTRG'!D23 -> -2.7514751e+08 | AD22: ='Consol PL-DTRG'!E23 -> -1.7482516e+09 | AE22: ='Consol PL-DTRG'!F23 -> -2.2526726e+09 | AF22: ='Consol PL-DTRG'!G23 -> -2.2428215e+09 | AG22: ='Consol PL-DTRG'!H23 -> -2.1242051e+09 | AH22: ='Consol PL-DTRG'!I23 -> -2.1726208e+09 | AI22: ='Consol PL-DTRG'!J23 -> -2.2110511e+09 | ... AM22: ='Consol PL-DTRG'!N23 -> -2.5142207e+09
A23: 632-CC | B23: Con-Con | P23: 4.2585738e+08 | Q23: 0 | R23: 0 | S23: 0 | T23: 0 | U23: 0 | V23: 0 | W23: 0 | X23: 0 | Y23: 0 | Z23: 0 | AA23: 0 | AB23: ='Consol PL-DTRG'!C24 -> 0 | AC23: ='Consol PL-DTRG'!D24 -> 0 | AD23: ='Consol PL-DTRG'!E24 -> 0 | AE23: ='Consol PL-DTRG'!F24 -> 0 | AF23: ='Consol PL-DTRG'!G24 -> 0 | AG23: ='Consol PL-DTRG'!H24 -> 0 | AH23: ='Consol PL-DTRG'!I24 -> 0 | AI23: ='Consol PL-DTRG'!J24 -> 0 | ... AM23: ='Consol PL-DTRG'!N24 -> 0
A24: URP-DK | B24: URP đầu kỳ | AB24: ='Consol PL-DTRG'!C25 -> 0 | AC24: ='Consol PL-DTRG'!D25 -> 1.0816536e+09 | AD24: ='Consol PL-DTRG'!E25 -> 1.2880142e+09 | AE24: ='Consol PL-DTRG'!F25 -> 2.5992029e+09 | AF24: ='Consol PL-DTRG'!G25 -> 4.2887073e+09 | AG24: ='Consol PL-DTRG'!H25 -> 4.8891699e+09 | AH24: ='Consol PL-DTRG'!I25 -> 6.2759631e+09 | AI24: ='Consol PL-DTRG'!J25 -> 6.59424e+09 | ... AM24: ='Consol PL-DTRG'!N25 -> 6.9202278e+09
A25: URP-CK | B25: URP cuối kỳ | AB25: ='Consol PL-DTRG'!C26 -> 1.0816536e+09 | AC25: ='Consol PL-DTRG'!D26 -> 1.2880142e+09 | AD25: ='Consol PL-DTRG'!E26 -> 2.5992029e+09 | AE25: ='Consol PL-DTRG'!F26 -> 4.2887073e+09 | AF25: ='Consol PL-DTRG'!G26 -> 4.8891699e+09 | AG25: ='Consol PL-DTRG'!H26 -> 6.2759631e+09 | AH25: ='Consol PL-DTRG'!I26 -> 6.59424e+09 | AI25: ='Consol PL-DTRG'!J26 -> 6.5630238e+09 | ... AM25: ='Consol PL-DTRG'!N26 -> 7.147605e+09
A26: 6 | B26: 5.Lợi nhuận gộp về bán hàng | D26: 9972483847 | E26: -515694066 | F26: 6460025611 | G26: 11991878921 | H26: 2441885278 | I26: -2815920597 | J26: -5713944325 | K26: 5363296363 | L26: 23385512729 | M26: 4592444587 | N26: 4429538531 | O26: 128144611272 | P26: 16483105268 | Q26: 32306332485 | R26: 21185923943 | S26: 17129551066 | T26: 23787733277 | U26: 15180844835 | V26: 13742767461 | W26: 17721449183 | X26: 2809810527 | Y26: 10770744743 | Z26: 8296122547 | AA26: 31676554728 | AB26: ='Consol PL-DTRG'!C27 -> 1.829274e+10 | AC26: ='Consol PL-DTRG'!D27 -> 1.3101005e+10 | AD26: ='Consol PL-DTRG'!E27 -> 2.1822866e+10 | AE26: ='Consol PL-DTRG'!F27 -> 1.9047554e+10 | AF26: ='Consol PL-DTRG'!G27 -> 2.2370862e+10 | AG26: ='Consol PL-DTRG'!H27 -> 2.0826655e+10 | AH26: ='Consol PL-DTRG'!I27 -> 2.7595329e+10 | AI26: ='Consol PL-DTRG'!J27 -> 2.7452735e+10 | ... AM26: ='Consol PL-DTRG'!N27 -> 2.7319454e+10
A27: LG-BN | B27: Bán ngoài | P27: 18169175374 | Q27: 33428829554 | R27: 20729888917 | S27: 15862165911 | T27: 22117103529 | U27: 12865358195 | V27: 9308616903 | W27: 13353316006 | X27: 1648424494 | Y27: 9013811657 | Z27: 7700329597 | AA27: 29599327112 | AB27: ='Consol PL-DTRG'!C28 -> 1.6850535e+10 | AC27: ='Consol PL-DTRG'!D28 -> 1.2825858e+10 | AD27: ='Consol PL-DTRG'!E28 -> 2.0074615e+10 | AE27: ='Consol PL-DTRG'!F28 -> 1.6794881e+10 | AF27: ='Consol PL-DTRG'!G28 -> 2.0128041e+10 | AG27: ='Consol PL-DTRG'!H28 -> 1.870245e+10 | AH27: ='Consol PL-DTRG'!I28 -> 2.5422708e+10 | AI27: ='Consol PL-DTRG'!J28 -> 2.5241684e+10 | ... AM27: ='Consol PL-DTRG'!N28 -> 2.4805233e+10
A28: LG-MC | B28: Mẹ-Con | P28: -1.2602127e+09 | Q28: -1122497069 | R28: 456035026 | S28: 1267385155 | T28: 1670629748 | U28: 2315486640 | V28: 4434150558 | W28: 4368133177 | X28: 1161386033 | Y28: 1756933086 | Z28: 595792950 | AA28: 2077227616 | AB28: ='Consol PL-DTRG'!C29 -> 1.4422047e+09 | AC28: ='Consol PL-DTRG'!D29 -> 2.7514751e+08 | AD28: ='Consol PL-DTRG'!E29 -> 1.7482516e+09 | AE28: ='Consol PL-DTRG'!F29 -> 2.2526726e+09 | AF28: ='Consol PL-DTRG'!G29 -> 2.2428215e+09 | AG28: ='Consol PL-DTRG'!H29 -> 2.1242051e+09 | AH28: ='Consol PL-DTRG'!I29 -> 2.1726208e+09 | AI28: ='Consol PL-DTRG'!J29 -> 2.2110511e+09 | ... AM28: ='Consol PL-DTRG'!N29 -> 2.5142207e+09
A29: LG-CC | B29: Con-Con | P29: -4.2585738e+08 | Q29: 0 | R29: 0 | S29: 0 | T29: 0 | U29: 0 | V29: 0 | W29: 0 | X29: 0 | Y29: 0 | Z29: 0 | AA29: 0 | AB29: ='Consol PL-DTRG'!C30 -> 0 | AC29: ='Consol PL-DTRG'!D30 -> 0 | AD29: ='Consol PL-DTRG'!E30 -> 0 | AE29: ='Consol PL-DTRG'!F30 -> 0 | AF29: ='Consol PL-DTRG'!G30 -> 0 | AG29: ='Consol PL-DTRG'!H30 -> 0 | AH29: ='Consol PL-DTRG'!I30 -> 0 | AI29: ='Consol PL-DTRG'!J30 -> 0 | ... AM29: ='Consol PL-DTRG'!N30 -> 0
A30: 7 | B30: 6.Lãi/lỗ của hoạt động bán, thanh lý bất động sản đầu tư | P30: 0 | Q30: 0 | R30: 0 | S30: 0 | T30: 0 | U30: 0 | V30: 0 | W30: 0 | X30: 0 | Y30: 0 | Z30: 0 | AA30: 0 | AB30: ='Consol PL-DTRG'!C31 -> 0 | AC30: ='Consol PL-DTRG'!D31 -> 0 | AD30: ='Consol PL-DTRG'!E31 -> 0 | AE30: ='Consol PL-DTRG'!F31 -> 0 | AF30: ='Consol PL-DTRG'!G31 -> 0 | AG30: ='Consol PL-DTRG'!H31 -> 0 | AH30: ='Consol PL-DTRG'!I31 -> 0 | AI30: ='Consol PL-DTRG'!J31 -> 0 | ... AM30: ='Consol PL-DTRG'!N31 -> 0
A31: TL-TSCĐ-BN | B31: Bán ngoài | P31: 0 | Q31: 0 | R31: 0 | S31: 0 | T31: 0 | U31: 0 | V31: 0 | W31: 0 | X31: 0 | Y31: 0 | Z31: 0 | AA31: 0 | AB31: ='Consol PL-DTRG'!C32 -> 0 | AC31: ='Consol PL-DTRG'!D32 -> 0 | AD31: ='Consol PL-DTRG'!E32 -> 0 | AE31: ='Consol PL-DTRG'!F32 -> 0 | AF31: ='Consol PL-DTRG'!G32 -> 0 | AG31: ='Consol PL-DTRG'!H32 -> 0 | AH31: ='Consol PL-DTRG'!I32 -> 0 | AI31: ='Consol PL-DTRG'!J32 -> 0 | ... AM31: ='Consol PL-DTRG'!N32 -> 0
A32: TL-TSCĐ-MC | B32: Mẹ-Con | P32: 0 | Q32: 0 | R32: 0 | S32: 0 | T32: 0 | U32: 0 | V32: 0 | W32: 0 | X32: 0 | Y32: 0 | Z32: 0 | AA32: 0 | AB32: ='Consol PL-DTRG'!C33 -> 0 | AC32: ='Consol PL-DTRG'!D33 -> 0 | AD32: ='Consol PL-DTRG'!E33 -> 0 | AE32: ='Consol PL-DTRG'!F33 -> 0 | AF32: ='Consol PL-DTRG'!G33 -> 0 | AG32: ='Consol PL-DTRG'!H33 -> 0 | AH32: ='Consol PL-DTRG'!I33 -> 0 | AI32: ='Consol PL-DTRG'!J33 -> 0 | ... AM32: ='Consol PL-DTRG'!N33 -> 0
A33: TL-TSCĐ-CC | B33: Con-Con | P33: 0 | Q33: 0 | R33: 0 | S33: 0 | T33: 0 | U33: 0 | V33: 0 | W33: 0 | X33: 0 | Y33: 0 | Z33: 0 | AA33: 0 | AB33: ='Consol PL-DTRG'!C34 -> 0 | AC33: ='Consol PL-DTRG'!D34 -> 0 | AD33: ='Consol PL-DTRG'!E34 -> 0 | AE33: ='Consol PL-DTRG'!F34 -> 0 | AF33: ='Consol PL-DTRG'!G34 -> 0 | AG33: ='Consol PL-DTRG'!H34 -> 0 | AH33: ='Consol PL-DTRG'!I34 -> 0 | AI33: ='Consol PL-DTRG'!J34 -> 0 | ... AM33: ='Consol PL-DTRG'!N34 -> 0
A34: 8 | B34: 7.Doanh thu hoạt động tài chính | D34: 712260969 | E34: 1111471110 | F34: 1004651784 | G34: 1746021208 | H34: 1032867505 | I34: 591086157 | J34: 376652862 | K34: 1253018630 | L34: 1560156089 | M34: 2831268643 | N34: 886951972 | O34: 2195155035 | P34: 830662240 | Q34: 1805467216 | R34: 941747687 | S34: 1368536357 | T34: 2440495098 | U34: 1651919997 | V34: 1450067480 | W34: 1506125345 | X34: 1236220214 | Y34: 2769344197 | Z34: 564107321 | AA34: 727547755 | AB34: ='Consol PL-DTRG'!C35 -> 20065548 | AC34: ='Consol PL-DTRG'!D35 -> 20065548 | AD34: ='Consol PL-DTRG'!E35 -> 20065548 | AE34: ='Consol PL-DTRG'!F35 -> 10065548 | AF34: ='Consol PL-DTRG'!G35 -> 10065548 | AG34: ='Consol PL-DTRG'!H35 -> 10065548 | AH34: ='Consol PL-DTRG'!I35 -> 10065548 | AI34: ='Consol PL-DTRG'!J35 -> 10065548 | ... AM34: ='Consol PL-DTRG'!N35 -> 10065548
A35: 9 | B35: 8.Chi phí tài chính | D35: 801399604 | E35: 695500231 | F35: 663502461 | G35: 1555671370 | H35: 936492932 | I35: 1103852896 | J35: 1608708972 | K35: 1489581015 | L35: 1372261307 | M35: 636041020 | N35: 1257673070 | O35: 993026233 | P35: 1529745602 | Q35: 1349010483 | R35: 902730488 | S35: 1450570894 | T35: 858169737 | U35: 1483876982 | V35: 1318435167 | W35: 1366041150 | X35: 1603769193 | Y35: 2900732378 | Z35: 1301741764 | AA35: 2479436989 | AB35: ='Consol PL-DTRG'!C36 -> 1.4407292e+09 | AC35: ='Consol PL-DTRG'!D36 -> 2.3144015e+09 | AD35: ='Consol PL-DTRG'!E36 -> 2.7548451e+09 | AE35: ='Consol PL-DTRG'!F36 -> 2.658974e+09 | AF35: ='Consol PL-DTRG'!G36 -> 2.9845639e+09 | AG35: ='Consol PL-DTRG'!H36 -> 3.0837659e+09 | AH35: ='Consol PL-DTRG'!I36 -> 3.1396192e+09 | AI35: ='Consol PL-DTRG'!J36 -> 3.3215811e+09 | ... AM35: ='Consol PL-DTRG'!N36 -> 3.1023551e+09
A36: 10 | B36: Trong đó: Chi phí lãi vay | D36: 460461775 | E36: 563909516 | F36: 587315920 | G36: 905708142 | H36: 974310029 | I36: 1115056080 | J36: 1160823006 | K36: 939585045 | L36: 859444105 | M36: 840165515 | N36: 889159081 | O36: 1032562923 | P36: 1114824276 | Q36: 928379281 | R36: 673966789 | S36: 888393452 | T36: 1186588729 | U36: 1448899822 | V36: 1245210526 | W36: 1303560910 | X36: 1595764355 | Y36: 1368802426 | Z36: 1256132292 | AA36: 1256103396 | AB36: ='Consol PL-DTRG'!C37 -> 1.4407292e+09 | AC36: ='Consol PL-DTRG'!D37 -> 2.3144015e+09 | AD36: ='Consol PL-DTRG'!E37 -> 2.7548451e+09 | AE36: ='Consol PL-DTRG'!F37 -> 2.658974e+09 | AF36: ='Consol PL-DTRG'!G37 -> 2.9845639e+09 | AG36: ='Consol PL-DTRG'!H37 -> 3.0837659e+09 | AH36: ='Consol PL-DTRG'!I37 -> 3.1396192e+09 | AI36: ='Consol PL-DTRG'!J37 -> 3.3215811e+09 | ... AM36: ='Consol PL-DTRG'!N37 -> 3.1023551e+09
A37: 11 | B37: 9.Chi phí bán hàng | D37: 4849994610 | E37: 1560472559 | F37: 4219375143 | G37: 4926459549 | H37: 2125110954 | I37: 2824966874 | J37: 2596964337 | K37: 8480107205 | L37: 7368729523 | M37: 4936551194 | N37: 2249627546 | O37: 10540748080 | P37: 4181224849 | Q37: 6634982258 | R37: 5629444776 | S37: 4622826734 | T37: 5242336575 | U37: 5451129528 | V37: 4248972349 | W37: 5750995751 | X37: 3513998286 | Y37: 7273403934 | Z37: 3829549635 | AA37: 5362380917 | AB37: ='Consol PL-DTRG'!C38 -> 5.7151198e+09 | AC37: ='Consol PL-DTRG'!D38 -> 4.5328953e+09 | AD37: ='Consol PL-DTRG'!E38 -> 5.3549859e+09 | AE37: ='Consol PL-DTRG'!F38 -> 4.7672285e+09 | AF37: ='Consol PL-DTRG'!G38 -> 6.360624e+09 | AG37: ='Consol PL-DTRG'!H38 -> 5.7198861e+09 | AH37: ='Consol PL-DTRG'!I38 -> 5.09689e+09 | AI37: ='Consol PL-DTRG'!J38 -> 4.9944445e+09 | ... AM37: ='Consol PL-DTRG'!N38 -> 5.5406114e+09
A38: 12 | B38: 10.Chi phí quản lý doanh nghiệp | D38: 5698695249 | E38: 5090845577 | F38: 5285019459 | G38: 5584474639 | H38: 6069340865 | I38: 5881960019 | J38: 5698093117 | K38: 6840474838 | L38: 8084946891 | M38: 8025871294 | N38: 9126335400 | O38: 7087963087 | P38: 8548199037 | Q38: 8928537962 | R38: 8618282018 | S38: 8518246563 | T38: 9277438311 | U38: 9026767632 | V38: 8998978187 | W38: 9320823983 | X38: 10936858648 | Y38: 5273319876 | Z38: 11469860627 | AA38: 17451279792 | AB38: ='Consol PL-DTRG'!C39 -> 1.0275861e+10 | AC38: ='Consol PL-DTRG'!D39 -> 8.7169324e+09 | AD38: ='Consol PL-DTRG'!E39 -> 8.7599047e+09 | AE38: ='Consol PL-DTRG'!F39 -> 8.9181475e+09 | AF38: ='Consol PL-DTRG'!G39 -> 9.0570395e+09 | AG38: ='Consol PL-DTRG'!H39 -> 9.5047244e+09 | AH38: ='Consol PL-DTRG'!I39 -> 9.9320859e+09 | AI38: ='Consol PL-DTRG'!J39 -> 1.030846e+10 | ... AM38: ='Consol PL-DTRG'!N39 -> 1.1367196e+10
A39: 13 | B39: 11.Lợi nhuận thuần từ hoạt động kinh doanh | D39: -665344647 | E39: -6751041323 | F39: -2703219668 | G39: 1671294571 | H39: -5656191968 | I39: -12035614229 | J39: -15241057889 | K39: -10193848065 | L39: 8119731097 | M39: -6174750278 | N39: -7317145513 | O39: 111718028907 | P39: 3054598020 | Q39: 17199268998 | R39: 6977214348 | S39: 3906443232 | T39: 10850283752 | U39: 870990690 | V39: 626449238 | W39: 2789713644 | X39: -12008595386 | Y39: -1907367248 | Z39: -7740922158 | AA39: 7111004785 | AB39: ='Consol PL-DTRG'!C40 -> 8.8109533e+08 | AC39: ='Consol PL-DTRG'!D40 -> -2.4431585e+09 | AD39: ='Consol PL-DTRG'!E40 -> 4.9731962e+09 | AE39: ='Consol PL-DTRG'!F40 -> 2.7132695e+09 | AF39: ='Consol PL-DTRG'!G40 -> 3.9787002e+09 | AG39: ='Consol PL-DTRG'!H40 -> 2.5283443e+09 | AH39: ='Consol PL-DTRG'!I40 -> 9.4367991e+09 | AI39: ='Consol PL-DTRG'!J40 -> 8.8383145e+09 | ... AM39: ='Consol PL-DTRG'!N40 -> 7.3193571e+09
A40: 14 | B40: 12.Thu nhập khác | D40: 1945 | E40: 1109349 | F40: 0 | G40: 81700000 | H40: 4696127 | I40: 64937878 | J40: 54384750 | K40: 184242778 | L40: 5869054 | M40: 3145774 | N40: 1405742798 | O40: 7237102 | P40: 105489733 | Q40: 7492780 | R40: 22177722 | S40: 54899780 | T40: 136977736 | U40: 60909877 | V40: 45395718 | W40: 516819765 | X40: 15045562 | Y40: 25464983 | Z40: 8392356 | AA40: 173856388 | AB40: ='Consol PL-DTRG'!C41 -> 0 | AC40: ='Consol PL-DTRG'!D41 -> 0 | AD40: ='Consol PL-DTRG'!E41 -> 0 | AE40: ='Consol PL-DTRG'!F41 -> 0 | AF40: ='Consol PL-DTRG'!G41 -> 0 | AG40: ='Consol PL-DTRG'!H41 -> 0 | AH40: ='Consol PL-DTRG'!I41 -> 0 | AI40: ='Consol PL-DTRG'!J41 -> 0 | ... AM40: ='Consol PL-DTRG'!N41 -> 0
A41: 15 | B41: 13.Chi phí khác | D41: 54643068 | E41: 9000870 | F41: 40101620 | G41: 84654154 | H41: 40312330 | I41: 171972294 | J41: 7603195 | K41: 4413241 | L41: 7331553 | M41: 177107310 | N41: 140746957 | O41: 8816704270 | P41: 60241342 | Q41: 133833312 | R41: 2500000 | S41: 24808640 | T41: 6500600 | U41: 57323484 | V41: 259624976 | W41: 553180625 | X41: 543708002 | Y41: 3516569246 | Z41: 1108557251 | AA41: 1609092429 | AB41: ='Consol PL-DTRG'!C42 -> 4.33625e+08 | AC41: ='Consol PL-DTRG'!D42 -> 4.33625e+08 | AD41: ='Consol PL-DTRG'!E42 -> 4.33625e+08 | AE41: ='Consol PL-DTRG'!F42 -> 4.33625e+08 | AF41: ='Consol PL-DTRG'!G42 -> 4.33625e+08 | AG41: ='Consol PL-DTRG'!H42 -> 4.33625e+08 | AH41: ='Consol PL-DTRG'!I42 -> 4.33625e+08 | AI41: ='Consol PL-DTRG'!J42 -> 4.33625e+08 | ... AM41: ='Consol PL-DTRG'!N42 -> 4.33625e+08
A42: 16 | B42: 14.Lợi nhuận khác | D42: -54641123 | E42: -7891521 | F42: -40101620 | G42: -2954154 | H42: -35616203 | I42: -107034416 | J42: 46781555 | K42: 179829537 | L42: -1462499 | M42: -173961536 | N42: 1264995841 | O42: -8809467168 | P42: 45248391 | Q42: -126340532 | R42: 19677722 | S42: 30091140 | T42: 130477136 | U42: 3586393 | V42: -214229258 | W42: -36360860 | X42: -528662440 | Y42: -3491104263 | Z42: -1100164895 | AA42: -1435236041 | AB42: ='Consol PL-DTRG'!C43 -> -4.33625e+08 | AC42: ='Consol PL-DTRG'!D43 -> -4.33625e+08 | AD42: ='Consol PL-DTRG'!E43 -> -4.33625e+08 | AE42: ='Consol PL-DTRG'!F43 -> -4.33625e+08 | AF42: ='Consol PL-DTRG'!G43 -> -4.33625e+08 | AG42: ='Consol PL-DTRG'!H43 -> -4.33625e+08 | AH42: ='Consol PL-DTRG'!I43 -> -4.33625e+08 | AI42: ='Consol PL-DTRG'!J43 -> -4.33625e+08 | ... AM42: ='Consol PL-DTRG'!N43 -> -4.33625e+08
...

Sheet BS
A2: Index BS | B2: PHẦN I-BÁO CÁO TÌNH HÌNH TÀI CHÍNH | D2: T01.2024 | E2: T02.2024 | F2: T03.2024 | G2: T04.2024 | H2: T05.2024 | I2: T06.2024 | J2: T07.2024 | K2: T08.2024 | L2: T09.2024 | M2: T10.2024 | N2: T11.2024 | O2: T12.2024 | P2: T01.2025 | Q2: T02.2025 | R2: T03.2025 | S2: T04.2025 | T2: T05.2025 | U2: T06.2025 | V2: T07.2025 | W2: T08.2025 | X2: T09.2025 | Y2: T10.2025 | Z2: T11.2025 | AA2: T12.2025 | AB2: T01.2026 | AC2: T02.2026 | AD2: T03.2026 | AE2: T04.2026 | AF2: T05.2026 | AG2: T06.2026 | AH2: T07.2026 | AI2: T08.2026 | AJ2: T09.2026 | AK2: T10.2026 | AL2: T11.2026 | AM2: T12.2026
A3: 1 | B3: A-TÀI SẢN NGẮN HẠN | D3: =D4+D7+D14+D22+D25+D29 -> 842504987537 | E3: =E4+E7+E14+E22+E25+E29 -> 828028218928 | F3: =F4+F7+F14+F22+F25+F29 -> 8.6664214e+11 | G3: =G4+G7+G14+G22+G25+G29 -> 9.2866377e+11 | H3: =H4+H7+H14+H22+H25+H29 -> 974972463666 | I3: =I4+I7+I14+I22+I25+I29 -> 1000977606992 | J3: =J4+J7+J14+J22+J25+J29 -> 945309048746 | K3: =K4+K7+K14+K22+K25+K29 -> 891517737502 | ... AM3: =AM4+AM7+AM14+AM22+AM25+AM29 -> 1.0277445e+12
A4: 2 | B4: I.Tiền và các khoản tương đương tiền | D4: =SUM(D5:D6) -> 46633249760 | E4: =SUM(E5:E6) -> 35851802774 | F4: =SUM(F5:F6) -> 26393055917 | G4: =SUM(G5:G6) -> 34593153167 | H4: =SUM(H5:H6) -> 33199136312 | I4: =SUM(I5:I6) -> 19638634542 | J4: =SUM(J5:J6) -> 56271006190 | K4: =SUM(K5:K6) -> 35429490170 | ... AM4: =SUM(AM5:AM6) -> 5.6555172e+10
A5: 3 | B5: 1.Tiền | C5: x | D5: ='[1]Tinh hinh tai chinh'!AN6 -> 39793249760 | E5: ='[1]Tinh hinh tai chinh'!AO6 -> 29011802774 | F5: ='[1]Tinh hinh tai chinh'!AP6 -> 21563055917 | G5: ='[1]Tinh hinh tai chinh'!AQ6 -> 25763153167 | H5: ='[1]Tinh hinh tai chinh'!AR6 -> 24369136312 | I5: ='[1]Tinh hinh tai chinh'!AS6 -> 14808634542 | J5: ='[1]Tinh hinh tai chinh'!AT6 -> 48441006190 | K5: ='[1]Tinh hinh tai chinh'!AU6 -> 27599490170 | ... AA5: ='[1]Tinh hinh tai chinh'!BK6 -> 48026156404 | AB5: ='Consol BS-DTRG'!D6 -> 4.5298494e+10 | AC5: ='Consol BS-DTRG'!E6 -> 4.5147824e+10 | AD5: ='Consol BS-DTRG'!F6 -> 4.6898466e+10 | AE5: ='Consol BS-DTRG'!G6 -> 3.8402023e+10 | AF5: ='Consol BS-DTRG'!H6 -> 4.9563717e+10 | AG5: ='Consol BS-DTRG'!I6 -> 4.7974731e+10 | AH5: ='Consol BS-DTRG'!J6 -> 4.8295443e+10 | AI5: ='Consol BS-DTRG'!K6 -> 5.6202871e+10 | ... AM5: ='Consol BS-DTRG'!O6 -> 5.5855172e+10
A6: 4 | B6: 2.Các khoản tương đương tiền | C6: x | D6: ='[1]Tinh hinh tai chinh'!AN7 -> 6840000000 | E6: ='[1]Tinh hinh tai chinh'!AO7 -> 6840000000 | F6: ='[1]Tinh hinh tai chinh'!AP7 -> 4830000000 | G6: ='[1]Tinh hinh tai chinh'!AQ7 -> 8830000000 | H6: ='[1]Tinh hinh tai chinh'!AR7 -> 8830000000 | I6: ='[1]Tinh hinh tai chinh'!AS7 -> 4830000000 | J6: ='[1]Tinh hinh tai chinh'!AT7 -> 7830000000 | K6: ='[1]Tinh hinh tai chinh'!AU7 -> 7830000000 | ... AA6: ='[1]Tinh hinh tai chinh'!BK7 -> 15700000000 | AB6: ='Consol BS-DTRG'!D7 -> 700000000 | AC6: ='Consol BS-DTRG'!E7 -> 700000000 | AD6: ='Consol BS-DTRG'!F7 -> 700000000 | AE6: ='Consol BS-DTRG'!G7 -> 700000000 | AF6: ='Consol BS-DTRG'!H7 -> 700000000 | AG6: ='Consol BS-DTRG'!I7 -> 700000000 | AH6: ='Consol BS-DTRG'!J7 -> 700000000 | AI6: ='Consol BS-DTRG'!K7 -> 700000000 | ... AM6: ='Consol BS-DTRG'!O7 -> 700000000
A7: 5 | B7: II.Đầu tư tài chính ngắn hạn | D7: =SUM(D8:D13) -> 108051581921 | E7: =SUM(E8:E13) -> 108041861921 | F7: =SUM(F8:F13) -> 108032141921 | G7: =SUM(G8:G13) -> 97522421921 | H7: =SUM(H8:H13) -> 97512701921 | I7: =SUM(I8:I13) -> 77502981921 | J7: =SUM(J8:J13) -> 57993261921 | K7: =SUM(K8:K13) -> 57983541921 | ... AM7: =SUM(AM8:AM13) -> 33042000000
A8: 6 | B8: 1.Chứng khoán kinh doanh | C8: x | D8: ='[1]Tinh hinh tai chinh'!AN9 -> 0 | E8: ='[1]Tinh hinh tai chinh'!AO9 -> 0 | F8: ='[1]Tinh hinh tai chinh'!AP9 -> 0 | G8: ='[1]Tinh hinh tai chinh'!AQ9 -> 0 | H8: ='[1]Tinh hinh tai chinh'!AR9 -> 0 | I8: ='[1]Tinh hinh tai chinh'!AS9 -> 0 | J8: ='[1]Tinh hinh tai chinh'!AT9 -> 0 | K8: ='[1]Tinh hinh tai chinh'!AU9 -> 0 | ... AA8: ='[1]Tinh hinh tai chinh'!BK9 -> 0 | AB8: ='Consol BS-DTRG'!D9 -> 0 | AC8: ='Consol BS-DTRG'!E9 -> 0 | AD8: ='Consol BS-DTRG'!F9 -> 0 | AE8: ='Consol BS-DTRG'!G9 -> 0 | AF8: ='Consol BS-DTRG'!H9 -> 0 | AG8: ='Consol BS-DTRG'!I9 -> 0 | AH8: ='Consol BS-DTRG'!J9 -> 0 | AI8: ='Consol BS-DTRG'!K9 -> 0 | ... AM8: ='Consol BS-DTRG'!O9 -> 0
A9: 7 | B9: 2.Dự phòng giảm giá chứng khoán kinh doanh (*) | C9: x | D9: ='[1]Tinh hinh tai chinh'!AN10 -> 0 | E9: ='[1]Tinh hinh tai chinh'!AO10 -> 0 | F9: ='[1]Tinh hinh tai chinh'!AP10 -> 0 | G9: ='[1]Tinh hinh tai chinh'!AQ10 -> 0 | H9: ='[1]Tinh hinh tai chinh'!AR10 -> 0 | I9: ='[1]Tinh hinh tai chinh'!AS10 -> 0 | J9: ='[1]Tinh hinh tai chinh'!AT10 -> 0 | K9: ='[1]Tinh hinh tai chinh'!AU10 -> 0 | ... AA9: ='[1]Tinh hinh tai chinh'!BK10 -> 0 | AB9: ='Consol BS-DTRG'!D10 -> 0 | AC9: ='Consol BS-DTRG'!E10 -> 0 | AD9: ='Consol BS-DTRG'!F10 -> 0 | AE9: ='Consol BS-DTRG'!G10 -> 0 | AF9: ='Consol BS-DTRG'!H10 -> 0 | AG9: ='Consol BS-DTRG'!I10 -> 0 | AH9: ='Consol BS-DTRG'!J10 -> 0 | AI9: ='Consol BS-DTRG'!K10 -> 0 | ... AM9: ='Consol BS-DTRG'!O10 -> 0
A10: 8 | B10: 3.Đầu tư nắm giữ đến ngày đáo hạn ngắn hạn | C10: x | D10: ='[1]Tinh hinh tai chinh'!AN11 -> 108051581921 | E10: ='[1]Tinh hinh tai chinh'!AO11 -> 108041861921 | F10: ='[1]Tinh hinh tai chinh'!AP11 -> 108032141921 | G10: ='[1]Tinh hinh tai chinh'!AQ11 -> 97522421921 | H10: ='[1]Tinh hinh tai chinh'!AR11 -> 97512701921 | I10: ='[1]Tinh hinh tai chinh'!AS11 -> 77502981921 | J10: ='[1]Tinh hinh tai chinh'!AT11 -> 57993261921 | K10: ='[1]Tinh hinh tai chinh'!AU11 -> 57983541921 | ... AA10: ='[1]Tinh hinh tai chinh'!BK11 -> 38542000000 | AB10: ='Consol BS-DTRG'!D11 -> 33042000000 | AC10: ='Consol BS-DTRG'!E11 -> 33042000000 | AD10: ='Consol BS-DTRG'!F11 -> 33042000000 | AE10: ='Consol BS-DTRG'!G11 -> 33042000000 | AF10: ='Consol BS-DTRG'!H11 -> 33042000000 | AG10: ='Consol BS-DTRG'!I11 -> 33042000000 | AH10: ='Consol BS-DTRG'!J11 -> 33042000000 | AI10: ='Consol BS-DTRG'!K11 -> 33042000000 | ... AM10: ='Consol BS-DTRG'!O11 -> 33042000000
A11: 9 | B11: 4.Dự phòng đầu tư nắm giữ đến ngày đáo hạn ngắn hạn (*) | C11: x | D11: ='[1]Tinh hinh tai chinh'!AN12 -> 0 | E11: ='[1]Tinh hinh tai chinh'!AO12 -> 0 | F11: ='[1]Tinh hinh tai chinh'!AP12 -> 0 | G11: ='[1]Tinh hinh tai chinh'!AQ12 -> 0 | H11: ='[1]Tinh hinh tai chinh'!AR12 -> 0 | I11: ='[1]Tinh hinh tai chinh'!AS12 -> 0 | J11: ='[1]Tinh hinh tai chinh'!AT12 -> 0 | K11: ='[1]Tinh hinh tai chinh'!AU12 -> 0 | ... AA11: ='[1]Tinh hinh tai chinh'!BK12 -> 0 | AB11: ='Consol BS-DTRG'!D12 -> 0 | AC11: ='Consol BS-DTRG'!E12 -> 0 | AD11: ='Consol BS-DTRG'!F12 -> 0 | AE11: ='Consol BS-DTRG'!G12 -> 0 | AF11: ='Consol BS-DTRG'!H12 -> 0 | AG11: ='Consol BS-DTRG'!I12 -> 0 | AH11: ='Consol BS-DTRG'!J12 -> 0 | AI11: ='Consol BS-DTRG'!K12 -> 0 | ... AM11: ='Consol BS-DTRG'!O12 -> 0
A12: 10 | B12: 5.Đầu tư ngắn hạn khác | C12: x | D12: ='[1]Tinh hinh tai chinh'!AN13 -> 0 | E12: ='[1]Tinh hinh tai chinh'!AO13 -> 0 | F12: ='[1]Tinh hinh tai chinh'!AP13 -> 0 | G12: ='[1]Tinh hinh tai chinh'!AQ13 -> 0 | H12: ='[1]Tinh hinh tai chinh'!AR13 -> 0 | I12: ='[1]Tinh hinh tai chinh'!AS13 -> 0 | J12: ='[1]Tinh hinh tai chinh'!AT13 -> 0 | K12: ='[1]Tinh hinh tai chinh'!AU13 -> 0 | ... AA12: ='[1]Tinh hinh tai chinh'!BK13 -> 0 | AB12: ='Consol BS-DTRG'!D13 -> 0 | AC12: ='Consol BS-DTRG'!E13 -> 0 | AD12: ='Consol BS-DTRG'!F13 -> 0 | AE12: ='Consol BS-DTRG'!G13 -> 0 | AF12: ='Consol BS-DTRG'!H13 -> 0 | AG12: ='Consol BS-DTRG'!I13 -> 0 | AH12: ='Consol BS-DTRG'!J13 -> 0 | AI12: ='Consol BS-DTRG'!K13 -> 0 | ... AM12: ='Consol BS-DTRG'!O13 -> 0
A13: 11 | B13: 6.Dự phòng tổn thất các khoản đầu tư ngắn hạn khác (*) | C13: x | D13: ='[1]Tinh hinh tai chinh'!AN14 -> 0 | E13: ='[1]Tinh hinh tai chinh'!AO14 -> 0 | F13: ='[1]Tinh hinh tai chinh'!AP14 -> 0 | G13: ='[1]Tinh hinh tai chinh'!AQ14 -> 0 | H13: ='[1]Tinh hinh tai chinh'!AR14 -> 0 | I13: ='[1]Tinh hinh tai chinh'!AS14 -> 0 | J13: ='[1]Tinh hinh tai chinh'!AT14 -> 0 | K13: ='[1]Tinh hinh tai chinh'!AU14 -> 0 | ... AA13: ='[1]Tinh hinh tai chinh'!BK14 -> 0 | AB13: ='Consol BS-DTRG'!D14 -> 0 | AC13: ='Consol BS-DTRG'!E14 -> 0 | AD13: ='Consol BS-DTRG'!F14 -> 0 | AE13: ='Consol BS-DTRG'!G14 -> 0 | AF13: ='Consol BS-DTRG'!H14 -> 0 | AG13: ='Consol BS-DTRG'!I14 -> 0 | AH13: ='Consol BS-DTRG'!J14 -> 0 | AI13: ='Consol BS-DTRG'!K14 -> 0 | ... AM13: ='Consol BS-DTRG'!O14 -> 0
A14: 12 | B14: III.Các khoản phải thu ngắn hạn | D14: =SUM(D15:D21) -> 2.0876077e+11 | E14: =SUM(E15:E21) -> 1.9391456e+11 | F14: =SUM(F15:F21) -> 201044728738 | G14: =SUM(G15:G21) -> 218534804131 | H14: =SUM(H15:H21) -> 2.2155237e+11 | I14: =SUM(I15:I21) -> 2.4767907e+11 | J14: =SUM(J15:J21) -> 1.528212e+11 | K14: =SUM(K15:K21) -> 1.7780637e+11 | ... AM14: =SUM(AM15:AM21) -> 1.8755837e+11
A15: 13 | B15: 1.Phải thu ngắn hạn của khách hàng | C15: x | D15: ='[1]Tinh hinh tai chinh'!AN16 -> 139866573147 | E15: ='[1]Tinh hinh tai chinh'!AO16 -> 145639317187 | F15: ='[1]Tinh hinh tai chinh'!AP16 -> 145029363992 | G15: ='[1]Tinh hinh tai chinh'!AQ16 -> 158990592845 | H15: ='[1]Tinh hinh tai chinh'!AR16 -> 169879811667 | I15: ='[1]Tinh hinh tai chinh'!AS16 -> 169929811366 | J15: ='[1]Tinh hinh tai chinh'!AT16 -> 102331112462 | K15: ='[1]Tinh hinh tai chinh'!AU16 -> 127587662576 | ... AA15: ='[1]Tinh hinh tai chinh'!BK16 -> 154220517132 | AB15: ='Consol BS-DTRG'!D16 -> 1.6476418e+11 | AC15: ='Consol BS-DTRG'!E16 -> 1.7525627e+11 | AD15: ='Consol BS-DTRG'!F16 -> 1.3433941e+11 | AE15: ='Consol BS-DTRG'!G16 -> 1.4061019e+11 | AF15: ='Consol BS-DTRG'!H16 -> 1.4120914e+11 | AG15: ='Consol BS-DTRG'!I16 -> 1.4348903e+11 | AH15: ='Consol BS-DTRG'!J16 -> 1.6390405e+11 | AI15: ='Consol BS-DTRG'!K16 -> 1.5510837e+11 | ... AM15: ='Consol BS-DTRG'!O16 -> 1.4027229e+11
A16: 14 | B16: 2.Trả trước cho người bán ngắn hạn | C16: x | D16: ='[1]Tinh hinh tai chinh'!AN17 -> 19848285706 | E16: ='[1]Tinh hinh tai chinh'!AO17 -> 18001368927 | F16: ='[1]Tinh hinh tai chinh'!AP17 -> 17409185425 | G16: ='[1]Tinh hinh tai chinh'!AQ17 -> 18980934468 | H16: ='[1]Tinh hinh tai chinh'!AR17 -> 18972917626 | I16: ='[1]Tinh hinh tai chinh'!AS17 -> 16946912554 | J16: ='[1]Tinh hinh tai chinh'!AT17 -> 15624304617 | K16: ='[1]Tinh hinh tai chinh'!AU17 -> 15352055458 | ... AA16: ='[1]Tinh hinh tai chinh'!BK17 -> 60848470883 | AB16: ='Consol BS-DTRG'!D17 -> 9.6171404e+10 | AC16: ='Consol BS-DTRG'!E17 -> 1.1335563e+11 | AD16: ='Consol BS-DTRG'!F17 -> 1.1151452e+11 | AE16: ='Consol BS-DTRG'!G17 -> 2.020689e+11 | AF16: ='Consol BS-DTRG'!H17 -> 1.4736612e+11 | AG16: ='Consol BS-DTRG'!I17 -> 1.5010307e+11 | AH16: ='Consol BS-DTRG'!J17 -> 1.4763286e+11 | AI16: ='Consol BS-DTRG'!K17 -> 1.4309779e+11 | ... AM16: ='Consol BS-DTRG'!O17 -> 3.8780793e+09
A17: 15 | B17: 3.Phải thu nội bộ ngắn hạn | C17: x | D17: ='[1]Tinh hinh tai chinh'!AN18 -> 0 | E17: ='[1]Tinh hinh tai chinh'!AO18 -> 0 | F17: ='[1]Tinh hinh tai chinh'!AP18 -> 0 | G17: ='[1]Tinh hinh tai chinh'!AQ18 -> 0 | H17: ='[1]Tinh hinh tai chinh'!AR18 -> 0 | I17: ='[1]Tinh hinh tai chinh'!AS18 -> 0 | J17: ='[1]Tinh hinh tai chinh'!AT18 -> 0 | K17: ='[1]Tinh hinh tai chinh'!AU18 -> 0 | ... AA17: ='[1]Tinh hinh tai chinh'!BK18 -> 0 | AB17: ='Consol BS-DTRG'!D18 -> 0 | AC17: ='Consol BS-DTRG'!E18 -> 0 | AD17: ='Consol BS-DTRG'!F18 -> 0 | AE17: ='Consol BS-DTRG'!G18 -> 0 | AF17: ='Consol BS-DTRG'!H18 -> 0 | AG17: ='Consol BS-DTRG'!I18 -> 0 | AH17: ='Consol BS-DTRG'!J18 -> 0 | AI17: ='Consol BS-DTRG'!K18 -> 0 | ... AM17: ='Consol BS-DTRG'!O18 -> 0
A18: 16 | B18: 4.Phải thu theo tiến độ hợp đồng xây dựng | C18: x | D18: ='[1]Tinh hinh tai chinh'!AN19 -> 0 | E18: ='[1]Tinh hinh tai chinh'!AO19 -> 0 | F18: ='[1]Tinh hinh tai chinh'!AP19 -> 0 | G18: ='[1]Tinh hinh tai chinh'!AQ19 -> 0 | H18: ='[1]Tinh hinh tai chinh'!AR19 -> 0 | I18: ='[1]Tinh hinh tai chinh'!AS19 -> 0 | J18: ='[1]Tinh hinh tai chinh'!AT19 -> 0 | K18: ='[1]Tinh hinh tai chinh'!AU19 -> 0 | ... AA18: ='[1]Tinh hinh tai chinh'!BK19 -> 0 | AB18: ='Consol BS-DTRG'!D19 -> 0 | AC18: ='Consol BS-DTRG'!E19 -> 0 | AD18: ='Consol BS-DTRG'!F19 -> 0 | AE18: ='Consol BS-DTRG'!G19 -> 0 | AF18: ='Consol BS-DTRG'!H19 -> 0 | AG18: ='Consol BS-DTRG'!I19 -> 0 | AH18: ='Consol BS-DTRG'!J19 -> 0 | AI18: ='Consol BS-DTRG'!K19 -> 0 | ... AM18: ='Consol BS-DTRG'!O19 -> 0
A19: 17 | B19: 5.Phải thu ngắn hạn khác | C19: x | D19: ='[1]Tinh hinh tai chinh'!AN20 -> 4.9691048e+10 | E19: ='[1]Tinh hinh tai chinh'!AO20 -> 3.0919005e+10 | F19: ='[1]Tinh hinh tai chinh'!AP20 -> 30825313041 | G19: ='[1]Tinh hinh tai chinh'!AQ20 -> 32782410538 | H19: ='[1]Tinh hinh tai chinh'!AR20 -> 3.334478e+10 | I19: ='[1]Tinh hinh tai chinh'!AS20 -> 6.1447479e+10 | J19: ='[1]Tinh hinh tai chinh'!AT20 -> 3.5510919e+10 | K19: ='[1]Tinh hinh tai chinh'!AU20 -> 3.5511786e+10 | ... AA19: ='[1]Tinh hinh tai chinh'!BK20 -> 96000050435 | AB19: ='Consol BS-DTRG'!D20 -> 86849601458 | AC19: ='Consol BS-DTRG'!E20 -> 40464601458 | AD19: ='Consol BS-DTRG'!F20 -> 40709601458 | AE19: ='Consol BS-DTRG'!G20 -> 42358001458 | AF19: ='Consol BS-DTRG'!H20 -> 42358001458 | AG19: ='Consol BS-DTRG'!I20 -> 42358001458 | AH19: ='Consol BS-DTRG'!J20 -> 43408001458 | AI19: ='Consol BS-DTRG'!K20 -> 43408001458 | ... AM19: ='Consol BS-DTRG'!O20 -> 43408001458
A20: 18 | B20: 6.Dự phòng phải thu ngắn hạn khó đòi (*) | C20: x | D20: ='[1]Tinh hinh tai chinh'!AN21 -> -120525864 | E20: ='[1]Tinh hinh tai chinh'!AO21 -> -120525864 | F20: ='[1]Tinh hinh tai chinh'!AP21 -> -120525864 | G20: ='[1]Tinh hinh tai chinh'!AQ21 -> -120525864 | H20: ='[1]Tinh hinh tai chinh'!AR21 -> -120525864 | I20: ='[1]Tinh hinh tai chinh'!AS21 -> -120525864 | J20: ='[1]Tinh hinh tai chinh'!AT21 -> -120525864 | K20: ='[1]Tinh hinh tai chinh'!AU21 -> -120525864 | ... AA20: ='[1]Tinh hinh tai chinh'!BK21 -> -609095700 | AB20: ='Consol BS-DTRG'!D21 -> 0 | AC20: ='Consol BS-DTRG'!E21 -> 0 | AD20: ='Consol BS-DTRG'!F21 -> 0 | AE20: ='Consol BS-DTRG'!G21 -> 0 | AF20: ='Consol BS-DTRG'!H21 -> 0 | AG20: ='Consol BS-DTRG'!I21 -> 0 | AH20: ='Consol BS-DTRG'!J21 -> 0 | AI20: ='Consol BS-DTRG'!K21 -> 0 | ... AM20: ='Consol BS-DTRG'!O21 -> 0
A21: 19 | B21: 7.Tài sản thiếu chờ xử lý | C21: x | D21: ='[1]Tinh hinh tai chinh'!AN22 -> -524609275 | E21: ='[1]Tinh hinh tai chinh'!AO22 -> -524609275 | F21: ='[1]Tinh hinh tai chinh'!AP22 -> 7901392144 | G21: ='[1]Tinh hinh tai chinh'!AQ22 -> 7901392144 | H21: ='[1]Tinh hinh tai chinh'!AR22 -> -524609275 | I21: ='[1]Tinh hinh tai chinh'!AS22 -> -524609275 | J21: ='[1]Tinh hinh tai chinh'!AT22 -> -524609275 | K21: ='[1]Tinh hinh tai chinh'!AU22 -> -524609275 | ... AA21: ='[1]Tinh hinh tai chinh'!BK22 -> 0 | AB21: ='Consol BS-DTRG'!D22 -> 0 | AC21: ='Consol BS-DTRG'!E22 -> 0 | AD21: ='Consol BS-DTRG'!F22 -> 0 | AE21: ='Consol BS-DTRG'!G22 -> 0 | AF21: ='Consol BS-DTRG'!H22 -> 0 | AG21: ='Consol BS-DTRG'!I22 -> 0 | AH21: ='Consol BS-DTRG'!J22 -> 0 | AI21: ='Consol BS-DTRG'!K22 -> 0 | ... AM21: ='Consol BS-DTRG'!O22 -> 0
A22: 20 | B22: IV. Hàng tồn kho | D22: =SUM(D23:D24) -> 4.3009648e+11 | E22: =SUM(E23:E24) -> 4.3730177e+11 | F22: =SUM(F23:F24) -> 4.7716206e+11 | G22: =SUM(G23:G24) -> 5.176144e+11 | H22: =SUM(H23:H24) -> 5.5763302e+11 | I22: =SUM(I23:I24) -> 6.1374291e+11 | J22: =SUM(J23:J24) -> 6.3087678e+11 | K22: =SUM(K23:K24) -> 5.7103508e+11 | ... AM22: =SUM(AM23:AM24) -> 6.329077e+11
A23: 21 | B23: 1.Hàng tồn kho | C23: x | D23: ='[1]Tinh hinh tai chinh'!AN24 -> 4.3009648e+11 | E23: ='[1]Tinh hinh tai chinh'!AO24 -> 4.3730177e+11 | F23: ='[1]Tinh hinh tai chinh'!AP24 -> 4.7716206e+11 | G23: ='[1]Tinh hinh tai chinh'!AQ24 -> 5.176144e+11 | H23: ='[1]Tinh hinh tai chinh'!AR24 -> 5.5763302e+11 | I23: ='[1]Tinh hinh tai chinh'!AS24 -> 6.1374291e+11 | J23: ='[1]Tinh hinh tai chinh'!AT24 -> 6.3087678e+11 | K23: ='[1]Tinh hinh tai chinh'!AU24 -> 5.7103508e+11 | ... AA23: ='[1]Tinh hinh tai chinh'!BK24 -> 5.7058451e+11 | AB23: ='Consol BS-DTRG'!D24 -> 5.0666529e+11 | AC23: ='Consol BS-DTRG'!E24 -> 5.4392361e+11 | AD23: ='Consol BS-DTRG'!F24 -> 6.2923927e+11 | AE23: ='Consol BS-DTRG'!G24 -> 5.8671665e+11 | AF23: ='Consol BS-DTRG'!H24 -> 6.1406082e+11 | AG23: ='Consol BS-DTRG'!I24 -> 6.3754304e+11 | AH23: ='Consol BS-DTRG'!J24 -> 6.0524777e+11 | AI23: ='Consol BS-DTRG'!K24 -> 6.1158407e+11 | ... AM23: ='Consol BS-DTRG'!O24 -> 6.329077e+11
A24: 22 | B24: 2.Dự phòng giảm giá hàng tồn kho (*) | C24: x | D24: ='[1]Tinh hinh tai chinh'!AN25 -> 0 | E24: ='[1]Tinh hinh tai chinh'!AO25 -> 0 | F24: ='[1]Tinh hinh tai chinh'!AP25 -> 0 | G24: ='[1]Tinh hinh tai chinh'!AQ25 -> 0 | H24: ='[1]Tinh hinh tai chinh'!AR25 -> 0 | I24: ='[1]Tinh hinh tai chinh'!AS25 -> 0 | J24: ='[1]Tinh hinh tai chinh'!AT25 -> 0 | K24: ='[1]Tinh hinh tai chinh'!AU25 -> 0 | ... AA24: ='[1]Tinh hinh tai chinh'!BK25 -> 0 | AB24: ='Consol BS-DTRG'!D25 -> 0 | AC24: ='Consol BS-DTRG'!E25 -> 0 | AD24: ='Consol BS-DTRG'!F25 -> 0 | AE24: ='Consol BS-DTRG'!G25 -> 0 | AF24: ='Consol BS-DTRG'!H25 -> 0 | AG24: ='Consol BS-DTRG'!I25 -> 0 | AH24: ='Consol BS-DTRG'!J25 -> 0 | AI24: ='Consol BS-DTRG'!K25 -> 0 | ... AM24: ='Consol BS-DTRG'!O25 -> 0
A25: 23 | B25: V. Tài sản sinh học ngắn hạn | D25: =SUM(D26:D28) -> 0 | E25: =SUM(E26:E28) -> 0 | F25: =SUM(F26:F28) -> 0 | G25: =SUM(G26:G28) -> 0 | H25: =SUM(H26:H28) -> 0 | I25: =SUM(I26:I28) -> 0 | J25: =SUM(J26:J28) -> 0 | K25: =SUM(K26:K28) -> 0 | ... AM25: =SUM(AM26:AM28) -> 0
A26: 24 | B26: 1.Súc vật nuôi lấy sản phẩm một lần ngắn hạn | C26: x | D26: ='[1]Tinh hinh tai chinh'!AN27 -> 0 | E26: ='[1]Tinh hinh tai chinh'!AO27 -> 0 | F26: ='[1]Tinh hinh tai chinh'!AP27 -> 0 | G26: ='[1]Tinh hinh tai chinh'!AQ27 -> 0 | H26: ='[1]Tinh hinh tai chinh'!AR27 -> 0 | I26: ='[1]Tinh hinh tai chinh'!AS27 -> 0 | J26: ='[1]Tinh hinh tai chinh'!AT27 -> 0 | K26: ='[1]Tinh hinh tai chinh'!AU27 -> 0 | ... AA26: ='[1]Tinh hinh tai chinh'!BK27 -> 0 | AB26: ='Consol BS-DTRG'!D27 -> 0 | AC26: ='Consol BS-DTRG'!E27 -> 0 | AD26: ='Consol BS-DTRG'!F27 -> 0 | AE26: ='Consol BS-DTRG'!G27 -> 0 | AF26: ='Consol BS-DTRG'!H27 -> 0 | AG26: ='Consol BS-DTRG'!I27 -> 0 | AH26: ='Consol BS-DTRG'!J27 -> 0 | AI26: ='Consol BS-DTRG'!K27 -> 0 | ... AM26: ='Consol BS-DTRG'!O27 -> 0
A27: 25 | B27: 2.Cây trồng theo mùa vụ hoặc lấy sản phẩm một lần ngắn hạn | C27: x | D27: ='[1]Tinh hinh tai chinh'!AN28 -> 0 | E27: ='[1]Tinh hinh tai chinh'!AO28 -> 0 | F27: ='[1]Tinh hinh tai chinh'!AP28 -> 0 | G27: ='[1]Tinh hinh tai chinh'!AQ28 -> 0 | H27: ='[1]Tinh hinh tai chinh'!AR28 -> 0 | I27: ='[1]Tinh hinh tai chinh'!AS28 -> 0 | J27: ='[1]Tinh hinh tai chinh'!AT28 -> 0 | K27: ='[1]Tinh hinh tai chinh'!AU28 -> 0 | ... AA27: ='[1]Tinh hinh tai chinh'!BK28 -> 0 | AB27: ='Consol BS-DTRG'!D28 -> 0 | AC27: ='Consol BS-DTRG'!E28 -> 0 | AD27: ='Consol BS-DTRG'!F28 -> 0 | AE27: ='Consol BS-DTRG'!G28 -> 0 | AF27: ='Consol BS-DTRG'!H28 -> 0 | AG27: ='Consol BS-DTRG'!I28 -> 0 | AH27: ='Consol BS-DTRG'!J28 -> 0 | AI27: ='Consol BS-DTRG'!K28 -> 0 | ... AM27: ='Consol BS-DTRG'!O28 -> 0
A28: 26 | B28: 3.Dự phòng tổn thất tài sản sinh học ngắn hạn (*) | C28: x | D28: ='[1]Tinh hinh tai chinh'!AN29 -> 0 | E28: ='[1]Tinh hinh tai chinh'!AO29 -> 0 | F28: ='[1]Tinh hinh tai chinh'!AP29 -> 0 | G28: ='[1]Tinh hinh tai chinh'!AQ29 -> 0 | H28: ='[1]Tinh hinh tai chinh'!AR29 -> 0 | I28: ='[1]Tinh hinh tai chinh'!AS29 -> 0 | J28: ='[1]Tinh hinh tai chinh'!AT29 -> 0 | K28: ='[1]Tinh hinh tai chinh'!AU29 -> 0 | ... AA28: ='[1]Tinh hinh tai chinh'!BK29 -> 0 | AB28: ='Consol BS-DTRG'!D29 -> 0 | AC28: ='Consol BS-DTRG'!E29 -> 0 | AD28: ='Consol BS-DTRG'!F29 -> 0 | AE28: ='Consol BS-DTRG'!G29 -> 0 | AF28: ='Consol BS-DTRG'!H29 -> 0 | AG28: ='Consol BS-DTRG'!I29 -> 0 | AH28: ='Consol BS-DTRG'!J29 -> 0 | AI28: ='Consol BS-DTRG'!K29 -> 0 | ... AM28: ='Consol BS-DTRG'!O29 -> 0
A29: 27 | B29: VI. Tài sản ngắn hạn khác | D29: =SUM(D30:D34) -> 48962900416 | E29: =SUM(E30:E34) -> 52918232539 | F29: =SUM(F30:F34) -> 54010150554 | G29: =SUM(G30:G34) -> 60398986934 | H29: =SUM(H30:H34) -> 65075235400 | I29: =SUM(I30:I34) -> 42414017441 | J29: =SUM(J30:J34) -> 47346796070 | K29: =SUM(K30:K34) -> 49263253112 | ... AM29: =SUM(AM30:AM34) -> 1.1768128e+11
A30: 28 | B30: 1.Chi phí chờ phân bổ ngắn hạn | C30: x | D30: ='[1]Tinh hinh tai chinh'!AN31 -> 7035999486 | E30: ='[1]Tinh hinh tai chinh'!AO31 -> 8848304154 | F30: ='[1]Tinh hinh tai chinh'!AP31 -> 7783371139 | G30: ='[1]Tinh hinh tai chinh'!AQ31 -> 8731138492 | H30: ='[1]Tinh hinh tai chinh'!AR31 -> 8451404044 | I30: ='[1]Tinh hinh tai chinh'!AS31 -> 9556103747 | J30: ='[1]Tinh hinh tai chinh'!AT31 -> 11050173464 | K30: ='[1]Tinh hinh tai chinh'!AU31 -> 11388113648 | ... AA30: ='[1]Tinh hinh tai chinh'!BK31 -> 9528997722 | AB30: ='Consol BS-DTRG'!D31 -> 0 | AC30: ='Consol BS-DTRG'!E31 -> 0 | AD30: ='Consol BS-DTRG'!F31 -> 0 | AE30: ='Consol BS-DTRG'!G31 -> 0 | AF30: ='Consol BS-DTRG'!H31 -> 0 | AG30: ='Consol BS-DTRG'!I31 -> 0 | AH30: ='Consol BS-DTRG'!J31 -> 0 | AI30: ='Consol BS-DTRG'!K31 -> 0 | ... AM30: ='Consol BS-DTRG'!O31 -> 0
A31: 29 | B31: 2.Thuế GTGT được khấu trừ | C31: x | D31: ='[1]Tinh hinh tai chinh'!AN32 -> 41926900930 | E31: ='[1]Tinh hinh tai chinh'!AO32 -> 43981339223 | F31: ='[1]Tinh hinh tai chinh'!AP32 -> 46171681706 | G31: ='[1]Tinh hinh tai chinh'!AQ32 -> 51636650946 | H31: ='[1]Tinh hinh tai chinh'!AR32 -> 56579510013 | I31: ='[1]Tinh hinh tai chinh'!AS32 -> 32789088899 | J31: ='[1]Tinh hinh tai chinh'!AT32 -> 36250538837 | K31: ='[1]Tinh hinh tai chinh'!AU32 -> 37779643794 | ... AA31: ='[1]Tinh hinh tai chinh'!BK32 -> 13603756376 | AB31: ='Consol BS-DTRG'!D32 -> 40327002681 | AC31: ='Consol BS-DTRG'!E32 -> 45327002681 | AD31: ='Consol BS-DTRG'!F32 -> 50327002681 | AE31: ='Consol BS-DTRG'!G32 -> 55327002681 | AF31: ='Consol BS-DTRG'!H32 -> 60327002681 | AG31: ='Consol BS-DTRG'!I32 -> 65327002681 | AH31: ='Consol BS-DTRG'!J32 -> 7.0327003e+10 | AI31: ='Consol BS-DTRG'!K32 -> 7.5327003e+10 | ... AM31: ='Consol BS-DTRG'!O32 -> 9.5327003e+10
