Workbook
Name \A: #REF!
Name \M: #REF!
Name ___ATS98: #REF!
Name ___BGT02: #REF!
Name ___CHF98: #REF!
Name ___CHX2002: #REF!
Name ___CHX2003: #REF!
Name ___CHX2004: #REF!
Name ___CHX2005: #REF!
Name ___DTB2003: #REF!
Name ___DTB2004: #REF!
Name ___LY01: #REF!
Name ___Mkt1: #REF!
Name ___VAR1: #REF!
Name ___VAR2: #REF!
Name ___var22: #REF!
Name ___VAR3: #REF!
Name ___VAR4: #REF!
Name ___VAR5: #REF!
Name ___VAR6: #REF!
Name ___VAR7: #REF!
Name __ATS98: #REF!
Name __BGT02: #REF!
Name __CHF98: #REF!
Name __CHX2002: #REF!
Name __CHX2003: #REF!
Name __CHX2004: #REF!
Name __CHX2005: #REF!
Name __DAT1: #REF!
Name __DAT10: #REF!
Name __DAT11: #REF!
Name __DAT12: #REF!
Name __DAT13: #REF!
Name __DAT14: #REF!
Name __DAT15: #REF!
Name __DAT16: #REF!
Name __DAT17: #REF!
Name __DAT18: #REF!
Name __DAT19: #REF!
Name __DAT2: #REF!
Name __DAT20: #REF!
Name __DAT21: #REF!
Name __DAT22: #REF!
Name __DAT23: #REF!
Name __DAT24: #REF!
Name __DAT25: #REF!
Name __DAT26: #REF!
Name __DAT27: #REF!
Name __DAT28: #REF!
Name __DAT29: #REF!
Name __DAT3: #REF!
Name __DAT30: #REF!
Name __DAT31: #REF!
Name __DAT32: #REF!
Name __DAT33: #REF!
Name __DAT34: #REF!
Name __DAT35: #REF!
Name __DAT36: #REF!
Name __DAT37: #REF!
Name __DAT38: #REF!

Sheet Trình bày 2026
B1: DANH MỤC THÀNH PHẨM
E3: Tháng 1 | L3: Tháng 2 | S3: Tháng 3 | Z3: Tháng 4
A4: STT | B4: Mã SAP | C4: Tên hàng hóa | D4: Màu | E4: Giá duyệt T12 (USD/ tấn) | F4: Giá bán đề nghị T1 (USD/ tấn) | G4: CL T12 sv T1 (USD/ tấn) | H4: Giá vốn | I4: Lợi nhuận trước thuế | J4: % lợi nhuận sau thuế | K4: Giá đề nghị của kinh doanh | L4: Giá duyệt T1 (USD/ tấn) | M4: Giá bán đề nghị T1 (USD/ tấn) | N4: CL T12 sv T1 (USD/ tấn) | O4: Giá vốn | P4: Lợi nhuận trước thuế | Q4: % lợi nhuận sau thuế | R4: Giá đề nghị của kinh doanh | S4: Giá duyệt T12 (USD/ tấn) | T4: Giá bán đề nghị T1 (USD/ tấn) | U4: CL T12 sv T1 (USD/ tấn) | V4: Giá vốn | W4: Lợi nhuận trước thuế | X4: % lợi nhuận sau thuế | Y4: Giá đề nghị của kinh doanh | Z4: Giá duyệt T12 (USD/ tấn) | AA4: Giá bán đề nghị T1 (USD/ tấn) | AB4: CL T12 sv T1 (USD/ tấn) | AC4: Giá vốn | AD4: Lợi nhuận trước thuế | AE4: % lợi nhuận sau thuế | AF4: Giá đề nghị của kinh doanh
A5: A | B5: rPET
A6: I | B6: MÃ HÀNG ĐANG BÁN
A7: 1 | B7: 110000354 | C7: Hạt nhựa rPET WSS01G 1 | E7: =VLOOKUP($B7,'Trình bày T1'!$B:$M,6,0) -> 1200 | F7: =VLOOKUP($B7,'Trình bày T1'!$B:$M,7,0) -> 1200 | G7: =F7-E7 -> 0 | H7: =VLOOKUP($B9,'Trình bày T1'!$B:$M,9,0) -> 1157.9867 | I7: =(F7-H7) -> 42.013296 | J7: =+I7/F7 -> 0.03501108 | K7: =VLOOKUP($B12,'Trình bày T1'!$B:$M,12,0) -> 1440 | L7: =VLOOKUP($B7,'Trình bày T2'!$B:$M,6,0) -> 1160 | M7: =VLOOKUP($B7,'Trình bày T2'!$B:$M,7,0) -> 1160 | N7: =M7-L7 -> 0 | O7: =VLOOKUP($B9,'Trình bày T2'!$B:$M,9,0) -> 1111 | P7: =(M7-O7) -> 49 | Q7: =+P7/M7 -> 0.042241379 | R7: =VLOOKUP($B12,'Trình bày T2'!$B:$M,12,0) -> 0 | S7: =VLOOKUP($B7,'Trình bày T3'!$B:$M,6,0) -> 1160 | T7: =VLOOKUP($B7,'Trình bày T3'!$B:$M,7,0) -> 1160 | U7: =T7-S7 -> 0 | V7: =VLOOKUP($B9,'Trình bày T3'!$B:$M,9,0) -> 1113.7705 | W7: =(T7-V7) -> 46.229474 | X7: =+W7/T7 -> 0.039852995 | Y7: =VLOOKUP($B12,'Trình bày T3'!$B:$M,12,0) -> #N/A | Z7: =VLOOKUP($B7,'Trình bày T4'!$B:$M,6,0) -> 1160 | AA7: =VLOOKUP($B7,'Trình bày T4'!$B:$M,7,0) -> 1280 | AB7: =AA7-Z7 -> 120 | AC7: =VLOOKUP($B9,'Trình bày T4'!$B:$M,9,0) -> 1136 | AD7: =(AA7-AC7) -> 144 | AE7: =+AD7/AA7 -> 0.1125 | AF7: =VLOOKUP($B12,'Trình bày T4'!$B:$M,12,0) -> 0
A8: =+A7+1 -> 2 | B8: 110000355 | C8: Hạt nhựa rPET iSS01G 1 | E8: =VLOOKUP($B8,'Trình bày T1'!$B:$M,6,0) -> 1230 | F8: =VLOOKUP($B8,'Trình bày T1'!$B:$M,7,0) -> 1230 | G8: =F8-E8 -> 0 | H8: =VLOOKUP($B8,'Trình bày T1'!$B:$M,9,0) -> 1096.8837 | I8: =(F8-H8) -> 133.11632 | J8: =+I8/F8 -> 0.10822465 | K8: =VLOOKUP($B8,'Trình bày T1'!$B:$M,12,0) -> 1210 | L8: =VLOOKUP($B8,'Trình bày T2'!$B:$M,6,0) -> 1190 | M8: =VLOOKUP($B8,'Trình bày T2'!$B:$M,7,0) -> 1190 | N8: =M8-L8 -> 0 | O8: =VLOOKUP($B8,'Trình bày T2'!$B:$M,9,0) -> 1056 | P8: =(M8-O8) -> 134 | Q8: =+P8/M8 -> 0.11260504 | R8: =VLOOKUP($B8,'Trình bày T2'!$B:$M,12,0) -> 0 | S8: =VLOOKUP($B8,'Trình bày T3'!$B:$M,6,0) -> 1190 | T8: =VLOOKUP($B8,'Trình bày T3'!$B:$M,7,0) -> 1190 | U8: =T8-S8 -> 0 | V8: =VLOOKUP($B8,'Trình bày T3'!$B:$M,9,0) -> 1057.7957 | W8: =(T8-V8) -> 132.20427 | X8: =+W8/T8 -> 0.11109603 | Y8: =VLOOKUP($B8,'Trình bày T3'!$B:$M,12,0) -> 0 | Z8: =VLOOKUP($B8,'Trình bày T4'!$B:$M,6,0) -> 1190 | AA8: =VLOOKUP($B8,'Trình bày T4'!$B:$M,7,0) -> 1310 | AB8: =AA8-Z8 -> 120 | AC8: =VLOOKUP($B8,'Trình bày T4'!$B:$M,9,0) -> 1078 | AD8: =(AA8-AC8) -> 232 | AE8: =+AD8/AA8 -> 0.17709924 | AF8: =VLOOKUP($B8,'Trình bày T4'!$B:$M,12,0) -> 0
A9: =+A8+1 -> 3 | B9: 110000332 | C9: Hạt nhựa rPET iSS01084G | E9: =VLOOKUP($B9,'Trình bày T1'!$B:$M,6,0) -> 1290 | F9: =VLOOKUP($B9,'Trình bày T1'!$B:$M,7,0) -> 1290 | G9: =F9-E9 -> 0 | H9: =VLOOKUP($B9,'Trình bày T1'!$B:$M,9,0) -> 1157.9867 | I9: =(F9-H9) -> 132.0133 | J9: =+I9/F9 -> 0.10233589 | K9: =VLOOKUP($B12,'Trình bày T1'!$B:$M,12,0) -> 1440 | L9: =VLOOKUP($B9,'Trình bày T2'!$B:$M,6,0) -> 1250 | M9: =VLOOKUP($B9,'Trình bày T2'!$B:$M,7,0) -> 1250 | N9: =M9-L9 -> 0 | O9: =VLOOKUP($B9,'Trình bày T2'!$B:$M,9,0) -> 1111 | P9: =(M9-O9) -> 139 | Q9: =+P9/M9 -> 0.1112 | R9: =VLOOKUP($B12,'Trình bày T2'!$B:$M,12,0) -> 0 | S9: =VLOOKUP($B9,'Trình bày T3'!$B:$M,6,0) -> 1250 | T9: =VLOOKUP($B9,'Trình bày T3'!$B:$M,7,0) -> 1250 | U9: =T9-S9 -> 0 | V9: =VLOOKUP($B9,'Trình bày T3'!$B:$M,9,0) -> 1113.7705 | W9: =(T9-V9) -> 136.22947 | X9: =+W9/T9 -> 0.10898358 | Y9: =VLOOKUP($B12,'Trình bày T3'!$B:$M,12,0) -> #N/A | Z9: =VLOOKUP($B9,'Trình bày T4'!$B:$M,6,0) -> 1250 | AA9: =VLOOKUP($B9,'Trình bày T4'!$B:$M,7,0) -> 1370 | AB9: =AA9-Z9 -> 120 | AC9: =VLOOKUP($B9,'Trình bày T4'!$B:$M,9,0) -> 1136 | AD9: =(AA9-AC9) -> 234 | AE9: =+AD9/AA9 -> 0.17080292 | AF9: =VLOOKUP($B12,'Trình bày T4'!$B:$M,12,0) -> 0
A10: =+A9+1 -> 4 | B10: 110000359 | C10: Hạt nhựa rPET WSS03G | E10: =VLOOKUP($B10,'Trình bày T1'!$B:$M,6,0) -> 1130 | F10: =VLOOKUP($B10,'Trình bày T1'!$B:$M,7,0) -> 1130 | G10: =F10-E10 -> 0 | H10: =VLOOKUP($B10,'Trình bày T1'!$B:$M,9,0) -> 1096.8837 | I10: =(F10-H10) -> 33.116321 | J10: =+I10/F10 -> 0.029306478 | K10: =VLOOKUP($B10,'Trình bày T1'!$B:$M,12,0) -> 1110 | L10: =VLOOKUP($B10,'Trình bày T2'!$B:$M,6,0) -> 1090 | M10: =VLOOKUP($B10,'Trình bày T2'!$B:$M,7,0) -> 1090 | N10: =M10-L10 -> 0 | O10: =VLOOKUP($B10,'Trình bày T2'!$B:$M,9,0) -> 1056 | P10: =(M10-O10) -> 34 | Q10: =+P10/M10 -> 0.031192661 | R10: =VLOOKUP($B10,'Trình bày T2'!$B:$M,12,0) -> 0 | S10: =VLOOKUP($B10,'Trình bày T3'!$B:$M,6,0) -> 1090 | T10: =VLOOKUP($B10,'Trình bày T3'!$B:$M,7,0) -> 1090 | U10: =T30-S10 -> -320 | V10: =VLOOKUP($B10,'Trình bày T3'!$B:$M,9,0) -> 1057.7957 | W10: =(T30-V10) -> -287.79573 | X10: =+W10/T30 -> -0.37376068 | Y10: =VLOOKUP($B10,'Trình bày T3'!$B:$M,12,0) -> 0 | Z10: =VLOOKUP($B10,'Trình bày T4'!$B:$M,6,0) -> 1090 | AA10: =VLOOKUP($B10,'Trình bày T4'!$B:$M,7,0) -> 1210 | AB10: =AA10-Z10 -> 120 | AC10: =VLOOKUP($B10,'Trình bày T4'!$B:$M,9,0) -> 1078 | AD10: =(AA10-AC10) -> 132 | AE10: =+AD10/AA10 -> 0.10909091 | AF10: =VLOOKUP($B10,'Trình bày T4'!$B:$M,12,0) -> 0
A11: =+A10+1 -> 5 | B11: 110000329 | C11: Hạt nhựa rPET WSS01 | E11: =VLOOKUP($B11,'Trình bày T1'!$B:$M,6,0) -> 1320 | F11: =VLOOKUP($B11,'Trình bày T1'!$B:$M,7,0) -> 1320 | G11: =F11-E11 -> 0 | H11: =VLOOKUP($B11,'Trình bày T1'!$B:$M,9,0) -> 1182.4815 | I11: =(F11-H11) -> 137.51854 | J11: =+I11/F11 -> 0.10418072 | K11: =VLOOKUP($B11,'Trình bày T1'!$B:$M,12,0) -> 1320 | L11: =VLOOKUP($B11,'Trình bày T2'!$B:$M,6,0) -> 1320 | M11: =VLOOKUP($B11,'Trình bày T2'!$B:$M,7,0) -> 1320 | N11: =M11-L11 -> 0 | O11: =VLOOKUP($B11,'Trình bày T2'!$B:$M,9,0) -> 1154 | P11: =(M11-O11) -> 166 | Q11: =+P11/M11 -> 0.12575758 | R11: =VLOOKUP($B11,'Trình bày T2'!$B:$M,12,0) -> 0 | S11: =VLOOKUP($B11,'Trình bày T3'!$B:$M,6,0) -> 1320 | T11: =VLOOKUP($B11,'Trình bày T3'!$B:$M,7,0) -> 1320 | U11: =T31-S11 -> -600 | V11: =VLOOKUP($B11,'Trình bày T3'!$B:$M,9,0) -> 1155.3596 | W11: =(T31-V11) -> -435.35965 | X11: =+W11/T31 -> -0.60466618 | Y11: =VLOOKUP($B11,'Trình bày T3'!$B:$M,12,0) -> 0 | Z11: =VLOOKUP($B11,'Trình bày T4'!$B:$M,6,0) -> 1290 | AA11: =VLOOKUP($B11,'Trình bày T4'!$B:$M,7,0) -> 1290 | AB11: =AA11-Z11 -> 0 | AC11: =VLOOKUP($B11,'Trình bày T4'!$B:$M,9,0) -> 1169 | AD11: =(AA11-AC11) -> 121 | AE11: =+AD11/AA11 -> 0.09379845 | AF11: =VLOOKUP($B11,'Trình bày T4'!$B:$M,12,0) -> 0
A12: =+A11+1 -> 6 | B12: 110000497 | C12: Hạt Nhựa rPET WSS01G-L | E12: =VLOOKUP($B12,'Trình bày T1'!$B:$M,6,0) -> 1440 | F12: =VLOOKUP($B12,'Trình bày T1'!$B:$M,7,0) -> 1440 | G12: =F12-E12 -> 0 | H12: =VLOOKUP($B12,'Trình bày T1'!$B:$M,9,0) -> 1235.0716 | I12: =(F12-H12) -> 204.92844 | J12: =+I12/F12 -> 0.14231141 | K12: =VLOOKUP($B12,'Trình bày T1'!$B:$M,12,0) -> 1440 | L12: =VLOOKUP($B12,'Trình bày T2'!$B:$M,6,0) -> 1440 | M12: =VLOOKUP($B12,'Trình bày T2'!$B:$M,7,0) -> 1440 | N12: =M12-L12 -> 0 | O12: =VLOOKUP($B12,'Trình bày T2'!$B:$M,9,0) -> 1201 | P12: =(M12-O12) -> 239 | Q12: =+P12/M12 -> 0.16597222 | R12: =VLOOKUP($B12,'Trình bày T2'!$B:$M,12,0) -> 0 | S12: =VLOOKUP($B12,'Trình bày T3'!$B:$M,6,0) -> #N/A | T12: =VLOOKUP($B12,'Trình bày T3'!$B:$M,7,0) -> #N/A | U12: =T32-S12 -> #N/A | V12: =VLOOKUP($B12,'Trình bày T3'!$B:$M,9,0) -> #N/A | W12: =(T32-V12) -> #N/A | X12: =+W12/T32 -> #N/A | Y12: =VLOOKUP($B12,'Trình bày T3'!$B:$M,12,0) -> #N/A | Z12: =VLOOKUP($B12,'Trình bày T4'!$B:$M,6,0) -> 0 | AA12: =VLOOKUP($B12,'Trình bày T4'!$B:$M,7,0) -> 0 | AB12: =AA12-Z12 -> 0 | AC12: =VLOOKUP($B12,'Trình bày T4'!$B:$M,9,0) -> 0 | AD12: =(AA12-AC12) -> 0 | AE12: =+AD12/AA12 -> #DIV/0! | AF12: =VLOOKUP($B12,'Trình bày T4'!$B:$M,12,0) -> 0
A13: =+A12+1 -> 7 | B13: 110000499 | C13: Hạt Nhựa rPET WSS01L | E13: =VLOOKUP($B13,'Trình bày T1'!$B:$M,6,0) -> 1200 | F13: =VLOOKUP($B13,'Trình bày T1'!$B:$M,7,0) -> 1200 | G13: =F13-E13 -> 0 | H13: =VLOOKUP($B13,'Trình bày T1'!$B:$M,9,0) -> 1015.2046 | I13: =(F13-H13) -> 184.79538 | J13: =+I13/F13 -> 0.15399615 | K13: =VLOOKUP($B13,'Trình bày T1'!$B:$M,12,0) -> 1180 | L13: =VLOOKUP($B13,'Trình bày T2'!$B:$M,6,0) -> 1160 | M13: =VLOOKUP($B13,'Trình bày T2'!$B:$M,7,0) -> 1160 | N13: =M13-L13 -> 0 | O13: =VLOOKUP($B13,'Trình bày T2'!$B:$M,9,0) -> 998 | P13: =(M13-O13) -> 162 | Q13: =+P13/M13 -> 0.13965517 | R13: =VLOOKUP($B13,'Trình bày T2'!$B:$M,12,0) -> 0 | S13: =VLOOKUP($B13,'Trình bày T3'!$B:$M,6,0) -> 1160 | T13: =VLOOKUP($B13,'Trình bày T3'!$B:$M,7,0) -> 1160 | U13: =T33-S13 -> -1160 | V13: =VLOOKUP($B13,'Trình bày T3'!$B:$M,9,0) -> 1006.566 | W13: =(T33-V13) -> -1006.566 | X13: =+W13/T33 -> #DIV/0! | Y13: =VLOOKUP($B13,'Trình bày T3'!$B:$M,12,0) -> 0 | Z13: =VLOOKUP($B13,'Trình bày T4'!$B:$M,6,0) -> 1160 | AA13: =VLOOKUP($B13,'Trình bày T4'!$B:$M,7,0) -> 1280 | AB13: =AA13-Z13 -> 120 | AC13: =VLOOKUP($B13,'Trình bày T4'!$B:$M,9,0) -> 1026 | AD13: =(AA13-AC13) -> 254 | AE13: =+AD13/AA13 -> 0.1984375 | AF13: =VLOOKUP($B13,'Trình bày T4'!$B:$M,12,0) -> 0
A14: =+A13+1 -> 8 | B14: 110000503 | C14: Hạt Nhựa rPET WSS01S | E14: =VLOOKUP($B14,'Trình bày T1'!$B:$M,6,0) -> 1200 | F14: =VLOOKUP($B14,'Trình bày T1'!$B:$M,7,0) -> 1200 | G14: =F14-E14 -> 0 | H14: =VLOOKUP($B14,'Trình bày T1'!$B:$M,9,0) -> 1025.9231 | I14: =(F14-H14) -> 174.07692 | J14: =+I14/F14 -> 0.1450641 | K14: =VLOOKUP($B14,'Trình bày T1'!$B:$M,12,0) -> 1180 | L14: =VLOOKUP($B14,'Trình bày T2'!$B:$M,6,0) -> 1160 | M14: =VLOOKUP($B14,'Trình bày T2'!$B:$M,7,0) -> 1160 | N14: =M14-L14 -> 0 | O14: =VLOOKUP($B14,'Trình bày T2'!$B:$M,9,0) -> 0 | P14: =(M14-O14) -> 1160 | Q14: =+P14/M14 -> 1 | R14: =VLOOKUP($B14,'Trình bày T2'!$B:$M,12,0) -> 0 | S14: =VLOOKUP($B14,'Trình bày T3'!$B:$M,6,0) -> #N/A | T14: =VLOOKUP($B14,'Trình bày T3'!$B:$M,7,0) -> #N/A | U14: =T34-S14 -> #N/A | V14: =VLOOKUP($B14,'Trình bày T3'!$B:$M,9,0) -> #N/A | W14: =(T34-V14) -> #N/A | X14: =+W14/T34 -> #N/A | Y14: =VLOOKUP($B14,'Trình bày T3'!$B:$M,12,0) -> #N/A | Z14: =VLOOKUP($B14,'Trình bày T4'!$B:$M,6,0) -> 0 | AA14: =VLOOKUP($B14,'Trình bày T4'!$B:$M,7,0) -> 0 | AB14: =AA14-Z14 -> 0 | AC14: =VLOOKUP($B14,'Trình bày T4'!$B:$M,9,0) -> 0 | AD14: =(AA14-AC14) -> 0 | AE14: =+AD14/AA14 -> #DIV/0! | AF14: =VLOOKUP($B14,'Trình bày T4'!$B:$M,12,0) -> 0
A15: =+A14+1 -> 9 | B15: 110000506 | C15: Hạt Nhựa rPET WSS01 & WSS01G-L | E15: =VLOOKUP($B15,'Trình bày T1'!$B:$M,6,0) -> 1410 | F15: =VLOOKUP($B15,'Trình bày T1'!$B:$M,7,0) -> 1410 | G15: =F15-E15 -> 0 | H15: =VLOOKUP($B15,'Trình bày T1'!$B:$M,9,0) -> 1208.7765 | I15: =(F15-H15) -> 201.22349 | J15: =+I15/F15 -> 0.1427117 | K15: =VLOOKUP($B15,'Trình bày T1'!$B:$M,12,0) -> 1410 | L15: =VLOOKUP($B15,'Trình bày T2'!$B:$M,6,0) -> 1410 | M15: =VLOOKUP($B15,'Trình bày T2'!$B:$M,7,0) -> 1410 | N15: =M15-L15 -> 0 | O15: =VLOOKUP($B15,'Trình bày T2'!$B:$M,9,0) -> 1222.6415 | P15: =(M15-O15) -> 187.35849 | Q15: =+P15/M15 -> 0.13287836 | R15: =VLOOKUP($B15,'Trình bày T2'!$B:$M,12,0) -> 0 | S15: =VLOOKUP($B15,'Trình bày T3'!$B:$M,6,0) -> 1410 | T15: =VLOOKUP($B15,'Trình bày T3'!$B:$M,7,0) -> 690 | U15: =T35-S15 -> -380 | V15: =VLOOKUP($B15,'Trình bày T3'!$B:$M,9,0) -> 1222.6415 | W15: =(T35-V15) -> -192.64151 | X15: =+W15/T35 -> -0.18703059 | Y15: =VLOOKUP($B15,'Trình bày T3'!$B:$M,12,0) -> 0 | Z15: =VLOOKUP($B15,'Trình bày T4'!$B:$M,6,0) -> 0 | AA15: =VLOOKUP($B15,'Trình bày T4'!$B:$M,7,0) -> 0 | AB15: =AA15-Z15 -> 0 | AC15: =VLOOKUP($B15,'Trình bày T4'!$B:$M,9,0) -> 1222.6415 | AD15: =(AA15-AC15) -> -1222.6415 | AE15: =+AD15/AA15 -> #DIV/0! | AF15: =VLOOKUP($B15,'Trình bày T4'!$B:$M,12,0) -> 0
A16: =+A15+1 -> 10 | B16: 110000483 | C16: Hạt Nhựa rPET iSS01G-S | E16: =VLOOKUP($B16,'Trình bày T1'!$B:$M,6,0) -> 1230 | F16: =VLOOKUP($B17,'Trình bày T1'!$B:$M,7,0) -> 0 | G16: =F16-E16 -> -1230 | H16: =VLOOKUP($B19,'Trình bày T1'!$B:$M,9,0) -> 1096.8837 | I16: =(F16-H16) -> -1096.8837 | J16: =+I16/F16 -> #DIV/0! | K16: =VLOOKUP($B112,'Trình bày T1'!$B:$M,12,0) -> 600 | L16: =VLOOKUP($B16,'Trình bày T2'!$B:$M,6,0) -> 1190 | M16: =VLOOKUP($B17,'Trình bày T2'!$B:$M,7,0) -> 0 | N16: =M16-L16 -> -1190 | O16: =VLOOKUP($B19,'Trình bày T2'!$B:$M,9,0) -> 1056 | P16: =(M16-O16) -> -1056 | Q16: =+P16/M16 -> #DIV/0! | R16: =VLOOKUP($B112,'Trình bày T2'!$B:$M,12,0) -> 0 | S16: =VLOOKUP($B16,'Trình bày T3'!$B:$M,6,0) -> 1190 | T16: =VLOOKUP($B17,'Trình bày T3'!$B:$M,7,0) -> 0 | U16: =T36-S16 -> -1190 | V16: =VLOOKUP($B19,'Trình bày T3'!$B:$M,9,0) -> 1057.7957 | W16: =(T36-V16) -> -1057.7957 | X16: =+W16/T36 -> #DIV/0! | Y16: =VLOOKUP($B112,'Trình bày T3'!$B:$M,12,0) -> 0 | Z16: =VLOOKUP($B16,'Trình bày T4'!$B:$M,6,0) -> 1190 | AA16: =VLOOKUP($B17,'Trình bày T4'!$B:$M,7,0) -> 0 | AB16: =AA16-Z16 -> -1190 | AC16: =VLOOKUP($B19,'Trình bày T4'!$B:$M,9,0) -> 1078 | AD16: =(AA16-AC16) -> -1078 | AE16: =+AD16/AA16 -> #DIV/0! | AF16: =VLOOKUP($B112,'Trình bày T4'!$B:$M,12,0) -> 0
A17: II | B17: MÃ HÀNG BÁN CHẬM
A18: 1 | B18: 110000378 | C18: Hạt nhựa rPET iSS01G 2 | E18: =VLOOKUP($B18,'Trình bày T1'!$B:$M,6,0) -> 1230 | F18: =VLOOKUP($B18,'Trình bày T1'!$B:$M,7,0) -> 1230 | G18: =F18-E18 -> 0 | H18: =VLOOKUP($B18,'Trình bày T1'!$B:$M,9,0) -> 1096.8837 | I18: =(F18-H18) -> 133.11632 | J18: =+I18/F18 -> 0.10822465 | K18: =VLOOKUP($B18,'Trình bày T1'!$B:$M,12,0) -> 1210 | L18: =VLOOKUP($B18,'Trình bày T2'!$B:$M,6,0) -> 1190 | M18: =VLOOKUP($B18,'Trình bày T2'!$B:$M,7,0) -> 1190 | N18: =M18-L18 -> 0 | O18: =VLOOKUP($B18,'Trình bày T2'!$B:$M,9,0) -> 1056 | P18: =(M18-O18) -> 134 | Q18: =+P18/M18 -> 0.11260504 | R18: =VLOOKUP($B18,'Trình bày T2'!$B:$M,12,0) -> 0 | S18: =VLOOKUP($B18,'Trình bày T3'!$B:$M,6,0) -> 1190 | T18: =VLOOKUP($B18,'Trình bày T3'!$B:$M,7,0) -> 1190 | U18: =T38-S18 -> -1190 | V18: =VLOOKUP($B18,'Trình bày T3'!$B:$M,9,0) -> 1057.7957 | W18: =(T38-V18) -> -1057.7957 | X18: =+W18/T38 -> #DIV/0! | Y18: =VLOOKUP($B18,'Trình bày T3'!$B:$M,12,0) -> 0 | Z18: =VLOOKUP($B18,'Trình bày T4'!$B:$M,6,0) -> 1190 | AA18: =VLOOKUP($B18,'Trình bày T4'!$B:$M,7,0) -> 1310 | AB18: =AA18-Z18 -> 120 | AC18: =VLOOKUP($B18,'Trình bày T4'!$B:$M,9,0) -> 1078 | AD18: =(AA18-AC18) -> 232 | AE18: =+AD18/AA18 -> 0.17709924 | AF18: =VLOOKUP($B18,'Trình bày T4'!$B:$M,12,0) -> 0
A19: =+A18+1 -> 2 | B19: 110000377 | C19: Hạt nhựa rPET WSS01G 2 | E19: =VLOOKUP($B19,'Trình bày T1'!$B:$M,6,0) -> 1200 | F19: =VLOOKUP($B19,'Trình bày T1'!$B:$M,7,0) -> 1200 | G19: =F19-E19 -> 0 | H19: =VLOOKUP($B19,'Trình bày T1'!$B:$M,9,0) -> 1096.8837 | I19: =(F19-H19) -> 103.11632 | J19: =+I19/F19 -> 0.085930267 | K19: =VLOOKUP($B112,'Trình bày T1'!$B:$M,12,0) -> 600 | L19: =VLOOKUP($B19,'Trình bày T2'!$B:$M,6,0) -> 1160 | M19: =VLOOKUP($B19,'Trình bày T2'!$B:$M,7,0) -> 1160 | N19: =M19-L19 -> 0 | O19: =VLOOKUP($B19,'Trình bày T2'!$B:$M,9,0) -> 1056 | P19: =(M19-O19) -> 104 | Q19: =+P19/M19 -> 0.089655172 | R19: =VLOOKUP($B112,'Trình bày T2'!$B:$M,12,0) -> 0 | S19: =VLOOKUP($B19,'Trình bày T3'!$B:$M,6,0) -> 1160 | T19: =VLOOKUP($B19,'Trình bày T3'!$B:$M,7,0) -> 1160 | U19: =T39-S19 -> -1160 | V19: =VLOOKUP($B19,'Trình bày T3'!$B:$M,9,0) -> 1057.7957 | W19: =(T39-V19) -> -1057.7957 | X19: =+W19/T39 -> #DIV/0! | Y19: =VLOOKUP($B112,'Trình bày T3'!$B:$M,12,0) -> 0 | Z19: =VLOOKUP($B19,'Trình bày T4'!$B:$M,6,0) -> 1160 | AA19: =VLOOKUP($B19,'Trình bày T4'!$B:$M,7,0) -> 1280 | AB19: =AA19-Z19 -> 120 | AC19: =VLOOKUP($B19,'Trình bày T4'!$B:$M,9,0) -> 1078 | AD19: =(AA19-AC19) -> 202 | AE19: =+AD19/AA19 -> 0.1578125 | AF19: =VLOOKUP($B112,'Trình bày T4'!$B:$M,12,0) -> 0
A20: =+A19+1 -> 3 | B20: 110000383 | C20: Hạt Nhựa rPET iSS84G-P | E20: =VLOOKUP($B20,'Trình bày T1'!$B:$M,6,0) -> 0 | F20: =VLOOKUP($B20,'Trình bày T1'!$B:$M,7,0) -> 0 | G20: =F20-E20 -> 0 | H20: =VLOOKUP($B20,'Trình bày T1'!$B:$M,9,0) -> 1130.6154 | K20: =VLOOKUP($B20,'Trình bày T1'!$B:$M,12,0) -> 0 | L20: =VLOOKUP($B20,'Trình bày T2'!$B:$M,6,0) -> 0 | M20: =VLOOKUP($B20,'Trình bày T2'!$B:$M,7,0) -> 0 | N20: =M20-L20 -> 0 | O20: =VLOOKUP($B20,'Trình bày T2'!$B:$M,9,0) -> 1109.283 | R20: =VLOOKUP($B20,'Trình bày T2'!$B:$M,12,0) -> 0 | S20: =VLOOKUP($B20,'Trình bày T3'!$B:$M,6,0) -> 0 | T20: =VLOOKUP($B20,'Trình bày T3'!$B:$M,7,0) -> 0 | U20: =T20-S20 -> 0 | V20: =VLOOKUP($B20,'Trình bày T3'!$B:$M,9,0) -> 1109.283 | Y20: =VLOOKUP($B20,'Trình bày T3'!$B:$M,12,0) -> 0 | Z20: =VLOOKUP($B20,'Trình bày T4'!$B:$M,6,0) -> 0 | AA20: =VLOOKUP($B20,'Trình bày T4'!$B:$M,7,0) -> 0 | AB20: =AA20-Z20 -> 0 | AC20: =VLOOKUP($B20,'Trình bày T4'!$B:$M,9,0) -> 1109.283 | AF20: =VLOOKUP($B20,'Trình bày T4'!$B:$M,12,0) -> 0
A21: =+A20+1 -> 4 | B21: 110000335 | C21: Hạt nhựa rPET WSS04 | E21: =VLOOKUP($B21,'Trình bày T1'!$B:$M,6,0) -> 0 | F21: =VLOOKUP($B21,'Trình bày T1'!$B:$M,7,0) -> 0 | G21: =F21-E21 -> 0 | H21: =VLOOKUP($B21,'Trình bày T1'!$B:$M,9,0) -> 1045.1154 | K21: =VLOOKUP($B21,'Trình bày T1'!$B:$M,12,0) -> 0 | L21: =VLOOKUP($B21,'Trình bày T2'!$B:$M,6,0) -> 0 | M21: =VLOOKUP($B21,'Trình bày T2'!$B:$M,7,0) -> 0 | N21: =M21-L21 -> 0 | O21: =VLOOKUP($B21,'Trình bày T2'!$B:$M,9,0) -> 0 | R21: =VLOOKUP($B21,'Trình bày T2'!$B:$M,12,0) -> 0 | S21: =VLOOKUP($B21,'Trình bày T3'!$B:$M,6,0) -> #N/A | T21: =VLOOKUP($B21,'Trình bày T3'!$B:$M,7,0) -> #N/A | U21: =T21-S21 -> #N/A | V21: =VLOOKUP($B21,'Trình bày T3'!$B:$M,9,0) -> #N/A | Y21: =VLOOKUP($B21,'Trình bày T3'!$B:$M,12,0) -> #N/A | Z21: =VLOOKUP($B21,'Trình bày T4'!$B:$M,6,0) -> 0 | AA21: =VLOOKUP($B21,'Trình bày T4'!$B:$M,7,0) -> 0 | AB21: =AA21-Z21 -> 0 | AC21: =VLOOKUP($B21,'Trình bày T4'!$B:$M,9,0) -> 0 | AF21: =VLOOKUP($B21,'Trình bày T4'!$B:$M,12,0) -> 0
A22: =+A21+1 -> 5 | B22: 110000358 | C22: Hạt nhựa rPET WSS02G | E22: =VLOOKUP($B22,'Trình bày T1'!$B:$M,6,0) -> 0 | F22: =VLOOKUP($B22,'Trình bày T1'!$B:$M,7,0) -> 0 | G22: =F22-E22 -> 0 | H22: =VLOOKUP($B22,'Trình bày T1'!$B:$M,9,0) -> 0 | K22: =VLOOKUP($B22,'Trình bày T1'!$B:$M,12,0) -> 0 | L22: =VLOOKUP($B22,'Trình bày T2'!$B:$M,6,0) -> 0 | M22: =VLOOKUP($B22,'Trình bày T2'!$B:$M,7,0) -> 0 | N22: =M22-L22 -> 0 | O22: =VLOOKUP($B22,'Trình bày T2'!$B:$M,9,0) -> 0 | R22: =VLOOKUP($B22,'Trình bày T2'!$B:$M,12,0) -> 0 | S22: =VLOOKUP($B22,'Trình bày T3'!$B:$M,6,0) -> #N/A | T22: =VLOOKUP($B22,'Trình bày T3'!$B:$M,7,0) -> #N/A | U22: =T22-S22 -> #N/A | V22: =VLOOKUP($B22,'Trình bày T3'!$B:$M,9,0) -> #N/A | Y22: =VLOOKUP($B22,'Trình bày T3'!$B:$M,12,0) -> #N/A | Z22: =VLOOKUP($B22,'Trình bày T4'!$B:$M,6,0) -> 0 | AA22: =VLOOKUP($B22,'Trình bày T4'!$B:$M,7,0) -> 0 | AB22: =AA22-Z22 -> 0 | AC22: =VLOOKUP($B22,'Trình bày T4'!$B:$M,9,0) -> 0 | AF22: =VLOOKUP($B22,'Trình bày T4'!$B:$M,12,0) -> 0
A23: =+A22+1 -> 6 | B23: 110000468 | C23: Hạt Nhựa rPET iSS80G-P | E23: =VLOOKUP($B23,'Trình bày T1'!$B:$M,6,0) -> 0 | F23: =VLOOKUP($B23,'Trình bày T1'!$B:$M,7,0) -> 0 | G23: =F23-E23 -> 0 | H23: =VLOOKUP($B23,'Trình bày T1'!$B:$M,9,0) -> 1056.2692 | K23: =VLOOKUP($B23,'Trình bày T1'!$B:$M,12,0) -> 0 | L23: =VLOOKUP($B23,'Trình bày T2'!$B:$M,6,0) -> 0 | M23: =VLOOKUP($B23,'Trình bày T2'!$B:$M,7,0) -> 0 | N23: =M23-L23 -> 0 | O23: =VLOOKUP($B23,'Trình bày T2'!$B:$M,9,0) -> 1036.3396 | R23: =VLOOKUP($B23,'Trình bày T2'!$B:$M,12,0) -> 0 | S23: =VLOOKUP($B23,'Trình bày T3'!$B:$M,6,0) -> 0 | T23: =VLOOKUP($B23,'Trình bày T3'!$B:$M,7,0) -> 0 | U23: =T23-S23 -> 0 | V23: =VLOOKUP($B23,'Trình bày T3'!$B:$M,9,0) -> 1042.1887 | Y23: =VLOOKUP($B23,'Trình bày T3'!$B:$M,12,0) -> 0 | Z23: =VLOOKUP($B23,'Trình bày T4'!$B:$M,6,0) -> 0 | AA23: =VLOOKUP($B23,'Trình bày T4'!$B:$M,7,0) -> 0 | AB23: =AA23-Z23 -> 0 | AC23: =VLOOKUP($B23,'Trình bày T4'!$B:$M,9,0) -> 1042.1887 | AF23: =VLOOKUP($B23,'Trình bày T4'!$B:$M,12,0) -> 0
A24: =+A23+1 -> 7 | B24: 110000333 | C24: Hạt nhựa rPET WSS03 | E24: =VLOOKUP($B24,'Trình bày T1'!$B:$M,6,0) -> 0 | F24: =VLOOKUP($B24,'Trình bày T1'!$B:$M,7,0) -> 0 | G24: =F24-E24 -> 0 | H24: =VLOOKUP($B24,'Trình bày T1'!$B:$M,9,0) -> 937.65385 | K24: =VLOOKUP($B24,'Trình bày T1'!$B:$M,12,0) -> 0 | L24: =VLOOKUP($B24,'Trình bày T2'!$B:$M,6,0) -> 0 | M24: =VLOOKUP($B24,'Trình bày T2'!$B:$M,7,0) -> 0 | N24: =M24-L24 -> 0 | O24: =VLOOKUP($B24,'Trình bày T2'!$B:$M,9,0) -> 0 | R24: =VLOOKUP($B24,'Trình bày T2'!$B:$M,12,0) -> 0 | S24: =VLOOKUP($B24,'Trình bày T3'!$B:$M,6,0) -> #N/A | T24: =VLOOKUP($B24,'Trình bày T3'!$B:$M,7,0) -> #N/A | U24: =T24-S24 -> #N/A | V24: =VLOOKUP($B24,'Trình bày T3'!$B:$M,9,0) -> #N/A | Y24: =VLOOKUP($B24,'Trình bày T3'!$B:$M,12,0) -> #N/A | Z24: =VLOOKUP($B24,'Trình bày T4'!$B:$M,6,0) -> 0 | AA24: =VLOOKUP($B24,'Trình bày T4'!$B:$M,7,0) -> 0 | AB24: =AA24-Z24 -> 0 | AC24: =VLOOKUP($B24,'Trình bày T4'!$B:$M,9,0) -> 0 | AF24: =VLOOKUP($B24,'Trình bày T4'!$B:$M,12,0) -> 0
A25: =+A24+1 -> 8 | B25: 110000376 | C25: Hạt nhựa rPET iSS01L | E25: =VLOOKUP($B25,'Trình bày T1'!$B:$M,6,0) -> 0 | F25: =VLOOKUP($B25,'Trình bày T1'!$B:$M,7,0) -> 0 | G25: =F25-E25 -> 0 | H25: =VLOOKUP($B25,'Trình bày T1'!$B:$M,9,0) -> 1198.8846 | K25: =VLOOKUP($B25,'Trình bày T1'!$B:$M,12,0) -> 0 | L25: =VLOOKUP($B25,'Trình bày T2'!$B:$M,6,0) -> 0 | M25: =VLOOKUP($B25,'Trình bày T2'!$B:$M,7,0) -> 0 | N25: =M25-L25 -> 0 | O25: =VLOOKUP($B25,'Trình bày T2'!$B:$M,9,0) -> 1176.2642 | R25: =VLOOKUP($B25,'Trình bày T2'!$B:$M,12,0) -> 0 | S25: =VLOOKUP($B25,'Trình bày T3'!$B:$M,6,0) -> 0 | T25: =VLOOKUP($B25,'Trình bày T3'!$B:$M,7,0) -> 0 | U25: =T25-S25 -> 0 | V25: =VLOOKUP($B25,'Trình bày T3'!$B:$M,9,0) -> 1176.2642 | Y25: =VLOOKUP($B25,'Trình bày T3'!$B:$M,12,0) -> 0 | Z25: =VLOOKUP($B25,'Trình bày T4'!$B:$M,6,0) -> 0 | AA25: =VLOOKUP($B25,'Trình bày T4'!$B:$M,7,0) -> 0 | AB25: =AA25-Z25 -> 0 | AC25: =VLOOKUP($B25,'Trình bày T4'!$B:$M,9,0) -> 1176.2642 | AF25: =VLOOKUP($B25,'Trình bày T4'!$B:$M,12,0) -> 0
A26: =+A25+1 -> 9 | B26: 110000331 | C26: Hạt nhựa rPET WSS02 | E26: =VLOOKUP($B26,'Trình bày T1'!$B:$M,6,0) -> 0 | F26: =VLOOKUP($B27,'Trình bày T1'!$B:$M,7,0) -> 0 | G26: =F26-E26 -> 0 | H26: =VLOOKUP($B29,'Trình bày T1'!$B:$M,9,0) -> 0 | K26: =VLOOKUP($B212,'Trình bày T1'!$B:$M,12,0) -> #N/A | L26: =VLOOKUP($B26,'Trình bày T2'!$B:$M,6,0) -> 0 | M26: =VLOOKUP($B27,'Trình bày T2'!$B:$M,7,0) -> 0 | N26: =M26-L26 -> 0 | O26: =VLOOKUP($B29,'Trình bày T2'!$B:$M,9,0) -> 0 | R26: =VLOOKUP($B212,'Trình bày T2'!$B:$M,12,0) -> #N/A | S26: =VLOOKUP($B26,'Trình bày T3'!$B:$M,6,0) -> #N/A | T26: =VLOOKUP($B27,'Trình bày T3'!$B:$M,7,0) -> #N/A | U26: =T26-S26 -> #N/A | V26: =VLOOKUP($B29,'Trình bày T3'!$B:$M,9,0) -> 0 | Y26: =VLOOKUP($B212,'Trình bày T3'!$B:$M,12,0) -> #N/A | Z26: =VLOOKUP($B26,'Trình bày T4'!$B:$M,6,0) -> 0 | AA26: =VLOOKUP($B27,'Trình bày T4'!$B:$M,7,0) -> 0 | AB26: =AA26-Z26 -> 0 | AC26: =VLOOKUP($B29,'Trình bày T4'!$B:$M,9,0) -> 0 | AF26: =VLOOKUP($B212,'Trình bày T4'!$B:$M,12,0) -> #N/A
A27: =+A26+1 -> 10 | B27: 110000330 | C27: Hạt nhựa rPET iSS01 | E27: =VLOOKUP($B27,'Trình bày T1'!$B:$M,6,0) -> 0 | F27: =VLOOKUP($B27,'Trình bày T1'!$B:$M,7,0) -> 0 | G27: =F27-E27 -> 0 | H27: =VLOOKUP($B29,'Trình bày T1'!$B:$M,9,0) -> 0 | K27: =VLOOKUP($B212,'Trình bày T1'!$B:$M,12,0) -> #N/A | L27: =VLOOKUP($B27,'Trình bày T2'!$B:$M,6,0) -> 0 | M27: =VLOOKUP($B27,'Trình bày T2'!$B:$M,7,0) -> 0 | N27: =M27-L27 -> 0 | O27: =VLOOKUP($B29,'Trình bày T2'!$B:$M,9,0) -> 0 | R27: =VLOOKUP($B212,'Trình bày T2'!$B:$M,12,0) -> #N/A | S27: =VLOOKUP($B27,'Trình bày T3'!$B:$M,6,0) -> #N/A | T27: =VLOOKUP($B27,'Trình bày T3'!$B:$M,7,0) -> #N/A | U27: =T27-S27 -> #N/A | V27: =VLOOKUP($B29,'Trình bày T3'!$B:$M,9,0) -> 0 | Y27: =VLOOKUP($B212,'Trình bày T3'!$B:$M,12,0) -> #N/A | Z27: =VLOOKUP($B27,'Trình bày T4'!$B:$M,6,0) -> 0 | AA27: =VLOOKUP($B27,'Trình bày T4'!$B:$M,7,0) -> 0 | AB27: =AA27-Z27 -> 0 | AC27: =VLOOKUP($B29,'Trình bày T4'!$B:$M,9,0) -> 0 | AF27: =VLOOKUP($B212,'Trình bày T4'!$B:$M,12,0) -> #N/A
A28: =+A27+1 -> 11 | B28: 110000475 | C28: Hạt nhựa rPET WSS03G FRH | E28: =VLOOKUP($B28,'Trình bày T1'!$B:$M,6,0) -> 0 | F28: =VLOOKUP($B28,'Trình bày T1'!$B:$M,7,0) -> 0 | G28: =F28-E28 -> 0 | H28: =VLOOKUP($B28,'Trình bày T1'!$B:$M,9,0) -> 0 | K28: =VLOOKUP($B28,'Trình bày T1'!$B:$M,12,0) -> 0 | L28: =VLOOKUP($B28,'Trình bày T2'!$B:$M,6,0) -> 0 | M28: =VLOOKUP($B28,'Trình bày T2'!$B:$M,7,0) -> 0 | N28: =M28-L28 -> 0 | O28: =VLOOKUP($B28,'Trình bày T2'!$B:$M,9,0) -> 0 | R28: =VLOOKUP($B28,'Trình bày T2'!$B:$M,12,0) -> 0 | S28: =VLOOKUP($B28,'Trình bày T3'!$B:$M,6,0) -> #N/A | T28: =VLOOKUP($B28,'Trình bày T3'!$B:$M,7,0) -> #N/A | U28: =T28-S28 -> #N/A | V28: =VLOOKUP($B28,'Trình bày T3'!$B:$M,9,0) -> #N/A | Y28: =VLOOKUP($B28,'Trình bày T3'!$B:$M,12,0) -> #N/A | Z28: =VLOOKUP($B28,'Trình bày T4'!$B:$M,6,0) -> 0 | AA28: =VLOOKUP($B28,'Trình bày T4'!$B:$M,7,0) -> 0 | AB28: =AA28-Z28 -> 0 | AC28: =VLOOKUP($B28,'Trình bày T4'!$B:$M,9,0) -> 0 | AF28: =VLOOKUP($B28,'Trình bày T4'!$B:$M,12,0) -> 0
A29: III | B29: MÃ HÀNG SẢN XUẤT TỪ PHÓ SẢN NGÀNH PET
A30: 1 | B30: 110000466 | C30: Hạt Nhựa rPET WSS05SB-2 | E30: =VLOOKUP($B30,'Trình bày T1'!$B:$M,6,0) -> 810 | F30: =VLOOKUP($B30,'Trình bày T1'!$B:$M,7,0) -> 810 | G30: =F30-E30 -> 0 | H30: =VLOOKUP($B30,'Trình bày T1'!$B:$M,9,0) -> 931.34534 | I30: =(F30-H30) -> -121.34534 | J30: =+I30/F30 -> -0.14980906 | K30: =VLOOKUP($B30,'Trình bày T1'!$B:$M,12,0) -> 800 | L30: =VLOOKUP($B30,'Trình bày T2'!$B:$M,6,0) -> 770 | M30: =VLOOKUP($B30,'Trình bày T2'!$B:$M,7,0) -> 770 | N30: =M30-L30 -> 0 | O30: =VLOOKUP($B30,'Trình bày T2'!$B:$M,9,0) -> 921 | P30: =(M30-O30) -> -151 | Q30: =+P30/M30 -> -0.1961039 | R30: =VLOOKUP($B30,'Trình bày T2'!$B:$M,12,0) -> 0 | S30: =VLOOKUP($B30,'Trình bày T3'!$B:$M,6,0) -> 770 | T30: =VLOOKUP($B30,'Trình bày T3'!$B:$M,7,0) -> 770 | U30: =T30-S30 -> 0 | V30: =VLOOKUP($B30,'Trình bày T3'!$B:$M,9,0) -> 853 | W30: =(T30-V30) -> -83 | X30: =+W30/T30 -> -0.10779221 | Y30: =VLOOKUP($B30,'Trình bày T3'!$B:$M,12,0) -> 0 | Z30: =VLOOKUP($B30,'Trình bày T4'!$B:$M,6,0) -> 770 | AA30: =VLOOKUP($B30,'Trình bày T4'!$B:$M,7,0) -> 0 | AB30: =AA30-Z30 -> -770 | AC30: =VLOOKUP($B30,'Trình bày T4'!$B:$M,9,0) -> 858 | AD30: =(AA30-AC30) -> -858 | AE30: =+AD30/AA30 -> #DIV/0! | AF30: =VLOOKUP($B30,'Trình bày T4'!$B:$M,12,0) -> 0
A31: =A30+1 -> 2 | B31: 110000436 | C31: Hạt nhựa rPET WSS05SB | E31: =VLOOKUP($B31,'Trình bày T1'!$B:$M,6,0) -> 760 | F31: =VLOOKUP($B31,'Trình bày T1'!$B:$M,7,0) -> 760 | G31: =F31-E31 -> 0 | H31: =VLOOKUP($B31,'Trình bày T1'!$B:$M,9,0) -> 957.10022 | I31: =(F31-H31) -> -197.10022 | J31: =+I31/F31 -> -0.25934239 | K31: =VLOOKUP($B31,'Trình bày T1'!$B:$M,12,0) -> 750 | L31: =VLOOKUP($B31,'Trình bày T2'!$B:$M,6,0) -> 720 | M31: =VLOOKUP($B31,'Trình bày T2'!$B:$M,7,0) -> 720 | N31: =M31-L31 -> 0 | O31: =VLOOKUP($B31,'Trình bày T2'!$B:$M,9,0) -> 949 | P31: =(M31-O31) -> -229 | Q31: =+P31/M31 -> -0.31805556 | R31: =VLOOKUP($B31,'Trình bày T2'!$B:$M,12,0) -> 0 | S31: =VLOOKUP($B31,'Trình bày T3'!$B:$M,6,0) -> 720 | T31: =VLOOKUP($B31,'Trình bày T3'!$B:$M,7,0) -> 720 | U31: =T31-S31 -> 0 | V31: =VLOOKUP($B31,'Trình bày T3'!$B:$M,9,0) -> 880 | W31: =(T31-V31) -> -160 | X31: =+W31/T31 -> -0.22222222 | Y31: =VLOOKUP($B31,'Trình bày T3'!$B:$M,12,0) -> 0 | Z31: =VLOOKUP($B31,'Trình bày T4'!$B:$M,6,0) -> 720 | AA31: =VLOOKUP($B31,'Trình bày T4'!$B:$M,7,0) -> 0 | AB31: =AA31-Z31 -> -720 | AC31: =VLOOKUP($B31,'Trình bày T4'!$B:$M,9,0) -> 884 | AD31: =(AA31-AC31) -> -884 | AE31: =+AD31/AA31 -> #DIV/0! | AF31: =VLOOKUP($B31,'Trình bày T4'!$B:$M,12,0) -> 0
A32: 2 | B32: 110000382 | C32: Hạt nhựa rPET WSS04SB | E32: =VLOOKUP($B32,'Trình bày T1'!$B:$M,6,0) -> 1070 | F32: =VLOOKUP($B32,'Trình bày T1'!$B:$M,7,0) -> 1070 | G32: =F32-E32 -> 0 | H32: =VLOOKUP($B32,'Trình bày T1'!$B:$M,9,0) -> 582.96769 | I32: =(F32-H32) -> 487.03231 | J32: =+I32/F32 -> 0.45517038 | K32: =VLOOKUP($B32,'Trình bày T1'!$B:$M,12,0) -> 0 | L32: =VLOOKUP($B32,'Trình bày T2'!$B:$M,6,0) -> 1030 | M32: =VLOOKUP($B32,'Trình bày T2'!$B:$M,7,0) -> 1030 | N32: =M32-L32 -> 0 | O32: =VLOOKUP($B32,'Trình bày T2'!$B:$M,9,0) -> 559 | P32: =(M32-O32) -> 471 | Q32: =+P32/M32 -> 0.45728155 | R32: =VLOOKUP($B32,'Trình bày T2'!$B:$M,12,0) -> 0 | S32: =VLOOKUP($B32,'Trình bày T3'!$B:$M,6,0) -> 1030 | T32: =VLOOKUP($B32,'Trình bày T3'!$B:$M,7,0) -> 1030 | U32: =T32-S32 -> 0 | V32: =VLOOKUP($B32,'Trình bày T3'!$B:$M,9,0) -> 517 | W32: =(T32-V32) -> 513 | X32: =+W32/T32 -> 0.49805825 | Y32: =VLOOKUP($B32,'Trình bày T3'!$B:$M,12,0) -> 0 | Z32: =VLOOKUP($B32,'Trình bày T4'!$B:$M,6,0) -> 1030 | AA32: =VLOOKUP($B32,'Trình bày T4'!$B:$M,7,0) -> 1150 | AB32: =AA32-Z32 -> 120 | AC32: =VLOOKUP($B32,'Trình bày T4'!$B:$M,9,0) -> 521 | AD32: =(AA32-AC32) -> 629 | AE32: =+AD32/AA32 -> 0.54695652 | AF32: =VLOOKUP($B32,'Trình bày T4'!$B:$M,12,0) -> 0
A33: =A32+1 -> 3 | B33: 110000384 | C33: Hạt Nhựa Xơ Sợi Thử Nghiệm | E33: =VLOOKUP($B33,'Trình bày T1'!$B:$M,6,0) -> 0 | F33: =VLOOKUP($B33,'Trình bày T1'!$B:$M,7,0) -> 0 | G33: =F33-E33 -> 0 | H33: =VLOOKUP($B33,'Trình bày T1'!$B:$M,9,0) -> 0 | K33: =VLOOKUP($B33,'Trình bày T1'!$B:$M,12,0) -> 0 | L33: =VLOOKUP($B33,'Trình bày T2'!$B:$M,6,0) -> 0 | M33: =VLOOKUP($B33,'Trình bày T2'!$B:$M,7,0) -> 0 | N33: =M33-L33 -> 0 | O33: =VLOOKUP($B33,'Trình bày T2'!$B:$M,9,0) -> 0 | R33: =VLOOKUP($B33,'Trình bày T2'!$B:$M,12,0) -> 0 | S33: =VLOOKUP($B33,'Trình bày T3'!$B:$M,6,0) -> 0 | T33: =VLOOKUP($B33,'Trình bày T3'!$B:$M,7,0) -> 0 | U33: =T33-S33 -> 0 | V33: =VLOOKUP($B33,'Trình bày T3'!$B:$M,9,0) -> 0 | Y33: =VLOOKUP($B33,'Trình bày T3'!$B:$M,12,0) -> 0 | Z33: =VLOOKUP($B33,'Trình bày T4'!$B:$M,6,0) -> 0 | AA33: =VLOOKUP($B33,'Trình bày T4'!$B:$M,7,0) -> 0 | AB33: =AA33-Z33 -> 0 | AC33: =VLOOKUP($B33,'Trình bày T4'!$B:$M,9,0) -> 0 | AF33: =VLOOKUP($B33,'Trình bày T4'!$B:$M,12,0) -> 0
A34: 3 | B34: 110000381 | C34: Hạt nhựa rPET WSS04SD | E34: =VLOOKUP($B34,'Trình bày T1'!$B:$M,6,0) -> 1070 | F34: =VLOOKUP($B34,'Trình bày T1'!$B:$M,7,0) -> 1070 | G34: =F34-E34 -> 0 | H34: =VLOOKUP($B34,'Trình bày T1'!$B:$M,9,0) -> 646.08292 | I34: =(F34-H34) -> 423.91708 | J34: =+I34/F34 -> 0.39618418 | K34: =VLOOKUP($B34,'Trình bày T1'!$B:$M,12,0) -> 0 | L34: =VLOOKUP($B34,'Trình bày T2'!$B:$M,6,0) -> 1030 | M34: =VLOOKUP($B34,'Trình bày T2'!$B:$M,7,0) -> 1030 | N34: =M34-L34 -> 0 | O34: =VLOOKUP($B34,'Trình bày T2'!$B:$M,9,0) -> 621 | P34: =(M34-O34) -> 409 | Q34: =+P34/M34 -> 0.39708738 | R34: =VLOOKUP($B34,'Trình bày T2'!$B:$M,12,0) -> 0 | S34: =VLOOKUP($B34,'Trình bày T3'!$B:$M,6,0) -> 1030 | T34: =VLOOKUP($B34,'Trình bày T3'!$B:$M,7,0) -> 1030 | U34: =T34-S34 -> 0 | V34: =VLOOKUP($B34,'Trình bày T3'!$B:$M,9,0) -> 579 | W34: =(T34-V34) -> 451 | X34: =+W34/T34 -> 0.43786408 | Y34: =VLOOKUP($B34,'Trình bày T3'!$B:$M,12,0) -> 0 | Z34: =VLOOKUP($B34,'Trình bày T4'!$B:$M,6,0) -> 1030 | AA34: =VLOOKUP($B34,'Trình bày T4'!$B:$M,7,0) -> 1150 | AB34: =AA34-Z34 -> 120 | AC34: =VLOOKUP($B34,'Trình bày T4'!$B:$M,9,0) -> 592 | AD34: =(AA34-AC34) -> 558 | AE34: =+AD34/AA34 -> 0.48521739 | AF34: =VLOOKUP($B34,'Trình bày T4'!$B:$M,12,0) -> 0
A35: =A34+1 -> 4 | B35: 110000387 | C35: Hạt nhựa rPET WSS03SD | E35: =VLOOKUP($B35,'Trình bày T1'!$B:$M,6,0) -> 1070 | F35: =VLOOKUP($B35,'Trình bày T1'!$B:$M,7,0) -> 1070 | G35: =F35-E35 -> 0 | H35: =VLOOKUP($B35,'Trình bày T1'!$B:$M,9,0) -> 736.55619 | I35: =(F35-H35) -> 333.44381 | J35: =+I35/F35 -> 0.31162973 | K35: =VLOOKUP($B35,'Trình bày T1'!$B:$M,12,0) -> 0 | L35: =VLOOKUP($B35,'Trình bày T2'!$B:$M,6,0) -> 1030 | M35: =VLOOKUP($B35,'Trình bày T2'!$B:$M,7,0) -> 1030 | N35: =M35-L35 -> 0 | O35: =VLOOKUP($B35,'Trình bày T2'!$B:$M,9,0) -> 710 | P35: =(M35-O35) -> 320 | Q35: =+P35/M35 -> 0.31067961 | R35: =VLOOKUP($B35,'Trình bày T2'!$B:$M,12,0) -> 0 | S35: =VLOOKUP($B35,'Trình bày T3'!$B:$M,6,0) -> 1030 | T35: =VLOOKUP($B35,'Trình bày T3'!$B:$M,7,0) -> 1030 | U35: =T35-S35 -> 0 | V35: =VLOOKUP($B35,'Trình bày T3'!$B:$M,9,0) -> 668 | W35: =(T35-V35) -> 362 | X35: =+W35/T35 -> 0.35145631 | Y35: =VLOOKUP($B35,'Trình bày T3'!$B:$M,12,0) -> 0 | Z35: =VLOOKUP($B35,'Trình bày T4'!$B:$M,6,0) -> 1030 | AA35: =VLOOKUP($B35,'Trình bày T4'!$B:$M,7,0) -> 1150 | AB35: =AA35-Z35 -> 120 | AC35: =VLOOKUP($B35,'Trình bày T4'!$B:$M,9,0) -> 1210.6038 | AD35: =(AA35-AC35) -> -60.603774 | AE35: =+AD35/AA35 -> -0.052698934 | AF35: =VLOOKUP($B35,'Trình bày T4'!$B:$M,12,0) -> 0
A36: 4 | B36: 110000464 | C36: Hạt Nhựa rPET WSS06SP-1 | E36: =VLOOKUP($B36,'Trình bày T1'!$B:$M,6,0) -> 610 | F36: =VLOOKUP($B37,'Trình bày T1'!$B:$M,7,0) -> 0 | G36: =F36-E36 -> -610 | H36: =VLOOKUP($B39,'Trình bày T1'!$B:$M,9,0) -> 0 | I36: =(F36-H36) -> 0 | J36: =+I36/F36 -> #DIV/0! | K36: =VLOOKUP($B312,'Trình bày T1'!$B:$M,12,0) -> #N/A | L36: =VLOOKUP($B36,'Trình bày T2'!$B:$M,6,0) -> 570 | M36: =VLOOKUP($B37,'Trình bày T2'!$B:$M,7,0) -> 0 | N36: =M36-L36 -> -570 | O36: =VLOOKUP($B39,'Trình bày T2'!$B:$M,9,0) -> 0 | P36: =(M36-O36) -> 0 | Q36: =+P36/M36 -> #DIV/0! | R36: =VLOOKUP($B312,'Trình bày T2'!$B:$M,12,0) -> #N/A | S36: =VLOOKUP($B36,'Trình bày T3'!$B:$M,6,0) -> 570 | T36: =VLOOKUP($B37,'Trình bày T3'!$B:$M,7,0) -> 0 | U36: =T36-S36 -> -570 | V36: =VLOOKUP($B39,'Trình bày T3'!$B:$M,9,0) -> 0 | W36: =(T36-V36) -> 0 | X36: =+W36/T36 -> #DIV/0! | Y36: =VLOOKUP($B312,'Trình bày T3'!$B:$M,12,0) -> #N/A | Z36: =VLOOKUP($B36,'Trình bày T4'!$B:$M,6,0) -> 570 | AA36: =VLOOKUP($B37,'Trình bày T4'!$B:$M,7,0) -> 0 | AB36: =AA36-Z36 -> -570 | AC36: =VLOOKUP($B39,'Trình bày T4'!$B:$M,9,0) -> 0 | AD36: =(AA36-AC36) -> 0 | AE36: =+AD36/AA36 -> #DIV/0! | AF36: =VLOOKUP($B312,'Trình bày T4'!$B:$M,12,0) -> #N/A
A37: =A36+1 -> 5 | B37: 110000430 | C37: Hạt Nhựa rPET Bán Thành Phẩm | E37: =VLOOKUP($B37,'Trình bày T1'!$B:$M,6,0) -> 0 | F37: =VLOOKUP($B37,'Trình bày T1'!$B:$M,7,0) -> 0 | H37: =VLOOKUP($B39,'Trình bày T1'!$B:$M,9,0) -> 0 | K37: =VLOOKUP($B312,'Trình bày T1'!$B:$M,12,0) -> #N/A | L37: =VLOOKUP($B37,'Trình bày T2'!$B:$M,6,0) -> 0 | M37: =VLOOKUP($B37,'Trình bày T2'!$B:$M,7,0) -> 0 | O37: =VLOOKUP($B39,'Trình bày T2'!$B:$M,9,0) -> 0 | R37: =VLOOKUP($B312,'Trình bày T2'!$B:$M,12,0) -> #N/A | S37: =VLOOKUP($B37,'Trình bày T3'!$B:$M,6,0) -> 0 | T37: =VLOOKUP($B37,'Trình bày T3'!$B:$M,7,0) -> 0 | V37: =VLOOKUP($B39,'Trình bày T3'!$B:$M,9,0) -> 0 | Y37: =VLOOKUP($B312,'Trình bày T3'!$B:$M,12,0) -> #N/A | Z37: =VLOOKUP($B37,'Trình bày T4'!$B:$M,6,0) -> 0 | AA37: =VLOOKUP($B37,'Trình bày T4'!$B:$M,7,0) -> 0 | AC37: =VLOOKUP($B39,'Trình bày T4'!$B:$M,9,0) -> 0 | AF37: =VLOOKUP($B312,'Trình bày T4'!$B:$M,12,0) -> #N/A
A38: B | B38: rHDPE THỔI
A39: I | B39: MÃ HÀNG ĐANG BÁN
A40: 1 | B40: 110000339 | C40: Hạt Nhựa rHDPE MBF01 | D40: Trong | E40: =VLOOKUP($B40,'Trình bày T1'!$B:$M,6,0) -> 0 | F40: =VLOOKUP($B40,'Trình bày T1'!$B:$M,7,0) -> 0 | G40: =F40-E40 -> 0 | H40: =VLOOKUP($B40,'Trình bày T1'!$B:$M,9,0) -> 0 | K40: =VLOOKUP($B40,'Trình bày T1'!$B:$M,12,0) -> 0 | L40: =VLOOKUP($B40,'Trình bày T2'!$B:$M,6,0) -> 0 | M40: =VLOOKUP($B40,'Trình bày T2'!$B:$M,7,0) -> 0 | N40: =M40-L40 -> 0 | O40: =VLOOKUP($B40,'Trình bày T2'!$B:$M,9,0) -> 1083.9522 | R40: =VLOOKUP($B40,'Trình bày T2'!$B:$M,12,0) -> 0 | S40: =VLOOKUP($B40,'Trình bày T3'!$B:$M,6,0) -> 0 | T40: =VLOOKUP($B40,'Trình bày T3'!$B:$M,7,0) -> 0 | U40: =T40-S40 -> 0 | V40: =VLOOKUP($B40,'Trình bày T3'!$B:$M,9,0) -> 1076 | Y40: =VLOOKUP($B40,'Trình bày T3'!$B:$M,12,0) -> 0 | Z40: =VLOOKUP($B40,'Trình bày T4'!$B:$M,6,0) -> 0 | AA40: =VLOOKUP($B40,'Trình bày T4'!$B:$M,7,0) -> 0 | AB40: =AA40-Z40 -> 0 | AC40: =VLOOKUP($B40,'Trình bày T4'!$B:$M,9,0) -> 1113 | AF40: =VLOOKUP($B40,'Trình bày T4'!$B:$M,12,0) -> 0
A41: =+A40+1 -> 2 | B41: 110000426 | C41: Hạt Nhựa HCBF-Yel-U | D41: Vàng | E41: =VLOOKUP($B41,'Trình bày T1'!$B:$M,6,0) -> 0 | F41: =VLOOKUP($B41,'Trình bày T1'!$B:$M,7,0) -> 0 | G41: =F41-E41 -> 0 | H41: =VLOOKUP($B41,'Trình bày T1'!$B:$M,9,0) -> 0 | K41: =VLOOKUP($B41,'Trình bày T1'!$B:$M,12,0) -> 0 | L41: =VLOOKUP($B41,'Trình bày T2'!$B:$M,6,0) -> 0 | M41: =VLOOKUP($B41,'Trình bày T2'!$B:$M,7,0) -> 0 | N41: =M41-L41 -> 0 | O41: =VLOOKUP($B41,'Trình bày T2'!$B:$M,9,0) -> 1078.3594 | R41: =VLOOKUP($B41,'Trình bày T2'!$B:$M,12,0) -> 0 | S41: =VLOOKUP($B41,'Trình bày T3'!$B:$M,6,0) -> 0 | T41: =VLOOKUP($B41,'Trình bày T3'!$B:$M,7,0) -> 0 | U41: =T41-S41 -> 0 | V41: =VLOOKUP($B41,'Trình bày T3'!$B:$M,9,0) -> 1071.1353 | Y41: =VLOOKUP($B41,'Trình bày T3'!$B:$M,12,0) -> 0 | Z41: =VLOOKUP($B41,'Trình bày T4'!$B:$M,6,0) -> 0 | AA41: =VLOOKUP($B41,'Trình bày T4'!$B:$M,7,0) -> 0 | AB41: =AA41-Z41 -> 0 | AC41: =VLOOKUP($B41,'Trình bày T4'!$B:$M,9,0) -> 1263.5849 | AF41: =VLOOKUP($B41,'Trình bày T4'!$B:$M,12,0) -> 0
...

Sheet Trình bày T1
B1: DANH MỤC THÀNH PHẨM
A4: STT | B4: Mã SAP | C4: Tên hàng hóa | D4: Màu | E4: Tồn kho 17/12/2025 (kg) | F4: Số lượng bán BQ 2025 (kg/ tháng) | G4: Giá duyệt T12 (USD/ tấn) | H4: Giá bán đề nghị T1 (USD/ tấn) | I4: CL T12 sv T1 (USD/ tấn) | J4: Giá vốn | K4: Lợi nhuận trước thuế | L4: % lợi nhuận sau thuế | M4: Giá đề nghị của kinh doanh | N4: Ghi chú | O4: Sử dụng phó sản
A5: A | B5: rPET
A6: I | B6: MÃ HÀNG ĐANG BÁN
A7: 1 | B7: 110000354 | C7: Hạt nhựa rPET WSS01G 1 | E7: =SUMIFS('[1]tồn TP 17.12'!H:H,'[1]tồn TP 17.12'!A:A,'[1]Trình bày'!B7) -> 1781047.8 | F7: =IFERROR(_xlfn.XLOOKUP(B7,'[1]tồn TP 17.12'!A:A,'[1]tồn TP 17.12'!L:L),0) -> 1667665.9 | G7: 1200 | H7: =1220-10-10 -> 1200 | I7: =H7-G7 -> 0 | J7: 1096.8837 | K7: =(H7-J7) -> 103.11632 | L7: =+K7/H7 -> 0.085930267 | M7: 1180
A8: =+A7+1 -> 2 | B8: 110000355 | C8: Hạt nhựa rPET iSS01G 1 | E8: =SUMIFS('[1]tồn TP 17.12'!H:H,'[1]tồn TP 17.12'!A:A,'[1]Trình bày'!B8) -> 284108.7 | F8: =IFERROR(_xlfn.XLOOKUP(B8,'[1]tồn TP 17.12'!A:A,'[1]tồn TP 17.12'!L:L),0) -> 967139.62 | G8: 1230 | H8: =+H7+30 -> 1230 | I8: =H8-G8 -> 0 | J8: =+J7 -> 1096.8837 | K8: =(H8-J8) -> 133.11632 | L8: =+K8/H8 -> 0.10822465 | M8: =+M7+30 -> 1210
A9: =+A8+1 -> 3 | B9: 110000332 | C9: Hạt nhựa rPET iSS01084G | E9: =SUMIFS('[1]tồn TP 17.12'!H:H,'[1]tồn TP 17.12'!A:A,'[1]Trình bày'!B9) -> 1197408.5 | F9: =IFERROR(_xlfn.XLOOKUP(B9,'[1]tồn TP 17.12'!A:A,'[1]tồn TP 17.12'!L:L),0) -> 496599.45 | G9: 1290 | H9: =H7+90 -> 1290 | I9: =H9-G9 -> 0 | J9: 1157.9867 | K9: =(H9-J9) -> 132.0133 | L9: =+K9/H9 -> 0.10233589 | M9: =M7+90 -> 1270
A10: =+A9+1 -> 4 | B10: 110000359 | C10: Hạt nhựa rPET WSS03G | E10: =SUMIFS('[1]tồn TP 17.12'!H:H,'[1]tồn TP 17.12'!A:A,'[1]Trình bày'!B10) -> 1614071.7 | F10: =IFERROR(_xlfn.XLOOKUP(B10,'[1]tồn TP 17.12'!A:A,'[1]tồn TP 17.12'!L:L),0) -> 172277.27 | G10: 1130 | H10: =+H7-70 -> 1130 | I10: =H10-G10 -> 0 | J10: =+J8 -> 1096.8837 | K10: =(H10-J10) -> 33.116321 | L10: =+K10/H10 -> 0.029306478 | M10: =+M7-70 -> 1110
A11: =+A10+1 -> 5 | B11: 110000329 | C11: Hạt nhựa rPET WSS01 | E11: =SUMIFS('[1]tồn TP 17.12'!H:H,'[1]tồn TP 17.12'!A:A,'[1]Trình bày'!B11) -> 480417.3 | F11: =IFERROR(_xlfn.XLOOKUP(B11,'[1]tồn TP 17.12'!A:A,'[1]tồn TP 17.12'!L:L),0) -> 16300 | G11: 1320 | H11: 1320 | I11: =H11-G11 -> 0 | J11: 1182.4815 | K11: =(H11-J11) -> 137.51854 | L11: =+K11/H11 -> 0.10418072 | M11: 1320 | N11: Bán cho Lavie
A12: =+A11+1 -> 6 | B12: 110000497 | C12: Hạt Nhựa rPET WSS01G-L | E12: =SUMIFS('[1]tồn TP 17.12'!H:H,'[1]tồn TP 17.12'!A:A,'[1]Trình bày'!B12) -> 5500 | F12: =IFERROR(_xlfn.XLOOKUP(B12,'[1]tồn TP 17.12'!A:A,'[1]tồn TP 17.12'!L:L),0) -> 250 | G12: 1440 | H12: 1440 | I12: =H12-G12 -> 0 | J12: 1235.0716 | K12: =(H12-J12) -> 204.92844 | L12: =+K12/H12 -> 0.14231141 | M12: 1440 | N12: Bán cho Lavie
A13: =+A12+1 -> 7 | B13: 110000499 | C13: Hạt Nhựa rPET WSS01L | E13: =SUMIFS('[1]tồn TP 17.12'!H:H,'[1]tồn TP 17.12'!A:A,'[1]Trình bày'!B13) -> 34080 | F13: =IFERROR(_xlfn.XLOOKUP(B13,'[1]tồn TP 17.12'!A:A,'[1]tồn TP 17.12'!L:L),0) -> 100 | G13: 1200 | H13: =H7 -> 1200 | I13: =H13-G13 -> 0 | J13: 1015.2046 | K13: =(H13-J13) -> 184.79538 | L13: =+K13/H13 -> 0.15399615 | M13: =M7 -> 1180
A14: =+A13+1 -> 8 | B14: 110000503 | C14: Hạt Nhựa rPET WSS01S | E14: =SUMIFS('[1]tồn TP 17.12'!H:H,'[1]tồn TP 17.12'!A:A,'[1]Trình bày'!B14) -> 499.5 | F14: =IFERROR(_xlfn.XLOOKUP(B14,'[1]tồn TP 17.12'!A:A,'[1]tồn TP 17.12'!L:L),0) -> 1954.5455 | G14: 1200 | H14: =H7 -> 1200 | I14: =H14-G14 -> 0 | J14: 1025.9231 | K14: =(H14-J14) -> 174.07692 | L14: =+K14/H14 -> 0.1450641 | M14: =M7 -> 1180 | O14: Giá tồn kho
A15: =+A14+1 -> 9 | B15: 110000506 | C15: Hạt Nhựa rPET WSS01 & WSS01G-L | E15: =SUMIFS('[1]tồn TP 17.12'!H:H,'[1]tồn TP 17.12'!A:A,'[1]Trình bày'!B15) -> 2154 | F15: =IFERROR(_xlfn.XLOOKUP(B15,'[1]tồn TP 17.12'!A:A,'[1]tồn TP 17.12'!L:L),0) -> 78100 | G15: 1410 | H15: =+(H11+H12)/2+30 -> 1410 | I15: =H15-G15 -> 0 | J15: =+J11*50%+J12*50% -> 1208.7765 | K15: =(H15-J15) -> 201.22349 | L15: =+K15/H15 -> 0.1427117 | M15: =+(M11+M12)/2+30 -> 1410 | N15: Bán cho Lavie
A16: =+A15+1 -> 10 | B16: 110000483 | C16: Hạt Nhựa rPET iSS01G-S | E16: =SUMIFS('[1]tồn TP 17.12'!H:H,'[1]tồn TP 17.12'!A:A,'[1]Trình bày'!B16) -> 74205.5 | F16: =IFERROR(_xlfn.XLOOKUP(B16,'[1]tồn TP 17.12'!A:A,'[1]tồn TP 17.12'!L:L),0) -> 353.63636 | G16: 1230 | H16: =H8 -> 1230 | I16: =H16-G16 -> 0 | J16: 1138.6538 | K16: =(H16-J16) -> 91.346154 | L16: =+K16/H16 -> 0.074265166 | M16: =M8 -> 1210 | N16: Sản phẩm mới | O16: Giá tồn kho
A17: II | B17: MÃ HÀNG BÁN CHẬM
A18: 1 | B18: 110000378 | C18: Hạt nhựa rPET iSS01G 2 | E18: =SUMIFS('[1]tồn TP 17.12'!H:H,'[1]tồn TP 17.12'!A:A,'[1]Trình bày'!B18) -> 1649997 | F18: =IFERROR(_xlfn.XLOOKUP(B18,'[1]tồn TP 17.12'!A:A,'[1]tồn TP 17.12'!L:L),0) -> 0 | G18: 1230 | H18: =+H7+30 -> 1230 | I18: =H18-G18 -> 0 | J18: =+J7 -> 1096.8837 | K18: =(H18-J18) -> 133.11632 | L18: =+K18/H18 -> 0.10822465 | M18: =+M7+30 -> 1210 | N18: Chuyển thành mã iSS01G 1 để bán
A19: =+A18+1 -> 2 | B19: 110000377 | C19: Hạt nhựa rPET WSS01G 2 | E19: =SUMIFS('[1]tồn TP 17.12'!H:H,'[1]tồn TP 17.12'!A:A,'[1]Trình bày'!B19) -> 307999.5 | F19: =IFERROR(_xlfn.XLOOKUP(B19,'[1]tồn TP 17.12'!A:A,'[1]tồn TP 17.12'!L:L),0) -> 0 | G19: 1200 | H19: =H7 -> 1200 | I19: =H19-G19 -> 0 | J19: =+J8 -> 1096.8837 | K19: =(H19-J19) -> 103.11632 | L19: =+K19/H19 -> 0.085930267 | M19: =M7 -> 1180 | N19: Chuyển thành mã wSS01G 1 để bán
A20: =+A19+1 -> 3 | B20: 110000383 | C20: Hạt Nhựa rPET iSS84G-P | E20: =SUMIFS('[1]tồn TP 17.12'!H:H,'[1]tồn TP 17.12'!A:A,'[1]Trình bày'!B20) -> 52800 | F20: =IFERROR(_xlfn.XLOOKUP(B20,'[1]tồn TP 17.12'!A:A,'[1]tồn TP 17.12'!L:L),0) -> 0 | I20: =H20-G20 -> 0 | J20: 1130.6154 | N20: Không báo giá (SP SX bán cho Amcor) | O20: Giá tồn kho
A21: =+A20+1 -> 4 | B21: 110000335 | C21: Hạt nhựa rPET WSS04 | E21: =SUMIFS('[1]tồn TP 17.12'!H:H,'[1]tồn TP 17.12'!A:A,'[1]Trình bày'!B21) -> 4420.7 | F21: =IFERROR(_xlfn.XLOOKUP(B21,'[1]tồn TP 17.12'!A:A,'[1]tồn TP 17.12'!L:L),0) -> 8800 | I21: =H21-G21 -> 0 | J21: 1045.1154 | N21: Không báo giá (hàng chờ xử lý) | O21: Giá tồn kho
A22: =+A21+1 -> 5 | B22: 110000358 | C22: Hạt nhựa rPET WSS02G | E22: =SUMIFS('[1]tồn TP 17.12'!H:H,'[1]tồn TP 17.12'!A:A,'[1]Trình bày'!B22) -> 0 | F22: =IFERROR(_xlfn.XLOOKUP(B22,'[1]tồn TP 17.12'!A:A,'[1]tồn TP 17.12'!L:L),0) -> 0 | I22: =H22-G22 -> 0 | N22: Không báo giá (hàng chờ xử lý)
A23: =+A22+1 -> 6 | B23: 110000468 | C23: Hạt Nhựa rPET iSS80G-P | E23: =SUMIFS('[1]tồn TP 17.12'!H:H,'[1]tồn TP 17.12'!A:A,'[1]Trình bày'!B23) -> 74800 | F23: =IFERROR(_xlfn.XLOOKUP(B23,'[1]tồn TP 17.12'!A:A,'[1]tồn TP 17.12'!L:L),0) -> 0 | I23: =H23-G23 -> 0 | J23: 1056.2692 | N23: Không báo giá (SP SX bán cho Amcor) | O23: Giá tồn kho
A24: =+A23+1 -> 7 | B24: 110000333 | C24: Hạt nhựa rPET WSS03 | E24: =SUMIFS('[1]tồn TP 17.12'!H:H,'[1]tồn TP 17.12'!A:A,'[1]Trình bày'!B24) -> 2269 | F24: =IFERROR(_xlfn.XLOOKUP(B24,'[1]tồn TP 17.12'!A:A,'[1]tồn TP 17.12'!L:L),0) -> 0 | I24: =H24-G24 -> 0 | J24: 937.65385 | N24: Không báo giá (hàng chờ xử lý) | O24: Giá tồn kho
A25: =+A24+1 -> 8 | B25: 110000376 | C25: Hạt nhựa rPET iSS01L | E25: =SUMIFS('[1]tồn TP 17.12'!H:H,'[1]tồn TP 17.12'!A:A,'[1]Trình bày'!B25) -> 1900 | F25: =IFERROR(_xlfn.XLOOKUP(B25,'[1]tồn TP 17.12'!A:A,'[1]tồn TP 17.12'!L:L),0) -> 27.272727 | I25: =H25-G25 -> 0 | J25: 1198.8846 | N25: Không báo giá (hàng chờ xử lý) | O25: Giá tồn kho
A26: =+A25+1 -> 9 | B26: 110000331 | C26: Hạt nhựa rPET WSS02 | E26: =SUMIFS('[1]tồn TP 17.12'!H:H,'[1]tồn TP 17.12'!A:A,'[1]Trình bày'!B26) -> 0 | F26: =IFERROR(_xlfn.XLOOKUP(B26,'[1]tồn TP 17.12'!A:A,'[1]tồn TP 17.12'!L:L),0) -> 0 | I26: =H26-G26 -> 0 | N26: Không báo giá (hàng chờ xử lý)
A27: =+A26+1 -> 10 | B27: 110000330 | C27: Hạt nhựa rPET iSS01 | E27: =SUMIFS('[1]tồn TP 17.12'!H:H,'[1]tồn TP 17.12'!A:A,'[1]Trình bày'!B27) -> 0 | F27: =IFERROR(_xlfn.XLOOKUP(B27,'[1]tồn TP 17.12'!A:A,'[1]tồn TP 17.12'!L:L),0) -> 0 | I27: =H27-G27 -> 0 | N27: Không báo giá (hàng chờ xử lý)
A28: =+A27+1 -> 11 | B28: 110000475 | C28: Hạt nhựa rPET WSS03G FRH | E28: =SUMIFS('[1]tồn TP 17.12'!H:H,'[1]tồn TP 17.12'!A:A,'[1]Trình bày'!B28) -> 0 | F28: =IFERROR(_xlfn.XLOOKUP(B28,'[1]tồn TP 17.12'!A:A,'[1]tồn TP 17.12'!L:L),0) -> 0 | I28: =H28-G28 -> 0 | N28: Không báo giá (hàng chờ xử lý)
A29: III | B29: MÃ HÀNG SẢN XUẤT TỪ PHÓ SẢN NGÀNH PET
A30: 1 | B30: 110000466 | C30: Hạt Nhựa rPET WSS05SB-2 | E30: =SUMIFS('[1]tồn TP 17.12'!H:H,'[1]tồn TP 17.12'!A:A,'[1]Trình bày'!B30) -> 17363.2 | F30: =IFERROR(_xlfn.XLOOKUP(B30,'[1]tồn TP 17.12'!A:A,'[1]tồn TP 17.12'!L:L),0) -> 40613.636 | G30: 810 | H30: =G30 -> 810 | I30: =H30-G30 -> 0 | J30: 931.34534 | K30: =(H30-J30) -> -121.34534 | L30: =+K30/H30 -> -0.14980906 | M30: 800 | O30: 82% Vảy B6.2_A3 và 18% vảy B7_A3
A31: =A30+1 -> 2 | B31: 110000436 | C31: Hạt nhựa rPET WSS05SB | E31: =SUMIFS('[1]tồn TP 17.12'!H:H,'[1]tồn TP 17.12'!A:A,'[1]Trình bày'!B31) -> 629780.7 | F31: =IFERROR(_xlfn.XLOOKUP(B31,'[1]tồn TP 17.12'!A:A,'[1]tồn TP 17.12'!L:L),0) -> 97670.455 | G31: 760 | H31: =G31 -> 760 | I31: =H31-G31 -> 0 | J31: 957.10022 | K31: =(H31-J31) -> -197.10022 | L31: =+K31/H31 -> -0.25934239 | M31: 750 | O31: 100% Vảy B6.2_A3 và 90% B6.2_A3, 10% Bụi tank C,D sau vắt
A32: 2 | B32: 110000382 | C32: Hạt nhựa rPET WSS04SB | E32: =SUMIFS('[1]tồn TP 17.12'!H:H,'[1]tồn TP 17.12'!A:A,'[1]Trình bày'!B32) -> 1850 | F32: =IFERROR(_xlfn.XLOOKUP(B32,'[1]tồn TP 17.12'!A:A,'[1]tồn TP 17.12'!L:L),0) -> 90.909091 | G32: 1070 | H32: =G32 -> 1070 | I32: =H32-G32 -> 0 | J32: 582.96769 | K32: =(H32-J32) -> 487.03231 | L32: =+K32/H32 -> 0.45517038 | O32: 100% vảy PET B1_A3
A33: =A32+1 -> 3 | B33: 110000384 | C33: Hạt Nhựa Xơ Sợi Thử Nghiệm | E33: =SUMIFS('[1]tồn TP 17.12'!H:H,'[1]tồn TP 17.12'!A:A,'[1]Trình bày'!B33) -> 185278.5 | F33: =IFERROR(_xlfn.XLOOKUP(B33,'[1]tồn TP 17.12'!A:A,'[1]tồn TP 17.12'!L:L),0) -> 0 | I33: =H33-G33 -> 0 | O33: Không đạt WSS04SB, WSS04SB, WSS04SD rớt xuống mã xơ sợi thử nghiệm
A34: 3 | B34: 110000381 | C34: Hạt nhựa rPET WSS04SD | E34: =SUMIFS('[1]tồn TP 17.12'!H:H,'[1]tồn TP 17.12'!A:A,'[1]Trình bày'!B34) -> 52855.8 | F34: =IFERROR(_xlfn.XLOOKUP(B34,'[1]tồn TP 17.12'!A:A,'[1]tồn TP 17.12'!L:L),0) -> 2.2727273 | G34: 1070 | H34: =G34 -> 1070 | I34: =H34-G34 -> 0 | J34: 646.08292 | K34: =(H34-J34) -> 423.91708 | L34: =+K34/H34 -> 0.39618418 | O34: Tomra_A1/ Zigzag_A1
A35: =A34+1 -> 4 | B35: 110000387 | C35: Hạt nhựa rPET WSS03SD | E35: =SUMIFS('[1]tồn TP 17.12'!H:H,'[1]tồn TP 17.12'!A:A,'[1]Trình bày'!B35) -> 15354.6 | F35: =IFERROR(_xlfn.XLOOKUP(B35,'[1]tồn TP 17.12'!A:A,'[1]tồn TP 17.12'!L:L),0) -> 2.2727273 | G35: 1070 | H35: =G35 -> 1070 | I35: =H35-G35 -> 0 | J35: 736.55619 | K35: =(H35-J35) -> 333.44381 | L35: =+K35/H35 -> 0.31162973 | O35: Tomra_A1/ Zigzag_A1
A36: 4 | B36: 110000464 | C36: Hạt Nhựa rPET WSS06SP-1 | E36: =SUMIFS('[1]tồn TP 17.12'!H:H,'[1]tồn TP 17.12'!A:A,'[1]Trình bày'!B36) -> 92423 | F36: =IFERROR(_xlfn.XLOOKUP(B36,'[1]tồn TP 17.12'!A:A,'[1]tồn TP 17.12'!L:L),0) -> 0 | G36: 610 | H36: =G36 -> 610 | I36: =H36-G36 -> 0 | J36: 657.90591 | K36: =(H36-J36) -> -47.905913 | L36: =+K36/H36 -> -0.078534284 | M36: 600 | O36: Chuyển từ hàng xơ sợi thử nghiệm qua
A37: =A36+1 -> 5 | B37: 110000430 | C37: Hạt Nhựa rPET Bán Thành Phẩm | E37: =SUMIFS('[1]tồn TP 17.12'!H:H,'[1]tồn TP 17.12'!A:A,'[1]Trình bày'!B37) -> 37399 | F37: =IFERROR(_xlfn.XLOOKUP(B37,'[1]tồn TP 17.12'!A:A,'[1]tồn TP 17.12'!L:L),0) -> 0 | O37: Phó sản PET tuyển nổi 2 + phó sản hạt cắt lỗi
A38: B | B38: rHDPE THỔI
A39: I | B39: MÃ HÀNG ĐANG BÁN
A40: 1 | B40: 110000339 | C40: Hạt Nhựa rHDPE MBF01 | D40: Trong | E40: =SUMIFS('[1]tồn TP 17.12'!H:H,'[1]tồn TP 17.12'!A:A,'[1]Trình bày'!B40) -> 493431.3 | F40: =IFERROR(_xlfn.XLOOKUP(B40,'[1]tồn TP 17.12'!A:A,'[1]tồn TP 17.12'!L:L),0) -> 110231.82 | I40: =H40-G40 -> 0 | N40: Theo giá U => ko đề xuất trong duyệt giá
A41: =+A40+1 -> 2 | B41: 110000426 | C41: Hạt Nhựa HCBF-Yel-U | D41: Vàng | E41: =SUMIFS('[1]tồn TP 17.12'!H:H,'[1]tồn TP 17.12'!A:A,'[1]Trình bày'!B41) -> 23776 | F41: =IFERROR(_xlfn.XLOOKUP(B41,'[1]tồn TP 17.12'!A:A,'[1]tồn TP 17.12'!L:L),0) -> 31625 | I41: =H41-G41 -> 0 | N41: Theo giá U => ko đề xuất trong duyệt giá
A42: =+A41+1 -> 3 | B42: 110000374 | C42: Hạt Nhựa rHDB03N02 | D42: Trong | E42: =SUMIFS('[1]tồn TP 17.12'!H:H,'[1]tồn TP 17.12'!A:A,'[1]Trình bày'!B42) -> 318748.4 | F42: =IFERROR(_xlfn.XLOOKUP(B42,'[1]tồn TP 17.12'!A:A,'[1]tồn TP 17.12'!L:L),0) -> 32027.273 | G42: 1200 | H42: 1200 | I42: =H42-G42 -> 0 | J42: 1111.3107 | K42: =(H42-J42) -> 88.689265 | L42: =+K42/H42 -> 0.07390772 | M42: 1150
...

Sheet Trình bày T2
B1: DANH MỤC THÀNH PHẨM
A4: STT | B4: Mã SAP | C4: Tên hàng hóa | D4: Màu | E4: Tồn kho 17/01/2026 (kg) | F4: Số lượng bán BQ 2025 (kg/ tháng) | G4: Giá duyệt T1 (USD/ tấn) | H4: Giá bán đề nghị T2 (USD/ tấn) | I4: CL T2 sv T1 (USD/ tấn) | J4: Giá vốn | K4: Lợi nhuận trước thuế | L4: % lợi nhuận sau thuế | M4: Giá đề nghị của kinh doanh | N4: Ghi chú | O4: Sử dụng phó sản
A5: A | B5: rPET
A6: I | B6: MÃ HÀNG ĐANG BÁN
A7: 1 | B7: 110000354 | C7: Hạt nhựa rPET WSS01G 1 | E7: =SUMIFS('[2]tồn TP 17.01'!H:H,'[2]tồn TP 17.01'!A:A,'[2]Trình bày'!B7) -> 677410 | F7: =IFERROR(_xlfn.XLOOKUP(B7,'[2]tồn TP 17.01'!A:A,'[2]tồn TP 17.01'!L:L),0) -> 1610552.1 | G7: 1160 | H7: 1160 | I7: =H7-G7 -> 0 | J7: 1056 | K7: =(H7-J7) -> 104 | L7: =+K7/H7 -> 0.089655172
A8: =+A7+1 -> 2 | B8: 110000355 | C8: Hạt nhựa rPET iSS01G 1 | E8: =SUMIFS('[2]tồn TP 17.01'!H:H,'[2]tồn TP 17.01'!A:A,'[2]Trình bày'!B8) -> 239583.75 | F8: =IFERROR(_xlfn.XLOOKUP(B8,'[2]tồn TP 17.01'!A:A,'[2]tồn TP 17.01'!L:L),0) -> 902311.32 | G8: 1190 | H8: =+H7+30 -> 1190 | I8: =H8-G8 -> 0 | J8: =+J7 -> 1056 | K8: =(H8-J8) -> 134 | L8: =+K8/H8 -> 0.11260504
A9: =+A8+1 -> 3 | B9: 110000332 | C9: Hạt nhựa rPET iSS01084G | E9: =SUMIFS('[2]tồn TP 17.01'!H:H,'[2]tồn TP 17.01'!A:A,'[2]Trình bày'!B9) -> 1168421.4 | F9: =IFERROR(_xlfn.XLOOKUP(B9,'[2]tồn TP 17.01'!A:A,'[2]tồn TP 17.01'!L:L),0) -> 534049.49 | G9: 1250 | H9: =H7+90 -> 1250 | I9: =H9-G9 -> 0 | J9: 1111 | K9: =(H9-J9) -> 139 | L9: =+K9/H9 -> 0.1112
A10: =+A9+1 -> 4 | B10: 110000359 | C10: Hạt nhựa rPET WSS03G | E10: =SUMIFS('[2]tồn TP 17.01'!H:H,'[2]tồn TP 17.01'!A:A,'[2]Trình bày'!B10) -> 1688517.7 | F10: =IFERROR(_xlfn.XLOOKUP(B10,'[2]tồn TP 17.01'!A:A,'[2]tồn TP 17.01'!L:L),0) -> 157920.83 | G10: 1090 | H10: =+H7-70 -> 1090 | I10: =H10-G10 -> 0 | J10: =+J8 -> 1056 | K10: =(H10-J10) -> 34 | L10: =+K10/H10 -> 0.031192661
A11: =+A10+1 -> 5 | B11: 110000329 | C11: Hạt nhựa rPET WSS01 | E11: =SUMIFS('[2]tồn TP 17.01'!H:H,'[2]tồn TP 17.01'!A:A,'[2]Trình bày'!B11) -> 404521.3 | F11: =IFERROR(_xlfn.XLOOKUP(B11,'[2]tồn TP 17.01'!A:A,'[2]tồn TP 17.01'!L:L),0) -> 24108.333 | G11: 1320 | H11: 1320 | I11: =H11-G11 -> 0 | J11: 1154 | K11: =(H11-J11) -> 166 | L11: =+K11/H11 -> 0.12575758 | N11: Bán cho Lavie
A12: =+A11+1 -> 6 | B12: 110000497 | C12: Hạt Nhựa rPET WSS01G-L | E12: =SUMIFS('[2]tồn TP 17.01'!H:H,'[2]tồn TP 17.01'!A:A,'[2]Trình bày'!B12) -> 0 | F12: =IFERROR(_xlfn.XLOOKUP(B12,'[2]tồn TP 17.01'!A:A,'[2]tồn TP 17.01'!L:L),0) -> 0 | G12: 1440 | H12: 1440 | I12: =H12-G12 -> 0 | J12: 1201 | K12: =(H12-J12) -> 239 | L12: =+K12/H12 -> 0.16597222 | N12: Bán cho Lavie
A13: =+A12+1 -> 7 | B13: 110000499 | C13: Hạt Nhựa rPET WSS01L | E13: =SUMIFS('[2]tồn TP 17.01'!H:H,'[2]tồn TP 17.01'!A:A,'[2]Trình bày'!B13) -> 34080 | F13: =IFERROR(_xlfn.XLOOKUP(B13,'[2]tồn TP 17.01'!A:A,'[2]tồn TP 17.01'!L:L),0) -> 91.666667 | G13: 1160 | H13: =H7 -> 1160 | I13: =H13-G13 -> 0 | J13: 998 | K13: =(H13-J13) -> 162 | L13: =+K13/H13 -> 0.13965517
A14: =+A13+1 -> 8 | B14: 110000503 | C14: Hạt Nhựa rPET WSS01S | E14: =SUMIFS('[2]tồn TP 17.01'!H:H,'[2]tồn TP 17.01'!A:A,'[2]Trình bày'!B14) -> 0 | F14: =IFERROR(_xlfn.XLOOKUP(B14,'[2]tồn TP 17.01'!A:A,'[2]tồn TP 17.01'!L:L),0) -> 0 | G14: 1160 | H14: =H7 -> 1160 | I14: =H14-G14 -> 0 | K14: =(H14-J14) -> 1160 | L14: =+K14/H14 -> 1 | O14: Giá tồn kho
A15: =+A14+1 -> 9 | B15: 110000506 | C15: Hạt Nhựa rPET WSS01 & WSS01G-L | E15: =SUMIFS('[2]tồn TP 17.01'!H:H,'[2]tồn TP 17.01'!A:A,'[2]Trình bày'!B15) -> 65840 | F15: =IFERROR(_xlfn.XLOOKUP(B15,'[2]tồn TP 17.01'!A:A,'[2]tồn TP 17.01'!L:L),0) -> 71591.667 | G15: 1410 | H15: =+(H11+H12)/2+30 -> 1410 | I15: =H15-G15 -> 0 | J15: =32400/26.5 -> 1222.6415 | K15: =(H15-J15) -> 187.35849 | L15: =+K15/H15 -> 0.13287836 | N15: Bán cho Lavie
A16: =+A15+1 -> 10 | B16: 110000483 | C16: Hạt Nhựa rPET iSS01G-S | E16: =SUMIFS('[2]tồn TP 17.01'!H:H,'[2]tồn TP 17.01'!A:A,'[2]Trình bày'!B16) -> 65404.5 | F16: =IFERROR(_xlfn.XLOOKUP(B16,'[2]tồn TP 17.01'!A:A,'[2]tồn TP 17.01'!L:L),0) -> 965.83333 | G16: 1190 | H16: =H8 -> 1190 | I16: =H16-G16 -> 0 | J16: =29605/26.5 -> 1117.1698 | K16: =(H16-J16) -> 72.830189 | L16: =+K16/H16 -> 0.061201839 | N16: Sản phẩm mới | O16: Giá tồn kho
A17: II | B17: MÃ HÀNG BÁN CHẬM
A18: 1 | B18: 110000378 | C18: Hạt nhựa rPET iSS01G 2 | E18: =SUMIFS('[2]tồn TP 17.01'!H:H,'[2]tồn TP 17.01'!A:A,'[2]Trình bày'!B18) -> 1649997 | F18: =IFERROR(_xlfn.XLOOKUP(B18,'[2]tồn TP 17.01'!A:A,'[2]tồn TP 17.01'!L:L),0) -> 0 | G18: 1190 | H18: =+H7+30 -> 1190 | I18: =H18-G18 -> 0 | J18: =+J7 -> 1056 | K18: =(H18-J18) -> 134 | L18: =+K18/H18 -> 0.11260504 | N18: Chuyển thành mã iSS01G 1 để bán
A19: =+A18+1 -> 2 | B19: 110000377 | C19: Hạt nhựa rPET WSS01G 2 | E19: =SUMIFS('[2]tồn TP 17.01'!H:H,'[2]tồn TP 17.01'!A:A,'[2]Trình bày'!B19) -> 299199.5 | F19: =IFERROR(_xlfn.XLOOKUP(B19,'[2]tồn TP 17.01'!A:A,'[2]tồn TP 17.01'!L:L),0) -> 0 | G19: 1160 | H19: =H7 -> 1160 | I19: =H19-G19 -> 0 | J19: =+J8 -> 1056 | K19: =(H19-J19) -> 104 | L19: =+K19/H19 -> 0.089655172 | N19: Chuyển thành mã wSS01G 1 để bán
A20: =+A19+1 -> 3 | B20: 110000383 | C20: Hạt Nhựa rPET iSS84G-P | E20: =SUMIFS('[2]tồn TP 17.01'!H:H,'[2]tồn TP 17.01'!A:A,'[2]Trình bày'!B20) -> 52800 | F20: =IFERROR(_xlfn.XLOOKUP(B20,'[2]tồn TP 17.01'!A:A,'[2]tồn TP 17.01'!L:L),0) -> 0 | I20: =H20-G20 -> 0 | J20: =29396/26.5 -> 1109.283 | N20: Không báo giá (SP SX bán cho Amcor) | O20: Giá tồn kho
A21: =+A20+1 -> 4 | B21: 110000335 | C21: Hạt nhựa rPET WSS04 | E21: =SUMIFS('[2]tồn TP 17.01'!H:H,'[2]tồn TP 17.01'!A:A,'[2]Trình bày'!B21) -> 0 | F21: =IFERROR(_xlfn.XLOOKUP(B21,'[2]tồn TP 17.01'!A:A,'[2]tồn TP 17.01'!L:L),0) -> 0 | I21: =H21-G21 -> 0 | N21: Không báo giá (hàng chờ xử lý) | O21: Giá tồn kho
A22: =+A21+1 -> 5 | B22: 110000358 | C22: Hạt nhựa rPET WSS02G | E22: =SUMIFS('[2]tồn TP 17.01'!H:H,'[2]tồn TP 17.01'!A:A,'[2]Trình bày'!B22) -> 0 | F22: =IFERROR(_xlfn.XLOOKUP(B22,'[2]tồn TP 17.01'!A:A,'[2]tồn TP 17.01'!L:L),0) -> 0 | I22: =H22-G22 -> 0 | N22: Không báo giá (hàng chờ xử lý)
A23: =+A22+1 -> 6 | B23: 110000468 | C23: Hạt Nhựa rPET iSS80G-P | E23: =SUMIFS('[2]tồn TP 17.01'!H:H,'[2]tồn TP 17.01'!A:A,'[2]Trình bày'!B23) -> 74800 | F23: =IFERROR(_xlfn.XLOOKUP(B23,'[2]tồn TP 17.01'!A:A,'[2]tồn TP 17.01'!L:L),0) -> 0 | I23: =H23-G23 -> 0 | J23: =27463/26.5 -> 1036.3396 | N23: Không báo giá (SP SX bán cho Amcor) | O23: Giá tồn kho
A24: =+A23+1 -> 7 | B24: 110000333 | C24: Hạt nhựa rPET WSS03 | E24: =SUMIFS('[2]tồn TP 17.01'!H:H,'[2]tồn TP 17.01'!A:A,'[2]Trình bày'!B24) -> 0 | F24: =IFERROR(_xlfn.XLOOKUP(B24,'[2]tồn TP 17.01'!A:A,'[2]tồn TP 17.01'!L:L),0) -> 0 | I24: =H24-G24 -> 0 | J24: 0 | N24: Không báo giá (hàng chờ xử lý) | O24: Giá tồn kho
A25: =+A24+1 -> 8 | B25: 110000376 | C25: Hạt nhựa rPET iSS01L | E25: =SUMIFS('[2]tồn TP 17.01'!H:H,'[2]tồn TP 17.01'!A:A,'[2]Trình bày'!B25) -> 800 | F25: =IFERROR(_xlfn.XLOOKUP(B25,'[2]tồn TP 17.01'!A:A,'[2]tồn TP 17.01'!L:L),0) -> 25 | I25: =H25-G25 -> 0 | J25: =31171/26.5 -> 1176.2642 | N25: Không báo giá (hàng chờ xử lý) | O25: Giá tồn kho
A26: =+A25+1 -> 9 | B26: 110000331 | C26: Hạt nhựa rPET WSS02 | E26: =SUMIFS('[2]tồn TP 17.01'!H:H,'[2]tồn TP 17.01'!A:A,'[2]Trình bày'!B26) -> 0 | F26: =IFERROR(_xlfn.XLOOKUP(B26,'[2]tồn TP 17.01'!A:A,'[2]tồn TP 17.01'!L:L),0) -> 0 | I26: =H26-G26 -> 0 | N26: Không báo giá (hàng chờ xử lý)
A27: =+A26+1 -> 10 | B27: 110000330 | C27: Hạt nhựa rPET iSS01 | E27: =SUMIFS('[2]tồn TP 17.01'!H:H,'[2]tồn TP 17.01'!A:A,'[2]Trình bày'!B27) -> 0 | F27: =IFERROR(_xlfn.XLOOKUP(B27,'[2]tồn TP 17.01'!A:A,'[2]tồn TP 17.01'!L:L),0) -> 0 | I27: =H27-G27 -> 0 | N27: Không báo giá (hàng chờ xử lý)
A28: =+A27+1 -> 11 | B28: 110000475 | C28: Hạt nhựa rPET WSS03G FRH | E28: =SUMIFS('[2]tồn TP 17.01'!H:H,'[2]tồn TP 17.01'!A:A,'[2]Trình bày'!B28) -> 0 | F28: =IFERROR(_xlfn.XLOOKUP(B28,'[2]tồn TP 17.01'!A:A,'[2]tồn TP 17.01'!L:L),0) -> 0 | I28: =H28-G28 -> 0 | N28: Không báo giá (hàng chờ xử lý)
A29: III | B29: MÃ HÀNG SẢN XUẤT TỪ PHÓ SẢN NGÀNH PET
A30: 1 | B30: 110000466 | C30: Hạt Nhựa rPET WSS05SB-2 | E30: =SUMIFS('[2]tồn TP 17.01'!H:H,'[2]tồn TP 17.01'!A:A,'[2]Trình bày'!B30) -> 16099 | F30: =IFERROR(_xlfn.XLOOKUP(B30,'[2]tồn TP 17.01'!A:A,'[2]tồn TP 17.01'!L:L),0) -> 37229.167 | G30: 770 | H30: 770 | J30: 921 | K30: =(H30-J30) -> -151 | L30: =+K30/H30 -> -0.1961039 | O30: 82% Vảy B6.2_A3 và 18% vảy B7_A3
A31: =A30+1 -> 2 | B31: 110000436 | C31: Hạt nhựa rPET WSS05SB | E31: =SUMIFS('[2]tồn TP 17.01'!H:H,'[2]tồn TP 17.01'!A:A,'[2]Trình bày'!B31) -> 652880.7 | F31: =IFERROR(_xlfn.XLOOKUP(B31,'[2]tồn TP 17.01'!A:A,'[2]tồn TP 17.01'!L:L),0) -> 91368.75 | G31: 720 | H31: 720 | I31: =H31-G31 -> 0 | J31: 949 | K31: =(H31-J31) -> -229 | L31: =+K31/H31 -> -0.31805556 | O31: 100% Vảy B6.2_A3 và 90% B6.2_A3, 10% Bụi tank C,D sau vắt
A32: 2 | B32: 110000382 | C32: Hạt nhựa rPET WSS04SB | E32: =SUMIFS('[2]tồn TP 17.01'!H:H,'[2]tồn TP 17.01'!A:A,'[2]Trình bày'!B32) -> 1050 | F32: =IFERROR(_xlfn.XLOOKUP(B32,'[2]tồn TP 17.01'!A:A,'[2]tồn TP 17.01'!L:L),0) -> 83.333333 | G32: 1030 | H32: =H7-130 -> 1030 | I32: =H32-G32 -> 0 | J32: 559 | K32: =(H32-J32) -> 471 | L32: =+K32/H32 -> 0.45728155 | O32: 100% vảy PET B1_A3
