Workbook
Name \A: #REF!
Name \M: #REF!
Name ___ATS98: #REF!
Name ___BGT02: #REF!
Name ___CHF98: #REF!
Name ___CHX2002: #REF!
Name ___CHX2003: #REF!
Name ___CHX2004: #REF!
Name ___CHX2005: #REF!
Name ___DTB2003: #REF!
Name ___DTB2004: #REF!
Name ___LY01: #REF!
Name ___Mkt1: #REF!
Name ___VAR1: #REF!
Name ___VAR2: #REF!
Name ___var22: #REF!
Name ___VAR3: #REF!
Name ___VAR4: #REF!
Name ___VAR5: #REF!
Name ___VAR6: #REF!
Name ___VAR7: #REF!
Name __ATS98: #REF!
Name __BGT02: #REF!
Name __CHF98: #REF!
Name __CHX2002: #REF!
Name __CHX2003: #REF!
Name __CHX2004: #REF!
Name __CHX2005: #REF!
Name __DAT1: #REF!
Name __DAT10: #REF!
Name __DAT11: #REF!
Name __DAT12: #REF!
Name __DAT13: #REF!
Name __DAT14: #REF!
Name __DAT15: #REF!
Name __DAT16: #REF!
Name __DAT17: #REF!
Name __DAT18: #REF!
Name __DAT19: #REF!
Name __DAT2: #REF!
Name __DAT20: #REF!
Name __DAT21: #REF!
Name __DAT22: #REF!
Name __DAT23: #REF!
Name __DAT24: #REF!
Name __DAT25: #REF!
Name __DAT26: #REF!
Name __DAT27: #REF!
Name __DAT28: #REF!
Name __DAT29: #REF!
Name __DAT3: #REF!
Name __DAT30: #REF!
Name __DAT31: #REF!
Name __DAT32: #REF!
Name __DAT33: #REF!
Name __DAT34: #REF!
Name __DAT35: #REF!
Name __DAT36: #REF!
Name __DAT37: #REF!
Name __DAT38: #REF!

Sheet Trình bày
B1: DANH MỤC THÀNH PHẨM
A4: STT | B4: Mã SAP | C4: Tên hàng hóa | D4: Màu | E4: Tồn kho 24/02/2026 (kg) | F4: Số lượng bán BQ 2026 (kg/ tháng) | N4: Ghi chú | O4: Sử dụng phó sản
A5: A | B5: rPET
A6: I | B6: MÃ HÀNG ĐANG BÁN
A7: 1 | B7: 110000354 | C7: Hạt nhựa rPET WSS01G 1 | E7: =SUMIFS('tồn TP 24.02'!H:H,'tồn TP 24.02'!A:A,'Trình bày'!B7) -> 503605 | F7: =IFERROR(_xlfn.XLOOKUP(B7,'tồn TP 24.02'!A:A,'tồn TP 24.02'!L:L),0) -> 2663100
A8: =+A7+1 -> 2 | B8: 110000355 | C8: Hạt nhựa rPET iSS01G 1 | E8: =SUMIFS('tồn TP 24.02'!H:H,'tồn TP 24.02'!A:A,'Trình bày'!B8) -> 154879.75 | F8: =IFERROR(_xlfn.XLOOKUP(B8,'tồn TP 24.02'!A:A,'tồn TP 24.02'!L:L),0) -> 25300
A9: =+A8+1 -> 3 | B9: 110000332 | C9: Hạt nhựa rPET iSS01084G | E9: =SUMIFS('tồn TP 24.02'!H:H,'tồn TP 24.02'!A:A,'Trình bày'!B9) -> 788631.35 | F9: =IFERROR(_xlfn.XLOOKUP(B9,'tồn TP 24.02'!A:A,'tồn TP 24.02'!L:L),0) -> 616000
A10: =+A9+1 -> 4 | B10: 110000359 | C10: Hạt nhựa rPET WSS03G | E10: =SUMIFS('tồn TP 24.02'!H:H,'tồn TP 24.02'!A:A,'Trình bày'!B10) -> 1999804.7 | F10: =IFERROR(_xlfn.XLOOKUP(B10,'tồn TP 24.02'!A:A,'tồn TP 24.02'!L:L),0) -> 244200
A11: =+A10+1 -> 5 | B11: 110000329 | C11: Hạt nhựa rPET WSS01 | E11: =SUMIFS('tồn TP 24.02'!H:H,'tồn TP 24.02'!A:A,'Trình bày'!B11) -> 378162 | F11: =IFERROR(_xlfn.XLOOKUP(B11,'tồn TP 24.02'!A:A,'tồn TP 24.02'!L:L),0) -> 0 | N11: Bán cho Lavie
A12: =+A11+1 -> 6 | B12: 110000497 | C12: Hạt Nhựa rPET WSS01G-L | E12: =SUMIFS('tồn TP 24.02'!H:H,'tồn TP 24.02'!A:A,'Trình bày'!B12) -> 0 | F12: =IFERROR(_xlfn.XLOOKUP(B12,'tồn TP 24.02'!A:A,'tồn TP 24.02'!L:L),0) -> 0 | I12: =H12-G12 -> 0 | K12: =(H12-J12) -> 0 | N12: Bán cho Lavie
A13: =+A12+1 -> 7 | B13: 110000499 | C13: Hạt Nhựa rPET WSS01L | E13: =SUMIFS('tồn TP 24.02'!H:H,'tồn TP 24.02'!A:A,'Trình bày'!B13) -> 34030 | F13: =IFERROR(_xlfn.XLOOKUP(B13,'tồn TP 24.02'!A:A,'tồn TP 24.02'!L:L),0) -> 0
A14: =+A13+1 -> 8 | B14: 110000503 | C14: Hạt Nhựa rPET WSS01S | E14: =SUMIFS('tồn TP 24.02'!H:H,'tồn TP 24.02'!A:A,'Trình bày'!B14) -> 0 | F14: =IFERROR(_xlfn.XLOOKUP(B14,'tồn TP 24.02'!A:A,'tồn TP 24.02'!L:L),0) -> 0 | I14: =H14-G14 -> 0 | K14: =(H14-J14) -> 0
A15: =+A14+1 -> 9 | B15: 110000506 | C15: Hạt Nhựa rPET WSS01 & WSS01G-L | E15: =SUMIFS('tồn TP 24.02'!H:H,'tồn TP 24.02'!A:A,'Trình bày'!B15) -> 65840 | F15: =IFERROR(_xlfn.XLOOKUP(B15,'tồn TP 24.02'!A:A,'tồn TP 24.02'!L:L),0) -> 0 | N15: Bán cho Lavie | O15: Giá tồn kho
A16: =+A15+1 -> 10 | B16: 110000483 | C16: Hạt Nhựa rPET iSS01G-S | E16: =SUMIFS('tồn TP 24.02'!H:H,'tồn TP 24.02'!A:A,'Trình bày'!B16) -> 32405.5 | F16: =IFERROR(_xlfn.XLOOKUP(B16,'tồn TP 24.02'!A:A,'tồn TP 24.02'!L:L),0) -> 6600 | N16: Sản phẩm mới | O16: Giá tồn kho
A17: II | B17: MÃ HÀNG BÁN CHẬM
A18: 1 | B18: 110000378 | C18: Hạt nhựa rPET iSS01G 2 | E18: =SUMIFS('tồn TP 24.02'!H:H,'tồn TP 24.02'!A:A,'Trình bày'!B18) -> 1649997 | F18: =IFERROR(_xlfn.XLOOKUP(B18,'tồn TP 24.02'!A:A,'tồn TP 24.02'!L:L),0) -> 0 | N18: Chuyển thành mã iSS01G 1 để bán
A19: =+A18+1 -> 2 | B19: 110000377 | C19: Hạt nhựa rPET WSS01G 2 | E19: =SUMIFS('tồn TP 24.02'!H:H,'tồn TP 24.02'!A:A,'Trình bày'!B19) -> 287099.5 | F19: =IFERROR(_xlfn.XLOOKUP(B19,'tồn TP 24.02'!A:A,'tồn TP 24.02'!L:L),0) -> 11000 | N19: Chuyển thành mã wSS01G 1 để bán
A20: =+A19+1 -> 3 | B20: 110000383 | C20: Hạt Nhựa rPET iSS84G-P | E20: =SUMIFS('tồn TP 24.02'!H:H,'tồn TP 24.02'!A:A,'Trình bày'!B20) -> 52800 | F20: =IFERROR(_xlfn.XLOOKUP(B20,'tồn TP 24.02'!A:A,'tồn TP 24.02'!L:L),0) -> 0 | N20: Không báo giá (SP SX bán cho Amcor) | O20: Giá tồn kho
A21: =+A20+1 -> 4 | B21: 110000335 | C21: Hạt nhựa rPET WSS04 | E21: =SUMIFS('tồn TP 24.02'!H:H,'tồn TP 24.02'!A:A,'Trình bày'!B21) -> 0 | F21: =IFERROR(_xlfn.XLOOKUP(B21,'tồn TP 24.02'!A:A,'tồn TP 24.02'!L:L),0) -> 0 | I21: =H21-G21 -> 0 | K21: =(H21-J21) -> 0 | O21: Giá tồn kho
A22: =+A21+1 -> 5 | B22: 110000358 | C22: Hạt nhựa rPET WSS02G | E22: =SUMIFS('tồn TP 24.02'!H:H,'tồn TP 24.02'!A:A,'Trình bày'!B22) -> 0 | F22: =IFERROR(_xlfn.XLOOKUP(B22,'tồn TP 24.02'!A:A,'tồn TP 24.02'!L:L),0) -> 0 | I22: =H22-G22 -> 0 | K22: =(H22-J22) -> 0
A23: =+A22+1 -> 6 | B23: 110000468 | C23: Hạt Nhựa rPET iSS80G-P | E23: =SUMIFS('tồn TP 24.02'!H:H,'tồn TP 24.02'!A:A,'Trình bày'!B23) -> 73650 | F23: =IFERROR(_xlfn.XLOOKUP(B23,'tồn TP 24.02'!A:A,'tồn TP 24.02'!L:L),0) -> 0 | N23: Không báo giá (SP SX bán cho Amcor) | O23: Giá tồn kho
A24: =+A23+1 -> 7 | B24: 110000333 | C24: Hạt nhựa rPET WSS03 | E24: =SUMIFS('tồn TP 24.02'!H:H,'tồn TP 24.02'!A:A,'Trình bày'!B24) -> 0 | F24: =IFERROR(_xlfn.XLOOKUP(B24,'tồn TP 24.02'!A:A,'tồn TP 24.02'!L:L),0) -> 0 | I24: =H24-G24 -> 0 | K24: =(H24-J24) -> 0 | O24: Giá tồn kho
A25: =+A24+1 -> 8 | B25: 110000376 | C25: Hạt nhựa rPET iSS01L | E25: =SUMIFS('tồn TP 24.02'!H:H,'tồn TP 24.02'!A:A,'Trình bày'!B25) -> 800 | F25: =IFERROR(_xlfn.XLOOKUP(B25,'tồn TP 24.02'!A:A,'tồn TP 24.02'!L:L),0) -> 0 | N25: Không báo giá (hàng chờ xử lý) | O25: Giá tồn kho
A26: =+A25+1 -> 9 | B26: 110000331 | C26: Hạt nhựa rPET WSS02 | E26: =SUMIFS('tồn TP 24.02'!H:H,'tồn TP 24.02'!A:A,'Trình bày'!B26) -> 0 | F26: =IFERROR(_xlfn.XLOOKUP(B26,'tồn TP 24.02'!A:A,'tồn TP 24.02'!L:L),0) -> 0 | I26: =H26-G26 -> 0 | K26: =(H26-J26) -> 0
A27: =+A26+1 -> 10 | B27: 110000330 | C27: Hạt nhựa rPET iSS01 | E27: =SUMIFS('tồn TP 24.02'!H:H,'tồn TP 24.02'!A:A,'Trình bày'!B27) -> 0 | F27: =IFERROR(_xlfn.XLOOKUP(B27,'tồn TP 24.02'!A:A,'tồn TP 24.02'!L:L),0) -> 0 | I27: =H27-G27 -> 0 | K27: =(H27-J27) -> 0
A28: =+A27+1 -> 11 | B28: 110000475 | C28: Hạt nhựa rPET WSS03G FRH | E28: =SUMIFS('tồn TP 24.02'!H:H,'tồn TP 24.02'!A:A,'Trình bày'!B28) -> 0 | F28: =IFERROR(_xlfn.XLOOKUP(B28,'tồn TP 24.02'!A:A,'tồn TP 24.02'!L:L),0) -> 0 | I28: =H28-G28 -> 0 | K28: =(H28-J28) -> 0
A29: III | B29: MÃ HÀNG SẢN XUẤT TỪ PHÓ SẢN NGÀNH PET
A30: 1 | B30: 110000466 | C30: Hạt Nhựa rPET WSS05SB-2 | E30: =SUMIFS('tồn TP 24.02'!H:H,'tồn TP 24.02'!A:A,'Trình bày'!B30) -> 16099 | F30: =IFERROR(_xlfn.XLOOKUP(B30,'tồn TP 24.02'!A:A,'tồn TP 24.02'!L:L),0) -> 0 | O30: 82% Vảy B6.2_A3 và 18% vảy B7_A3
A31: =A30+1 -> 2 | B31: 110000436 | C31: Hạt nhựa rPET WSS05SB | E31: =SUMIFS('tồn TP 24.02'!H:H,'tồn TP 24.02'!A:A,'Trình bày'!B31) -> 570335.7 | F31: =IFERROR(_xlfn.XLOOKUP(B31,'tồn TP 24.02'!A:A,'tồn TP 24.02'!L:L),0) -> 23100 | O31: 100% Vảy B6.2_A3 và 90% B6.2_A3, 10% Bụi tank C,D sau vắt
A32: 2 | B32: 110000382 | C32: Hạt nhựa rPET WSS04SB | E32: =SUMIFS('tồn TP 24.02'!H:H,'tồn TP 24.02'!A:A,'Trình bày'!B32) -> 4514.7 | F32: =IFERROR(_xlfn.XLOOKUP(B32,'tồn TP 24.02'!A:A,'tồn TP 24.02'!L:L),0) -> 0 | O32: 100% vảy PET B1_A3
A33: =A32+1 -> 3 | B33: 110000384 | C33: Hạt Nhựa Xơ Sợi Thử Nghiệm | E33: =SUMIFS('tồn TP 24.02'!H:H,'tồn TP 24.02'!A:A,'Trình bày'!B33) -> 171597.5 | F33: =IFERROR(_xlfn.XLOOKUP(B33,'tồn TP 24.02'!A:A,'tồn TP 24.02'!L:L),0) -> 0 | O33: Không đạt WSS04SB, WSS04SB, WSS04SD rớt xuống mã xơ sợi thử nghiệm
A34: 3 | B34: 110000381 | C34: Hạt nhựa rPET WSS04SD | E34: =SUMIFS('tồn TP 24.02'!H:H,'tồn TP 24.02'!A:A,'Trình bày'!B34) -> 68711.6 | F34: =IFERROR(_xlfn.XLOOKUP(B34,'tồn TP 24.02'!A:A,'tồn TP 24.02'!L:L),0) -> -17600 | O34: Tomra_A1/ Zigzag_A1
A35: =A34+1 -> 4 | B35: 110000387 | C35: Hạt nhựa rPET WSS03SD | E35: =SUMIFS('tồn TP 24.02'!H:H,'tồn TP 24.02'!A:A,'Trình bày'!B35) -> 13179.6 | F35: =IFERROR(_xlfn.XLOOKUP(B35,'tồn TP 24.02'!A:A,'tồn TP 24.02'!L:L),0) -> 0 | O35: Tomra_A1/ Zigzag_A1
A36: 4 | B36: 110000464 | C36: Hạt Nhựa rPET WSS06SP-1 | E36: =SUMIFS('tồn TP 24.02'!H:H,'tồn TP 24.02'!A:A,'Trình bày'!B36) -> 90593 | F36: =IFERROR(_xlfn.XLOOKUP(B36,'tồn TP 24.02'!A:A,'tồn TP 24.02'!L:L),0) -> 0 | O36: Chuyển từ hàng xơ sợi thử nghiệm qua
A37: =A36+1 -> 5 | B37: 110000430 | C37: Hạt Nhựa rPET Bán Thành Phẩm | E37: =SUMIFS('tồn TP 24.02'!H:H,'tồn TP 24.02'!A:A,'Trình bày'!B37) -> 37399 | F37: =IFERROR(_xlfn.XLOOKUP(B37,'tồn TP 24.02'!A:A,'tồn TP 24.02'!L:L),0) -> 0 | O37: Phó sản PET tuyển nổi 2 + phó sản hạt cắt lỗi
A38: B | B38: rHDPE THỔI
A39: I | B39: MÃ HÀNG ĐANG BÁN
A40: 1 | B40: 110000339 | C40: Hạt Nhựa rHDPE MBF01 | D40: Trong | E40: =SUMIFS('tồn TP 24.02'!H:H,'tồn TP 24.02'!A:A,'Trình bày'!B40) -> 404076.5 | F40: =IFERROR(_xlfn.XLOOKUP(B40,'tồn TP 24.02'!A:A,'tồn TP 24.02'!L:L),0) -> 211750 | N40: Theo giá U => ko đề xuất trong duyệt giá
A41: =+A40+1 -> 2 | B41: 110000426 | C41: Hạt Nhựa HCBF-Yel-U | D41: Vàng | E41: =SUMIFS('tồn TP 24.02'!H:H,'tồn TP 24.02'!A:A,'Trình bày'!B41) -> 40547 | F41: =IFERROR(_xlfn.XLOOKUP(B41,'tồn TP 24.02'!A:A,'tồn TP 24.02'!L:L),0) -> 0 | N41: Theo giá U => ko đề xuất trong duyệt giá
A42: =+A41+1 -> 3 | B42: 110000374 | C42: Hạt Nhựa rHDB03N02 | D42: Trong | E42: =SUMIFS('tồn TP 24.02'!H:H,'tồn TP 24.02'!A:A,'Trình bày'!B42) -> 326364.4 | F42: =IFERROR(_xlfn.XLOOKUP(B42,'tồn TP 24.02'!A:A,'tồn TP 24.02'!L:L),0) -> 44500
...

Sheet KH 2025
C1: Công ty CP Nhựa Tái Chế Duy Tân | H1: Tỷ giá:
C2: NGÂN SÁCH 2025 | H2: USD | I2: 25000
C3: LẦN 1 | H3: VND | I3: 1
D5: KẾ HOẠCH BÁN HÀNG NĂM | E5: 2025
O6: =O7/M7 -> 1279.7747 | P6: =Q7/M7 -> 484.86926 | T6: Tỷ giá | U6: 26000
L7: CỘNG: | M7: =SUBTOTAL(9,M11:M77) -> 5940.96 | O7: =SUBTOTAL(9,O11:O77) -> 7603090.4 | Q7: =SUBTOTAL(9,Q11:Q77) -> 2880588.9 | R7: =SUBTOTAL(9,R11:R77) -> -4722501.6 | S7: =SUBTOTAL(9,S11:S77) -> -122785040300
V8: LN TT | W8: 1.9661585e+10
N9: Ngân sách T12 | P9: Đề xuất T12 | R9: Chênh lệch đề xuất - NS | V9: CPXK | W9: 11134240500
A10: AM | B10: Manager | C10: Mã khách hàng | D10: Tên khách hàng | E10: Kênh bán hàng | F10: Incorterm | G10: Mã SP | H10: Tên SP | I10: Nhóm hàng | J10: IV | K10: Application | L10: Mức độ khả thi | M10: SL T12 | N10: Giá bán | O10: Doanh thu | P10: Giá bán | Q10: Doanh thu | R10: USD | S10: VND | V10: Dây đai | W10: 2850000000
A11: Nghĩa | B11: B2B | C11: 200344 | D11: Wiese | E11: Xuất Khẩu | F11: CIF | G11: 110000332 | H11: Hạt nhựa rPET iSS01084G | I11: rPET | J11: 0 | K11: Injection | L11: 0.8 | M11: 44 | N11: 1350 | O11: =IFERROR(M11*N11,0) -> 59400 | P11: =_xlfn.XLOOKUP(G11,'Trình bày'!B:B,'Trình bày'!H:H) -> 0 | Q11: =IFERROR(M11*P11,0) -> 0 | R11: =Q11-O11 -> -59400 | S11: =R11*$U$6 -> -1544400000 | V11: Tài trợ | W11: 3271999000
A12: Nghĩa | B12: B2B | C12: 105208 | D12: Việt Thành | E12: Nội địa | F12: Nội địa | G12: Sản phẩm mới | H12: HD Flake | I12: rHDPE | J12: 0 | K12: Injection | L12: 0.8 | M12: 5.25 | N12: 850 | O12: =IFERROR(M12*N12,0) -> 4462.5 | P12: 665 | Q12: =IFERROR(M12*P12,0) -> 3491.25 | R12: =Q12-O12 -> -971.25 | S12: =R12*$U$6 -> -25252500
A13: Cường | B13: Khác | C13: 105208 | D13: Việt Thành | E13: Nội địa | F13: Nội địa | G13: Sản phẩm mới | H13: PP Flake | I13: rPP | J13: 0 | K13: Blowing | L13: 0.8 | M13: 10.5 | N13: 850 | O13: =IFERROR(M13*N13,0) -> 8925 | P13: 650 | Q13: =IFERROR(M13*P13,0) -> 6825 | R13: =Q13-O13 -> -2100 | S13: =R13*$U$6 -> -54600000 | V13: LNTT cấn trừ | W13: =W8-SUM(W9:W11) -> 2.4053456e+09
A14: Nghĩa | B14: B2B | C14: 104877 | D14: Uy Kiệt | E14: Nội địa | F14: Nội địa | G14: 110000359 | H14: Hạt nhựa rPET WSS03G | I14: rPET | J14: 0.8 | K14: Food Grade | L14: 0.8 | M14: 110 | N14: 1075 | O14: =IFERROR(M14*N14,0) -> 118250 | P14: =_xlfn.XLOOKUP(G14,'Trình bày'!B:B,'Trình bày'!H:H) -> 0 | Q14: =IFERROR(M14*P14,0) -> 0 | R14: =Q14-O14 -> -118250 | S14: =R14*$U$6 -> -3074500000 | V14: Giá bán giảm | W14: =S7 -> -122785040300
A15: Cường | B15: B2B | C15: 105243 | D15: Unilever | E15: Nội địa | F15: Nội địa | G15: 110000426 | H15: Hạt Nhựa HCBF-Yel-U | I15: rHDPE | J15: 0.84 | K15: Food Grade | L15: 0.8 | M15: 44 | N15: 1380 | O15: =IFERROR(M15*N15,0) -> 60720 | P15: 1330 | Q15: =IFERROR(M15*P15,0) -> 58520 | R15: =Q15-O15 -> -2200 | S15: =R15*$U$6 -> -57200000
A16: Cường | B16: B2B | C16: 105303 | D16: Tân Lập Thành | E16: Nội địa | F16: Nội địa | G16: 110000355 | H16: Hạt nhựa rPET iSS01G | I16: rPET | J16: 0.84 | K16: Food Grade | L16: 0.8 | M16: 50 | N16: 1260 | O16: =IFERROR(M16*N16,0) -> 63000 | P16: =_xlfn.XLOOKUP(G16,'Trình bày'!B:B,'Trình bày'!H:H) -> 0 | Q16: =IFERROR(M16*P16,0) -> 0 | R16: =Q16-O16 -> -63000 | S16: =R16*$U$6 -> -1638000000 | V16: LNTT T12 | W16: =W13+W14 -> -1.2037969e+11
A17: Quốc Anh | B17: B2B | C17: 105194 | D17: Suntory Việt Nam | E17: Nội địa | F17: Nội địa | G17: 110000332 | H17: Hạt nhựa rPET iSS01084G | I17: rPET | J17: 0.7 | K17: Fiber | L17: 1 | M17: 264 | N17: 1400 | O17: =IFERROR(M17*N17,0) -> 369600 | P17: =_xlfn.XLOOKUP(G17,'Trình bày'!B:B,'Trình bày'!H:H) -> 0 | Q17: =IFERROR(M17*P17,0) -> 0 | R17: =Q17-O17 -> -369600 | S17: =R17*$U$6 -> -9609600000 | V17: % | W17: =W16/W13 -> -50.046736
A18: Thông | B18: XK | C18: 105194 | D18: Suntory Việt Nam | E18: Nội địa | F18: Nội địa | G18: 110000332 | H18: Hạt nhựa rPET iSS01084G | I18: rPET | J18: 0 | K18: Injection | L18: 0.8 | M18: 176 | N18: 1400 | O18: =IFERROR(M18*N18,0) -> 246400 | P18: =_xlfn.XLOOKUP(G18,'Trình bày'!B:B,'Trình bày'!H:H) -> 0 | Q18: =IFERROR(M18*P18,0) -> 0 | R18: =Q18-O18 -> -246400 | S18: =R18*$U$6 -> -6406400000
A19: Thông | B19: XK | D19: Sợi Thế Kỷ | E19: Nội địa | F19: Nội địa | G19: 110000387 | H19: Hạt nhựa rPET WSS03SD | I19: Xơ sợi | J19: 0 | K19: Injection | L19: 0.8 | M19: 100 | N19: 1100 | O19: =IFERROR(M19*N19,0) -> 110000 | P19: =_xlfn.XLOOKUP(G19,'Trình bày'!B:B,'Trình bày'!H:H) -> 0 | Q19: =IFERROR(M19*P19,0) -> 0 | R19: =Q19-O19 -> -110000 | S19: =R19*$U$6 -> -2860000000
A20: Thông | B20: XK | C20: 200358 | D20: Reynera | E20: Xuất Khẩu | F20: FOB | G20: 110000472 | H20: Hạt Nhựa rPP20Gy01 | I20: rPP | J20: 0 | K20: Injection | L20: 0.8 | M20: 5.83 | N20: 1000 | O20: =IFERROR(M20*N20,0) -> 5830 | P20: 915 | Q20: =IFERROR(M20*P20,0) -> 5334.45 | R20: =Q20-O20 -> -495.55 | S20: =R20*$U$6 -> -12884300
A21: Quỳnh Anh | B21: XK | C21: 200358 | D21: Reynera | E21: Xuất Khẩu | F21: FOB | G21: 110000470 | H21: Hạt Nhựa rPP20L04 | I21: rPP | J21: 0 | K21: Blowing | L21: 0.8 | M21: 6.11 | N21: 1000 | O21: =IFERROR(M21*N21,0) -> 6110 | P21: 915 | Q21: =IFERROR(M21*P21,0) -> 5590.65 | R21: =Q21-O21 -> -519.35 | S21: =R21*$U$6 -> -13503100
A22: Quỳnh Anh | B22: XK | C22: 200358 | D22: Reynera | E22: Xuất Khẩu | F22: FOB | G22: 110000471 | H22: Hạt Nhựa rPP20L05 | I22: rPP | J22: 0.74 | K22: Food Grade | L22: 0.8 | M22: 13 | N22: 1000 | O22: =IFERROR(M22*N22,0) -> 13000 | P22: 915 | Q22: =IFERROR(M22*P22,0) -> 11895 | R22: =Q22-O22 -> -1105 | S22: =R22*$U$6 -> -28730000
A23: Cường | B23: XK | C23: 200343 | D23: Premium Water | E23: Xuất Khẩu | F23: FOB | G23: 110000359 | H23: Hạt nhựa rPET WSS03G | I23: rPET | J23: 0.84 | K23: Food Grade | L23: 0.8 | M23: 400 | N23: 1075 | O23: =IFERROR(M23*N23,0) -> 430000 | P23: 1100 | Q23: =IFERROR(M23*P23,0) -> 440000 | R23: =Q23-O23 -> 10000 | S23: =R23*$U$6 -> 260000000
A24: Thông | B24: B2B | D24: PepsiCo North America | E24: Xuất Khẩu | F24: DDP | G24: 110000383 | H24: Hạt Nhựa rPET iSS84G-P | I24: rPET | J24: 0 | K24: Injection | L24: 0.8 | M24: 550 | N24: 1500 | O24: =IFERROR(M24*N24,0) -> 825000 | P24: =_xlfn.XLOOKUP(G24,'Trình bày'!B:B,'Trình bày'!H:H) -> 0 | Q24: =IFERROR(M24*P24,0) -> 0 | R24: =Q24-O24 -> -825000 | S24: =R24*$U$6 -> -21450000000
A25: Thông | B25: B2B | D25: Nhựa Bình Thuận | E25: Nội địa | F25: Nội địa | G25: 110000469 | H25: Vảy HD Ép Dương Bình Thuận | I25: rHDPE | J25: 0.8 | K25: Food Grade | L25: 0.8 | M25: 25 | N25: 850 | O25: =IFERROR(M25*N25,0) -> 21250 | P25: 665 | Q25: =IFERROR(M25*P25,0) -> 16625 | R25: =Q25-O25 -> -4625 | S25: =R25*$U$6 -> -120250000
A26: Long | B26: B2B | C26: 105217 | D26: Nestle | E26: Nội địa | F26: Nội địa | G26: 110000329 | H26: Hạt nhựa rPET WSS01 | I26: rPET | J26: 0 | K26: Blowing | L26: 0.8 | M26: 22 | N26: 1330 | O26: =IFERROR(M26*N26,0) -> 29260 | P26: =_xlfn.XLOOKUP(G26,'Trình bày'!B:B,'Trình bày'!H:H) -> 0 | Q26: =IFERROR(M26*P26,0) -> 0 | R26: =Q26-O26 -> -29260 | S26: =R26*$U$6 -> -760760000
A27: Quốc Anh | B27: B2B | C27: 105284 | D27: Motul | E27: Nội địa | F27: Nội địa | G27: 110000339 | H27: MBF01-Motul | I27: rHDPE | J27: 0.84 | K27: Food Grade | L27: 0.8 | M27: 40 | N27: 1350 | O27: =IFERROR(M27*N27,0) -> 54000 | P27: 1200 | Q27: =IFERROR(M27*P27,0) -> 48000 | R27: =Q27-O27 -> -6000 | S27: =R27*$U$6 -> -156000000
A28: Long | B28: XK | C28: 105286 | D28: Mondelez | E28: Nội địa | F28: Nội địa | G28: 110000332 | H28: Hạt nhựa rPET iSS01084G | I28: rPET | J28: 0.84 | K28: Food Grade | L28: 0.8 | M28: 50 | N28: 1350 | O28: =IFERROR(M28*N28,0) -> 67500 | P28: =_xlfn.XLOOKUP(G28,'Trình bày'!B:B,'Trình bày'!H:H) -> 0 | Q28: =IFERROR(M28*P28,0) -> 0 | R28: =Q28-O28 -> -67500 | S28: =R28*$U$6 -> -1755000000
A29: Quốc Anh | B29: B2B | C29: 200362 | D29: Magma Int | E29: Xuất Khẩu | F29: CIF | G29: 110000332 | H29: Hạt nhựa rPET iSS01084G | I29: rPET | J29: 0.78 | K29: Food Grade | L29: 0.8 | M29: 88 | N29: 1350 | O29: =IFERROR(M29*N29,0) -> 118800 | P29: =_xlfn.XLOOKUP(G29,'Trình bày'!B:B,'Trình bày'!H:H) -> 0 | Q29: =IFERROR(M29*P29,0) -> 0 | R29: =Q29-O29 -> -118800 | S29: =R29*$U$6 -> -3088800000
A30: Quốc Anh | B30: B2B | D30: IKEA | E30: Nội địa | F30: Nội địa | G30: 110000354 | H30: Hạt nhựa rPET WSS01G | I30: rPET | J30: 0 | K30: Injection | L30: 0.8 | M30: 5 | N30: 1270 | O30: =IFERROR(M30*N30,0) -> 6350 | P30: =_xlfn.XLOOKUP(G30,'Trình bày'!B:B,'Trình bày'!H:H) -> 0 | Q30: =IFERROR(M30*P30,0) -> 0 | R30: =Q30-O30 -> -6350 | S30: =R30*$U$6 -> -165100000
A31: Quốc Anh | B31: B2B | D31: IKEA | E31: Nội địa | F31: Nội địa | G31: 110000393 | H31: Hạt nhựa rPP20Be01 | I31: rPP | J31: 0 | K31: Injection | L31: 0.8 | M31: 6 | N31: 850 | O31: =IFERROR(M31*N31,0) -> 5100 | P31: 705 | Q31: =IFERROR(M31*P31,0) -> 4230 | R31: =Q31-O31 -> -870 | S31: =R31*$U$6 -> -22620000
A32: Cường | B32: Khác | D32: Huyie | E32: Nội địa | F32: Nội địa | G32: 110000371 | H32: Hạt nhựa rPP15B01 | I32: rPP | J32: 0 | K32: Injection | L32: 0.8 | M32: 25 | N32: 850 | O32: =IFERROR(M32*N32,0) -> 21250 | P32: 705 | Q32: =IFERROR(M32*P32,0) -> 17625 | R32: =Q32-O32 -> -3625 | S32: =R32*$U$6 -> -94250000
A33: Cường | B33: Khác | C33: 1000 | D33: DTP | E33: Nội địa | F33: Nội địa | G33: 110000363 | H33: Hạt nhựa rHDI3Gy01 | I33: rHDPE | J33: 0 | K33: Injection | L33: 0.8 | M33: 10 | N33: 850 | O33: =IFERROR(M33*N33,0) -> 8500 | P33: =_xlfn.XLOOKUP(G33,'Trình bày'!B:B,'Trình bày'!H:H) -> 0 | Q33: =IFERROR(M33*P33,0) -> 0 | R33: =Q33-O33 -> -8500 | S33: =R33*$U$6 -> -221000000
A34: Quốc Anh | B34: B2B | C34: 1000 | D34: DTP | E34: Nội địa | F34: Nội địa | G34: 110000394 | H34: Hạt nhựa rPP15Gy02 | I34: rPP | J34: 0 | K34: Blowing | L34: 0.8 | M34: 10 | N34: 850 | O34: =IFERROR(M34*N34,0) -> 8500 | P34: 705 | Q34: =IFERROR(M34*P34,0) -> 7050 | R34: =Q34-O34 -> -1450 | S34: =R34*$U$6 -> -37700000
A35: Long | B35: B2B | C35: 105292 | D35: Donaplast | E35: Nội địa | F35: Nội địa | G35: 110000341 | H35: Hạt nhựa rHDB04B01 | I35: rHDPE | J35: 0.84 | K35: Food Grade | L35: 0.8 | M35: 50 | N35: 840 | O35: =IFERROR(M35*N35,0) -> 42000 | P35: =_xlfn.XLOOKUP(G35,'Trình bày'!B:B,'Trình bày'!H:H) -> 0 | Q35: =IFERROR(M35*P35,0) -> 0 | R35: =Q35-O35 -> -42000 | S35: =R35*$U$6 -> -1092000000
A36: Cường | B36: B2B | C36: 105222 | D36: Cocacola | E36: Nội địa | F36: Nội địa | G36: 110000332 | H36: Hạt nhựa rPET iSS01084G | I36: rPET | J36: 0.78 | K36: Food Grade | L36: 0.8 | M36: 88 | N36: 1360 | O36: =IFERROR(M36*N36,0) -> 119680 | P36: =_xlfn.XLOOKUP(G36,'Trình bày'!B:B,'Trình bày'!H:H) -> 0 | Q36: =IFERROR(M36*P36,0) -> 0 | R36: =Q36-O36 -> -119680 | S36: =R36*$U$6 -> -3111680000
A37: Cường | B37: Khác | C37: 105243 | D37: Unilever | E37: Nội địa | F37: Nội địa | G37: 110000354 | H37: Hạt nhựa rPET WSS01G | I37: rPET | J37: 0 | K37: Blowing | L37: 1 | M37: 364 | N37: 1326 | O37: =IFERROR(M37*N37,0) -> 482664 | P37: 1280 | Q37: =IFERROR(M37*P37,0) -> 465920 | R37: =Q37-O37 -> -16744 | S37: =R37*$U$6 -> -435344000
A38: Cường | B38: Khác | C38: 105243 | D38: Unilever | E38: Nội địa | F38: Nội địa | G38: 110000339 | H38: Hạt Nhựa rHDPE MBF01 | I38: rHDPE | J38: 0 | K38: Blowing | L38: 1 | M38: 250 | N38: 1428 | O38: =IFERROR(M38*N38,0) -> 357000 | P38: 1380 | Q38: =IFERROR(M38*P38,0) -> 345000 | R38: =Q38-O38 -> -12000 | S38: =R38*$U$6 -> -312000000
A39: Nghĩa | B39: XK | C39: 105243 | D39: Unilever | E39: Nội địa | F39: Nội địa | G39: 110000481 | H39: Hạt Nhựa rHDPE PCF01 | I39: rHDPE | J39: 0.84 | K39: Food Grade | L39: 1 | M39: 150 | N39: 1428 | O39: =IFERROR(M39*N39,0) -> 214200 | P39: 1380 | Q39: =IFERROR(M39*P39,0) -> 207000 | R39: =Q39-O39 -> -7200 | S39: =R39*$U$6 -> -187200000
A40: Quỳnh Anh | B40: XK | D40: Ravago Americas | E40: Xuất Khẩu | F40: CIF | G40: 110000332 | H40: Hạt nhựa rPET iSS01084G | I40: rPET | J40: 0.78 | K40: Food Grade | L40: 1 | M40: 110 | N40: 1350 | O40: =IFERROR(M40*N40,0) -> 148500 | P40: =_xlfn.XLOOKUP(G40,'Trình bày'!B:B,'Trình bày'!H:H) -> 0 | Q40: =IFERROR(M40*P40,0) -> 0 | R40: =Q40-O40 -> -148500 | S40: =R40*$U$6 -> -3861000000
A41: Quốc Anh | B41: XK | C41: 200311 | D41: Plascene | E41: Xuất Khẩu | F41: FOB | G41: 110000354 | H41: Hạt nhựa rPET WSS01G | I41: rPET | J41: 0.78 | K41: Food Grade | L41: 1 | M41: 66 | N41: 1270 | O41: =IFERROR(M41*N41,0) -> 83820 | P41: 1080 | Q41: =IFERROR(M41*P41,0) -> 71280 | R41: =Q41-O41 -> -12540 | S41: =R41*$U$6 -> -326040000
...

Sheet Dự báo
D1: ƯỚC TÍNH T11: | M1: Tỷ giá | N1: 26000
D2: Doanh thu (exw) | E2: =N10 -> 60260200000
D3: LN gộp | E3: =P10 -> -2.9027175e+10
D4: CP thuê xưởng + máy | E4: 5498752515
D5: Ước tính CP bán hàng | E5: 1513399753 | F5: 641 ( ko tính CP VC+ XK)
D6: Ước tính CP quản lý | E6: 8132746433 | F6: 642
D7: Ước tính CP khác | E7: 1368802426 | F7: CP lãi vay
D8: Lợi nhuận trước thuế | E8: =E3-SUM(E4:E7) -> -4.5540876e+10 | M8: Giá bán không thay đổi theo duyệt giá
K10: =SUBTOTAL(9,K12:K53) -> 3248.125 | M10: =SUBTOTAL(9,M12:M53) -> 2317700 | N10: =SUBTOTAL(9,N12:N53) -> 60260200000 | O10: =SUBTOTAL(9,O12:O53) -> 8.9287375e+10 | P10: =SUBTOTAL(9,P12:P53) -> -2.9027175e+10
A11: No. | B11: AM | C11: Manager | D11: Khách hàng | E11: Mã SP | F11: Tên sản phẩm | G11: Phân loại | H11: Mức IV | I11: Cam kết năm | J11: Mức độ khả thi | K11: SL bán T12 ( tấn) | L11: Giá bán đề xuất (USD) | M11: Doanh thu (USD) | N11: Doanh thu (VND) | O11: Giá vốn ( VND) | P11: LN gộp (VNĐ)
A12: 1 | B12: Quốc Anh | C12: Quốc Anh | D12: Niagara UK | E12: 110000354 | F12: Hạt nhựa rPET WSS01G 1 | G12: rPET | H12: 0.78 | I12: Đã có | J12: 1 | K12: 440 | L12: 1080 | M12: =K12*L12 -> 475200 | N12: =M12*$N$1 -> 12355200000 | O12: =K12*IFERROR(SUMIFS('tồn 30.11'!M:M,'tồn 30.11'!A:A,'Dự báo'!E12)/SUMIFS('tồn 30.11'!I:I,'tồn 30.11'!A:A,'Dự báo'!E12),0)*1000 -> 1.1635905e+10 | P12: =N12-O12 -> 7.1929451e+08
A13: =+A12+1 -> 2 | B13: Long | C13: Outeirinho | D13: NNG-CC - Unilever | E13: 110000354 | F13: Hạt nhựa rPET WSS01G 1 | G13: rPET | J13: 1 | K13: 330 | L13: 1280 | M13: =K13*L13 -> 422400 | N13: =M13*$N$1 -> 10982400000 | O13: =K13*IFERROR(SUMIFS('tồn 30.11'!M:M,'tồn 30.11'!A:A,'Dự báo'!E13)/SUMIFS('tồn 30.11'!I:I,'tồn 30.11'!A:A,'Dự báo'!E13),0)*1000 -> 8.7269291e+09 | P13: =N13-O13 -> 2.2554709e+09
A14: =+A13+1 -> 3 | B14: Cường | C14: Cường | D14: Suntory Pepsico Berverage CSD - SPFV | E14: 110000332 | F14: Hạt nhựa rPET iSS01084G | G14: rPET | H14: 0.84 | I14: Đã có | J14: 1 | K14: 550 | L14: =_xlfn.XLOOKUP(E14,'Trình bày'!B:B,'Trình bày'!H:H) -> 0 | M14: =K14*L14 -> 0 | N14: =M14*$N$1 -> 0 | O14: =K14*IFERROR(SUMIFS('tồn 30.11'!M:M,'tồn 30.11'!A:A,'Dự báo'!E14)/SUMIFS('tồn 30.11'!I:I,'tồn 30.11'!A:A,'Dự báo'!E14),0)*1000 -> 1.6703362e+10 | P14: =N14-O14 -> -1.6703362e+10
A15: =+A14+1 -> 4 | B15: Quỳnh Anh | C15: Cường | D15: Lavie | E15: 110000329 | F15: Hạt nhựa rPET WSS01 | G15: rPET | H15: 0 | I15: Chưa có | J15: 0.8 | K15: 88 | L15: =_xlfn.XLOOKUP(E15,'Trình bày'!B:B,'Trình bày'!H:H) -> 0 | M15: =K15*L15 -> 0 | N15: =M15*$N$1 -> 0 | O15: =K15*IFERROR(SUMIFS('tồn 30.11'!M:M,'tồn 30.11'!A:A,'Dự báo'!E15)/SUMIFS('tồn 30.11'!I:I,'tồn 30.11'!A:A,'Dự báo'!E15),0)*1000 -> 2.7372888e+09 | P15: =N15-O15 -> -2.7372888e+09
A16: =+A15+1 -> 5 | B16: Nghĩa | C16: Quốc Anh | D16: DTP - Unilever | E16: 110000339 | F16: Hạt Nhựa rHDPE MBF01 | G16: rHDPE | H16: 0.78 | I16: Đã có | J16: 1 | K16: 100 | L16: 1380 | M16: =K16*L16 -> 138000 | N16: =M16*$N$1 -> 3588000000 | O16: =K16*IFERROR(SUMIFS('tồn 30.11'!M:M,'tồn 30.11'!A:A,'Dự báo'!E16)/SUMIFS('tồn 30.11'!I:I,'tồn 30.11'!A:A,'Dự báo'!E16),0)*1000 -> 2.7100633e+09 | P16: =N16-O16 -> 8.7793666e+08
A17: =+A16+1 -> 6 | B17: Thông | C17: Quốc Anh | D17: Genesis Polymers International | E17: 110000332 | F17: Hạt nhựa rPET iSS01084G | G17: rPET | H17: #N/A | I17: Đã có | J17: 0.8 | K17: 66 | L17: =_xlfn.XLOOKUP(E17,'Trình bày'!B:B,'Trình bày'!H:H) -> 0 | M17: =K17*L17 -> 0 | N17: =M17*$N$1 -> 0 | O17: =K17*IFERROR(SUMIFS('tồn 30.11'!M:M,'tồn 30.11'!A:A,'Dự báo'!E17)/SUMIFS('tồn 30.11'!I:I,'tồn 30.11'!A:A,'Dự báo'!E17),0)*1000 -> 2.0044035e+09 | P17: =N17-O17 -> -2.0044035e+09
A18: =+A17+1 -> 7 | B18: Thông | C18: Quốc Anh | D18: NNG-TN - Unilever | E18: 110000354 | F18: Hạt nhựa rPET WSS01G 1 | G18: rPET | H18: 0.8 | J18: 0.8 | K18: 110 | L18: 1280 | M18: =K18*L18 -> 140800 | N18: =M18*$N$1 -> 3660800000 | O18: =K18*IFERROR(SUMIFS('tồn 30.11'!M:M,'tồn 30.11'!A:A,'Dự báo'!E18)/SUMIFS('tồn 30.11'!I:I,'tồn 30.11'!A:A,'Dự báo'!E18),0)*1000 -> 2.9089764e+09 | P18: =N18-O18 -> 7.5182363e+08
A19: =+A18+1 -> 8 | B19: Nghĩa | C19: Quốc Anh | D19: DTP - Plascene | E19: 110000354 | F19: Hạt nhựa rPET WSS01G 1 | G19: rPET | H19: 0.84 | I19: Chưa có | J19: 0.8 | K19: 88 | L19: 1080 | M19: =K19*L19 -> 95040 | N19: =M19*$N$1 -> 2471040000 | O19: =K19*IFERROR(SUMIFS('tồn 30.11'!M:M,'tồn 30.11'!A:A,'Dự báo'!E19)/SUMIFS('tồn 30.11'!I:I,'tồn 30.11'!A:A,'Dự báo'!E19),0)*1000 -> 2.3271811e+09 | P19: =N19-O19 -> 1.438589e+08
A20: =+A19+1 -> 9 | B20: Quỳnh Anh | C20: Cường | D20: Genesis Distribucion De Colombia | E20: 110000332 | F20: Hạt nhựa rPET iSS01084G | G20: rPET | H20: 0.55 | I20: Chưa có | J20: 0.8 | K20: 44 | L20: =_xlfn.XLOOKUP(E20,'Trình bày'!B:B,'Trình bày'!H:H) -> 0 | M20: =K20*L20 -> 0 | N20: =M20*$N$1 -> 0 | O20: =K20*IFERROR(SUMIFS('tồn 30.11'!M:M,'tồn 30.11'!A:A,'Dự báo'!E20)/SUMIFS('tồn 30.11'!I:I,'tồn 30.11'!A:A,'Dự báo'!E20),0)*1000 -> 1.336269e+09 | P20: =N20-O20 -> -1.336269e+09
A21: =+A20+1 -> 10 | B21: Nghĩa | C21: Quốc Anh | D21: Genesis Polymers International | E21: 110000355 | F21: Hạt nhựa rPET iSS01G 1 | G21: rPET | H21: 0.84 | J21: 0.8 | K21: 44 | L21: =_xlfn.XLOOKUP(E21,'Trình bày'!B:B,'Trình bày'!H:H) -> 0 | M21: =K21*L21 -> 0 | N21: =M21*$N$1 -> 0 | O21: =K21*IFERROR(SUMIFS('tồn 30.11'!M:M,'tồn 30.11'!A:A,'Dự báo'!E21)/SUMIFS('tồn 30.11'!I:I,'tồn 30.11'!A:A,'Dự báo'!E21),0)*1000 -> 1.1849759e+09 | P21: =N21-O21 -> -1.1849759e+09
A22: =+A21+1 -> 11 | B22: Nghĩa | C22: Quốc Anh | D22: Vilube - DTP | E22: 110000374 | F22: Hạt Nhựa rHDB03N02 | G22: rHDPE | H22: 0 | I22: Đã có | J22: 0.8 | K22: 55 | L22: =_xlfn.XLOOKUP(E22,'Trình bày'!B:B,'Trình bày'!H:H) -> 0 | M22: =K22*L22 -> 0 | N22: =M22*$N$1 -> 0 | O22: =K22*IFERROR(SUMIFS('tồn 30.11'!M:M,'tồn 30.11'!A:A,'Dự báo'!E22)/SUMIFS('tồn 30.11'!I:I,'tồn 30.11'!A:A,'Dự báo'!E22),0)*1000 -> 1.7706256e+09 | P22: =N22-O22 -> -1.7706256e+09
A23: =+A22+1 -> 12 | B23: Nghĩa | C23: Quốc Anh | D23: Nature Oragnics/PIA | E23: 110000354 | F23: Hạt nhựa rPET WSS01G 1 | G23: rPET | H23: 0.78 | I23: Đã có | J23: 0.8 | K23: 44 | L23: =_xlfn.XLOOKUP(E23,'Trình bày'!B:B,'Trình bày'!H:H) -> 0 | M23: =K23*L23 -> 0 | N23: =M23*$N$1 -> 0 | O23: =K23*IFERROR(SUMIFS('tồn 30.11'!M:M,'tồn 30.11'!A:A,'Dự báo'!E23)/SUMIFS('tồn 30.11'!I:I,'tồn 30.11'!A:A,'Dự báo'!E23),0)*1000 -> 1.1635905e+09 | P23: =N23-O23 -> -1.1635905e+09
A24: =+A23+1 -> 13 | B24: Thông | C24: Quốc Anh | D24: Huy Thành | E24: 110000366 | F24: Hạt nhựa rHDI3G01 | G24: rHDPE | H24: 0.78 | I24: Đã có | J24: 0.8 | K24: 33 | L24: =_xlfn.XLOOKUP(E24,'Trình bày'!B:B,'Trình bày'!H:H) -> 0 | M24: =K24*L24 -> 0 | N24: =M24*$N$1 -> 0 | O24: =K24*IFERROR(SUMIFS('tồn 30.11'!M:M,'tồn 30.11'!A:A,'Dự báo'!E24)/SUMIFS('tồn 30.11'!I:I,'tồn 30.11'!A:A,'Dự báo'!E24),0)*1000 -> 9.874464e+08 | P24: =N24-O24 -> -9.874464e+08
A25: =+A24+1 -> 14 | B25: Thông | C25: Quốc Anh | D25: MTVN Plastic ( Eatone Pro) | E25: 110000341 | F25: Hạt nhựa rHDB04B01 | G25: rHDPE | H25: 0.8 | I25: Chưa có | J25: 0.8 | K25: 33 | L25: =_xlfn.XLOOKUP(E25,'Trình bày'!B:B,'Trình bày'!H:H) -> 0 | M25: =K25*L25 -> 0 | N25: =M25*$N$1 -> 0 | O25: =K25*IFERROR(SUMIFS('tồn 30.11'!M:M,'tồn 30.11'!A:A,'Dự báo'!E25)/SUMIFS('tồn 30.11'!I:I,'tồn 30.11'!A:A,'Dự báo'!E25),0)*1000 -> 7.8571142e+08 | P25: =N25-O25 -> -7.8571142e+08
A26: =+A25+1 -> 15 | B26: Quỳnh Anh | C26: Cường | D26: Pentaplast | E26: 110000392 | F26: Hạt nhựa rPP20B01 | G26: rPP | H26: 0 | I26: Chưa có | J26: 0.8 | K26: 25 | L26: 605 | M26: =K26*L26 -> 15125 | N26: =M26*$N$1 -> 393250000 | O26: =K26*IFERROR(SUMIFS('tồn 30.11'!M:M,'tồn 30.11'!A:A,'Dự báo'!E26)/SUMIFS('tồn 30.11'!I:I,'tồn 30.11'!A:A,'Dự báo'!E26),0)*1000 -> 4.4519512e+08 | P26: =N26-O26 -> -51945123
A27: =+A26+1 -> 16 | B27: Thông | C27: Quốc Anh | D27: DTP | E27: 110000360 | F27: Hạt nhựa rHDI4L01 | G27: rHDPE | H27: 0.78 | I27: Đã có | J27: 0.8 | K27: 16.5 | L27: =_xlfn.XLOOKUP(E27,'Trình bày'!B:B,'Trình bày'!H:H) -> 0 | M27: =K27*L27 -> 0 | N27: =M27*$N$1 -> 0 | O27: =K27*IFERROR(SUMIFS('tồn 30.11'!M:M,'tồn 30.11'!A:A,'Dự báo'!E27)/SUMIFS('tồn 30.11'!I:I,'tồn 30.11'!A:A,'Dự báo'!E27),0)*1000 -> 4.5474103e+08 | P27: =N27-O27 -> -4.5474103e+08
A28: =+A27+1 -> 17 | B28: Nghĩa | C28: Quốc Anh | D28: DTP - Unilever | E28: 110000426 | F28: Hạt Nhựa HCBF-Yel-U | G28: rHDPE | H28: 0 | I28: Đã có | J28: 1 | K28: 22 | L28: 1330 | M28: =K28*L28 -> 29260 | N28: =M28*$N$1 -> 760760000 | O28: =K28*IFERROR(SUMIFS('tồn 30.11'!M:M,'tồn 30.11'!A:A,'Dự báo'!E28)/SUMIFS('tồn 30.11'!I:I,'tồn 30.11'!A:A,'Dự báo'!E28),0)*1000 -> 6.3213872e+08 | P28: =N28-O28 -> 1.2862128e+08
A29: =+A28+1 -> 18 | B29: Quỳnh Anh | C29: Cường | D29: Huy Thành | E29: 110000431 | F29: Hạt nhựa rHDI3Gy02 | G29: rHDPE | H29: 0.84 | I29: Chưa có | J29: 1 | K29: 11 | L29: =_xlfn.XLOOKUP(E29,'Trình bày'!B:B,'Trình bày'!H:H) -> 0 | M29: =K29*L29 -> 0 | N29: =M29*$N$1 -> 0 | O29: =K29*IFERROR(SUMIFS('tồn 30.11'!M:M,'tồn 30.11'!A:A,'Dự báo'!E29)/SUMIFS('tồn 30.11'!I:I,'tồn 30.11'!A:A,'Dự báo'!E29),0)*1000 -> 2.6193704e+08 | P29: =N29-O29 -> -2.6193704e+08
A30: =+A29+1 -> 19 | B30: Long | C30: Quốc Anh | D30: Tân Lập Thành | E30: 110000354 | F30: Hạt nhựa rPET WSS01G 1 | G30: rPET | H30: 0 | I30: Chưa có | J30: 0.8 | K30: 22 | L30: =_xlfn.XLOOKUP(E30,'Trình bày'!B:B,'Trình bày'!H:H) -> 0 | M30: =K30*L30 -> 0 | N30: =M30*$N$1 -> 0 | O30: =K30*IFERROR(SUMIFS('tồn 30.11'!M:M,'tồn 30.11'!A:A,'Dự báo'!E30)/SUMIFS('tồn 30.11'!I:I,'tồn 30.11'!A:A,'Dự báo'!E30),0)*1000 -> 5.8179527e+08 | P30: =N30-O30 -> -5.8179527e+08
A31: =+A30+1 -> 20 | B31: Thông | C31: Quốc Anh | D31: Nhựa Trường An | E31: 110000407 | F31: Vảy HD ép Đỏ | G31: rHDPE | H31: 0.8 | I31: Đã có | J31: 1 | K31: 12 | L31: =_xlfn.XLOOKUP(E31,'Trình bày'!B:B,'Trình bày'!H:H) -> 0 | M31: =K31*L31 -> 0 | N31: =M31*$N$1 -> 0 | O31: =K31*IFERROR(SUMIFS('tồn 30.11'!M:M,'tồn 30.11'!A:A,'Dự báo'!E31)/SUMIFS('tồn 30.11'!I:I,'tồn 30.11'!A:A,'Dự báo'!E31),0)*1000 -> 4.9817545e+08 | P31: =N31-O31 -> -4.9817545e+08
A32: =+A31+1 -> 21 | B32: Nghĩa | C32: Quốc Anh | D32: Koryfes | E32: 110000443 | F32: Hạt Nhựa rHDA03N01 | G32: rHDPE | H32: 0 | I32: Đã có | J32: 0.8 | K32: 99 | L32: =_xlfn.XLOOKUP(E32,'Trình bày'!B:B,'Trình bày'!H:H) -> 0 | M32: =K32*L32 -> 0 | N32: =M32*$N$1 -> 0 | O32: =K32*IFERROR(SUMIFS('tồn 30.11'!M:M,'tồn 30.11'!A:A,'Dự báo'!E32)/SUMIFS('tồn 30.11'!I:I,'tồn 30.11'!A:A,'Dự báo'!E32),0)*1000 -> 2.9835169e+09 | P32: =N32-O32 -> -2.9835169e+09
A33: =+A32+1 -> 22 | B33: Thông | C33: Quốc Anh | D33: Nhựa Trường An | E33: 110000408 | F33: Vảy HD Ép Trắng | G33: rHDPE | H33: 0.78 | I33: Chưa có | J33: 1 | K33: 6 | L33: =_xlfn.XLOOKUP(E33,'Trình bày'!B:B,'Trình bày'!H:H) -> 0 | M33: =K33*L33 -> 0 | N33: =M33*$N$1 -> 0 | O33: =K33*IFERROR(SUMIFS('tồn 30.11'!M:M,'tồn 30.11'!A:A,'Dự báo'!E33)/SUMIFS('tồn 30.11'!I:I,'tồn 30.11'!A:A,'Dự báo'!E33),0)*1000 -> 1.4554445e+08 | P33: =N33-O33 -> -1.4554445e+08
A34: =+A33+1 -> 23 | B34: Quỳnh Anh | C34: Cường | D34: DNP - Unilever | E34: 110000339 | F34: Hạt Nhựa rHDPE MBF01 | G34: rHDPE | H34: 0 | I34: Chưa có | J34: 1 | K34: 40 | L34: 1380 | M34: =K34*L34 -> 55200 | N34: =M34*$N$1 -> 1435200000 | O34: =K34*IFERROR(SUMIFS('tồn 30.11'!M:M,'tồn 30.11'!A:A,'Dự báo'!E34)/SUMIFS('tồn 30.11'!I:I,'tồn 30.11'!A:A,'Dự báo'!E34),0)*1000 -> 1.0840253e+09 | P34: =N34-O34 -> 3.5117467e+08
A35: =+A34+1 -> 24 | B35: Cường | C35: Cường | D35: DTP - Unilever | E35: 110000481 | F35: Hạt Nhựa rHDPE PCF01 | G35: rHDPE | H35: 0 | I35: Đã có | J35: 1 | K35: 20 | L35: 1380 | M35: =K35*L35 -> 27600 | N35: =M35*$N$1 -> 717600000 | O35: =K35*IFERROR(SUMIFS('tồn 30.11'!M:M,'tồn 30.11'!A:A,'Dự báo'!E35)/SUMIFS('tồn 30.11'!I:I,'tồn 30.11'!A:A,'Dự báo'!E35),0)*1000 -> 5.6040437e+08 | P35: =N35-O35 -> 1.5719563e+08
A36: =+A35+1 -> 25 | B36: Quỳnh Anh | C36: Cường | D36: DTP - Unilever | E36: 110000354 | F36: Hạt nhựa rPET WSS01G 1 | G36: rPET | H36: 0 | I36: Chưa có | J36: 1 | K36: 11 | L36: 1280 | M36: =K36*L36 -> 14080 | N36: =M36*$N$1 -> 366080000 | O36: =K36*IFERROR(SUMIFS('tồn 30.11'!M:M,'tồn 30.11'!A:A,'Dự báo'!E36)/SUMIFS('tồn 30.11'!I:I,'tồn 30.11'!A:A,'Dự báo'!E36),0)*1000 -> 2.9089764e+08 | P36: =N36-O36 -> 75182363
A37: =+A36+1 -> 26 | B37: Quỳnh Anh | C37: Cường | D37: Huy Thành | E37: 110000361 | F37: Hạt nhựa rHDI3R01 | G37: rHDPE | H37: 0.8 | I37: Chưa có | J37: 1 | K37: 11 | L37: =_xlfn.XLOOKUP(E37,'Trình bày'!B:B,'Trình bày'!H:H) -> 0 | M37: =K37*L37 -> 0 | N37: =M37*$N$1 -> 0 | O37: =K37*IFERROR(SUMIFS('tồn 30.11'!M:M,'tồn 30.11'!A:A,'Dự báo'!E37)/SUMIFS('tồn 30.11'!I:I,'tồn 30.11'!A:A,'Dự báo'!E37),0)*1000 -> 2.3504966e+08 | P37: =N37-O37 -> -2.3504966e+08
A38: =+A37+1 -> 27 | B38: Long | C38: Quốc Anh | D38: Mondelez Việt Nam | E38: 110000355 | F38: Hạt nhựa rPET iSS01G 1 | G38: rPET | H38: 0 | I38: Chưa có | J38: 0.8 | K38: 11 | L38: =_xlfn.XLOOKUP(E38,'Trình bày'!B:B,'Trình bày'!H:H) -> 0 | M38: =K38*L38 -> 0 | N38: =M38*$N$1 -> 0 | O38: =K38*IFERROR(SUMIFS('tồn 30.11'!M:M,'tồn 30.11'!A:A,'Dự báo'!E38)/SUMIFS('tồn 30.11'!I:I,'tồn 30.11'!A:A,'Dự báo'!E38),0)*1000 -> 2.9624397e+08 | P38: =N38-O38 -> -2.9624397e+08
A39: =+A38+1 -> 28 | B39: Cường | C39: Cường | D39: Nhựa Văn Minh | E39: 110000408 | F39: Vảy HD Ép Trắng | G39: rHDPE | H39: 0 | I39: Đã có | J39: 1 | K39: 33 | L39: =_xlfn.XLOOKUP(E39,'Trình bày'!B:B,'Trình bày'!H:H) -> 0 | M39: =K39*L39 -> 0 | N39: =M39*$N$1 -> 0 | O39: =K39*IFERROR(SUMIFS('tồn 30.11'!M:M,'tồn 30.11'!A:A,'Dự báo'!E39)/SUMIFS('tồn 30.11'!I:I,'tồn 30.11'!A:A,'Dự báo'!E39),0)*1000 -> 8.0049449e+08 | P39: =N39-O39 -> -8.0049449e+08
A40: =+A39+1 -> 29 | B40: Cường | C40: Cường | D40: Huy Thành | E40: 110000364 | F40: Hạt nhựa rHDI3Y01 | G40: rHDPE | H40: 0 | J40: 1 | K40: 10.5 | L40: =_xlfn.XLOOKUP(E40,'Trình bày'!B:B,'Trình bày'!H:H) -> 0 | M40: =K40*L40 -> 0 | N40: =M40*$N$1 -> 0 | O40: =K40*IFERROR(SUMIFS('tồn 30.11'!M:M,'tồn 30.11'!A:A,'Dự báo'!E40)/SUMIFS('tồn 30.11'!I:I,'tồn 30.11'!A:A,'Dự báo'!E40),0)*1000 -> 2.4588776e+08 | P40: =N40-O40 -> -2.4588776e+08
A41: =+A40+1 -> 30 | B41: Quỳnh Anh | C41: Cường | D41: DTP | E41: 110000361 | F41: Hạt nhựa rHDI3R01 | G41: rHDPE | H41: 0 | I41: Chưa có | J41: 0.8 | K41: 5.5 | L41: =_xlfn.XLOOKUP(E41,'Trình bày'!B:B,'Trình bày'!H:H) -> 0 | M41: =K41*L41 -> 0 | N41: =M41*$N$1 -> 0 | O41: =K41*IFERROR(SUMIFS('tồn 30.11'!M:M,'tồn 30.11'!A:A,'Dự báo'!E41)/SUMIFS('tồn 30.11'!I:I,'tồn 30.11'!A:A,'Dự báo'!E41),0)*1000 -> 1.1752483e+08 | P41: =N41-O41 -> -1.1752483e+08
...

Sheet tồn 30.11
A1: Material | B1: Material Description | C1: BUn | D1: From Date | E1: To Date | F1: Opening Sto | G1: Total Recei | H1: Total Issue | I1: Closing Sto | J1: Opening Value | K1: Total Receipt Va | L1: Total Issue Valu | M1: Closing Value | N1: Crcy
A2: 110000329 | B2: Hạt nhựa rPET WSS01 | C2: KG | D2: 30.11.2025 | E2: 30.11.2025 | F2: 448252.3 | G2: 0 | H2: 0 | I2: 448252.3 | J2: 11533979931 | K2: 2409156226 | L2: 0 | M2: 13943136157 | N2: VND
A3: 110000330 | B3: Hạt nhựa rPET iSS01 | C3: KG | D3: 30.11.2025 | E3: 30.11.2025 | F3: 0 | G3: 0 | H3: 0 | I3: 0 | J3: 0 | K3: 0 | L3: 0 | M3: 0 | N3: VND
A4: 110000331 | B4: Hạt nhựa rPET WSS02 | C4: KG | D4: 30.11.2025 | E4: 30.11.2025 | F4: 0 | G4: 0 | H4: 0 | I4: 0 | J4: 0 | K4: 0 | L4: 0 | M4: 0 | N4: VND
A5: 110000332 | B5: Hạt nhựa rPET iSS01084G | C5: KG | D5: 30.11.2025 | E5: 30.11.2025 | F5: 1354251.4 | G5: 29700 | H5: -34100 | I5: 1349851.4 | J5: 35707546665 | K5: 6186217493 | L5: -899114700 | M5: 40994649458 | N5: VND
A6: 110000333 | B6: Hạt nhựa rPET WSS03 | C6: KG | D6: 30.11.2025 | E6: 30.11.2025 | F6: 2269 | G6: 0 | H6: 0 | I6: 2269 | J6: 56257586 | K6: 0 | L6: -941628 | M6: 55315958 | N6: VND
A7: 110000334 | B7: Hạt nhựa rPET SS03 | C7: KG | D7: 30.11.2025 | E7: 30.11.2025 | F7: 0 | G7: 0 | H7: 0 | I7: 0 | J7: 0 | K7: 0 | L7: 0 | M7: 0 | N7: VND
A8: 110000335 | B8: Hạt nhựa rPET WSS04 | C8: KG | D8: 30.11.2025 | E8: 30.11.2025 | F8: 4420.7 | G8: 0 | H8: 0 | I8: 4420.7 | J8: 104178216 | K8: 15943950 | L8: 0 | M8: 120122166 | N8: VND
A9: 110000336 | B9: Hạt nhựa rHDPE thử nghiệm | C9: KG | D9: 30.11.2025 | E9: 30.11.2025 | F9: 6611.1 | G9: 5811 | H9: -5811 | I9: 6611.1 | J9: 168774772 | K9: 148349019 | L9: -164502981 | M9: 152620810 | N9: VND
A10: 110000337 | B10: Hạt Nhựa rHDB03W01 | C10: KG | D10: 30.11.2025 | E10: 30.11.2025 | F10: 9199.8 | G10: 0 | H10: 0 | I10: 9199.8 | J10: 254632064 | K10: 15668163 | L10: 0 | M10: 270300227 | N10: VND
A11: 110000338 | B11: Hạt nhựa rPET SS05 | C11: KG | D11: 30.11.2025 | E11: 30.11.2025 | F11: 0 | G11: 0 | H11: 0 | I11: 0 | J11: 0 | K11: 0 | L11: 0 | M11: 0 | N11: VND
A12: 110000339 | B12: Hạt Nhựa rHDPE MBF01 | C12: KG | D12: 30.11.2025 | E12: 30.11.2025 | F12: 526562.3 | G12: 25600 | H12: 0 | I12: 552162.3 | J12: 15663122176 | K12: 761497600 | L12: -1460671722 | M12: 14963948054 | N12: VND
A13: 110000340 | B13: Hạt nhựa rHDPE MBF02 | C13: KG | D13: 30.11.2025 | E13: 30.11.2025 | F13: 0 | G13: 0 | H13: 0 | I13: 0 | J13: 0 | K13: 0 | L13: 0 | M13: 0 | N13: VND
... A180: 110000510 | B180: Hạt Nhựa rPET WSS05SB PL | C180: KG | D180: 30.11.2025 | E180: 30.11.2025 | F180: 28348 | G180: 0 | H180: 0 | I180: 28348 | J180: 640664800 | K180: 20868543 | L180: 0 | M180: 661533343 | N180: VND

Sheet tồn TP 24.02
H1: =SUBTOTAL(9,H3:H944) -> 2773739.5 | K1: =SUBTOTAL(9,K3:K99) -> 3580725
A2: Material | B2: Material Description | C2: Storage Location | D2: Descr. of Storage Loc. | E2: Base Unit of Measure | F2: Unrestricted | G2: Blocked | H2: Tồn 24/02 | I2: Phân loại | J2: Màu | K2: SL bán 2026 | L2: SL bán BQ/ tháng | M2: Check file bán
A3: 110000329 | B3: Hạt nhựa rPET WSS01 | C3: 1301 | D3: Kho Thành phẩm | E3: KG | F3: 204834 | G3: 3300 | H3: =+F3+G3 -> 208134 | I3: =IFERROR(_xlfn.XLOOKUP(A3,data!A:A,data!D:D)," ") -> rPET | J3: =IFERROR(_xlfn.XLOOKUP(A3,data!A:A,data!E:E)," ") -> 0 | K3: 0 | L3: =IFERROR(K3/1,0) -> 0 | M3: =VLOOKUP(A3,'Trình bày'!B:B,1,0) -> 110000329
A4: 110000329 | B4: Hạt nhựa rPET WSS01 | C4: 1303 | D4: Kho Thành phẩm 2 | E4: KG | F4: 163428 | G4: 6600 | H4: =+F4+G4 -> 170028 | I4: =IFERROR(_xlfn.XLOOKUP(A4,data!A:A,data!D:D)," ") -> rPET | J4: =IFERROR(_xlfn.XLOOKUP(A4,data!A:A,data!E:E)," ") -> 0 | K4: 0 | L4: =IFERROR(K4/1,0) -> 0 | M4: =VLOOKUP(A4,'Trình bày'!B:B,1,0) -> 110000329
A5: 110000332 | B5: Hạt nhựa rPET iSS01084G | C5: 1301 | D5: Kho Thành phẩm | E5: KG | F5: 542023.5 | G5: 17654 | H5: =+F5+G5 -> 559677.5 | I5: =IFERROR(_xlfn.XLOOKUP(A5,data!A:A,data!D:D)," ") -> rPET | J5: =IFERROR(_xlfn.XLOOKUP(A5,data!A:A,data!E:E)," ") -> 0 | K5: 616000 | L5: =IFERROR(K5/1,0) -> 616000 | M5: =VLOOKUP(A5,'Trình bày'!B:B,1,0) -> 110000332
A6: 110000332 | B6: Hạt nhựa rPET iSS01084G | C6: 1303 | D6: Kho Thành phẩm 2 | E6: KG | F6: 5500 | G6: 221312 | H6: =+F6+G6 -> 226812 | I6: =IFERROR(_xlfn.XLOOKUP(A6,data!A:A,data!D:D)," ") -> rPET | J6: =IFERROR(_xlfn.XLOOKUP(A6,data!A:A,data!E:E)," ") -> 0 | K6: 616000 | L6: =IFERROR(K6/1,0) -> 616000 | M6: =VLOOKUP(A6,'Trình bày'!B:B,1,0) -> 110000332
A7: 110000332 | B7: Hạt nhựa rPET iSS01084G | C7: 1306 | D7: Kho Xuất bán | E7: KG | F7: 2141.85 | G7: 0 | H7: =+F7+G7 -> 2141.85 | I7: =IFERROR(_xlfn.XLOOKUP(A7,data!A:A,data!D:D)," ") -> rPET | J7: =IFERROR(_xlfn.XLOOKUP(A7,data!A:A,data!E:E)," ") -> 0 | K7: 616000 | L7: =IFERROR(K7/1,0) -> 616000 | M7: =VLOOKUP(A7,'Trình bày'!B:B,1,0) -> 110000332
A8: 110000336 | B8: Hạt nhựa rHDPE thử nghiệm | C8: 1303 | D8: Kho Thành phẩm 2 | E8: KG | F8: 1382.9 | G8: 9921 | H8: =+F8+G8 -> 11303.9 | I8: =IFERROR(_xlfn.XLOOKUP(A8,data!A:A,data!D:D)," ") -> HD thổi | J8: =IFERROR(_xlfn.XLOOKUP(A8,data!A:A,data!E:E)," ") -> 0 | K8: 0 | L8: =IFERROR(K8/1,0) -> 0 | M8: =VLOOKUP(A8,'Trình bày'!B:B,1,0) -> 110000336
A9: 110000337 | B9: Hạt Nhựa rHDB03W01 | C9: 1205 | D9: Xưởng F2 HD/PP | E9: KG | F9: 350 | G9: 0 | H9: =+F9+G9 -> 350 | I9: =IFERROR(_xlfn.XLOOKUP(A9,data!A:A,data!D:D)," ") -> HD thổi | J9: =IFERROR(_xlfn.XLOOKUP(A9,data!A:A,data!E:E)," ") -> Trắng | K9: 0 | L9: =IFERROR(K9/1,0) -> 0 | M9: =VLOOKUP(A9,'Trình bày'!B:B,1,0) -> 110000337
A10: 110000339 | B10: Hạt Nhựa rHDPE MBF01 | C10: 1205 | D10: Xưởng F2 HD/PP | E10: KG | F10: 9416 | G10: 0 | H10: =+F10+G10 -> 9416 | I10: =IFERROR(_xlfn.XLOOKUP(A10,data!A:A,data!D:D)," ") -> HD thổi | J10: =IFERROR(_xlfn.XLOOKUP(A10,data!A:A,data!E:E)," ") -> Trong | K10: 211750 | L10: =IFERROR(K10/1,0) -> 211750 | M10: =VLOOKUP(A10,'Trình bày'!B:B,1,0) -> 110000339
A11: 110000339 | B11: Hạt Nhựa rHDPE MBF01 | C11: 1303 | D11: Kho Thành phẩm 2 | E11: KG | F11: 234462.5 | G11: 137998 | H11: =+F11+G11 -> 372460.5 | I11: =IFERROR(_xlfn.XLOOKUP(A11,data!A:A,data!D:D)," ") -> HD thổi | J11: =IFERROR(_xlfn.XLOOKUP(A11,data!A:A,data!E:E)," ") -> Trong | K11: 211750 | L11: =IFERROR(K11/1,0) -> 211750 | M11: =VLOOKUP(A11,'Trình bày'!B:B,1,0) -> 110000339
A12: 110000339 | B12: Hạt Nhựa rHDPE MBF01 | C12: 1306 | D12: Kho Xuất bán | E12: KG | F12: 20625 | G12: 1575 | H12: =+F12+G12 -> 22200 | I12: =IFERROR(_xlfn.XLOOKUP(A12,data!A:A,data!D:D)," ") -> HD thổi | J12: =IFERROR(_xlfn.XLOOKUP(A12,data!A:A,data!E:E)," ") -> Trong | K12: 211750 | L12: =IFERROR(K12/1,0) -> 211750 | M12: =VLOOKUP(A12,'Trình bày'!B:B,1,0) -> 110000339
A13: 110000341 | B13: Hạt nhựa rHDB04B01 | C13: 1301 | D13: Kho Thành phẩm | E13: KG | F13: 15000 | G13: 0 | H13: =+F13+G13 -> 15000 | I13: =IFERROR(_xlfn.XLOOKUP(A13,data!A:A,data!D:D)," ") -> HD thổi | J13: =IFERROR(_xlfn.XLOOKUP(A13,data!A:A,data!E:E)," ") -> Đen | K13: 15625 | L13: =IFERROR(K13/1,0) -> 15625 | M13: =VLOOKUP(A13,'Trình bày'!B:B,1,0) -> 110000341
A14: 110000341 | B14: Hạt nhựa rHDB04B01 | C14: 1303 | D14: Kho Thành phẩm 2 | E14: KG | F14: 141975.5 | G14: 2350 | H14: =+F14+G14 -> 144325.5 | I14: =IFERROR(_xlfn.XLOOKUP(A14,data!A:A,data!D:D)," ") -> HD thổi | J14: =IFERROR(_xlfn.XLOOKUP(A14,data!A:A,data!E:E)," ") -> Đen | K14: 15625 | L14: =IFERROR(K14/1,0) -> 15625 | M14: =VLOOKUP(A14,'Trình bày'!B:B,1,0) -> 110000341
... A139: 110000510 | B139: Hạt Nhựa rPET WSS05SB PL | C139: 1303 | D139: Kho Thành phẩm 2 | E139: KG | F139: 32548 | G139: 0 | H139: =+F139+G139 -> 32548 | I139: =IFERROR(_xlfn.XLOOKUP(A139,data!A:A,data!D:D)," ") -> Xơ sợi | J139: =IFERROR(_xlfn.XLOOKUP(A139,data!A:A,data!E:E)," ") -> 0 | K139: 0 | L139: =IFERROR(K139/1,0) -> 0 | M139: =VLOOKUP(A139,'Trình bày'!B:B,1,0) -> #N/A

Sheet data
A1: Material | B1: Material Description | C1: BUn | D1: PL | E1: Màu
A2: 110000378 | B2: Hạt nhựa rPET iSS01G 2 | C2: KG | D2: rPET
A3: 110000377 | B3: Hạt nhựa rPET WSS01G 2 | C3: KG | D3: rPET
A4: 110000354 | B4: Hạt nhựa rPET WSS01G 1 | C4: KG | D4: rPET
A5: 110000492 | B5: Hạt Nhựa rPET WSS03G PL | C5: KG | D5: rPET
A6: 110000355 | B6: Hạt nhựa rPET iSS01G 1 | C6: KG | D6: rPET
A7: 110000483 | B7: Hạt Nhựa rPET iSS01G-S | C7: KG | D7: rPET
A8: 110000339 | B8: Hạt Nhựa rHDPE MBF01 | C8: KG | D8: HD thổi | E8: Trong
A9: 110000426 | B9: Hạt Nhựa HCBF-Yel-U | C9: KG | D9: HD thổi | E9: Vàng
A10: 110000374 | B10: Hạt Nhựa rHDB03N02 | C10: KG | D10: HD thổi | E10: Trong
A11: 110000481 | B11: Hạt Nhựa rHDPE PCF01 | C11: KG | D11: HD thổi | E11: Trong
A12: 110000341 | B12: Hạt nhựa rHDB04B01 | C12: KG | D12: HD thổi | E12: Đen
A13: 110000425 | B13: Hạt Nhựa HCBF-Whi-U | C13: KG | D13: HD thổi | E13: Trắng
A14: 110000383 | B14: Hạt Nhựa rPET iSS84G-P | C14: KG | D14: rPET
A15: 110000484 | B15: Hạt Nhựa rPET WSS01G 1 PL | C15: KG | D15: rPET
A16: 110000335 | B16: Hạt nhựa rPET WSS04 | C16: KG | D16: rPET
A17: 110000358 | B17: Hạt nhựa rPET WSS02G | C17: KG | D17: rPET
A18: 110000360 | B18: Hạt nhựa rHDI4L01 | C18: KG | D18: HD ép | E18: Dương
A19: 110000366 | B19: Hạt nhựa rHDI3G01 | C19: KG | D19: HD ép | E19: Lá
A20: 110000361 | B20: Hạt nhựa rHDI3R01 | C20: KG | D20: HD ép | E20: Đỏ
A21: 110000496 | B21: Hạt Nhựa rHDI7DL02 | C21: KG | D21: HD ép | E21: Dương
A22: 110000364 | B22: Hạt nhựa rHDI3Y01 | C22: KG | D22: HD ép | E22: Vàng
A23: 110000365 | B23: Hạt nhựa rHDI3W01 | C23: KG | D23: HD ép | E23: Trắng
A24: 110000389 | B24: Hạt nhựa rPP20R02 | C24: KG | D24: rPP | E24: Đỏ
A25: 110000471 | B25: Hạt Nhựa rPP20L05 | C25: KG | D25: rPP | E25: Dương
A26: 110000472 | B26: Hạt Nhựa rPP20Gy01 | C26: KG | D26: rPP | E26: Xám
A27: 110000392 | B27: Hạt nhựa rPP20B01 | C27: KG | D27: rPP | E27: Đen
A28: 110000363 | B28: Hạt nhựa rHDI3Gy01 | C28: KG | D28: HD ép | E28: Xám
A29: 110000495 | B29: Hạt Nhựa rHDA03W01 | C29: KG | D29: HD thổi | E29: Trắng
A30: 110000430 | B30: Hạt Nhựa rPET Bán Thành Phẩm | C30: KG | D30: rPET
A31: 110000468 | B31: Hạt Nhựa rPET iSS80G-P | C31: KG | D31: rPET
A32: 110000500 | B32: Hạt Nhựa rPET WSS01L PL | C32: KG | D32: rPET
A33: 110000381 | B33: Hạt nhựa rPET WSS04SD | C33: KG | D33: Xơ sợi
A34: 110000382 | B34: Hạt nhựa rPET WSS04SB | C34: KG | D34: Xơ sợi
A35: 110000332 | B35: Hạt nhựa rPET iSS01084G | C35: KG | D35: rPET
A36: 110000384 | B36: Hạt Nhựa Xơ Sợi Thử Nghiệm | C36: KG | D36: Xơ sợi
A37: 110000336 | B37: Hạt nhựa rHDPE thử nghiệm | C37: KG | D37: HD thổi
A38: 110000387 | B38: Hạt nhựa rPET WSS03SD | C38: KG | D38: Xơ sợi
A39: 110000435 | B39: Hạt Nhựa rPP20L03 | C39: KG | D39: rPP | E39: Dương
A40: 110000482 | B40: Hạt Nhựa rPP20W01 | C40: KG | D40: rPP | E40: Trắng
...
