Workbook
Name \A: #REF!
Name \M: #REF!
Name ___ATS98: #REF!
Name ___BGT02: #REF!
Name ___CHF98: #REF!
Name ___CHX2002: #REF!
Name ___CHX2003: #REF!
Name ___CHX2004: #REF!
Name ___CHX2005: #REF!
Name ___DTB2003: #REF!
Name ___DTB2004: #REF!
Name ___LY01: #REF!
Name ___Mkt1: #REF!
Name ___VAR1: #REF!
Name ___VAR2: #REF!
Name ___var22: #REF!
Name ___VAR3: #REF!
Name ___VAR4: #REF!
Name ___VAR5: #REF!
Name ___VAR6: #REF!
Name ___VAR7: #REF!
Name __ATS98: #REF!
Name __BGT02: #REF!
Name __CHF98: #REF!
Name __CHX2002: #REF!
Name __CHX2003: #REF!
Name __CHX2004: #REF!
Name __CHX2005: #REF!
Name __DAT1: #REF!
Name __DAT10: #REF!
Name __DAT11: #REF!
Name __DAT12: #REF!
Name __DAT13: #REF!
Name __DAT14: #REF!
Name __DAT15: #REF!
Name __DAT16: #REF!
Name __DAT17: #REF!
Name __DAT18: #REF!
Name __DAT19: #REF!
Name __DAT2: #REF!
Name __DAT20: #REF!
Name __DAT21: #REF!
Name __DAT22: #REF!
Name __DAT23: #REF!
Name __DAT24: #REF!
Name __DAT25: #REF!
Name __DAT26: #REF!
Name __DAT27: #REF!
Name __DAT28: #REF!
Name __DAT29: #REF!
Name __DAT3: #REF!
Name __DAT30: #REF!
Name __DAT31: #REF!
Name __DAT32: #REF!
Name __DAT33: #REF!
Name __DAT34: #REF!
Name __DAT35: #REF!
Name __DAT36: #REF!
Name __DAT37: #REF!
Name __DAT38: #REF!

Sheet Trình bày
B1: DANH MỤC THÀNH PHẨM
A4: STT | B4: Mã SAP | C4: Tên hàng hóa | D4: Màu | E4: Tồn kho 17/04/2026 (kg) | F4: Số lượng bán BQ 2026 (kg/ tháng) | G4: Giá duyệt T4 (USD/ tấn) | H4: Giá bán đề nghị T5 (USD/ tấn) | I4: CL T5 sv T4 (USD/ tấn) | J4: Giá vốn | K4: Lợi nhuận trước thuế | L4: % lợi nhuận trước thuế | M4: Giá đề nghị của kinh doanh | N4: Ghi chú | O4: Sử dụng phó sản
A5: A | B5: rPET
A6: I | B6: MÃ HÀNG ĐANG BÁN
A7: 1 | B7: 110000354 | C7: Hạt nhựa rPET WSS01G 1 | E7: =SUMIFS('tồn TP 17.04'!F:F,'tồn TP 17.04'!A:A,'Trình bày'!B7) -> 737486 | F7: =IFERROR(_xlfn.XLOOKUP(B7,'tồn TP 17.04'!A:A,'tồn TP 17.04'!J:J),0) -> 2156000 | G7: 1280 | H7: 1380 | I7: =H7-G7 -> 100 | J7: 1157 | K7: =(H7-J7) -> 223 | L7: =+K7/H7 -> 0.1615942
A8: =+A7+1 -> 2 | B8: 110000355 | C8: Hạt nhựa rPET iSS01G 1 | E8: =SUMIFS('tồn TP 17.04'!F:F,'tồn TP 17.04'!A:A,'Trình bày'!B8) -> 70122.75 | F8: =IFERROR(_xlfn.XLOOKUP(B8,'tồn TP 17.04'!A:A,'tồn TP 17.04'!J:J),0) -> 198016.67 | G8: =+G7+30 -> 1310 | H8: =+H7+30 -> 1410 | I8: =H8-G8 -> 100 | J8: =+J7 -> 1157 | K8: =(H8-J8) -> 253 | L8: =+K8/H8 -> 0.17943262
A9: =+A8+1 -> 3 | B9: 110000332 | C9: Hạt nhựa rPET iSS01084G | E9: =SUMIFS('tồn TP 17.04'!F:F,'tồn TP 17.04'!A:A,'Trình bày'!B9) -> 428988.2 | F9: =IFERROR(_xlfn.XLOOKUP(B9,'tồn TP 17.04'!A:A,'tồn TP 17.04'!J:J),0) -> 595466.67 | G9: =G7+90 -> 1370 | H9: =H7+90 -> 1470 | I9: =H9-G9 -> 100 | J9: 1221 | K9: =(H9-J9) -> 249 | L9: =+K9/H9 -> 0.16938776
A10: =+A9+1 -> 4 | B10: 110000359 | C10: Hạt nhựa rPET WSS03G | E10: =SUMIFS('tồn TP 17.04'!F:F,'tồn TP 17.04'!A:A,'Trình bày'!B10) -> 1911089.5 | F10: =IFERROR(_xlfn.XLOOKUP(B10,'tồn TP 17.04'!A:A,'tồn TP 17.04'!J:J),0) -> 303283.33 | G10: =+G7-70 -> 1210 | H10: =+H7-70 -> 1310 | I10: =H10-G10 -> 100 | J10: =+J7 -> 1157 | K10: =(H10-J10) -> 153 | L10: =+K10/H10 -> 0.11679389
A11: =+A10+1 -> 5 | B11: 110000329 | C11: Hạt nhựa rPET WSS01 | E11: =SUMIFS('tồn TP 17.04'!F:F,'tồn TP 17.04'!A:A,'Trình bày'!B11) -> 384888 | F11: =IFERROR(_xlfn.XLOOKUP(B11,'tồn TP 17.04'!A:A,'tồn TP 17.04'!J:J),0) -> 36666.667 | G11: 1290 | H11: 1290 | I11: =H11-G11 -> 0 | J11: 1239 | K11: =(H11-J11) -> 51 | L11: =+K11/H11 -> 0.039534884 | N11: Bán cho Lavie
A12: =+A11+1 -> 6 | B12: 110000497 | C12: Hạt Nhựa rPET WSS01G-L | E12: =SUMIFS('tồn TP 17.04'!F:F,'tồn TP 17.04'!A:A,'Trình bày'!B12) -> 0 | F12: =IFERROR(_xlfn.XLOOKUP(B12,'tồn TP 17.04'!A:A,'tồn TP 17.04'!J:J),0) -> 0 | I12: =H12-G12 -> 0 | K12: =(H12-J12) -> 0
A13: =+A12+1 -> 7 | B13: 110000499 | C13: Hạt Nhựa rPET WSS01L | E13: =SUMIFS('tồn TP 17.04'!F:F,'tồn TP 17.04'!A:A,'Trình bày'!B13) -> 28530 | F13: =IFERROR(_xlfn.XLOOKUP(B13,'tồn TP 17.04'!A:A,'tồn TP 17.04'!J:J),0) -> 1833.3333 | G13: =G7 -> 1280 | H13: =H7 -> 1380 | I13: =H13-G13 -> 100 | J13: 1056 | K13: =(H13-J13) -> 324 | L13: =+K13/H13 -> 0.23478261
A14: =+A13+1 -> 8 | B14: 110000503 | C14: Hạt Nhựa rPET WSS01S | E14: =SUMIFS('tồn TP 17.04'!F:F,'tồn TP 17.04'!A:A,'Trình bày'!B14) -> 0 | F14: =IFERROR(_xlfn.XLOOKUP(B14,'tồn TP 17.04'!A:A,'tồn TP 17.04'!J:J),0) -> 0 | I14: =H14-G14 -> 0 | K14: =(H14-J14) -> 0
A15: =+A14+1 -> 9 | B15: 110000506 | C15: Hạt Nhựa rPET WSS01 & WSS01G-L | E15: =SUMIFS('tồn TP 17.04'!F:F,'tồn TP 17.04'!A:A,'Trình bày'!B15) -> 65840 | F15: =IFERROR(_xlfn.XLOOKUP(B15,'tồn TP 17.04'!A:A,'tồn TP 17.04'!J:J),0) -> 0 | I15: =H15-G15 -> 0 | J15: =32400/26.5 -> 1222.6415 | K15: =(H15-J15) -> -1222.6415 | L15: =+K15/H15 -> #DIV/0! | O15: Giá tồn kho
A16: =+A14+1 -> 9 | B16: 110000483 | C16: Hạt Nhựa rPET iSS01G-S | E16: =SUMIFS('tồn TP 17.04'!F:F,'tồn TP 17.04'!A:A,'Trình bày'!B16) -> 1035.5 | F16: =IFERROR(_xlfn.XLOOKUP(B16,'tồn TP 17.04'!A:A,'tồn TP 17.04'!J:J),0) -> 2200 | G16: =G7 -> 1280 | H16: =H7 -> 1380 | I16: =H16-G16 -> 100 | J16: =29605/26.5 -> 1117.1698 | K16: =(H16-J16) -> 262.83019 | L16: =+K16/H16 -> 0.19045666 | N16: Sản phẩm mới | O16: Giá tồn kho
A17: =+A15+1 -> 10 | B17: 110000507 | C17: Vảy FPET201 | E17: =SUMIFS('tồn TP 17.04'!F:F,'tồn TP 17.04'!A:A,'Trình bày'!B17) -> 265836 | F17: =IFERROR(_xlfn.XLOOKUP(B17,'tồn TP 17.04'!A:A,'tồn TP 17.04'!J:J),0) -> 0 | G17: 0 | H17: =H7-320 -> 1060 | I17: =H17-G17 -> 1060 | J17: 844 | K17: =(H17-J17) -> 216 | L17: =+K17/H17 -> 0.20377358 | N17: Sản phẩm mới
A18: II | B18: MÃ HÀNG BÁN CHẬM
A19: 1 | B19: 110000378 | C19: Hạt nhựa rPET iSS01G 2 | E19: =SUMIFS('tồn TP 17.04'!F:F,'tồn TP 17.04'!A:A,'Trình bày'!B19) -> 1246297 | F19: =IFERROR(_xlfn.XLOOKUP(B19,'tồn TP 17.04'!A:A,'tồn TP 17.04'!J:J),0) -> 330000 | G19: =+G7+30 -> 1310 | H19: =+H7+30 -> 1410 | I19: =H19-G19 -> 100 | J19: =+J7 -> 1157 | K19: =(H19-J19) -> 253 | L19: =+K19/H19 -> 0.17943262 | M19: =M8 -> 0 | N19: Chuyển thành mã iSS01G 1 để bán
A20: =+A19+1 -> 2 | B20: 110000377 | C20: Hạt nhựa rPET WSS01G 2 | E20: =SUMIFS('tồn TP 17.04'!F:F,'tồn TP 17.04'!A:A,'Trình bày'!B20) -> 134200 | F20: =IFERROR(_xlfn.XLOOKUP(B20,'tồn TP 17.04'!A:A,'tồn TP 17.04'!J:J),0) -> 7333.3333 | G20: =G7 -> 1280 | H20: =H7 -> 1380 | I20: =H20-G20 -> 100 | J20: =+J8 -> 1157 | K20: =(H20-J20) -> 223 | L20: =+K20/H20 -> 0.1615942 | M20: =M7 -> 0 | N20: Chuyển thành mã wSS01G 1 để bán
A21: =+A20+1 -> 3 | B21: 110000383 | C21: Hạt Nhựa rPET iSS84G-P | E21: =SUMIFS('tồn TP 17.04'!F:F,'tồn TP 17.04'!A:A,'Trình bày'!B21) -> 52800 | F21: =IFERROR(_xlfn.XLOOKUP(B21,'tồn TP 17.04'!A:A,'tồn TP 17.04'!J:J),0) -> 0 | I21: =H21-G21 -> 0 | J21: =29396/26.5 -> 1109.283 | N21: Không báo giá (SP SX bán cho Amcor) | O21: Giá tồn kho
A22: =+A21+1 -> 4 | B22: 110000335 | C22: Hạt nhựa rPET WSS04 | E22: =SUMIFS('tồn TP 17.04'!F:F,'tồn TP 17.04'!A:A,'Trình bày'!B22) -> 0 | F22: =IFERROR(_xlfn.XLOOKUP(B22,'tồn TP 17.04'!A:A,'tồn TP 17.04'!J:J),0) -> 0 | I22: =H22-G22 -> 0 | K22: =(H22-J22) -> 0 | O22: Giá tồn kho
A23: =+A22+1 -> 5 | B23: 110000358 | C23: Hạt nhựa rPET WSS02G | E23: =SUMIFS('tồn TP 17.04'!F:F,'tồn TP 17.04'!A:A,'Trình bày'!B23) -> 0 | F23: =IFERROR(_xlfn.XLOOKUP(B23,'tồn TP 17.04'!A:A,'tồn TP 17.04'!J:J),0) -> 0 | I23: =H23-G23 -> 0 | K23: =(H23-J23) -> 0
A24: =+A23+1 -> 6 | B24: 110000468 | C24: Hạt Nhựa rPET iSS80G-P | E24: =SUMIFS('tồn TP 17.04'!F:F,'tồn TP 17.04'!A:A,'Trình bày'!B24) -> 50600 | F24: =IFERROR(_xlfn.XLOOKUP(B24,'tồn TP 17.04'!A:A,'tồn TP 17.04'!J:J),0) -> 0 | I24: =H24-G24 -> 0 | J24: =27618/26.5 -> 1042.1887 | N24: Không báo giá (SP SX bán cho Amcor) | O24: Giá tồn kho
A25: =+A24+1 -> 7 | B25: 110000333 | C25: Hạt nhựa rPET WSS03 | E25: =SUMIFS('tồn TP 17.04'!F:F,'tồn TP 17.04'!A:A,'Trình bày'!B25) -> 0 | F25: =IFERROR(_xlfn.XLOOKUP(B25,'tồn TP 17.04'!A:A,'tồn TP 17.04'!J:J),0) -> 0 | I25: =H25-G25 -> 0 | K25: =(H25-J25) -> 0 | O25: Giá tồn kho
A26: =+A25+1 -> 8 | B26: 110000376 | C26: Hạt nhựa rPET iSS01L | E26: =SUMIFS('tồn TP 17.04'!F:F,'tồn TP 17.04'!A:A,'Trình bày'!B26) -> 800 | F26: =IFERROR(_xlfn.XLOOKUP(B26,'tồn TP 17.04'!A:A,'tồn TP 17.04'!J:J),0) -> 0 | I26: =H26-G26 -> 0 | J26: =31171/26.5 -> 1176.2642 | N26: Không báo giá (hàng chờ xử lý) | O26: Giá tồn kho
A27: =+A26+1 -> 9 | B27: 110000331 | C27: Hạt nhựa rPET WSS02 | E27: =SUMIFS('tồn TP 17.04'!F:F,'tồn TP 17.04'!A:A,'Trình bày'!B27) -> 0 | F27: =IFERROR(_xlfn.XLOOKUP(B27,'tồn TP 17.04'!A:A,'tồn TP 17.04'!J:J),0) -> 0 | I27: =H27-G27 -> 0 | K27: =(H27-J27) -> 0
A28: =+A27+1 -> 10 | B28: 110000330 | C28: Hạt nhựa rPET iSS01 | E28: =SUMIFS('tồn TP 17.04'!F:F,'tồn TP 17.04'!A:A,'Trình bày'!B28) -> 0 | F28: =IFERROR(_xlfn.XLOOKUP(B28,'tồn TP 17.04'!A:A,'tồn TP 17.04'!J:J),0) -> 0 | I28: =H28-G28 -> 0 | K28: =(H28-J28) -> 0
A29: =+A28+1 -> 11 | B29: 110000475 | C29: Hạt nhựa rPET WSS03G FRH | E29: =SUMIFS('tồn TP 17.04'!F:F,'tồn TP 17.04'!A:A,'Trình bày'!B29) -> 0 | F29: =IFERROR(_xlfn.XLOOKUP(B29,'tồn TP 17.04'!A:A,'tồn TP 17.04'!J:J),0) -> 0 | I29: =H29-G29 -> 0 | K29: =(H29-J29) -> 0
A30: III | B30: MÃ HÀNG SẢN XUẤT TỪ PHÓ SẢN NGÀNH PET
A31: 1 | B31: 110000466 | C31: Hạt Nhựa rPET WSS05SB-2 | E31: =SUMIFS('tồn TP 17.04'!F:F,'tồn TP 17.04'!A:A,'Trình bày'!B31) -> 11899 | F31: =IFERROR(_xlfn.XLOOKUP(B31,'tồn TP 17.04'!A:A,'tồn TP 17.04'!J:J),0) -> 0 | I31: =H31-G31 -> 0 | J31: =26575/26.5 -> 1002.8302 | K31: =(H31-J31) -> -1002.8302 | L31: =+K31/H31 -> #DIV/0! | O31: Hàng tồn từ T7.2025
A32: =A31+1 -> 2 | B32: 110000436 | C32: Hạt nhựa rPET WSS05SB | E32: =SUMIFS('tồn TP 17.04'!F:F,'tồn TP 17.04'!A:A,'Trình bày'!B32) -> 150922.7 | F32: =IFERROR(_xlfn.XLOOKUP(B32,'tồn TP 17.04'!A:A,'tồn TP 17.04'!J:J),0) -> 144266.67 | I32: =H32-G32 -> 0 | J32: 956 | K32: =(H32-J32) -> -956 | L32: =+K32/H32 -> #DIV/0!
A33: =A32+1 -> 3 | B33: 110000382 | C33: Hạt nhựa rPET WSS04SB | E33: =SUMIFS('tồn TP 17.04'!F:F,'tồn TP 17.04'!A:A,'Trình bày'!B33) -> 6837.7 | F33: =IFERROR(_xlfn.XLOOKUP(B33,'tồn TP 17.04'!A:A,'tồn TP 17.04'!J:J),0) -> 3150 | G33: =G7-130 -> 1150 | H33: =H7-130 -> 1250 | I33: =H33-G33 -> 100 | J33: 519 | K33: =(H33-J33) -> 731 | L33: =+K33/H33 -> 0.5848 | O33: 100% vảy PET B1_A3
A34: =A33+1 -> 4 | B34: 110000384 | C34: Hạt Nhựa Xơ Sợi Thử Nghiệm | E34: =SUMIFS('tồn TP 17.04'!F:F,'tồn TP 17.04'!A:A,'Trình bày'!B34) -> 0 | F34: =IFERROR(_xlfn.XLOOKUP(B34,'tồn TP 17.04'!A:A,'tồn TP 17.04'!J:J),0) -> 0 | I34: =H34-G34 -> 0 | O34: Không đạt WSS04SB, WSS04SB, WSS04SD rớt xuống mã xơ sợi thử nghiệm
A35: =A34+1 -> 5 | B35: 110000381 | C35: Hạt nhựa rPET WSS04SD | E35: =SUMIFS('tồn TP 17.04'!F:F,'tồn TP 17.04'!A:A,'Trình bày'!B35) -> 219291.2 | F35: =IFERROR(_xlfn.XLOOKUP(B35,'tồn TP 17.04'!A:A,'tồn TP 17.04'!J:J),0) -> 1133.3333 | G35: =G33 -> 1150 | H35: =H33 -> 1250 | I35: =H35-G35 -> 100 | J35: 590 | K35: =(H35-J35) -> 660 | L35: =+K35/H35 -> 0.528 | O35: Tomra_A1/ Zigzag_A1
A36: =A35+1 -> 6 | B36: 110000387 | C36: Hạt nhựa rPET WSS03SD | E36: =SUMIFS('tồn TP 17.04'!F:F,'tồn TP 17.04'!A:A,'Trình bày'!B36) -> 0 | F36: =IFERROR(_xlfn.XLOOKUP(B36,'tồn TP 17.04'!A:A,'tồn TP 17.04'!J:J),0) -> 0 | G36: =G33 -> 1150 | H36: =H33 -> 1250 | I36: =H36-G36 -> 100 | J36: =32081/26.5 -> 1210.6038 | K36: =(H36-J36) -> 39.396226 | L36: =+K36/H36 -> 0.031516981 | N36: Tồn kho từ T9/2024
A37: =A36+1 -> 7 | B37: 110000522 | C37: Hạt Nhựa rPET WSS03NC | E37: =SUMIFS('tồn TP 17.04'!F:F,'tồn TP 17.04'!A:A,'Trình bày'!B37) -> 50 | F37: =IFERROR(_xlfn.XLOOKUP(B37,'tồn TP 17.04'!A:A,'tồn TP 17.04'!J:J),0) -> 0 | G37: =G34 -> 0 | H37: =H7-130 -> 1250 | I37: =H37-G37 -> 1250 | J37: 994 | K37: =(H37-J37) -> 256 | L37: =+K37/H37 -> 0.2048
A38: =A37+1 -> 8 | B38: 110000464 | C38: Hạt Nhựa rPET WSS06SP-1 | E38: =SUMIFS('tồn TP 17.04'!F:F,'tồn TP 17.04'!A:A,'Trình bày'!B38) -> 103790.5 | F38: =IFERROR(_xlfn.XLOOKUP(B38,'tồn TP 17.04'!A:A,'tồn TP 17.04'!J:J),0) -> 0 | I38: =H38-G38 -> 0 | J38: =18090/26.5 -> 682.64151 | K38: =(H38-J38) -> -682.64151 | L38: =+K38/H38 -> #DIV/0! | O38: Chuyển từ hàng xơ sợi thử nghiệm qua
A39: =A38+1 -> 9 | B39: 110000430 | C39: Hạt Nhựa rPET Bán Thành Phẩm | E39: =SUMIFS('tồn TP 17.04'!F:F,'tồn TP 17.04'!A:A,'Trình bày'!B39) -> 37397.8 | F39: =IFERROR(_xlfn.XLOOKUP(B39,'tồn TP 17.04'!A:A,'tồn TP 17.04'!J:J),0) -> 0 | O39: Phó sản PET tuyển nổi 2 + phó sản hạt cắt lỗi
A40: B | B40: rHDPE THỔI
A41: I | B41: MÃ HÀNG ĐANG BÁN
A42: 1 | B42: 110000339 | C42: Hạt Nhựa rHDPE MBF01 | D42: Trong | E42: =SUMIFS('tồn TP 17.04'!F:F,'tồn TP 17.04'!A:A,'Trình bày'!B42) -> 151662.5 | F42: =IFERROR(_xlfn.XLOOKUP(B42,'tồn TP 17.04'!A:A,'tồn TP 17.04'!J:J),0) -> 230083.33 | I42: =H42-G42 -> 0 | J42: 1201 | N42: Theo giá U => ko đề xuất trong duyệt giá
...

Sheet tồn TP 17.04
F1: =SUBTOTAL(9,F3:F878) -> 8383230.3 | I1: =SUBTOTAL(9,I3:I90) -> 13163325 | J1: 3
A2: Material | B2: Material Description | C2: Base Unit of Measure | D2: Unrestricted | E2: Blocked | F2: Tồn 17/04 | G2: Phân loại | H2: Màu | I2: SL bán 2026 | J2: SL bán BQ/ tháng | K2: Check file bán
A3: 110000329 | B3: Hạt nhựa rPET WSS01 | C3: KG | D3: 384888 | E3: 0 | F3: =+D3+E3 -> 384888 | G3: =IFERROR(_xlfn.XLOOKUP(A3,data!A:A,data!D:D)," ") -> rPET | H3: =IFERROR(_xlfn.XLOOKUP(A3,data!A:A,data!E:E)," ") -> 0 | I3: 110000 | J3: =IFERROR(I3/$J$1,0) -> 36666.667 | K3: =VLOOKUP(A3,'Trình bày'!B:B,1,0) -> 110000329
A4: 110000332 | B4: Hạt nhựa rPET iSS01084G | C4: KG | D4: 188980.2 | E4: 240008 | F4: =+D4+E4 -> 428988.2 | G4: =IFERROR(_xlfn.XLOOKUP(A4,data!A:A,data!D:D)," ") -> rPET | H4: =IFERROR(_xlfn.XLOOKUP(A4,data!A:A,data!E:E)," ") -> 0 | I4: 1786400 | J4: =IFERROR(I4/$J$1,0) -> 595466.67 | K4: =VLOOKUP(A4,'Trình bày'!B:B,1,0) -> 110000332
A5: 110000336 | B5: Hạt nhựa rHDPE thử nghiệm | C5: KG | D5: 23066.9 | E5: 9450 | F5: =+D5+E5 -> 32516.9 | G5: =IFERROR(_xlfn.XLOOKUP(A5,data!A:A,data!D:D)," ") -> HD thổi | H5: =IFERROR(_xlfn.XLOOKUP(A5,data!A:A,data!E:E)," ") -> 0 | I5: 0 | J5: =IFERROR(I5/$J$1,0) -> 0 | K5: =VLOOKUP(A5,'Trình bày'!B:B,1,0) -> 110000336
A6: 110000339 | B6: Hạt Nhựa rHDPE MBF01 | C6: KG | D6: 96662.5 | E6: 55000 | F6: =+D6+E6 -> 151662.5 | G6: =IFERROR(_xlfn.XLOOKUP(A6,data!A:A,data!D:D)," ") -> HD thổi | H6: =IFERROR(_xlfn.XLOOKUP(A6,data!A:A,data!E:E)," ") -> Trong | I6: 690250 | J6: =IFERROR(I6/$J$1,0) -> 230083.33 | K6: =VLOOKUP(A6,'Trình bày'!B:B,1,0) -> 110000339
A7: 110000341 | B7: Hạt nhựa rHDB04B01 | C7: KG | D7: 109750.5 | E7: 7850 | F7: =+D7+E7 -> 117600.5 | G7: =IFERROR(_xlfn.XLOOKUP(A7,data!A:A,data!D:D)," ") -> HD thổi | H7: =IFERROR(_xlfn.XLOOKUP(A7,data!A:A,data!E:E)," ") -> Đen | I7: 156250 | J7: =IFERROR(I7/$J$1,0) -> 52083.333 | K7: =VLOOKUP(A7,'Trình bày'!B:B,1,0) -> 110000341
A8: 110000343 | B8: Hạt Nhựa rHDB03G01 | C8: KG | D8: 13140 | E8: 0 | F8: =+D8+E8 -> 13140 | G8: =IFERROR(_xlfn.XLOOKUP(A8,data!A:A,data!D:D)," ") -> HD thổi | H8: =IFERROR(_xlfn.XLOOKUP(A8,data!A:A,data!E:E)," ") -> Lá | I8: 0 | J8: =IFERROR(I8/$J$1,0) -> 0 | K8: =VLOOKUP(A8,'Trình bày'!B:B,1,0) -> 110000343
A9: 110000345 | B9: Hạt Nhựa rHDB03Y01 | C9: KG | D9: 1365 | E9: 2200 | F9: =+D9+E9 -> 3565 | G9: =IFERROR(_xlfn.XLOOKUP(A9,data!A:A,data!D:D)," ") -> HD thổi | H9: =IFERROR(_xlfn.XLOOKUP(A9,data!A:A,data!E:E)," ") -> Vàng | I9: 0 | J9: =IFERROR(I9/$J$1,0) -> 0 | K9: =VLOOKUP(A9,'Trình bày'!B:B,1,0) -> 110000345
A10: 110000354 | B10: Hạt nhựa rPET WSS01G 1 | C10: KG | D10: 737486 | E10: 0 | F10: =+D10+E10 -> 737486 | G10: =IFERROR(_xlfn.XLOOKUP(A10,data!A:A,data!D:D)," ") -> rPET | H10: =IFERROR(_xlfn.XLOOKUP(A10,data!A:A,data!E:E)," ") -> 0 | I10: 6468000 | J10: =IFERROR(I10/$J$1,0) -> 2156000 | K10: =VLOOKUP(A10,'Trình bày'!B:B,1,0) -> 110000354
A11: 110000355 | B11: Hạt nhựa rPET iSS01G 1 | C11: KG | D11: 70122.75 | E11: 0 | F11: =+D11+E11 -> 70122.75 | G11: =IFERROR(_xlfn.XLOOKUP(A11,data!A:A,data!D:D)," ") -> rPET | H11: =IFERROR(_xlfn.XLOOKUP(A11,data!A:A,data!E:E)," ") -> 0 | I11: 594050 | J11: =IFERROR(I11/$J$1,0) -> 198016.67 | K11: =VLOOKUP(A11,'Trình bày'!B:B,1,0) -> 110000355
A12: 110000359 | B12: Hạt nhựa rPET WSS03G | C12: KG | D12: 1884689.5 | E12: 26400 | F12: =+D12+E12 -> 1911089.5 | G12: =IFERROR(_xlfn.XLOOKUP(A12,data!A:A,data!D:D)," ") -> rPET | H12: =IFERROR(_xlfn.XLOOKUP(A12,data!A:A,data!E:E)," ") -> 0 | I12: 909850 | J12: =IFERROR(I12/$J$1,0) -> 303283.33 | K12: =VLOOKUP(A12,'Trình bày'!B:B,1,0) -> 110000359
A13: 110000360 | B13: Hạt nhựa rHDI4L01 | C13: KG | D13: 40070 | E13: 0 | F13: =+D13+E13 -> 40070 | G13: =IFERROR(_xlfn.XLOOKUP(A13,data!A:A,data!D:D)," ") -> HD ép | H13: =IFERROR(_xlfn.XLOOKUP(A13,data!A:A,data!E:E)," ") -> Dương | I13: 45500 | J13: =IFERROR(I13/$J$1,0) -> 15166.667 | K13: =VLOOKUP(A13,'Trình bày'!B:B,1,0) -> 110000360
A14: 110000361 | B14: Hạt nhựa rHDI3R01 | C14: KG | D14: 26650 | E14: 0 | F14: =+D14+E14 -> 26650 | G14: =IFERROR(_xlfn.XLOOKUP(A14,data!A:A,data!D:D)," ") -> HD ép | H14: =IFERROR(_xlfn.XLOOKUP(A14,data!A:A,data!E:E)," ") -> Đỏ | I14: 33000 | J14: =IFERROR(I14/$J$1,0) -> 11000 | K14: =VLOOKUP(A14,'Trình bày'!B:B,1,0) -> 110000361
... A90: 110000522 | B90: Hạt Nhựa rPET WSS03NC | C90: KG | D90: 50 | E90: 0 | F90: =+D90+E90 -> 50 | G90: =IFERROR(_xlfn.XLOOKUP(A90,data!A:A,data!D:D)," ") | H90: =IFERROR(_xlfn.XLOOKUP(A90,data!A:A,data!E:E)," ") | I90: 0 | J90: =IFERROR(I90/$J$1,0) -> 0 | K90: =VLOOKUP(A90,'Trình bày'!B:B,1,0) -> 110000522

Sheet data
A1: Material | B1: Material Description | C1: BUn | D1: PL | E1: Màu
A2: 110000378 | B2: Hạt nhựa rPET iSS01G 2 | C2: KG | D2: rPET
A3: 110000377 | B3: Hạt nhựa rPET WSS01G 2 | C3: KG | D3: rPET
A4: 110000354 | B4: Hạt nhựa rPET WSS01G 1 | C4: KG | D4: rPET
A5: 110000492 | B5: Hạt Nhựa rPET WSS03G PL | C5: KG | D5: rPET
A6: 110000355 | B6: Hạt nhựa rPET iSS01G 1 | C6: KG | D6: rPET
A7: 110000483 | B7: Hạt Nhựa rPET iSS01G-S | C7: KG | D7: rPET
A8: 110000339 | B8: Hạt Nhựa rHDPE MBF01 | C8: KG | D8: HD thổi | E8: Trong
A9: 110000426 | B9: Hạt Nhựa HCBF-Yel-U | C9: KG | D9: HD thổi | E9: Vàng
A10: 110000374 | B10: Hạt Nhựa rHDB03N02 | C10: KG | D10: HD thổi | E10: Trong
A11: 110000481 | B11: Hạt Nhựa rHDPE PCF01 | C11: KG | D11: HD thổi | E11: Trong
A12: 110000341 | B12: Hạt nhựa rHDB04B01 | C12: KG | D12: HD thổi | E12: Đen
A13: 110000425 | B13: Hạt Nhựa HCBF-Whi-U | C13: KG | D13: HD thổi | E13: Trắng
A14: 110000383 | B14: Hạt Nhựa rPET iSS84G-P | C14: KG | D14: rPET
A15: 110000484 | B15: Hạt Nhựa rPET WSS01G 1 PL | C15: KG | D15: rPET
A16: 110000335 | B16: Hạt nhựa rPET WSS04 | C16: KG | D16: rPET
A17: 110000358 | B17: Hạt nhựa rPET WSS02G | C17: KG | D17: rPET
A18: 110000360 | B18: Hạt nhựa rHDI4L01 | C18: KG | D18: HD ép | E18: Dương
A19: 110000366 | B19: Hạt nhựa rHDI3G01 | C19: KG | D19: HD ép | E19: Lá
A20: 110000361 | B20: Hạt nhựa rHDI3R01 | C20: KG | D20: HD ép | E20: Đỏ
A21: 110000496 | B21: Hạt Nhựa rHDI7DL02 | C21: KG | D21: HD ép | E21: Dương
A22: 110000364 | B22: Hạt nhựa rHDI3Y01 | C22: KG | D22: HD ép | E22: Vàng
A23: 110000365 | B23: Hạt nhựa rHDI3W01 | C23: KG | D23: HD ép | E23: Trắng
A24: 110000389 | B24: Hạt nhựa rPP20R02 | C24: KG | D24: rPP | E24: Đỏ
A25: 110000471 | B25: Hạt Nhựa rPP20L05 | C25: KG | D25: rPP | E25: Dương
A26: 110000472 | B26: Hạt Nhựa rPP20Gy01 | C26: KG | D26: rPP | E26: Xám
A27: 110000392 | B27: Hạt nhựa rPP20B01 | C27: KG | D27: rPP | E27: Đen
A28: 110000363 | B28: Hạt nhựa rHDI3Gy01 | C28: KG | D28: HD ép | E28: Xám
A29: 110000495 | B29: Hạt Nhựa rHDA03W01 | C29: KG | D29: HD thổi | E29: Trắng
A30: 110000430 | B30: Hạt Nhựa rPET Bán Thành Phẩm | C30: KG | D30: rPET
A31: 110000468 | B31: Hạt Nhựa rPET iSS80G-P | C31: KG | D31: rPET
A32: 110000500 | B32: Hạt Nhựa rPET WSS01L PL | C32: KG | D32: rPET
A33: 110000381 | B33: Hạt nhựa rPET WSS04SD | C33: KG | D33: Xơ sợi
A34: 110000382 | B34: Hạt nhựa rPET WSS04SB | C34: KG | D34: Xơ sợi
A35: 110000332 | B35: Hạt nhựa rPET iSS01084G | C35: KG | D35: rPET
A36: 110000384 | B36: Hạt Nhựa Xơ Sợi Thử Nghiệm | C36: KG | D36: Xơ sợi
A37: 110000336 | B37: Hạt nhựa rHDPE thử nghiệm | C37: KG | D37: HD thổi
A38: 110000387 | B38: Hạt nhựa rPET WSS03SD | C38: KG | D38: Xơ sợi
A39: 110000435 | B39: Hạt Nhựa rPP20L03 | C39: KG | D39: rPP | E39: Dương
A40: 110000482 | B40: Hạt Nhựa rPP20W01 | C40: KG | D40: rPP | E40: Trắng
...
