Workbook

Sheet Data
B1: Lấy đầu 11*
B2: Mã SKU | Tên SKU | C2: Tên KH | D2: SẢN LƯỢNG (Kg) | AQ2: GBTB EXW (USD/ton) | CD2: GIÁ XUẤT KHO TB (VND/kg)
D3: 2024 | Q3: 2025 | AD3: 2026 | AQ3: 2024 | BD3: 2025 | BQ3: 2026 | CD3: 2024 | CQ3: 2025 | DD3: 2026
A4: LINK | D4: 01 | E4: 02 | F4: 03 | G4: 04 | H4: 05 | I4: 06 | J4: 07 | K4: 08 | L4: 09 | M4: 10 | N4: 11 | O4: 12 | P4: TỔNG | Q4: 01 | R4: 02 | S4: 03 | T4: 04 | U4: 05 | V4: 06 | W4: 07 | X4: 08 | Y4: 09 | Z4: 10 | AA4: 11 | AB4: 12 | AC4: TỔNG | AD4: 01 | AE4: 02 | AF4: 03 | AG4: 04 | AH4: 05 | AI4: 06 | AJ4: 07 | AK4: 08 | AL4: 09 | AM4: 10 | AN4: 11 | AO4: 12 | AP4: TỔNG | AQ4: 01 | AR4: 02 | AS4: 03 | AT4: 04 | AU4: 05 | AV4: 06 | AW4: 07 | AX4: 08 | AY4: 09 | AZ4: 10 | BA4: 11 | BB4: 12 | BC4: TỔNG | BD4: 01 | BE4: 02 | BF4: 03 | BG4: 04 | BH4: 05 | BI4: 06 | BJ4: 07 | BK4: 08 | BL4: 09 | BM4: 10 | BN4: 11 | BO4: 12 | BP4: TỔNG | BQ4: 01 | BR4: 02 | BS4: 03 | BT4: 04 | BU4: 05 | BV4: 06 | BW4: 07 | BX4: 08 | BY4: 09 | BZ4: 10 | CA4: 11 | CB4: 12 | CC4: TỔNG | CD4: 01 | CE4: 02 | CF4: 03 | CG4: 04 | CH4: 05 | CI4: 06 | CJ4: 07 | CK4: 08 | CL4: 09 | CM4: 10 | CN4: 11 | CO4: 12 | CP4: TỔNG | CQ4: 01 | CR4: 02 | CS4: 03 | CT4: 04 | CU4: 05 | CV4: 06 | CW4: 07 | CX4: 08 | CY4: 09 | CZ4: 10 | DA4: 11 | DB4: 12 | DC4: TỔNG | DD4: 01 | DE4: 02 | DF4: 03 | DG4: 04 | DH4: 05 | DI4: 06 | DJ4: 07 | DK4: 08 | DL4: 09 | DM4: 10 | DN4: 11 | DO4: 12 | DP4: TỔNG
B5: 110000329 | WSS01 | C5: Công ty TNHH La Vie | D5: 88000 | E5: 176000 | F5: 286000 | G5: 0 | H5: 1400000 | I5: 600000 | J5: 88000 | K5: 154000 | L5: 242000 | M5: 187000 | N5: 79200 | O5: 239800 | P5: 3540000 | W5: 0 | X5: 0 | Z5: 60500 | AA5: 96800 | AB5: 110000 | AC5: 267300 | AE5: 33000 | AF5: 77000 | AG5: 22000 | AP5: 132000 | AQ5: 1238.9973 | AR5: 1236.0482 | AS5: 1229.9736 | AU5: 1227.2228 | AV5: 1226.6016 | AW5: 1321.8484 | AX5: 1336.7718 | AY5: 1360.9668 | AZ5: 1338.7941 | BA5: 1317.0061 | BB5: 1321.6748 | BC5: 1258.6328 | BM5: 1310.2241 | BN5: 1292.5488 | BO5: 1311.5731 | BP5: 1296.4747 | BR5: 1298.421 | BS5: 1286.9449 | BT5: 1288.8697 | CC5: 1290.1347 | CD5: 22652.271 | CE5: 23698.605 | CF5: 23937.019 | CH5: 24901.606 | CI5: 24637.229 | CJ5: 26923.659 | CK5: 21709.969 | CL5: 22756.025 | CM5: 26091.048 | CN5: 26825.151 | CO5: 27914.628 | CP5: 24737.855 | CZ5: 30205.005 | DA5: 31105.554 | DB5: 31949.205 | DC5: 31248.908 | DE5: 32814.242 | DF5: 33259.409 | DG5: 33259.409 | DP5: 33148.117
B6: 110000329 | WSS01 | C6: CPSX Nhựa Duy Tân | E6: 33000 | F6: 99000 | G6: 88000 | H6: -4400 | P6: 215600 | AR6: 1294.3457 | AS6: 1254.6301 | AT6: 1230.0786 | AU6: 1228.2129 | BC6: 1251.2271 | CE6: 23698.605 | CF6: 23937.019 | CG6: 23937.015 | CH6: 24901.606 | CP6: 23880.84
B7: 110000329 | WSS01 | C7: Dung Avient | H7: 100 | P7: 100 | AU7: 1310.9651 | BC7: 1310.9651 | CH7: 24901.606 | CP7: 24901.606
B8: 110000329 | WSS01 | C8: Nestle Việt Nam | M8: 200 | O8: 44000 | P8: 44200 | AZ8: 1306.6096 | BB8: 1314.8794 | BC8: 1314.8419 | CM8: 26091.048 | CO8: 27914.628 | CP8: 27906.377
B9: 110000329 | WSS01 | C9: Plascene- DTP | I9: 55000 | P9: 55000 | Q9: 22000 | AC9: 22000 | AG9: 38500 | AP9: 38500 | AV9: 1252.7959 | BC9: 1252.7959 | BD9: 1289.1609 | BP9: 1289.1609 | BT9: 1215.1238 | CC9: 1215.1238 | CI9: 24637.229 | CP9: 24637.229 | CQ9: 28427.722 | DC9: 28427.722 | DG9: 33259.409 | DP9: 33259.409
B10: 110000329 | WSS01 | C10: TÂN LẬP THÀNH | N10: 13200 | O10: -9900 | P10: 3300 | BA10: 1280.0029 | BB10: 1284.1304 | BC10: 1267.6205 | CN10: 26825.151 | CO10: 27914.628 | CP10: 23556.717
A11: Hạt WSS01G | B11: 110000329 | WSS01 Total | D11: 88000 | E11: 209000 | F11: 385000 | G11: 88000 | H11: 1395700 | I11: 655000 | J11: 88000 | K11: 154000 | L11: 242000 | M11: 187200 | N11: 92400 | O11: 273900 | P11: 3858200 | Q11: 22000 | W11: 0 | X11: 0 | Z11: 60500 | AA11: 96800 | AB11: 110000 | AC11: 289300 | AE11: 33000 | AF11: 77000 | AG11: 60500 | AP11: 170500 | AQ11: 1238.9973 | AR11: 1245.2531 | AS11: 1236.3139 | AT11: 1230.0786 | AU11: 1227.2257 | AV11: 1228.8011 | AW11: 1321.8484 | AX11: 1336.7718 | AY11: 1360.9668 | AZ11: 1338.7597 | BA11: 1311.7199 | BB11: 1321.9402 | BC11: 1258.7887 | BD11: 1289.1609 | BM11: 1310.2241 | BN11: 1292.5488 | BO11: 1311.5731 | BP11: 1295.9186 | BR11: 1298.421 | BS11: 1286.9449 | BT11: 1241.9405 | CC11: 1273.1968 | CD11: 22652.271 | CE11: 23698.605 | CF11: 23937.019 | CG11: 23937.015 | CH11: 24901.606 | CI11: 24637.229 | CJ11: 26923.659 | CK11: 21709.969 | CL11: 22756.025 | CM11: 26091.048 | CN11: 26825.151 | CO11: 27914.628 | CP11: 24723.823 | CQ11: 28427.722 | CZ11: 30205.005 | DA11: 31105.554 | DB11: 31949.205 | DC11: 31034.369 | DE11: 32814.242 | DF11: 33259.409 | DG11: 33259.409 | DP11: 33173.248
B12: 110000332 | iSS01084G | C12: INDUSTRIAS SALCOM | AA12: 44000 | AB12: 88000 | AC12: 132000 | BN12: 1288.1976 | BO12: 1289.2792 | BP12: 1288.9186 | DA12: 30369.75 | DB12: 27529.345 | DC12: 28476.147
B13: 110000332 | iSS01084G | C13: CN Cty Coca - Hà Nội | D13: 44000 | E13: 90200 | H13: 44000 | K13: 57200 | L13: 66000 | M13: 44000 | N13: 44000 | O13: 0 | P13: 389400 | Q13: 88000 | R13: 88000 | S13: 66000 | AB13: 0 | AC13: 242000 | AF13: 44000 | AG13: 44000 | AP13: 88000 | AQ13: 1333.315 | AR13: 1337.4927 | AU13: 1337.2729 | AX13: 1347.7288 | AY13: 1317.1049 | AZ13: 1323.3574 | BA13: 1333.9826 | BC13: 1333.05 | BD13: 1336.7139 | BE13: 1411.0778 | BF13: 1416.5304 | BP13: 1411.6911 | BS13: 1267.5166 | BT13: 1274.4286 | CC13: 1270.9726 | CD13: 21238.244 | CE13: 22878.932 | CH13: 24249.994 | CK13: 31248.215 | CL13: 29615.282 | CM13: 28196.916 | CN13: 27347.503 | CP13: 26325.432 | CQ13: 26518.029 | CR13: 26406.714 | CS13: 26379.931 | DC13: 26439.888 | DF13: 28764.36 | DG13: 28764.36 | DP13: 28764.36
B14: 110000332 | iSS01084G | C14: COCA COLA ĐÀ NẴNG | X14: 88000 | AC14: 88000 | BK14: 1408.8838 | BP14: 1408.8838 | CX14: 29299.876 | DC14: 29299.876
B15: 110000332 | iSS01084G | C15: Coca-Cola Thủ Đức | D15: 145200 | E15: 74800 | G15: 72600 | I15: 116600 | J15: 0 | N15: 110000 | P15: 519200 | Q15: 72600 | AC15: 72600 | AQ15: 1318.078 | AR15: 1323.2309 | AT15: 1304.5039 | AV15: 1322.0066 | BA15: 1321.5697 | BC15: 1318.5443 | BD15: 1326.7663 | BP15: 1326.7663 | CD15: 21238.244 | CE15: 22878.932 | CG15: 24292.539 | CI15: 25375.877 | CN15: 27347.503 | CP15: 24125.247 | CQ15: 26518.029 | DC15: 26518.029
B16: 110000332 | iSS01084G | C16: COCA-COLA VIỆT NAM TẠI TỈNH TÂY NINH | S16: 88000 | T16: 66000 | V16: 88000 | X16: 44000 | AB16: 0 | AC16: 286000 | AE16: 44000 | AF16: 132000 | AG16: 66000 | AP16: 242000 | BF16: 1415.5997 | BG16: 1398.374 | BI16: 1325.0309 | BK16: 1398.4289 | BP16: 1435.7427 | BR16: 1289.0507 | BS16: 1265.8863 | BT16: 1277.8476 | CC16: 1273.3602 | CS16: 26379.931 | CT16: 26574.885 | CV16: 27988.794 | CX16: 29299.876 | DC16: 27369.177 | DE16: 28728.819 | DF16: 28764.36 | DG16: 28764.36 | DP16: 28757.898
B17: 110000332 | iSS01084G | C17: CÔNG TY TNHH HON CHUAN VIETNAM | V17: 2789.2 | AC17: 2789.2 | AF17: 2200 | AG17: 22000 | AP17: 24200 | BI17: 1324.3545 | BP17: 1324.3545 | BS17: 1181.5536 | BT17: 1203.1429 | CC17: 1201.1802 | CV17: 27988.794 | DC17: 27988.794 | DF17: 28764.36 | DG17: 28764.36 | DP17: 28764.36
B18: 110000332 | iSS01084G | C18: CORAL A.E. | S18: 1100 | AC18: 1100 | BF18: 1306.8511 | BP18: 1306.8511 | CS18: 26379.931 | DC18: 26379.931
B19: 110000332 | iSS01084G | C19: CTY NGỌC NGHĨA-TÂY NINH | F19: 16500 | K19: 22000 | L19: 0 | M19: 44000 | N19: 0 | P19: 82500 | U19: 2200 | AC19: 2200 | AS19: 1413.7831 | AX19: 1432.987 | AZ19: 1447.2004 | BC19: 1436.7267 | BH19: 1345.1656 | BP19: 1345.1656 | CF19: 23530.176 | CK19: 31248.215 | CM19: 28196.916 | CP19: 28077.248 | CU19: 27745.546 | DC19: 27745.546
B20: 110000332 | iSS01084G | C20: Dung Avient | D20: 25 | P20: 25 | AQ20: 1410.0473 | BC20: 1410.0473 | CD20: 21238.244 | CP20: 21238.244
B21: 110000332 | iSS01084G | C21: GENESIS DISTRIBUCIÓN DE COLOMBIA SA | V21: 22000 | AC21: 22000 | BI21: 1321.4931 | BP21: 1321.4931 | CV21: 27988.794 | DC21: 27988.794
B22: 110000332 | iSS01084G | C22: Genesis Polymers International | I22: 22000 | L22: 88000 | P22: 110000 | U22: 220000 | AC22: 220000 | AV22: 1298.6539 | AY22: 1296.4686 | BC22: 1296.9056 | BH22: 1341.2159 | BP22: 1341.2159 | CI22: 25375.877 | CL22: 29615.282 | CP22: 28767.401 | CU22: 27745.546 | DC22: 27745.546
B23: 110000332 | iSS01084G | C23: KORYFES SA | T23: 22000 | AC23: 22000 | BG23: 1345.29 | BP23: 1345.29 | CT23: 26574.885 | DC23: 26574.885
B24: 110000332 | iSS01084G | C24: MCP-Resinex | K24: 22000 | P24: 22000 | AX24: 1267.3787 | BC24: 1267.3787 | CK24: 31248.215 | CP24: 31248.215
B25: 110000332 | iSS01084G | C25: MISS PLASTICS INC. | AE25: 2200 | AP25: 2200 | BR25: 1181.82 | CC25: 1181.82 | DE25: 28728.819 | DP25: 28728.819
B26: 110000332 | iSS01084G | C26: Người mua hàng không lấy hóa đơn | O26: 1100 | P26: 1100 | BB26: 1297.7678 | BC26: 1297.7678 | CO26: 26134.394 | CP26: 26134.394
B27: 110000332 | iSS01084G | C27: Parker-DTP | I27: 500 | N27: -400 | P27: 100 | AV27: 1293.6303 | BA27: 1314.3419 | BC27: 1210.7839 | CI27: 25375.877 | CN27: 27347.503 | CP27: 17489.374
B28: 110000332 | iSS01084G | C28: Resinex | R28: 66000 | AC28: 66000 | BE28: 1286.2298 | BP28: 1286.2298 | CR28: 26406.714 | DC28: 26406.714
B29: 110000332 | iSS01084G | C29: SodaStream | Q29: 44000 | AC29: 44000 | BD29: 1350.4402 | BP29: 1350.4402 | CQ29: 26518.029 | DC29: 26518.029
B30: 110000332 | iSS01084G | C30: Suntory - Ngọc Nghĩa Hưng Yên | T30: 3300 | AC30: 3300 | BG30: 1581.2955 | BP30: 1581.2955 | CT30: 26574.885 | DC30: 26574.885
B31: 110000332 | iSS01084G | C31: Suntory- Ngọc Nghĩa Tây Ninh | G31: 44000 | H31: 44000 | I31: 22000 | J31: 22000 | N31: 22000 | O31: 22000 | P31: 176000 | Q31: 44000 | S31: 22000 | T31: 22000 | U31: 44000 | V31: 22000 | W31: 66000 | X31: 44000 | Y31: 110000 | AA31: 110000 | AC31: 484000 | AD31: 44000 | AE31: 22000 | AF31: 88000 | AG31: 132000 | AP31: 286000 | AT31: 1397.3665 | AU31: 1370.9873 | AV31: 1394.028 | AW31: 1409.6445 | BA31: 1427.4993 | BB31: 1444.4629 | BC31: 1401.5428 | BD31: 1441.5855 | BF31: 1336.5648 | BG31: 1355.0074 | BH31: 1372.8437 | BI31: 1368.2949 | BJ31: 1370.0188 | BK31: 1360.7887 | BL31: 1311.1208 | BN31: 1318.2886 | BP31: 1348.5185 | BQ31: 1257.5213 | BR31: 1269.1526 | BS31: 1124.3288 | BT31: 1125.7789 | CC31: 1156.6295 | CG31: 24292.539 | CH31: 24249.994 | CI31: 25375.877 | CJ31: 27313.012 | CN31: 27347.503 | CO31: 26134.394 | CP31: 25406.981 | CQ31: 26518.029 | CS31: 26379.931 | CT31: 26574.885 | CU31: 27745.546 | CV31: 27988.794 | CW31: 28635.041 | CX31: 29299.876 | CY31: 29454.494 | DA31: 30369.75 | DC31: 28777.13 | DD31: 28300.028 | DE31: 28728.819 | DF31: 28764.36 | DG31: 28764.36 | DP31: 28690.191
B32: 110000332 | iSS01084G | C32: Suntory Sri Thái Bình Dương | D32: 14300 | E32: 44000 | F32: 31900 | G32: 44000 | K32: -29981.8 | L32: 66000 | M32: 0 | N32: 88000 | O32: 22000 | P32: 280218.2 | Q32: -13750.7 | R32: 22000 | S32: 88000 | T32: 44000 | U32: -40039.7 | W32: 50969.1 | X32: 43293 | AA32: 88000 | AB32: 176000 | AC32: 458471.7 | AD32: 220000 | AE32: 44000 | AF32: 154000 | AG32: 88000 | AP32: 506000 | AQ32: 1410.5925 | AR32: 1418.7887 | AS32: 1404.4741 | AT32: 1397.1488 | AX32: 1419.0734 | AY32: 1465.2747 | BA32: 1420.9509 | BB32: 1441.884 | BC32: 1426.7536 | BD32: 1457.7516 | BE32: 1399.1938 | BF32: 1358.5985 | BG32: 1354.0928 | BH32: 1360.7312 | BJ32: 1370.8477 | BK32: 1350.2563 | BN32: 1317.5508 | BO32: 1320.572 | BP32: 1335.0514 | BQ32: 1256.4391 | BR32: 1268.4175 | BS32: 1122.723 | BT32: 1130.3471 | CC32: 1194.8555 | CD32: 21238.244 | CE32: 22878.932 | CF32: 23530.176 | CG32: 24292.539 | CK32: 31248.215 | CL32: 29615.282 | CN32: 27347.503 | CO32: 26134.394 | CP32: 25441.36 | CQ32: 26518.029 | CR32: 26406.714 | CS32: 26379.931 | CT32: 26574.885 | CU32: 27745.546 | CW32: 28635.041 | CX32: 29299.876 | DA32: 30369.75 | DB32: 27529.345 | DC32: 28010.009 | DD32: 28300.028 | DE32: 28728.819 | DF32: 28764.36 | DG32: 28764.36 | DP32: 28559.386
B33: 110000332 | iSS01084G | C33: Suntory Việt Nam | I33: 6600 | J33: 4400 | K33: 651200 | L33: 153900 | M33: 311300 | N33: 418000 | O33: 572000 | P33: 2117400 | Q33: 154000 | R33: 484000 | S33: 154000 | T33: 374000 | U33: 330000 | V33: 351633 | W33: 132000 | X33: 616000 | Y33: 126500 | Z33: 382660 | AA33: 475340 | AB33: 682000 | AC33: 4262133 | AD33: 352000 | AE33: 264000 | AF33: 352000 | AG33: 528000 | AP33: 1496000 | AV33: 1362.6053 | AW33: 1367.2553 | AX33: 1425.6234 | AY33: 1407.8242 | AZ33: 1444.0849 | BA33: 1428.5148 | BB33: 1442.9236 | BC33: 1431.9705 | BD33: 1446.9593 | BE33: 1401.325 | BF33: 1364.2032 | BG33: 1343.7075 | BH33: 1374.0044 | BI33: 1340.6907 | BJ33: 1372.4129 | BK33: 1340.9875 | BL33: 1110.65 | BM33: 1286.0621 | BN33: 1310.4913 | BO33: 1321.4294 | BP33: 1337.9526 | BQ33: 1259.6401 | BR33: 1237.5293 | BS33: 1124.0658 | BT33: 1129.499 | CC33: 1177.9062 | CI33: 25375.877 | CJ33: 27313.012 | CK33: 31248.215 | CL33: 29615.282 | CM33: 28196.916 | CN33: 27347.503 | CO33: 26134.394 | CP33: 28502.936 | CQ33: 26518.029 | CR33: 26406.714 | CS33: 26379.931 | CT33: 26574.885 | CU33: 27745.546 | CV33: 27988.794 | CW33: 28635.041 | CX33: 29299.876 | CY33: 29454.494 | CZ33: 31284.463 | DA33: 30369.75 | DB33: 27529.345 | DC33: 28295.875 | DD33: 28300.028 | DE33: 28728.819 | DF33: 28764.36 | DG33: 28764.36 | DP33: 28648.834
B34: 110000332 | iSS01084G | C34: TRICON | AE34: 22000 | AP34: 22000 | BR34: 1270.8117 | CC34: 1270.8117 | DE34: 28728.819 | DP34: 28728.819
B35: 110000332 | iSS01084G | C35: Wiese | I35: 44000 | J35: 44000 | P35: 88000 | AV35: 1316.547 | AW35: 1318.6048 | BC35: 1317.5759 | CI35: 25375.877 | CJ35: 27313.012 | CP35: 26344.444
A36: Hạt iSS01084G | B36: 110000332 | iSS01084G Total | D36: 203525 | E36: 209000 | F36: 48400 | G36: 160600 | H36: 88000 | I36: 211700 | J36: 70400 | K36: 722418.2 | L36: 373900 | M36: 399300 | N36: 681600 | O36: 617100 | P36: 3785943.2 | Q36: 388849.3 | R36: 660000 | S36: 419100 | T36: 531300 | U36: 556160.3 | V36: 486422.2 | W36: 248969.1 | X36: 835293 | Y36: 236500 | Z36: 382660 | AA36: 717340 | AB36: 946000 | AC36: 6408593.9 | AD36: 616000 | AE36: 398200 | AF36: 772200 | AG36: 880000 | AP36: 2666400 | AQ36: 1327.8836 | AR36: 1349.5034 | AS36: 1407.6476 | AT36: 1355.3279 | AU36: 1354.1301 | AV36: 1327.1283 | AW36: 1350.0954 | AX36: 1415.1329 | AY36: 1375.7433 | AZ36: 1431.1249 | BA36: 1404.2107 | BB36: 1442.6826 | BC36: 1396.9593 | BD36: 1387.6579 | BE36: 1391.0448 | BF36: 1380.4574 | BG36: 1353.3675 | BH36: 1361.784 | BI36: 1338.1442 | BJ36: 1371.4578 | BK36: 1352.6898 | BL36: 1203.8923 | BM36: 1286.0621 | BN36: 1311.1855 | BO36: 1341.4884 | BP36: 1345.2792 | BQ36: 1258.3456 | BR36: 1249.9135 | BS36: 1156.4084 | BT36: 1149.2395 | CC36: 1191.5563 | CD36: 21238.244 | CE36: 22878.932 | CF36: 23530.176 | CG36: 24292.539 | CH36: 24249.994 | CI36: 25375.877 | CJ36: 27313.012 | CK36: 31248.215 | CL36: 29615.282 | CM36: 28196.916 | CN36: 27347.503 | CO36: 26134.394 | CP36: 27271.253 | CQ36: 26518.029 | CR36: 26406.714 | CS36: 26379.931 | CT36: 26574.885 | CU36: 27745.546 | CV36: 27988.794 | CW36: 28635.041 | CX36: 29299.876 | CY36: 29454.494 | CZ36: 31284.463 | DA36: 30369.75 | DB36: 27529.345 | DC36: 28138.633 | DD36: 28300.028 | DE36: 28728.819 | DF36: 28764.36 | DG36: 28764.36 | DP36: 28651.781
B37: 110000333 | WSS03 | C37: WORLD ELASTOMER | H37: 25 | P37: 25 | AU37: 1267.3217 | BC37: 1267.3217 | CH37: 28181.64 | CP37: 28181.64
A38: Hạt WSS03G | B38: 110000333 | WSS03 Total | H38: 25 | P38: 25 | AU38: 1267.3217 | BC38: 1267.3217 | CH38: 28181.64 | CP38: 28181.64
B39: 110000335 | WSS04 | C39: MEKONG BROS | Y39: 19800 | Z39: 9900 | AC39: 29700 | BL39: 728.82478 | BM39: 736.84149 | BP39: 731.49702 | CY39: 29897.192 | CZ39: 29310.476 | DC39: 29701.62
B40: 110000335 | WSS04 | C40: Việt Thành Plast | Y40: 24200 | Z40: 12100 | AA40: 30800 | AC40: 67100 | BL40: 740.8942 | BM40: 752.31395 | BN40: 786.39438 | BP40: 763.83883 | CY40: 29897.192 | CZ40: 29310.476 | DA40: 27172.658 | DC40: 28540.785
...

Sheet Data-Cũ
B1: Lấy đầu 11*
B2: Mã SKU | Tên SKU | C2: Tên KH | D2: SẢN LƯỢNG (Kg) | AQ2: GBTB EXW (USD/ton)
D3: 2024 | Q3: 2025 | AD3: 2026 | AQ3: 2024 | BD3: 2025 | BQ3: 2026
D4: 01 | E4: 02 | F4: 03 | G4: 04 | H4: 05 | I4: 06 | J4: 07 | K4: 08 | L4: 09 | M4: 10 | N4: 11 | O4: 12 | P4: TỔNG | Q4: 01 | R4: 02 | S4: 03 | T4: 04 | U4: 05 | V4: 06 | W4: 07 | X4: 08 | Y4: 09 | Z4: 10 | AA4: 11 | AB4: 12 | AC4: TỔNG | AD4: 01 | AE4: 02 | AF4: 03 | AG4: 04 | AH4: 05 | AI4: 06 | AJ4: 07 | AK4: 08 | AL4: 09 | AM4: 10 | AN4: 11 | AO4: 12 | AP4: TỔNG | AQ4: 01 | AR4: 02 | AS4: 03 | AT4: 04 | AU4: 05 | AV4: 06 | AW4: 07 | AX4: 08 | AY4: 09 | AZ4: 10 | BA4: 11 | BB4: 12 | BC4: TỔNG | BD4: 01 | BE4: 02 | BF4: 03 | BG4: 04 | BH4: 05 | BI4: 06 | BJ4: 07 | BK4: 08 | BL4: 09 | BM4: 10 | BN4: 11 | BO4: 12 | BP4: TỔNG | BQ4: 01 | BR4: 02 | BS4: 03 | BT4: 04 | BU4: 05 | BV4: 06 | BW4: 07 | BX4: 08 | BY4: 09 | BZ4: 10 | CA4: 11 | CB4: 12 | CC4: TỔNG
B5: 110000329 | WSS01 | C5: Công ty TNHH La Vie | D5: 88000 | E5: 176000 | F5: 286000 | G5: 0 | H5: 1400000 | I5: 600000 | J5: 88000 | K5: 154000 | L5: 242000 | M5: 187000 | N5: 79200 | O5: 239800 | P5: 3540000 | W5: 0 | X5: 0 | Z5: 60500 | AA5: 96800 | AB5: 110000 | AC5: 267300 | AE5: 33000 | AF5: 77000 | AG5: 22000 | AP5: 132000 | AQ5: 1238.9973 | AR5: 1236.0482 | AS5: 1229.9736 | AU5: 1227.2228 | AV5: 1226.6016 | AW5: 1321.8484 | AX5: 1336.7718 | AY5: 1360.9668 | AZ5: 1338.7941 | BA5: 1317.0061 | BB5: 1321.6748 | BC5: 1258.6328 | BM5: 1310.2241 | BN5: 1292.5488 | BO5: 1311.5731 | BP5: 1296.4747 | BR5: 1298.421 | BS5: 1286.9449 | BT5: 1288.8591 | CC5: 1290.133
B6: 110000329 | WSS01 | C6: CPSX Nhựa Duy Tân | E6: 33000 | F6: 99000 | G6: 88000 | H6: -4400 | P6: 215600 | AR6: 1294.3457 | AS6: 1254.6301 | AT6: 1230.0786 | AU6: 1228.2129 | BC6: 1251.2271
B7: 110000329 | WSS01 | C7: Dung Avient | H7: 100 | P7: 100 | AU7: 1310.9651 | BC7: 1310.9651
B8: 110000329 | WSS01 | C8: Nestle Việt Nam | M8: 200 | O8: 44000 | P8: 44200 | AZ8: 1306.6096 | BB8: 1314.8794 | BC8: 1314.8419
B9: 110000329 | WSS01 | C9: Plascene- DTP | I9: 55000 | P9: 55000 | Q9: 22000 | AC9: 22000 | AG9: 5500 | AP9: 5500 | AV9: 1252.7959 | BC9: 1252.7959 | BD9: 1289.1609 | BP9: 1289.1609 | BT9: 1215.1138 | CC9: 1215.1138
B10: 110000329 | WSS01 | C10: TÂN LẬP THÀNH | N10: 13200 | O10: -9900 | P10: 3300 | BA10: 1280.0029 | BB10: 1284.1304 | BC10: 1267.6205
A11: Hạt WSS01G | B11: 110000329 | WSS01 Total | D11: 88000 | E11: 209000 | F11: 385000 | G11: 88000 | H11: 1395700 | I11: 655000 | J11: 88000 | K11: 154000 | L11: 242000 | M11: 187200 | N11: 92400 | O11: 273900 | P11: 3858200 | Q11: 22000 | W11: 0 | X11: 0 | Z11: 60500 | AA11: 96800 | AB11: 110000 | AC11: 289300 | AE11: 33000 | AF11: 77000 | AG11: 27500 | AP11: 137500 | AQ11: 1238.9973 | AR11: 1245.2531 | AS11: 1236.3139 | AT11: 1230.0786 | AU11: 1227.2257 | AV11: 1228.8011 | AW11: 1321.8484 | AX11: 1336.7718 | AY11: 1360.9668 | AZ11: 1338.7597 | BA11: 1311.7199 | BB11: 1321.9402 | BC11: 1258.7887 | BD11: 1289.1609 | BM11: 1310.2241 | BN11: 1292.5488 | BO11: 1311.5731 | BP11: 1295.9186 | BR11: 1298.421 | BS11: 1286.9449 | BT11: 1274.11 | CC11: 1287.1322
B12: 110000332 | iSS01084G | C12: INDUSTRIAS SALCOM | AA12: 44000 | AB12: 88000 | AC12: 132000 | BN12: 1288.1976 | BO12: 1289.2792 | BP12: 1288.9186
B13: 110000332 | iSS01084G | C13: CN Cty Coca - Hà Nội | D13: 44000 | E13: 90200 | H13: 44000 | K13: 57200 | L13: 66000 | M13: 44000 | N13: 44000 | O13: 0 | P13: 389400 | Q13: 88000 | R13: 88000 | S13: 66000 | AB13: 0 | AC13: 242000 | AF13: 44000 | AG13: 22000 | AP13: 66000 | AQ13: 1333.315 | AR13: 1337.4927 | AU13: 1337.2729 | AX13: 1347.7288 | AY13: 1317.1049 | AZ13: 1323.3574 | BA13: 1333.9826 | BC13: 1333.05 | BD13: 1336.7139 | BE13: 1411.0778 | BF13: 1416.5304 | BP13: 1411.6911 | BS13: 1267.5166 | BT13: 1274.418 | CC13: 1269.8171
B14: 110000332 | iSS01084G | C14: COCA COLA ĐÀ NẴNG | X14: 88000 | AC14: 88000 | BK14: 1408.8838 | BP14: 1408.8838
B15: 110000332 | iSS01084G | C15: Coca-Cola Thủ Đức | D15: 145200 | E15: 74800 | G15: 72600 | I15: 116600 | J15: 0 | N15: 110000 | P15: 519200 | Q15: 72600 | AC15: 72600 | AQ15: 1318.078 | AR15: 1323.2309 | AT15: 1304.5039 | AV15: 1322.0066 | BA15: 1321.5697 | BC15: 1318.5443 | BD15: 1326.7663 | BP15: 1326.7663
B16: 110000332 | iSS01084G | C16: COCA-COLA VIỆT NAM TẠI TỈNH TÂY NINH | S16: 88000 | T16: 66000 | V16: 88000 | X16: 44000 | AB16: 0 | AC16: 286000 | AE16: 44000 | AF16: 132000 | AG16: 66000 | AP16: 242000 | BF16: 1415.5997 | BG16: 1398.374 | BI16: 1325.0309 | BK16: 1398.4289 | BP16: 1435.7427 | BR16: 1289.0507 | BS16: 1265.8863 | BT16: 1277.8371 | CC16: 1273.3573
B17: 110000332 | iSS01084G | C17: CÔNG TY TNHH HON CHUAN VIETNAM | V17: 2789.2 | AC17: 2789.2 | AF17: 2200 | AG17: 22000 | AP17: 24200 | BI17: 1324.3545 | BP17: 1324.3545 | BS17: 1181.5536 | BT17: 1203.1329 | CC17: 1201.1712
B18: 110000332 | iSS01084G | C18: CORAL A.E. | S18: 1100 | AC18: 1100 | BF18: 1306.8511 | BP18: 1306.8511
B19: 110000332 | iSS01084G | C19: CTY NGỌC NGHĨA-TÂY NINH | F19: 16500 | K19: 22000 | L19: 0 | M19: 44000 | N19: 0 | P19: 82500 | U19: 2200 | AC19: 2200 | AS19: 1413.7831 | AX19: 1432.987 | AZ19: 1447.2004 | BC19: 1436.7267 | BH19: 1345.1656 | BP19: 1345.1656
B20: 110000332 | iSS01084G | C20: Dung Avient | D20: 25 | P20: 25 | AQ20: 1410.0473 | BC20: 1410.0473
B21: 110000332 | iSS01084G | C21: GENESIS DISTRIBUCIÓN DE COLOMBIA SA | V21: 22000 | AC21: 22000 | BI21: 1321.4931 | BP21: 1321.4931
B22: 110000332 | iSS01084G | C22: Genesis Polymers International | I22: 22000 | L22: 88000 | P22: 110000 | U22: 220000 | AC22: 220000 | AV22: 1298.6539 | AY22: 1296.4686 | BC22: 1296.9056 | BH22: 1341.2159 | BP22: 1341.2159
B23: 110000332 | iSS01084G | C23: KORYFES SA | T23: 22000 | AC23: 22000 | BG23: 1345.29 | BP23: 1345.29
B24: 110000332 | iSS01084G | C24: MCP-Resinex | K24: 22000 | P24: 22000 | AX24: 1267.3787 | BC24: 1267.3787
B25: 110000332 | iSS01084G | C25: MISS PLASTICS INC. | AE25: 2200 | AP25: 2200 | BR25: 1181.82 | CC25: 1181.82
B26: 110000332 | iSS01084G | C26: Người mua hàng không lấy hóa đơn | O26: 1100 | P26: 1100 | BB26: 1297.7678 | BC26: 1297.7678
B27: 110000332 | iSS01084G | C27: Parker-DTP | I27: 500 | N27: -400 | P27: 100 | AV27: 1293.6303 | BA27: 1314.3419 | BC27: 1210.7839
B28: 110000332 | iSS01084G | C28: Resinex | R28: 66000 | AC28: 66000 | BE28: 1286.2298 | BP28: 1286.2298
B29: 110000332 | iSS01084G | C29: SodaStream | Q29: 44000 | AC29: 44000 | BD29: 1350.4402 | BP29: 1350.4402
B30: 110000332 | iSS01084G | C30: Suntory - Ngọc Nghĩa Hưng Yên | T30: 3300 | AC30: 3300 | BG30: 1581.2955 | BP30: 1581.2955
B31: 110000332 | iSS01084G | C31: Suntory- Ngọc Nghĩa Tây Ninh | G31: 44000 | H31: 44000 | I31: 22000 | J31: 22000 | N31: 22000 | O31: 22000 | P31: 176000 | Q31: 44000 | S31: 22000 | T31: 22000 | U31: 44000 | V31: 22000 | W31: 66000 | X31: 44000 | Y31: 110000 | AA31: 110000 | AC31: 484000 | AD31: 44000 | AE31: 22000 | AF31: 88000 | AG31: 110000 | AP31: 264000 | AT31: 1397.3665 | AU31: 1370.9873 | AV31: 1394.028 | AW31: 1409.6445 | BA31: 1427.4993 | BB31: 1444.4629 | BC31: 1401.5428 | BD31: 1441.5855 | BF31: 1336.5648 | BG31: 1355.0074 | BH31: 1372.8437 | BI31: 1368.2949 | BJ31: 1370.0188 | BK31: 1360.7887 | BL31: 1311.1208 | BN31: 1318.2886 | BP31: 1348.5185 | BQ31: 1257.5213 | BR31: 1269.1526 | BS31: 1124.3288 | BT31: 1124.8616 | CC31: 1158.8182
B32: 110000332 | iSS01084G | C32: Suntory Sri Thái Bình Dương | D32: 14300 | E32: 44000 | F32: 31900 | G32: 44000 | K32: -29981.8 | L32: 66000 | M32: 0 | N32: 88000 | O32: 22000 | P32: 280218.2 | Q32: -13750.7 | R32: 22000 | S32: 88000 | T32: 44000 | U32: -40039.7 | W32: 50969.1 | X32: 43293 | AA32: 88000 | AB32: 176000 | AC32: 458471.7 | AD32: 220000 | AE32: 44000 | AF32: 154000 | AG32: 88000 | AP32: 506000 | AQ32: 1410.5925 | AR32: 1418.7887 | AS32: 1404.4741 | AT32: 1397.1488 | AX32: 1419.0734 | AY32: 1465.2747 | BA32: 1420.9509 | BB32: 1441.884 | BC32: 1426.7536 | BD32: 1457.7516 | BE32: 1399.1938 | BF32: 1358.5985 | BG32: 1354.0928 | BH32: 1360.7312 | BJ32: 1370.8477 | BK32: 1350.2563 | BN32: 1317.5508 | BO32: 1320.572 | BP32: 1335.0514 | BQ32: 1256.4391 | BR32: 1268.4175 | BS32: 1122.723 | BT32: 1130.3378 | CC32: 1194.8538
B33: 110000332 | iSS01084G | C33: Suntory Việt Nam | I33: 6600 | J33: 4400 | K33: 651200 | L33: 153900 | M33: 311300 | N33: 418000 | O33: 572000 | P33: 2117400 | Q33: 154000 | R33: 484000 | S33: 154000 | T33: 374000 | U33: 330000 | V33: 351633 | W33: 132000 | X33: 616000 | Y33: 126500 | Z33: 382660 | AA33: 475340 | AB33: 682000 | AC33: 4262133 | AD33: 352000 | AE33: 264000 | AF33: 352000 | AG33: 528000 | AP33: 1496000 | AV33: 1362.6053 | AW33: 1367.2553 | AX33: 1425.6234 | AY33: 1407.8242 | AZ33: 1444.0849 | BA33: 1428.5148 | BB33: 1442.9236 | BC33: 1431.9705 | BD33: 1446.9593 | BE33: 1401.325 | BF33: 1364.2032 | BG33: 1343.7075 | BH33: 1374.0044 | BI33: 1340.6907 | BJ33: 1372.4129 | BK33: 1340.9875 | BL33: 1110.65 | BM33: 1286.0621 | BN33: 1310.4913 | BO33: 1321.4294 | BP33: 1337.9526 | BQ33: 1259.6401 | BR33: 1237.5293 | BS33: 1124.0658 | BT33: 1129.4897 | CC33: 1177.9029
B34: 110000332 | iSS01084G | C34: TRICON | AE34: 22000 | AP34: 22000 | BR34: 1270.8117 | CC34: 1270.8117
B35: 110000332 | iSS01084G | C35: Wiese | I35: 44000 | J35: 44000 | P35: 88000 | AV35: 1316.547 | AW35: 1318.6048 | BC35: 1317.5759
A36: Hạt iSS01084G | B36: 110000332 | iSS01084G Total | D36: 203525 | E36: 209000 | F36: 48400 | G36: 160600 | H36: 88000 | I36: 211700 | J36: 70400 | K36: 722418.2 | L36: 373900 | M36: 399300 | N36: 681600 | O36: 617100 | P36: 3785943.2 | Q36: 388849.3 | R36: 660000 | S36: 419100 | T36: 531300 | U36: 556160.3 | V36: 486422.2 | W36: 248969.1 | X36: 835293 | Y36: 236500 | Z36: 382660 | AA36: 717340 | AB36: 946000 | AC36: 6408593.9 | AD36: 616000 | AE36: 398200 | AF36: 772200 | AG36: 836000 | AP36: 2622400 | AQ36: 1327.8836 | AR36: 1349.5034 | AS36: 1407.6476 | AT36: 1355.3279 | AU36: 1354.1301 | AV36: 1327.1283 | AW36: 1350.0954 | AX36: 1415.1329 | AY36: 1375.7433 | AZ36: 1431.1249 | BA36: 1404.2107 | BB36: 1442.6826 | BC36: 1396.9593 | BD36: 1387.6579 | BE36: 1391.0448 | BF36: 1380.4574 | BG36: 1353.3675 | BH36: 1361.784 | BI36: 1338.1442 | BJ36: 1371.4578 | BK36: 1352.6898 | BL36: 1203.8923 | BM36: 1286.0621 | BN36: 1311.1855 | BO36: 1341.4884 | BP36: 1345.2792 | BQ36: 1258.3456 | BR36: 1249.9135 | BS36: 1156.4084 | BT36: 1146.4335 | CC36: 1191.3718
B37: 110000333 | WSS03 | C37: WORLD ELASTOMER | H37: 25 | P37: 25 | AU37: 1267.3217 | BC37: 1267.3217
A38: Hạt WSS03G | B38: 110000333 | WSS03 Total | H38: 25 | P38: 25 | AU38: 1267.3217 | BC38: 1267.3217
B39: 110000335 | WSS04 | C39: MEKONG BROS | Y39: 19800 | Z39: 9900 | AC39: 29700 | BL39: 728.82478 | BM39: 736.84149 | BP39: 731.49702
B40: 110000335 | WSS04 | C40: Việt Thành Plast | Y40: 24200 | Z40: 12100 | AA40: 30800 | AC40: 67100 | BL40: 740.8942 | BM40: 752.31395 | BN40: 786.39438 | BP40: 763.83883
...

Sheet Tóm tắt
B2: STT | C2: SẢN PHẨM | D2: GHI CHÚ | F2: SẢN LƯỢNG (Tấn) | AT2: GIÁ BÁN EXW (USD/Tấn) | CH2: GIÁ VỐN ĐƠN VỊ (VND/kg) | DV2: 24858.781 | DW2: 25788.124 | DX2: 26183.994 | ED2: 24858.781 | EE2: 25788.124 | EF2: 26183.994
F3: 2024 | S3: 2025 | AF3: 2026 | AT3: 2024 | BG3: 2025 | BT3: 2026 | CH3: 2024 | CU3: 2025 | DH3: 2026 | DV3: LG | DZ3: % SL | ED3: % BIÊN LG
A4: Link | F4: 1 | G4: 2 | H4: 3 | I4: 4 | J4: 5 | K4: 6 | L4: 7 | M4: 8 | N4: 9 | O4: 10 | P4: 11 | Q4: 12 | R4: TỔNG | S4: 1 | T4: 2 | U4: 3 | V4: 4 | W4: 5 | X4: 6 | Y4: 7 | Z4: 8 | AA4: 9 | AB4: 10 | AC4: 11 | AD4: 12 | AE4: TỔNG | AF4: 1 | AG4: 2 | AH4: 3 | AI4: 4 | AJ4: 5 | AK4: 6 | AL4: 7 | AM4: 8 | AN4: 9 | AO4: 10 | AP4: 11 | AQ4: 12 | AR4: TỔNG | AT4: 1 | AU4: 2 | AV4: 3 | AW4: 4 | AX4: 5 | AY4: 6 | AZ4: 7 | BA4: 8 | BB4: 9 | BC4: 10 | BD4: 11 | BE4: 12 | BF4: TỔNG | BG4: 1 | BH4: 2 | BI4: 3 | BJ4: 4 | BK4: 5 | BL4: 6 | BM4: 7 | BN4: 8 | BO4: 9 | BP4: 10 | BQ4: 11 | BR4: 12 | BS4: TỔNG | BT4: 1 | BU4: 2 | BV4: 3 | BW4: 4 | BX4: 5 | BY4: 6 | BZ4: 7 | CA4: 8 | CB4: 9 | CC4: 10 | CD4: 11 | CE4: 12 | CF4: TỔNG | CH4: 1 | CI4: 2 | CJ4: 3 | CK4: 4 | CL4: 5 | CM4: 6 | CN4: 7 | CO4: 8 | CP4: 9 | CQ4: 10 | CR4: 11 | CS4: 12 | CT4: TỔNG | CU4: 1 | CV4: 2 | CW4: 3 | CX4: 4 | CY4: 5 | CZ4: 6 | DA4: 7 | DB4: 8 | DC4: 9 | DD4: 10 | DE4: 11 | DF4: 12 | DG4: TỔNG | DH4: 1 | DI4: 2 | DJ4: 3 | DK4: 4 | DL4: 5 | DM4: 6 | DN4: 7 | DO4: 8 | DP4: 9 | DQ4: 10 | DR4: 11 | DS4: 12 | DT4: TỔNG | DV4: 2024 | DW4: 2025 | DX4: 2026 | DZ4: 2024 | EA4: 2025 | EB4: 2026 | ED4: 2024 | EE4: 2025 | EF4: 2026
A5: Hạt iSS01084G | B5: 1 | C5: Hạt iSS01084G | F5: =SUMIFS(Data!D$5:D$448,Data!$A$5:$A$448,'Tóm tắt'!$A5) -> 203525 | G5: =SUMIFS(Data!E$5:E$448,Data!$A$5:$A$448,'Tóm tắt'!$A5) -> 209000 | H5: =SUMIFS(Data!F$5:F$448,Data!$A$5:$A$448,'Tóm tắt'!$A5) -> 48400 | I5: =SUMIFS(Data!G$5:G$448,Data!$A$5:$A$448,'Tóm tắt'!$A5) -> 160600 | J5: =SUMIFS(Data!H$5:H$448,Data!$A$5:$A$448,'Tóm tắt'!$A5) -> 88000 | K5: =SUMIFS(Data!I$5:I$448,Data!$A$5:$A$448,'Tóm tắt'!$A5) -> 211700 | L5: =SUMIFS(Data!J$5:J$448,Data!$A$5:$A$448,'Tóm tắt'!$A5) -> 70400 | M5: =SUMIFS(Data!K$5:K$448,Data!$A$5:$A$448,'Tóm tắt'!$A5) -> 722418.2 | ... Q5: =SUMIFS(Data!O$5:O$448,Data!$A$5:$A$448,'Tóm tắt'!$A5) -> 617100 | R5: =SUM(F5:Q5) -> 3785943.2 | S5: =SUMIFS(Data!Q$5:Q$448,Data!$A$5:$A$448,'Tóm tắt'!$A5) -> 388849.3 | T5: =SUMIFS(Data!R$5:R$448,Data!$A$5:$A$448,'Tóm tắt'!$A5) -> 660000 | U5: =SUMIFS(Data!S$5:S$448,Data!$A$5:$A$448,'Tóm tắt'!$A5) -> 419100 | V5: =SUMIFS(Data!T$5:T$448,Data!$A$5:$A$448,'Tóm tắt'!$A5) -> 531300 | W5: =SUMIFS(Data!U$5:U$448,Data!$A$5:$A$448,'Tóm tắt'!$A5) -> 556160.3 | X5: =SUMIFS(Data!V$5:V$448,Data!$A$5:$A$448,'Tóm tắt'!$A5) -> 486422.2 | Y5: =SUMIFS(Data!W$5:W$448,Data!$A$5:$A$448,'Tóm tắt'!$A5) -> 248969.1 | Z5: =SUMIFS(Data!X$5:X$448,Data!$A$5:$A$448,'Tóm tắt'!$A5) -> 835293 | ... AD5: =SUMIFS(Data!AB$5:AB$448,Data!$A$5:$A$448,'Tóm tắt'!$A5) -> 946000 | AE5: =SUM(S5:AD5) -> 6408593.9 | AF5: =SUMIFS(Data!AD$5:AD$448,Data!$A$5:$A$448,'Tóm tắt'!$A5) -> 616000 | AG5: =SUMIFS(Data!AE$5:AE$448,Data!$A$5:$A$448,'Tóm tắt'!$A5) -> 398200 | AH5: =SUMIFS(Data!AF$5:AF$448,Data!$A$5:$A$448,'Tóm tắt'!$A5) -> 772200 | AI5: =SUMIFS(Data!AG$5:AG$448,Data!$A$5:$A$448,'Tóm tắt'!$A5) -> 880000 | AR5: =SUM(AF5:AQ5) -> 2666400 | AT5: {=IFERROR(SUMPRODUCT(Data!D$5:D$448*Data!AQ$5:AQ$448*(Data!$A$5:$A$448='Tóm tắt'!$A5))/SUMIFS(Data!D$5:D$448,Data!$A$5:$A$448,'Tóm tắt'!$A5),0)} -> 1327.8836 | AU5: {=IFERROR(SUMPRODUCT(Data!E$5:E$448*Data!AR$5:AR$448*(Data!$A$5:$A$448='Tóm tắt'!$A5))/SUMIFS(Data!E$5:E$448,Data!$A$5:$A$448,'Tóm tắt'!$A5),0)} -> 1349.5034 | AV5: {=IFERROR(SUMPRODUCT(Data!F$5:F$448*Data!AS$5:AS$448*(Data!$A$5:$A$448='Tóm tắt'!$A5))/SUMIFS(Data!F$5:F$448,Data!$A$5:$A$448,'Tóm tắt'!$A5),0)} -> 1407.6476 | AW5: {=IFERROR(SUMPRODUCT(Data!G$5:G$448*Data!AT$5:AT$448*(Data!$A$5:$A$448='Tóm tắt'!$A5))/SUMIFS(Data!G$5:G$448,Data!$A$5:$A$448,'Tóm tắt'!$A5),0)} -> 1355.3279 | AX5: {=IFERROR(SUMPRODUCT(Data!H$5:H$448*Data!AU$5:AU$448*(Data!$A$5:$A$448='Tóm tắt'!$A5))/SUMIFS(Data!H$5:H$448,Data!$A$5:$A$448,'Tóm tắt'!$A5),0)} -> 1354.1301 | AY5: {=IFERROR(SUMPRODUCT(Data!I$5:I$448*Data!AV$5:AV$448*(Data!$A$5:$A$448='Tóm tắt'!$A5))/SUMIFS(Data!I$5:I$448,Data!$A$5:$A$448,'Tóm tắt'!$A5),0)} -> 1327.1283 | AZ5: {=IFERROR(SUMPRODUCT(Data!J$5:J$448*Data!AW$5:AW$448*(Data!$A$5:$A$448='Tóm tắt'!$A5))/SUMIFS(Data!J$5:J$448,Data!$A$5:$A$448,'Tóm tắt'!$A5),0)} -> 1350.0954 | BA5: {=IFERROR(SUMPRODUCT(Data!K$5:K$448*Data!AX$5:AX$448*(Data!$A$5:$A$448='Tóm tắt'!$A5))/SUMIFS(Data!K$5:K$448,Data!$A$5:$A$448,'Tóm tắt'!$A5),0)} -> 1415.1329 | ... CF5: {=IFERROR(SUMPRODUCT(Data!AP$5:AP$448*Data!CC$5:CC$448*(Data!$A$5:$A$448='Tóm tắt'!$A5))/SUMIFS(Data!AP$5:AP$448,Data!$A$5:$A$448,'Tóm tắt'!$A5),0)} -> 1191.5563 | CH5: {=IFERROR(SUMPRODUCT(Data!CD$5:CD$448*Data!D$5:D$448*(Data!$A$5:$A$448='Tóm tắt'!$A5))/SUMIFS(Data!D$5:D$448,Data!$A$5:$A$448,'Tóm tắt'!$A5),0)} -> 21238.244 | CI5: {=IFERROR(SUMPRODUCT(Data!CE$5:CE$448*Data!E$5:E$448*(Data!$A$5:$A$448='Tóm tắt'!$A5))/SUMIFS(Data!E$5:E$448,Data!$A$5:$A$448,'Tóm tắt'!$A5),0)} -> 22878.932 | CJ5: {=IFERROR(SUMPRODUCT(Data!CF$5:CF$448*Data!F$5:F$448*(Data!$A$5:$A$448='Tóm tắt'!$A5))/SUMIFS(Data!F$5:F$448,Data!$A$5:$A$448,'Tóm tắt'!$A5),0)} -> 23530.176 | CK5: {=IFERROR(SUMPRODUCT(Data!CG$5:CG$448*Data!G$5:G$448*(Data!$A$5:$A$448='Tóm tắt'!$A5))/SUMIFS(Data!G$5:G$448,Data!$A$5:$A$448,'Tóm tắt'!$A5),0)} -> 24292.539 | CL5: {=IFERROR(SUMPRODUCT(Data!CH$5:CH$448*Data!H$5:H$448*(Data!$A$5:$A$448='Tóm tắt'!$A5))/SUMIFS(Data!H$5:H$448,Data!$A$5:$A$448,'Tóm tắt'!$A5),0)} -> 24249.994 | CM5: {=IFERROR(SUMPRODUCT(Data!CI$5:CI$448*Data!I$5:I$448*(Data!$A$5:$A$448='Tóm tắt'!$A5))/SUMIFS(Data!I$5:I$448,Data!$A$5:$A$448,'Tóm tắt'!$A5),0)} -> 25375.877 | CN5: {=IFERROR(SUMPRODUCT(Data!CJ$5:CJ$448*Data!J$5:J$448*(Data!$A$5:$A$448='Tóm tắt'!$A5))/SUMIFS(Data!J$5:J$448,Data!$A$5:$A$448,'Tóm tắt'!$A5),0)} -> 27313.012 | CO5: {=IFERROR(SUMPRODUCT(Data!CK$5:CK$448*Data!K$5:K$448*(Data!$A$5:$A$448='Tóm tắt'!$A5))/SUMIFS(Data!K$5:K$448,Data!$A$5:$A$448,'Tóm tắt'!$A5),0)} -> 31248.215 | ... DT5: {=IFERROR(SUMPRODUCT(Data!DP$5:DP$448*Data!AP$5:AP$448*(Data!$A$5:$A$448='Tóm tắt'!$A5))/SUMIFS(Data!AP$5:AP$448,Data!$A$5:$A$448,'Tóm tắt'!$A5),0)} -> 28651.781 | DV5: =(BF5/1000*$DV$2)-CT5 -> 7455.4526 | DW5: =(BS5/1000*$DW$2)-DG5 -> 6553.5938 | DX5: =(CF5/1000*$DX$2)-DT5 -> 2547.9223 | DZ5: =IFERROR(R5/SUM($R$5:$R$12),0) -> 0.10673147 | EA5: =IFERROR(AE5/SUM($AE$5:$AE$12),0) -> 0.15279483 | EB5: =IFERROR(AR5/SUM($AR$5:$AR$12),0) -> 0.16131306 | ED5: =IFERROR(1-CT5/(BF5*ED$2/10^3),0) -> 0.21468931 | EE5: =IFERROR(1-DG5/(BS5*EE$2/10^3),0) -> 0.18890669 | EF5: =IFERROR(1-DT5/(CF5*EF$2/10^3),0) -> 0.081664954
A6: Hạt iSS01G | B6: 2 | C6: Hạt iSS01G | F6: =SUMIFS(Data!D$5:D$448,Data!$A$5:$A$448,'Tóm tắt'!$A6) -> 902000 | G6: =SUMIFS(Data!E$5:E$448,Data!$A$5:$A$448,'Tóm tắt'!$A6) -> 44000 | H6: =SUMIFS(Data!F$5:F$448,Data!$A$5:$A$448,'Tóm tắt'!$A6) -> 666600 | I6: =SUMIFS(Data!G$5:G$448,Data!$A$5:$A$448,'Tóm tắt'!$A6) -> 668800 | J6: =SUMIFS(Data!H$5:H$448,Data!$A$5:$A$448,'Tóm tắt'!$A6) -> 23100 | K6: =SUMIFS(Data!I$5:I$448,Data!$A$5:$A$448,'Tóm tắt'!$A6) -> 92400 | L6: =SUMIFS(Data!J$5:J$448,Data!$A$5:$A$448,'Tóm tắt'!$A6) -> 6600 | M6: =SUMIFS(Data!K$5:K$448,Data!$A$5:$A$448,'Tóm tắt'!$A6) -> 631400 | ... Q6: =SUMIFS(Data!O$5:O$448,Data!$A$5:$A$448,'Tóm tắt'!$A6) -> 7700 | R6: =SUM(F6:Q6) -> 4414400 | S6: =SUMIFS(Data!Q$5:Q$448,Data!$A$5:$A$448,'Tóm tắt'!$A6) -> 143000 | T6: =SUMIFS(Data!R$5:R$448,Data!$A$5:$A$448,'Tóm tắt'!$A6) -> 2270400 | U6: =SUMIFS(Data!S$5:S$448,Data!$A$5:$A$448,'Tóm tắt'!$A6) -> 1786400 | V6: =SUMIFS(Data!T$5:T$448,Data!$A$5:$A$448,'Tóm tắt'!$A6) -> 1189600 | W6: =SUMIFS(Data!U$5:U$448,Data!$A$5:$A$448,'Tóm tắt'!$A6) -> 1854000 | X6: =SUMIFS(Data!V$5:V$448,Data!$A$5:$A$448,'Tóm tắt'!$A6) -> 1077435.8 | Y6: =SUMIFS(Data!W$5:W$448,Data!$A$5:$A$448,'Tóm tắt'!$A6) -> 957000 | Z6: =SUMIFS(Data!X$5:X$448,Data!$A$5:$A$448,'Tóm tắt'!$A6) -> 1287000 | ... AD6: =SUMIFS(Data!AB$5:AB$448,Data!$A$5:$A$448,'Tóm tắt'!$A6) -> 189200 | AE6: =SUM(S6:AD6) -> 10827736 | AF6: =SUMIFS(Data!AD$5:AD$448,Data!$A$5:$A$448,'Tóm tắt'!$A6) -> 25300 | AG6: =SUMIFS(Data!AE$5:AE$448,Data!$A$5:$A$448,'Tóm tắt'!$A6) -> 492800 | AH6: =SUMIFS(Data!AF$5:AF$448,Data!$A$5:$A$448,'Tóm tắt'!$A6) -> 1065950 | AI6: =SUMIFS(Data!AG$5:AG$448,Data!$A$5:$A$448,'Tóm tắt'!$A6) -> 103450 | AR6: =SUM(AF6:AQ6) -> 1687500 | AT6: {=IFERROR(SUMPRODUCT(Data!D$5:D$448*Data!AQ$5:AQ$448*(Data!$A$5:$A$448='Tóm tắt'!$A6))/SUMIFS(Data!D$5:D$448,Data!$A$5:$A$448,'Tóm tắt'!$A6),0)} -> 1128.4001 | AU6: {=IFERROR(SUMPRODUCT(Data!E$5:E$448*Data!AR$5:AR$448*(Data!$A$5:$A$448='Tóm tắt'!$A6))/SUMIFS(Data!E$5:E$448,Data!$A$5:$A$448,'Tóm tắt'!$A6),0)} -> 1252.8996 | AV6: {=IFERROR(SUMPRODUCT(Data!F$5:F$448*Data!AS$5:AS$448*(Data!$A$5:$A$448='Tóm tắt'!$A6))/SUMIFS(Data!F$5:F$448,Data!$A$5:$A$448,'Tóm tắt'!$A6),0)} -> 1266.1993 | AW6: {=IFERROR(SUMPRODUCT(Data!G$5:G$448*Data!AT$5:AT$448*(Data!$A$5:$A$448='Tóm tắt'!$A6))/SUMIFS(Data!G$5:G$448,Data!$A$5:$A$448,'Tóm tắt'!$A6),0)} -> 1260.6154 | AX6: {=IFERROR(SUMPRODUCT(Data!H$5:H$448*Data!AU$5:AU$448*(Data!$A$5:$A$448='Tóm tắt'!$A6))/SUMIFS(Data!H$5:H$448,Data!$A$5:$A$448,'Tóm tắt'!$A6),0)} -> 1225.5506 | AY6: {=IFERROR(SUMPRODUCT(Data!I$5:I$448*Data!AV$5:AV$448*(Data!$A$5:$A$448='Tóm tắt'!$A6))/SUMIFS(Data!I$5:I$448,Data!$A$5:$A$448,'Tóm tắt'!$A6),0)} -> 1353.2539 | AZ6: {=IFERROR(SUMPRODUCT(Data!J$5:J$448*Data!AW$5:AW$448*(Data!$A$5:$A$448='Tóm tắt'!$A6))/SUMIFS(Data!J$5:J$448,Data!$A$5:$A$448,'Tóm tắt'!$A6),0)} -> 1359.7878 | BA6: {=IFERROR(SUMPRODUCT(Data!K$5:K$448*Data!AX$5:AX$448*(Data!$A$5:$A$448='Tóm tắt'!$A6))/SUMIFS(Data!K$5:K$448,Data!$A$5:$A$448,'Tóm tắt'!$A6),0)} -> 1194.5947 | ... CF6: {=IFERROR(SUMPRODUCT(Data!AP$5:AP$448*Data!CC$5:CC$448*(Data!$A$5:$A$448='Tóm tắt'!$A6))/SUMIFS(Data!AP$5:AP$448,Data!$A$5:$A$448,'Tóm tắt'!$A6),0)} -> 1141.4236 | CH6: {=IFERROR(SUMPRODUCT(Data!CD$5:CD$448*Data!D$5:D$448*(Data!$A$5:$A$448='Tóm tắt'!$A6))/SUMIFS(Data!D$5:D$448,Data!$A$5:$A$448,'Tóm tắt'!$A6),0)} -> 21465.658 | CI6: {=IFERROR(SUMPRODUCT(Data!CE$5:CE$448*Data!E$5:E$448*(Data!$A$5:$A$448='Tóm tắt'!$A6))/SUMIFS(Data!E$5:E$448,Data!$A$5:$A$448,'Tóm tắt'!$A6),0)} -> 21452.451 | CJ6: {=IFERROR(SUMPRODUCT(Data!CF$5:CF$448*Data!F$5:F$448*(Data!$A$5:$A$448='Tóm tắt'!$A6))/SUMIFS(Data!F$5:F$448,Data!$A$5:$A$448,'Tóm tắt'!$A6),0)} -> 22381.843 | CK6: {=IFERROR(SUMPRODUCT(Data!CG$5:CG$448*Data!G$5:G$448*(Data!$A$5:$A$448='Tóm tắt'!$A6))/SUMIFS(Data!G$5:G$448,Data!$A$5:$A$448,'Tóm tắt'!$A6),0)} -> 22418.984 | CL6: {=IFERROR(SUMPRODUCT(Data!CH$5:CH$448*Data!H$5:H$448*(Data!$A$5:$A$448='Tóm tắt'!$A6))/SUMIFS(Data!H$5:H$448,Data!$A$5:$A$448,'Tóm tắt'!$A6),0)} -> 24247.446 | CM6: {=IFERROR(SUMPRODUCT(Data!CI$5:CI$448*Data!I$5:I$448*(Data!$A$5:$A$448='Tóm tắt'!$A6))/SUMIFS(Data!I$5:I$448,Data!$A$5:$A$448,'Tóm tắt'!$A6),0)} -> 23118.401 | CN6: {=IFERROR(SUMPRODUCT(Data!CJ$5:CJ$448*Data!J$5:J$448*(Data!$A$5:$A$448='Tóm tắt'!$A6))/SUMIFS(Data!J$5:J$448,Data!$A$5:$A$448,'Tóm tắt'!$A6),0)} -> 23390.034 | CO6: {=IFERROR(SUMPRODUCT(Data!CK$5:CK$448*Data!K$5:K$448*(Data!$A$5:$A$448='Tóm tắt'!$A6))/SUMIFS(Data!K$5:K$448,Data!$A$5:$A$448,'Tóm tắt'!$A6),0)} -> 23973.139 | ... DT6: {=IFERROR(SUMPRODUCT(Data!DP$5:DP$448*Data!AP$5:AP$448*(Data!$A$5:$A$448='Tóm tắt'!$A6))/SUMIFS(Data!AP$5:AP$448,Data!$A$5:$A$448,'Tóm tắt'!$A6),0)} -> 26450.813 | DV6: =(BF6/1000*$DV$2)-CT6 -> 7344.2375 | DW6: =(BS6/1000*$DW$2)-DG6 -> 6156.4827 | DX6: =(CF6/1000*$DX$2)-DT6 -> 3436.2169 | DZ6: =IFERROR(R6/SUM($R$5:$R$12),0) -> 0.12444862 | EA6: =IFERROR(AE6/SUM($AE$5:$AE$12),0) -> 0.25815679 | EB6: =IFERROR(AR6/SUM($AR$5:$AR$12),0) -> 0.10209113 | ED6: =IFERROR(1-CT6/(BF6*ED$2/10^3),0) -> 0.24154413 | EE6: =IFERROR(1-DG6/(BS6*EE$2/10^3),0) -> 0.19283262 | EF6: =IFERROR(1-DT6/(CF6*EF$2/10^3),0) -> 0.11497352
A7: Hạt WSS01G | B7: 3 | C7: Hạt WSS01G | D7: Bao gồm WSS01 | F7: =SUMIFS(Data!D$5:D$448,Data!$A$5:$A$448,'Tóm tắt'!$A7) -> 1302400 | G7: =SUMIFS(Data!E$5:E$448,Data!$A$5:$A$448,'Tóm tắt'!$A7) -> 1709400 | H7: =SUMIFS(Data!F$5:F$448,Data!$A$5:$A$448,'Tóm tắt'!$A7) -> 1788900 | I7: =SUMIFS(Data!G$5:G$448,Data!$A$5:$A$448,'Tóm tắt'!$A7) -> 1463000 | J7: =SUMIFS(Data!H$5:H$448,Data!$A$5:$A$448,'Tóm tắt'!$A7) -> 2441800 | K7: =SUMIFS(Data!I$5:I$448,Data!$A$5:$A$448,'Tóm tắt'!$A7) -> 1150000 | L7: =SUMIFS(Data!J$5:J$448,Data!$A$5:$A$448,'Tóm tắt'!$A7) -> 1217900 | M7: =SUMIFS(Data!K$5:K$448,Data!$A$5:$A$448,'Tóm tắt'!$A7) -> 2181700 | ... Q7: =SUMIFS(Data!O$5:O$448,Data!$A$5:$A$448,'Tóm tắt'!$A7) -> 1725900 | R7: =SUM(F7:Q7) -> 19788700 | S7: =SUMIFS(Data!Q$5:Q$448,Data!$A$5:$A$448,'Tóm tắt'!$A7) -> 2850100 | T7: =SUMIFS(Data!R$5:R$448,Data!$A$5:$A$448,'Tóm tắt'!$A7) -> 2172500 | U7: =SUMIFS(Data!S$5:S$448,Data!$A$5:$A$448,'Tóm tắt'!$A7) -> 1581700 | V7: =SUMIFS(Data!T$5:T$448,Data!$A$5:$A$448,'Tóm tắt'!$A7) -> 1699500 | W7: =SUMIFS(Data!U$5:U$448,Data!$A$5:$A$448,'Tóm tắt'!$A7) -> 1785300 | X7: =SUMIFS(Data!V$5:V$448,Data!$A$5:$A$448,'Tóm tắt'!$A7) -> 1272725 | Y7: =SUMIFS(Data!W$5:W$448,Data!$A$5:$A$448,'Tóm tắt'!$A7) -> 2068000 | Z7: =SUMIFS(Data!X$5:X$448,Data!$A$5:$A$448,'Tóm tắt'!$A7) -> 1771300 | ... AD7: =SUMIFS(Data!AB$5:AB$448,Data!$A$5:$A$448,'Tóm tắt'!$A7) -> 1092300 | AE7: =SUM(S7:AD7) -> 19703925 | AF7: =SUMIFS(Data!AD$5:AD$448,Data!$A$5:$A$448,'Tóm tắt'!$A7) -> 2674100 | AG7: =SUMIFS(Data!AE$5:AE$448,Data!$A$5:$A$448,'Tóm tắt'!$A7) -> 1868900 | AH7: =SUMIFS(Data!AF$5:AF$448,Data!$A$5:$A$448,'Tóm tắt'!$A7) -> 2057000 | AI7: =SUMIFS(Data!AG$5:AG$448,Data!$A$5:$A$448,'Tóm tắt'!$A7) -> 1929600 | AR7: =SUM(AF7:AQ7) -> 8529600 | AT7: {=IFERROR(SUMPRODUCT(Data!D$5:D$448*Data!AQ$5:AQ$448*(Data!$A$5:$A$448='Tóm tắt'!$A7))/SUMIFS(Data!D$5:D$448,Data!$A$5:$A$448,'Tóm tắt'!$A7),0)} -> 1213.1984 | AU7: {=IFERROR(SUMPRODUCT(Data!E$5:E$448*Data!AR$5:AR$448*(Data!$A$5:$A$448='Tóm tắt'!$A7))/SUMIFS(Data!E$5:E$448,Data!$A$5:$A$448,'Tóm tắt'!$A7),0)} -> 1214.8932 | AV7: {=IFERROR(SUMPRODUCT(Data!F$5:F$448*Data!AS$5:AS$448*(Data!$A$5:$A$448='Tóm tắt'!$A7))/SUMIFS(Data!F$5:F$448,Data!$A$5:$A$448,'Tóm tắt'!$A7),0)} -> 1214.5032 | AW7: {=IFERROR(SUMPRODUCT(Data!G$5:G$448*Data!AT$5:AT$448*(Data!$A$5:$A$448='Tóm tắt'!$A7))/SUMIFS(Data!G$5:G$448,Data!$A$5:$A$448,'Tóm tắt'!$A7),0)} -> 1188.4613 | AX7: {=IFERROR(SUMPRODUCT(Data!H$5:H$448*Data!AU$5:AU$448*(Data!$A$5:$A$448='Tóm tắt'!$A7))/SUMIFS(Data!H$5:H$448,Data!$A$5:$A$448,'Tóm tắt'!$A7),0)} -> 1217.1202 | AY7: {=IFERROR(SUMPRODUCT(Data!I$5:I$448*Data!AV$5:AV$448*(Data!$A$5:$A$448='Tóm tắt'!$A7))/SUMIFS(Data!I$5:I$448,Data!$A$5:$A$448,'Tóm tắt'!$A7),0)} -> 1231.3255 | AZ7: {=IFERROR(SUMPRODUCT(Data!J$5:J$448*Data!AW$5:AW$448*(Data!$A$5:$A$448='Tóm tắt'!$A7))/SUMIFS(Data!J$5:J$448,Data!$A$5:$A$448,'Tóm tắt'!$A7),0)} -> 1204.9108 | BA7: {=IFERROR(SUMPRODUCT(Data!K$5:K$448*Data!AX$5:AX$448*(Data!$A$5:$A$448='Tóm tắt'!$A7))/SUMIFS(Data!K$5:K$448,Data!$A$5:$A$448,'Tóm tắt'!$A7),0)} -> 1207.1536 | ... CF7: {=IFERROR(SUMPRODUCT(Data!AP$5:AP$448*Data!CC$5:CC$448*(Data!$A$5:$A$448='Tóm tắt'!$A7))/SUMIFS(Data!AP$5:AP$448,Data!$A$5:$A$448,'Tóm tắt'!$A7),0)} -> 1113.4411 | CH7: {=IFERROR(SUMPRODUCT(Data!CD$5:CD$448*Data!D$5:D$448*(Data!$A$5:$A$448='Tóm tắt'!$A7))/SUMIFS(Data!D$5:D$448,Data!$A$5:$A$448,'Tóm tắt'!$A7),0)} -> 22677.159 | CI7: {=IFERROR(SUMPRODUCT(Data!CE$5:CE$448*Data!E$5:E$448*(Data!$A$5:$A$448='Tóm tắt'!$A7))/SUMIFS(Data!E$5:E$448,Data!$A$5:$A$448,'Tóm tắt'!$A7),0)} -> 23766.92 | CJ7: {=IFERROR(SUMPRODUCT(Data!CF$5:CF$448*Data!F$5:F$448*(Data!$A$5:$A$448='Tóm tắt'!$A7))/SUMIFS(Data!F$5:F$448,Data!$A$5:$A$448,'Tóm tắt'!$A7),0)} -> 23757.094 | CK7: {=IFERROR(SUMPRODUCT(Data!CG$5:CG$448*Data!G$5:G$448*(Data!$A$5:$A$448='Tóm tắt'!$A7))/SUMIFS(Data!G$5:G$448,Data!$A$5:$A$448,'Tóm tắt'!$A7),0)} -> 23816 | CL7: {=IFERROR(SUMPRODUCT(Data!CH$5:CH$448*Data!H$5:H$448*(Data!$A$5:$A$448='Tóm tắt'!$A7))/SUMIFS(Data!H$5:H$448,Data!$A$5:$A$448,'Tóm tắt'!$A7),0)} -> 24951.226 | CM7: {=IFERROR(SUMPRODUCT(Data!CI$5:CI$448*Data!I$5:I$448*(Data!$A$5:$A$448='Tóm tắt'!$A7))/SUMIFS(Data!I$5:I$448,Data!$A$5:$A$448,'Tóm tắt'!$A7),0)} -> 24543.866 | CN7: {=IFERROR(SUMPRODUCT(Data!CJ$5:CJ$448*Data!J$5:J$448*(Data!$A$5:$A$448='Tóm tắt'!$A7))/SUMIFS(Data!J$5:J$448,Data!$A$5:$A$448,'Tóm tắt'!$A7),0)} -> 24508.522 | CO7: {=IFERROR(SUMPRODUCT(Data!CK$5:CK$448*Data!K$5:K$448*(Data!$A$5:$A$448='Tóm tắt'!$A7))/SUMIFS(Data!K$5:K$448,Data!$A$5:$A$448,'Tóm tắt'!$A7),0)} -> 24710.339 | ... DT7: {=IFERROR(SUMPRODUCT(Data!DP$5:DP$448*Data!AP$5:AP$448*(Data!$A$5:$A$448='Tóm tắt'!$A7))/SUMIFS(Data!AP$5:AP$448,Data!$A$5:$A$448,'Tóm tắt'!$A7),0)} -> 26272.021 | DV7: =(BF7/1000*$DV$2)-CT7 -> 6035.1009 | DW7: =(BS7/1000*$DW$2)-DG7 -> 4306.8816 | DX7: =(CF7/1000*$DX$2)-DT7 -> 2882.3153 | DZ7: =IFERROR(R7/SUM($R$5:$R$12),0) -> 0.5578734 | EA7: =IFERROR(AE7/SUM($AE$5:$AE$12),0) -> 0.46978446 | EB7: =IFERROR(AR7/SUM($AR$5:$AR$12),0) -> 0.51602755 | ED7: =IFERROR(1-CT7/(BF7*ED$2/10^3),0) -> 0.19830199 | EE7: =IFERROR(1-DG7/(BS7*EE$2/10^3),0) -> 0.13868111 | EF7: =IFERROR(1-DT7/(CF7*EF$2/10^3),0) -> 0.098864034
A8: Hạt WSS03G | B8: 4 | C8: Hạt WSS03G | D8: Bao gồm WSS03: Không bao gồm lượng bán cho PW | F8: =SUMIFS(Data!D$5:D$448,Data!$A$5:$A$448,'Tóm tắt'!$A8) -> 440000 | G8: =SUMIFS(Data!E$5:E$448,Data!$A$5:$A$448,'Tóm tắt'!$A8) -> 0 | H8: =SUMIFS(Data!F$5:F$448,Data!$A$5:$A$448,'Tóm tắt'!$A8) -> 176000 | I8: =SUMIFS(Data!G$5:G$448,Data!$A$5:$A$448,'Tóm tắt'!$A8) -> 441100 | J8: =SUMIFS(Data!H$5:H$448,Data!$A$5:$A$448,'Tóm tắt'!$A8) -> 330025 | K8: =SUMIFS(Data!I$5:I$448,Data!$A$5:$A$448,'Tóm tắt'!$A8) -> 110000 | L8: =SUMIFS(Data!J$5:J$448,Data!$A$5:$A$448,'Tóm tắt'!$A8) -> 1100 | M8: =SUMIFS(Data!K$5:K$448,Data!$A$5:$A$448,'Tóm tắt'!$A8) -> 5500 | ... Q8: =SUMIFS(Data!O$5:O$448,Data!$A$5:$A$448,'Tóm tắt'!$A8) -> 1100 | R8: =SUM(F8:Q8) -> 1740225 | S8: =SUMIFS(Data!Q$5:Q$448,Data!$A$5:$A$448,'Tóm tắt'!$A8) -> 0 | T8: =SUMIFS(Data!R$5:R$448,Data!$A$5:$A$448,'Tóm tắt'!$A8) -> 45100 | U8: =SUMIFS(Data!S$5:S$448,Data!$A$5:$A$448,'Tóm tắt'!$A8) -> 231000 | V8: =SUMIFS(Data!T$5:T$448,Data!$A$5:$A$448,'Tóm tắt'!$A8) -> 154000 | W8: =SUMIFS(Data!U$5:U$448,Data!$A$5:$A$448,'Tóm tắt'!$A8) -> 11000 | X8: =SUMIFS(Data!V$5:V$448,Data!$A$5:$A$448,'Tóm tắt'!$A8) -> 44000 | Y8: =SUMIFS(Data!W$5:W$448,Data!$A$5:$A$448,'Tóm tắt'!$A8) -> 374850 | Z8: =SUMIFS(Data!X$5:X$448,Data!$A$5:$A$448,'Tóm tắt'!$A8) -> 44000 | ... AD8: =SUMIFS(Data!AB$5:AB$448,Data!$A$5:$A$448,'Tóm tắt'!$A8) -> 0 | AE8: =SUM(S8:AD8) -> 1235050 | AF8: =SUMIFS(Data!AD$5:AD$448,Data!$A$5:$A$448,'Tóm tắt'!$A8) -> 2200 | AG8: =SUMIFS(Data!AE$5:AE$448,Data!$A$5:$A$448,'Tóm tắt'!$A8) -> 5500 | AH8: =SUMIFS(Data!AF$5:AF$448,Data!$A$5:$A$448,'Tóm tắt'!$A8) -> 440150 | AI8: =SUMIFS(Data!AG$5:AG$448,Data!$A$5:$A$448,'Tóm tắt'!$A8) -> 798600 | AR8: =SUM(AF8:AQ8) -> 1246450 | AT8: {=IFERROR(SUMPRODUCT(Data!D$5:D$448*Data!AQ$5:AQ$448*(Data!$A$5:$A$448='Tóm tắt'!$A8))/SUMIFS(Data!D$5:D$448,Data!$A$5:$A$448,'Tóm tắt'!$A8),0)} -> 1100.8707 | AU8: {=IFERROR(SUMPRODUCT(Data!E$5:E$448*Data!AR$5:AR$448*(Data!$A$5:$A$448='Tóm tắt'!$A8))/SUMIFS(Data!E$5:E$448,Data!$A$5:$A$448,'Tóm tắt'!$A8),0)} -> 0 | AV8: {=IFERROR(SUMPRODUCT(Data!F$5:F$448*Data!AS$5:AS$448*(Data!$A$5:$A$448='Tóm tắt'!$A8))/SUMIFS(Data!F$5:F$448,Data!$A$5:$A$448,'Tóm tắt'!$A8),0)} -> 1078.9487 | AW8: {=IFERROR(SUMPRODUCT(Data!G$5:G$448*Data!AT$5:AT$448*(Data!$A$5:$A$448='Tóm tắt'!$A8))/SUMIFS(Data!G$5:G$448,Data!$A$5:$A$448,'Tóm tắt'!$A8),0)} -> 1054.632 | AX8: {=IFERROR(SUMPRODUCT(Data!H$5:H$448*Data!AU$5:AU$448*(Data!$A$5:$A$448='Tóm tắt'!$A8))/SUMIFS(Data!H$5:H$448,Data!$A$5:$A$448,'Tóm tắt'!$A8),0)} -> 1049.6032 | AY8: {=IFERROR(SUMPRODUCT(Data!I$5:I$448*Data!AV$5:AV$448*(Data!$A$5:$A$448='Tóm tắt'!$A8))/SUMIFS(Data!I$5:I$448,Data!$A$5:$A$448,'Tóm tắt'!$A8),0)} -> 1061.9429 | AZ8: {=IFERROR(SUMPRODUCT(Data!J$5:J$448*Data!AW$5:AW$448*(Data!$A$5:$A$448='Tóm tắt'!$A8))/SUMIFS(Data!J$5:J$448,Data!$A$5:$A$448,'Tóm tắt'!$A8),0)} -> 1046.668 | BA8: {=IFERROR(SUMPRODUCT(Data!K$5:K$448*Data!AX$5:AX$448*(Data!$A$5:$A$448='Tóm tắt'!$A8))/SUMIFS(Data!K$5:K$448,Data!$A$5:$A$448,'Tóm tắt'!$A8),0)} -> 1220.8142 | ... CF8: {=IFERROR(SUMPRODUCT(Data!AP$5:AP$448*Data!CC$5:CC$448*(Data!$A$5:$A$448='Tóm tắt'!$A8))/SUMIFS(Data!AP$5:AP$448,Data!$A$5:$A$448,'Tóm tắt'!$A8),0)} -> 1104.6328 | CH8: {=IFERROR(SUMPRODUCT(Data!CD$5:CD$448*Data!D$5:D$448*(Data!$A$5:$A$448='Tóm tắt'!$A8))/SUMIFS(Data!D$5:D$448,Data!$A$5:$A$448,'Tóm tắt'!$A8),0)} -> 28600.565 | CI8: {=IFERROR(SUMPRODUCT(Data!CE$5:CE$448*Data!E$5:E$448*(Data!$A$5:$A$448='Tóm tắt'!$A8))/SUMIFS(Data!E$5:E$448,Data!$A$5:$A$448,'Tóm tắt'!$A8),0)} -> 0 | CJ8: {=IFERROR(SUMPRODUCT(Data!CF$5:CF$448*Data!F$5:F$448*(Data!$A$5:$A$448='Tóm tắt'!$A8))/SUMIFS(Data!F$5:F$448,Data!$A$5:$A$448,'Tóm tắt'!$A8),0)} -> 31994.902 | CK8: {=IFERROR(SUMPRODUCT(Data!CG$5:CG$448*Data!G$5:G$448*(Data!$A$5:$A$448='Tóm tắt'!$A8))/SUMIFS(Data!G$5:G$448,Data!$A$5:$A$448,'Tóm tắt'!$A8),0)} -> 22894.548 | CL8: {=IFERROR(SUMPRODUCT(Data!CH$5:CH$448*Data!H$5:H$448*(Data!$A$5:$A$448='Tóm tắt'!$A8))/SUMIFS(Data!H$5:H$448,Data!$A$5:$A$448,'Tóm tắt'!$A8),0)} -> 35741.912 | CM8: {=IFERROR(SUMPRODUCT(Data!CI$5:CI$448*Data!I$5:I$448*(Data!$A$5:$A$448='Tóm tắt'!$A8))/SUMIFS(Data!I$5:I$448,Data!$A$5:$A$448,'Tóm tắt'!$A8),0)} -> 36010.117 | CN8: {=IFERROR(SUMPRODUCT(Data!CJ$5:CJ$448*Data!J$5:J$448*(Data!$A$5:$A$448='Tóm tắt'!$A8))/SUMIFS(Data!J$5:J$448,Data!$A$5:$A$448,'Tóm tắt'!$A8),0)} -> 34637.483 | CO8: {=IFERROR(SUMPRODUCT(Data!CK$5:CK$448*Data!K$5:K$448*(Data!$A$5:$A$448='Tóm tắt'!$A8))/SUMIFS(Data!K$5:K$448,Data!$A$5:$A$448,'Tóm tắt'!$A8),0)} -> 32734.511 | ... DT8: {=IFERROR(SUMPRODUCT(Data!DP$5:DP$448*Data!AP$5:AP$448*(Data!$A$5:$A$448='Tóm tắt'!$A8))/SUMIFS(Data!AP$5:AP$448,Data!$A$5:$A$448,'Tóm tắt'!$A8),0)} -> 27210.348 | DV8: =(BF8/1000*$DV$2)-CT8 -> -2656.7833 | DW8: =(BS8/1000*$DW$2)-DG8 -> 2396.4609 | DX8: =(CF8/1000*$DX$2)-DT8 -> 1713.3515 | DZ8: =IFERROR(R8/SUM($R$5:$R$12),0) -> 0.049059576 | EA8: =IFERROR(AE8/SUM($AE$5:$AE$12),0) -> 0.02944628 | EB8: =IFERROR(AR8/SUM($AR$5:$AR$12),0) -> 0.075408289 | ED8: =IFERROR(1-CT8/(BF8*ED$2/10^3),0) -> -0.099977432 | EE8: =IFERROR(1-DG8/(BS8*EE$2/10^3),0) -> 0.085174979 | EF8: =IFERROR(1-DT8/(CF8*EF$2/10^3),0) -> 0.05923694
A9: Hạt WSS03G-PW | B9: 5 | C9: Hạt WSS03G-PW | F9: =SUMIFS(Data!D$5:D$448,Data!$A$5:$A$448,'Tóm tắt'!$A9) -> 0 | G9: =SUMIFS(Data!E$5:E$448,Data!$A$5:$A$448,'Tóm tắt'!$A9) -> 0 | H9: =SUMIFS(Data!F$5:F$448,Data!$A$5:$A$448,'Tóm tắt'!$A9) -> 0 | I9: =SUMIFS(Data!G$5:G$448,Data!$A$5:$A$448,'Tóm tắt'!$A9) -> 0 | J9: =SUMIFS(Data!H$5:H$448,Data!$A$5:$A$448,'Tóm tắt'!$A9) -> 0 | K9: =SUMIFS(Data!I$5:I$448,Data!$A$5:$A$448,'Tóm tắt'!$A9) -> 0 | L9: =SUMIFS(Data!J$5:J$448,Data!$A$5:$A$448,'Tóm tắt'!$A9) -> 211200 | M9: =SUMIFS(Data!K$5:K$448,Data!$A$5:$A$448,'Tóm tắt'!$A9) -> 887300 | ... Q9: =SUMIFS(Data!O$5:O$448,Data!$A$5:$A$448,'Tóm tắt'!$A9) -> 0 | R9: =SUM(F9:Q9) -> 2418500 | S9: =SUMIFS(Data!Q$5:Q$448,Data!$A$5:$A$448,'Tóm tắt'!$A9) -> 0 | T9: =SUMIFS(Data!R$5:R$448,Data!$A$5:$A$448,'Tóm tắt'!$A9) -> 0 | U9: =SUMIFS(Data!S$5:S$448,Data!$A$5:$A$448,'Tóm tắt'!$A9) -> 0 | V9: =SUMIFS(Data!T$5:T$448,Data!$A$5:$A$448,'Tóm tắt'!$A9) -> 0 | W9: =SUMIFS(Data!U$5:U$448,Data!$A$5:$A$448,'Tóm tắt'!$A9) -> 0 | X9: =SUMIFS(Data!V$5:V$448,Data!$A$5:$A$448,'Tóm tắt'!$A9) -> 220000 | Y9: =SUMIFS(Data!W$5:W$448,Data!$A$5:$A$448,'Tóm tắt'!$A9) -> 0 | Z9: =SUMIFS(Data!X$5:X$448,Data!$A$5:$A$448,'Tóm tắt'!$A9) -> 220000 | ... AD9: =SUMIFS(Data!AB$5:AB$448,Data!$A$5:$A$448,'Tóm tắt'!$A9) -> 0 | AE9: =SUM(S9:AD9) -> 660000 | AF9: =SUMIFS(Data!AD$5:AD$448,Data!$A$5:$A$448,'Tóm tắt'!$A9) -> 242000 | AG9: =SUMIFS(Data!AE$5:AE$448,Data!$A$5:$A$448,'Tóm tắt'!$A9) -> 0 | AH9: =SUMIFS(Data!AF$5:AF$448,Data!$A$5:$A$448,'Tóm tắt'!$A9) -> 220000 | AI9: =SUMIFS(Data!AG$5:AG$448,Data!$A$5:$A$448,'Tóm tắt'!$A9) -> 440000 | AR9: =SUM(AF9:AQ9) -> 902000 | AT9: {=IFERROR(SUMPRODUCT(Data!D$5:D$448*Data!AQ$5:AQ$448*(Data!$A$5:$A$448='Tóm tắt'!$A9))/SUMIFS(Data!D$5:D$448,Data!$A$5:$A$448,'Tóm tắt'!$A9),0)} -> 0 | AU9: {=IFERROR(SUMPRODUCT(Data!E$5:E$448*Data!AR$5:AR$448*(Data!$A$5:$A$448='Tóm tắt'!$A9))/SUMIFS(Data!E$5:E$448,Data!$A$5:$A$448,'Tóm tắt'!$A9),0)} -> 0 | AV9: {=IFERROR(SUMPRODUCT(Data!F$5:F$448*Data!AS$5:AS$448*(Data!$A$5:$A$448='Tóm tắt'!$A9))/SUMIFS(Data!F$5:F$448,Data!$A$5:$A$448,'Tóm tắt'!$A9),0)} -> 0 | AW9: {=IFERROR(SUMPRODUCT(Data!G$5:G$448*Data!AT$5:AT$448*(Data!$A$5:$A$448='Tóm tắt'!$A9))/SUMIFS(Data!G$5:G$448,Data!$A$5:$A$448,'Tóm tắt'!$A9),0)} -> 0 | AX9: {=IFERROR(SUMPRODUCT(Data!H$5:H$448*Data!AU$5:AU$448*(Data!$A$5:$A$448='Tóm tắt'!$A9))/SUMIFS(Data!H$5:H$448,Data!$A$5:$A$448,'Tóm tắt'!$A9),0)} -> 0 | AY9: {=IFERROR(SUMPRODUCT(Data!I$5:I$448*Data!AV$5:AV$448*(Data!$A$5:$A$448='Tóm tắt'!$A9))/SUMIFS(Data!I$5:I$448,Data!$A$5:$A$448,'Tóm tắt'!$A9),0)} -> 0 | AZ9: {=IFERROR(SUMPRODUCT(Data!J$5:J$448*Data!AW$5:AW$448*(Data!$A$5:$A$448='Tóm tắt'!$A9))/SUMIFS(Data!J$5:J$448,Data!$A$5:$A$448,'Tóm tắt'!$A9),0)} -> 1040.193 | BA9: {=IFERROR(SUMPRODUCT(Data!K$5:K$448*Data!AX$5:AX$448*(Data!$A$5:$A$448='Tóm tắt'!$A9))/SUMIFS(Data!K$5:K$448,Data!$A$5:$A$448,'Tóm tắt'!$A9),0)} -> 1041.3398 | ... CF9: {=IFERROR(SUMPRODUCT(Data!AP$5:AP$448*Data!CC$5:CC$448*(Data!$A$5:$A$448='Tóm tắt'!$A9))/SUMIFS(Data!AP$5:AP$448,Data!$A$5:$A$448,'Tóm tắt'!$A9),0)} -> 1034.1907 | CH9: {=IFERROR(SUMPRODUCT(Data!CD$5:CD$448*Data!D$5:D$448*(Data!$A$5:$A$448='Tóm tắt'!$A9))/SUMIFS(Data!D$5:D$448,Data!$A$5:$A$448,'Tóm tắt'!$A9),0)} -> 0 | CI9: {=IFERROR(SUMPRODUCT(Data!CE$5:CE$448*Data!E$5:E$448*(Data!$A$5:$A$448='Tóm tắt'!$A9))/SUMIFS(Data!E$5:E$448,Data!$A$5:$A$448,'Tóm tắt'!$A9),0)} -> 0 | CJ9: {=IFERROR(SUMPRODUCT(Data!CF$5:CF$448*Data!F$5:F$448*(Data!$A$5:$A$448='Tóm tắt'!$A9))/SUMIFS(Data!F$5:F$448,Data!$A$5:$A$448,'Tóm tắt'!$A9),0)} -> 0 | CK9: {=IFERROR(SUMPRODUCT(Data!CG$5:CG$448*Data!G$5:G$448*(Data!$A$5:$A$448='Tóm tắt'!$A9))/SUMIFS(Data!G$5:G$448,Data!$A$5:$A$448,'Tóm tắt'!$A9),0)} -> 0 | CL9: {=IFERROR(SUMPRODUCT(Data!CH$5:CH$448*Data!H$5:H$448*(Data!$A$5:$A$448='Tóm tắt'!$A9))/SUMIFS(Data!H$5:H$448,Data!$A$5:$A$448,'Tóm tắt'!$A9),0)} -> 0 | CM9: {=IFERROR(SUMPRODUCT(Data!CI$5:CI$448*Data!I$5:I$448*(Data!$A$5:$A$448='Tóm tắt'!$A9))/SUMIFS(Data!I$5:I$448,Data!$A$5:$A$448,'Tóm tắt'!$A9),0)} -> 0 | CN9: {=IFERROR(SUMPRODUCT(Data!CJ$5:CJ$448*Data!J$5:J$448*(Data!$A$5:$A$448='Tóm tắt'!$A9))/SUMIFS(Data!J$5:J$448,Data!$A$5:$A$448,'Tóm tắt'!$A9),0)} -> 34637.483 | CO9: {=IFERROR(SUMPRODUCT(Data!CK$5:CK$448*Data!K$5:K$448*(Data!$A$5:$A$448='Tóm tắt'!$A9))/SUMIFS(Data!K$5:K$448,Data!$A$5:$A$448,'Tóm tắt'!$A9),0)} -> 32734.511 | ... DT9: {=IFERROR(SUMPRODUCT(Data!DP$5:DP$448*Data!AP$5:AP$448*(Data!$A$5:$A$448='Tóm tắt'!$A9))/SUMIFS(Data!AP$5:AP$448,Data!$A$5:$A$448,'Tóm tắt'!$A9),0)} -> 27142.653 | DV9: =(BF9/1000*$DV$2)-CT9 -> -4540.5051 | DW9: =(BS9/1000*$DW$2)-DG9 -> -181.90601 | DX9: =(CF9/1000*$DX$2)-DT9 -> -63.410749 | DZ9: =IFERROR(R9/SUM($R$5:$R$12),0) -> 0.068181175 | EA9: =IFERROR(AE9/SUM($AE$5:$AE$12),0) -> 0.015735836 | EB9: =IFERROR(AR9/SUM($AR$5:$AR$12),0) -> 0.054569599 | ED9: =IFERROR(1-CT9/(BF9*ED$2/10^3),0) -> -0.1744607 | EE9: =IFERROR(1-DG9/(BS9*EE$2/10^3),0) -> -0.0072350472 | EF9: =IFERROR(1-DT9/(CF9*EF$2/10^3),0) -> -0.0023416737
A10: Hạt WSS05SB | B10: 6 | C10: Hạt WSS05SB (sợi ngắn) | F10: =SUMIFS(Data!D$5:D$448,Data!$A$5:$A$448,'Tóm tắt'!$A10) -> 0 | G10: =SUMIFS(Data!E$5:E$448,Data!$A$5:$A$448,'Tóm tắt'!$A10) -> 0 | H10: =SUMIFS(Data!F$5:F$448,Data!$A$5:$A$448,'Tóm tắt'!$A10) -> 0 | I10: =SUMIFS(Data!G$5:G$448,Data!$A$5:$A$448,'Tóm tắt'!$A10) -> 225500 | J10: =SUMIFS(Data!H$5:H$448,Data!$A$5:$A$448,'Tóm tắt'!$A10) -> 82500 | K10: =SUMIFS(Data!I$5:I$448,Data!$A$5:$A$448,'Tóm tắt'!$A10) -> 185900 | L10: =SUMIFS(Data!J$5:J$448,Data!$A$5:$A$448,'Tóm tắt'!$A10) -> 165000 | M10: =SUMIFS(Data!K$5:K$448,Data!$A$5:$A$448,'Tóm tắt'!$A10) -> 0 | ... Q10: =SUMIFS(Data!O$5:O$448,Data!$A$5:$A$448,'Tóm tắt'!$A10) -> 242000 | R10: =SUM(F10:Q10) -> 1362900 | S10: =SUMIFS(Data!Q$5:Q$448,Data!$A$5:$A$448,'Tóm tắt'!$A10) -> 11000 | T10: =SUMIFS(Data!R$5:R$448,Data!$A$5:$A$448,'Tóm tắt'!$A10) -> 16500 | U10: =SUMIFS(Data!S$5:S$448,Data!$A$5:$A$448,'Tóm tắt'!$A10) -> 33000 | V10: =SUMIFS(Data!T$5:T$448,Data!$A$5:$A$448,'Tóm tắt'!$A10) -> 0 | W10: =SUMIFS(Data!U$5:U$448,Data!$A$5:$A$448,'Tóm tắt'!$A10) -> 0 | X10: =SUMIFS(Data!V$5:V$448,Data!$A$5:$A$448,'Tóm tắt'!$A10) -> 146900 | Y10: =SUMIFS(Data!W$5:W$448,Data!$A$5:$A$448,'Tóm tắt'!$A10) -> 567800 | Z10: =SUMIFS(Data!X$5:X$448,Data!$A$5:$A$448,'Tóm tắt'!$A10) -> 321350 | ... AD10: =SUMIFS(Data!AB$5:AB$448,Data!$A$5:$A$448,'Tóm tắt'!$A10) -> 22050 | AE10: =SUM(S10:AD10) -> 1543175 | AF10: =SUMIFS(Data!AD$5:AD$448,Data!$A$5:$A$448,'Tóm tắt'!$A10) -> 23100 | AG10: =SUMIFS(Data!AE$5:AE$448,Data!$A$5:$A$448,'Tóm tắt'!$A10) -> 67200 | AH10: =SUMIFS(Data!AF$5:AF$448,Data!$A$5:$A$448,'Tóm tắt'!$A10) -> 342500 | AI10: =SUMIFS(Data!AG$5:AG$448,Data!$A$5:$A$448,'Tóm tắt'!$A10) -> 249000 | AR10: =SUM(AF10:AQ10) -> 681800 | AT10: {=IFERROR(SUMPRODUCT(Data!D$5:D$448*Data!AQ$5:AQ$448*(Data!$A$5:$A$448='Tóm tắt'!$A10))/SUMIFS(Data!D$5:D$448,Data!$A$5:$A$448,'Tóm tắt'!$A10),0)} -> 0 | AU10: {=IFERROR(SUMPRODUCT(Data!E$5:E$448*Data!AR$5:AR$448*(Data!$A$5:$A$448='Tóm tắt'!$A10))/SUMIFS(Data!E$5:E$448,Data!$A$5:$A$448,'Tóm tắt'!$A10),0)} -> 0 | AV10: {=IFERROR(SUMPRODUCT(Data!F$5:F$448*Data!AS$5:AS$448*(Data!$A$5:$A$448='Tóm tắt'!$A10))/SUMIFS(Data!F$5:F$448,Data!$A$5:$A$448,'Tóm tắt'!$A10),0)} -> 0 | AW10: {=IFERROR(SUMPRODUCT(Data!G$5:G$448*Data!AT$5:AT$448*(Data!$A$5:$A$448='Tóm tắt'!$A10))/SUMIFS(Data!G$5:G$448,Data!$A$5:$A$448,'Tóm tắt'!$A10),0)} -> 660.75676 | AX10: {=IFERROR(SUMPRODUCT(Data!H$5:H$448*Data!AU$5:AU$448*(Data!$A$5:$A$448='Tóm tắt'!$A10))/SUMIFS(Data!H$5:H$448,Data!$A$5:$A$448,'Tóm tắt'!$A10),0)} -> 776.62806 | AY10: {=IFERROR(SUMPRODUCT(Data!I$5:I$448*Data!AV$5:AV$448*(Data!$A$5:$A$448='Tóm tắt'!$A10))/SUMIFS(Data!I$5:I$448,Data!$A$5:$A$448,'Tóm tắt'!$A10),0)} -> 657.24161 | AZ10: {=IFERROR(SUMPRODUCT(Data!J$5:J$448*Data!AW$5:AW$448*(Data!$A$5:$A$448='Tóm tắt'!$A10))/SUMIFS(Data!J$5:J$448,Data!$A$5:$A$448,'Tóm tắt'!$A10),0)} -> 647.38245 | BA10: {=IFERROR(SUMPRODUCT(Data!K$5:K$448*Data!AX$5:AX$448*(Data!$A$5:$A$448='Tóm tắt'!$A10))/SUMIFS(Data!K$5:K$448,Data!$A$5:$A$448,'Tóm tắt'!$A10),0)} -> 0 | ... CF10: {=IFERROR(SUMPRODUCT(Data!AP$5:AP$448*Data!CC$5:CC$448*(Data!$A$5:$A$448='Tóm tắt'!$A10))/SUMIFS(Data!AP$5:AP$448,Data!$A$5:$A$448,'Tóm tắt'!$A10),0)} -> 677.32982 | CH10: {=IFERROR(SUMPRODUCT(Data!CD$5:CD$448*Data!D$5:D$448*(Data!$A$5:$A$448='Tóm tắt'!$A10))/SUMIFS(Data!D$5:D$448,Data!$A$5:$A$448,'Tóm tắt'!$A10),0)} -> 0 | CI10: {=IFERROR(SUMPRODUCT(Data!CE$5:CE$448*Data!E$5:E$448*(Data!$A$5:$A$448='Tóm tắt'!$A10))/SUMIFS(Data!E$5:E$448,Data!$A$5:$A$448,'Tóm tắt'!$A10),0)} -> 0 | CJ10: {=IFERROR(SUMPRODUCT(Data!CF$5:CF$448*Data!F$5:F$448*(Data!$A$5:$A$448='Tóm tắt'!$A10))/SUMIFS(Data!F$5:F$448,Data!$A$5:$A$448,'Tóm tắt'!$A10),0)} -> 0 | CK10: {=IFERROR(SUMPRODUCT(Data!CG$5:CG$448*Data!G$5:G$448*(Data!$A$5:$A$448='Tóm tắt'!$A10))/SUMIFS(Data!G$5:G$448,Data!$A$5:$A$448,'Tóm tắt'!$A10),0)} -> 22576.962 | CL10: {=IFERROR(SUMPRODUCT(Data!CH$5:CH$448*Data!H$5:H$448*(Data!$A$5:$A$448='Tóm tắt'!$A10))/SUMIFS(Data!H$5:H$448,Data!$A$5:$A$448,'Tóm tắt'!$A10),0)} -> 17180.141 | CM10: {=IFERROR(SUMPRODUCT(Data!CI$5:CI$448*Data!I$5:I$448*(Data!$A$5:$A$448='Tóm tắt'!$A10))/SUMIFS(Data!I$5:I$448,Data!$A$5:$A$448,'Tóm tắt'!$A10),0)} -> 20929.099 | CN10: {=IFERROR(SUMPRODUCT(Data!CJ$5:CJ$448*Data!J$5:J$448*(Data!$A$5:$A$448='Tóm tắt'!$A10))/SUMIFS(Data!J$5:J$448,Data!$A$5:$A$448,'Tóm tắt'!$A10),0)} -> 23715.01 | CO10: {=IFERROR(SUMPRODUCT(Data!CK$5:CK$448*Data!K$5:K$448*(Data!$A$5:$A$448='Tóm tắt'!$A10))/SUMIFS(Data!K$5:K$448,Data!$A$5:$A$448,'Tóm tắt'!$A10),0)} -> 0 | ... DT10: {=IFERROR(SUMPRODUCT(Data!DP$5:DP$448*Data!AP$5:AP$448*(Data!$A$5:$A$448='Tóm tắt'!$A10))/SUMIFS(Data!AP$5:AP$448,Data!$A$5:$A$448,'Tóm tắt'!$A10),0)} -> 28400.674 | DV10: =(BF10/1000*$DV$2)-CT10 -> -5304.2025 | DW10: =(BS10/1000*$DW$2)-DG10 -> -9503.7105 | DX10: =(CF10/1000*$DX$2)-DT10 -> -10665.474 | DZ10: =IFERROR(R10/SUM($R$5:$R$12),0) -> 0.038422213 | EA10: =IFERROR(AE10/SUM($AE$5:$AE$12),0) -> 0.036792651 | EB10: =IFERROR(AR10/SUM($AR$5:$AR$12),0) -> 0.041247841 | ED10: =IFERROR(1-CT10/(BF10*ED$2/10^3),0) -> -0.30591295 | EE10: =IFERROR(1-DG10/(BS10*EE$2/10^3),0) -> -0.55380621 | EF10: =IFERROR(1-DT10/(CF10*EF$2/10^3),0) -> -0.60137322
