Workbook

Sheet Chụp hình
F1: x | G1: cthuc | H1: x | I1: cthuc | J1: x | L1: x | M1: cthuc | N1: x | R1: x | S1: cthuc | U1: x | V1: cthuc | W1: cthuc | X1: x | Y1: cthuc | Z1: cthuc | AC1: Check | AD1: Check | AE1: Check | AF1: Check | AL1: Check
C2: STT | D2: Phân loại | E2: Chỉ tiêu ĐVT: triệu đồng/tấn | F2: BQ TT 2023 | G2: Tỷ trọng BQ TT 2023 | H2: BQ TT 2024 | I2: Tỷ trọng BQ TT 2024 | J2: BQ TT 2025 | K2: Tỷ trọng BQ TT 2025 | L2: ĐINH MỨC 2026 | M2: % | N2: T1.26 | O2: T2.26 | P2: T3.26 | Q2: T04.26 | R2: T05.26 | S2: %T05 | T2: Biểu đồ | U2: BQ TT 2026 | V2: Tỷ trọng BQ TT 2026 | W2: BQ TT 2026 sv BQ TT 2025 | X2: KH T05.26 | Y2: %KH T05.26 | Z2: T05.26 sv KHT05.26 | AC2: BQ TT 2023 | AD2: BQ TT 2024 | AE2: BQ TT 2025 | AF2: ĐINH MỨC 2026 | AG2: 1 | AH2: 2 | AI2: 3 | AJ2: 4 | AK2: 5 | AL2: BQ TT 2026 | AM2: KH T05.26
C3: I | E3: BIẾN PHÍ | F3: 21.103404 | G3: =IFERROR(F3/F$23,0) -> 0.85569853 | H3: 21.105216 | I3: =IFERROR(H3/H$23,0) -> 0.74480595 | J3: 22.537179 | K3: =IFERROR(J3/J$23,0) -> 0.71567875 | L3: 20.18159 | M3: =IFERROR(L3/L$23,0) -> 0.69714186 | N3: 21.773669 | O3: 20.618296 | P3: 21.39789 | Q3: 20.698947 | R3: 22.131872 | S3: =IFERROR(R3/R$23,0) -> 0.7105949 | U3: 21.345378 | V3: =IFERROR(U3/U$23,0) -> 0.69646507 | W3: =U3-H3 -> 0.24016262 | X3: 20.124577 | Y3: =IFERROR(X3/X$23,0) -> 0.69349147 | Z3: =R3-X3 -> 2.0072952 | AC3: =F3-'18 KMP- Tháng (Tâm)'!Q40 -> 0 | AD3: =H3-'18 KMP- Tháng (Tâm)'!AD40 -> 0 | AE3: =J3-'18 KMP- Tháng (Tâm)'!AQ40 -> 0 | AF3: =L3-'18 KMP- Tháng (Tâm)'!BE40 -> -0.00041127798 | AG3: =N3-'18 KMP- Tháng (Tâm)'!BF40 -> 0 | AH3: =O3-'18 KMP- Tháng (Tâm)'!BG40 -> 0 | AI3: =P3-'18 KMP- Tháng (Tâm)'!BH40 -> 0 | AJ3: =Q3-'18 KMP- Tháng (Tâm)'!BI40 -> 0 | AK3: =R3-'18 KMP- Tháng (Tâm)'!BJ40 -> 0 | AL3: =U3-'18 KMP- Tháng (Tâm)'!BR40 -> -0.19896252 | AM3: =X3-'18 KMP- Tháng (Tâm)'!AW40 -> 0
C4: 1 | D4: Biến phí | E4: Nguyên liệu nhựa (chai, vảy) | F4: 19.326224 | G4: =IFERROR(F4/F$23,0) -> 0.78363763 | H4: 18.507378 | I4: =IFERROR(H4/H$23,0) -> 0.6531279 | J4: 19.649038 | K4: =IFERROR(J4/J$23,0) -> 0.62396447 | L4: 17.822333 | M4: =IFERROR(L4/L$23,0) -> 0.61564496 | N4: 18.923356 | O4: 18.104206 | P4: 18.460639 | Q4: 17.780534 | R4: 18.757434 | S4: =IFERROR(R4/R$23,0) -> 0.60225076 | U4: 18.388298 | V4: =IFERROR(U4/U$23,0) -> 0.59998033 | W4: =U4-H4 -> -0.11908005 | X4: 17.818769 | Y4: =IFERROR(X4/X$23,0) -> 0.61403348 | Z4: =R4-X4 -> 0.93866542 | AC4: =F4-'18 KMP- Tháng (Tâm)'!Q41 -> 0 | AD4: =H4-'18 KMP- Tháng (Tâm)'!AD41 -> 0 | AE4: =J4-'18 KMP- Tháng (Tâm)'!AQ41 -> 0 | AF4: =L4-'18 KMP- Tháng (Tâm)'!BE41 -> 0 | AG4: =N4-'18 KMP- Tháng (Tâm)'!BF41 -> 0 | AH4: =O4-'18 KMP- Tháng (Tâm)'!BG41 -> 0 | AI4: =P4-'18 KMP- Tháng (Tâm)'!BH41 -> 0 | AJ4: =Q4-'18 KMP- Tháng (Tâm)'!BI41 -> 0 | AK4: =R4-'18 KMP- Tháng (Tâm)'!BJ41 -> 0 | AL4: =U4-'18 KMP- Tháng (Tâm)'!BR41 -> -0.15698232 | AM4: =X4-'18 KMP- Tháng (Tâm)'!AW41 -> 0
C5: 2 | D5: Biến phí | E5: Điện | F5: 0.77740656 | G5: =IFERROR(F5/F$23,0) -> 0.031522197 | H5: 1.3414 | I5: =IFERROR(H5/H$23,0) -> 0.047338189 | J5: 1.5446285 | K5: =IFERROR(J5/J$23,0) -> 0.049050407 | L5: 1.2213584 | M5: =IFERROR(L5/L$23,0) -> 0.042189941 | N5: 1.4296972 | O5: 1.3841663 | P5: 1.3377107 | Q5: 1.3171969 | R5: 1.6388901 | S5: =IFERROR(R5/R$23,0) -> 0.052620353 | U5: 1.4169204 | V5: =IFERROR(U5/U$23,0) -> 0.046231813 | W5: =U5-H5 -> 0.075520399 | X5: 1.1702205 | Y5: =IFERROR(X5/X$23,0) -> 0.040325714 | Z5: =R5-X5 -> 0.46866957 | AC5: =F5-'18 KMP- Tháng (Tâm)'!Q42 -> 0 | AD5: =H5-'18 KMP- Tháng (Tâm)'!AD42 -> 0 | AE5: =J5-'18 KMP- Tháng (Tâm)'!AQ42 -> 0 | AF5: =L5-'18 KMP- Tháng (Tâm)'!BE42 -> 0 | AG5: =N5-'18 KMP- Tháng (Tâm)'!BF42 -> 0 | AH5: =O5-'18 KMP- Tháng (Tâm)'!BG42 -> 0 | AI5: =P5-'18 KMP- Tháng (Tâm)'!BH42 -> 0 | AJ5: =Q5-'18 KMP- Tháng (Tâm)'!BI42 -> 0 | AK5: =R5-'18 KMP- Tháng (Tâm)'!BJ42 -> 0 | AL5: =U5-'18 KMP- Tháng (Tâm)'!BR42 -> -0.026403582 | AM5: =X5-'18 KMP- Tháng (Tâm)'!AW42 -> 0
C6: 3 | D6: Biến phí | E6: Chi phí bán hàng | F6: 0.24640422 | G6: =IFERROR(F6/F$23,0) -> 0.0099911713 | H6: 0.34817413 | I6: =IFERROR(H6/H$23,0) -> 0.012287112 | J6: 0.35394856 | K6: =IFERROR(J6/J$23,0) -> 0.011239803 | L6: 0.16237096 | M6: =IFERROR(L6/L$23,0) -> 0.0056088541 | N6: 0.39672845 | O6: 0.37364426 | P6: 0.55097182 | Q6: 0.59141362 | R6: 0.55539731 | S6: =IFERROR(R6/R$23,0) -> 0.017832314 | U6: 0.50913359 | V6: =IFERROR(U6/U$23,0) -> 0.016612203 | W6: =U6-H6 -> 0.16095947 | X6: 0.16150262 | Y6: =IFERROR(X6/X$23,0) -> 0.0055653685 | Z6: =R6-X6 -> 0.39389469 | AC6: =F6-'18 KMP- Tháng (Tâm)'!Q43 -> 0 | AD6: =H6-'18 KMP- Tháng (Tâm)'!AD43 -> 0 | AE6: =J6-'18 KMP- Tháng (Tâm)'!AQ43 -> 0 | AF6: =L6-'18 KMP- Tháng (Tâm)'!BE43 -> -0.00091127798 | AG6: =N6-'18 KMP- Tháng (Tâm)'!BF43 -> 0 | AH6: =O6-'18 KMP- Tháng (Tâm)'!BG43 -> 0 | AI6: =P6-'18 KMP- Tháng (Tâm)'!BH43 -> 0 | AJ6: =Q6-'18 KMP- Tháng (Tâm)'!BI43 -> 0 | AK6: =R6-'18 KMP- Tháng (Tâm)'!BJ43 -> 0 | AL6: =U6-'18 KMP- Tháng (Tâm)'!BR43 -> 0.0058066273 | AM6: =X6-'18 KMP- Tháng (Tâm)'!AW43 -> 0
C7: 4 | D7: Biến phí | E7: Phụ gia theo Bom | F7: 0.262149 | G7: =IFERROR(F7/F$23,0) -> 0.010629589 | H7: 0.32217464 | I7: =IFERROR(H7/H$23,0) -> 0.011369587 | J7: 0.38434714 | K7: =IFERROR(J7/J$23,0) -> 0.012205124 | L7: 0.32147451 | M7: =IFERROR(L7/L$23,0) -> 0.011104841 | N7: 0.31066963 | O7: 0.1593293 | P7: 0.4120435 | Q7: 0.31727822 | R7: 0.50520515 | S7: =IFERROR(R7/R$23,0) -> 0.016220779 | U7: 0.36311703 | V7: =IFERROR(U7/U$23,0) -> 0.01184792 | W7: =U7-H7 -> 0.040942396 | X7: 0.32224192 | Y7: =IFERROR(X7/X$23,0) -> 0.011104433 | Z7: =R7-X7 -> 0.18296324 | AC7: =F7-'18 KMP- Tháng (Tâm)'!Q44 -> 0 | AD7: =H7-'18 KMP- Tháng (Tâm)'!AD44 -> 0 | AE7: =J7-'18 KMP- Tháng (Tâm)'!AQ44 -> 0 | AF7: =L7-'18 KMP- Tháng (Tâm)'!BE44 -> 0 | AG7: =N7-'18 KMP- Tháng (Tâm)'!BF44 -> 0 | AH7: =O7-'18 KMP- Tháng (Tâm)'!BG44 -> 0 | AI7: =P7-'18 KMP- Tháng (Tâm)'!BH44 -> 0 | AJ7: =Q7-'18 KMP- Tháng (Tâm)'!BI44 -> 0 | AK7: =R7-'18 KMP- Tháng (Tâm)'!BJ44 -> 0 | AL7: =U7-'18 KMP- Tháng (Tâm)'!BR44 -> -0.013784646 | AM7: =X7-'18 KMP- Tháng (Tâm)'!AW44 -> 0
C8: 5 | D8: Biến phí | E8: Vật liệu phục vụ SX | F8: 0.16637841 | G8: =IFERROR(F8/F$23,0) -> 0.0067462935 | H8: 0.2040567 | I8: =IFERROR(H8/H$23,0) -> 0.0072011889 | J8: 0.19485263 | K8: =IFERROR(J8/J$23,0) -> 0.006187637 | L8: 0.21560547 | M8: =IFERROR(L8/L$23,0) -> 0.007447758 | N8: 0.25226622 | O8: 0.21272439 | P8: 0.1901747 | Q8: 0.1999204 | R8: 0.19067252 | S8: =IFERROR(R8/R$23,0) -> 0.0061219817 | U8: 0.20573619 | V8: =IFERROR(U8/U$23,0) -> 0.0067128382 | W8: =U8-H8 -> 0.0016794913 | X8: 0.2153132 | Y8: =IFERROR(X8/X$23,0) -> 0.0074196772 | Z8: =R8-X8 -> -0.024640683 | AC8: =F8-'18 KMP- Tháng (Tâm)'!Q45 -> 0 | AD8: =H8-'18 KMP- Tháng (Tâm)'!AD45 -> 0 | AE8: =J8-'18 KMP- Tháng (Tâm)'!AQ45 -> 0 | AF8: =L8-'18 KMP- Tháng (Tâm)'!BE45 -> 0.0005 | AG8: =N8-'18 KMP- Tháng (Tâm)'!BF45 -> 0 | AH8: =O8-'18 KMP- Tháng (Tâm)'!BG45 -> 0 | AI8: =P8-'18 KMP- Tháng (Tâm)'!BH45 -> 0 | AJ8: =Q8-'18 KMP- Tháng (Tâm)'!BI45 -> 0 | AK8: =R8-'18 KMP- Tháng (Tâm)'!BJ45 -> 0 | AL8: =U8-'18 KMP- Tháng (Tâm)'!BR45 -> -0.0003598435 | AM8: =X8-'18 KMP- Tháng (Tâm)'!AW45 -> 0
C9: 6 | D9: Biến phí | E9: Bao bì theo Bom | F9: 0.0985497 | G9: =IFERROR(F9/F$23,0) -> 0.0039959825 | H9: 0.17167992 | I9: =IFERROR(H9/H$23,0) -> 0.0060586077 | J9: 0.18658237 | K9: =IFERROR(J9/J$23,0) -> 0.0059250111 | L9: 0.17243903 | M9: =IFERROR(L9/L$23,0) -> 0.00595664 | N9: 0.21148089 | O9: 0.19195792 | P9: 0.19018724 | Q9: 0.23440054 | R9: 0.21860374 | S9: =IFERROR(R9/R$23,0) -> 0.007018778 | U9: 0.21143784 | V9: =IFERROR(U9/U$23,0) -> 0.0068988737 | W9: =U9-H9 -> 0.039757925 | X9: 0.17175223 | Y9: =IFERROR(X9/X$23,0) -> 0.0059185693 | Z9: =R9-X9 -> 0.046851509 | AC9: =F9-'18 KMP- Tháng (Tâm)'!Q46 -> 0 | AD9: =H9-'18 KMP- Tháng (Tâm)'!AD46 -> 0 | AE9: =J9-'18 KMP- Tháng (Tâm)'!AQ46 -> 0 | AF9: =L9-'18 KMP- Tháng (Tâm)'!BE46 -> 0 | AG9: =N9-'18 KMP- Tháng (Tâm)'!BF46 -> 0 | AH9: =O9-'18 KMP- Tháng (Tâm)'!BG46 -> 0 | AI9: =P9-'18 KMP- Tháng (Tâm)'!BH46 -> 0 | AJ9: =Q9-'18 KMP- Tháng (Tâm)'!BI46 -> 0 | AK9: =R9-'18 KMP- Tháng (Tâm)'!BJ46 -> 0 | AL9: =U9-'18 KMP- Tháng (Tâm)'!BR46 -> -0.0019371452 | AM9: =X9-'18 KMP- Tháng (Tâm)'!AW46 -> 0
C10: 7 | D10: Biến phí | E10: Xăng dầu | F10: 0.087574391 | G10: =IFERROR(F10/F$23,0) -> 0.0035509569 | H10: 0.089762189 | I10: =IFERROR(H10/H$23,0) -> 0.0031677199 | J10: 0.059670505 | K10: =IFERROR(J10/J$23,0) -> 0.001894865 | L10: 0.0556608 | M10: =IFERROR(L10/L$23,0) -> 0.0019227164 | N10: 0.056262493 | O10: 0.059392774 | P10: 0.080017807 | Q10: 0.090513136 | R10: 0.099345285 | S10: =IFERROR(R10/R$23,0) -> 0.0031897099 | U10: 0.080597362 | V10: =IFERROR(U10/U$23,0) -> 0.0026297612 | W10: =U10-H10 -> -0.009164827 | X10: 0.055951749 | Y10: =IFERROR(X10/X$23,0) -> 0.0019280932 | Z10: =R10-X10 -> 0.043393536 | AC10: =F10-'18 KMP- Tháng (Tâm)'!Q47 -> 0 | AD10: =H10-'18 KMP- Tháng (Tâm)'!AD47 -> 0 | AE10: =J10-'18 KMP- Tháng (Tâm)'!AQ47 -> 0 | AF10: =L10-'18 KMP- Tháng (Tâm)'!BE47 -> 0 | AG10: =N10-'18 KMP- Tháng (Tâm)'!BF47 -> 0 | AH10: =O10-'18 KMP- Tháng (Tâm)'!BG47 -> 0 | AI10: =P10-'18 KMP- Tháng (Tâm)'!BH47 -> 0 | AJ10: =Q10-'18 KMP- Tháng (Tâm)'!BI47 -> 0 | AK10: =R10-'18 KMP- Tháng (Tâm)'!BJ47 -> 0 | AL10: =U10-'18 KMP- Tháng (Tâm)'!BR47 -> -0.00099452763 | AM10: =X10-'18 KMP- Tháng (Tâm)'!AW47 -> 0
C11: 8 | D11: Biến phí | E11: Hóa chất theo Bom | F11: 0.065260354 | G11: =IFERROR(F11/F$23,0) -> 0.0026461697 | H11: 0.060344766 | I11: =IFERROR(H11/H$23,0) -> 0.002129575 | J11: 0.082818259 | K11: =IFERROR(J11/J$23,0) -> 0.0026299328 | L11: 0.11366734 | M11: =IFERROR(L11/L$23,0) -> 0.0039264626 | N11: 0.087970546 | O11: 0.044184172 | P11: 0.081501785 | Q11: 0.10486957 | R11: 0.10735033 | S11: =IFERROR(R11/R$23,0) -> 0.0034467303 | U11: 0.090127159 | V11: =IFERROR(U11/U$23,0) -> 0.002940703 | W11: =U11-H11 -> 0.029782393 | X11: 0.11384384 | Y11: =IFERROR(X11/X$23,0) -> 0.0039230504 | Z11: =R11-X11 -> -0.0064935099 | AC11: =F11-'18 KMP- Tháng (Tâm)'!Q48 -> 0 | AD11: =H11-'18 KMP- Tháng (Tâm)'!AD48 -> 0 | AE11: =J11-'18 KMP- Tháng (Tâm)'!AQ48 -> 0 | AF11: =L11-'18 KMP- Tháng (Tâm)'!BE48 -> 0 | AG11: =N11-'18 KMP- Tháng (Tâm)'!BF48 -> 0 | AH11: =O11-'18 KMP- Tháng (Tâm)'!BG48 -> 0 | AI11: =P11-'18 KMP- Tháng (Tâm)'!BH48 -> 0 | AJ11: =Q11-'18 KMP- Tháng (Tâm)'!BI48 -> 0 | AK11: =R11-'18 KMP- Tháng (Tâm)'!BJ48 -> 0 | AL11: =U11-'18 KMP- Tháng (Tâm)'!BR48 -> -0.0027313829 | AM11: =X11-'18 KMP- Tháng (Tâm)'!AW48 -> 0
C12: 9 | D12: Biến phí | E12: Hóa chất XLNT | F12: 0.030350639 | G12: =IFERROR(F12/F$23,0) -> 0.0012306544 | H12: 0.022706169 | I12: =IFERROR(H12/H$23,0) -> 0.00080130382 | J12: 0.023539575 | K12: =IFERROR(J12/J$23,0) -> 0.00074751031 | L12: 0.030105657 | M12: =IFERROR(L12/L$23,0) -> 0.0010399534 | N12: 0.024412645 | O12: 0.022889019 | P12: 0.023206195 | Q12: 0.025077589 | R12: 0.023418515 | S12: =IFERROR(R12/R$23,0) -> 0.00075190554 | U12: 0.023905142 | V12: =IFERROR(U12/U$23,0) -> 0.00077998601 | W12: =U12-H12 -> 0.0011989729 | X12: 0.029519561 | Y12: =IFERROR(X12/X$23,0) -> 0.0010172419 | Z12: =R12-X12 -> -0.0061010455 | AC12: =F12-'18 KMP- Tháng (Tâm)'!Q49 -> 0 | AD12: =H12-'18 KMP- Tháng (Tâm)'!AD49 -> 0 | AE12: =J12-'18 KMP- Tháng (Tâm)'!AQ49 -> 0 | AF12: =L12-'18 KMP- Tháng (Tâm)'!BE49 -> 0 | AG12: =N12-'18 KMP- Tháng (Tâm)'!BF49 -> 0 | AH12: =O12-'18 KMP- Tháng (Tâm)'!BG49 -> 0 | AI12: =P12-'18 KMP- Tháng (Tâm)'!BH49 -> 0 | AJ12: =Q12-'18 KMP- Tháng (Tâm)'!BI49 -> 0 | AK12: =R12-'18 KMP- Tháng (Tâm)'!BJ49 -> 0 | AL12: =U12-'18 KMP- Tháng (Tâm)'!BR49 -> -0.00074642193 | AM12: =X12-'18 KMP- Tháng (Tâm)'!AW49 -> 0
C13: 10 | D13: Biến phí | E13: Nước | F13: 0.034821989 | G13: =IFERROR(F13/F$23,0) -> 0.0014119582 | H13: 0.033800688 | I13: =IFERROR(H13/H$23,0) -> 0.0011928309 | J13: 0.040146216 | K13: =IFERROR(J13/J$23,0) -> 0.001274862 | L13: 0.052572473 | M13: =IFERROR(L13/L$23,0) -> 0.0018160349 | N13: 0.038964303 | O13: 0.043897742 | P13: 0.024758423 | Q13: 0.028485417 | R13: 0.034816441 | S13: =IFERROR(R13/R$23,0) -> 0.0011178623 | U13: 0.032312855 | V13: =IFERROR(U13/U$23,0) -> 0.001054316 | W13: =U13-H13 -> -0.0014878327 | X13: 0.053434829 | Y13: =IFERROR(X13/X$23,0) -> 0.0018413603 | Z13: =R13-X13 -> -0.018618388 | AC13: =F13-'18 KMP- Tháng (Tâm)'!Q50 -> 0 | AD13: =H13-'18 KMP- Tháng (Tâm)'!AD50 -> 0 | AE13: =J13-'18 KMP- Tháng (Tâm)'!AQ50 -> 0 | AF13: =L13-'18 KMP- Tháng (Tâm)'!BE50 -> 0 | AG13: =N13-'18 KMP- Tháng (Tâm)'!BF50 -> 0 | AH13: =O13-'18 KMP- Tháng (Tâm)'!BG50 -> 0 | AI13: =P13-'18 KMP- Tháng (Tâm)'!BH50 -> 0 | AJ13: =Q13-'18 KMP- Tháng (Tâm)'!BI50 -> 0 | AK13: =R13-'18 KMP- Tháng (Tâm)'!BJ50 -> 0 | AL13: =U13-'18 KMP- Tháng (Tâm)'!BR50 -> -0.0013314819 | AM13: =X13-'18 KMP- Tháng (Tâm)'!AW50 -> 0
C14: 11 | D14: Biến phí | E14: Màu theo Bom | F14: 0.0082847347 | G14: =IFERROR(F14/F$23,0) -> 0.00033592852 | H14: 0.0037386384 | I14: =IFERROR(H14/H$23,0) -> 0.00013193706 | J14: 0.017607302 | K14: =IFERROR(J14/J$23,0) -> 0.00055912817 | L14: 0.014002637 | M14: =IFERROR(L14/L$23,0) -> 0.00048369947 | N14: 0.04186059 | O14: 0.021903815 | P14: 0.046679319 | Q14: 0.0092575517 | R14: 0.00073900223 | S14: =IFERROR(R14/R$23,0) -> 2.3727374e-05 | U14: 0.02379292 | V14: =IFERROR(U14/U$23,0) -> 0.00077632436 | W14: =U14-H14 -> 0.020054281 | X14: 0.012028119 | Y14: =IFERROR(X14/X$23,0) -> 0.0004144881 | Z14: =R14-X14 -> -0.011289117 | AC14: =F14-'18 KMP- Tháng (Tâm)'!Q51 -> 0 | AD14: =H14-'18 KMP- Tháng (Tâm)'!AD51 -> 0 | AE14: =J14-'18 KMP- Tháng (Tâm)'!AQ51 -> 0 | AF14: =L14-'18 KMP- Tháng (Tâm)'!BE51 -> 0 | AG14: =N14-'18 KMP- Tháng (Tâm)'!BF51 -> 0 | AH14: =O14-'18 KMP- Tháng (Tâm)'!BG51 -> 0 | AI14: =P14-'18 KMP- Tháng (Tâm)'!BH51 -> 0 | AJ14: =Q14-'18 KMP- Tháng (Tâm)'!BI51 -> 0 | AK14: =R14-'18 KMP- Tháng (Tâm)'!BJ51 -> 0 | AL14: =U14-'18 KMP- Tháng (Tâm)'!BR51 -> 0.00050220505 | AM14: =X14-'18 KMP- Tháng (Tâm)'!AW51 -> 0
C15: II | E15: ĐỊNH PHÍ | F15: 3.5587911 | G15: =IFERROR(F15/F$23,0) -> 0.14430147 | H15: 7.2313138 | I15: =IFERROR(H15/H$23,0) -> 0.25519405 | J15: 8.9534572 | K15: =IFERROR(J15/J$23,0) -> 0.28432125 | L15: 8.7674535 | M15: =IFERROR(L15/L$23,0) -> 0.30285814 | N15: 11.221398 | O15: 16.523061 | P15: 7.0711973 | Q15: 7.4741788 | R15: 9.0136825 | S15: =IFERROR(R15/R$23,0) -> 0.2894051 | U15: 9.3027896 | V15: =IFERROR(U15/U$23,0) -> 0.30353493 | W15: =U15-H15 -> 2.0714758 | X15: 8.8946365 | Y15: =IFERROR(X15/X$23,0) -> 0.30650853 | Z15: =R15-X15 -> 0.11904602 | AC15: =F15-'18 KMP- Tháng (Tâm)'!Q52 -> 0 | AD15: =H15-'18 KMP- Tháng (Tâm)'!AD52 -> 0 | AE15: =J15-'18 KMP- Tháng (Tâm)'!AQ52 -> 0 | AF15: =L15-'18 KMP- Tháng (Tâm)'!BE52 -> 0.0005 | AG15: =N15-'18 KMP- Tháng (Tâm)'!BF52 -> 0 | AH15: =O15-'18 KMP- Tháng (Tâm)'!BG52 -> 0 | AI15: =P15-'18 KMP- Tháng (Tâm)'!BH52 -> 0 | AJ15: =Q15-'18 KMP- Tháng (Tâm)'!BI52 -> 0 | AK15: =R15-'18 KMP- Tháng (Tâm)'!BJ52 -> 0 | AL15: =U15-'18 KMP- Tháng (Tâm)'!BR52 -> 0.19127481 | AM15: =X15-'18 KMP- Tháng (Tâm)'!AW52 -> 0
C16: 1 | D16: Định phí | E16: Thuê Xưởng, Kho, thuê máy | F16: 0.35525717 | G16: =IFERROR(F16/F$23,0) -> 0.014404929 | H16: 1.9766107 | I16: =IFERROR(H16/H$23,0) -> 0.069754863 | J16: 2.1726816 | K16: =IFERROR(J16/J$23,0) -> 0.068994527 | L16: 1.3968 | M16: =IFERROR(L16/L$23,0) -> 0.048250298 | N16: 3.2548166 | O16: 5.1552464 | P16: 2.1817247 | Q16: 2.1363975 | R16: 2.5988013 | S16: =IFERROR(R16/R$23,0) -> 0.08344052 | U16: 2.7587157 | V16: =IFERROR(U16/U$23,0) -> 0.090012417 | W16: =U16-H16 -> 0.78210495 | X16: 1.4041013 | Y16: =IFERROR(X16/X$23,0) -> 0.04838523 | Z16: =R16-X16 -> 1.1947 | AC16: =F16-'18 KMP- Tháng (Tâm)'!Q53 -> 0 | AD16: =H16-'18 KMP- Tháng (Tâm)'!AD53 -> 0 | AE16: =J16-'18 KMP- Tháng (Tâm)'!AQ53 -> 0 | AF16: =L16-'18 KMP- Tháng (Tâm)'!BE53 -> 0 | AG16: =N16-'18 KMP- Tháng (Tâm)'!BF53 -> 0 | AH16: =O16-'18 KMP- Tháng (Tâm)'!BG53 -> 0 | AI16: =P16-'18 KMP- Tháng (Tâm)'!BH53 -> 0 | AJ16: =Q16-'18 KMP- Tháng (Tâm)'!BI53 -> 0 | AK16: =R16-'18 KMP- Tháng (Tâm)'!BJ53 -> 0 | AL16: =U16-'18 KMP- Tháng (Tâm)'!BR53 -> 0.079114321 | AM16: =X16-'18 KMP- Tháng (Tâm)'!AW53 -> 0
C17: 2 | D17: Định phí | E17: Tổng Lương và Phụ Cấp | F17: 2.0163215 | G17: =IFERROR(F17/F$23,0) -> 0.081757584 | H17: 2.8576456 | I17: =IFERROR(H17/H$23,0) -> 0.1008467 | J17: 3.817523 | K17: =IFERROR(J17/J$23,0) -> 0.12122724 | L17: 3.9170466 | M17: =IFERROR(L17/L$23,0) -> 0.13530833 | N17: 5.0240012 | O17: 7.1171893 | P17: 3.245178 | Q17: 3.5580893 | R17: 4.0775622 | S17: =IFERROR(R17/R$23,0) -> 0.13091956 | U17: 4.2186539 | V17: =IFERROR(U17/U$23,0) -> 0.13764783 | W17: =U17-H17 -> 1.3610082 | X17: 3.8221589 | Y17: =IFERROR(X17/X$23,0) -> 0.13171132 | Z17: =R17-X17 -> 0.2554034 | AC17: =F17-'18 KMP- Tháng (Tâm)'!Q54 -> 0 | AD17: =H17-'18 KMP- Tháng (Tâm)'!AD54 -> 0 | AE17: =J17-'18 KMP- Tháng (Tâm)'!AQ54 -> 0 | AF17: =L17-'18 KMP- Tháng (Tâm)'!BE54 -> 0 | AG17: =N17-'18 KMP- Tháng (Tâm)'!BF54 -> 0 | AH17: =O17-'18 KMP- Tháng (Tâm)'!BG54 -> 0 | AI17: =P17-'18 KMP- Tháng (Tâm)'!BH54 -> 0 | AJ17: =Q17-'18 KMP- Tháng (Tâm)'!BI54 -> 0 | AK17: =R17-'18 KMP- Tháng (Tâm)'!BJ54 -> 0 | AL17: =U17-'18 KMP- Tháng (Tâm)'!BR54 -> 0.051242683 | AM17: =X17-'18 KMP- Tháng (Tâm)'!AW54 -> 0
C18: 3 | D18: Biến phí | E18: Khấu hao | F18: 0.6999357 | G18: =IFERROR(F18/F$23,0) -> 0.028380917 | H18: 0.88827791 | I18: =IFERROR(H18/H$23,0) -> 0.031347449 | J18: 1.0856966 | K18: =IFERROR(J18/J$23,0) -> 0.034476806 | L18: 1.4046146 | M18: =IFERROR(L18/L$23,0) -> 0.048520242 | N18: 0.74391401 | O18: 1.1611775 | P18: 0.49494497 | Q18: 0.52123863 | R18: 0.64881266 | S18: =IFERROR(R18/R$23,0) -> 0.020831629 | U18: 0.6479108 | V18: =IFERROR(U18/U$23,0) -> 0.021140278 | W18: =U18-H18 -> -0.24036711 | X18: 1.4055717 | Y18: =IFERROR(X18/X$23,0) -> 0.048435898 | Z18: =R18-X18 -> -0.75675901 | AC18: =F18-'18 KMP- Tháng (Tâm)'!Q55 -> 0 | AD18: =H18-'18 KMP- Tháng (Tâm)'!AD55 -> 0 | AE18: =J18-'18 KMP- Tháng (Tâm)'!AQ55 -> 0 | AF18: =L18-'18 KMP- Tháng (Tâm)'!BE55 -> 0 | AG18: =N18-'18 KMP- Tháng (Tâm)'!BF55 -> 0 | AH18: =O18-'18 KMP- Tháng (Tâm)'!BG55 -> 0 | AI18: =P18-'18 KMP- Tháng (Tâm)'!BH55 -> 0 | AJ18: =Q18-'18 KMP- Tháng (Tâm)'!BI55 -> 0 | AK18: =R18-'18 KMP- Tháng (Tâm)'!BJ55 -> 0 | AL18: =U18-'18 KMP- Tháng (Tâm)'!BR55 -> 0.010179817 | AM18: =X18-'18 KMP- Tháng (Tâm)'!AW55 -> 0
C19: 4 | D19: Định phí | E19: Chi phí hoạt động quản lý | F19: 0.20428741 | G19: =IFERROR(F19/F$23,0) -> 0.0082834237 | H19: 0.81309305 | I19: =IFERROR(H19/H$23,0) -> 0.028694165 | J19: 1.0043486 | K19: =IFERROR(J19/J$23,0) -> 0.031893564 | L19: 0.86899983 | M19: =IFERROR(L19/L$23,0) -> 0.030018257 | N19: 1.2247128 | O19: 1.7770847 | P19: 0.58153306 | Q19: 0.65035304 | R19: 0.93397193 | S19: =IFERROR(R19/R$23,0) -> 0.029987326 | U19: 0.91111535 | V19: =IFERROR(U19/U$23,0) -> 0.029728216 | W19: =U19-H19 -> 0.098022296 | X19: 1.070242 | Y19: =IFERROR(X19/X$23,0) -> 0.03688046 | Z19: =R19-X19 -> -0.13627003 | AC19: =F19-'18 KMP- Tháng (Tâm)'!Q56 -> 0 | AD19: =H19-'18 KMP- Tháng (Tâm)'!AD56 -> 0 | AE19: =J19-'18 KMP- Tháng (Tâm)'!AQ56 -> 0 | AF19: =L19-'18 KMP- Tháng (Tâm)'!BE56 -> 0 | AG19: =N19-'18 KMP- Tháng (Tâm)'!BF56 -> 0 | AH19: =O19-'18 KMP- Tháng (Tâm)'!BG56 -> 0 | AI19: =P19-'18 KMP- Tháng (Tâm)'!BH56 -> 0 | AJ19: =Q19-'18 KMP- Tháng (Tâm)'!BI56 -> 0 | AK19: =R19-'18 KMP- Tháng (Tâm)'!BJ56 -> 0 | AL19: =U19-'18 KMP- Tháng (Tâm)'!BR56 -> 0.0292212 | AM19: =X19-'18 KMP- Tháng (Tâm)'!AW56 -> 0
C20: 5 | E20: Công cụ dụng cụ | F20: 0.14263415 | G20: =IFERROR(F20/F$23,0) -> 0.0057835141 | H20: 0.23255042 | I20: =IFERROR(H20/H$23,0) -> 0.0082067361 | J20: 0.25359604 | K20: =IFERROR(J20/J$23,0) -> 0.0080530619 | L20: 0.19863491 | M20: =IFERROR(L20/L$23,0) -> 0.0068615361 | N20: 0.20940054 | O20: 0.28756324 | P20: 0.14167265 | Q20: 0.13201921 | R20: 0.16986217 | S20: =IFERROR(R20/R$23,0) -> 0.0054538175 | U20: 0.17225937 | V20: =IFERROR(U20/U$23,0) -> 0.0056205437 | W20: =U20-H20 -> -0.060291054 | X20: 0.18992579 | Y20: =IFERROR(X20/X$23,0) -> 0.0065448288 | Z20: =R20-X20 -> -0.020063611 | AC20: =F20-'18 KMP- Tháng (Tâm)'!Q57 -> 0 | AD20: =H20-'18 KMP- Tháng (Tâm)'!AD57 -> 0 | AE20: =J20-'18 KMP- Tháng (Tâm)'!AQ57 -> 0 | AF20: =L20-'18 KMP- Tháng (Tâm)'!BE57 -> 0 | AG20: =N20-'18 KMP- Tháng (Tâm)'!BF57 -> 0 | AH20: =O20-'18 KMP- Tháng (Tâm)'!BG57 -> 0 | AI20: =P20-'18 KMP- Tháng (Tâm)'!BH57 -> 0 | AJ20: =Q20-'18 KMP- Tháng (Tâm)'!BI57 -> 0 | AK20: =R20-'18 KMP- Tháng (Tâm)'!BJ57 -> 0 | AL20: =U20-'18 KMP- Tháng (Tâm)'!BR57 -> 0.002374761 | AM20: =X20-'18 KMP- Tháng (Tâm)'!AW57 -> 0
C21: 6 | E21: Bảo Trì + Sữa Chữa | F21: 0.11402198 | G21: =IFERROR(F21/F$23,0) -> 0.004623351 | H21: 0.22975675 | I21: =IFERROR(H21/H$23,0) -> 0.008108147 | J21: 0.30611705 | K21: =IFERROR(J21/J$23,0) -> 0.0097208912 | L21: 0.2900394 | M21: =IFERROR(L21/L$23,0) -> 0.010018963 | N21: 0.33224167 | O21: 0.38635959 | P21: 0.20188385 | Q21: 0.23305708 | R21: 0.35118735 | S21: =IFERROR(R21/R$23,0) -> 0.011275681 | U21: 0.28347409 | V21: =IFERROR(U21/U$23,0) -> 0.0092492998 | W21: =U21-H21 -> 0.053717346 | X21: 0.28259736 | Y21: =IFERROR(X21/X$23,0) -> 0.0097382844 | Z21: =R21-X21 -> 0.068589992 | AC21: =F21-'18 KMP- Tháng (Tâm)'!Q58 -> 0 | AD21: =H21-'18 KMP- Tháng (Tâm)'!AD58 -> 0 | AE21: =J21-'18 KMP- Tháng (Tâm)'!AQ58 -> 0 | AF21: =L21-'18 KMP- Tháng (Tâm)'!BE58 -> 0.0005 | AG21: =N21-'18 KMP- Tháng (Tâm)'!BF58 -> 0 | AH21: =O21-'18 KMP- Tháng (Tâm)'!BG58 -> 0 | AI21: =P21-'18 KMP- Tháng (Tâm)'!BH58 -> 0 | AJ21: =Q21-'18 KMP- Tháng (Tâm)'!BI58 -> 0 | AK21: =R21-'18 KMP- Tháng (Tâm)'!BJ58 -> 0 | AL21: =U21-'18 KMP- Tháng (Tâm)'!BR58 -> 0.0017770728 | AM21: =X21-'18 KMP- Tháng (Tâm)'!AW58 -> 0
C22: 7 | D22: Định phí | E22: Lãi Vay | F22: 0.026333133 | G22: =IFERROR(F22/F$23,0) -> 0.001067753 | H22: 0.23337929 | I22: =IFERROR(H22/H$23,0) -> 0.008235987 | J22: 0.31349431 | K22: =IFERROR(J22/J$23,0) -> 0.0099551597 | L22: 0.69131809 | M22: =IFERROR(L22/L$23,0) -> 0.023880515 | N22: 0.43231136 | O22: 0.63844041 | P22: 0.22426008 | Q22: 0.24302405 | R22: 0.23348484 | S22: =IFERROR(R22/R$23,0) -> 0.0074965703 | U22: 0.3106604 | V22: =IFERROR(U22/U$23,0) -> 0.010136345 | W22: =U22-H22 -> 0.077281109 | X22: 0.72003953 | Y22: =IFERROR(X22/X$23,0) -> 0.02481251 | Z22: =R22-X22 -> -0.48655469 | AC22: =F22-'18 KMP- Tháng (Tâm)'!Q59 -> 0 | AD22: =H22-'18 KMP- Tháng (Tâm)'!AD59 -> 0 | AE22: =J22-'18 KMP- Tháng (Tâm)'!AQ59 -> 0 | AF22: =L22-'18 KMP- Tháng (Tâm)'!BE59 -> 0 | AG22: =N22-'18 KMP- Tháng (Tâm)'!BF59 -> 0 | AH22: =O22-'18 KMP- Tháng (Tâm)'!BG59 -> 0 | AI22: =P22-'18 KMP- Tháng (Tâm)'!BH59 -> 0 | AJ22: =Q22-'18 KMP- Tháng (Tâm)'!BI59 -> 0 | AK22: =R22-'18 KMP- Tháng (Tâm)'!BJ59 -> 0 | AL22: =U22-'18 KMP- Tháng (Tâm)'!BR59 -> 0.017364954 | AM22: =X22-'18 KMP- Tháng (Tâm)'!AW59 -> 0
C23: Tổng chi phí / tấn | F23: 24.662195 | G23: =IFERROR(F23/F$23,0) -> 1 | H23: 28.33653 | I23: =IFERROR(H23/H$23,0) -> 1 | J23: 31.490636 | K23: =IFERROR(J23/J$23,0) -> 1 | L23: 28.949044 | M23: =IFERROR(L23/L$23,0) -> 1 | N23: 32.995067 | O23: 37.141357 | P23: 28.469087 | Q23: 28.173126 | R23: 31.145555 | S23: =IFERROR(R23/R$23,0) -> 1 | U23: 30.648168 | V23: =IFERROR(U23/U$23,0) -> 1 | W23: =U23-H23 -> 2.3116384 | X23: 29.019214 | Y23: =IFERROR(X23/X$23,0) -> 1 | Z23: =R23-X23 -> 2.1263412 | AC23: =F23-'18 KMP- Tháng (Tâm)'!Q60 -> 0 | AD23: =H23-'18 KMP- Tháng (Tâm)'!AD60 -> 0 | AE23: =J23-'18 KMP- Tháng (Tâm)'!AQ60 -> 0 | AF23: =L23-'18 KMP- Tháng (Tâm)'!BE60 -> 8.8722024e-05 | AG23: =N23-'18 KMP- Tháng (Tâm)'!BF60 -> 0 | AH23: =O23-'18 KMP- Tháng (Tâm)'!BG60 -> 0 | AI23: =P23-'18 KMP- Tháng (Tâm)'!BH60 -> 0 | AJ23: =Q23-'18 KMP- Tháng (Tâm)'!BI60 -> 0 | AK23: =R23-'18 KMP- Tháng (Tâm)'!BJ60 -> 0 | AL23: =U23-'18 KMP- Tháng (Tâm)'!BR60 -> -0.007687713 | AM23: =X23-'18 KMP- Tháng (Tâm)'!AW60 -> 0
C24: Tổng chi phí / tấn (không gồm thuê xưởng, kho, máy và khấu hao) | F24: 23.607002 | H24: 25.471641 | J24: 28.232258 | L24: 26.147629 | N24: 28.996336 | O24: 30.824933 | P24: 25.792418 | Q24: 25.51549 | R24: 27.897941 | U24: 27.241542 | W24: =U24-H24 -> 1.7699005 | X24: 26.209541 | Z24: =R24-X24 -> 1.6884003 | AC24: =F24-'18 KMP- Tháng (Tâm)'!Q61 -> 0 | AD24: =H24-'18 KMP- Tháng (Tâm)'!AD61 -> 0 | AE24: =J24-'18 KMP- Tháng (Tâm)'!AQ61 -> 0 | AF24: =L24-'18 KMP- Tháng (Tâm)'!BE61 -> 8.8722024e-05 | AG24: =N24-'18 KMP- Tháng (Tâm)'!BF61 -> 0 | AH24: =O24-'18 KMP- Tháng (Tâm)'!BG61 -> 0 | AI24: =P24-'18 KMP- Tháng (Tâm)'!BH61 -> 0 | AJ24: =Q24-'18 KMP- Tháng (Tâm)'!BI61 -> 0 | AK24: =R24-'18 KMP- Tháng (Tâm)'!BJ61 -> 0 | AL24: =U24-'18 KMP- Tháng (Tâm)'!BR61 -> -0.096981851 | AM24: =X24-'18 KMP- Tháng (Tâm)'!AW61 -> 0
C25: Sản lượng thành phẩm SX | F25: 1954.7762 | H25: 3688.024 | J25: 3792.1955 | L25: 4166.6667 | N25: 2868.5693 | O25: 1811.1 | P25: 4279.489 | Q25: 4370.2854 | R25: 3592.682 | U25: 3384.4251 | W25: =U25-H25 -> -303.59889 | X25: 4145 | Z25: =R25-X25 -> -552.318 | AC25: =F25-'18 KMP- Tháng (Tâm)'!Q62 -> 0 | AD25: =H25-'18 KMP- Tháng (Tâm)'!AD62 -> 0 | AE25: =J25-'18 KMP- Tháng (Tâm)'!AQ62 -> 0 | AF25: =L25-'18 KMP- Tháng (Tâm)'!BE62 -> 0 | AG25: =N25-'18 KMP- Tháng (Tâm)'!BF62 -> 0 | AH25: =O25-'18 KMP- Tháng (Tâm)'!BG62 -> 0 | AI25: =P25-'18 KMP- Tháng (Tâm)'!BH62 -> 0 | AJ25: =Q25-'18 KMP- Tháng (Tâm)'!BI62 -> 0 | AK25: =R25-'18 KMP- Tháng (Tâm)'!BJ62 -> 0 | AL25: =U25-'18 KMP- Tháng (Tâm)'!BR62 -> -89.816778 | AM25: =X25-'18 KMP- Tháng (Tâm)'!AW62 -> 0
A26: Updated T05 | B26: Cẩn thận dòng này | C26: Nguyên liệu nhựa (chai,vảy)/tấn | F26: =F4 -> 19.326224 | G26: =IFERROR(F26/F$23,0) -> 0.78363763 | H26: =H4 -> 18.507378 | I26: =IFERROR(H26/H$23,0) -> 0.6531279 | J26: =J4 -> 19.649038 | K26: =IFERROR(J26/J$23,0) -> 0.62396447 | L26: =L4 -> 17.822333 | M26: =IFERROR(L26/L$23,0) -> 0.61564496 | N26: =N4 -> 18.923356 | O26: =O4 -> 18.104206 | P26: =P4 -> 18.460639 | Q26: =Q4 -> 17.780534 | R26: =R4 -> 18.757434 | S26: =IFERROR(R26/R$23,0) -> 0.60225076 | U26: =U4 -> 18.388298 | V26: =IFERROR(U26/U$23,0) -> 0.59998033 | W26: =U26-H26 -> -0.11908005 | X26: =X4 -> 17.818769 | Y26: =IFERROR(X26/X$23,0) -> 0.61403348 | Z26: =R26-X26 -> 0.93866542
A27: Updated T05 | B27: Cẩn thận dòng này | C27: Chi phí sản xuất trong BOM/tấn | F27: =F7+F9+F11+F14 -> 0.43424379 | G27: =IFERROR(F27/F$23,0) -> 0.01760767 | H27: =H7+H9+H11+H14 -> 0.55793796 | I27: =IFERROR(H27/H$23,0) -> 0.019689707 | J27: =J7+J9+J11+J14 -> 0.67135506 | K27: =IFERROR(J27/J$23,0) -> 0.021319196 | L27: =L7+L9+L11+L14 -> 0.62158352 | M27: =IFERROR(L27/L$23,0) -> 0.021471643 | N27: =N7+N9+N11+N14 -> 0.65198165 | O27: =O7+O9+O11+O14 -> 0.4173752 | P27: =P7+P9+P11+P14 -> 0.73041184 | Q27: =Q7+Q9+Q11+Q14 -> 0.66580588 | R27: =R7+R9+R11+R14 -> 0.83189822 | S27: =IFERROR(R27/R$23,0) -> 0.026710014 | U27: =U7+U9+U11+U14 -> 0.68847495 | V27: =IFERROR(U27/U$23,0) -> 0.022463821 | W27: =U27-H27 -> 0.130537 | X27: =X7+X9+X11+X14 -> 0.6198661 | Y27: =IFERROR(X27/X$23,0) -> 0.021360541 | Z27: =R27-X27 -> 0.21203212
B28: Cẩn thận dòng này-CT | C28: Chi phí sản xuất ngoài BOM/tấn | F28: =F34-F26-F27 -> 3.6195248 | G28: =IFERROR(F28/F$23,0) -> 0.1467641 | H28: =H34-H26-H27 -> 6.678909 | I28: =IFERROR(H28/H$23,0) -> 0.23569961 | J28: =J34-J26-J27 -> 7.8537216 | K28: =IFERROR(J28/J$23,0) -> 0.24939863 | L28: =L34-L26-L27 -> 7.2271606 | M28: =IFERROR(L28/L$23,0) -> 0.2496511 | N28: =N34-N26-N27 -> 9.2754694 | O28: =O34-O26-O27 -> 12.673245 | P28: =P34-P26-P27 -> 5.8044003 | Q28: =Q34-Q26-Q27 -> 6.6580629 | R28: =R34-R26-R27 -> 8.0844349 | S28: =IFERROR(R28/R$23,0) -> 0.25956946 | U28: =U34-U26-U27 -> 7.8324762 | V28: =IFERROR(U28/U$23,0) -> 0.25556099 | W28: =U28-H28 -> 1.1535672 | X28: =X34-X26-X27 -> 7.1458149 | Y28: =IFERROR(X28/X$23,0) -> 0.24624426 | Z28: =R28-X28 -> 0.93861997
A29: Updated T05 | B29: Cẩn thận dòng này | C29: Chi phí bán hàng/tấn | F29: 0.32014393 | G29: =IFERROR(F29/F$23,0) -> 0.012981161 | H29: 0.69009316 | I29: =IFERROR(H29/H$23,0) -> 0.024353482 | J29: 0.75564115 | K29: =IFERROR(J29/J$23,0) -> 0.023995741 | L29: 0.49174289 | M29: =IFERROR(L29/L$23,0) -> 0.016986499 | N29: 0.74875362 | O29: 0.85709105 | P29: 0.87289004 | Q29: 0.9503997 | R29: 0.97236255 | S29: =IFERROR(R29/R$23,0) -> 0.031219946 | U29: 0.86794336 | V29: =IFERROR(U29/U$23,0) -> 0.028319584 | W29: =U29-H29 -> 0.1778502 | X29: 0.71669593 | Y29: =IFERROR(X29/X$23,0) -> 0.02469729 | Z29: =R29-X29 -> 0.25566662
B30: Cẩn thận dòng này-CT | C30: Chi phí quản lý doanh nghiệp/tấn | F30: =F23-SUM(F26:F29,F31) -> 0.93572536 | G30: =IFERROR(F30/F$23,0) -> 0.03794169 | H30: =H23-SUM(H26:H29,H31) -> 1.6688322 | I30: =IFERROR(H30/H$23,0) -> 0.058893317 | J30: =J23-SUM(J26:J29,J31) -> 2.2473862 | K30: =IFERROR(J30/J$23,0) -> 0.071366807 | L30: =L23-SUM(L26:L29,L31) -> 2.0949057 | M30: =IFERROR(L30/L$23,0) -> 0.072365282 | N30: =N23-SUM(N26:N29,N31) -> 2.9631952 | O30: =O23-SUM(O26:O29,O31) -> 4.4509991 | P30: =P23-SUM(P26:P29,P31) -> 2.3764865 | Q30: =Q23-SUM(Q26:Q29,Q31) -> 1.8752992 | R30: =R23-SUM(R26:R29,R31) -> 2.2659403 | S30: =IFERROR(R30/R$23,0) -> 0.07275325 | U30: =U23-SUM(U26:U29,U31) -> 2.5603151 | V30: =IFERROR(U30/U$23,0) -> 0.083538929 | W30: =U30-H30 -> 0.89148291 | X30: =X23-SUM(X26:X29,X31) -> 1.9980285 | Y30: =IFERROR(X30/X$23,0) -> 0.068851919 | Z30: =R30-X30 -> 0.2679118
A31: Updated T05 | B31: Cẩn thận dòng này | C31: Chi phí lãi vay/tấn | F31: =F22 -> 0.026333133 | G31: =IFERROR(F31/F$23,0) -> 0.001067753 | H31: =H22 -> 0.23337929 | I31: =IFERROR(H31/H$23,0) -> 0.008235987 | J31: =J22 -> 0.31349431 | K31: =IFERROR(J31/J$23,0) -> 0.0099551597 | L31: =L22 -> 0.69131809 | M31: =IFERROR(L31/L$23,0) -> 0.023880515 | N31: =N22 -> 0.43231136 | O31: =O22 -> 0.63844041 | P31: =P22 -> 0.22426008 | Q31: =Q22 -> 0.24302405 | R31: =R22 -> 0.23348484 | S31: =IFERROR(R31/R$23,0) -> 0.0074965703 | U31: =U22 -> 0.3106604 | V31: =IFERROR(U31/U$23,0) -> 0.010136345 | W31: =U31-H31 -> 0.077281109 | X31: =X22 -> 0.72003953 | Y31: =IFERROR(X31/X$23,0) -> 0.02481251 | Z31: =R31-X31 -> -0.48655469
A34: Updated T04 | C34: Cp 621,622.627 | F34: 23.379993 | H34: 25.744225 | J34: 28.174115 | L34: 25.671077 | N34: 28.850807 | O34: 31.194826 | P34: 24.995451 | Q34: 25.104403 | R34: 27.673767 | U34: 26.909249 | X34: 25.58445
H35: ok | J35: ok | L35: ok | N35: ok | O35: ok | P35: ok | Q35: ok | R35: ok | U35: ok | X35: ok

Sheet Chụp hình-2
G1: x | H1: CT | J1: x | K1: x | L1: x | N1: CT | O1: x | P1: x
B2: STT | C2: Chỉ tiêu | D2: BQ TT 2023 | E2: BQ TT 2024 | F2: BQ TT 2025 | G2: ĐINH MỨC 2026 | H2: BQ TT 2026 | J2: T1.26 | K2: T2.26 | L2: T3.26 | M2: T04.26 | N2: T05.26 | P2: KH 05.26 | T2: BQ TT 2023 | U2: BQ TT 2024 | V2: BQ TT 2025 | W2: ĐINH MỨC 2026 | X2: BQ TT 2026 | Y2: 1 | Z2: 2 | AA2: 3 | AB2: 4 | AC2: 5 | AD2: KH 05.26
B3: I | C3: BIẾN PHÍ | D3: 0.85569853 | E3: 0.74480595 | F3: 0.71567875 | G3: 0.69714186 | H3: =I3-G3 -> -0.0006767932 | I3: 0.69646507 | J3: 0.65990679 | K3: 0.55513038 | L3: 0.75161841 | M3: 0.73470538 | N3: =O3-P3 -> 0.017103426 | O3: 0.7105949 | P3: 0.69349147 | T3: =D3-'18 KMP- Tháng (Tâm)'!Q70 -> 0 | U3: =E3-'18 KMP- Tháng (Tâm)'!AD70 -> 0 | V3: =F3-'18 KMP- Tháng (Tâm)'!AQ70 -> 0 | W3: =G3-'18 KMP- Tháng (Tâm)'!BE70 -> -1.6343589e-05 | X3: =I3-'18 KMP- Tháng (Tâm)'!BR70 -> -0.0063155405 | Y3: =J3-'18 KMP- Tháng (Tâm)'!BF70 -> 0 | Z3: =K3-'18 KMP- Tháng (Tâm)'!BG70 -> 0 | AA3: =L3-'18 KMP- Tháng (Tâm)'!BH70 -> 0 | AB3: =M3-'18 KMP- Tháng (Tâm)'!BI70 -> 0 | AC3: =O3-'18 KMP- Tháng (Tâm)'!BJ70 -> 0 | AD3: =P3-'18 KMP- Tháng (Tâm)'!AW70 -> 0
B4: 1 | C4: Nguyên liệu nhựa | D4: 0.78363763 | E4: 0.6531279 | F4: 0.62396447 | G4: 0.61564496 | H4: =I4-G4 -> -0.015664632 | I4: 0.59998033 | J4: 0.57352075 | K4: 0.48744062 | L4: 0.64844505 | M4: 0.63111684 | N4: =O4-P4 -> -0.011782718 | O4: 0.60225076 | P4: 0.61403348 | T4: =D4-'18 KMP- Tháng (Tâm)'!Q71 -> 0 | U4: =E4-'18 KMP- Tháng (Tâm)'!AD71 -> 0 | V4: =F4-'18 KMP- Tháng (Tâm)'!AQ71 -> 0 | W4: =G4-'18 KMP- Tháng (Tâm)'!BE71 -> -1.8868131e-06 | X4: =I4-'18 KMP- Tháng (Tâm)'!BR71 -> -0.0049703341 | Y4: =J4-'18 KMP- Tháng (Tâm)'!BF71 -> 0 | Z4: =K4-'18 KMP- Tháng (Tâm)'!BG71 -> 0 | AA4: =L4-'18 KMP- Tháng (Tâm)'!BH71 -> 0 | AB4: =M4-'18 KMP- Tháng (Tâm)'!BI71 -> 0 | AC4: =O4-'18 KMP- Tháng (Tâm)'!BJ71 -> 0 | AD4: =P4-'18 KMP- Tháng (Tâm)'!AW71 -> 0
B5: 2 | C5: Điện | D5: 0.031522197 | E5: 0.047338189 | F5: 0.049050407 | G5: 0.042189941 | H5: =I5-G5 -> 0.0040418727 | I5: 0.046231813 | J5: 0.043330636 | K5: 0.037267522 | L5: 0.046988184 | M5: 0.046753666 | N5: =O5-P5 -> 0.012294638 | O5: 0.052620353 | P5: 0.040325714 | T5: =D5-'18 KMP- Tháng (Tâm)'!Q72 -> 0 | U5: =E5-'18 KMP- Tháng (Tâm)'!AD72 -> 0 | V5: =F5-'18 KMP- Tháng (Tâm)'!AQ72 -> 0 | W5: =G5-'18 KMP- Tháng (Tâm)'!BE72 -> -1.2930266e-07 | X5: =I5-'18 KMP- Tháng (Tâm)'!BR72 -> -0.00084969623 | Y5: =J5-'18 KMP- Tháng (Tâm)'!BF72 -> 0 | Z5: =K5-'18 KMP- Tháng (Tâm)'!BG72 -> 0 | AA5: =L5-'18 KMP- Tháng (Tâm)'!BH72 -> 0 | AB5: =M5-'18 KMP- Tháng (Tâm)'!BI72 -> 0 | AC5: =O5-'18 KMP- Tháng (Tâm)'!BJ72 -> 0 | AD5: =P5-'18 KMP- Tháng (Tâm)'!AW72 -> 0
B6: 3 | C6: Chi phí bán hàng | D6: 0.0099911713 | E6: 0.012287112 | F6: 0.011239803 | G6: 0.0056088541 | H6: =I6-G6 -> 0.011003349 | I6: 0.016612203 | J6: 0.012023872 | K6: 0.010060059 | L6: 0.019353336 | M6: 0.020992119 | N6: =O6-P6 -> 0.012266945 | O6: 0.017832314 | P6: 0.0055653685 | T6: =D6-'18 KMP- Tháng (Tâm)'!Q73 -> 0 | U6: =E6-'18 KMP- Tháng (Tâm)'!AD73 -> 0 | V6: =F6-'18 KMP- Tháng (Tâm)'!AQ73 -> 0 | W6: =G6-'18 KMP- Tháng (Tâm)'!BE73 -> -3.1495976e-05 | X6: =I6-'18 KMP- Tháng (Tâm)'!BR73 -> 0.00019357924 | Y6: =J6-'18 KMP- Tháng (Tâm)'!BF73 -> 0 | Z6: =K6-'18 KMP- Tháng (Tâm)'!BG73 -> 0 | AA6: =L6-'18 KMP- Tháng (Tâm)'!BH73 -> 0 | AB6: =M6-'18 KMP- Tháng (Tâm)'!BI73 -> 0 | AC6: =O6-'18 KMP- Tháng (Tâm)'!BJ73 -> 0 | AD6: =P6-'18 KMP- Tháng (Tâm)'!AW73 -> 0
B7: 4 | C7: Phụ gia theo Bom | D7: 0.010629589 | E7: 0.011369587 | F7: 0.012205124 | G7: 0.011104841 | H7: =I7-G7 -> 0.00074307911 | I7: 0.01184792 | J7: 0.0094156387 | K7: 0.0042898083 | L7: 0.014473365 | M7: 0.011261733 | N7: =O7-P7 -> 0.0051163456 | O7: 0.016220779 | P7: 0.011104433 | T7: =D7-'18 KMP- Tháng (Tâm)'!Q74 -> 0 | U7: =E7-'18 KMP- Tháng (Tâm)'!AD74 -> 0 | V7: =F7-'18 KMP- Tháng (Tâm)'!AQ74 -> 0 | W7: =G7-'18 KMP- Tháng (Tâm)'!BE74 -> -3.4033834e-08 | X7: =I7-'18 KMP- Tháng (Tâm)'!BR74 -> -0.0004466867 | Y7: =J7-'18 KMP- Tháng (Tâm)'!BF74 -> 0 | Z7: =K7-'18 KMP- Tháng (Tâm)'!BG74 -> 0 | AA7: =L7-'18 KMP- Tháng (Tâm)'!BH74 -> 0 | AB7: =M7-'18 KMP- Tháng (Tâm)'!BI74 -> 0 | AC7: =O7-'18 KMP- Tháng (Tâm)'!BJ74 -> 0 | AD7: =P7-'18 KMP- Tháng (Tâm)'!AW74 -> 0
B8: 5 | C8: Vật liệu phục vụ SX | D8: 0.0067462935 | E8: 0.0072011889 | F8: 0.006187637 | G8: 0.007447758 | H8: =I8-G8 -> -0.00073491981 | I8: 0.0067128382 | J8: 0.0076455738 | K8: 0.0057274264 | L8: 0.006680042 | M8: 0.0070961384 | N8: =O8-P8 -> -0.0012976956 | O8: 0.0061219817 | P8: 0.0074196772 | T8: =D8-'18 KMP- Tháng (Tâm)'!Q75 -> 0 | U8: =E8-'18 KMP- Tháng (Tâm)'!AD75 -> 0 | V8: =F8-'18 KMP- Tháng (Tâm)'!AQ75 -> 0 | W8: =G8-'18 KMP- Tháng (Tâm)'!BE75 -> 1.7248955e-05 | X8: =I8-'18 KMP- Tháng (Tâm)'!BR75 -> -1.0054755e-05 | Y8: =J8-'18 KMP- Tháng (Tâm)'!BF75 -> 0 | Z8: =K8-'18 KMP- Tháng (Tâm)'!BG75 -> 0 | AA8: =L8-'18 KMP- Tháng (Tâm)'!BH75 -> 0 | AB8: =M8-'18 KMP- Tháng (Tâm)'!BI75 -> 0 | AC8: =O8-'18 KMP- Tháng (Tâm)'!BJ75 -> 0 | AD8: =P8-'18 KMP- Tháng (Tâm)'!AW75 -> 0
B9: 6 | C9: Bao bì theo Bom | D9: 0.0039959825 | E9: 0.0060586077 | F9: 0.0059250111 | G9: 0.00595664 | H9: =I9-G9 -> 0.00094223373 | I9: 0.0068988737 | J9: 0.00640947 | K9: 0.0051683066 | L9: 0.0066804824 | M9: 0.0083200046 | N9: =O9-P9 -> 0.0011002087 | O9: 0.007018778 | P9: 0.0059185693 | T9: =D9-'18 KMP- Tháng (Tâm)'!Q76 -> 0 | U9: =E9-'18 KMP- Tháng (Tâm)'!AD76 -> 0 | V9: =F9-'18 KMP- Tháng (Tâm)'!AQ76 -> 0 | W9: =G9-'18 KMP- Tháng (Tâm)'!BE76 -> -1.8255759e-08 | X9: =I9-'18 KMP- Tháng (Tâm)'!BR76 -> -6.145999e-05 | Y9: =J9-'18 KMP- Tháng (Tâm)'!BF76 -> 0 | Z9: =K9-'18 KMP- Tháng (Tâm)'!BG76 -> 0 | AA9: =L9-'18 KMP- Tháng (Tâm)'!BH76 -> 0 | AB9: =M9-'18 KMP- Tháng (Tâm)'!BI76 -> 0 | AC9: =O9-'18 KMP- Tháng (Tâm)'!BJ76 -> 0 | AD9: =P9-'18 KMP- Tháng (Tâm)'!AW76 -> 0
B10: 7 | C10: Xăng dầu | D10: 0.0035509569 | E10: 0.0031677199 | F10: 0.001894865 | G10: 0.0019227164 | H10: =I10-G10 -> 0.0007070448 | I10: 0.0026297612 | J10: 0.0017051789 | K10: 0.0015991008 | L10: 0.002810691 | M10: 0.0032127473 | N10: =O10-P10 -> 0.0012616167 | O10: 0.0031897099 | P10: 0.0019280932 | T10: =D10-'18 KMP- Tháng (Tâm)'!Q77 -> 0 | U10: =E10-'18 KMP- Tháng (Tâm)'!AD77 -> 0 | V10: =F10-'18 KMP- Tháng (Tâm)'!AQ77 -> 0 | W10: =G10-'18 KMP- Tháng (Tâm)'!BE77 -> -5.8926924e-09 | X10: =I10-'18 KMP- Tháng (Tâm)'!BR77 -> -3.1782208e-05 | Y10: =J10-'18 KMP- Tháng (Tâm)'!BF77 -> 0 | Z10: =K10-'18 KMP- Tháng (Tâm)'!BG77 -> 0 | AA10: =L10-'18 KMP- Tháng (Tâm)'!BH77 -> 0 | AB10: =M10-'18 KMP- Tháng (Tâm)'!BI77 -> 0 | AC10: =O10-'18 KMP- Tháng (Tâm)'!BJ77 -> 0 | AD10: =P10-'18 KMP- Tháng (Tâm)'!AW77 -> 0
B11: 8 | C11: Hóa chất theo Bom | D11: 0.0026461697 | E11: 0.002129575 | F11: 0.0026299328 | G11: 0.0039264626 | H11: =I11-G11 -> -0.00098575959 | I11: 0.002940703 | J11: 0.0026661727 | K11: 0.0011896219 | L11: 0.0028628169 | M11: 0.0037223265 | N11: =O11-P11 -> -0.00047632009 | O11: 0.0034467303 | P11: 0.0039230504 | T11: =D11-'18 KMP- Tháng (Tâm)'!Q78 -> 0 | U11: =E11-'18 KMP- Tháng (Tâm)'!AD78 -> 0 | V11: =F11-'18 KMP- Tháng (Tâm)'!AQ78 -> 0 | W11: =G11-'18 KMP- Tháng (Tâm)'!BE78 -> -1.2033723e-08 | X11: =I11-'18 KMP- Tháng (Tâm)'!BR78 -> -8.8360789e-05 | Y11: =J11-'18 KMP- Tháng (Tâm)'!BF78 -> 0 | Z11: =K11-'18 KMP- Tháng (Tâm)'!BG78 -> 0 | AA11: =L11-'18 KMP- Tháng (Tâm)'!BH78 -> 0 | AB11: =M11-'18 KMP- Tháng (Tâm)'!BI78 -> 0 | AC11: =O11-'18 KMP- Tháng (Tâm)'!BJ78 -> 0 | AD11: =P11-'18 KMP- Tháng (Tâm)'!AW78 -> 0
B12: 9 | C12: Hóa chất XLNT | D12: 0.0012306544 | E12: 0.00080130382 | F12: 0.00074751031 | G12: 0.0010399534 | H12: =I12-G12 -> -0.00025996741 | I12: 0.00077998601 | J12: 0.00073988773 | K12: 0.00061626771 | L12: 0.00081513661 | M12: 0.00089012448 | N12: =O12-P12 -> -0.00026533638 | O12: 0.00075190554 | P12: 0.0010172419 | T12: =D12-'18 KMP- Tháng (Tâm)'!Q79 -> 0 | U12: =E12-'18 KMP- Tháng (Tâm)'!AD79 -> 0 | V12: =F12-'18 KMP- Tháng (Tâm)'!AQ79 -> 0 | W12: =G12-'18 KMP- Tháng (Tâm)'!BE79 -> -3.1872229e-09 | X12: =I12-'18 KMP- Tháng (Tâm)'!BR79 -> -2.4152828e-05 | Y12: =J12-'18 KMP- Tháng (Tâm)'!BF79 -> 0 | Z12: =K12-'18 KMP- Tháng (Tâm)'!BG79 -> 0 | AA12: =L12-'18 KMP- Tháng (Tâm)'!BH79 -> 0 | AB12: =M12-'18 KMP- Tháng (Tâm)'!BI79 -> 0 | AC12: =O12-'18 KMP- Tháng (Tâm)'!BJ79 -> 0 | AD12: =P12-'18 KMP- Tháng (Tâm)'!AW79 -> 0
B13: 10 | C13: Nước | D13: 0.0014119582 | E13: 0.0011928309 | F13: 0.001274862 | G13: 0.0018160349 | H13: =I13-G13 -> -0.00076171883 | I13: 0.001054316 | J13: 0.001180913 | K13: 0.00118191 | L13: 0.00086965988 | M13: 0.0010110847 | N13: =O13-P13 -> -0.00072349806 | O13: 0.0011178623 | P13: 0.0018413603 | T13: =D13-'18 KMP- Tháng (Tâm)'!Q80 -> 0 | U13: =E13-'18 KMP- Tháng (Tâm)'!AD80 -> 0 | V13: =F13-'18 KMP- Tháng (Tâm)'!AQ80 -> 0 | W13: =G13-'18 KMP- Tháng (Tâm)'!BE80 -> -5.5657377e-09 | X13: =I13-'18 KMP- Tháng (Tâm)'!BR80 -> -4.3168803e-05 | Y13: =J13-'18 KMP- Tháng (Tâm)'!BF80 -> 0 | Z13: =K13-'18 KMP- Tháng (Tâm)'!BG80 -> 0 | AA13: =L13-'18 KMP- Tháng (Tâm)'!BH80 -> 0 | AB13: =M13-'18 KMP- Tháng (Tâm)'!BI80 -> 0 | AC13: =O13-'18 KMP- Tháng (Tâm)'!BJ80 -> 0 | AD13: =P13-'18 KMP- Tháng (Tâm)'!AW80 -> 0
B14: 11 | C14: Màu theo Bom | D14: 0.00033592852 | E14: 0.00013193706 | F14: 0.00055912817 | G14: 0.00048369947 | H14: =I14-G14 -> 0.0002926249 | I14: 0.00077632436 | J14: 0.0012686924 | K14: 0.00058974193 | L14: 0.0016396493 | M14: 0.00032859512 | N14: =O14-P14 -> -0.00039076073 | O14: 2.3727374e-05 | P14: 0.0004144881 | T14: =D14-'18 KMP- Tháng (Tâm)'!Q81 -> 0 | U14: =E14-'18 KMP- Tháng (Tâm)'!AD81 -> 0 | V14: =F14-'18 KMP- Tháng (Tâm)'!AQ81 -> 0 | W14: =G14-'18 KMP- Tháng (Tâm)'!BE81 -> -1.4824299e-09 | X14: =I14-'18 KMP- Tháng (Tâm)'!BR81 -> 1.6576709e-05 | Y14: =J14-'18 KMP- Tháng (Tâm)'!BF81 -> 0 | Z14: =K14-'18 KMP- Tháng (Tâm)'!BG81 -> 0 | AA14: =L14-'18 KMP- Tháng (Tâm)'!BH81 -> 0 | AB14: =M14-'18 KMP- Tháng (Tâm)'!BI81 -> 0 | AC14: =O14-'18 KMP- Tháng (Tâm)'!BJ81 -> 0 | AD14: =P14-'18 KMP- Tháng (Tâm)'!AW81 -> 0
B15: II | C15: ĐỊNH PHÍ | D15: 0.14430147 | E15: 0.25519405 | F15: 0.28432125 | G15: 0.30285814 | H15: =I15-G15 -> 0.0006767932 | I15: 0.30353493 | J15: 0.34009321 | K15: 0.44486962 | L15: 0.24838159 | M15: 0.26529462 | N15: =O15-P15 -> -0.017103426 | O15: 0.2894051 | P15: 0.30650853 | T15: =D15-'18 KMP- Tháng (Tâm)'!Q82 -> 0 | U15: =E15-'18 KMP- Tháng (Tâm)'!AD82 -> 0 | V15: =F15-'18 KMP- Tháng (Tâm)'!AQ82 -> 0 | W15: =G15-'18 KMP- Tháng (Tâm)'!BE82 -> 1.6343589e-05 | X15: =I15-'18 KMP- Tháng (Tâm)'!BR82 -> 0.0063155405 | Y15: =J15-'18 KMP- Tháng (Tâm)'!BF82 -> 0 | Z15: =K15-'18 KMP- Tháng (Tâm)'!BG82 -> 0 | AA15: =L15-'18 KMP- Tháng (Tâm)'!BH82 -> 0 | AB15: =M15-'18 KMP- Tháng (Tâm)'!BI82 -> 0 | AC15: =O15-'18 KMP- Tháng (Tâm)'!BJ82 -> 0 | AD15: =P15-'18 KMP- Tháng (Tâm)'!AW82 -> 0
B16: 1 | C16: Thuê Xưởng, Kho, thuê máy | D16: 0.014404929 | E16: 0.069754863 | F16: 0.068994527 | G16: 0.048250298 | H16: =I16-G16 -> 0.041762118 | I16: 0.090012417 | J16: 0.098645551 | K16: 0.1388007 | L16: 0.076634864 | M16: 0.07583104 | N16: =O16-P16 -> 0.03505529 | O16: 0.08344052 | P16: 0.04838523 | T16: =D16-'18 KMP- Tháng (Tâm)'!Q83 -> 0 | U16: =E16-'18 KMP- Tháng (Tâm)'!AD83 -> 0 | V16: =F16-'18 KMP- Tháng (Tâm)'!AQ83 -> 0 | W16: =G16-'18 KMP- Tháng (Tâm)'!BE83 -> -1.4787629e-07 | X16: =I16-'18 KMP- Tháng (Tâm)'!BR83 -> 0.0026032974 | Y16: =J16-'18 KMP- Tháng (Tâm)'!BF83 -> 0 | Z16: =K16-'18 KMP- Tháng (Tâm)'!BG83 -> 0 | AA16: =L16-'18 KMP- Tháng (Tâm)'!BH83 -> 0 | AB16: =M16-'18 KMP- Tháng (Tâm)'!BI83 -> 0 | AC16: =O16-'18 KMP- Tháng (Tâm)'!BJ83 -> 0 | AD16: =P16-'18 KMP- Tháng (Tâm)'!AW83 -> 0
B17: 2 | C17: Tổng Lương và Phụ Cấp | D17: 0.081757584 | E17: 0.1008467 | F17: 0.12122724 | G17: 0.13530833 | H17: =I17-G17 -> 0.002339506 | I17: 0.13764783 | J17: 0.15226522 | K17: 0.19162438 | L17: 0.11398953 | M17: 0.12629374 | N17: =O17-P17 -> -0.00079176009 | O17: 0.13091956 | P17: 0.13171132 | T17: =D17-'18 KMP- Tháng (Tâm)'!Q84 -> 0 | U17: =E17-'18 KMP- Tháng (Tâm)'!AD84 -> 0 | V17: =F17-'18 KMP- Tháng (Tâm)'!AQ84 -> 0 | W17: =G17-'18 KMP- Tháng (Tâm)'!BE84 -> -4.1468953e-07 | X17: =I17-'18 KMP- Tháng (Tâm)'!BR84 -> 0.0017060649 | Y17: =J17-'18 KMP- Tháng (Tâm)'!BF84 -> 0 | Z17: =K17-'18 KMP- Tháng (Tâm)'!BG84 -> 0 | AA17: =L17-'18 KMP- Tháng (Tâm)'!BH84 -> 0 | AB17: =M17-'18 KMP- Tháng (Tâm)'!BI84 -> 0 | AC17: =O17-'18 KMP- Tháng (Tâm)'!BJ84 -> 0 | AD17: =P17-'18 KMP- Tháng (Tâm)'!AW84 -> 0
B18: 3 | C18: Khấu hao | D18: 0.028380917 | E18: 0.031347449 | F18: 0.034476806 | G18: 0.048520242 | H18: =I18-G18 -> -0.027379964 | I18: 0.021140278 | J18: 0.022546219 | K18: 0.031263733 | L18: 0.017385347 | M18: 0.018501271 | N18: =O18-P18 -> -0.027604268 | O18: 0.020831629 | P18: 0.048435898 | T18: =D18-'18 KMP- Tháng (Tâm)'!Q85 -> 0 | U18: =E18-'18 KMP- Tháng (Tâm)'!AD85 -> 0 | V18: =F18-'18 KMP- Tháng (Tâm)'!AQ85 -> 0 | W18: =G18-'18 KMP- Tháng (Tâm)'!BE85 -> -1.4870361e-07 | X18: =I18-'18 KMP- Tháng (Tâm)'!BR85 -> 0.00033736908 | Y18: =J18-'18 KMP- Tháng (Tâm)'!BF85 -> 0 | Z18: =K18-'18 KMP- Tháng (Tâm)'!BG85 -> 0 | AA18: =L18-'18 KMP- Tháng (Tâm)'!BH85 -> 0 | AB18: =M18-'18 KMP- Tháng (Tâm)'!BI85 -> 0 | AC18: =O18-'18 KMP- Tháng (Tâm)'!BJ85 -> 0 | AD18: =P18-'18 KMP- Tháng (Tâm)'!AW85 -> 0
B19: 4 | C19: Chi phí hoạt động quản lý | D19: 0.0082834237 | E19: 0.028694165 | F19: 0.031893564 | G19: 0.030018257 | H19: =I19-G19 -> -0.00029004099 | I19: 0.029728216 | J19: 0.037118058 | K19: 0.047846521 | L19: 0.020426825 | M19: 0.023084163 | N19: =O19-P19 -> -0.0068931337 | O19: 0.029987326 | P19: 0.03688046 | T19: =D19-'18 KMP- Tháng (Tâm)'!Q86 -> 0 | U19: =E19-'18 KMP- Tháng (Tâm)'!AD86 -> 0 | V19: =F19-'18 KMP- Tháng (Tâm)'!AQ86 -> 0 | W19: =G19-'18 KMP- Tháng (Tâm)'!BE86 -> -9.1999193e-08 | X19: =I19-'18 KMP- Tháng (Tâm)'!BR86 -> 0.00096065635 | Y19: =J19-'18 KMP- Tháng (Tâm)'!BF86 -> 0 | Z19: =K19-'18 KMP- Tháng (Tâm)'!BG86 -> 0 | AA19: =L19-'18 KMP- Tháng (Tâm)'!BH86 -> 0 | AB19: =M19-'18 KMP- Tháng (Tâm)'!BI86 -> 0 | AC19: =O19-'18 KMP- Tháng (Tâm)'!BJ86 -> 0 | AD19: =P19-'18 KMP- Tháng (Tâm)'!AW86 -> 0
B20: 5 | C20: Công cụ dụng cụ | D20: 0.0057835141 | E20: 0.0082067361 | F20: 0.0080530619 | G20: 0.0068615361 | H20: =I20-G20 -> -0.0012409924 | I20: 0.0056205437 | J20: 0.0063464196 | K20: 0.0077424001 | L20: 0.0049763679 | M20: 0.0046859977 | N20: =O20-P20 -> -0.0010910112 | O20: 0.0054538175 | P20: 0.0065448288 | T20: =D20-'18 KMP- Tháng (Tâm)'!Q87 -> 0 | U20: =E20-'18 KMP- Tháng (Tâm)'!AD87 -> 0 | V20: =F20-'18 KMP- Tháng (Tâm)'!AQ87 -> 0 | W20: =G20-'18 KMP- Tháng (Tâm)'!BE87 -> -2.1029062e-08 | X20: =I20-'18 KMP- Tháng (Tâm)'!BR87 -> 7.8874658e-05 | Y20: =J20-'18 KMP- Tháng (Tâm)'!BF87 -> 0 | Z20: =K20-'18 KMP- Tháng (Tâm)'!BG87 -> 0 | AA20: =L20-'18 KMP- Tháng (Tâm)'!BH87 -> 0 | AB20: =M20-'18 KMP- Tháng (Tâm)'!BI87 -> 0 | AC20: =O20-'18 KMP- Tháng (Tâm)'!BJ87 -> 0 | AD20: =P20-'18 KMP- Tháng (Tâm)'!AW87 -> 0
B21: 6 | C21: Bảo Trì + Sữa Chữa | D21: 0.004623351 | E21: 0.008108147 | F21: 0.0097208912 | G21: 0.010018963 | H21: =I21-G21 -> -0.00076966336 | I21: 0.0092492998 | J21: 0.010069435 | K21: 0.010402409 | L21: 0.0070913353 | M21: 0.0082723189 | N21: =O21-P21 -> 0.0015373968 | O21: 0.011275681 | P21: 0.0097382844 | T21: =D21-'18 KMP- Tháng (Tâm)'!Q88 -> 0 | U21: =E21-'18 KMP- Tháng (Tâm)'!AD88 -> 0 | V21: =F21-'18 KMP- Tháng (Tâm)'!AQ88 -> 0 | W21: =G21-'18 KMP- Tháng (Tâm)'!BE88 -> 1.7241075e-05 | X21: =I21-'18 KMP- Tháng (Tâm)'!BR88 -> 6.0287951e-05 | Y21: =J21-'18 KMP- Tháng (Tâm)'!BF88 -> 0 | Z21: =K21-'18 KMP- Tháng (Tâm)'!BG88 -> 0 | AA21: =L21-'18 KMP- Tháng (Tâm)'!BH88 -> 0 | AB21: =M21-'18 KMP- Tháng (Tâm)'!BI88 -> 0 | AC21: =O21-'18 KMP- Tháng (Tâm)'!BJ88 -> 0 | AD21: =P21-'18 KMP- Tháng (Tâm)'!AW88 -> 0
B22: 7 | C22: Lãi Vay | D22: 0.001067753 | E22: 0.008235987 | F22: 0.0099551597 | G22: 0.023880515 | H22: =I22-G22 -> -0.013744171 | I22: 0.010136345 | J22: 0.013102303 | K22: 0.017189475 | L22: 0.007877319 | M22: 0.0086260947 | N22: =O22-P22 -> -0.01731594 | O22: 0.0074965703 | P22: 0.02481251 | T22: =D22-'18 KMP- Tháng (Tâm)'!Q89 -> 0 | U22: =E22-'18 KMP- Tháng (Tâm)'!AD89 -> 0 | V22: =F22-'18 KMP- Tháng (Tâm)'!AQ89 -> 0 | W22: =G22-'18 KMP- Tháng (Tâm)'!BE89 -> -7.3188399e-08 | X22: =I22-'18 KMP- Tháng (Tâm)'!BR89 -> 0.00056899013 | Y22: =J22-'18 KMP- Tháng (Tâm)'!BF89 -> 0 | Z22: =K22-'18 KMP- Tháng (Tâm)'!BG89 -> 0 | AA22: =L22-'18 KMP- Tháng (Tâm)'!BH89 -> 0 | AB22: =M22-'18 KMP- Tháng (Tâm)'!BI89 -> 0 | AC22: =O22-'18 KMP- Tháng (Tâm)'!BJ89 -> 0 | AD22: =P22-'18 KMP- Tháng (Tâm)'!AW89 -> 0
B23: TỔNG CHI PHÍ | D23: 1 | E23: 1 | F23: 1 | G23: 1 | H23: =I23-G23 -> 0 | I23: 1 | J23: 1 | K23: 1 | L23: 1 | M23: 1 | N23: =O23=P23 -> TRUE | O23: 1 | P23: 1 | T23: =D23-'18 KMP- Tháng (Tâm)'!Q90 -> 0 | U23: =E23-'18 KMP- Tháng (Tâm)'!AD90 -> 0 | V23: =F23-'18 KMP- Tháng (Tâm)'!AQ90 -> 0 | W23: =G23-'18 KMP- Tháng (Tâm)'!BE90 -> 0 | X23: =I23-'18 KMP- Tháng (Tâm)'!BR90 -> 0 | Y23: =J23-'18 KMP- Tháng (Tâm)'!BF90 -> 0 | Z23: =K23-'18 KMP- Tháng (Tâm)'!BG90 -> 0 | AA23: =L23-'18 KMP- Tháng (Tâm)'!BH90 -> 0 | AB23: =M23-'18 KMP- Tháng (Tâm)'!BI90 -> 0 | AC23: =O23-'18 KMP- Tháng (Tâm)'!BJ90 -> 0 | AD23: =P23-'18 KMP- Tháng (Tâm)'!AW90 -> 0

Sheet Phương Phương
D1: 5
B3: STT | C3: Phân loại | D3: Chỉ tiêu ĐVT: triệu đồng | F3: ="THÁNG "&TEXT($D$1,"00") -> THÁNG 05 | L3: LŨY KẾ
F4: Thực tế | G4: %TT | H4: Ngân sách | I4: %NS | J4: TT vs NS | L4: Thực tế | M4: %TT | N4: Ngân sách | O4: %NS | P4: TT vs NS | Q4: Cùng kỳ | R4: %CK
A5: 2 | B5: I | D5: BIẾN PHÍ | F5: =SUM(F6:F16) -> 80287.264 | G5: =IFERROR(F5/F$25,0) -> 0.71258423 | H5: =SUM(H6:H16) -> 83498.325 | I5: =IFERROR(H5/H$25,0) -> 0.69370016 | J5: =SUM(J6:J16) -> -3211.0614 | L5: =SUM(L6:L16) -> 364354.62 | M5: =IFERROR(L5/L$25,0) -> 0.69829487 | N5: =SUM(N6:N16) -> 396296.15 | O5: =IFERROR(N5/N$25,0) -> 0.69062869 | P5: =SUM(P6:P16) -> -31941.533 | Q5: =SUM(Q6:Q16) -> 411515.4 | R5: =IFERROR(Q5/Q$25,0) -> 0.7281234 | U5: =J5/H5 -> -0.038456597
A6: 3 | B6: 1 | C6: Biến phí | D6: Nguyên liệu nhựa (chai, vảy) | F6: {=SUMPRODUCT('18 KMP- Tháng (Tâm)'!$BF$9:$BQ$34*('18 KMP- Tháng (Tâm)'!$BF$7:$BQ$7=$D$1)*('18 KMP- Tháng (Tâm)'!$A$9:$A$34=$A6))} -> 67389.496 | G6: =IFERROR(F6/F$25,0) -> 0.59811096 | H6: {=SUMPRODUCT('18 KMP- Tháng (Tâm)'!$AS$9:$BD$34*('18 KMP- Tháng (Tâm)'!$AS$7:$BD$7=$D$1)*('18 KMP- Tháng (Tâm)'!$A$9:$A$34=$A6))} -> 73858.796 | I6: =IFERROR(H6/H$25,0) -> 0.61361541 | J6: =F6-H6 -> -6469.3003 | L6: {=SUMPRODUCT('18 KMP- Tháng (Tâm)'!$BF$9:$BQ$34*('18 KMP- Tháng (Tâm)'!$BF$7:$BQ$7<=$D$1)*('18 KMP- Tháng (Tâm)'!$A$9:$A$34=$A6))} -> 311169.09 | M6: =IFERROR(L6/L$25,0) -> 0.59636346 | N6: {=SUMPRODUCT('18 KMP- Tháng (Tâm)'!$AS$9:$BD$34*('18 KMP- Tháng (Tâm)'!$AS$7:$BD$7<=$D$1)*('18 KMP- Tháng (Tâm)'!$A$9:$A$34=$A6))} -> 350037.64 | O6: =IFERROR(N6/N$25,0) -> 0.61001359 | P6: =L6-N6 -> -38868.553 | Q6: {=SUMPRODUCT('18 KMP- Tháng (Tâm)'!$AE$9:$AP$34*('18 KMP- Tháng (Tâm)'!$AE$7:$AP$7<=$D$1)*('18 KMP- Tháng (Tâm)'!$A$9:$A$34=$A6))} -> 361216.47 | R6: =IFERROR(Q6/Q$25,0) -> 0.63912595 | U6: =J6/H6 -> -0.087590113
A7: 4 | B7: =B6+1 -> 2 | C7: Biến phí | D7: Điện | F7: {=SUMPRODUCT('18 KMP- Tháng (Tâm)'!$BF$9:$BQ$34*('18 KMP- Tháng (Tâm)'!$BF$7:$BQ$7=$D$1)*('18 KMP- Tháng (Tâm)'!$A$9:$A$34=$A7))} -> 5888.0109 | G7: =IFERROR(F7/F$25,0) -> 0.052258647 | H7: {=SUMPRODUCT('18 KMP- Tháng (Tâm)'!$AS$9:$BD$34*('18 KMP- Tháng (Tâm)'!$AS$7:$BD$7=$D$1)*('18 KMP- Tháng (Tâm)'!$A$9:$A$34=$A7))} -> 4850.5641 | I7: =IFERROR(H7/H$25,0) -> 0.040298258 | J7: =F7-H7 -> 1037.4469 | L7: {=SUMPRODUCT('18 KMP- Tháng (Tâm)'!$BF$9:$BQ$34*('18 KMP- Tháng (Tâm)'!$BF$7:$BQ$7<=$D$1)*('18 KMP- Tháng (Tâm)'!$A$9:$A$34=$A7))} -> 23977.305 | M7: =IFERROR(L7/L$25,0) -> 0.045953113 | N7: {=SUMPRODUCT('18 KMP- Tháng (Tâm)'!$AS$9:$BD$34*('18 KMP- Tháng (Tâm)'!$AS$7:$BD$7<=$D$1)*('18 KMP- Tháng (Tâm)'!$A$9:$A$34=$A7))} -> 23170.541 | O7: =IFERROR(N7/N$25,0) -> 0.0403795 | P7: =L7-N7 -> 806.76363 | Q7: {=SUMPRODUCT('18 KMP- Tháng (Tâm)'!$AE$9:$AP$34*('18 KMP- Tháng (Tâm)'!$AE$7:$AP$7<=$D$1)*('18 KMP- Tháng (Tâm)'!$A$9:$A$34=$A7))} -> 26810.601 | R7: =IFERROR(Q7/Q$25,0) -> 0.047437899 | U7: =J7/H7 -> 0.21388169
A8: 6 | B8: =B7+1 -> 3 | C8: Biến phí | D8: Chi phí bán hàng | F8: {=SUMPRODUCT('18 KMP- Tháng (Tâm)'!$BF$9:$BQ$34*('18 KMP- Tháng (Tâm)'!$BF$7:$BQ$7=$D$1)*('18 KMP- Tháng (Tâm)'!$A$9:$A$34=$A8))} -> 2769.8497 | G8: =IFERROR(F8/F$25,0) -> 0.024583615 | H8: {=SUMPRODUCT('18 KMP- Tháng (Tâm)'!$AS$9:$BD$34*('18 KMP- Tháng (Tâm)'!$AS$7:$BD$7=$D$1)*('18 KMP- Tháng (Tâm)'!$A$9:$A$34=$A8))} -> 751.38067 | I8: =IFERROR(H8/H$25,0) -> 0.0062424353 | J8: =F8-H8 -> 2018.469 | L8: {=SUMPRODUCT('18 KMP- Tháng (Tâm)'!$BF$9:$BQ$34*('18 KMP- Tháng (Tâm)'!$BF$7:$BQ$7<=$D$1)*('18 KMP- Tháng (Tâm)'!$A$9:$A$34=$A8))} -> 11761.062 | M8: =IFERROR(L8/L$25,0) -> 0.022540375 | N8: {=SUMPRODUCT('18 KMP- Tháng (Tâm)'!$AS$9:$BD$34*('18 KMP- Tháng (Tâm)'!$AS$7:$BD$7<=$D$1)*('18 KMP- Tháng (Tâm)'!$A$9:$A$34=$A8))} -> 3646.7706 | O8: =IFERROR(N8/N$25,0) -> 0.0063552584 | P8: =L8-N8 -> 8114.2917 | Q8: {=SUMPRODUCT('18 KMP- Tháng (Tâm)'!$AE$9:$AP$34*('18 KMP- Tháng (Tâm)'!$AE$7:$AP$7<=$D$1)*('18 KMP- Tháng (Tâm)'!$A$9:$A$34=$A8))} -> 6577.8191 | R8: =IFERROR(Q8/Q$25,0) -> 0.011638602 | U8: =J8/H8 -> 2.6863468
A9: 7 | B9: =B8+1 -> 4 | C9: Biến phí | D9: Phụ gia theo Bom | F9: {=SUMPRODUCT('18 KMP- Tháng (Tâm)'!$BF$9:$BQ$34*('18 KMP- Tháng (Tâm)'!$BF$7:$BQ$7=$D$1)*('18 KMP- Tháng (Tâm)'!$A$9:$A$34=$A9))} -> 1815.0415 | G9: =IFERROR(F9/F$25,0) -> 0.016109279 | H9: {=SUMPRODUCT('18 KMP- Tháng (Tâm)'!$AS$9:$BD$34*('18 KMP- Tháng (Tâm)'!$AS$7:$BD$7=$D$1)*('18 KMP- Tháng (Tâm)'!$A$9:$A$34=$A9))} -> 1335.6927 | I9: =IFERROR(H9/H$25,0) -> 0.011096872 | J9: =F9-H9 -> 479.34871 | L9: {=SUMPRODUCT('18 KMP- Tháng (Tâm)'!$BF$9:$BQ$34*('18 KMP- Tháng (Tâm)'!$BF$7:$BQ$7<=$D$1)*('18 KMP- Tháng (Tâm)'!$A$9:$A$34=$A9))} -> 6144.712 | M9: =IFERROR(L9/L$25,0) -> 0.011776497 | N9: {=SUMPRODUCT('18 KMP- Tháng (Tâm)'!$AS$9:$BD$34*('18 KMP- Tháng (Tâm)'!$AS$7:$BD$7<=$D$1)*('18 KMP- Tháng (Tâm)'!$A$9:$A$34=$A9))} -> 6329.9798 | O9: =IFERROR(N9/N$25,0) -> 0.01103131 | P9: =L9-N9 -> -185.2677 | Q9: {=SUMPRODUCT('18 KMP- Tháng (Tâm)'!$AE$9:$AP$34*('18 KMP- Tháng (Tâm)'!$AE$7:$AP$7<=$D$1)*('18 KMP- Tháng (Tâm)'!$A$9:$A$34=$A9))} -> 6382.9852 | R9: =IFERROR(Q9/Q$25,0) -> 0.011293869 | U9: =J9/H9 -> 0.35887648
A10: 8 | B10: =B9+1 -> 5 | C10: Biến phí | D10: Vật liệu phục vụ SX | F10: {=SUMPRODUCT('18 KMP- Tháng (Tâm)'!$BF$9:$BQ$34*('18 KMP- Tháng (Tâm)'!$BF$7:$BQ$7=$D$1)*('18 KMP- Tháng (Tâm)'!$A$9:$A$34=$A10))} -> 685.02572 | G10: =IFERROR(F10/F$25,0) -> 0.0060798999 | H10: {=SUMPRODUCT('18 KMP- Tháng (Tâm)'!$AS$9:$BD$34*('18 KMP- Tháng (Tâm)'!$AS$7:$BD$7=$D$1)*('18 KMP- Tháng (Tâm)'!$A$9:$A$34=$A10))} -> 892.47321 | I10: =IFERROR(H10/H$25,0) -> 0.0074146255 | J10: =F10-H10 -> -207.44749 | L10: {=SUMPRODUCT('18 KMP- Tháng (Tâm)'!$BF$9:$BQ$34*('18 KMP- Tháng (Tâm)'!$BF$7:$BQ$7<=$D$1)*('18 KMP- Tháng (Tâm)'!$A$9:$A$34=$A10))} -> 3481.4937 | M10: =IFERROR(L10/L$25,0) -> 0.0066723711 | N10: {=SUMPRODUCT('18 KMP- Tháng (Tâm)'!$AS$9:$BD$34*('18 KMP- Tháng (Tâm)'!$AS$7:$BD$7<=$D$1)*('18 KMP- Tháng (Tâm)'!$A$9:$A$34=$A10))} -> 4411.0132 | O10: =IFERROR(N10/N$25,0) -> 0.0076871104 | P10: =L10-N10 -> -929.51943 | Q10: {=SUMPRODUCT('18 KMP- Tháng (Tâm)'!$AE$9:$AP$34*('18 KMP- Tháng (Tâm)'!$AE$7:$AP$7<=$D$1)*('18 KMP- Tháng (Tâm)'!$A$9:$A$34=$A10))} -> 3734.9116 | R10: =IFERROR(Q10/Q$25,0) -> 0.0066084443 | U10: =J10/H10 -> -0.23244114
A11: 9 | B11: =B10+1 -> 6 | C11: Biến phí | D11: Bao bì theo Bom | F11: {=SUMPRODUCT('18 KMP- Tháng (Tâm)'!$BF$9:$BQ$34*('18 KMP- Tháng (Tâm)'!$BF$7:$BQ$7=$D$1)*('18 KMP- Tháng (Tâm)'!$A$9:$A$34=$A11))} -> 785.37371 | G11: =IFERROR(F11/F$25,0) -> 0.0069705318 | H11: {=SUMPRODUCT('18 KMP- Tháng (Tâm)'!$AS$9:$BD$34*('18 KMP- Tháng (Tâm)'!$AS$7:$BD$7=$D$1)*('18 KMP- Tháng (Tâm)'!$A$9:$A$34=$A11))} -> 711.91298 | I11: =IFERROR(H11/H$25,0) -> 0.0059145396 | J11: =F11-H11 -> 73.460728 | L11: {=SUMPRODUCT('18 KMP- Tháng (Tâm)'!$BF$9:$BQ$34*('18 KMP- Tháng (Tâm)'!$BF$7:$BQ$7<=$D$1)*('18 KMP- Tháng (Tâm)'!$A$9:$A$34=$A11))} -> 3577.9777 | M11: =IFERROR(L11/L$25,0) -> 0.0068572851 | N11: {=SUMPRODUCT('18 KMP- Tháng (Tâm)'!$AS$9:$BD$34*('18 KMP- Tháng (Tâm)'!$AS$7:$BD$7<=$D$1)*('18 KMP- Tháng (Tâm)'!$A$9:$A$34=$A11))} -> 3380.3508 | O11: =IFERROR(N11/N$25,0) -> 0.0058909663 | P11: =L11-N11 -> 197.62689 | Q11: {=SUMPRODUCT('18 KMP- Tháng (Tâm)'!$AE$9:$AP$34*('18 KMP- Tháng (Tâm)'!$AE$7:$AP$7<=$D$1)*('18 KMP- Tháng (Tâm)'!$A$9:$A$34=$A11))} -> 3216.4253 | R11: =IFERROR(Q11/Q$25,0) -> 0.0056910497 | U11: =J11/H11 -> 0.10318779
A12: 10 | B12: =B11+1 -> 7 | C12: Biến phí | D12: Xăng dầu | F12: {=SUMPRODUCT('18 KMP- Tháng (Tâm)'!$BF$9:$BQ$34*('18 KMP- Tháng (Tâm)'!$BF$7:$BQ$7=$D$1)*('18 KMP- Tháng (Tâm)'!$A$9:$A$34=$A12))} -> 356.91602 | G12: =IFERROR(F12/F$25,0) -> 0.0031677842 | H12: {=SUMPRODUCT('18 KMP- Tháng (Tâm)'!$AS$9:$BD$34*('18 KMP- Tháng (Tâm)'!$AS$7:$BD$7=$D$1)*('18 KMP- Tháng (Tâm)'!$A$9:$A$34=$A12))} -> 231.92 | I12: =IFERROR(H12/H$25,0) -> 0.0019267805 | J12: =F12-H12 -> 124.99602 | L12: {=SUMPRODUCT('18 KMP- Tháng (Tâm)'!$BF$9:$BQ$34*('18 KMP- Tháng (Tâm)'!$BF$7:$BQ$7<=$D$1)*('18 KMP- Tháng (Tâm)'!$A$9:$A$34=$A12))} -> 1363.8787 | M12: =IFERROR(L12/L$25,0) -> 0.0026139081 | N12: {=SUMPRODUCT('18 KMP- Tháng (Tâm)'!$AS$9:$BD$34*('18 KMP- Tháng (Tâm)'!$AS$7:$BD$7<=$D$1)*('18 KMP- Tháng (Tâm)'!$A$9:$A$34=$A12))} -> 1159.6 | O12: =IFERROR(N12/N$25,0) -> 0.0020208448 | P12: =L12-N12 -> 204.27869 | Q12: {=SUMPRODUCT('18 KMP- Tháng (Tâm)'!$AE$9:$AP$34*('18 KMP- Tháng (Tâm)'!$AE$7:$AP$7<=$D$1)*('18 KMP- Tháng (Tâm)'!$A$9:$A$34=$A12))} -> 1164.3456 | R12: =IFERROR(Q12/Q$25,0) -> 0.0020601593 | U12: =J12/H12 -> 0.53896178
A13: 11 | B13: =B12+1 -> 8 | C13: Biến phí | D13: Hóa chất theo Bom | F13: {=SUMPRODUCT('18 KMP- Tháng (Tâm)'!$BF$9:$BQ$34*('18 KMP- Tháng (Tâm)'!$BF$7:$BQ$7=$D$1)*('18 KMP- Tháng (Tâm)'!$A$9:$A$34=$A13))} -> 385.67559 | G13: =IFERROR(F13/F$25,0) -> 0.0034230379 | H13: {=SUMPRODUCT('18 KMP- Tháng (Tâm)'!$AS$9:$BD$34*('18 KMP- Tháng (Tâm)'!$AS$7:$BD$7=$D$1)*('18 KMP- Tháng (Tâm)'!$A$9:$A$34=$A13))} -> 471.8827 | I13: =IFERROR(H13/H$25,0) -> 0.0039203793 | J13: =F13-H13 -> -86.207116 | L13: {=SUMPRODUCT('18 KMP- Tháng (Tâm)'!$BF$9:$BQ$34*('18 KMP- Tháng (Tâm)'!$BF$7:$BQ$7<=$D$1)*('18 KMP- Tháng (Tâm)'!$A$9:$A$34=$A13))} -> 1525.1431 | M13: =IFERROR(L13/L$25,0) -> 0.0029229755 | N13: {=SUMPRODUCT('18 KMP- Tháng (Tâm)'!$AS$9:$BD$34*('18 KMP- Tháng (Tâm)'!$AS$7:$BD$7<=$D$1)*('18 KMP- Tháng (Tâm)'!$A$9:$A$34=$A13))} -> 2230.1306 | O13: =IFERROR(N13/N$25,0) -> 0.0038864677 | P13: =L13-N13 -> -704.98748 | Q13: {=SUMPRODUCT('18 KMP- Tháng (Tâm)'!$AE$9:$AP$34*('18 KMP- Tháng (Tâm)'!$AE$7:$AP$7<=$D$1)*('18 KMP- Tháng (Tâm)'!$A$9:$A$34=$A13))} -> 1172.2512 | R13: =IFERROR(Q13/Q$25,0) -> 0.0020741473 | U13: =J13/H13 -> -0.1826876
A14: 12 | B14: =B13+1 -> 9 | C14: Biến phí | D14: Hóa chất XLNT | F14: {=SUMPRODUCT('18 KMP- Tháng (Tâm)'!$BF$9:$BQ$34*('18 KMP- Tháng (Tâm)'!$BF$7:$BQ$7=$D$1)*('18 KMP- Tháng (Tâm)'!$A$9:$A$34=$A14))} -> 84.135278 | G14: =IFERROR(F14/F$25,0) -> 0.00074673703 | H14: {=SUMPRODUCT('18 KMP- Tháng (Tâm)'!$AS$9:$BD$34*('18 KMP- Tháng (Tâm)'!$AS$7:$BD$7=$D$1)*('18 KMP- Tháng (Tâm)'!$A$9:$A$34=$A14))} -> 122.35858 | I14: =IFERROR(H14/H$25,0) -> 0.0010165493 | J14: =F14-H14 -> -38.223301 | L14: {=SUMPRODUCT('18 KMP- Tháng (Tâm)'!$BF$9:$BQ$34*('18 KMP- Tháng (Tâm)'!$BF$7:$BQ$7<=$D$1)*('18 KMP- Tháng (Tâm)'!$A$9:$A$34=$A14))} -> 404.52582 | M14: =IFERROR(L14/L$25,0) -> 0.00077528401 | N14: {=SUMPRODUCT('18 KMP- Tháng (Tâm)'!$AS$9:$BD$34*('18 KMP- Tháng (Tâm)'!$AS$7:$BD$7<=$D$1)*('18 KMP- Tháng (Tâm)'!$A$9:$A$34=$A14))} -> 617.51687 | O14: =IFERROR(N14/N$25,0) -> 0.0010761519 | P14: =L14-N14 -> -212.99104 | Q14: {=SUMPRODUCT('18 KMP- Tháng (Tâm)'!$AE$9:$AP$34*('18 KMP- Tháng (Tâm)'!$AE$7:$AP$7<=$D$1)*('18 KMP- Tháng (Tâm)'!$A$9:$A$34=$A14))} -> 351.53636 | R14: =IFERROR(Q14/Q$25,0) -> 0.00062199824 | U14: =J14/H14 -> -0.31238759
A15: 13 | B15: =B14+1 -> 10 | C15: Biến phí | D15: Nước | F15: {=SUMPRODUCT('18 KMP- Tháng (Tâm)'!$BF$9:$BQ$34*('18 KMP- Tháng (Tâm)'!$BF$7:$BQ$7=$D$1)*('18 KMP- Tháng (Tâm)'!$A$9:$A$34=$A15))} -> 125.0844 | G15: =IFERROR(F15/F$25,0) -> 0.0011101782 | H15: {=SUMPRODUCT('18 KMP- Tháng (Tâm)'!$AS$9:$BD$34*('18 KMP- Tháng (Tâm)'!$AS$7:$BD$7=$D$1)*('18 KMP- Tháng (Tâm)'!$A$9:$A$34=$A15))} -> 221.48737 | I15: =IFERROR(H15/H$25,0) -> 0.0018401066 | J15: =F15-H15 -> -96.402966 | L15: {=SUMPRODUCT('18 KMP- Tháng (Tâm)'!$BF$9:$BQ$34*('18 KMP- Tháng (Tâm)'!$BF$7:$BQ$7<=$D$1)*('18 KMP- Tháng (Tâm)'!$A$9:$A$34=$A15))} -> 546.8022 | M15: =IFERROR(L15/L$25,0) -> 0.0010479603 | N15: {=SUMPRODUCT('18 KMP- Tháng (Tâm)'!$AS$9:$BD$34*('18 KMP- Tháng (Tâm)'!$AS$7:$BD$7<=$D$1)*('18 KMP- Tháng (Tâm)'!$A$9:$A$34=$A15))} -> 1052.8955 | O15: =IFERROR(N15/N$25,0) -> 0.0018348899 | P15: =L15-N15 -> -506.09325 | Q15: {=SUMPRODUCT('18 KMP- Tháng (Tâm)'!$AE$9:$AP$34*('18 KMP- Tháng (Tâm)'!$AE$7:$AP$7<=$D$1)*('18 KMP- Tháng (Tâm)'!$A$9:$A$34=$A15))} -> 642.6658 | R15: =IFERROR(Q15/Q$25,0) -> 0.0011371142 | U15: =J15/H15 -> -0.43525266
