Workbook

Sheet 18 KMP- Tháng (Tâm)
R1: =R22-R34 -> 7116.8543 | S1: =S22-S34 -> 7116.8543 | T1: =T22-T34 -> 7639.8543 | U1: =U22-U34 -> 6076.0361 | V1: =V22-V34 -> 6002.0361 | W1: =W22-W34 -> 6002.0361 | X1: =X22-X34 -> 6002.0361 | Y1: =Y22-Y34 -> 6002.0361 | ... AC1: =AC22-AC34 -> 1449.1667
D2: BÁO CÁO THÁNG
D3: TỔNG CHI PHÍ THÁNG (bao gồm chi phí thuê máy, thuê xưởng)
D4: 1 | AP4: =COUNTIFS($AE$10:$AP$10,"<>"&0) -> 12
E5: 2024 | F5: 2024 | G5: 2024 | H5: 2024 | I5: 2024 | J5: 2024 | K5: 2024 | L5: 2024 | M5: 2024 | N5: 2024 | O5: 2024 | P5: 2024 | R5: 2024 | S5: 2024 | T5: 2024 | U5: 2024 | V5: 2024 | W5: 2024 | X5: 2024 | Y5: 2024 | Z5: 2024 | AA5: 2024 | AB5: 2024 | AC5: 2024 | AD5: 2024 | AE5: 2025 | AF5: 2025 | AG5: 2025 | AH5: 2025 | AI5: 2025 | AJ5: 2025 | AK5: 2025 | AL5: 2025 | AM5: 2025 | AN5: 2025 | AO5: 2025 | AP5: 2025 | AQ5: 2025 | AS5: 2026 | AT5: 2026 | AU5: 2026 | AV5: 2026 | AW5: 2026 | AX5: 2026 | AY5: 2026 | AZ5: 2026 | BA5: 2026 | BB5: 2026 | BC5: 2026 | BD5: 2026 | BE5: 2026 | BF5: 2026 | BG5: 2026 | BH5: 2026 | BI5: 2026 | BJ5: 2026 | BK5: 2026 | BL5: 2026 | BM5: 2026 | BN5: 2026 | BO5: 2026 | BP5: 2026 | BQ5: 2026 | BR5: 2026
E6: TT | F6: TT | G6: TT | H6: TT | I6: TT | J6: TT | K6: TT | L6: TT | M6: TT | N6: TT | O6: TT | P6: TT | R6: TT | S6: TT | T6: TT | U6: TT | V6: TT | W6: TT | X6: TT | Y6: TT | Z6: TT | AA6: TT | AB6: TT | AC6: TT | AF6: TT | AG6: TT | AH6: TT | AI6: TT | AJ6: TT | AK6: TT | AL6: TT | AM6: TT | AN6: TT | AO6: TT | AP6: TT | AQ6: TT | AS6: KH | AT6: KH | AU6: KH | AV6: KH | AW6: KH | AX6: KH | AY6: KH | AZ6: KH | BA6: KH | BB6: KH | BC6: KH | BD6: KH | BE6: KH | BG6: TT | BH6: TT | BI6: TT | BJ6: TT | BK6: TT | BL6: TT | BM6: TT | BN6: TT | BO6: TT | BP6: TT | BQ6: TT | BR6: TT
E7: 1 | F7: 2 | G7: 3 | H7: 4 | I7: 5 | J7: 6 | K7: 7 | L7: 8 | M7: 9 | N7: 10 | O7: 11 | P7: 12 | R7: 1 | S7: 2 | T7: 3 | U7: 4 | V7: 5 | W7: 6 | X7: 7 | Y7: 8 | Z7: 9 | AA7: 10 | AB7: 11 | AC7: 12 | AE7: 1 | AF7: 2 | AG7: 3 | AH7: 4 | AI7: 5 | AJ7: 6 | AK7: 7 | AL7: 8 | AM7: 9 | AN7: 10 | AO7: 11 | AP7: 12 | AS7: 1 | AT7: 2 | AU7: 3 | AV7: 4 | AW7: 5 | AX7: 6 | AY7: 7 | AZ7: 8 | BA7: 9 | BB7: 10 | BC7: 11 | BD7: 12 | BF7: 1 | BG7: 2 | BH7: 3 | BI7: 4 | BJ7: 5 | BK7: 6 | BL7: 7 | BM7: 8 | BN7: 9 | BO7: 10 | BP7: 11 | BQ7: 12
A8: 1 | B8: STT | C8: Phân loại | D8: Chỉ tiêu ĐVT: triệu đồng | E8: T1.23 | F8: T2.23 | G8: T3.23 | H8: T4.23 | I8: T5.23 | J8: T6.23 | K8: T7.23 | L8: T8.23 | M8: T9.23 | N8: T10.23 | O8: T11.23 | P8: T12.23 | Q8: BQ TT 2023 | R8: T1.24 | S8: T2.24 | T8: T3.24 | U8: T4.24 | V8: T5.24 | W8: T6.24 | X8: T7.24 | Y8: T8.24 | Z8: T9.24 | AA8: T10.24 | AB8: T11.24 | AC8: T12.24 | AD8: BQ TT 2024 | AE8: T1.25 | AF8: T2.25 | AG8: T3.25 | AH8: T4.25 | AI8: T5.25 | AJ8: T6.25 | AK8: T7.25 | AL8: T8.25 | AM8: T9.25 | AN8: T10.25 | AO8: T11.25 | AP8: T12.25 | AQ8: BQ TT 2025 | AR8: Lũy kế 2025 | AS8: KH T1.2026 | AT8: KH T2.2026 | AU8: KH T3.2026 | AV8: KH T4.2026 | AW8: KH T5.2026 | AX8: KH T6.2026 | AY8: KH T7.2026 | AZ8: KH T8.2026 | BA8: KH T9.2026 | BB8: KH T10.2026 | BC8: KH T11.2026 | BD8: KH T12.2026 | BE8: BQ KH 2026 | BF8: T1.26 | BG8: T2.26 | BH8: T3.26 | BI8: T4.26 | BJ8: T5.26 | BK8: T6.26 | BL8: T7.26 | BM8: T8.26 | BN8: T9.26 | BO8: T10.26 | BP8: T11.26 | BQ8: T12.26 | BR8: BQ TT 2026 | BS8: Lũy kế 2026 | BT8: ="% +/- "&"T"&$D$4&".26"&" sv KH T"&$D$4&".26" -> % +/- T1.26 sv KH T1.26 | BU8: Tỷ trọng lũy kế 2026 | BV8: Giải trình
A9: 2 | B9: I | D9: BIẾN PHÍ | E9: =SUM(E10:E20) -> 21899.782 | F9: =SUM(F10:F20) -> 33453.411 | G9: =SUM(G10:G20) -> 42421.458 | H9: =SUM(H10:H20) -> 36738.301 | I9: =SUM(I10:I20) -> 45685.664 | J9: =SUM(J10:J20) -> 39025.693 | K9: =SUM(K10:K20) -> 46671.954 | L9: =SUM(L10:L20) -> 48424.686 | ... BS9: =SUM(BS10:BS20) -> 352178.69 | BT9: =IFERROR(BF9/AS9-1,"-") -> -0.22365911 | BU9: =BS9/$BS$29 -> 0.77340428
A10: 3 | B10: 1 | C10: Biến phí | D10: Nguyên liệu nhựa | E10: =INDEX('18 KMP- Tháng'!$E$6:$Q$29,MATCH($A10,'18 KMP- Tháng'!$A$6:$A$29,0),MATCH(E$7,'18 KMP- Tháng'!$E$2:$P$2,0)) -> 19184.787 | F10: =INDEX('18 KMP- Tháng'!$E$6:$Q$29,MATCH($A10,'18 KMP- Tháng'!$A$6:$A$29,0),MATCH(F$7,'18 KMP- Tháng'!$E$2:$P$2,0)) -> 29413.013 | G10: =INDEX('18 KMP- Tháng'!$E$6:$Q$29,MATCH($A10,'18 KMP- Tháng'!$A$6:$A$29,0),MATCH(G$7,'18 KMP- Tháng'!$E$2:$P$2,0)) -> 36905.746 | H10: =INDEX('18 KMP- Tháng'!$E$6:$Q$29,MATCH($A10,'18 KMP- Tháng'!$A$6:$A$29,0),MATCH(H$7,'18 KMP- Tháng'!$E$2:$P$2,0)) -> 31466.941 | I10: =INDEX('18 KMP- Tháng'!$E$6:$Q$29,MATCH($A10,'18 KMP- Tháng'!$A$6:$A$29,0),MATCH(I$7,'18 KMP- Tháng'!$E$2:$P$2,0)) -> 39521.728 | J10: =INDEX('18 KMP- Tháng'!$E$6:$Q$29,MATCH($A10,'18 KMP- Tháng'!$A$6:$A$29,0),MATCH(J$7,'18 KMP- Tháng'!$E$2:$P$2,0)) -> 33022.7 | K10: =INDEX('18 KMP- Tháng'!$E$6:$Q$29,MATCH($A10,'18 KMP- Tháng'!$A$6:$A$29,0),MATCH(K$7,'18 KMP- Tháng'!$E$2:$P$2,0)) -> 40067.115 | L10: =INDEX('18 KMP- Tháng'!$E$6:$Q$29,MATCH($A10,'18 KMP- Tháng'!$A$6:$A$29,0),MATCH(L$7,'18 KMP- Tháng'!$E$2:$P$2,0)) -> 41710.886 | ... P10: =INDEX('18 KMP- Tháng'!$E$6:$Q$29,MATCH($A10,'18 KMP- Tháng'!$A$6:$A$29,0),MATCH(P$7,'18 KMP- Tháng'!$E$2:$P$2,0)) -> 71767.131 | Q10: =AVERAGE(E10:P10) -> 37778.444 | R10: =INDEX('18 KMP- Tháng'!$R$6:$AC$24,MATCH($A10,'18 KMP- Tháng'!$A$6:$A$24,0),MATCH(R$7,'18 KMP- Tháng'!$R$2:$AC$2,0)) -> 82388.014 | S10: =INDEX('18 KMP- Tháng'!$R$6:$AC$24,MATCH($A10,'18 KMP- Tháng'!$A$6:$A$24,0),MATCH(S$7,'18 KMP- Tháng'!$R$2:$AC$2,0)) -> 54679.339 | T10: =INDEX('18 KMP- Tháng'!$R$6:$AC$24,MATCH($A10,'18 KMP- Tháng'!$A$6:$A$24,0),MATCH(T$7,'18 KMP- Tháng'!$R$2:$AC$2,0)) -> 92225.012 | U10: =INDEX('18 KMP- Tháng'!$R$6:$AC$24,MATCH($A10,'18 KMP- Tháng'!$A$6:$A$24,0),MATCH(U$7,'18 KMP- Tháng'!$R$2:$AC$2,0))+3500 -> 88305.105 | V10: =INDEX('18 KMP- Tháng'!$R$6:$AC$24,MATCH($A10,'18 KMP- Tháng'!$A$6:$A$24,0),MATCH(V$7,'18 KMP- Tháng'!$R$2:$AC$2,0))-3500 -> 82512.811 | W10: =INDEX('18 KMP- Tháng'!$R$6:$AC$24,MATCH($A10,'18 KMP- Tháng'!$A$6:$A$24,0),MATCH(W$7,'18 KMP- Tháng'!$R$2:$AC$2,0)) -> 63429.137 | X10: =INDEX('18 KMP- Tháng'!$R$6:$AC$24,MATCH($A10,'18 KMP- Tháng'!$A$6:$A$24,0),MATCH(X$7,'18 KMP- Tháng'!$R$2:$AC$2,0)) -> 34124.938 | Y10: =INDEX('18 KMP- Tháng'!$R$6:$AC$24,MATCH($A10,'18 KMP- Tháng'!$A$6:$A$24,0),MATCH(Y$7,'18 KMP- Tháng'!$R$2:$AC$2,0)) -> 39820.046 | Z10: =INDEX('18 KMP- Tháng'!$R$6:$AC$24,MATCH($A10,'18 KMP- Tháng'!$A$6:$A$24,0),MATCH(Z$7,'18 KMP- Tháng'!$R$2:$AC$2,0)) -> 53180.748 | AA10: =INDEX('18 KMP- Tháng'!$R$6:$AC$24,MATCH($A10,'18 KMP- Tháng'!$A$6:$A$24,0),MATCH(AA$7,'18 KMP- Tháng'!$R$2:$AC$2,0)) -> 80242.846 | AB10: =INDEX('18 KMP- Tháng'!$R$6:$AC$24,MATCH($A10,'18 KMP- Tháng'!$A$6:$A$24,0),MATCH(AB$7,'18 KMP- Tháng'!$R$2:$AC$2,0)) -> 87480.524 | AC10: =INDEX('18 KMP- Tháng'!$R$6:$AC$24,MATCH($A10,'18 KMP- Tháng'!$A$6:$A$24,0),MATCH(AC$7,'18 KMP- Tháng'!$R$2:$AC$2,0)) -> 60679.338 | AD10: =AVERAGE(R10:AC10) -> 68255.655 | AE10: =INDEX('18 KMP- Tháng'!$AF$6:$AQ$29,MATCH($A10,'18 KMP- Tháng'!$A$6:$A$29,0),MATCH(AE$7,'18 KMP- Tháng'!$AF$2:$AQ$2,0)) -> 33690.154 | AF10: =INDEX('18 KMP- Tháng'!$AF$6:$AQ$29,MATCH($A10,'18 KMP- Tháng'!$A$6:$A$29,0),MATCH(AF$7,'18 KMP- Tháng'!$AF$2:$AQ$2,0)) -> 54984.763 | AG10: =INDEX('18 KMP- Tháng'!$AF$6:$AQ$29,MATCH($A10,'18 KMP- Tháng'!$A$6:$A$29,0),MATCH(AG$7,'18 KMP- Tháng'!$AF$2:$AQ$2,0)) -> 93493.566 | AH10: =INDEX('18 KMP- Tháng'!$AF$6:$AQ$29,MATCH($A10,'18 KMP- Tháng'!$A$6:$A$29,0),MATCH(AH$7,'18 KMP- Tháng'!$AF$2:$AQ$2,0)) -> 81794.172 | AI10: =INDEX('18 KMP- Tháng'!$AF$6:$AQ$29,MATCH($A10,'18 KMP- Tháng'!$A$6:$A$29,0),MATCH(AI$7,'18 KMP- Tháng'!$AF$2:$AQ$2,0)) -> 97253.82 | AJ10: =INDEX('18 KMP- Tháng'!$AF$6:$AQ$29,MATCH($A10,'18 KMP- Tháng'!$A$6:$A$29,0),MATCH(AJ$7,'18 KMP- Tháng'!$AF$2:$AQ$2,0)) -> 84746.444 | AK10: =INDEX('18 KMP- Tháng'!$AF$6:$AQ$29,MATCH($A10,'18 KMP- Tháng'!$A$6:$A$29,0),MATCH(AK$7,'18 KMP- Tháng'!$AF$2:$AQ$2,0)) -> 93606.745 | AL10: =INDEX('18 KMP- Tháng'!$AF$6:$AQ$29,MATCH($A10,'18 KMP- Tháng'!$A$6:$A$29,0),MATCH(AL$7,'18 KMP- Tháng'!$AF$2:$AQ$2,0)) -> 93602.195 | ... AP10: =INDEX('18 KMP- Tháng'!$AF$6:$AQ$29,MATCH($A10,'18 KMP- Tháng'!$A$6:$A$29,0),MATCH(AP$7,'18 KMP- Tháng'!$AF$2:$AQ$2,0)) -> 66382.966 | AQ10: =SUM(AE10:AP10)/COUNTIFS($AE$29:$AP$29,"<>"&0) -> 74512.994 | AR10: =SUM(AE10:AP10) -> 894155.93 | AS10: =INDEX('18 KMP- Tháng'!$BH$6:$BS$29,MATCH($A10,'18 KMP- Tháng'!$A$6:$A$29,0),MATCH(AS$7,'18 KMP- Tháng'!$BH$2:$BS$2,0)) -> 70449.794 | AT10: =INDEX('18 KMP- Tháng'!$BH$6:$BS$29,MATCH($A10,'18 KMP- Tháng'!$A$6:$A$29,0),MATCH(AT$7,'18 KMP- Tháng'!$BH$2:$BS$2,0)) -> 57841.876 | AU10: =INDEX('18 KMP- Tháng'!$BH$6:$BS$29,MATCH($A10,'18 KMP- Tháng'!$A$6:$A$29,0),MATCH(AU$7,'18 KMP- Tháng'!$BH$2:$BS$2,0)) -> 73858.796 | AV10: =INDEX('18 KMP- Tháng'!$BH$6:$BS$29,MATCH($A10,'18 KMP- Tháng'!$A$6:$A$29,0),MATCH(AV$7,'18 KMP- Tháng'!$BH$2:$BS$2,0)) -> 74028.379 | AW10: =INDEX('18 KMP- Tháng'!$BH$6:$BS$29,MATCH($A10,'18 KMP- Tháng'!$A$6:$A$29,0),MATCH(AW$7,'18 KMP- Tháng'!$BH$2:$BS$2,0)) -> 73858.796 | AX10: =INDEX('18 KMP- Tháng'!$BH$6:$BS$29,MATCH($A10,'18 KMP- Tháng'!$A$6:$A$29,0),MATCH(AX$7,'18 KMP- Tháng'!$BH$2:$BS$2,0)) -> 75365.564 | AY10: =INDEX('18 KMP- Tháng'!$BH$6:$BS$29,MATCH($A10,'18 KMP- Tháng'!$A$6:$A$29,0),MATCH(AY$7,'18 KMP- Tháng'!$BH$2:$BS$2,0)) -> 77176.425 | AZ10: =INDEX('18 KMP- Tháng'!$BH$6:$BS$29,MATCH($A10,'18 KMP- Tháng'!$A$6:$A$29,0),MATCH(AZ$7,'18 KMP- Tháng'!$BH$2:$BS$2,0)) -> 77920.069 | ... BD10: =INDEX('18 KMP- Tháng'!$BH$6:$BS$29,MATCH($A10,'18 KMP- Tháng'!$A$6:$A$29,0),MATCH(BD$7,'18 KMP- Tháng'!$BH$2:$BS$2,0)) -> 77920.069 | BE10: =AVERAGE(AS10:BD10) -> 74259.721 | BF10: =INDEX('18 KMP- Tháng'!$AS$6:$BD$29,MATCH($A10,'18 KMP- Tháng'!$A$6:$A$29,0),MATCH(BF$7,'18 KMP- Tháng'!$AS$2:$BD$2,0)) -> 54282.956 | BG10: =INDEX('18 KMP- Tháng'!$AS$6:$BD$29,MATCH($A10,'18 KMP- Tháng'!$A$6:$A$29,0),MATCH(BG$7,'18 KMP- Tháng'!$AS$2:$BD$2,0)) -> 32788.527 | BH10: =INDEX('18 KMP- Tháng'!$AS$6:$BD$29,MATCH($A10,'18 KMP- Tháng'!$A$6:$A$29,0),MATCH(BH$7,'18 KMP- Tháng'!$AS$2:$BD$2,0)) -> 79002.1 | BI10: =INDEX('18 KMP- Tháng'!$AS$6:$BD$29,MATCH($A10,'18 KMP- Tháng'!$A$6:$A$29,0),MATCH(BI$7,'18 KMP- Tháng'!$AS$2:$BD$2,0)) -> 77706.01 | BJ10: =INDEX('18 KMP- Tháng'!$AS$6:$BD$29,MATCH($A10,'18 KMP- Tháng'!$A$6:$A$29,0),MATCH(BJ$7,'18 KMP- Tháng'!$AS$2:$BD$2,0)) -> 67389.496 | BK10: =INDEX('18 KMP- Tháng'!$AS$6:$BD$29,MATCH($A10,'18 KMP- Tháng'!$A$6:$A$29,0),MATCH(BK$7,'18 KMP- Tháng'!$AS$2:$BD$2,0)) -> 0 | BL10: =INDEX('18 KMP- Tháng'!$AS$6:$BD$29,MATCH($A10,'18 KMP- Tháng'!$A$6:$A$29,0),MATCH(BL$7,'18 KMP- Tháng'!$AS$2:$BD$2,0)) -> 0 | BM10: =INDEX('18 KMP- Tháng'!$AS$6:$BD$29,MATCH($A10,'18 KMP- Tháng'!$A$6:$A$29,0),MATCH(BM$7,'18 KMP- Tháng'!$AS$2:$BD$2,0)) -> 0 | ... BQ10: =INDEX('18 KMP- Tháng'!$AS$6:$BD$29,MATCH($A10,'18 KMP- Tháng'!$A$6:$A$29,0),MATCH(BQ$7,'18 KMP- Tháng'!$AS$2:$BD$2,0)) -> 0 | BR10: =SUM(BF10:BQ10)/COUNTIFS($BF$29:$BQ$29,"<>"&0) -> 62233.818 | BS10: =SUM(BF10:BQ10) -> 311169.09 | BT10: =IFERROR(BF10/AS10-1,"-") -> -0.22948028 | BU10: =BS10/$BS$29 -> 0.68334489
A11: 4 | B11: =B10+1 -> 2 | C11: Biến phí | D11: Điện | E11: =INDEX('18 KMP- Tháng'!$E$6:$Q$29,MATCH($A11,'18 KMP- Tháng'!$A$6:$A$29,0),MATCH(E$7,'18 KMP- Tháng'!$E$2:$P$2,0)) -> 1376.9572 | F11: =INDEX('18 KMP- Tháng'!$E$6:$Q$29,MATCH($A11,'18 KMP- Tháng'!$A$6:$A$29,0),MATCH(F$7,'18 KMP- Tháng'!$E$2:$P$2,0)) -> 2218.3915 | G11: =INDEX('18 KMP- Tháng'!$E$6:$Q$29,MATCH($A11,'18 KMP- Tháng'!$A$6:$A$29,0),MATCH(G$7,'18 KMP- Tháng'!$E$2:$P$2,0)) -> 2574.9329 | H11: =INDEX('18 KMP- Tháng'!$E$6:$Q$29,MATCH($A11,'18 KMP- Tháng'!$A$6:$A$29,0),MATCH(H$7,'18 KMP- Tháng'!$E$2:$P$2,0)) -> 2388.6837 | I11: =INDEX('18 KMP- Tháng'!$E$6:$Q$29,MATCH($A11,'18 KMP- Tháng'!$A$6:$A$29,0),MATCH(I$7,'18 KMP- Tháng'!$E$2:$P$2,0)) -> 2787.5241 | J11: =INDEX('18 KMP- Tháng'!$E$6:$Q$29,MATCH($A11,'18 KMP- Tháng'!$A$6:$A$29,0),MATCH(J$7,'18 KMP- Tháng'!$E$2:$P$2,0)) -> 2655.8263 | K11: =INDEX('18 KMP- Tháng'!$E$6:$Q$29,MATCH($A11,'18 KMP- Tháng'!$A$6:$A$29,0),MATCH(K$7,'18 KMP- Tháng'!$E$2:$P$2,0)) -> 3135.2611 | L11: =INDEX('18 KMP- Tháng'!$E$6:$Q$29,MATCH($A11,'18 KMP- Tháng'!$A$6:$A$29,0),MATCH(L$7,'18 KMP- Tháng'!$E$2:$P$2,0)) -> 2978.86 | ... P11: =INDEX('18 KMP- Tháng'!$E$6:$Q$29,MATCH($A11,'18 KMP- Tháng'!$A$6:$A$29,0),MATCH(P$7,'18 KMP- Tháng'!$E$2:$P$2,0)) -> 5223.2615 | Q11: =AVERAGE(E11:P11) -> 2867.0941 | R11: =INDEX('18 KMP- Tháng'!$R$6:$AC$24,MATCH($A11,'18 KMP- Tháng'!$A$6:$A$24,0),MATCH(R$7,'18 KMP- Tháng'!$R$2:$AC$2,0)) -> 5469.8475 | S11: =INDEX('18 KMP- Tháng'!$R$6:$AC$24,MATCH($A11,'18 KMP- Tháng'!$A$6:$A$24,0),MATCH(S$7,'18 KMP- Tháng'!$R$2:$AC$2,0)) -> 4124.0471 | T11: =INDEX('18 KMP- Tháng'!$R$6:$AC$24,MATCH($A11,'18 KMP- Tháng'!$A$6:$A$24,0),MATCH(T$7,'18 KMP- Tháng'!$R$2:$AC$2,0)) -> 5082.6309 | U11: =INDEX('18 KMP- Tháng'!$R$6:$AC$24,MATCH($A11,'18 KMP- Tháng'!$A$6:$A$24,0),MATCH(U$7,'18 KMP- Tháng'!$R$2:$AC$2,0))+380 -> 5884.6555 | V11: =INDEX('18 KMP- Tháng'!$R$6:$AC$24,MATCH($A11,'18 KMP- Tháng'!$A$6:$A$24,0),MATCH(V$7,'18 KMP- Tháng'!$R$2:$AC$2,0))-380 -> 5562.4358 | W11: =INDEX('18 KMP- Tháng'!$R$6:$AC$24,MATCH($A11,'18 KMP- Tháng'!$A$6:$A$24,0),MATCH(W$7,'18 KMP- Tháng'!$R$2:$AC$2,0)) -> 4785.0316 | X11: =INDEX('18 KMP- Tháng'!$R$6:$AC$24,MATCH($A11,'18 KMP- Tháng'!$A$6:$A$24,0),MATCH(X$7,'18 KMP- Tháng'!$R$2:$AC$2,0)) -> 3003.788 | Y11: =INDEX('18 KMP- Tháng'!$R$6:$AC$24,MATCH($A11,'18 KMP- Tháng'!$A$6:$A$24,0),MATCH(Y$7,'18 KMP- Tháng'!$R$2:$AC$2,0)) -> 3483.1443 | Z11: =INDEX('18 KMP- Tháng'!$R$6:$AC$24,MATCH($A11,'18 KMP- Tháng'!$A$6:$A$24,0),MATCH(Z$7,'18 KMP- Tháng'!$R$2:$AC$2,0)) -> 4629.7979 | AA11: =INDEX('18 KMP- Tháng'!$R$6:$AC$24,MATCH($A11,'18 KMP- Tháng'!$A$6:$A$24,0),MATCH(AA$7,'18 KMP- Tháng'!$R$2:$AC$2,0)) -> 5506.447 | AB11: =INDEX('18 KMP- Tháng'!$R$6:$AC$24,MATCH($A11,'18 KMP- Tháng'!$A$6:$A$24,0),MATCH(AB$7,'18 KMP- Tháng'!$R$2:$AC$2,0)) -> 6370.1385 | AC11: =INDEX('18 KMP- Tháng'!$R$6:$AC$24,MATCH($A11,'18 KMP- Tháng'!$A$6:$A$24,0),MATCH(AC$7,'18 KMP- Tháng'!$R$2:$AC$2,0)) -> 4868.7792 | AD11: =AVERAGE(R11:AC11) -> 4897.5619 | AE11: =INDEX('18 KMP- Tháng'!$AF$6:$AQ$29,MATCH($A11,'18 KMP- Tháng'!$A$6:$A$29,0),MATCH(AE$7,'18 KMP- Tháng'!$AF$2:$AQ$2,0)) -> 3129.9322 | AF11: =INDEX('18 KMP- Tháng'!$AF$6:$AQ$29,MATCH($A11,'18 KMP- Tháng'!$A$6:$A$29,0),MATCH(AF$7,'18 KMP- Tháng'!$AF$2:$AQ$2,0)) -> 4149.1147 | AG11: =INDEX('18 KMP- Tháng'!$AF$6:$AQ$29,MATCH($A11,'18 KMP- Tháng'!$A$6:$A$29,0),MATCH(AG$7,'18 KMP- Tháng'!$AF$2:$AQ$2,0)) -> 6492.4917 | AH11: =INDEX('18 KMP- Tháng'!$AF$6:$AQ$29,MATCH($A11,'18 KMP- Tháng'!$A$6:$A$29,0),MATCH(AH$7,'18 KMP- Tháng'!$AF$2:$AQ$2,0)) -> 6124.5742 | AI11: =INDEX('18 KMP- Tháng'!$AF$6:$AQ$29,MATCH($A11,'18 KMP- Tháng'!$A$6:$A$29,0),MATCH(AI$7,'18 KMP- Tháng'!$AF$2:$AQ$2,0)) -> 6554.5568 | AJ11: =INDEX('18 KMP- Tháng'!$AF$6:$AQ$29,MATCH($A11,'18 KMP- Tháng'!$A$6:$A$29,0),MATCH(AJ$7,'18 KMP- Tháng'!$AF$2:$AQ$2,0)) -> 6352.5089 | AK11: =INDEX('18 KMP- Tháng'!$AF$6:$AQ$29,MATCH($A11,'18 KMP- Tháng'!$A$6:$A$29,0),MATCH(AK$7,'18 KMP- Tháng'!$AF$2:$AQ$2,0)) -> 7055.0789 | AL11: =INDEX('18 KMP- Tháng'!$AF$6:$AQ$29,MATCH($A11,'18 KMP- Tháng'!$A$6:$A$29,0),MATCH(AL$7,'18 KMP- Tháng'!$AF$2:$AQ$2,0)) -> 7228.286 | ... AP11: =INDEX('18 KMP- Tháng'!$AF$6:$AQ$29,MATCH($A11,'18 KMP- Tháng'!$A$6:$A$29,0),MATCH(AP$7,'18 KMP- Tháng'!$AF$2:$AQ$2,0)) -> 4859.3911 | AQ11: =SUM(AE11:AP11)/COUNTIFS($AE$29:$AP$29,"<>"&0) -> 5786.8104 | AR11: =SUM(AE11:AP11) -> 69441.725 | AS11: =INDEX('18 KMP- Tháng'!$BH$6:$BS$29,MATCH($A11,'18 KMP- Tháng'!$A$6:$A$29,0),MATCH(AS$7,'18 KMP- Tháng'!$BH$2:$BS$2,0)) -> 4625.491 | AT11: =INDEX('18 KMP- Tháng'!$BH$6:$BS$29,MATCH($A11,'18 KMP- Tháng'!$A$6:$A$29,0),MATCH(AT$7,'18 KMP- Tháng'!$BH$2:$BS$2,0)) -> 3822.1486 | AU11: =INDEX('18 KMP- Tháng'!$BH$6:$BS$29,MATCH($A11,'18 KMP- Tháng'!$A$6:$A$29,0),MATCH(AU$7,'18 KMP- Tháng'!$BH$2:$BS$2,0)) -> 4770.531 | AV11: =INDEX('18 KMP- Tháng'!$BH$6:$BS$29,MATCH($A11,'18 KMP- Tháng'!$A$6:$A$29,0),MATCH(AV$7,'18 KMP- Tháng'!$BH$2:$BS$2,0)) -> 4814.412 | AW11: =INDEX('18 KMP- Tháng'!$BH$6:$BS$29,MATCH($A11,'18 KMP- Tháng'!$A$6:$A$29,0),MATCH(AW$7,'18 KMP- Tháng'!$BH$2:$BS$2,0)) -> 4778.7154 | AX11: =INDEX('18 KMP- Tháng'!$BH$6:$BS$29,MATCH($A11,'18 KMP- Tháng'!$A$6:$A$29,0),MATCH(AX$7,'18 KMP- Tháng'!$BH$2:$BS$2,0)) -> 4943.8433 | AY11: =INDEX('18 KMP- Tháng'!$BH$6:$BS$29,MATCH($A11,'18 KMP- Tháng'!$A$6:$A$29,0),MATCH(AY$7,'18 KMP- Tháng'!$BH$2:$BS$2,0)) -> 5284.2898 | AZ11: =INDEX('18 KMP- Tháng'!$BH$6:$BS$29,MATCH($A11,'18 KMP- Tháng'!$A$6:$A$29,0),MATCH(AZ$7,'18 KMP- Tháng'!$BH$2:$BS$2,0)) -> 5351.233 | ... BD11: =INDEX('18 KMP- Tháng'!$BH$6:$BS$29,MATCH($A11,'18 KMP- Tháng'!$A$6:$A$29,0),MATCH(BD$7,'18 KMP- Tháng'!$BH$2:$BS$2,0)) -> 5490.0689 | BE11: =AVERAGE(AS11:BD11) -> 5017.1449 | BF11: =INDEX('18 KMP- Tháng'!$AS$6:$BD$29,MATCH($A11,'18 KMP- Tháng'!$A$6:$A$29,0),MATCH(BF$7,'18 KMP- Tháng'!$AS$2:$BD$2,0)) -> 4042.8838 | BG11: =INDEX('18 KMP- Tháng'!$AS$6:$BD$29,MATCH($A11,'18 KMP- Tháng'!$A$6:$A$29,0),MATCH(BG$7,'18 KMP- Tháng'!$AS$2:$BD$2,0)) -> 2462.251 | BH11: =INDEX('18 KMP- Tháng'!$AS$6:$BD$29,MATCH($A11,'18 KMP- Tháng'!$A$6:$A$29,0),MATCH(BH$7,'18 KMP- Tháng'!$AS$2:$BD$2,0)) -> 5644.5231 | BI11: =INDEX('18 KMP- Tháng'!$AS$6:$BD$29,MATCH($A11,'18 KMP- Tháng'!$A$6:$A$29,0),MATCH(BI$7,'18 KMP- Tháng'!$AS$2:$BD$2,0)) -> 5669.3827 | BJ11: =INDEX('18 KMP- Tháng'!$AS$6:$BD$29,MATCH($A11,'18 KMP- Tháng'!$A$6:$A$29,0),MATCH(BJ$7,'18 KMP- Tháng'!$AS$2:$BD$2,0)) -> 5791.0108 | BK11: =INDEX('18 KMP- Tháng'!$AS$6:$BD$29,MATCH($A11,'18 KMP- Tháng'!$A$6:$A$29,0),MATCH(BK$7,'18 KMP- Tháng'!$AS$2:$BD$2,0)) -> 0 | BL11: =INDEX('18 KMP- Tháng'!$AS$6:$BD$29,MATCH($A11,'18 KMP- Tháng'!$A$6:$A$29,0),MATCH(BL$7,'18 KMP- Tháng'!$AS$2:$BD$2,0)) -> 0 | BM11: =INDEX('18 KMP- Tháng'!$AS$6:$BD$29,MATCH($A11,'18 KMP- Tháng'!$A$6:$A$29,0),MATCH(BM$7,'18 KMP- Tháng'!$AS$2:$BD$2,0)) -> 0 | ... BQ11: =INDEX('18 KMP- Tháng'!$AS$6:$BD$29,MATCH($A11,'18 KMP- Tháng'!$A$6:$A$29,0),MATCH(BQ$7,'18 KMP- Tháng'!$AS$2:$BD$2,0)) -> 0 | BR11: =SUM(BF11:BQ11)/COUNTIFS($BF$29:$BQ$29,"<>"&0) -> 4722.0103 | BS11: =SUM(BF11:BQ11) -> 23610.051 | BT11: =IFERROR(BF11/AS11-1,"-") -> -0.12595575 | BU11: =BS11/$BS$29 -> 0.051849006
A12: 6 | B12: =B11+1 -> 3 | C12: Biến phí | D12: Chi phí bán hàng | E12: =INDEX('18 KMP- Tháng'!$E$6:$Q$29,MATCH($A12,'18 KMP- Tháng'!$A$6:$A$29,0),MATCH(E$7,'18 KMP- Tháng'!$E$2:$P$2,0)) -> 0 | F12: =INDEX('18 KMP- Tháng'!$E$6:$Q$29,MATCH($A12,'18 KMP- Tháng'!$A$6:$A$29,0),MATCH(F$7,'18 KMP- Tháng'!$E$2:$P$2,0)) -> 0 | G12: =INDEX('18 KMP- Tháng'!$E$6:$Q$29,MATCH($A12,'18 KMP- Tháng'!$A$6:$A$29,0),MATCH(G$7,'18 KMP- Tháng'!$E$2:$P$2,0)) -> 505.50536 | H12: =INDEX('18 KMP- Tháng'!$E$6:$Q$29,MATCH($A12,'18 KMP- Tháng'!$A$6:$A$29,0),MATCH(H$7,'18 KMP- Tháng'!$E$2:$P$2,0)) -> 384.26619 | I12: =INDEX('18 KMP- Tháng'!$E$6:$Q$29,MATCH($A12,'18 KMP- Tháng'!$A$6:$A$29,0),MATCH(I$7,'18 KMP- Tháng'!$E$2:$P$2,0)) -> 373.59722 | J12: =INDEX('18 KMP- Tháng'!$E$6:$Q$29,MATCH($A12,'18 KMP- Tháng'!$A$6:$A$29,0),MATCH(J$7,'18 KMP- Tháng'!$E$2:$P$2,0)) -> 646.866 | K12: =INDEX('18 KMP- Tháng'!$E$6:$Q$29,MATCH($A12,'18 KMP- Tháng'!$A$6:$A$29,0),MATCH(K$7,'18 KMP- Tháng'!$E$2:$P$2,0)) -> 461.83938 | L12: =INDEX('18 KMP- Tháng'!$E$6:$Q$29,MATCH($A12,'18 KMP- Tháng'!$A$6:$A$29,0),MATCH(L$7,'18 KMP- Tháng'!$E$2:$P$2,0)) -> 712.82108 | ... P12: =INDEX('18 KMP- Tháng'!$E$6:$Q$29,MATCH($A12,'18 KMP- Tháng'!$A$6:$A$29,0),MATCH(P$7,'18 KMP- Tháng'!$E$2:$P$2,0)) -> 533.65458 | Q12: =AVERAGE(E12:P12) -> 446.99778 | R12: =INDEX('18 KMP- Tháng'!$R$6:$AC$24,MATCH($A12,'18 KMP- Tháng'!$A$6:$A$24,0),MATCH(R$7,'18 KMP- Tháng'!$R$2:$AC$2,0)) -> 10 | S12: =INDEX('18 KMP- Tháng'!$R$6:$AC$24,MATCH($A12,'18 KMP- Tháng'!$A$6:$A$24,0),MATCH(S$7,'18 KMP- Tháng'!$R$2:$AC$2,0)) -> 0 | T12: =INDEX('18 KMP- Tháng'!$R$6:$AC$24,MATCH($A12,'18 KMP- Tháng'!$A$6:$A$24,0),MATCH(T$7,'18 KMP- Tháng'!$R$2:$AC$2,0)) -> -5 | U12: =INDEX('18 KMP- Tháng'!$R$6:$AC$24,MATCH($A12,'18 KMP- Tháng'!$A$6:$A$24,0),MATCH(U$7,'18 KMP- Tháng'!$R$2:$AC$2,0)) -> 0 | V12: =INDEX('18 KMP- Tháng'!$R$6:$AC$24,MATCH($A12,'18 KMP- Tháng'!$A$6:$A$24,0),MATCH(V$7,'18 KMP- Tháng'!$R$2:$AC$2,0)) -> 32 | W12: =INDEX('18 KMP- Tháng'!$R$6:$AC$24,MATCH($A12,'18 KMP- Tháng'!$A$6:$A$24,0),MATCH(W$7,'18 KMP- Tháng'!$R$2:$AC$2,0)) -> 0 | X12: =INDEX('18 KMP- Tháng'!$R$6:$AC$24,MATCH($A12,'18 KMP- Tháng'!$A$6:$A$24,0),MATCH(X$7,'18 KMP- Tháng'!$R$2:$AC$2,0)) -> 0 | Y12: =INDEX('18 KMP- Tháng'!$R$6:$AC$24,MATCH($A12,'18 KMP- Tháng'!$A$6:$A$24,0),MATCH(Y$7,'18 KMP- Tháng'!$R$2:$AC$2,0)) -> 0 | ... AC12: =INDEX('18 KMP- Tháng'!$R$6:$AC$24,MATCH($A12,'18 KMP- Tháng'!$A$6:$A$24,0),MATCH(AC$7,'18 KMP- Tháng'!$R$2:$AC$2,0)) -> 0 | AD12: =AVERAGE(R12:AC12) -> 5.032258 | AE12: =INDEX('18 KMP- Tháng'!$AF$6:$AQ$29,MATCH($A12,'18 KMP- Tháng'!$A$6:$A$29,0),MATCH(AE$7,'18 KMP- Tháng'!$AF$2:$AQ$2,0)) -> 0 | AF12: =INDEX('18 KMP- Tháng'!$AF$6:$AQ$29,MATCH($A12,'18 KMP- Tháng'!$A$6:$A$29,0),MATCH(AF$7,'18 KMP- Tháng'!$AF$2:$AQ$2,0)) -> 0 | AG12: =INDEX('18 KMP- Tháng'!$AF$6:$AQ$29,MATCH($A12,'18 KMP- Tháng'!$A$6:$A$29,0),MATCH(AG$7,'18 KMP- Tháng'!$AF$2:$AQ$2,0)) -> 0 | AH12: =INDEX('18 KMP- Tháng'!$AF$6:$AQ$29,MATCH($A12,'18 KMP- Tháng'!$A$6:$A$29,0),MATCH(AH$7,'18 KMP- Tháng'!$AF$2:$AQ$2,0)) -> 0 | AI12: =INDEX('18 KMP- Tháng'!$AF$6:$AQ$29,MATCH($A12,'18 KMP- Tháng'!$A$6:$A$29,0),MATCH(AI$7,'18 KMP- Tháng'!$AF$2:$AQ$2,0)) -> 0 | AJ12: =INDEX('18 KMP- Tháng'!$AF$6:$AQ$29,MATCH($A12,'18 KMP- Tháng'!$A$6:$A$29,0),MATCH(AJ$7,'18 KMP- Tháng'!$AF$2:$AQ$2,0)) -> 0 | AK12: =INDEX('18 KMP- Tháng'!$AF$6:$AQ$29,MATCH($A12,'18 KMP- Tháng'!$A$6:$A$29,0),MATCH(AK$7,'18 KMP- Tháng'!$AF$2:$AQ$2,0)) -> 0 | AL12: =INDEX('18 KMP- Tháng'!$AF$6:$AQ$29,MATCH($A12,'18 KMP- Tháng'!$A$6:$A$29,0),MATCH(AL$7,'18 KMP- Tháng'!$AF$2:$AQ$2,0)) -> 0 | ... AP12: =INDEX('18 KMP- Tháng'!$AF$6:$AQ$29,MATCH($A12,'18 KMP- Tháng'!$A$6:$A$29,0),MATCH(AP$7,'18 KMP- Tháng'!$AF$2:$AQ$2,0)) -> 0 | AQ12: =SUM(AE12:AP12)/COUNTIFS($AE$29:$AP$29,"<>"&0) -> 0 | AR12: =SUM(AE12:AP12) -> 0 | AS12: =INDEX('18 KMP- Tháng'!$BH$6:$BS$29,MATCH($A12,'18 KMP- Tháng'!$A$6:$A$29,0),MATCH(AS$7,'18 KMP- Tháng'!$BH$2:$BS$2,0)) -> 0 | AT12: =INDEX('18 KMP- Tháng'!$BH$6:$BS$29,MATCH($A12,'18 KMP- Tháng'!$A$6:$A$29,0),MATCH(AT$7,'18 KMP- Tháng'!$BH$2:$BS$2,0)) -> 0 | AU12: =INDEX('18 KMP- Tháng'!$BH$6:$BS$29,MATCH($A12,'18 KMP- Tháng'!$A$6:$A$29,0),MATCH(AU$7,'18 KMP- Tháng'!$BH$2:$BS$2,0)) -> 0 | AV12: =INDEX('18 KMP- Tháng'!$BH$6:$BS$29,MATCH($A12,'18 KMP- Tháng'!$A$6:$A$29,0),MATCH(AV$7,'18 KMP- Tháng'!$BH$2:$BS$2,0)) -> 0 | AW12: =INDEX('18 KMP- Tháng'!$BH$6:$BS$29,MATCH($A12,'18 KMP- Tháng'!$A$6:$A$29,0),MATCH(AW$7,'18 KMP- Tháng'!$BH$2:$BS$2,0)) -> 0 | AX12: =INDEX('18 KMP- Tháng'!$BH$6:$BS$29,MATCH($A12,'18 KMP- Tháng'!$A$6:$A$29,0),MATCH(AX$7,'18 KMP- Tháng'!$BH$2:$BS$2,0)) -> 0 | AY12: =INDEX('18 KMP- Tháng'!$BH$6:$BS$29,MATCH($A12,'18 KMP- Tháng'!$A$6:$A$29,0),MATCH(AY$7,'18 KMP- Tháng'!$BH$2:$BS$2,0)) -> 0 | AZ12: =INDEX('18 KMP- Tháng'!$BH$6:$BS$29,MATCH($A12,'18 KMP- Tháng'!$A$6:$A$29,0),MATCH(AZ$7,'18 KMP- Tháng'!$BH$2:$BS$2,0)) -> 0 | ... BD12: =INDEX('18 KMP- Tháng'!$BH$6:$BS$29,MATCH($A12,'18 KMP- Tháng'!$A$6:$A$29,0),MATCH(BD$7,'18 KMP- Tháng'!$BH$2:$BS$2,0)) -> 0 | BE12: =AVERAGE(AS12:BD12) -> 0 | BF12: =INDEX('18 KMP- Tháng'!$AS$6:$BD$29,MATCH($A12,'18 KMP- Tháng'!$A$6:$A$29,0),MATCH(BF$7,'18 KMP- Tháng'!$AS$2:$BD$2,0)) -> 0 | BG12: =INDEX('18 KMP- Tháng'!$AS$6:$BD$29,MATCH($A12,'18 KMP- Tháng'!$A$6:$A$29,0),MATCH(BG$7,'18 KMP- Tháng'!$AS$2:$BD$2,0)) -> 0 | BH12: =INDEX('18 KMP- Tháng'!$AS$6:$BD$29,MATCH($A12,'18 KMP- Tháng'!$A$6:$A$29,0),MATCH(BH$7,'18 KMP- Tháng'!$AS$2:$BD$2,0)) -> 0 | BI12: =INDEX('18 KMP- Tháng'!$AS$6:$BD$29,MATCH($A12,'18 KMP- Tháng'!$A$6:$A$29,0),MATCH(BI$7,'18 KMP- Tháng'!$AS$2:$BD$2,0)) -> 0 | BJ12: =INDEX('18 KMP- Tháng'!$AS$6:$BD$29,MATCH($A12,'18 KMP- Tháng'!$A$6:$A$29,0),MATCH(BJ$7,'18 KMP- Tháng'!$AS$2:$BD$2,0)) -> 0 | BK12: =INDEX('18 KMP- Tháng'!$AS$6:$BD$29,MATCH($A12,'18 KMP- Tháng'!$A$6:$A$29,0),MATCH(BK$7,'18 KMP- Tháng'!$AS$2:$BD$2,0)) -> 0 | BL12: =INDEX('18 KMP- Tháng'!$AS$6:$BD$29,MATCH($A12,'18 KMP- Tháng'!$A$6:$A$29,0),MATCH(BL$7,'18 KMP- Tháng'!$AS$2:$BD$2,0)) -> 0 | BM12: =INDEX('18 KMP- Tháng'!$AS$6:$BD$29,MATCH($A12,'18 KMP- Tháng'!$A$6:$A$29,0),MATCH(BM$7,'18 KMP- Tháng'!$AS$2:$BD$2,0)) -> 0 | ... BQ12: =INDEX('18 KMP- Tháng'!$AS$6:$BD$29,MATCH($A12,'18 KMP- Tháng'!$A$6:$A$29,0),MATCH(BQ$7,'18 KMP- Tháng'!$AS$2:$BD$2,0)) -> 0 | BR12: =SUM(BF12:BQ12)/COUNTIFS($BF$29:$BQ$29,"<>"&0) -> 0 | BS12: =SUM(BF12:BQ12) -> 0 | BT12: =IFERROR(BF12/AS12-1,"-") -> - | BU12: =BS12/$BS$29 -> 0
A13: 7 | B13: =B12+1 -> 4 | C13: Biến phí | D13: Phụ gia theo Bom | E13: =INDEX('18 KMP- Tháng'!$E$6:$Q$29,MATCH($A13,'18 KMP- Tháng'!$A$6:$A$29,0),MATCH(E$7,'18 KMP- Tháng'!$E$2:$P$2,0)) -> 67.509566 | F13: =INDEX('18 KMP- Tháng'!$E$6:$Q$29,MATCH($A13,'18 KMP- Tháng'!$A$6:$A$29,0),MATCH(F$7,'18 KMP- Tháng'!$E$2:$P$2,0)) -> 146.57459 | G13: =INDEX('18 KMP- Tháng'!$E$6:$Q$29,MATCH($A13,'18 KMP- Tháng'!$A$6:$A$29,0),MATCH(G$7,'18 KMP- Tháng'!$E$2:$P$2,0)) -> 512.58851 | H13: =INDEX('18 KMP- Tháng'!$E$6:$Q$29,MATCH($A13,'18 KMP- Tháng'!$A$6:$A$29,0),MATCH(H$7,'18 KMP- Tháng'!$E$2:$P$2,0)) -> 669.23911 | I13: =INDEX('18 KMP- Tháng'!$E$6:$Q$29,MATCH($A13,'18 KMP- Tháng'!$A$6:$A$29,0),MATCH(I$7,'18 KMP- Tháng'!$E$2:$P$2,0)) -> 986.13165 | J13: =INDEX('18 KMP- Tháng'!$E$6:$Q$29,MATCH($A13,'18 KMP- Tháng'!$A$6:$A$29,0),MATCH(J$7,'18 KMP- Tháng'!$E$2:$P$2,0)) -> 456.94688 | K13: =INDEX('18 KMP- Tháng'!$E$6:$Q$29,MATCH($A13,'18 KMP- Tháng'!$A$6:$A$29,0),MATCH(K$7,'18 KMP- Tháng'!$E$2:$P$2,0)) -> 1054.6791 | L13: =INDEX('18 KMP- Tháng'!$E$6:$Q$29,MATCH($A13,'18 KMP- Tháng'!$A$6:$A$29,0),MATCH(L$7,'18 KMP- Tháng'!$E$2:$P$2,0)) -> 1179.6289 | ... P13: =INDEX('18 KMP- Tháng'!$E$6:$Q$29,MATCH($A13,'18 KMP- Tháng'!$A$6:$A$29,0),MATCH(P$7,'18 KMP- Tháng'!$E$2:$P$2,0)) -> 2043.1246 | Q13: =AVERAGE(E13:P13) -> 966.8118 | R13: =INDEX('18 KMP- Tháng'!$R$6:$AC$24,MATCH($A13,'18 KMP- Tháng'!$A$6:$A$24,0),MATCH(R$7,'18 KMP- Tháng'!$R$2:$AC$2,0)) -> 1729.6175 | S13: =INDEX('18 KMP- Tháng'!$R$6:$AC$24,MATCH($A13,'18 KMP- Tháng'!$A$6:$A$24,0),MATCH(S$7,'18 KMP- Tháng'!$R$2:$AC$2,0)) -> 1517.4507 | T13: =INDEX('18 KMP- Tháng'!$R$6:$AC$24,MATCH($A13,'18 KMP- Tháng'!$A$6:$A$24,0),MATCH(T$7,'18 KMP- Tháng'!$R$2:$AC$2,0)) -> 1767.7928 | U13: =INDEX('18 KMP- Tháng'!$R$6:$AC$24,MATCH($A13,'18 KMP- Tháng'!$A$6:$A$24,0),MATCH(U$7,'18 KMP- Tháng'!$R$2:$AC$2,0)) -> 1045.853 | V13: =INDEX('18 KMP- Tháng'!$R$6:$AC$24,MATCH($A13,'18 KMP- Tháng'!$A$6:$A$24,0),MATCH(V$7,'18 KMP- Tháng'!$R$2:$AC$2,0)) -> 972.02423 | W13: =INDEX('18 KMP- Tháng'!$R$6:$AC$24,MATCH($A13,'18 KMP- Tháng'!$A$6:$A$24,0),MATCH(W$7,'18 KMP- Tháng'!$R$2:$AC$2,0)) -> 591.19552 | X13: =INDEX('18 KMP- Tháng'!$R$6:$AC$24,MATCH($A13,'18 KMP- Tháng'!$A$6:$A$24,0),MATCH(X$7,'18 KMP- Tháng'!$R$2:$AC$2,0)) -> 1077.2919 | Y13: =INDEX('18 KMP- Tháng'!$R$6:$AC$24,MATCH($A13,'18 KMP- Tháng'!$A$6:$A$24,0),MATCH(Y$7,'18 KMP- Tháng'!$R$2:$AC$2,0)) -> 549.30052 | ... AC13: =INDEX('18 KMP- Tháng'!$R$6:$AC$24,MATCH($A13,'18 KMP- Tháng'!$A$6:$A$24,0),MATCH(AC$7,'18 KMP- Tháng'!$R$2:$AC$2,0)) -> 321.65228 | AD13: =AVERAGE(R13:AC13) -> 1188.1878 | AE13: =INDEX('18 KMP- Tháng'!$AF$6:$AQ$29,MATCH($A13,'18 KMP- Tháng'!$A$6:$A$29,0),MATCH(AE$7,'18 KMP- Tháng'!$AF$2:$AQ$2,0)) -> 333.0016 | AF13: =INDEX('18 KMP- Tháng'!$AF$6:$AQ$29,MATCH($A13,'18 KMP- Tháng'!$A$6:$A$29,0),MATCH(AF$7,'18 KMP- Tháng'!$AF$2:$AQ$2,0)) -> 880.94691 | AG13: =INDEX('18 KMP- Tháng'!$AF$6:$AQ$29,MATCH($A13,'18 KMP- Tháng'!$A$6:$A$29,0),MATCH(AG$7,'18 KMP- Tháng'!$AF$2:$AQ$2,0)) -> 1570.4421 | AH13: =INDEX('18 KMP- Tháng'!$AF$6:$AQ$29,MATCH($A13,'18 KMP- Tháng'!$A$6:$A$29,0),MATCH(AH$7,'18 KMP- Tháng'!$AF$2:$AQ$2,0)) -> 1637.6224 | AI13: =INDEX('18 KMP- Tháng'!$AF$6:$AQ$29,MATCH($A13,'18 KMP- Tháng'!$A$6:$A$29,0),MATCH(AI$7,'18 KMP- Tháng'!$AF$2:$AQ$2,0)) -> 1960.9722 | AJ13: =INDEX('18 KMP- Tháng'!$AF$6:$AQ$29,MATCH($A13,'18 KMP- Tháng'!$A$6:$A$29,0),MATCH(AJ$7,'18 KMP- Tháng'!$AF$2:$AQ$2,0)) -> 1965.8737 | AK13: =INDEX('18 KMP- Tháng'!$AF$6:$AQ$29,MATCH($A13,'18 KMP- Tháng'!$A$6:$A$29,0),MATCH(AK$7,'18 KMP- Tháng'!$AF$2:$AQ$2,0)) -> 2547.1121 | AL13: =INDEX('18 KMP- Tháng'!$AF$6:$AQ$29,MATCH($A13,'18 KMP- Tháng'!$A$6:$A$29,0),MATCH(AL$7,'18 KMP- Tháng'!$AF$2:$AQ$2,0)) -> 2288.5134 | ... AP13: =INDEX('18 KMP- Tháng'!$AF$6:$AQ$29,MATCH($A13,'18 KMP- Tháng'!$A$6:$A$29,0),MATCH(AP$7,'18 KMP- Tháng'!$AF$2:$AQ$2,0)) -> 1143.2731 | AQ13: =SUM(AE13:AP13)/COUNTIFS($AE$29:$AP$29,"<>"&0) -> 1457.5195 | AR13: =SUM(AE13:AP13) -> 17490.234 | AS13: =INDEX('18 KMP- Tháng'!$BH$6:$BS$29,MATCH($A13,'18 KMP- Tháng'!$A$6:$A$29,0),MATCH(AS$7,'18 KMP- Tháng'!$BH$2:$BS$2,0)) -> 1261.1159 | AT13: =INDEX('18 KMP- Tháng'!$BH$6:$BS$29,MATCH($A13,'18 KMP- Tháng'!$A$6:$A$29,0),MATCH(AT$7,'18 KMP- Tháng'!$BH$2:$BS$2,0)) -> 1061.7856 | AU13: =INDEX('18 KMP- Tháng'!$BH$6:$BS$29,MATCH($A13,'18 KMP- Tháng'!$A$6:$A$29,0),MATCH(AU$7,'18 KMP- Tháng'!$BH$2:$BS$2,0)) -> 1335.6927 | AV13: =INDEX('18 KMP- Tháng'!$BH$6:$BS$29,MATCH($A13,'18 KMP- Tháng'!$A$6:$A$29,0),MATCH(AV$7,'18 KMP- Tháng'!$BH$2:$BS$2,0)) -> 1335.6927 | AW13: =INDEX('18 KMP- Tháng'!$BH$6:$BS$29,MATCH($A13,'18 KMP- Tháng'!$A$6:$A$29,0),MATCH(AW$7,'18 KMP- Tháng'!$BH$2:$BS$2,0)) -> 1335.6927 | AX13: =INDEX('18 KMP- Tháng'!$BH$6:$BS$29,MATCH($A13,'18 KMP- Tháng'!$A$6:$A$29,0),MATCH(AX$7,'18 KMP- Tháng'!$BH$2:$BS$2,0)) -> 1367.5559 | AY13: =INDEX('18 KMP- Tháng'!$BH$6:$BS$29,MATCH($A13,'18 KMP- Tháng'!$A$6:$A$29,0),MATCH(AY$7,'18 KMP- Tháng'!$BH$2:$BS$2,0)) -> 1380.1001 | AZ13: =INDEX('18 KMP- Tháng'!$BH$6:$BS$29,MATCH($A13,'18 KMP- Tháng'!$A$6:$A$29,0),MATCH(AZ$7,'18 KMP- Tháng'!$BH$2:$BS$2,0)) -> 1411.9633 | ... BD13: =INDEX('18 KMP- Tháng'!$BH$6:$BS$29,MATCH($A13,'18 KMP- Tháng'!$A$6:$A$29,0),MATCH(BD$7,'18 KMP- Tháng'!$BH$2:$BS$2,0)) -> 1411.9633 | BE13: =AVERAGE(AS13:BD13) -> 1339.4771 | BF13: =INDEX('18 KMP- Tháng'!$AS$6:$BD$29,MATCH($A13,'18 KMP- Tháng'!$A$6:$A$29,0),MATCH(BF$7,'18 KMP- Tháng'!$AS$2:$BD$2,0)) -> 891.17734 | BG13: =INDEX('18 KMP- Tháng'!$AS$6:$BD$29,MATCH($A13,'18 KMP- Tháng'!$A$6:$A$29,0),MATCH(BG$7,'18 KMP- Tháng'!$AS$2:$BD$2,0)) -> 288.5613 | BH13: =INDEX('18 KMP- Tháng'!$AS$6:$BD$29,MATCH($A13,'18 KMP- Tháng'!$A$6:$A$29,0),MATCH(BH$7,'18 KMP- Tháng'!$AS$2:$BD$2,0)) -> 1763.3356 | BI13: =INDEX('18 KMP- Tháng'!$AS$6:$BD$29,MATCH($A13,'18 KMP- Tháng'!$A$6:$A$29,0),MATCH(BI$7,'18 KMP- Tháng'!$AS$2:$BD$2,0)) -> 1386.5964 | BJ13: =INDEX('18 KMP- Tháng'!$AS$6:$BD$29,MATCH($A13,'18 KMP- Tháng'!$A$6:$A$29,0),MATCH(BJ$7,'18 KMP- Tháng'!$AS$2:$BD$2,0)) -> 1815.0415 | BK13: =INDEX('18 KMP- Tháng'!$AS$6:$BD$29,MATCH($A13,'18 KMP- Tháng'!$A$6:$A$29,0),MATCH(BK$7,'18 KMP- Tháng'!$AS$2:$BD$2,0)) -> 0 | BL13: =INDEX('18 KMP- Tháng'!$AS$6:$BD$29,MATCH($A13,'18 KMP- Tháng'!$A$6:$A$29,0),MATCH(BL$7,'18 KMP- Tháng'!$AS$2:$BD$2,0)) -> 0 | BM13: =INDEX('18 KMP- Tháng'!$AS$6:$BD$29,MATCH($A13,'18 KMP- Tháng'!$A$6:$A$29,0),MATCH(BM$7,'18 KMP- Tháng'!$AS$2:$BD$2,0)) -> 0 | ... BQ13: =INDEX('18 KMP- Tháng'!$AS$6:$BD$29,MATCH($A13,'18 KMP- Tháng'!$A$6:$A$29,0),MATCH(BQ$7,'18 KMP- Tháng'!$AS$2:$BD$2,0)) -> 0 | BR13: =SUM(BF13:BQ13)/COUNTIFS($BF$29:$BQ$29,"<>"&0) -> 1228.9424 | BS13: =SUM(BF13:BQ13) -> 6144.712 | BT13: =IFERROR(BF13/AS13-1,"-") -> -0.29334225 | BU13: =BS13/$BS$29 -> 0.013494135
A14: 8 | B14: =B13+1 -> 5 | C14: Biến phí | D14: Vật liệu phục vụ SX | E14: =INDEX('18 KMP- Tháng'!$E$6:$Q$29,MATCH($A14,'18 KMP- Tháng'!$A$6:$A$29,0),MATCH(E$7,'18 KMP- Tháng'!$E$2:$P$2,0)) -> 506.18997 | F14: =INDEX('18 KMP- Tháng'!$E$6:$Q$29,MATCH($A14,'18 KMP- Tháng'!$A$6:$A$29,0),MATCH(F$7,'18 KMP- Tháng'!$E$2:$P$2,0)) -> 672.82796 | G14: =INDEX('18 KMP- Tháng'!$E$6:$Q$29,MATCH($A14,'18 KMP- Tháng'!$A$6:$A$29,0),MATCH(G$7,'18 KMP- Tháng'!$E$2:$P$2,0)) -> 560.09279 | H14: =INDEX('18 KMP- Tháng'!$E$6:$Q$29,MATCH($A14,'18 KMP- Tháng'!$A$6:$A$29,0),MATCH(H$7,'18 KMP- Tháng'!$E$2:$P$2,0)) -> 560.44612 | I14: =INDEX('18 KMP- Tháng'!$E$6:$Q$29,MATCH($A14,'18 KMP- Tháng'!$A$6:$A$29,0),MATCH(I$7,'18 KMP- Tháng'!$E$2:$P$2,0)) -> 799.14081 | J14: =INDEX('18 KMP- Tháng'!$E$6:$Q$29,MATCH($A14,'18 KMP- Tháng'!$A$6:$A$29,0),MATCH(J$7,'18 KMP- Tháng'!$E$2:$P$2,0)) -> 873.28511 | K14: =INDEX('18 KMP- Tháng'!$E$6:$Q$29,MATCH($A14,'18 KMP- Tháng'!$A$6:$A$29,0),MATCH(K$7,'18 KMP- Tháng'!$E$2:$P$2,0)) -> 761.83256 | L14: =INDEX('18 KMP- Tháng'!$E$6:$Q$29,MATCH($A14,'18 KMP- Tháng'!$A$6:$A$29,0),MATCH(L$7,'18 KMP- Tháng'!$E$2:$P$2,0)) -> 645.47634 | ... P14: =INDEX('18 KMP- Tháng'!$E$6:$Q$29,MATCH($A14,'18 KMP- Tháng'!$A$6:$A$29,0),MATCH(P$7,'18 KMP- Tháng'!$E$2:$P$2,0)) -> 659.73067 | Q14: =AVERAGE(E14:P14) -> 613.60756 | R14: =INDEX('18 KMP- Tháng'!$R$6:$AC$24,MATCH($A14,'18 KMP- Tháng'!$A$6:$A$24,0),MATCH(R$7,'18 KMP- Tháng'!$R$2:$AC$2,0)) -> 1024.1533 | S14: =INDEX('18 KMP- Tháng'!$R$6:$AC$24,MATCH($A14,'18 KMP- Tháng'!$A$6:$A$24,0),MATCH(S$7,'18 KMP- Tháng'!$R$2:$AC$2,0)) -> 494.67675 | T14: =INDEX('18 KMP- Tháng'!$R$6:$AC$24,MATCH($A14,'18 KMP- Tháng'!$A$6:$A$24,0),MATCH(T$7,'18 KMP- Tháng'!$R$2:$AC$2,0)) -> 832.50089 | U14: =INDEX('18 KMP- Tháng'!$R$6:$AC$24,MATCH($A14,'18 KMP- Tháng'!$A$6:$A$24,0),MATCH(U$7,'18 KMP- Tháng'!$R$2:$AC$2,0)) -> 1314.4848 | V14: =INDEX('18 KMP- Tháng'!$R$6:$AC$24,MATCH($A14,'18 KMP- Tháng'!$A$6:$A$24,0),MATCH(V$7,'18 KMP- Tháng'!$R$2:$AC$2,0)) -> 883.52531 | W14: =INDEX('18 KMP- Tháng'!$R$6:$AC$24,MATCH($A14,'18 KMP- Tháng'!$A$6:$A$24,0),MATCH(W$7,'18 KMP- Tháng'!$R$2:$AC$2,0)) -> 901.03992 | X14: =INDEX('18 KMP- Tháng'!$R$6:$AC$24,MATCH($A14,'18 KMP- Tháng'!$A$6:$A$24,0),MATCH(X$7,'18 KMP- Tháng'!$R$2:$AC$2,0)) -> 420.23725 | Y14: =INDEX('18 KMP- Tháng'!$R$6:$AC$24,MATCH($A14,'18 KMP- Tháng'!$A$6:$A$24,0),MATCH(Y$7,'18 KMP- Tháng'!$R$2:$AC$2,0)) -> 546.30616 | ... AC14: =INDEX('18 KMP- Tháng'!$R$6:$AC$24,MATCH($A14,'18 KMP- Tháng'!$A$6:$A$24,0),MATCH(AC$7,'18 KMP- Tháng'!$R$2:$AC$2,0)) -> 606.28838 | AD14: =AVERAGE(R14:AC14) -> 715.36335 | AE14: =INDEX('18 KMP- Tháng'!$AF$6:$AQ$29,MATCH($A14,'18 KMP- Tháng'!$A$6:$A$29,0),MATCH(AE$7,'18 KMP- Tháng'!$AF$2:$AQ$2,0)) -> 605.82139 | AF14: =INDEX('18 KMP- Tháng'!$AF$6:$AQ$29,MATCH($A14,'18 KMP- Tháng'!$A$6:$A$29,0),MATCH(AF$7,'18 KMP- Tháng'!$AF$2:$AQ$2,0)) -> 632.16747 | AG14: =INDEX('18 KMP- Tháng'!$AF$6:$AQ$29,MATCH($A14,'18 KMP- Tháng'!$A$6:$A$29,0),MATCH(AG$7,'18 KMP- Tháng'!$AF$2:$AQ$2,0)) -> 631.30053 | AH14: =INDEX('18 KMP- Tháng'!$AF$6:$AQ$29,MATCH($A14,'18 KMP- Tháng'!$A$6:$A$29,0),MATCH(AH$7,'18 KMP- Tháng'!$AF$2:$AQ$2,0)) -> 952.50042 | AI14: =INDEX('18 KMP- Tháng'!$AF$6:$AQ$29,MATCH($A14,'18 KMP- Tháng'!$A$6:$A$29,0),MATCH(AI$7,'18 KMP- Tháng'!$AF$2:$AQ$2,0)) -> 688.62718 | AJ14: =INDEX('18 KMP- Tháng'!$AF$6:$AQ$29,MATCH($A14,'18 KMP- Tháng'!$A$6:$A$29,0),MATCH(AJ$7,'18 KMP- Tháng'!$AF$2:$AQ$2,0)) -> 708.02669 | AK14: =INDEX('18 KMP- Tháng'!$AF$6:$AQ$29,MATCH($A14,'18 KMP- Tháng'!$A$6:$A$29,0),MATCH(AK$7,'18 KMP- Tháng'!$AF$2:$AQ$2,0)) -> 711.72475 | AL14: =INDEX('18 KMP- Tháng'!$AF$6:$AQ$29,MATCH($A14,'18 KMP- Tháng'!$A$6:$A$29,0),MATCH(AL$7,'18 KMP- Tháng'!$AF$2:$AQ$2,0)) -> 825.34859 | ... AP14: =INDEX('18 KMP- Tháng'!$AF$6:$AQ$29,MATCH($A14,'18 KMP- Tháng'!$A$6:$A$29,0),MATCH(AP$7,'18 KMP- Tháng'!$AF$2:$AQ$2,0)) -> 605.37268 | AQ14: =SUM(AE14:AP14)/COUNTIFS($AE$29:$AP$29,"<>"&0) -> 682.17334 | AR14: =SUM(AE14:AP14) -> 8186.0801 | AS14: =INDEX('18 KMP- Tháng'!$BH$6:$BS$29,MATCH($A14,'18 KMP- Tháng'!$A$6:$A$29,0),MATCH(AS$7,'18 KMP- Tháng'!$BH$2:$BS$2,0)) -> 830.57138 | AT14: =INDEX('18 KMP- Tháng'!$BH$6:$BS$29,MATCH($A14,'18 KMP- Tháng'!$A$6:$A$29,0),MATCH(AT$7,'18 KMP- Tháng'!$BH$2:$BS$2,0)) -> 821.44441 | AU14: =INDEX('18 KMP- Tháng'!$BH$6:$BS$29,MATCH($A14,'18 KMP- Tháng'!$A$6:$A$29,0),MATCH(AU$7,'18 KMP- Tháng'!$BH$2:$BS$2,0)) -> 888.06936 | AV14: =INDEX('18 KMP- Tháng'!$BH$6:$BS$29,MATCH($A14,'18 KMP- Tháng'!$A$6:$A$29,0),MATCH(AV$7,'18 KMP- Tháng'!$BH$2:$BS$2,0)) -> 885.34368 | AW14: =INDEX('18 KMP- Tháng'!$BH$6:$BS$29,MATCH($A14,'18 KMP- Tháng'!$A$6:$A$29,0),MATCH(AW$7,'18 KMP- Tháng'!$BH$2:$BS$2,0)) -> 869.69543 | AX14: =INDEX('18 KMP- Tháng'!$BH$6:$BS$29,MATCH($A14,'18 KMP- Tháng'!$A$6:$A$29,0),MATCH(AX$7,'18 KMP- Tháng'!$BH$2:$BS$2,0)) -> 895.74545 | AY14: =INDEX('18 KMP- Tháng'!$BH$6:$BS$29,MATCH($A14,'18 KMP- Tháng'!$A$6:$A$29,0),MATCH(AY$7,'18 KMP- Tháng'!$BH$2:$BS$2,0)) -> 884.57374 | AZ14: =INDEX('18 KMP- Tháng'!$BH$6:$BS$29,MATCH($A14,'18 KMP- Tháng'!$A$6:$A$29,0),MATCH(AZ$7,'18 KMP- Tháng'!$BH$2:$BS$2,0)) -> 863.51318 | ... BD14: =INDEX('18 KMP- Tháng'!$BH$6:$BS$29,MATCH($A14,'18 KMP- Tháng'!$A$6:$A$29,0),MATCH(BD$7,'18 KMP- Tháng'!$BH$2:$BS$2,0)) -> 862.72621 | BE14: =AVERAGE(AS14:BD14) -> 873.5228 | BF14: =INDEX('18 KMP- Tháng'!$AS$6:$BD$29,MATCH($A14,'18 KMP- Tháng'!$A$6:$A$29,0),MATCH(BF$7,'18 KMP- Tháng'!$AS$2:$BD$2,0)) -> 716.76955 | BG14: =INDEX('18 KMP- Tháng'!$AS$6:$BD$29,MATCH($A14,'18 KMP- Tháng'!$A$6:$A$29,0),MATCH(BG$7,'18 KMP- Tháng'!$AS$2:$BD$2,0)) -> 416.00508 | BH14: =INDEX('18 KMP- Tháng'!$AS$6:$BD$29,MATCH($A14,'18 KMP- Tháng'!$A$6:$A$29,0),MATCH(BH$7,'18 KMP- Tháng'!$AS$2:$BD$2,0)) -> 995.70252 | BI14: =INDEX('18 KMP- Tháng'!$AS$6:$BD$29,MATCH($A14,'18 KMP- Tháng'!$A$6:$A$29,0),MATCH(BI$7,'18 KMP- Tháng'!$AS$2:$BD$2,0)) -> 756.27039 | BJ14: =INDEX('18 KMP- Tháng'!$AS$6:$BD$29,MATCH($A14,'18 KMP- Tháng'!$A$6:$A$29,0),MATCH(BJ$7,'18 KMP- Tháng'!$AS$2:$BD$2,0)) -> 660.65853 | BK14: =INDEX('18 KMP- Tháng'!$AS$6:$BD$29,MATCH($A14,'18 KMP- Tháng'!$A$6:$A$29,0),MATCH(BK$7,'18 KMP- Tháng'!$AS$2:$BD$2,0)) -> 0 | BL14: =INDEX('18 KMP- Tháng'!$AS$6:$BD$29,MATCH($A14,'18 KMP- Tháng'!$A$6:$A$29,0),MATCH(BL$7,'18 KMP- Tháng'!$AS$2:$BD$2,0)) -> 0 | BM14: =INDEX('18 KMP- Tháng'!$AS$6:$BD$29,MATCH($A14,'18 KMP- Tháng'!$A$6:$A$29,0),MATCH(BM$7,'18 KMP- Tháng'!$AS$2:$BD$2,0)) -> 0 | ... BQ14: =INDEX('18 KMP- Tháng'!$AS$6:$BD$29,MATCH($A14,'18 KMP- Tháng'!$A$6:$A$29,0),MATCH(BQ$7,'18 KMP- Tháng'!$AS$2:$BD$2,0)) -> 0 | BR14: =SUM(BF14:BQ14)/COUNTIFS($BF$29:$BQ$29,"<>"&0) -> 709.08121 | BS14: =SUM(BF14:BQ14) -> 3545.4061 | BT14: =IFERROR(BF14/AS14-1,"-") -> -0.13701632 | BU14: =BS14/$BS$29 -> 0.0077859119
A15: 9 | B15: =B14+1 -> 6 | C15: Biến phí | D15: Bao bì theo Bom | E15: =INDEX('18 KMP- Tháng'!$E$6:$Q$29,MATCH($A15,'18 KMP- Tháng'!$A$6:$A$29,0),MATCH(E$7,'18 KMP- Tháng'!$E$2:$P$2,0)) -> 152.05215 | F15: =INDEX('18 KMP- Tháng'!$E$6:$Q$29,MATCH($A15,'18 KMP- Tháng'!$A$6:$A$29,0),MATCH(F$7,'18 KMP- Tháng'!$E$2:$P$2,0)) -> 295.56509 | G15: =INDEX('18 KMP- Tháng'!$E$6:$Q$29,MATCH($A15,'18 KMP- Tháng'!$A$6:$A$29,0),MATCH(G$7,'18 KMP- Tháng'!$E$2:$P$2,0)) -> 305.73982 | H15: =INDEX('18 KMP- Tháng'!$E$6:$Q$29,MATCH($A15,'18 KMP- Tháng'!$A$6:$A$29,0),MATCH(H$7,'18 KMP- Tháng'!$E$2:$P$2,0)) -> 277.99662 | I15: =INDEX('18 KMP- Tháng'!$E$6:$Q$29,MATCH($A15,'18 KMP- Tháng'!$A$6:$A$29,0),MATCH(I$7,'18 KMP- Tháng'!$E$2:$P$2,0)) -> 375.61648 | J15: =INDEX('18 KMP- Tháng'!$E$6:$Q$29,MATCH($A15,'18 KMP- Tháng'!$A$6:$A$29,0),MATCH(J$7,'18 KMP- Tháng'!$E$2:$P$2,0)) -> 369.88612 | K15: =INDEX('18 KMP- Tháng'!$E$6:$Q$29,MATCH($A15,'18 KMP- Tháng'!$A$6:$A$29,0),MATCH(K$7,'18 KMP- Tháng'!$E$2:$P$2,0)) -> 387.17142 | L15: =INDEX('18 KMP- Tháng'!$E$6:$Q$29,MATCH($A15,'18 KMP- Tháng'!$A$6:$A$29,0),MATCH(L$7,'18 KMP- Tháng'!$E$2:$P$2,0)) -> 391.41398 | ... P15: =INDEX('18 KMP- Tháng'!$E$6:$Q$29,MATCH($A15,'18 KMP- Tháng'!$A$6:$A$29,0),MATCH(P$7,'18 KMP- Tháng'!$E$2:$P$2,0)) -> 684.97182 | Q15: =AVERAGE(E15:P15) -> 363.45366 | R15: =INDEX('18 KMP- Tháng'!$R$6:$AC$24,MATCH($A15,'18 KMP- Tháng'!$A$6:$A$24,0),MATCH(R$7,'18 KMP- Tháng'!$R$2:$AC$2,0)) -> 914.03018 | S15: =INDEX('18 KMP- Tháng'!$R$6:$AC$24,MATCH($A15,'18 KMP- Tháng'!$A$6:$A$24,0),MATCH(S$7,'18 KMP- Tháng'!$R$2:$AC$2,0)) -> 427.32569 | T15: =INDEX('18 KMP- Tháng'!$R$6:$AC$24,MATCH($A15,'18 KMP- Tháng'!$A$6:$A$24,0),MATCH(T$7,'18 KMP- Tháng'!$R$2:$AC$2,0)) -> 761.12916 | U15: =INDEX('18 KMP- Tháng'!$R$6:$AC$24,MATCH($A15,'18 KMP- Tháng'!$A$6:$A$24,0),MATCH(U$7,'18 KMP- Tháng'!$R$2:$AC$2,0)) -> 676.13009 | V15: =INDEX('18 KMP- Tháng'!$R$6:$AC$24,MATCH($A15,'18 KMP- Tháng'!$A$6:$A$24,0),MATCH(V$7,'18 KMP- Tháng'!$R$2:$AC$2,0)) -> 693.03545 | W15: =INDEX('18 KMP- Tháng'!$R$6:$AC$24,MATCH($A15,'18 KMP- Tháng'!$A$6:$A$24,0),MATCH(W$7,'18 KMP- Tháng'!$R$2:$AC$2,0)) -> 782.9713 | X15: =INDEX('18 KMP- Tháng'!$R$6:$AC$24,MATCH($A15,'18 KMP- Tháng'!$A$6:$A$24,0),MATCH(X$7,'18 KMP- Tháng'!$R$2:$AC$2,0)) -> 321.45074 | Y15: =INDEX('18 KMP- Tháng'!$R$6:$AC$24,MATCH($A15,'18 KMP- Tháng'!$A$6:$A$24,0),MATCH(Y$7,'18 KMP- Tháng'!$R$2:$AC$2,0)) -> 361.48229 | ... AC15: =INDEX('18 KMP- Tháng'!$R$6:$AC$24,MATCH($A15,'18 KMP- Tháng'!$A$6:$A$24,0),MATCH(AC$7,'18 KMP- Tháng'!$R$2:$AC$2,0)) -> 612.23484 | AD15: =AVERAGE(R15:AC15) -> 633.15965 | AE15: =INDEX('18 KMP- Tháng'!$AF$6:$AQ$29,MATCH($A15,'18 KMP- Tháng'!$A$6:$A$29,0),MATCH(AE$7,'18 KMP- Tháng'!$AF$2:$AQ$2,0)) -> 300.54102 | AF15: =INDEX('18 KMP- Tháng'!$AF$6:$AQ$29,MATCH($A15,'18 KMP- Tháng'!$A$6:$A$29,0),MATCH(AF$7,'18 KMP- Tháng'!$AF$2:$AQ$2,0)) -> 507.62119 | AG15: =INDEX('18 KMP- Tháng'!$AF$6:$AQ$29,MATCH($A15,'18 KMP- Tháng'!$A$6:$A$29,0),MATCH(AG$7,'18 KMP- Tháng'!$AF$2:$AQ$2,0)) -> 790.04556 | AH15: =INDEX('18 KMP- Tháng'!$AF$6:$AQ$29,MATCH($A15,'18 KMP- Tháng'!$A$6:$A$29,0),MATCH(AH$7,'18 KMP- Tháng'!$AF$2:$AQ$2,0)) -> 662.42186 | AI15: =INDEX('18 KMP- Tháng'!$AF$6:$AQ$29,MATCH($A15,'18 KMP- Tháng'!$A$6:$A$29,0),MATCH(AI$7,'18 KMP- Tháng'!$AF$2:$AQ$2,0)) -> 955.79571 | AJ15: =INDEX('18 KMP- Tháng'!$AF$6:$AQ$29,MATCH($A15,'18 KMP- Tháng'!$A$6:$A$29,0),MATCH(AJ$7,'18 KMP- Tháng'!$AF$2:$AQ$2,0)) -> 756.01674 | AK15: =INDEX('18 KMP- Tháng'!$AF$6:$AQ$29,MATCH($A15,'18 KMP- Tháng'!$A$6:$A$29,0),MATCH(AK$7,'18 KMP- Tháng'!$AF$2:$AQ$2,0)) -> 856.03757 | AL15: =INDEX('18 KMP- Tháng'!$AF$6:$AQ$29,MATCH($A15,'18 KMP- Tháng'!$A$6:$A$29,0),MATCH(AL$7,'18 KMP- Tháng'!$AF$2:$AQ$2,0)) -> 870.71485 | ... AP15: =INDEX('18 KMP- Tháng'!$AF$6:$AQ$29,MATCH($A15,'18 KMP- Tháng'!$A$6:$A$29,0),MATCH(AP$7,'18 KMP- Tháng'!$AF$2:$AQ$2,0)) -> 735.36081 | AQ15: =SUM(AE15:AP15)/COUNTIFS($AE$29:$AP$29,"<>"&0) -> 707.55683 | AR15: =SUM(AE15:AP15) -> 8490.6819 | AS15: =INDEX('18 KMP- Tháng'!$BH$6:$BS$29,MATCH($A15,'18 KMP- Tháng'!$A$6:$A$29,0),MATCH(AS$7,'18 KMP- Tháng'!$BH$2:$BS$2,0)) -> 679.00817 | AT15: =INDEX('18 KMP- Tháng'!$BH$6:$BS$29,MATCH($A15,'18 KMP- Tháng'!$A$6:$A$29,0),MATCH(AT$7,'18 KMP- Tháng'!$BH$2:$BS$2,0)) -> 562.30503 | AU15: =INDEX('18 KMP- Tháng'!$BH$6:$BS$29,MATCH($A15,'18 KMP- Tháng'!$A$6:$A$29,0),MATCH(AU$7,'18 KMP- Tháng'!$BH$2:$BS$2,0)) -> 711.91298 | AV15: =INDEX('18 KMP- Tháng'!$BH$6:$BS$29,MATCH($A15,'18 KMP- Tháng'!$A$6:$A$29,0),MATCH(AV$7,'18 KMP- Tháng'!$BH$2:$BS$2,0)) -> 715.21167 | AW15: =INDEX('18 KMP- Tháng'!$BH$6:$BS$29,MATCH($A15,'18 KMP- Tháng'!$A$6:$A$29,0),MATCH(AW$7,'18 KMP- Tháng'!$BH$2:$BS$2,0)) -> 711.91298 | AX15: =INDEX('18 KMP- Tháng'!$BH$6:$BS$29,MATCH($A15,'18 KMP- Tháng'!$A$6:$A$29,0),MATCH(AX$7,'18 KMP- Tháng'!$BH$2:$BS$2,0)) -> 735.36096 | AY15: =INDEX('18 KMP- Tháng'!$BH$6:$BS$29,MATCH($A15,'18 KMP- Tháng'!$A$6:$A$29,0),MATCH(AY$7,'18 KMP- Tháng'!$BH$2:$BS$2,0)) -> 745.36358 | AZ15: =INDEX('18 KMP- Tháng'!$BH$6:$BS$29,MATCH($A15,'18 KMP- Tháng'!$A$6:$A$29,0),MATCH(AZ$7,'18 KMP- Tháng'!$BH$2:$BS$2,0)) -> 753.96743 | ... BD15: =INDEX('18 KMP- Tháng'!$BH$6:$BS$29,MATCH($A15,'18 KMP- Tháng'!$A$6:$A$29,0),MATCH(BD$7,'18 KMP- Tháng'!$BH$2:$BS$2,0)) -> 753.96743 | BE15: =AVERAGE(AS15:BD15) -> 718.49597 | BF15: =INDEX('18 KMP- Tháng'!$AS$6:$BD$29,MATCH($A15,'18 KMP- Tháng'!$A$6:$A$29,0),MATCH(BF$7,'18 KMP- Tháng'!$AS$2:$BD$2,0)) -> 606.64758 | BG15: =INDEX('18 KMP- Tháng'!$AS$6:$BD$29,MATCH($A15,'18 KMP- Tháng'!$A$6:$A$29,0),MATCH(BG$7,'18 KMP- Tháng'!$AS$2:$BD$2,0)) -> 347.65498 | BH15: =INDEX('18 KMP- Tháng'!$AS$6:$BD$29,MATCH($A15,'18 KMP- Tháng'!$A$6:$A$29,0),MATCH(BH$7,'18 KMP- Tháng'!$AS$2:$BD$2,0)) -> 813.9042 | BI15: =INDEX('18 KMP- Tháng'!$AS$6:$BD$29,MATCH($A15,'18 KMP- Tháng'!$A$6:$A$29,0),MATCH(BI$7,'18 KMP- Tháng'!$AS$2:$BD$2,0)) -> 1024.3973 | BJ15: =INDEX('18 KMP- Tháng'!$AS$6:$BD$29,MATCH($A15,'18 KMP- Tháng'!$A$6:$A$29,0),MATCH(BJ$7,'18 KMP- Tháng'!$AS$2:$BD$2,0)) -> 785.37371 | BK15: =INDEX('18 KMP- Tháng'!$AS$6:$BD$29,MATCH($A15,'18 KMP- Tháng'!$A$6:$A$29,0),MATCH(BK$7,'18 KMP- Tháng'!$AS$2:$BD$2,0)) -> 0 | BL15: =INDEX('18 KMP- Tháng'!$AS$6:$BD$29,MATCH($A15,'18 KMP- Tháng'!$A$6:$A$29,0),MATCH(BL$7,'18 KMP- Tháng'!$AS$2:$BD$2,0)) -> 0 | BM15: =INDEX('18 KMP- Tháng'!$AS$6:$BD$29,MATCH($A15,'18 KMP- Tháng'!$A$6:$A$29,0),MATCH(BM$7,'18 KMP- Tháng'!$AS$2:$BD$2,0)) -> 0 | ... BQ15: =INDEX('18 KMP- Tháng'!$AS$6:$BD$29,MATCH($A15,'18 KMP- Tháng'!$A$6:$A$29,0),MATCH(BQ$7,'18 KMP- Tháng'!$AS$2:$BD$2,0)) -> 0 | BR15: =SUM(BF15:BQ15)/COUNTIFS($BF$29:$BQ$29,"<>"&0) -> 715.59554 | BS15: =SUM(BF15:BQ15) -> 3577.9777 | BT15: =IFERROR(BF15/AS15-1,"-") -> -0.10656808 | BU15: =BS15/$BS$29 -> 0.0078574411
A16: 10 | B16: =B15+1 -> 7 | C16: Biến phí | D16: Xăng dầu | E16: =INDEX('18 KMP- Tháng'!$E$6:$Q$29,MATCH($A16,'18 KMP- Tháng'!$A$6:$A$29,0),MATCH(E$7,'18 KMP- Tháng'!$E$2:$P$2,0)) -> 182.59013 | F16: =INDEX('18 KMP- Tháng'!$E$6:$Q$29,MATCH($A16,'18 KMP- Tháng'!$A$6:$A$29,0),MATCH(F$7,'18 KMP- Tháng'!$E$2:$P$2,0)) -> 256.21135 | G16: =INDEX('18 KMP- Tháng'!$E$6:$Q$29,MATCH($A16,'18 KMP- Tháng'!$A$6:$A$29,0),MATCH(G$7,'18 KMP- Tháng'!$E$2:$P$2,0)) -> 301.6939 | H16: =INDEX('18 KMP- Tháng'!$E$6:$Q$29,MATCH($A16,'18 KMP- Tháng'!$A$6:$A$29,0),MATCH(H$7,'18 KMP- Tháng'!$E$2:$P$2,0)) -> 299.17255 | I16: =INDEX('18 KMP- Tháng'!$E$6:$Q$29,MATCH($A16,'18 KMP- Tháng'!$A$6:$A$29,0),MATCH(I$7,'18 KMP- Tháng'!$E$2:$P$2,0)) -> 189.9545 | J16: =INDEX('18 KMP- Tháng'!$E$6:$Q$29,MATCH($A16,'18 KMP- Tháng'!$A$6:$A$29,0),MATCH(J$7,'18 KMP- Tháng'!$E$2:$P$2,0)) -> 375.78277 | K16: =INDEX('18 KMP- Tháng'!$E$6:$Q$29,MATCH($A16,'18 KMP- Tháng'!$A$6:$A$29,0),MATCH(K$7,'18 KMP- Tháng'!$E$2:$P$2,0)) -> 320.30578 | L16: =INDEX('18 KMP- Tháng'!$E$6:$Q$29,MATCH($A16,'18 KMP- Tháng'!$A$6:$A$29,0),MATCH(L$7,'18 KMP- Tháng'!$E$2:$P$2,0)) -> 367.61022 | ... P16: =INDEX('18 KMP- Tháng'!$E$6:$Q$29,MATCH($A16,'18 KMP- Tháng'!$A$6:$A$29,0),MATCH(P$7,'18 KMP- Tháng'!$E$2:$P$2,0)) -> 393.87627 | Q16: =AVERAGE(E16:P16) -> 322.97646 | R16: =INDEX('18 KMP- Tháng'!$R$6:$AC$24,MATCH($A16,'18 KMP- Tháng'!$A$6:$A$24,0),MATCH(R$7,'18 KMP- Tháng'!$R$2:$AC$2,0)) -> 377.49691 | S16: =INDEX('18 KMP- Tháng'!$R$6:$AC$24,MATCH($A16,'18 KMP- Tháng'!$A$6:$A$24,0),MATCH(S$7,'18 KMP- Tháng'!$R$2:$AC$2,0)) -> 255.24873 | T16: =INDEX('18 KMP- Tháng'!$R$6:$AC$24,MATCH($A16,'18 KMP- Tháng'!$A$6:$A$24,0),MATCH(T$7,'18 KMP- Tháng'!$R$2:$AC$2,0)) -> 394.67352 | U16: =INDEX('18 KMP- Tháng'!$R$6:$AC$24,MATCH($A16,'18 KMP- Tháng'!$A$6:$A$24,0),MATCH(U$7,'18 KMP- Tháng'!$R$2:$AC$2,0)) -> 371.32545 | V16: =INDEX('18 KMP- Tháng'!$R$6:$AC$24,MATCH($A16,'18 KMP- Tháng'!$A$6:$A$24,0),MATCH(V$7,'18 KMP- Tháng'!$R$2:$AC$2,0)) -> 367.60268 | W16: =INDEX('18 KMP- Tháng'!$R$6:$AC$24,MATCH($A16,'18 KMP- Tháng'!$A$6:$A$24,0),MATCH(W$7,'18 KMP- Tháng'!$R$2:$AC$2,0)) -> 326.45109 | X16: =INDEX('18 KMP- Tháng'!$R$6:$AC$24,MATCH($A16,'18 KMP- Tháng'!$A$6:$A$24,0),MATCH(X$7,'18 KMP- Tháng'!$R$2:$AC$2,0)) -> 297.34215 | Y16: =INDEX('18 KMP- Tháng'!$R$6:$AC$24,MATCH($A16,'18 KMP- Tháng'!$A$6:$A$24,0),MATCH(Y$7,'18 KMP- Tháng'!$R$2:$AC$2,0)) -> 252.43173 | ... AC16: =INDEX('18 KMP- Tháng'!$R$6:$AC$24,MATCH($A16,'18 KMP- Tháng'!$A$6:$A$24,0),MATCH(AC$7,'18 KMP- Tháng'!$R$2:$AC$2,0)) -> 273.17536 | AD16: =AVERAGE(R16:AC16) -> 313.60796 | AE16: =INDEX('18 KMP- Tháng'!$AF$6:$AQ$29,MATCH($A16,'18 KMP- Tháng'!$A$6:$A$29,0),MATCH(AE$7,'18 KMP- Tháng'!$AF$2:$AQ$2,0)) -> 165.84903 | AF16: =INDEX('18 KMP- Tháng'!$AF$6:$AQ$29,MATCH($A16,'18 KMP- Tháng'!$A$6:$A$29,0),MATCH(AF$7,'18 KMP- Tháng'!$AF$2:$AQ$2,0)) -> 208.23159 | AG16: =INDEX('18 KMP- Tháng'!$AF$6:$AQ$29,MATCH($A16,'18 KMP- Tháng'!$A$6:$A$29,0),MATCH(AG$7,'18 KMP- Tháng'!$AF$2:$AQ$2,0)) -> 262.06535 | AH16: =INDEX('18 KMP- Tháng'!$AF$6:$AQ$29,MATCH($A16,'18 KMP- Tháng'!$A$6:$A$29,0),MATCH(AH$7,'18 KMP- Tháng'!$AF$2:$AQ$2,0)) -> 221.74891 | AI16: =INDEX('18 KMP- Tháng'!$AF$6:$AQ$29,MATCH($A16,'18 KMP- Tháng'!$A$6:$A$29,0),MATCH(AI$7,'18 KMP- Tháng'!$AF$2:$AQ$2,0)) -> 226.69143 | AJ16: =INDEX('18 KMP- Tháng'!$AF$6:$AQ$29,MATCH($A16,'18 KMP- Tháng'!$A$6:$A$29,0),MATCH(AJ$7,'18 KMP- Tháng'!$AF$2:$AQ$2,0)) -> 212.6532 | AK16: =INDEX('18 KMP- Tháng'!$AF$6:$AQ$29,MATCH($A16,'18 KMP- Tháng'!$A$6:$A$29,0),MATCH(AK$7,'18 KMP- Tháng'!$AF$2:$AQ$2,0)) -> 238.152 | AL16: =INDEX('18 KMP- Tháng'!$AF$6:$AQ$29,MATCH($A16,'18 KMP- Tháng'!$A$6:$A$29,0),MATCH(AL$7,'18 KMP- Tháng'!$AF$2:$AQ$2,0)) -> 172.60772 | ... AP16: =INDEX('18 KMP- Tháng'!$AF$6:$AQ$29,MATCH($A16,'18 KMP- Tháng'!$A$6:$A$29,0),MATCH(AP$7,'18 KMP- Tháng'!$AF$2:$AQ$2,0)) -> 180.05128 | AQ16: =SUM(AE16:AP16)/COUNTIFS($AE$29:$AP$29,"<>"&0) -> 210.66734 | AR16: =SUM(AE16:AP16) -> 2528.0081 | AS16: =INDEX('18 KMP- Tháng'!$BH$6:$BS$29,MATCH($A16,'18 KMP- Tháng'!$A$6:$A$29,0),MATCH(AS$7,'18 KMP- Tháng'!$BH$2:$BS$2,0)) -> 214.12 | AT16: =INDEX('18 KMP- Tháng'!$BH$6:$BS$29,MATCH($A16,'18 KMP- Tháng'!$A$6:$A$29,0),MATCH(AT$7,'18 KMP- Tháng'!$BH$2:$BS$2,0)) -> 214.12 | AU16: =INDEX('18 KMP- Tháng'!$BH$6:$BS$29,MATCH($A16,'18 KMP- Tháng'!$A$6:$A$29,0),MATCH(AU$7,'18 KMP- Tháng'!$BH$2:$BS$2,0)) -> 214.12 | AV16: =INDEX('18 KMP- Tháng'!$BH$6:$BS$29,MATCH($A16,'18 KMP- Tháng'!$A$6:$A$29,0),MATCH(AV$7,'18 KMP- Tháng'!$BH$2:$BS$2,0)) -> 214.12 | AW16: =INDEX('18 KMP- Tháng'!$BH$6:$BS$29,MATCH($A16,'18 KMP- Tháng'!$A$6:$A$29,0),MATCH(AW$7,'18 KMP- Tháng'!$BH$2:$BS$2,0)) -> 214.12 | AX16: =INDEX('18 KMP- Tháng'!$BH$6:$BS$29,MATCH($A16,'18 KMP- Tháng'!$A$6:$A$29,0),MATCH(AX$7,'18 KMP- Tháng'!$BH$2:$BS$2,0)) -> 214.12 | AY16: =INDEX('18 KMP- Tháng'!$BH$6:$BS$29,MATCH($A16,'18 KMP- Tháng'!$A$6:$A$29,0),MATCH(AY$7,'18 KMP- Tháng'!$BH$2:$BS$2,0)) -> 214.12 | AZ16: =INDEX('18 KMP- Tháng'!$BH$6:$BS$29,MATCH($A16,'18 KMP- Tháng'!$A$6:$A$29,0),MATCH(AZ$7,'18 KMP- Tháng'!$BH$2:$BS$2,0)) -> 214.12 | ... BD16: =INDEX('18 KMP- Tháng'!$BH$6:$BS$29,MATCH($A16,'18 KMP- Tháng'!$A$6:$A$29,0),MATCH(BD$7,'18 KMP- Tháng'!$BH$2:$BS$2,0)) -> 214.12 | BE16: =AVERAGE(AS16:BD16) -> 214.12 | BF16: =INDEX('18 KMP- Tháng'!$AS$6:$BD$29,MATCH($A16,'18 KMP- Tháng'!$A$6:$A$29,0),MATCH(BF$7,'18 KMP- Tháng'!$AS$2:$BD$2,0)) -> 150.19266 | BG16: =INDEX('18 KMP- Tháng'!$AS$6:$BD$29,MATCH($A16,'18 KMP- Tháng'!$A$6:$A$29,0),MATCH(BG$7,'18 KMP- Tháng'!$AS$2:$BD$2,0)) -> 102.02832 | BH16: =INDEX('18 KMP- Tháng'!$AS$6:$BD$29,MATCH($A16,'18 KMP- Tháng'!$A$6:$A$29,0),MATCH(BH$7,'18 KMP- Tháng'!$AS$2:$BD$2,0)) -> 337.28312 | BI16: =INDEX('18 KMP- Tháng'!$AS$6:$BD$29,MATCH($A16,'18 KMP- Tháng'!$A$6:$A$29,0),MATCH(BI$7,'18 KMP- Tháng'!$AS$2:$BD$2,0)) -> 388.21782 | BJ16: =INDEX('18 KMP- Tháng'!$AS$6:$BD$29,MATCH($A16,'18 KMP- Tháng'!$A$6:$A$29,0),MATCH(BJ$7,'18 KMP- Tháng'!$AS$2:$BD$2,0)) -> 352.8556 | BK16: =INDEX('18 KMP- Tháng'!$AS$6:$BD$29,MATCH($A16,'18 KMP- Tháng'!$A$6:$A$29,0),MATCH(BK$7,'18 KMP- Tháng'!$AS$2:$BD$2,0)) -> 0 | BL16: =INDEX('18 KMP- Tháng'!$AS$6:$BD$29,MATCH($A16,'18 KMP- Tháng'!$A$6:$A$29,0),MATCH(BL$7,'18 KMP- Tháng'!$AS$2:$BD$2,0)) -> 0 | BM16: =INDEX('18 KMP- Tháng'!$AS$6:$BD$29,MATCH($A16,'18 KMP- Tháng'!$A$6:$A$29,0),MATCH(BM$7,'18 KMP- Tháng'!$AS$2:$BD$2,0)) -> 0 | ... BQ16: =INDEX('18 KMP- Tháng'!$AS$6:$BD$29,MATCH($A16,'18 KMP- Tháng'!$A$6:$A$29,0),MATCH(BQ$7,'18 KMP- Tháng'!$AS$2:$BD$2,0)) -> 0 | BR16: =SUM(BF16:BQ16)/COUNTIFS($BF$29:$BQ$29,"<>"&0) -> 266.1155 | BS16: =SUM(BF16:BQ16) -> 1330.5775 | BT16: =IFERROR(BF16/AS16-1,"-") -> -0.29855849 | BU16: =BS16/$BS$29 -> 0.0029220234
A17: 11 | B17: =B16+1 -> 8 | C17: Biến phí | D17: Hóa chất theo Bom | E17: =INDEX('18 KMP- Tháng'!$E$6:$Q$29,MATCH($A17,'18 KMP- Tháng'!$A$6:$A$29,0),MATCH(E$7,'18 KMP- Tháng'!$E$2:$P$2,0)) -> 188.62548 | F17: =INDEX('18 KMP- Tháng'!$E$6:$Q$29,MATCH($A17,'18 KMP- Tháng'!$A$6:$A$29,0),MATCH(F$7,'18 KMP- Tháng'!$E$2:$P$2,0)) -> 196.28917 | G17: =INDEX('18 KMP- Tháng'!$E$6:$Q$29,MATCH($A17,'18 KMP- Tháng'!$A$6:$A$29,0),MATCH(G$7,'18 KMP- Tháng'!$E$2:$P$2,0)) -> 460.43098 | H17: =INDEX('18 KMP- Tháng'!$E$6:$Q$29,MATCH($A17,'18 KMP- Tháng'!$A$6:$A$29,0),MATCH(H$7,'18 KMP- Tháng'!$E$2:$P$2,0)) -> 381.88882 | I17: =INDEX('18 KMP- Tháng'!$E$6:$Q$29,MATCH($A17,'18 KMP- Tháng'!$A$6:$A$29,0),MATCH(I$7,'18 KMP- Tháng'!$E$2:$P$2,0)) -> 279.47783 | J17: =INDEX('18 KMP- Tháng'!$E$6:$Q$29,MATCH($A17,'18 KMP- Tháng'!$A$6:$A$29,0),MATCH(J$7,'18 KMP- Tháng'!$E$2:$P$2,0)) -> 269.28565 | K17: =INDEX('18 KMP- Tháng'!$E$6:$Q$29,MATCH($A17,'18 KMP- Tháng'!$A$6:$A$29,0),MATCH(K$7,'18 KMP- Tháng'!$E$2:$P$2,0)) -> 204.9691 | L17: =INDEX('18 KMP- Tháng'!$E$6:$Q$29,MATCH($A17,'18 KMP- Tháng'!$A$6:$A$29,0),MATCH(L$7,'18 KMP- Tháng'!$E$2:$P$2,0)) -> 144.5965 | ... P17: =INDEX('18 KMP- Tháng'!$E$6:$Q$29,MATCH($A17,'18 KMP- Tháng'!$A$6:$A$29,0),MATCH(P$7,'18 KMP- Tháng'!$E$2:$P$2,0)) -> 234.21601 | Q17: =AVERAGE(E17:P17) -> 240.68175 | R17: =INDEX('18 KMP- Tháng'!$R$6:$AC$24,MATCH($A17,'18 KMP- Tháng'!$A$6:$A$24,0),MATCH(R$7,'18 KMP- Tháng'!$R$2:$AC$2,0)) -> 168.93013 | S17: =INDEX('18 KMP- Tháng'!$R$6:$AC$24,MATCH($A17,'18 KMP- Tháng'!$A$6:$A$24,0),MATCH(S$7,'18 KMP- Tháng'!$R$2:$AC$2,0)) -> 139.05925 | T17: =INDEX('18 KMP- Tháng'!$R$6:$AC$24,MATCH($A17,'18 KMP- Tháng'!$A$6:$A$24,0),MATCH(T$7,'18 KMP- Tháng'!$R$2:$AC$2,0)) -> 130.9827 | U17: =INDEX('18 KMP- Tháng'!$R$6:$AC$24,MATCH($A17,'18 KMP- Tháng'!$A$6:$A$24,0),MATCH(U$7,'18 KMP- Tháng'!$R$2:$AC$2,0)) -> 216.14341 | V17: =INDEX('18 KMP- Tháng'!$R$6:$AC$24,MATCH($A17,'18 KMP- Tháng'!$A$6:$A$24,0),MATCH(V$7,'18 KMP- Tháng'!$R$2:$AC$2,0)) -> 304.87665 | W17: =INDEX('18 KMP- Tháng'!$R$6:$AC$24,MATCH($A17,'18 KMP- Tháng'!$A$6:$A$24,0),MATCH(W$7,'18 KMP- Tháng'!$R$2:$AC$2,0)) -> 295.18419 | X17: =INDEX('18 KMP- Tháng'!$R$6:$AC$24,MATCH($A17,'18 KMP- Tháng'!$A$6:$A$24,0),MATCH(X$7,'18 KMP- Tháng'!$R$2:$AC$2,0)) -> 186.81336 | Y17: =INDEX('18 KMP- Tháng'!$R$6:$AC$24,MATCH($A17,'18 KMP- Tháng'!$A$6:$A$24,0),MATCH(Y$7,'18 KMP- Tháng'!$R$2:$AC$2,0)) -> 232.26438 | ... AC17: =INDEX('18 KMP- Tháng'!$R$6:$AC$24,MATCH($A17,'18 KMP- Tháng'!$A$6:$A$24,0),MATCH(AC$7,'18 KMP- Tháng'!$R$2:$AC$2,0)) -> 306.84791 | AD17: =AVERAGE(R17:AC17) -> 222.55295 | AE17: =INDEX('18 KMP- Tháng'!$AF$6:$AQ$29,MATCH($A17,'18 KMP- Tháng'!$A$6:$A$29,0),MATCH(AE$7,'18 KMP- Tháng'!$AF$2:$AQ$2,0)) -> 210.76332 | AF17: =INDEX('18 KMP- Tháng'!$AF$6:$AQ$29,MATCH($A17,'18 KMP- Tháng'!$A$6:$A$29,0),MATCH(AF$7,'18 KMP- Tháng'!$AF$2:$AQ$2,0)) -> 188.40178 | AG17: =INDEX('18 KMP- Tháng'!$AF$6:$AQ$29,MATCH($A17,'18 KMP- Tháng'!$A$6:$A$29,0),MATCH(AG$7,'18 KMP- Tháng'!$AF$2:$AQ$2,0)) -> 282.89573 | AH17: =INDEX('18 KMP- Tháng'!$AF$6:$AQ$29,MATCH($A17,'18 KMP- Tháng'!$A$6:$A$29,0),MATCH(AH$7,'18 KMP- Tháng'!$AF$2:$AQ$2,0)) -> 195.67146 | AI17: =INDEX('18 KMP- Tháng'!$AF$6:$AQ$29,MATCH($A17,'18 KMP- Tháng'!$A$6:$A$29,0),MATCH(AI$7,'18 KMP- Tháng'!$AF$2:$AQ$2,0)) -> 294.51893 | AJ17: =INDEX('18 KMP- Tháng'!$AF$6:$AQ$29,MATCH($A17,'18 KMP- Tháng'!$A$6:$A$29,0),MATCH(AJ$7,'18 KMP- Tháng'!$AF$2:$AQ$2,0)) -> 310.99887 | AK17: =INDEX('18 KMP- Tháng'!$AF$6:$AQ$29,MATCH($A17,'18 KMP- Tháng'!$A$6:$A$29,0),MATCH(AK$7,'18 KMP- Tháng'!$AF$2:$AQ$2,0)) -> 473.82858 | AL17: =INDEX('18 KMP- Tháng'!$AF$6:$AQ$29,MATCH($A17,'18 KMP- Tháng'!$A$6:$A$29,0),MATCH(AL$7,'18 KMP- Tháng'!$AF$2:$AQ$2,0)) -> 440.19382 | ... AP17: =INDEX('18 KMP- Tháng'!$AF$6:$AQ$29,MATCH($A17,'18 KMP- Tháng'!$A$6:$A$29,0),MATCH(AP$7,'18 KMP- Tháng'!$AF$2:$AQ$2,0)) -> 280.2819 | AQ17: =SUM(AE17:AP17)/COUNTIFS($AE$29:$AP$29,"<>"&0) -> 314.06303 | AR17: =SUM(AE17:AP17) -> 3768.7564 | AS17: =INDEX('18 KMP- Tháng'!$BH$6:$BS$29,MATCH($A17,'18 KMP- Tháng'!$A$6:$A$29,0),MATCH(AS$7,'18 KMP- Tháng'!$BH$2:$BS$2,0)) -> 452.49026 | AT17: =INDEX('18 KMP- Tháng'!$BH$6:$BS$29,MATCH($A17,'18 KMP- Tháng'!$A$6:$A$29,0),MATCH(AT$7,'18 KMP- Tháng'!$BH$2:$BS$2,0)) -> 361.99221 | AU17: =INDEX('18 KMP- Tháng'!$BH$6:$BS$29,MATCH($A17,'18 KMP- Tháng'!$A$6:$A$29,0),MATCH(AU$7,'18 KMP- Tháng'!$BH$2:$BS$2,0)) -> 471.8827 | AV17: =INDEX('18 KMP- Tháng'!$BH$6:$BS$29,MATCH($A17,'18 KMP- Tháng'!$A$6:$A$29,0),MATCH(AV$7,'18 KMP- Tháng'!$BH$2:$BS$2,0)) -> 471.8827 | AW17: =INDEX('18 KMP- Tháng'!$BH$6:$BS$29,MATCH($A17,'18 KMP- Tháng'!$A$6:$A$29,0),MATCH(AW$7,'18 KMP- Tháng'!$BH$2:$BS$2,0)) -> 471.8827 | AX17: =INDEX('18 KMP- Tháng'!$BH$6:$BS$29,MATCH($A17,'18 KMP- Tháng'!$A$6:$A$29,0),MATCH(AX$7,'18 KMP- Tháng'!$BH$2:$BS$2,0)) -> 471.8827 | AY17: =INDEX('18 KMP- Tháng'!$BH$6:$BS$29,MATCH($A17,'18 KMP- Tháng'!$A$6:$A$29,0),MATCH(AY$7,'18 KMP- Tháng'!$BH$2:$BS$2,0)) -> 496.89226 | AZ17: =INDEX('18 KMP- Tháng'!$BH$6:$BS$29,MATCH($A17,'18 KMP- Tháng'!$A$6:$A$29,0),MATCH(AZ$7,'18 KMP- Tháng'!$BH$2:$BS$2,0)) -> 496.89226 | ... BD17: =INDEX('18 KMP- Tháng'!$BH$6:$BS$29,MATCH($A17,'18 KMP- Tháng'!$A$6:$A$29,0),MATCH(BD$7,'18 KMP- Tháng'!$BH$2:$BS$2,0)) -> 496.89226 | BE17: =AVERAGE(AS17:BD17) -> 473.6139 | BF17: =INDEX('18 KMP- Tháng'!$AS$6:$BD$29,MATCH($A17,'18 KMP- Tháng'!$A$6:$A$29,0),MATCH(BF$7,'18 KMP- Tháng'!$AS$2:$BD$2,0)) -> 252.3496 | BG17: =INDEX('18 KMP- Tháng'!$AS$6:$BD$29,MATCH($A17,'18 KMP- Tháng'!$A$6:$A$29,0),MATCH(BG$7,'18 KMP- Tháng'!$AS$2:$BD$2,0)) -> 80.021954 | BH17: =INDEX('18 KMP- Tháng'!$AS$6:$BD$29,MATCH($A17,'18 KMP- Tháng'!$A$6:$A$29,0),MATCH(BH$7,'18 KMP- Tháng'!$AS$2:$BD$2,0)) -> 348.78599 | BI17: =INDEX('18 KMP- Tháng'!$AS$6:$BD$29,MATCH($A17,'18 KMP- Tháng'!$A$6:$A$29,0),MATCH(BI$7,'18 KMP- Tháng'!$AS$2:$BD$2,0)) -> 458.30997 | BJ17: =INDEX('18 KMP- Tháng'!$AS$6:$BD$29,MATCH($A17,'18 KMP- Tháng'!$A$6:$A$29,0),MATCH(BJ$7,'18 KMP- Tháng'!$AS$2:$BD$2,0)) -> 385.67559 | BK17: =INDEX('18 KMP- Tháng'!$AS$6:$BD$29,MATCH($A17,'18 KMP- Tháng'!$A$6:$A$29,0),MATCH(BK$7,'18 KMP- Tháng'!$AS$2:$BD$2,0)) -> 0 | BL17: =INDEX('18 KMP- Tháng'!$AS$6:$BD$29,MATCH($A17,'18 KMP- Tháng'!$A$6:$A$29,0),MATCH(BL$7,'18 KMP- Tháng'!$AS$2:$BD$2,0)) -> 0 | BM17: =INDEX('18 KMP- Tháng'!$AS$6:$BD$29,MATCH($A17,'18 KMP- Tháng'!$A$6:$A$29,0),MATCH(BM$7,'18 KMP- Tháng'!$AS$2:$BD$2,0)) -> 0 | ... BQ17: =INDEX('18 KMP- Tháng'!$AS$6:$BD$29,MATCH($A17,'18 KMP- Tháng'!$A$6:$A$29,0),MATCH(BQ$7,'18 KMP- Tháng'!$AS$2:$BD$2,0)) -> 0 | BR17: =SUM(BF17:BQ17)/COUNTIFS($BF$29:$BQ$29,"<>"&0) -> 305.02862 | BS17: =SUM(BF17:BQ17) -> 1525.1431 | BT17: =IFERROR(BF17/AS17-1,"-") -> -0.44230932 | BU17: =BS17/$BS$29 -> 0.0033493004
