Workbook
Name Data_Chitieu: #REF!
Name DS_sale_1: #REF!
Name DSsale: #REF!
Name DTR_MaNCC: #REF!
Name DTR_nam: #REF!
Name DTR_nhom: #REF!
Name DTR_sanluong: #REF!
Name DTR_tengoi: #REF!
Name DTR_tenNCC: #REF!
Name DTR_thang: #REF!
Name DTR_Tuan: #REF!
Name KH_NCC: #REF!
Name KH_NHOM: #REF!
Name KH_SL: #REF!
Name KH_TUAN: #REF!
Name NĂM: #REF!
Name nganh: #REF!
Name nhom: #REF!
Name NVL: #REF!
Name sanluong: #REF!
Name SL_PO: #REF!
Name tenncc: #REF!
Name THÁNG: #REF!

Sheet CS Thị trường
B1: CHÍNH SÁCH LƯƠNG VÀ THƯỞNG KPIs CỦA NHÂN SỰ MUA HÀNG THỊ TRƯỜNG
A3: Soạn Thảo | B3: Kiểm tra | C3: Kiểm tra | D3: Xem xét
A6: Nguyễn Trọng Tân | B6: Trần Nhựt Hiện | C6: Trần Thị Tuyết Xuân | D6: Huỳnh Ngọc Thạch
A7: Ngày: / / 2023 | B7: Ngày: / / 2023 | C7: Ngày: / / 2023 | D7: Ngày: / / 2023
A9: DANH MỤC | B9: Nhân viên mua hàng | C9: Giám sát mua hàng | D9: Nhóm trưởng mua hàng
A10: Sản lượng quản lý (Tấn/tháng) | B10: 300 | C10: 600-800 | D10: 1500
A11: Số tỉnh quản lý tối thiểu | B11: 3 | C11: 6-10 | D11: 15-20
A12: Số NCC quản lý tối thiểu | B12: 10 | C12: 15-20 | D12: 25-40
A13: Số nhân viên trực tiếp dưới quyền tối đa | B13: 0 | C13: 2 | D13: 3
A14: I. TỔNG THU NHẬP CĂN BẢN VÀ KPIS | B14: =B16+B18 -> 16300000 | C14: =C16+C18 -> 18700000 | D14: =D16+D18 -> 27000000
A16: 1. THU NHẬP CĂN BẢN | B16: 7300000 | C16: 8700000 | D16: 15000000
A18: 2. THƯỞNG CHỈ TIÊU | B18: =B19+B24 -> 9000000 | C18: =C19+C24 -> 10000000 | D18: =D19+D24 -> 12000000
A19: A. KPI sản lượng (KPI Lagging) | B19: =MAX(B20:B23) -> 8000000 | C19: =MAX(C20:C23) -> 9000000 | D19: =MAX(D20:D23) -> 11000000
A20: 70% <= x <=80% | B20: 3000000 | C20: 4000000 | D20: 6000000
A21: 80% < x <=95% | B21: 4000000 | C21: 5000000 | D21: 7000000
A22: 95% < x <=100% | B22: 6000000 | C22: 7000000 | D22: 9000000
A23: x>100% | B23: 8000000 | C23: 9000000 | D23: 11000000
A24: B. KPIs khác (KPIs Leading) | B24: =B25+B27 -> 1000000 | C24: =C25+C27 -> 1000000 | D24: =D25+D27 -> 1000000
A25: B1. Viếng thăm nhà cung cấp | B25: =B26 -> 500000 | C25: =C26 -> 500000 | D25: =D26 -> 500000
A26: Viếng thăm NCC theo lịch định kỳ được giao, báo cáo đầy đủ, chấp hành nội quy, chuyên cần,… | B26: 500000 | C26: 500000 | D26: 500000 | E26: Bảo cung cấp
A27: B2. Chỉ tiêu mở NCC mới: linh động theo từng tháng. | B27: =B28 -> 500000 | C27: =C28 -> 500000 | D27: =D28 -> 500000
A28: Đạt 100% chỉ tiêu mở mới NCC | B28: 500000 | C28: 500000 | D28: 500000 | E28: Admin miền
A30: II. TỔNG CHI PHÍ | B30: =SUM(B31,B35) -> 9100000 | C30: =SUM(C31,C35) -> 11200000 | D30: =SUM(D31,D35) -> 12200000
A31: 1.TRỢ CẤP CÔNG TÁC | B31: =SUM(B32:B34) -> 3600000 | C31: =SUM(C32:C34) -> 4600000 | D31: =SUM(D32:D34) -> 5600000
A32: Xăng xe | B32: =60000*26 -> 1560000 | C32: =60000*26 -> 1560000 | D32: =60000*26 -> 1560000
A33: Cơm trưa | B33: 1040000 | C33: 1040000 | D33: 1040000
A34: Giao tế | B34: 1000000 | C34: 2000000 | D34: 3000000
A35: 2. KHOÁN CÔNG TÁC TỈNH | B35: =B36+B37 -> 5500000 | C35: =C36+C37 -> 6600000 | D35: =D36+D37 -> 6600000
A36: Khoán công tác đi tỉnh | B36: 4500000 | C36: 5600000 | D36: 5600000
A37: Khoán công tác phí di chuyển về DTR/trạm họp, huấn luyện | B37: 1000000 | C37: 1000000 | D37: 1000000
A38: III. TỔNG THU NHẬP VÀ TRỢ CẤP | B38: =B14+B30 -> 25400000 | C38: =C14+C30 -> 29900000 | D38: =D14+D30 -> 39200000
A40: III. TỔNG THU NHẬP VÀ TRỢ CẤP NĂM 2022 ĐẾN THÁNG 1.2023 | B40: 16010000 | C40: 19410000
A42: CHÊNH LỆCH SO VS CHÍNH SÁCH CŨ | B42: =B38-B40 -> 9390000 | C42: =C38-C40 -> 10490000
A43: Tổng lương 2022 | B43: =B40*7 -> 112070000 | C43: =C40*5 -> 97050000
A44: Tổng lương tăng 2023 | B44: =B38*7 -> 177800000 | C44: =C38*5 -> 149500000
A45: Chênh lệch tổng lương | B45: =B44-B43 -> 65730000 | C45: =C44-C43 -> 52450000
B46: =B44/B43-1 -> 0.58650843 | C46: =C44/C43-1 -> 0.54044307

Sheet CS Admin
B1: CHÍNH SÁCH LƯƠNG VÀ THƯỞNG KPIs CỦA ADMIN DTR&TRẠM
A3: Soạn Thảo | B3: Kiểm tra | C3: Kiểm tra | D3: Xem xét
A6: Nguyễn Trọng Tân | B6: Trần Nhựt Hiện | C6: Trần Thị Tuyết Xuân | D6: Huỳnh Ngọc Thạch
A7: Ngày: / / 2023 | B7: Ngày: / / 2023 | C7: Ngày: / / 2023 | D7: Ngày: / / 2023
A9: DANH MỤC | B9: Admin Trạm | C9: Admin DTR | D9: Tổ Trưởng Admin DTR | E9: Cách tính
A10: Sản lượng quản lý (Tấn/tháng) | B10: 300 | C10: 600-800 | D10: 1500
A11: Số tỉnh quản lý tối thiểu | B11: 3 | C11: 6-10 | D11: 15-20
A12: Số NCC quản lý tối thiểu | B12: 10 | C12: 15-20 | D12: 25-40
A13: Số nhân viên trực tiếp dưới quyền tối đa | B13: 0 | C13: 2 | D13: 3
A14: 1. THƯỞNG CHỈ TIÊU | B14: =B15+B19+B29 -> 3000000 | C14: =C15+C20+C29 -> 3000000 | D14: =D15+D19+D29 -> 2000000
A15: A. KPI sản lượng (KPI Lagging) | B15: =MAX(B16:B18) -> 2000000 | C15: =MAX(C16:C18) -> 2000000 | D15: =MAX(D16:D18) -> 2000000
A16: 70% <= x <=80% | B16: 1000000 | C16: 1000000 | D16: 1000000
A17: 80% < x <=90% | B17: 1500000 | C17: 1500000 | D17: 1500000
A18: 90% < x <=100% | B18: 2000000 | C18: 2000000 | D18: 2000000
A19: B. KPIs khác (KPIs Leading) | D19: =D21+D23+D25+D27 -> 0
A20: B1.1 Nhân viên điều phối DTR | C20: =C22+C24+C26+C28 -> 1000000
A21: 1.Tỷ lệ hoàn thành PO | B21: =B22 -> 0 | C21: =C22 -> 400000 | D21: =D22 -> 0
A22: Đảm bảo các PO ký kết với NCC hoàn thành ≥ 90% | C22: 400000 | D22: 0 | E22: Các PO hoàn thành/ Tổng số PO đã ký trong tháng X $
A23: 2. Giá trị Tiết kiệm | B23: =B24 -> 0 | C23: =C24 -> 200000 | D23: =D24 -> 0 | F23: admin cung cấp
A24: Các PO ký kết với NCC có Giá mua thấp hơn Giá duyệt. | C24: 200000 | D24: 0 | E24: Các PO Giá mua thấp/ Tổng Số PO ký trong tháng X $
A25: 3. Hoàn thành công việc | C25: =C26 -> 200000
A26: Đảm bảo các báo cáo hoàn thành đúng tiến độ, cập nhật số liệu chính xác. | C26: 200000
A27: 4. Khiếu nại Nhà cung cấp | C27: =C28 -> 200000
A28: Đảm bảo không có khiếu nại hoặc tất cả các khiếu nại điều được giải quyết | C28: 200000
A29: B1.2 Nhân viên điều phối Trạm | B29: =B30+B32+B34+B36 -> 1000000 | C29: =C30+C32+C34+C36 -> 0 | D29: =D30+D32+D34+D36 -> 0
A30: 1. Tần suất liên hệ Nhà cung cấp: | B30: =B31 -> 300000 | C30: =C31 -> 0 | D30: =D31 -> 0
A31: Liên hệ tối thiểu 50 nhà cung cấp và 1 Nhà cung cấp liên hệ tối thiếu 2 lần/ tháng | B31: 300000
A32: 2. Duy trì số lượng NCC giao dịch trong tháng | B32: =B33 -> 300000 | C32: =C33 -> 0 | D32: =D33 -> 0
A33: Đảm bảo số NCC giao dịch trong tháng ≥ tháng trước | B33: 300000
A34: 3. Hoàn thành công việc | B34: =B35 -> 200000 | C34: =C35 -> 0 | D34: =D35 -> 0
A35: Đảm bảo các báo cáo hoàn thành đúng tiến độ, cập nhật số liệu chính xác. | B35: 200000
A36: 4. Khiếu nại Nhà cung cấp | B36: =B37 -> 200000 | C36: =C37 -> 0 | D36: =D37 -> 0
A37: Đảm bảo không có khiếu nại hoặc tất cả các khiếu nại điều được giải quyết | B37: 200000
A39: III. TỔNG THU NHẬP VÀ TRỢ CẤP NĂM 2022 ĐẾN THÁNG 1.2023 | B39: 16010000 | C39: 19410000
A41: CHÊNH LỆCH SO VS CHÍNH SÁCH CŨ | B41: =#REF!-B39 -> #REF! | C41: =#REF!-C39 -> #REF!
A42: Tổng lương 2022 | B42: =B39*7 -> 112070000 | C42: =C39*5 -> 97050000
A43: Tổng lương tăng 2023 | B43: =#REF!*7 -> #REF! | C43: =#REF!*5 -> #REF!
A44: Chênh lệch tổng lương | B44: =B43-B42 -> #REF! | C44: =C43-C42 -> #REF!
B45: =B43/B42-1 -> #REF! | C45: =C43/C42-1 -> #REF!

Sheet Thị trường
G1: =SUM(H1:K1) -> 6620 | H1: =SUMIFS('Chỉ tiêu'!$I:$I,'Chỉ tiêu'!$H:$H,'Thị trường'!H$3) -> 3000 | I1: =SUMIFS('Chỉ tiêu'!$I:$I,'Chỉ tiêu'!$H:$H,'Thị trường'!I$3) -> 3090 | J1: =SUMIFS('Chỉ tiêu'!$I:$I,'Chỉ tiêu'!$H:$H,'Thị trường'!J$3) -> 530 | K1: =SUMIFS('Chỉ tiêu'!$I:$I,'Chỉ tiêu'!$H:$H,'Thị trường'!K$3) -> 0 | L1: =SUM(M1:P1) -> 5762.3398 | M1: =SUMIFS('Chỉ tiêu'!$K:$K,'Chỉ tiêu'!$H:$H,'Thị trường'!H$3) -> 2544.518 | N1: =SUMIFS('Chỉ tiêu'!$K:$K,'Chỉ tiêu'!$H:$H,'Thị trường'!I$3) -> 2974.3168 | O1: =SUMIFS('Chỉ tiêu'!$K:$K,'Chỉ tiêu'!$H:$H,'Thị trường'!J$3) -> 243.505 | P1: =SUMIFS('Chỉ tiêu'!$K:$K,'Chỉ tiêu'!$H:$H,'Thị trường'!K$3) -> 0 | Q1: =L1/G1 -> 0.87044408
A2: KPI TÍNH LƯƠNG THÁNG 05/2026 | G2: Chỉ tiêu | L2: Thực đạt
A3: STT | B3: Mã nhân viên | C3: Họ và tên | D3: Chức vụ | E3: CV Kiêm nhiệm | F3: Pis | G3: Tổng | H3: PET vảy | I3: PET chai | J3: HDPE | K3: PP | L3: Tổng | M3: PET vảy | N3: PET chai | O3: HDPE | P3: PP | Q3: % | R3: Thưởng chỉ tiêu | S3: KPI T05/2026
A4: 1 | B4: 90027817 | C4: Nguyễn Thành Dân | D4: Giám sát mua hàng | E4: GS | F4: Sản lượng tất cả sản phẩm rPET, rHDPE, rPP | G4: =SUM(H4:K4) -> 999 | H4: =IF(E4="GS",SUMIFS(Chitieu[Chỉ tiêu],Chitieu[GS],'Thị trường'!C4,Chitieu[[qui đổi ]],'Thị trường'!$H$3),SUMIFS(Chitieu[Chỉ tiêu],Chitieu[NV],'Thị trường'!C4,Chitieu[[qui đổi ]],'Thị trường'!$H$3)) -> 200 | I4: =IF(E4="GS",SUMIFS(Chitieu[Chỉ tiêu],Chitieu[GS],'Thị trường'!C4,Chitieu[[qui đổi ]],'Thị trường'!$I$3),SUMIFS(Chitieu[Chỉ tiêu],Chitieu[NV],'Thị trường'!C4,Chitieu[[qui đổi ]],'Thị trường'!$I$3)) -> 799 | J4: =IF(E4="GS",SUMIFS(Chitieu[Chỉ tiêu],Chitieu[GS],'Thị trường'!C4,Chitieu[[qui đổi ]],'Thị trường'!$J$3),SUMIFS(Chitieu[Chỉ tiêu],Chitieu[NV],'Thị trường'!C4,Chitieu[[qui đổi ]],'Thị trường'!$J$3)) -> 0 | K4: =IF(E4="GS",SUMIFS(Chitieu[Chỉ tiêu],Chitieu[GS],'Thị trường'!C4,Chitieu[[qui đổi ]],'Thị trường'!$K$3),SUMIFS(Chitieu[Chỉ tiêu],Chitieu[NV],'Thị trường'!C4,Chitieu[[qui đổi ]],'Thị trường'!$K$3)) -> 0 | L4: =SUM(M4:P4) -> 805.9778 | M4: =IF(E4="GS",SUMIFS(Chitieu[Thực hiện],Chitieu[GS],'Thị trường'!C4,Chitieu[[qui đổi ]],'Thị trường'!$M$3),SUMIFS(Chitieu[Thực hiện],Chitieu[NV],'Thị trường'!C4,Chitieu[[qui đổi ]],'Thị trường'!$M$3)) -> 94.354 | N4: =IF(E4="GS",SUMIFS(Chitieu[Thực hiện],Chitieu[GS],'Thị trường'!C4,Chitieu[[qui đổi ]],'Thị trường'!$N$3),SUMIFS(Chitieu[Thực hiện],Chitieu[NV],'Thị trường'!C4,Chitieu[[qui đổi ]],'Thị trường'!$N$3)) -> 711.6238 | O4: =IF(E4="GS",SUMIFS(Chitieu[Thực hiện],Chitieu[GS],'Thị trường'!C4,Chitieu[[qui đổi ]],'Thị trường'!$O$3),SUMIFS(Chitieu[Thực hiện],Chitieu[NV],'Thị trường'!C4,Chitieu[[qui đổi ]],'Thị trường'!$O$3)) -> 0 | P4: =IF(E4="GS",SUMIFS(Chitieu[Thực hiện],Chitieu[GS],'Thị trường'!C4,Chitieu[[qui đổi ]],'Thị trường'!$P$3),SUMIFS(Chitieu[Thực hiện],Chitieu[NV],'Thị trường'!C4,Chitieu[[qui đổi ]],'Thị trường'!$P$3)) -> 0 | Q4: =L4/G4 -> 0.80678458 | R4: =IF(AND(Q4>=70%,Q4<=80%),4000000,IF(AND(Q4>80%,Q4<=95%),5000000,IF(AND(Q4>95%,Q4<=100%),7000000,IF(Q4>100%,9000000,0)))) -> 5000000 | S4: =SUM(R4,R5,R6) -> 6000000 | T4: ok
F5: Hoàn thành kế hoạch viếng thăm, gọi điện các NCC. | G5: 1 | L5: 0.905 | Q5: =IF(L5=0,0,L5/G5) -> 0.905 | R5: =IF(Q5>=90%,500000,0) -> 500000
F6: NCC Mới | G6: 0 | L6: =IF(E4="GS",SUMIFS(Table4[Đếm],Table4[Giám sát],'Thị trường'!C4),SUMIFS(Table4[Đếm],Table4[Nhân viên],'Thị trường'!C4)) -> 4 | Q6: =IFERROR((L6/G6),0) -> 0 | R6: =IF(L6>0,500000,0) -> 500000
A7: =A4+1 -> 2 | B7: 90026683 | C7: Nguyễn Duy Tân | D7: Nhân viên mua hàng thị trường | E7: NV | F7: Sản lượng tất cả sản phẩm rPET, rHDPE, rPP | G7: =SUM(H7:K7) -> 465 | H7: =IF(E7="GS",SUMIFS(Chitieu[Chỉ tiêu],Chitieu[GS],'Thị trường'!C7,Chitieu[[qui đổi ]],'Thị trường'!$H$3),SUMIFS(Chitieu[Chỉ tiêu],Chitieu[NV],'Thị trường'!C7,Chitieu[[qui đổi ]],'Thị trường'!$H$3)) -> 200 | I7: =IF(E7="GS",SUMIFS(Chitieu[Chỉ tiêu],Chitieu[GS],'Thị trường'!C7,Chitieu[[qui đổi ]],'Thị trường'!$I$3),SUMIFS(Chitieu[Chỉ tiêu],Chitieu[NV],'Thị trường'!C7,Chitieu[[qui đổi ]],'Thị trường'!$I$3)) -> 265 | J7: =IF(E7="GS",SUMIFS(Chitieu[Chỉ tiêu],Chitieu[GS],'Thị trường'!C7,Chitieu[[qui đổi ]],'Thị trường'!$J$3),SUMIFS(Chitieu[Chỉ tiêu],Chitieu[NV],'Thị trường'!C7,Chitieu[[qui đổi ]],'Thị trường'!$J$3)) -> 0 | K7: =IF(E7="GS",SUMIFS(Chitieu[Chỉ tiêu],Chitieu[GS],'Thị trường'!C7,Chitieu[[qui đổi ]],'Thị trường'!$K$3),SUMIFS(Chitieu[Chỉ tiêu],Chitieu[NV],'Thị trường'!C7,Chitieu[[qui đổi ]],'Thị trường'!$K$3)) -> 0 | L7: =SUM(M7:P7) -> 313.3828 | M7: =IF(E7="GS",SUMIFS(Chitieu[Thực hiện],Chitieu[GS],'Thị trường'!C7,Chitieu[[qui đổi ]],'Thị trường'!$M$3),SUMIFS(Chitieu[Thực hiện],Chitieu[NV],'Thị trường'!C7,Chitieu[[qui đổi ]],'Thị trường'!$M$3)) -> 94.354 | N7: =IF(E7="GS",SUMIFS(Chitieu[Thực hiện],Chitieu[GS],'Thị trường'!C7,Chitieu[[qui đổi ]],'Thị trường'!$N$3),SUMIFS(Chitieu[Thực hiện],Chitieu[NV],'Thị trường'!C7,Chitieu[[qui đổi ]],'Thị trường'!$N$3)) -> 219.0288 | O7: =IF(E7="GS",SUMIFS(Chitieu[Thực hiện],Chitieu[GS],'Thị trường'!C7,Chitieu[[qui đổi ]],'Thị trường'!$O$3),SUMIFS(Chitieu[Thực hiện],Chitieu[NV],'Thị trường'!C7,Chitieu[[qui đổi ]],'Thị trường'!$O$3)) -> 0 | P7: =IF(E7="GS",SUMIFS(Chitieu[Thực hiện],Chitieu[GS],'Thị trường'!C7,Chitieu[[qui đổi ]],'Thị trường'!$P$3),SUMIFS(Chitieu[Thực hiện],Chitieu[NV],'Thị trường'!C7,Chitieu[[qui đổi ]],'Thị trường'!$P$3)) -> 0 | Q7: =IFERROR((L7/G7),0) -> 0.67394151 | R7: =IF(AND(Q7>=70%,Q7<=80%),3000000,IF(AND(Q7>80%,Q7<=95%),4000000,IF(AND(Q7>95%,Q7<=100%),6000000,IF(Q7>100%,8000000,0)))) -> 0 | S7: =SUM(R7,R8,R9) -> 1000000 | T7: ok
F8: Hoàn thành kế hoạch viếng thăm, gọi điện các NCC. | G8: 0.9 | L8: 0.896 | Q8: =IF(L8=0,0,L8/G8) -> 0.99555556 | R8: =IF(Q8>=90%,500000,0) -> 500000
F9: NCC Mới | G9: 0 | L9: =IF(E7="GS",SUMIFS(Table4[Đếm],Table4[Giám sát],'Thị trường'!C7),SUMIFS(Table4[Đếm],Table4[Nhân viên],'Thị trường'!C7)) -> 2 | Q9: =IFERROR((L9/G9),0) -> 0 | R9: =IF(L9>0,500000,0) -> 500000
A10: =A7+1 -> 3 | B10: 90024356 | C10: Lâm Đỗ Anh Hào | D10: Nhân viên mua hàng thị trường | E10: NV | F10: Sản lượng tất cả sản phẩm rPET, rHDPE, rPP | G10: =SUM(H10:K10) -> 534 | H10: =IF(E10="GS",SUMIFS(Chitieu[Chỉ tiêu],Chitieu[GS],'Thị trường'!C10,Chitieu[[qui đổi ]],'Thị trường'!$H$3),SUMIFS(Chitieu[Chỉ tiêu],Chitieu[NV],'Thị trường'!C10,Chitieu[[qui đổi ]],'Thị trường'!$H$3)) -> 0 | I10: =IF(E10="GS",SUMIFS(Chitieu[Chỉ tiêu],Chitieu[GS],'Thị trường'!C10,Chitieu[[qui đổi ]],'Thị trường'!$I$3),SUMIFS(Chitieu[Chỉ tiêu],Chitieu[NV],'Thị trường'!C10,Chitieu[[qui đổi ]],'Thị trường'!$I$3)) -> 534 | J10: =IF(E10="GS",SUMIFS(Chitieu[Chỉ tiêu],Chitieu[GS],'Thị trường'!C10,Chitieu[[qui đổi ]],'Thị trường'!$J$3),SUMIFS(Chitieu[Chỉ tiêu],Chitieu[NV],'Thị trường'!C10,Chitieu[[qui đổi ]],'Thị trường'!$J$3)) -> 0 | K10: =IF(E10="GS",SUMIFS(Chitieu[Chỉ tiêu],Chitieu[GS],'Thị trường'!C10,Chitieu[[qui đổi ]],'Thị trường'!$K$3),SUMIFS(Chitieu[Chỉ tiêu],Chitieu[NV],'Thị trường'!C10,Chitieu[[qui đổi ]],'Thị trường'!$K$3)) -> 0 | L10: =SUM(M10:P10) -> 492.595 | M10: =IF(E10="GS",SUMIFS(Chitieu[Thực hiện],Chitieu[GS],'Thị trường'!C10,Chitieu[[qui đổi ]],'Thị trường'!$M$3),SUMIFS(Chitieu[Thực hiện],Chitieu[NV],'Thị trường'!C10,Chitieu[[qui đổi ]],'Thị trường'!$M$3)) -> 0 | N10: =IF(E10="GS",SUMIFS(Chitieu[Thực hiện],Chitieu[GS],'Thị trường'!C10,Chitieu[[qui đổi ]],'Thị trường'!$N$3),SUMIFS(Chitieu[Thực hiện],Chitieu[NV],'Thị trường'!C10,Chitieu[[qui đổi ]],'Thị trường'!$N$3)) -> 492.595 | O10: =IF(E10="GS",SUMIFS(Chitieu[Thực hiện],Chitieu[GS],'Thị trường'!C10,Chitieu[[qui đổi ]],'Thị trường'!$O$3),SUMIFS(Chitieu[Thực hiện],Chitieu[NV],'Thị trường'!C10,Chitieu[[qui đổi ]],'Thị trường'!$O$3)) -> 0 | P10: =IF(E10="GS",SUMIFS(Chitieu[Thực hiện],Chitieu[GS],'Thị trường'!C10,Chitieu[[qui đổi ]],'Thị trường'!$P$3),SUMIFS(Chitieu[Thực hiện],Chitieu[NV],'Thị trường'!C10,Chitieu[[qui đổi ]],'Thị trường'!$P$3)) -> 0 | Q10: =IFERROR((L10/G10),0) -> 0.92246255 | R10: =IF(AND(Q10>=70%,Q10<=80%),3000000,IF(AND(Q10>80%,Q10<=95%),4000000,IF(AND(Q10>95%,Q10<=100%),6000000,IF(Q10>100%,8000000,0)))) -> 4000000 | S10: =SUM(R10,R11,R12) -> 5000000 | T10: ok
F11: Hoàn thành kế hoạch viếng thăm, gọi điện các NCC. | G11: 0.9 | L11: 1 | Q11: =IF(L11=0,0,L11/G11) -> 1.1111111 | R11: =IF(Q11>=90%,500000,0) -> 500000
F12: NCC Mới | G12: 0 | L12: =IF(E10="GS",SUMIFS(Table4[Đếm],Table4[Giám sát],'Thị trường'!C10),SUMIFS(Table4[Đếm],Table4[Nhân viên],'Thị trường'!C10)) -> 2 | Q12: =IFERROR((L12/G12),0) -> 0 | R12: =IF(L12>0,500000,0) -> 500000
A13: =A10+1 -> 4 | B13: 90024839 | C13: Phạm Huỳnh Hữu Lộc | D13: Giám sát mua hàng | E13: GS | F13: Sản lượng tất cả sản phẩm rPET, rHDPE, rPP | G13: =SUM(H13:K13) -> 966 | H13: =IF(E13="GS",SUMIFS(Chitieu[Chỉ tiêu],Chitieu[GS],'Thị trường'!C13,Chitieu[[qui đổi ]],'Thị trường'!$H$3),SUMIFS(Chitieu[Chỉ tiêu],Chitieu[NV],'Thị trường'!C13,Chitieu[[qui đổi ]],'Thị trường'!$H$3)) -> 0 | I13: =IF(E13="GS",SUMIFS(Chitieu[Chỉ tiêu],Chitieu[GS],'Thị trường'!C13,Chitieu[[qui đổi ]],'Thị trường'!$I$3),SUMIFS(Chitieu[Chỉ tiêu],Chitieu[NV],'Thị trường'!C13,Chitieu[[qui đổi ]],'Thị trường'!$I$3)) -> 916 | J13: =IF(E13="GS",SUMIFS(Chitieu[Chỉ tiêu],Chitieu[GS],'Thị trường'!C13,Chitieu[[qui đổi ]],'Thị trường'!$J$3),SUMIFS(Chitieu[Chỉ tiêu],Chitieu[NV],'Thị trường'!C13,Chitieu[[qui đổi ]],'Thị trường'!$J$3)) -> 50 | K13: =IF(E13="GS",SUMIFS(Chitieu[Chỉ tiêu],Chitieu[GS],'Thị trường'!C13,Chitieu[[qui đổi ]],'Thị trường'!$K$3),SUMIFS(Chitieu[Chỉ tiêu],Chitieu[NV],'Thị trường'!C13,Chitieu[[qui đổi ]],'Thị trường'!$K$3)) -> 0 | L13: =SUM(M13:P13) -> 853.937 | M13: =IF(E13="GS",SUMIFS(Chitieu[Thực hiện],Chitieu[GS],'Thị trường'!C13,Chitieu[[qui đổi ]],'Thị trường'!$M$3),SUMIFS(Chitieu[Thực hiện],Chitieu[NV],'Thị trường'!C13,Chitieu[[qui đổi ]],'Thị trường'!$M$3)) -> 0 | N13: =IF(E13="GS",SUMIFS(Chitieu[Thực hiện],Chitieu[GS],'Thị trường'!C13,Chitieu[[qui đổi ]],'Thị trường'!$N$3),SUMIFS(Chitieu[Thực hiện],Chitieu[NV],'Thị trường'!C13,Chitieu[[qui đổi ]],'Thị trường'!$N$3)) -> 850.411 | O13: =IF(E13="GS",SUMIFS(Chitieu[Thực hiện],Chitieu[GS],'Thị trường'!C13,Chitieu[[qui đổi ]],'Thị trường'!$O$3),SUMIFS(Chitieu[Thực hiện],Chitieu[NV],'Thị trường'!C13,Chitieu[[qui đổi ]],'Thị trường'!$O$3)) -> 3.526 | P13: =IF(E13="GS",SUMIFS(Chitieu[Thực hiện],Chitieu[GS],'Thị trường'!C13,Chitieu[[qui đổi ]],'Thị trường'!$P$3),SUMIFS(Chitieu[Thực hiện],Chitieu[NV],'Thị trường'!C13,Chitieu[[qui đổi ]],'Thị trường'!$P$3)) -> 0 | Q13: =IFERROR((L13/G13),0) -> 0.88399275 | R13: =IF(AND(Q13>=70%,Q13<=80%),4000000,IF(AND(Q13>80%,Q13<=95%),5000000,IF(AND(Q13>95%,Q13<=100%),7000000,IF(Q13>100%,9000000,0)))) -> 5000000 | S13: =SUM(R13,R14,R15) -> 6000000 | T13: ok
F14: Hoàn thành kế hoạch viếng thăm, gọi điện các NCC. | G14: 0.9 | L14: 0.91 | Q14: =IF(L14=0,0,L14/G14) -> 1.0111111 | R14: =IF(Q14>=90%,500000,0) -> 500000
F15: NCC Mới | G15: 0 | L15: =IF(E13="GS",SUMIFS(Table4[Đếm],Table4[Giám sát],'Thị trường'!C13),SUMIFS(Table4[Đếm],Table4[Nhân viên],'Thị trường'!C13)) -> 7 | Q15: =IFERROR((L15/G15),0) -> 0 | R15: =IF(L15>0,500000,0) -> 500000
A16: =A13+1 -> 5 | B16: 90024169 | C16: Nguyễn Ngọc Lâm | D16: Giám sát mua hàng | E16: NV | F16: Sản lượng tất cả sản phẩm rPET, rHDPE, rPP | G16: =SUM(H16:K16) -> 181 | H16: =IF(E16="GS",SUMIFS(Chitieu[Chỉ tiêu],Chitieu[GS],'Thị trường'!C16,Chitieu[[qui đổi ]],'Thị trường'!$H$3),SUMIFS(Chitieu[Chỉ tiêu],Chitieu[NV],'Thị trường'!C16,Chitieu[[qui đổi ]],'Thị trường'!$H$3)) -> 0 | I16: =IF(E16="GS",SUMIFS(Chitieu[Chỉ tiêu],Chitieu[GS],'Thị trường'!C16,Chitieu[[qui đổi ]],'Thị trường'!$I$3),SUMIFS(Chitieu[Chỉ tiêu],Chitieu[NV],'Thị trường'!C16,Chitieu[[qui đổi ]],'Thị trường'!$I$3)) -> 181 | J16: =IF(E16="GS",SUMIFS(Chitieu[Chỉ tiêu],Chitieu[GS],'Thị trường'!C16,Chitieu[[qui đổi ]],'Thị trường'!$J$3),SUMIFS(Chitieu[Chỉ tiêu],Chitieu[NV],'Thị trường'!C16,Chitieu[[qui đổi ]],'Thị trường'!$J$3)) -> 0 | K16: =IF(E16="GS",SUMIFS(Chitieu[Chỉ tiêu],Chitieu[GS],'Thị trường'!C16,Chitieu[[qui đổi ]],'Thị trường'!$K$3),SUMIFS(Chitieu[Chỉ tiêu],Chitieu[NV],'Thị trường'!C16,Chitieu[[qui đổi ]],'Thị trường'!$K$3)) -> 0 | L16: =SUM(M16:P16) -> 165.808 | M16: =IF(E16="GS",SUMIFS(Chitieu[Thực hiện],Chitieu[GS],'Thị trường'!C16,Chitieu[[qui đổi ]],'Thị trường'!$M$3),SUMIFS(Chitieu[Thực hiện],Chitieu[NV],'Thị trường'!C16,Chitieu[[qui đổi ]],'Thị trường'!$M$3)) -> 0 | N16: =IF(E16="GS",SUMIFS(Chitieu[Thực hiện],Chitieu[GS],'Thị trường'!C16,Chitieu[[qui đổi ]],'Thị trường'!$N$3),SUMIFS(Chitieu[Thực hiện],Chitieu[NV],'Thị trường'!C16,Chitieu[[qui đổi ]],'Thị trường'!$N$3)) -> 165.808 | O16: =IF(E16="GS",SUMIFS(Chitieu[Thực hiện],Chitieu[GS],'Thị trường'!C16,Chitieu[[qui đổi ]],'Thị trường'!$O$3),SUMIFS(Chitieu[Thực hiện],Chitieu[NV],'Thị trường'!C16,Chitieu[[qui đổi ]],'Thị trường'!$O$3)) -> 0 | P16: =IF(E16="GS",SUMIFS(Chitieu[Thực hiện],Chitieu[GS],'Thị trường'!C16,Chitieu[[qui đổi ]],'Thị trường'!$P$3),SUMIFS(Chitieu[Thực hiện],Chitieu[NV],'Thị trường'!C16,Chitieu[[qui đổi ]],'Thị trường'!$P$3)) -> 0 | Q16: =IFERROR((L16/G16),0) -> 0.9160663 | R16: =IF(AND(Q16>=70%,Q16<=80%),4000000,IF(AND(Q16>80%,Q16<=95%),5000000,IF(AND(Q16>95%,Q16<=100%),7000000,IF(Q16>100%,9000000,0)))) -> 5000000 | S16: =SUM(R16,R17,R18) -> 6000000 | T16: ok
F17: Hoàn thành kế hoạch viếng thăm, gọi điện các NCC. | G17: 0.9 | L17: 0.94 | Q17: =IF(L17=0,0,L17/G17) -> 1.0444444 | R17: =IF(Q17>=90%,500000,0) -> 500000
F18: NCC Mới | G18: 0 | L18: =IF(E16="GS",SUMIFS(Table4[Đếm],Table4[Giám sát],'Thị trường'!C16),SUMIFS(Table4[Đếm],Table4[Nhân viên],'Thị trường'!C16)) -> 3 | Q18: =IFERROR((L18/G18),0) -> 0 | R18: =IF(L18>0,500000,0) -> 500000
A19: 6 | B19: 90024358 | C19: Thái Tân Văn | D19: Nhân viên mua hàng thị trường | E19: NV | F19: Sản lượng tất cả sản phẩm rPET, rHDPE, rPP | G19: =SUM(H19:K19) -> 123 | H19: =IF(E19="GS",SUMIFS(Chitieu[Chỉ tiêu],Chitieu[GS],'Thị trường'!C19,Chitieu[[qui đổi ]],'Thị trường'!$H$3),SUMIFS(Chitieu[Chỉ tiêu],Chitieu[NV],'Thị trường'!C19,Chitieu[[qui đổi ]],'Thị trường'!$H$3)) -> 0 | I19: =IF(E19="GS",SUMIFS(Chitieu[Chỉ tiêu],Chitieu[GS],'Thị trường'!C19,Chitieu[[qui đổi ]],'Thị trường'!$I$3),SUMIFS(Chitieu[Chỉ tiêu],Chitieu[NV],'Thị trường'!C19,Chitieu[[qui đổi ]],'Thị trường'!$I$3)) -> 123 | J19: =IF(E19="GS",SUMIFS(Chitieu[Chỉ tiêu],Chitieu[GS],'Thị trường'!C19,Chitieu[[qui đổi ]],'Thị trường'!$J$3),SUMIFS(Chitieu[Chỉ tiêu],Chitieu[NV],'Thị trường'!C19,Chitieu[[qui đổi ]],'Thị trường'!$J$3)) -> 0 | K19: =IF(E19="GS",SUMIFS(Chitieu[Chỉ tiêu],Chitieu[GS],'Thị trường'!C19,Chitieu[[qui đổi ]],'Thị trường'!$K$3),SUMIFS(Chitieu[Chỉ tiêu],Chitieu[NV],'Thị trường'!C19,Chitieu[[qui đổi ]],'Thị trường'!$K$3)) -> 0 | L19: =SUM(M19:P19) -> 147.589 | M19: =IF(E19="GS",SUMIFS(Chitieu[Thực hiện],Chitieu[GS],'Thị trường'!C19,Chitieu[[qui đổi ]],'Thị trường'!$M$3),SUMIFS(Chitieu[Thực hiện],Chitieu[NV],'Thị trường'!C19,Chitieu[[qui đổi ]],'Thị trường'!$M$3)) -> 0 | N19: =IF(E19="GS",SUMIFS(Chitieu[Thực hiện],Chitieu[GS],'Thị trường'!C19,Chitieu[[qui đổi ]],'Thị trường'!$N$3),SUMIFS(Chitieu[Thực hiện],Chitieu[NV],'Thị trường'!C19,Chitieu[[qui đổi ]],'Thị trường'!$N$3)) -> 147.589 | O19: =IF(E19="GS",SUMIFS(Chitieu[Thực hiện],Chitieu[GS],'Thị trường'!C19,Chitieu[[qui đổi ]],'Thị trường'!$O$3),SUMIFS(Chitieu[Thực hiện],Chitieu[NV],'Thị trường'!C19,Chitieu[[qui đổi ]],'Thị trường'!$O$3)) -> 0 | P19: =IF(E19="GS",SUMIFS(Chitieu[Thực hiện],Chitieu[GS],'Thị trường'!C19,Chitieu[[qui đổi ]],'Thị trường'!$P$3),SUMIFS(Chitieu[Thực hiện],Chitieu[NV],'Thị trường'!C19,Chitieu[[qui đổi ]],'Thị trường'!$P$3)) -> 0 | Q19: =IFERROR((L19/G19),0) -> 1.1999106 | R19: =IF(AND(Q19>=70%,Q19<=80%),3000000,IF(AND(Q19>80%,Q19<=95%),4000000,IF(AND(Q19>95%,Q19<=100%),6000000,IF(Q19>100%,8000000,0)))) -> 8000000 | S19: =SUM(R19,R20,R21) -> 8000000 | T19: ok
F20: Hoàn thành kế hoạch viếng thăm, gọi điện các NCC. | G20: 0.9 | L20: 0.66 | Q20: =IF(L20=0,0,L20/G20) -> 0.73333333 | R20: =IF(Q20>=90%,500000,0) -> 0
F21: NCC Mới | G21: 0 | L21: =IF(E19="GS",SUMIFS(Table4[Đếm],Table4[Giám sát],'Thị trường'!C19),SUMIFS(Table4[Đếm],Table4[Nhân viên],'Thị trường'!C19)) -> 0 | Q21: =IFERROR((L21/G21),0) -> 0 | R21: =IF(L21>0,500000,0) -> 0
A22: 7 | B22: 90027819 | C22: Lê Quốc Việt | D22: Nhân viên mua hàng thị trường | E22: NV | F22: Sản lượng tất cả sản phẩm rPET, rHDPE, rPP | G22: =SUM(H22:K22) -> 398 | H22: =IF(E22="GS",SUMIFS(Chitieu[Chỉ tiêu],Chitieu[GS],'Thị trường'!C22,Chitieu[[qui đổi ]],'Thị trường'!$H$3),SUMIFS(Chitieu[Chỉ tiêu],Chitieu[NV],'Thị trường'!C22,Chitieu[[qui đổi ]],'Thị trường'!$H$3)) -> 0 | I22: =IF(E22="GS",SUMIFS(Chitieu[Chỉ tiêu],Chitieu[GS],'Thị trường'!C22,Chitieu[[qui đổi ]],'Thị trường'!$I$3),SUMIFS(Chitieu[Chỉ tiêu],Chitieu[NV],'Thị trường'!C22,Chitieu[[qui đổi ]],'Thị trường'!$I$3)) -> 348 | J22: =IF(E22="GS",SUMIFS(Chitieu[Chỉ tiêu],Chitieu[GS],'Thị trường'!C22,Chitieu[[qui đổi ]],'Thị trường'!$J$3),SUMIFS(Chitieu[Chỉ tiêu],Chitieu[NV],'Thị trường'!C22,Chitieu[[qui đổi ]],'Thị trường'!$J$3)) -> 50 | K22: =IF(E22="GS",SUMIFS(Chitieu[Chỉ tiêu],Chitieu[GS],'Thị trường'!C22,Chitieu[[qui đổi ]],'Thị trường'!$K$3),SUMIFS(Chitieu[Chỉ tiêu],Chitieu[NV],'Thị trường'!C22,Chitieu[[qui đổi ]],'Thị trường'!$K$3)) -> 0 | L22: =SUM(M22:P22) -> 322.69 | M22: =IF(E22="GS",SUMIFS(Chitieu[Thực hiện],Chitieu[GS],'Thị trường'!C22,Chitieu[[qui đổi ]],'Thị trường'!$M$3),SUMIFS(Chitieu[Thực hiện],Chitieu[NV],'Thị trường'!C22,Chitieu[[qui đổi ]],'Thị trường'!$M$3)) -> 0 | N22: =IF(E22="GS",SUMIFS(Chitieu[Thực hiện],Chitieu[GS],'Thị trường'!C22,Chitieu[[qui đổi ]],'Thị trường'!$N$3),SUMIFS(Chitieu[Thực hiện],Chitieu[NV],'Thị trường'!C22,Chitieu[[qui đổi ]],'Thị trường'!$N$3)) -> 319.164 | O22: =IF(E22="GS",SUMIFS(Chitieu[Thực hiện],Chitieu[GS],'Thị trường'!C22,Chitieu[[qui đổi ]],'Thị trường'!$O$3),SUMIFS(Chitieu[Thực hiện],Chitieu[NV],'Thị trường'!C22,Chitieu[[qui đổi ]],'Thị trường'!$O$3)) -> 3.526 | P22: =IF(E22="GS",SUMIFS(Chitieu[Thực hiện],Chitieu[GS],'Thị trường'!C22,Chitieu[[qui đổi ]],'Thị trường'!$P$3),SUMIFS(Chitieu[Thực hiện],Chitieu[NV],'Thị trường'!C22,Chitieu[[qui đổi ]],'Thị trường'!$P$3)) -> 0 | Q22: =IFERROR((L22/G22),0) -> 0.81077889 | R22: =IF(AND(Q22>=70%,Q22<=80%),3000000,IF(AND(Q22>80%,Q22<=95%),4000000,IF(AND(Q22>95%,Q22<=100%),6000000,IF(Q22>100%,8000000,0)))) -> 4000000 | S22: =SUM(R22,R23,R24) -> 5000000 | T22: ok
F23: Hoàn thành kế hoạch viếng thăm, gọi điện các NCC. | G23: 0.9 | L23: 0.843 | Q23: =IF(L23=0,0,L23/G23) -> 0.93666667 | R23: =IF(Q23>=90%,500000,0) -> 500000
F24: NCC Mới | G24: 0 | L24: =IF(E22="GS",SUMIFS(Table4[Đếm],Table4[Giám sát],'Thị trường'!C22),SUMIFS(Table4[Đếm],Table4[Nhân viên],'Thị trường'!C22)) -> 3 | Q24: =IFERROR((L9/G9),0) -> 0 | R24: =IF(L24>0,500000,0) -> 500000
A25: 8 | B25: 90024168 | C25: Đặng Nguyễn Hoàng Lộc | D25: Giám sát mua hàng | E25: GS | F25: Sản lượng tất cả sản phẩm rPET, rHDPE, rPP | G25: =SUM(H25:K25) -> 3090 | H25: =IF(E25="GS",SUMIFS(Chitieu[Chỉ tiêu],Chitieu[GS],'Thị trường'!C25,Chitieu[[qui đổi ]],'Thị trường'!$H$3),SUMIFS(Chitieu[Chỉ tiêu],Chitieu[NV],'Thị trường'!C25,Chitieu[[qui đổi ]],'Thị trường'!$H$3)) -> 2100 | I25: =IF(E25="GS",SUMIFS(Chitieu[Chỉ tiêu],Chitieu[GS],'Thị trường'!C25,Chitieu[[qui đổi ]],'Thị trường'!$I$3),SUMIFS(Chitieu[Chỉ tiêu],Chitieu[NV],'Thị trường'!C25,Chitieu[[qui đổi ]],'Thị trường'!$I$3)) -> 510 | J25: =IF(E25="GS",SUMIFS(Chitieu[Chỉ tiêu],Chitieu[GS],'Thị trường'!C25,Chitieu[[qui đổi ]],'Thị trường'!$J$3),SUMIFS(Chitieu[Chỉ tiêu],Chitieu[NV],'Thị trường'!C25,Chitieu[[qui đổi ]],'Thị trường'!$J$3)) -> 480 | K25: =IF(E25="GS",SUMIFS(Chitieu[Chỉ tiêu],Chitieu[GS],'Thị trường'!C25,Chitieu[[qui đổi ]],'Thị trường'!$K$3),SUMIFS(Chitieu[Chỉ tiêu],Chitieu[NV],'Thị trường'!C25,Chitieu[[qui đổi ]],'Thị trường'!$K$3)) -> 0 | L25: =SUM(M25:P25) -> 3142.449 | M25: =IF(E25="GS",SUMIFS(Chitieu[Thực hiện],Chitieu[GS],'Thị trường'!C25,Chitieu[[qui đổi ]],'Thị trường'!$M$3),SUMIFS(Chitieu[Thực hiện],Chitieu[NV],'Thị trường'!C25,Chitieu[[qui đổi ]],'Thị trường'!$M$3)) -> 2362.04 | N25: =IF(E25="GS",SUMIFS(Chitieu[Thực hiện],Chitieu[GS],'Thị trường'!C25,Chitieu[[qui đổi ]],'Thị trường'!$N$3),SUMIFS(Chitieu[Thực hiện],Chitieu[NV],'Thị trường'!C25,Chitieu[[qui đổi ]],'Thị trường'!$N$3)) -> 543.518 | O25: =IF(E25="GS",SUMIFS(Chitieu[Thực hiện],Chitieu[GS],'Thị trường'!C25,Chitieu[[qui đổi ]],'Thị trường'!$O$3),SUMIFS(Chitieu[Thực hiện],Chitieu[NV],'Thị trường'!C25,Chitieu[[qui đổi ]],'Thị trường'!$O$3)) -> 236.891 | P25: =IF(E25="GS",SUMIFS(Chitieu[Thực hiện],Chitieu[GS],'Thị trường'!C25,Chitieu[[qui đổi ]],'Thị trường'!$P$3),SUMIFS(Chitieu[Thực hiện],Chitieu[NV],'Thị trường'!C25,Chitieu[[qui đổi ]],'Thị trường'!$P$3)) -> 0 | Q25: =IFERROR((L25/G25),0) -> 1.0169738 | R25: =IF(AND(Q25>=70%,Q25<=80%),4000000,IF(AND(Q25>80%,Q25<=95%),5000000,IF(AND(Q25>95%,Q25<=100%),7000000,IF(Q25>100%,9000000,0)))) -> 9000000 | S25: =SUM(R25,R26,R27) -> 10000000 | T25: ok
F26: Hoàn thành kế hoạch viếng thăm, gọi điện các NCC. | G26: 0.9 | L26: 0.95 | Q26: =IF(L26=0,0,L26/G26) -> 1.0555556 | R26: =IF(Q26>=90%,500000,0) -> 500000
F27: NCC Mới | G27: 0 | L27: =IF(E25="GS",SUMIFS(Table4[Đếm],Table4[Giám sát],'Thị trường'!C25),SUMIFS(Table4[Đếm],Table4[Nhân viên],'Thị trường'!C25)) -> 4 | Q27: =IFERROR((L9/G9),0) -> 0 | R27: =IF(L27>0,500000,0) -> 500000
A28: 9 | B28: 90026395 | C28: Bùi Vũ Thanh Huy | D28: Nhân viên mua hàng thị trường | E28: NV | F28: Sản lượng tất cả sản phẩm rPET, rHDPE, rPP | G28: =SUM(H28:K28) -> 2420 | H28: =IF(E28="GS",SUMIFS(Chitieu[Chỉ tiêu],Chitieu[GS],'Thị trường'!C28,Chitieu[[qui đổi ]],'Thị trường'!$H$3),SUMIFS(Chitieu[Chỉ tiêu],Chitieu[NV],'Thị trường'!C28,Chitieu[[qui đổi ]],'Thị trường'!$H$3)) -> 1900 | I28: =IF(E28="GS",SUMIFS(Chitieu[Chỉ tiêu],Chitieu[GS],'Thị trường'!C28,Chitieu[[qui đổi ]],'Thị trường'!$I$3),SUMIFS(Chitieu[Chỉ tiêu],Chitieu[NV],'Thị trường'!C28,Chitieu[[qui đổi ]],'Thị trường'!$I$3)) -> 40 | J28: =IF(E28="GS",SUMIFS(Chitieu[Chỉ tiêu],Chitieu[GS],'Thị trường'!C28,Chitieu[[qui đổi ]],'Thị trường'!$J$3),SUMIFS(Chitieu[Chỉ tiêu],Chitieu[NV],'Thị trường'!C28,Chitieu[[qui đổi ]],'Thị trường'!$J$3)) -> 480 | K28: =IF(E28="GS",SUMIFS(Chitieu[Chỉ tiêu],Chitieu[GS],'Thị trường'!C28,Chitieu[[qui đổi ]],'Thị trường'!$K$3),SUMIFS(Chitieu[Chỉ tiêu],Chitieu[NV],'Thị trường'!C28,Chitieu[[qui đổi ]],'Thị trường'!$K$3)) -> 0 | L28: =SUM(M28:P28) -> 2818.495 | M28: =IF(E28="GS",SUMIFS(Chitieu[Thực hiện],Chitieu[GS],'Thị trường'!C28,Chitieu[[qui đổi ]],'Thị trường'!$M$3),SUMIFS(Chitieu[Thực hiện],Chitieu[NV],'Thị trường'!C28,Chitieu[[qui đổi ]],'Thị trường'!$M$3)) -> 2362.04 | N28: =IF(E28="GS",SUMIFS(Chitieu[Thực hiện],Chitieu[GS],'Thị trường'!C28,Chitieu[[qui đổi ]],'Thị trường'!$N$3),SUMIFS(Chitieu[Thực hiện],Chitieu[NV],'Thị trường'!C28,Chitieu[[qui đổi ]],'Thị trường'!$N$3)) -> 250.968 | O28: =IF(E28="GS",SUMIFS(Chitieu[Thực hiện],Chitieu[GS],'Thị trường'!C28,Chitieu[[qui đổi ]],'Thị trường'!$O$3),SUMIFS(Chitieu[Thực hiện],Chitieu[NV],'Thị trường'!C28,Chitieu[[qui đổi ]],'Thị trường'!$O$3)) -> 205.487 | P28: =IF(E28="GS",SUMIFS(Chitieu[Thực hiện],Chitieu[GS],'Thị trường'!C28,Chitieu[[qui đổi ]],'Thị trường'!$P$3),SUMIFS(Chitieu[Thực hiện],Chitieu[NV],'Thị trường'!C28,Chitieu[[qui đổi ]],'Thị trường'!$P$3)) -> 0 | Q28: =IFERROR((L28/G28),0) -> 1.1646674 | R28: =IF(AND(Q28>=70%,Q28<=80%),3000000,IF(AND(Q28>80%,Q28<=95%),4000000,IF(AND(Q28>95%,Q28<=100%),6000000,IF(Q28>100%,8000000,0)))) -> 8000000 | S28: =SUM(R28,R29,R30) -> 8500000 | T28: ok
F29: Hoàn thành kế hoạch viếng thăm, gọi điện các NCC. | G29: 0.9 | L29: 0.99 | Q29: =IF(L29=0,0,L29/G29) -> 1.1 | R29: =IF(Q29>=90%,500000,0) -> 500000
F30: NCC Mới | G30: 0 | L30: =IF(E28="GS",SUMIFS(Table4[Đếm],Table4[Giám sát],'Thị trường'!C28),SUMIFS(Table4[Đếm],Table4[Nhân viên],'Thị trường'!C28)) -> 0 | Q30: =IFERROR((L9/G9),0) -> 0 | R30: =IF(L30>0,500000,0) -> 0
A31: 10 | B31: 90024315 | C31: Nguyễn Văn Phú | D31: Nhân viên mua hàng thị trường | E31: NV | F31: Sản lượng tất cả sản phẩm rPET, rHDPE, rPP | G31: =SUM(H31:K31) -> 240 | H31: =IF(E31="GS",SUMIFS(Chitieu[Chỉ tiêu],Chitieu[GS],'Thị trường'!C31,Chitieu[[qui đổi ]],'Thị trường'!$H$3),SUMIFS(Chitieu[Chỉ tiêu],Chitieu[NV],'Thị trường'!C31,Chitieu[[qui đổi ]],'Thị trường'!$H$3)) -> 0 | I31: =IF(E31="GS",SUMIFS(Chitieu[Chỉ tiêu],Chitieu[GS],'Thị trường'!C31,Chitieu[[qui đổi ]],'Thị trường'!$I$3),SUMIFS(Chitieu[Chỉ tiêu],Chitieu[NV],'Thị trường'!C31,Chitieu[[qui đổi ]],'Thị trường'!$I$3)) -> 240 | J31: =IF(E31="GS",SUMIFS(Chitieu[Chỉ tiêu],Chitieu[GS],'Thị trường'!C31,Chitieu[[qui đổi ]],'Thị trường'!$J$3),SUMIFS(Chitieu[Chỉ tiêu],Chitieu[NV],'Thị trường'!C31,Chitieu[[qui đổi ]],'Thị trường'!$J$3)) -> 0 | K31: =IF(E31="GS",SUMIFS(Chitieu[Chỉ tiêu],Chitieu[GS],'Thị trường'!C31,Chitieu[[qui đổi ]],'Thị trường'!$K$3),SUMIFS(Chitieu[Chỉ tiêu],Chitieu[NV],'Thị trường'!C31,Chitieu[[qui đổi ]],'Thị trường'!$K$3)) -> 0 | L31: =SUM(M31:P31) -> 98.027 | M31: =IF(E31="GS",SUMIFS(Chitieu[Thực hiện],Chitieu[GS],'Thị trường'!C31,Chitieu[[qui đổi ]],'Thị trường'!$M$3),SUMIFS(Chitieu[Thực hiện],Chitieu[NV],'Thị trường'!C31,Chitieu[[qui đổi ]],'Thị trường'!$M$3)) -> 0 | N31: =IF(E31="GS",SUMIFS(Chitieu[Thực hiện],Chitieu[GS],'Thị trường'!C31,Chitieu[[qui đổi ]],'Thị trường'!$N$3),SUMIFS(Chitieu[Thực hiện],Chitieu[NV],'Thị trường'!C31,Chitieu[[qui đổi ]],'Thị trường'!$N$3)) -> 66.623 | O31: =IF(E31="GS",SUMIFS(Chitieu[Thực hiện],Chitieu[GS],'Thị trường'!C31,Chitieu[[qui đổi ]],'Thị trường'!$O$3),SUMIFS(Chitieu[Thực hiện],Chitieu[NV],'Thị trường'!C31,Chitieu[[qui đổi ]],'Thị trường'!$O$3)) -> 31.404 | P31: =IF(E31="GS",SUMIFS(Chitieu[Thực hiện],Chitieu[GS],'Thị trường'!C31,Chitieu[[qui đổi ]],'Thị trường'!$P$3),SUMIFS(Chitieu[Thực hiện],Chitieu[NV],'Thị trường'!C31,Chitieu[[qui đổi ]],'Thị trường'!$P$3)) -> 0 | Q31: =IFERROR((L31/G31),0) -> 0.40844583 | R31: =IF(AND(Q31>=70%,Q31<=80%),3000000,IF(AND(Q31>80%,Q31<=95%),4000000,IF(AND(Q31>95%,Q31<=100%),6000000,IF(Q31>100%,8000000,0)))) -> 0 | S31: =SUM(R31,R32,R33) -> 1000000 | T31: ok
F32: Hoàn thành kế hoạch viếng thăm, gọi điện các NCC. | G32: 0.9 | L32: 0.99 | Q32: =IF(L32=0,0,L32/G32) -> 1.1 | R32: =IF(Q32>=90%,500000,0) -> 500000
F33: NCC Mới | G33: 0 | L33: =IF(E31="GS",SUMIFS(Table4[Đếm],Table4[Giám sát],'Thị trường'!C31),SUMIFS(Table4[Đếm],Table4[Nhân viên],'Thị trường'!C31)) -> 1 | Q33: =IFERROR((L33/G33),0) -> 0 | R33: =IF(L33>0,500000,0) -> 500000
A34: 11 | B34: 90024809 | C34: Phan Hiếu Lộc | D34: Nhân viên mua hàng thị trường | E34: NV | F34: Sản lượng tất cả sản phẩm rPET, rHDPE, rPP | G34: =SUM(H34:K34) -> 430 | H34: =IF(E34="GS",SUMIFS(Chitieu[Chỉ tiêu],Chitieu[GS],'Thị trường'!C34,Chitieu[[qui đổi ]],'Thị trường'!$H$3),SUMIFS(Chitieu[Chỉ tiêu],Chitieu[NV],'Thị trường'!C34,Chitieu[[qui đổi ]],'Thị trường'!$H$3)) -> 200 | I34: =IF(E34="GS",SUMIFS(Chitieu[Chỉ tiêu],Chitieu[GS],'Thị trường'!C34,Chitieu[[qui đổi ]],'Thị trường'!$I$3),SUMIFS(Chitieu[Chỉ tiêu],Chitieu[NV],'Thị trường'!C34,Chitieu[[qui đổi ]],'Thị trường'!$I$3)) -> 230 | J34: =IF(E34="GS",SUMIFS(Chitieu[Chỉ tiêu],Chitieu[GS],'Thị trường'!C34,Chitieu[[qui đổi ]],'Thị trường'!$J$3),SUMIFS(Chitieu[Chỉ tiêu],Chitieu[NV],'Thị trường'!C34,Chitieu[[qui đổi ]],'Thị trường'!$J$3)) -> 0 | K34: =IF(E34="GS",SUMIFS(Chitieu[Chỉ tiêu],Chitieu[GS],'Thị trường'!C34,Chitieu[[qui đổi ]],'Thị trường'!$K$3),SUMIFS(Chitieu[Chỉ tiêu],Chitieu[NV],'Thị trường'!C34,Chitieu[[qui đổi ]],'Thị trường'!$K$3)) -> 0 | L34: =SUM(M34:P34) -> 225.927 | M34: =IF(E34="GS",SUMIFS(Chitieu[Thực hiện],Chitieu[GS],'Thị trường'!C34,Chitieu[[qui đổi ]],'Thị trường'!$M$3),SUMIFS(Chitieu[Thực hiện],Chitieu[NV],'Thị trường'!C34,Chitieu[[qui đổi ]],'Thị trường'!$M$3)) -> 0 | N34: =IF(E34="GS",SUMIFS(Chitieu[Thực hiện],Chitieu[GS],'Thị trường'!C34,Chitieu[[qui đổi ]],'Thị trường'!$N$3),SUMIFS(Chitieu[Thực hiện],Chitieu[NV],'Thị trường'!C34,Chitieu[[qui đổi ]],'Thị trường'!$N$3)) -> 225.927 | O34: =IF(E34="GS",SUMIFS(Chitieu[Thực hiện],Chitieu[GS],'Thị trường'!C34,Chitieu[[qui đổi ]],'Thị trường'!$O$3),SUMIFS(Chitieu[Thực hiện],Chitieu[NV],'Thị trường'!C34,Chitieu[[qui đổi ]],'Thị trường'!$O$3)) -> 0 | P34: =IF(E34="GS",SUMIFS(Chitieu[Thực hiện],Chitieu[GS],'Thị trường'!C34,Chitieu[[qui đổi ]],'Thị trường'!$P$3),SUMIFS(Chitieu[Thực hiện],Chitieu[NV],'Thị trường'!C34,Chitieu[[qui đổi ]],'Thị trường'!$P$3)) -> 0 | Q34: =IFERROR((L34/G34),0) -> 0.52541163 | R34: =IF(AND(Q34>=70%,Q34<=80%),3000000,IF(AND(Q34>80%,Q34<=95%),4000000,IF(AND(Q34>95%,Q34<=100%),6000000,IF(Q34>100%,8000000,0)))) -> 0 | S34: =SUM(R34,R35,R36) -> 1000000 | T34: ok
F35: Hoàn thành kế hoạch viếng thăm, gọi điện các NCC. | G35: 0.9 | L35: 1 | Q35: =IF(L35=0,0,L35/G35) -> 1.1111111 | R35: =IF(Q35>=90%,500000,0) -> 500000
F36: NCC Mới | G36: 0 | L36: =IF(E34="GS",SUMIFS(Table4[Đếm],Table4[Giám sát],'Thị trường'!C34),SUMIFS(Table4[Đếm],Table4[Nhân viên],'Thị trường'!C34)) -> 3 | Q36: =IFERROR((L9/G9),0) -> 0 | R36: =IF(L36>0,500000,0) -> 500000
A37: 12 | B37: 90024355 | C37: Dương Quốc Trung | D37: Giám sát mua hàng | E37: GS | F37: Sản lượng tất cả sản phẩm rPET, rHDPE, rPP | G37: =SUM(H37:K37) -> 405 | H37: =IF(E37="GS",SUMIFS(Chitieu[Chỉ tiêu],Chitieu[GS],'Thị trường'!C37,Chitieu[[qui đổi ]],'Thị trường'!$H$3),SUMIFS(Chitieu[Chỉ tiêu],Chitieu[NV],'Thị trường'!C37,Chitieu[[qui đổi ]],'Thị trường'!$H$3)) -> 0 | I37: =IF(E37="GS",SUMIFS(Chitieu[Chỉ tiêu],Chitieu[GS],'Thị trường'!C37,Chitieu[[qui đổi ]],'Thị trường'!$I$3),SUMIFS(Chitieu[Chỉ tiêu],Chitieu[NV],'Thị trường'!C37,Chitieu[[qui đổi ]],'Thị trường'!$I$3)) -> 405 | J37: =IF(E37="GS",SUMIFS(Chitieu[Chỉ tiêu],Chitieu[GS],'Thị trường'!C37,Chitieu[[qui đổi ]],'Thị trường'!$J$3),SUMIFS(Chitieu[Chỉ tiêu],Chitieu[NV],'Thị trường'!C37,Chitieu[[qui đổi ]],'Thị trường'!$J$3)) -> 0 | K37: =IF(E37="GS",SUMIFS(Chitieu[Chỉ tiêu],Chitieu[GS],'Thị trường'!C37,Chitieu[[qui đổi ]],'Thị trường'!$K$3),SUMIFS(Chitieu[Chỉ tiêu],Chitieu[NV],'Thị trường'!C37,Chitieu[[qui đổi ]],'Thị trường'!$K$3)) -> 0 | L37: =SUM(M37:P37) -> 488.321 | M37: =IF(E37="GS",SUMIFS(Chitieu[Thực hiện],Chitieu[GS],'Thị trường'!C37,Chitieu[[qui đổi ]],'Thị trường'!$M$3),SUMIFS(Chitieu[Thực hiện],Chitieu[NV],'Thị trường'!C37,Chitieu[[qui đổi ]],'Thị trường'!$M$3)) -> 0 | N37: =IF(E37="GS",SUMIFS(Chitieu[Thực hiện],Chitieu[GS],'Thị trường'!C37,Chitieu[[qui đổi ]],'Thị trường'!$N$3),SUMIFS(Chitieu[Thực hiện],Chitieu[NV],'Thị trường'!C37,Chitieu[[qui đổi ]],'Thị trường'!$N$3)) -> 488.321 | O37: =IF(E37="GS",SUMIFS(Chitieu[Thực hiện],Chitieu[GS],'Thị trường'!C37,Chitieu[[qui đổi ]],'Thị trường'!$O$3),SUMIFS(Chitieu[Thực hiện],Chitieu[NV],'Thị trường'!C37,Chitieu[[qui đổi ]],'Thị trường'!$O$3)) -> 0 | P37: =IF(E37="GS",SUMIFS(Chitieu[Thực hiện],Chitieu[GS],'Thị trường'!C37,Chitieu[[qui đổi ]],'Thị trường'!$P$3),SUMIFS(Chitieu[Thực hiện],Chitieu[NV],'Thị trường'!C37,Chitieu[[qui đổi ]],'Thị trường'!$P$3)) -> 0 | Q37: =IFERROR((L37/G37),0) -> 1.2057309 | R37: =IF(AND(Q37>=70%,Q37<=80%),4000000,IF(AND(Q37>80%,Q37<=95%),5000000,IF(AND(Q37>95%,Q37<=100%),7000000,IF(Q37>100%,9000000,0)))) -> 9000000 | S37: =SUM(R37,R38,R39) -> 10000000 | T37: ok
F38: Hoàn thành kế hoạch viếng thăm, gọi điện các NCC. | G38: 0.9 | L38: 0.9 | Q38: =IF(L38=0,0,L38/G38) -> 1 | R38: =IF(Q38>=90%,500000,0) -> 500000
F39: NCC Mới | G39: 0 | L39: =IF(E37="GS",SUMIFS(Table4[Đếm],Table4[Giám sát],'Thị trường'!C37),SUMIFS(Table4[Đếm],Table4[Nhân viên],'Thị trường'!C37)) -> 1 | Q39: =IFERROR((L9/G9),0) -> 0 | R39: =IF(L39>0,500000,0) -> 500000
A40: =A37+1 -> 13 | B40: 90028045 | C40: Võ Văn Hảo | D40: Nhân viên mua hàng thị trường | E40: NV | F40: Sản lượng tất cả sản phẩm rPET, rHDPE, rPP | G40: =SUM(H40:K40) -> 70 | H40: =IF(E40="GS",SUMIFS(Chitieu[Chỉ tiêu],Chitieu[GS],'Thị trường'!C40,Chitieu[[qui đổi ]],'Thị trường'!$H$3),SUMIFS(Chitieu[Chỉ tiêu],Chitieu[NV],'Thị trường'!C40,Chitieu[[qui đổi ]],'Thị trường'!$H$3)) -> 0 | I40: =IF(E40="GS",SUMIFS(Chitieu[Chỉ tiêu],Chitieu[GS],'Thị trường'!C40,Chitieu[[qui đổi ]],'Thị trường'!$I$3),SUMIFS(Chitieu[Chỉ tiêu],Chitieu[NV],'Thị trường'!C40,Chitieu[[qui đổi ]],'Thị trường'!$I$3)) -> 70 | J40: =IF(E40="GS",SUMIFS(Chitieu[Chỉ tiêu],Chitieu[GS],'Thị trường'!C40,Chitieu[[qui đổi ]],'Thị trường'!$J$3),SUMIFS(Chitieu[Chỉ tiêu],Chitieu[NV],'Thị trường'!C40,Chitieu[[qui đổi ]],'Thị trường'!$J$3)) -> 0 | K40: =IF(E40="GS",SUMIFS(Chitieu[Chỉ tiêu],Chitieu[GS],'Thị trường'!C40,Chitieu[[qui đổi ]],'Thị trường'!$K$3),SUMIFS(Chitieu[Chỉ tiêu],Chitieu[NV],'Thị trường'!C40,Chitieu[[qui đổi ]],'Thị trường'!$K$3)) -> 0 | L40: =SUM(M40:P40) -> 63.267 | M40: =IF(E40="GS",SUMIFS(Chitieu[Thực hiện],Chitieu[GS],'Thị trường'!C40,Chitieu[[qui đổi ]],'Thị trường'!$M$3),SUMIFS(Chitieu[Thực hiện],Chitieu[NV],'Thị trường'!C40,Chitieu[[qui đổi ]],'Thị trường'!$M$3)) -> 0 | N40: =IF(E40="GS",SUMIFS(Chitieu[Thực hiện],Chitieu[GS],'Thị trường'!C40,Chitieu[[qui đổi ]],'Thị trường'!$N$3),SUMIFS(Chitieu[Thực hiện],Chitieu[NV],'Thị trường'!C40,Chitieu[[qui đổi ]],'Thị trường'!$N$3)) -> 63.267 | O40: =IF(E40="GS",SUMIFS(Chitieu[Thực hiện],Chitieu[GS],'Thị trường'!C40,Chitieu[[qui đổi ]],'Thị trường'!$O$3),SUMIFS(Chitieu[Thực hiện],Chitieu[NV],'Thị trường'!C40,Chitieu[[qui đổi ]],'Thị trường'!$O$3)) -> 0 | P40: =IF(E40="GS",SUMIFS(Chitieu[Thực hiện],Chitieu[GS],'Thị trường'!C40,Chitieu[[qui đổi ]],'Thị trường'!$P$3),SUMIFS(Chitieu[Thực hiện],Chitieu[NV],'Thị trường'!C40,Chitieu[[qui đổi ]],'Thị trường'!$P$3)) -> 0 | Q40: =IFERROR((L40/G40),0) -> 0.90381429 | R40: =IF(AND(Q40>=70%,Q40<=80%),3000000,IF(AND(Q40>80%,Q40<=95%),4000000,IF(AND(Q40>95%,Q40<=100%),6000000,IF(Q40>100%,8000000,0)))) -> 4000000 | S40: =SUM(R40,R41,R42) -> 5000000 | T40: ok
...

Sheet Admin_DTR
G1: =G4 -> 6620 | H1: =H4 -> 3000 | I1: =I4 -> 3090 | J1: =J4 -> 530 | K1: =K4 -> 0 | L1: =L4 -> 5762.3398 | M1: =M4 -> 2544.518 | N1: =N4 -> 2974.3168 | ... P1: =P4 -> 0 | Q1: =L1/G1 -> 0.87044408
A2: ='Thị trường'!A2 -> KPI TÍNH LƯƠNG THÁNG 05/2026 | G2: Chỉ tiêu | L2: Thực đạt
A3: STT | B3: Mã nhân viên | C3: Họ và tên | D3: Chức vụ | E3: CV Kiêm nhiệm | F3: Pis | G3: Tổng | H3: PET vảy | I3: PET chai | J3: HDPE | K3: PP | L3: Tổng | M3: PET vảy | N3: PET chai | O3: HDPE | P3: PP | Q3: % | R3: Thưởng chỉ tiêu | S3: ='Thị trường'!S3 -> KPI T05/2026
A4: 1 | B4: 90026859 | C4: Trương Tường Vy | D4: Kiêm Tổ trưởng Admin | F4: Sản lượng tất cả sản phẩm rPET, rHDPE, rPP | G4: =G5+G10+G15+G20+G25 -> 6620 | H4: =H5+H10+H15+H20+H25 -> 3000 | I4: =I5+I10+I15+I20+I25 -> 3090 | J4: =J5+J10+J15+J20+J25 -> 530 | K4: =K5+K10+K15+K20+K25 -> 0 | L4: =L5+L10+L15+L20+L25 -> 5762.3398 | M4: =M5+M10+M15+M20+M25 -> 2544.518 | N4: =N5+N10+N15+N20+N25 -> 2974.3168 | ... P4: =P5+P10+P15+P20+P25 -> 0 | Q4: =L4/G4 -> 0.87044408 | R4: =IF(AND(Q4>70%,Q4<=80%),1000000,IF(AND(Q4>80%,Q4<=90%),1500000,IF(Q4>90%,2000000,0))) -> 1500000 | S4: =R4 -> 1500000
A5: =A4+1 -> 2 | B5: 90024840 | C5: Phạm Thị Thúy Duy | D5: Admin DTR | F5: Sản lượng tất cả sản phẩm rPET, rHDPE, rPP | G5: =SUM(H5:K5) -> 1915 | H5: =SUMIFS(Chitieu[Chỉ tiêu],Chitieu[[qui đổi ]],Admin_DTR!H$3,Chitieu[Admin Miền],Admin_DTR!$C5) -> 200 | I5: =SUMIFS(Chitieu[Chỉ tiêu],Chitieu[[qui đổi ]],Admin_DTR!I$3,Chitieu[Admin Miền],Admin_DTR!$C5) -> 1665 | J5: =SUMIFS(Chitieu[Chỉ tiêu],Chitieu[[qui đổi ]],Admin_DTR!J$3,Chitieu[Admin Miền],Admin_DTR!$C5) -> 50 | K5: =SUMIFS(Chitieu[Chỉ tiêu],Chitieu[[qui đổi ]],Admin_DTR!K$3,Chitieu[Admin Miền],Admin_DTR!$C5) -> 0 | L5: =SUM(M5:P5) -> 1611.394 | M5: =SUMIFS(Chitieu[Thực hiện],Chitieu[[qui đổi ]],Admin_DTR!$M$3,Chitieu[Admin Miền],Admin_DTR!C5) -> 94.354 | N5: =SUMIFS(Chitieu[Thực hiện],Chitieu[[qui đổi ]],Admin_DTR!$N$3,Chitieu[Admin Miền],Admin_DTR!C5) -> 1513.514 | O5: =SUMIFS(Chitieu[Thực hiện],Chitieu[[qui đổi ]],Admin_DTR!$O$3,Chitieu[Admin Miền],Admin_DTR!C5) -> 3.526 | P5: =SUMIFS(Chitieu[Thực hiện],Chitieu[[qui đổi ]],Admin_DTR!$P$3,Chitieu[Admin Miền],Admin_DTR!C5) -> 0 | Q5: =L5/G5 -> 0.84145901 | R5: =IF(AND(Q5>70%,Q5<=80%),1000000,IF(AND(Q5>80%,Q5<=90%),1500000,IF(Q5>90%,2000000,0))) -> 1500000 | S5: =SUM(R5:R9) -> 2366666.7
F6: Ký kết PO đạt 90% | G6: 6 | H6: =SUMIFS('Chỉ tiêu'!$P:$P,'Chỉ tiêu'!$B:$B,Admin_DTR!$C5,'Chỉ tiêu'!$H:$H,Admin_DTR!H$3) -> 0 | I6: =SUMIFS('Chỉ tiêu'!$P:$P,'Chỉ tiêu'!$B:$B,Admin_DTR!$C5,'Chỉ tiêu'!$H:$H,Admin_DTR!I$3) -> 0 | J6: =SUMIFS('Chỉ tiêu'!$P:$P,'Chỉ tiêu'!$B:$B,Admin_DTR!$C5,'Chỉ tiêu'!$H:$H,Admin_DTR!J$3) -> 0 | K6: =SUMIFS('Chỉ tiêu'!$P:$P,'Chỉ tiêu'!$B:$B,Admin_DTR!$C5,'Chỉ tiêu'!$H:$H,Admin_DTR!K$3) -> 0 | L6: 6 | M6: =SUMIFS('Chỉ tiêu'!$N:$N,'Chỉ tiêu'!$B:$B,Admin_DTR!$C5,'Chỉ tiêu'!$H:$H,Admin_DTR!M$3) -> 0 | N6: =SUMIFS('Chỉ tiêu'!$N:$N,'Chỉ tiêu'!$B:$B,Admin_DTR!$C5,'Chỉ tiêu'!$H:$H,Admin_DTR!N$3) -> 0 | O6: =SUMIFS('Chỉ tiêu'!$N:$N,'Chỉ tiêu'!$B:$B,Admin_DTR!$C5,'Chỉ tiêu'!$H:$H,Admin_DTR!O$3) -> 0 | P6: =SUMIFS('Chỉ tiêu'!$N:$N,'Chỉ tiêu'!$B:$B,Admin_DTR!$C5,'Chỉ tiêu'!$H:$H,Admin_DTR!P$3) -> 0 | Q6: =L6/G6 -> 1 | R6: =Q6*'CS Admin'!$C$21 -> 400000
F7: PO ký thấp hơn giá duyệt | G7: =G6 -> 6 | H7: =H6 -> 0 | I7: =I6 -> 0 | J7: =J6 -> 0 | K7: =K6 -> 0 | L7: 2 | M7: =SUMIFS('Giá mua'!$J:$J,'Giá mua'!$E:$E,Admin_DTR!M$3,'Giá mua'!$A:$A,Admin_DTR!$C5) -> 1 | N7: =SUMIFS('Giá mua'!$J:$J,'Giá mua'!$E:$E,Admin_DTR!N$3,'Giá mua'!$A:$A,Admin_DTR!$C5) -> 0 | O7: =SUMIFS('Giá mua'!$J:$J,'Giá mua'!$E:$E,Admin_DTR!O$3,'Giá mua'!$A:$A,Admin_DTR!$C5) -> 1 | P7: =SUMIFS('Giá mua'!$J:$J,'Giá mua'!$E:$E,Admin_DTR!P$3,'Giá mua'!$A:$A,Admin_DTR!$C5) -> 0 | Q7: =IFERROR((L7/G7),0) -> 0.33333333 | R7: =Q7*'CS Admin'!$C$23 -> 66666.667
F8: Báo cáo | G8: 4 | L8: 4 | Q8: =L8/G8 -> 1 | R8: 200000
F9: Khiếu nại NCC | G9: 1 | L9: 0 | Q9: =L9/G9 -> 0 | R9: 200000
A10: =A5+1 -> 3 | B10: 90027474 | C10: Nguyễn Hoàng Thúy KN | D10: Admin DTR | F10: Sản lượng tất cả sản phẩm rPET, rHDPE, rPP | G10: =SUM(H10:K10) -> 865 | H10: =SUMIFS(Chitieu[Chỉ tiêu],Chitieu[[qui đổi ]],Admin_DTR!H$3,Chitieu[Admin Miền],Admin_DTR!$C10) -> 0 | I10: =SUMIFS(Chitieu[Chỉ tiêu],Chitieu[[qui đổi ]],Admin_DTR!I$3,Chitieu[Admin Miền],Admin_DTR!$C10) -> 865 | J10: =SUMIFS(Chitieu[Chỉ tiêu],Chitieu[[qui đổi ]],Admin_DTR!J$3,Chitieu[Admin Miền],Admin_DTR!$C10) -> 0 | K10: =SUMIFS(Chitieu[Chỉ tiêu],Chitieu[[qui đổi ]],Admin_DTR!K$3,Chitieu[Admin Miền],Admin_DTR!$C10) -> 0 | L10: =SUM(M10:P10) -> 871.852 | M10: =SUMIFS(Chitieu[Thực hiện],Chitieu[[qui đổi ]],Admin_DTR!$M$3,Chitieu[Admin Miền],Admin_DTR!C10) -> 0 | N10: =SUMIFS(Chitieu[Thực hiện],Chitieu[[qui đổi ]],Admin_DTR!$N$3,Chitieu[Admin Miền],Admin_DTR!C10) -> 868.764 | O10: =SUMIFS(Chitieu[Thực hiện],Chitieu[[qui đổi ]],Admin_DTR!$O$3,Chitieu[Admin Miền],Admin_DTR!C10) -> 3.088 | P10: =SUMIFS(Chitieu[Thực hiện],Chitieu[[qui đổi ]],Admin_DTR!$P$3,Chitieu[Admin Miền],Admin_DTR!C10) -> 0 | Q10: =L10/G10 -> 1.0079214 | R10: =IF(AND(Q10>70%,Q10<=80%),1000000,IF(AND(Q10>80%,Q10<=90%),1500000,IF(Q10>90%,2000000,0))) -> 2000000 | S10: =SUM(R10:R14) -> 2400000
F11: Ký kết PO đạt 90% | G11: 0 | H11: =SUMIFS('Chỉ tiêu'!$P:$P,'Chỉ tiêu'!$B:$B,Admin_DTR!$C10,'Chỉ tiêu'!$H:$H,Admin_DTR!H$3) -> 0 | I11: =SUMIFS('Chỉ tiêu'!$P:$P,'Chỉ tiêu'!$B:$B,Admin_DTR!$C10,'Chỉ tiêu'!$H:$H,Admin_DTR!I$3) -> 0 | J11: =SUMIFS('Chỉ tiêu'!$P:$P,'Chỉ tiêu'!$B:$B,Admin_DTR!$C10,'Chỉ tiêu'!$H:$H,Admin_DTR!J$3) -> 0 | K11: =SUMIFS('Chỉ tiêu'!$P:$P,'Chỉ tiêu'!$B:$B,Admin_DTR!$C10,'Chỉ tiêu'!$H:$H,Admin_DTR!K$3) -> 0 | L11: 0 | M11: =SUMIFS('Chỉ tiêu'!$N:$N,'Chỉ tiêu'!$B:$B,Admin_DTR!$C10,'Chỉ tiêu'!$H:$H,Admin_DTR!M$3) -> 0 | N11: =SUMIFS('Chỉ tiêu'!$N:$N,'Chỉ tiêu'!$B:$B,Admin_DTR!$C10,'Chỉ tiêu'!$H:$H,Admin_DTR!N$3) -> 0 | O11: =SUMIFS('Chỉ tiêu'!$N:$N,'Chỉ tiêu'!$B:$B,Admin_DTR!$C10,'Chỉ tiêu'!$H:$H,Admin_DTR!O$3) -> 0 | P11: =SUMIFS('Chỉ tiêu'!$N:$N,'Chỉ tiêu'!$B:$B,Admin_DTR!$C10,'Chỉ tiêu'!$H:$H,Admin_DTR!P$3) -> 0 | Q11: =IFERROR(L11/G101,0) -> 0 | R11: =Q11*'CS Admin'!$C$21 -> 0
F12: PO ký thấp hơn giá duyệt | G12: 0 | H12: =H11 -> 0 | I12: =I11 -> 0 | J12: =J11 -> 0 | K12: =K11 -> 0 | L12: 0 | M12: =SUMIFS('Giá mua'!$J:$J,'Giá mua'!$E:$E,Admin_DTR!M$3,'Giá mua'!$A:$A,Admin_DTR!$C10) -> 0 | N12: =SUMIFS('Giá mua'!$J:$J,'Giá mua'!$E:$E,Admin_DTR!N$3,'Giá mua'!$A:$A,Admin_DTR!$C10) -> 0 | O12: =SUMIFS('Giá mua'!$J:$J,'Giá mua'!$E:$E,Admin_DTR!O$3,'Giá mua'!$A:$A,Admin_DTR!$C10) -> 0 | P12: =SUMIFS('Giá mua'!$J:$J,'Giá mua'!$E:$E,Admin_DTR!P$3,'Giá mua'!$A:$A,Admin_DTR!$C10) -> 0 | Q12: =IFERROR((L12/G12),0) -> 0 | R12: =Q12*'CS Admin'!$C$23 -> 0
F13: Báo cáo | G13: 4 | L13: 4 | Q13: =L13/G13 -> 1 | R13: 200000
F14: Khiếu nại NCC | G14: 1 | L14: 0 | Q14: =L14/G14 -> 0 | R14: 200000
A15: =A10+1 -> 4 | B15: 90027474 | C15: Nguyễn Hoàng Thúy | D15: Admin DTR | F15: Sản lượng tất cả sản phẩm rPET, rHDPE, rPP | G15: =SUM(H15:K15) -> 3060 | H15: =SUMIFS(Chitieu[Chỉ tiêu],Chitieu[[qui đổi ]],Admin_DTR!H$3,Chitieu[Admin Miền],Admin_DTR!$C15) -> 2100 | I15: =SUMIFS(Chitieu[Chỉ tiêu],Chitieu[[qui đổi ]],Admin_DTR!I$3,Chitieu[Admin Miền],Admin_DTR!$C15) -> 510 | J15: =SUMIFS(Chitieu[Chỉ tiêu],Chitieu[[qui đổi ]],Admin_DTR!J$3,Chitieu[Admin Miền],Admin_DTR!$C15) -> 450 | K15: =SUMIFS(Chitieu[Chỉ tiêu],Chitieu[[qui đổi ]],Admin_DTR!K$3,Chitieu[Admin Miền],Admin_DTR!$C15) -> 0 | L15: =SUM(M15:P15) -> 3132.789 | M15: =SUMIFS(Chitieu[Thực hiện],Chitieu[[qui đổi ]],Admin_DTR!$M$3,Chitieu[Admin Miền],Admin_DTR!C15) -> 2362.04 | N15: =SUMIFS(Chitieu[Thực hiện],Chitieu[[qui đổi ]],Admin_DTR!$N$3,Chitieu[Admin Miền],Admin_DTR!C15) -> 543.518 | O15: =SUMIFS(Chitieu[Thực hiện],Chitieu[[qui đổi ]],Admin_DTR!$O$3,Chitieu[Admin Miền],Admin_DTR!C15) -> 227.231 | P15: =SUMIFS(Chitieu[Thực hiện],Chitieu[[qui đổi ]],Admin_DTR!$P$3,Chitieu[Admin Miền],Admin_DTR!C15) -> 0 | Q15: =L15/G15 -> 1.0237873 | R15: =IF(AND(Q15>70%,Q15<=80%),1000000,IF(AND(Q15>80%,Q15<=90%),1500000,IF(Q15>90%,2000000,0))) -> 2000000 | S15: =SUM(R15:R19) -> 3000000
F16: Ký kết PO đạt 90% | G16: 5 | H16: =SUMIFS('Chỉ tiêu'!$P:$P,'Chỉ tiêu'!$B:$B,Admin_DTR!$C15,'Chỉ tiêu'!$H:$H,Admin_DTR!H$3) -> 0 | I16: =SUMIFS('Chỉ tiêu'!$P:$P,'Chỉ tiêu'!$B:$B,Admin_DTR!$C15,'Chỉ tiêu'!$H:$H,Admin_DTR!I$3) -> 0 | J16: =SUMIFS('Chỉ tiêu'!$P:$P,'Chỉ tiêu'!$B:$B,Admin_DTR!$C15,'Chỉ tiêu'!$H:$H,Admin_DTR!J$3) -> 0 | K16: =SUMIFS('Chỉ tiêu'!$P:$P,'Chỉ tiêu'!$B:$B,Admin_DTR!$C15,'Chỉ tiêu'!$H:$H,Admin_DTR!K$3) -> 0 | L16: 5 | M16: =SUMIFS('Chỉ tiêu'!$N:$N,'Chỉ tiêu'!$B:$B,Admin_DTR!$C15,'Chỉ tiêu'!$H:$H,Admin_DTR!M$3) -> 0 | N16: =SUMIFS('Chỉ tiêu'!$N:$N,'Chỉ tiêu'!$B:$B,Admin_DTR!$C15,'Chỉ tiêu'!$H:$H,Admin_DTR!N$3) -> 0 | O16: =SUMIFS('Chỉ tiêu'!$N:$N,'Chỉ tiêu'!$B:$B,Admin_DTR!$C15,'Chỉ tiêu'!$H:$H,Admin_DTR!O$3) -> 0 | P16: =SUMIFS('Chỉ tiêu'!$N:$N,'Chỉ tiêu'!$B:$B,Admin_DTR!$C15,'Chỉ tiêu'!$H:$H,Admin_DTR!P$3) -> 0 | Q16: =L16/G16 -> 1 | R16: =Q16*'CS Admin'!$C$21 -> 400000
F17: PO ký thấp hơn giá duyệt | G17: =G16 -> 5 | H17: =H16 -> 0 | I17: =I16 -> 0 | J17: =J16 -> 0 | K17: =K16 -> 0 | L17: 5 | M17: =SUMIFS('Giá mua'!$J:$J,'Giá mua'!$E:$E,Admin_DTR!M$3,'Giá mua'!$A:$A,Admin_DTR!$C15) -> 0 | N17: =SUMIFS('Giá mua'!$J:$J,'Giá mua'!$E:$E,Admin_DTR!N$3,'Giá mua'!$A:$A,Admin_DTR!$C15) -> 0 | O17: =SUMIFS('Giá mua'!$J:$J,'Giá mua'!$E:$E,Admin_DTR!O$3,'Giá mua'!$A:$A,Admin_DTR!$C15) -> 0 | P17: =SUMIFS('Giá mua'!$J:$J,'Giá mua'!$E:$E,Admin_DTR!P$3,'Giá mua'!$A:$A,Admin_DTR!$C15) -> 0 | Q17: =IFERROR((L17/G17),0) -> 1 | R17: =Q17*'CS Admin'!$C$23 -> 200000
F18: Báo cáo | G18: 4 | L18: 4 | Q18: =L18/G18 -> 1 | R18: 200000
F19: Khiếu nại NCC | G19: 1 | L19: 0 | Q19: =L19/G19 -> 0 | R19: 200000
A20: =A15+1 -> 5 | B20: 90026248 | C20: Trần Dương Quang Ngọc Linh | D20: Admin DTR | F20: Sản lượng tất cả sản phẩm rPET, rHDPE, rPP | G20: =SUM(H20:K20) -> 80 | H20: =SUMIFS(Chitieu[Chỉ tiêu],Chitieu[[qui đổi ]],Admin_DTR!H$3,Chitieu[Admin Miền],Admin_DTR!$C20) -> 0 | I20: =SUMIFS(Chitieu[Chỉ tiêu],Chitieu[[qui đổi ]],Admin_DTR!I$3,Chitieu[Admin Miền],Admin_DTR!$C20) -> 50 | J20: =SUMIFS(Chitieu[Chỉ tiêu],Chitieu[[qui đổi ]],Admin_DTR!J$3,Chitieu[Admin Miền],Admin_DTR!$C20) -> 30 | K20: =SUMIFS(Chitieu[Chỉ tiêu],Chitieu[[qui đổi ]],Admin_DTR!K$3,Chitieu[Admin Miền],Admin_DTR!$C20) -> 0 | L20: =SUM(M20:P20) -> 58.1808 | M20: =SUMIFS(Chitieu[Thực hiện],Chitieu[[qui đổi ]],Admin_DTR!$M$3,Chitieu[Admin Miền],Admin_DTR!C20) -> 0 | N20: =SUMIFS(Chitieu[Thực hiện],Chitieu[[qui đổi ]],Admin_DTR!$N$3,Chitieu[Admin Miền],Admin_DTR!C20) -> 48.5208 | O20: =SUMIFS(Chitieu[Thực hiện],Chitieu[[qui đổi ]],Admin_DTR!$O$3,Chitieu[Admin Miền],Admin_DTR!C20) -> 9.66 | P20: =SUMIFS(Chitieu[Thực hiện],Chitieu[[qui đổi ]],Admin_DTR!$P$3,Chitieu[Admin Miền],Admin_DTR!C20) -> 0 | Q20: =L20/G20 -> 0.72726 | R20: =IF(AND(Q20>70%,Q20<=80%),1000000,IF(AND(Q20>80%,Q20<=90%),1500000,IF(Q20>90%,2000000,0))) -> 1000000 | S20: =SUM(R20:R24) -> 1800000
F21: Ký kết PO đạt 90% | G21: 2 | H21: =SUMIFS('Chỉ tiêu'!$P:$P,'Chỉ tiêu'!$B:$B,Admin_DTR!$C20,'Chỉ tiêu'!$H:$H,Admin_DTR!H$3) -> 0 | I21: =SUMIFS('Chỉ tiêu'!$P:$P,'Chỉ tiêu'!$B:$B,Admin_DTR!$C20,'Chỉ tiêu'!$H:$H,Admin_DTR!I$3) -> 0 | J21: =SUMIFS('Chỉ tiêu'!$P:$P,'Chỉ tiêu'!$B:$B,Admin_DTR!$C20,'Chỉ tiêu'!$H:$H,Admin_DTR!J$3) -> 0 | K21: =SUMIFS('Chỉ tiêu'!$P:$P,'Chỉ tiêu'!$B:$B,Admin_DTR!$C20,'Chỉ tiêu'!$H:$H,Admin_DTR!K$3) -> 0 | L21: 2 | M21: =SUMIFS('Chỉ tiêu'!$N:$N,'Chỉ tiêu'!$B:$B,Admin_DTR!$C20,'Chỉ tiêu'!$H:$H,Admin_DTR!M$3) -> 0 | N21: =SUMIFS('Chỉ tiêu'!$N:$N,'Chỉ tiêu'!$B:$B,Admin_DTR!$C20,'Chỉ tiêu'!$H:$H,Admin_DTR!N$3) -> 0 | O21: =SUMIFS('Chỉ tiêu'!$N:$N,'Chỉ tiêu'!$B:$B,Admin_DTR!$C20,'Chỉ tiêu'!$H:$H,Admin_DTR!O$3) -> 0 | P21: =SUMIFS('Chỉ tiêu'!$N:$N,'Chỉ tiêu'!$B:$B,Admin_DTR!$C20,'Chỉ tiêu'!$H:$H,Admin_DTR!P$3) -> 0 | Q21: =L21/G21 -> 1 | R21: =Q21*'CS Admin'!$C$21 -> 400000
F22: PO ký thấp hơn giá duyệt | G22: =SUM(H22:K22) -> 0 | H22: =H21 -> 0 | I22: =I21 -> 0 | J22: =J21 -> 0 | K22: =K21 -> 0 | L22: 0 | M22: =SUMIFS('Giá mua'!$J:$J,'Giá mua'!$E:$E,Admin_DTR!M$3,'Giá mua'!$A:$A,Admin_DTR!$C20) -> 0 | N22: =SUMIFS('Giá mua'!$J:$J,'Giá mua'!$E:$E,Admin_DTR!N$3,'Giá mua'!$A:$A,Admin_DTR!$C20) -> 0 | O22: =SUMIFS('Giá mua'!$J:$J,'Giá mua'!$E:$E,Admin_DTR!O$3,'Giá mua'!$A:$A,Admin_DTR!$C20) -> 0 | P22: =SUMIFS('Giá mua'!$J:$J,'Giá mua'!$E:$E,Admin_DTR!P$3,'Giá mua'!$A:$A,Admin_DTR!$C20) -> 0 | Q22: =IFERROR((L22/G22),0) -> 0 | R22: =Q22*'CS Admin'!$C$23 -> 0
F23: Báo cáo | G23: 4 | L23: 4 | Q23: =L23/G23 -> 1 | R23: 200000
F24: Khiếu nại NCC | G24: 1 | L24: 0 | Q24: =IF(L24=0,0,L24/G24) -> 0 | R24: 200000
A25: =A20+1 -> 6 | C25: Từ Thị Yến Oanh | D25: Trưởng phòng điều phối | F25: Sản lượng tất cả sản phẩm rPET, rHDPE, rPP | G25: =SUM(H25:K25) -> 700 | H25: =SUMIFS(Chitieu[Chỉ tiêu],Chitieu[[qui đổi ]],Admin_DTR!H$3,Chitieu[Admin Miền],Admin_DTR!$C25) -> 700 | I25: =SUMIFS(Chitieu[Chỉ tiêu],Chitieu[[qui đổi ]],Admin_DTR!I$3,Chitieu[Admin Miền],Admin_DTR!$C25) -> 0 | J25: =SUMIFS(Chitieu[Chỉ tiêu],Chitieu[[qui đổi ]],Admin_DTR!J$3,Chitieu[Admin Miền],Admin_DTR!$C25) -> 0 | K25: =SUMIFS(Chitieu[Chỉ tiêu],Chitieu[[qui đổi ]],Admin_DTR!K$3,Chitieu[Admin Miền],Admin_DTR!$C25) -> 0 | L25: =SUM(M25:P25) -> 88.124 | M25: =SUMIFS(Chitieu[Thực hiện],Chitieu[[qui đổi ]],Admin_DTR!$M$3,Chitieu[Admin Miền],Admin_DTR!C25) -> 88.124 | N25: =SUMIFS(Chitieu[Thực hiện],Chitieu[[qui đổi ]],Admin_DTR!$N$3,Chitieu[Admin Miền],Admin_DTR!C25) -> 0 | O25: =SUMIFS(Chitieu[Thực hiện],Chitieu[[qui đổi ]],Admin_DTR!$O$3,Chitieu[Admin Miền],Admin_DTR!C25) -> 0 | P25: =SUMIFS(Chitieu[Thực hiện],Chitieu[[qui đổi ]],Admin_DTR!$P$3,Chitieu[Admin Miền],Admin_DTR!C25) -> 0 | Q25: =L25/G25 -> 0.12589143 | S25: =SUM(R25:R29) -> 0
F26: Ký kết PO đạt 90% | G26: =SUM(H26:K26) -> 0 | H26: =SUMIFS('Chỉ tiêu'!$P:$P,'Chỉ tiêu'!$B:$B,Admin_DTR!$C25,'Chỉ tiêu'!$H:$H,Admin_DTR!H$3) -> 0 | I26: =SUMIFS('Chỉ tiêu'!$P:$P,'Chỉ tiêu'!$B:$B,Admin_DTR!$C25,'Chỉ tiêu'!$H:$H,Admin_DTR!I$3) -> 0 | J26: =SUMIFS('Chỉ tiêu'!$P:$P,'Chỉ tiêu'!$B:$B,Admin_DTR!$C25,'Chỉ tiêu'!$H:$H,Admin_DTR!J$3) -> 0 | K26: =SUMIFS('Chỉ tiêu'!$P:$P,'Chỉ tiêu'!$B:$B,Admin_DTR!$C25,'Chỉ tiêu'!$H:$H,Admin_DTR!K$3) -> 0 | L26: =SUM(M26:P26) -> 0 | M26: =SUMIFS('Chỉ tiêu'!$N:$N,'Chỉ tiêu'!$B:$B,Admin_DTR!$C25,'Chỉ tiêu'!$H:$H,Admin_DTR!M$3) -> 0 | N26: =SUMIFS('Chỉ tiêu'!$N:$N,'Chỉ tiêu'!$B:$B,Admin_DTR!$C25,'Chỉ tiêu'!$H:$H,Admin_DTR!N$3) -> 0 | O26: =SUMIFS('Chỉ tiêu'!$N:$N,'Chỉ tiêu'!$B:$B,Admin_DTR!$C25,'Chỉ tiêu'!$H:$H,Admin_DTR!O$3) -> 0 | P26: =SUMIFS('Chỉ tiêu'!$N:$N,'Chỉ tiêu'!$B:$B,Admin_DTR!$C25,'Chỉ tiêu'!$H:$H,Admin_DTR!P$3) -> 0 | Q26: =L26/G26 -> #DIV/0!
F27: PO ký thấp hơn giá duyệt | G27: 12 | H27: =H26 -> 0 | I27: =I26 -> 0 | J27: =J26 -> 0 | K27: =K26 -> 0 | M27: =SUMIFS('Giá mua'!$J:$J,'Giá mua'!$E:$E,Admin_DTR!M$3,'Giá mua'!$A:$A,Admin_DTR!$C25) -> 0 | N27: =SUMIFS('Giá mua'!$J:$J,'Giá mua'!$E:$E,Admin_DTR!N$3,'Giá mua'!$A:$A,Admin_DTR!$C25) -> 0 | O27: =SUMIFS('Giá mua'!$J:$J,'Giá mua'!$E:$E,Admin_DTR!O$3,'Giá mua'!$A:$A,Admin_DTR!$C25) -> 0 | P27: =SUMIFS('Giá mua'!$J:$J,'Giá mua'!$E:$E,Admin_DTR!P$3,'Giá mua'!$A:$A,Admin_DTR!$C25) -> 0 | Q27: =IFERROR((L27/G27),0) -> 0
F28: Báo cáo | G28: 4 | Q28: =L28/G28 -> 0
F29: Khiếu nại NCC | G29: 1 | L29: 0 | Q29: =L29/G29 -> 0
A30: 7 | B30: 90024168 | F30: Sản lượng tất cả sản phẩm rPET, rHDPE, rPP | G30: =SUM(H30:K30) -> #REF! | H30: =SUMIFS('Chỉ tiêu'!$I:$I,'Chỉ tiêu'!$H:$H,Admin_DTR!H$3,'Chỉ tiêu'!#REF!,Admin_DTR!$C30)+H33 -> #REF! | I30: =SUMIFS('Chỉ tiêu'!$I:$I,'Chỉ tiêu'!$H:$H,Admin_DTR!I$3,'Chỉ tiêu'!#REF!,Admin_DTR!$C30)+I33 -> #REF! | J30: =SUMIFS('Chỉ tiêu'!$I:$I,'Chỉ tiêu'!$H:$H,Admin_DTR!J$3,'Chỉ tiêu'!#REF!,Admin_DTR!$C30)+J33 -> #REF! | K30: =SUMIFS('Chỉ tiêu'!$I:$I,'Chỉ tiêu'!$H:$H,Admin_DTR!K$3,'Chỉ tiêu'!#REF!,Admin_DTR!$C30)+K33 -> #REF! | L30: =SUM(M30:P30) -> #REF! | M30: =SUMIFS('Chỉ tiêu'!$K:$K,'Chỉ tiêu'!$H:$H,Admin_DTR!H$3,'Chỉ tiêu'!#REF!,Admin_DTR!$C30)+M33 -> #REF! | N30: =SUMIFS('Chỉ tiêu'!$K:$K,'Chỉ tiêu'!$H:$H,Admin_DTR!I$3,'Chỉ tiêu'!#REF!,Admin_DTR!$C30)+N33 -> #REF! | O30: =SUMIFS('Chỉ tiêu'!$K:$K,'Chỉ tiêu'!$H:$H,Admin_DTR!J$3,'Chỉ tiêu'!#REF!,Admin_DTR!$C30)+O33 -> #REF! | P30: =SUMIFS('Chỉ tiêu'!$K:$K,'Chỉ tiêu'!$H:$H,Admin_DTR!K$3,'Chỉ tiêu'!#REF!,Admin_DTR!$C30)+P33 -> #REF! | Q30: =IFERROR((L30/G30),0) -> 0 | R30: =IF(AND(Q30>70%,Q30<=80%),4000000,IF(Q30>80%,5000000,0)) -> 0 | S30: =SUM(R30,R31,R32) -> 1000000
F31: Hoàn thành kế hoạch viếng thăm, gọi điện các NCC. | G31: 1 | L31: 1 | Q31: =IF(L31=0,0,L31/G31) -> 1 | R31: =IF(Q31>=80%,500000,0) -> 500000
F32: NCC Mới/báo cáo | G32: 4 | L32: 4 | Q32: =IF(L32=0,0,L32/G32) -> 1 | R32: =IF(Q32>=100%,500000,0) -> 500000
A33: 8 | B33: 90026395 | F33: Sản lượng tất cả sản phẩm rPET, rHDPE, rPP | G33: =SUM(H33:K33) -> #REF! | H33: =SUMIFS('Chỉ tiêu'!$I:$I,'Chỉ tiêu'!$H:$H,Admin_DTR!H$3,'Chỉ tiêu'!#REF!,Admin_DTR!$C33) -> #REF! | I33: =SUMIFS('Chỉ tiêu'!$I:$I,'Chỉ tiêu'!$H:$H,Admin_DTR!I$3,'Chỉ tiêu'!#REF!,Admin_DTR!$C33) -> #REF! | J33: =SUMIFS('Chỉ tiêu'!$I:$I,'Chỉ tiêu'!$H:$H,Admin_DTR!J$3,'Chỉ tiêu'!#REF!,Admin_DTR!$C33) -> #REF! | K33: =SUMIFS('Chỉ tiêu'!$I:$I,'Chỉ tiêu'!$H:$H,Admin_DTR!K$3,'Chỉ tiêu'!#REF!,Admin_DTR!$C33) -> #REF! | L33: =SUM(M33:P33) -> #REF! | M33: =SUMIFS('Chỉ tiêu'!$K:$K,'Chỉ tiêu'!$H:$H,Admin_DTR!H$3,'Chỉ tiêu'!#REF!,Admin_DTR!$C33) -> #REF! | N33: =SUMIFS('Chỉ tiêu'!$K:$K,'Chỉ tiêu'!$H:$H,Admin_DTR!I$3,'Chỉ tiêu'!#REF!,Admin_DTR!$C33) -> #REF! | O33: =SUMIFS('Chỉ tiêu'!$K:$K,'Chỉ tiêu'!$H:$H,Admin_DTR!J$3,'Chỉ tiêu'!#REF!,Admin_DTR!$C33) -> #REF! | P33: =SUMIFS('Chỉ tiêu'!$K:$K,'Chỉ tiêu'!$H:$H,Admin_DTR!K$3,'Chỉ tiêu'!#REF!,Admin_DTR!$C33) -> #REF! | Q33: =IFERROR((L33/G33),0) -> 0 | R33: =IF(AND(Q33>70%,Q33<=80%),3000000,IF(Q33>80%,4000000,0)) -> 0 | S33: =SUM(R33,R34,R35) -> 1000000
F34: Hoàn thành kế hoạch viếng thăm, gọi điện các NCC. | G34: 1 | L34: 0.9808 | Q34: =IF(L34=0,0,L34/G34) -> 0.9808 | R34: =IF(Q34>=80%,500000,0) -> 500000
F35: NCC Mới/báo cáo | G35: 4 | L35: 4 | Q35: =IF(L35=0,0,L35/G35) -> 1 | R35: =IF(Q35>=100%,500000,0) -> 500000
A36: 9 | B36: 90026683 | F36: Sản lượng tất cả sản phẩm rPET, rHDPE, rPP | G36: =SUM(H36:K36) -> #REF! | H36: =SUMIFS('Chỉ tiêu'!$I:$I,'Chỉ tiêu'!$H:$H,Admin_DTR!H$3,'Chỉ tiêu'!#REF!,Admin_DTR!$C36)+H39 -> #REF! | I36: =SUMIFS('Chỉ tiêu'!$I:$I,'Chỉ tiêu'!$H:$H,Admin_DTR!I$3,'Chỉ tiêu'!#REF!,Admin_DTR!$C36)+I39 -> #REF! | J36: =SUMIFS('Chỉ tiêu'!$I:$I,'Chỉ tiêu'!$H:$H,Admin_DTR!J$3,'Chỉ tiêu'!#REF!,Admin_DTR!$C36)+J39 -> #REF! | K36: =SUMIFS('Chỉ tiêu'!$I:$I,'Chỉ tiêu'!$H:$H,Admin_DTR!K$3,'Chỉ tiêu'!#REF!,Admin_DTR!$C36)+K39 -> #REF! | L36: =SUM(M36:P36) -> #REF! | M36: =SUMIFS('Chỉ tiêu'!$K:$K,'Chỉ tiêu'!$H:$H,Admin_DTR!H$3,'Chỉ tiêu'!#REF!,Admin_DTR!$C36)+M39 -> #REF! | N36: =SUMIFS('Chỉ tiêu'!$K:$K,'Chỉ tiêu'!$H:$H,Admin_DTR!I$3,'Chỉ tiêu'!#REF!,Admin_DTR!$C36)+N39 -> #REF! | O36: =SUMIFS('Chỉ tiêu'!$K:$K,'Chỉ tiêu'!$H:$H,Admin_DTR!J$3,'Chỉ tiêu'!#REF!,Admin_DTR!$C36)+O39 -> #REF! | P36: =SUMIFS('Chỉ tiêu'!$K:$K,'Chỉ tiêu'!$H:$H,Admin_DTR!K$3,'Chỉ tiêu'!#REF!,Admin_DTR!$C36)+P39 -> #REF! | Q36: =IFERROR((L36/G36),0) -> 0 | R36: =IF(AND(Q36>70%,Q36<=80%),4000000,IF(Q36>80%,5000000,0)) -> 0 | S36: =SUM(R36,R37,R38) -> 1000000
F37: Hoàn thành kế hoạch viếng thăm, gọi điện các NCC. | G37: 1 | L37: 1 | Q37: =IF(L37=0,0,L37/G37) -> 1 | R37: =IF(Q37>=80%,500000,0) -> 500000
F38: NCC Mới/báo cáo | G38: 4 | L38: 4 | Q38: =IF(L38=0,0,L38/G38) -> 1 | R38: =IF(Q38>=100%,500000,0) -> 500000
