Workbook
Name __accountcodevg__X: #REF!
Name __disaccountcode1__X: #REF!
Name __disaccountcode2__X: #REF!
Name __disaccountcode3__X: #REF!
Name __lookup1__X: #REF!
Name __lookup2__X: #REF!
Name __params__: #REF!
Name thang10: #REF!
Name thang12: #REF!

Sheet TH công ngoài giờ
A1: Bộ phận | B1: Giờ công ngoài giờ (CN + Lễ)
B2: 1 | C2: 2 | D2: 3 | E2: 4 | F2: 5 | G2: 6 | H2: 7 | I2: 8 | J2: 9 | K2: 10 | L2: 11 | M2: 12 | N2: Tổng
A3: Kỹ Thuật | B3: ='Chi tiết công ngoài giờ'!E2 -> 72 | C3: ='Chi tiết công ngoài giờ'!E3 -> 312 | D3: ='Chi tiết công ngoài giờ'!E4 -> 36 | E3: ='Chi tiết công ngoài giờ'!E5 -> 280 | F3: ='Chi tiết công ngoài giờ'!E6 -> 419 | G3: ='Chi tiết công ngoài giờ'!E7 -> 0 | H3: ='Chi tiết công ngoài giờ'!E8 -> 0 | I3: ='Chi tiết công ngoài giờ'!E9 -> 0 | J3: ='Chi tiết công ngoài giờ'!E10 -> 0 | K3: ='Chi tiết công ngoài giờ'!E11 -> 0 | L3: ='Chi tiết công ngoài giờ'!E12 -> 0 | M3: ='Chi tiết công ngoài giờ'!E13 -> 0 | N3: =SUM(B3:M3) -> 1119
A4: Xưởng Sản Xuất | D4: ='Chi tiết công ngoài giờ'!E18 -> 99 | F4: ='Chi tiết công ngoài giờ'!E20 -> 452 | J4: ='Chi tiết công ngoài giờ'!E24 -> 0 | N4: =SUM(B4:M4) -> 551
A5: Hành Chánh Nhân Sự | B5: ='Chi tiết công ngoài giờ'!E30 -> 96 | C5: ='Chi tiết công ngoài giờ'!E31 -> 480 | E5: ='Chi tiết công ngoài giờ'!E33 -> 0 | F5: ='Chi tiết công ngoài giờ'!E34 -> 296 | I5: ='Chi tiết công ngoài giờ'!E37 -> 0 | J5: ='Chi tiết công ngoài giờ'!E38 -> 0 | N5: =SUM(B5:M5) -> 872
A6: Kế Toán | F6: ='Chi tiết công ngoài giờ'!E62 -> 52 | H6: ='Chi tiết công ngoài giờ'!E64 -> 0 | J6: ='Chi tiết công ngoài giờ'!E66 -> 0 | N6: =SUM(B6:M6) -> 52
A7: Kiểm Soát Chất Lượng | F7: ='Chi tiết công ngoài giờ'!E48 -> 144 | I7: ='Chi tiết công ngoài giờ'!E51 -> 0 | J7: ='Chi tiết công ngoài giờ'!E52 -> 0 | N7: =SUM(B7:M7) -> 144
A8: Tổng | B8: =SUM(B3:B7) -> 168 | C8: =SUM(C3:C7) -> 792 | D8: =SUM(D3:D7) -> 135 | E8: =SUM(E3:E7) -> 280 | F8: =SUM(F3:F7) -> 1363 | G8: =SUM(G3:G7) -> 0 | H8: =SUM(H3:H7) -> 0 | I8: =SUM(I3:I7) -> 0 | ... M8: =SUM(M3:M7) -> 0 | N8: =SUM(B8:M8) -> 2738

Sheet Lương CN + LỄ
A1: Bộ phận | B1: T1 | D1: T2 | F1: T3 | G1: T4 | I1: T5 | K1: T6 | L1: T7 | M1: T8 | N1: T9 | P1: T10 | Q1: T11 | R1: T12 | S1: Lũy kế
B2: CN | C2: Lễ | D2: CN | E2: Lễ | F2: CN | G2: CN | H2: Lễ | I2: CN | J2: Lễ | K2: CN | L2: CN | M2: CN | N2: CN | O2: Lễ | P2: CN | Q2: CN | R2: CN | S2: CN | T2: Lễ | U2: TỔNG
A3: Kỹ Thuật | C3: 14525795 | D3: 8243523 | E3: 51364720 | F3: 4233072 | G3: 30354669 | I3: 14218595 | J3: 64993683 | S3: =B3+D3+F3+G3+I3+K3+L3+M3+N3+P3+Q3+R3 -> 57049859 | T3: =C3+J3+O3+E3+H3 -> 1.308842e+08 | U3: =S3+T3 -> 1.8793406e+08 | V3: =U3/$U$8 -> 0.47935291
A4: Xưởng Sản Xuất | F4: 5505626 | J4: 53986870 | S4: =B4+D4+F4+G4+I4+K4+L4+M4+N4+P4+Q4+R4 -> 5505626 | T4: =C4+J4+O4+E4+H4 -> 53986870 | U4: =S4+T4 -> 59492496 | V4: =U4/$U$8 -> 0.15174419
A5: Hành Chánh Nhân Sự | C5: 12771562 | E5: 63857808 | I5: 426080 | J5: 38688163 | S5: =B5+D5+F5+G5+I5+K5+L5+M5+N5+P5+Q5+R5 -> 426080 | T5: =C5+J5+O5+E5+H5 -> 1.1531753e+08 | U5: =S5+T5 -> 1.1574361e+08 | V5: =U5/$U$8 -> 0.29522077
A6: Kiểm Soát Chất Lượng | J6: 20597546 | S6: =B6+D6+F6+G6+I6+K6+L6+M6+N6+P6+Q6+R6 -> 0 | T6: =C6+J6+O6+E6+H6 -> 20597546 | U6: =S6+T6 -> 20597546 | V6: =U6/$U$8 -> 0.052537009
A7: Kế Toán | J7: 8290112 | S7: =B7+D7+F7+G7+I7+K7+L7+M7+N7+P7+Q7+R7 -> 0 | T7: =C7+J7+O7+E7+H7 -> 8290112 | U7: =S7+T7 -> 8290112 | V7: =U7/$U$8 -> 0.021145126
A8: Tổng | B8: =SUM(B3:B7) -> 0 | C8: =SUM(C3:C7) -> 27297357 | D8: =SUM(D3:D7) -> 8243523 | E8: =SUM(E3:E7) -> 115222528 | F8: =SUM(F3:F7) -> 9738698 | G8: =SUM(G3:G7) -> 30354669 | H8: =SUM(H3:H7) -> 0 | I8: =SUM(I3:I7) -> 14644675 | ... U8: =SUM(U3:U7) -> 3.9205782e+08
A9: sản lượng TP ( Tấn)
A10: Số tiền/ Tấn | B10: =B8/B9 -> #DIV/0! | C10: =C8/C9 -> #DIV/0! | D10: =D8/D9 -> #DIV/0! | F10: =F8/F9 -> #DIV/0! | G10: =G8/G9 -> #DIV/0! | I10: =I8/I9 -> #DIV/0! | J10: =J8/J9 -> #DIV/0! | K10: =K8/K9 -> #DIV/0! | L10: =L8/L9 -> #DIV/0! | M10: =M8/M9 -> #DIV/0! | N10: =N8/N9 -> #DIV/0! | O10: =O8/O9 -> #DIV/0! | P10: =P8/P9 -> #DIV/0! | ... T10: =T8/T9 -> #DIV/0!
A11: $/tấn | B11: =B10/24000 -> #DIV/0! | C11: =C10/24000 -> #DIV/0! | D11: =D10/24000 -> #DIV/0! | F11: =F10/24000 -> #DIV/0! | G11: =G10/24000 -> #DIV/0! | I11: =I10/24000 -> #DIV/0! | J11: =J10/24000 -> #DIV/0! | K11: =K10/24000 -> #DIV/0! | L11: =L10/24000 -> #DIV/0! | M11: =M10/24000 -> #DIV/0! | N11: =N10/24000 -> #DIV/0! | O11: =O10/24000 -> #DIV/0! | P11: =P10/24000 -> #DIV/0! | ... T11: =T10/24000 -> #DIV/0!

Sheet Chi tiết công ngoài giờ
A1: Tháng | B1: Phòng ban | C1: Giờ công CN | D1: Giờ công lễ | E1: Tổng | G1: Tổng kết | H1: Số giờ công CN | I1: Số giờ công Lễ | J1: Số tiền vượt | K1: Số ngày lễ | L1: Cộng ngày CN + Lễ
A2: 1 | B2: Kỹ Thuật | D2: 72 | E2: =C2+D2 -> 72 | G2: Kỹ Thuật | H2: =C14 -> 531 | I2: =D14 -> 588 | J2: ='Lương CN + LỄ'!U3 -> 1.8793406e+08 | K2: =#REF! -> #REF! | L2: =H2+K2 -> #REF!
A3: 2 | B3: Kỹ Thuật | C3: 72 | D3: 240 | E3: =C3+D3 -> 312 | G3: Xưởng Sản Xuất | H3: =C28 -> 99 | I3: =D28 -> 452 | J3: ='Lương CN + LỄ'!U4 -> 59492496 | K3: =#REF! -> #REF! | L3: =H3+K3 -> #REF!
A4: 3 | B4: Kỹ Thuật | C4: 36 | E4: =C4+D4 -> 36 | G4: Hành Chánh Nhân Sự | H4: =C42 -> 8 | I4: =D42 -> 864 | J4: ='Lương CN + LỄ'!U5 -> 1.1574361e+08 | K4: =#REF! -> #REF! | L4: =H4+K4 -> #REF!
A5: 4 | B5: Kỹ Thuật | C5: 280 | E5: =C5+D5 -> 280 | G5: Kiểm Soát Chất Lượng | H5: =C56 -> 0 | I5: =D56 -> 144 | J5: ='Lương CN + LỄ'!U6 -> 20597546 | K5: =#REF! -> #REF! | L5: =H5+K5 -> #REF!
A6: 5 | B6: Kỹ Thuật | C6: 143 | D6: 276 | E6: =C6+D6 -> 419 | G6: Kế toán | H6: =C70 -> 0 | I6: =D70 -> 52 | J6: ='Lương CN + LỄ'!U7 -> 8290112 | K6: =SUM(K2:K5) -> #REF! | L6: =SUM(L2:L5) -> #REF!
A7: 6 | B7: Kỹ Thuật | E7: =C7+D7 -> 0 | G7: Tổng | H7: =SUM(H2:H6) -> 638 | I7: =SUM(I2:I6) -> 2100 | J7: =SUM(J2:J6) -> 3.9205782e+08
A8: 7 | B8: Kỹ Thuật | E8: =C8+D8 -> 0
A9: 8 | B9: Kỹ Thuật | E9: =C9+D9 -> 0
A10: 9 | B10: Kỹ Thuật | E10: =C10+D10 -> 0
A11: 10 | B11: Kỹ Thuật | E11: =C11+D11 -> 0
A12: 11 | B12: Kỹ Thuật | E12: =C12+D12 -> 0
A13: 12 | B13: Kỹ Thuật | E13: =C13+D13 -> 0
B14: Cộng Phòng kỹ thuật | C14: =SUM(C2:C13) -> 531 | D14: =SUM(D2:D13) -> 588 | E14: =SUM(E2:E13) -> 1119
A16: 1 | B16: Xưởng Sản Xuất | E16: =C16+D16 -> 0
A17: 2 | B17: Xưởng Sản Xuất | E17: =C17+D17 -> 0
A18: 3 | B18: Xưởng Sản Xuất | C18: 99 | E18: =C18+D18 -> 99
A19: 4 | B19: Xưởng Sản Xuất | E19: =C19+D19 -> 0
A20: 5 | B20: Xưởng Sản Xuất | D20: 452 | E20: =C20+D20 -> 452
A21: 6 | B21: Xưởng Sản Xuất | E21: =C21+D21 -> 0
A22: 7 | B22: Xưởng Sản Xuất | E22: =C22+D22 -> 0
A23: 8 | B23: Xưởng Sản Xuất | E23: =C23+D23 -> 0
A24: 9 | B24: Xưởng Sản Xuất | E24: =C24+D24 -> 0
A25: 10 | B25: Xưởng Sản Xuất | E25: =C25+D25 -> 0
A26: 11 | B26: Xưởng Sản Xuất | E26: =C26+D26 -> 0
A27: 12 | B27: Xưởng Sản Xuất | E27: =C27+D27 -> 0
B28: Cộng Xưởng Sản xuất | C28: =SUM(C16:C27) -> 99 | D28: =SUM(D16:D27) -> 452 | E28: =SUM(E16:E27) -> 551
A30: 1 | B30: Hành Chánh Nhân Sự | D30: 96 | E30: =C30+D30 -> 96
A31: 2 | B31: Hành Chánh Nhân Sự | D31: 480 | E31: =C31+D31 -> 480
A32: 3 | B32: Hành Chánh Nhân Sự | E32: =C32+D32 -> 0
A33: 4 | B33: Hành Chánh Nhân Sự | E33: =C33+D33 -> 0
A34: 5 | B34: Hành Chánh Nhân Sự | C34: 8 | D34: 288 | E34: =C34+D34 -> 296
A35: 6 | B35: Hành Chánh Nhân Sự | E35: =C35+D35 -> 0
A36: 7 | B36: Hành Chánh Nhân Sự | E36: =C36+D36 -> 0
A37: 8 | B37: Hành Chánh Nhân Sự | E37: =C37+D37 -> 0
A38: 9 | B38: Hành Chánh Nhân Sự | E38: =C38+D38 -> 0
A39: 10 | B39: Hành Chánh Nhân Sự | E39: =C39+D39 -> 0
A40: 11 | B40: Hành Chánh Nhân Sự | E40: =C40+D40 -> 0
A41: 12 | B41: Hành Chánh Nhân Sự | E41: =C41+D41 -> 0
B42: Cộng HCNS | C42: =SUM(C30:C41) -> 8 | D42: =SUM(D30:D41) -> 864 | E42: =SUM(E30:E41) -> 872
...

Sheet CP thưởng khác
A1: CP thưởng cho NV không tham gia tiệc tất niên
B2: =B5+B7+B10+B14+B19 -> 103200000
A3: Đơn vị | B3: Thưởng khác | C3: KMP | F3: KMP
A4: Công ty Cổ phần Nhựa Tái Chế Duy Tân | B4: 103200000 | F4: 642 | G4: =SUMIFS(B:B,C:C,F4) -> 8100000
A5: Cung Ứng | B5: 2100000 | C5: 642 | F5: 627 | G5: =SUMIFS(B:B,C:C,F5) -> 36300000
A6: Tổ Cung ứng | B6: 2100000 | F6: 622 | G6: =SUMIFS(B:B,C:C,F6) -> 58800000
A7: Hành Chánh Nhân Sự | B7: 6000000 | C7: 642 | G7: =SUM(G4:G6) -> 103200000
A8: Bảo vệ | B8: 3000000
A9: Tổ Tạp Vụ | B9: 3000000
A10: Kiểm Soát Chất Lượng | B10: 7800000 | C10: 627
A11: Tổ chất lượng HDPE | B11: 1500000
A12: Tổ chất lượng PET | B12: 5700000
A13: Tổ Chất Lượng PP | B13: 600000
A14: Kỹ Thuật | B14: 14700000 | C14: 627
A15: Bảo trì | B15: 2400000
A16: Tổ Điện | B16: 1800000
A17: Tổ Nước | B17: 2100000
A18: Tổ Vận Hành | B18: 8400000
A19: Xưởng Sản Xuất | B19: 72600000
A20: Hành Chánh Xưởng HDPE | B20: 600000 | C20: 627
A21: Hành Chánh Xưởng PET | B21: 2700000 | C21: 627
A22: Lái Xe Nâng HDPE | B22: 1800000 | C22: 622
A23: Lái Xe Nâng PET | B23: 8100000 | C23: 622
A24: Tổ Kho | B24: 10500000 | C24: 627
A25: Vận Hành Máy HDPE | B25: 6900000 | C25: 622
A26: Vận Hành Máy PET | B26: 41100000 | C26: 622
A27: Vận Hành Máy PP | B27: 900000 | C27: 622
