Workbook

Sheet 2024-2026
D1: 2026 | E1: 2026 | F1: 2026 | G1: 2026 | H1: 2026 | I1: 2026 | J1: 2026 | K1: 2026 | L1: 2026 | M1: 2026 | P1: 2026 | Q1: 2026 | R1: 2026 | S1: 2026 | T1: 2026 | U1: 2026 | V1: 2026 | W1: 2026 | X1: 2026 | Y1: 2026 | AB1: 2026 | AC1: 2026 | AD1: 2026 | AE1: 2026 | AF1: 2026 | AG1: 2026 | AH1: 2026 | AI1: 2026 | AJ1: 2026 | AK1: 2026 | AN1: 2026 | AO1: 2026 | AP1: 2026 | AQ1: 2026 | AR1: 2026 | AS1: 2026 | AT1: 2026 | AU1: 2026 | AV1: 2026 | AW1: 2026 | AZ1: 2026 | BA1: 2026 | BB1: 2026 | BC1: 2026 | BD1: 2026 | BE1: 2026 | BF1: 2026 | BG1: 2026 | BH1: 2026 | BI1: 2026 | BL1: 2026 | BM1: 2026 | BN1: 2026 | BO1: 2026 | BP1: 2026 | BQ1: 2026 | BR1: 2026 | BS1: 2026 | BT1: 2026 | BU1: 2026 | BX1: 2026 | BY1: 2026 | BZ1: 2026 | CA1: 2026 | CB1: 2026 | CC1: 2026 | CD1: 2026 | CE1: 2026 | CF1: 2026 | CG1: 2026 | CJ1: 2026 | CK1: 2026 | CL1: 2026 | CM1: 2026 | CN1: 2026 | CO1: 2026 | CP1: 2026 | CQ1: 2026 | CR1: 2026 | CS1: 2026 | CV1: 2026 | CW1: 2026 | CX1: 2026 | CY1: 2026 | CZ1: 2026 | DA1: 2026 | DB1: 2026 | DC1: 2026 | DD1: 2026 | DE1: 2026 | DH1: 2026 | DI1: 2026 | DJ1: 2026 | DK1: 2026 | DL1: 2026 | DM1: 2026 | DN1: 2026 | DO1: 2026 | DP1: 2026 | DQ1: 2026 | DT1: 2026 | DU1: 2026 | DV1: 2026 | DW1: 2026 | DX1: 2026 | DY1: 2026 | DZ1: 2026 | EA1: 2026 | EB1: 2026 | EC1: 2026 | EF1: 2026 | EG1: 2026 | EH1: 2026 | EI1: 2026 | EJ1: 2026 | EK1: 2026 | EL1: 2026 | EM1: 2026 | EN1: 2026 | EO1: 2026 | ER1: 2026 | ES1: 2026 | ET1: 2026 | EU1: 2026 | EV1: 2026 | EW1: 2026 | EX1: 2026 | EY1: 2026 | EZ1: 2026 | FA1: 2026
D2: FY | E2: FY | F2: FY | G2: FY | H2: FY | I2: FY | J2: FY | K2: FY | L2: FY | M2: FY | P2: 1 | Q2: 1 | R2: 1 | S2: 1 | T2: 1 | U2: 1 | V2: 1 | W2: 1 | X2: 1 | Y2: 1 | AB2: 2 | AC2: 2 | AD2: 2 | AE2: 2 | AF2: 2 | AG2: 2 | AH2: 2 | AI2: 2 | AJ2: 2 | AK2: 2 | AN2: 3 | AO2: 3 | AP2: 3 | AQ2: 3 | AR2: 3 | AS2: 3 | AT2: 3 | AU2: 3 | AV2: 3 | AW2: 3 | AZ2: 4 | BA2: 4 | BB2: 4 | BC2: 4 | BD2: 4 | BE2: 4 | BF2: 4 | BG2: 4 | BH2: 4 | BI2: 4 | BL2: 5 | BM2: 5 | BN2: 5 | BO2: 5 | BP2: 5 | BQ2: 5 | BR2: 5 | BS2: 5 | BT2: 5 | BU2: 5 | BX2: 6 | BY2: 6 | BZ2: 6 | CA2: 6 | CB2: 6 | CC2: 6 | CD2: 6 | CE2: 6 | CF2: 6 | CG2: 6 | CJ2: 7 | CK2: 7 | CL2: 7 | CM2: 7 | CN2: 7 | CO2: 7 | CP2: 7 | CQ2: 7 | CR2: 7 | CS2: 7 | CV2: 8 | CW2: 8 | CX2: 8 | CY2: 8 | CZ2: 8 | DA2: 8 | DB2: 8 | DC2: 8 | DD2: 8 | DE2: 8 | DH2: 9 | DI2: 9 | DJ2: 9 | DK2: 9 | DL2: 9 | DM2: 9 | DN2: 9 | DO2: 9 | DP2: 9 | DQ2: 9 | DT2: 10 | DU2: 10 | DV2: 10 | DW2: 10 | DX2: 10 | DY2: 10 | DZ2: 10 | EA2: 10 | EB2: 10 | EC2: 10 | EF2: 11 | EG2: 11 | EH2: 11 | EI2: 11 | EJ2: 11 | EK2: 11 | EL2: 11 | EM2: 11 | EN2: 11 | EO2: 11 | ER2: 12 | ES2: 12 | ET2: 12 | EU2: 12 | EV2: 12 | EW2: 12 | EX2: 12 | EY2: 12 | EZ2: 12 | FA2: 12
D3: iSS01084 | E3: iSS01 | F3: WSS01 | G3: WSS02 | H3: WSS03 | I3: iSS01084-PL | J3: iSS01-PL | K3: WSS01-PL | L3: WSS03-PL | M3: Khác | P3: iSS01084 | Q3: iSS01 | R3: WSS01 | S3: WSS02 | T3: WSS03 | U3: iSS01084-PL | V3: iSS01-PL | W3: WSS01-PL | X3: WSS03-PL | Y3: Khác | AB3: iSS01084 | AC3: iSS01 | AD3: WSS01 | AE3: WSS02 | AF3: WSS03 | AG3: iSS01084-PL | AH3: iSS01-PL | AI3: WSS01-PL | AJ3: WSS03-PL | AK3: Khác | AN3: iSS01084 | AO3: iSS01 | AP3: WSS01 | AQ3: WSS02 | AR3: WSS03 | AS3: iSS01084-PL | AT3: iSS01-PL | AU3: WSS01-PL | AV3: WSS03-PL | AW3: Khác | AZ3: iSS01084 | BA3: iSS01 | BB3: WSS01 | BC3: WSS02 | BD3: WSS03 | BE3: iSS01084-PL | BF3: iSS01-PL | BG3: WSS01-PL | BH3: WSS03-PL | BI3: Khác | BL3: iSS01084 | BM3: iSS01 | BN3: WSS01 | BO3: WSS02 | BP3: WSS03 | BQ3: iSS01084-PL | BR3: iSS01-PL | BS3: WSS01-PL | BT3: WSS03-PL | BU3: Khác | BX3: iSS01084 | BY3: iSS01 | BZ3: WSS01 | CA3: WSS02 | CB3: WSS03 | CC3: iSS01084-PL | CD3: iSS01-PL | CE3: WSS01-PL | CF3: WSS03-PL | CG3: Khác | CJ3: iSS01084 | CK3: iSS01 | CL3: WSS01 | CM3: WSS02 | CN3: WSS03 | CO3: iSS01084-PL | CP3: iSS01-PL | CQ3: WSS01-PL | CR3: WSS03-PL | CS3: Khác | CV3: iSS01084 | CW3: iSS01 | CX3: WSS01 | CY3: WSS02 | CZ3: WSS03 | DA3: iSS01084-PL | DB3: iSS01-PL | DC3: WSS01-PL | DD3: WSS03-PL | DE3: Khác | DH3: iSS01084 | DI3: iSS01 | DJ3: WSS01 | DK3: WSS02 | DL3: WSS03 | DM3: iSS01084-PL | DN3: iSS01-PL | DO3: WSS01-PL | DP3: WSS03-PL | DQ3: Khác | DT3: iSS01084 | DU3: iSS01 | DV3: WSS01 | DW3: WSS02 | DX3: WSS03 | DY3: iSS01084-PL | DZ3: iSS01-PL | EA3: WSS01-PL | EB3: WSS03-PL | EC3: Khác | EF3: iSS01084 | EG3: iSS01 | EH3: WSS01 | EI3: WSS02 | EJ3: WSS03 | EK3: iSS01084-PL | EL3: iSS01-PL | EM3: WSS01-PL | EN3: WSS03-PL | EO3: Khác | ER3: iSS01084 | ES3: iSS01 | ET3: WSS01 | EU3: WSS02 | EV3: WSS03 | EW3: iSS01084-PL | EX3: iSS01-PL | EY3: WSS01-PL | EZ3: WSS03-PL | FA3: Khác
B4: Main SKU name (Đvt: tấn) | D4: NĂM 2024-2026-THU HỒI | P4: THÁNG 1-THU HỒI | AB4: THÁNG 2-THU HỒI | AN4: THÁNG 3-THU HỒI | AZ4: THÁNG 4-THU HỒI | BL4: THÁNG 5-THU HỒI | BX4: THÁNG 6-THU HỒI | CJ4: THÁNG 7-THU HỒI | CV4: THÁNG 8-THU HỒI | DH4: THÁNG 9-THU HỒI | DT4: THÁNG 10-THU HỒI | EF4: THÁNG 11-THU HỒI | ER4: THÁNG 12-THU HỒI
D5: iSS01084 | E5: iSS01 | F5: WSS01 | G5: WSS02 | H5: WSS03 | I5: iSS01084-PL | J5: iSS01-PL | K5: WSS01-PL | L5: WSS03-PL | M5: Khác | N5: TỔNG | P5: iSS01084 | Q5: iSS01 | R5: WSS01 | S5: WSS02 | T5: WSS03 | U5: iSS01084-PL | V5: iSS01-PL | W5: WSS01-PL | X5: WSS03-PL | Y5: Khác | Z5: TỔNG | AB5: iSS01084 | AC5: iSS01 | AD5: WSS01 | AE5: WSS02 | AF5: WSS03 | AG5: iSS01084-PL | AH5: iSS01-PL | AI5: WSS01-PL | AJ5: WSS03-PL | AK5: Khác | AL5: TỔNG | AN5: iSS01084 | AO5: iSS01 | AP5: WSS01 | AQ5: WSS02 | AR5: WSS03 | AS5: iSS01084-PL | AT5: iSS01-PL | AU5: WSS01-PL | AV5: WSS03-PL | AW5: Khác | AX5: TỔNG | AZ5: iSS01084 | BA5: iSS01 | BB5: WSS01 | BC5: WSS02 | BD5: WSS03 | BE5: iSS01084-PL | BF5: iSS01-PL | BG5: WSS01-PL | BH5: WSS03-PL | BI5: Khác | BJ5: TỔNG | BL5: iSS01084 | BM5: iSS01 | BN5: WSS01 | BO5: WSS02 | BP5: WSS03 | BQ5: iSS01084-PL | BR5: iSS01-PL | BS5: WSS01-PL | BT5: WSS03-PL | BU5: Khác | BV5: TỔNG | BX5: iSS01084 | BY5: iSS01 | BZ5: WSS01 | CA5: WSS02 | CB5: WSS03 | CC5: iSS01084-PL | CD5: iSS01-PL | CE5: WSS01-PL | CF5: WSS03-PL | CG5: Khác | CH5: TỔNG | CJ5: iSS01084 | CK5: iSS01 | CL5: WSS01 | CM5: WSS02 | CN5: WSS03 | CO5: iSS01084-PL | CP5: iSS01-PL | CQ5: WSS01-PL | CR5: WSS03-PL | CS5: Khác | CT5: TỔNG | CV5: iSS01084 | CW5: iSS01 | CX5: WSS01 | CY5: WSS02 | CZ5: WSS03 | DA5: iSS01084-PL | DB5: iSS01-PL | DC5: WSS01-PL | DD5: WSS03-PL | DE5: Khác | DF5: TỔNG | DH5: iSS01084 | DI5: iSS01 | DJ5: WSS01 | DK5: WSS02 | DL5: WSS03 | DM5: iSS01084-PL | DN5: iSS01-PL | DO5: WSS01-PL | DP5: WSS03-PL | DQ5: Khác | DR5: TỔNG | DT5: iSS01084 | DU5: iSS01 | DV5: WSS01 | DW5: WSS02 | DX5: WSS03 | DY5: iSS01084-PL | DZ5: iSS01-PL | EA5: WSS01-PL | EB5: WSS03-PL | EC5: Khác | ED5: TỔNG | EF5: iSS01084 | EG5: iSS01 | EH5: WSS01 | EI5: WSS02 | EJ5: WSS03 | EK5: iSS01084-PL | EL5: iSS01-PL | EM5: WSS01-PL | EN5: WSS03-PL | EO5: Khác | EP5: TỔNG | ER5: iSS01084 | ES5: iSS01 | ET5: WSS01 | EU5: WSS02 | EV5: WSS03 | EW5: iSS01084-PL | EX5: iSS01-PL | EY5: WSS01-PL | EZ5: WSS03-PL | FA5: Khác | FB5: TỔNG
A6: iSS01084 | B6: iSS01084 | D6: =SUM('2026:2024'!D6) -> 13340733 | E6: =SUM('2026:2024'!E6) -> 603400 | F6: =SUM('2026:2024'!F6) -> 199061 | G6: =SUM('2026:2024'!G6) -> 17600 | H6: =SUM('2026:2024'!H6) -> 790003.5 | I6: =SUM('2026:2024'!I6) -> 103400 | J6: =SUM('2026:2024'!J6) -> 23100 | K6: =SUM('2026:2024'!K6) -> 39600 | L6: =SUM('2026:2024'!L6) -> 72000 | M6: {=IF(M$2="FY",SUMPRODUCT(Data[Nhập-SPC+SPP-NX]*(Data[Year]=M$1)*(Data[Main SKU name_GOM]=$A6)*(Data[SKU name_NHẬP_GOM]=M$3)),SUMPRODUCT(Data[Nhập-SPC+SPP-NX]*(Data[Year]=M$1)*(Data[Month]=M$2)*(Data[Main SKU name_GOM]=$A6)*(Data[SKU name_NHẬP_GOM]=M$3)))} -> 0 | N6: =SUM(D6:M6) -> 15188898 | P6: =SUM('2026:2024'!P6) -> 895498 | Q6: =SUM('2026:2024'!Q6) -> 17600 | R6: =SUM('2026:2024'!R6) -> 2161 | S6: =SUM('2026:2024'!S6) -> 5500 | T6: =SUM('2026:2024'!T6) -> 44000 | U6: =SUM('2026:2024'!U6) -> 1100 | V6: =SUM('2026:2024'!V6) -> 2200 | W6: =SUM('2026:2024'!W6) -> 0 | X6: =SUM('2026:2024'!X6) -> 0 | Y6: {=IF(Y$2="FY",SUMPRODUCT(Data[Nhập-SPC+SPP-NX]*(Data[Year]=Y$1)*(Data[Main SKU name_GOM]=$A6)*(Data[SKU name_NHẬP_GOM]=Y$3)),SUMPRODUCT(Data[Nhập-SPC+SPP-NX]*(Data[Year]=Y$1)*(Data[Month]=Y$2)*(Data[Main SKU name_GOM]=$A6)*(Data[SKU name_NHẬP_GOM]=Y$3)))} -> 0 | Z6: =SUM(P6:Y6) -> 968059 | AB6: =SUM('2026:2024'!AB6) -> 1067133 | AC6: =SUM('2026:2024'!AC6) -> 64900 | AD6: =SUM('2026:2024'!AD6) -> 2200 | AE6: =SUM('2026:2024'!AE6) -> 6600 | AF6: =SUM('2026:2024'!AF6) -> 57200 | AG6: =SUM('2026:2024'!AG6) -> 4400 | AH6: =SUM('2026:2024'!AH6) -> 4400 | AI6: =SUM('2026:2024'!AI6) -> 0 | AJ6: =SUM('2026:2024'!AJ6) -> 4400 | AK6: {=IF(AK$2="FY",SUMPRODUCT(Data[Nhập-SPC+SPP-NX]*(Data[Year]=AK$1)*(Data[Main SKU name_GOM]=$A6)*(Data[SKU name_NHẬP_GOM]=AK$3)),SUMPRODUCT(Data[Nhập-SPC+SPP-NX]*(Data[Year]=AK$1)*(Data[Month]=AK$2)*(Data[Main SKU name_GOM]=$A6)*(Data[SKU name_NHẬP_GOM]=AK$3)))} -> 0 | AL6: =SUM(AB6:AK6) -> 1211233 | AN6: =SUM('2026:2024'!AN6) -> 644600 | AO6: =SUM('2026:2024'!AO6) -> 11000 | AP6: =SUM('2026:2024'!AP6) -> 1100 | AQ6: =SUM('2026:2024'!AQ6) -> 0 | AR6: =SUM('2026:2024'!AR6) -> 11000 | AS6: =SUM('2026:2024'!AS6) -> 0 | AT6: =SUM('2026:2024'!AT6) -> 6600 | AU6: =SUM('2026:2024'!AU6) -> 0 | AV6: =SUM('2026:2024'!AV6) -> 0 | AW6: {=IF(AW$2="FY",SUMPRODUCT(Data[Nhập-SPC+SPP-NX]*(Data[Year]=AW$1)*(Data[Main SKU name_GOM]=$A6)*(Data[SKU name_NHẬP_GOM]=AW$3)),SUMPRODUCT(Data[Nhập-SPC+SPP-NX]*(Data[Year]=AW$1)*(Data[Month]=AW$2)*(Data[Main SKU name_GOM]=$A6)*(Data[SKU name_NHẬP_GOM]=AW$3)))} -> 0 | AX6: =SUM(AN6:AW6) -> 674300 | AZ6: =SUM('2026:2024'!AZ6) -> 980100 | BA6: =SUM('2026:2024'!BA6) -> 20900 | BB6: =SUM('2026:2024'!BB6) -> 47300 | BC6: =SUM('2026:2024'!BC6) -> 0 | BD6: =SUM('2026:2024'!BD6) -> 14300 | BE6: =SUM('2026:2024'!BE6) -> 2200 | BF6: =SUM('2026:2024'!BF6) -> 2200 | BG6: =SUM('2026:2024'!BG6) -> 0 | BH6: =SUM('2026:2024'!BH6) -> 2200 | BI6: {=IF(BI$2="FY",SUMPRODUCT(Data[Nhập-SPC+SPP-NX]*(Data[Year]=BI$1)*(Data[Main SKU name_GOM]=$A6)*(Data[SKU name_NHẬP_GOM]=BI$3)),SUMPRODUCT(Data[Nhập-SPC+SPP-NX]*(Data[Year]=BI$1)*(Data[Month]=BI$2)*(Data[Main SKU name_GOM]=$A6)*(Data[SKU name_NHẬP_GOM]=BI$3)))} -> 0 | BJ6: =SUM(AZ6:BI6) -> 1069200 | BL6: =SUM('2026:2024'!BL6) -> 526900 | BM6: =SUM('2026:2024'!BM6) -> 129800 | BN6: =SUM('2026:2024'!BN6) -> 0 | BO6: =SUM('2026:2024'!BO6) -> 4400 | BP6: =SUM('2026:2024'!BP6) -> 17600 | BQ6: =SUM('2026:2024'!BQ6) -> 1100 | BR6: =SUM('2026:2024'!BR6) -> 0 | BS6: =SUM('2026:2024'!BS6) -> 14300 | BT6: =SUM('2026:2024'!BT6) -> 0 | BU6: {=IF(BU$2="FY",SUMPRODUCT(Data[Nhập-SPC+SPP-NX]*(Data[Year]=BU$1)*(Data[Main SKU name_GOM]=$A6)*(Data[SKU name_NHẬP_GOM]=BU$3)),SUMPRODUCT(Data[Nhập-SPC+SPP-NX]*(Data[Year]=BU$1)*(Data[Month]=BU$2)*(Data[Main SKU name_GOM]=$A6)*(Data[SKU name_NHẬP_GOM]=BU$3)))} -> 0 | BV6: =SUM(BL6:BU6) -> 694100 | BX6: =SUM('2026:2024'!BX6) -> 669900 | BY6: =SUM('2026:2024'!BY6) -> 30800 | BZ6: =SUM('2026:2024'!BZ6) -> 0 | CA6: =SUM('2026:2024'!CA6) -> 0 | CB6: =SUM('2026:2024'!CB6) -> 7700 | CC6: =SUM('2026:2024'!CC6) -> 6600 | CD6: =SUM('2026:2024'!CD6) -> 4400 | CE6: =SUM('2026:2024'!CE6) -> 2200 | CF6: =SUM('2026:2024'!CF6) -> 6600 | CG6: {=IF(CG$2="FY",SUMPRODUCT(Data[Nhập-SPC+SPP-NX]*(Data[Year]=CG$1)*(Data[Main SKU name_GOM]=$A6)*(Data[SKU name_NHẬP_GOM]=CG$3)),SUMPRODUCT(Data[Nhập-SPC+SPP-NX]*(Data[Year]=CG$1)*(Data[Month]=CG$2)*(Data[Main SKU name_GOM]=$A6)*(Data[SKU name_NHẬP_GOM]=CG$3)))} -> 0 | CH6: =SUM(BX6:CG6) -> 728200 | CJ6: =SUM('2026:2024'!CJ6) -> 657800 | CK6: =SUM('2026:2024'!CK6) -> 70400 | CL6: =SUM('2026:2024'!CL6) -> 7700 | CM6: =SUM('2026:2024'!CM6) -> 0 | CN6: =SUM('2026:2024'!CN6) -> 28600 | CO6: =SUM('2026:2024'!CO6) -> 11000 | CP6: =SUM('2026:2024'!CP6) -> 0 | CQ6: =SUM('2026:2024'!CQ6) -> 0 | CR6: =SUM('2026:2024'!CR6) -> 6600 | CS6: {=IF(CS$2="FY",SUMPRODUCT(Data[Nhập-SPC+SPP-NX]*(Data[Year]=CS$1)*(Data[Main SKU name_GOM]=$A6)*(Data[SKU name_NHẬP_GOM]=CS$3)),SUMPRODUCT(Data[Nhập-SPC+SPP-NX]*(Data[Year]=CS$1)*(Data[Month]=CS$2)*(Data[Main SKU name_GOM]=$A6)*(Data[SKU name_NHẬP_GOM]=CS$3)))} -> 0 | CT6: =SUM(CJ6:CS6) -> 782100 | CV6: =SUM('2026:2024'!CV6) -> 1119800 | CW6: =SUM('2026:2024'!CW6) -> 44245 | CX6: =SUM('2026:2024'!CX6) -> 1100 | CY6: =SUM('2026:2024'!CY6) -> 0 | CZ6: =SUM('2026:2024'!CZ6) -> 59399 | DA6: =SUM('2026:2024'!DA6) -> 0 | DB6: =SUM('2026:2024'!DB6) -> 1100 | DC6: =SUM('2026:2024'!DC6) -> 6600 | DD6: =SUM('2026:2024'!DD6) -> 10400 | DE6: {=IF(DE$2="FY",SUMPRODUCT(Data[Nhập-SPC+SPP-NX]*(Data[Year]=DE$1)*(Data[Main SKU name_GOM]=$A6)*(Data[SKU name_NHẬP_GOM]=DE$3)),SUMPRODUCT(Data[Nhập-SPC+SPP-NX]*(Data[Year]=DE$1)*(Data[Month]=DE$2)*(Data[Main SKU name_GOM]=$A6)*(Data[SKU name_NHẬP_GOM]=DE$3)))} -> 0 | DF6: =SUM(CV6:DE6) -> 1242644 | DH6: =SUM('2026:2024'!DH6) -> 1568600 | DI6: =SUM('2026:2024'!DI6) -> 93855 | DJ6: =SUM('2026:2024'!DJ6) -> 3300 | DK6: =SUM('2026:2024'!DK6) -> 0 | DL6: =SUM('2026:2024'!DL6) -> 159704.5 | DM6: =SUM('2026:2024'!DM6) -> 0 | DN6: =SUM('2026:2024'!DN6) -> 0 | DO6: =SUM('2026:2024'!DO6) -> 0 | DP6: =SUM('2026:2024'!DP6) -> 1100 | DQ6: {=IF(DQ$2="FY",SUMPRODUCT(Data[Nhập-SPC+SPP-NX]*(Data[Year]=DQ$1)*(Data[Main SKU name_GOM]=$A6)*(Data[SKU name_NHẬP_GOM]=DQ$3)),SUMPRODUCT(Data[Nhập-SPC+SPP-NX]*(Data[Year]=DQ$1)*(Data[Month]=DQ$2)*(Data[Main SKU name_GOM]=$A6)*(Data[SKU name_NHẬP_GOM]=DQ$3)))} -> 0 | DR6: =SUM(DH6:DQ6) -> 1826559.5 | DT6: =SUM('2026:2024'!DT6) -> 1432202 | DU6: =SUM('2026:2024'!DU6) -> 85800 | DV6: =SUM('2026:2024'!DV6) -> 105600 | DW6: =SUM('2026:2024'!DW6) -> 1100 | DX6: =SUM('2026:2024'!DX6) -> 189200 | DY6: =SUM('2026:2024'!DY6) -> 59400 | DZ6: =SUM('2026:2024'!DZ6) -> 0 | EA6: =SUM('2026:2024'!EA6) -> 16500 | EB6: =SUM('2026:2024'!EB6) -> 20900 | EC6: {=IF(EC$2="FY",SUMPRODUCT(Data[Nhập-SPC+SPP-NX]*(Data[Year]=EC$1)*(Data[Main SKU name_GOM]=$A6)*(Data[SKU name_NHẬP_GOM]=EC$3)),SUMPRODUCT(Data[Nhập-SPC+SPP-NX]*(Data[Year]=EC$1)*(Data[Month]=EC$2)*(Data[Main SKU name_GOM]=$A6)*(Data[SKU name_NHẬP_GOM]=EC$3)))} -> 0 | ED6: =SUM(DT6:EC6) -> 1910702 | EF6: =SUM('2026:2024'!EF6) -> 1910400 | EG6: =SUM('2026:2024'!EG6) -> 26400 | EH6: =SUM('2026:2024'!EH6) -> 12100 | EI6: =SUM('2026:2024'!EI6) -> 0 | EJ6: =SUM('2026:2024'!EJ6) -> 147400 | EK6: =SUM('2026:2024'!EK6) -> 2200 | EL6: =SUM('2026:2024'!EL6) -> 0 | EM6: =SUM('2026:2024'!EM6) -> 0 | EN6: =SUM('2026:2024'!EN6) -> 7700 | EO6: {=IF(EO$2="FY",SUMPRODUCT(Data[Nhập-SPC+SPP-NX]*(Data[Year]=EO$1)*(Data[Main SKU name_GOM]=$A6)*(Data[SKU name_NHẬP_GOM]=EO$3)),SUMPRODUCT(Data[Nhập-SPC+SPP-NX]*(Data[Year]=EO$1)*(Data[Month]=EO$2)*(Data[Main SKU name_GOM]=$A6)*(Data[SKU name_NHẬP_GOM]=EO$3)))} -> 0 | EP6: =SUM(EF6:EO6) -> 2106200 | ER6: =SUM('2026:2024'!ER6) -> 1867800 | ES6: =SUM('2026:2024'!ES6) -> 7700 | ET6: =SUM('2026:2024'!ET6) -> 16500 | EU6: =SUM('2026:2024'!EU6) -> 0 | EV6: =SUM('2026:2024'!EV6) -> 53900 | EW6: =SUM('2026:2024'!EW6) -> 15400 | EX6: =SUM('2026:2024'!EX6) -> 2200 | EY6: =SUM('2026:2024'!EY6) -> 0 | EZ6: =SUM('2026:2024'!EZ6) -> 12100 | FA6: {=IF(FA$2="FY",SUMPRODUCT(Data[Nhập-SPC+SPP-NX]*(Data[Year]=FA$1)*(Data[Main SKU name_GOM]=$A6)*(Data[SKU name_NHẬP_GOM]=FA$3)),SUMPRODUCT(Data[Nhập-SPC+SPP-NX]*(Data[Year]=FA$1)*(Data[Month]=FA$2)*(Data[Main SKU name_GOM]=$A6)*(Data[SKU name_NHẬP_GOM]=FA$3)))} -> 0 | FB6: =SUM(ER6:FA6) -> 1975600
A7: iSS01 | B7: iSS01 | D7: =SUM('2026:2024'!D7) -> 293538 | E7: =SUM('2026:2024'!E7) -> 12990577 | F7: =SUM('2026:2024'!F7) -> 432300 | G7: =SUM('2026:2024'!G7) -> 0 | H7: =SUM('2026:2024'!H7) -> 189276.5 | I7: =SUM('2026:2024'!I7) -> 3300 | J7: =SUM('2026:2024'!J7) -> 141900 | K7: =SUM('2026:2024'!K7) -> 16500 | L7: =SUM('2026:2024'!L7) -> 28650 | M7: {=IF(M$2="FY",SUMPRODUCT(Data[Nhập-SPC+SPP-NX]*(Data[Year]=M$1)*(Data[Main SKU name_GOM]=$A7)*(Data[SKU name_NHẬP_GOM]=M$3)),SUMPRODUCT(Data[Nhập-SPC+SPP-NX]*(Data[Year]=M$1)*(Data[Month]=M$2)*(Data[Main SKU name_GOM]=$A7)*(Data[SKU name_NHẬP_GOM]=M$3)))} -> 0 | N7: =SUM(D7:M7) -> 14096042 | P7: =SUM('2026:2024'!P7) -> 8800 | Q7: =SUM('2026:2024'!Q7) -> 492800 | R7: =SUM('2026:2024'!R7) -> 2200 | S7: =SUM('2026:2024'!S7) -> 0 | T7: =SUM('2026:2024'!T7) -> 5500 | U7: =SUM('2026:2024'!U7) -> 0 | V7: =SUM('2026:2024'!V7) -> 1100 | W7: =SUM('2026:2024'!W7) -> 0 | X7: =SUM('2026:2024'!X7) -> 2200 | Y7: {=IF(Y$2="FY",SUMPRODUCT(Data[Nhập-SPC+SPP-NX]*(Data[Year]=Y$1)*(Data[Main SKU name_GOM]=$A7)*(Data[SKU name_NHẬP_GOM]=Y$3)),SUMPRODUCT(Data[Nhập-SPC+SPP-NX]*(Data[Year]=Y$1)*(Data[Month]=Y$2)*(Data[Main SKU name_GOM]=$A7)*(Data[SKU name_NHẬP_GOM]=Y$3)))} -> 0 | Z7: =SUM(P7:Y7) -> 512600 | AB7: =SUM('2026:2024'!AB7) -> 1100 | AC7: =SUM('2026:2024'!AC7) -> 737440 | AD7: =SUM('2026:2024'!AD7) -> 6600 | AE7: =SUM('2026:2024'!AE7) -> 0 | AF7: =SUM('2026:2024'!AF7) -> 19800 | AG7: =SUM('2026:2024'!AG7) -> 0 | AH7: =SUM('2026:2024'!AH7) -> 24200 | AI7: =SUM('2026:2024'!AI7) -> 0 | AJ7: =SUM('2026:2024'!AJ7) -> 5500 | AK7: {=IF(AK$2="FY",SUMPRODUCT(Data[Nhập-SPC+SPP-NX]*(Data[Year]=AK$1)*(Data[Main SKU name_GOM]=$A7)*(Data[SKU name_NHẬP_GOM]=AK$3)),SUMPRODUCT(Data[Nhập-SPC+SPP-NX]*(Data[Year]=AK$1)*(Data[Month]=AK$2)*(Data[Main SKU name_GOM]=$A7)*(Data[SKU name_NHẬP_GOM]=AK$3)))} -> 0 | AL7: =SUM(AB7:AK7) -> 794640 | AN7: =SUM('2026:2024'!AN7) -> 11000 | AO7: =SUM('2026:2024'!AO7) -> 1915100 | AP7: =SUM('2026:2024'!AP7) -> 39600 | AQ7: =SUM('2026:2024'!AQ7) -> 0 | AR7: =SUM('2026:2024'!AR7) -> 23015 | AS7: =SUM('2026:2024'!AS7) -> 0 | AT7: =SUM('2026:2024'!AT7) -> 13200 | AU7: =SUM('2026:2024'!AU7) -> 1100 | AV7: =SUM('2026:2024'!AV7) -> 1100 | AW7: {=IF(AW$2="FY",SUMPRODUCT(Data[Nhập-SPC+SPP-NX]*(Data[Year]=AW$1)*(Data[Main SKU name_GOM]=$A7)*(Data[SKU name_NHẬP_GOM]=AW$3)),SUMPRODUCT(Data[Nhập-SPC+SPP-NX]*(Data[Year]=AW$1)*(Data[Month]=AW$2)*(Data[Main SKU name_GOM]=$A7)*(Data[SKU name_NHẬP_GOM]=AW$3)))} -> 0 | AX7: =SUM(AN7:AW7) -> 2004115 | AZ7: =SUM('2026:2024'!AZ7) -> 0 | BA7: =SUM('2026:2024'!BA7) -> 1502936 | BB7: =SUM('2026:2024'!BB7) -> 39600 | BC7: =SUM('2026:2024'!BC7) -> 0 | BD7: =SUM('2026:2024'!BD7) -> 12745 | BE7: =SUM('2026:2024'!BE7) -> 0 | BF7: =SUM('2026:2024'!BF7) -> 33000 | BG7: =SUM('2026:2024'!BG7) -> 7700 | BH7: =SUM('2026:2024'!BH7) -> 12150 | BI7: {=IF(BI$2="FY",SUMPRODUCT(Data[Nhập-SPC+SPP-NX]*(Data[Year]=BI$1)*(Data[Main SKU name_GOM]=$A7)*(Data[SKU name_NHẬP_GOM]=BI$3)),SUMPRODUCT(Data[Nhập-SPC+SPP-NX]*(Data[Year]=BI$1)*(Data[Month]=BI$2)*(Data[Main SKU name_GOM]=$A7)*(Data[SKU name_NHẬP_GOM]=BI$3)))} -> 0 | BJ7: =SUM(AZ7:BI7) -> 1608131 | BL7: =SUM('2026:2024'!BL7) -> 2200 | BM7: =SUM('2026:2024'!BM7) -> 1322200 | BN7: =SUM('2026:2024'!BN7) -> 23100 | BO7: =SUM('2026:2024'!BO7) -> 0 | BP7: =SUM('2026:2024'!BP7) -> 18700 | BQ7: =SUM('2026:2024'!BQ7) -> 0 | BR7: =SUM('2026:2024'!BR7) -> 11000 | BS7: =SUM('2026:2024'!BS7) -> 2200 | BT7: =SUM('2026:2024'!BT7) -> 1100 | BU7: {=IF(BU$2="FY",SUMPRODUCT(Data[Nhập-SPC+SPP-NX]*(Data[Year]=BU$1)*(Data[Main SKU name_GOM]=$A7)*(Data[SKU name_NHẬP_GOM]=BU$3)),SUMPRODUCT(Data[Nhập-SPC+SPP-NX]*(Data[Year]=BU$1)*(Data[Month]=BU$2)*(Data[Main SKU name_GOM]=$A7)*(Data[SKU name_NHẬP_GOM]=BU$3)))} -> 0 | BV7: =SUM(BL7:BU7) -> 1380500 | BX7: =SUM('2026:2024'!BX7) -> 37400 | BY7: =SUM('2026:2024'!BY7) -> 1905200 | BZ7: =SUM('2026:2024'!BZ7) -> 27500 | CA7: =SUM('2026:2024'!CA7) -> 0 | CB7: =SUM('2026:2024'!CB7) -> 4400 | CC7: =SUM('2026:2024'!CC7) -> 0 | CD7: =SUM('2026:2024'!CD7) -> 12100 | CE7: =SUM('2026:2024'!CE7) -> 2200 | CF7: =SUM('2026:2024'!CF7) -> 4400 | CG7: {=IF(CG$2="FY",SUMPRODUCT(Data[Nhập-SPC+SPP-NX]*(Data[Year]=CG$1)*(Data[Main SKU name_GOM]=$A7)*(Data[SKU name_NHẬP_GOM]=CG$3)),SUMPRODUCT(Data[Nhập-SPC+SPP-NX]*(Data[Year]=CG$1)*(Data[Month]=CG$2)*(Data[Main SKU name_GOM]=$A7)*(Data[SKU name_NHẬP_GOM]=CG$3)))} -> 0 | CH7: =SUM(BX7:CG7) -> 1993200 | CJ7: =SUM('2026:2024'!CJ7) -> 112200 | CK7: =SUM('2026:2024'!CK7) -> 1305700 | CL7: =SUM('2026:2024'!CL7) -> 68200 | CM7: =SUM('2026:2024'!CM7) -> 0 | CN7: =SUM('2026:2024'!CN7) -> 22000 | CO7: =SUM('2026:2024'!CO7) -> 0 | CP7: =SUM('2026:2024'!CP7) -> 12100 | CQ7: =SUM('2026:2024'!CQ7) -> 0 | CR7: =SUM('2026:2024'!CR7) -> 0 | CS7: {=IF(CS$2="FY",SUMPRODUCT(Data[Nhập-SPC+SPP-NX]*(Data[Year]=CS$1)*(Data[Main SKU name_GOM]=$A7)*(Data[SKU name_NHẬP_GOM]=CS$3)),SUMPRODUCT(Data[Nhập-SPC+SPP-NX]*(Data[Year]=CS$1)*(Data[Month]=CS$2)*(Data[Main SKU name_GOM]=$A7)*(Data[SKU name_NHẬP_GOM]=CS$3)))} -> 0 | CT7: =SUM(CJ7:CS7) -> 1520200 | CV7: =SUM('2026:2024'!CV7) -> 91300 | CW7: =SUM('2026:2024'!CW7) -> 1106600 | CX7: =SUM('2026:2024'!CX7) -> 69300 | CY7: =SUM('2026:2024'!CY7) -> 0 | CZ7: =SUM('2026:2024'!CZ7) -> 14300 | DA7: =SUM('2026:2024'!DA7) -> 0 | DB7: =SUM('2026:2024'!DB7) -> 14300 | DC7: =SUM('2026:2024'!DC7) -> 3300 | DD7: =SUM('2026:2024'!DD7) -> 2200 | DE7: {=IF(DE$2="FY",SUMPRODUCT(Data[Nhập-SPC+SPP-NX]*(Data[Year]=DE$1)*(Data[Main SKU name_GOM]=$A7)*(Data[SKU name_NHẬP_GOM]=DE$3)),SUMPRODUCT(Data[Nhập-SPC+SPP-NX]*(Data[Year]=DE$1)*(Data[Month]=DE$2)*(Data[Main SKU name_GOM]=$A7)*(Data[SKU name_NHẬP_GOM]=DE$3)))} -> 0 | DF7: =SUM(CV7:DE7) -> 1301300 | DH7: =SUM('2026:2024'!DH7) -> 0 | DI7: =SUM('2026:2024'!DI7) -> 847000 | DJ7: =SUM('2026:2024'!DJ7) -> 40700 | DK7: =SUM('2026:2024'!DK7) -> 0 | DL7: =SUM('2026:2024'!DL7) -> 13200 | DM7: =SUM('2026:2024'!DM7) -> 0 | DN7: =SUM('2026:2024'!DN7) -> 8800 | DO7: =SUM('2026:2024'!DO7) -> 0 | DP7: =SUM('2026:2024'!DP7) -> 0 | DQ7: {=IF(DQ$2="FY",SUMPRODUCT(Data[Nhập-SPC+SPP-NX]*(Data[Year]=DQ$1)*(Data[Main SKU name_GOM]=$A7)*(Data[SKU name_NHẬP_GOM]=DQ$3)),SUMPRODUCT(Data[Nhập-SPC+SPP-NX]*(Data[Year]=DQ$1)*(Data[Month]=DQ$2)*(Data[Main SKU name_GOM]=$A7)*(Data[SKU name_NHẬP_GOM]=DQ$3)))} -> 0 | DR7: =SUM(DH7:DQ7) -> 909700 | DT7: =SUM('2026:2024'!DT7) -> 16338 | DU7: =SUM('2026:2024'!DU7) -> 484000 | DV7: =SUM('2026:2024'!DV7) -> 11000 | DW7: =SUM('2026:2024'!DW7) -> 0 | DX7: =SUM('2026:2024'!DX7) -> 13816.5 | DY7: =SUM('2026:2024'!DY7) -> 0 | DZ7: =SUM('2026:2024'!DZ7) -> 12100 | EA7: =SUM('2026:2024'!EA7) -> 0 | EB7: =SUM('2026:2024'!EB7) -> 0 | EC7: {=IF(EC$2="FY",SUMPRODUCT(Data[Nhập-SPC+SPP-NX]*(Data[Year]=EC$1)*(Data[Main SKU name_GOM]=$A7)*(Data[SKU name_NHẬP_GOM]=EC$3)),SUMPRODUCT(Data[Nhập-SPC+SPP-NX]*(Data[Year]=EC$1)*(Data[Month]=EC$2)*(Data[Main SKU name_GOM]=$A7)*(Data[SKU name_NHẬP_GOM]=EC$3)))} -> 0 | ED7: =SUM(DT7:EC7) -> 537254.5 | EF7: =SUM('2026:2024'!EF7) -> 13200 | EG7: =SUM('2026:2024'!EG7) -> 1211001 | EH7: =SUM('2026:2024'!EH7) -> 82500 | EI7: =SUM('2026:2024'!EI7) -> 0 | EJ7: =SUM('2026:2024'!EJ7) -> 41800 | EK7: =SUM('2026:2024'!EK7) -> 0 | EL7: =SUM('2026:2024'!EL7) -> 0 | EM7: =SUM('2026:2024'!EM7) -> 0 | EN7: =SUM('2026:2024'!EN7) -> 0 | EO7: {=IF(EO$2="FY",SUMPRODUCT(Data[Nhập-SPC+SPP-NX]*(Data[Year]=EO$1)*(Data[Main SKU name_GOM]=$A7)*(Data[SKU name_NHẬP_GOM]=EO$3)),SUMPRODUCT(Data[Nhập-SPC+SPP-NX]*(Data[Year]=EO$1)*(Data[Month]=EO$2)*(Data[Main SKU name_GOM]=$A7)*(Data[SKU name_NHẬP_GOM]=EO$3)))} -> 0 | EP7: =SUM(EF7:EO7) -> 1348501 | ER7: =SUM('2026:2024'!ER7) -> 0 | ES7: =SUM('2026:2024'!ES7) -> 160600 | ET7: =SUM('2026:2024'!ET7) -> 22000 | EU7: =SUM('2026:2024'!EU7) -> 0 | EV7: =SUM('2026:2024'!EV7) -> 0 | EW7: =SUM('2026:2024'!EW7) -> 3300 | EX7: =SUM('2026:2024'!EX7) -> 0 | EY7: =SUM('2026:2024'!EY7) -> 0 | EZ7: =SUM('2026:2024'!EZ7) -> 0 | FA7: {=IF(FA$2="FY",SUMPRODUCT(Data[Nhập-SPC+SPP-NX]*(Data[Year]=FA$1)*(Data[Main SKU name_GOM]=$A7)*(Data[SKU name_NHẬP_GOM]=FA$3)),SUMPRODUCT(Data[Nhập-SPC+SPP-NX]*(Data[Year]=FA$1)*(Data[Month]=FA$2)*(Data[Main SKU name_GOM]=$A7)*(Data[SKU name_NHẬP_GOM]=FA$3)))} -> 0 | FB7: =SUM(ER7:FA7) -> 185900
A8: WSS01 | B8: WSS01 | D8: =SUM('2026:2024'!D8) -> 58300 | E8: =SUM('2026:2024'!E8) -> 3794120 | F8: =SUM('2026:2024'!F8) -> 48292039 | G8: =SUM('2026:2024'!G8) -> 895544 | H8: =SUM('2026:2024'!H8) -> 1763694.5 | I8: =SUM('2026:2024'!I8) -> 2200 | J8: =SUM('2026:2024'!J8) -> 11000 | K8: =SUM('2026:2024'!K8) -> 543400 | L8: =SUM('2026:2024'!L8) -> 156172.25 | M8: {=IF(M$2="FY",SUMPRODUCT(Data[Nhập-SPC+SPP-NX]*(Data[Year]=M$1)*(Data[Main SKU name_GOM]=$A8)*(Data[SKU name_NHẬP_GOM]=M$3)),SUMPRODUCT(Data[Nhập-SPC+SPP-NX]*(Data[Year]=M$1)*(Data[Month]=M$2)*(Data[Main SKU name_GOM]=$A8)*(Data[SKU name_NHẬP_GOM]=M$3)))} -> 0 | N8: =SUM(D8:M8) -> 55516470 | P8: =SUM('2026:2024'!P8) -> 1100 | Q8: =SUM('2026:2024'!Q8) -> 500500 | R8: =SUM('2026:2024'!R8) -> 6360658 | S8: =SUM('2026:2024'!S8) -> 164344 | T8: =SUM('2026:2024'!T8) -> 44892 | U8: =SUM('2026:2024'!U8) -> 0 | V8: =SUM('2026:2024'!V8) -> 5500 | W8: =SUM('2026:2024'!W8) -> 18700 | X8: =SUM('2026:2024'!X8) -> 17572.25 | Y8: {=IF(Y$2="FY",SUMPRODUCT(Data[Nhập-SPC+SPP-NX]*(Data[Year]=Y$1)*(Data[Main SKU name_GOM]=$A8)*(Data[SKU name_NHẬP_GOM]=Y$3)),SUMPRODUCT(Data[Nhập-SPC+SPP-NX]*(Data[Year]=Y$1)*(Data[Month]=Y$2)*(Data[Main SKU name_GOM]=$A8)*(Data[SKU name_NHẬP_GOM]=Y$3)))} -> 0 | Z8: =SUM(P8:Y8) -> 7113266.2 | AB8: =SUM('2026:2024'!AB8) -> 0 | AC8: =SUM('2026:2024'!AC8) -> 266200 | AD8: =SUM('2026:2024'!AD8) -> 3754482 | AE8: =SUM('2026:2024'!AE8) -> 150700 | AF8: =SUM('2026:2024'!AF8) -> 21931 | AG8: =SUM('2026:2024'!AG8) -> 0 | AH8: =SUM('2026:2024'!AH8) -> 1100 | AI8: =SUM('2026:2024'!AI8) -> 51700 | AJ8: =SUM('2026:2024'!AJ8) -> 8800 | AK8: {=IF(AK$2="FY",SUMPRODUCT(Data[Nhập-SPC+SPP-NX]*(Data[Year]=AK$1)*(Data[Main SKU name_GOM]=$A8)*(Data[SKU name_NHẬP_GOM]=AK$3)),SUMPRODUCT(Data[Nhập-SPC+SPP-NX]*(Data[Year]=AK$1)*(Data[Month]=AK$2)*(Data[Main SKU name_GOM]=$A8)*(Data[SKU name_NHẬP_GOM]=AK$3)))} -> 0 | AL8: =SUM(AB8:AK8) -> 4254913 | AN8: =SUM('2026:2024'!AN8) -> 0 | AO8: =SUM('2026:2024'!AO8) -> 487300 | AP8: =SUM('2026:2024'!AP8) -> 7017929 | AQ8: =SUM('2026:2024'!AQ8) -> 118800 | AR8: =SUM('2026:2024'!AR8) -> 62700 | AS8: =SUM('2026:2024'!AS8) -> 0 | AT8: =SUM('2026:2024'!AT8) -> 3300 | AU8: =SUM('2026:2024'!AU8) -> 15400 | AV8: =SUM('2026:2024'!AV8) -> 6600 | AW8: {=IF(AW$2="FY",SUMPRODUCT(Data[Nhập-SPC+SPP-NX]*(Data[Year]=AW$1)*(Data[Main SKU name_GOM]=$A8)*(Data[SKU name_NHẬP_GOM]=AW$3)),SUMPRODUCT(Data[Nhập-SPC+SPP-NX]*(Data[Year]=AW$1)*(Data[Month]=AW$2)*(Data[Main SKU name_GOM]=$A8)*(Data[SKU name_NHẬP_GOM]=AW$3)))} -> 0 | AX8: =SUM(AN8:AW8) -> 7712029 | AZ8: =SUM('2026:2024'!AZ8) -> 3300 | BA8: =SUM('2026:2024'!BA8) -> 398201 | BB8: =SUM('2026:2024'!BB8) -> 5655100 | BC8: =SUM('2026:2024'!BC8) -> 47300 | BD8: =SUM('2026:2024'!BD8) -> 69300 | BE8: =SUM('2026:2024'!BE8) -> 0 | BF8: =SUM('2026:2024'!BF8) -> 0 | BG8: =SUM('2026:2024'!BG8) -> 17600 | BH8: =SUM('2026:2024'!BH8) -> 11000 | BI8: {=IF(BI$2="FY",SUMPRODUCT(Data[Nhập-SPC+SPP-NX]*(Data[Year]=BI$1)*(Data[Main SKU name_GOM]=$A8)*(Data[SKU name_NHẬP_GOM]=BI$3)),SUMPRODUCT(Data[Nhập-SPC+SPP-NX]*(Data[Year]=BI$1)*(Data[Month]=BI$2)*(Data[Main SKU name_GOM]=$A8)*(Data[SKU name_NHẬP_GOM]=BI$3)))} -> 0 | BJ8: =SUM(AZ8:BI8) -> 6201801 | BL8: =SUM('2026:2024'!BL8) -> 0 | BM8: =SUM('2026:2024'!BM8) -> 586300 | BN8: =SUM('2026:2024'!BN8) -> 4692600 | BO8: =SUM('2026:2024'!BO8) -> 238700 | BP8: =SUM('2026:2024'!BP8) -> 286000 | BQ8: =SUM('2026:2024'!BQ8) -> 0 | BR8: =SUM('2026:2024'!BR8) -> 0 | BS8: =SUM('2026:2024'!BS8) -> 18700 | BT8: =SUM('2026:2024'!BT8) -> 6600 | BU8: {=IF(BU$2="FY",SUMPRODUCT(Data[Nhập-SPC+SPP-NX]*(Data[Year]=BU$1)*(Data[Main SKU name_GOM]=$A8)*(Data[SKU name_NHẬP_GOM]=BU$3)),SUMPRODUCT(Data[Nhập-SPC+SPP-NX]*(Data[Year]=BU$1)*(Data[Month]=BU$2)*(Data[Main SKU name_GOM]=$A8)*(Data[SKU name_NHẬP_GOM]=BU$3)))} -> 0 | BV8: =SUM(BL8:BU8) -> 5828900 | BX8: =SUM('2026:2024'!BX8) -> 16500 | BY8: =SUM('2026:2024'!BY8) -> 558800 | BZ8: =SUM('2026:2024'!BZ8) -> 4213000 | CA8: =SUM('2026:2024'!CA8) -> 105600 | CB8: =SUM('2026:2024'!CB8) -> 390700 | CC8: =SUM('2026:2024'!CC8) -> 2200 | CD8: =SUM('2026:2024'!CD8) -> 0 | CE8: =SUM('2026:2024'!CE8) -> 27500 | CF8: =SUM('2026:2024'!CF8) -> 7700 | CG8: {=IF(CG$2="FY",SUMPRODUCT(Data[Nhập-SPC+SPP-NX]*(Data[Year]=CG$1)*(Data[Main SKU name_GOM]=$A8)*(Data[SKU name_NHẬP_GOM]=CG$3)),SUMPRODUCT(Data[Nhập-SPC+SPP-NX]*(Data[Year]=CG$1)*(Data[Month]=CG$2)*(Data[Main SKU name_GOM]=$A8)*(Data[SKU name_NHẬP_GOM]=CG$3)))} -> 0 | CH8: =SUM(BX8:CG8) -> 5322000 | CJ8: =SUM('2026:2024'!CJ8) -> 1100 | CK8: =SUM('2026:2024'!CK8) -> 78100 | CL8: =SUM('2026:2024'!CL8) -> 2101000 | CM8: =SUM('2026:2024'!CM8) -> 3300 | CN8: =SUM('2026:2024'!CN8) -> 47000 | CO8: =SUM('2026:2024'!CO8) -> 0 | CP8: =SUM('2026:2024'!CP8) -> 0 | CQ8: =SUM('2026:2024'!CQ8) -> 113300 | CR8: =SUM('2026:2024'!CR8) -> 9900 | CS8: {=IF(CS$2="FY",SUMPRODUCT(Data[Nhập-SPC+SPP-NX]*(Data[Year]=CS$1)*(Data[Main SKU name_GOM]=$A8)*(Data[SKU name_NHẬP_GOM]=CS$3)),SUMPRODUCT(Data[Nhập-SPC+SPP-NX]*(Data[Year]=CS$1)*(Data[Month]=CS$2)*(Data[Main SKU name_GOM]=$A8)*(Data[SKU name_NHẬP_GOM]=CS$3)))} -> 0 | CT8: =SUM(CJ8:CS8) -> 2353700 | CV8: =SUM('2026:2024'!CV8) -> 2200 | CW8: =SUM('2026:2024'!CW8) -> 214719 | CX8: =SUM('2026:2024'!CX8) -> 2832059 | CY8: =SUM('2026:2024'!CY8) -> 2200 | CZ8: =SUM('2026:2024'!CZ8) -> 76198 | DA8: =SUM('2026:2024'!DA8) -> 0 | DB8: =SUM('2026:2024'!DB8) -> 0 | DC8: =SUM('2026:2024'!DC8) -> 94600 | DD8: =SUM('2026:2024'!DD8) -> 15400 | DE8: {=IF(DE$2="FY",SUMPRODUCT(Data[Nhập-SPC+SPP-NX]*(Data[Year]=DE$1)*(Data[Main SKU name_GOM]=$A8)*(Data[SKU name_NHẬP_GOM]=DE$3)),SUMPRODUCT(Data[Nhập-SPC+SPP-NX]*(Data[Year]=DE$1)*(Data[Month]=DE$2)*(Data[Main SKU name_GOM]=$A8)*(Data[SKU name_NHẬP_GOM]=DE$3)))} -> 0 | DF8: =SUM(CV8:DE8) -> 3237376 | DH8: =SUM('2026:2024'!DH8) -> 9900 | DI8: =SUM('2026:2024'!DI8) -> 159500 | DJ8: =SUM('2026:2024'!DJ8) -> 2840201 | DK8: =SUM('2026:2024'!DK8) -> 4100 | DL8: =SUM('2026:2024'!DL8) -> 96032.5 | DM8: =SUM('2026:2024'!DM8) -> 0 | DN8: =SUM('2026:2024'!DN8) -> 1100 | DO8: =SUM('2026:2024'!DO8) -> 24200 | DP8: =SUM('2026:2024'!DP8) -> 7700 | DQ8: {=IF(DQ$2="FY",SUMPRODUCT(Data[Nhập-SPC+SPP-NX]*(Data[Year]=DQ$1)*(Data[Main SKU name_GOM]=$A8)*(Data[SKU name_NHẬP_GOM]=DQ$3)),SUMPRODUCT(Data[Nhập-SPC+SPP-NX]*(Data[Year]=DQ$1)*(Data[Month]=DQ$2)*(Data[Main SKU name_GOM]=$A8)*(Data[SKU name_NHẬP_GOM]=DQ$3)))} -> 0 | DR8: =SUM(DH8:DQ8) -> 3142733.5 | DT8: =SUM('2026:2024'!DT8) -> 12100 | DU8: =SUM('2026:2024'!DU8) -> 141900 | DV8: =SUM('2026:2024'!DV8) -> 3730910 | DW8: =SUM('2026:2024'!DW8) -> 52800 | DX8: =SUM('2026:2024'!DX8) -> 604006 | DY8: =SUM('2026:2024'!DY8) -> 0 | DZ8: =SUM('2026:2024'!DZ8) -> 0 | EA8: =SUM('2026:2024'!EA8) -> 27500 | EB8: =SUM('2026:2024'!EB8) -> 33000 | EC8: {=IF(EC$2="FY",SUMPRODUCT(Data[Nhập-SPC+SPP-NX]*(Data[Year]=EC$1)*(Data[Main SKU name_GOM]=$A8)*(Data[SKU name_NHẬP_GOM]=EC$3)),SUMPRODUCT(Data[Nhập-SPC+SPP-NX]*(Data[Year]=EC$1)*(Data[Month]=EC$2)*(Data[Main SKU name_GOM]=$A8)*(Data[SKU name_NHẬP_GOM]=EC$3)))} -> 0 | ED8: =SUM(DT8:EC8) -> 4602216 | EF8: =SUM('2026:2024'!EF8) -> 0 | EG8: =SUM('2026:2024'!EG8) -> 247500 | EH8: =SUM('2026:2024'!EH8) -> 1930500 | EI8: =SUM('2026:2024'!EI8) -> 5500 | EJ8: =SUM('2026:2024'!EJ8) -> 30835 | EK8: =SUM('2026:2024'!EK8) -> 0 | EL8: =SUM('2026:2024'!EL8) -> 0 | EM8: =SUM('2026:2024'!EM8) -> 81400 | EN8: =SUM('2026:2024'!EN8) -> 11000 | EO8: {=IF(EO$2="FY",SUMPRODUCT(Data[Nhập-SPC+SPP-NX]*(Data[Year]=EO$1)*(Data[Main SKU name_GOM]=$A8)*(Data[SKU name_NHẬP_GOM]=EO$3)),SUMPRODUCT(Data[Nhập-SPC+SPP-NX]*(Data[Year]=EO$1)*(Data[Month]=EO$2)*(Data[Main SKU name_GOM]=$A8)*(Data[SKU name_NHẬP_GOM]=EO$3)))} -> 0 | EP8: =SUM(EF8:EO8) -> 2306735 | ER8: =SUM('2026:2024'!ER8) -> 12100 | ES8: =SUM('2026:2024'!ES8) -> 155100 | ET8: =SUM('2026:2024'!ET8) -> 3163600 | EU8: =SUM('2026:2024'!EU8) -> 2200 | EV8: =SUM('2026:2024'!EV8) -> 34100 | EW8: =SUM('2026:2024'!EW8) -> 0 | EX8: =SUM('2026:2024'!EX8) -> 0 | EY8: =SUM('2026:2024'!EY8) -> 52800 | EZ8: =SUM('2026:2024'!EZ8) -> 20900 | FA8: {=IF(FA$2="FY",SUMPRODUCT(Data[Nhập-SPC+SPP-NX]*(Data[Year]=FA$1)*(Data[Main SKU name_GOM]=$A8)*(Data[SKU name_NHẬP_GOM]=FA$3)),SUMPRODUCT(Data[Nhập-SPC+SPP-NX]*(Data[Year]=FA$1)*(Data[Month]=FA$2)*(Data[Main SKU name_GOM]=$A8)*(Data[SKU name_NHẬP_GOM]=FA$3)))} -> 0 | FB8: =SUM(ER8:FA8) -> 3440800
A9: WSS03 | B9: WSS03 | D9: =SUM('2026:2024'!D9) -> 0 | E9: =SUM('2026:2024'!E9) -> 0 | F9: =SUM('2026:2024'!F9) -> 0 | G9: =SUM('2026:2024'!G9) -> 2200 | H9: =SUM('2026:2024'!H9) -> 3015100 | I9: =SUM('2026:2024'!I9) -> 0 | J9: =SUM('2026:2024'!J9) -> 0 | K9: =SUM('2026:2024'!K9) -> 0 | L9: =SUM('2026:2024'!L9) -> 74800 | M9: {=IF(M$2="FY",SUMPRODUCT(Data[Nhập-SPC+SPP-NX]*(Data[Year]=M$1)*(Data[Main SKU name_GOM]=$A9)*(Data[SKU name_NHẬP_GOM]=M$3)),SUMPRODUCT(Data[Nhập-SPC+SPP-NX]*(Data[Year]=M$1)*(Data[Month]=M$2)*(Data[Main SKU name_GOM]=$A9)*(Data[SKU name_NHẬP_GOM]=M$3)))} -> 0 | N9: =SUM(D9:M9) -> 3092100 | P9: =SUM('2026:2024'!P9) -> 0 | Q9: =SUM('2026:2024'!Q9) -> 0 | R9: =SUM('2026:2024'!R9) -> 0 | S9: =SUM('2026:2024'!S9) -> 0 | T9: =SUM('2026:2024'!T9) -> 376200 | U9: =SUM('2026:2024'!U9) -> 0 | V9: =SUM('2026:2024'!V9) -> 0 | W9: =SUM('2026:2024'!W9) -> 0 | X9: =SUM('2026:2024'!X9) -> 2200 | Y9: {=IF(Y$2="FY",SUMPRODUCT(Data[Nhập-SPC+SPP-NX]*(Data[Year]=Y$1)*(Data[Main SKU name_GOM]=$A9)*(Data[SKU name_NHẬP_GOM]=Y$3)),SUMPRODUCT(Data[Nhập-SPC+SPP-NX]*(Data[Year]=Y$1)*(Data[Month]=Y$2)*(Data[Main SKU name_GOM]=$A9)*(Data[SKU name_NHẬP_GOM]=Y$3)))} -> 0 | Z9: =SUM(P9:Y9) -> 378400 | AB9: =SUM('2026:2024'!AB9) -> 0 | AC9: =SUM('2026:2024'!AC9) -> 0 | AD9: =SUM('2026:2024'!AD9) -> 0 | AE9: =SUM('2026:2024'!AE9) -> 0 | AF9: =SUM('2026:2024'!AF9) -> 5500 | AG9: =SUM('2026:2024'!AG9) -> 0 | AH9: =SUM('2026:2024'!AH9) -> 0 | AI9: =SUM('2026:2024'!AI9) -> 0 | AJ9: =SUM('2026:2024'!AJ9) -> 2200 | AK9: {=IF(AK$2="FY",SUMPRODUCT(Data[Nhập-SPC+SPP-NX]*(Data[Year]=AK$1)*(Data[Main SKU name_GOM]=$A9)*(Data[SKU name_NHẬP_GOM]=AK$3)),SUMPRODUCT(Data[Nhập-SPC+SPP-NX]*(Data[Year]=AK$1)*(Data[Month]=AK$2)*(Data[Main SKU name_GOM]=$A9)*(Data[SKU name_NHẬP_GOM]=AK$3)))} -> 0 | AL9: =SUM(AB9:AK9) -> 7700 | AN9: =SUM('2026:2024'!AN9) -> 0 | AO9: =SUM('2026:2024'!AO9) -> 0 | AP9: =SUM('2026:2024'!AP9) -> 0 | AQ9: =SUM('2026:2024'!AQ9) -> 0 | AR9: =SUM('2026:2024'!AR9) -> 628100 | AS9: =SUM('2026:2024'!AS9) -> 0 | AT9: =SUM('2026:2024'!AT9) -> 0 | AU9: =SUM('2026:2024'!AU9) -> 0 | AV9: =SUM('2026:2024'!AV9) -> 23100 | AW9: {=IF(AW$2="FY",SUMPRODUCT(Data[Nhập-SPC+SPP-NX]*(Data[Year]=AW$1)*(Data[Main SKU name_GOM]=$A9)*(Data[SKU name_NHẬP_GOM]=AW$3)),SUMPRODUCT(Data[Nhập-SPC+SPP-NX]*(Data[Year]=AW$1)*(Data[Month]=AW$2)*(Data[Main SKU name_GOM]=$A9)*(Data[SKU name_NHẬP_GOM]=AW$3)))} -> 0 | AX9: =SUM(AN9:AW9) -> 651200 | AZ9: =SUM('2026:2024'!AZ9) -> 0 | BA9: =SUM('2026:2024'!BA9) -> 0 | BB9: =SUM('2026:2024'!BB9) -> 0 | BC9: =SUM('2026:2024'!BC9) -> 0 | BD9: =SUM('2026:2024'!BD9) -> 1118700 | BE9: =SUM('2026:2024'!BE9) -> 0 | BF9: =SUM('2026:2024'!BF9) -> 0 | BG9: =SUM('2026:2024'!BG9) -> 0 | BH9: =SUM('2026:2024'!BH9) -> 7700 | BI9: {=IF(BI$2="FY",SUMPRODUCT(Data[Nhập-SPC+SPP-NX]*(Data[Year]=BI$1)*(Data[Main SKU name_GOM]=$A9)*(Data[SKU name_NHẬP_GOM]=BI$3)),SUMPRODUCT(Data[Nhập-SPC+SPP-NX]*(Data[Year]=BI$1)*(Data[Month]=BI$2)*(Data[Main SKU name_GOM]=$A9)*(Data[SKU name_NHẬP_GOM]=BI$3)))} -> 0 | BJ9: =SUM(AZ9:BI9) -> 1126400 | BL9: =SUM('2026:2024'!BL9) -> 0 | BM9: =SUM('2026:2024'!BM9) -> 0 | BN9: =SUM('2026:2024'!BN9) -> 0 | BO9: =SUM('2026:2024'!BO9) -> 0 | BP9: =SUM('2026:2024'!BP9) -> 0 | BQ9: =SUM('2026:2024'!BQ9) -> 0 | BR9: =SUM('2026:2024'!BR9) -> 0 | BS9: =SUM('2026:2024'!BS9) -> 0 | BT9: =SUM('2026:2024'!BT9) -> 0 | BU9: {=IF(BU$2="FY",SUMPRODUCT(Data[Nhập-SPC+SPP-NX]*(Data[Year]=BU$1)*(Data[Main SKU name_GOM]=$A9)*(Data[SKU name_NHẬP_GOM]=BU$3)),SUMPRODUCT(Data[Nhập-SPC+SPP-NX]*(Data[Year]=BU$1)*(Data[Month]=BU$2)*(Data[Main SKU name_GOM]=$A9)*(Data[SKU name_NHẬP_GOM]=BU$3)))} -> 0 | BV9: =SUM(BL9:BU9) -> 0 | BX9: =SUM('2026:2024'!BX9) -> 0 | BY9: =SUM('2026:2024'!BY9) -> 0 | BZ9: =SUM('2026:2024'!BZ9) -> 0 | CA9: =SUM('2026:2024'!CA9) -> 0 | CB9: =SUM('2026:2024'!CB9) -> 0 | CC9: =SUM('2026:2024'!CC9) -> 0 | CD9: =SUM('2026:2024'!CD9) -> 0 | CE9: =SUM('2026:2024'!CE9) -> 0 | CF9: =SUM('2026:2024'!CF9) -> 0 | CG9: {=IF(CG$2="FY",SUMPRODUCT(Data[Nhập-SPC+SPP-NX]*(Data[Year]=CG$1)*(Data[Main SKU name_GOM]=$A9)*(Data[SKU name_NHẬP_GOM]=CG$3)),SUMPRODUCT(Data[Nhập-SPC+SPP-NX]*(Data[Year]=CG$1)*(Data[Month]=CG$2)*(Data[Main SKU name_GOM]=$A9)*(Data[SKU name_NHẬP_GOM]=CG$3)))} -> 0 | CH9: =SUM(BX9:CG9) -> 0 | CJ9: =SUM('2026:2024'!CJ9) -> 0 | CK9: =SUM('2026:2024'!CK9) -> 0 | CL9: =SUM('2026:2024'!CL9) -> 0 | CM9: =SUM('2026:2024'!CM9) -> 0 | CN9: =SUM('2026:2024'!CN9) -> 0 | CO9: =SUM('2026:2024'!CO9) -> 0 | CP9: =SUM('2026:2024'!CP9) -> 0 | CQ9: =SUM('2026:2024'!CQ9) -> 0 | CR9: =SUM('2026:2024'!CR9) -> 0 | CS9: {=IF(CS$2="FY",SUMPRODUCT(Data[Nhập-SPC+SPP-NX]*(Data[Year]=CS$1)*(Data[Main SKU name_GOM]=$A9)*(Data[SKU name_NHẬP_GOM]=CS$3)),SUMPRODUCT(Data[Nhập-SPC+SPP-NX]*(Data[Year]=CS$1)*(Data[Month]=CS$2)*(Data[Main SKU name_GOM]=$A9)*(Data[SKU name_NHẬP_GOM]=CS$3)))} -> 0 | CT9: =SUM(CJ9:CS9) -> 0 | CV9: =SUM('2026:2024'!CV9) -> 0 | CW9: =SUM('2026:2024'!CW9) -> 0 | CX9: =SUM('2026:2024'!CX9) -> 0 | CY9: =SUM('2026:2024'!CY9) -> 0 | CZ9: =SUM('2026:2024'!CZ9) -> 0 | DA9: =SUM('2026:2024'!DA9) -> 0 | DB9: =SUM('2026:2024'!DB9) -> 0 | DC9: =SUM('2026:2024'!DC9) -> 0 | DD9: =SUM('2026:2024'!DD9) -> 0 | DE9: {=IF(DE$2="FY",SUMPRODUCT(Data[Nhập-SPC+SPP-NX]*(Data[Year]=DE$1)*(Data[Main SKU name_GOM]=$A9)*(Data[SKU name_NHẬP_GOM]=DE$3)),SUMPRODUCT(Data[Nhập-SPC+SPP-NX]*(Data[Year]=DE$1)*(Data[Month]=DE$2)*(Data[Main SKU name_GOM]=$A9)*(Data[SKU name_NHẬP_GOM]=DE$3)))} -> 0 | DF9: =SUM(CV9:DE9) -> 0 | DH9: =SUM('2026:2024'!DH9) -> 0 | DI9: =SUM('2026:2024'!DI9) -> 0 | DJ9: =SUM('2026:2024'!DJ9) -> 0 | DK9: =SUM('2026:2024'!DK9) -> 0 | DL9: =SUM('2026:2024'!DL9) -> 157300 | DM9: =SUM('2026:2024'!DM9) -> 0 | DN9: =SUM('2026:2024'!DN9) -> 0 | DO9: =SUM('2026:2024'!DO9) -> 0 | DP9: =SUM('2026:2024'!DP9) -> 0 | DQ9: {=IF(DQ$2="FY",SUMPRODUCT(Data[Nhập-SPC+SPP-NX]*(Data[Year]=DQ$1)*(Data[Main SKU name_GOM]=$A9)*(Data[SKU name_NHẬP_GOM]=DQ$3)),SUMPRODUCT(Data[Nhập-SPC+SPP-NX]*(Data[Year]=DQ$1)*(Data[Month]=DQ$2)*(Data[Main SKU name_GOM]=$A9)*(Data[SKU name_NHẬP_GOM]=DQ$3)))} -> 0 | DR9: =SUM(DH9:DQ9) -> 157300 | DT9: =SUM('2026:2024'!DT9) -> 0 | DU9: =SUM('2026:2024'!DU9) -> 0 | DV9: =SUM('2026:2024'!DV9) -> 0 | DW9: =SUM('2026:2024'!DW9) -> 0 | DX9: =SUM('2026:2024'!DX9) -> 108900 | DY9: =SUM('2026:2024'!DY9) -> 0 | DZ9: =SUM('2026:2024'!DZ9) -> 0 | EA9: =SUM('2026:2024'!EA9) -> 0 | EB9: =SUM('2026:2024'!EB9) -> 33000 | EC9: {=IF(EC$2="FY",SUMPRODUCT(Data[Nhập-SPC+SPP-NX]*(Data[Year]=EC$1)*(Data[Main SKU name_GOM]=$A9)*(Data[SKU name_NHẬP_GOM]=EC$3)),SUMPRODUCT(Data[Nhập-SPC+SPP-NX]*(Data[Year]=EC$1)*(Data[Month]=EC$2)*(Data[Main SKU name_GOM]=$A9)*(Data[SKU name_NHẬP_GOM]=EC$3)))} -> 0 | ED9: =SUM(DT9:EC9) -> 141900 | EF9: =SUM('2026:2024'!EF9) -> 0 | EG9: =SUM('2026:2024'!EG9) -> 0 | EH9: =SUM('2026:2024'!EH9) -> 0 | EI9: =SUM('2026:2024'!EI9) -> 1100 | EJ9: =SUM('2026:2024'!EJ9) -> 93500 | EK9: =SUM('2026:2024'!EK9) -> 0 | EL9: =SUM('2026:2024'!EL9) -> 0 | EM9: =SUM('2026:2024'!EM9) -> 0 | EN9: =SUM('2026:2024'!EN9) -> 0 | EO9: {=IF(EO$2="FY",SUMPRODUCT(Data[Nhập-SPC+SPP-NX]*(Data[Year]=EO$1)*(Data[Main SKU name_GOM]=$A9)*(Data[SKU name_NHẬP_GOM]=EO$3)),SUMPRODUCT(Data[Nhập-SPC+SPP-NX]*(Data[Year]=EO$1)*(Data[Month]=EO$2)*(Data[Main SKU name_GOM]=$A9)*(Data[SKU name_NHẬP_GOM]=EO$3)))} -> 0 | EP9: =SUM(EF9:EO9) -> 94600 | ER9: =SUM('2026:2024'!ER9) -> 0 | ES9: =SUM('2026:2024'!ES9) -> 0 | ET9: =SUM('2026:2024'!ET9) -> 0 | EU9: =SUM('2026:2024'!EU9) -> 1100 | EV9: =SUM('2026:2024'!EV9) -> 526900 | EW9: =SUM('2026:2024'!EW9) -> 0 | EX9: =SUM('2026:2024'!EX9) -> 0 | EY9: =SUM('2026:2024'!EY9) -> 0 | EZ9: =SUM('2026:2024'!EZ9) -> 6600 | FA9: {=IF(FA$2="FY",SUMPRODUCT(Data[Nhập-SPC+SPP-NX]*(Data[Year]=FA$1)*(Data[Main SKU name_GOM]=$A9)*(Data[SKU name_NHẬP_GOM]=FA$3)),SUMPRODUCT(Data[Nhập-SPC+SPP-NX]*(Data[Year]=FA$1)*(Data[Month]=FA$2)*(Data[Main SKU name_GOM]=$A9)*(Data[SKU name_NHẬP_GOM]=FA$3)))} -> 0 | FB9: =SUM(ER9:FA9) -> 534600
B10: TỔNG | D10: =SUM(D6:D9) -> 13692571 | E10: =SUM(E6:E9) -> 17388097 | F10: =SUM(F6:F9) -> 48923400 | G10: =SUM(G6:G9) -> 915344 | H10: =SUM(H6:H9) -> 5758074.5 | I10: =SUM(I6:I9) -> 108900 | J10: =SUM(J6:J9) -> 176000 | K10: =SUM(K6:K9) -> 599500 | ... N10: =SUM(N6:N9) -> 87893509 | P10: =SUM(P6:P9) -> 905398 | Q10: =SUM(Q6:Q9) -> 1010900 | R10: =SUM(R6:R9) -> 6365019 | S10: =SUM(S6:S9) -> 169844 | T10: =SUM(T6:T9) -> 470592 | U10: =SUM(U6:U9) -> 1100 | V10: =SUM(V6:V9) -> 8800 | W10: =SUM(W6:W9) -> 18700 | ... Z10: =SUM(Z6:Z9) -> 8972325.2 | AB10: =SUM(AB6:AB9) -> 1068233 | AC10: =SUM(AC6:AC9) -> 1068540 | AD10: =SUM(AD6:AD9) -> 3763282 | AE10: =SUM(AE6:AE9) -> 157300 | AF10: =SUM(AF6:AF9) -> 104431 | AG10: =SUM(AG6:AG9) -> 4400 | AH10: =SUM(AH6:AH9) -> 29700 | AI10: =SUM(AI6:AI9) -> 51700 | ... AL10: =SUM(AL6:AL9) -> 6268486 | AN10: =SUM(AN6:AN9) -> 655600 | AO10: =SUM(AO6:AO9) -> 2413400 | AP10: =SUM(AP6:AP9) -> 7058629 | AQ10: =SUM(AQ6:AQ9) -> 118800 | AR10: =SUM(AR6:AR9) -> 724815 | AS10: =SUM(AS6:AS9) -> 0 | AT10: =SUM(AT6:AT9) -> 23100 | AU10: =SUM(AU6:AU9) -> 16500 | ... AX10: =SUM(AX6:AX9) -> 11041644 | AZ10: =SUM(AZ6:AZ9) -> 983400 | BA10: =SUM(BA6:BA9) -> 1922037 | BB10: =SUM(BB6:BB9) -> 5742000 | BC10: =SUM(BC6:BC9) -> 47300 | BD10: =SUM(BD6:BD9) -> 1215045 | BE10: =SUM(BE6:BE9) -> 2200 | BF10: =SUM(BF6:BF9) -> 35200 | BG10: =SUM(BG6:BG9) -> 25300 | ... BJ10: =SUM(BJ6:BJ9) -> 10005532 | BL10: =SUM(BL6:BL9) -> 529100 | BM10: =SUM(BM6:BM9) -> 2038300 | BN10: =SUM(BN6:BN9) -> 4715700 | BO10: =SUM(BO6:BO9) -> 243100 | BP10: =SUM(BP6:BP9) -> 322300 | BQ10: =SUM(BQ6:BQ9) -> 1100 | BR10: =SUM(BR6:BR9) -> 11000 | BS10: =SUM(BS6:BS9) -> 35200 | ... BV10: =SUM(BV6:BV9) -> 7903500 | BX10: =SUM(BX6:BX9) -> 723800 | BY10: =SUM(BY6:BY9) -> 2494800 | BZ10: =SUM(BZ6:BZ9) -> 4240500 | CA10: =SUM(CA6:CA9) -> 105600 | CB10: =SUM(CB6:CB9) -> 402800 | CC10: =SUM(CC6:CC9) -> 8800 | CD10: =SUM(CD6:CD9) -> 16500 | CE10: =SUM(CE6:CE9) -> 31900 | ... CH10: =SUM(CH6:CH9) -> 8043400 | CJ10: =SUM(CJ6:CJ9) -> 771100 | CK10: =SUM(CK6:CK9) -> 1454200 | CL10: =SUM(CL6:CL9) -> 2176900 | CM10: =SUM(CM6:CM9) -> 3300 | CN10: =SUM(CN6:CN9) -> 97600 | CO10: =SUM(CO6:CO9) -> 11000 | CP10: =SUM(CP6:CP9) -> 12100 | CQ10: =SUM(CQ6:CQ9) -> 113300 | ... CT10: =SUM(CT6:CT9) -> 4656000 | CV10: =SUM(CV6:CV9) -> 1213300 | CW10: =SUM(CW6:CW9) -> 1365564 | CX10: =SUM(CX6:CX9) -> 2902459 | CY10: =SUM(CY6:CY9) -> 2200 | CZ10: =SUM(CZ6:CZ9) -> 149897 | DA10: =SUM(DA6:DA9) -> 0 | DB10: =SUM(DB6:DB9) -> 15400 | DC10: =SUM(DC6:DC9) -> 104500 | ... DF10: =SUM(DF6:DF9) -> 5781320 | DH10: =SUM(DH6:DH9) -> 1578500 | DI10: =SUM(DI6:DI9) -> 1100355 | DJ10: =SUM(DJ6:DJ9) -> 2884201 | DK10: =SUM(DK6:DK9) -> 4100 | DL10: =SUM(DL6:DL9) -> 426237 | DM10: =SUM(DM6:DM9) -> 0 | DN10: =SUM(DN6:DN9) -> 9900 | DO10: =SUM(DO6:DO9) -> 24200 | ... DR10: =SUM(DR6:DR9) -> 6036293 | DT10: =SUM(DT6:DT9) -> 1460640 | DU10: =SUM(DU6:DU9) -> 711700 | DV10: =SUM(DV6:DV9) -> 3847510 | DW10: =SUM(DW6:DW9) -> 53900 | DX10: =SUM(DX6:DX9) -> 915922.5 | DY10: =SUM(DY6:DY9) -> 59400 | DZ10: =SUM(DZ6:DZ9) -> 12100 | EA10: =SUM(EA6:EA9) -> 44000 | ... ED10: =SUM(ED6:ED9) -> 7192072.5 | EF10: =SUM(EF6:EF9) -> 1923600 | EG10: =SUM(EG6:EG9) -> 1484901 | EH10: =SUM(EH6:EH9) -> 2025100 | EI10: =SUM(EI6:EI9) -> 6600 | EJ10: =SUM(EJ6:EJ9) -> 313535 | EK10: =SUM(EK6:EK9) -> 2200 | EL10: =SUM(EL6:EL9) -> 0 | EM10: =SUM(EM6:EM9) -> 81400 | ... EP10: =SUM(EP6:EP9) -> 5856036 | ER10: =SUM(ER6:ER9) -> 1879900 | ES10: =SUM(ES6:ES9) -> 323400 | ET10: =SUM(ET6:ET9) -> 3202100 | EU10: =SUM(EU6:EU9) -> 3300 | EV10: =SUM(EV6:EV9) -> 614900 | EW10: =SUM(EW6:EW9) -> 18700 | EX10: =SUM(EX6:EX9) -> 2200 | EY10: =SUM(EY6:EY9) -> 52800 | ... FB10: =SUM(FB6:FB9) -> 6136900
B13: %Thu hồi
B14: iSS01084 | D14: =IFERROR(D6/N6,0) -> 0.87832135 | E14: =IFERROR(E6/N6,0) -> 0.039726386 | F14: =IFERROR(F6/N6,0) -> 0.013105691 | G14: =IFERROR(G6/N6,0) -> 0.0011587411 | H14: =IFERROR(H6/N6,0) -> 0.052011905 | I14: =IFERROR(I6/N6,0) -> 0.006807604 | J14: =IFERROR(J6/N6,0) -> 0.0015208477 | K14: =IFERROR(K6/N6,0) -> 0.0026071675 | L14: =IFERROR(L6/N6,0) -> 0.0047403046 | M14: =IFERROR(M6/N6,0) -> 0 | N14: =IFERROR(N6/N6,0) -> 1 | P14: =IFERROR(P6/Z6,0) -> 0.92504486 | Q14: =IFERROR(Q6/Z6,0) -> 0.01818071 | R14: =IFERROR(R6/Z6,0) -> 0.002232302 | S14: =IFERROR(S6/Z6,0) -> 0.0056814719 | T14: =IFERROR(T6/Z6,0) -> 0.045451775 | U14: =IFERROR(U6/Z6,0) -> 0.0011362944 | V14: =IFERROR(V6/Z6,0) -> 0.0022725888 | W14: =IFERROR(W6/Z6,0) -> 0 | X14: =IFERROR(X6/Z6,0) -> 0 | Y14: =IFERROR(Y6/Z6,0) -> 0 | Z14: =IFERROR(Z6/Z6,0) -> 1 | AB14: =IFERROR(AB6/AL6,0) -> 0.88103032 | AC14: =IFERROR(AC6/AL6,0) -> 0.053581763 | AD14: =IFERROR(AD6/AL6,0) -> 0.001816331 | AE14: =IFERROR(AE6/AL6,0) -> 0.0054489929 | AF14: =IFERROR(AF6/AL6,0) -> 0.047224605 | AG14: =IFERROR(AG6/AL6,0) -> 0.0036326619 | AH14: =IFERROR(AH6/AL6,0) -> 0.0036326619 | AI14: =IFERROR(AI6/AL6,0) -> 0 | AJ14: =IFERROR(AJ6/AL6,0) -> 0.0036326619 | AK14: =IFERROR(AK6/AL6,0) -> 0 | AL14: =IFERROR(AL6/AL6,0) -> 1 | AN14: =IFERROR(AN6/AX6,0) -> 0.95595432 | AO14: =IFERROR(AO6/AX6,0) -> 0.016313214 | AP14: =IFERROR(AP6/AX6,0) -> 0.0016313214 | AQ14: =IFERROR(AQ6/AX6,0) -> 0 | AR14: =IFERROR(AR6/AX6,0) -> 0.016313214 | AS14: =IFERROR(AS6/AX6,0) -> 0 | AT14: =IFERROR(AT6/AX6,0) -> 0.0097879282 | AU14: =IFERROR(AU6/AX6,0) -> 0 | AV14: =IFERROR(AV6/AX6,0) -> 0 | AW14: =IFERROR(AW6/AX6,0) -> 0 | AX14: =IFERROR(AX6/AX6,0) -> 1 | AZ14: =IFERROR(AZ6/BJ6,0) -> 0.91666667 | BA14: =IFERROR(BA6/BJ6,0) -> 0.019547325 | BB14: =IFERROR(BB6/BJ6,0) -> 0.044238683 | BC14: =IFERROR(BC6/BJ6,0) -> 0 | BD14: =IFERROR(BD6/BJ6,0) -> 0.013374486 | BE14: =IFERROR(BE6/BJ6,0) -> 0.0020576132 | BF14: =IFERROR(BF6/BJ6,0) -> 0.0020576132 | BG14: =IFERROR(BG6/BJ6,0) -> 0 | BH14: =IFERROR(BH6/BJ6,0) -> 0.0020576132 | BI14: =IFERROR(BI6/BJ6,0) -> 0 | BJ14: =IFERROR(BJ6/BJ6,0) -> 1 | BL14: =IFERROR(BL6/BV6,0) -> 0.75911252 | BM14: =IFERROR(BM6/BV6,0) -> 0.18700475 | BN14: =IFERROR(BN6/BV6,0) -> 0 | BO14: =IFERROR(BO6/BV6,0) -> 0.0063391442 | BP14: =IFERROR(BP6/BV6,0) -> 0.025356577 | BQ14: =IFERROR(BQ6/BV6,0) -> 0.0015847861 | BR14: =IFERROR(BR6/BV6,0) -> 0 | BS14: =IFERROR(BS6/BV6,0) -> 0.020602219 | BT14: =IFERROR(BT6/BV6,0) -> 0 | BU14: =IFERROR(BU6/BV6,0) -> 0 | BV14: =IFERROR(BV6/BV6,0) -> 1 | BX14: =IFERROR(BX6/CH6,0) -> 0.91993958 | BY14: =IFERROR(BY6/CH6,0) -> 0.042296073 | BZ14: =IFERROR(BZ6/CH6,0) -> 0 | CA14: =IFERROR(CA6/CH6,0) -> 0 | CB14: =IFERROR(CB6/CH6,0) -> 0.010574018 | CC14: =IFERROR(CC6/CH6,0) -> 0.0090634441 | CD14: =IFERROR(CD6/CH6,0) -> 0.0060422961 | CE14: =IFERROR(CE6/CH6,0) -> 0.003021148 | CF14: =IFERROR(CF6/CH6,0) -> 0.0090634441 | CG14: =IFERROR(CG6/CH6,0) -> 0 | CH14: =IFERROR(CH6/CH6,0) -> 1 | CJ14: =IFERROR(CJ6/CT6,0) -> 0.84106892 | CK14: =IFERROR(CK6/CT6,0) -> 0.090014065 | CL14: =IFERROR(CL6/CT6,0) -> 0.0098452883 | CM14: =IFERROR(CM6/CT6,0) -> 0 | CN14: =IFERROR(CN6/CT6,0) -> 0.036568214 | CO14: =IFERROR(CO6/CT6,0) -> 0.014064698 | CP14: =IFERROR(CP6/CT6,0) -> 0 | CQ14: =IFERROR(CQ6/CT6,0) -> 0 | CR14: =IFERROR(CR6/CT6,0) -> 0.0084388186 | CS14: =IFERROR(CS6/CT6,0) -> 0 | CT14: =IFERROR(CT6/CT6,0) -> 1 | CV14: =IFERROR(CV6/DF6,0) -> 0.90114305 | CW14: =IFERROR(CW6/DF6,0) -> 0.035605531 | CX14: =IFERROR(CX6/DF6,0) -> 0.00088520928 | CY14: =IFERROR(CY6/DF6,0) -> 0 | CZ14: =IFERROR(CZ6/DF6,0) -> 0.047800496 | DA14: =IFERROR(DA6/DF6,0) -> 0 | DB14: =IFERROR(DB6/DF6,0) -> 0.00088520928 | DC14: =IFERROR(DC6/DF6,0) -> 0.0053112557 | DD14: =IFERROR(DD6/DF6,0) -> 0.0083692514 | DE14: =IFERROR(DE6/DF6,0) -> 0 | DF14: =IFERROR(DF6/DF6,0) -> 1 | DH14: =IFERROR(DH6/DR6,0) -> 0.85877301 | DI14: =IFERROR(DI6/DR6,0) -> 0.051383489 | DJ14: =IFERROR(DJ6/DR6,0) -> 0.0018066753 | DK14: =IFERROR(DK6/DR6,0) -> 0 | DL14: =IFERROR(DL6/DR6,0) -> 0.0874346 | DM14: =IFERROR(DM6/DR6,0) -> 0 | DN14: =IFERROR(DN6/DR6,0) -> 0 | DO14: =IFERROR(DO6/DR6,0) -> 0 | DP14: =IFERROR(DP6/DR6,0) -> 0.00060222511 | DQ14: =IFERROR(DQ6/DR6,0) -> 0 | DR14: =IFERROR(DR6/DR6,0) -> 1 | DT14: =IFERROR(DT6/ED6,0) -> 0.74956848 | DU14: =IFERROR(DU6/ED6,0) -> 0.044904962 | DV14: =IFERROR(DV6/ED6,0) -> 0.055267645 | DW14: =IFERROR(DW6/ED6,0) -> 0.00057570464 | DX14: =IFERROR(DX6/ED6,0) -> 0.099021197 | DY14: =IFERROR(DY6/ED6,0) -> 0.03108805 | DZ14: =IFERROR(DZ6/ED6,0) -> 0 | EA14: =IFERROR(EA6/ED6,0) -> 0.0086355695 | EB14: =IFERROR(EB6/ED6,0) -> 0.010938388 | EC14: =IFERROR(EC6/ED6,0) -> 0 | ED14: =IFERROR(ED6/ED6,0) -> 1 | EF14: =IFERROR(EF6/EP6,0) -> 0.90703637 | EG14: =IFERROR(EG6/EP6,0) -> 0.012534422 | EH14: =IFERROR(EH6/EP6,0) -> 0.0057449435 | EI14: =IFERROR(EI6/EP6,0) -> 0 | EJ14: =IFERROR(EJ6/EP6,0) -> 0.069983857 | EK14: =IFERROR(EK6/EP6,0) -> 0.0010445352 | EL14: =IFERROR(EL6/EP6,0) -> 0 | EM14: =IFERROR(EM6/EP6,0) -> 0 | EN14: =IFERROR(EN6/EP6,0) -> 0.0036558731 | EO14: =IFERROR(EO6/EP6,0) -> 0 | EP14: =IFERROR(EP6/EP6,0) -> 1 | ER14: =IFERROR(ER6/FB6,0) -> 0.9454343 | ES14: =IFERROR(ES6/FB6,0) -> 0.0038975501 | ET14: =IFERROR(ET6/FB6,0) -> 0.0083518931 | EU14: =IFERROR(EU6/FB6,0) -> 0 | EV14: =IFERROR(EV6/FB6,0) -> 0.027282851 | EW14: =IFERROR(EW6/FB6,0) -> 0.0077951002 | EX14: =IFERROR(EX6/FB6,0) -> 0.0011135857 | EY14: =IFERROR(EY6/FB6,0) -> 0 | EZ14: =IFERROR(EZ6/FB6,0) -> 0.0061247216 | FA14: =IFERROR(FA6/FB6,0) -> 0 | FB14: =IFERROR(FB6/FB6,0) -> 1
B15: iSS01 | D15: =IFERROR(D7/N7,0) -> 0.020824144 | E15: =IFERROR(E7/N7,0) -> 0.92157625 | F15: =IFERROR(F7/N7,0) -> 0.030668184 | G15: =IFERROR(G7/N7,0) -> 0 | H15: =IFERROR(H7/N7,0) -> 0.013427635 | I15: =IFERROR(I7/N7,0) -> 0.00023410828 | J15: =IFERROR(J7/N7,0) -> 0.010066656 | K15: =IFERROR(K7/N7,0) -> 0.0011705414 | L15: =IFERROR(L7/N7,0) -> 0.0020324855 | M15: =IFERROR(M7/N7,0) -> 0 | N15: =IFERROR(N7/N7,0) -> 1 | P15: =IFERROR(P7/Z7,0) -> 0.017167382 | Q15: =IFERROR(Q7/Z7,0) -> 0.96137339 | R15: =IFERROR(R7/Z7,0) -> 0.0042918455 | S15: =IFERROR(S7/Z7,0) -> 0 | T15: =IFERROR(T7/Z7,0) -> 0.010729614 | U15: =IFERROR(U7/Z7,0) -> 0 | V15: =IFERROR(V7/Z7,0) -> 0.0021459227 | W15: =IFERROR(W7/Z7,0) -> 0 | X15: =IFERROR(X7/Z7,0) -> 0.0042918455 | Y15: =IFERROR(Y7/Z7,0) -> 0 | Z15: =IFERROR(Z7/Z7,0) -> 1 | AB15: =IFERROR(AB7/AL7,0) -> 0.0013842746 | AC15: =IFERROR(AC7/AL7,0) -> 0.92801772 | AD15: =IFERROR(AD7/AL7,0) -> 0.0083056478 | AE15: =IFERROR(AE7/AL7,0) -> 0 | AF15: =IFERROR(AF7/AL7,0) -> 0.024916944 | AG15: =IFERROR(AG7/AL7,0) -> 0 | AH15: =IFERROR(AH7/AL7,0) -> 0.030454042 | AI15: =IFERROR(AI7/AL7,0) -> 0 | AJ15: =IFERROR(AJ7/AL7,0) -> 0.0069213732 | AK15: =IFERROR(AK7/AL7,0) -> 0 | AL15: =IFERROR(AL7/AL7,0) -> 1 | AN15: =IFERROR(AN7/AX7,0) -> 0.005488707 | AO15: =IFERROR(AO7/AX7,0) -> 0.95558389 | AP15: =IFERROR(AP7/AX7,0) -> 0.019759345 | AQ15: =IFERROR(AQ7/AX7,0) -> 0 | AR15: =IFERROR(AR7/AX7,0) -> 0.011483872 | AS15: =IFERROR(AS7/AX7,0) -> 0 | AT15: =IFERROR(AT7/AX7,0) -> 0.0065864484 | AU15: =IFERROR(AU7/AX7,0) -> 0.0005488707 | AV15: =IFERROR(AV7/AX7,0) -> 0.0005488707 | AW15: =IFERROR(AW7/AX7,0) -> 0 | AX15: =IFERROR(AX7/AX7,0) -> 1 | AZ15: =IFERROR(AZ7/BJ7,0) -> 0 | BA15: =IFERROR(BA7/BJ7,0) -> 0.93458555 | BB15: =IFERROR(BB7/BJ7,0) -> 0.02462486 | BC15: =IFERROR(BC7/BJ7,0) -> 0 | BD15: =IFERROR(BD7/BJ7,0) -> 0.0079253494 | BE15: =IFERROR(BE7/BJ7,0) -> 0 | BF15: =IFERROR(BF7/BJ7,0) -> 0.020520716 | BG15: =IFERROR(BG7/BJ7,0) -> 0.0047881671 | BH15: =IFERROR(BH7/BJ7,0) -> 0.0075553546 | BI15: =IFERROR(BI7/BJ7,0) -> 0 | BJ15: =IFERROR(BJ7/BJ7,0) -> 1 | BL15: =IFERROR(BL7/BV7,0) -> 0.0015936255 | BM15: =IFERROR(BM7/BV7,0) -> 0.95776892 | BN15: =IFERROR(BN7/BV7,0) -> 0.016733068 | BO15: =IFERROR(BO7/BV7,0) -> 0 | BP15: =IFERROR(BP7/BV7,0) -> 0.013545817 | BQ15: =IFERROR(BQ7/BV7,0) -> 0 | BR15: =IFERROR(BR7/BV7,0) -> 0.0079681275 | BS15: =IFERROR(BS7/BV7,0) -> 0.0015936255 | BT15: =IFERROR(BT7/BV7,0) -> 0.00079681275 | BU15: =IFERROR(BU7/BV7,0) -> 0 | BV15: =IFERROR(BV7/BV7,0) -> 1 | BX15: =IFERROR(BX7/CH7,0) -> 0.018763797 | BY15: =IFERROR(BY7/CH7,0) -> 0.95584989 | BZ15: =IFERROR(BZ7/CH7,0) -> 0.013796909 | CA15: =IFERROR(CA7/CH7,0) -> 0 | CB15: =IFERROR(CB7/CH7,0) -> 0.0022075055 | CC15: =IFERROR(CC7/CH7,0) -> 0 | CD15: =IFERROR(CD7/CH7,0) -> 0.0060706402 | CE15: =IFERROR(CE7/CH7,0) -> 0.0011037528 | CF15: =IFERROR(CF7/CH7,0) -> 0.0022075055 | CG15: =IFERROR(CG7/CH7,0) -> 0 | CH15: =IFERROR(CH7/CH7,0) -> 1 | CJ15: =IFERROR(CJ7/CT7,0) -> 0.073806078 | CK15: =IFERROR(CK7/CT7,0) -> 0.85890014 | CL15: =IFERROR(CL7/CT7,0) -> 0.044862518 | CM15: =IFERROR(CM7/CT7,0) -> 0 | CN15: =IFERROR(CN7/CT7,0) -> 0.01447178 | CO15: =IFERROR(CO7/CT7,0) -> 0 | CP15: =IFERROR(CP7/CT7,0) -> 0.007959479 | CQ15: =IFERROR(CQ7/CT7,0) -> 0 | CR15: =IFERROR(CR7/CT7,0) -> 0 | CS15: =IFERROR(CS7/CT7,0) -> 0 | CT15: =IFERROR(CT7/CT7,0) -> 1 | CV15: =IFERROR(CV7/DF7,0) -> 0.070160609 | CW15: =IFERROR(CW7/DF7,0) -> 0.85038039 | CX15: =IFERROR(CX7/DF7,0) -> 0.053254438 | CY15: =IFERROR(CY7/DF7,0) -> 0 | CZ15: =IFERROR(CZ7/DF7,0) -> 0.010989011 | DA15: =IFERROR(DA7/DF7,0) -> 0 | DB15: =IFERROR(DB7/DF7,0) -> 0.010989011 | DC15: =IFERROR(DC7/DF7,0) -> 0.0025359256 | DD15: =IFERROR(DD7/DF7,0) -> 0.0016906171 | DE15: =IFERROR(DE7/DF7,0) -> 0 | DF15: =IFERROR(DF7/DF7,0) -> 1 | DH15: =IFERROR(DH7/DR7,0) -> 0 | DI15: =IFERROR(DI7/DR7,0) -> 0.93107618 | DJ15: =IFERROR(DJ7/DR7,0) -> 0.044740024 | DK15: =IFERROR(DK7/DR7,0) -> 0 | DL15: =IFERROR(DL7/DR7,0) -> 0.014510278 | DM15: =IFERROR(DM7/DR7,0) -> 0 | DN15: =IFERROR(DN7/DR7,0) -> 0.0096735187 | DO15: =IFERROR(DO7/DR7,0) -> 0 | DP15: =IFERROR(DP7/DR7,0) -> 0 | DQ15: =IFERROR(DQ7/DR7,0) -> 0 | DR15: =IFERROR(DR7/DR7,0) -> 1 | DT15: =IFERROR(DT7/ED7,0) -> 0.030410169 | DU15: =IFERROR(DU7/ED7,0) -> 0.90087659 | DV15: =IFERROR(DV7/ED7,0) -> 0.020474468 | DW15: =IFERROR(DW7/ED7,0) -> 0 | DX15: =IFERROR(DX7/ED7,0) -> 0.025716862 | DY15: =IFERROR(DY7/ED7,0) -> 0 | DZ15: =IFERROR(DZ7/ED7,0) -> 0.022521915 | EA15: =IFERROR(EA7/ED7,0) -> 0 | EB15: =IFERROR(EB7/ED7,0) -> 0 | EC15: =IFERROR(EC7/ED7,0) -> 0 | ED15: =IFERROR(ED7/ED7,0) -> 1 | EF15: =IFERROR(EF7/EP7,0) -> 0.0097886468 | EG15: =IFERROR(EG7/EP7,0) -> 0.89803493 | EH15: =IFERROR(EH7/EP7,0) -> 0.061179043 | EI15: =IFERROR(EI7/EP7,0) -> 0 | EJ15: =IFERROR(EJ7/EP7,0) -> 0.030997382 | EK15: =IFERROR(EK7/EP7,0) -> 0 | EL15: =IFERROR(EL7/EP7,0) -> 0 | EM15: =IFERROR(EM7/EP7,0) -> 0 | EN15: =IFERROR(EN7/EP7,0) -> 0 | EO15: =IFERROR(EO7/EP7,0) -> 0 | EP15: =IFERROR(EP7/EP7,0) -> 1 | ER15: =IFERROR(ER7/FB7,0) -> 0 | ES15: =IFERROR(ES7/FB7,0) -> 0.86390533 | ET15: =IFERROR(ET7/FB7,0) -> 0.1183432 | EU15: =IFERROR(EU7/FB7,0) -> 0 | EV15: =IFERROR(EV7/FB7,0) -> 0 | EW15: =IFERROR(EW7/FB7,0) -> 0.017751479 | EX15: =IFERROR(EX7/FB7,0) -> 0 | EY15: =IFERROR(EY7/FB7,0) -> 0 | EZ15: =IFERROR(EZ7/FB7,0) -> 0 | FA15: =IFERROR(FA7/FB7,0) -> 0 | FB15: =IFERROR(FB7/FB7,0) -> 1
