Workbook

Sheet >>Matrix-Nhập

Sheet Nhập-2026
D1: 2026 | E1: 2026 | F1: 2026 | G1: 2026 | H1: 2026 | I1: 2026 | J1: 2026 | K1: 2026 | L1: 2026 | M1: 2026 | N1: 2026 | O1: 2026 | P1: 2026 | Q1: 2026 | R1: 2026 | S1: 2026 | T1: 2026 | V1: 2026 | W1: 2026 | X1: 2026 | Y1: 2026 | Z1: 2026 | AA1: 2026 | AB1: 2026 | AC1: 2026 | AD1: 2026 | AE1: 2026 | AF1: 2026 | AG1: 2026 | AH1: 2026 | AI1: 2026 | AJ1: 2026 | AK1: 2026 | AN1: 2026 | AO1: 2026 | AP1: 2026 | AQ1: 2026 | AR1: 2026 | AS1: 2026 | AT1: 2026 | AU1: 2026 | AV1: 2026 | AW1: 2026 | AX1: 2026 | AY1: 2026 | AZ1: 2026 | BA1: 2026 | BB1: 2026 | BC1: 2026 | BF1: 2026 | BG1: 2026 | BH1: 2026 | BI1: 2026 | BJ1: 2026 | BK1: 2026 | BL1: 2026 | BM1: 2026 | BN1: 2026 | BO1: 2026 | BP1: 2026 | BQ1: 2026 | BR1: 2026 | BS1: 2026 | BT1: 2026 | BU1: 2026 | BX1: 2026 | BY1: 2026 | BZ1: 2026 | CA1: 2026 | CB1: 2026 | CC1: 2026 | CD1: 2026 | CE1: 2026 | CF1: 2026 | CG1: 2026 | CH1: 2026 | CI1: 2026 | CJ1: 2026 | CK1: 2026 | CL1: 2026 | CM1: 2026 | CP1: 2026 | CQ1: 2026 | CR1: 2026 | CS1: 2026 | CT1: 2026 | CU1: 2026 | CV1: 2026 | CW1: 2026 | CX1: 2026 | CY1: 2026 | CZ1: 2026 | DA1: 2026 | DB1: 2026 | DC1: 2026 | DD1: 2026 | DE1: 2026 | DH1: 2026 | DI1: 2026 | DJ1: 2026 | DK1: 2026 | DL1: 2026 | DM1: 2026 | DN1: 2026 | DO1: 2026 | DP1: 2026 | DQ1: 2026 | DR1: 2026 | DS1: 2026 | DT1: 2026 | DU1: 2026 | DV1: 2026 | DW1: 2026 | DZ1: 2026 | EA1: 2026 | EB1: 2026 | EC1: 2026 | ED1: 2026 | EE1: 2026 | EF1: 2026 | EG1: 2026 | EH1: 2026 | EI1: 2026 | EJ1: 2026 | EK1: 2026 | EL1: 2026 | EM1: 2026 | EN1: 2026 | EO1: 2026 | ER1: 2026 | ES1: 2026 | ET1: 2026 | EU1: 2026 | EV1: 2026 | EW1: 2026 | EX1: 2026 | EY1: 2026 | EZ1: 2026 | FA1: 2026 | FB1: 2026 | FC1: 2026 | FD1: 2026 | FE1: 2026 | FF1: 2026 | FG1: 2026 | FJ1: 2026 | FK1: 2026 | FL1: 2026 | FM1: 2026 | FN1: 2026 | FO1: 2026 | FP1: 2026 | FQ1: 2026 | FR1: 2026 | FS1: 2026 | FT1: 2026 | FU1: 2026 | FV1: 2026 | FW1: 2026 | FX1: 2026 | FY1: 2026 | GB1: 2026 | GC1: 2026 | GD1: 2026 | GE1: 2026 | GF1: 2026 | GG1: 2026 | GH1: 2026 | GI1: 2026 | GJ1: 2026 | GK1: 2026 | GL1: 2026 | GM1: 2026 | GN1: 2026 | GO1: 2026 | GP1: 2026 | GQ1: 2026 | GT1: 2026 | GU1: 2026 | GV1: 2026 | GW1: 2026 | GX1: 2026 | GY1: 2026 | GZ1: 2026 | HA1: 2026 | HB1: 2026 | HC1: 2026 | HD1: 2026 | HE1: 2026 | HF1: 2026 | HG1: 2026 | HH1: 2026 | HI1: 2026 | HL1: 2026 | HM1: 2026 | HN1: 2026 | HO1: 2026 | HP1: 2026 | HQ1: 2026 | HR1: 2026 | HS1: 2026 | HT1: 2026 | HU1: 2026 | HV1: 2026 | HW1: 2026 | HX1: 2026 | HY1: 2026 | HZ1: 2026 | IA1: 2026
D2: FY | E2: FY | F2: FY | G2: FY | H2: FY | I2: FY | J2: FY | K2: FY | L2: FY | M2: FY | N2: FY | O2: FY | P2: FY | Q2: FY | R2: FY | S2: FY | T2: FY | V2: 1 | W2: 1 | X2: =W2 -> 1 | Y2: =X2 -> 1 | Z2: =Y2 -> 1 | AA2: =Z2 -> 1 | AB2: =AA2 -> 1 | AC2: =AB2 -> 1 | AD2: =AC2 -> 1 | AE2: =AD2 -> 1 | ... AK2: =AJ2 -> 1 | AN2: =V2+1 -> 2 | AO2: =AN2 -> 2 | AP2: =AO2 -> 2 | AQ2: =AP2 -> 2 | AR2: =AQ2 -> 2 | AS2: =AR2 -> 2 | AT2: =AS2 -> 2 | AU2: =AT2 -> 2 | AV2: =AU2 -> 2 | ... BC2: =BB2 -> 2 | BF2: =AN2+1 -> 3 | BG2: =BF2 -> 3 | BH2: =BG2 -> 3 | BI2: =BH2 -> 3 | BJ2: =BI2 -> 3 | BK2: =BJ2 -> 3 | BL2: =BK2 -> 3 | BM2: =BL2 -> 3 | BN2: =BM2 -> 3 | ... BU2: =BT2 -> 3 | BX2: =BF2+1 -> 4 | BY2: =BX2 -> 4 | BZ2: =BY2 -> 4 | CA2: =BZ2 -> 4 | CB2: =CA2 -> 4 | CC2: =CB2 -> 4 | CD2: =CC2 -> 4 | CE2: =CD2 -> 4 | CF2: =CE2 -> 4 | ... CM2: =CL2 -> 4 | CP2: =BX2+1 -> 5 | CQ2: =CP2 -> 5 | CR2: =CQ2 -> 5 | CS2: =CR2 -> 5 | CT2: =CS2 -> 5 | CU2: =CT2 -> 5 | CV2: =CU2 -> 5 | CW2: =CV2 -> 5 | CX2: =CW2 -> 5 | ... DE2: =DD2 -> 5 | DH2: =CP2+1 -> 6 | DI2: =DH2 -> 6 | DJ2: =DI2 -> 6 | DK2: =DJ2 -> 6 | DL2: =DK2 -> 6 | DM2: =DL2 -> 6 | DN2: =DM2 -> 6 | DO2: =DN2 -> 6 | DP2: =DO2 -> 6 | ... DW2: =DV2 -> 6 | DZ2: =DH2+1 -> 7 | EA2: =DZ2 -> 7 | EB2: =EA2 -> 7 | EC2: =EB2 -> 7 | ED2: =EC2 -> 7 | EE2: =ED2 -> 7 | EF2: =EE2 -> 7 | EG2: =EF2 -> 7 | EH2: =EG2 -> 7 | ... EO2: =EN2 -> 7 | ER2: =DZ2+1 -> 8 | ES2: =ER2 -> 8 | ET2: =ES2 -> 8 | EU2: =ET2 -> 8 | EV2: =EU2 -> 8 | EW2: =EV2 -> 8 | EX2: =EW2 -> 8 | EY2: =EX2 -> 8 | EZ2: =EY2 -> 8 | ... FG2: =FF2 -> 8 | FJ2: =ER2+1 -> 9 | FK2: =FJ2 -> 9 | FL2: =FK2 -> 9 | FM2: =FL2 -> 9 | FN2: =FM2 -> 9 | FO2: =FN2 -> 9 | FP2: =FO2 -> 9 | FQ2: =FP2 -> 9 | FR2: =FQ2 -> 9 | ... FY2: =FX2 -> 9 | GB2: =FJ2+1 -> 10 | GC2: =GB2 -> 10 | GD2: =GC2 -> 10 | GE2: =GD2 -> 10 | GF2: =GE2 -> 10 | GG2: =GF2 -> 10 | GH2: =GG2 -> 10 | GI2: =GH2 -> 10 | GJ2: =GI2 -> 10 | ... GQ2: =GP2 -> 10 | GT2: =GB2+1 -> 11 | GU2: =GT2 -> 11 | GV2: =GU2 -> 11 | GW2: =GV2 -> 11 | GX2: =GW2 -> 11 | GY2: =GX2 -> 11 | GZ2: =GY2 -> 11 | HA2: =GZ2 -> 11 | HB2: =HA2 -> 11 | ... HI2: =HH2 -> 11 | HL2: =GT2+1 -> 12 | HM2: =HL2 -> 12 | HN2: =HM2 -> 12 | HO2: =HN2 -> 12 | HP2: =HO2 -> 12 | HQ2: =HP2 -> 12 | HR2: =HQ2 -> 12 | HS2: =HR2 -> 12 | HT2: =HS2 -> 12 | ... IA2: =HZ2 -> 12
E3: iSS01084 | F3: iSS01 | G3: WSS01 | H3: WSS02 | I3: WSS03 | J3: WSS04 | K3: WSS05 | L3: WSS06 | M3: iSS01084-PL | N3: iSS01-PL | O3: WSS01-PL | P3: WSS03-PL | Q3: WSS05 PL | R3: Phó sản | S3: Khác | W3: iSS01084 | X3: iSS01 | Y3: WSS01 | Z3: WSS02 | AA3: WSS03 | AB3: WSS04 | AC3: WSS05 | AD3: WSS06 | AE3: iSS01084-PL | AF3: iSS01-PL | AG3: WSS01-PL | AH3: WSS03-PL | AI3: WSS05 PL | AJ3: Phó sản | AK3: Khác | AO3: iSS01084 | AP3: iSS01 | AQ3: WSS01 | AR3: WSS02 | AS3: WSS03 | AT3: WSS04 | AU3: WSS05 | AV3: WSS06 | AW3: iSS01084-PL | AX3: iSS01-PL | AY3: WSS01-PL | AZ3: WSS03-PL | BA3: WSS05 PL | BB3: Phó sản | BC3: Khác | BG3: iSS01084 | BH3: iSS01 | BI3: WSS01 | BJ3: WSS02 | BK3: WSS03 | BL3: WSS04 | BM3: WSS05 | BN3: WSS06 | BO3: iSS01084-PL | BP3: iSS01-PL | BQ3: WSS01-PL | BR3: WSS03-PL | BS3: WSS05 PL | BT3: Phó sản | BU3: Khác | BY3: iSS01084 | BZ3: iSS01 | CA3: WSS01 | CB3: WSS02 | CC3: WSS03 | CD3: WSS04 | CE3: WSS05 | CF3: WSS06 | CG3: iSS01084-PL | CH3: iSS01-PL | CI3: WSS01-PL | CJ3: WSS03-PL | CK3: WSS05 PL | CL3: Phó sản | CM3: Khác | CQ3: iSS01084 | CR3: iSS01 | CS3: WSS01 | CT3: WSS02 | CU3: WSS03 | CV3: WSS04 | CW3: WSS05 | CX3: WSS06 | CY3: iSS01084-PL | CZ3: iSS01-PL | DA3: WSS01-PL | DB3: WSS03-PL | DC3: WSS05 PL | DD3: Phó sản | DE3: Khác | DI3: iSS01084 | DJ3: iSS01 | DK3: WSS01 | DL3: WSS02 | DM3: WSS03 | DN3: WSS04 | DO3: WSS05 | DP3: WSS06 | DQ3: iSS01084-PL | DR3: iSS01-PL | DS3: WSS01-PL | DT3: WSS03-PL | DU3: WSS05 PL | DV3: Phó sản | DW3: Khác | EA3: iSS01084 | EB3: iSS01 | EC3: WSS01 | ED3: WSS02 | EE3: WSS03 | EF3: WSS04 | EG3: WSS05 | EH3: WSS06 | EI3: iSS01084-PL | EJ3: iSS01-PL | EK3: WSS01-PL | EL3: WSS03-PL | EM3: WSS05 PL | EN3: Phó sản | EO3: Khác | ES3: iSS01084 | ET3: iSS01 | EU3: WSS01 | EV3: WSS02 | EW3: WSS03 | EX3: WSS04 | EY3: WSS05 | EZ3: WSS06 | FA3: iSS01084-PL | FB3: iSS01-PL | FC3: WSS01-PL | FD3: WSS03-PL | FE3: WSS05 PL | FF3: Phó sản | FG3: Khác | FK3: iSS01084 | FL3: iSS01 | FM3: WSS01 | FN3: WSS02 | FO3: WSS03 | FP3: WSS04 | FQ3: WSS05 | FR3: WSS06 | FS3: iSS01084-PL | FT3: iSS01-PL | FU3: WSS01-PL | FV3: WSS03-PL | FW3: WSS05 PL | FX3: Phó sản | FY3: Khác | GC3: iSS01084 | GD3: iSS01 | GE3: WSS01 | GF3: WSS02 | GG3: WSS03 | GH3: WSS04 | GI3: WSS05 | GJ3: WSS06 | GK3: iSS01084-PL | GL3: iSS01-PL | GM3: WSS01-PL | GN3: WSS03-PL | GO3: WSS05 PL | GP3: Phó sản | GQ3: Khác | GU3: iSS01084 | GV3: iSS01 | GW3: WSS01 | GX3: WSS02 | GY3: WSS03 | GZ3: WSS04 | HA3: WSS05 | HB3: WSS06 | HC3: iSS01084-PL | HD3: iSS01-PL | HE3: WSS01-PL | HF3: WSS03-PL | HG3: WSS05 PL | HH3: Phó sản | HI3: Khác | HM3: iSS01084 | HN3: iSS01 | HO3: WSS01 | HP3: WSS02 | HQ3: WSS03 | HR3: WSS04 | HS3: WSS05 | HT3: WSS06 | HU3: iSS01084-PL | HV3: iSS01-PL | HW3: WSS01-PL | HX3: WSS03-PL | HY3: WSS05 PL | HZ3: Phó sản | IA3: Khác
B4: Main SKU name (Đvt: tấn) | D4: NĂM 2024-THU HỒI | V4: ="THÁNG "&W2&"-THU HỒI" -> THÁNG 1-THU HỒI | AN4: ="THÁNG "&AO2&"-THU HỒI" -> THÁNG 2-THU HỒI | BF4: ="THÁNG "&BG2&"-THU HỒI" -> THÁNG 3-THU HỒI | BX4: ="THÁNG "&BY2&"-THU HỒI" -> THÁNG 4-THU HỒI | CP4: ="THÁNG "&CQ2&"-THU HỒI" -> THÁNG 5-THU HỒI | DH4: ="THÁNG "&DI2&"-THU HỒI" -> THÁNG 6-THU HỒI | DZ4: ="THÁNG "&EA2&"-THU HỒI" -> THÁNG 7-THU HỒI | ER4: ="THÁNG "&ES2&"-THU HỒI" -> THÁNG 8-THU HỒI | FJ4: ="THÁNG "&FK2&"-THU HỒI" -> THÁNG 9-THU HỒI | GB4: ="THÁNG "&GC2&"-THU HỒI" -> THÁNG 10-THU HỒI | GT4: ="THÁNG "&GU2&"-THU HỒI" -> THÁNG 11-THU HỒI | HL4: ="THÁNG "&HM2&"-THU HỒI" -> THÁNG 12-THU HỒI
D5: TỔNG-XUẤT | E5: iSS01084 | F5: iSS01 | G5: WSS01 | H5: WSS02 | I5: WSS03 | J5: WSS04 | K5: WSS05 | L5: WSS06 | M5: iSS01084-PL | N5: iSS01-PL | O5: WSS01-PL | P5: WSS03-PL | Q5: WSS05 PL | R5: Phó sản | S5: Khác | T5: TỔNG-NHẬP | V5: TỔNG-XUẤT | W5: iSS01084 | X5: iSS01 | Y5: WSS01 | Z5: WSS02 | AA5: WSS03 | AB5: WSS04 | AC5: WSS05 | AD5: WSS06 | AE5: iSS01084-PL | AF5: iSS01-PL | AG5: WSS01-PL | AH5: WSS03-PL | AI5: WSS05 PL | AJ5: Phó sản | AK5: Khác | AL5: TỔNG-NHẬP | AN5: TỔNG-XUẤT | AO5: iSS01084 | AP5: iSS01 | AQ5: WSS01 | AR5: WSS02 | AS5: WSS03 | AT5: WSS04 | AU5: WSS05 | AV5: WSS06 | AW5: iSS01084-PL | AX5: iSS01-PL | AY5: WSS01-PL | AZ5: WSS03-PL | BA5: WSS05 PL | BB5: Phó sản | BC5: Khác | BD5: TỔNG-NHẬP | BF5: TỔNG-XUẤT | BG5: iSS01084 | BH5: iSS01 | BI5: WSS01 | BJ5: WSS02 | BK5: WSS03 | BL5: WSS04 | BM5: WSS05 | BN5: WSS06 | BO5: iSS01084-PL | BP5: iSS01-PL | BQ5: WSS01-PL | BR5: WSS03-PL | BS5: WSS05 PL | BT5: Phó sản | BU5: Khác | BV5: TỔNG-NHẬP | BX5: TỔNG-XUẤT | BY5: iSS01084 | BZ5: iSS01 | CA5: WSS01 | CB5: WSS02 | CC5: WSS03 | CD5: WSS04 | CE5: WSS05 | CF5: WSS06 | CG5: iSS01084-PL | CH5: iSS01-PL | CI5: WSS01-PL | CJ5: WSS03-PL | CK5: WSS05 PL | CL5: Phó sản | CM5: Khác | CN5: TỔNG-NHẬP | CP5: TỔNG-XUẤT | CQ5: iSS01084 | CR5: iSS01 | CS5: WSS01 | CT5: WSS02 | CU5: WSS03 | CV5: WSS04 | CW5: WSS05 | CX5: WSS06 | CY5: iSS01084-PL | CZ5: iSS01-PL | DA5: WSS01-PL | DB5: WSS03-PL | DC5: WSS05 PL | DD5: Phó sản | DE5: Khác | DF5: TỔNG-NHẬP | DH5: TỔNG-XUẤT | DI5: iSS01084 | DJ5: iSS01 | DK5: WSS01 | DL5: WSS02 | DM5: WSS03 | DN5: WSS04 | DO5: WSS05 | DP5: WSS06 | DQ5: iSS01084-PL | DR5: iSS01-PL | DS5: WSS01-PL | DT5: WSS03-PL | DU5: WSS05 PL | DV5: Phó sản | DW5: Khác | DX5: TỔNG-NHẬP | DZ5: TỔNG-XUẤT | EA5: iSS01084 | EB5: iSS01 | EC5: WSS01 | ED5: WSS02 | EE5: WSS03 | EF5: WSS04 | EG5: WSS05 | EH5: WSS06 | EI5: iSS01084-PL | EJ5: iSS01-PL | EK5: WSS01-PL | EL5: WSS03-PL | EM5: WSS05 PL | EN5: Phó sản | EO5: Khác | EP5: TỔNG-NHẬP | ER5: TỔNG-XUẤT | ES5: iSS01084 | ET5: iSS01 | EU5: WSS01 | EV5: WSS02 | EW5: WSS03 | EX5: WSS04 | EY5: WSS05 | EZ5: WSS06 | FA5: iSS01084-PL | FB5: iSS01-PL | FC5: WSS01-PL | FD5: WSS03-PL | FE5: WSS05 PL | FF5: Phó sản | FG5: Khác | FH5: TỔNG-NHẬP | FJ5: TỔNG-XUẤT | FK5: iSS01084 | FL5: iSS01 | FM5: WSS01 | FN5: WSS02 | FO5: WSS03 | FP5: WSS04 | FQ5: WSS05 | FR5: WSS06 | FS5: iSS01084-PL | FT5: iSS01-PL | FU5: WSS01-PL | FV5: WSS03-PL | FW5: WSS05 PL | FX5: Phó sản | FY5: Khác | FZ5: TỔNG-NHẬP | GB5: TỔNG-XUẤT | GC5: iSS01084 | GD5: iSS01 | GE5: WSS01 | GF5: WSS02 | GG5: WSS03 | GH5: WSS04 | GI5: WSS05 | GJ5: WSS06 | GK5: iSS01084-PL | GL5: iSS01-PL | GM5: WSS01-PL | GN5: WSS03-PL | GO5: WSS05 PL | GP5: Phó sản | GQ5: Khác | GR5: TỔNG-NHẬP | GT5: TỔNG-XUẤT | GU5: iSS01084 | GV5: iSS01 | GW5: WSS01 | GX5: WSS02 | GY5: WSS03 | GZ5: WSS04 | HA5: WSS05 | HB5: WSS06 | HC5: iSS01084-PL | HD5: iSS01-PL | HE5: WSS01-PL | HF5: WSS03-PL | HG5: WSS05 PL | HH5: Phó sản | HI5: Khác | HJ5: TỔNG-NHẬP | HL5: TỔNG-XUẤT | HM5: iSS01084 | HN5: iSS01 | HO5: WSS01 | HP5: WSS02 | HQ5: WSS03 | HR5: WSS04 | HS5: WSS05 | HT5: WSS06 | HU5: iSS01084-PL | HV5: iSS01-PL | HW5: WSS01-PL | HX5: WSS03-PL | HY5: WSS05 PL | HZ5: Phó sản | IA5: Khác | IB5: TỔNG-NHẬP
A6: iSS01084 | B6: iSS01084 | D6: {=IF(D$2="FY",SUMPRODUCT(Data_Xuất[Xuất-NX]*(Data_Xuất[Year]=D$1)*(Data_Xuất[Main SKU name_GOM]=$A6)),SUMPRODUCT(Data_Xuất[Xuất-NX]*(Data_Xuất[Year]=D$1)*(Data_Xuất[Main SKU name_GOM]=$A6)*Data_Xuất[Month]=D$2))} -> 2362674 | E6: {=IF(E$2="FY",SUMPRODUCT(Data_Nhập[Tổng Nhập-NX]*(Data_Nhập[Year]=E$1)*(Data_Nhập[Main SKU name_GOM]=$A6)*(Data_Nhập[SKU name_NHẬP_GOM]=E$3)),SUMPRODUCT(Data_Nhập[Tổng Nhập-NX]*(Data_Nhập[Year]=E$1)*(Data_Nhập[Month]=E$2)*(Data_Nhập[Main SKU name_GOM]=$A6)*(Data_Nhập[SKU name_NHẬP_GOM]=E$3)))} -> 2068000 | F6: {=IF(F$2="FY",SUMPRODUCT(Data_Nhập[Tổng Nhập-NX]*(Data_Nhập[Year]=F$1)*(Data_Nhập[Main SKU name_GOM]=$A6)*(Data_Nhập[SKU name_NHẬP_GOM]=F$3)),SUMPRODUCT(Data_Nhập[Tổng Nhập-NX]*(Data_Nhập[Year]=F$1)*(Data_Nhập[Month]=F$2)*(Data_Nhập[Main SKU name_GOM]=$A6)*(Data_Nhập[SKU name_NHẬP_GOM]=F$3)))} -> 40700 | G6: {=IF(G$2="FY",SUMPRODUCT(Data_Nhập[Tổng Nhập-NX]*(Data_Nhập[Year]=G$1)*(Data_Nhập[Main SKU name_GOM]=$A6)*(Data_Nhập[SKU name_NHẬP_GOM]=G$3)),SUMPRODUCT(Data_Nhập[Tổng Nhập-NX]*(Data_Nhập[Year]=G$1)*(Data_Nhập[Month]=G$2)*(Data_Nhập[Main SKU name_GOM]=$A6)*(Data_Nhập[SKU name_NHẬP_GOM]=G$3)))} -> 47300 | H6: {=IF(H$2="FY",SUMPRODUCT(Data_Nhập[Tổng Nhập-NX]*(Data_Nhập[Year]=H$1)*(Data_Nhập[Main SKU name_GOM]=$A6)*(Data_Nhập[SKU name_NHẬP_GOM]=H$3)),SUMPRODUCT(Data_Nhập[Tổng Nhập-NX]*(Data_Nhập[Year]=H$1)*(Data_Nhập[Month]=H$2)*(Data_Nhập[Main SKU name_GOM]=$A6)*(Data_Nhập[SKU name_NHẬP_GOM]=H$3)))} -> 0 | I6: {=IF(I$2="FY",SUMPRODUCT(Data_Nhập[Tổng Nhập-NX]*(Data_Nhập[Year]=I$1)*(Data_Nhập[Main SKU name_GOM]=$A6)*(Data_Nhập[SKU name_NHẬP_GOM]=I$3)),SUMPRODUCT(Data_Nhập[Tổng Nhập-NX]*(Data_Nhập[Year]=I$1)*(Data_Nhập[Month]=I$2)*(Data_Nhập[Main SKU name_GOM]=$A6)*(Data_Nhập[SKU name_NHẬP_GOM]=I$3)))} -> 72600 | J6: {=IF(J$2="FY",SUMPRODUCT(Data_Nhập[Tổng Nhập-NX]*(Data_Nhập[Year]=J$1)*(Data_Nhập[Main SKU name_GOM]=$A6)*(Data_Nhập[SKU name_NHẬP_GOM]=J$3)),SUMPRODUCT(Data_Nhập[Tổng Nhập-NX]*(Data_Nhập[Year]=J$1)*(Data_Nhập[Month]=J$2)*(Data_Nhập[Main SKU name_GOM]=$A6)*(Data_Nhập[SKU name_NHẬP_GOM]=J$3)))} -> 0 | K6: {=IF(K$2="FY",SUMPRODUCT(Data_Nhập[Tổng Nhập-NX]*(Data_Nhập[Year]=K$1)*(Data_Nhập[Main SKU name_GOM]=$A6)*(Data_Nhập[SKU name_NHẬP_GOM]=K$3)),SUMPRODUCT(Data_Nhập[Tổng Nhập-NX]*(Data_Nhập[Year]=K$1)*(Data_Nhập[Month]=K$2)*(Data_Nhập[Main SKU name_GOM]=$A6)*(Data_Nhập[SKU name_NHẬP_GOM]=K$3)))} -> 0 | L6: {=IF(L$2="FY",SUMPRODUCT(Data_Nhập[Tổng Nhập-NX]*(Data_Nhập[Year]=L$1)*(Data_Nhập[Main SKU name_GOM]=$A6)*(Data_Nhập[SKU name_NHẬP_GOM]=L$3)),SUMPRODUCT(Data_Nhập[Tổng Nhập-NX]*(Data_Nhập[Year]=L$1)*(Data_Nhập[Month]=L$2)*(Data_Nhập[Main SKU name_GOM]=$A6)*(Data_Nhập[SKU name_NHẬP_GOM]=L$3)))} -> 0 | ... S6: {=IF(S$2="FY",SUMPRODUCT(Data_Nhập[Tổng Nhập-NX]*(Data_Nhập[Year]=S$1)*(Data_Nhập[Main SKU name_GOM]=$A6)*(Data_Nhập[SKU name_NHẬP_GOM]=S$3)),SUMPRODUCT(Data_Nhập[Tổng Nhập-NX]*(Data_Nhập[Year]=S$1)*(Data_Nhập[Month]=S$2)*(Data_Nhập[Main SKU name_GOM]=$A6)*(Data_Nhập[SKU name_NHẬP_GOM]=S$3)))} -> 0 | T6: =SUM(E6:S6) -> 2327110 | V6: {=IF(V$2="FY",SUMPRODUCT(Data_Xuất[Xuất-NX]*(Data_Xuất[Year]=V$1)*(Data_Xuất[Main SKU name_GOM]=$A6)),SUMPRODUCT(Data_Xuất[Xuất-NX]*(Data_Xuất[Year]=V$1)*(Data_Xuất[Main SKU name_GOM]=$A6)*(Data_Xuất[Month]=V$2)))} -> 354282 | W6: {=IF(W$2="FY",SUMPRODUCT(Data_Nhập[Tổng Nhập-NX]*(Data_Nhập[Year]=W$1)*(Data_Nhập[Main SKU name_GOM]=$A6)*(Data_Nhập[SKU name_NHẬP_GOM]=W$3)),SUMPRODUCT(Data_Nhập[Tổng Nhập-NX]*(Data_Nhập[Year]=W$1)*(Data_Nhập[Month]=W$2)*(Data_Nhập[Main SKU name_GOM]=$A6)*(Data_Nhập[SKU name_NHẬP_GOM]=W$3)))} -> 301400 | X6: {=IF(X$2="FY",SUMPRODUCT(Data_Nhập[Tổng Nhập-NX]*(Data_Nhập[Year]=X$1)*(Data_Nhập[Main SKU name_GOM]=$A6)*(Data_Nhập[SKU name_NHẬP_GOM]=X$3)),SUMPRODUCT(Data_Nhập[Tổng Nhập-NX]*(Data_Nhập[Year]=X$1)*(Data_Nhập[Month]=X$2)*(Data_Nhập[Main SKU name_GOM]=$A6)*(Data_Nhập[SKU name_NHẬP_GOM]=X$3)))} -> 1100 | Y6: {=IF(Y$2="FY",SUMPRODUCT(Data_Nhập[Tổng Nhập-NX]*(Data_Nhập[Year]=Y$1)*(Data_Nhập[Main SKU name_GOM]=$A6)*(Data_Nhập[SKU name_NHẬP_GOM]=Y$3)),SUMPRODUCT(Data_Nhập[Tổng Nhập-NX]*(Data_Nhập[Year]=Y$1)*(Data_Nhập[Month]=Y$2)*(Data_Nhập[Main SKU name_GOM]=$A6)*(Data_Nhập[SKU name_NHẬP_GOM]=Y$3)))} -> 0 | Z6: {=IF(Z$2="FY",SUMPRODUCT(Data_Nhập[Tổng Nhập-NX]*(Data_Nhập[Year]=Z$1)*(Data_Nhập[Main SKU name_GOM]=$A6)*(Data_Nhập[SKU name_NHẬP_GOM]=Z$3)),SUMPRODUCT(Data_Nhập[Tổng Nhập-NX]*(Data_Nhập[Year]=Z$1)*(Data_Nhập[Month]=Z$2)*(Data_Nhập[Main SKU name_GOM]=$A6)*(Data_Nhập[SKU name_NHẬP_GOM]=Z$3)))} -> 0 | AA6: {=IF(AA$2="FY",SUMPRODUCT(Data_Nhập[Tổng Nhập-NX]*(Data_Nhập[Year]=AA$1)*(Data_Nhập[Main SKU name_GOM]=$A6)*(Data_Nhập[SKU name_NHẬP_GOM]=AA$3)),SUMPRODUCT(Data_Nhập[Tổng Nhập-NX]*(Data_Nhập[Year]=AA$1)*(Data_Nhập[Month]=AA$2)*(Data_Nhập[Main SKU name_GOM]=$A6)*(Data_Nhập[SKU name_NHẬP_GOM]=AA$3)))} -> 27500 | AB6: {=IF(AB$2="FY",SUMPRODUCT(Data_Nhập[Tổng Nhập-NX]*(Data_Nhập[Year]=AB$1)*(Data_Nhập[Main SKU name_GOM]=$A6)*(Data_Nhập[SKU name_NHẬP_GOM]=AB$3)),SUMPRODUCT(Data_Nhập[Tổng Nhập-NX]*(Data_Nhập[Year]=AB$1)*(Data_Nhập[Month]=AB$2)*(Data_Nhập[Main SKU name_GOM]=$A6)*(Data_Nhập[SKU name_NHẬP_GOM]=AB$3)))} -> 0 | AC6: {=IF(AC$2="FY",SUMPRODUCT(Data_Nhập[Tổng Nhập-NX]*(Data_Nhập[Year]=AC$1)*(Data_Nhập[Main SKU name_GOM]=$A6)*(Data_Nhập[SKU name_NHẬP_GOM]=AC$3)),SUMPRODUCT(Data_Nhập[Tổng Nhập-NX]*(Data_Nhập[Year]=AC$1)*(Data_Nhập[Month]=AC$2)*(Data_Nhập[Main SKU name_GOM]=$A6)*(Data_Nhập[SKU name_NHẬP_GOM]=AC$3)))} -> 0 | AD6: {=IF(AD$2="FY",SUMPRODUCT(Data_Nhập[Tổng Nhập-NX]*(Data_Nhập[Year]=AD$1)*(Data_Nhập[Main SKU name_GOM]=$A6)*(Data_Nhập[SKU name_NHẬP_GOM]=AD$3)),SUMPRODUCT(Data_Nhập[Tổng Nhập-NX]*(Data_Nhập[Year]=AD$1)*(Data_Nhập[Month]=AD$2)*(Data_Nhập[Main SKU name_GOM]=$A6)*(Data_Nhập[SKU name_NHẬP_GOM]=AD$3)))} -> 0 | ... AK6: {=IF(AK$2="FY",SUMPRODUCT(Data_Nhập[Tổng Nhập-NX]*(Data_Nhập[Year]=AK$1)*(Data_Nhập[Main SKU name_GOM]=$A6)*(Data_Nhập[SKU name_NHẬP_GOM]=AK$3)),SUMPRODUCT(Data_Nhập[Tổng Nhập-NX]*(Data_Nhập[Year]=AK$1)*(Data_Nhập[Month]=AK$2)*(Data_Nhập[Main SKU name_GOM]=$A6)*(Data_Nhập[SKU name_NHẬP_GOM]=AK$3)))} -> 0 | AL6: =SUM(W6:AK6) -> 348142 | AN6: {=IF(AN$2="FY",SUMPRODUCT(Data_Xuất[Xuất-NX]*(Data_Xuất[Year]=AN$1)*(Data_Xuất[Main SKU name_GOM]=$A6)),SUMPRODUCT(Data_Xuất[Xuất-NX]*(Data_Xuất[Year]=AN$1)*(Data_Xuất[Main SKU name_GOM]=$A6)*(Data_Xuất[Month]=AN$2)))} -> 372581 | AO6: {=IF(AO$2="FY",SUMPRODUCT(Data_Nhập[Tổng Nhập-NX]*(Data_Nhập[Year]=AO$1)*(Data_Nhập[Main SKU name_GOM]=$A6)*(Data_Nhập[SKU name_NHẬP_GOM]=AO$3)),SUMPRODUCT(Data_Nhập[Tổng Nhập-NX]*(Data_Nhập[Year]=AO$1)*(Data_Nhập[Month]=AO$2)*(Data_Nhập[Main SKU name_GOM]=$A6)*(Data_Nhập[SKU name_NHẬP_GOM]=AO$3)))} -> 300300 | AP6: {=IF(AP$2="FY",SUMPRODUCT(Data_Nhập[Tổng Nhập-NX]*(Data_Nhập[Year]=AP$1)*(Data_Nhập[Main SKU name_GOM]=$A6)*(Data_Nhập[SKU name_NHẬP_GOM]=AP$3)),SUMPRODUCT(Data_Nhập[Tổng Nhập-NX]*(Data_Nhập[Year]=AP$1)*(Data_Nhập[Month]=AP$2)*(Data_Nhập[Main SKU name_GOM]=$A6)*(Data_Nhập[SKU name_NHẬP_GOM]=AP$3)))} -> 25300 | AQ6: {=IF(AQ$2="FY",SUMPRODUCT(Data_Nhập[Tổng Nhập-NX]*(Data_Nhập[Year]=AQ$1)*(Data_Nhập[Main SKU name_GOM]=$A6)*(Data_Nhập[SKU name_NHẬP_GOM]=AQ$3)),SUMPRODUCT(Data_Nhập[Tổng Nhập-NX]*(Data_Nhập[Year]=AQ$1)*(Data_Nhập[Month]=AQ$2)*(Data_Nhập[Main SKU name_GOM]=$A6)*(Data_Nhập[SKU name_NHẬP_GOM]=AQ$3)))} -> 0 | AR6: {=IF(AR$2="FY",SUMPRODUCT(Data_Nhập[Tổng Nhập-NX]*(Data_Nhập[Year]=AR$1)*(Data_Nhập[Main SKU name_GOM]=$A6)*(Data_Nhập[SKU name_NHẬP_GOM]=AR$3)),SUMPRODUCT(Data_Nhập[Tổng Nhập-NX]*(Data_Nhập[Year]=AR$1)*(Data_Nhập[Month]=AR$2)*(Data_Nhập[Main SKU name_GOM]=$A6)*(Data_Nhập[SKU name_NHẬP_GOM]=AR$3)))} -> 0 | AS6: {=IF(AS$2="FY",SUMPRODUCT(Data_Nhập[Tổng Nhập-NX]*(Data_Nhập[Year]=AS$1)*(Data_Nhập[Main SKU name_GOM]=$A6)*(Data_Nhập[SKU name_NHẬP_GOM]=AS$3)),SUMPRODUCT(Data_Nhập[Tổng Nhập-NX]*(Data_Nhập[Year]=AS$1)*(Data_Nhập[Month]=AS$2)*(Data_Nhập[Main SKU name_GOM]=$A6)*(Data_Nhập[SKU name_NHẬP_GOM]=AS$3)))} -> 23100 | AT6: {=IF(AT$2="FY",SUMPRODUCT(Data_Nhập[Tổng Nhập-NX]*(Data_Nhập[Year]=AT$1)*(Data_Nhập[Main SKU name_GOM]=$A6)*(Data_Nhập[SKU name_NHẬP_GOM]=AT$3)),SUMPRODUCT(Data_Nhập[Tổng Nhập-NX]*(Data_Nhập[Year]=AT$1)*(Data_Nhập[Month]=AT$2)*(Data_Nhập[Main SKU name_GOM]=$A6)*(Data_Nhập[SKU name_NHẬP_GOM]=AT$3)))} -> 0 | AU6: {=IF(AU$2="FY",SUMPRODUCT(Data_Nhập[Tổng Nhập-NX]*(Data_Nhập[Year]=AU$1)*(Data_Nhập[Main SKU name_GOM]=$A6)*(Data_Nhập[SKU name_NHẬP_GOM]=AU$3)),SUMPRODUCT(Data_Nhập[Tổng Nhập-NX]*(Data_Nhập[Year]=AU$1)*(Data_Nhập[Month]=AU$2)*(Data_Nhập[Main SKU name_GOM]=$A6)*(Data_Nhập[SKU name_NHẬP_GOM]=AU$3)))} -> 0 | AV6: {=IF(AV$2="FY",SUMPRODUCT(Data_Nhập[Tổng Nhập-NX]*(Data_Nhập[Year]=AV$1)*(Data_Nhập[Main SKU name_GOM]=$A6)*(Data_Nhập[SKU name_NHẬP_GOM]=AV$3)),SUMPRODUCT(Data_Nhập[Tổng Nhập-NX]*(Data_Nhập[Year]=AV$1)*(Data_Nhập[Month]=AV$2)*(Data_Nhập[Main SKU name_GOM]=$A6)*(Data_Nhập[SKU name_NHẬP_GOM]=AV$3)))} -> 0 | ... BC6: {=IF(BC$2="FY",SUMPRODUCT(Data_Nhập[Tổng Nhập-NX]*(Data_Nhập[Year]=BC$1)*(Data_Nhập[Main SKU name_GOM]=$A6)*(Data_Nhập[SKU name_NHẬP_GOM]=BC$3)),SUMPRODUCT(Data_Nhập[Tổng Nhập-NX]*(Data_Nhập[Year]=BC$1)*(Data_Nhập[Month]=BC$2)*(Data_Nhập[Main SKU name_GOM]=$A6)*(Data_Nhập[SKU name_NHẬP_GOM]=BC$3)))} -> 0 | BD6: =SUM(AO6:BC6) -> 366874 | BF6: {=IF(BF$2="FY",SUMPRODUCT(Data_Xuất[Xuất-NX]*(Data_Xuất[Year]=BF$1)*(Data_Xuất[Main SKU name_GOM]=$A6)),SUMPRODUCT(Data_Xuất[Xuất-NX]*(Data_Xuất[Year]=BF$1)*(Data_Xuất[Main SKU name_GOM]=$A6)*(Data_Xuất[Month]=BF$2)))} -> 672030 | BG6: {=IF(BG$2="FY",SUMPRODUCT(Data_Nhập[Tổng Nhập-NX]*(Data_Nhập[Year]=BG$1)*(Data_Nhập[Main SKU name_GOM]=$A6)*(Data_Nhập[SKU name_NHẬP_GOM]=BG$3)),SUMPRODUCT(Data_Nhập[Tổng Nhập-NX]*(Data_Nhập[Year]=BG$1)*(Data_Nhập[Month]=BG$2)*(Data_Nhập[Main SKU name_GOM]=$A6)*(Data_Nhập[SKU name_NHẬP_GOM]=BG$3)))} -> 616000 | BH6: {=IF(BH$2="FY",SUMPRODUCT(Data_Nhập[Tổng Nhập-NX]*(Data_Nhập[Year]=BH$1)*(Data_Nhập[Main SKU name_GOM]=$A6)*(Data_Nhập[SKU name_NHẬP_GOM]=BH$3)),SUMPRODUCT(Data_Nhập[Tổng Nhập-NX]*(Data_Nhập[Year]=BH$1)*(Data_Nhập[Month]=BH$2)*(Data_Nhập[Main SKU name_GOM]=$A6)*(Data_Nhập[SKU name_NHẬP_GOM]=BH$3)))} -> 1100 | BI6: {=IF(BI$2="FY",SUMPRODUCT(Data_Nhập[Tổng Nhập-NX]*(Data_Nhập[Year]=BI$1)*(Data_Nhập[Main SKU name_GOM]=$A6)*(Data_Nhập[SKU name_NHẬP_GOM]=BI$3)),SUMPRODUCT(Data_Nhập[Tổng Nhập-NX]*(Data_Nhập[Year]=BI$1)*(Data_Nhập[Month]=BI$2)*(Data_Nhập[Main SKU name_GOM]=$A6)*(Data_Nhập[SKU name_NHẬP_GOM]=BI$3)))} -> 0 | BJ6: {=IF(BJ$2="FY",SUMPRODUCT(Data_Nhập[Tổng Nhập-NX]*(Data_Nhập[Year]=BJ$1)*(Data_Nhập[Main SKU name_GOM]=$A6)*(Data_Nhập[SKU name_NHẬP_GOM]=BJ$3)),SUMPRODUCT(Data_Nhập[Tổng Nhập-NX]*(Data_Nhập[Year]=BJ$1)*(Data_Nhập[Month]=BJ$2)*(Data_Nhập[Main SKU name_GOM]=$A6)*(Data_Nhập[SKU name_NHẬP_GOM]=BJ$3)))} -> 0 | BK6: {=IF(BK$2="FY",SUMPRODUCT(Data_Nhập[Tổng Nhập-NX]*(Data_Nhập[Year]=BK$1)*(Data_Nhập[Main SKU name_GOM]=$A6)*(Data_Nhập[SKU name_NHẬP_GOM]=BK$3)),SUMPRODUCT(Data_Nhập[Tổng Nhập-NX]*(Data_Nhập[Year]=BK$1)*(Data_Nhập[Month]=BK$2)*(Data_Nhập[Main SKU name_GOM]=$A6)*(Data_Nhập[SKU name_NHẬP_GOM]=BK$3)))} -> 8800 | BL6: {=IF(BL$2="FY",SUMPRODUCT(Data_Nhập[Tổng Nhập-NX]*(Data_Nhập[Year]=BL$1)*(Data_Nhập[Main SKU name_GOM]=$A6)*(Data_Nhập[SKU name_NHẬP_GOM]=BL$3)),SUMPRODUCT(Data_Nhập[Tổng Nhập-NX]*(Data_Nhập[Year]=BL$1)*(Data_Nhập[Month]=BL$2)*(Data_Nhập[Main SKU name_GOM]=$A6)*(Data_Nhập[SKU name_NHẬP_GOM]=BL$3)))} -> 0 | BM6: {=IF(BM$2="FY",SUMPRODUCT(Data_Nhập[Tổng Nhập-NX]*(Data_Nhập[Year]=BM$1)*(Data_Nhập[Main SKU name_GOM]=$A6)*(Data_Nhập[SKU name_NHẬP_GOM]=BM$3)),SUMPRODUCT(Data_Nhập[Tổng Nhập-NX]*(Data_Nhập[Year]=BM$1)*(Data_Nhập[Month]=BM$2)*(Data_Nhập[Main SKU name_GOM]=$A6)*(Data_Nhập[SKU name_NHẬP_GOM]=BM$3)))} -> 0 | BN6: {=IF(BN$2="FY",SUMPRODUCT(Data_Nhập[Tổng Nhập-NX]*(Data_Nhập[Year]=BN$1)*(Data_Nhập[Main SKU name_GOM]=$A6)*(Data_Nhập[SKU name_NHẬP_GOM]=BN$3)),SUMPRODUCT(Data_Nhập[Tổng Nhập-NX]*(Data_Nhập[Year]=BN$1)*(Data_Nhập[Month]=BN$2)*(Data_Nhập[Main SKU name_GOM]=$A6)*(Data_Nhập[SKU name_NHẬP_GOM]=BN$3)))} -> 0 | ... BU6: {=IF(BU$2="FY",SUMPRODUCT(Data_Nhập[Tổng Nhập-NX]*(Data_Nhập[Year]=BU$1)*(Data_Nhập[Main SKU name_GOM]=$A6)*(Data_Nhập[SKU name_NHẬP_GOM]=BU$3)),SUMPRODUCT(Data_Nhập[Tổng Nhập-NX]*(Data_Nhập[Year]=BU$1)*(Data_Nhập[Month]=BU$2)*(Data_Nhập[Main SKU name_GOM]=$A6)*(Data_Nhập[SKU name_NHẬP_GOM]=BU$3)))} -> 0 | BV6: =SUM(BG6:BU6) -> 661671 | BX6: {=IF(BX$2="FY",SUMPRODUCT(Data_Xuất[Xuất-NX]*(Data_Xuất[Year]=BX$1)*(Data_Xuất[Main SKU name_GOM]=$A6)),SUMPRODUCT(Data_Xuất[Xuất-NX]*(Data_Xuất[Year]=BX$1)*(Data_Xuất[Main SKU name_GOM]=$A6)*(Data_Xuất[Month]=BX$2)))} -> 963781 | BY6: {=IF(BY$2="FY",SUMPRODUCT(Data_Nhập[Tổng Nhập-NX]*(Data_Nhập[Year]=BY$1)*(Data_Nhập[Main SKU name_GOM]=$A6)*(Data_Nhập[SKU name_NHẬP_GOM]=BY$3)),SUMPRODUCT(Data_Nhập[Tổng Nhập-NX]*(Data_Nhập[Year]=BY$1)*(Data_Nhập[Month]=BY$2)*(Data_Nhập[Main SKU name_GOM]=$A6)*(Data_Nhập[SKU name_NHẬP_GOM]=BY$3)))} -> 850300 | BZ6: {=IF(BZ$2="FY",SUMPRODUCT(Data_Nhập[Tổng Nhập-NX]*(Data_Nhập[Year]=BZ$1)*(Data_Nhập[Main SKU name_GOM]=$A6)*(Data_Nhập[SKU name_NHẬP_GOM]=BZ$3)),SUMPRODUCT(Data_Nhập[Tổng Nhập-NX]*(Data_Nhập[Year]=BZ$1)*(Data_Nhập[Month]=BZ$2)*(Data_Nhập[Main SKU name_GOM]=$A6)*(Data_Nhập[SKU name_NHẬP_GOM]=BZ$3)))} -> 13200 | CA6: {=IF(CA$2="FY",SUMPRODUCT(Data_Nhập[Tổng Nhập-NX]*(Data_Nhập[Year]=CA$1)*(Data_Nhập[Main SKU name_GOM]=$A6)*(Data_Nhập[SKU name_NHẬP_GOM]=CA$3)),SUMPRODUCT(Data_Nhập[Tổng Nhập-NX]*(Data_Nhập[Year]=CA$1)*(Data_Nhập[Month]=CA$2)*(Data_Nhập[Main SKU name_GOM]=$A6)*(Data_Nhập[SKU name_NHẬP_GOM]=CA$3)))} -> 47300 | CB6: {=IF(CB$2="FY",SUMPRODUCT(Data_Nhập[Tổng Nhập-NX]*(Data_Nhập[Year]=CB$1)*(Data_Nhập[Main SKU name_GOM]=$A6)*(Data_Nhập[SKU name_NHẬP_GOM]=CB$3)),SUMPRODUCT(Data_Nhập[Tổng Nhập-NX]*(Data_Nhập[Year]=CB$1)*(Data_Nhập[Month]=CB$2)*(Data_Nhập[Main SKU name_GOM]=$A6)*(Data_Nhập[SKU name_NHẬP_GOM]=CB$3)))} -> 0 | CC6: {=IF(CC$2="FY",SUMPRODUCT(Data_Nhập[Tổng Nhập-NX]*(Data_Nhập[Year]=CC$1)*(Data_Nhập[Main SKU name_GOM]=$A6)*(Data_Nhập[SKU name_NHẬP_GOM]=CC$3)),SUMPRODUCT(Data_Nhập[Tổng Nhập-NX]*(Data_Nhập[Year]=CC$1)*(Data_Nhập[Month]=CC$2)*(Data_Nhập[Main SKU name_GOM]=$A6)*(Data_Nhập[SKU name_NHẬP_GOM]=CC$3)))} -> 13200 | CD6: {=IF(CD$2="FY",SUMPRODUCT(Data_Nhập[Tổng Nhập-NX]*(Data_Nhập[Year]=CD$1)*(Data_Nhập[Main SKU name_GOM]=$A6)*(Data_Nhập[SKU name_NHẬP_GOM]=CD$3)),SUMPRODUCT(Data_Nhập[Tổng Nhập-NX]*(Data_Nhập[Year]=CD$1)*(Data_Nhập[Month]=CD$2)*(Data_Nhập[Main SKU name_GOM]=$A6)*(Data_Nhập[SKU name_NHẬP_GOM]=CD$3)))} -> 0 | CE6: {=IF(CE$2="FY",SUMPRODUCT(Data_Nhập[Tổng Nhập-NX]*(Data_Nhập[Year]=CE$1)*(Data_Nhập[Main SKU name_GOM]=$A6)*(Data_Nhập[SKU name_NHẬP_GOM]=CE$3)),SUMPRODUCT(Data_Nhập[Tổng Nhập-NX]*(Data_Nhập[Year]=CE$1)*(Data_Nhập[Month]=CE$2)*(Data_Nhập[Main SKU name_GOM]=$A6)*(Data_Nhập[SKU name_NHẬP_GOM]=CE$3)))} -> 0 | CF6: {=IF(CF$2="FY",SUMPRODUCT(Data_Nhập[Tổng Nhập-NX]*(Data_Nhập[Year]=CF$1)*(Data_Nhập[Main SKU name_GOM]=$A6)*(Data_Nhập[SKU name_NHẬP_GOM]=CF$3)),SUMPRODUCT(Data_Nhập[Tổng Nhập-NX]*(Data_Nhập[Year]=CF$1)*(Data_Nhập[Month]=CF$2)*(Data_Nhập[Main SKU name_GOM]=$A6)*(Data_Nhập[SKU name_NHẬP_GOM]=CF$3)))} -> 0 | ... CM6: {=IF(CM$2="FY",SUMPRODUCT(Data_Nhập[Tổng Nhập-NX]*(Data_Nhập[Year]=CM$1)*(Data_Nhập[Main SKU name_GOM]=$A6)*(Data_Nhập[SKU name_NHẬP_GOM]=CM$3)),SUMPRODUCT(Data_Nhập[Tổng Nhập-NX]*(Data_Nhập[Year]=CM$1)*(Data_Nhập[Month]=CM$2)*(Data_Nhập[Main SKU name_GOM]=$A6)*(Data_Nhập[SKU name_NHẬP_GOM]=CM$3)))} -> 0 | CN6: =SUM(BY6:CM6) -> 950423 | CP6: {=IF(CP$2="FY",SUMPRODUCT(Data_Xuất[Xuất-NX]*(Data_Xuất[Year]=CP$1)*(Data_Xuất[Main SKU name_GOM]=$A6)),SUMPRODUCT(Data_Xuất[Xuất-NX]*(Data_Xuất[Year]=CP$1)*(Data_Xuất[Main SKU name_GOM]=$A6)*(Data_Xuất[Month]=CP$2)))} -> 0 | CQ6: {=IF(CQ$2="FY",SUMPRODUCT(Data_Nhập[Tổng Nhập-NX]*(Data_Nhập[Year]=CQ$1)*(Data_Nhập[Main SKU name_GOM]=$A6)*(Data_Nhập[SKU name_NHẬP_GOM]=CQ$3)),SUMPRODUCT(Data_Nhập[Tổng Nhập-NX]*(Data_Nhập[Year]=CQ$1)*(Data_Nhập[Month]=CQ$2)*(Data_Nhập[Main SKU name_GOM]=$A6)*(Data_Nhập[SKU name_NHẬP_GOM]=CQ$3)))} -> 0 | CR6: {=IF(CR$2="FY",SUMPRODUCT(Data_Nhập[Tổng Nhập-NX]*(Data_Nhập[Year]=CR$1)*(Data_Nhập[Main SKU name_GOM]=$A6)*(Data_Nhập[SKU name_NHẬP_GOM]=CR$3)),SUMPRODUCT(Data_Nhập[Tổng Nhập-NX]*(Data_Nhập[Year]=CR$1)*(Data_Nhập[Month]=CR$2)*(Data_Nhập[Main SKU name_GOM]=$A6)*(Data_Nhập[SKU name_NHẬP_GOM]=CR$3)))} -> 0 | CS6: {=IF(CS$2="FY",SUMPRODUCT(Data_Nhập[Tổng Nhập-NX]*(Data_Nhập[Year]=CS$1)*(Data_Nhập[Main SKU name_GOM]=$A6)*(Data_Nhập[SKU name_NHẬP_GOM]=CS$3)),SUMPRODUCT(Data_Nhập[Tổng Nhập-NX]*(Data_Nhập[Year]=CS$1)*(Data_Nhập[Month]=CS$2)*(Data_Nhập[Main SKU name_GOM]=$A6)*(Data_Nhập[SKU name_NHẬP_GOM]=CS$3)))} -> 0 | CT6: {=IF(CT$2="FY",SUMPRODUCT(Data_Nhập[Tổng Nhập-NX]*(Data_Nhập[Year]=CT$1)*(Data_Nhập[Main SKU name_GOM]=$A6)*(Data_Nhập[SKU name_NHẬP_GOM]=CT$3)),SUMPRODUCT(Data_Nhập[Tổng Nhập-NX]*(Data_Nhập[Year]=CT$1)*(Data_Nhập[Month]=CT$2)*(Data_Nhập[Main SKU name_GOM]=$A6)*(Data_Nhập[SKU name_NHẬP_GOM]=CT$3)))} -> 0 | CU6: {=IF(CU$2="FY",SUMPRODUCT(Data_Nhập[Tổng Nhập-NX]*(Data_Nhập[Year]=CU$1)*(Data_Nhập[Main SKU name_GOM]=$A6)*(Data_Nhập[SKU name_NHẬP_GOM]=CU$3)),SUMPRODUCT(Data_Nhập[Tổng Nhập-NX]*(Data_Nhập[Year]=CU$1)*(Data_Nhập[Month]=CU$2)*(Data_Nhập[Main SKU name_GOM]=$A6)*(Data_Nhập[SKU name_NHẬP_GOM]=CU$3)))} -> 0 | CV6: {=IF(CV$2="FY",SUMPRODUCT(Data_Nhập[Tổng Nhập-NX]*(Data_Nhập[Year]=CV$1)*(Data_Nhập[Main SKU name_GOM]=$A6)*(Data_Nhập[SKU name_NHẬP_GOM]=CV$3)),SUMPRODUCT(Data_Nhập[Tổng Nhập-NX]*(Data_Nhập[Year]=CV$1)*(Data_Nhập[Month]=CV$2)*(Data_Nhập[Main SKU name_GOM]=$A6)*(Data_Nhập[SKU name_NHẬP_GOM]=CV$3)))} -> 0 | CW6: {=IF(CW$2="FY",SUMPRODUCT(Data_Nhập[Tổng Nhập-NX]*(Data_Nhập[Year]=CW$1)*(Data_Nhập[Main SKU name_GOM]=$A6)*(Data_Nhập[SKU name_NHẬP_GOM]=CW$3)),SUMPRODUCT(Data_Nhập[Tổng Nhập-NX]*(Data_Nhập[Year]=CW$1)*(Data_Nhập[Month]=CW$2)*(Data_Nhập[Main SKU name_GOM]=$A6)*(Data_Nhập[SKU name_NHẬP_GOM]=CW$3)))} -> 0 | CX6: {=IF(CX$2="FY",SUMPRODUCT(Data_Nhập[Tổng Nhập-NX]*(Data_Nhập[Year]=CX$1)*(Data_Nhập[Main SKU name_GOM]=$A6)*(Data_Nhập[SKU name_NHẬP_GOM]=CX$3)),SUMPRODUCT(Data_Nhập[Tổng Nhập-NX]*(Data_Nhập[Year]=CX$1)*(Data_Nhập[Month]=CX$2)*(Data_Nhập[Main SKU name_GOM]=$A6)*(Data_Nhập[SKU name_NHẬP_GOM]=CX$3)))} -> 0 | ... DE6: {=IF(DE$2="FY",SUMPRODUCT(Data_Nhập[Tổng Nhập-NX]*(Data_Nhập[Year]=DE$1)*(Data_Nhập[Main SKU name_GOM]=$A6)*(Data_Nhập[SKU name_NHẬP_GOM]=DE$3)),SUMPRODUCT(Data_Nhập[Tổng Nhập-NX]*(Data_Nhập[Year]=DE$1)*(Data_Nhập[Month]=DE$2)*(Data_Nhập[Main SKU name_GOM]=$A6)*(Data_Nhập[SKU name_NHẬP_GOM]=DE$3)))} -> 0 | DF6: =SUM(CQ6:DE6) -> 0 | DH6: {=IF(DH$2="FY",SUMPRODUCT(Data_Xuất[Xuất-NX]*(Data_Xuất[Year]=DH$1)*(Data_Xuất[Main SKU name_GOM]=$A6)),SUMPRODUCT(Data_Xuất[Xuất-NX]*(Data_Xuất[Year]=DH$1)*(Data_Xuất[Main SKU name_GOM]=$A6)*(Data_Xuất[Month]=DH$2)))} -> 0 | DI6: {=IF(DI$2="FY",SUMPRODUCT(Data_Nhập[Tổng Nhập-NX]*(Data_Nhập[Year]=DI$1)*(Data_Nhập[Main SKU name_GOM]=$A6)*(Data_Nhập[SKU name_NHẬP_GOM]=DI$3)),SUMPRODUCT(Data_Nhập[Tổng Nhập-NX]*(Data_Nhập[Year]=DI$1)*(Data_Nhập[Month]=DI$2)*(Data_Nhập[Main SKU name_GOM]=$A6)*(Data_Nhập[SKU name_NHẬP_GOM]=DI$3)))} -> 0 | DJ6: {=IF(DJ$2="FY",SUMPRODUCT(Data_Nhập[Tổng Nhập-NX]*(Data_Nhập[Year]=DJ$1)*(Data_Nhập[Main SKU name_GOM]=$A6)*(Data_Nhập[SKU name_NHẬP_GOM]=DJ$3)),SUMPRODUCT(Data_Nhập[Tổng Nhập-NX]*(Data_Nhập[Year]=DJ$1)*(Data_Nhập[Month]=DJ$2)*(Data_Nhập[Main SKU name_GOM]=$A6)*(Data_Nhập[SKU name_NHẬP_GOM]=DJ$3)))} -> 0 | DK6: {=IF(DK$2="FY",SUMPRODUCT(Data_Nhập[Tổng Nhập-NX]*(Data_Nhập[Year]=DK$1)*(Data_Nhập[Main SKU name_GOM]=$A6)*(Data_Nhập[SKU name_NHẬP_GOM]=DK$3)),SUMPRODUCT(Data_Nhập[Tổng Nhập-NX]*(Data_Nhập[Year]=DK$1)*(Data_Nhập[Month]=DK$2)*(Data_Nhập[Main SKU name_GOM]=$A6)*(Data_Nhập[SKU name_NHẬP_GOM]=DK$3)))} -> 0 | DL6: {=IF(DL$2="FY",SUMPRODUCT(Data_Nhập[Tổng Nhập-NX]*(Data_Nhập[Year]=DL$1)*(Data_Nhập[Main SKU name_GOM]=$A6)*(Data_Nhập[SKU name_NHẬP_GOM]=DL$3)),SUMPRODUCT(Data_Nhập[Tổng Nhập-NX]*(Data_Nhập[Year]=DL$1)*(Data_Nhập[Month]=DL$2)*(Data_Nhập[Main SKU name_GOM]=$A6)*(Data_Nhập[SKU name_NHẬP_GOM]=DL$3)))} -> 0 | DM6: {=IF(DM$2="FY",SUMPRODUCT(Data_Nhập[Tổng Nhập-NX]*(Data_Nhập[Year]=DM$1)*(Data_Nhập[Main SKU name_GOM]=$A6)*(Data_Nhập[SKU name_NHẬP_GOM]=DM$3)),SUMPRODUCT(Data_Nhập[Tổng Nhập-NX]*(Data_Nhập[Year]=DM$1)*(Data_Nhập[Month]=DM$2)*(Data_Nhập[Main SKU name_GOM]=$A6)*(Data_Nhập[SKU name_NHẬP_GOM]=DM$3)))} -> 0 | DN6: {=IF(DN$2="FY",SUMPRODUCT(Data_Nhập[Tổng Nhập-NX]*(Data_Nhập[Year]=DN$1)*(Data_Nhập[Main SKU name_GOM]=$A6)*(Data_Nhập[SKU name_NHẬP_GOM]=DN$3)),SUMPRODUCT(Data_Nhập[Tổng Nhập-NX]*(Data_Nhập[Year]=DN$1)*(Data_Nhập[Month]=DN$2)*(Data_Nhập[Main SKU name_GOM]=$A6)*(Data_Nhập[SKU name_NHẬP_GOM]=DN$3)))} -> 0 | DO6: {=IF(DO$2="FY",SUMPRODUCT(Data_Nhập[Tổng Nhập-NX]*(Data_Nhập[Year]=DO$1)*(Data_Nhập[Main SKU name_GOM]=$A6)*(Data_Nhập[SKU name_NHẬP_GOM]=DO$3)),SUMPRODUCT(Data_Nhập[Tổng Nhập-NX]*(Data_Nhập[Year]=DO$1)*(Data_Nhập[Month]=DO$2)*(Data_Nhập[Main SKU name_GOM]=$A6)*(Data_Nhập[SKU name_NHẬP_GOM]=DO$3)))} -> 0 | DP6: {=IF(DP$2="FY",SUMPRODUCT(Data_Nhập[Tổng Nhập-NX]*(Data_Nhập[Year]=DP$1)*(Data_Nhập[Main SKU name_GOM]=$A6)*(Data_Nhập[SKU name_NHẬP_GOM]=DP$3)),SUMPRODUCT(Data_Nhập[Tổng Nhập-NX]*(Data_Nhập[Year]=DP$1)*(Data_Nhập[Month]=DP$2)*(Data_Nhập[Main SKU name_GOM]=$A6)*(Data_Nhập[SKU name_NHẬP_GOM]=DP$3)))} -> 0 | ... DW6: {=IF(DW$2="FY",SUMPRODUCT(Data_Nhập[Tổng Nhập-NX]*(Data_Nhập[Year]=DW$1)*(Data_Nhập[Main SKU name_GOM]=$A6)*(Data_Nhập[SKU name_NHẬP_GOM]=DW$3)),SUMPRODUCT(Data_Nhập[Tổng Nhập-NX]*(Data_Nhập[Year]=DW$1)*(Data_Nhập[Month]=DW$2)*(Data_Nhập[Main SKU name_GOM]=$A6)*(Data_Nhập[SKU name_NHẬP_GOM]=DW$3)))} -> 0 | DX6: =SUM(DI6:DW6) -> 0 | DZ6: {=IF(DZ$2="FY",SUMPRODUCT(Data_Xuất[Xuất-NX]*(Data_Xuất[Year]=DZ$1)*(Data_Xuất[Main SKU name_GOM]=$A6)),SUMPRODUCT(Data_Xuất[Xuất-NX]*(Data_Xuất[Year]=DZ$1)*(Data_Xuất[Main SKU name_GOM]=$A6)*(Data_Xuất[Month]=DZ$2)))} -> 0 | EA6: {=IF(EA$2="FY",SUMPRODUCT(Data_Nhập[Tổng Nhập-NX]*(Data_Nhập[Year]=EA$1)*(Data_Nhập[Main SKU name_GOM]=$A6)*(Data_Nhập[SKU name_NHẬP_GOM]=EA$3)),SUMPRODUCT(Data_Nhập[Tổng Nhập-NX]*(Data_Nhập[Year]=EA$1)*(Data_Nhập[Month]=EA$2)*(Data_Nhập[Main SKU name_GOM]=$A6)*(Data_Nhập[SKU name_NHẬP_GOM]=EA$3)))} -> 0 | EB6: {=IF(EB$2="FY",SUMPRODUCT(Data_Nhập[Tổng Nhập-NX]*(Data_Nhập[Year]=EB$1)*(Data_Nhập[Main SKU name_GOM]=$A6)*(Data_Nhập[SKU name_NHẬP_GOM]=EB$3)),SUMPRODUCT(Data_Nhập[Tổng Nhập-NX]*(Data_Nhập[Year]=EB$1)*(Data_Nhập[Month]=EB$2)*(Data_Nhập[Main SKU name_GOM]=$A6)*(Data_Nhập[SKU name_NHẬP_GOM]=EB$3)))} -> 0 | EC6: {=IF(EC$2="FY",SUMPRODUCT(Data_Nhập[Tổng Nhập-NX]*(Data_Nhập[Year]=EC$1)*(Data_Nhập[Main SKU name_GOM]=$A6)*(Data_Nhập[SKU name_NHẬP_GOM]=EC$3)),SUMPRODUCT(Data_Nhập[Tổng Nhập-NX]*(Data_Nhập[Year]=EC$1)*(Data_Nhập[Month]=EC$2)*(Data_Nhập[Main SKU name_GOM]=$A6)*(Data_Nhập[SKU name_NHẬP_GOM]=EC$3)))} -> 0 | ED6: {=IF(ED$2="FY",SUMPRODUCT(Data_Nhập[Tổng Nhập-NX]*(Data_Nhập[Year]=ED$1)*(Data_Nhập[Main SKU name_GOM]=$A6)*(Data_Nhập[SKU name_NHẬP_GOM]=ED$3)),SUMPRODUCT(Data_Nhập[Tổng Nhập-NX]*(Data_Nhập[Year]=ED$1)*(Data_Nhập[Month]=ED$2)*(Data_Nhập[Main SKU name_GOM]=$A6)*(Data_Nhập[SKU name_NHẬP_GOM]=ED$3)))} -> 0 | EE6: {=IF(EE$2="FY",SUMPRODUCT(Data_Nhập[Tổng Nhập-NX]*(Data_Nhập[Year]=EE$1)*(Data_Nhập[Main SKU name_GOM]=$A6)*(Data_Nhập[SKU name_NHẬP_GOM]=EE$3)),SUMPRODUCT(Data_Nhập[Tổng Nhập-NX]*(Data_Nhập[Year]=EE$1)*(Data_Nhập[Month]=EE$2)*(Data_Nhập[Main SKU name_GOM]=$A6)*(Data_Nhập[SKU name_NHẬP_GOM]=EE$3)))} -> 0 | EF6: {=IF(EF$2="FY",SUMPRODUCT(Data_Nhập[Tổng Nhập-NX]*(Data_Nhập[Year]=EF$1)*(Data_Nhập[Main SKU name_GOM]=$A6)*(Data_Nhập[SKU name_NHẬP_GOM]=EF$3)),SUMPRODUCT(Data_Nhập[Tổng Nhập-NX]*(Data_Nhập[Year]=EF$1)*(Data_Nhập[Month]=EF$2)*(Data_Nhập[Main SKU name_GOM]=$A6)*(Data_Nhập[SKU name_NHẬP_GOM]=EF$3)))} -> 0 | EG6: {=IF(EG$2="FY",SUMPRODUCT(Data_Nhập[Tổng Nhập-NX]*(Data_Nhập[Year]=EG$1)*(Data_Nhập[Main SKU name_GOM]=$A6)*(Data_Nhập[SKU name_NHẬP_GOM]=EG$3)),SUMPRODUCT(Data_Nhập[Tổng Nhập-NX]*(Data_Nhập[Year]=EG$1)*(Data_Nhập[Month]=EG$2)*(Data_Nhập[Main SKU name_GOM]=$A6)*(Data_Nhập[SKU name_NHẬP_GOM]=EG$3)))} -> 0 | EH6: {=IF(EH$2="FY",SUMPRODUCT(Data_Nhập[Tổng Nhập-NX]*(Data_Nhập[Year]=EH$1)*(Data_Nhập[Main SKU name_GOM]=$A6)*(Data_Nhập[SKU name_NHẬP_GOM]=EH$3)),SUMPRODUCT(Data_Nhập[Tổng Nhập-NX]*(Data_Nhập[Year]=EH$1)*(Data_Nhập[Month]=EH$2)*(Data_Nhập[Main SKU name_GOM]=$A6)*(Data_Nhập[SKU name_NHẬP_GOM]=EH$3)))} -> 0 | ... EO6: {=IF(EO$2="FY",SUMPRODUCT(Data_Nhập[Tổng Nhập-NX]*(Data_Nhập[Year]=EO$1)*(Data_Nhập[Main SKU name_GOM]=$A6)*(Data_Nhập[SKU name_NHẬP_GOM]=EO$3)),SUMPRODUCT(Data_Nhập[Tổng Nhập-NX]*(Data_Nhập[Year]=EO$1)*(Data_Nhập[Month]=EO$2)*(Data_Nhập[Main SKU name_GOM]=$A6)*(Data_Nhập[SKU name_NHẬP_GOM]=EO$3)))} -> 0 | EP6: =SUM(EA6:EO6) -> 0 | ER6: {=IF(ER$2="FY",SUMPRODUCT(Data_Xuất[Xuất-NX]*(Data_Xuất[Year]=ER$1)*(Data_Xuất[Main SKU name_GOM]=$A6)),SUMPRODUCT(Data_Xuất[Xuất-NX]*(Data_Xuất[Year]=ER$1)*(Data_Xuất[Main SKU name_GOM]=$A6)*(Data_Xuất[Month]=ER$2)))} -> 0 | ES6: {=IF(ES$2="FY",SUMPRODUCT(Data_Nhập[Tổng Nhập-NX]*(Data_Nhập[Year]=ES$1)*(Data_Nhập[Main SKU name_GOM]=$A6)*(Data_Nhập[SKU name_NHẬP_GOM]=ES$3)),SUMPRODUCT(Data_Nhập[Tổng Nhập-NX]*(Data_Nhập[Year]=ES$1)*(Data_Nhập[Month]=ES$2)*(Data_Nhập[Main SKU name_GOM]=$A6)*(Data_Nhập[SKU name_NHẬP_GOM]=ES$3)))} -> 0 | ET6: {=IF(ET$2="FY",SUMPRODUCT(Data_Nhập[Tổng Nhập-NX]*(Data_Nhập[Year]=ET$1)*(Data_Nhập[Main SKU name_GOM]=$A6)*(Data_Nhập[SKU name_NHẬP_GOM]=ET$3)),SUMPRODUCT(Data_Nhập[Tổng Nhập-NX]*(Data_Nhập[Year]=ET$1)*(Data_Nhập[Month]=ET$2)*(Data_Nhập[Main SKU name_GOM]=$A6)*(Data_Nhập[SKU name_NHẬP_GOM]=ET$3)))} -> 0 | EU6: {=IF(EU$2="FY",SUMPRODUCT(Data_Nhập[Tổng Nhập-NX]*(Data_Nhập[Year]=EU$1)*(Data_Nhập[Main SKU name_GOM]=$A6)*(Data_Nhập[SKU name_NHẬP_GOM]=EU$3)),SUMPRODUCT(Data_Nhập[Tổng Nhập-NX]*(Data_Nhập[Year]=EU$1)*(Data_Nhập[Month]=EU$2)*(Data_Nhập[Main SKU name_GOM]=$A6)*(Data_Nhập[SKU name_NHẬP_GOM]=EU$3)))} -> 0 | EV6: {=IF(EV$2="FY",SUMPRODUCT(Data_Nhập[Tổng Nhập-NX]*(Data_Nhập[Year]=EV$1)*(Data_Nhập[Main SKU name_GOM]=$A6)*(Data_Nhập[SKU name_NHẬP_GOM]=EV$3)),SUMPRODUCT(Data_Nhập[Tổng Nhập-NX]*(Data_Nhập[Year]=EV$1)*(Data_Nhập[Month]=EV$2)*(Data_Nhập[Main SKU name_GOM]=$A6)*(Data_Nhập[SKU name_NHẬP_GOM]=EV$3)))} -> 0 | EW6: {=IF(EW$2="FY",SUMPRODUCT(Data_Nhập[Tổng Nhập-NX]*(Data_Nhập[Year]=EW$1)*(Data_Nhập[Main SKU name_GOM]=$A6)*(Data_Nhập[SKU name_NHẬP_GOM]=EW$3)),SUMPRODUCT(Data_Nhập[Tổng Nhập-NX]*(Data_Nhập[Year]=EW$1)*(Data_Nhập[Month]=EW$2)*(Data_Nhập[Main SKU name_GOM]=$A6)*(Data_Nhập[SKU name_NHẬP_GOM]=EW$3)))} -> 0 | EX6: {=IF(EX$2="FY",SUMPRODUCT(Data_Nhập[Tổng Nhập-NX]*(Data_Nhập[Year]=EX$1)*(Data_Nhập[Main SKU name_GOM]=$A6)*(Data_Nhập[SKU name_NHẬP_GOM]=EX$3)),SUMPRODUCT(Data_Nhập[Tổng Nhập-NX]*(Data_Nhập[Year]=EX$1)*(Data_Nhập[Month]=EX$2)*(Data_Nhập[Main SKU name_GOM]=$A6)*(Data_Nhập[SKU name_NHẬP_GOM]=EX$3)))} -> 0 | EY6: {=IF(EY$2="FY",SUMPRODUCT(Data_Nhập[Tổng Nhập-NX]*(Data_Nhập[Year]=EY$1)*(Data_Nhập[Main SKU name_GOM]=$A6)*(Data_Nhập[SKU name_NHẬP_GOM]=EY$3)),SUMPRODUCT(Data_Nhập[Tổng Nhập-NX]*(Data_Nhập[Year]=EY$1)*(Data_Nhập[Month]=EY$2)*(Data_Nhập[Main SKU name_GOM]=$A6)*(Data_Nhập[SKU name_NHẬP_GOM]=EY$3)))} -> 0 | EZ6: {=IF(EZ$2="FY",SUMPRODUCT(Data_Nhập[Tổng Nhập-NX]*(Data_Nhập[Year]=EZ$1)*(Data_Nhập[Main SKU name_GOM]=$A6)*(Data_Nhập[SKU name_NHẬP_GOM]=EZ$3)),SUMPRODUCT(Data_Nhập[Tổng Nhập-NX]*(Data_Nhập[Year]=EZ$1)*(Data_Nhập[Month]=EZ$2)*(Data_Nhập[Main SKU name_GOM]=$A6)*(Data_Nhập[SKU name_NHẬP_GOM]=EZ$3)))} -> 0 | ... FG6: {=IF(FG$2="FY",SUMPRODUCT(Data_Nhập[Tổng Nhập-NX]*(Data_Nhập[Year]=FG$1)*(Data_Nhập[Main SKU name_GOM]=$A6)*(Data_Nhập[SKU name_NHẬP_GOM]=FG$3)),SUMPRODUCT(Data_Nhập[Tổng Nhập-NX]*(Data_Nhập[Year]=FG$1)*(Data_Nhập[Month]=FG$2)*(Data_Nhập[Main SKU name_GOM]=$A6)*(Data_Nhập[SKU name_NHẬP_GOM]=FG$3)))} -> 0 | FH6: =SUM(ES6:FG6) -> 0 | FJ6: {=IF(FJ$2="FY",SUMPRODUCT(Data_Xuất[Xuất-NX]*(Data_Xuất[Year]=FJ$1)*(Data_Xuất[Main SKU name_GOM]=$A6)),SUMPRODUCT(Data_Xuất[Xuất-NX]*(Data_Xuất[Year]=FJ$1)*(Data_Xuất[Main SKU name_GOM]=$A6)*(Data_Xuất[Month]=FJ$2)))} -> 0 | FK6: {=IF(FK$2="FY",SUMPRODUCT(Data_Nhập[Tổng Nhập-NX]*(Data_Nhập[Year]=FK$1)*(Data_Nhập[Main SKU name_GOM]=$A6)*(Data_Nhập[SKU name_NHẬP_GOM]=FK$3)),SUMPRODUCT(Data_Nhập[Tổng Nhập-NX]*(Data_Nhập[Year]=FK$1)*(Data_Nhập[Month]=FK$2)*(Data_Nhập[Main SKU name_GOM]=$A6)*(Data_Nhập[SKU name_NHẬP_GOM]=FK$3)))} -> 0 | FL6: {=IF(FL$2="FY",SUMPRODUCT(Data_Nhập[Tổng Nhập-NX]*(Data_Nhập[Year]=FL$1)*(Data_Nhập[Main SKU name_GOM]=$A6)*(Data_Nhập[SKU name_NHẬP_GOM]=FL$3)),SUMPRODUCT(Data_Nhập[Tổng Nhập-NX]*(Data_Nhập[Year]=FL$1)*(Data_Nhập[Month]=FL$2)*(Data_Nhập[Main SKU name_GOM]=$A6)*(Data_Nhập[SKU name_NHẬP_GOM]=FL$3)))} -> 0 | FM6: {=IF(FM$2="FY",SUMPRODUCT(Data_Nhập[Tổng Nhập-NX]*(Data_Nhập[Year]=FM$1)*(Data_Nhập[Main SKU name_GOM]=$A6)*(Data_Nhập[SKU name_NHẬP_GOM]=FM$3)),SUMPRODUCT(Data_Nhập[Tổng Nhập-NX]*(Data_Nhập[Year]=FM$1)*(Data_Nhập[Month]=FM$2)*(Data_Nhập[Main SKU name_GOM]=$A6)*(Data_Nhập[SKU name_NHẬP_GOM]=FM$3)))} -> 0 | FN6: {=IF(FN$2="FY",SUMPRODUCT(Data_Nhập[Tổng Nhập-NX]*(Data_Nhập[Year]=FN$1)*(Data_Nhập[Main SKU name_GOM]=$A6)*(Data_Nhập[SKU name_NHẬP_GOM]=FN$3)),SUMPRODUCT(Data_Nhập[Tổng Nhập-NX]*(Data_Nhập[Year]=FN$1)*(Data_Nhập[Month]=FN$2)*(Data_Nhập[Main SKU name_GOM]=$A6)*(Data_Nhập[SKU name_NHẬP_GOM]=FN$3)))} -> 0 | FO6: {=IF(FO$2="FY",SUMPRODUCT(Data_Nhập[Tổng Nhập-NX]*(Data_Nhập[Year]=FO$1)*(Data_Nhập[Main SKU name_GOM]=$A6)*(Data_Nhập[SKU name_NHẬP_GOM]=FO$3)),SUMPRODUCT(Data_Nhập[Tổng Nhập-NX]*(Data_Nhập[Year]=FO$1)*(Data_Nhập[Month]=FO$2)*(Data_Nhập[Main SKU name_GOM]=$A6)*(Data_Nhập[SKU name_NHẬP_GOM]=FO$3)))} -> 0 | FP6: {=IF(FP$2="FY",SUMPRODUCT(Data_Nhập[Tổng Nhập-NX]*(Data_Nhập[Year]=FP$1)*(Data_Nhập[Main SKU name_GOM]=$A6)*(Data_Nhập[SKU name_NHẬP_GOM]=FP$3)),SUMPRODUCT(Data_Nhập[Tổng Nhập-NX]*(Data_Nhập[Year]=FP$1)*(Data_Nhập[Month]=FP$2)*(Data_Nhập[Main SKU name_GOM]=$A6)*(Data_Nhập[SKU name_NHẬP_GOM]=FP$3)))} -> 0 | FQ6: {=IF(FQ$2="FY",SUMPRODUCT(Data_Nhập[Tổng Nhập-NX]*(Data_Nhập[Year]=FQ$1)*(Data_Nhập[Main SKU name_GOM]=$A6)*(Data_Nhập[SKU name_NHẬP_GOM]=FQ$3)),SUMPRODUCT(Data_Nhập[Tổng Nhập-NX]*(Data_Nhập[Year]=FQ$1)*(Data_Nhập[Month]=FQ$2)*(Data_Nhập[Main SKU name_GOM]=$A6)*(Data_Nhập[SKU name_NHẬP_GOM]=FQ$3)))} -> 0 | FR6: {=IF(FR$2="FY",SUMPRODUCT(Data_Nhập[Tổng Nhập-NX]*(Data_Nhập[Year]=FR$1)*(Data_Nhập[Main SKU name_GOM]=$A6)*(Data_Nhập[SKU name_NHẬP_GOM]=FR$3)),SUMPRODUCT(Data_Nhập[Tổng Nhập-NX]*(Data_Nhập[Year]=FR$1)*(Data_Nhập[Month]=FR$2)*(Data_Nhập[Main SKU name_GOM]=$A6)*(Data_Nhập[SKU name_NHẬP_GOM]=FR$3)))} -> 0 | ... FY6: {=IF(FY$2="FY",SUMPRODUCT(Data_Nhập[Tổng Nhập-NX]*(Data_Nhập[Year]=FY$1)*(Data_Nhập[Main SKU name_GOM]=$A6)*(Data_Nhập[SKU name_NHẬP_GOM]=FY$3)),SUMPRODUCT(Data_Nhập[Tổng Nhập-NX]*(Data_Nhập[Year]=FY$1)*(Data_Nhập[Month]=FY$2)*(Data_Nhập[Main SKU name_GOM]=$A6)*(Data_Nhập[SKU name_NHẬP_GOM]=FY$3)))} -> 0 | FZ6: =SUM(FK6:FY6) -> 0 | GB6: {=IF(GB$2="FY",SUMPRODUCT(Data_Xuất[Xuất-NX]*(Data_Xuất[Year]=GB$1)*(Data_Xuất[Main SKU name_GOM]=$A6)),SUMPRODUCT(Data_Xuất[Xuất-NX]*(Data_Xuất[Year]=GB$1)*(Data_Xuất[Main SKU name_GOM]=$A6)*(Data_Xuất[Month]=GB$2)))} -> 0 | GC6: {=IF(GC$2="FY",SUMPRODUCT(Data_Nhập[Tổng Nhập-NX]*(Data_Nhập[Year]=GC$1)*(Data_Nhập[Main SKU name_GOM]=$A6)*(Data_Nhập[SKU name_NHẬP_GOM]=GC$3)),SUMPRODUCT(Data_Nhập[Tổng Nhập-NX]*(Data_Nhập[Year]=GC$1)*(Data_Nhập[Month]=GC$2)*(Data_Nhập[Main SKU name_GOM]=$A6)*(Data_Nhập[SKU name_NHẬP_GOM]=GC$3)))} -> 0 | GD6: {=IF(GD$2="FY",SUMPRODUCT(Data_Nhập[Tổng Nhập-NX]*(Data_Nhập[Year]=GD$1)*(Data_Nhập[Main SKU name_GOM]=$A6)*(Data_Nhập[SKU name_NHẬP_GOM]=GD$3)),SUMPRODUCT(Data_Nhập[Tổng Nhập-NX]*(Data_Nhập[Year]=GD$1)*(Data_Nhập[Month]=GD$2)*(Data_Nhập[Main SKU name_GOM]=$A6)*(Data_Nhập[SKU name_NHẬP_GOM]=GD$3)))} -> 0 | GE6: {=IF(GE$2="FY",SUMPRODUCT(Data_Nhập[Tổng Nhập-NX]*(Data_Nhập[Year]=GE$1)*(Data_Nhập[Main SKU name_GOM]=$A6)*(Data_Nhập[SKU name_NHẬP_GOM]=GE$3)),SUMPRODUCT(Data_Nhập[Tổng Nhập-NX]*(Data_Nhập[Year]=GE$1)*(Data_Nhập[Month]=GE$2)*(Data_Nhập[Main SKU name_GOM]=$A6)*(Data_Nhập[SKU name_NHẬP_GOM]=GE$3)))} -> 0 | GF6: {=IF(GF$2="FY",SUMPRODUCT(Data_Nhập[Tổng Nhập-NX]*(Data_Nhập[Year]=GF$1)*(Data_Nhập[Main SKU name_GOM]=$A6)*(Data_Nhập[SKU name_NHẬP_GOM]=GF$3)),SUMPRODUCT(Data_Nhập[Tổng Nhập-NX]*(Data_Nhập[Year]=GF$1)*(Data_Nhập[Month]=GF$2)*(Data_Nhập[Main SKU name_GOM]=$A6)*(Data_Nhập[SKU name_NHẬP_GOM]=GF$3)))} -> 0 | GG6: {=IF(GG$2="FY",SUMPRODUCT(Data_Nhập[Tổng Nhập-NX]*(Data_Nhập[Year]=GG$1)*(Data_Nhập[Main SKU name_GOM]=$A6)*(Data_Nhập[SKU name_NHẬP_GOM]=GG$3)),SUMPRODUCT(Data_Nhập[Tổng Nhập-NX]*(Data_Nhập[Year]=GG$1)*(Data_Nhập[Month]=GG$2)*(Data_Nhập[Main SKU name_GOM]=$A6)*(Data_Nhập[SKU name_NHẬP_GOM]=GG$3)))} -> 0 | GH6: {=IF(GH$2="FY",SUMPRODUCT(Data_Nhập[Tổng Nhập-NX]*(Data_Nhập[Year]=GH$1)*(Data_Nhập[Main SKU name_GOM]=$A6)*(Data_Nhập[SKU name_NHẬP_GOM]=GH$3)),SUMPRODUCT(Data_Nhập[Tổng Nhập-NX]*(Data_Nhập[Year]=GH$1)*(Data_Nhập[Month]=GH$2)*(Data_Nhập[Main SKU name_GOM]=$A6)*(Data_Nhập[SKU name_NHẬP_GOM]=GH$3)))} -> 0 | GI6: {=IF(GI$2="FY",SUMPRODUCT(Data_Nhập[Tổng Nhập-NX]*(Data_Nhập[Year]=GI$1)*(Data_Nhập[Main SKU name_GOM]=$A6)*(Data_Nhập[SKU name_NHẬP_GOM]=GI$3)),SUMPRODUCT(Data_Nhập[Tổng Nhập-NX]*(Data_Nhập[Year]=GI$1)*(Data_Nhập[Month]=GI$2)*(Data_Nhập[Main SKU name_GOM]=$A6)*(Data_Nhập[SKU name_NHẬP_GOM]=GI$3)))} -> 0 | GJ6: {=IF(GJ$2="FY",SUMPRODUCT(Data_Nhập[Tổng Nhập-NX]*(Data_Nhập[Year]=GJ$1)*(Data_Nhập[Main SKU name_GOM]=$A6)*(Data_Nhập[SKU name_NHẬP_GOM]=GJ$3)),SUMPRODUCT(Data_Nhập[Tổng Nhập-NX]*(Data_Nhập[Year]=GJ$1)*(Data_Nhập[Month]=GJ$2)*(Data_Nhập[Main SKU name_GOM]=$A6)*(Data_Nhập[SKU name_NHẬP_GOM]=GJ$3)))} -> 0 | ... GQ6: {=IF(GQ$2="FY",SUMPRODUCT(Data_Nhập[Tổng Nhập-NX]*(Data_Nhập[Year]=GQ$1)*(Data_Nhập[Main SKU name_GOM]=$A6)*(Data_Nhập[SKU name_NHẬP_GOM]=GQ$3)),SUMPRODUCT(Data_Nhập[Tổng Nhập-NX]*(Data_Nhập[Year]=GQ$1)*(Data_Nhập[Month]=GQ$2)*(Data_Nhập[Main SKU name_GOM]=$A6)*(Data_Nhập[SKU name_NHẬP_GOM]=GQ$3)))} -> 0 | GR6: =SUM(GC6:GQ6) -> 0 | GT6: {=IF(GT$2="FY",SUMPRODUCT(Data_Xuất[Xuất-NX]*(Data_Xuất[Year]=GT$1)*(Data_Xuất[Main SKU name_GOM]=$A6)),SUMPRODUCT(Data_Xuất[Xuất-NX]*(Data_Xuất[Year]=GT$1)*(Data_Xuất[Main SKU name_GOM]=$A6)*(Data_Xuất[Month]=GT$2)))} -> 0 | GU6: {=IF(GU$2="FY",SUMPRODUCT(Data_Nhập[Tổng Nhập-NX]*(Data_Nhập[Year]=GU$1)*(Data_Nhập[Main SKU name_GOM]=$A6)*(Data_Nhập[SKU name_NHẬP_GOM]=GU$3)),SUMPRODUCT(Data_Nhập[Tổng Nhập-NX]*(Data_Nhập[Year]=GU$1)*(Data_Nhập[Month]=GU$2)*(Data_Nhập[Main SKU name_GOM]=$A6)*(Data_Nhập[SKU name_NHẬP_GOM]=GU$3)))} -> 0 | GV6: {=IF(GV$2="FY",SUMPRODUCT(Data_Nhập[Tổng Nhập-NX]*(Data_Nhập[Year]=GV$1)*(Data_Nhập[Main SKU name_GOM]=$A6)*(Data_Nhập[SKU name_NHẬP_GOM]=GV$3)),SUMPRODUCT(Data_Nhập[Tổng Nhập-NX]*(Data_Nhập[Year]=GV$1)*(Data_Nhập[Month]=GV$2)*(Data_Nhập[Main SKU name_GOM]=$A6)*(Data_Nhập[SKU name_NHẬP_GOM]=GV$3)))} -> 0 | GW6: {=IF(GW$2="FY",SUMPRODUCT(Data_Nhập[Tổng Nhập-NX]*(Data_Nhập[Year]=GW$1)*(Data_Nhập[Main SKU name_GOM]=$A6)*(Data_Nhập[SKU name_NHẬP_GOM]=GW$3)),SUMPRODUCT(Data_Nhập[Tổng Nhập-NX]*(Data_Nhập[Year]=GW$1)*(Data_Nhập[Month]=GW$2)*(Data_Nhập[Main SKU name_GOM]=$A6)*(Data_Nhập[SKU name_NHẬP_GOM]=GW$3)))} -> 0 | GX6: {=IF(GX$2="FY",SUMPRODUCT(Data_Nhập[Tổng Nhập-NX]*(Data_Nhập[Year]=GX$1)*(Data_Nhập[Main SKU name_GOM]=$A6)*(Data_Nhập[SKU name_NHẬP_GOM]=GX$3)),SUMPRODUCT(Data_Nhập[Tổng Nhập-NX]*(Data_Nhập[Year]=GX$1)*(Data_Nhập[Month]=GX$2)*(Data_Nhập[Main SKU name_GOM]=$A6)*(Data_Nhập[SKU name_NHẬP_GOM]=GX$3)))} -> 0 | GY6: {=IF(GY$2="FY",SUMPRODUCT(Data_Nhập[Tổng Nhập-NX]*(Data_Nhập[Year]=GY$1)*(Data_Nhập[Main SKU name_GOM]=$A6)*(Data_Nhập[SKU name_NHẬP_GOM]=GY$3)),SUMPRODUCT(Data_Nhập[Tổng Nhập-NX]*(Data_Nhập[Year]=GY$1)*(Data_Nhập[Month]=GY$2)*(Data_Nhập[Main SKU name_GOM]=$A6)*(Data_Nhập[SKU name_NHẬP_GOM]=GY$3)))} -> 0 | GZ6: {=IF(GZ$2="FY",SUMPRODUCT(Data_Nhập[Tổng Nhập-NX]*(Data_Nhập[Year]=GZ$1)*(Data_Nhập[Main SKU name_GOM]=$A6)*(Data_Nhập[SKU name_NHẬP_GOM]=GZ$3)),SUMPRODUCT(Data_Nhập[Tổng Nhập-NX]*(Data_Nhập[Year]=GZ$1)*(Data_Nhập[Month]=GZ$2)*(Data_Nhập[Main SKU name_GOM]=$A6)*(Data_Nhập[SKU name_NHẬP_GOM]=GZ$3)))} -> 0 | HA6: {=IF(HA$2="FY",SUMPRODUCT(Data_Nhập[Tổng Nhập-NX]*(Data_Nhập[Year]=HA$1)*(Data_Nhập[Main SKU name_GOM]=$A6)*(Data_Nhập[SKU name_NHẬP_GOM]=HA$3)),SUMPRODUCT(Data_Nhập[Tổng Nhập-NX]*(Data_Nhập[Year]=HA$1)*(Data_Nhập[Month]=HA$2)*(Data_Nhập[Main SKU name_GOM]=$A6)*(Data_Nhập[SKU name_NHẬP_GOM]=HA$3)))} -> 0 | HB6: {=IF(HB$2="FY",SUMPRODUCT(Data_Nhập[Tổng Nhập-NX]*(Data_Nhập[Year]=HB$1)*(Data_Nhập[Main SKU name_GOM]=$A6)*(Data_Nhập[SKU name_NHẬP_GOM]=HB$3)),SUMPRODUCT(Data_Nhập[Tổng Nhập-NX]*(Data_Nhập[Year]=HB$1)*(Data_Nhập[Month]=HB$2)*(Data_Nhập[Main SKU name_GOM]=$A6)*(Data_Nhập[SKU name_NHẬP_GOM]=HB$3)))} -> 0 | ... HI6: {=IF(HI$2="FY",SUMPRODUCT(Data_Nhập[Tổng Nhập-NX]*(Data_Nhập[Year]=HI$1)*(Data_Nhập[Main SKU name_GOM]=$A6)*(Data_Nhập[SKU name_NHẬP_GOM]=HI$3)),SUMPRODUCT(Data_Nhập[Tổng Nhập-NX]*(Data_Nhập[Year]=HI$1)*(Data_Nhập[Month]=HI$2)*(Data_Nhập[Main SKU name_GOM]=$A6)*(Data_Nhập[SKU name_NHẬP_GOM]=HI$3)))} -> 0 | HJ6: =SUM(GU6:HI6) -> 0 | HL6: {=IF(HL$2="FY",SUMPRODUCT(Data_Xuất[Xuất-NX]*(Data_Xuất[Year]=HL$1)*(Data_Xuất[Main SKU name_GOM]=$A6)),SUMPRODUCT(Data_Xuất[Xuất-NX]*(Data_Xuất[Year]=HL$1)*(Data_Xuất[Main SKU name_GOM]=$A6)*(Data_Xuất[Month]=HL$2)))} -> 0 | HM6: {=IF(HM$2="FY",SUMPRODUCT(Data_Nhập[Tổng Nhập-NX]*(Data_Nhập[Year]=HM$1)*(Data_Nhập[Main SKU name_GOM]=$A6)*(Data_Nhập[SKU name_NHẬP_GOM]=HM$3)),SUMPRODUCT(Data_Nhập[Tổng Nhập-NX]*(Data_Nhập[Year]=HM$1)*(Data_Nhập[Month]=HM$2)*(Data_Nhập[Main SKU name_GOM]=$A6)*(Data_Nhập[SKU name_NHẬP_GOM]=HM$3)))} -> 0 | HN6: {=IF(HN$2="FY",SUMPRODUCT(Data_Nhập[Tổng Nhập-NX]*(Data_Nhập[Year]=HN$1)*(Data_Nhập[Main SKU name_GOM]=$A6)*(Data_Nhập[SKU name_NHẬP_GOM]=HN$3)),SUMPRODUCT(Data_Nhập[Tổng Nhập-NX]*(Data_Nhập[Year]=HN$1)*(Data_Nhập[Month]=HN$2)*(Data_Nhập[Main SKU name_GOM]=$A6)*(Data_Nhập[SKU name_NHẬP_GOM]=HN$3)))} -> 0 | HO6: {=IF(HO$2="FY",SUMPRODUCT(Data_Nhập[Tổng Nhập-NX]*(Data_Nhập[Year]=HO$1)*(Data_Nhập[Main SKU name_GOM]=$A6)*(Data_Nhập[SKU name_NHẬP_GOM]=HO$3)),SUMPRODUCT(Data_Nhập[Tổng Nhập-NX]*(Data_Nhập[Year]=HO$1)*(Data_Nhập[Month]=HO$2)*(Data_Nhập[Main SKU name_GOM]=$A6)*(Data_Nhập[SKU name_NHẬP_GOM]=HO$3)))} -> 0 | HP6: {=IF(HP$2="FY",SUMPRODUCT(Data_Nhập[Tổng Nhập-NX]*(Data_Nhập[Year]=HP$1)*(Data_Nhập[Main SKU name_GOM]=$A6)*(Data_Nhập[SKU name_NHẬP_GOM]=HP$3)),SUMPRODUCT(Data_Nhập[Tổng Nhập-NX]*(Data_Nhập[Year]=HP$1)*(Data_Nhập[Month]=HP$2)*(Data_Nhập[Main SKU name_GOM]=$A6)*(Data_Nhập[SKU name_NHẬP_GOM]=HP$3)))} -> 0 | HQ6: {=IF(HQ$2="FY",SUMPRODUCT(Data_Nhập[Tổng Nhập-NX]*(Data_Nhập[Year]=HQ$1)*(Data_Nhập[Main SKU name_GOM]=$A6)*(Data_Nhập[SKU name_NHẬP_GOM]=HQ$3)),SUMPRODUCT(Data_Nhập[Tổng Nhập-NX]*(Data_Nhập[Year]=HQ$1)*(Data_Nhập[Month]=HQ$2)*(Data_Nhập[Main SKU name_GOM]=$A6)*(Data_Nhập[SKU name_NHẬP_GOM]=HQ$3)))} -> 0 | HR6: {=IF(HR$2="FY",SUMPRODUCT(Data_Nhập[Tổng Nhập-NX]*(Data_Nhập[Year]=HR$1)*(Data_Nhập[Main SKU name_GOM]=$A6)*(Data_Nhập[SKU name_NHẬP_GOM]=HR$3)),SUMPRODUCT(Data_Nhập[Tổng Nhập-NX]*(Data_Nhập[Year]=HR$1)*(Data_Nhập[Month]=HR$2)*(Data_Nhập[Main SKU name_GOM]=$A6)*(Data_Nhập[SKU name_NHẬP_GOM]=HR$3)))} -> 0 | HS6: {=IF(HS$2="FY",SUMPRODUCT(Data_Nhập[Tổng Nhập-NX]*(Data_Nhập[Year]=HS$1)*(Data_Nhập[Main SKU name_GOM]=$A6)*(Data_Nhập[SKU name_NHẬP_GOM]=HS$3)),SUMPRODUCT(Data_Nhập[Tổng Nhập-NX]*(Data_Nhập[Year]=HS$1)*(Data_Nhập[Month]=HS$2)*(Data_Nhập[Main SKU name_GOM]=$A6)*(Data_Nhập[SKU name_NHẬP_GOM]=HS$3)))} -> 0 | HT6: {=IF(HT$2="FY",SUMPRODUCT(Data_Nhập[Tổng Nhập-NX]*(Data_Nhập[Year]=HT$1)*(Data_Nhập[Main SKU name_GOM]=$A6)*(Data_Nhập[SKU name_NHẬP_GOM]=HT$3)),SUMPRODUCT(Data_Nhập[Tổng Nhập-NX]*(Data_Nhập[Year]=HT$1)*(Data_Nhập[Month]=HT$2)*(Data_Nhập[Main SKU name_GOM]=$A6)*(Data_Nhập[SKU name_NHẬP_GOM]=HT$3)))} -> 0 | ... IA6: {=IF(IA$2="FY",SUMPRODUCT(Data_Nhập[Tổng Nhập-NX]*(Data_Nhập[Year]=IA$1)*(Data_Nhập[Main SKU name_GOM]=$A6)*(Data_Nhập[SKU name_NHẬP_GOM]=IA$3)),SUMPRODUCT(Data_Nhập[Tổng Nhập-NX]*(Data_Nhập[Year]=IA$1)*(Data_Nhập[Month]=IA$2)*(Data_Nhập[Main SKU name_GOM]=$A6)*(Data_Nhập[SKU name_NHẬP_GOM]=IA$3)))} -> 0 | IB6: =SUM(HM6:IA6) -> 0
