Workbook

Sheet 2024-2026
D1: 2026 | E1: 2026 | F1: 2026 | G1: 2026 | H1: 2026 | I1: 2026 | J1: 2026 | K1: 2026 | L1: 2026 | M1: 2026 | N1: 2026 | O1: 2026 | P1: 2026 | Q1: 2026 | R1: 2026 | S1: 2026 | T1: 2026 | V1: 2026 | W1: 2026 | X1: 2026 | Y1: 2026 | Z1: 2026 | AA1: 2026 | AB1: 2026 | AC1: 2026 | AD1: 2026 | AE1: 2026 | AF1: 2026 | AG1: 2026 | AH1: 2026 | AI1: 2026 | AJ1: 2026 | AK1: 2026 | AN1: 2026 | AO1: 2026 | AP1: 2026 | AQ1: 2026 | AR1: 2026 | AS1: 2026 | AT1: 2026 | AU1: 2026 | AV1: 2026 | AW1: 2026 | AX1: 2026 | AY1: 2026 | AZ1: 2026 | BA1: 2026 | BB1: 2026 | BC1: 2026 | BF1: 2026 | BG1: 2026 | BH1: 2026 | BI1: 2026 | BJ1: 2026 | BK1: 2026 | BL1: 2026 | BM1: 2026 | BN1: 2026 | BO1: 2026 | BP1: 2026 | BQ1: 2026 | BR1: 2026 | BS1: 2026 | BT1: 2026 | BU1: 2026 | BX1: 2026 | BY1: 2026 | BZ1: 2026 | CA1: 2026 | CB1: 2026 | CC1: 2026 | CD1: 2026 | CE1: 2026 | CF1: 2026 | CG1: 2026 | CH1: 2026 | CI1: 2026 | CJ1: 2026 | CK1: 2026 | CL1: 2026 | CM1: 2026 | CP1: 2026 | CQ1: 2026 | CR1: 2026 | CS1: 2026 | CT1: 2026 | CU1: 2026 | CV1: 2026 | CW1: 2026 | CX1: 2026 | CY1: 2026 | CZ1: 2026 | DA1: 2026 | DB1: 2026 | DC1: 2026 | DD1: 2026 | DE1: 2026 | DH1: 2026 | DI1: 2026 | DJ1: 2026 | DK1: 2026 | DL1: 2026 | DM1: 2026 | DN1: 2026 | DO1: 2026 | DP1: 2026 | DQ1: 2026 | DR1: 2026 | DS1: 2026 | DT1: 2026 | DU1: 2026 | DV1: 2026 | DW1: 2026 | DZ1: 2026 | EA1: 2026 | EB1: 2026 | EC1: 2026 | ED1: 2026 | EE1: 2026 | EF1: 2026 | EG1: 2026 | EH1: 2026 | EI1: 2026 | EJ1: 2026 | EK1: 2026 | EL1: 2026 | EM1: 2026 | EN1: 2026 | EO1: 2026 | ER1: 2026 | ES1: 2026 | ET1: 2026 | EU1: 2026 | EV1: 2026 | EW1: 2026 | EX1: 2026 | EY1: 2026 | EZ1: 2026 | FA1: 2026 | FB1: 2026 | FC1: 2026 | FD1: 2026 | FE1: 2026 | FF1: 2026 | FG1: 2026 | FJ1: 2026 | FK1: 2026 | FL1: 2026 | FM1: 2026 | FN1: 2026 | FO1: 2026 | FP1: 2026 | FQ1: 2026 | FR1: 2026 | FS1: 2026 | FT1: 2026 | FU1: 2026 | FV1: 2026 | FW1: 2026 | FX1: 2026 | FY1: 2026 | GB1: 2026 | GC1: 2026 | GD1: 2026 | GE1: 2026 | GF1: 2026 | GG1: 2026 | GH1: 2026 | GI1: 2026 | GJ1: 2026 | GK1: 2026 | GL1: 2026 | GM1: 2026 | GN1: 2026 | GO1: 2026 | GP1: 2026 | GQ1: 2026 | GT1: 2026 | GU1: 2026 | GV1: 2026 | GW1: 2026 | GX1: 2026 | GY1: 2026 | GZ1: 2026 | HA1: 2026 | HB1: 2026 | HC1: 2026 | HD1: 2026 | HE1: 2026 | HF1: 2026 | HG1: 2026 | HH1: 2026 | HI1: 2026 | HL1: 2026 | HM1: 2026 | HN1: 2026 | HO1: 2026 | HP1: 2026 | HQ1: 2026 | HR1: 2026 | HS1: 2026 | HT1: 2026 | HU1: 2026 | HV1: 2026 | HW1: 2026 | HX1: 2026 | HY1: 2026 | HZ1: 2026 | IA1: 2026
D2: FY | E2: FY | F2: FY | G2: FY | H2: FY | I2: FY | J2: FY | K2: FY | L2: FY | M2: FY | N2: FY | O2: FY | P2: FY | Q2: FY | R2: FY | S2: FY | T2: FY | V2: 1 | W2: 1 | X2: =W2 -> 1 | Y2: =X2 -> 1 | Z2: =Y2 -> 1 | AA2: =Z2 -> 1 | AB2: =AA2 -> 1 | AC2: =AB2 -> 1 | AD2: =AC2 -> 1 | AE2: =AD2 -> 1 | ... AK2: =AJ2 -> 1 | AN2: =V2+1 -> 2 | AO2: =AN2 -> 2 | AP2: =AO2 -> 2 | AQ2: =AP2 -> 2 | AR2: =AQ2 -> 2 | AS2: =AR2 -> 2 | AT2: =AS2 -> 2 | AU2: =AT2 -> 2 | AV2: =AU2 -> 2 | ... BC2: =BB2 -> 2 | BF2: =AN2+1 -> 3 | BG2: =BF2 -> 3 | BH2: =BG2 -> 3 | BI2: =BH2 -> 3 | BJ2: =BI2 -> 3 | BK2: =BJ2 -> 3 | BL2: =BK2 -> 3 | BM2: =BL2 -> 3 | BN2: =BM2 -> 3 | ... BU2: =BT2 -> 3 | BX2: =BF2+1 -> 4 | BY2: =BX2 -> 4 | BZ2: =BY2 -> 4 | CA2: =BZ2 -> 4 | CB2: =CA2 -> 4 | CC2: =CB2 -> 4 | CD2: =CC2 -> 4 | CE2: =CD2 -> 4 | CF2: =CE2 -> 4 | ... CM2: =CL2 -> 4 | CP2: =BX2+1 -> 5 | CQ2: =CP2 -> 5 | CR2: =CQ2 -> 5 | CS2: =CR2 -> 5 | CT2: =CS2 -> 5 | CU2: =CT2 -> 5 | CV2: =CU2 -> 5 | CW2: =CV2 -> 5 | CX2: =CW2 -> 5 | ... DE2: =DD2 -> 5 | DH2: =CP2+1 -> 6 | DI2: =DH2 -> 6 | DJ2: =DI2 -> 6 | DK2: =DJ2 -> 6 | DL2: =DK2 -> 6 | DM2: =DL2 -> 6 | DN2: =DM2 -> 6 | DO2: =DN2 -> 6 | DP2: =DO2 -> 6 | ... DW2: =DV2 -> 6 | DZ2: =DH2+1 -> 7 | EA2: =DZ2 -> 7 | EB2: =EA2 -> 7 | EC2: =EB2 -> 7 | ED2: =EC2 -> 7 | EE2: =ED2 -> 7 | EF2: =EE2 -> 7 | EG2: =EF2 -> 7 | EH2: =EG2 -> 7 | ... EO2: =EN2 -> 7 | ER2: =DZ2+1 -> 8 | ES2: =ER2 -> 8 | ET2: =ES2 -> 8 | EU2: =ET2 -> 8 | EV2: =EU2 -> 8 | EW2: =EV2 -> 8 | EX2: =EW2 -> 8 | EY2: =EX2 -> 8 | EZ2: =EY2 -> 8 | ... FG2: =FF2 -> 8 | FJ2: =ER2+1 -> 9 | FK2: =FJ2 -> 9 | FL2: =FK2 -> 9 | FM2: =FL2 -> 9 | FN2: =FM2 -> 9 | FO2: =FN2 -> 9 | FP2: =FO2 -> 9 | FQ2: =FP2 -> 9 | FR2: =FQ2 -> 9 | ... FY2: =FX2 -> 9 | GB2: =FJ2+1 -> 10 | GC2: =GB2 -> 10 | GD2: =GC2 -> 10 | GE2: =GD2 -> 10 | GF2: =GE2 -> 10 | GG2: =GF2 -> 10 | GH2: =GG2 -> 10 | GI2: =GH2 -> 10 | GJ2: =GI2 -> 10 | ... GQ2: =GP2 -> 10 | GT2: =GB2+1 -> 11 | GU2: =GT2 -> 11 | GV2: =GU2 -> 11 | GW2: =GV2 -> 11 | GX2: =GW2 -> 11 | GY2: =GX2 -> 11 | GZ2: =GY2 -> 11 | HA2: =GZ2 -> 11 | HB2: =HA2 -> 11 | ... HI2: =HH2 -> 11 | HL2: =GT2+1 -> 12 | HM2: =HL2 -> 12 | HN2: =HM2 -> 12 | HO2: =HN2 -> 12 | HP2: =HO2 -> 12 | HQ2: =HP2 -> 12 | HR2: =HQ2 -> 12 | HS2: =HR2 -> 12 | HT2: =HS2 -> 12 | ... IA2: =HZ2 -> 12
E3: iSS01084 | F3: iSS01 | G3: WSS01 | H3: WSS02 | I3: WSS03 | J3: WSS04 | K3: WSS05 | L3: WSS06 | M3: iSS01084-PL | N3: iSS01-PL | O3: WSS01-PL | P3: WSS03-PL | Q3: WSS05 PL | R3: Phó sản | S3: Khác | W3: iSS01084 | X3: iSS01 | Y3: WSS01 | Z3: WSS02 | AA3: WSS03 | AB3: WSS04 | AC3: WSS05 | AD3: WSS06 | AE3: iSS01084-PL | AF3: iSS01-PL | AG3: WSS01-PL | AH3: WSS03-PL | AI3: WSS05 PL | AJ3: Phó sản | AK3: Khác | AO3: iSS01084 | AP3: iSS01 | AQ3: WSS01 | AR3: WSS02 | AS3: WSS03 | AT3: WSS04 | AU3: WSS05 | AV3: WSS06 | AW3: iSS01084-PL | AX3: iSS01-PL | AY3: WSS01-PL | AZ3: WSS03-PL | BA3: WSS05 PL | BB3: Phó sản | BC3: Khác | BG3: iSS01084 | BH3: iSS01 | BI3: WSS01 | BJ3: WSS02 | BK3: WSS03 | BL3: WSS04 | BM3: WSS05 | BN3: WSS06 | BO3: iSS01084-PL | BP3: iSS01-PL | BQ3: WSS01-PL | BR3: WSS03-PL | BS3: WSS05 PL | BT3: Phó sản | BU3: Khác | BY3: iSS01084 | BZ3: iSS01 | CA3: WSS01 | CB3: WSS02 | CC3: WSS03 | CD3: WSS04 | CE3: WSS05 | CF3: WSS06 | CG3: iSS01084-PL | CH3: iSS01-PL | CI3: WSS01-PL | CJ3: WSS03-PL | CK3: WSS05 PL | CL3: Phó sản | CM3: Khác | CQ3: iSS01084 | CR3: iSS01 | CS3: WSS01 | CT3: WSS02 | CU3: WSS03 | CV3: WSS04 | CW3: WSS05 | CX3: WSS06 | CY3: iSS01084-PL | CZ3: iSS01-PL | DA3: WSS01-PL | DB3: WSS03-PL | DC3: WSS05 PL | DD3: Phó sản | DE3: Khác | DI3: iSS01084 | DJ3: iSS01 | DK3: WSS01 | DL3: WSS02 | DM3: WSS03 | DN3: WSS04 | DO3: WSS05 | DP3: WSS06 | DQ3: iSS01084-PL | DR3: iSS01-PL | DS3: WSS01-PL | DT3: WSS03-PL | DU3: WSS05 PL | DV3: Phó sản | DW3: Khác | EA3: iSS01084 | EB3: iSS01 | EC3: WSS01 | ED3: WSS02 | EE3: WSS03 | EF3: WSS04 | EG3: WSS05 | EH3: WSS06 | EI3: iSS01084-PL | EJ3: iSS01-PL | EK3: WSS01-PL | EL3: WSS03-PL | EM3: WSS05 PL | EN3: Phó sản | EO3: Khác | ES3: iSS01084 | ET3: iSS01 | EU3: WSS01 | EV3: WSS02 | EW3: WSS03 | EX3: WSS04 | EY3: WSS05 | EZ3: WSS06 | FA3: iSS01084-PL | FB3: iSS01-PL | FC3: WSS01-PL | FD3: WSS03-PL | FE3: WSS05 PL | FF3: Phó sản | FG3: Khác | FK3: iSS01084 | FL3: iSS01 | FM3: WSS01 | FN3: WSS02 | FO3: WSS03 | FP3: WSS04 | FQ3: WSS05 | FR3: WSS06 | FS3: iSS01084-PL | FT3: iSS01-PL | FU3: WSS01-PL | FV3: WSS03-PL | FW3: WSS05 PL | FX3: Phó sản | FY3: Khác | GC3: iSS01084 | GD3: iSS01 | GE3: WSS01 | GF3: WSS02 | GG3: WSS03 | GH3: WSS04 | GI3: WSS05 | GJ3: WSS06 | GK3: iSS01084-PL | GL3: iSS01-PL | GM3: WSS01-PL | GN3: WSS03-PL | GO3: WSS05 PL | GP3: Phó sản | GQ3: Khác | GU3: iSS01084 | GV3: iSS01 | GW3: WSS01 | GX3: WSS02 | GY3: WSS03 | GZ3: WSS04 | HA3: WSS05 | HB3: WSS06 | HC3: iSS01084-PL | HD3: iSS01-PL | HE3: WSS01-PL | HF3: WSS03-PL | HG3: WSS05 PL | HH3: Phó sản | HI3: Khác | HM3: iSS01084 | HN3: iSS01 | HO3: WSS01 | HP3: WSS02 | HQ3: WSS03 | HR3: WSS04 | HS3: WSS05 | HT3: WSS06 | HU3: iSS01084-PL | HV3: iSS01-PL | HW3: WSS01-PL | HX3: WSS03-PL | HY3: WSS05 PL | HZ3: Phó sản | IA3: Khác
B4: Main SKU name (Đvt: tấn) | D4: NĂM 2026-THU HỒI | V4: ="THÁNG "&W2&"-THU HỒI" -> THÁNG 1-THU HỒI | AN4: ="THÁNG "&AO2&"-THU HỒI" -> THÁNG 2-THU HỒI | BF4: ="THÁNG "&BG2&"-THU HỒI" -> THÁNG 3-THU HỒI | BX4: ="THÁNG "&BY2&"-THU HỒI" -> THÁNG 4-THU HỒI | CP4: ="THÁNG "&CQ2&"-THU HỒI" -> THÁNG 5-THU HỒI | DH4: ="THÁNG "&DI2&"-THU HỒI" -> THÁNG 6-THU HỒI | DZ4: ="THÁNG "&EA2&"-THU HỒI" -> THÁNG 7-THU HỒI | ER4: ="THÁNG "&ES2&"-THU HỒI" -> THÁNG 8-THU HỒI | FJ4: ="THÁNG "&FK2&"-THU HỒI" -> THÁNG 9-THU HỒI | GB4: ="THÁNG "&GC2&"-THU HỒI" -> THÁNG 10-THU HỒI | GT4: ="THÁNG "&GU2&"-THU HỒI" -> THÁNG 11-THU HỒI | HL4: ="THÁNG "&HM2&"-THU HỒI" -> THÁNG 12-THU HỒI
D5: TỔNG-XUẤT | E5: iSS01084 | F5: iSS01 | G5: WSS01 | H5: WSS02 | I5: WSS03 | J5: WSS04 | K5: WSS05 | L5: WSS06 | M5: iSS01084-PL | N5: iSS01-PL | O5: WSS01-PL | P5: WSS03-PL | Q5: WSS05 PL | R5: Phó sản | S5: Khác | T5: TỔNG-NHẬP | V5: TỔNG-XUẤT | W5: iSS01084 | X5: iSS01 | Y5: WSS01 | Z5: WSS02 | AA5: WSS03 | AB5: WSS04 | AC5: WSS05 | AD5: WSS06 | AE5: iSS01084-PL | AF5: iSS01-PL | AG5: WSS01-PL | AH5: WSS03-PL | AI5: WSS05 PL | AJ5: Phó sản | AK5: Khác | AL5: TỔNG-NHẬP | AN5: TỔNG-XUẤT | AO5: iSS01084 | AP5: iSS01 | AQ5: WSS01 | AR5: WSS02 | AS5: WSS03 | AT5: WSS04 | AU5: WSS05 | AV5: WSS06 | AW5: iSS01084-PL | AX5: iSS01-PL | AY5: WSS01-PL | AZ5: WSS03-PL | BA5: WSS05 PL | BB5: Phó sản | BC5: Khác | BD5: TỔNG-NHẬP | BF5: TỔNG-XUẤT | BG5: iSS01084 | BH5: iSS01 | BI5: WSS01 | BJ5: WSS02 | BK5: WSS03 | BL5: WSS04 | BM5: WSS05 | BN5: WSS06 | BO5: iSS01084-PL | BP5: iSS01-PL | BQ5: WSS01-PL | BR5: WSS03-PL | BS5: WSS05 PL | BT5: Phó sản | BU5: Khác | BV5: TỔNG-NHẬP | BX5: TỔNG-XUẤT | BY5: iSS01084 | BZ5: iSS01 | CA5: WSS01 | CB5: WSS02 | CC5: WSS03 | CD5: WSS04 | CE5: WSS05 | CF5: WSS06 | CG5: iSS01084-PL | CH5: iSS01-PL | CI5: WSS01-PL | CJ5: WSS03-PL | CK5: WSS05 PL | CL5: Phó sản | CM5: Khác | CN5: TỔNG-NHẬP | CP5: TỔNG-XUẤT | CQ5: iSS01084 | CR5: iSS01 | CS5: WSS01 | CT5: WSS02 | CU5: WSS03 | CV5: WSS04 | CW5: WSS05 | CX5: WSS06 | CY5: iSS01084-PL | CZ5: iSS01-PL | DA5: WSS01-PL | DB5: WSS03-PL | DC5: WSS05 PL | DD5: Phó sản | DE5: Khác | DF5: TỔNG-NHẬP | DH5: TỔNG-XUẤT | DI5: iSS01084 | DJ5: iSS01 | DK5: WSS01 | DL5: WSS02 | DM5: WSS03 | DN5: WSS04 | DO5: WSS05 | DP5: WSS06 | DQ5: iSS01084-PL | DR5: iSS01-PL | DS5: WSS01-PL | DT5: WSS03-PL | DU5: WSS05 PL | DV5: Phó sản | DW5: Khác | DX5: TỔNG-NHẬP | DZ5: TỔNG-XUẤT | EA5: iSS01084 | EB5: iSS01 | EC5: WSS01 | ED5: WSS02 | EE5: WSS03 | EF5: WSS04 | EG5: WSS05 | EH5: WSS06 | EI5: iSS01084-PL | EJ5: iSS01-PL | EK5: WSS01-PL | EL5: WSS03-PL | EM5: WSS05 PL | EN5: Phó sản | EO5: Khác | EP5: TỔNG-NHẬP | ER5: TỔNG-XUẤT | ES5: iSS01084 | ET5: iSS01 | EU5: WSS01 | EV5: WSS02 | EW5: WSS03 | EX5: WSS04 | EY5: WSS05 | EZ5: WSS06 | FA5: iSS01084-PL | FB5: iSS01-PL | FC5: WSS01-PL | FD5: WSS03-PL | FE5: WSS05 PL | FF5: Phó sản | FG5: Khác | FH5: TỔNG-NHẬP | FJ5: TỔNG-XUẤT | FK5: iSS01084 | FL5: iSS01 | FM5: WSS01 | FN5: WSS02 | FO5: WSS03 | FP5: WSS04 | FQ5: WSS05 | FR5: WSS06 | FS5: iSS01084-PL | FT5: iSS01-PL | FU5: WSS01-PL | FV5: WSS03-PL | FW5: WSS05 PL | FX5: Phó sản | FY5: Khác | FZ5: TỔNG-NHẬP | GB5: TỔNG-XUẤT | GC5: iSS01084 | GD5: iSS01 | GE5: WSS01 | GF5: WSS02 | GG5: WSS03 | GH5: WSS04 | GI5: WSS05 | GJ5: WSS06 | GK5: iSS01084-PL | GL5: iSS01-PL | GM5: WSS01-PL | GN5: WSS03-PL | GO5: WSS05 PL | GP5: Phó sản | GQ5: Khác | GR5: TỔNG-NHẬP | GT5: TỔNG-XUẤT | GU5: iSS01084 | GV5: iSS01 | GW5: WSS01 | GX5: WSS02 | GY5: WSS03 | GZ5: WSS04 | HA5: WSS05 | HB5: WSS06 | HC5: iSS01084-PL | HD5: iSS01-PL | HE5: WSS01-PL | HF5: WSS03-PL | HG5: WSS05 PL | HH5: Phó sản | HI5: Khác | HJ5: TỔNG-NHẬP | HL5: TỔNG-XUẤT | HM5: iSS01084 | HN5: iSS01 | HO5: WSS01 | HP5: WSS02 | HQ5: WSS03 | HR5: WSS04 | HS5: WSS05 | HT5: WSS06 | HU5: iSS01084-PL | HV5: iSS01-PL | HW5: WSS01-PL | HX5: WSS03-PL | HY5: WSS05 PL | HZ5: Phó sản | IA5: Khác | IB5: TỔNG-NHẬP
A6: iSS01084 | B6: iSS01084 | D6: =SUM('2026:2024'!D6) -> 15928682 | E6: =SUM('2026:2024'!E6) -> 13340733 | F6: =SUM('2026:2024'!F6) -> 603400 | G6: =SUM('2026:2024'!G6) -> 199061 | H6: =SUM('2026:2024'!H6) -> 17600 | I6: =SUM('2026:2024'!I6) -> 790003.5 | J6: =SUM('2026:2024'!J6) -> 0 | K6: =SUM('2026:2024'!K6) -> 0 | ... S6: =SUM('2026:2024'!S6) -> 0 | T6: =SUM(E6:S6) -> 15793833 | V6: =SUM('2026:2024'!V6) -> 1008496 | W6: =SUM('2026:2024'!W6) -> 895498 | X6: =SUM('2026:2024'!X6) -> 17600 | Y6: =SUM('2026:2024'!Y6) -> 2161 | Z6: =SUM('2026:2024'!Z6) -> 5500 | AA6: =SUM('2026:2024'!AA6) -> 44000 | AB6: =SUM('2026:2024'!AB6) -> 0 | AC6: =SUM('2026:2024'!AC6) -> 0 | ... AK6: =SUM('2026:2024'!AK6) -> 0 | AL6: =SUM(W6:AK6) -> 1001694 | AN6: =SUM('2026:2024'!AN6) -> 1270781 | AO6: =SUM('2026:2024'!AO6) -> 1067133 | AP6: =SUM('2026:2024'!AP6) -> 64900 | AQ6: =SUM('2026:2024'!AQ6) -> 2200 | AR6: =SUM('2026:2024'!AR6) -> 6600 | AS6: =SUM('2026:2024'!AS6) -> 57200 | AT6: =SUM('2026:2024'!AT6) -> 0 | AU6: =SUM('2026:2024'!AU6) -> 0 | ... BC6: =SUM('2026:2024'!BC6) -> 0 | BD6: =SUM(AO6:BC6) -> 1261861 | BF6: =SUM('2026:2024'!BF6) -> 714030 | BG6: =SUM('2026:2024'!BG6) -> 644600 | BH6: =SUM('2026:2024'!BH6) -> 11000 | BI6: =SUM('2026:2024'!BI6) -> 1100 | BJ6: =SUM('2026:2024'!BJ6) -> 0 | BK6: =SUM('2026:2024'!BK6) -> 11000 | BL6: =SUM('2026:2024'!BL6) -> 0 | BM6: =SUM('2026:2024'!BM6) -> 0 | ... BU6: =SUM('2026:2024'!BU6) -> 0 | BV6: =SUM(BG6:BU6) -> 703885 | BX6: =SUM('2026:2024'!BX6) -> 1111086 | BY6: =SUM('2026:2024'!BY6) -> 980100 | BZ6: =SUM('2026:2024'!BZ6) -> 20900 | CA6: =SUM('2026:2024'!CA6) -> 47300 | CB6: =SUM('2026:2024'!CB6) -> 0 | CC6: =SUM('2026:2024'!CC6) -> 14300 | CD6: =SUM('2026:2024'!CD6) -> 0 | CE6: =SUM('2026:2024'!CE6) -> 0 | ... CM6: =SUM('2026:2024'!CM6) -> 0 | CN6: =SUM(BY6:CM6) -> 1094563 | CP6: =SUM('2026:2024'!CP6) -> 732096 | CQ6: =SUM('2026:2024'!CQ6) -> 526900 | CR6: =SUM('2026:2024'!CR6) -> 129800 | CS6: =SUM('2026:2024'!CS6) -> 0 | CT6: =SUM('2026:2024'!CT6) -> 4400 | CU6: =SUM('2026:2024'!CU6) -> 17600 | CV6: =SUM('2026:2024'!CV6) -> 0 | CW6: =SUM('2026:2024'!CW6) -> 0 | ... DE6: =SUM('2026:2024'!DE6) -> 0 | DF6: =SUM(CQ6:DE6) -> 727404.5 | DH6: =SUM('2026:2024'!DH6) -> 770583 | DI6: =SUM('2026:2024'!DI6) -> 669900 | DJ6: =SUM('2026:2024'!DJ6) -> 30800 | DK6: =SUM('2026:2024'!DK6) -> 0 | DL6: =SUM('2026:2024'!DL6) -> 0 | DM6: =SUM('2026:2024'!DM6) -> 7700 | DN6: =SUM('2026:2024'!DN6) -> 0 | DO6: =SUM('2026:2024'!DO6) -> 0 | ... DW6: =SUM('2026:2024'!DW6) -> 0 | DX6: =SUM(DI6:DW6) -> 760193.5 | DZ6: =SUM('2026:2024'!DZ6) -> 848454.68 | EA6: =SUM('2026:2024'!EA6) -> 657800 | EB6: =SUM('2026:2024'!EB6) -> 70400 | EC6: =SUM('2026:2024'!EC6) -> 7700 | ED6: =SUM('2026:2024'!ED6) -> 0 | EE6: =SUM('2026:2024'!EE6) -> 28600 | EF6: =SUM('2026:2024'!EF6) -> 0 | EG6: =SUM('2026:2024'!EG6) -> 0 | ... EO6: =SUM('2026:2024'!EO6) -> 0 | EP6: =SUM(EA6:EO6) -> 842958.4 | ER6: =SUM('2026:2024'!ER6) -> 1301515.9 | ES6: =SUM('2026:2024'!ES6) -> 1119800 | ET6: =SUM('2026:2024'!ET6) -> 44245 | EU6: =SUM('2026:2024'!EU6) -> 1100 | EV6: =SUM('2026:2024'!EV6) -> 0 | EW6: =SUM('2026:2024'!EW6) -> 59399 | EX6: =SUM('2026:2024'!EX6) -> 0 | EY6: =SUM('2026:2024'!EY6) -> 0 | ... FG6: =SUM('2026:2024'!FG6) -> 0 | FH6: =SUM(ES6:FG6) -> 1290208 | FJ6: =SUM('2026:2024'!FJ6) -> 1894393.7 | FK6: =SUM('2026:2024'!FK6) -> 1568600 | FL6: =SUM('2026:2024'!FL6) -> 93855 | FM6: =SUM('2026:2024'!FM6) -> 3300 | FN6: =SUM('2026:2024'!FN6) -> 0 | FO6: =SUM('2026:2024'!FO6) -> 159704.5 | FP6: =SUM('2026:2024'!FP6) -> 0 | FQ6: =SUM('2026:2024'!FQ6) -> 0 | ... FY6: =SUM('2026:2024'!FY6) -> 0 | FZ6: =SUM(FK6:FY6) -> 1887493.9 | GB6: =SUM('2026:2024'!GB6) -> 2004780 | GC6: =SUM('2026:2024'!GC6) -> 1432202 | GD6: =SUM('2026:2024'!GD6) -> 85800 | GE6: =SUM('2026:2024'!GE6) -> 105600 | GF6: =SUM('2026:2024'!GF6) -> 1100 | GG6: =SUM('2026:2024'!GG6) -> 189200 | GH6: =SUM('2026:2024'!GH6) -> 0 | GI6: =SUM('2026:2024'!GI6) -> 0 | ... GQ6: =SUM('2026:2024'!GQ6) -> 0 | GR6: =SUM(GC6:GQ6) -> 1988284.4 | GT6: =SUM('2026:2024'!GT6) -> 2202565.8 | GU6: =SUM('2026:2024'!GU6) -> 1910400 | GV6: =SUM('2026:2024'!GV6) -> 26400 | GW6: =SUM('2026:2024'!GW6) -> 12100 | GX6: =SUM('2026:2024'!GX6) -> 0 | GY6: =SUM('2026:2024'!GY6) -> 147400 | GZ6: =SUM('2026:2024'!GZ6) -> 0 | HA6: =SUM('2026:2024'!HA6) -> 0 | ... HI6: =SUM('2026:2024'!HI6) -> 0 | HJ6: =SUM(GU6:HI6) -> 2183041 | HL6: =SUM('2026:2024'!HL6) -> 2069900 | HM6: =SUM('2026:2024'!HM6) -> 1867800 | HN6: =SUM('2026:2024'!HN6) -> 7700 | HO6: =SUM('2026:2024'!HO6) -> 16500 | HP6: =SUM('2026:2024'!HP6) -> 0 | HQ6: =SUM('2026:2024'!HQ6) -> 53900 | HR6: =SUM('2026:2024'!HR6) -> 0 | HS6: =SUM('2026:2024'!HS6) -> 0 | ... IA6: =SUM('2026:2024'!IA6) -> 0 | IB6: =SUM(HM6:IA6) -> 2052246
A7: iSS01 | B7: iSS01 | D7: =SUM('2026:2024'!D7) -> 15035790 | E7: =SUM('2026:2024'!E7) -> 293538 | F7: =SUM('2026:2024'!F7) -> 12990577 | G7: =SUM('2026:2024'!G7) -> 432300 | H7: =SUM('2026:2024'!H7) -> 0 | I7: =SUM('2026:2024'!I7) -> 189276.5 | J7: =SUM('2026:2024'!J7) -> 0 | K7: =SUM('2026:2024'!K7) -> 0 | ... S7: =SUM('2026:2024'!S7) -> 3500 | T7: =SUM(E7:S7) -> 14899004 | V7: =SUM('2026:2024'!V7) -> 535000 | W7: =SUM('2026:2024'!W7) -> 8800 | X7: =SUM('2026:2024'!X7) -> 492800 | Y7: =SUM('2026:2024'!Y7) -> 2200 | Z7: =SUM('2026:2024'!Z7) -> 0 | AA7: =SUM('2026:2024'!AA7) -> 5500 | AB7: =SUM('2026:2024'!AB7) -> 0 | AC7: =SUM('2026:2024'!AC7) -> 0 | ... AK7: =SUM('2026:2024'!AK7) -> 0 | AL7: =SUM(W7:AK7) -> 530877.5 | AN7: =SUM('2026:2024'!AN7) -> 857700 | AO7: =SUM('2026:2024'!AO7) -> 1100 | AP7: =SUM('2026:2024'!AP7) -> 737440 | AQ7: =SUM('2026:2024'!AQ7) -> 6600 | AR7: =SUM('2026:2024'!AR7) -> 0 | AS7: =SUM('2026:2024'!AS7) -> 19800 | AT7: =SUM('2026:2024'!AT7) -> 0 | AU7: =SUM('2026:2024'!AU7) -> 0 | ... BC7: =SUM('2026:2024'!BC7) -> 0 | BD7: =SUM(AO7:BC7) -> 855684 | BF7: =SUM('2026:2024'!BF7) -> 2126499 | BG7: =SUM('2026:2024'!BG7) -> 11000 | BH7: =SUM('2026:2024'!BH7) -> 1915100 | BI7: =SUM('2026:2024'!BI7) -> 39600 | BJ7: =SUM('2026:2024'!BJ7) -> 0 | BK7: =SUM('2026:2024'!BK7) -> 23015 | BL7: =SUM('2026:2024'!BL7) -> 0 | BM7: =SUM('2026:2024'!BM7) -> 0 | ... BU7: =SUM('2026:2024'!BU7) -> 3500 | BV7: =SUM(BG7:BU7) -> 2111500 | BX7: =SUM('2026:2024'!BX7) -> 1737443 | BY7: =SUM('2026:2024'!BY7) -> 0 | BZ7: =SUM('2026:2024'!BZ7) -> 1502936 | CA7: =SUM('2026:2024'!CA7) -> 39600 | CB7: =SUM('2026:2024'!CB7) -> 0 | CC7: =SUM('2026:2024'!CC7) -> 12745 | CD7: =SUM('2026:2024'!CD7) -> 0 | CE7: =SUM('2026:2024'!CE7) -> 0 | ... CM7: =SUM('2026:2024'!CM7) -> 0 | CN7: =SUM(BY7:CM7) -> 1727054 | CP7: =SUM('2026:2024'!CP7) -> 1457049 | CQ7: =SUM('2026:2024'!CQ7) -> 2200 | CR7: =SUM('2026:2024'!CR7) -> 1322200 | CS7: =SUM('2026:2024'!CS7) -> 23100 | CT7: =SUM('2026:2024'!CT7) -> 0 | CU7: =SUM('2026:2024'!CU7) -> 18700 | CV7: =SUM('2026:2024'!CV7) -> 0 | CW7: =SUM('2026:2024'!CW7) -> 0 | ... DE7: =SUM('2026:2024'!DE7) -> 0 | DF7: =SUM(CQ7:DE7) -> 1438901 | DH7: =SUM('2026:2024'!DH7) -> 2115446.8 | DI7: =SUM('2026:2024'!DI7) -> 37400 | DJ7: =SUM('2026:2024'!DJ7) -> 1905200 | DK7: =SUM('2026:2024'!DK7) -> 27500 | DL7: =SUM('2026:2024'!DL7) -> 0 | DM7: =SUM('2026:2024'!DM7) -> 4400 | DN7: =SUM('2026:2024'!DN7) -> 0 | DO7: =SUM('2026:2024'!DO7) -> 0 | ... DW7: =SUM('2026:2024'!DW7) -> 0 | DX7: =SUM(DI7:DW7) -> 2084373 | DZ7: =SUM('2026:2024'!DZ7) -> 1613617.8 | EA7: =SUM('2026:2024'!EA7) -> 112200 | EB7: =SUM('2026:2024'!EB7) -> 1305700 | EC7: =SUM('2026:2024'!EC7) -> 68200 | ED7: =SUM('2026:2024'!ED7) -> 0 | EE7: =SUM('2026:2024'!EE7) -> 22000 | EF7: =SUM('2026:2024'!EF7) -> 0 | EG7: =SUM('2026:2024'!EG7) -> 0 | ... EO7: =SUM('2026:2024'!EO7) -> 0 | EP7: =SUM(EA7:EO7) -> 1597027 | ER7: =SUM('2026:2024'!ER7) -> 1403140.9 | ES7: =SUM('2026:2024'!ES7) -> 91300 | ET7: =SUM('2026:2024'!ET7) -> 1106600 | EU7: =SUM('2026:2024'!EU7) -> 69300 | EV7: =SUM('2026:2024'!EV7) -> 0 | EW7: =SUM('2026:2024'!EW7) -> 14300 | EX7: =SUM('2026:2024'!EX7) -> 0 | EY7: =SUM('2026:2024'!EY7) -> 0 | ... FG7: =SUM('2026:2024'!FG7) -> 0 | FH7: =SUM(ES7:FG7) -> 1386295 | FJ7: =SUM('2026:2024'!FJ7) -> 961238 | FK7: =SUM('2026:2024'!FK7) -> 0 | FL7: =SUM('2026:2024'!FL7) -> 847000 | FM7: =SUM('2026:2024'!FM7) -> 40700 | FN7: =SUM('2026:2024'!FN7) -> 0 | FO7: =SUM('2026:2024'!FO7) -> 13200 | FP7: =SUM('2026:2024'!FP7) -> 0 | FQ7: =SUM('2026:2024'!FQ7) -> 0 | ... FY7: =SUM('2026:2024'!FY7) -> 0 | FZ7: =SUM(FK7:FY7) -> 947732 | GB7: =SUM('2026:2024'!GB7) -> 578641.5 | GC7: =SUM('2026:2024'!GC7) -> 16338 | GD7: =SUM('2026:2024'!GD7) -> 484000 | GE7: =SUM('2026:2024'!GE7) -> 11000 | GF7: =SUM('2026:2024'!GF7) -> 0 | GG7: =SUM('2026:2024'!GG7) -> 13816.5 | GH7: =SUM('2026:2024'!GH7) -> 0 | GI7: =SUM('2026:2024'!GI7) -> 0 | ... GQ7: =SUM('2026:2024'!GQ7) -> 0 | GR7: =SUM(GC7:GQ7) -> 575612.5 | GT7: =SUM('2026:2024'!GT7) -> 1447334 | GU7: =SUM('2026:2024'!GU7) -> 13200 | GV7: =SUM('2026:2024'!GV7) -> 1211001 | GW7: =SUM('2026:2024'!GW7) -> 82500 | GX7: =SUM('2026:2024'!GX7) -> 0 | GY7: =SUM('2026:2024'!GY7) -> 41800 | GZ7: =SUM('2026:2024'!GZ7) -> 0 | HA7: =SUM('2026:2024'!HA7) -> 0 | ... HI7: =SUM('2026:2024'!HI7) -> 0 | HJ7: =SUM(GU7:HI7) -> 1442629 | HL7: =SUM('2026:2024'!HL7) -> 202680 | HM7: =SUM('2026:2024'!HM7) -> 0 | HN7: =SUM('2026:2024'!HN7) -> 160600 | HO7: =SUM('2026:2024'!HO7) -> 22000 | HP7: =SUM('2026:2024'!HP7) -> 0 | HQ7: =SUM('2026:2024'!HQ7) -> 0 | HR7: =SUM('2026:2024'!HR7) -> 0 | HS7: =SUM('2026:2024'!HS7) -> 0 | ... IA7: =SUM('2026:2024'!IA7) -> 0 | IB7: =SUM(HM7:IA7) -> 201319
A8: WSS01 | B8: WSS01 | D8: =SUM('2026:2024'!D8) -> 58251712 | E8: =SUM('2026:2024'!E8) -> 58300 | F8: =SUM('2026:2024'!F8) -> 3794120 | G8: =SUM('2026:2024'!G8) -> 48333936 | H8: =SUM('2026:2024'!H8) -> 895544 | I8: =SUM('2026:2024'!I8) -> 1775747.5 | J8: =SUM('2026:2024'!J8) -> 0 | K8: =SUM('2026:2024'!K8) -> 0 | ... S8: =SUM('2026:2024'!S8) -> 0 | T8: =SUM(E8:S8) -> 57778169 | V8: =SUM('2026:2024'!V8) -> 7368506 | W8: =SUM('2026:2024'!W8) -> 1100 | X8: =SUM('2026:2024'!X8) -> 500500 | Y8: =SUM('2026:2024'!Y8) -> 6360658 | Z8: =SUM('2026:2024'!Z8) -> 164344 | AA8: =SUM('2026:2024'!AA8) -> 44892 | AB8: =SUM('2026:2024'!AB8) -> 0 | AC8: =SUM('2026:2024'!AC8) -> 0 | ... AK8: =SUM('2026:2024'!AK8) -> 0 | AL8: =SUM(W8:AK8) -> 7313147.7 | AN8: =SUM('2026:2024'!AN8) -> 4457183.8 | AO8: =SUM('2026:2024'!AO8) -> 0 | AP8: =SUM('2026:2024'!AP8) -> 266200 | AQ8: =SUM('2026:2024'!AQ8) -> 3754482 | AR8: =SUM('2026:2024'!AR8) -> 150700 | AS8: =SUM('2026:2024'!AS8) -> 21931 | AT8: =SUM('2026:2024'!AT8) -> 0 | AU8: =SUM('2026:2024'!AU8) -> 0 | ... BC8: =SUM('2026:2024'!BC8) -> 0 | BD8: =SUM(AO8:BC8) -> 4426661 | BF8: =SUM('2026:2024'!BF8) -> 8081225 | BG8: =SUM('2026:2024'!BG8) -> 0 | BH8: =SUM('2026:2024'!BH8) -> 487300 | BI8: =SUM('2026:2024'!BI8) -> 7017929 | BJ8: =SUM('2026:2024'!BJ8) -> 118800 | BK8: =SUM('2026:2024'!BK8) -> 62700 | BL8: =SUM('2026:2024'!BL8) -> 0 | BM8: =SUM('2026:2024'!BM8) -> 0 | ... BU8: =SUM('2026:2024'!BU8) -> 0 | BV8: =SUM(BG8:BU8) -> 8026094 | BX8: =SUM('2026:2024'!BX8) -> 6517599.4 | BY8: =SUM('2026:2024'!BY8) -> 3300 | BZ8: =SUM('2026:2024'!BZ8) -> 398201 | CA8: =SUM('2026:2024'!CA8) -> 5655100 | CB8: =SUM('2026:2024'!CB8) -> 47300 | CC8: =SUM('2026:2024'!CC8) -> 69300 | CD8: =SUM('2026:2024'!CD8) -> 0 | CE8: =SUM('2026:2024'!CE8) -> 0 | ... CM8: =SUM('2026:2024'!CM8) -> 0 | CN8: =SUM(BY8:CM8) -> 6462272 | CP8: =SUM('2026:2024'!CP8) -> 6084751.1 | CQ8: =SUM('2026:2024'!CQ8) -> 0 | CR8: =SUM('2026:2024'!CR8) -> 586300 | CS8: =SUM('2026:2024'!CS8) -> 4692600 | CT8: =SUM('2026:2024'!CT8) -> 238700 | CU8: =SUM('2026:2024'!CU8) -> 286000 | CV8: =SUM('2026:2024'!CV8) -> 0 | CW8: =SUM('2026:2024'!CW8) -> 0 | ... DE8: =SUM('2026:2024'!DE8) -> 0 | DF8: =SUM(CQ8:DE8) -> 6038461.2 | DH8: =SUM('2026:2024'!DH8) -> 5594326.8 | DI8: =SUM('2026:2024'!DI8) -> 16500 | DJ8: =SUM('2026:2024'!DJ8) -> 558800 | DK8: =SUM('2026:2024'!DK8) -> 4226200 | DL8: =SUM('2026:2024'!DL8) -> 105600 | DM8: =SUM('2026:2024'!DM8) -> 390700 | DN8: =SUM('2026:2024'!DN8) -> 0 | DO8: =SUM('2026:2024'!DO8) -> 0 | ... DW8: =SUM('2026:2024'!DW8) -> 0 | DX8: =SUM(DI8:DW8) -> 5551255.4 | DZ8: =SUM('2026:2024'!DZ8) -> 2527587.9 | EA8: =SUM('2026:2024'!EA8) -> 1100 | EB8: =SUM('2026:2024'!EB8) -> 78100 | EC8: =SUM('2026:2024'!EC8) -> 2125300 | ED8: =SUM('2026:2024'!ED8) -> 3300 | EE8: =SUM('2026:2024'!EE8) -> 47000 | EF8: =SUM('2026:2024'!EF8) -> 0 | EG8: =SUM('2026:2024'!EG8) -> 0 | ... EO8: =SUM('2026:2024'!EO8) -> 0 | EP8: =SUM(EA8:EO8) -> 2494531 | ER8: =SUM('2026:2024'!ER8) -> 3456680.1 | ES8: =SUM('2026:2024'!ES8) -> 2200 | ET8: =SUM('2026:2024'!ET8) -> 214719 | EU8: =SUM('2026:2024'!EU8) -> 2836456 | EV8: =SUM('2026:2024'!EV8) -> 2200 | EW8: =SUM('2026:2024'!EW8) -> 88251 | EX8: =SUM('2026:2024'!EX8) -> 0 | EY8: =SUM('2026:2024'!EY8) -> 0 | ... FG8: =SUM('2026:2024'!FG8) -> 0 | FH8: =SUM(ES8:FG8) -> 3417228.2 | FJ8: =SUM('2026:2024'!FJ8) -> 3300896.3 | FK8: =SUM('2026:2024'!FK8) -> 9900 | FL8: =SUM('2026:2024'!FL8) -> 159500 | FM8: =SUM('2026:2024'!FM8) -> 2840201 | FN8: =SUM('2026:2024'!FN8) -> 4100 | FO8: =SUM('2026:2024'!FO8) -> 96032.5 | FP8: =SUM('2026:2024'!FP8) -> 0 | FQ8: =SUM('2026:2024'!FQ8) -> 0 | ... FY8: =SUM('2026:2024'!FY8) -> 0 | FZ8: =SUM(FK8:FY8) -> 3272454.5 | GB8: =SUM('2026:2024'!GB8) -> 4835544 | GC8: =SUM('2026:2024'!GC8) -> 12100 | GD8: =SUM('2026:2024'!GD8) -> 141900 | GE8: =SUM('2026:2024'!GE8) -> 3730910 | GF8: =SUM('2026:2024'!GF8) -> 52800 | GG8: =SUM('2026:2024'!GG8) -> 604006 | GH8: =SUM('2026:2024'!GH8) -> 0 | GI8: =SUM('2026:2024'!GI8) -> 0 | ... GQ8: =SUM('2026:2024'!GQ8) -> 0 | GR8: =SUM(GC8:GQ8) -> 4792019 | GT8: =SUM('2026:2024'!GT8) -> 2412321 | GU8: =SUM('2026:2024'!GU8) -> 0 | GV8: =SUM('2026:2024'!GV8) -> 247500 | GW8: =SUM('2026:2024'!GW8) -> 1930500 | GX8: =SUM('2026:2024'!GX8) -> 5500 | GY8: =SUM('2026:2024'!GY8) -> 30835 | GZ8: =SUM('2026:2024'!GZ8) -> 0 | HA8: =SUM('2026:2024'!HA8) -> 0 | ... HI8: =SUM('2026:2024'!HI8) -> 0 | HJ8: =SUM(GU8:HI8) -> 2400386 | HL8: =SUM('2026:2024'!HL8) -> 3615090.5 | HM8: =SUM('2026:2024'!HM8) -> 12100 | HN8: =SUM('2026:2024'!HN8) -> 155100 | HO8: =SUM('2026:2024'!HO8) -> 3163600 | HP8: =SUM('2026:2024'!HP8) -> 2200 | HQ8: =SUM('2026:2024'!HQ8) -> 34100 | HR8: =SUM('2026:2024'!HR8) -> 0 | HS8: =SUM('2026:2024'!HS8) -> 0 | ... IA8: =SUM('2026:2024'!IA8) -> 0 | IB8: =SUM(HM8:IA8) -> 3583659
A9: WSS03 | B9: WSS03 | D9: =SUM('2026:2024'!D9) -> 3382548 | E9: =SUM('2026:2024'!E9) -> 0 | F9: =SUM('2026:2024'!F9) -> 0 | G9: =SUM('2026:2024'!G9) -> 0 | H9: =SUM('2026:2024'!H9) -> 2200 | I9: =SUM('2026:2024'!I9) -> 3087891 | J9: =SUM('2026:2024'!J9) -> 0 | K9: =SUM('2026:2024'!K9) -> 6994 | ... S9: =SUM('2026:2024'!S9) -> 0 | T9: =SUM(E9:S9) -> 3342813 | V9: =SUM('2026:2024'!V9) -> 403783 | W9: =SUM('2026:2024'!W9) -> 0 | X9: =SUM('2026:2024'!X9) -> 0 | Y9: =SUM('2026:2024'!Y9) -> 0 | Z9: =SUM('2026:2024'!Z9) -> 0 | AA9: =SUM('2026:2024'!AA9) -> 376761 | AB9: =SUM('2026:2024'!AB9) -> 0 | AC9: =SUM('2026:2024'!AC9) -> 4130 | ... AK9: =SUM('2026:2024'!AK9) -> 0 | AL9: =SUM(W9:AK9) -> 397586 | AN9: =SUM('2026:2024'!AN9) -> 12600 | AO9: =SUM('2026:2024'!AO9) -> 0 | AP9: =SUM('2026:2024'!AP9) -> 0 | AQ9: =SUM('2026:2024'!AQ9) -> 0 | AR9: =SUM('2026:2024'!AR9) -> 0 | AS9: =SUM('2026:2024'!AS9) -> 5500 | AT9: =SUM('2026:2024'!AT9) -> 0 | AU9: =SUM('2026:2024'!AU9) -> 2864 | ... BC9: =SUM('2026:2024'!BC9) -> 0 | BD9: =SUM(AO9:BC9) -> 12550 | BF9: =SUM('2026:2024'!BF9) -> 713578 | BG9: =SUM('2026:2024'!BG9) -> 0 | BH9: =SUM('2026:2024'!BH9) -> 0 | BI9: =SUM('2026:2024'!BI9) -> 0 | BJ9: =SUM('2026:2024'!BJ9) -> 0 | BK9: =SUM('2026:2024'!BK9) -> 640630 | BL9: =SUM('2026:2024'!BL9) -> 0 | BM9: =SUM('2026:2024'!BM9) -> 0 | ... BU9: =SUM('2026:2024'!BU9) -> 0 | BV9: =SUM(BG9:BU9) -> 708155 | BX9: =SUM('2026:2024'!BX9) -> 1192892 | BY9: =SUM('2026:2024'!BY9) -> 0 | BZ9: =SUM('2026:2024'!BZ9) -> 0 | CA9: =SUM('2026:2024'!CA9) -> 0 | CB9: =SUM('2026:2024'!CB9) -> 0 | CC9: =SUM('2026:2024'!CC9) -> 1137400 | CD9: =SUM('2026:2024'!CD9) -> 0 | CE9: =SUM('2026:2024'!CE9) -> 0 | ... CM9: =SUM('2026:2024'!CM9) -> 0 | CN9: =SUM(BY9:CM9) -> 1178259 | CP9: =SUM('2026:2024'!CP9) -> 39600 | CQ9: =SUM('2026:2024'!CQ9) -> 0 | CR9: =SUM('2026:2024'!CR9) -> 0 | CS9: =SUM('2026:2024'!CS9) -> 0 | CT9: =SUM('2026:2024'!CT9) -> 0 | CU9: =SUM('2026:2024'!CU9) -> 39600 | CV9: =SUM('2026:2024'!CV9) -> 0 | CW9: =SUM('2026:2024'!CW9) -> 0 | ... DE9: =SUM('2026:2024'!DE9) -> 0 | DF9: =SUM(CQ9:DE9) -> 39600 | DH9: =SUM('2026:2024'!DH9) -> 1400 | DI9: =SUM('2026:2024'!DI9) -> 0 | DJ9: =SUM('2026:2024'!DJ9) -> 0 | DK9: =SUM('2026:2024'!DK9) -> 0 | DL9: =SUM('2026:2024'!DL9) -> 0 | DM9: =SUM('2026:2024'!DM9) -> 1400 | DN9: =SUM('2026:2024'!DN9) -> 0 | DO9: =SUM('2026:2024'!DO9) -> 0 | ... DW9: =SUM('2026:2024'!DW9) -> 0 | DX9: =SUM(DI9:DW9) -> 1400 | DZ9: =SUM('2026:2024'!DZ9) -> 0 | EA9: =SUM('2026:2024'!EA9) -> 0 | EB9: =SUM('2026:2024'!EB9) -> 0 | EC9: =SUM('2026:2024'!EC9) -> 0 | ED9: =SUM('2026:2024'!ED9) -> 0 | EE9: =SUM('2026:2024'!EE9) -> 0 | EF9: =SUM('2026:2024'!EF9) -> 0 | EG9: =SUM('2026:2024'!EG9) -> 0 | ... EO9: =SUM('2026:2024'!EO9) -> 0 | EP9: =SUM(EA9:EO9) -> 0 | ER9: =SUM('2026:2024'!ER9) -> 0 | ES9: =SUM('2026:2024'!ES9) -> 0 | ET9: =SUM('2026:2024'!ET9) -> 0 | EU9: =SUM('2026:2024'!EU9) -> 0 | EV9: =SUM('2026:2024'!EV9) -> 0 | EW9: =SUM('2026:2024'!EW9) -> 0 | EX9: =SUM('2026:2024'!EX9) -> 0 | EY9: =SUM('2026:2024'!EY9) -> 0 | ... FG9: =SUM('2026:2024'!FG9) -> 0 | FH9: =SUM(ES9:FG9) -> 0 | FJ9: =SUM('2026:2024'!FJ9) -> 168000 | FK9: =SUM('2026:2024'!FK9) -> 0 | FL9: =SUM('2026:2024'!FL9) -> 0 | FM9: =SUM('2026:2024'!FM9) -> 0 | FN9: =SUM('2026:2024'!FN9) -> 0 | FO9: =SUM('2026:2024'!FO9) -> 157300 | FP9: =SUM('2026:2024'!FP9) -> 0 | FQ9: =SUM('2026:2024'!FQ9) -> 0 | ... FY9: =SUM('2026:2024'!FY9) -> 0 | FZ9: =SUM(FK9:FY9) -> 165520 | GB9: =SUM('2026:2024'!GB9) -> 157250 | GC9: =SUM('2026:2024'!GC9) -> 0 | GD9: =SUM('2026:2024'!GD9) -> 0 | GE9: =SUM('2026:2024'!GE9) -> 0 | GF9: =SUM('2026:2024'!GF9) -> 0 | GG9: =SUM('2026:2024'!GG9) -> 108900 | GH9: =SUM('2026:2024'!GH9) -> 0 | GI9: =SUM('2026:2024'!GI9) -> 0 | ... GQ9: =SUM('2026:2024'!GQ9) -> 0 | GR9: =SUM(GC9:GQ9) -> 156190 | GT9: =SUM('2026:2024'!GT9) -> 105000 | GU9: =SUM('2026:2024'!GU9) -> 0 | GV9: =SUM('2026:2024'!GV9) -> 0 | GW9: =SUM('2026:2024'!GW9) -> 0 | GX9: =SUM('2026:2024'!GX9) -> 1100 | GY9: =SUM('2026:2024'!GY9) -> 93500 | GZ9: =SUM('2026:2024'!GZ9) -> 0 | HA9: =SUM('2026:2024'!HA9) -> 0 | ... HI9: =SUM('2026:2024'!HI9) -> 0 | HJ9: =SUM(GU9:HI9) -> 103700 | HL9: =SUM('2026:2024'!HL9) -> 588445 | HM9: =SUM('2026:2024'!HM9) -> 0 | HN9: =SUM('2026:2024'!HN9) -> 0 | HO9: =SUM('2026:2024'!HO9) -> 0 | HP9: =SUM('2026:2024'!HP9) -> 1100 | HQ9: =SUM('2026:2024'!HQ9) -> 526900 | HR9: =SUM('2026:2024'!HR9) -> 0 | HS9: =SUM('2026:2024'!HS9) -> 0 | ... IA9: =SUM('2026:2024'!IA9) -> 0 | IB9: =SUM(HM9:IA9) -> 579853
A10: WSS04 | B10: WSS04 | D10: =SUM('2026:2024'!D10) -> 64880 | E10: =SUM('2026:2024'!E10) -> 0 | F10: =SUM('2026:2024'!F10) -> 0 | G10: =SUM('2026:2024'!G10) -> 0 | H10: =SUM('2026:2024'!H10) -> 0 | I10: =SUM('2026:2024'!I10) -> 0 | J10: =SUM('2026:2024'!J10) -> 23818 | K10: =SUM('2026:2024'!K10) -> 29980 | ... S10: =SUM('2026:2024'!S10) -> 0 | T10: =SUM(E10:S10) -> 61824 | V10: =SUM('2026:2024'!V10) -> 16970 | W10: =SUM('2026:2024'!W10) -> 0 | X10: =SUM('2026:2024'!X10) -> 0 | Y10: =SUM('2026:2024'!Y10) -> 0 | Z10: =SUM('2026:2024'!Z10) -> 0 | AA10: =SUM('2026:2024'!AA10) -> 0 | AB10: =SUM('2026:2024'!AB10) -> 1365 | AC10: =SUM('2026:2024'!AC10) -> 11705 | ... AK10: =SUM('2026:2024'!AK10) -> 0 | AL10: =SUM(W10:AK10) -> 15110 | AN10: =SUM('2026:2024'!AN10) -> 18500 | AO10: =SUM('2026:2024'!AO10) -> 0 | AP10: =SUM('2026:2024'!AP10) -> 0 | AQ10: =SUM('2026:2024'!AQ10) -> 0 | AR10: =SUM('2026:2024'!AR10) -> 0 | AS10: =SUM('2026:2024'!AS10) -> 0 | AT10: =SUM('2026:2024'!AT10) -> 11550 | AU10: =SUM('2026:2024'!AU10) -> 4782 | ... BC10: =SUM('2026:2024'!BC10) -> 0 | BD10: =SUM(AO10:BC10) -> 17756 | BF10: =SUM('2026:2024'!BF10) -> 8500 | BG10: =SUM('2026:2024'!BG10) -> 0 | BH10: =SUM('2026:2024'!BH10) -> 0 | BI10: =SUM('2026:2024'!BI10) -> 0 | BJ10: =SUM('2026:2024'!BJ10) -> 0 | BK10: =SUM('2026:2024'!BK10) -> 0 | BL10: =SUM('2026:2024'!BL10) -> 4423 | BM10: =SUM('2026:2024'!BM10) -> 2793 | ... BU10: =SUM('2026:2024'!BU10) -> 0 | BV10: =SUM(BG10:BU10) -> 8176 | BX10: =SUM('2026:2024'!BX10) -> 1600 | BY10: =SUM('2026:2024'!BY10) -> 0 | BZ10: =SUM('2026:2024'!BZ10) -> 0 | CA10: =SUM('2026:2024'!CA10) -> 0 | CB10: =SUM('2026:2024'!CB10) -> 0 | CC10: =SUM('2026:2024'!CC10) -> 0 | CD10: =SUM('2026:2024'!CD10) -> 0 | CE10: =SUM('2026:2024'!CE10) -> 0 | ... CM10: =SUM('2026:2024'!CM10) -> 0 | CN10: =SUM(BY10:CM10) -> 1522 | CP10: =SUM('2026:2024'!CP10) -> 0 | CQ10: =SUM('2026:2024'!CQ10) -> 0 | CR10: =SUM('2026:2024'!CR10) -> 0 | CS10: =SUM('2026:2024'!CS10) -> 0 | CT10: =SUM('2026:2024'!CT10) -> 0 | CU10: =SUM('2026:2024'!CU10) -> 0 | CV10: =SUM('2026:2024'!CV10) -> 0 | CW10: =SUM('2026:2024'!CW10) -> 0 | ... DE10: =SUM('2026:2024'!DE10) -> 0 | DF10: =SUM(CQ10:DE10) -> 0 | DH10: =SUM('2026:2024'!DH10) -> 0 | DI10: =SUM('2026:2024'!DI10) -> 0 | DJ10: =SUM('2026:2024'!DJ10) -> 0 | DK10: =SUM('2026:2024'!DK10) -> 0 | DL10: =SUM('2026:2024'!DL10) -> 0 | DM10: =SUM('2026:2024'!DM10) -> 0 | DN10: =SUM('2026:2024'!DN10) -> 0 | DO10: =SUM('2026:2024'!DO10) -> 0 | ... DW10: =SUM('2026:2024'!DW10) -> 0 | DX10: =SUM(DI10:DW10) -> 0 | DZ10: =SUM('2026:2024'!DZ10) -> 0 | EA10: =SUM('2026:2024'!EA10) -> 0 | EB10: =SUM('2026:2024'!EB10) -> 0 | EC10: =SUM('2026:2024'!EC10) -> 0 | ED10: =SUM('2026:2024'!ED10) -> 0 | EE10: =SUM('2026:2024'!EE10) -> 0 | EF10: =SUM('2026:2024'!EF10) -> 0 | EG10: =SUM('2026:2024'!EG10) -> 0 | ... EO10: =SUM('2026:2024'!EO10) -> 0 | EP10: =SUM(EA10:EO10) -> 0 | ER10: =SUM('2026:2024'!ER10) -> 0 | ES10: =SUM('2026:2024'!ES10) -> 0 | ET10: =SUM('2026:2024'!ET10) -> 0 | EU10: =SUM('2026:2024'!EU10) -> 0 | EV10: =SUM('2026:2024'!EV10) -> 0 | EW10: =SUM('2026:2024'!EW10) -> 0 | EX10: =SUM('2026:2024'!EX10) -> 0 | EY10: =SUM('2026:2024'!EY10) -> 0 | ... FG10: =SUM('2026:2024'!FG10) -> 0 | FH10: =SUM(ES10:FG10) -> 0 | FJ10: =SUM('2026:2024'!FJ10) -> 8310 | FK10: =SUM('2026:2024'!FK10) -> 0 | FL10: =SUM('2026:2024'!FL10) -> 0 | FM10: =SUM('2026:2024'!FM10) -> 0 | FN10: =SUM('2026:2024'!FN10) -> 0 | FO10: =SUM('2026:2024'!FO10) -> 0 | FP10: =SUM('2026:2024'!FP10) -> 2200 | FQ10: =SUM('2026:2024'!FQ10) -> 5450 | ... FY10: =SUM('2026:2024'!FY10) -> 0 | FZ10: =SUM(FK10:FY10) -> 8310 | GB10: =SUM('2026:2024'!GB10) -> 0 | GC10: =SUM('2026:2024'!GC10) -> 0 | GD10: =SUM('2026:2024'!GD10) -> 0 | GE10: =SUM('2026:2024'!GE10) -> 0 | GF10: =SUM('2026:2024'!GF10) -> 0 | GG10: =SUM('2026:2024'!GG10) -> 0 | GH10: =SUM('2026:2024'!GH10) -> 0 | GI10: =SUM('2026:2024'!GI10) -> 0 | ... GQ10: =SUM('2026:2024'!GQ10) -> 0 | GR10: =SUM(GC10:GQ10) -> 0 | GT10: =SUM('2026:2024'!GT10) -> 7500 | GU10: =SUM('2026:2024'!GU10) -> 0 | GV10: =SUM('2026:2024'!GV10) -> 0 | GW10: =SUM('2026:2024'!GW10) -> 0 | GX10: =SUM('2026:2024'!GX10) -> 0 | GY10: =SUM('2026:2024'!GY10) -> 0 | GZ10: =SUM('2026:2024'!GZ10) -> 1850 | HA10: =SUM('2026:2024'!HA10) -> 5250 | ... HI10: =SUM('2026:2024'!HI10) -> 0 | HJ10: =SUM(GU10:HI10) -> 7450 | HL10: =SUM('2026:2024'!HL10) -> 3500 | HM10: =SUM('2026:2024'!HM10) -> 0 | HN10: =SUM('2026:2024'!HN10) -> 0 | HO10: =SUM('2026:2024'!HO10) -> 0 | HP10: =SUM('2026:2024'!HP10) -> 0 | HQ10: =SUM('2026:2024'!HQ10) -> 0 | HR10: =SUM('2026:2024'!HR10) -> 2430 | HS10: =SUM('2026:2024'!HS10) -> 0 | ... IA10: =SUM('2026:2024'!IA10) -> 0 | IB10: =SUM(HM10:IA10) -> 3500
A11: WSS05 | B11: WSS05 | D11: =SUM('2026:2024'!D11) -> 3963044 | E11: =SUM('2026:2024'!E11) -> 0 | F11: =SUM('2026:2024'!F11) -> 0 | G11: =SUM('2026:2024'!G11) -> 0 | H11: =SUM('2026:2024'!H11) -> 0 | I11: =SUM('2026:2024'!I11) -> 0 | J11: =SUM('2026:2024'!J11) -> 6300 | K11: =SUM('2026:2024'!K11) -> 3498076 | ... S11: =SUM('2026:2024'!S11) -> 0 | T11: =SUM(E11:S11) -> 3920819.5 | V11: =SUM('2026:2024'!V11) -> 206381 | W11: =SUM('2026:2024'!W11) -> 0 | X11: =SUM('2026:2024'!X11) -> 0 | Y11: =SUM('2026:2024'!Y11) -> 0 | Z11: =SUM('2026:2024'!Z11) -> 0 | AA11: =SUM('2026:2024'!AA11) -> 0 | AB11: =SUM('2026:2024'!AB11) -> 5250 | AC11: =SUM('2026:2024'!AC11) -> 142300 | ... AK11: =SUM('2026:2024'!AK11) -> 0 | AL11: =SUM(W11:AK11) -> 193255.5 | AN11: =SUM('2026:2024'!AN11) -> 256600 | AO11: =SUM('2026:2024'!AO11) -> 0 | AP11: =SUM('2026:2024'!AP11) -> 0 | AQ11: =SUM('2026:2024'!AQ11) -> 0 | AR11: =SUM('2026:2024'!AR11) -> 0 | AS11: =SUM('2026:2024'!AS11) -> 0 | AT11: =SUM('2026:2024'!AT11) -> 0 | AU11: =SUM('2026:2024'!AU11) -> 224133 | ... BC11: =SUM('2026:2024'!BC11) -> 0 | BD11: =SUM(AO11:BC11) -> 255020 | BF11: =SUM('2026:2024'!BF11) -> 474791 | BG11: =SUM('2026:2024'!BG11) -> 0 | BH11: =SUM('2026:2024'!BH11) -> 0 | BI11: =SUM('2026:2024'!BI11) -> 0 | BJ11: =SUM('2026:2024'!BJ11) -> 0 | BK11: =SUM('2026:2024'!BK11) -> 0 | BL11: =SUM('2026:2024'!BL11) -> 1050 | BM11: =SUM('2026:2024'!BM11) -> 415989 | ... BU11: =SUM('2026:2024'!BU11) -> 0 | BV11: =SUM(BG11:BU11) -> 471874 | BX11: =SUM('2026:2024'!BX11) -> 194973 | BY11: =SUM('2026:2024'!BY11) -> 0 | BZ11: =SUM('2026:2024'!BZ11) -> 0 | CA11: =SUM('2026:2024'!CA11) -> 0 | CB11: =SUM('2026:2024'!CB11) -> 0 | CC11: =SUM('2026:2024'!CC11) -> 0 | CD11: =SUM('2026:2024'!CD11) -> 0 | CE11: =SUM('2026:2024'!CE11) -> 176328 | ... CM11: =SUM('2026:2024'!CM11) -> 0 | CN11: =SUM(BY11:CM11) -> 192568 | CP11: =SUM('2026:2024'!CP11) -> 520534 | CQ11: =SUM('2026:2024'!CQ11) -> 0 | CR11: =SUM('2026:2024'!CR11) -> 0 | CS11: =SUM('2026:2024'!CS11) -> 0 | CT11: =SUM('2026:2024'!CT11) -> 0 | CU11: =SUM('2026:2024'!CU11) -> 0 | CV11: =SUM('2026:2024'!CV11) -> 0 | CW11: =SUM('2026:2024'!CW11) -> 499750 | ... DE11: =SUM('2026:2024'!DE11) -> 0 | DF11: =SUM(CQ11:DE11) -> 518460 | DH11: =SUM('2026:2024'!DH11) -> 346396 | DI11: =SUM('2026:2024'!DI11) -> 0 | DJ11: =SUM('2026:2024'!DJ11) -> 0 | DK11: =SUM('2026:2024'!DK11) -> 0 | DL11: =SUM('2026:2024'!DL11) -> 0 | DM11: =SUM('2026:2024'!DM11) -> 0 | DN11: =SUM('2026:2024'!DN11) -> 0 | DO11: =SUM('2026:2024'!DO11) -> 339408 | ... DW11: =SUM('2026:2024'!DW11) -> 0 | DX11: =SUM(DI11:DW11) -> 345564 | DZ11: =SUM('2026:2024'!DZ11) -> 583953 | EA11: =SUM('2026:2024'!EA11) -> 0 | EB11: =SUM('2026:2024'!EB11) -> 0 | EC11: =SUM('2026:2024'!EC11) -> 0 | ED11: =SUM('2026:2024'!ED11) -> 0 | EE11: =SUM('2026:2024'!EE11) -> 0 | EF11: =SUM('2026:2024'!EF11) -> 0 | EG11: =SUM('2026:2024'!EG11) -> 514889 | ... EO11: =SUM('2026:2024'!EO11) -> 0 | EP11: =SUM(EA11:EO11) -> 580343 | ER11: =SUM('2026:2024'!ER11) -> 326514 | ES11: =SUM('2026:2024'!ES11) -> 0 | ET11: =SUM('2026:2024'!ET11) -> 0 | EU11: =SUM('2026:2024'!EU11) -> 0 | EV11: =SUM('2026:2024'!EV11) -> 0 | EW11: =SUM('2026:2024'!EW11) -> 0 | EX11: =SUM('2026:2024'!EX11) -> 0 | EY11: =SUM('2026:2024'!EY11) -> 290278 | ... FG11: =SUM('2026:2024'!FG11) -> 0 | FH11: =SUM(ES11:FG11) -> 321572 | FJ11: =SUM('2026:2024'!FJ11) -> 350947 | FK11: =SUM('2026:2024'!FK11) -> 0 | FL11: =SUM('2026:2024'!FL11) -> 0 | FM11: =SUM('2026:2024'!FM11) -> 0 | FN11: =SUM('2026:2024'!FN11) -> 0 | FO11: =SUM('2026:2024'!FO11) -> 0 | FP11: =SUM('2026:2024'!FP11) -> 0 | FQ11: =SUM('2026:2024'!FQ11) -> 309183 | ... FY11: =SUM('2026:2024'!FY11) -> 0 | FZ11: =SUM(FK11:FY11) -> 346403 | GB11: =SUM('2026:2024'!GB11) -> 351968 | GC11: =SUM('2026:2024'!GC11) -> 0 | GD11: =SUM('2026:2024'!GD11) -> 0 | GE11: =SUM('2026:2024'!GE11) -> 0 | GF11: =SUM('2026:2024'!GF11) -> 0 | GG11: =SUM('2026:2024'!GG11) -> 0 | GH11: =SUM('2026:2024'!GH11) -> 0 | GI11: =SUM('2026:2024'!GI11) -> 285800 | ... GQ11: =SUM('2026:2024'!GQ11) -> 0 | GR11: =SUM(GC11:GQ11) -> 347580 | GT11: =SUM('2026:2024'!GT11) -> 187437 | GU11: =SUM('2026:2024'!GU11) -> 0 | GV11: =SUM('2026:2024'!GV11) -> 0 | GW11: =SUM('2026:2024'!GW11) -> 0 | GX11: =SUM('2026:2024'!GX11) -> 0 | GY11: =SUM('2026:2024'!GY11) -> 0 | GZ11: =SUM('2026:2024'!GZ11) -> 0 | HA11: =SUM('2026:2024'!HA11) -> 163136 | ... HI11: =SUM('2026:2024'!HI11) -> 0 | HJ11: =SUM(GU11:HI11) -> 186962 | HL11: =SUM('2026:2024'!HL11) -> 162550 | HM11: =SUM('2026:2024'!HM11) -> 0 | HN11: =SUM('2026:2024'!HN11) -> 0 | HO11: =SUM('2026:2024'!HO11) -> 0 | HP11: =SUM('2026:2024'!HP11) -> 0 | HQ11: =SUM('2026:2024'!HQ11) -> 0 | HR11: =SUM('2026:2024'!HR11) -> 0 | HS11: =SUM('2026:2024'!HS11) -> 136882 | ... IA11: =SUM('2026:2024'!IA11) -> 0 | IB11: =SUM(HM11:IA11) -> 161218
A12: Khác | B12: Khác | D12: =SUM('2026:2024'!D12) -> 30000 | E12: =SUM('2026:2024'!E12) -> 0 | F12: =SUM('2026:2024'!F12) -> 0 | G12: =SUM('2026:2024'!G12) -> 0 | H12: =SUM('2026:2024'!H12) -> 0 | I12: =SUM('2026:2024'!I12) -> 0 | J12: =SUM('2026:2024'!J12) -> 0 | K12: =SUM('2026:2024'!K12) -> 0 | ... S12: =SUM('2026:2024'!S12) -> 28925 | T12: =SUM(E12:S12) -> 29680 | V12: =SUM('2026:2024'!V12) -> 6000 | W12: =SUM('2026:2024'!W12) -> 0 | X12: =SUM('2026:2024'!X12) -> 0 | Y12: =SUM('2026:2024'!Y12) -> 0 | Z12: =SUM('2026:2024'!Z12) -> 0 | AA12: =SUM('2026:2024'!AA12) -> 0 | AB12: =SUM('2026:2024'!AB12) -> 0 | AC12: =SUM('2026:2024'!AC12) -> 0 | ... AK12: =SUM('2026:2024'!AK12) -> 6000 | AL12: =SUM(W12:AK12) -> 6000 | AN12: =SUM('2026:2024'!AN12) -> 0 | AO12: =SUM('2026:2024'!AO12) -> 0 | AP12: =SUM('2026:2024'!AP12) -> 0 | AQ12: =SUM('2026:2024'!AQ12) -> 0 | AR12: =SUM('2026:2024'!AR12) -> 0 | AS12: =SUM('2026:2024'!AS12) -> 0 | AT12: =SUM('2026:2024'!AT12) -> 0 | AU12: =SUM('2026:2024'!AU12) -> 0 | ... BC12: =SUM('2026:2024'!BC12) -> 0 | BD12: =SUM(AO12:BC12) -> 0 | BF12: =SUM('2026:2024'!BF12) -> 0 | BG12: =SUM('2026:2024'!BG12) -> 0 | BH12: =SUM('2026:2024'!BH12) -> 0 | BI12: =SUM('2026:2024'!BI12) -> 0 | BJ12: =SUM('2026:2024'!BJ12) -> 0 | BK12: =SUM('2026:2024'!BK12) -> 0 | BL12: =SUM('2026:2024'!BL12) -> 0 | BM12: =SUM('2026:2024'!BM12) -> 0 | ... BU12: =SUM('2026:2024'!BU12) -> 0 | BV12: =SUM(BG12:BU12) -> 0 | BX12: =SUM('2026:2024'!BX12) -> 0 | BY12: =SUM('2026:2024'!BY12) -> 0 | BZ12: =SUM('2026:2024'!BZ12) -> 0 | CA12: =SUM('2026:2024'!CA12) -> 0 | CB12: =SUM('2026:2024'!CB12) -> 0 | CC12: =SUM('2026:2024'!CC12) -> 0 | CD12: =SUM('2026:2024'!CD12) -> 0 | CE12: =SUM('2026:2024'!CE12) -> 0 | ... CM12: =SUM('2026:2024'!CM12) -> 0 | CN12: =SUM(BY12:CM12) -> 0 | CP12: =SUM('2026:2024'!CP12) -> 0 | CQ12: =SUM('2026:2024'!CQ12) -> 0 | CR12: =SUM('2026:2024'!CR12) -> 0 | CS12: =SUM('2026:2024'!CS12) -> 0 | CT12: =SUM('2026:2024'!CT12) -> 0 | CU12: =SUM('2026:2024'!CU12) -> 0 | CV12: =SUM('2026:2024'!CV12) -> 0 | CW12: =SUM('2026:2024'!CW12) -> 0 | ... DE12: =SUM('2026:2024'!DE12) -> 0 | DF12: =SUM(CQ12:DE12) -> 0 | DH12: =SUM('2026:2024'!DH12) -> 0 | DI12: =SUM('2026:2024'!DI12) -> 0 | DJ12: =SUM('2026:2024'!DJ12) -> 0 | DK12: =SUM('2026:2024'!DK12) -> 0 | DL12: =SUM('2026:2024'!DL12) -> 0 | DM12: =SUM('2026:2024'!DM12) -> 0 | DN12: =SUM('2026:2024'!DN12) -> 0 | DO12: =SUM('2026:2024'!DO12) -> 0 | ... DW12: =SUM('2026:2024'!DW12) -> 0 | DX12: =SUM(DI12:DW12) -> 0 | DZ12: =SUM('2026:2024'!DZ12) -> 0 | EA12: =SUM('2026:2024'!EA12) -> 0 | EB12: =SUM('2026:2024'!EB12) -> 0 | EC12: =SUM('2026:2024'!EC12) -> 0 | ED12: =SUM('2026:2024'!ED12) -> 0 | EE12: =SUM('2026:2024'!EE12) -> 0 | EF12: =SUM('2026:2024'!EF12) -> 0 | EG12: =SUM('2026:2024'!EG12) -> 0 | ... EO12: =SUM('2026:2024'!EO12) -> 0 | EP12: =SUM(EA12:EO12) -> 0 | ER12: =SUM('2026:2024'!ER12) -> 0 | ES12: =SUM('2026:2024'!ES12) -> 0 | ET12: =SUM('2026:2024'!ET12) -> 0 | EU12: =SUM('2026:2024'!EU12) -> 0 | EV12: =SUM('2026:2024'!EV12) -> 0 | EW12: =SUM('2026:2024'!EW12) -> 0 | EX12: =SUM('2026:2024'!EX12) -> 0 | EY12: =SUM('2026:2024'!EY12) -> 0 | ... FG12: =SUM('2026:2024'!FG12) -> 0 | FH12: =SUM(ES12:FG12) -> 0 | FJ12: =SUM('2026:2024'!FJ12) -> 22000 | FK12: =SUM('2026:2024'!FK12) -> 0 | FL12: =SUM('2026:2024'!FL12) -> 0 | FM12: =SUM('2026:2024'!FM12) -> 0 | FN12: =SUM('2026:2024'!FN12) -> 0 | FO12: =SUM('2026:2024'!FO12) -> 0 | FP12: =SUM('2026:2024'!FP12) -> 0 | FQ12: =SUM('2026:2024'!FQ12) -> 0 | ... FY12: =SUM('2026:2024'!FY12) -> 21000 | FZ12: =SUM(FK12:FY12) -> 21700 | GB12: =SUM('2026:2024'!GB12) -> 2000 | GC12: =SUM('2026:2024'!GC12) -> 0 | GD12: =SUM('2026:2024'!GD12) -> 0 | GE12: =SUM('2026:2024'!GE12) -> 0 | GF12: =SUM('2026:2024'!GF12) -> 0 | GG12: =SUM('2026:2024'!GG12) -> 0 | GH12: =SUM('2026:2024'!GH12) -> 0 | GI12: =SUM('2026:2024'!GI12) -> 0 | ... GQ12: =SUM('2026:2024'!GQ12) -> 1925 | GR12: =SUM(GC12:GQ12) -> 1980 | GT12: =SUM('2026:2024'!GT12) -> 0 | GU12: =SUM('2026:2024'!GU12) -> 0 | GV12: =SUM('2026:2024'!GV12) -> 0 | GW12: =SUM('2026:2024'!GW12) -> 0 | GX12: =SUM('2026:2024'!GX12) -> 0 | GY12: =SUM('2026:2024'!GY12) -> 0 | GZ12: =SUM('2026:2024'!GZ12) -> 0 | HA12: =SUM('2026:2024'!HA12) -> 0 | ... HI12: =SUM('2026:2024'!HI12) -> 0 | HJ12: =SUM(GU12:HI12) -> 0 | HL12: =SUM('2026:2024'!HL12) -> 0 | HM12: =SUM('2026:2024'!HM12) -> 0 | HN12: =SUM('2026:2024'!HN12) -> 0 | HO12: =SUM('2026:2024'!HO12) -> 0 | HP12: =SUM('2026:2024'!HP12) -> 0 | HQ12: =SUM('2026:2024'!HQ12) -> 0 | HR12: =SUM('2026:2024'!HR12) -> 0 | HS12: =SUM('2026:2024'!HS12) -> 0 | ... IA12: =SUM('2026:2024'!IA12) -> 0 | IB12: =SUM(HM12:IA12) -> 0
B13: TỔNG | D13: =SUM(D6:D12) -> 96656656 | E13: =SUM(E6:E12) -> 13692571 | F13: =SUM(F6:F12) -> 17388097 | G13: =SUM(G6:G12) -> 48965297 | H13: =SUM(H6:H12) -> 915344 | I13: =SUM(I6:I12) -> 5842918.5 | J13: =SUM(J6:J12) -> 30118 | K13: =SUM(K6:K12) -> 3535050 | ... T13: =SUM(T6:T12) -> 95826142 | V13: =SUM(V6:V12) -> 9545136 | W13: =SUM(W6:W12) -> 905398 | X13: =SUM(X6:X12) -> 1010900 | Y13: =SUM(Y6:Y12) -> 6365019 | Z13: =SUM(Z6:Z12) -> 169844 | AA13: =SUM(AA6:AA12) -> 471153 | AB13: =SUM(AB6:AB12) -> 6615 | AC13: =SUM(AC6:AC12) -> 158135 | ... AL13: =SUM(AL6:AL12) -> 9457670.8 | AN13: =SUM(AN6:AN12) -> 6873364.8 | AO13: =SUM(AO6:AO12) -> 1068233 | AP13: =SUM(AP6:AP12) -> 1068540 | AQ13: =SUM(AQ6:AQ12) -> 3763282 | AR13: =SUM(AR6:AR12) -> 157300 | AS13: =SUM(AS6:AS12) -> 104431 | AT13: =SUM(AT6:AT12) -> 11550 | AU13: =SUM(AU6:AU12) -> 231779 | ... BD13: =SUM(BD6:BD12) -> 6829532 | BF13: =SUM(BF6:BF12) -> 12118623 | BG13: =SUM(BG6:BG12) -> 655600 | BH13: =SUM(BH6:BH12) -> 2413400 | BI13: =SUM(BI6:BI12) -> 7058629 | BJ13: =SUM(BJ6:BJ12) -> 118800 | BK13: =SUM(BK6:BK12) -> 737345 | BL13: =SUM(BL6:BL12) -> 5473 | BM13: =SUM(BM6:BM12) -> 418782 | ... BV13: =SUM(BV6:BV12) -> 12029684 | BX13: =SUM(BX6:BX12) -> 10755593 | BY13: =SUM(BY6:BY12) -> 983400 | BZ13: =SUM(BZ6:BZ12) -> 1922037 | CA13: =SUM(CA6:CA12) -> 5742000 | CB13: =SUM(CB6:CB12) -> 47300 | CC13: =SUM(CC6:CC12) -> 1233745 | CD13: =SUM(CD6:CD12) -> 0 | CE13: =SUM(CE6:CE12) -> 176328 | ... CN13: =SUM(CN6:CN12) -> 10656238 | CP13: =SUM(CP6:CP12) -> 8834030.1 | CQ13: =SUM(CQ6:CQ12) -> 529100 | CR13: =SUM(CR6:CR12) -> 2038300 | CS13: =SUM(CS6:CS12) -> 4715700 | CT13: =SUM(CT6:CT12) -> 243100 | CU13: =SUM(CU6:CU12) -> 361900 | CV13: =SUM(CV6:CV12) -> 0 | CW13: =SUM(CW6:CW12) -> 499750 | ... DF13: =SUM(DF6:DF12) -> 8762826.7 | DH13: =SUM(DH6:DH12) -> 8828152.6 | DI13: =SUM(DI6:DI12) -> 723800 | DJ13: =SUM(DJ6:DJ12) -> 2494800 | DK13: =SUM(DK6:DK12) -> 4253700 | DL13: =SUM(DL6:DL12) -> 105600 | DM13: =SUM(DM6:DM12) -> 404200 | DN13: =SUM(DN6:DN12) -> 0 | DO13: =SUM(DO6:DO12) -> 339408 | ... DX13: =SUM(DX6:DX12) -> 8742785.9 | DZ13: =SUM(DZ6:DZ12) -> 5573613.4 | EA13: =SUM(EA6:EA12) -> 771100 | EB13: =SUM(EB6:EB12) -> 1454200 | EC13: =SUM(EC6:EC12) -> 2201200 | ED13: =SUM(ED6:ED12) -> 3300 | EE13: =SUM(EE6:EE12) -> 97600 | EF13: =SUM(EF6:EF12) -> 0 | EG13: =SUM(EG6:EG12) -> 514889 | ... EP13: =SUM(EP6:EP12) -> 5514859.4 | ER13: =SUM(ER6:ER12) -> 6487850.9 | ES13: =SUM(ES6:ES12) -> 1213300 | ET13: =SUM(ET6:ET12) -> 1365564 | EU13: =SUM(EU6:EU12) -> 2906856 | EV13: =SUM(EV6:EV12) -> 2200 | EW13: =SUM(EW6:EW12) -> 161950 | EX13: =SUM(EX6:EX12) -> 0 | EY13: =SUM(EY6:EY12) -> 290278 | ... FH13: =SUM(FH6:FH12) -> 6415303.2 | FJ13: =SUM(FJ6:FJ12) -> 6705785 | FK13: =SUM(FK6:FK12) -> 1578500 | FL13: =SUM(FL6:FL12) -> 1100355 | FM13: =SUM(FM6:FM12) -> 2884201 | FN13: =SUM(FN6:FN12) -> 4100 | FO13: =SUM(FO6:FO12) -> 426237 | FP13: =SUM(FP6:FP12) -> 2200 | FQ13: =SUM(FQ6:FQ12) -> 314633 | ... FZ13: =SUM(FZ6:FZ12) -> 6649613.4 | GB13: =SUM(GB6:GB12) -> 7930183.5 | GC13: =SUM(GC6:GC12) -> 1460640 | GD13: =SUM(GD6:GD12) -> 711700 | GE13: =SUM(GE6:GE12) -> 3847510 | GF13: =SUM(GF6:GF12) -> 53900 | GG13: =SUM(GG6:GG12) -> 915922.5 | GH13: =SUM(GH6:GH12) -> 0 | GI13: =SUM(GI6:GI12) -> 285800 | ... GR13: =SUM(GR6:GR12) -> 7861665.9 | GT13: =SUM(GT6:GT12) -> 6362157.8 | GU13: =SUM(GU6:GU12) -> 1923600 | GV13: =SUM(GV6:GV12) -> 1484901 | GW13: =SUM(GW6:GW12) -> 2025100 | GX13: =SUM(GX6:GX12) -> 6600 | GY13: =SUM(GY6:GY12) -> 313535 | GZ13: =SUM(GZ6:GZ12) -> 1850 | HA13: =SUM(HA6:HA12) -> 168386 | ... HJ13: =SUM(HJ6:HJ12) -> 6324168 | HL13: =SUM(HL6:HL12) -> 6642165.5 | HM13: =SUM(HM6:HM12) -> 1879900 | HN13: =SUM(HN6:HN12) -> 323400 | HO13: =SUM(HO6:HO12) -> 3202100 | HP13: =SUM(HP6:HP12) -> 3300 | HQ13: =SUM(HQ6:HQ12) -> 614900 | HR13: =SUM(HR6:HR12) -> 2430 | HS13: =SUM(HS6:HS12) -> 136882 | ... IB13: =SUM(IB6:IB12) -> 6581795
T14: =D13-T13 -> 830513.55 | AL14: =V13-AL13 -> 87465.25 | BD14: =AN13-BD13 -> 43832.8 | BV14: =BF13-BV13 -> 88939 | CN14: =BX13-CN13 -> 99355.4
T15: =T14/D13 -> 0.0085924093 | AL15: =AL14/V13 -> 0.009163332 | BD15: =BD14/AN13 -> 0.0063771968 | BV15: =BV14/BF13 -> 0.0073390351 | CN15: =CN14/BX13 -> 0.0092375563
B16: %Thu hồi
B17: iSS01084 | D17: =IFERROR(D6/T6,0) -> 1.0085381 | E17: =IFERROR(E6/T6,0) -> 0.8446799 | F17: =IFERROR(F6/T6,0) -> 0.038204786 | G17: =IFERROR(G6/T6,0) -> 0.012603717 | H17: =IFERROR(H6/T6,0) -> 0.001114359 | I17: =IFERROR(I6/T6,0) -> 0.050019746 | J17: =IFERROR(J6/T6,0) -> 0 | K17: =IFERROR(K6/T6,0) -> 0 | L17: =IFERROR(L6/T6,0) -> 0 | M17: =IFERROR(M6/T6,0) -> 0.0065468593 | N17: =IFERROR(N6/T6,0) -> 0.0014625962 | O17: =IFERROR(O6/T6,0) -> 0.0025073078 | P17: =IFERROR(P6/T6,0) -> 0.0045587415 | Q17: =IFERROR(Q6/T6,0) -> 0 | R17: =IFERROR(R6/T6,0) -> 0.038301991 | S17: =IFERROR(S6/T6,0) -> 0 | T17: =IFERROR(T6/T6,0) -> 1 | V17: =IFERROR(V6/AL6,0) -> 1.0067905 | W17: =IFERROR(W6/AL6,0) -> 0.89398359 | X17: =IFERROR(X6/AL6,0) -> 0.017570236 | Y17: =IFERROR(Y6/AL6,0) -> 0.0021573455 | Z17: =IFERROR(Z6/AL6,0) -> 0.0054906988 | AA17: =IFERROR(AA6/AL6,0) -> 0.04392559 | AB17: =IFERROR(AB6/AL6,0) -> 0 | AC17: =IFERROR(AC6/AL6,0) -> 0 | AD17: =IFERROR(AD6/AL6,0) -> 0 | AE17: =IFERROR(AE6/AL6,0) -> 0.0010981398 | AF17: =IFERROR(AF6/AL6,0) -> 0.0021962795 | AG17: =IFERROR(AG6/AL6,0) -> 0 | AH17: =IFERROR(AH6/AL6,0) -> 0 | AI17: =IFERROR(AI6/AL6,0) -> 0 | AJ17: =IFERROR(AJ6/AL6,0) -> 0.033578119 | AK17: =IFERROR(AK6/AL6,0) -> 0 | AL17: =IFERROR(AL6/AL6,0) -> 1 | AN17: =IFERROR(AN6/BD6,0) -> 1.0070689 | AO17: =IFERROR(AO6/BD6,0) -> 0.84568189 | AP17: =IFERROR(AP6/BD6,0) -> 0.051431972 | AQ17: =IFERROR(AQ6/BD6,0) -> 0.0017434567 | AR17: =IFERROR(AR6/BD6,0) -> 0.0052303701 | AS17: =IFERROR(AS6/BD6,0) -> 0.045329874 | AT17: =IFERROR(AT6/BD6,0) -> 0 | AU17: =IFERROR(AU6/BD6,0) -> 0 | AV17: =IFERROR(AV6/BD6,0) -> 0 | AW17: =IFERROR(AW6/BD6,0) -> 0.0034869134 | AX17: =IFERROR(AX6/BD6,0) -> 0.0034869134 | AY17: =IFERROR(AY6/BD6,0) -> 0 | AZ17: =IFERROR(AZ6/BD6,0) -> 0.0034869134 | BA17: =IFERROR(BA6/BD6,0) -> 0 | BB17: =IFERROR(BB6/BD6,0) -> 0.040121693 | BC17: =IFERROR(BC6/BD6,0) -> 0 | BD17: =IFERROR(BD6/BD6,0) -> 1 | BF17: =IFERROR(BF6/BV6,0) -> 1.0144129 | BG17: =IFERROR(BG6/BV6,0) -> 0.91577459 | BH17: =IFERROR(BH6/BV6,0) -> 0.015627553 | BI17: =IFERROR(BI6/BV6,0) -> 0.0015627553 | BJ17: =IFERROR(BJ6/BV6,0) -> 0 | BK17: =IFERROR(BK6/BV6,0) -> 0.015627553 | BL17: =IFERROR(BL6/BV6,0) -> 0 | BM17: =IFERROR(BM6/BV6,0) -> 0 | BN17: =IFERROR(BN6/BV6,0) -> 0 | BO17: =IFERROR(BO6/BV6,0) -> 0 | BP17: =IFERROR(BP6/BV6,0) -> 0.0093765317 | BQ17: =IFERROR(BQ6/BV6,0) -> 0 | BR17: =IFERROR(BR6/BV6,0) -> 0 | BS17: =IFERROR(BS6/BV6,0) -> 0 | BT17: =IFERROR(BT6/BV6,0) -> 0.042031014 | BU17: =IFERROR(BU6/BV6,0) -> 0 | BV17: =IFERROR(BV6/BV6,0) -> 1 | BX17: =IFERROR(BX6/CN6,0) -> 1.0150955 | BY17: =IFERROR(BY6/CN6,0) -> 0.89542585 | BZ17: =IFERROR(BZ6/CN6,0) -> 0.019094378 | CA17: =IFERROR(CA6/CN6,0) -> 0.043213593 | CB17: =IFERROR(CB6/CN6,0) -> 0 | CC17: =IFERROR(CC6/CN6,0) -> 0.013064575 | CD17: =IFERROR(CD6/CN6,0) -> 0 | CE17: =IFERROR(CE6/CN6,0) -> 0 | CF17: =IFERROR(CF6/CN6,0) -> 0 | CG17: =IFERROR(CG6/CN6,0) -> 0.0020099346 | CH17: =IFERROR(CH6/CN6,0) -> 0.0020099346 | CI17: =IFERROR(CI6/CN6,0) -> 0 | CJ17: =IFERROR(CJ6/CN6,0) -> 0.0020099346 | CK17: =IFERROR(CK6/CN6,0) -> 0 | CL17: =IFERROR(CL6/CN6,0) -> 0.023171805 | CM17: =IFERROR(CM6/CN6,0) -> 0 | CN17: =IFERROR(CN6/CN6,0) -> 1 | CP17: =IFERROR(CP6/DF6,0) -> 1.0064496 | CQ17: =IFERROR(CQ6/DF6,0) -> 0.72435626 | CR17: =IFERROR(CR6/DF6,0) -> 0.17844267 | CS17: =IFERROR(CS6/DF6,0) -> 0 | CT17: =IFERROR(CT6/DF6,0) -> 0.006048904 | CU17: =IFERROR(CU6/DF6,0) -> 0.024195616 | CV17: =IFERROR(CV6/DF6,0) -> 0 | CW17: =IFERROR(CW6/DF6,0) -> 0 | CX17: =IFERROR(CX6/DF6,0) -> 0 | CY17: =IFERROR(CY6/DF6,0) -> 0.001512226 | CZ17: =IFERROR(CZ6/DF6,0) -> 0 | DA17: =IFERROR(DA6/DF6,0) -> 0.019658938 | DB17: =IFERROR(DB6/DF6,0) -> 0 | DC17: =IFERROR(DC6/DF6,0) -> 0 | DD17: =IFERROR(DD6/DF6,0) -> 0.045785392 | DE17: =IFERROR(DE6/DF6,0) -> 0 | DF17: =IFERROR(DF6/DF6,0) -> 1 | DH17: =IFERROR(DH6/DX6,0) -> 1.0136669 | DI17: =IFERROR(DI6/DX6,0) -> 0.881223 | DJ17: =IFERROR(DJ6/DX6,0) -> 0.040516 | DK17: =IFERROR(DK6/DX6,0) -> 0 | DL17: =IFERROR(DL6/DX6,0) -> 0 | DM17: =IFERROR(DM6/DX6,0) -> 0.010129 | DN17: =IFERROR(DN6/DX6,0) -> 0 | DO17: =IFERROR(DO6/DX6,0) -> 0 | DP17: =IFERROR(DP6/DX6,0) -> 0 | DQ17: =IFERROR(DQ6/DX6,0) -> 0.008682 | DR17: =IFERROR(DR6/DX6,0) -> 0.005788 | DS17: =IFERROR(DS6/DX6,0) -> 0.002894 | DT17: =IFERROR(DT6/DX6,0) -> 0.008682 | DU17: =IFERROR(DU6/DX6,0) -> 0 | DV17: =IFERROR(DV6/DX6,0) -> 0.042085995 | DW17: =IFERROR(DW6/DX6,0) -> 0 | DX17: =IFERROR(DX6/DX6,0) -> 1 | DZ17: =IFERROR(DZ6/EP6,0) -> 1.0065202 | EA17: =IFERROR(EA6/EP6,0) -> 0.78034693 | EB17: =IFERROR(EB6/EP6,0) -> 0.083515391 | EC17: =IFERROR(EC6/EP6,0) -> 0.0091344958 | ED17: =IFERROR(ED6/EP6,0) -> 0 | EE17: =IFERROR(EE6/EP6,0) -> 0.033928127 | EF17: =IFERROR(EF6/EP6,0) -> 0 | EG17: =IFERROR(EG6/EP6,0) -> 0 | EH17: =IFERROR(EH6/EP6,0) -> 0 | EI17: =IFERROR(EI6/EP6,0) -> 0.01304928 | EJ17: =IFERROR(EJ6/EP6,0) -> 0 | EK17: =IFERROR(EK6/EP6,0) -> 0 | EL17: =IFERROR(EL6/EP6,0) -> 0.0078295679 | EM17: =IFERROR(EM6/EP6,0) -> 0 | EN17: =IFERROR(EN6/EP6,0) -> 0.072196208 | EO17: =IFERROR(EO6/EP6,0) -> 0 | EP17: =IFERROR(EP6/EP6,0) -> 1 | ER17: =IFERROR(ER6/FH6,0) -> 1.0087644 | ES17: =IFERROR(ES6/FH6,0) -> 0.86792207 | ET17: =IFERROR(ET6/FH6,0) -> 0.03429292 | EU17: =IFERROR(EU6/FH6,0) -> 0.00085257571 | EV17: =IFERROR(EV6/FH6,0) -> 0 | EW17: =IFERROR(EW6/FH6,0) -> 0.046038313 | EX17: =IFERROR(EX6/FH6,0) -> 0 | EY17: =IFERROR(EY6/FH6,0) -> 0 | EZ17: =IFERROR(EZ6/FH6,0) -> 0 | FA17: =IFERROR(FA6/FH6,0) -> 0 | FB17: =IFERROR(FB6/FH6,0) -> 0.00085257571 | FC17: =IFERROR(FC6/FH6,0) -> 0.0051154543 | FD17: =IFERROR(FD6/FH6,0) -> 0.0080607158 | FE17: =IFERROR(FE6/FH6,0) -> 0 | FF17: =IFERROR(FF6/FH6,0) -> 0.036865374 | FG17: =IFERROR(FG6/FH6,0) -> 0 | FH17: =IFERROR(FH6/FH6,0) -> 1 | FJ17: =IFERROR(FJ6/FZ6,0) -> 1.0036555 | FK17: =IFERROR(FK6/FZ6,0) -> 0.83104902 | FL17: =IFERROR(FL6/FZ6,0) -> 0.049724663 | FM17: =IFERROR(FM6/FZ6,0) -> 0.00174835 | FN17: =IFERROR(FN6/FZ6,0) -> 0 | FO17: =IFERROR(FO6/FZ6,0) -> 0.084611927 | FP17: =IFERROR(FP6/FZ6,0) -> 0 | FQ17: =IFERROR(FQ6/FZ6,0) -> 0 | FR17: =IFERROR(FR6/FZ6,0) -> 0 | FS17: =IFERROR(FS6/FZ6,0) -> 0 | FT17: =IFERROR(FT6/FZ6,0) -> 0 | FU17: =IFERROR(FU6/FZ6,0) -> 0 | FV17: =IFERROR(FV6/FZ6,0) -> 0.00058278333 | FW17: =IFERROR(FW6/FZ6,0) -> 0 | FX17: =IFERROR(FX6/FZ6,0) -> 0.032283253 | FY17: =IFERROR(FY6/FZ6,0) -> 0 | FZ17: =IFERROR(FZ6/FZ6,0) -> 1 | GB17: =IFERROR(GB6/GR6,0) -> 1.0082964 | GC17: =IFERROR(GC6/GR6,0) -> 0.72032049 | GD17: =IFERROR(GD6/GR6,0) -> 0.04315278 | GE17: =IFERROR(GE6/GR6,0) -> 0.053111114 | GF17: =IFERROR(GF6/GR6,0) -> 0.00055324077 | GG17: =IFERROR(GG6/GR6,0) -> 0.095157413 | GH17: =IFERROR(GH6/GR6,0) -> 0 | GI17: =IFERROR(GI6/GR6,0) -> 0 | GJ17: =IFERROR(GJ6/GR6,0) -> 0 | GK17: =IFERROR(GK6/GR6,0) -> 0.029875002 | GL17: =IFERROR(GL6/GR6,0) -> 0 | GM17: =IFERROR(GM6/GR6,0) -> 0.0082986116 | GN17: =IFERROR(GN6/GR6,0) -> 0.010511575 | GO17: =IFERROR(GO6/GR6,0) -> 0 | GP17: =IFERROR(GP6/GR6,0) -> 0.03901977 | GQ17: =IFERROR(GQ6/GR6,0) -> 0 | GR17: =IFERROR(GR6/GR6,0) -> 1 | GT17: =IFERROR(GT6/HJ6,0) -> 1.0089438 | GU17: =IFERROR(GU6/HJ6,0) -> 0.87510954 | GV17: =IFERROR(GV6/HJ6,0) -> 0.012093222 | GW17: =IFERROR(GW6/HJ6,0) -> 0.0055427269 | GX17: =IFERROR(GX6/HJ6,0) -> 0 | GY17: =IFERROR(GY6/HJ6,0) -> 0.067520491 | GZ17: =IFERROR(GZ6/HJ6,0) -> 0 | HA17: =IFERROR(HA6/HJ6,0) -> 0 | HB17: =IFERROR(HB6/HJ6,0) -> 0 | HC17: =IFERROR(HC6/HJ6,0) -> 0.0010077685 | HD17: =IFERROR(HD6/HJ6,0) -> 0 | HE17: =IFERROR(HE6/HJ6,0) -> 0 | HF17: =IFERROR(HF6/HJ6,0) -> 0.0035271898 | HG17: =IFERROR(HG6/HJ6,0) -> 0 | HH17: =IFERROR(HH6/HJ6,0) -> 0.035199064 | HI17: =IFERROR(HI6/HJ6,0) -> 0 | HJ17: =IFERROR(HJ6/HJ6,0) -> 1 | HL17: =IFERROR(HL6/IB6,0) -> 1.0086023 | HM17: =IFERROR(HM6/IB6,0) -> 0.91012481 | HN17: =IFERROR(HN6/IB6,0) -> 0.0037519868 | HO17: =IFERROR(HO6/IB6,0) -> 0.0080399718 | HP17: =IFERROR(HP6/IB6,0) -> 0 | HQ17: =IFERROR(HQ6/IB6,0) -> 0.026263908 | HR17: =IFERROR(HR6/IB6,0) -> 0 | HS17: =IFERROR(HS6/IB6,0) -> 0 | HT17: =IFERROR(HT6/IB6,0) -> 0 | HU17: =IFERROR(HU6/IB6,0) -> 0.0075039737 | HV17: =IFERROR(HV6/IB6,0) -> 0.0010719962 | HW17: =IFERROR(HW6/IB6,0) -> 0 | HX17: =IFERROR(HX6/IB6,0) -> 0.0058959793 | HY17: =IFERROR(HY6/IB6,0) -> 0 | HZ17: =IFERROR(HZ6/IB6,0) -> 0.037347375 | IA17: =IFERROR(IA6/IB6,0) -> 0 | IB17: =IFERROR(IB6/IB6,0) -> 1
