Workbook

Sheet QTSX

Sheet CĐSX
A2: STT | B2: Công đoạn SX
A3: 1 | B3: Thu mua
A4: 2 | B4: Vận chuyển NL về NM
A5: 3 | B5: Nhập hàng và tồn kho NL
A6: 5 | B6: Xuất NL, phá kiện
A7: 6 | B7: Phân loại chai trước tách nhãn
A8: 7 | B8: Tách nhãn
A9: 8 | B9: Phân loại chai sau tách nhãn
A10: 9 | B10: Ép kiện
A11: 10 | B11: Băm vảy
A12: 12 | B12: Rửa vảy
A13: 13 | B13: Tồn kho TP
A14: 14 | B14: Xuất bán, vận chyển

Sheet CAP.Chính
A1: ĐẦU TƯ CAPEX - MÁY CHÍNH
A2: A | B2: CHUYỀN PHÂN LOẠI CHAI
A3: STT | B3: Hạng mục đầu tư | C3: Nhà cung cấp | D3: Công suất/ 1 công đoạn | E3: Đơn giá ( chưa bao gồm VAT) | F3: H.S 40% | H3: H.S 60% | J3: H.S 80% | L3: H.S 100% | N3: Ghi chú
F4: Số lượng | G4: Tổng giá trị (VND) | H4: Số lượng | I4: Tổng giá trị (VND) | J4: Số lượng | K4: Tổng giá trị (VND) | L4: Số lượng | M4: Tổng giá trị (VND)
A5: I | B5: MÁY MÓC THIẾT BỊ CHÍNH | G5: =G6+G9+G12+G15+G25+G32+G39 -> 16230006000 | I5: =I6+I9+I12+I15+I25+I32+I39 -> 16230006000 | K5: =K6+K9+K12+K15+K25+K32+K39 -> 16230006000 | M5: =M6+M9+M12+M15+M25+M32+M39 -> 16230006000
A6: 1 | B6: Cấp liệu | D6: 3 tấn/h | G6: =G7+G8 -> 160000000 | I6: =I7+I8 -> 160000000 | K6: =K7+K8 -> 160000000 | M6: =M7+M8 -> 160000000
B7: Sàn thao tác chai đầu vào | C7: Plenma/HTL | E7: 80000000 | F7: 1 | G7: =$E7*F7 -> 80000000 | H7: 1 | I7: =$E7*H7 -> 80000000 | J7: 1 | K7: =$E7*J7 -> 80000000 | L7: 1 | M7: =$E7*L7 -> 80000000
B8: Băng tải phân loại bì tạp | C8: Plenma/HTL | E8: 80000000 | F8: 1 | G8: =$E8*F8 -> 80000000 | H8: 1 | I8: =$E8*H8 -> 80000000 | J8: 1 | K8: =$E8*J8 -> 80000000 | L8: 1 | M8: =$E8*L8 -> 80000000
A9: 2 | B9: Phá kiện | D9: 2 tấn/h | G9: =G10 -> 445000000 | I9: =I10 -> 445000000 | K9: =K10 -> 445000000 | M9: =M10 -> 445000000
B10: Máy phá kiện | C10: Plenma/HTL | E10: 445000000 | F10: 1 | G10: =$E10*F10 -> 445000000 | H10: 1 | I10: =$E10*H10 -> 445000000 | J10: 1 | K10: =$E10*J10 -> 445000000 | L10: 1 | M10: =$E10*L10 -> 445000000 | N10: GĐ 1 không có
B11: Băng tải máy phá kiện | C11: Plenma/HTL | E11: 120000000 | F11: 1 | G11: =$E11*F11 -> 120000000 | H11: 1 | I11: =$E11*H11 -> 120000000 | J11: 1 | K11: =$E11*J11 -> 120000000 | L11: 1 | M11: =$E11*L11 -> 120000000 | N11: GĐ 1 không có
A12: 3 | B12: Sàn tách tạp chất | D12: 3 tấn/h | G12: =G13+G14 -> 590000000 | I12: =I13+I14 -> 590000000 | K12: =K13+K14 -> 590000000 | M12: =M13+M14 -> 590000000
B13: Băng tải nam châm tách kim loại tự động | C13: Plenma/HTL | E13: 120000000 | F13: 2 | G13: =$E13*F13 -> 240000000 | H13: 2 | I13: =$E13*H13 -> 240000000 | J13: 2 | K13: =$E13*J13 -> 240000000 | L13: 2 | M13: =$E13*L13 -> 240000000
B14: Máy sàn cát đá tromel | C14: HTL | E14: 350000000 | F14: 1 | G14: =$E14*F14 -> 350000000 | H14: 1 | I14: =$E14*H14 -> 350000000 | J14: 1 | K14: =$E14*J14 -> 350000000 | L14: 1 | M14: =$E14*L14 -> 350000000
A15: 4 | B15: Lựa phân loại chai | D15: 3 tấn/h | G15: =SUM(G16:G24) -> 5575000000 | I15: =SUM(I16:I24) -> 5575000000 | K15: =SUM(K16:K24) -> 5575000000 | M15: =SUM(M16:M24) -> 5575000000
B16: Máy sort chai tự động 3 tấn/giờ | C16: Databeyond | E16: 950000000 | F16: 2 | G16: =$E16*F16 -> 1900000000 | H16: 2 | I16: =$E16*H16 -> 1900000000 | J16: 2 | K16: =$E16*J16 -> 1900000000 | L16: 2 | M16: =$E16*L16 -> 1900000000
B17: Lập trình và vận hành máy sort chai | C17: Databeyond | E17: 180000000 | F17: 1 | G17: =$E17*F17 -> 180000000 | H17: 1 | I17: =$E17*H17 -> 180000000 | J17: 1 | K17: =$E17*J17 -> 180000000 | L17: 1 | M17: =$E17*L17 -> 180000000
B18: Băng tải cấp chai máy sort | C18: Plenma/HTL | E18: 295000000 | F18: 1 | G18: =$E18*F18 -> 295000000 | H18: 1 | I18: =$E18*H18 -> 295000000 | J18: 1 | K18: =$E18*J18 -> 295000000 | L18: 1 | M18: =$E18*L18 -> 295000000
B19: Khung sàn thao tác máy sort | C19: Plenma/HTL | E19: 350000000 | F19: 1 | G19: =$E19*F19 -> 350000000 | H19: 1 | I19: =$E19*H19 -> 350000000 | J19: 1 | K19: =$E19*J19 -> 350000000 | L19: 1 | M19: =$E19*L19 -> 350000000
B20: Quạt thổi chai | C20: Plenma/HTL | E20: 240000000 | F20: 5 | G20: =$E20*F20 -> 1200000000 | H20: 5 | I20: =$E20*H20 -> 1200000000 | J20: 5 | K20: =$E20*J20 -> 1200000000 | L20: 5 | M20: =$E20*L20 -> 1200000000
B21: Lồng chứa chai B1 | C21: Plenma/HTL | E21: 600000000 | F21: 1 | G21: =$E21*F21 -> 600000000 | H21: 1 | I21: =$E21*H21 -> 600000000 | J21: 1 | K21: =$E21*J21 -> 600000000 | L21: 1 | M21: =$E21*L21 -> 600000000
B22: Lồng chứa chai B6 | C22: Plenma/HTL | E22: 400000000 | F22: 1 | G22: =$E22*F22 -> 400000000 | H22: 1 | I22: =$E22*H22 -> 400000000 | J22: 1 | K22: =$E22*J22 -> 400000000 | L22: 1 | M22: =$E22*L22 -> 400000000
B23: Lồng chứa chai B2.2 | C23: Plenma/HTL | E23: 350000000 | F23: 1 | G23: =$E23*F23 -> 350000000 | H23: 1 | I23: =$E23*H23 -> 350000000 | J23: 1 | K23: =$E23*J23 -> 350000000 | L23: 1 | M23: =$E23*L23 -> 350000000
B24: Lồng chứa chai B4, B5 | C24: Plenma/HTL | E24: 150000000 | F24: 2 | G24: =$E24*F24 -> 300000000 | H24: 2 | I24: =$E24*H24 -> 300000000 | J24: 2 | K24: =$E24*J24 -> 300000000 | L24: 2 | M24: =$E24*L24 -> 300000000
A25: 5 | B25: Tách nhãn | D25: 1 tấn/h | G25: =SUM(G26:G31) -> 3230000000 | I25: =SUM(I26:I31) -> 3230000000 | K25: =SUM(K26:K31) -> 3230000000 | M25: =SUM(M26:M31) -> 3230000000
B26: Máy tách nhãn | C26: Plenma/HTL | E26: 660000000 | F26: 3 | G26: =$E26*F26 -> 1980000000 | H26: 3 | I26: =$E26*H26 -> 1980000000 | J26: 3 | K26: =$E26*J26 -> 1980000000 | L26: 3 | M26: =$E26*L26 -> 1980000000 | N26: GĐ 1 = 2 Cái
B27: Cylon máy tách nhãn | C27: Plenma/HTL | E27: 50000000 | F27: 2 | G27: =$E27*F27 -> 100000000 | H27: 2 | I27: =$E27*H27 -> 100000000 | J27: 2 | K27: =$E27*J27 -> 100000000 | L27: 2 | M27: =$E27*L27 -> 100000000 | N27: GĐ 1 = 1 Cái
B28: Phòng cách âm cho máy tách nhãn | C28: Lê Quốc | E28: 100000000 | F28: 2 | G28: =$E28*F28 -> 200000000 | H28: 2 | I28: =$E28*H28 -> 200000000 | J28: 2 | K28: =$E28*J28 -> 200000000 | L28: 2 | M28: =$E28*L28 -> 200000000 | N28: GĐ 1 = 1 Cái
B29: Băng tải cấp chai từ lồng chứa | C29: Plenma/HTL | E29: 160000000 | F29: 3 | G29: =$E29*F29 -> 480000000 | H29: 3 | I29: =$E29*H29 -> 480000000 | J29: 3 | K29: =$E29*J29 -> 480000000 | L29: 3 | M29: =$E29*L29 -> 480000000
B30: Băng tải cấp chai máy tách nhãn | C30: Plenma/HTL | E30: 175000000 | F30: 2 | G30: =$E30*F30 -> 350000000 | H30: 2 | I30: =$E30*H30 -> 350000000 | J30: 2 | K30: =$E30*J30 -> 350000000 | L30: 2 | M30: =$E30*L30 -> 350000000 | N30: GĐ 1 = 1 Cái
B31: Băng tải quay đầu | C31: Plenma/HTL | E31: 120000000 | F31: 1 | G31: =$E31*F31 -> 120000000 | H31: 1 | I31: =$E31*H31 -> 120000000 | J31: 1 | K31: =$E31*J31 -> 120000000 | L31: 1 | M31: =$E31*L31 -> 120000000
A32: 6 | B32: Lựa phân loại chai sau tách nhãn | D32: 3 tấn/h | G32: =SUM(G33:G38) -> 3850000000 | I32: =SUM(I33:I38) -> 3850000000 | K32: =SUM(K33:K38) -> 3850000000 | M32: =SUM(M33:M38) -> 3850000000
B33: Máy sort chai tự động 3 tấn/giờ | C33: Databeyond | E33: 950000000 | F33: 3 | G33: =$E33*F33 -> 2850000000 | H33: 3 | I33: =$E33*H33 -> 2850000000 | J33: 3 | K33: =$E33*J33 -> 2850000000 | L33: 3 | M33: =$E33*L33 -> 2850000000 | N33: GĐ 1 = 2 Cái
B34: Khung sàn máy sort chai sau tách nhãn | C34: Plenma/HTL | E34: 100000000 | F34: 2 | G34: =$E34*F34 -> 200000000 | H34: 2 | I34: =$E34*H34 -> 200000000 | J34: 2 | K34: =$E34*J34 -> 200000000 | L34: 2 | M34: =$E34*L34 -> 200000000 | N34: GĐ 1 = 1 Cái
B35: Băng tải cầp chai máy sort | C35: Plenma/HTL | E35: 120000000 | F35: 2 | G35: =$E35*F35 -> 240000000 | H35: 2 | I35: =$E35*H35 -> 240000000 | J35: 2 | K35: =$E35*J35 -> 240000000 | L35: 2 | M35: =$E35*L35 -> 240000000 | N35: GĐ 1 = 1 Cái
B36: Băng tải đứng cấp chai máy line 2 máy sort | C36: Plenma/HTL | E36: 150000000 | F36: 2 | G36: =$E36*F36 -> 300000000 | H36: 2 | I36: =$E36*H36 -> 300000000 | J36: 2 | K36: =$E36*J36 -> 300000000 | L36: 2 | M36: =$E36*L36 -> 300000000 | N36: GĐ 1 = 1 Cái
B37: Băng tải con lăn | C37: Plenma/HTL | E37: 50000000 | F37: 2 | G37: =$E37*F37 -> 100000000 | H37: 2 | I37: =$E37*H37 -> 100000000 | J37: 2 | K37: =$E37*J37 -> 100000000 | L37: 2 | M37: =$E37*L37 -> 100000000 | N37: GĐ 1 = 1 Cái
B38: Băng tải phân loại chai tách nhãn | C38: Plenma/HTL | E38: 80000000 | F38: 2 | G38: =$E38*F38 -> 160000000 | H38: 2 | I38: =$E38*H38 -> 160000000 | J38: 2 | K38: =$E38*J38 -> 160000000 | L38: 2 | M38: =$E38*L38 -> 160000000 | N38: GĐ 1 = 1 Cái
A39: 7 | B39: Ép kiện | D39: 1.5 tấn/h | G39: =SUM(G40:G42) -> 2380006000 | I39: =SUM(I40:I42) -> 2380006000 | K39: =SUM(K40:K42) -> 2380006000 | M39: =SUM(M40:M42) -> 2380006000
B40: Máy ép kiện ngang | C40: HTL | E40: 1015003000 | F40: 2 | G40: =$E40*F40 -> 2030006000 | H40: 2 | I40: =$E40*H40 -> 2030006000 | J40: 2 | K40: =$E40*J40 -> 2030006000 | L40: 2 | M40: =$E40*L40 -> 2030006000 | N40: GĐ 1 = 1 Cái
...

Sheet CAP.Phụ
B1: TRẠM HCM
B2: ĐÁNH GIÁ HIỆU QUẢ ĐẦU TƯ
B3: KẾ HOẠCH ĐẦU TƯ VÀ KHẤU HAO
A5: ĐẦU TƯ CAPEX - THIẾT BỊ PHỤ
A6: A | B6: CHUYỀN PHÂN LOẠI CHAI
A7: STT | B7: Hạng mục đầu tư | C7: Nhà cung cấp | D7: Công suất | E7: Đơn giá ( chưa bao gồm VAT) | F7: H.S 40% | H7: H.S 60% | J7: H.S 80% | L7: H.S 100% | N7: Ghi chú
F8: Số lượng | G8: Tổng giá trị (VND) | H8: Số lượng | I8: Tổng giá trị (VND) | J8: Số lượng | K8: Tổng giá trị (VND) | L8: Số lượng | M8: Tổng giá trị (VND)
A9: I | B9: THIẾT BỊ PHỤC VỤ SẢN XUẤT | G9: =SUM(G10:G13) -> 1724000000 | I9: =SUM(I10:I13) -> 1724000000 | K9: =SUM(K10:K13) -> 1724000000 | M9: =SUM(M10:M13) -> 1724000000
A10: 1 | B10: Xe nâng 2,5 tấn | C10: BYD | D10: 2.5 Tấn | E10: 500000000 | F10: 2 | G10: =$E10*F10 -> 1000000000 | H10: 2 | I10: =$E10*H10 -> 1000000000 | J10: 2 | K10: =$E10*J10 -> 1000000000 | L10: 2 | M10: =$E10*L10 -> 1000000000
A11: 2 | B11: Xe nâng tay 1,5 tấn | C11: BYD | D11: 1.5 Tấn | E11: 87000000 | F11: 2 | G11: =$E11*F11 -> 174000000 | H11: 2 | I11: =$E11*H11 -> 174000000 | J11: 2 | K11: =$E11*J11 -> 174000000 | L11: 2 | M11: =$E11*L11 -> 174000000 | N11: GĐ 1 = 1 Cái
A12: 3 | B12: Trạm cân 40 tấn | C12: MK-Cell | D12: 40 Tấn | E12: 450000000 | F12: 1 | G12: =$E12*F12 -> 450000000 | H12: 1 | I12: =$E12*H12 -> 450000000 | J12: 1 | K12: =$E12*J12 -> 450000000 | L12: 1 | M12: =$E12*L12 -> 450000000
A13: 4 | B13: Nhà chứa máy nén khí | C13: Thành Công | E13: 100000000 | F13: 1 | G13: =$E13*F13 -> 100000000 | H13: 1 | I13: =$E13*H13 -> 100000000 | J13: 1 | K13: =$E13*J13 -> 100000000 | L13: 1 | M13: =$E13*L13 -> 100000000
A14: II | B14: THIẾT BỊ PHỤC VỤ QUẢN LÝ | G14: =SUM(G15:G17) -> 201000000 | I14: =SUM(I15:I17) -> 201000000 | K14: =SUM(K15:K17) -> 201000000 | M14: =SUM(M15:M17) -> 201000000
A15: 1 | B15: Hồ sơ pháp lý ban đầu | E15: 20000000 | F15: 5 | G15: =$E15*F15 -> 100000000 | H15: 5 | I15: =$E15*H15 -> 100000000 | J15: 5 | K15: =$E15*J15 -> 100000000 | L15: 5 | M15: =$E15*L15 -> 100000000
A16: 2 | B16: Chi phí văn phòng, cải tạo cơ sở hạ tầng | E16: 100000000 | F16: 1 | G16: =$E16*F16 -> 100000000 | H16: 1 | I16: =$E16*H16 -> 100000000 | J16: 1 | K16: =$E16*J16 -> 100000000 | L16: 1 | M16: =$E16*L16 -> 100000000
A17: 3 | B17: Chi phí cho công tác huấn luyện & đào tạo | E17: 1000000 | F17: 1 | G17: =$E17*F17 -> 1000000 | H17: 1 | I17: =$E17*H17 -> 1000000 | J17: 1 | K17: =$E17*J17 -> 1000000 | L17: 1 | M17: =$E17*L17 -> 1000000
B18: TỔNG | G18: =G9+G14 -> 1925000000 | I18: =I9+I14 -> 1925000000 | K18: =K9+K14 -> 1925000000 | M18: =M9+M14 -> 1925000000
A20: B | B20: CHUYỀN BĂM CHAI PET
A21: STT | B21: Hạng mục đầu tư | C21: Nhà cung cấp | D21: Công suất | E21: Đơn giá ( chưa bao gồm VAT) | F21: H.S 40% | H21: H.S 60% | J21: H.S 80% | L21: H.S 100%
F22: Số lượng | G22: Tổng giá trị (VND) | H22: Số lượng | I22: Tổng giá trị (VND) | J22: Số lượng | K22: Tổng giá trị (VND) | L22: Số lượng | M22: Tổng giá trị (VND)
A23: I | B23: THIẾT BỊ PHỤC VỤ SẢN XUẤT | G23: =G24 -> 0 | I23: =I24 -> 0 | K23: =K24 -> 0 | M23: =M24 -> 0
A24: 1
B25: TỔNG | G25: =G23 -> 0 | I25: =I23 -> 0 | K25: =K23 -> 0 | M25: =M23 -> 0

Sheet C.Suất
B2: KẾ HOẠCH CÔNG SUẤT THEO CÔNG ĐOẠN VÀ ĐỊNH BIÊN LAO ĐỘNG TRỰC TIẾP
B3: 1/ CHUYỀN PHÂN LOẠI CHAI GĐ 1: | D3: Lưu ý: xác định rõ công suất của từng máy ở mỗi công đoạn để xác định bottle neck (nếu có) và tối ưu đầu tư!
B4: STT | C4: Công sản xuất: | D4: 1 - Cấp liệu | E4: 2 - Phá kiện | F4: 3 - Sàn tách tạp chất | G4: 4 - Lựa phân loại chai | H4: 5 - Tách nhãn 1 | I4: 6 - Lựa phân loại chai sau tách nhãn 1 | J4: 7 - Ép kiện 1 | K4: 8 - Tách nhãn 2 | L4: 9 - Lựa phân loại chai sau tách nhãn 2 | M4: 10 - Ép kiện 2 | N4: 11- Nhập/xuất kho | O4: Công suất thành phẩm cả chuyền
B5: 1 | C5: Tên máy móc thiết bị: | D5: Băng tải cấp liệu | F5: Lồng quay tách tạp chất | G5: Chuyền phân loại (5 loại) | H5: Máy tách nhãn 1 | I5: Chuyền phân loại | J5: Máy ép kiện + xe nâng tay | N5: Xe nâng | O5: Giả định hao hụt 10%
B6: 2 | C6: Công suất THIẾT KẾ: (Kg NVL đầu vào / giờ) | D6: 3000 | F6: 3000 | G6: 3000 | H6: 1000 | I6: 3000 | J6: 1500 | N6: =J6 -> 1500 | O6: =MIN(D6:N6) -> 1000
B7: 3 | C7: Công suất ĐỊNH MỨC: (Kg NVL đầu vào / giờ) | D7: 3000 | F7: 3000 | G7: 3000 | H7: 800 | I7: =H7*90% -> 720 | J7: =I7 -> 720 | N7: =J7 -> 720 | O7: =MIN(D7:N7) -> 720
B8: 4 | C8: Định mức công nhân sản xuất: (Số NV / Ca8) | D8: 2 | F8: 0 | G8: 1 | H8: 1 | I8: 1 | J8: 1 | N8: 0 | O8: =SUM(D8:N8) -> 6
C9: Diễn giải: | D9: 1 NV khuân hàng, 1NV cắt đổ bao | G9: NV lựa chai B4 và tạp bì | H9: NV kéo và thay các bao: nhãn, tạp bì trả, chai còn nhãn | I9: - 1 NV phân loại chai còn nhãn + nắp | J9: - 1 NV ép kiện, ép: thành phẩm, phế liệu, phó sản. | N9: - 1 NV ép kiện kiêm nhiệm
C10: Định mức kỹ thuật vận hành: (Số NV / Ca8) | F10: 1 kỹ thuật toàn chuyền | O10: 1
B12: 2/ CHUYỀN PHÂN LOẠI CHAI GĐ 2:
B13: STT | C13: Công sản xuất: | D13: 1 - Cấp liệu | E13: 2 - Phá kiện | F13: 3 - Sàn tách tạp chất | G13: 4 - Lựa phân loại chai | H13: 5 - Tách nhãn 1 | I13: 6 - Lựa phân loại chai sau tách nhãn 1 | J13: 7 - Ép kiện 1 | K13: 8 - Tách nhãn 2 | L13: 9 - Lựa phân loại chai sau tách nhãn 2 | M13: 10 - Ép kiện 2 | N13: 11- Nhập/xuất kho | O13: Công suất thành phẩm cả chuyền
B14: 1 | C14: Tên máy móc thiết bị: | D14: Băng tải cấp liệu | E14: Máy phá kiện (thủ công hay tự động) + băng tải phụ trợ | F14: Lồng quay tách tạp chất | G14: Chuyền phân loại (5 loại) | H14: Máy tách nhãn 1 | I14: Chuyền phân loại 1 | J14: Máy ép kiện 1 + xe nâng tay | K14: Máy tách nhãn 2 | L14: Chuyền phân loại 2 | M14: Máy ép kiện 2 | N14: Xe nâng | O14: Giả định hao hụt 10%
B15: 2 | C15: Công suất THIẾT KẾ: (Kg NVL đầu vào / giờ) | D15: 3000 | E15: 2000 | F15: 3000 | G15: 3000 | H15: 1000 | I15: 3000 | J15: 1500 | K15: 1000 | L15: 3000 | M15: 1500 | N15: =J15 -> 1500 | O15: =1500 -> 1500
B16: 3 | C16: Công suất ĐỊNH MỨC: (Kg NVL đầu vào / giờ) | D16: 3000 | E16: 2000 | F16: 3000 | G16: 3000 | H16: 800 | I16: =H16*0.9 -> 720 | J16: =I16 -> 720 | K16: 800 | L16: =K16*0.9 -> 720 | M16: =L16 -> 720 | N16: =J16 -> 720 | O16: =J16 -> 720
B17: 4 | C17: Định mức nhân công: (Số NV / Ca8) | D17: 2 | F17: 0 | G17: 1 | H17: 1 | I17: 1 | J17: 1 | K17: 0 | L17: 1 | M17: 1 | N17: 0 | O17: =SUM(D17:N17) -> 8
C18: Diễn giải: | D18: Luân chuyển 2 NV line 1: 1NV lái xe nâng, 1NV cắt dây | G18: NV lựa chai B4 và tạp bì | H18: NV kéo và thay các bao: nhãn, tạp bì trả, chai còn nhãn (2 line) | I18: - 1 NV phân loại chai còn nhãn + nắp | J18: - 1 NV ép kiện, ép: thành phẩm, phế liệu, phó sản. | K18: NV kéo và thay các bao: kiêm nhiệm | L18: - 1 NV phân loại chai còn nhãn + nắp | M18: - 1 NV ép kiện kiêm nhiệm | N18: - 1 NV ép kiện kiêm nhiệm
C19: Định mức kỹ thuật vận hành: (Số NV / Ca8) | F19: 1 kỹ thuật toàn chuyền | O19: 1

Sheet Đ.Biên
B1: ĐỊNH BIÊN NHÂN SỰ
B2: I - ĐỊNH BIÊN PHÂN LOẠI CHAI | K2: ĐVT: Người
B3: STT | C3: Phòng ban | D3: Tài khoản | E3: H.S 40% | F3: H.S 60% | G3: H.S 80% | H3: H.S 100% | I3: Lương cơ bản/ tháng | J3: Số Ca SX | K3: Ghi chú
C4: Số Ca sản xuất | E4: =G.Định!F18 -> 1 | F4: =G.Định!H18 -> 2 | G4: =G.Định!J18 -> 2.5 | H4: =G.Định!L18 -> 3
B5: 1 | C5: Ban giám đốc | D5: 642 | E5: =SUM(E6:E7) -> 1 | F5: =SUM(F6:F7) -> 1 | G5: =SUM(G6:G7) -> 1 | H5: =SUM(H6:H7) -> 1
C6: Giám đốc Trạm | E6: 1 | F6: 1 | G6: 1 | H6: 1 | I6: 70000000 | J6: 1 | K6: Kiêm người ĐDPL
C7: Người đại diện pháp luật | J7: 1
B8: 2 | C8: Phòng Hành chánh nhân sự | D8: 642 | E8: =SUM(E9:E12) -> 3 | F8: =SUM(F9:F12) -> 3 | G8: =SUM(G9:G12) -> 3 | H8: =SUM(H9:H12) -> 3
C9: Trưởng phòng nhân sự | E9: 1 | F9: 1 | G9: 1 | H9: 1 | I9: 28000000 | J9: 1
C10: Nhân viên hành chính | E10: 1 | F10: 1 | G10: 1 | H10: 1 | I10: 12000000 | J10: 1
C11: Nhân viên nhân sự | I11: 12000000 | J11: 1
C12: Nhân viên tạp vụ | E12: 1 | F12: 1 | G12: 1 | H12: 1 | I12: 8000000 | J12: 1
B13: 3 | C13: Phòng Kế toán | D13: 642 | E13: =SUM(E14:E16) -> 3 | F13: =SUM(F14:F16) -> 3 | G13: =SUM(G14:G16) -> 3 | H13: =SUM(H14:H16) -> 3
C14: Kế toán trưởng | E14: 1 | F14: 1 | G14: 1 | H14: 1 | I14: 28000000 | J14: 1
C15: Kế toán tổng hợp | E15: 1 | F15: 1 | G15: 1 | H15: 1 | I15: 18000000 | J15: 1
C16: Kế toán viên | E16: 1 | F16: 1 | G16: 1 | H16: 1 | I16: 12000000 | J16: 1
B17: 4 | C17: Phòng Cung ứng | D17: 642 | E17: =E18 -> 0 | F17: =F18 -> 1 | G17: =G18 -> 1 | H17: =H18 -> 1
C18: Nhân viên mua hàng/ nhận hàng | F18: 1 | G18: 1 | H18: 1 | I18: 12000000 | J18: 1
B19: 5 | C19: Phòng Mua hàng (Bao gồm NVL + Vật tư) | D19: 642 | E19: =E20 -> 1 | F19: =F20 -> 1 | G19: =G20 -> 1 | H19: =H20 -> 1
C20: Nhân viên mua hàng (ngoại trừ mua chai) | E20: 1 | F20: 1 | G20: 1 | H20: 1 | I20: 12000000 | J20: 1
B21: 6 | C21: Phòng Quản Trị Hệ Thống | D21: 642 | E21: =E22 -> 0 | F21: =F22 -> 1 | G21: =G22 -> 1 | H21: =H22 -> 1
C22: Nhân viên QTHT (ISO, 3Q,…) | F22: 1 | G22: 1 | H22: 1 | I22: 12000000 | J22: 1
B23: 7 | C23: Phòng 5S & an toàn | D23: 642 | E23: =E24 -> 0 | F23: =F24 -> 1 | G23: =G24 -> 1 | H23: =H24 -> 1
C24: Nhân viên 5S & an toàn | F24: 1 | G24: 1 | H24: 1 | I24: 12000000 | J24: 1
B25: 8 | C25: Phòng Kho vận (NVL+TP) | D25: 627 | E25: =SUM(E26:E27) -> 2 | F25: =SUM(F26:F27) -> 3 | G25: =SUM(G26:G27) -> 5 | H25: =SUM(H26:H27) -> 5
C26: Thủ kho (phiếu nhập, xuất, quản lý kho) | F26: 1 | G26: 1 | H26: 1 | I26: 12000000 | J26: 1
C27: Nhân viên xuống/lên hàng (1 nhập NVL, 1 xuất TP) | E27: 2 | F27: 2 | G27: 4 | H27: 4 | I27: 10000000 | J27: 1
B28: 9 | C28: Phòng Kiểm soát chất lượng | D28: 627 | E28: =SUM(E29:E30) -> 1 | F28: =SUM(F29:F30) -> 2 | G28: =SUM(G29:G30) -> 3 | H28: =SUM(H29:H30) -> 3
C29: Kiểm soát chất lượng NVL nhập - 1 ca hành chánh | E29: 1 | F29: 1 | G29: 1 | H29: 1 | I29: 12000000 | J29: 1
C30: Kiểm soát chất lượng thành phẩm (1 ca) | F30: 1 | G30: 2 | H30: 2 | I30: 12000000 | J30: 1 | K30: Theo Ca
B31: 10 | C31: Phòng Kỹ thuật | D31: 627 | E31: =SUM(E32:E33) -> 2 | F31: =SUM(F32:F33) -> 3 | G31: =SUM(G32:G33) -> 5 | H31: =SUM(H32:H33) -> 5
C32: Tổ trưởng kỹ thuật | E32: 1 | F32: 1 | G32: 1 | H32: 1 | I32: 12000000 | J32: 1
C33: Nhân viên bảo trì (1 điện, 1 cơ) (1 ca) | E33: 1 | F33: =E33*2 -> 2 | G33: 4 | H33: 4 | I33: 10000000 | J33: 1 | K33: Theo Ca
B34: 11 | C34: Phòng Sản xuất | E34: =E35+E39 -> 12 | F34: =F35+F39 -> 20 | G34: =G35+G39 -> 25 | H34: =H35+H39 -> 29
B35: 11.1 | C35: Bộ phận quản lý sản xuất | D35: 627 | E35: =SUM(E36:E38) -> 3 | F35: =SUM(F36:F38) -> 4 | G35: =SUM(G36:G38) -> 4 | H35: =SUM(H36:H38) -> 4
C36: Quản lý sản xuất | E36: 1 | F36: 1 | G36: 1 | H36: 1 | I36: 40000000 | J36: 1
C37: Tổ trưởng sản xuất (1 ca) | E37: 1 | F37: =E37*2 -> 2 | G37: 2 | H37: 2 | I37: 12000000 | J37: 1 | K37: Theo Ca
C38: Kế hoạch sản xuất | E38: 1 | F38: 1 | G38: 1 | H38: 1 | I38: 10000000 | J38: 1
B39: 11.2 | C39: Công nhân trực tiếp sản xuất | D39: 622 | E39: =E40+E41 -> 9 | F39: =F40+F41 -> 16 | G39: =G40+G41 -> 21 | H39: =H40+H41 -> 25
C40: Nhân viên phân loại (1ca) | E40: 7 | F40: =E40*2 -> 14 | G40: 17 | H40: =E40*3 -> 21 | I40: 8000000 | J40: 1 | K40: Theo Ca
...

Sheet DMSX
A3: ĐỊNH MỨC BIẾN PHÍ SẢN XUẤT | I3: ĐVT: Đồng
A4: STT | B4: Khoản mục phí | C4: ĐVT | D4: Số lượng tiêu hao | E4: Đơn giá | F4: Tổng chi phí | G4: Định mức thành phẩm (kg) | H4: Chi phí đồng/ kg sản phẩm | I4: Ghi chú
A5: I | B5: ĐỊNH MỨC PHÂN LOẠI CHAI
A6: 1 | B6: Chi phí điện sản xuất | C6: Kw/h | D6: ='DMSX C.tiết'!C9 -> 130.8 | E6: 2100 | F6: =D6*E6 -> 274680 | G6: 2700 | H6: =F6/G6 -> 101.73333 | I6: Công suất 1 chuyền/h = 2.700 kg
A7: 2 | B7: Chi phí dây đai | C7: Cuộn/kiện chai | D7: 0.35 | E7: 51000 | F7: =D7*E7 -> 17850 | G7: 230 | H7: =F7/G7 -> 77.608696 | I7: 1 kiện chai = 230 kg
A8: 3 | B8: Chi phí dao tách nhãn | C8: Bộ | D8: 1 | E8: 165000000 | F8: =D8*E8 -> 165000000 | G8: 1500000 | H8: =F8/G8 -> 110 | I8: 1 bộ băm được 1,5 tấn
A9: 4 | B9: Vật tư khác phục vụ sản xuất
A10: 5 | B10: Chi phí xăng, dầu xe nâng | C10: Lít/h | D10: 2.7 | E10: 15000 | F10: =D10*E10 -> 40500 | G10: =2700/2 -> 1350 | H10: =F10/G10 -> 30 | I10: CĐ băm sử dụng 2 xe nâng
A11: 6 | B11: Chi phí xử lý rác thải CN (nhãn) | C11: Đồng/kg nhãn | D11: 1 | E11: 300 | F11: =D11*E11 -> 300 | G11: =D11/5% -> 20 | H11: =F11/G11 -> 15 | I11: Thuê xử lý nhãn chai, tỷ lệ hao huạt nhãn 5%
A12: 7 | B12: Chi phí sửa chữa, bảo trì MMTB sản xuất | C12: % giá trị MMTB
A13: 8 | B13: Chi phí sửa chữa, bảo trì xe nâng | C13: Đồng/tháng/chiếc | D13: 2 | E13: 3000000 | F13: =D13*E13 -> 6000000 | G13: =G6*16*26 -> 1123200 | H13: =F13/G13 -> 5.3418803 | I13: Sửa chữa xe nâng
A14: II | B14: CÔNG ĐOẠN BĂM VẢY
A15: 1 | B15: Chi phí điện sản xuất | C15: Kw/h | D15: ='DMSX C.tiết'!C19 -> 197.16 | E15: 2200 | F15: =D15*E15 -> 433752 | G15: 1650 | H15: =F15/G15 -> 262.88 | I15: Công suất băm/h = 1.650 kg; Máy chính: 255kwh/giờ - Máy phụ: 90kwh/giờ
A16: 2 | B16: Chi phí hóa chất (rửa vảy)
A17: 3 | B17: Chi phí dao băm vảy | C17: Bộ | D17: 1 | E17: =ROUND('DMSX C.tiết'!H28,-6) -> 72000000 | F17: =D17*E17 -> 72000000 | G17: =ROUND('DMSX C.tiết'!H28/'DMSX C.tiết'!I28,-5) -> 700000 | H17: =F17/G17 -> 102.85714 | I17: 1 bộ băm được 700 tấn
A18: 4 | B18: Chi phí bao jumbo đựng vảy | C18: Bao | D18: 1 | E18: 71000 | F18: =D18*E18 -> 71000 | G18: 450 | H18: =F18/G18 -> 157.77778 | I18: 1 bao jumbo vảy = 450 kg
A19: 5 | B19: Vật tư khác phục vụ sản xuất
A20: 6 | B20: Chi phí nước sản xuất (băm, rửa vảy) | C20: m3/h | D20: 3 | E20: 11500 | F20: =D20*E20 -> 34500 | G20: 1650 | H20: =F20/G20 -> 20.909091
A21: 7 | B21: Chi phí xăng, dầu xe nâng | C21: Lít/h | D21: 2.7 | E21: 15000 | F21: =D21*E21 -> 40500 | G21: 1650 | H21: =F21/G21 -> 24.545455 | I21: CĐ băm sử dụng 1 xe nâng
A22: 8 | B22: Chi phí xử lý nước thải | C22: m3/h | D22: =D20 -> 3 | E22: 50000 | F22: =D22*E22 -> 150000 | G22: 1650 | H22: =F22/G22 -> 90.909091 | I22: Hóa chất XLNT
A23: 9 | B23: Chi phí xử lý bùn thải | C23: đồng/kg bùn thải | D23: =G15*3% -> 49.5 | E23: 1200 | F23: =D23*E23 -> 59400 | G23: 1650 | H23: =F23/G23 -> 36 | I23: Hao hụt bùn đất 3%
A24: 10 | B24: Chi phí sửa chữa, bảo trì MMTB sản xuất | C24: % giá trị MMTB
A25: 11 | B25: Chi phí sửa chữa, bảo trì xe nâng | C25: đồng/tháng/chiếc | D25: 1 | E25: 3000000 | F25: =D25*E25 -> 3000000 | G25: =1650*16*26 -> 686400 | H25: =F25/G25 -> 4.3706294 | I25: Sửa chữa xe nâng
A26: III | B26: ĐỊNH MỨC VẬN CHUYỂN
A27: 1 | B27: Chi phí vận chuyển chai | C27: Chuyến | D27: 1 | E27: =1500000 -> 1500000 | F27: =D27*E27 -> 1500000 | G27: 8000 | H27: =F27/G27 -> 187.5 | I27: Xe trọng tải 10 tấn, chở được 8 tấn chai
A28: 2 | B28: Chi phí vận chuyển vảy | C28: Km

Sheet DMSX C.tiết
B1: ĐỊNH MỨC SX CHI TIẾT
B2: 1 - Định mức điện Chuyền AI (1 chuyền)
B3: Tên MMTB sử dụng điện | C3: Số điện sử dụng kwh/ giờ | D3: Số điện sử dụng kwh/ 1 kg TP
B4: Hệ thống máy Sort + TB phụ | C4: 85 | D4: =C4/$E$24 -> 1.4166667e-05
B5: 2 Chuyền phân loại chai | C5: 31 | D5: =C5/$E$24 -> 5.1666667e-06
B6: Tách nhãn BRT | C6: 57 | D6: =C6/$E$24 -> 9.5e-06
B7: Máy nén khí phân loại 80% | C7: =90*50% -> 45 | D7: =C7/$E$24 -> 7.5e-06
B8: Định mức thiết kế HT AI | C8: =SUM(C4:C7) -> 218 | D8: =C8/$E$24 -> 3.6333333e-05
B9: Thực tế tiêu hao 62% | C9: =C8*60% -> 130.8 | D9: =C9/$E$24 -> 2.18e-05
B11: 2 - Định mức điện chuyền băm vảy
B12: Tên MMTB sử dụng điện | C12: Số điện sử dụng kwh/ giờ
B13: Máy phá kiện | C13: 25
B14: Hệ thống băm thô | C14: 255
B15: Hệ thống rửa lạnh
B16: Thiết bị phụ trợ: Bơm nước, HT li tâm | C16: 20
B17: Máy nén khí phân loại 20% | C17: =90*20% -> 18
B18: Định mức thiết kế | C18: =SUM(C13:C17) -> 318
B19: Thực tế tiêu hao 62% | C19: =C18*62% -> 197.16
B21: 3 - Định mức dao băm vảy
B22: Nội dung | C22: Đơn vị tính | D22: Số lượng | E22: Đơn giá | F22: Sản lượng SX / 1 lưỡi dao (Tấn/1 lưỡi dao) | G22: Sản lượng SX / 1 bộ dao (kg/1 bộ dao) | H22: Tổng CP | I22: Đồng/kg
B23: Dao băm động - chiều dài 60cm | C23: Cái | D23: 14 | E23: 2400000 | F23: 46 | G23: =D23*F23 -> 644 | H23: =D23*E23 -> 33600000 | I23: =(D23*E23)/G23/1000 -> 52.173913
B24: Dao băm tĩnh - chiều dài 120cm | C24: Cái | D24: 6 | E24: 6000000 | F24: 324 | G24: =D24*F24 -> 1944 | H24: =D24*E24 -> 36000000 | I24: =(D24*E24)/G24/1000 -> 18.518519
B25: Bu long M20x110 | C25: Con | D25: 28 | E25: 23000 | G25: =2*G23 -> 1288 | H25: =D25*E25 -> 644000 | I25: =(D25*E25)/G25/1000 -> 0.5
B26: Bu long M20x70 | C26: Con | D26: 28 | E26: 25000 | G26: 1288 | H26: =D26*E26 -> 700000 | I26: =(D26*E26)/G26/1000 -> 0.54347826
B27: Đá mài dao | C27: Viên | D27: 3 | E27: 464000 | G27: =(D23*D27)+(D24*3) -> 60 | H27: =D27*E27 -> 1392000 | I27: =(D27*E27)/G27/1000 -> 23.2
B28: Tổng cộng | H28: =SUM(H23:H27) -> 72336000 | I28: =SUM(I23:I27)*110% -> 104.4295

Sheet DMQL
B1: ĐỊNH MỨC CHI PHÍ QUẢN LÝ (ĐVT: đồng) | O1: ĐVT: Triệu đồng
B2: STT | C2: Mục phí cấp 1 | D2: Mục phí cấp 2 | E2: Mục phí cấp 3 | F2: Link công thức | G2: H.S 40% | I2: H.S 60% | K2: H.S 80% | M2: H.S 100% | O2: Ghi chú
G3: 1 Tháng | H3: Cả Năm | I3: 1 Tháng | J3: Cả Năm | K3: 1 Tháng | L3: Cả Năm | M3: 1 Tháng | N3: Cả Năm
B4: 1 | C4: Chi phí điện, nước quản lý | D4: Chi phí điện quản lý | E4: Chi phí điện quản lý | F4: Chi phí điện quản lý | G4: 2000000 | I4: 2000000 | K4: 2000000 | M4: 2000000
D5: Chi phí nước sinh hoạt | E5: Chi phí nước sinh hoạt | F5: Chi phí nước sinh hoạt | G5: 3000000 | I5: 3000000 | K5: 3000000 | M5: 3000000
B6: =IF(C6=0,"",MAX($B$4:B5)+1) -> 2 | C6: Chi phí in ấn, vật tư, VPP | D6: Chi phí in ấn, vật tư, VPP | E6: Chi phí thuê máy photo, máy in | F6: Chi phí in ấn, vật tư, VPP | G6: 2000000 | I6: 2000000 | K6: 2000000 | M6: 2000000
B7: =IF(C7=0,"",MAX($B$4:B6)+1) | E7: Chi phí VPP | F7: Chi phí in ấn, vật tư, VPP | G7: 2000000 | I7: 2000000 | K7: 2000000 | M7: 2000000
B8: =IF(C8=0,"",MAX($B$4:B7)+1) | E8: Chi phí mực in, mực photo | F8: Chi phí in ấn, vật tư, VPP | G8: 200000 | I8: 200000 | K8: 200000 | M8: 200000
B9: =IF(C9=0,"",MAX($B$4:B8)+1) | E9: Chi phí công chứng, sao y, thuế khác | F9: Chi phí in ấn, vật tư, VPP | G9: 300000 | I9: 300000 | K9: 300000 | M9: 300000
B10: =IF(C10=0,"",MAX($B$4:B9)+1) | E10: Chi phí vật dụng quản lý khác | F10: Chi phí in ấn, vật tư, VPP
B11: =IF(C11=0,"",MAX($B$4:B10)+1) -> 3 | C11: Thuế, phí, lệ phí, bồi thường, nộp phạt, khếu nại khách hàng | D11: Thuế, phí, lệ phí | E11: Thuế môn bài | F11: Thuế, phí, lệ phí | H11: 3000000 | J11: 3000000 | L11: 3000000 | N11: 3000000 | O11: Vốn >10 tỷ = 3 triệu
E12: Thuế, phí, lệ phí khác | F12: Thuế, phí, lệ phí
B13: =IF(C13=0,"",MAX($B$4:B11)+1) -> 4 | C13: Chi phí bảo hiểm tài sản | D13: Chi phí bảo hiểm tài sản | E13: Chi phí bảo hiểm tài sản | F13: Chi phí bảo hiểm tài sản | H13: ='K.Hao, L.v'!C12*0.2% -> 44380012 | J13: ='K.Hao, L.v'!D12*0.2% -> 44380012 | L13: ='K.Hao, L.v'!E12*0.2% -> 44380012 | N13: ='K.Hao, L.v'!F12*0.2% -> 44380012 | O13: Cháy nổ bắt buộc (0.2% giá trị TS)
B14: =IF(C14=0,"",MAX($B$4:B13)+1) -> 5 | C14: Chi phí ủng hộ, hỗ trợ, tài trợ | D14: Chi phí ủng hộ, hỗ trợ, tài trợ | E14: Chi phí ủng hộ, hỗ trợ, tài trợ | F14: Chi phí ủng hộ, hỗ trợ, tài trợ | G14: 2000000 | I14: 2000000 | K14: 2000000 | M14: 2000000
B15: 6 | C15: Chi phí internet, điện thoại, bưu phẩm | D15: Chi phí internet, điện thoại, bưu phẩm | E15: Chi phí internet | F15: Chi phí internet, điện thoại, bưu phẩm | G15: 1000000 | I15: 1000000 | K15: 1000000 | M15: 1000000
E16: Chi phí điện thoại bàn | F16: Chi phí internet, điện thoại, bưu phẩm | G16: 200000 | I16: 200000 | K16: 200000 | M16: 200000
E17: Chi phí bưu phẩm | F17: Chi phí internet, điện thoại, bưu phẩm | G17: 300000 | I17: 300000 | K17: 300000 | M17: 300000
B18: 7 | C18: Chi phí tiếp khách | D18: Chi phí tiếp khách | E18: Chi phí tiếp khách | F18: Chi phí tiếp khách | G18: =3000000 -> 3000000 | I18: =3000000 -> 3000000 | K18: =3000000 -> 3000000 | M18: =3000000 -> 3000000
B19: =IF(C19=0,"",MAX($B$4:B18)+1) | E19: Chi phí quà tặng khách | F19: Chi phí tiếp khách | H19: 10000000 | J19: 10000000 | L19: 10000000 | N19: 10000000 | O19: Quà tặng lễ tết
B20: =IF(C20=0,"",MAX($B$4:B19)+1) | E20: Chi phí bồi dưỡng | F20: Chi phí tiếp khách
B21: 8 | C21: Chi phí công tác | D21: Chi phí công tác | E21: Vé máy bay, xe | F21: Chi phí công tác | G21: 1000000 | I21: 1000000 | K21: 1000000 | M21: 1000000
E22: Khách sạn | F22: Chi phí công tác | G22: 500000 | I22: 500000 | K22: 500000 | M22: 500000
B23: 9 | C23: Chi phí hành chánh văn phòng | D23: Chi phí hành chánh văn phòng | E23: Chi phí nước uống | F23: Chi phí nước uống | G23: 5000000 | I23: 5000000 | K23: 5000000 | M23: 5000000
B24: =IF(C24=0,"",MAX($B$4:B23)+1) | E24: Chi phí cà phê, bánh phòng họp | F24: Chi phí khác
B25: =IF(C25=0,"",MAX($B$4:B24)+1) | E25: Chi phí trang trí văn phòng | F25: Chi phí khác | H25: 5000000 | J25: 5000000 | L25: 5000000 | N25: 5000000 | O25: Trang trí lễ tết
B26: =IF(C26=0,"",MAX($B$4:B25)+1) | E26: Chi phí 5S, an toàn lao động, PCCC | F26: Chi phí 5S, an toàn lao động, PCCC | G26: 1000000 | I26: 1000000 | K26: 1000000 | M26: 1000000
B27: =IF(C27=0,"",MAX($B$4:B26)+1) | E27: Chi phí rác thải sinh hoạt, rác y tế | F27: Chi phí khác | G27: 500000 | I27: 500000 | K27: 500000 | M27: 500000
B28: =IF(C28=0,"",MAX($B$4:B27)+1) | E28: Chi phí kiểm soát côn trùng | F28: Chi phí khác
B29: =IF(C29=0,"",MAX($B$4:B28)+1) | E29: Chi phí vật tư quản lý | F29: Chi phí khác
B30: =IF(C30=0,"",MAX($B$4:B29)+1) | E30: Chi phí hành chánh văn phòng khác | F30: Chi phí khác
B31: =IF(C31=0,"",MAX($B$4:B30)+1) -> 10 | C31: Phúc lợi nhân viên | D31: Chi phí y tế, khám sức khỏe, bảo hiểm sức khỏe | E31: Chi phí y tế, khám sức khỏe, bảo hiểm sức khỏe | F31: Chi phí y tế, khám sức khỏe, bảo hiểm sức khỏe | H31: =Đ.Biên!$E$57*1000000 -> 25000000 | J31: =Đ.Biên!$F$57*1000000 -> 39000000 | L31: =Đ.Biên!$G$57*1000000 -> 49000000 | N31: =Đ.Biên!$H$57*1000000 -> 53000000 | O31: 1 triệu/đồng/người
B32: =IF(C32=0,"",MAX($B$4:B31)+1) | D32: Chi phí suất ăn, tiền ăn giữa ca | E32: Chi phí suất ăn, tiền ăn giữa ca | F32: Chi phí suất ăn, tiền ăn giữa ca | H32: =Đ.Biên!$E$57*30000*26 -> 19500000 | J32: =Đ.Biên!$F$57*30000*26 -> 30420000 | L32: =Đ.Biên!$G$57*30000*26 -> 38220000 | N32: =Đ.Biên!$H$57*30000*26 -> 41340000 | O32: 30.000 đồng/người
B33: =IF(C33=0,"",MAX($B$4:B32)+1) | D33: Chi phí đồng phục, đồ bảo hộ lao động | E33: Chi phí đồng phục | F33: Chi phí đồng phục, đồ bảo hộ lao động | H33: =Đ.Biên!$E$57*800000 -> 20000000 | J33: =Đ.Biên!$F$57*800000 -> 31200000 | L33: =Đ.Biên!$G$57*800000 -> 39200000 | N33: =Đ.Biên!$H$57*800000 -> 42400000 | O33: 800.000 đồng/người
B34: =IF(C34=0,"",MAX($B$4:B33)+1) | E34: Chi phí đồ bảo hộ lao động | F34: Chi phí đồng phục, đồ bảo hộ lao động | G34: 1500000 | I34: 1500000 | K34: 1500000 | M34: 1500000
B35: =IF(C35=0,"",MAX($B$4:B34)+1) | D35: Chi phí tiệc tất niên, tổng kết | E35: Chi phí tiệc tất niên, tổng kết | F35: Chi phí tiệc tất niên, tổng kết | H35: =Đ.Biên!$E$57*1000000 -> 25000000 | J35: =Đ.Biên!$F$57*1000000 -> 39000000 | L35: =Đ.Biên!$G$57*1000000 -> 49000000 | N35: =Đ.Biên!$H$57*1000000 -> 53000000 | O35: 1 triệu/đồng/người (gồm chi phí chung)
B36: =IF(C36=0,"",MAX($B$4:B35)+1) | D36: Chi phí teambuilding | E36: Chi phí teambuilding | F36: Chi phí teambuilding | H36: =Đ.Biên!$E$57*4000000 -> 100000000 | J36: =Đ.Biên!$F$57*4000000 -> 156000000 | L36: =Đ.Biên!$G$57*4000000 -> 196000000 | N36: =Đ.Biên!$H$57*4000000 -> 212000000 | O36: 4 triệu/đồng/người (gồm chi phí chung)
B37: =IF(C37=0,"",MAX($B$4:B36)+1) | D37: Chi phí thuê xe đưa rước nhân viên | E37: Chi phí thuê xe đưa rước nhân viên | F37: Chi phí thuê xe đưa rước nhân viên
B38: =IF(C38=0,"",MAX($B$4:B37)+1) | D38: Chi phí tuyển dụng | E38: Chi phí tuyển dụng | F38: Chi phí tuyển dụng, đào tạo
B39: =IF(C39=0,"",MAX($B$4:B38)+1) | D39: Chi phí đào tạo | E39: Chi phí đào tạo | F39: Chi phí tuyển dụng, đào tạo | G39: 2000000 | I39: 2000000 | K39: 2000000 | M39: 2000000
B40: =IF(C40=0,"",MAX($B$4:B39)+1) | D40: Chi phí phúc lợi nhân viên khác | E40: Chi phí phụ cấp điện thoại di động | F40: Chi phí khác | G40: 500000 | I40: 500000 | K40: 500000 | M40: 500000
...

Sheet G.Định
C2: CÁC GIẢ ĐỊNH
C3: Mồ hình sản xuất
C4: Phân loại chai / băm vảy | D4: Phân loại chai | E4: Băm vảy
C5: Chọn: → | D5: x
C7: Công suất thiết kế chuyền | N7: Công suất
C8: Quy mô đầu tư | D8: ĐVT | E8: H.S 40% | F8: H.S 60% | G8: H.S 80% | H8: H.S 100% | N8: 1giờ | O8: 1500 | P8: tấn
C9: Sản lượng NVL đầu vào (Chai B0) | D9: Tấn/Tháng | E9: 1000000 | F9: 1000000 | G9: 1000000 | H9: 1000000 | N9: 1 ca | O9: 8 | P9: giờ
N10: 1 tháng | O10: 30 | P10: ngày
C11: Hiệu suất mong muốn | N11: Công suất 1 ca/1 tháng | O11: =O8*O9*O10 -> 360000 | P11: Tấn
C12: Chỉ tiêu | E12: Các mức hiệu suất máy mong muốn
C13: Hiệu suất_40% | D13: Chọn: → | F13: x
C14: Hiệu suất_60% | H14: x
C15: Hiệu suất_80% | J15: x
C16: Hiệu suất_100% | L16: x
C17: Hiệu suất mong muốn | D17: % | E17: 0.3 | F17: 0.4 | G17: 0.5 | H17: 0.6 | I17: 0.7 | J17: 0.8 | K17: 0.9 | L17: 1
C18: Số Ca sản xuất | D18: Ca | F18: 1 | H18: 2 | J18: 2.5 | L18: 3
C20: 1 - Diện tích xưởng, giá thuê
C21: Chuyền | D21: ĐVT | E21: H.S 40% | F21: H.S 60% | G21: H.S 80% | H21: H.S 100% | I21: Giá thuê (USD) | N21: Tỷ giá USD (đồng)
H22: Chọn: → | J22: x | Q22: x
C23: Phân loại chai | D23: m2 | E23: 3500 | F23: 3500 | G23: 3500 | H23: 3500
C24: Băm vảy | D24: m2
C25: Tổng diện tích | E25: =E23+E24 -> 3500 | F25: =F23+F24 -> 3500 | G25: =G23+G24 -> 3500 | H25: =H23+H24 -> 3500 | I25: =J25-0.5 -> 4 | J25: =K25-0.5 -> 4.5 | K25: 5 | L25: =K25+0.5 -> 5.5 | M25: =L25+0.5 -> 6 | N25: =O25-300 -> 25400 | O25: =P25-300 -> 25700 | P25: 26000 | Q25: =P25+300 -> 26300 | R25: =Q25+300 -> 26600 | S25: =R25+300 -> 26900
C27: 2 - Giá mua chai B0, tỷ lệ mua, % hao hụt
C28: Loại chai nguyên liệu | D28: Giá mua | M28: Tỷ lệ mua chai | Q28: Tỷ lệ hao hụt
C29: Chọn: → | G29: x | O29: x | R29: x
C30: Chai B0 - Xá tròn | D30: =E30-500 -> 8500 | E30: =F30-500 -> 9000 | F30: =G30-500 -> 9500 | G30: 10000 | H30: =G30+500 -> 10500 | I30: =H30+500 -> 11000 | J30: =I30+500 -> 11500 | K30: =J30+500 -> 12000 | L30: =K30+500 -> 12500 | M30: 0.3 | N30: 0.5 | O30: 0.8 | P30: 1 | Q30: =R30-1% -> 0.06 | R30: 0.07 | S30: =R30+1% -> 0.08
C31: Chai B0 - Ép kiện | D31: =E31-500 -> 8500 | E31: =F31-500 -> 9000 | F31: =G31-500 -> 9500 | G31: 10000 | H31: =G31+500 -> 10500 | I31: =H31+500 -> 11000 | J31: =I31+500 -> 11500 | K31: =J31+500 -> 12000 | L31: =K31+500 -> 12500 | M31: 0.7 | N31: 0.5 | O31: 0.2 | P31: 0 | Q31: =R31-1% -> 0.09 | R31: 0.1 | S31: =R31+1% -> 0.11
C32: Chai B1.4 (xô tuyển -> ép kiện) | D32: =E32-500 -> 10500 | E32: =F32-500 -> 11000 | F32: =G32-500 -> 11500 | G32: 12000 | H32: =G32+500 -> 12500 | I32: =H32+500 -> 13000 | J32: =I32+500 -> 13500 | K32: =J32+500 -> 14000 | L32: =K32+500 -> 14500 | M32: 0 | N32: 0 | O32: 0 | P32: 0 | Q32: =R32-1% -> 0.04 | R32: 0.05 | S32: =R32+1% -> 0.06
C33: Tổng: | M33: =SUM(M30:M32) -> 1 | N33: =SUM(N30:N32) -> 1 | O33: =SUM(O30:O32) -> 1 | P33: =SUM(P30:P32) -> 1
C35: 3 - Giá bán chai thành phẩm, vảy (đồng/kg)
C36: Chai thành phẩm | G36: Vảy thành phẩm | K36: → GAP
C37: Loại chai | D37: Giá chai | G37: Loai vảy | H37: Giá vảy
C38: Chọn: → | E38: x | G38: Chọn: → | I38: x
C39: Chai B1 | D39: =E39-500 -> 14500 | E39: ='[1]DG M-B'!$D$7 -> 15000 | F39: =E39+500 -> 15500 | G39: Vảy B1 | H39: =I39-500 -> 16500 | I39: 17000 | J39: =I39+500 -> 17500 | K39: =HLOOKUP("x",$H$38:$J$45,ROWS($H$38:$H39),0)-HLOOKUP("x",$D$38:$F$45,ROWS($H$38:$H39),0) -> 2000
C40: Chai B2.2 | D40: =E40-500 -> 13000 | E40: ='[1]DG M-B'!$D$9 -> 13500 | F40: =E40+500 -> 14000 | G40: Vảy B2.2 | H40: =I40-500 -> 15000 | I40: 15500 | J40: =I40+500 -> 16000 | K40: =HLOOKUP("x",$H$38:$J$45,ROWS($H$38:$H40),0)-HLOOKUP("x",$D$38:$F$45,ROWS($H$38:$H40),0) -> 2000
C41: Chai B4 | D41: =E41-500 -> 11500 | E41: 12000 | F41: =E41+500 -> 12500 | G41: Vảy B4 | H41: =I41-500 -> 14000 | I41: 14500 | J41: =I41+500 -> 15000 | K41: =HLOOKUP("x",$H$38:$J$45,ROWS($H$38:$H41),0)-HLOOKUP("x",$D$38:$F$45,ROWS($H$38:$H41),0) -> 2500
C42: Chai B5 | D42: =E42-500 -> 11500 | E42: 12000 | F42: =E42+500 -> 12500 | G42: Vảy B5 | H42: =I42-500 -> 14000 | I42: 14500 | J42: =I42+500 -> 15000 | K42: =HLOOKUP("x",$H$38:$J$45,ROWS($H$38:$H42),0)-HLOOKUP("x",$D$38:$F$45,ROWS($H$38:$H42),0) -> 2500
C43: Chai B6.2 | D43: =E43-500 -> 13000 | E43: ='[1]DG M-B'!$D$9 -> 13500 | F43: =E43+500 -> 14000 | G43: Vảy B6.2 | H43: =I43-500 -> 16000 | I43: 16500 | J43: =I43+500 -> 17000 | K43: =HLOOKUP("x",$H$38:$J$45,ROWS($H$38:$H43),0)-HLOOKUP("x",$D$38:$F$45,ROWS($H$38:$H43),0) -> 3000
C44: Cổ Chai | D44: =E44-500 -> 7500 | E44: 8000 | F44: =E44+500 -> 8500 | G44: Vảy Cổ Chai | H44: =I44-500 -> 9500 | I44: 10000 | J44: =I44+500 -> 10500 | K44: =HLOOKUP("x",$H$38:$J$45,ROWS($H$38:$H44),0)-HLOOKUP("x",$D$38:$F$45,ROWS($H$38:$H44),0) -> 2000
C45: Nắp chai | D45: =E45-500 -> 7500 | E45: 8000 | F45: =E45+500 -> 8500 | G45: Vảy Nắp chai | H45: =I45-500 -> 9500 | I45: 10000 | J45: =I45+500 -> 10500 | K45: =HLOOKUP("x",$H$38:$J$45,ROWS($H$38:$H45),0)-HLOOKUP("x",$D$38:$F$45,ROWS($H$38:$H45),0) -> 2000
...

Sheet B.đồ
B2: Đầu tư, công suất
B3: Loại chai | C3: Tổng | D3: 1.MMTB chính | E3: 2.Điện, hơi | F3: 3.Thiết bị SX | G3: 4.Thiết bị QL
B4: Công suất thiết kế | C4: =G.Định!E9 -> 1000000 | D4: =G.Định!F9 -> 1000000 | E4: =G.Định!F9 -> 1000000 | F4: =G.Định!G9 -> 1000000 | G4: =G.Định!H9 -> 1000000
B5: Chuyền phân loại chai | C5: =SUM(D5:G5) -> 22190006000 | D5: ='CAP.Chính'!G5 -> 16230006000 | E5: ='CAP.Chính'!G43 -> 4035000000 | F5: ='CAP.Phụ'!G9 -> 1724000000 | G5: ='CAP.Phụ'!G14 -> 201000000
B6: Chuyền băm vảy
B7: Tổng đầu tư | C7: =SUM(C5:C6) -> 22190006000 | D7: =SUM(D5:D6) -> 16230006000 | E7: =SUM(E5:E6) -> 4035000000 | F7: =SUM(F5:F6) -> 1724000000 | G7: =SUM(G5:G6) -> 201000000
B11: Sản lượng, hiệu suất
B12: Loại chai | C12: H.S 40% | D12: H.S 60% | E12: H.S 80% | F12: H.S 100%
B13: SL mua B0 | C13: =S.Lượng!C7 -> 400000 | D13: =S.Lượng!D7 -> 600000 | E13: =S.Lượng!E7 -> 800000 | F13: =S.Lượng!F7 -> 1000000
B14: SL bán Chai | C14: =S.Lượng!C40 -> 369600 | D14: =S.Lượng!D40 -> 554400 | E14: =S.Lượng!E40 -> 739200 | F14: =S.Lượng!F40 -> 924000
B15: SL bán Vảy | C15: =S.Lượng!C29 -> 0 | D15: =S.Lượng!D29 -> 0 | E15: =S.Lượng!E29 -> 0 | F15: =S.Lượng!F29 -> 0
B16: Công suất Chai | C16: =G.Định!E9 -> 1000000 | D16: =G.Định!F9 -> 1000000 | E16: =G.Định!G9 -> 1000000 | F16: =G.Định!H9 -> 1000000
B17: Công suất Vay | C17: =C16 -> 1000000 | D17: =D16 -> 1000000 | E17: =E16 -> 1000000 | F17: =F16 -> 1000000
B18: Hiệu suất Chai | C18: =C13/C16 -> 0.4 | D18: =D13/D16 -> 0.6 | E18: =E13/E16 -> 0.8 | F18: =F13/F16 -> 1
B19: Hiệu suất Vảy | C19: =S.Lượng!C54/B.đồ!C17 -> 0 | D19: =S.Lượng!D54/B.đồ!D17 -> 0 | E19: =S.Lượng!E54/B.đồ!E17 -> 0 | F19: =S.Lượng!F54/B.đồ!F17 -> 0
B22: Doanh thu, lợi nhuận
B23: Loại chai | C23: H.S 40% | D23: H.S 60% | E23: H.S 80% | F23: H.S 100%
B24: Doanh thu | C24: =KQKD!H5 -> 63302400000 | D24: =KQKD!I5 -> 94953600000 | E24: =KQKD!J5 -> 126604800000 | F24: =KQKD!K5 -> 158256000000
B25: Lãi biến phí | C25: =KQKD!H28 -> 1.2982154e+10 | D25: =KQKD!I28 -> 1.9473231e+10 | E25: =KQKD!J28 -> 2.5964308e+10 | F25: =KQKD!K28 -> 3.2455385e+10
B26: % lãi biến phí | C26: =KQKD!H29 -> 0.20508155 | D26: =KQKD!I29 -> 0.20508155 | E26: =KQKD!J29 -> 0.20508155 | F26: =KQKD!K29 -> 0.20508155
B27: LN sau thuế | C27: =KQKD!H103 -> -2.9060747e+09 | D27: =KQKD!I103 -> 1.1007649e+09 | E27: =KQKD!J103 -> 4.9621272e+09 | F27: =KQKD!K103 -> 9.6840719e+09
B28: % LN sau thuế | C28: =KQKD!H104 -> -0.045907813 | D28: =KQKD!I104 -> 0.011592661 | E28: =KQKD!J104 -> 0.039193832 | F28: =KQKD!K104 -> 0.061192447
B29: EBITDA | C29: =KQKD!H105 -> -9.7669923e+08 | D29: =KQKD!I105 -> 3.0301404e+09 | E29: =KQKD!J105 -> 6.8915027e+09 | F29: =KQKD!K105 -> 1.1613447e+10
B30: % EBITDA | C30: =KQKD!H106 -> -0.015429103 | D30: =KQKD!I106 -> 0.031911801 | E30: =KQKD!J106 -> 0.054433187 | F30: =KQKD!K106 -> 0.073383931
B36: Chỉ tiêu | C36: H.S 40% | D36: H.S 60% | E36: H.S 80% | F36: H.S 100%
B37: BIẾN PHÍ | C37: =KQKD!H7 -> 5.0320246e+10 | D37: =KQKD!I7 -> 7.5480369e+10 | E37: =KQKD!J7 -> 1.0064049e+11 | F37: =KQKD!K7 -> 1.2580061e+11
B38: % biến phí | C38: =C37/C41 -> 0.76002726 | D38: =D37/D41 -> 0.80660685 | E38: =E37/E41 -> 0.83586962 | F38: =F37/F41 -> 0.86075834
B39: ĐỊNH PHÍ | C39: =KQKD!H31 -> 1.5888229e+10 | D39: =KQKD!I31 -> 1.8097275e+10 | E39: =KQKD!J31 -> 1.9761649e+10 | F39: =KQKD!K31 -> 2.0350295e+10
B40: % định phí | C40: =C39/C41 -> 0.23997274 | D40: =D39/D41 -> 0.19339315 | E40: =E39/E41 -> 0.16413038 | F40: =F39/F41 -> 0.13924166
B41: TỔNG CHI PHÍ | C41: =C37+C39 -> 6.6208475e+10 | D41: =D37+D39 -> 9.3577644e+10 | E41: =E37+E39 -> 1.2040214e+11 | F41: =F37+F39 -> 1.4615091e+11
B42: % tổng chi phí/ DT | C42: =C41/C24 -> 1.0459078 | D42: =D41/D24 -> 0.98550917 | E42: =E41/E24 -> 0.95100771 | F42: =F41/F24 -> 0.92350944
B44: BIẾN PHÍ | C44: H.S 40% | D44: H.S 60% | E44: H.S 80% | F44: H.S 100%
B45: Biến phí bán hàng | C45: =KQKD!H10 -> 831600000 | D45: =KQKD!I10 -> 1247400000 | E45: =KQKD!J10 -> 1663200000 | F45: =KQKD!K10 -> 2079000000
B46: % biến phí bán hàng | C46: =C45/C49 -> 0.016526151 | D46: =D45/D49 -> 0.016526151 | E46: =E45/E49 -> 0.016526151 | F46: =F45/F49 -> 0.016526151
B47: Biến phí sản xuất | C47: =KQKD!H13 -> 4.9488646e+10 | D47: =KQKD!I13 -> 7.4232969e+10 | E47: =KQKD!J13 -> 9.8977292e+10 | F47: =KQKD!K13 -> 1.2372161e+11
B48: % định phí SX | C48: =C47/C49 -> 0.98347385 | D48: =D47/D49 -> 0.98347385 | E48: =E47/E49 -> 0.98347385 | F48: =F47/F49 -> 0.98347385
B49: Tổng Biến phí | C49: =C37 -> 5.0320246e+10 | D49: =D37 -> 7.5480369e+10 | E49: =E37 -> 1.0064049e+11 | F49: =F37 -> 1.2580061e+11
B51: ĐỊNH PHÍ | C51: H.S 40% | D51: H.S 60% | E51: H.S 80% | F51: H.S 100%
B52: Định phí sản xuất | C52: =KQKD!H34 -> 5.4423794e+09 | D52: =KQKD!I34 -> 5.5262255e+09 | E52: =KQKD!J34 -> 5.6100717e+09 | F52: =KQKD!K34 -> 5.7059178e+09
B53: % định phí sản xuất | C53: =C52/C$62 -> 0.3425416 | D53: =D52/D$62 -> 0.3053623 | E53: =E52/E$62 -> 0.28388682 | F53: =F52/F$62 -> 0.28038502
...

Sheet KQKD
A1: KẾT QUẢ KINH DOANH | K1: ĐVT: triệu đồng
A2: STT | B2: CHỈ TIÊU | D2: BÌNH QUÂN 1 THÁNG | H2: CẢ NĂM
D3: H.S 40% | E3: H.S 60% | F3: H.S 80% | G3: H.S 100% | H3: H.S 40% | I3: H.S 60% | J3: H.S 80% | K3: H.S 100%
A4: 1 | B4: SẢN LƯỢNG BÁN (Tấn) | D4: =S.Lượng!C42 -> 369600 | E4: =S.Lượng!D42 -> 554400 | F4: =S.Lượng!E42 -> 739200 | G4: =S.Lượng!F42 -> 924000 | H4: =D4*12 -> 4435200 | I4: =E4*12 -> 6652800 | J4: =F4*12 -> 8870400 | K4: =G4*12 -> 11088000
A5: 2 | B5: DOANH THU THUẦN | D5: =D.Thu!C24 -> 5275200000 | E5: =D.Thu!D24 -> 7912800000 | F5: =D.Thu!E24 -> 10550400000 | G5: =D.Thu!F24 -> 13188000000 | H5: =D5*12 -> 63302400000 | I5: =E5*12 -> 94953600000 | J5: =F5*12 -> 126604800000 | K5: =G5*12 -> 158256000000
C6: Giá bán / Tấn (Triệu đồng/Tấn) | D6: =D5/D4*1000 -> 14272727 | E6: =E5/E4*1000 -> 14272727 | F6: =F5/F4*1000 -> 14272727 | G6: =G5/G4*1000 -> 14272727 | H6: =H5/H4*1000 -> 14272727 | I6: =I5/I4*1000 -> 14272727 | J6: =J5/J4*1000 -> 14272727 | K6: =K5/K4*1000 -> 14272727
A7: 3 | B7: BIẾN PHÍ | D7: =D10+D13 -> 4.1933538e+09 | E7: =E10+E13 -> 6.2900307e+09 | F7: =F10+F13 -> 8.3867077e+09 | G7: =G10+G13 -> 1.0483385e+10 | H7: =H10+H13 -> 5.0320246e+10 | I7: =I10+I13 -> 7.5480369e+10 | J7: =J10+J13 -> 1.0064049e+11 | K7: =K10+K13 -> 1.2580061e+11
C8: Biến phí / Doanh thu (%) | D8: =IFERROR(D7/D$5,0) -> 0.79491845 | E8: =IFERROR(E7/E$5,0) -> 0.79491845 | F8: =IFERROR(F7/F$5,0) -> 0.79491845 | G8: =IFERROR(G7/G$5,0) -> 0.79491845 | H8: =IFERROR(H7/H$5,0) -> 0.79491845 | I8: =IFERROR(I7/I$5,0) -> 0.79491845 | J8: =IFERROR(J7/J$5,0) -> 0.79491845 | K8: =IFERROR(K7/K$5,0) -> 0.79491845
C9: Biến phí / Tấn (Triệu đồng/Tấn) | D9: =IFERROR(D7/D$4,0)*1000 -> 11345654 | E9: =IFERROR(E7/E$4,0)*1000 -> 11345654 | F9: =IFERROR(F7/F$4,0)*1000 -> 11345654 | G9: =IFERROR(G7/G$4,0)*1000 -> 11345654 | H9: =IFERROR(H7/H$4,0)*1000 -> 11345654 | I9: =IFERROR(I7/I$4,0)*1000 -> 11345654 | J9: =IFERROR(J7/J$4,0)*1000 -> 11345654 | K9: =IFERROR(K7/K$4,0)*1000 -> 11345654
A10: 3.1 | B10: Biến phí bán hàng | D10: =CPBH!C5 -> 69300000 | E10: =CPBH!D5 -> 103950000 | F10: =CPBH!E5 -> 138600000 | G10: =CPBH!F5 -> 173250000 | H10: =D10*12 -> 831600000 | I10: =E10*12 -> 1247400000 | J10: =F10*12 -> 1663200000 | K10: =G10*12 -> 2079000000
C11: Biến phí / Doanh thu (%) | D11: =IFERROR(D10/D$5,0) -> 0.013136943 | E11: =IFERROR(E10/E$5,0) -> 0.013136943 | F11: =IFERROR(F10/F$5,0) -> 0.013136943 | G11: =IFERROR(G10/G$5,0) -> 0.013136943 | H11: =IFERROR(H10/H$5,0) -> 0.013136943 | I11: =IFERROR(I10/I$5,0) -> 0.013136943 | J11: =IFERROR(J10/J$5,0) -> 0.013136943 | K11: =IFERROR(K10/K$5,0) -> 0.013136943
C12: Biến phí / Tấn (Triệu đồng/Tấn) | D12: =IFERROR(D10/D$4,0)*1000 -> 187500 | E12: =IFERROR(E10/E$4,0)*1000 -> 187500 | F12: =IFERROR(F10/F$4,0)*1000 -> 187500 | G12: =IFERROR(G10/G$4,0)*1000 -> 187500 | H12: =IFERROR(H10/H$4,0)*1000 -> 187500 | I12: =IFERROR(I10/I$4,0)*1000 -> 187500 | J12: =IFERROR(J10/J$4,0)*1000 -> 187500 | K12: =IFERROR(K10/K$4,0)*1000 -> 187500
A13: 3.2 | B13: Biến phí sản xuất | D13: =D16+SUM(D18:D27) -> 4.1240538e+09 | E13: =E16+SUM(E18:E27) -> 6.1860807e+09 | F13: =F16+SUM(F18:F27) -> 8.2481077e+09 | G13: =G16+SUM(G18:G27) -> 1.0310135e+10 | H13: =H16+SUM(H18:H27) -> 4.9488646e+10 | I13: =I16+SUM(I18:I27) -> 7.4232969e+10 | J13: =J16+SUM(J18:J27) -> 9.8977292e+10 | K13: =K16+SUM(K18:K27) -> 1.2372161e+11
C14: Biến phí sản xuất/ Doanh thu (%) | D14: =IFERROR(D13/D$5,0) -> 0.78178151 | E14: =IFERROR(E13/E$5,0) -> 0.78178151 | F14: =IFERROR(F13/F$5,0) -> 0.78178151 | G14: =IFERROR(G13/G$5,0) -> 0.78178151 | H14: =IFERROR(H13/H$5,0) -> 0.78178151 | I14: =IFERROR(I13/I$5,0) -> 0.78178151 | J14: =IFERROR(J13/J$5,0) -> 0.78178151 | K14: =IFERROR(K13/K$5,0) -> 0.78178151
C15: Biến phí sản xuất/ Tấn (Triệu đồng/Tấn) | D15: =IFERROR(D13/D$4,0)*1000 -> 11158154 | E15: =IFERROR(E13/E$4,0)*1000 -> 11158154 | F15: =IFERROR(F13/F$4,0)*1000 -> 11158154 | G15: =IFERROR(G13/G$4,0)*1000 -> 11158154 | H15: =IFERROR(H13/H$4,0)*1000 -> 11158154 | I15: =IFERROR(I13/I$4,0)*1000 -> 11158154 | J15: =IFERROR(J13/J$4,0)*1000 -> 11158154 | K15: =IFERROR(K13/K$4,0)*1000 -> 11158154
A16: -1 | C16: Chi phí nguyên liệu (chai B0) | D16: =VLOOKUP($C16,'CPSX-Chai'!$B:$F,COLUMNS('CPSX-Chai'!$B$4:C$4),0) -> 4000000000 | E16: =VLOOKUP($C16,'CPSX-Chai'!$B:$F,COLUMNS('CPSX-Chai'!$B$4:D$4),0) -> 6000000000 | F16: =VLOOKUP($C16,'CPSX-Chai'!$B:$F,COLUMNS('CPSX-Chai'!$B$4:E$4),0) -> 8000000000 | G16: =VLOOKUP($C16,'CPSX-Chai'!$B:$F,COLUMNS('CPSX-Chai'!$B$4:F$4),0) -> 10000000000 | H16: =D16*12 -> 48000000000 | I16: =E16*12 -> 72000000000 | J16: =F16*12 -> 96000000000 | K16: =G16*12 -> 120000000000
C17: Lãi nguyên liệu / Doanh thu (%) | D17: =IFERROR(D16/D$5,0) -> 0.75826509 | E17: =IFERROR(E16/E$5,0) -> 0.75826509 | F17: =IFERROR(F16/F$5,0) -> 0.75826509 | G17: =IFERROR(G16/G$5,0) -> 0.75826509 | H17: =IFERROR(H16/H$5,0) -> 0.75826509 | I17: =IFERROR(I16/I$5,0) -> 0.75826509 | J17: =IFERROR(J16/J$5,0) -> 0.75826509 | K17: =IFERROR(K16/K$5,0) -> 0.75826509
A18: -2 | C18: Chi phí bao jumbo | D18: =VLOOKUP($C18,'CPSX-Chai'!$B:$F,COLUMNS('CPSX-Chai'!$B$4:C$4),0)+VLOOKUP($C18,'CPSX-Vảy'!$B:$F,COLUMNS('CPSX-Vảy'!$B$4:C$4),0) -> 946666.67 | E18: =VLOOKUP($C18,'CPSX-Chai'!$B:$F,COLUMNS('CPSX-Chai'!$B$4:D$4),0)+VLOOKUP($C18,'CPSX-Vảy'!$B:$F,COLUMNS('CPSX-Vảy'!$B$4:D$4),0) -> 1420000 | F18: =VLOOKUP($C18,'CPSX-Chai'!$B:$F,COLUMNS('CPSX-Chai'!$B$4:E$4),0)+VLOOKUP($C18,'CPSX-Vảy'!$B:$F,COLUMNS('CPSX-Vảy'!$B$4:E$4),0) -> 1893333.3 | G18: =VLOOKUP($C18,'CPSX-Chai'!$B:$F,COLUMNS('CPSX-Chai'!$B$4:F$4),0)+VLOOKUP($C18,'CPSX-Vảy'!$B:$F,COLUMNS('CPSX-Vảy'!$B$4:F$4),0) -> 2366666.7 | H18: =D18*12 -> 11360000 | I18: =E18*12 -> 17040000 | J18: =F18*12 -> 22720000 | K18: =G18*12 -> 28400000
A19: -3 | C19: Chi phí dây đai | D19: =VLOOKUP($C19,'CPSX-Chai'!$B:$F,COLUMNS('CPSX-Chai'!$B$4:C$4),0)+VLOOKUP($C19,'CPSX-Vảy'!$B:$F,COLUMNS('CPSX-Vảy'!$B$4:C$4),0) -> 28218522 | E19: =VLOOKUP($C19,'CPSX-Chai'!$B:$F,COLUMNS('CPSX-Chai'!$B$4:D$4),0)+VLOOKUP($C19,'CPSX-Vảy'!$B:$F,COLUMNS('CPSX-Vảy'!$B$4:D$4),0) -> 42327783 | F19: =VLOOKUP($C19,'CPSX-Chai'!$B:$F,COLUMNS('CPSX-Chai'!$B$4:E$4),0)+VLOOKUP($C19,'CPSX-Vảy'!$B:$F,COLUMNS('CPSX-Vảy'!$B$4:E$4),0) -> 56437043 | G19: =VLOOKUP($C19,'CPSX-Chai'!$B:$F,COLUMNS('CPSX-Chai'!$B$4:F$4),0)+VLOOKUP($C19,'CPSX-Vảy'!$B:$F,COLUMNS('CPSX-Vảy'!$B$4:F$4),0) -> 70546304 | H19: =D19*12 -> 3.3862226e+08 | I19: =E19*12 -> 5.0793339e+08 | J19: =F19*12 -> 6.7724452e+08 | K19: =G19*12 -> 8.4655565e+08
A20: -4 | C20: Chi phí điện sản xuất | D20: =VLOOKUP($C20,'CPSX-Chai'!$B:$F,COLUMNS('CPSX-Chai'!$B$4:C$4),0)+VLOOKUP($C20,'CPSX-Vảy'!$B:$F,COLUMNS('CPSX-Vảy'!$B$4:C$4),0) -> 37600640 | E20: =VLOOKUP($C20,'CPSX-Chai'!$B:$F,COLUMNS('CPSX-Chai'!$B$4:D$4),0)+VLOOKUP($C20,'CPSX-Vảy'!$B:$F,COLUMNS('CPSX-Vảy'!$B$4:D$4),0) -> 56400960 | F20: =VLOOKUP($C20,'CPSX-Chai'!$B:$F,COLUMNS('CPSX-Chai'!$B$4:E$4),0)+VLOOKUP($C20,'CPSX-Vảy'!$B:$F,COLUMNS('CPSX-Vảy'!$B$4:E$4),0) -> 75201280 | G20: =VLOOKUP($C20,'CPSX-Chai'!$B:$F,COLUMNS('CPSX-Chai'!$B$4:F$4),0)+VLOOKUP($C20,'CPSX-Vảy'!$B:$F,COLUMNS('CPSX-Vảy'!$B$4:F$4),0) -> 94001600 | H20: =D20*12 -> 4.5120768e+08 | I20: =E20*12 -> 6.7681152e+08 | J20: =F20*12 -> 9.0241536e+08 | K20: =G20*12 -> 1.1280192e+09
A21: -5 | C21: Chi phí nước sản xuất | D21: =VLOOKUP($C21,'CPSX-Chai'!$B:$F,COLUMNS('CPSX-Chai'!$B$4:C$4),0)+VLOOKUP($C21,'CPSX-Vảy'!$B:$F,COLUMNS('CPSX-Vảy'!$B$4:C$4),0) -> 0 | E21: =VLOOKUP($C21,'CPSX-Chai'!$B:$F,COLUMNS('CPSX-Chai'!$B$4:D$4),0)+VLOOKUP($C21,'CPSX-Vảy'!$B:$F,COLUMNS('CPSX-Vảy'!$B$4:D$4),0) -> 0 | F21: =VLOOKUP($C21,'CPSX-Chai'!$B:$F,COLUMNS('CPSX-Chai'!$B$4:E$4),0)+VLOOKUP($C21,'CPSX-Vảy'!$B:$F,COLUMNS('CPSX-Vảy'!$B$4:E$4),0) -> 0 | G21: =VLOOKUP($C21,'CPSX-Chai'!$B:$F,COLUMNS('CPSX-Chai'!$B$4:F$4),0)+VLOOKUP($C21,'CPSX-Vảy'!$B:$F,COLUMNS('CPSX-Vảy'!$B$4:F$4),0) -> 0 | H21: =D21*12 -> 0 | I21: =E21*12 -> 0 | J21: =F21*12 -> 0 | K21: =G21*12 -> 0
A22: -6 | C22: Chi phí xăng, dầu xe nâng | D22: =VLOOKUP($C22,'CPSX-Chai'!$B:$F,COLUMNS('CPSX-Chai'!$B$4:C$4),0)+VLOOKUP($C22,'CPSX-Vảy'!$B:$F,COLUMNS('CPSX-Vảy'!$B$4:C$4),0) -> 11088000 | E22: =VLOOKUP($C22,'CPSX-Chai'!$B:$F,COLUMNS('CPSX-Chai'!$B$4:D$4),0)+VLOOKUP($C22,'CPSX-Vảy'!$B:$F,COLUMNS('CPSX-Vảy'!$B$4:D$4),0) -> 16632000 | F22: =VLOOKUP($C22,'CPSX-Chai'!$B:$F,COLUMNS('CPSX-Chai'!$B$4:E$4),0)+VLOOKUP($C22,'CPSX-Vảy'!$B:$F,COLUMNS('CPSX-Vảy'!$B$4:E$4),0) -> 22176000 | G22: =VLOOKUP($C22,'CPSX-Chai'!$B:$F,COLUMNS('CPSX-Chai'!$B$4:F$4),0)+VLOOKUP($C22,'CPSX-Vảy'!$B:$F,COLUMNS('CPSX-Vảy'!$B$4:F$4),0) -> 27720000 | H22: =D22*12 -> 133056000 | I22: =E22*12 -> 199584000 | J22: =F22*12 -> 266112000 | K22: =G22*12 -> 332640000
A23: -7 | C23: Chi phí xử lý nước thải | D23: =VLOOKUP($C23,'CPSX-Chai'!$B:$F,COLUMNS('CPSX-Chai'!$B$4:C$4),0)+VLOOKUP($C23,'CPSX-Vảy'!$B:$F,COLUMNS('CPSX-Vảy'!$B$4:C$4),0) -> 0 | E23: =VLOOKUP($C23,'CPSX-Chai'!$B:$F,COLUMNS('CPSX-Chai'!$B$4:D$4),0)+VLOOKUP($C23,'CPSX-Vảy'!$B:$F,COLUMNS('CPSX-Vảy'!$B$4:D$4),0) -> 0 | F23: =VLOOKUP($C23,'CPSX-Chai'!$B:$F,COLUMNS('CPSX-Chai'!$B$4:E$4),0)+VLOOKUP($C23,'CPSX-Vảy'!$B:$F,COLUMNS('CPSX-Vảy'!$B$4:E$4),0) -> 0 | G23: =VLOOKUP($C23,'CPSX-Chai'!$B:$F,COLUMNS('CPSX-Chai'!$B$4:F$4),0)+VLOOKUP($C23,'CPSX-Vảy'!$B:$F,COLUMNS('CPSX-Vảy'!$B$4:F$4),0) -> 0 | H23: =D23*12 -> 0 | I23: =E23*12 -> 0 | J23: =F23*12 -> 0 | K23: =G23*12 -> 0
A24: -8 | C24: Chi phí xử lý bùn thải | D24: =VLOOKUP($C24,'CPSX-Chai'!$B:$F,COLUMNS('CPSX-Chai'!$B$4:C$4),0)+VLOOKUP($C24,'CPSX-Vảy'!$B:$F,COLUMNS('CPSX-Vảy'!$B$4:C$4),0) -> 0 | E24: =VLOOKUP($C24,'CPSX-Chai'!$B:$F,COLUMNS('CPSX-Chai'!$B$4:D$4),0)+VLOOKUP($C24,'CPSX-Vảy'!$B:$F,COLUMNS('CPSX-Vảy'!$B$4:D$4),0) -> 0 | F24: =VLOOKUP($C24,'CPSX-Chai'!$B:$F,COLUMNS('CPSX-Chai'!$B$4:E$4),0)+VLOOKUP($C24,'CPSX-Vảy'!$B:$F,COLUMNS('CPSX-Vảy'!$B$4:E$4),0) -> 0 | G24: =VLOOKUP($C24,'CPSX-Chai'!$B:$F,COLUMNS('CPSX-Chai'!$B$4:F$4),0)+VLOOKUP($C24,'CPSX-Vảy'!$B:$F,COLUMNS('CPSX-Vảy'!$B$4:F$4),0) -> 0 | H24: =D24*12 -> 0 | I24: =E24*12 -> 0 | J24: =F24*12 -> 0 | K24: =G24*12 -> 0
A25: -9 | C25: Chi phí xử lý rác thải CN | D25: =VLOOKUP($C25,'CPSX-Chai'!$B:$F,COLUMNS('CPSX-Chai'!$B$4:C$4),0)+VLOOKUP($C25,'CPSX-Vảy'!$B:$F,COLUMNS('CPSX-Vảy'!$B$4:C$4),0) -> 5544000 | E25: =VLOOKUP($C25,'CPSX-Chai'!$B:$F,COLUMNS('CPSX-Chai'!$B$4:D$4),0)+VLOOKUP($C25,'CPSX-Vảy'!$B:$F,COLUMNS('CPSX-Vảy'!$B$4:D$4),0) -> 8316000 | F25: =VLOOKUP($C25,'CPSX-Chai'!$B:$F,COLUMNS('CPSX-Chai'!$B$4:E$4),0)+VLOOKUP($C25,'CPSX-Vảy'!$B:$F,COLUMNS('CPSX-Vảy'!$B$4:E$4),0) -> 11088000 | G25: =VLOOKUP($C25,'CPSX-Chai'!$B:$F,COLUMNS('CPSX-Chai'!$B$4:F$4),0)+VLOOKUP($C25,'CPSX-Vảy'!$B:$F,COLUMNS('CPSX-Vảy'!$B$4:F$4),0) -> 13860000 | H25: =D25*12 -> 66528000 | I25: =E25*12 -> 99792000 | J25: =F25*12 -> 133056000 | K25: =G25*12 -> 166320000
A26: -10 | C26: Chi phí dao tách nhãn, băm vảy | D26: =VLOOKUP($C26,'CPSX-Chai'!$B:$F,COLUMNS('CPSX-Chai'!$B$4:C$4),0)+VLOOKUP($C26,'CPSX-Vảy'!$B:$F,COLUMNS('CPSX-Vảy'!$B$4:C$4),0) -> 40656000 | E26: =VLOOKUP($C26,'CPSX-Chai'!$B:$F,COLUMNS('CPSX-Chai'!$B$4:D$4),0)+VLOOKUP($C26,'CPSX-Vảy'!$B:$F,COLUMNS('CPSX-Vảy'!$B$4:D$4),0) -> 60984000 | F26: =VLOOKUP($C26,'CPSX-Chai'!$B:$F,COLUMNS('CPSX-Chai'!$B$4:E$4),0)+VLOOKUP($C26,'CPSX-Vảy'!$B:$F,COLUMNS('CPSX-Vảy'!$B$4:E$4),0) -> 81312000 | G26: =VLOOKUP($C26,'CPSX-Chai'!$B:$F,COLUMNS('CPSX-Chai'!$B$4:F$4),0)+VLOOKUP($C26,'CPSX-Vảy'!$B:$F,COLUMNS('CPSX-Vảy'!$B$4:F$4),0) -> 101640000 | H26: =D26*12 -> 487872000 | I26: =E26*12 -> 731808000 | J26: =F26*12 -> 975744000 | K26: =G26*12 -> 1219680000
A27: -11 | C27: Chi phí vật tư kỹ thuật phục vụ sản xuất khác | D27: =VLOOKUP($C27,'CPSX-Chai'!$B:$F,COLUMNS('CPSX-Chai'!$B$4:C$4),0)+VLOOKUP($C27,'CPSX-Vảy'!$B:$F,COLUMNS('CPSX-Vảy'!$B$4:C$4),0) -> 0 | E27: =VLOOKUP($C27,'CPSX-Chai'!$B:$F,COLUMNS('CPSX-Chai'!$B$4:D$4),0)+VLOOKUP($C27,'CPSX-Vảy'!$B:$F,COLUMNS('CPSX-Vảy'!$B$4:D$4),0) -> 0 | F27: =VLOOKUP($C27,'CPSX-Chai'!$B:$F,COLUMNS('CPSX-Chai'!$B$4:E$4),0)+VLOOKUP($C27,'CPSX-Vảy'!$B:$F,COLUMNS('CPSX-Vảy'!$B$4:E$4),0) -> 0 | G27: =VLOOKUP($C27,'CPSX-Chai'!$B:$F,COLUMNS('CPSX-Chai'!$B$4:F$4),0)+VLOOKUP($C27,'CPSX-Vảy'!$B:$F,COLUMNS('CPSX-Vảy'!$B$4:F$4),0) -> 0 | H27: =D27*12 -> 0 | I27: =E27*12 -> 0 | J27: =F27*12 -> 0 | K27: =G27*12 -> 0
A28: 4 | B28: LÃI BIẾN PHÍ | D28: =D5-D7 -> 1.0818462e+09 | E28: =E5-E7 -> 1.6227693e+09 | F28: =F5-F7 -> 2.1636923e+09 | G28: =G5-G7 -> 2.7046154e+09 | H28: =H5-H7 -> 1.2982154e+10 | I28: =I5-I7 -> 1.9473231e+10 | J28: =J5-J7 -> 2.5964308e+10 | K28: =K5-K7 -> 3.2455385e+10
C29: Tỷ lệ Lãi biến phí (%) | D29: =IFERROR(D28/D$5,0) -> 0.20508155 | E29: =IFERROR(E28/E$5,0) -> 0.20508155 | F29: =IFERROR(F28/F$5,0) -> 0.20508155 | G29: =IFERROR(G28/G$5,0) -> 0.20508155 | H29: =IFERROR(H28/H$5,0) -> 0.20508155 | I29: =IFERROR(I28/I$5,0) -> 0.20508155 | J29: =IFERROR(J28/J$5,0) -> 0.20508155 | K29: =IFERROR(K28/K$5,0) -> 0.20508155
C30: Lãi biến phí / Tấn (Triệu đồng/Tấn) | D30: =IFERROR(D28/D$4,0)*1000 -> 2927073 | E30: =IFERROR(E28/E$4,0)*1000 -> 2927073 | F30: =IFERROR(F28/F$4,0)*1000 -> 2927073 | G30: =IFERROR(G28/G$4,0)*1000 -> 2927073 | H30: =IFERROR(H28/H$4,0)*1000 -> 2927073 | I30: =IFERROR(I28/I$4,0)*1000 -> 2927073 | J30: =IFERROR(J28/J$4,0)*1000 -> 2927073 | K30: =IFERROR(K28/K$4,0)*1000 -> 2927073
A31: 5 | B31: ĐỊNH PHÍ | D31: =D34+D47+D66+D92+D95 -> 1.3240191e+09 | E31: =E34+E47+E66+E92+E95 -> 1.5081062e+09 | F31: =F34+F47+F66+F92+F95 -> 1.6468041e+09 | G31: =G34+G47+G66+G92+G95 -> 1.6958579e+09 | H31: =H34+H47+H66+H92+H95 -> 1.5888229e+10 | I31: =I34+I47+I66+I92+I95 -> 1.8097275e+10 | J31: =J34+J47+J66+J92+J95 -> 1.9761649e+10 | K31: =K34+K47+K66+K92+K95 -> 2.0350295e+10
C32: Định phí / Doanh thu (%) | D32: =IFERROR(D31/D$5,0) -> 0.25098936 | E32: =IFERROR(E31/E$5,0) -> 0.19059072 | F32: =IFERROR(F31/F$5,0) -> 0.15608926 | G32: =IFERROR(G31/G$5,0) -> 0.12859099 | H32: =IFERROR(H31/H$5,0) -> 0.25098936 | I32: =IFERROR(I31/I$5,0) -> 0.19059072 | J32: =IFERROR(J31/J$5,0) -> 0.15608926 | K32: =IFERROR(K31/K$5,0) -> 0.12859099
C33: Định phí / Tấn (Triệu đồng/Tấn) | D33: =IFERROR(D31/D$4,0)*1000 -> 3582302.7 | E33: =IFERROR(E31/E$4,0)*1000 -> 2720249.4 | F33: =IFERROR(F31/F$4,0)*1000 -> 2227819.4 | G33: =IFERROR(G31/G$4,0)*1000 -> 1835344.1 | H33: =IFERROR(H31/H$4,0)*1000 -> 3582302.7 | I33: =IFERROR(I31/I$4,0)*1000 -> 2720249.4 | J33: =IFERROR(J31/J$4,0)*1000 -> 2227819.4 | K33: =IFERROR(K31/K$4,0)*1000 -> 1835344.1
A34: 5.1 | B34: Định phí sản xuất | D34: =SUM(D36:D46) -> 4.5353161e+08 | E34: =SUM(E36:E46) -> 4.6051879e+08 | F34: =SUM(F36:F46) -> 4.6750597e+08 | G34: =SUM(G36:G46) -> 4.7549315e+08 | H34: =SUM(H36:H46) -> 5.4423794e+09 | I34: =SUM(I36:I46) -> 5.5262255e+09 | J34: =SUM(J36:J46) -> 5.6100717e+09 | K34: =SUM(K36:K46) -> 5.7059178e+09
C35: Định phí sản xuất / Doanh thu (%) | D35: =IFERROR(D34/D$5,0) -> 0.085974298 | E35: =IFERROR(E34/E$5,0) -> 0.058199221 | F35: =IFERROR(F34/F$5,0) -> 0.044311682 | G35: =IFERROR(G34/G$5,0) -> 0.036054986 | H35: =IFERROR(H34/H$5,0) -> 0.085974298 | I35: =IFERROR(I34/I$5,0) -> 0.058199221 | J35: =IFERROR(J34/J$5,0) -> 0.044311682 | K35: =IFERROR(K34/K$5,0) -> 0.036054986
A36: -1 | C36: Chi phí sửa chữa, bảo trì máy móc thiết bị sản xuất | D36: =VLOOKUP($C36,'CPSX-Chai'!$B:$F,COLUMNS('CPSX-Chai'!$B$4:C$4),0)+VLOOKUP($C36,'CPSX-Vảy'!$B:$F,COLUMNS('CPSX-Vảy'!$B$4:C$4),0) -> 22190006 | E36: =VLOOKUP($C36,'CPSX-Chai'!$B:$F,COLUMNS('CPSX-Chai'!$B$4:D$4),0)+VLOOKUP($C36,'CPSX-Vảy'!$B:$F,COLUMNS('CPSX-Vảy'!$B$4:D$4),0) -> 22190006 | F36: =VLOOKUP($C36,'CPSX-Chai'!$B:$F,COLUMNS('CPSX-Chai'!$B$4:E$4),0)+VLOOKUP($C36,'CPSX-Vảy'!$B:$F,COLUMNS('CPSX-Vảy'!$B$4:E$4),0) -> 22190006 | G36: =VLOOKUP($C36,'CPSX-Chai'!$B:$F,COLUMNS('CPSX-Chai'!$B$4:F$4),0)+VLOOKUP($C36,'CPSX-Vảy'!$B:$F,COLUMNS('CPSX-Vảy'!$B$4:F$4),0) -> 22190006 | H36: =D36*12 -> 266280072 | I36: =E36*12 -> 266280072 | J36: =F36*12 -> 266280072 | K36: =G36*12 -> 266280072
A37: -2 | C37: Chi phí sửa chữa, bảo trì phương tiện vận tải | D37: =VLOOKUP($C37,'CPSX-Chai'!$B:$F,COLUMNS('CPSX-Chai'!$B$4:C$4),0)+VLOOKUP($C37,'CPSX-Vảy'!$B:$F,COLUMNS('CPSX-Vảy'!$B$4:C$4),0) -> 1974359 | E37: =VLOOKUP($C37,'CPSX-Chai'!$B:$F,COLUMNS('CPSX-Chai'!$B$4:D$4),0)+VLOOKUP($C37,'CPSX-Vảy'!$B:$F,COLUMNS('CPSX-Vảy'!$B$4:D$4),0) -> 2961538.5 | F37: =VLOOKUP($C37,'CPSX-Chai'!$B:$F,COLUMNS('CPSX-Chai'!$B$4:E$4),0)+VLOOKUP($C37,'CPSX-Vảy'!$B:$F,COLUMNS('CPSX-Vảy'!$B$4:E$4),0) -> 3948717.9 | G37: =VLOOKUP($C37,'CPSX-Chai'!$B:$F,COLUMNS('CPSX-Chai'!$B$4:F$4),0)+VLOOKUP($C37,'CPSX-Vảy'!$B:$F,COLUMNS('CPSX-Vảy'!$B$4:F$4),0) -> 4935897.4 | H37: =D37*12 -> 23692308 | I37: =E37*12 -> 35538462 | J37: =F37*12 -> 47384615 | K37: =G37*12 -> 59230769
A38: -3 | C38: Chi phí sửa chữa, bảo trì công trình xây dựng (nhà xưởng, ... ) | D38: =VLOOKUP($C38,'CPSX-Chai'!$B:$F,COLUMNS('CPSX-Chai'!$B$4:C$4),0)+VLOOKUP($C38,'CPSX-Vảy'!$B:$F,COLUMNS('CPSX-Vảy'!$B$4:C$4),0) -> 4142250 | E38: =VLOOKUP($C38,'CPSX-Chai'!$B:$F,COLUMNS('CPSX-Chai'!$B$4:D$4),0)+VLOOKUP($C38,'CPSX-Vảy'!$B:$F,COLUMNS('CPSX-Vảy'!$B$4:D$4),0) -> 4142250 | F38: =VLOOKUP($C38,'CPSX-Chai'!$B:$F,COLUMNS('CPSX-Chai'!$B$4:E$4),0)+VLOOKUP($C38,'CPSX-Vảy'!$B:$F,COLUMNS('CPSX-Vảy'!$B$4:E$4),0) -> 4142250 | G38: =VLOOKUP($C38,'CPSX-Chai'!$B:$F,COLUMNS('CPSX-Chai'!$B$4:F$4),0)+VLOOKUP($C38,'CPSX-Vảy'!$B:$F,COLUMNS('CPSX-Vảy'!$B$4:F$4),0) -> 4142250 | H38: =D38*12 -> 49707000 | I38: =E38*12 -> 49707000 | J38: =F38*12 -> 49707000 | K38: =G38*12 -> 49707000
