Workbook
Name mth: Mth!$B$2
Name year: Mth!$B$1

Sheet Mth
B1: 2025
B2: 12

Sheet S6
C4: =C12/C7 -> 0.039634091
A5: ĐVT: VND; kg; VND/kg; USD/ton | K5: TÁC ĐỘNG
B6: KH | C6: TT | D6: +/ | F6: %Cơ cấu SL-KH | G6: %Cơ cấu SL-TT | H6: SL-TT-Cơ cấu KH | I6: DT-TT-Cơ cấu KH | K6: Sản lượng | L6: Cơ cấu ngành | M6: Giá bán | N6: Tỷ giá | O6: Khác | P6: Cp vận chuyển, hoa hồng, chiết khấu | U6: Label chart-SL-KH | V6: Label chart-SL-TT
A7: Sản lượng SPC | B7: =SUM(B8:B12) -> 5940960 | C7: =SUM(C8:C12) -> 2776650 | D7: =C7-B7 -> -3164310 | E7: =D7/B7 -> -0.53262604 | H7: =SUM(H8:H12) -> 2776650
A8: rPET | B8: ='S7'!P43*10^6 -> 4674770 | C8: ='S7'!Q43*10^6 -> 2255200 | D8: =C8-B8 -> -2419570 | E8: =D8/B8 -> -0.51758054 | F8: =B8/B$7 -> 0.78687115 | G8: =C8/C$7 -> 0.81220175 | H8: =F8*C$7 -> 2184865.8 | K8: =I14-B20 -> -8.0252415e+10 | L8: =C8*B14-I14 -> 2.2669515e+09 | M8: =D33*C8/10^3*$B$39 -> -2.868699e+09 | N8: =IFERROR(C20-C20/C40*B40,0) -> 3.1967169e+09 | Q8: =SUM(K8:P8) -> -7.7657446e+10 | R8: =SUM(K8:L8) -> -7.7985464e+10 | S8: -2.4223451e+10 | U8: =_xlfn.TEXTJOIN(" | ",FALSE,TEXT(B8/10^3,"#,###"),TEXT(F8,"0.0%")) -> 4,675 | 78.7% | V8: =_xlfn.TEXTJOIN(" | ",FALSE,TEXT(C8/10^3,"#,###"),TEXT(G8,"0.0%")) -> 2,255 | 81.2%
A9: rHDPE thổi | B9: ='S7'!P44*10^6 -> 916000 | C9: ='S7'!Q44*10^6 -> 272500 | D9: =C9-B9 -> -643500 | E9: =D9/B9 -> -0.70251092 | F9: =B9/B$7 -> 0.15418384 | G9: =C9/C$7 -> 0.098139845 | H9: =F9*C$7 -> 428114.55 | K9: =I15-B21 -> -1.6305281e+10 | L9: =C9*B15-I15 -> -5.2006857e+09 | M9: =D34*C9/10^3*$B$39 -> -5.6917281e+08 | N9: =IFERROR(C21-C21/C41*B41,0) -> 3.8840416e+08 | Q9: =SUM(K9:P9) -> -2.1686735e+10 | R9: =SUM(K9:L9) -> -2.1505967e+10 | S9: -1.6262315e+10 | U9: =_xlfn.TEXTJOIN(" | ",FALSE,TEXT(B9/10^3,"#,###"),TEXT(F9,"0.0%")) -> 916 | 15.4% | V9: =_xlfn.TEXTJOIN(" | ",FALSE,TEXT(C9/10^3,"#,###"),TEXT(G9,"0.0%")) -> 273 | 9.8%
A10: rHDPE ép | B10: ='S7'!P45*10^6 -> 162750 | C10: ='S7'!Q45*10^6 -> 115150 | D10: =C10-B10 -> -47600 | E10: =D10/B10 -> -0.29247312 | F10: =B10/B$7 -> 0.027394562 | G10: =C10/C$7 -> 0.041470837 | H10: =F10*C$7 -> 76065.112 | K10: =I16-B22 -> -1.7931189e+09 | L10: =C10*B16-I16 -> 8.0848982e+08 | M10: =D35*C10/10^3*$B$39 -> -3.9679767e+08 | N10: =IFERROR(C22-C22/C42*B42,0) -> 90307755 | Q10: =SUM(K10:P10) -> -1.291119e+09 | R10: =SUM(K10:L10) -> -9.8462903e+08 | S10: -1.6304001e+09 | U10: =_xlfn.TEXTJOIN(" | ",FALSE,TEXT(B10/10^3,"#,###"),TEXT(F10,"0.0%")) -> 163 | 2.7% | V10: =_xlfn.TEXTJOIN(" | ",FALSE,TEXT(C10/10^3,"#,###"),TEXT(G10,"0.0%")) -> 115 | 4.1%
A11: rPP | B11: ='S7'!P46*10^6 -> 87440 | C11: ='S7'!Q46*10^6 -> 23750 | D11: =C11-B11 -> -63690 | E11: =D11/B11 -> -0.72838518 | F11: =B11/B$7 -> 0.01471816 | G11: =C11/C$7 -> 0.0085534727 | H11: =F11*C$7 -> 40867.179 | K11: =I17-B23 -> -1.0394863e+09 | L11: =C11*B17-I17 -> -3.8204843e+08 | M11: =D36*C11/10^3*$B$39 -> -77692396 | N11: =IFERROR(C23-C23/C43*B43,0) -> 20580475 | Q11: =SUM(K11:P11) -> -1.4786466e+09 | R11: =SUM(K11:L11) -> -1.4215347e+09 | S11: -1.1216801e+09 | U11: =_xlfn.TEXTJOIN(" | ",FALSE,TEXT(B11/10^3,"#,###"),TEXT(F11,"0.0%")) -> 87 | 1.5% | V11: =_xlfn.TEXTJOIN(" | ",FALSE,TEXT(C11/10^3,"#,###"),TEXT(G11,"0.0%")) -> 24 | 0.9%
A12: Xơ sợi | B12: ='S7'!P47*10^6 -> 100000 | C12: ='S7'!Q47*10^6 -> 110050 | D12: =C12-B12 -> 10050 | E12: =D12/B12 -> 0.1005 | F12: =B12/B$7 -> 0.016832296 | G12: =C12/C$7 -> 0.039634091 | H12: =F12*C$7 -> 46737.396 | K12: =I18-B24 -> -1.4647216e+09 | L12: =C12*B18-I18 -> 1.7410966e+09 | M12: =D37*C12/10^3*$B$39 -> -1.0871463e+09 | N12: =IFERROR(C24-C24/C44*B44,0) -> 88219348 | Q12: =SUM(K12:P12) -> -7.2255199e+08 | R12: =SUM(K12:L12) -> 276375000 | S12: 1.28645e+10 | U12: =_xlfn.TEXTJOIN(" | ",FALSE,TEXT(B12/10^3,"#,###"),TEXT(F12,"0.0%")) -> 100 | 1.7% | V12: =_xlfn.TEXTJOIN(" | ",FALSE,TEXT(C12/10^3,"#,###"),TEXT(G12,"0.0%")) -> 110 | 4.0%
A13: GB EXW (VND/kg) | B13: 30553.285 | C13: 28801.443 | D13: =C13-B13 -> -1751.8418 | I13: =SUM(I14:I18) -> 8.8499262e+10
A14: rPET | B14: =B33*B40/10^3 -> 32231.125 | C14: =C33*C40/10^3 -> 32376.575 | I14: =H8*B14 -> 7.0420682e+10
A15: rHDPE thổi | B15: =B34*B41/10^3 -> 33420.306 | C15: =C34*C41/10^3 -> 32756.935 | I15: =H9*B15 -> 1.4307719e+10
A16: rHDPE ép | B16: =B35*B42/10^3 -> 20685.484 | C16: =C35*C42/10^3 -> 18023.826 | I16: =H10*B16 -> 1.5734436e+09
A17: rPP | B17: =B36*B43/10^3 -> 22319.591 | C17: =C36*C43/10^3 -> 19914.878 | I17: =H11*B17 -> 9.121387e+08
A18: Xơ sợi | B18: =B37*B44/10^3 -> 27500 | C18: =C37*C44/10^3 -> 18422.971 | I18: =H12*B18 -> 1.2852784e+09
A19: Doanh thu SPC | B19: =SUM(B20:B24) -> 189354285000 | C19: =SUM(C20:C24) -> 8.6517786e+10 | D19: =C19-B19 -> -1.028365e+11
A20: rPET | B20: =B8*B14 -> 150673097500 | C20: =C8*C14 -> 7.3015652e+10 | E20: =C20-B20 -> -7.7657446e+10 | F20: =E20/B20 -> -0.51540353
A21: rHDPE thổi | B21: =B9*B15 -> 3.0613e+10 | C21: =C9*C15 -> 8.9262647e+09 | E21: =C21-B21 -> -2.1686735e+10 | F21: =E21/B21 -> -0.70841588
A22: rHDPE ép | B22: =B10*B16 -> 3.3665625e+09 | C22: =C10*C16 -> 2.0754435e+09 | E22: =C22-B22 -> -1.291119e+09 | F22: =E22/B22 -> -0.38351254
A23: rPP | B23: =B11*B17 -> 1.951625e+09 | C23: =C11*C17 -> 4.7297836e+08 | E23: =C23-B23 -> -1.4786466e+09 | F23: =E23/B23 -> -0.75764896
A24: Xơ sợi | B24: =B12*B18 -> 2.75e+09 | C24: =C12*C18 -> 2.027448e+09 | E24: =C24-B24 -> -7.2255199e+08 | F24: =E24/B24 -> -0.26274618
A25: Tài trợ | B25: 3271999000 | C25: 8295287500 | D25: =C25-B25 -> 5023288500 | O25: =D25 -> 5023288500 | Q25: =SUM(K25:P25) -> 5023288500
A26: Dây đai, phó sản | B26: 2640000000 | C26: 3.5977384e+09 | D26: =C26-B26 -> 9.5773843e+08 | O26: =D26 -> 9.5773843e+08 | Q26: =SUM(K26:P26) -> 9.5773843e+08
A27: Khác | C27: 6.3174504e+08 | D27: =C27-B27 -> 6.3174504e+08 | O27: =D27 -> 6.3174504e+08 | Q27: =SUM(K27:P27) -> 6.3174504e+08
A28: Cp vận chuyển, hoa hồng, chiết khấu | B28: ='S7'!C20 -> 12595919900 | C28: ='S7'!G20 -> 2.3925254e+09 | D28: =C28-B28 -> -1.0203394e+10 | P28: =D28 -> -1.0203394e+10
A29: Tổng dthu thuần | B29: =B19+B25+B26+B27+B28 -> 207862203900 | C29: =C19+C25+C26+C27+C28 -> 101435082581 | D29: =C29-B29 -> -106427121319 | K29: =SUM(K7:K28) -> -1.0085502e+11 | L29: =SUM(L7:L28) -> -7.6619622e+08 | M29: =SUM(M7:M28) -> -4.9995082e+09 | N29: =SUM(N7:N28) -> 3.7842287e+09 | O29: =SUM(O7:O28) -> 6.612772e+09 | P29: =SUM(P7:P28) -> -1.0203394e+10 | Q29: =SUM(K29:P29) -> -106427121319
A30: check | B30: =B29-'S7'!C3 -> 0 | C30: =C29-'S7'!G17 -> 0 | D30: =D29/B29 -> -0.51200805 | P30: Check | Q30: =Q29-D29 -> 0
A32: GB EXW (USD/ton) | B32: KH | C32: TT
A33: rPET | B33: 1289.245 | C33: 1238.3635 | D33: =C33-B33 -> -50.881501 | E33: =IFERROR(D33/B33,0) -> -0.039466122 | Q33: -52808442002
A34: rHDPE thổi | B34: 1336.8122 | C34: 1253.2639 | D34: =C34-B34 -> -83.548302 | E34: =IFERROR(D34/B34,0) -> -0.062498158 | Q34: =Q33-Q29 -> 53618679317
A35: rHDPE ép | B35: 827.41935 | C35: 689.58256 | D35: =C35-B35 -> -137.83679 | E35: =IFERROR(D35/B35,0) -> -0.16658638
A36: rPP | B36: 892.78362 | C36: 761.93327 | D36: =C36-B36 -> -130.85035 | E36: =IFERROR(D36/B36,0) -> -0.14656446
A37: Xơ sợi | B37: 1100 | C37: 704.85367 | D37: =C37-B37 -> -395.14633 | E37: =IFERROR(D37/B37,0) -> -0.35922394
A39: Exchange rate | B39: 25000 | C39: 26142.715 | D39: =C39-B39 -> 1142.7146 | E39: =IFERROR(D39/B39,0) -> 0.045708584
A40: rPET | B40: 25000 | C40: 26144.645
A41: rHDPE thổi | B41: 25000 | C41: 26137.299
A42: rHDPE ép | B42: 25000 | C42: 26137.299
A43: rPP | B43: 25000 | C43: 26137.299
A44: Xơ sợi | B44: 25000 | C44: 26137.299
A47: Vẽ (VND nhưng thể hiện là tỷ)
...

Sheet S7
A1: ĐVT: VND nhưng show là tỷ đồng | AE1: Dthu (theo tỷ giá KH)
C2: Start | D2: Hidden | E2: Increase | F2: Decrease | G2: End | H2: Chênh lệch | K2: T/Đ làm từng SKU | M2: T/Đ nếu như nhóm ngành | P2: KH | Q2: TT | U2: KH | V2: TT | Z2: Tổng tác động | AA2: SL | AB2: GB | AC2: EXR | AE2: KH | AF2: TT
A3: KH T12 | C3: =H3 -> 207862203900 | H3: 207862203900
A4: rPET | B4: Sản lượng | D4: =C3+E3-F4 -> 1.2987674e+11 | E4: =IF(H4>0,H4,0) -> 0 | F4: =IF(H4<0,-H4,0) -> 7.7985464e+10 | H4: =M4 -> -7.7985464e+10 | K4: -7.5861725e+10 | M4: =AA4 -> -7.7985464e+10 | O4: tấn | P4: 4674.77 | Q4: 2255.2 | R4: =Q4-P4 -> -2419.57 | S4: =R4/P4 -> -0.51758054 | Z4: =SUM(AA4:AC4) -> -7.7657446e+10 | AA4: =R4*P5*U5 -> -7.7985464e+10 | AB4: =R5*Q4*U5 -> -2.868699e+09 | AC4: =Q4*Q5*W5 -> 3.1967169e+09 | AE4: =P4*P5*U5 -> 150673097500 | AF4: =Q4*Q5*U5 -> 6.9818935e+10 | AH4: =Q4*Q5*V5 -> 7.3015652e+10 | AI4: =AH4-AF4-AC4 -> 0 | AK4: =AF4-AE4 -> -8.0854163e+10 | AL4: =AK4/AE4 -> -0.53661977
B5: Giá bán | D5: =D4+E4-F5 -> 1.2700804e+11 | E5: =IF(H5>0,H5,0) -> 0 | F5: =IF(H5<0,-H5,0) -> 2.868699e+09 | H5: =M5 -> -2.868699e+09 | K5: -4.9598921e+09 | L5: =SUM(K4:K5)-SUM(M4:M5) -> 32545787 | M5: =AB4 -> -2.868699e+09 | O5: $/tấn | P5: 1289.245 | Q5: 1238.3635 | R5: =Q5-P5 -> -50.881501 | S5: =R5/P5 -> -0.039466122 | U5: 25000 | V5: 26144.645 | W5: =V5-U5 -> 1144.6454 | X5: =W5/U5 -> 0.045785816
A6: rHDPE thổi | B6: Sản lượng | D6: =D5+E5-F6 -> 1.0550207e+11 | E6: =IF(H6>0,H6,0) -> 0 | F6: =IF(H6<0,-H6,0) -> 2.1505967e+10 | H6: =M6 -> -2.1505967e+10 | K6: -2.1660312e+10 | M6: =AA6 -> -2.1505967e+10 | O6: tấn | P6: 916 | Q6: 272.5 | R6: =Q6-P6 -> -643.5 | S6: =R6/P6 -> -0.70251092 | Z6: =SUM(AA6:AC6) -> -2.1686735e+10 | AA6: =R6*P7*U7 -> -2.1505967e+10 | AB6: =R7*Q6*U7 -> -5.6917281e+08 | AC6: =Q6*Q7*W7 -> 3.8840416e+08 | AE6: =P6*P7*U7 -> 30613000000 | AF6: =Q6*Q7*U7 -> 8.5378605e+09 | AH6: =Q6*Q7*V7 -> 8.9262647e+09 | AI6: =AH6-AF6-AC6 -> 0 | AK6: =AF6-AE6 -> -2.207514e+10 | AL6: =AK6/AE6 -> -0.72110344
B7: Giá bán | D7: =D6+E6-F7 -> 1.049329e+11 | E7: =IF(H7>0,H7,0) -> 0 | F7: =IF(H7<0,-H7,0) -> 5.6917281e+08 | H7: =M7 -> -5.6917281e+08 | K7: -3.22566e+08 | L7: =SUM(K6:K7)-SUM(M6:M7) -> 92261094 | M7: =AB6 -> -5.6917281e+08 | O7: $/tấn | P7: 1336.8122 | Q7: 1253.2639 | R7: =Q7-P7 -> -83.548302 | S7: =R7/P7 -> -0.062498158 | U7: 25000 | V7: 26137.299 | W7: =V7-U7 -> 1137.2995 | X7: =W7/U7 -> 0.045491978
A8: rHDPE ép | B8: Sản lượng | D8: =D7+E7-F8 -> 1.0394827e+11 | E8: =IF(H8>0,H8,0) -> 0 | F8: =IF(H8<0,-H8,0) -> 9.8462903e+08 | H8: =M8 -> -9.8462903e+08 | K8: -1.2473525e+09 | M8: =AA8 -> -9.8462903e+08 | O8: tấn | P8: 162.75 | Q8: 115.15 | R8: =Q8-P8 -> -47.6 | S8: =R8/P8 -> -0.29247312 | Z8: =SUM(AA8:AC8) -> -1.291119e+09 | AA8: =R8*P9*U9 -> -9.8462903e+08 | AB8: =R9*Q8*U9 -> -3.9679767e+08 | AC8: =Q8*Q9*W9 -> 90307755 | AE8: =P8*P9*U9 -> 3366562500 | AF8: =Q8*Q9*U9 -> 1.9851358e+09 | AH8: =Q8*Q9*V9 -> 2.0754435e+09 | AI8: =AH8-AF8-AC8 -> 0 | AK8: =AF8-AE8 -> -1.3814267e+09 | AL8: =AK8/AE8 -> -0.41033746
B9: Giá bán | D9: =D8+E8-F9 -> 1.0355147e+11 | E9: =IF(H9>0,H9,0) -> 0 | F9: =IF(H9<0,-H9,0) -> 3.9679767e+08 | H9: =M9 -> -3.9679767e+08 | K9: -51797672 | L9: =SUM(K8:K9)-SUM(M8:M9) -> 82276487 | M9: =AB8 -> -3.9679767e+08 | O9: $/tấn | P9: 827.41935 | Q9: 689.58256 | R9: =Q9-P9 -> -137.83679 | S9: =R9/P9 -> -0.16658638 | U9: 25000 | V9: 26137.299 | W9: =V9-U9 -> 1137.2995 | X9: =W9/U9 -> 0.045491978
A10: rPP | B10: Sản lượng | D10: =D9+E9-F10 -> 1.0212994e+11 | E10: =IF(H10>0,H10,0) -> 0 | F10: =IF(H10<0,-H10,0) -> 1.4215347e+09 | H10: =M10 -> -1.4215347e+09 | K10: -1.4652871e+09 | M10: =AA10 -> -1.4215347e+09 | O10: tấn | P10: 87.44 | Q10: 23.75 | R10: =Q10-P10 -> -63.69 | S10: =R10/P10 -> -0.72838518 | Z10: =SUM(AA10:AC10) -> -1.4786466e+09 | AA10: =R10*P11*U11 -> -1.4215347e+09 | AB10: =R11*Q10*U11 -> -77692396 | AC10: =Q10*Q11*W11 -> 20580475 | AE10: =P10*P11*U11 -> 1951625000 | AF10: =Q10*Q11*U11 -> 4.5239788e+08 | AH10: =Q10*Q11*V11 -> 4.7297836e+08 | AI10: =AH10-AF10-AC10 -> 0 | AK10: =AF10-AE10 -> -1.4992271e+09 | AL10: =AK10/AE10 -> -0.76819426
B11: Giá bán | D11: =D10+E10-F11 -> 1.0205225e+11 | E11: =IF(H11>0,H11,0) -> 0 | F11: =IF(H11<0,-H11,0) -> 77692396 | H11: =M11 -> -77692396 | K11: -15769680 | L11: =SUM(K10:K11)-SUM(M10:M11) -> 18170295 | M11: =AB10 -> -77692396 | O11: $/tấn | P11: 892.78362 | Q11: 761.93327 | R11: =Q11-P11 -> -130.85035 | S11: =R11/P11 -> -0.14656446 | U11: 25000 | V11: 26137.299 | W11: =V11-U11 -> 1137.2995 | X11: =W11/U11 -> 0.045491978
A12: Xơ sợi | B12: Sản lượng | D12: =D11+E11-F12 -> 1.0205225e+11 | E12: =IF(H12>0,H12,0) -> 2.76375e+08 | F12: =IF(H12<0,-H12,0) -> 0 | H12: =M12 -> 2.76375e+08 | K12: -7.2255199e+08 | M12: =AA12 -> 2.76375e+08 | O12: tấn | P12: 100 | Q12: 110.05 | R12: =Q12-P12 -> 10.05 | S12: =R12/P12 -> 0.1005 | Z12: =SUM(AA12:AC12) -> -7.2255199e+08 | AA12: =R12*P13*U13 -> 2.76375e+08 | AB12: =R13*Q12*U13 -> -1.0871463e+09 | AC12: =Q12*Q13*W13 -> 88219348 | AE12: =P12*P13*U13 -> 2750000000 | AF12: =Q12*Q13*U13 -> 1.9392287e+09 | AH12: =Q12*Q13*V13 -> 2.027448e+09 | AI12: =AH12-AF12-AC12 -> 0 | AK12: =AF12-AE12 -> -8.1077134e+08 | AL12: =AK12/AE12 -> -0.29482594
B13: Giá bán | D13: =D12+E12-F13 -> 1.0124148e+11 | E13: =IF(H13>0,H13,0) -> 0 | F13: =IF(H13<0,-H13,0) -> 1.0871463e+09 | H13: =M13 -> -1.0871463e+09 | K13: 0 | L13: =SUM(K12:K13)-SUM(M12:M13) -> 88219348 | M13: =AB12 -> -1.0871463e+09 | O13: $/tấn | P13: 1100 | Q13: 704.85367 | R13: =Q13-P13 -> -395.14633 | S13: =R13/P13 -> -0.35922394 | U13: 25000 | V13: 26137.299 | W13: =V13-U13 -> 1137.2995 | X13: =W13/U13 -> 0.045491978
A14: Tỷ giá | D14: =D13+E13-F14 -> 1.0124148e+11 | E14: =IF(H14>0,H14,0) -> 3.7842287e+09 | F14: =IF(H14<0,-H14,0) -> 0 | H14: =M14 -> 3.7842287e+09 | K14: 3.5428341e+09 | M14: =AC4+AC6+AC8+AC10+AC12 -> 3.7842287e+09
A15: Khác | D15: =D14+E14-F15 -> 1.0502571e+11 | E15: =IF(H15>0,H15,0) -> 6.612772e+09 | F15: =IF(H15<0,-H15,0) -> 0 | H15: =H17-SUM(H3:H14,H16) -> 6.612772e+09 | AE15: =AE17-SUM(AE3:AE14) -> 18507918900 | AF15: =AF17-SUM(AF3:AF14) -> 1.4917296e+10
A16: hoa hồng, chiết khấu | B16: Cp vận chuyển | D16: =D15+E15-F16 -> 101435082581 | E16: =IF(H16>0,H16,0) -> 0 | F16: =IF(H16<0,-H16,0) -> 1.0203394e+10 | H16: =G20-C20 -> -1.0203394e+10
A17: TT T12 | G17: =D16+E16 -> 101435082581 | H17: 101435082581 | I17: =H17-H3 -> -106427121319 | J17: =H17/H3-1 -> -0.51200805 | U17: 25000 | V17: 26142.715 | W17: =V17-U17 -> 1142.7146 | X17: =W17/U17 -> 0.045708584 | AE17: =C3 -> 207862203900 | AF17: =G17-H14 -> 9.7650854e+10 | AH17: =G17-AF17 -> 3.7842287e+09
A18: Check | G18: =G17-H17 -> 0
O19: Dthu (tỷ VND) | P19: KH | Q19: TT
A20: Cp vận chuyển, hoa hồng, chiết khấu | C20: =C3-C21 -> 12595919900 | G20: =H17-G21 -> 2.3925254e+09 | O20: rPET | P20: =P4*P5*U5/10^9 -> 150.6731 | Q20: =Q4*Q5*V5/10^9 -> 73.015652 | R20: =Q20-P20 -> -77.657446 | S20: =IFERROR(R20/P20,0) -> -0.51540353 | U20: =Q20/Q27 -> 0.71982641
A21: Doanh thu EXW | C21: 195266284000 | G21: 9.9042557e+10 | O21: rHDPE thổi | P21: =P6*P7*U7/10^9 -> 30.613 | Q21: =Q6*Q7*V7/10^9 -> 8.9262647 | R21: =Q21-P21 -> -21.686735 | S21: =IFERROR(R21/P21,0) -> -0.70841588
O22: rHDPE ép | P22: =P8*P9*U9/10^9 -> 3.3665625 | Q22: =Q8*Q9*V9/10^9 -> 2.0754435 | R22: =Q22-P22 -> -1.291119 | S22: =IFERROR(R22/P22,0) -> -0.38351254
O23: rPP | P23: =P10*P11*U11/10^9 -> 1.951625 | Q23: =Q10*Q11*V11/10^9 -> 0.47297836 | R23: =Q23-P23 -> -1.4786466 | S23: =IFERROR(R23/P23,0) -> -0.75764896
O24: Xơ sợi | P24: =P12*P13*U13/10^9 -> 2.75 | Q24: =Q12*Q13*V13/10^9 -> 2.027448 | R24: =Q24-P24 -> -0.72255199 | S24: =IFERROR(R24/P24,0) -> -0.26274618
O25: Khác | P25: =C3/10^9-SUM(P20:P24,P26) -> 5.911999 | Q25: =G17/10^9-SUM(Q20:Q24,Q26) -> 12.524771 | R25: =Q25-P25 -> 6.612772 | S25: =IFERROR(R25/P25,0) -> 1.118534
O26: Cp vận chuyển, hoa hồng, chiết khấu | P26: =C20/10^9 -> 12.59592 | Q26: =G20/10^9 -> 2.3925254 | R26: =Q26-P26 -> -10.203394 | S26: =IFERROR(R26/P26,0) -> -0.81005552
G27: SL | H27: =H4+H6+H8+H10+H12 -> -1.0162122e+11 | O27: Tổng | P27: =SUM(P20:P26) -> 207.8622 | Q27: =SUM(Q20:Q26) -> 101.43508 | R27: =Q27-P27 -> -106.42712 | S27: =IFERROR(R27/P27,0) -> -0.51200805
G28: GB | H28: =H5+H7+H9+H11+H13 -> -4.9995082e+09
O30: Dthu (tỷ VND) | P30: KH | Q30: TT | R30: - Loại trừ chênh lệch tỷ giá
O31: rPET | P31: =P4*P5*U5/10^9 -> 150.6731 | Q31: =Q4*Q5*U5/10^9 -> 69.818935 | R31: =Q31-P31 -> -80.854163 | S31: =IFERROR(R31/P31,0) -> -0.53661977
O32: rHDPE thổi | P32: =P6*P7*U7/10^9 -> 30.613 | Q32: =Q6*Q7*U7/10^9 -> 8.5378605 | R32: =Q32-P32 -> -22.07514 | S32: =IFERROR(R32/P32,0) -> -0.72110344
O33: rHDPE ép | P33: =P8*P9*U9/10^9 -> 3.3665625 | Q33: =Q8*Q9*U9/10^9 -> 1.9851358 | R33: =Q33-P33 -> -1.3814267 | S33: =IFERROR(R33/P33,0) -> -0.41033746
O34: rPP | P34: =P10*P11*U11/10^9 -> 1.951625 | Q34: =Q10*Q11*U11/10^9 -> 0.45239788 | R34: =Q34-P34 -> -1.4992271 | S34: =IFERROR(R34/P34,0) -> -0.76819426
O35: Xơ sợi | P35: =P12*P13*U13/10^9 -> 2.75 | Q35: =Q12*Q13*U13/10^9 -> 1.9392287 | R35: =Q35-P35 -> -0.81077134 | S35: =IFERROR(R35/P35,0) -> -0.29482594
O36: Chênh lệch tỷ giá | Q36: =(AC4+AC6+AC8+AC10+AC12)/10^9 -> 3.7842287 | R36: =Q36-P36 -> 3.7842287 | S36: =IFERROR(R36/P36,0) -> 0
O37: Khác | P37: =C3/10^9-SUM(P31:P36,P38) -> 5.911999 | Q37: =G17/10^9-SUM(Q31:Q36,Q38) -> 12.524771 | R37: =Q37-P37 -> 6.612772 | S37: =IFERROR(R37/P37,0) -> 1.118534
O38: Cp vận chuyển, hoa hồng, chiết khấu | P38: =C20/10^9 -> 12.59592 | Q38: =G20/10^9 -> 2.3925254 | R38: =Q38-P38 -> -10.203394 | S38: =IFERROR(R38/P38,0) -> -0.81005552
O39: Tổng | P39: =SUM(P31:P38) -> 207.8622 | Q39: =SUM(Q31:Q38) -> 101.43508 | R39: =Q39-P39 -> -106.42712 | S39: =IFERROR(R39/P39,0) -> -0.51200805
O42: Sản lượng (ng.tấn) | P42: KH | Q42: TT | R42: +-/- | S42: %+-/- | T42: %Thực hiện
O43: rPET | P43: =P4/10^3 -> 4.67477 | Q43: =Q4/10^3 -> 2.2552 | R43: =Q43-P43 -> -2.41957 | S43: =IFERROR(R43/P43,0) -> -0.51758054 | T43: =Q43/P43 -> 0.48241946
...

Sheet S8
A1: ĐVT: VND nhưng show là tỷ đồng | AH1: LG EXW (THEO TỶ GIÁ KH) | AO1: DTHU EXW (THEO TỶ GIÁ KH) | AR1: %Biên
C2: Start | D2: Hidden | E2: Increase | F2: Decrease | G2: End | H2: Chênh lệch | M2: T/Đ nếu như nhóm ngành | P2: KH | Q2: TT | U2: KH | V2: TT | Z2: Tổng tác động | AA2: SL | AB2: GB | AC2: GV | AD2: EXR | AE2: Model | AH2: KH | AI2: TT | AJ2: +/- | AK2: %+/- | AO2: KH | AP2: TT
A3: ='S7'!A3 -> KH T12 | C3: =H3 -> 4.8578489e+10 | H3: 4.8578489e+10
A4: rPET | B4: Sản lượng | D4: =C3+E3-F4 -> 3.365798e+10 | E4: =IF(H4>0,H4,0) -> 0 | F4: =IF(H4<0,-H4,0) -> 1.4920508e+10 | H4: =M4 -> -1.4920508e+10 | M4: {=TRANSPOSE(AA4:AC4)} -> -1.4920508e+10 | O4: tấn | P4: 4674.77 | Q4: 2255.2 | R4: =Q4-P4 -> -2419.57 | S4: =R4/P4 -> -0.51758054 | Z4: =SUM(AA4:AD4) -> -1.6821239e+10 | AA4: =R4*(P5*U5-P6*10^3) -> -1.4920508e+10 | AB4: =R5*Q4*U5 -> -2.868699e+09 | AC4: =-R6*Q4*10^3 -> -2.2287492e+09 | AD4: =Q4*Q5*W5 -> 3.1967169e+09 | AE4: -1.6821239e+10 | AF4: =Z4-AE4 -> 0.00026512146 | AH4: =P4*(P5*U5-P6*10^3) -> 2.8827413e+10 | AI4: =Q4*(Q5*U5-Q6*10^3) -> 8.8094567e+09 | AJ4: =AI4-AH4 -> -2.0017956e+10 | AK4: =AJ4/AH4 -> -0.69440696 | AM4: =Q4*(Q5*V5-Q6*10^3) -> 1.2006174e+10 | AN4: =AM4-AI4-AD4 -> 0 | AO4: ='S7'!AE4 -> 150673097500 | AP4: ='S7'!AF4 -> 6.9818935e+10 | AR4: =AH4/AO4 -> 0.19132422 | AS4: =AI4/AP4 -> 0.12617575
B5: Giá bán | D5: =D4+E4-F5 -> 3.0789281e+10 | E5: =IF(H5>0,H5,0) -> 0 | F5: =IF(H5<0,-H5,0) -> 2.868699e+09 | H5: =M5 -> -2.868699e+09 | I5: =H5*(1-13.11%) -> -2.4926126e+09 | M5: -2.868699e+09 | O5: $/tấn | P5: 1289.245 | Q5: 1238.3635 | R5: =Q5-P5 -> -50.881501 | S5: =R5/P5 -> -0.039466122 | U5: 25000 | V5: 26144.645 | W5: =V5-U5 -> 1144.6454 | X5: =W5/U5 -> 0.045785816
B6: Giá vốn | D6: =D5+E5-F6 -> 2.8560532e+10 | E6: =IF(H6>0,H6,0) -> 0 | F6: =IF(H6<0,-H6,0) -> 2.2287492e+09 | H6: =M6 -> -2.2287492e+09 | I6: =H6*(1-13.11%) -> -1.9365602e+09 | M6: -2.2287492e+09 | O6: VND/kg | P6: 26064.53 | Q6: 27052.802 | R6: =Q6-P6 -> 988.27121 | S6: =R6/P6 -> 0.037916325
A7: rHDPE thổi | B7: Sản lượng | D7: =D6+E6-F7 -> 2.4788293e+10 | E7: =IF(H7>0,H7,0) -> 0 | F7: =IF(H7<0,-H7,0) -> 3.7722396e+09 | H7: =M7 -> -3.7722396e+09 | M7: {=TRANSPOSE(AA7:AC7)} -> -3.7722396e+09 | O7: tấn | P7: 916 | Q7: 272.5 | R7: =Q7-P7 -> -643.5 | S7: =R7/P7 -> -0.70251092 | Z7: =SUM(AA7:AD7) -> -4.157819e+09 | AA7: =R7*(P8*U8-P9*10^3) -> -3.7722396e+09 | AB7: =R8*Q7*U8 -> -5.6917281e+08 | AC7: =-R9*Q7*10^3 -> -2.0481075e+08 | AD7: =Q7*Q8*W8 -> 3.8840416e+08 | AE7: -4.157819e+09 | AF7: =Z7-AE7 -> 0 | AH7: =P7*(P8*U8-P9*10^3) -> 5.3696526e+09 | AI7: =Q7*(Q8*U8-Q9*10^3) -> 8.2342946e+08 | AJ7: =AI7-AH7 -> -4.5462231e+09 | AK7: =AJ7/AH7 -> -0.84665126 | AM7: =Q7*(Q8*V8-Q9*10^3) -> 1.2118336e+09 | AN7: =AM7-AI7-AD7 -> 0 | AO7: ='S7'!AE6 -> 30613000000 | AP7: ='S7'!AF6 -> 8.5378605e+09 | AR7: =AH7/AO7 -> 0.17540432 | AS7: =AI7/AP7 -> 0.096444474
B8: Giá bán | D8: =D7+E7-F8 -> 2.421912e+10 | E8: =IF(H8>0,H8,0) -> 0 | F8: =IF(H8<0,-H8,0) -> 5.6917281e+08 | H8: =M8 -> -5.6917281e+08 | M8: -5.6917281e+08 | O8: $/tấn | P8: 1336.8122 | Q8: 1253.2639 | R8: =Q8-P8 -> -83.548302 | S8: =R8/P8 -> -0.062498158 | U8: 25000 | V8: 26137.299 | W8: =V8-U8 -> 1137.2995 | X8: =W8/U8 -> 0.045491978
B9: Giá vốn | D9: =D8+E8-F9 -> 2.4014309e+10 | E9: =IF(H9>0,H9,0) -> 0 | F9: =IF(H9<0,-H9,0) -> 2.0481075e+08 | H9: =M9 -> -2.0481075e+08 | M9: -2.0481075e+08 | O9: VND/kg | P9: 27558.24 | Q9: 28309.839 | R9: =Q9-P9 -> 751.5991 | S9: =R9/P9 -> 0.027273117
A10: rHDPE ép | B10: Sản lượng | D10: =D9+E9-F10 -> 2.3761224e+10 | E10: =IF(H10>0,H10,0) -> 0 | F10: =IF(H10<0,-H10,0) -> 2.5308488e+08 | H10: =M10 -> -2.5308488e+08 | M10: {=TRANSPOSE(AA10:AC10)} -> -2.5308488e+08 | O10: tấn | P10: 162.75 | Q10: 115.15 | R10: =Q10-P10 -> -47.6 | S10: =R10/P10 -> -0.29247312 | Z10: =SUM(AA10:AD10) -> -1.7720648e+09 | AA10: =R10*(P11*U11-P12*10^3) -> -2.5308488e+08 | AB10: =R11*Q10*U11 -> -3.9679767e+08 | AC10: =-R12*Q10*10^3 -> -1.21249e+09 | AD10: =Q10*Q11*W11 -> 90307755 | AE10: -1.7720648e+09 | AF10: =Z10-AE10 -> 0 | AH10: =P10*(P11*U11-P12*10^3) -> 8.6532696e+08 | AI10: =Q10*(Q11*U11-Q12*10^3) -> -9.9704557e+08 | AJ10: =AI10-AH10 -> -1.8623725e+09 | AK10: =AJ10/AH10 -> -2.1522183 | AM10: =Q10*(Q11*V11-Q12*10^3) -> -9.0673781e+08 | AN10: =AM10-AI10-AD10 -> 0 | AO10: ='S7'!AE8 -> 3366562500 | AP10: ='S7'!AF8 -> 1.9851358e+09 | AR10: =AH10/AO10 -> 0.25703576 | AS10: =AI10/AP10 -> -0.5022556
B11: Giá bán | D11: =D10+E10-F11 -> 2.3364426e+10 | E11: =IF(H11>0,H11,0) -> 0 | F11: =IF(H11<0,-H11,0) -> 3.9679767e+08 | H11: =M11 -> -3.9679767e+08 | M11: -3.9679767e+08 | O11: $/tấn | P11: 827.41935 | Q11: 689.58256 | R11: =Q11-P11 -> -137.83679 | S11: =R11/P11 -> -0.16658638 | U11: 25000 | V11: 26137.299 | W11: =V11-U11 -> 1137.2995 | X11: =W11/U11 -> 0.045491978
B12: Giá vốn | D12: =D11+E11-F12 -> 2.2151936e+10 | E12: =IF(H12>0,H12,0) -> 0 | F12: =IF(H12<0,-H12,0) -> 1.21249e+09 | H12: =M12 -> -1.21249e+09 | M12: -1.21249e+09 | O12: VND/kg | P12: 15368.575 | Q12: 25898.232 | R12: =Q12-P12 -> 10529.657 | S12: =R12/P12 -> 0.68514205
A13: rPP | B13: Sản lượng | D13: =D12+E12-F13 -> 2.2151936e+10 | E13: =IF(H13>0,H13,0) -> 2.7670524e+08 | F13: =IF(H13<0,-H13,0) -> 0 | H13: =M13 -> 2.7670524e+08 | M13: {=TRANSPOSE(AA13:AC13)} -> 2.7670524e+08 | O13: tấn | P13: 87.44 | Q13: 23.75 | R13: =Q13-P13 -> -63.69 | S13: =R13/P13 -> -0.72838518 | Z13: =SUM(AA13:AD13) -> 1.4782765e+08 | AA13: =R13*(P14*U14-P15*10^3) -> 2.7670524e+08 | AB13: =R14*Q13*U14 -> -77692396 | AC13: =-R15*Q13*10^3 -> -71765673 | AD13: =Q13*Q14*W14 -> 20580475 | AE13: 1.4782765e+08 | AF13: =Z13-AE13 -> -5.6624413e-07 | AH13: =P13*(P14*U14-P15*10^3) -> -3.7988862e+08 | AI13: =Q13*(Q14*U14-Q15*10^3) -> -2.5264145e+08 | AJ13: =AI13-AH13 -> 1.2724718e+08 | AK13: =AJ13/AH13 -> -0.33495916 | AM13: =Q13*(Q14*V14-Q15*10^3) -> -2.3206097e+08 | AN13: =AM13-AI13-AD13 -> 0 | AO13: ='S7'!AE10 -> 1951625000 | AP13: ='S7'!AF10 -> 4.5239788e+08 | AR13: =AH13/AO13 -> -0.19465247 | AS13: =AI13/AP13 -> -0.55844968
B14: Giá bán | D14: =D13+E13-F14 -> 2.2350949e+10 | E14: =IF(H14>0,H14,0) -> 0 | F14: =IF(H14<0,-H14,0) -> 77692396 | H14: =M14 -> -77692396 | M14: -77692396 | O14: $/tấn | P14: 892.78362 | Q14: 761.93327 | R14: =Q14-P14 -> -130.85035 | S14: =R14/P14 -> -0.14656446 | U14: 25000 | V14: 26137.299 | W14: =V14-U14 -> 1137.2995 | X14: =W14/U14 -> 0.045491978
B15: Giá vốn | D15: =D14+E14-F15 -> 2.2279184e+10 | E15: =IF(H15>0,H15,0) -> 0 | F15: =IF(H15<0,-H15,0) -> 71765673 | H15: =M15 -> -71765673 | M15: -71765673 | O15: VND/kg | P15: 26664.154 | Q15: 29685.867 | R15: =Q15-P15 -> 3021.7125 | S15: =R15/P15 -> 0.1133249
A16: Xơ sợi | B16: Sản lượng | D16: =D15+E15-F16 -> 2.2278924e+10 | E16: =IF(H16>0,H16,0) -> 0 | F16: =IF(H16<0,-H16,0) -> 259726.54 | H16: =M16 -> -259726.54 | M16: {=TRANSPOSE(AA16:AC16)} -> -259726.54 | O16: tấn | P16: 100 | Q16: 110.05 | R16: =Q16-P16 -> 10.05 | S16: =R16/P16 -> 0.1005 | Z16: =SUM(AA16:AD16) -> -8.5055229e+08 | AA16: =R16*(P17*U17-P18*10^3) -> -259726.54 | AB16: =R17*Q16*U17 -> -1.0871463e+09 | AC16: =-R18*Q16*10^3 -> 1.4863443e+08 | AD16: =Q16*Q17*W17 -> 88219348 | AE16: -8.5055229e+08 | AF16: =Z16-AE16 -> 0 | AH16: =P16*(P17*U17-P18*10^3) -> -2584343.7 | AI16: =Q16*(Q17*U17-Q18*10^3) -> -9.4135598e+08 | AJ16: =AI16-AH16 -> -9.3877164e+08 | AK16: =AJ16/AH16 -> 363.2534 | AM16: =Q16*(Q17*V17-Q18*10^3) -> -8.5313663e+08 | AN16: =AM16-AI16-AD16 -> 0 | AO16: ='S7'!AE12 -> 2750000000 | AP16: ='S7'!AF12 -> 1.9392287e+09 | AR16: =AH16/AO16 -> -0.00093976134 | AS16: =AI16/AP16 -> -0.48542805
B17: Giá bán | D17: =D16+E16-F17 -> 2.1191778e+10 | E17: =IF(H17>0,H17,0) -> 0 | F17: =IF(H17<0,-H17,0) -> 1.0871463e+09 | H17: =M17 -> -1.0871463e+09 | M17: -1.0871463e+09 | O17: $/tấn | P17: 1100 | Q17: 704.85367 | R17: =Q17-P17 -> -395.14633 | S17: =R17/P17 -> -0.35922394 | U17: 25000 | V17: 26137.299 | W17: =V17-U17 -> 1137.2995 | X17: =W17/U17 -> 0.045491978
B18: Giá vốn | D18: =D17+E17-F18 -> 2.1191778e+10 | E18: =IF(H18>0,H18,0) -> 1.4863443e+08 | F18: =IF(H18<0,-H18,0) -> 0 | H18: =M18 -> 1.4863443e+08 | M18: 1.4863443e+08 | O18: VND/kg | P18: 27525.843 | Q18: 26175.235 | R18: =Q18-P18 -> -1350.6081 | S18: =R18/P18 -> -0.049066912
A19: Tỷ giá | D19: =D18+E18-F19 -> 2.1340412e+10 | E19: =IF(H19>0,H19,0) -> 3.7842287e+09 | F19: =IF(H19<0,-H19,0) -> 0 | H19: =M19 -> 3.7842287e+09 | M19: =AD4+AD7+AD10+AD13+AD16 -> 3.7842287e+09
A20: Khác | D20: =D19+E19-F20 -> 2.5124641e+10 | E20: =IF(H20>0,H20,0) -> 2.0245328e+10 | F20: =IF(H20<0,-H20,0) -> 0 | H20: =H22-SUM(H3:H19,H21) -> 2.0245328e+10 | AH20: =AH22-SUM(AH3:AH19) -> 13898568900 | AI20: =AI22-SUM(AI3:AI19) -> 2.3940503e+10 | AJ20: =AI20-AH20 -> 1.0041934e+10 | AK20: =AJ20/AH20 -> 0.72251567 | AO20: ='S7'!AE15 -> 18507918900 | AP20: ='S7'!AF15 -> 1.4917296e+10
A21: Cp vận chuyển, hoa hồng, chiết khấu | D21: =D20+E20-F21 -> 3.5166575e+10 | E21: =IF(H21>0,H21,0) -> 0 | F21: =IF(H21<0,-H21,0) -> 1.0203394e+10 | H21: =G27-C27 -> -1.0203394e+10
A22: ='S7'!A17 -> TT T12 | G22: =D21+E21 -> 3.5166575e+10 | H22: 3.5166575e+10 | I22: =H22-H3 -> -1.3411914e+10 | J22: =H22/H3-1 -> -0.27608751 | U22: 25000 | V22: 26142.715 | W22: =V22-U22 -> 1142.7146 | X22: =W22/U22 -> 0.045708584 | AH22: =C3 -> 4.8578489e+10 | AI22: =G22-H19 -> 3.1382346e+10 | AJ22: =AI22-AH22 -> -1.7196143e+10 | AK22: =AJ22/AH22 -> -0.35398678 | AO22: =SUM(AO3:AO20) -> 207862203900 | AP22: =SUM(AP3:AP20) -> 9.7650854e+10
A23: Check | F23: =G22-C3 -> -1.3411914e+10 | G23: =G22-H22 -> 0 | AO23: =AO22-'S7'!AE17 -> 0 | AP23: =AP22-'S7'!AF17 -> 0
F24: =F23/C3 -> -0.27608751 | AI24: =G24 -> 0
C26: KH | G26: TT
A27: Cp vận chuyển, hoa hồng, chiết khấu | C27: ='S7'!C20 -> 12595919900 | G27: ='S7'!G20 -> 2.3925254e+09
A28: Trong đó: Pallet | C28: 0 | G28: 2.4228471e+08
A29: LG EXW | C29: =C3-C27+C28 -> 3.5982569e+10 | G29: =G22-G27+G28 -> 3.3016334e+10 | H29: =G29-C29 -> -2.9662349e+09
A31: Tài trợ | C31: ='S6'!B25 -> 3271999000 | G31: ='S6'!C25 -> 8295287500
A32: LG EXW không gồm tài trợ | C32: =C29-C31 -> 3.271057e+10 | G32: =G29-G31 -> 2.4721046e+10 | H32: =G32-G23 -> 2.4721046e+10
A33: Dthu EXW không gồm tài trợ | C33: ='S6'!B29-'S6'!B28-C31 -> 191994285000 | G33: ='S6'!C29-'S6'!C28-'S6'!C25 -> 9.074727e+10
A34: %Biên | C34: =IFERROR(C32/C33,0) -> 0.17037262 | G34: =IFERROR(G32/G33,0) -> 0.27241642
H39: =SUM(H5:H6,H8:H9,H11:H12,H14:H15,H17:H18) -> -8.5686895e+09
G40: Tổng t/đ SL | H40: =H4+H7+H10+H13+H16 -> -1.8669387e+10
G41: SL-LNST | H41: =H40*(1-13.11%) -> -1.622183e+10
G43: Tổng t/đ LG đơn vị | H43: =H5+H6+H8+H9+H11+H12+H14+H15+H17+H18 -> -8.5686895e+09
G44: LGĐV-LNST | H44: =H43*(1-13.11%) -> -7.4453343e+09
G46: PET | H46: =SUM(H5:H6) -> -5.0974483e+09
G47: PET-LNST | H47: =H46*(1-13.11%) -> -4.4291728e+09
G49: Xơ sợi | H49: =SUM(H17:H18) -> -9.3851191e+08
...

Sheet BĐ-LG EXW-v2
C4: =C12/C7 -> 0.039634091
A5: ĐVT: VND; kg; VND/kg; USD/ton | K5: TÁC ĐỘNG
B6: KH | C6: TT | D6: +/ | F6: %Cơ cấu SL-KH | G6: %Cơ cấu SL-TT | H6: SL-TT-Cơ cấu KH | I6: DT-TT-Cơ cấu KH | K6: Sản lượng | L6: Cơ cấu ngành | M6: Giá bán | N6: Tỷ giá | O6: Khác | P6: Cp vận chuyển, hoa hồng, chiết khấu
A7: Sản lượng SPC | B7: =SUM(B8:B12) -> 5940960 | C7: =SUM(C8:C12) -> 2776650 | D7: =C7-B7 -> -3164310 | E7: =D7/B7 -> -0.53262604 | H7: =SUM(H8:H12) -> 2776650
A8: rPET | B8: ='S6'!B8 -> 4674770 | C8: ='S6'!C8 -> 2255200 | D8: =C8-B8 -> -2419570 | F8: =B8/B$7 -> 0.78687115 | G8: =C8/C$7 -> 0.81220175 | H8: =F8*C$7 -> 2184865.8
A9: rHDPE thổi | B9: ='S6'!B9 -> 916000 | C9: ='S6'!C9 -> 272500 | D9: =C9-B9 -> -643500 | F9: =B9/B$7 -> 0.15418384 | G9: =C9/C$7 -> 0.098139845 | H9: =F9*C$7 -> 428114.55
A10: rHDPE ép | B10: ='S6'!B10 -> 162750 | C10: ='S6'!C10 -> 115150 | D10: =C10-B10 -> -47600 | F10: =B10/B$7 -> 0.027394562 | G10: =C10/C$7 -> 0.041470837 | H10: =F10*C$7 -> 76065.112
A11: rPP | B11: ='S6'!B11 -> 87440 | C11: ='S6'!C11 -> 23750 | D11: =C11-B11 -> -63690 | F11: =B11/B$7 -> 0.01471816 | G11: =C11/C$7 -> 0.0085534727 | H11: =F11*C$7 -> 40867.179
A12: Xơ sợi | B12: ='S6'!B12 -> 100000 | C12: ='S6'!C12 -> 110050 | D12: =C12-B12 -> 10050 | F12: =B12/B$7 -> 0.016832296 | G12: =C12/C$7 -> 0.039634091 | H12: =F12*C$7 -> 46737.396
A13: GB EXW (VND/kg) | B13: 30553.285 | C13: 28801.443 | D13: =C13-B13 -> -1751.8418 | I13: =SUM(I14:I18) -> 8.8499262e+10
A14: rPET | B14: ='S6'!B14 -> 32231.125 | C14: ='S6'!C14 -> 32376.575 | I14: =H8*B14 -> 7.0420682e+10
A15: rHDPE thổi | B15: ='S6'!B15 -> 33420.306 | C15: ='S6'!C15 -> 32756.935 | I15: =H9*B15 -> 1.4307719e+10
A16: rHDPE ép | B16: ='S6'!B16 -> 20685.484 | C16: ='S6'!C16 -> 18023.826 | I16: =H10*B16 -> 1.5734436e+09
A17: rPP | B17: ='S6'!B17 -> 22319.591 | C17: ='S6'!C17 -> 19914.878 | I17: =H11*B17 -> 9.121387e+08
A18: Xơ sợi | B18: ='S6'!B18 -> 27500 | C18: ='S6'!C18 -> 18422.971 | I18: =H12*B18 -> 1.2852784e+09
A19: Doanh thu SPC | B19: =SUM(B20:B24) -> 189354285000 | C19: =SUM(C20:C24) -> 8.6517786e+10 | D19: =C19-B19 -> -1.028365e+11
A20: rPET | B20: =B8*B14 -> 150673097500 | C20: =C8*C14 -> 7.3015652e+10 | D20: =C20-B20 -> -7.7657446e+10 | K20: =I14-B20 -> -8.0252415e+10 | L20: =C8*B14-I14 -> 2.2669515e+09 | M20: =D63*C8/10^3*$B$69 -> -2.868699e+09 | N20: =IFERROR(C20-C20/C70*B70,0) -> 3.1967169e+09
A21: rHDPE thổi | B21: =B9*B15 -> 3.0613e+10 | C21: =C9*C15 -> 8.9262647e+09 | D21: =C21-B21 -> -2.1686735e+10 | K21: =I15-B21 -> -1.6305281e+10 | L21: =C9*B15-I15 -> -5.2006857e+09 | M21: =D64*C9/10^3*$B$69 -> -5.6917281e+08 | N21: =IFERROR(C21-C21/C71*B71,0) -> 3.8840416e+08
A22: rHDPE ép | B22: =B10*B16 -> 3.3665625e+09 | C22: =C10*C16 -> 2.0754435e+09 | D22: =C22-B22 -> -1.291119e+09 | K22: =I16-B22 -> -1.7931189e+09 | L22: =C10*B16-I16 -> 8.0848982e+08 | M22: =D65*C10/10^3*$B$69 -> -3.9679767e+08 | N22: =IFERROR(C22-C22/C72*B72,0) -> 90307755
A23: rPP | B23: =B11*B17 -> 1.951625e+09 | C23: =C11*C17 -> 4.7297836e+08 | D23: =C23-B23 -> -1.4786466e+09 | K23: =I17-B23 -> -1.0394863e+09 | L23: =C11*B17-I17 -> -3.8204843e+08 | M23: =D66*C11/10^3*$B$69 -> -77692396 | N23: =IFERROR(C23-C23/C73*B73,0) -> 20580475
A24: Xơ sợi | B24: =B12*B18 -> 2.75e+09 | C24: =C12*C18 -> 2.027448e+09 | D24: =C24-B24 -> -7.2255199e+08 | K24: =I18-B24 -> -1.4647216e+09 | L24: =C12*B18-I18 -> 1.7410966e+09 | M24: =D67*C12/10^3*$B$69 -> -1.0871463e+09 | N24: =IFERROR(C24-C24/C74*B74,0) -> 88219348
A25: Tài trợ | B25: ='S6'!B25 -> 3271999000 | C25: ='S6'!C25 -> 8295287500 | D25: =C25-B25 -> 5023288500 | O25: =D25 -> 5023288500 | Q25: =SUM(K25:P25) -> 5023288500
A26: Dây đai, phó sản | B26: ='S6'!B26 -> 2640000000 | C26: ='S6'!C26 -> 3.5977384e+09 | D26: =C26-B26 -> 9.5773843e+08 | O26: =D26 -> 9.5773843e+08 | Q26: =SUM(K26:P26) -> 9.5773843e+08
A27: Khác | B27: ='S6'!B27 -> 0 | C27: ='S6'!C27 -> 6.3174504e+08 | D27: =C27-B27 -> 6.3174504e+08 | O27: =D27 -> 6.3174504e+08 | Q27: =SUM(K27:P27) -> 6.3174504e+08
A28: Cp vận chuyển, hoa hồng, chiết khấu | B28: ='S8'!C27 -> 12595919900 | C28: ='S8'!G27 -> 2.3925254e+09 | D28: =C28-B28 -> -1.0203394e+10 | P28: =D28 -> -1.0203394e+10 | Q28: =SUM(K28:P28) -> -1.0203394e+10
A29: Tổng dthu thuần | B29: =B19+B25+B26+B27+B28 -> 207862203900 | C29: =C19+C25+C26+C27+C28 -> 101435082581 | D29: =C29-B29 -> -106427121319 | K29: =SUM(K7:K28) -> -1.0085502e+11 | L29: =SUM(L7:L28) -> -7.6619622e+08 | M29: =SUM(M7:M28) -> -4.9995082e+09 | N29: =SUM(N7:N28) -> 3.7842287e+09 | O29: =SUM(O7:O28) -> 6.612772e+09 | P29: =SUM(P7:P28) -> -1.0203394e+10 | Q29: =SUM(K29:P29) -> -106427121319
P30: Check | Q30: =Q29-D29 -> 0
A31: GVĐV (đ/kg)
A32: rPET | B32: 26064.53 | C32: 27052.802 | D32: =C32-B32 -> 988.27121
A33: rHDPE thổi | B33: 27558.24 | C33: 28309.839 | D33: =C33-B33 -> 751.5991
A34: rHDPE ép | B34: 15368.575 | C34: 25898.232 | D34: =C34-B34 -> 10529.657
A35: rPP | B35: 26664.154 | C35: 29685.867 | D35: =C35-B35 -> 3021.7125
A36: Xơ sợi | B36: 27525.843 | C36: 26175.235 | D36: =C36-B36 -> -1350.6081
A38: GVHB-SPC | B38: =SUM(B39:B43) -> 1.5467437e+11 | C38: =SUM(C39:C43) -> 7.5291714e+10
A39: rPET | B39: =B32*B8 -> 1.2184568e+11 | C39: =C32*C8 -> 6.1009478e+10
A40: rHDPE thổi | B40: =B33*B9 -> 2.5243347e+10 | C40: =C33*C9 -> 7.714431e+09
A41: rHDPE ép | B41: =B34*B10 -> 2.5012355e+09 | C41: =C34*C10 -> 2.9821814e+09
A42: rPP | B42: =B35*B11 -> 2.3315136e+09 | C42: =C35*C11 -> 705039330
A43: Xơ sợi | B43: =B36*B12 -> 2.7525843e+09 | C43: =C36*C12 -> 2880584644
A44: Tài trợ
...

Sheet S10
A1: -1
A2: CHỈ TIÊU | B2: KH | C2: TT | D2: +/- | E2: %+/-
A3: LG EXW | B3: ='S8'!C3-('S8'!C27-'S8'!C28) -> 3.5982569e+10 | C3: ='S8'!G22-('S8'!G27-'S8'!G28) -> 3.3016334e+10 | D3: =C3-B3 -> -2.9662349e+09 | E3: =IFERROR(D3/B3,0) -> -0.082435329
A4: CPBH | B4: -1039387157 | C4: -2567444870 | D4: =C4-B4 -> -1528057713 | E4: =IFERROR(D4/B4,0) -> 1.4701526
A5: CPQLDN | B5: -1.0870136e+10 | C5: -10510637512 | D5: =C5-B5 -> 3.5949871e+08 | E5: =IFERROR(D5/B5,0) -> -0.033072144
A6: Cp lãi vay | B6: -4.7382862e+09 | C6: -1256103396 | D6: =C6-B6 -> 3.4821828e+09 | E6: =IFERROR(D6/B6,0) -> -0.73490343
A7: Dthu/Cp tài chính-Tỷ giá | C7: -830498211 | D7: =C7-B7 -> -830498211 | E7: =IFERROR(D7/B7,0) -> 0
A8: Lãi tiền gửi | B8: 326826000 | C8: 313729918 | D8: =C8-B8 -> -13096082 | E8: =IFERROR(D8/B8,0) -> -0.040070502
A9: Thu nhập/Chi phí khác | C9: -1560547381 | D9: =C9-B9 -> -1560547381 | E9: =IFERROR(D9/B9,0) -> 0
A10: Thuế TNDN | B10: -2.7526219e+09 | C10: -2388437945 | D10: =C10-B10 -> 3.6418397e+08 | E10: =IFERROR(D10/B10,0) -> -0.13230439
A11: LNST | B11: =SUM(B3:B10) -> 1.6908963e+10 | C11: =SUM(C3:C10) -> 1.4216394e+10 | D11: =C11-B11 -> -2.6925688e+09 | E11: =IFERROR(D11/B11,0) -> -0.15923914
B14: Start | C14: Hidden | D14: Increase | E14: Decrease | F14: End | I14: Increase | J14: Decrease | K14: Cumulative
A15: ='S7'!A3 -> KH T12 | B15: =B11 -> 1.6908963e+10
A16: LG EXW | C16: =B15-E16 -> 1.3942728e+10 | D16: =IF(G16>0,G16,0) -> 0 | E16: =IF(G16<0,-G16,0) -> 2.9662349e+09 | G16: =D3 -> -2.9662349e+09 | H16: =B15+G16 -> 1.3942728e+10 | I16: =IF(G16>0,G16,0) -> 0 | J16: =IF(G16<0,-G16,0) -> 2.9662349e+09 | K16: =SUM($B$15,G$16:G16) -> 1.3942728e+10
A17: CPBH | C17: =C16+D16-E17 -> 1.2414671e+10 | D17: =IF(G17>0,G17,0) -> 0 | E17: =IF(G17<0,-G17,0) -> 1528057713 | G17: =D4 -> -1528057713 | H17: =H16+G17 -> 1.2414671e+10 | I17: =IF(G17>0,G17,0) -> 0 | J17: =IF(G17<0,-G17,0) -> 1528057713 | K17: =SUM($B$15,G$16:G17) -> 1.2414671e+10
A18: CPQLDN | C18: =C17+D17-E18 -> 1.2414671e+10 | D18: =IF(G18>0,G18,0) -> 3.5949871e+08 | E18: =IF(G18<0,-G18,0) -> 0 | G18: =D5 -> 3.5949871e+08 | H18: =H17+G18 -> 1.2774169e+10 | I18: =IF(G18>0,G18,0) -> 3.5949871e+08 | J18: =IF(G18<0,-G18,0) -> 0 | K18: =SUM($B$15,G$16:G18) -> 1.2774169e+10
A19: Cp lãi vay | C19: =C18+D18-E19 -> 1.2774169e+10 | D19: =IF(G19>0,G19,0) -> 3.4821828e+09 | E19: =IF(G19<0,-G19,0) -> 0 | G19: =D6 -> 3.4821828e+09 | H19: =H18+G19 -> 1.6256352e+10 | I19: =IF(G19>0,G19,0) -> 3.4821828e+09 | J19: =IF(G19<0,-G19,0) -> 0 | K19: =SUM($B$15,G$16:G19) -> 1.6256352e+10
A20: Dthu/Cp tài chính-Tỷ giá | C20: =C19+D19-E20 -> 1.5425854e+10 | D20: =IF(G20>0,G20,0) -> 0 | E20: =IF(G20<0,-G20,0) -> 830498211 | G20: =D7 -> -830498211 | H20: =H19+G20 -> 1.5425854e+10 | I20: =IF(G20>0,G20,0) -> 0 | J20: =IF(G20<0,-G20,0) -> 830498211 | K20: =SUM($B$15,G$16:G20) -> 1.5425854e+10
A21: Lãi tiền gửi | C21: =C20+D20-E21 -> 1.5412758e+10 | D21: =IF(G21>0,G21,0) -> 0 | E21: =IF(G21<0,-G21,0) -> 13096082 | G21: =D8 -> -13096082 | H21: =H20+G21 -> 1.5412758e+10 | I21: =IF(G21>0,G21,0) -> 0 | J21: =IF(G21<0,-G21,0) -> 13096082 | K21: =SUM($B$15,G$16:G21) -> 1.5412758e+10
A22: Thu nhập khác | C22: =C21+D21-E22 -> 1.385221e+10 | D22: =IF(G22>0,G22,0) -> 0 | E22: =IF(G22<0,-G22,0) -> 1560547381 | G22: =D9 -> -1560547381 | H22: =H21+G22 -> 1.385221e+10 | I22: =IF(G22>0,G22,0) -> 0 | J22: =IF(G22<0,-G22,0) -> 1560547381 | K22: =SUM($B$15,G$16:G22) -> 1.385221e+10
A23: Thuế TNDN | C23: =C22+D22-E23 -> 1.385221e+10 | D23: =IF(G23>0,G23,0) -> 3.6418397e+08 | E23: =IF(G23<0,-G23,0) -> 0 | G23: =D10 -> 3.6418397e+08 | H23: =H22+G23 -> 1.4216394e+10 | I23: =IF(G23>0,G23,0) -> 3.6418397e+08 | J23: =IF(G23<0,-G23,0) -> 0 | K23: =SUM($B$15,G$16:G23) -> 1.4216394e+10
A24: ='S7'!A17 -> TT T12 | F24: =C23+D23 -> 1.4216394e+10
F25: =F24-C11 -> 0
A27: Dthu | B27: ='S7'!C3 -> 207862203900 | C27: ='S7'!G17 -> 101435082581
B28: =B11/B27 -> 0.081346983 | C28: =C11/C27 -> 0.14015264
B58: Tổng t/đ SL | C58: -2.2184183e+10
B59: SL-LNST | C59: -1.9275837e+10
B61: Tổng t/đ LG đơn vị | C61: -1.4265745e+10
B62: LGĐV-LNST | C62: -1.2395506e+10

Sheet Giải trình
C2: Thuế suất | D2: 0.1311
A3: STT | B3: Tác động | C3: LNTT | D3: LNST | E3: Ghi chú
A4: =IF(B4<>"",SUBTOTAL(3,B$4:B4),"") -> 1 | B4: Tác động sản lượng | C4: ='S8'!H4+'S8'!H7+'S8'!H10+'S8'!H13+'S8'!H16 -> -1.8669387e+10 | D4: =C4*(1-$D$2) -> -1.622183e+10
A5: =IF(B5<>"",SUBTOTAL(3,B$4:B5),"") -> 2 | B5: Giá bán trung bình ngành rPET thấp sv KH | C5: ='S8'!$H$5 -> -2.868699e+09 | D5: =C5*(1-$D$2) -> -2.4926126e+09
A6: =IF(B6<>"",SUBTOTAL(3,B$4:B6),"") -> 3 | B6: Giá vốn trung bình rPET tăng | C6: ='S8'!$H$6 -> -2.2287492e+09 | D6: =C6*(1-$D$2) -> -1.9365602e+09
A7: =IF(B7<>"",SUBTOTAL(3,B$4:B7),"") -> 4 | B7: Đẩy bán HD ép | C7: ='S8'!H11+'S8'!H12 -> -1.6092877e+09 | D7: =C7*(1-$D$2) -> -1.39831e+09
B9: Điều chỉnh thuê xưởng, thuê máy theo yêu cầu kiểm toán | C9: 11414476126 | D9: =C9*(1-$D$2) -> 9.9180383e+09
B10: Điều chỉnh lương vào IO | C10: 4428241305 | D10: =C10*(1-$D$2) -> 3.8476989e+09
B11: EPR | C11: ='BĐ-LG EXW-v2'!D25 -> 5023288500 | D11: =C11*(1-$D$2) -> 4.3647354e+09
A13: =IF(B13<>"",SUBTOTAL(3,B$4:B13),"") -> 8 | B13: Tổng | C13: =SUM(C4:C12) -> -4.510117e+09 | D13: =SUM(D4:D12) -> -3.9188407e+09
