Workbook

Sheet PnL đầy đủ
A1: BẢNG TÍNH PnL
A3: DANH MỤC | F3: NGUỒN VỐN | H3: =SUM(H5:H8) -> 4909500000 | J3: DANH MỤC | O3: NGUỒN VỐN | Q3: =SUM(Q5:Q8) -> 4909500000 | S3: DANH MỤC | X3: NGUỒN VỐN | Z3: =SUM(Z5:Z8) -> 4909500000 | AB3: DANH MỤC | AG3: NGUỒN VỐN | AI3: =SUM(AI5:AI8) -> 4909500000 | AK3: DANH MỤC | AP3: NGUỒN VỐN | AR3: =SUM(AR5:AR8) -> 4909500000 | AT3: DANH MỤC | AY3: NGUỒN VỐN | BA3: =SUM(BA5:BA8) -> 4909500000
A5: 1 | B5: Sản lượng chai xá/ngày | C5: =C6/26 -> 23076.923 | D5: Kg | F5: 1 | G5: Chi phí đầu tư 1 chuyền | H5: =G43+G53 -> 2103000000 | J5: 1 | K5: Sản lượng chai xá/ngày | L5: =L6/26 -> 1153.8462 | M5: Kg | O5: 1 | P5: Chi phí đầu tư 1 chuyền | Q5: =P43+P53 -> 2103000000 | S5: 1 | T5: Sản lượng chai xá/ngày | U5: =U6/26 -> 1923.0769 | V5: Kg | X5: 1 | Y5: Chi phí đầu tư 1 chuyền | Z5: =Y43+Y53 -> 2103000000 | AB5: 1 | AC5: Sản lượng chai xá/ngày | AD5: =AD6/26 -> 3461.5385 | AE5: Kg | AG5: 1 | AH5: Chi phí đầu tư 1 chuyền | AI5: =AH43+AH53 -> 2103000000 | AK5: 1 | AL5: Sản lượng chai xá/ngày | AM5: =AM6/26 -> 3846.1538 | AN5: Kg | AP5: 1 | AQ5: Chi phí đầu tư 1 chuyền | AR5: =AQ43+AQ53 -> 2103000000 | AT5: 1 | AU5: Sản lượng chai xá/ngày | AV5: =AV6/26 -> 5769.2308 | AW5: Kg | AY5: 1 | AZ5: Chi phí đầu tư 1 chuyền | BA5: =AZ43+AZ53 -> 2103000000
A6: 2 | B6: Sản lượng sản xuất / tháng (26 ngày) | C6: 600000 | D6: Kg | F6: 2 | G6: Đầu tư CSHT | H6: =G57 -> 806500000 | J6: 2 | K6: Sản lượng sản xuất / tháng (26 ngày) | L6: 30000 | M6: Kg | O6: 2 | P6: Đầu tư CSHT | Q6: =P57 -> 806500000 | S6: 2 | T6: Sản lượng sản xuất / tháng (26 ngày) | U6: 50000 | V6: Kg | X6: 2 | Y6: Đầu tư CSHT | Z6: =Y57 -> 806500000 | AB6: 2 | AC6: Sản lượng sản xuất / tháng (26 ngày) | AD6: 90000 | AE6: Kg | AG6: 2 | AH6: Đầu tư CSHT | AI6: =AH57 -> 806500000 | AK6: 2 | AL6: Sản lượng sản xuất / tháng (26 ngày) | AM6: 100000 | AN6: Kg | AP6: 2 | AQ6: Đầu tư CSHT | AR6: =AQ57 -> 806500000 | AT6: 2 | AU6: Sản lượng sản xuất / tháng (26 ngày) | AV6: 150000 | AW6: Kg | AY6: 2 | AZ6: Đầu tư CSHT | BA6: =AZ57 -> 806500000
A7: 3 | B7: Giá chai xá mua trung bình tại vựa (GV) | C7: 8000 | D7: Vnđ/Kg | F7: 3 | G7: Xe | H7: 0 | J7: 3 | K7: Giá chai xá mua trung bình tại vựa (GV) | L7: 8000 | M7: Vnđ/Kg | O7: 3 | P7: Xe | Q7: 0 | S7: 3 | T7: Giá chai xá mua trung bình tại vựa (GV) | U7: 8000 | V7: Vnđ/Kg | X7: 3 | Y7: Xe | Z7: 0 | AB7: 3 | AC7: Giá chai xá mua trung bình tại vựa (GV) | AD7: 8000 | AE7: Vnđ/Kg | AG7: 3 | AH7: Xe | AI7: 0 | AK7: 3 | AL7: Giá chai xá mua trung bình tại vựa (GV) | AM7: 8000 | AN7: Vnđ/Kg | AP7: 3 | AQ7: Xe | AR7: 0 | AT7: 3 | AU7: Giá chai xá mua trung bình tại vựa (GV) | AV7: 8000 | AW7: Vnđ/Kg | AY7: 3 | AZ7: Xe | BA7: 0
A8: 4 | B8: Đơn giá gia công (CP+KH-GV) | C8: =F13-C7 -> 1203 | D8: Vnđ/Kg | F8: 4 | G8: Vốn lưu động + dự phòng | H8: 2000000000 | J8: 4 | K8: Đơn giá gia công (CP+KH-GV) | L8: =O13-L7 -> 2404 | M8: Vnđ/Kg | O8: 4 | P8: Vốn lưu động + dự phòng | Q8: 2000000000 | S8: 4 | T8: Đơn giá gia công (CP+KH-GV) | U8: =X13-U7 -> 1838 | V8: Vnđ/Kg | X8: 4 | Y8: Vốn lưu động + dự phòng | Z8: 2000000000 | AB8: 4 | AC8: Đơn giá gia công (CP+KH-GV) | AD8: =AG13-AD7 -> 1736 | AE8: Vnđ/Kg | AG8: 4 | AH8: Vốn lưu động + dự phòng | AI8: 2000000000 | AK8: 4 | AL8: Đơn giá gia công (CP+KH-GV) | AM8: =AP13-AM7 -> 1651 | AN8: Vnđ/Kg | AP8: 4 | AQ8: Vốn lưu động + dự phòng | AR8: 2000000000 | AT8: 4 | AU8: Đơn giá gia công (CP+KH-GV) | AV8: =AY13-AV7 -> 1423 | AW8: Vnđ/Kg | AY8: 4 | AZ8: Vốn lưu động + dự phòng | BA8: 2000000000
A9: 5 | B9: Lãi gộp kỳ vọng (LG) | C9: 500 | D9: Vnđ/Kg | J9: 5 | K9: Lãi gộp kỳ vọng (LG) | L9: 500 | M9: Vnđ/Kg | S9: 5 | T9: Lãi gộp kỳ vọng (LG) | U9: 500 | V9: Vnđ/Kg | AB9: 5 | AC9: Lãi gộp kỳ vọng (LG) | AD9: 500 | AE9: Vnđ/Kg | AK9: 5 | AL9: Lãi gộp kỳ vọng (LG) | AM9: 500 | AN9: Vnđ/Kg | AT9: 5 | AU9: Lãi gộp kỳ vọng (LG) | AV9: 500 | AW9: Vnđ/Kg
A11: STT | B11: DANH MỤC | C11: CHI TIẾT | D11: TỈ LỆ/ĐVT | E11: SL | F11: ĐƠN GIÁ | G11: THÀNH TIỀN | H11: GHI CHÚ | J11: STT | K11: DANH MỤC | L11: CHI TIẾT | M11: TỈ LỆ/ĐVT | N11: SL | O11: ĐƠN GIÁ | P11: THÀNH TIỀN | Q11: GHI CHÚ | S11: STT | T11: DANH MỤC | U11: CHI TIẾT | V11: TỈ LỆ/ĐVT | W11: SL | X11: ĐƠN GIÁ | Y11: THÀNH TIỀN | Z11: GHI CHÚ | AB11: STT | AC11: DANH MỤC | AD11: CHI TIẾT | AE11: TỈ LỆ/ĐVT | AF11: SL | AG11: ĐƠN GIÁ | AH11: THÀNH TIỀN | AI11: GHI CHÚ | AK11: STT | AL11: DANH MỤC | AM11: CHI TIẾT | AN11: TỈ LỆ/ĐVT | AO11: SL | AP11: ĐƠN GIÁ | AQ11: THÀNH TIỀN | AR11: GHI CHÚ | AT11: STT | AU11: DANH MỤC | AV11: CHI TIẾT | AW11: TỈ LỆ/ĐVT | AX11: SL | AY11: ĐƠN GIÁ | AZ11: THÀNH TIỀN | BA11: GHI CHÚ
A12: A | B12: Doanh thu | D12: Kg | E12: =E13 -> 570000 | F12: =IF(SUM(C7:C9)>9700,9700,SUM(C7:C9)) -> 9700 | G12: =E12*F12 -> 5529000000 | J12: A | K12: Doanh thu | M12: Kg | N12: =N13 -> 28500 | O12: =IF(SUM(L7:L9)>9700,9700,SUM(L7:L9)) -> 9700 | P12: =N12*O12 -> 276450000 | S12: A | T12: Doanh thu | V12: Kg | W12: =W13 -> 47500 | X12: =IF(SUM(U7:U9)>9700,9700,SUM(U7:U9)) -> 9700 | Y12: =W12*X12 -> 460750000 | AB12: A | AC12: Doanh thu | AE12: Kg | AF12: =AF13 -> 85500 | AG12: =IF(SUM(AD7:AD9)>9700,9700,SUM(AD7:AD9)) -> 9700 | AH12: =AF12*AG12 -> 829350000 | AK12: A | AL12: Doanh thu | AN12: Kg | AO12: =AO13 -> 95000 | AP12: =IF(SUM(AM7:AM9)>9700,9700,SUM(AM7:AM9)) -> 9700 | AQ12: =AO12*AP12 -> 921500000 | AT12: A | AU12: Doanh thu | AW12: Kg | AX12: =AX13 -> 142500 | AY12: =IF(SUM(AV7:AV9)>9700,9700,SUM(AV7:AV9)) -> 9700 | AZ12: =AX12*AY12 -> 1382250000
A13: B | B13: Tổng chi phí gia công thành phẩm (CP) | D13: Kg | E13: =C6-E18 -> 570000 | F13: =ROUNDUP(G13/E13,0) -> 9203 | G13: =G14+G25+G32+G38+G40+G56 -> 5.2454529e+09 | J13: B | K13: Tổng chi phí gia công thành phẩm (CP) | M13: Kg | N13: =L6-N18 -> 28500 | O13: =ROUNDUP(P13/N13,0) -> 10404 | P13: =P14+P25+P32+P38+P40+P56 -> 2.9650198e+08 | S13: B | T13: Tổng chi phí gia công thành phẩm (CP) | V13: Kg | W13: =U6-W18 -> 47500 | X13: =ROUNDUP(Y13/W13,0) -> 9838 | Y13: =Y14+Y25+Y32+Y38+Y40+Y56 -> 4.6728885e+08 | AB13: B | AC13: Tổng chi phí gia công thành phẩm (CP) | AE13: Kg | AF13: =AD6-AF18 -> 85500 | AG13: =ROUNDUP(AH13/AF13,0) -> 9736 | AH13: =AH14+AH25+AH32+AH38+AH40+AH56 -> 8.3238759e+08 | AK13: B | AL13: Tổng chi phí gia công thành phẩm (CP) | AN13: Kg | AO13: =AM6-AO18 -> 95000 | AP13: =ROUNDUP(AQ13/AO13,0) -> 9651 | AQ13: =AQ14+AQ25+AQ32+AQ38+AQ40+AQ56 -> 9.1678103e+08 | AT13: B | AU13: Tổng chi phí gia công thành phẩm (CP) | AW13: Kg | AX13: =AV6-AX18 -> 142500 | AY13: =ROUNDUP(AZ13/AX13,0) -> 9423 | AZ13: =AZ14+AZ25+AZ32+AZ38+AZ40+AZ56 -> 1.3427482e+09
A14: 1 | B14: COGS | D14: Kg | E14: =E13 -> 570000 | F14: =G14/E14 -> 8421.0526 | G14: =SUM(G15:G18) -> 4800000000 | J14: 1 | K14: COGS | M14: Kg | N14: =N13 -> 28500 | O14: =P14/N14 -> 8421.0526 | P14: =SUM(P15:P18) -> 240000000 | S14: 1 | T14: COGS | V14: Kg | W14: =W13 -> 47500 | X14: =Y14/W14 -> 8421.0526 | Y14: =SUM(Y15:Y18) -> 400000000 | AB14: 1 | AC14: COGS | AE14: Kg | AF14: =AF13 -> 85500 | AG14: =AH14/AF14 -> 8421.0526 | AH14: =SUM(AH15:AH18) -> 720000000 | AK14: 1 | AL14: COGS | AN14: Kg | AO14: =AO13 -> 95000 | AP14: =AQ14/AO14 -> 8421.0526 | AQ14: =SUM(AQ15:AQ18) -> 800000000 | AT14: 1 | AU14: COGS | AW14: Kg | AX14: =AX13 -> 142500 | AY14: =AZ14/AX14 -> 8421.0526 | AZ14: =SUM(AZ15:AZ18) -> 1200000000
A15: 1.1 | B15: B0 nhập đến kho | D15: 1 | E15: =C6 -> 600000 | F15: =C7 -> 8000 | G15: =E15*F15 -> 4800000000 | J15: 1.1 | K15: B0 nhập đến kho | M15: 1 | N15: =L6 -> 30000 | O15: =L7 -> 8000 | P15: =N15*O15 -> 240000000 | S15: 1.1 | T15: B0 nhập đến kho | V15: 1 | W15: =U6 -> 50000 | X15: =U7 -> 8000 | Y15: =W15*X15 -> 400000000 | AB15: 1.1 | AC15: B0 nhập đến kho | AE15: 1 | AF15: =AD6 -> 90000 | AG15: =AD7 -> 8000 | AH15: =AF15*AG15 -> 720000000 | AK15: 1.1 | AL15: B0 nhập đến kho | AN15: 1 | AO15: =AM6 -> 100000 | AP15: =AM7 -> 8000 | AQ15: =AO15*AP15 -> 800000000 | AT15: 1.1 | AU15: B0 nhập đến kho | AW15: 1 | AX15: =AV6 -> 150000 | AY15: =AV7 -> 8000 | AZ15: =AX15*AY15 -> 1200000000
B16: Mua chai xá | C16: Chi phí mua chai xá giao đến trạm | E16: =C6 -> 600000 | F16: =C7 -> 8000 | K16: Mua chai xá | L16: Chi phí mua chai xá giao đến trạm | N16: =L6 -> 30000 | O16: =L7 -> 8000 | T16: Mua chai xá | U16: Chi phí mua chai xá giao đến trạm | W16: =U6 -> 50000 | X16: =U7 -> 8000 | AC16: Mua chai xá | AD16: Chi phí mua chai xá giao đến trạm | AF16: =AD6 -> 90000 | AG16: =AD7 -> 8000 | AL16: Mua chai xá | AM16: Chi phí mua chai xá giao đến trạm | AO16: =AM6 -> 100000 | AP16: =AM7 -> 8000 | AU16: Mua chai xá | AV16: Chi phí mua chai xá giao đến trạm | AX16: =AV6 -> 150000 | AY16: =AV7 -> 8000
B17: Chi phí thu gom | C17: Nếu gom từ vựa | E17: =E16 -> 600000 | F17: 0 | K17: Chi phí thu gom | L17: Nếu gom từ vựa | N17: =N16 -> 30000 | O17: 0 | T17: Chi phí thu gom | U17: Nếu gom từ vựa | W17: =W16 -> 50000 | X17: 0 | AC17: Chi phí thu gom | AD17: Nếu gom từ vựa | AF17: =AF16 -> 90000 | AG17: 0 | AL17: Chi phí thu gom | AM17: Nếu gom từ vựa | AO17: =AO16 -> 100000 | AP17: 0 | AU17: Chi phí thu gom | AV17: Nếu gom từ vựa | AX17: =AX16 -> 150000 | AY17: 0
A18: 1.2 | B18: Hao hụt | D18: 0.05 | E18: =E15*D18 -> 30000 | F18: 0 | G18: =F18*E18 -> 0 | H18: Tính mất đi hoàn toàn và không thu hồi được | J18: 1.2 | K18: Hao hụt | M18: 0.05 | N18: =N15*M18 -> 1500 | O18: 0 | P18: =O18*N18 -> 0 | Q18: Tính mất đi hoàn toàn và không thu hồi được | S18: 1.2 | T18: Hao hụt | V18: 0.05 | W18: =W15*V18 -> 2500 | X18: 0 | Y18: =X18*W18 -> 0 | Z18: Tính mất đi hoàn toàn và không thu hồi được | AB18: 1.2 | AC18: Hao hụt | AE18: 0.05 | AF18: =AF15*AE18 -> 4500 | AG18: 0 | AH18: =AG18*AF18 -> 0 | AI18: Tính mất đi hoàn toàn và không thu hồi được | AK18: 1.2 | AL18: Hao hụt | AN18: 0.05 | AO18: =AO15*AN18 -> 5000 | AP18: 0 | AQ18: =AP18*AO18 -> 0 | AR18: Tính mất đi hoàn toàn và không thu hồi được | AT18: 1.2 | AU18: Hao hụt | AW18: 0.05 | AX18: =AX15*AW18 -> 7500 | AY18: 0 | AZ18: =AY18*AX18 -> 0 | BA18: Tính mất đi hoàn toàn và không thu hồi được
B19: Công đoạn 1: Nhập hàng | K19: Công đoạn 1: Nhập hàng | T19: Công đoạn 1: Nhập hàng | AC19: Công đoạn 1: Nhập hàng | AL19: Công đoạn 1: Nhập hàng | AU19: Công đoạn 1: Nhập hàng
B20: Công đoạn 2: Sạc bì | K20: Công đoạn 2: Sạc bì | T20: Công đoạn 2: Sạc bì | AC20: Công đoạn 2: Sạc bì | AL20: Công đoạn 2: Sạc bì | AU20: Công đoạn 2: Sạc bì
B21: Công đoạn 3: Ép kiện và lưu kho | K21: Công đoạn 3: Ép kiện và lưu kho | T21: Công đoạn 3: Ép kiện và lưu kho | AC21: Công đoạn 3: Ép kiện và lưu kho | AL21: Công đoạn 3: Ép kiện và lưu kho | AU21: Công đoạn 3: Ép kiện và lưu kho
B22: Công đoạn 4: Nhập kho thanh toán hàng | K22: Công đoạn 4: Nhập kho thanh toán hàng | T22: Công đoạn 4: Nhập kho thanh toán hàng | AC22: Công đoạn 4: Nhập kho thanh toán hàng | AL22: Công đoạn 4: Nhập kho thanh toán hàng | AU22: Công đoạn 4: Nhập kho thanh toán hàng
B23: Công đoạn 5: Xuất kho bán hàng | H23: Không bao gồm vận chuyển | K23: Công đoạn 5: Xuất kho bán hàng | Q23: Không bao gồm vận chuyển | T23: Công đoạn 5: Xuất kho bán hàng | Z23: Không bao gồm vận chuyển | AC23: Công đoạn 5: Xuất kho bán hàng | AI23: Không bao gồm vận chuyển | AL23: Công đoạn 5: Xuất kho bán hàng | AR23: Không bao gồm vận chuyển | AU23: Công đoạn 5: Xuất kho bán hàng | BA23: Không bao gồm vận chuyển
A25: 2 | B25: CHI PHÍ SẢN XUẤT | D25: Kg | E25: =E13 -> 570000 | F25: =G25/E25 -> 380.01086 | G25: =G26+G27 -> 2.1660619e+08 | J25: 2 | K25: CHI PHÍ SẢN XUẤT | M25: Kg | N25: =N13 -> 28500 | O25: =P25/N25 -> 602.81787 | P25: =P26+P27 -> 17180309 | S25: 2 | T25: CHI PHÍ SẢN XUẤT | V25: Kg | W25: =W13 -> 47500 | X25: =Y25/W25 -> 567.73015 | Y25: =Y26+Y27 -> 26967182 | AB25: 2 | AC25: CHI PHÍ SẢN XUẤT | AE25: Kg | AF25: =AF13 -> 85500 | AG25: =AH25/AF25 -> 544.33834 | AH25: =AH26+AH27 -> 46540928 | AK25: 2 | AL25: CHI PHÍ SẢN XUẤT | AN25: Kg | AO25: =AO13 -> 95000 | AP25: =AQ25/AO25 -> 536.15121 | AQ25: =AQ26+AQ27 -> 50934365 | AT25: 2 | AU25: CHI PHÍ SẢN XUẤT | AW25: Kg | AX25: =AX13 -> 142500 | AY25: =AZ25/AX25 -> 525.62489 | AZ25: =AZ26+AZ27 -> 74901547
A26: 2.1 | B26: Chi phí nhân công sản xuất theo sản phẩm | C26: 3 nhân công cơ bản | D26: Kg | E26: =E13 -> 570000 | F26: =(3*10000000)/C6 -> 50 | G26: =F26*E26 -> 28500000 | H26: Áp dụng cho sản lượng của 1 chuyền, công suất 900 kg/giờ | J26: 2.1 | K26: Chi phí nhân công sản xuất theo sản phẩm | L26: 3 nhân công cơ bản | M26: Kg | N26: =N13 -> 28500 | O26: =(3*10000000)/200000 -> 150 | P26: =O26*N26 -> 4275000 | Q26: Áp dụng cho sản lượng của 1 chuyền, công suất 900 kg/giờ | S26: 2.1 | T26: Chi phí nhân công sản xuất theo sản phẩm | U26: 3 nhân công cơ bản | V26: Kg | W26: =W13 -> 47500 | X26: =(3*10000000)/200000 -> 150 | Y26: =X26*W26 -> 7125000 | Z26: Áp dụng cho sản lượng của 1 chuyền, công suất 900 kg/giờ | AB26: 2.1 | AC26: Chi phí nhân công sản xuất theo sản phẩm | AD26: 3 nhân công cơ bản | AE26: Kg | AF26: =AF13 -> 85500 | AG26: =(3*10000000)/200000 -> 150 | AH26: =AG26*AF26 -> 12825000 | AI26: Áp dụng cho sản lượng của 1 chuyền, công suất 900 kg/giờ | AK26: 2.1 | AL26: Chi phí nhân công sản xuất theo sản phẩm | AM26: 3 nhân công cơ bản | AN26: Kg | AO26: =AO13 -> 95000 | AP26: =(3*10000000)/200000 -> 150 | AQ26: =AP26*AO26 -> 14250000 | AR26: Áp dụng cho sản lượng của 1 chuyền, công suất 900 kg/giờ | AT26: 2.1 | AU26: Chi phí nhân công sản xuất theo sản phẩm | AV26: 3 nhân công cơ bản | AW26: Kg | AX26: =AX13 -> 142500 | AY26: =(3*10000000)/200000 -> 150 | AZ26: =AY26*AX26 -> 21375000 | BA26: Áp dụng cho sản lượng của 1 chuyền, công suất 900 kg/giờ
A27: 2.2 | B27: Chi phí sản xuất chung | D27: Kg | E27: =E13 -> 570000 | F27: =G27/E27 -> 330.01086 | G27: =SUM(G28:G31) -> 1.8810619e+08 | J27: 2.2 | K27: Chi phí sản xuất chung | M27: Kg | N27: =N13 -> 28500 | O27: =P27/N27 -> 452.81787 | P27: =SUM(P28:P31) -> 12905309 | S27: 2.2 | T27: Chi phí sản xuất chung | V27: Kg | W27: =W13 -> 47500 | X27: =Y27/W27 -> 417.73015 | Y27: =SUM(Y28:Y31) -> 19842182 | AB27: 2.2 | AC27: Chi phí sản xuất chung | AE27: Kg | AF27: =AF13 -> 85500 | AG27: =AH27/AF27 -> 394.33834 | AH27: =SUM(AH28:AH31) -> 33715928 | AK27: 2.2 | AL27: Chi phí sản xuất chung | AN27: Kg | AO27: =AO13 -> 95000 | AP27: =AQ27/AO27 -> 386.15121 | AQ27: =SUM(AQ28:AQ31) -> 36684365 | AT27: 2.2 | AU27: Chi phí sản xuất chung | AW27: Kg | AX27: =AX13 -> 142500 | AY27: =AZ27/AX27 -> 375.62489 | AZ27: =SUM(AZ28:AZ31) -> 53526547
A28: 2.2.1 | B28: Chi phí điện nhà xưởng | C28: Băng tải 2 kW Quạt thổi 10 kW Vít tải 7,5 kW (40%) Máy ép 75 kW (40%) Quạt đèn 1 kW | D28: Kwh | E28: =(2+10+(7.5+75)*0.4+1)*8*26*(C5/900/8) -> 30666.667 | F28: =(1.5*3640+6.5*1987)/8 -> 2296.9375 | G28: =F28*E28 -> 70439417 | H28: Cao điểm: 3,640 đ/kWh; 1,5 giờ/ngày Bình thường: 1,987 đ/kWh; 6,5 giờ/ngày. Công suất máy 900 kg/giờ | J28: 2.2.1 | K28: Chi phí điện nhà xưởng | L28: Băng tải 2 kW Quạt thổi 10 kW Vít tải 7,5 kW (40%) Máy ép 75 kW (40%) Quạt đèn 1 kW | M28: Kwh | N28: =(2+10+(7.5+75)*0.4+1)*8*26*(L5/900/8) -> 1533.3333 | O28: =(1.5*3640+6.5*1987)/8 -> 2296.9375 | P28: =O28*N28 -> 3521970.8 | Q28: Cao điểm: 3,640 đ/kWh; 1,5 giờ/ngày Bình thường: 1,987 đ/kWh; 6,5 giờ/ngày. Công suất máy 900 kg/giờ | S28: 2.2.1 | T28: Chi phí điện nhà xưởng | U28: Băng tải 2 kW Quạt thổi 10 kW Vít tải 7,5 kW (40%) Máy ép 75 kW (40%) Quạt đèn 1 kW | V28: Kwh | W28: =(2+10+(7.5+75)*0.4+1)*8*26*(U5/900/8) -> 2555.5556 | X28: =(1.5*3640+6.5*1987)/8 -> 2296.9375 | Y28: =X28*W28 -> 5869951.4 | Z28: Cao điểm: 3,640 đ/kWh; 1,5 giờ/ngày Bình thường: 1,987 đ/kWh; 6,5 giờ/ngày. Công suất máy 900 kg/giờ | AB28: 2.2.1 | AC28: Chi phí điện nhà xưởng | AD28: Băng tải 2 kW Quạt thổi 10 kW Vít tải 7,5 kW (40%) Máy ép 75 kW (40%) Quạt đèn 1 kW | AE28: Kwh | AF28: =(2+10+(7.5+75)*0.4+1)*8*26*(AD5/900/8) -> 4600 | AG28: =(1.5*3640+6.5*1987)/8 -> 2296.9375 | AH28: =AG28*AF28 -> 10565912 | AI28: Cao điểm: 3,640 đ/kWh; 1,5 giờ/ngày Bình thường: 1,987 đ/kWh; 6,5 giờ/ngày. Công suất máy 900 kg/giờ | AK28: 2.2.1 | AL28: Chi phí điện nhà xưởng | AM28: Băng tải 2 kW Quạt thổi 10 kW Vít tải 7,5 kW (40%) Máy ép 75 kW (40%) Quạt đèn 1 kW | AN28: Kwh | AO28: =(2+10+(7.5+75)*0.4+1)*8*26*(AM5/900/8) -> 5111.1111 | AP28: =(1.5*3640+6.5*1987)/8 -> 2296.9375 | AQ28: =AP28*AO28 -> 11739903 | AR28: Cao điểm: 3,640 đ/kWh; 1,5 giờ/ngày Bình thường: 1,987 đ/kWh; 6,5 giờ/ngày. Công suất máy 900 kg/giờ | AT28: 2.2.1 | AU28: Chi phí điện nhà xưởng | AV28: Băng tải 2 kW Quạt thổi 10 kW Vít tải 7,5 kW (40%) Máy ép 75 kW (40%) Quạt đèn 1 kW | AW28: Kwh | AX28: =(2+10+(7.5+75)*0.4+1)*8*26*(AV5/900/8) -> 7666.6667 | AY28: =(1.5*3640+6.5*1987)/8 -> 2296.9375 | AZ28: =AY28*AX28 -> 17609854 | BA28: Cao điểm: 3,640 đ/kWh; 1,5 giờ/ngày Bình thường: 1,987 đ/kWh; 6,5 giờ/ngày. Công suất máy 900 kg/giờ
A29: 2.2.2 | B29: Chi phí dây cột kiện | D29: Kg | E29: =0.26*(E27/110)*1.05 -> 1414.6364 | F29: 50926 | G29: =F29*E29 -> 72041771 | H29: ="110 kg/kiện <=> ~"& ROUNDUP(E27/110,0)&" kiện, 0,26kg dây/kiện, hao hụt đứt dây 5%" -> 110 kg/kiện <=> ~5182 kiện, 0,26kg dây/kiện, hao hụt đứt dây 5% | J29: 2.2.2 | K29: Chi phí dây cột kiện | M29: Kg | N29: =0.26*(N27/110)*1.05 -> 70.731818 | O29: 50926 | P29: =O29*N29 -> 3602088.6 | Q29: ="110 kg/kiện <=> ~"& ROUNDUP(N27/110,0)&" kiện, 0,26kg dây/kiện, hao hụt đứt dây 5%" -> 110 kg/kiện <=> ~260 kiện, 0,26kg dây/kiện, hao hụt đứt dây 5% | S29: 2.2.2 | T29: Chi phí dây cột kiện | V29: Kg | W29: =0.26*(W27/110)*1.05 -> 117.88636 | X29: 50926 | Y29: =X29*W29 -> 6003481 | Z29: ="110 kg/kiện <=> ~"& ROUNDUP(W27/110,0)&" kiện, 0,26kg dây/kiện, hao hụt đứt dây 5%" -> 110 kg/kiện <=> ~432 kiện, 0,26kg dây/kiện, hao hụt đứt dây 5% | AB29: 2.2.2 | AC29: Chi phí dây cột kiện | AE29: Kg | AF29: =0.26*(AF27/110)*1.05 -> 212.19545 | AG29: 50926 | AH29: =AG29*AF29 -> 10806266 | AI29: ="110 kg/kiện <=> ~"& ROUNDUP(AF27/110,0)&" kiện, 0,26kg dây/kiện, hao hụt đứt dây 5%" -> 110 kg/kiện <=> ~778 kiện, 0,26kg dây/kiện, hao hụt đứt dây 5% | AK29: 2.2.2 | AL29: Chi phí dây cột kiện | AN29: Kg | AO29: =0.26*(AO27/110)*1.05 -> 235.77273 | AP29: 50926 | AQ29: =AP29*AO29 -> 12006962 | AR29: ="110 kg/kiện <=> ~"& ROUNDUP(AO27/110,0)&" kiện, 0,26kg dây/kiện, hao hụt đứt dây 5%" -> 110 kg/kiện <=> ~864 kiện, 0,26kg dây/kiện, hao hụt đứt dây 5% | AT29: 2.2.2 | AU29: Chi phí dây cột kiện | AW29: Kg | AX29: =0.26*(AX27/110)*1.05 -> 353.65909 | AY29: 50926 | AZ29: =AY29*AX29 -> 18010443 | BA29: ="110 kg/kiện <=> ~"& ROUNDUP(AX27/110,0)&" kiện, 0,26kg dây/kiện, hao hụt đứt dây 5%" -> 110 kg/kiện <=> ~1296 kiện, 0,26kg dây/kiện, hao hụt đứt dây 5%
A30: 2.2.3 | B30: Chi phí xăng dầu xe nâng | D30: Kg | E30: =E27 -> 570000 | F30: =10000000/160000 -> 62.5 | G30: =F30*E30 -> 35625000 | H30: 10tr tiền dầu sản xuất được 160 tấn thành phẩm | J30: 2.2.3 | K30: Chi phí xăng dầu xe nâng | M30: Kg | N30: =N27 -> 28500 | O30: =10000000/160000 -> 62.5 | P30: =O30*N30 -> 1781250 | Q30: 10tr tiền dầu sản xuất được 160 tấn thành phẩm | S30: 2.2.3 | T30: Chi phí xăng dầu xe nâng | V30: Kg | W30: =W27 -> 47500 | X30: =10000000/160000 -> 62.5 | Y30: =X30*W30 -> 2968750 | Z30: 10tr tiền dầu sản xuất được 160 tấn thành phẩm | AB30: 2.2.3 | AC30: Chi phí xăng dầu xe nâng | AE30: Kg | AF30: =AF27 -> 85500 | AG30: =10000000/160000 -> 62.5 | AH30: =AG30*AF30 -> 5343750 | AI30: 10tr tiền dầu sản xuất được 160 tấn thành phẩm | AK30: 2.2.3 | AL30: Chi phí xăng dầu xe nâng | AN30: Kg | AO30: =AO27 -> 95000 | AP30: =10000000/160000 -> 62.5 | AQ30: =AP30*AO30 -> 5937500 | AR30: 10tr tiền dầu sản xuất được 160 tấn thành phẩm | AT30: 2.2.3 | AU30: Chi phí xăng dầu xe nâng | AW30: Kg | AX30: =AX27 -> 142500 | AY30: =10000000/160000 -> 62.5 | AZ30: =AY30*AX30 -> 8906250 | BA30: 10tr tiền dầu sản xuất được 160 tấn thành phẩm
A31: 2.2.4 | B31: Chi phí CCDC, thiết bị - phục vụ sản xuất (bảo dưỡng MMTB) | D31: Tháng | E31: 1 | F31: 10000000 | G31: =F31*E31 -> 10000000 | H31: sửa chữa,bơm dầu, mỡ,… hàng tháng | J31: 2.2.4 | K31: Chi phí CCDC, thiết bị - phục vụ sản xuất (bảo dưỡng MMTB) | M31: Tháng | N31: 1 | O31: 4000000 | P31: =O31*N31 -> 4000000 | Q31: sửa chữa,bơm dầu, mỡ,… hàng tháng | S31: 2.2.4 | T31: Chi phí CCDC, thiết bị - phục vụ sản xuất (bảo dưỡng MMTB) | V31: Tháng | W31: 1 | X31: 5000000 | Y31: =X31*W31 -> 5000000 | Z31: bơm dầu, mỡ,… hàng tháng | AB31: 2.2.4 | AC31: Chi phí CCDC, thiết bị - phục vụ sản xuất (bảo dưỡng MMTB) | AE31: Tháng | AF31: 1 | AG31: 7000000 | AH31: =AG31*AF31 -> 7000000 | AI31: bơm dầu, mỡ,… hàng tháng | AK31: 2.2.4 | AL31: Chi phí CCDC, thiết bị - phục vụ sản xuất (bảo dưỡng MMTB) | AN31: Tháng | AO31: 1 | AP31: 7000000 | AQ31: =AP31*AO31 -> 7000000 | AR31: bơm dầu, mỡ,… hàng tháng | AT31: 2.2.4 | AU31: Chi phí CCDC, thiết bị - phục vụ sản xuất (bảo dưỡng MMTB) | AW31: Tháng | AX31: 1 | AY31: 9000000 | AZ31: =AY31*AX31 -> 9000000 | BA31: bơm dầu, mỡ,… hàng tháng
A32: 3 | B32: Chi phí quản lý chung | D32: Kg | E32: =E13 -> 570000 | F32: =G32/E32 -> 377.90351 | G32: =SUM(G33:G37) -> 215405000 | J32: 3 | K32: Chi phí quản lý chung | M32: Kg | N32: =N13 -> 28500 | O32: =P32/N32 -> 908.07018 | P32: =SUM(P33:P37) -> 25880000 | S32: 3 | T32: Chi phí quản lý chung | V32: Kg | W32: =W13 -> 47500 | X32: =Y32/W32 -> 565.89474 | Y32: =SUM(Y33:Y37) -> 26880000 | AB32: 3 | AC32: Chi phí quản lý chung | AE32: Kg | AF32: =AF13 -> 85500 | AG32: =AH32/AF32 -> 612.92398 | AH32: =SUM(AH33:AH37) -> 52405000 | AK32: 3 | AL32: Chi phí quản lý chung | AN32: Kg | AO32: =AO13 -> 95000 | AP32: =AQ32/AO32 -> 551.63158 | AQ32: =SUM(AQ33:AQ37) -> 52405000 | AT32: 3 | AU32: Chi phí quản lý chung | AW32: Kg | AX32: =AX13 -> 142500 | AY32: =AZ32/AX32 -> 381.78947 | AZ32: =SUM(AZ33:AZ37) -> 54405000
A33: 3.1 | B33: Tổ Trưởng Trạm | D33: Người | E33: 1 | F33: ='Chi phí sản xuất'!$D$18 -> 23525000 | G33: =F33*E33 -> 23525000 | H33: 1 nhân sự kiểm tra và coi hàng | J33: 3.1 | K33: Tổ Trưởng Trạm | M33: Người | N33: 0 | O33: ='Chi phí sản xuất'!$D$18 -> 23525000 | P33: =O33*N33 -> 0 | Q33: 1 nhân sự kiểm tra và coi hàng | S33: 3.1 | T33: Tổ Trưởng Trạm | V33: Người | W33: 0 | X33: ='Chi phí sản xuất'!$D$18 -> 23525000 | Y33: =X33*W33 -> 0 | Z33: 1 nhân sự kiểm tra và coi hàng | AB33: 3.1 | AC33: Tổ Trưởng Trạm | AE33: Người | AF33: 1 | AG33: ='Chi phí sản xuất'!$D$18 -> 23525000 | AH33: =AG33*AF33 -> 23525000 | AI33: 1 nhân sự kiểm tra và coi hàng | AK33: 3.1 | AL33: Tổ Trưởng Trạm | AN33: Người | AO33: 1 | AP33: ='Chi phí sản xuất'!$D$18 -> 23525000 | AQ33: =AP33*AO33 -> 23525000 | AR33: 1 nhân sự kiểm tra và coi hàng | AT33: 3.1 | AU33: Tổ Trưởng Trạm | AW33: Người | AX33: 1 | AY33: ='Chi phí sản xuất'!$D$18 -> 23525000 | AZ33: =AY33*AX33 -> 23525000 | BA33: 1 nhân sự kiểm tra và coi hàng
A34: 3.2 | B34: Admin mua/bán hàng & kế toán | D34: Người | E34: 1 | F34: ='Chi phí sản xuất'!$E$10 -> 11880000 | G34: =F34*E34 -> 11880000 | J34: 3.2 | K34: Admin mua/bán hàng & kế toán | M34: Người | N34: 1 | O34: ='Chi phí sản xuất'!$E$10 -> 11880000 | P34: =O34*N34 -> 11880000 | S34: 3.2 | T34: Admin mua/bán hàng & kế toán | V34: Người | W34: 1 | X34: ='Chi phí sản xuất'!$E$10 -> 11880000 | Y34: =X34*W34 -> 11880000 | AB34: 3.2 | AC34: Admin mua/bán hàng & kế toán | AE34: Người | AF34: 1 | AG34: ='Chi phí sản xuất'!$E$10 -> 11880000 | AH34: =AG34*AF34 -> 11880000 | AK34: 3.2 | AL34: Admin mua/bán hàng & kế toán | AN34: Người | AO34: 1 | AP34: ='Chi phí sản xuất'!$E$10 -> 11880000 | AQ34: =AP34*AO34 -> 11880000 | AT34: 3.2 | AU34: Admin mua/bán hàng & kế toán | AW34: Người | AX34: 1 | AY34: ='Chi phí sản xuất'!$E$10 -> 11880000 | AZ34: =AY34*AX34 -> 11880000
A35: 3.3 | B35: Chi phí bảo vệ | D35: Người | E35: 1 | F35: ='Chi phí sản xuất'!$D$16 -> 10000000 | G35: =F35*E35 -> 10000000 | J35: 3.3 | K35: Chi phí bảo vệ | M35: Người | N35: 1 | O35: ='Chi phí sản xuất'!$D$16 -> 10000000 | P35: =O35*N35 -> 10000000 | S35: 3.3 | T35: Chi phí bảo vệ | V35: Người | W35: 1 | X35: ='Chi phí sản xuất'!$D$16 -> 10000000 | Y35: =X35*W35 -> 10000000 | AB35: 3.3 | AC35: Chi phí bảo vệ | AE35: Người | AF35: 1 | AG35: ='Chi phí sản xuất'!$D$16 -> 10000000 | AH35: =AG35*AF35 -> 10000000 | AK35: 3.3 | AL35: Chi phí bảo vệ | AN35: Người | AO35: 1 | AP35: ='Chi phí sản xuất'!$D$16 -> 10000000 | AQ35: =AP35*AO35 -> 10000000 | AT35: 3.3 | AU35: Chi phí bảo vệ | AW35: Người | AX35: 1 | AY35: ='Chi phí sản xuất'!$D$16 -> 10000000 | AZ35: =AY35*AX35 -> 10000000
A36: 3.4 | B36: Mặt bằng thuê | D36: Người | E36: 1 | F36: 160000000 | G36: =F36*E36 -> 160000000 | J36: 3.4 | K36: Mặt bằng thuê | M36: Người | N36: 0 | O36: 60000000 | P36: =O36*N36 -> 0 | S36: 3.4 | T36: Mặt bằng thuê | V36: Người | W36: 0 | X36: 60000000 | Y36: =X36*W36 -> 0 | AB36: 3.4 | AC36: Mặt bằng thuê | AE36: Người | AF36: 0 | AG36: 60000000 | AH36: =AG36*AF36 -> 0 | AK36: 3.4 | AL36: Mặt bằng thuê | AN36: Người | AO36: 0 | AP36: 60000000 | AQ36: =AP36*AO36 -> 0 | AT36: 3.4 | AU36: Mặt bằng thuê | AW36: Người | AX36: 0 | AY36: 60000000 | AZ36: =AY36*AX36 -> 0
A37: 3.5 | B37: Dịch vụ xưởng (wifi, nước sinh hoạt, VPP) | D37: Tháng | E37: 1 | F37: 10000000 | G37: =F37*E37 -> 10000000 | J37: 3.5 | K37: Dịch vụ xưởng (wifi, nước sinh hoạt, VPP) | M37: Tháng | N37: 1 | O37: 4000000 | P37: =O37*N37 -> 4000000 | S37: 3.5 | T37: Dịch vụ xưởng (wifi, nước sinh hoạt, VPP) | V37: Tháng | W37: 1 | X37: 5000000 | Y37: =X37*W37 -> 5000000 | AB37: 3.5 | AC37: Dịch vụ xưởng (wifi, nước sinh hoạt, VPP) | AE37: Tháng | AF37: 1 | AG37: 7000000 | AH37: =AG37*AF37 -> 7000000 | AK37: 3.5 | AL37: Dịch vụ xưởng (wifi, nước sinh hoạt, VPP) | AN37: Tháng | AO37: 1 | AP37: 7000000 | AQ37: =AP37*AO37 -> 7000000 | AT37: 3.5 | AU37: Dịch vụ xưởng (wifi, nước sinh hoạt, VPP) | AW37: Tháng | AX37: 1 | AY37: 9000000 | AZ37: =AY37*AX37 -> 9000000
A38: 4 | B38: Chi phí bán hàng | D38: Kg | E38: =E39 -> 0 | F38: =IFERROR(G38/E38,0) -> 0 | G38: =SUM(G39:G39) -> 0 | J38: 4 | K38: Chi phí bán hàng | M38: Kg | N38: =N39 -> 0 | O38: =IFERROR(P38/N38,0) -> 0 | P38: =SUM(P39:P39) -> 0 | S38: 4 | T38: Chi phí bán hàng | V38: Kg | W38: =W39 -> 0 | X38: =IFERROR(Y38/W38,0) -> 0 | Y38: =SUM(Y39:Y39) -> 0 | AB38: 4 | AC38: Chi phí bán hàng | AE38: Kg | AF38: =AF39 -> 0 | AG38: =IFERROR(AH38/AF38,0) -> 0 | AH38: =SUM(AH39:AH39) -> 0 | AK38: 4 | AL38: Chi phí bán hàng | AN38: Kg | AO38: =AO39 -> 0 | AP38: =IFERROR(AQ38/AO38,0) -> 0 | AQ38: =SUM(AQ39:AQ39) -> 0 | AT38: 4 | AU38: Chi phí bán hàng | AW38: Kg | AX38: =AX39 -> 0 | AY38: =IFERROR(AZ38/AX38,0) -> 0 | AZ38: =SUM(AZ39:AZ39) -> 0
A39: 4.1 | B39: Chi phí vận chuyển đến trạm TPHCM | D39: Kg | F39: =900000/6000 -> 150 | G39: =E39*F39 -> 0 | H39: Trung bình xe 7 tấn chở đc 6 tấn/chuyến, đơn giá 900K (từ TLP=> TPHCM), DTR hỗ trợ tính 0 VNĐ | J39: 4.1 | K39: Chi phí vận chuyển đến trạm TPHCM | M39: Kg | O39: =900000/6000 -> 150 | P39: =N39*O39 -> 0 | Q39: Trung bình xe 7 tấn chở đc 6 tấn/chuyến, đơn giá 900K (từ TLP=> TPHCM), DTR hỗ trợ tính 0 VNĐ | S39: 4.1 | T39: Chi phí vận chuyển đến trạm TPHCM | V39: Kg | X39: =900000/6000 -> 150 | Y39: =W39*X39 -> 0 | Z39: Trung bình xe 7 tấn chở đc 6 tấn/chuyến, đơn giá 900K (từ TLP=> TPHCM), DTR hỗ trợ tính 0 VNĐ | AB39: 4.1 | AC39: Chi phí vận chuyển đến trạm TPHCM | AE39: Kg | AG39: =900000/6000 -> 150 | AH39: =AF39*AG39 -> 0 | AI39: Trung bình xe 7 tấn chở đc 6 tấn/chuyến, đơn giá 900K (từ TLP=> TPHCM), DTR hỗ trợ tính 0 VNĐ | AK39: 4.1 | AL39: Chi phí vận chuyển đến trạm TPHCM | AN39: Kg | AP39: =900000/6000 -> 150 | AQ39: =AO39*AP39 -> 0 | AR39: Trung bình xe 7 tấn chở đc 6 tấn/chuyến, đơn giá 900K (từ TLP=> TPHCM), DTR hỗ trợ tính 0 VNĐ | AT39: 4.1 | AU39: Chi phí vận chuyển đến trạm TPHCM | AW39: Kg | AY39: =900000/6000 -> 150 | AZ39: =AX39*AY39 -> 0 | BA39: Trung bình xe 7 tấn chở đc 6 tấn/chuyến, đơn giá 900K (từ TLP=> TPHCM), DTR hỗ trợ tính 0 VNĐ
A40: 5 | B40: Chi phí lãi vay | D40: Tháng | E40: 1 | G40: ='Phân tích đầu tư'!B19*'Phân tích đầu tư'!C19/12 -> 0 | J40: 5 | K40: Chi phí lãi vay | M40: Tháng | N40: 1 | P40: ='Phân tích đầu tư'!K19*'Phân tích đầu tư'!L19/12 -> 0 | S40: 5 | T40: Chi phí lãi vay | V40: Tháng | W40: 1 | Y40: ='Phân tích đầu tư'!T19*'Phân tích đầu tư'!U19/12 -> 0 | AB40: 5 | AC40: Chi phí lãi vay | AE40: Tháng | AF40: 1 | AH40: ='Phân tích đầu tư'!AC19*'Phân tích đầu tư'!AD19/12 -> 0 | AK40: 5 | AL40: Chi phí lãi vay | AN40: Tháng | AO40: 1 | AQ40: ='Phân tích đầu tư'!AL19*'Phân tích đầu tư'!AM19/12 -> 0 | AT40: 5 | AU40: Chi phí lãi vay | AW40: Tháng | AX40: 1 | AZ40: ='Phân tích đầu tư'!AU19*'Phân tích đầu tư'!AV19/12 -> 0
A42: 6 | B42: Chi phí khấu hao DTR trên kg sản phẩm (KH) | D42: Kg | E42: =E13 -> 570000 | F42: =(G43+G53)/(5*12*200000*0.95) -> 184.47368 | G42: =E42*F42 -> 1.0515e+08 | J42: 6 | K42: Chi phí khấu hao DTR trên kg sản phẩm (KH) | M42: Kg | N42: =N13 -> 28500 | O42: =(P43+P53)/(5*12*200000*0.95) -> 184.47368 | P42: =N42*O42 -> 5257500 | S42: 6 | T42: Chi phí khấu hao DTR trên kg sản phẩm (KH) | V42: Kg | W42: =W13 -> 47500 | X42: =(Y43+Y53)/(5*12*200000*0.95) -> 184.47368 | Y42: =W42*X42 -> 8762500 | AB42: 6 | AC42: Chi phí khấu hao DTR trên kg sản phẩm (KH) | AE42: Kg | AF42: =AF13 -> 85500 | AG42: =(AH43+AH53)/(5*12*200000*0.95) -> 184.47368 | AH42: =AF42*AG42 -> 15772500 | AK42: 6 | AL42: Chi phí khấu hao DTR trên kg sản phẩm (KH) | AN42: Kg | AO42: =AO13 -> 95000 | AP42: =(AQ43+AQ53)/(5*12*200000*0.95) -> 184.47368 | AQ42: =AO42*AP42 -> 17525000 | AT42: 6 | AU42: Chi phí khấu hao DTR trên kg sản phẩm (KH) | AW42: Kg | AX42: =AX13 -> 142500 | AY42: =(AZ43+AZ53)/(5*12*200000*0.95) -> 184.47368 | AZ42: =AX42*AY42 -> 26287500
A43: 6.1 | B43: Máy móc thiết bị | C43: Tất cả máy móc của tất cả các chuyền | G43: =SUM(G44:G52) -> 2083000000 | H43: ="5 năm <=> "&5*12*200000*0.95&" kg" -> 5 năm <=> 11400000 kg | J43: 6.1 | K43: Máy móc thiết bị | L43: Tất cả máy móc của tất cả các chuyền | P43: =SUM(P44:P52) -> 2083000000 | Q43: ="5 năm <=> "&5*12*200000*0.95&" kg" -> 5 năm <=> 11400000 kg | S43: 6.1 | T43: Máy móc thiết bị | U43: Tất cả máy móc của tất cả các chuyền | Y43: =SUM(Y44:Y52) -> 2083000000 | Z43: ="5 năm <=> "&5*12*200000*0.95&" kg" -> 5 năm <=> 11400000 kg | AB43: 6.1 | AC43: Máy móc thiết bị | AD43: Tất cả máy móc của tất cả các chuyền | AH43: =SUM(AH44:AH52) -> 2083000000 | AI43: ="5 năm <=> "&5*12*200000*0.95&" kg" -> 5 năm <=> 11400000 kg | AK43: 6.1 | AL43: Máy móc thiết bị | AM43: Tất cả máy móc của tất cả các chuyền | AQ43: =SUM(AQ44:AQ52) -> 2083000000 | AR43: ="5 năm <=> "&5*12*200000*0.95&" kg" -> 5 năm <=> 11400000 kg | AT43: 6.1 | AU43: Máy móc thiết bị | AV43: Tất cả máy móc của tất cả các chuyền | AZ43: =SUM(AZ44:AZ52) -> 2083000000 | BA43: ="5 năm <=> "&5*12*200000*0.95&" kg" -> 5 năm <=> 11400000 kg
A44: 6.1.1 | B44: Sàn thao tác | E44: 1 | F44: 59000000 | G44: =F44*E44 -> 59000000 | J44: 6.1.1 | K44: Sàn thao tác | N44: 1 | O44: 59000000 | P44: =O44*N44 -> 59000000 | S44: 6.1.1 | T44: Sàn thao tác | W44: 1 | X44: 59000000 | Y44: =X44*W44 -> 59000000 | AB44: 6.1.1 | AC44: Sàn thao tác | AF44: 1 | AG44: 59000000 | AH44: =AG44*AF44 -> 59000000 | AK44: 6.1.1 | AL44: Sàn thao tác | AO44: 1 | AP44: 59000000 | AQ44: =AP44*AO44 -> 59000000 | AT44: 6.1.1 | AU44: Sàn thao tác | AX44: 1 | AY44: 59000000 | AZ44: =AY44*AX44 -> 59000000
A45: 6.1.2 | B45: Băng tải lựa | E45: 1 | F45: 129000000 | G45: =F45*E45 -> 129000000 | J45: 6.1.2 | K45: Băng tải lựa | N45: 1 | O45: 129000000 | P45: =O45*N45 -> 129000000 | S45: 6.1.2 | T45: Băng tải lựa | W45: 1 | X45: 129000000 | Y45: =X45*W45 -> 129000000 | AB45: 6.1.2 | AC45: Băng tải lựa | AF45: 1 | AG45: 129000000 | AH45: =AG45*AF45 -> 129000000 | AK45: 6.1.2 | AL45: Băng tải lựa | AO45: 1 | AP45: 129000000 | AQ45: =AP45*AO45 -> 129000000 | AT45: 6.1.2 | AU45: Băng tải lựa | AX45: 1 | AY45: 129000000 | AZ45: =AY45*AX45 -> 129000000
...

Sheet Phân tích đầu tư
A1: Hạng mục | B1: Thông tin
A2: Tên dự án | B2: Trạm ép phế liệu Tân Lợi Phát
A3: Địa điểm
A4: Mục tiêu | B4: Thu gom – lựa bì - ép kiện nguyên liệu nhựa tái chế
A5: Thời gian đầu tư | B5: 1 năm
A7: TỔNG VỐN ĐẦU TƯ BAN ĐẦU | B7: =SUM(B8+B13) -> 4909500000 | K7: 913000000
A8: Đầu tư mới | B8: =SUM(B9:B11) -> 4909500000 | K8: 440000000
A9: Đầu tư CSHT | B9: ='PnL đầy đủ'!H6 -> 806500000 | K9: =K8+K7 -> 1353000000
A10: Đầu tư máy móc thiết bị | B10: ='PnL đầy đủ'!H5 -> 2103000000 | K10: =K9*1.1 -> 1.4883e+09
A11: Vốn lưu động | B11: 2000000000
A13: Đang sở hữu | B13: =SUM(B14) -> 0
A14: Xe vận chuyển | B14: 0
A16: CƠ CẤU NGUỒN VỐN | B16: =B8 -> 4909500000
A17: Vốn TLP | B17: =B9 -> 806500000
A18: Vốn DTR | B18: =B10 -> 2103000000
A19: Vốn vay | B19: 2000000000 | C19: 0
A21: KẾT QUẢ KINH DOANH/THÁNG DỰ KIẾN
A22: Sản lượng bán | B22: ='PnL đầy đủ'!E12 -> 570000 | C22: Kg/tháng
A23: Chi phí xử lý, sản xuất,… | B23: ='PnL đầy đủ'!G13-'PnL đầy đủ'!G42 -> 5.1403029e+09 | C23: VNĐ/tháng
A24: Giá vốn nguyên liệu | B24: ='PnL đầy đủ'!C7 -> 8000 | C24: VNĐ/kg
A25: Đơn giá sản xuất | B25: =ROUNDUP(B23/B22,0)-B24 -> 1019 | C25: VNĐ/kg
A26: Khấu hao MMTB | B26: ='PnL đầy đủ'!F42 -> 184.47368 | C26: VNĐ/kg
A27: LG kỳ vọng | B27: ='PnL đầy đủ'!C9 -> 500 | C27: VNĐ/kg
A28: Đơn giá bán | B28: =B25+B26+B27+B24 -> 9703.4737 | C28: VNĐ/kg
A29: Lợi nhuận ròng | B29: ='PnL đầy đủ'!G67 -> 2.8354715e+08 | C29: VNĐ/tháng
B30: =B29/B22 -> 497.45113 | C30: VNĐ/kg
A31: HIỆU QUẢ ĐẦU TƯ
A32: ROI (vốn 100% DTR) | B32: =B29*12/SUM(B17:B18) -> 1.1694675 | C32: %
A33: Thời gian hoàn vốn (năm) | B33: =1/B32 -> 0.85509002 | C33: Năm | E33: =B33*12 -> 10.26108
A35: TLP đầu tư một phần
A36: ROI | B36: =B29*12/B18 -> 1.617958 | C36: %
A37: Thời gian hoàn vốn | B37: =1/B36 -> 0.618063 | C37: Năm | E37: =B37*12 -> 7.416756
A39: Với đơn giá bán = giá vốn (GV) + gia công (GC) + Khấu hao (KH) + Lãi gộp (LG)
A40: PHƯƠNG ÁN HOÀN VỐN | B40: Sản lượng (tấn/tháng)
A41: Kịch bản Bi quan | B41: 70 | C41: ~2,7 tấn/ngày
A42: ROI (KN 100%) | B42: 0.19
A43: Thời gian hoàn vốn (năm) | B43: =1/B42 -> 5.2631579 | C43: Năm | E43: =B43*12 -> 63.157895
A45: Kịch bản khả quan | B45: 200 | C45: ~7,7 tấn/ngày
A46: ROI KN 100%) | B46: 0.54
A47: Thời gian hoàn vốn (năm) | B47: =1/B46 -> 1.8518519 | C47: Năm | E47: =B47*12 -> 22.222222
...

Sheet Chi phí sản xuất
C2: Nhân sự | D2: Đơn giá | E2: Thành tiền
B3: Tổng cộng | C3: =SUM(C4:C18) -> 6 | E3: =SUM(E4:E18) -> 75405000
B4: Nhập hàng | C4: 3 | D4: =10000000 -> 10000000 | E4: =D4*C4 -> 30000000
B5: Lựa bì | F5: Khoán sản lượng
B6: Ép kiện
B7: Xuất hàng
B8: Kho
B10: Admin mua/bán hàng | C10: 1 | D10: =10000000+8000000*23.5% -> 11880000 | E10: =D10*C10 -> 11880000 | F10: Đóng BHXH mức 8 triệu
B11: Kế toán
B14: Dự phòng | C14: 0 | D14: 10000000 | E14: =D14*C14 -> 0
B16: Bảo vệ | C16: 1 | D16: 10000000 | E16: =D16*C16 -> 10000000
B18: Tổ trưởng trạm | C18: 1 | D18: =20000000+15000000*23.5% -> 23525000 | E18: =D18*C18 -> 23525000 | F18: Đóng BHXH mức 15 triệu
B19: QC

Sheet Sheet1
B1: Cấp 0: Nhà máy Tái chế | C1: Cấp 1: Nhà SX vảy nóng | D1: Cấp 2: Nhà Xử lý chai/ xử lý thô | E1: Cấp 3: Đại lý | F1: Cấp 4: Vựa | G1: Tỉnh | H1: Sản lượng
A2: TPHCM | B2: 24 | C2: 95 | D2: 51 | E2: 77 | F2: 889 | G2: TPHCM | H2: 2602
A3: BR-VT | B3: 1 | C3: 3 | D3: 8 | E3: 31 | F3: 31 | G3: BR-VT | H3: 75
A4: Bình Dương | B4: 3 | C4: 21 | D4: 17 | E4: 7 | F4: 119 | G4: Bình Dương | H4: 522
A5: Long An | B5: 6 | C5: 14 | D5: 15 | E5: 40 | F5: 163 | G5: Long An | H5: 551
