Workbook
Name mth: '>>Mth'!$B$2
Name year: '>>Mth'!$B$1

Sheet >>Mth

Sheet BĐ-Dthu EXW
A1: ĐVT: VND nhưng show là tỷ đồng | P1: 1000 | AE1: Dthu (theo tỷ giá KH)
C2: Start | D2: Hidden | E2: Increase | F2: Decrease | G2: End | H2: Chênh lệch | K2: T/Đ làm từng SKU | M2: T/Đ nếu như nhóm ngành | P2: KH | Q2: TT | U2: KH | V2: TT | Z2: Tổng tác động | AA2: SL | AB2: GB | AC2: EXR | AE2: KH | AF2: TT
A3: KH T03 | C3: =H3 -> 1.4159949e+11 | H3: 1.4159949e+11
A4: rPET | B4: Sản lượng | D4: =C3+E3-F4 -> 1.4159949e+11 | E4: =IF(H4>0,H4,0) -> 2.0374037e+10 | F4: =IF(H4<0,-H4,0) -> 0 | H4: =M4 -> 2.0374037e+10 | K4: 19255256395 | M4: =AA4 -> 2.0374037e+10 | O4: tấn | P4: 3872.9704 | Q4: 4560.8 | R4: =Q4-P4 -> 687.82958 | S4: =R4/P4 -> 0.17759743 | Z4: =SUM(AA4:AC4) -> 1.8051294e+10 | AA4: =R4*P5*U5 -> 2.0374037e+10 | AB4: =R5*Q4*U5 -> -8.4940861e+08 | AC4: =Q4*Q5*W5 -> -1.4733344e+09 | AE4: =P4*P5*U5 -> 1.1472034e+11 | AF4: =Q4*Q5*U5 -> 1.3424496e+11 | AH4: =Q4*Q5*V5 -> 1.3277163e+11 | AI4: =AH4-AF4-AC4 -> -5.4836273e-06 | AK4: =AF4-AE4 -> 1.9524628e+10 | AL4: =AK4/AE4 -> 0.17019326
B5: Giá bán | D5: =D4+E4-F5 -> 1.6112412e+11 | E5: =IF(H5>0,H5,0) -> 0 | F5: =IF(H5<0,-H5,0) -> 8.4940861e+08 | H5: =M5 -> -8.4940861e+08 | K5: 2.6788484e+08 | L5: =SUM(K4:K5)-SUM(M4:M5) -> -1486696.2 | M5: =AB4 -> -8.4940861e+08 | O5: $/tấn | P5: 1117.7646 | Q5: 1110.7367 | R5: =Q5-P5 -> -7.0279677 | S5: =R5/P5 -> -0.0062875203 | U5: 26500 | V5: 26209.163 | W5: =V5-U5 -> -290.8367 | X5: =W5/U5 -> -0.01097497
A6: rHDPE thổi | B6: Sản lượng | D6: =D5+E5-F6 -> 1.5882449e+11 | E6: =IF(H6>0,H6,0) -> 0 | F6: =IF(H6<0,-H6,0) -> 2.2996278e+09 | H6: =M6 -> -2.2996278e+09 | K6: -3158442250 | M6: =AA6 -> -2.2996278e+09 | O6: tấn | P6: 636 | Q6: 562.375 | R6: =Q6-P6 -> -73.625 | S6: =R6/P6 -> -0.11576258 | Z6: =SUM(AA6:AC6) -> -2493688594 | AA6: =R6*P7*U7 -> -2.2996278e+09 | AB6: =R7*Q6*U7 -> -1759707 | AC6: =Q6*Q7*W7 -> -1.923011e+08 | AE6: =P6*P7*U7 -> 19865036000 | AF6: =Q6*Q7*U7 -> 1.7563649e+10 | AH6: =Q6*Q7*V7 -> 17371347406 | AI6: =AH6-AF6-AC6 -> 2.3841858e-07 | AK6: =AF6-AE6 -> -2.3013875e+09 | AL6: =AK6/AE6 -> -0.11585116
B7: Giá bán | D7: =D6+E6-F7 -> 1.5882273e+11 | E7: =IF(H7>0,H7,0) -> 0 | F7: =IF(H7<0,-H7,0) -> 1759707 | H7: =M7 -> -1759707 | K7: 8.5705475e+08 | L7: =SUM(K6:K7)-SUM(M6:M7) -> 0 | M7: =AB6 -> -1759707 | O7: $/tấn | P7: 1178.6541 | Q7: 1178.536 | R7: =Q7-P7 -> -0.11807786 | S7: =R7/P7 -> -0.00010018025 | U7: 26500 | V7: 26209.856 | W7: =V7-U7 -> -290.14353 | X7: =W7/U7 -> -0.010948813
A8: rHDPE ép | D8: =D7+E7-F8 -> 1.5882273e+11 | E8: =IF(H8>0,H8,0) -> 3.9515484e+09 | F8: =IF(H8<0,-H8,0) -> 0 | H8: =M8 -> 3.9515484e+09 | K8: 3.9515484e+09 | M8: =AA8 -> 3.9515484e+09 | O8: tấn | P8: 0 | Q8: 223.725 | R8: =Q8-P8 -> 223.725 | S8: =R8/P8 -> #DIV/0! | Z8: =SUM(AA8:AC8) -> 3.9515484e+09 | AA8: =Q8*Q9*V9 -> 3.9515484e+09 | AE8: =P8*P9*U9 -> 0 | AF8: =AA8 -> 3.9515484e+09 | AH8: =Q8*Q9*V9 -> 3.9515484e+09 | AI8: =AH8-AF8-AC8 -> 0 | AK8: =AF8-AE8 -> 3.9515484e+09 | AL8: =AK8/AE8 -> #DIV/0!
D9: =D8+E8-F9 -> 1.6277428e+11 | E9: =IF(H9>0,H9,0) -> 0 | F9: =IF(H9<0,-H9,0) -> 0 | H9: =M9 -> 0 | K9: - | L9: =SUM(K8:K9)-SUM(M8:M9) -> 0 | M9: =AB8 -> 0 | O9: $/tấn | P9: 0 | Q9: 673.90655 | R9: =Q9-P9 -> 673.90655 | S9: =R9/P9 -> #DIV/0! | U9: 26500 | V9: 26209.16 | W9: =V9-U9 -> -290.83964 | X9: =W9/U9 -> -0.010975081
A10: rPP | B10: Sản lượng | D10: =D9+E9-F10 -> 1.6188944e+11 | E10: =IF(H10>0,H10,0) -> 0 | F10: =IF(H10<0,-H10,0) -> 8.8484052e+08 | H10: =M10 -> -8.8484052e+08 | M10: =AA10 -> -8.8484052e+08 | O10: tấn | P10: 72 | Q10: 23.725 | R10: =Q10-P10 -> -48.275 | S10: =R10/P10 -> -0.67048611 | Z10: =SUM(AA10:AC10) -> -9.064723e+08 | AA10: =R10*P11*U11 -> -8.8484052e+08 | AB10: =R11*Q10*U11 -> -17046244 | AC10: =Q10*Q11*W11 -> -4585533.9 | AE10: =P10*P11*U11 -> 1319700000 | AF10: =Q10*Q11*U11 -> 4.1781323e+08 | AH10: =Q10*Q11*V11 -> 4.132277e+08 | AI10: =AH10-AF10-AC10 -> 0 | AK10: =AF10-AE10 -> -9.0188677e+08 | AL10: =AK10/AE10 -> -0.68340287
B11: Giá bán | D11: =D10+E10-F11 -> 1.6187239e+11 | E11: =IF(H11>0,H11,0) -> 0 | F11: =IF(H11<0,-H11,0) -> 17046244 | H11: =M11 -> -17046244 | L11: =SUM(K10:K11)-SUM(M10:M11) -> 9.0188677e+08 | M11: =AB10 -> -17046244 | O11: $/tấn | P11: 691.66667 | Q11: 664.55373 | R11: =Q11-P11 -> -27.11294 | S11: =R11/P11 -> -0.039199431 | U11: 26500 | V11: 26209.16 | W11: =V11-U11 -> -290.83964 | X11: =W11/U11 -> -0.010975081
A12: Xơ sợi | B12: Sản lượng | D12: =D11+E11-F12 -> 1.6187239e+11 | E12: =IF(H12>0,H12,0) -> 4.5446173e+09 | F12: =IF(H12<0,-H12,0) -> 0 | H12: =M12 -> 4.5446173e+09 | M12: =AA12 -> 4.5446173e+09 | O12: tấn | P12: 86.586983 | Q12: 363.5 | R12: =Q12-P12 -> 276.91302 | S12: =R12/P12 -> 3.1980906 | Z12: =SUM(AA12:AC12) -> 4.5851604e+09 | AA12: =R12*P13*U13 -> 4.5446173e+09 | AB12: =R13*Q12*U13 -> 1.0766244e+08 | AC12: =Q12*Q13*W13 -> -67119374 | AE12: =P12*P13*U13 -> 1.4210408e+09 | AF12: =Q12*Q13*U13 -> 6.0733206e+09 | AH12: =Q12*Q13*V13 -> 6.0062012e+09 | AI12: =AH12-AF12-AC12 -> -2.0861626e-07 | AK12: =AF12-AE12 -> 4.6522798e+09 | AL12: =AK12/AE12 -> 3.2738537
B13: Giá bán | D13: =D12+E12-F13 -> 1.6641701e+11 | E13: =IF(H13>0,H13,0) -> 1.0766244e+08 | F13: =IF(H13<0,-H13,0) -> 0 | H13: =M13 -> 1.0766244e+08 | L13: =SUM(K12:K13)-SUM(M12:M13) -> -4.6522798e+09 | M13: =AB12 -> 1.0766244e+08 | O13: $/tấn | P13: 619.30997 | Q13: 630.48668 | R13: =Q13-P13 -> 11.176709 | S13: =R13/P13 -> 0.018047035 | U13: 26500 | V13: 26207.135 | W13: =V13-U13 -> -292.86506 | X13: =W13/U13 -> -0.011051512
A14: Tỷ giá | D14: =D13+E13-F14 -> 1.6474348e+11 | E14: =IF(H14>0,H14,0) -> 0 | F14: =IF(H14<0,-H14,0) -> 1.7811902e+09 | H14: =M14 -> -1.7811902e+09 | K14: -1.7313843e+09 | L14: =M14-K14 -> -5956094.9 | M14: =AC4+AC6+AC8+AC10+AC12 -> -1.7373404e+09
A15: Khác | D15: =D14+E14-F15 -> 1.6474348e+11 | E15: =IF(H15>0,H15,0) -> 7.560749e+09 | F15: =IF(H15<0,-H15,0) -> 0 | H15: =H17-SUM(H3:H14,H16) -> 7.560749e+09 | AE15: =AE17-SUM(AE3:AE14) -> 4.2733785e+09 | AF15: =AF17-SUM(AF3:AF14) -> 1.2835718e+10
A16: hoa hồng, chiết khấu | B16: Cp vận chuyển | D16: =D15+E15-F16 -> 1.7230423e+11 | E16: =IF(H16>0,H16,0) -> 1.0015901e+09 | F16: =IF(H16<0,-H16,0) -> 0 | H16: =G20-C20 -> 1.0015901e+09
A17: TT T03 | G17: =D16+E16 -> 1.7330582e+11 | H17: 1.7330582e+11 | I17: =H17-H3 -> 3.1706331e+10 | J17: =H17/H3-1 -> 0.22391557 | U17: 26500 | V17: 26209.162 | W17: =V17-U17 -> -290.83776 | X17: =W17/U17 -> -0.01097501 | AE17: =C3 -> 1.4159949e+11 | AF17: =G17-H14 -> 1.7508701e+11 | AH17: =G17-AF17 -> -1.7811902e+09
A18: Check | G18: =G17-H17 -> 0
O19: Dthu (tỷ VND) | P19: KH | Q19: TT
A20: Cp vận chuyển, hoa hồng, chiết khấu | C20: =C3-C21 -> 4.1276285e+09 | G20: =H17-G21 -> 5.1292186e+09 | O20: rPET | P20: =P4*P5*U5/10^9 -> 114.72034 | Q20: =Q4*Q5*V5/10^9 -> 132.77163 | R20: =Q20-P20 -> 18.051294 | S20: =IFERROR(R20/P20,0) -> 0.15735042 | U20: =Q20/Q27 -> 0.76611177
A21: Doanh thu EXW | C21: 1.3747186e+11 | G21: 1.681766e+11 | O21: rHDPE thổi | P21: =P6*P7*U7/10^9 -> 19.865036 | Q21: =Q6*Q7*V7/10^9 -> 17.371347 | R21: =Q21-P21 -> -2.4936886 | S21: =IFERROR(R21/P21,0) -> -0.12553154
O22: rHDPE ép | P22: =P8*P9*U9/10^9 -> 0 | Q22: =Q8*Q9*V9/10^9 -> 3.9515484 | R22: =Q22-P22 -> 3.9515484 | S22: =IFERROR(R22/P22,0) -> 0
O23: rPP | P23: =P10*P11*U11/10^9 -> 1.3197 | Q23: =Q10*Q11*V11/10^9 -> 0.4132277 | R23: =Q23-P23 -> -0.9064723 | S23: =IFERROR(R23/P23,0) -> -0.68687755
O24: Xơ sợi | P24: =P12*P13*U13/10^9 -> 1.4210408 | Q24: =Q12*Q13*V13/10^9 -> 6.0062012 | R24: =Q24-P24 -> 4.5851604 | S24: =IFERROR(R24/P24,0) -> 3.2266211
O25: Khác | P25: =C3/10^9-SUM(P20:P24,P26) -> 0.14575 | Q25: =G17/10^9-SUM(Q20:Q24,Q26) -> 7.6626492 | R25: =Q25-P25 -> 7.5168992 | S25: =IFERROR(R25/P25,0) -> 51.573922
O26: Cp vận chuyển, hoa hồng, chiết khấu | P26: =C20/10^9 -> 4.1276285 | Q26: =G20/10^9 -> 5.1292186 | R26: =Q26-P26 -> 1.0015901 | S26: =IFERROR(R26/P26,0) -> 0.24265511
G27: SL | H27: =H4+H6+H8+H10+H12 -> 2.5685734e+10 | O27: Tổng | P27: =SUM(P20:P26) -> 141.59949 | Q27: =SUM(Q20:Q26) -> 173.30582 | R27: =Q27-P27 -> 31.706331 | S27: =IFERROR(R27/P27,0) -> 0.22391557
G28: GB | H28: =H5+H7+H9+H11+H13 -> -7.6055212e+08
O30: Dthu (tỷ VND) | P30: KH | Q30: TT | R30: - Loại trừ chênh lệch tỷ giá
O31: rPET | P31: =P4*P5*U5/10^9 -> 114.72034 | Q31: =Q4*Q5*U5/10^9 -> 134.24496 | R31: =Q31-P31 -> 19.524628 | S31: =IFERROR(R31/P31,0) -> 0.17019326
O32: rHDPE thổi | P32: =P6*P7*U7/10^9 -> 19.865036 | Q32: =Q6*Q7*U7/10^9 -> 17.563649 | R32: =Q32-P32 -> -2.3013875 | S32: =IFERROR(R32/P32,0) -> -0.11585116
O33: rHDPE ép | P33: =P8*P9*U9/10^9 -> 0 | Q33: =Q8*Q9*U9/10^9 -> 3.9953982 | R33: =Q33-P33 -> 3.9953982 | S33: =IFERROR(R33/P33,0) -> 0
O34: rPP | P34: =P10*P11*U11/10^9 -> 1.3197 | Q34: =Q10*Q11*U11/10^9 -> 0.41781323 | R34: =Q34-P34 -> -0.90188677 | S34: =IFERROR(R34/P34,0) -> -0.68340287
O35: Xơ sợi | P35: =P12*P13*U13/10^9 -> 1.4210408 | Q35: =Q12*Q13*U13/10^9 -> 6.0733206 | R35: =Q35-P35 -> 4.6522798 | S35: =IFERROR(R35/P35,0) -> 3.2738537
O36: Chênh lệch tỷ giá | Q36: =(AC4+AC6+AC8+AC10+AC12)/10^9 -> -1.7373404 | R36: =Q36-P36 -> -1.7373404 | S36: =IFERROR(R36/P36,0) -> 0
O37: Khác | P37: =C3/10^9-SUM(P31:P36,P38) -> 0.14575 | Q37: =G17/10^9-SUM(Q31:Q36,Q38) -> 7.6187994 | R37: =Q37-P37 -> 7.4730494 | S37: =IFERROR(R37/P37,0) -> 51.273066
O38: Cp vận chuyển, hoa hồng, chiết khấu | P38: =C20/10^9 -> 4.1276285 | Q38: =G20/10^9 -> 5.1292186 | R38: =Q38-P38 -> 1.0015901 | S38: =IFERROR(R38/P38,0) -> 0.24265511
O39: Tổng | P39: =SUM(P31:P38) -> 141.59949 | Q39: =SUM(Q31:Q38) -> 173.30582 | R39: =Q39-P39 -> 31.706331 | S39: =IFERROR(R39/P39,0) -> 0.22391557
O42: Sản lượng (ng.tấn) | P42: KH | Q42: TT | R42: +-/- | S42: %+-/- | T42: %Thực hiện
O43: rPET | P43: =P4/10^3 -> 3.8729704 | Q43: =Q4/10^3 -> 4.5608 | R43: =Q43-P43 -> 0.68782958 | S43: =IFERROR(R43/P43,0) -> 0.17759743 | T43: =Q43/P43 -> 1.1775974
...

Sheet BĐ-Dthu EXW-v2
A2: ĐVT: VND; kg; VND/kg; USD/ton | K2: TÁC ĐỘNG
B3: KH | C3: TT | D3: +/ | F3: %Cơ cấu SL-KH | G3: %Cơ cấu SL-TT | H3: SL-TT-Cơ cấu KH | I3: DT-TT-Cơ cấu KH | K3: Sản lượng | L3: Cơ cấu ngành | M3: Giá bán | N3: Tỷ giá | O3: Khác | P3: Cp vận chuyển, hoa hồng, chiết khấu | U3: Label chart-SL-KH | V3: Label chart-SL-TT
A4: Sản lượng SPC | B4: =SUM(B5:B9) -> 4667557.4 | C4: =SUM(C5:C9) -> 5734125 | D4: =C4-B4 -> 1066567.6 | E4: =D4/B4 -> 0.22850658 | H4: =SUM(H5:H9) -> 5734125
A5: rPET | B5: ='BĐ-Dthu EXW'!P43*10^6 -> 3872970.4 | C5: ='BĐ-Dthu EXW'!Q43*10^6 -> 4560800 | D5: =C5-B5 -> 687829.58 | E5: =D5/B5 -> 0.17759743 | F5: =B5/B$4 -> 0.82976385 | G5: =C5/C$4 -> 0.79537855 | H5: =F5*C$4 -> 4757969.7 | K5: =I11-B17 -> 2.6214352e+10 | L5: =C5*B11-I11 -> -5.8403156e+09 | M5: =D30*C5/10^3*$B$36 -> -8.4940861e+08 | N5: =IFERROR(C17-C17/C37*B37,0) -> -1.4733344e+09 | Q5: =SUM(K5:P5) -> 1.8051294e+10 | R5: =SUM(K5:L5) -> 2.0374037e+10 | S5: -2.4223451e+10 | U5: =_xlfn.TEXTJOIN(" | ",FALSE,TEXT(B5/10^3,"#,###"),TEXT(F5,"0.0%")) -> 3,873 | 83.0% | V5: =_xlfn.TEXTJOIN(" | ",FALSE,TEXT(C5/10^3,"#,###"),TEXT(G5,"0.0%")) -> 4,561 | 79.5%
A6: rHDPE thổi | B6: ='BĐ-Dthu EXW'!P44*10^6 -> 636000 | C6: ='BĐ-Dthu EXW'!Q44*10^6 -> 562375 | D6: =C6-B6 -> -73625 | E6: =D6/B6 -> -0.11576258 | F6: =B6/B$4 -> 0.13625971 | G6: =C6/C$4 -> 0.09807512 | H6: =F6*C$4 -> 781330.19 | K6: =I12-B18 -> 4.5392915e+09 | L6: =C6*B12-I12 -> -6.8389193e+09 | M6: =D31*C6/10^3*$B$36 -> -1759707 | N6: =IFERROR(C18-C18/C38*B38,0) -> -1.923011e+08 | Q6: =SUM(K6:P6) -> -2.4936886e+09 | R6: =SUM(K6:L6) -> -2.2996278e+09 | S6: -1.6262315e+10 | U6: =_xlfn.TEXTJOIN(" | ",FALSE,TEXT(B6/10^3,"#,###"),TEXT(F6,"0.0%")) -> 636 | 13.6% | V6: =_xlfn.TEXTJOIN(" | ",FALSE,TEXT(C6/10^3,"#,###"),TEXT(G6,"0.0%")) -> 562 | 9.8%
A7: rHDPE ép | B7: ='BĐ-Dthu EXW'!P45*10^6 -> 0 | C7: ='BĐ-Dthu EXW'!Q45*10^6 -> 223725 | D7: =C7-B7 -> 223725 | E7: =D7/B7 -> #DIV/0! | F7: =B7/B$4 -> 0 | G7: =C7/C$4 -> 0.039016415 | H7: =F7*C$4 -> 0 | K7: =C19 -> 3.9515484e+09 | Q7: =SUM(K7:P7) -> 3.9515484e+09 | R7: =SUM(K7:L7) -> 3.9515484e+09 | S7: -1.6304001e+09 | U7: =_xlfn.TEXTJOIN(" | ",FALSE,TEXT(B7/10^3,"#,###"),TEXT(F7,"0.0%")) -> | 0.0% | V7: =_xlfn.TEXTJOIN(" | ",FALSE,TEXT(C7/10^3,"#,###"),TEXT(G7,"0.0%")) -> 224 | 3.9%
A8: rPP | B8: ='BĐ-Dthu EXW'!P46*10^6 -> 72000 | C8: ='BĐ-Dthu EXW'!Q46*10^6 -> 23725 | D8: =C8-B8 -> -48275 | E8: =D8/B8 -> -0.67048611 | F8: =B8/B$4 -> 0.015425627 | G8: =C8/C$4 -> 0.0041375101 | H8: =F8*C$4 -> 88452.474 | K8: =I14-B20 -> 3.0156014e+08 | L8: =C8*B14-I14 -> -1.1864007e+09 | M8: =D33*C8/10^3*$B$36 -> -17046244 | N8: =IFERROR(C20-C20/C40*B40,0) -> -4585533.9 | Q8: =SUM(K8:P8) -> -9.064723e+08 | R8: =SUM(K8:L8) -> -8.8484052e+08 | S8: -1.1216801e+09 | U8: =_xlfn.TEXTJOIN(" | ",FALSE,TEXT(B8/10^3,"#,###"),TEXT(F8,"0.0%")) -> 72 | 1.5% | V8: =_xlfn.TEXTJOIN(" | ",FALSE,TEXT(C8/10^3,"#,###"),TEXT(G8,"0.0%")) -> 24 | 0.4%
A9: Xơ sợi | B9: ='BĐ-Dthu EXW'!P47*10^6 -> 86586.983 | C9: ='BĐ-Dthu EXW'!Q47*10^6 -> 363500 | D9: =C9-B9 -> 276913.02 | E9: =D9/B9 -> 3.1980906 | F9: =B9/B$4 -> 0.018550813 | G9: =C9/C$4 -> 0.063392409 | H9: =F9*C$4 -> 106372.68 | K9: =I15-B21 -> 3.2471719e+08 | L9: =C9*B15-I15 -> 4.2199001e+09 | M9: =D34*C9/10^3*$B$36 -> 1.0766244e+08 | N9: =IFERROR(C21-C21/C41*B41,0) -> -67119374 | Q9: =SUM(K9:P9) -> 4.5851604e+09 | R9: =SUM(K9:L9) -> 4.5446173e+09 | S9: 1.28645e+10 | U9: =_xlfn.TEXTJOIN(" | ",FALSE,TEXT(B9/10^3,"#,###"),TEXT(F9,"0.0%")) -> 87 | 1.9% | V9: =_xlfn.TEXTJOIN(" | ",FALSE,TEXT(C9/10^3,"#,###"),TEXT(G9,"0.0%")) -> 364 | 6.3%
A10: GB EXW (VND/kg) | B10: 30553.285 | C10: 28801.443 | D10: =C10-B10 -> -1751.8418 | I10: =SUM(I11:I15) -> 1.6870603e+11
A11: rPET | B11: =B30*B37/10^3 -> 29620.762 | C11: =C30*C37/10^3 -> 29111.478 | I11: =H5*B11 -> 1.4093469e+11
A12: rHDPE thổi | B12: =B31*B38/10^3 -> 31234.333 | C12: =C31*C38/10^3 -> 30889.26 | I12: =H6*B12 -> 2.4404328e+10
A13: rHDPE ép | B13: =B32*B39/10^3 -> 0 | C13: =C32*C39/10^3 -> 17662.525 | I13: =H7*B13 -> 0
A14: rPP | B14: =B33*B40/10^3 -> 18329.167 | C14: =C33*C40/10^3 -> 17417.395 | I14: =H8*B14 -> 1.6212601e+09
A15: Xơ sợi | B15: =B34*B41/10^3 -> 16411.714 | C15: =C34*C41/10^3 -> 16523.25 | I15: =H9*B15 -> 1.745758e+09
A16: Doanh thu SPC | B16: =SUM(B17:B21) -> 1.3732611e+11 | C16: =SUM(C17:C21) -> 1.6051395e+11 | D16: =C16-B16 -> 2.3187841e+10
A17: rPET | B17: =B5*B11 -> 1.1472034e+11 | C17: =C5*C11 -> 1.3277163e+11 | E17: =C17-B17 -> 1.8051294e+10 | F17: =E17/B17 -> 0.15735042
A18: rHDPE thổi | B18: =B6*B12 -> 19865036000 | C18: =C6*C12 -> 1.7371347e+10 | E18: =C18-B18 -> -2.4936886e+09 | F18: =E18/B18 -> -0.12553154
A19: rHDPE ép | B19: =B7*B13 -> 0 | C19: =C7*C13 -> 3.9515484e+09 | E19: =C19-B19 -> 3.9515484e+09 | F19: =E19/B19 -> #DIV/0!
A20: rPP | B20: =B8*B14 -> 1.3197e+09 | C20: =C8*C14 -> 4.132277e+08 | E20: =C20-B20 -> -9.064723e+08 | F20: =E20/B20 -> -0.68687755
A21: Xơ sợi | B21: =B9*B15 -> 1.4210408e+09 | C21: =C9*C15 -> 6.0062012e+09 | E21: =C21-B21 -> 4.5851604e+09 | F21: =E21/B21 -> 3.2266211
A22: Tài trợ | C22: 190015000 | D22: =C22-B22 -> 190015000 | O22: =D22 -> 190015000 | Q22: =SUM(K22:P22) -> 190015000
A23: Dây đai, phó sản | B23: 145750000 | C23: 7.7164078e+09 | D23: =C23-B23 -> 7.5706578e+09 | O23: =D23 -> 7.5706578e+09 | Q23: =SUM(K23:P23) -> 7.5706578e+09
A24: Khác | C24: -2.4377357e+08 | D24: =C24-B24 -> -2.4377357e+08 | O24: =D24 -> -2.4377357e+08 | Q24: =SUM(K24:P24) -> -2.4377357e+08
A25: Cp vận chuyển, hoa hồng, chiết khấu | B25: ='BĐ-Dthu EXW'!C20 -> 4.1276285e+09 | C25: ='BĐ-Dthu EXW'!G20 -> 5.1292186e+09 | D25: =C25-B25 -> 1.0015901e+09 | P25: =D25 -> 1.0015901e+09
A26: Tổng dthu thuần | B26: =B16+B22+B23+B24+B25 -> 1.4159949e+11 | C26: =C16+C22+C23+C24+C25 -> 1.7330582e+11 | D26: =C26-B26 -> 3.1706331e+10 | K26: =SUM(K4:K25) -> 3.5331469e+10 | L26: =SUM(L4:L25) -> -9.6457355e+09 | M26: =SUM(M4:M25) -> -7.6055212e+08 | N26: =SUM(N4:N25) -> -1.7373404e+09 | O26: =SUM(O4:O25) -> 7.5168992e+09 | P26: =SUM(P4:P25) -> 1.0015901e+09 | Q26: =SUM(K26:P26) -> 3.1706331e+10
A27: check | B27: =B26-'BĐ-Dthu EXW'!C3 -> 0 | C27: =C26-'BĐ-Dthu EXW'!G17 -> 0 | D27: =D26/B26 -> 0.22391557 | P27: Check | Q27: =Q26-D26 -> 0
A29: GB EXW (USD/ton) | B29: KH | C29: TT
A30: rPET | B30: ='BĐ-Dthu EXW'!P5 -> 1117.7646 | C30: ='BĐ-Dthu EXW'!Q5 -> 1110.7367 | D30: =C30-B30 -> -7.0279677 | E30: =IFERROR(D30/B30,0) -> -0.0062875203 | Q30: -52808442002
A31: rHDPE thổi | B31: ='BĐ-Dthu EXW'!P7 -> 1178.6541 | C31: ='BĐ-Dthu EXW'!Q7 -> 1178.536 | D31: =C31-B31 -> -0.11807786 | E31: =IFERROR(D31/B31,0) -> -0.00010018025 | Q31: =Q30-Q26 -> -8.4514773e+10
A32: rHDPE ép | B32: ='BĐ-Dthu EXW'!P9 -> 0 | C32: ='BĐ-Dthu EXW'!Q9 -> 673.90655 | D32: =C32-B32 -> 673.90655 | E32: =IFERROR(D32/B32,0) -> 0
A33: rPP | B33: ='BĐ-Dthu EXW'!P11 -> 691.66667 | C33: ='BĐ-Dthu EXW'!Q11 -> 664.55373 | D33: =C33-B33 -> -27.11294 | E33: =IFERROR(D33/B33,0) -> -0.039199431
A34: Xơ sợi | B34: ='BĐ-Dthu EXW'!P13 -> 619.30997 | C34: ='BĐ-Dthu EXW'!Q13 -> 630.48668 | D34: =C34-B34 -> 11.176709 | E34: =IFERROR(D34/B34,0) -> 0.018047035
A36: Exchange rate | B36: 26500 | C36: ='BĐ-Dthu EXW'!V17 -> 26209.162 | D36: =C36-B36 -> -290.83776 | E36: =IFERROR(D36/B36,0) -> -0.01097501
A37: rPET | B37: 26500 | C37: ='BĐ-Dthu EXW'!V5 -> 26209.163
A38: rHDPE thổi | B38: 26500 | C38: ='BĐ-Dthu EXW'!V7 -> 26209.856
A39: rHDPE ép | B39: 26500 | C39: ='BĐ-Dthu EXW'!V9 -> 26209.16
A40: rPP | B40: 26500 | C40: ='BĐ-Dthu EXW'!V11 -> 26209.16
A41: Xơ sợi | B41: 26500 | C41: ='BĐ-Dthu EXW'!V13 -> 26207.135
A44: Vẽ (VND nhưng thể hiện là tỷ)
C45: Start | D45: Hidden | E45: Increase | F45: Decrease | G45: End
...

Sheet .

Sheet BĐ-LG EXW
A1: ĐVT: VND nhưng show là tỷ đồng | AH1: LG EXW (THEO TỶ GIÁ KH) | AO1: DTHU EXW (THEO TỶ GIÁ KH) | AR1: %Biên
C2: Start | D2: Hidden | E2: Increase | F2: Decrease | G2: End | H2: Chênh lệch | M2: T/Đ nếu như nhóm ngành | P2: KH | Q2: TT | U2: KH | V2: TT | Z2: Tổng tác động | AA2: SL | AB2: GB | AC2: GV | AD2: EXR | AE2: Model | AH2: KH | AI2: TT | AJ2: +/- | AK2: %+/- | AO2: KH | AP2: TT
A3: ='BĐ-Dthu EXW'!A3 -> KH T03 | C3: =H3 -> 2.1385804e+10 | H3: 2.1385804e+10
A4: rPET | B4: Sản lượng | D4: =C3+E3-F4 -> 2.1385804e+10 | E4: =IF(H4>0,H4,0) -> 2.5528016e+09 | F4: =IF(H4<0,-H4,0) -> 0 | H4: =M4 -> 2.5528016e+09 | M4: {=TRANSPOSE(AA4:AC4)} -> 2.5528016e+09 | O4: tấn | P4: ='BĐ-Dthu EXW'!P4 -> 3872.9704 | Q4: ='BĐ-Dthu EXW'!Q4 -> 4560.8 | R4: =Q4-P4 -> 687.82958 | S4: =R4/P4 -> 0.17759743 | Z4: =SUM(AA4:AD4) -> -3.022062e+09 | AA4: =R4*(P5*U5-P6*10^3) -> 2.5528016e+09 | AB4: =R5*Q4*U5 -> -8.4940861e+08 | AC4: =-R6*Q4*10^3 -> -3.2521206e+09 | AD4: =Q4*Q5*W5 -> -1.4733344e+09 | AE4: -1.6821239e+10 | AF4: =Z4-AE4 -> 1.3799177e+10 | AH4: =P4*(P5*U5-P6*10^3) -> 1.4374091e+10 | AI4: =Q4*(Q5*U5-Q6*10^3) -> 1.2825364e+10 | AJ4: =AI4-AH4 -> -1.5487276e+09 | AK4: =AJ4/AH4 -> -0.10774438 | AM4: =Q4*(Q5*V5-Q6*10^3) -> 1.1352029e+10 | AN4: =AM4-AI4-AD4 -> -9.2983246e-06 | AO4: ='BĐ-Dthu EXW'!AE4 -> 1.1472034e+11 | AP4: ='BĐ-Dthu EXW'!AF4 -> 1.3424496e+11 | AR4: =AH4/AO4 -> 0.1252968 | AS4: =AI4/AP4 -> 0.095537019
B5: Giá bán | D5: =D4+E4-F5 -> 2.3089197e+10 | E5: =IF(H5>0,H5,0) -> 0 | F5: =IF(H5<0,-H5,0) -> 8.4940861e+08 | H5: =M5 -> -8.4940861e+08 | I5: =H5*(1-13.11%) -> -7.3805114e+08 | M5: -8.4940861e+08 | O5: $/tấn | P5: ='BĐ-Dthu EXW'!P5 -> 1117.7646 | Q5: ='BĐ-Dthu EXW'!Q5 -> 1110.7367 | R5: =Q5-P5 -> -7.0279677 | S5: =R5/P5 -> -0.0062875203 | U5: 26500 | V5: ='BĐ-Dthu EXW'!V5 -> 26209.163 | W5: =V5-U5 -> -290.8367 | X5: =W5/U5 -> -0.01097497
B6: Giá vốn | D6: =D5+E5-F6 -> 1.9837076e+10 | E6: =IF(H6>0,H6,0) -> 0 | F6: =IF(H6<0,-H6,0) -> 3.2521206e+09 | H6: =M6 -> -3.2521206e+09 | I6: =H6*(1-13.11%) -> -2.8257676e+09 | M6: -3.2521206e+09 | O6: VND/kg | P6: 25909.376 | Q6: 26622.435 | R6: =Q6-P6 -> 713.05925 | S6: =R6/P6 -> 0.027521283
A7: rHDPE thổi | B7: Sản lượng | D7: =D6+E6-F7 -> 1.9326197e+10 | E7: =IF(H7>0,H7,0) -> 0 | F7: =IF(H7<0,-H7,0) -> 5.108793e+08 | H7: =M7 -> -5.108793e+08 | M7: {=TRANSPOSE(AA7:AC7)} -> -5.108793e+08 | O7: tấn | P7: ='BĐ-Dthu EXW'!P6 -> 636 | Q7: ='BĐ-Dthu EXW'!Q6 -> 562.375 | R7: =Q7-P7 -> -73.625 | S7: =R7/P7 -> -0.11576258 | Z7: =SUM(AA7:AD7) -> -2.2032877e+09 | AA7: =R7*(P8*U8-P9*10^3) -> -5.108793e+08 | AB7: =R8*Q7*U8 -> -1759707 | AC7: =-R9*Q7*10^3 -> -1.4983476e+09 | AD7: =Q7*Q8*W8 -> -1.923011e+08 | AE7: -4.157819e+09 | AF7: =Z7-AE7 -> 1.9545313e+09 | AH7: =P7*(P8*U8-P9*10^3) -> 4.4131645e+09 | AI7: =Q7*(Q8*U8-Q9*10^3) -> 2.4021779e+09 | AJ7: =AI7-AH7 -> -2.0109866e+09 | AK7: =AJ7/AH7 -> -0.45567905 | AM7: =Q7*(Q8*V8-Q9*10^3) -> 2.2098768e+09 | AN7: =AM7-AI7-AD7 -> -2.3841858e-07 | AO7: ='BĐ-Dthu EXW'!AE6 -> 19865036000 | AP7: ='BĐ-Dthu EXW'!AF6 -> 1.7563649e+10 | AR7: =AH7/AO7 -> 0.22215739 | AS7: =AI7/AP7 -> 0.13676987
B8: Giá bán | D8: =D7+E7-F8 -> 1.9324437e+10 | E8: =IF(H8>0,H8,0) -> 0 | F8: =IF(H8<0,-H8,0) -> 1759707 | H8: =M8 -> -1759707 | M8: -1759707 | O8: $/tấn | P8: ='BĐ-Dthu EXW'!P7 -> 1178.6541 | Q8: ='BĐ-Dthu EXW'!Q7 -> 1178.536 | R8: =Q8-P8 -> -0.11807786 | S8: =R8/P8 -> -0.00010018025 | U8: 26500 | V8: ='BĐ-Dthu EXW'!V7 -> 26209.856 | W8: =V8-U8 -> -290.14353 | X8: =W8/U8 -> -0.010948813
B9: Giá vốn | D9: =D8+E8-F9 -> 1.7826089e+10 | E9: =IF(H9>0,H9,0) -> 0 | F9: =IF(H9<0,-H9,0) -> 1.4983476e+09 | H9: =M9 -> -1.4983476e+09 | M9: -1.4983476e+09 | O9: VND/kg | P9: 24295.396 | Q9: 26959.717 | R9: =Q9-P9 -> 2664.3211 | S9: =R9/P9 -> 0.10966362
A10: rHDPE ép | B10: Sản lượng | D10: =D9+E9-F10 -> 1.4552736e+10 | E10: =IF(H10>0,H10,0) -> 0 | F10: =IF(H10<0,-H10,0) -> 3.2733538e+09 | H10: =M10 -> -3.2733538e+09 | M10: {=TRANSPOSE(AA10:AC10)} -> -3.2733538e+09 | O10: tấn | P10: ='BĐ-Dthu EXW'!P8 -> 0 | Q10: ='BĐ-Dthu EXW'!Q8 -> 223.725 | R10: =Q10-P10 -> 223.725 | S10: =R10/P10 -> #DIV/0! | Z10: =SUM(AA10:AD10) -> -3.2733538e+09 | AA10: =Q10*(Q11*V11/10^3-Q12)*10^3 -> -3.2733538e+09 | AE10: -1.7720648e+09 | AF10: =Z10-AE10 -> -1.501289e+09 | AJ10: =AI10-AH10 -> 0 | AK10: =AJ10/AH10 -> #DIV/0! | AM10: =Q10*(Q11*V11-Q12*10^3) -> -3.2733538e+09 | AN10: =AM10-AI10-AD10 -> -3.2733538e+09 | AO10: ='BĐ-Dthu EXW'!AE8 -> 0 | AP10: ='BĐ-Dthu EXW'!AF8 -> 3.9515484e+09 | AR10: =AH10/AO10 -> #DIV/0! | AS10: =AI10/AP10 -> 0
B11: Giá bán | D11: =D10+E10-F11 -> 1.4552736e+10 | E11: =IF(H11>0,H11,0) -> 0 | F11: =IF(H11<0,-H11,0) -> 0 | H11: =M11 -> 0 | M11: 0 | O11: $/tấn | P11: ='BĐ-Dthu EXW'!P9 -> 0 | Q11: ='BĐ-Dthu EXW'!Q9 -> 673.90655 | R11: =Q11-P11 -> 673.90655 | S11: =R11/P11 -> #DIV/0! | U11: 26500 | V11: ='BĐ-Dthu EXW'!V9 -> 26209.16 | W11: =V11-U11 -> -290.83964 | X11: =W11/U11 -> -0.010975081
B12: Giá vốn | D12: =D11+E11-F12 -> 1.4552736e+10 | E12: =IF(H12>0,H12,0) -> 0 | F12: =IF(H12<0,-H12,0) -> 0 | H12: =M12 -> 0 | M12: 0 | O12: VND/kg | Q12: 32293.674 | R12: =Q12-P12 -> 32293.674 | S12: =R12/P12 -> #DIV/0!
A13: rPP | B13: Sản lượng | D13: =D12+E12-F13 -> 1.4552736e+10 | E13: =IF(H13>0,H13,0) -> 2.0659688e+08 | F13: =IF(H13<0,-H13,0) -> 0 | H13: =M13 -> 2.0659688e+08 | M13: {=TRANSPOSE(AA13:AC13)} -> 2.0659688e+08 | O13: tấn | P13: ='BĐ-Dthu EXW'!P10 -> 72 | Q13: ='BĐ-Dthu EXW'!Q10 -> 23.725 | R13: =Q13-P13 -> -48.275 | S13: =R13/P13 -> -0.67048611 | Z13: =SUM(AA13:AD13) -> 2.2239683e+08 | AA13: =R13*(P14*U14-P15*10^3) -> 2.0659688e+08 | AB13: =R14*Q13*U14 -> -17046244 | AC13: =-R15*Q13*10^3 -> 37431734 | AD13: =Q13*Q14*W14 -> -4585533.9 | AE13: 1.4782765e+08 | AF13: =Z13-AE13 -> 74569183 | AH13: =P13*(P14*U14-P15*10^3) -> -3.0812999e+08 | AI13: =Q13*(Q14*U14-Q15*10^3) -> -81147620 | AJ13: =AI13-AH13 -> 2.2698237e+08 | AK13: =AJ13/AH13 -> -0.73664485 | AM13: =Q13*(Q14*V14-Q15*10^3) -> -85733154 | AN13: =AM13-AI13-AD13 -> 4.4703484e-08 | AO13: ='BĐ-Dthu EXW'!AE10 -> 1319700000 | AP13: ='BĐ-Dthu EXW'!AF10 -> 4.1781323e+08 | AR13: =AH13/AO13 -> -0.23348487 | AS13: =AI13/AP13 -> -0.19421984
B14: Giá bán | D14: =D13+E13-F14 -> 1.4742286e+10 | E14: =IF(H14>0,H14,0) -> 0 | F14: =IF(H14<0,-H14,0) -> 17046244 | H14: =M14 -> -17046244 | M14: -17046244 | O14: $/tấn | P14: ='BĐ-Dthu EXW'!P11 -> 691.66667 | Q14: ='BĐ-Dthu EXW'!Q11 -> 664.55373 | R14: =Q14-P14 -> -27.11294 | S14: =R14/P14 -> -0.039199431 | U14: 26500 | V14: ='BĐ-Dthu EXW'!V11 -> 26209.16 | W14: =V14-U14 -> -290.83964 | X14: =W14/U14 -> -0.010975081
B15: Giá vốn | D15: =D14+E14-F15 -> 1.4742286e+10 | E15: =IF(H15>0,H15,0) -> 37431734 | F15: =IF(H15<0,-H15,0) -> 0 | H15: =M15 -> 37431734 | M15: 37431734 | O15: VND/kg | P15: 22608.75 | Q15: 21031.016 | R15: =Q15-P15 -> -1577.7338 | S15: =R15/P15 -> -0.069784212
A16: Xơ sợi | B16: Sản lượng | D16: =D15+E15-F16 -> 1.205346e+10 | E16: =IF(H16>0,H16,0) -> 0 | F16: =IF(H16<0,-H16,0) -> 2.7262576e+09 | H16: =M16 -> -2.7262576e+09 | M16: {=TRANSPOSE(AA16:AC16)} -> -2.7262576e+09 | O16: tấn | P16: ='BĐ-Dthu EXW'!P12 -> 86.586983 | Q16: ='BĐ-Dthu EXW'!Q12 -> 363.5 | R16: =Q16-P16 -> 276.91302 | S16: =R16/P16 -> 3.1980906 | Z16: =SUM(AA16:AD16) -> -3.399573e+09 | AA16: =R16*(P17*U17-P18*10^3) -> -2.7262576e+09 | AB16: =R17*Q16*U17 -> 1.0766244e+08 | AC16: =-R18*Q16*10^3 -> -7.1385843e+08 | AD16: =Q16*Q17*W17 -> -67119374 | AE16: -8.5055229e+08 | AF16: =Z16-AE16 -> -2.5490207e+09 | AH16: =P16*(P17*U17-P18*10^3) -> -8.5246415e+08 | AI16: =Q16*(Q17*U17-Q18*10^3) -> -4.1849177e+09 | AJ16: =AI16-AH16 -> -3.3324536e+09 | AK16: =AJ16/AH16 -> 3.9092008 | AM16: =Q16*(Q17*V17-Q18*10^3) -> -4.2520371e+09 | AN16: =AM16-AI16-AD16 -> -2.0861626e-07 | AO16: ='BĐ-Dthu EXW'!AE12 -> 1.4210408e+09 | AP16: ='BĐ-Dthu EXW'!AF12 -> 6.0733206e+09 | AR16: =AH16/AO16 -> -0.59988716 | AS16: =AI16/AP16 -> -0.68906584
B17: Giá bán | D17: =D16+E16-F17 -> 1.205346e+10 | E17: =IF(H17>0,H17,0) -> 1.0766244e+08 | F17: =IF(H17<0,-H17,0) -> 0 | H17: =M17 -> 1.0766244e+08 | M17: 1.0766244e+08 | O17: $/tấn | P17: ='BĐ-Dthu EXW'!P13 -> 619.30997 | Q17: ='BĐ-Dthu EXW'!Q13 -> 630.48668 | R17: =Q17-P17 -> 11.176709 | S17: =R17/P17 -> 0.018047035 | U17: 26500 | V17: ='BĐ-Dthu EXW'!V13 -> 26207.135 | W17: =V17-U17 -> -292.86506 | X17: =W17/U17 -> -0.011051512
B18: Giá vốn | D18: =D17+E17-F18 -> 1.1447264e+10 | E18: =IF(H18>0,H18,0) -> 0 | F18: =IF(H18<0,-H18,0) -> 7.1385843e+08 | H18: =M18 -> -7.1385843e+08 | M18: -7.1385843e+08 | O18: VND/kg | P18: 26256.891 | Q18: 28220.738 | R18: =Q18-P18 -> 1963.8471 | S18: =R18/P18 -> 0.07479359
A19: Tỷ giá | D19: =D18+E18-F19 -> 9.7099239e+09 | E19: =IF(H19>0,H19,0) -> 0 | F19: =IF(H19<0,-H19,0) -> 1.7373404e+09 | H19: =M19 -> -1.7373404e+09 | M19: =AD4+AD7+AD10+AD13+AD16 -> -1.7373404e+09
A20: Khác | D20: =D19+E19-F20 -> 6.4594925e+09 | E20: =IF(H20>0,H20,0) -> 0 | F20: =IF(H20<0,-H20,0) -> 3.2504314e+09 | H20: =H22-SUM(H3:H19,H21) -> -3.2504314e+09 | AH20: =AH22-SUM(AH3:AH19) -> 3.7591418e+09 | AI20: =AI22-SUM(AI3:AI19) -> -1.7630532e+09 | AJ20: =AI20-AH20 -> -5.522195e+09 | AK20: =AJ20/AH20 -> -1.4690042 | AO20: ='BĐ-Dthu EXW'!AE15 -> 4.2733785e+09 | AP20: ='BĐ-Dthu EXW'!AF15 -> 1.2835718e+10
A21: Cp vận chuyển, hoa hồng, chiết khấu | D21: =D20+E20-F21 -> 6.4594925e+09 | E21: =IF(H21>0,H21,0) -> 1.0015901e+09 | F21: =IF(H21<0,-H21,0) -> 0 | H21: =G27-C27 -> 1.0015901e+09
A22: ='BĐ-Dthu EXW'!A17 -> TT T03 | G22: =D21+E21 -> 7461082664 | H22: 7461082664 | I22: =H22-H3 -> -1.3924721e+10 | J22: =H22/H3-1 -> -0.65111983 | U22: 26500 | V22: ='BĐ-Dthu EXW'!V17 -> 26209.162 | W22: =V22-U22 -> -290.83776 | X22: =W22/U22 -> -0.01097501 | AH22: =C3 -> 2.1385804e+10 | AI22: =G22-H19 -> 9.1984231e+09 | AJ22: =AI22-AH22 -> -1.218738e+10 | AK22: =AJ22/AH22 -> -0.56988181 | AO22: =SUM(AO3:AO20) -> 1.4159949e+11 | AP22: =SUM(AP3:AP20) -> 1.7508701e+11
A23: Check | F23: =G22-C3 -> -1.3924721e+10 | G23: =G22-H22 -> 0 | AO23: =AO22-'BĐ-Dthu EXW'!AE17 -> 0 | AP23: =AP22-'BĐ-Dthu EXW'!AF17 -> 0
F24: =F23/C3 -> -0.65111983
C26: KH | G26: TT
A27: Cp vận chuyển, hoa hồng, chiết khấu | C27: ='BĐ-Dthu EXW'!C20 -> 4.1276285e+09 | G27: ='BĐ-Dthu EXW'!G20 -> 5.1292186e+09
A28: Trong đó: Pallet | C28: 4.7023665e+08 | G28: 5.4622475e+08
A29: LG EXW | C29: =C3-C27+C28 -> 1.7728412e+10 | G29: =G22-G27+G28 -> 2.8780888e+09 | H29: =G29-C29 -> -1.4850323e+10
A31: Tài trợ | C31: ='BĐ-Dthu EXW-v2'!B22 -> 0 | G31: ='BĐ-Dthu EXW-v2'!C22 -> 190015000
A32: LG EXW không gồm tài trợ | C32: =C29-C31 -> 1.7728412e+10 | G32: =G29-G31 -> 2.6880738e+09 | H32: =G32-G23 -> 2.6880738e+09
A33: Dthu EXW không gồm tài trợ | C33: ='BĐ-Dthu EXW-v2'!B26-'BĐ-Dthu EXW-v2'!B25-C31 -> 1.3747186e+11 | G33: ='BĐ-Dthu EXW-v2'!C26-'BĐ-Dthu EXW-v2'!C25-'BĐ-Dthu EXW-v2'!C22 -> 1.6798659e+11
A34: %Biên | C34: =IFERROR(C32/C33,0) -> 0.12896029 | G34: =IFERROR(G32/G33,0) -> 0.016001717
H39: =SUM(H5:H6,H8:H9,H11:H12,H14:H15,H17:H18) -> -6.1874471e+09
G40: Tổng t/đ SL | H40: =H4+H7+H10+H13+H16 -> -3.7510922e+09
G41: SL-LNST | H41: =H40*(1-13.11%) -> -3.259324e+09
G43: Tổng t/đ LG đơn vị | H43: =H5+H6+H8+H9+H11+H12+H14+H15+H17+H18 -> -6.1874471e+09
G44: LGĐV-LNST | H44: =H43*(1-13.11%) -> -5.3762727e+09
G46: PET | H46: =SUM(H5:H6) -> -4.1015293e+09
G47: PET-LNST | H47: =H46*(1-13.11%) -> -3.5638188e+09
G49: Xơ sợi | H49: =SUM(H17:H18) -> -6.0619599e+08
...

Sheet BĐ-LG EXW-v2
C4: =C12/C7 -> 0.063392409
A5: ĐVT: VND; kg; VND/kg; USD/ton | K5: TÁC ĐỘNG
B6: KH | C6: TT | D6: +/ | F6: %Cơ cấu SL-KH | G6: %Cơ cấu SL-TT | H6: SL-TT-Cơ cấu KH | I6: DT-TT-Cơ cấu KH | K6: Sản lượng | L6: Cơ cấu ngành | M6: Giá bán | N6: Tỷ giá | O6: Khác | P6: Cp vận chuyển, hoa hồng, chiết khấu
A7: Sản lượng SPC | B7: =SUM(B8:B12) -> 4667557.4 | C7: =SUM(C8:C12) -> 5734125 | D7: =C7-B7 -> 1066567.6 | E7: =D7/B7 -> 0.22850658 | H7: =SUM(H8:H12) -> 5734125
A8: rPET | B8: ='BĐ-Dthu EXW-v2'!B5 -> 3872970.4 | C8: ='BĐ-Dthu EXW-v2'!C5 -> 4560800 | D8: =C8-B8 -> 687829.58 | F8: =B8/B$7 -> 0.82976385 | G8: =C8/C$7 -> 0.79537855 | H8: =F8*C$7 -> 4757969.7
A9: rHDPE thổi | B9: ='BĐ-Dthu EXW-v2'!B6 -> 636000 | C9: ='BĐ-Dthu EXW-v2'!C6 -> 562375 | D9: =C9-B9 -> -73625 | F9: =B9/B$7 -> 0.13625971 | G9: =C9/C$7 -> 0.09807512 | H9: =F9*C$7 -> 781330.19
A10: rHDPE ép | B10: ='BĐ-Dthu EXW-v2'!B7 -> 0 | C10: ='BĐ-Dthu EXW-v2'!C7 -> 223725 | D10: =C10-B10 -> 223725 | F10: =B10/B$7 -> 0 | G10: =C10/C$7 -> 0.039016415 | H10: =F10*C$7 -> 0
A11: rPP | B11: ='BĐ-Dthu EXW-v2'!B8 -> 72000 | C11: ='BĐ-Dthu EXW-v2'!C8 -> 23725 | D11: =C11-B11 -> -48275 | F11: =B11/B$7 -> 0.015425627 | G11: =C11/C$7 -> 0.0041375101 | H11: =F11*C$7 -> 88452.474
A12: Xơ sợi | B12: ='BĐ-Dthu EXW-v2'!B9 -> 86586.983 | C12: ='BĐ-Dthu EXW-v2'!C9 -> 363500 | D12: =C12-B12 -> 276913.02 | F12: =B12/B$7 -> 0.018550813 | G12: =C12/C$7 -> 0.063392409 | H12: =F12*C$7 -> 106372.68
A13: GB EXW (VND/kg) | B13: 30553.285 | C13: 28801.443 | D13: =C13-B13 -> -1751.8418 | I13: =SUM(I14:I18) -> 1.6870603e+11
A14: rPET | B14: ='BĐ-Dthu EXW-v2'!B11 -> 29620.762 | C14: ='BĐ-Dthu EXW-v2'!C11 -> 29111.478 | I14: =H8*B14 -> 1.4093469e+11
A15: rHDPE thổi | B15: ='BĐ-Dthu EXW-v2'!B12 -> 31234.333 | C15: ='BĐ-Dthu EXW-v2'!C12 -> 30889.26 | I15: =H9*B15 -> 2.4404328e+10
A16: rHDPE ép | B16: ='BĐ-Dthu EXW-v2'!B13 -> 0 | C16: ='BĐ-Dthu EXW-v2'!C13 -> 17662.525 | I16: =H10*B16 -> 0
A17: rPP | B17: ='BĐ-Dthu EXW-v2'!B14 -> 18329.167 | C17: ='BĐ-Dthu EXW-v2'!C14 -> 17417.395 | I17: =H11*B17 -> 1.6212601e+09
A18: Xơ sợi | B18: ='BĐ-Dthu EXW-v2'!B15 -> 16411.714 | C18: ='BĐ-Dthu EXW-v2'!C15 -> 16523.25 | I18: =H12*B18 -> 1.745758e+09
A19: Doanh thu SPC | B19: =SUM(B20:B24) -> 1.3732611e+11 | C19: =SUM(C20:C24) -> 1.6051395e+11 | D19: =C19-B19 -> 2.3187841e+10
A20: rPET | B20: =B8*B14 -> 1.1472034e+11 | C20: =C8*C14 -> 1.3277163e+11 | D20: =C20-B20 -> 1.8051294e+10 | K20: =I14-B20 -> 2.6214352e+10 | L20: =C8*B14-I14 -> -5.8403156e+09 | M20: =D63*C8/10^3*$B$69 -> -8.4940861e+08 | N20: =IFERROR(C20-C20/C70*B70,0) -> -1.4733344e+09
A21: rHDPE thổi | B21: =B9*B15 -> 19865036000 | C21: =C9*C15 -> 1.7371347e+10 | D21: =C21-B21 -> -2.4936886e+09 | K21: =I15-B21 -> 4.5392915e+09 | L21: =C9*B15-I15 -> -6.8389193e+09 | M21: =D64*C9/10^3*$B$69 -> -1759707 | N21: =IFERROR(C21-C21/C71*B71,0) -> -1.923011e+08
A22: rHDPE ép | B22: =B10*B16 -> 0 | C22: =C10*C16 -> 3.9515484e+09 | D22: =C22-B22 -> 3.9515484e+09 | K22: =I16-B22 -> 0 | L22: =C10*B16-I16 -> 0 | M22: =D65*C10/10^3*$B$69 -> 3.9953982e+09 | N22: =IFERROR(C22-C22/C72*B72,0) -> -43849817
A23: rPP | B23: =B11*B17 -> 1.3197e+09 | C23: =C11*C17 -> 4.132277e+08 | D23: =C23-B23 -> -9.064723e+08 | K23: =I17-B23 -> 3.0156014e+08 | L23: =C11*B17-I17 -> -1.1864007e+09 | M23: =D66*C11/10^3*$B$69 -> -17046244 | N23: =IFERROR(C23-C23/C73*B73,0) -> -4585533.9
A24: Xơ sợi | B24: =B12*B18 -> 1.4210408e+09 | C24: =C12*C18 -> 6.0062012e+09 | D24: =C24-B24 -> 4.5851604e+09 | K24: =I18-B24 -> 3.2471719e+08 | L24: =C12*B18-I18 -> 4.2199001e+09 | M24: =D67*C12/10^3*$B$69 -> 1.0766244e+08 | N24: =IFERROR(C24-C24/C74*B74,0) -> -67119374
A25: Tài trợ | B25: ='BĐ-Dthu EXW-v2'!B22 -> 0 | C25: ='BĐ-Dthu EXW-v2'!C22 -> 190015000 | D25: =C25-B25 -> 190015000 | O25: =D25 -> 190015000 | Q25: =SUM(K25:P25) -> 190015000
A26: Dây đai, phó sản | B26: ='BĐ-Dthu EXW-v2'!B23 -> 145750000 | C26: ='BĐ-Dthu EXW-v2'!C23 -> 7.7164078e+09 | D26: =C26-B26 -> 7.5706578e+09 | O26: =D26 -> 7.5706578e+09 | Q26: =SUM(K26:P26) -> 7.5706578e+09
A27: Khác | B27: ='BĐ-Dthu EXW-v2'!B24 -> 0 | C27: ='BĐ-Dthu EXW-v2'!C24 -> -2.4377357e+08 | D27: =C27-B27 -> -2.4377357e+08 | O27: =D27 -> -2.4377357e+08 | Q27: =SUM(K27:P27) -> -2.4377357e+08
A28: Cp vận chuyển, hoa hồng, chiết khấu | B28: ='BĐ-LG EXW'!C27 -> 4.1276285e+09 | C28: ='BĐ-LG EXW'!G27 -> 5.1292186e+09 | D28: =C28-B28 -> 1.0015901e+09 | P28: =D28 -> 1.0015901e+09 | Q28: =SUM(K28:P28) -> 1.0015901e+09
A29: Tổng dthu thuần | B29: =B19+B25+B26+B27+B28 -> 1.4159949e+11 | C29: =C19+C25+C26+C27+C28 -> 1.7330582e+11 | D29: =C29-B29 -> 3.1706331e+10 | K29: =SUM(K7:K28) -> 3.1379921e+10 | L29: =SUM(L7:L28) -> -9.6457355e+09 | M29: =SUM(M7:M28) -> 3.2348461e+09 | N29: =SUM(N7:N28) -> -1.7811902e+09 | O29: =SUM(O7:O28) -> 7.5168992e+09 | P29: =SUM(P7:P28) -> 1.0015901e+09 | Q29: =SUM(K29:P29) -> 3.1706331e+10
P30: Check | Q30: =Q29-D29 -> 0
A31: GVĐV (đ/kg)
A32: rPET | B32: ='BĐ-LG EXW'!P6 -> 25909.376 | C32: ='BĐ-LG EXW'!Q6 -> 26622.435 | D32: =C32-B32 -> 713.05925
A33: rHDPE thổi | B33: ='BĐ-LG EXW'!P9 -> 24295.396 | C33: ='BĐ-LG EXW'!Q9 -> 26959.717 | D33: =C33-B33 -> 2664.3211
A34: rHDPE ép | B34: ='BĐ-LG EXW'!P12 -> 0 | C34: ='BĐ-LG EXW'!Q12 -> 32293.674 | D34: =C34-B34 -> 32293.674
A35: rPP | B35: ='BĐ-LG EXW'!P15 -> 22608.75 | C35: ='BĐ-LG EXW'!Q15 -> 21031.016 | D35: =C35-B35 -> -1577.7338
A36: Xơ sợi | B36: ='BĐ-LG EXW'!P18 -> 26256.891 | C36: ='BĐ-LG EXW'!Q18 -> 28220.738 | D36: =C36-B36 -> 1963.8471
A38: GVHB-SPC | B38: =SUM(B39:B43) -> 1.1969945e+11 | C38: =SUM(C39:C43) -> 1.5456317e+11
A39: rPET | B39: =B32*B8 -> 1.0034625e+11 | C39: =C32*C8 -> 1.214196e+11
A40: rHDPE thổi | B40: =B33*B9 -> 1.5451872e+10 | C40: =C33*C9 -> 1.5161471e+10
A41: rHDPE ép | B41: =B34*B10 -> 0 | C41: =C34*C10 -> 7.2249021e+09
A42: rPP | B42: =B35*B11 -> 1.62783e+09 | C42: =C35*C11 -> 498960855
A43: Xơ sợi | B43: =B36*B12 -> 2.273505e+09 | C43: =C36*C12 -> 1.0258238e+10
A44: Tài trợ
...

Sheet ||

Sheet BĐ-PL
A1: -1
A2: CHỈ TIÊU | B2: KH | C2: TT | D2: +/- | E2: %+/- | L2: KH | M2: TT
A3: LG EXW | B3: ='BĐ-LG EXW'!C3-('BĐ-LG EXW'!C27-'BĐ-LG EXW'!C28) -> 1.7728412e+10 | C3: ='BĐ-LG EXW'!G22-('BĐ-LG EXW'!G27-'BĐ-LG EXW'!G28) -> 2.8780888e+09 | D3: =C3-B3 -> -1.4850323e+10 | E3: =IFERROR(D3/B3,0) -> -0.8376567 | K3: LNST | L3: 5.0635798e+09 | M3: -6665406624
A4: CPBH | B4: -943473064 | C4: -1662701952 | D4: =C4-B4 -> -719228888 | E4: =IFERROR(D4/B4,0) -> 0.76232053 | K4: Check | L4: =L3-B11 -> -0.12642288 | M4: =M3-C11 -> -2.8610229e-05
A5: CPQLDN | B5: -7.5982697e+09 | C5: -7329810589 | D5: =C5-B5 -> 2.6845908e+08 | E5: =IFERROR(D5/B5,0) -> -0.035331608
A6: Cp lãi vay | B6: -2.7548451e+09 | C6: -959718564 | D6: =C6-B6 -> 1.7951265e+09 | E6: =IFERROR(D6/B6,0) -> -0.65162522
A7: Dthu/Cp tài chính-Tỷ giá | C7: -59018048 | D7: =C7-B7 -> -59018048 | E7: =IFERROR(D7/B7,0) -> 0
A8: Lãi tiền gửi | C8: 347548135 | D8: =C8-B8 -> 347548135 | E8: =IFERROR(D8/B8,0) -> 0
A9: Thu nhập/Chi phí khác | B9: -4.33625e+08 | C9: -32855301 | D9: =C9-B9 -> 4.007697e+08 | E9: =IFERROR(D9/B9,0) -> -0.92423107
A10: Thuế TNDN | B10: -9.3461904e+08 | C10: 153060867 | D10: =C10-B10 -> 1.0876799e+09 | E10: =IFERROR(D10/B10,0) -> -1.1637682
A11: LNST | B11: =SUM(B3:B10) -> 5.0635798e+09 | C11: =SUM(C3:C10) -> -6.6654066e+09 | D11: =C11-B11 -> -1.1728986e+10 | E11: =IFERROR(D11/B11,0) -> -2.3163428
B14: Start | C14: Hidden | D14: Increase | E14: Decrease | F14: End | I14: Increase | J14: Decrease | K14: Cumulative
A15: ='BĐ-Dthu EXW'!A3 -> KH T03 | B15: =B11 -> 5.0635798e+09
A16: LG EXW | D16: =B15 -> 5.0635798e+09 | E16: =G16+D16 -> -9.7867431e+09 | G16: =D3 -> -1.4850323e+10 | H16: =B15+G16 -> -9.7867431e+09 | I16: =IF(G16>0,G16,0) -> 0 | J16: =IF(G16<0,-G16,0) -> 1.4850323e+10 | K16: =SUM($B$15,G$16:G16) -> -9.7867431e+09
A17: CPBH | C17: =E16 -> -9.7867431e+09 | E17: =G17 -> -719228888 | G17: =D4 -> -719228888 | H17: =H16+G17 -> -1.0505972e+10 | I17: =IF(G17>0,G17,0) -> 0 | J17: =IF(G17<0,-G17,0) -> 719228888 | K17: =SUM($B$15,G$16:G17) -> -1.0505972e+10
A18: CPQLDN | C18: =C17+E17-D18 -> -1.0237513e+10 | D18: =-G18 -> -2.6845908e+08 | G18: =D5 -> 2.6845908e+08 | H18: =H17+G18 -> -1.0237513e+10 | I18: =IF(G18>0,G18,0) -> 2.6845908e+08 | J18: =IF(G18<0,-G18,0) -> 0 | K18: =SUM($B$15,G$16:G18) -> -1.0237513e+10
A19: Cp lãi vay | C19: =C18-D19 -> -8.4423863e+09 | D19: =-G19 -> -1.7951265e+09 | G19: =D6 -> 1.7951265e+09 | H19: =H18+G19 -> -8.4423863e+09 | I19: =IF(G19>0,G19,0) -> 1.7951265e+09 | J19: =IF(G19<0,-G19,0) -> 0 | K19: =SUM($B$15,G$16:G19) -> -8.4423863e+09
A20: Dthu/Cp tài chính-Tỷ giá | C20: =C19 -> -8.4423863e+09 | E20: =G20 -> -59018048 | G20: =D7 -> -59018048 | H20: =H19+G20 -> -8.5014044e+09 | I20: =IF(G20>0,G20,0) -> 0 | J20: =IF(G20<0,-G20,0) -> 59018048 | K20: =SUM($B$15,G$16:G20) -> -8.5014044e+09
A21: Lãi tiền gửi | C21: =C20+E20-D21 -> -8.1538562e+09 | D21: =-G21 -> -347548135 | G21: =D8 -> 347548135 | H21: =H20+G21 -> -8.1538562e+09 | I21: =IF(G21>0,G21,0) -> 347548135 | J21: =IF(G21<0,-G21,0) -> 0 | K21: =SUM($B$15,G$16:G21) -> -8.1538562e+09
A22: Thu nhập khác | C22: =C21+E21-D22 -> -7.7530865e+09 | D22: =-G22 -> -4.007697e+08 | G22: =D9 -> 4.007697e+08 | H22: =H21+G22 -> -7.7530865e+09 | I22: =IF(G22>0,G22,0) -> 4.007697e+08 | J22: =IF(G22<0,-G22,0) -> 0 | K22: =SUM($B$15,G$16:G22) -> -7.7530865e+09
A23: Thuế TNDN | C23: =C22+E22-D23 -> -6.6654066e+09 | D23: =-G23 -> -1.0876799e+09 | G23: =D10 -> 1.0876799e+09 | H23: =H22+G23 -> -6.6654066e+09 | I23: =IF(G23>0,G23,0) -> 1.0876799e+09 | J23: =IF(G23<0,-G23,0) -> 0 | K23: =SUM($B$15,G$16:G23) -> -6.6654066e+09
A24: ='BĐ-Dthu EXW'!A17 -> TT T03 | F24: =C23 -> -6.6654066e+09
F25: =F24-C11 -> 0
A27: Dthu | B27: ='BĐ-Dthu EXW'!C3 -> 1.4159949e+11 | C27: ='BĐ-Dthu EXW'!G17 -> 1.7330582e+11
B28: =B11/B27 -> 0.035759873 | C28: =C11/C27 -> -0.038460373
B58: Tổng t/đ SL | C58: -2.2184183e+10
B59: SL-LNST | C59: -1.9275837e+10
B61: Tổng t/đ LG đơn vị | C61: -1.4265745e+10
B62: LGĐV-LNST | C62: -1.2395506e+10

Sheet Giải trình
C2: Thuế suất | D2: 0
A3: STT | B3: Tác động | C3: LNTT | D3: LNST | E3: Ghi chú
A4: 1 | B4: Nhóm hàng rHDPE ép lỗ | C4: -3.2733538e+09 | D4: =C4*(1-$D$2) -> -3.2733538e+09 | E4: Ngân sách không lập bán nhóm hàng này
A5: =A4+1 -> 2 | B5: Đẩy mạnh bán nhóm xơ sợi | C5: -3.399573e+09 | D5: =C5*(1-$D$2) -> -3.399573e+09 | E5: Ngân sách lập bán 86.6 tấn. Thực tế bán 363.5 tấn
A6: =A5+1 -> 3 | B6: Dây đai PET lỗ | C6: -787956466 | D6: =C6*(1-$D$2) -> -787956466
A7: =A6+1 -> 4 | B7: Bụi tank lỗ | C7: -592294567 | D7: =C7*(1-$D$2) -> -592294567
A8: =A7+1 -> 5 | B8: Tỷ giá thực tế trung bình là 26,209 (KH: 26,500) | C8: -1.7373404e+09 | D8: =C8*(1-$D$2) -> -1.7373404e+09
A9: =A8+1 -> 6 | B9: Điều chỉnh thuê xưởng-thuê máy theo yêu cầu kiểm toán | C9: -1113447612 | D9: =C9*(1-$D$2) -> -1113447612
A10: =A9+1 -> 7 | B10: Tổng | C10: =SUM(C4:C9) -> -1.0903966e+10 | D10: =SUM(D4:D9) -> -1.0903966e+10
B22: LNST
B23: Kế hoạch | C23: 5.0635798e+09
B24: Thực tế | C24: -6665406624
B25: TT sv KH | C25: =C24-C23 -> -1.1728986e+10

Sheet KH-SP lỗ
B1: X | C1: X | D1: X | E1: X | F1: X | G1: X | K1: X
B2: NHỮNG KHÁCH HÀNG, SẢN PHẨM BÁN LỖ NHIỀU LÀ NGUYÊN NHÂN CHÍNH LỢI NHUẬN T03.2026 BỊ LỖ
E3: Tấn | F3: Đồng/kg | G3: Triệu đồng | H3: Đồng/kg | I3: Tỷ đồng | J3: Tỷ đồng | L3: Tỷ đồng | M3: Tỷ đồng
B4: STT | C4: Công ty | D4: Sản phẩm | E4: SL bán | F4: Giá EXW BQ | G4: Doanh thu EXW | H4: Giá thành | I4: Tổng chi phí SX | J4: Tổng Lãi gộp | K4: % Lãi gộp/DT | L4: CP bán hàng, quản lý, TC phân bổ | M4: LNST | N4: % LNST/DT
B5: =IF(C5<>"",SUBTOTAL(3,C$5:C5),"") -> 1 | C5: VĨNH MINH PHƯỚC | D5: Hạt nhựa rPET WSS05SB | E5: 210100 | F5: 15852.338 | G5: 3.3305762e+09 | H5: =F5*(1-K5) -> 28354.81 | I5: =E5*H5 -> 5.9573455e+09 | J5: =G5-I5 -> -2.6267694e+09 | K5: -0.78868317 | L5: =G5*$E$45 -> 1.9776772e+08 | M5: =J5-L5 -> -2.8245371e+09 | N5: =M5/G5 -> -0.84806261
B6: =IF(C6<>"",SUBTOTAL(3,C$5:C6),"") -> 2 | C6: NHỰA TRƯỜNG AN | D6: Vảy HD Ép Đỏ | E6: 40500 | F6: 15791.665 | G6: 6.3956245e+08 | H6: =F6*(1-K6) -> 52854.635 | I6: =E6*H6 -> 2.1406127e+09 | J6: =G6-I6 -> -1.5010503e+09 | K6: -2.3469956 | L6: =G6*$E$45 -> 37976855 | M6: =J6-L6 -> -1.5390271e+09 | N6: =M6/G6 -> -2.406375
B7: =IF(C7<>"",SUBTOTAL(3,C$5:C7),"") -> 3 | C7: ĐẠI LỤC | D7: Hạt nhựa rPET WSS05SB | E7: 109300 | F7: 17603.354 | G7: 1.9240466e+09 | H7: =F7*(1-K7) -> 28354.81 | I7: =E7*H7 -> 3.0991807e+09 | J7: =G7-I7 -> -1.1751341e+09 | K7: -0.61076177 | L7: =G7*$E$45 -> 1.1424879e+08 | M7: =J7-L7 -> -1.2893829e+09 | N7: =M7/G7 -> -0.6701412
B8: =IF(C8<>"",SUBTOTAL(3,C$5:C8),"") -> 4 | C8: GIA TƯỜNG | D8: Dây đai PET | E8: 154500 | F8: 16143.689 | G8: 2494200000 | H8: =F8*(1-K8) -> 21246.657 | I8: =E8*H8 -> 3.2826085e+09 | J8: =G8-I8 -> -7.8840847e+08 | K8: -0.31609673 | L8: =G8*$E$45 -> 1.4810418e+08 | M8: =J8-L8 -> -9.3651265e+08 | N8: =M8/G8 -> -0.37547617
B9: =IF(C9<>"",SUBTOTAL(3,C$5:C9),"") -> 5 | C9: ĐẠI NHẤT LONG | D9: Vảy HD Ép Đỏ | E9: 14250 | F9: 15996.878 | G9: 2.2795551e+08 | H9: =F9*(1-K9) -> 52854.635 | I9: =E9*H9 -> 7.5317854e+08 | J9: =G9-I9 -> -5.2522303e+08 | K9: -2.3040594 | L9: =G9*$E$45 -> 13535869 | M9: =J9-L9 -> -5.387589e+08 | N9: =M9/G9 -> -2.3634388
B10: =IF(C10<>"",SUBTOTAL(3,C$5:C10),"") | D10: Vảy PP Đỏ Nhạt | E10: 20000 | F10: 16939.256 | G10: 3.3878512e+08 | H10: =F10*(1-K10) -> 20383.262 | I10: =E10*H10 -> 4.0766524e+08 | J10: =G10-I10 -> -68880117 | K10: -0.20331506 | L10: =G10*$E$45 -> 20116868 | M10: =J10-L10 -> -88996985 | N10: =M10/G10 -> -0.26269449
B11: =IF(C11<>"",SUBTOTAL(3,C$5:C11),"") | D11: Hạt nhựa rPP20R02 | E11: 2000 | F11: 18328.145 | G11: 36656290 | H11: =F11*(1-K11) -> 27705.922 | I11: =E11*H11 -> 55411843 | J11: =G11-I11 -> -18755553 | K11: -0.51165989 | L11: =G11*$E$45 -> 2176629.7 | M11: =J11-L11 -> -20932183 | N11: =M11/G11 -> -0.57103932
B12: =IF(C12<>"",SUBTOTAL(3,C$5:C12),"") -> 6 | C12: HOÀNG TẤN | D12: Phó Sản PET Bụi Tank A | E12: 37440 | F12: 4166.6666 | G12: 155999998 | H12: =F12*(1-K12) -> 10337.376 | I12: =E12*H12 -> 3.8703137e+08 | J12: =G12-I12 -> -2.3103137e+08 | K12: -1.4809704 | L12: =G12*$E$45 -> 9263191.3 | M12: =J12-L12 -> -2.4029456e+08 | N12: =M12/G12 -> -1.5403498
B13: =IF(C13<>"",SUBTOTAL(3,C$5:C13),"") | D13: Phó Sản PET Bụi Tank D | E13: 37510 | F13: 4166.6666 | G13: 156291666 | H13: =F13*(1-K13) -> 10232.893 | I13: =E13*H13 -> 3.8383582e+08 | J13: =G13-I13 -> -2.2754416e+08 | K13: -1.4558944 | L13: =G13*$E$45 -> 9280510.3 | M13: =J13-L13 -> -2.3682467e+08 | N13: =M13/G13 -> -1.5152738
B14: =IF(C14<>"",SUBTOTAL(3,C$5:C14),"") | D14: Phó Sản PET Bụi Tank B | E14: 36520 | F14: 4166.6667 | G14: 152166668 | H14: =F14*(1-K14) -> 8124.0787 | I14: =E14*H14 -> 2.9669136e+08 | J14: =G14-I14 -> -1.4452469e+08 | K14: -0.94977888 | L14: =G14*$E$45 -> 9035570.3 | M14: =J14-L14 -> -1.5356026e+08 | N14: =M14/G14 -> -1.0091583
B15: =IF(C15<>"",SUBTOTAL(3,C$5:C15),"") -> 7 | C15: HUY THÀNH | D15: Hạt nhựa rHDI3R01 | E15: 11000 | F15: 18500 | G15: 203500000 | H15: =F15*(1-K15) -> 47786.684 | I15: =E15*H15 -> 5.2565353e+08 | J15: =G15-I15 -> -3.2215353e+08 | K15: -1.583064 | L15: =G15*$E$45 -> 12083714 | M15: =J15-L15 -> -3.3423724e+08 | N15: =M15/G15 -> -1.6424434
B16: =IF(C16<>"",SUBTOTAL(3,C$5:C16),"") | D16: Hạt nhựa rHDI3G01 | E16: 38500 | F16: 18928.571 | G16: 728750000 | H16: =F16*(1-K16) -> 24977.833 | I16: =E16*H16 -> 9.6164657e+08 | J16: =G16-I16 -> -2.3289657e+08 | K16: -0.31958363 | L16: =G16*$E$45 -> 43272761 | M16: =J16-L16 -> -2.7616933e+08 | N16: =M16/G16 -> -0.37896306
B17: =IF(C17<>"",SUBTOTAL(3,C$5:C17),"") | D17: Hạt nhựa rHDI3Y01 | E17: 11000 | F17: 18500 | G17: 203500000 | H17: =F17*(1-K17) -> 21943.237 | I17: =E17*H17 -> 241375611 | J17: =G17-I17 -> -37875611 | K17: -0.18612094 | L17: =G17*$E$45 -> 12083714 | M17: =J17-L17 -> -49959325 | N17: =M17/G17 -> -0.24550037
B18: =IF(C18<>"",SUBTOTAL(3,C$5:C18),"") -> 8 | C18: CƯỜNG GIA PHÁT | D18: Vảy PET GC Dây Đai | E18: 77926 | F18: 11761.128 | G18: 9.1649769e+08 | H18: =F18*(1-K18) -> 19244.965 | I18: =E18*H18 -> 1.4996832e+09 | J18: =G18-I18 -> -5.8318549e+08 | K18: -0.63631964 | L18: =G18*$E$45 -> 54421112 | M18: =J18-L18 -> -6.376066e+08 | N18: =M18/G18 -> -0.69569908
B19: =IF(C19<>"",SUBTOTAL(3,C$5:C19),"") -> 9 | C19: CPSX Nhựa Duy Tân | D19: Hạt nhựa rHDI3R01 | E19: 16500 | F19: 19455 | G19: 321007500 | H19: =F19*(1-K19) -> 47786.684 | I19: =E19*H19 -> 7.8848029e+08 | J19: =G19-I19 -> -4.6747279e+08 | K19: -1.4562675 | L19: =G19*$E$45 -> 19061243 | M19: =J19-L19 -> -4.8653403e+08 | N19: =M19/G19 -> -1.5156469
B20: =IF(C20<>"",SUBTOTAL(3,C$5:C20),"") | D20: Hạt nhựa rHDI4L01 | E20: 22000 | F20: 19261.364 | G20: 423750000 | H20: =F20*(1-K20) -> 23264.948 | I20: =E20*H20 -> 5.1182885e+08 | J20: =G20-I20 -> -88078845 | K20: -0.20785568 | L20: =G20*$E$45 -> 25162034 | M20: =J20-L20 -> -1.1324088e+08 | N20: =M20/G20 -> -0.26723511
B21: =IF(C21<>"",SUBTOTAL(3,C$5:C21),"") -> 10 | C21: Quang Chí Bảo | D21: Hạt nhựa rPET WSS05SB | E21: 21000 | F21: 15852.267 | G21: 3.3289762e+08 | H21: =F21*(1-K21) -> 28354.81 | I21: =E21*H21 -> 5.95451e+08 | J21: =G21-I21 -> -2.6255339e+08 | K21: -0.78869111 | L21: =G21*$E$45 -> 19767271 | M21: =J21-L21 -> -2.8232066e+08 | N21: =M21/G21 -> -0.84807054
B22: =IF(C22<>"",SUBTOTAL(3,C$5:C22),"") -> 11 | C22: ANTEX | D22: Hạt nhựa rPET WSS04SD | E22: 21000 | F22: 16937.183 | G22: 3.5568084e+08 | H22: =F22*(1-K22) -> 26034.095 | I22: =E22*H22 -> 5.4671599e+08 | J22: =G22-I22 -> -1.9103515e+08 | K22: -0.5370971 | L22: =G22*$E$45 -> 21120126 | M22: =J22-L22 -> -2.1215528e+08 | N22: =M22/G22 -> -0.59647653
B23: =IF(C23<>"",SUBTOTAL(3,C$5:C23),"") -> 12 | C23: VĂN MINH | D23: Vảy HD Ép Trắng | E23: 36000 | F23: 15859.7 | G23: 5.7094921e+08 | H23: =F23*(1-K23) -> 20292.772 | I23: =E23*H23 -> 7.3053979e+08 | J23: =G23-I23 -> -1.5959058e+08 | K23: -0.279518 | L23: =G23*$E$45 -> 33902640 | M23: =J23-L23 -> -1.9349322e+08 | N23: =M23/G23 -> -0.33889743
B24: =IF(C24<>"",SUBTOTAL(3,C$5:C24),"") -> 13 | C24: MHE ENTERPRISE | D24: Hạt nhựa rHDB04B01 | E24: 108000 | F24: 19177.115 | G24: 2071128419 | H24: =F24*(1-K24) -> 20349.585 | I24: =E24*H24 -> 2.1977552e+09 | J24: =G24-I24 -> -1.2662675e+08 | K24: -0.061139016 | L24: =G24*$E$45 -> 1.2298243e+08 | M24: =J24-L24 -> -2.4960918e+08 | N24: =M24/G24 -> -0.12051845
B25: =IF(C25<>"",SUBTOTAL(3,C$5:C25),"") -> 14 | C25: MTVN Plastic | D25: Hạt nhựa rHDB04B01 | E25: 27500 | F25: 15972.222 | G25: 439236112 | H25: =F25*(1-K25) -> 20349.585 | I25: =E25*H25 -> 5.5961359e+08 | J25: =G25-I25 -> -1.2037747e+08 | K25: -0.27406097 | L25: =G25*$E$45 -> 26081591 | M25: =J25-L25 -> -1.4645906e+08 | N25: =M25/G25 -> -0.3334404
B26: =IF(C26<>"",SUBTOTAL(3,C$5:C26),"") -> 15 | C26: TỔNG | E26: =SUM(E5:E25) -> 1052546 | G26: =SUM(G5:G25) -> 1.6023138e+10 | I26: =SUM(I5:I25) -> 2.5922305e+10 | J26: =SUM(J5:J25) -> -9.8991673e+09 | K26: =J26/$G26 -> -0.61780454 | L26: =SUM(L5:L25) -> 9.5144482e+08 | M26: =SUM(M5:M25) -> -1.0850612e+10 | N26: =M26/$G26 -> -0.67718397
B27: Ngoài ra các khách đang có %Lãi gộp thấp:
B28: * | C28: Suntory | D28: Hạt nhựa rPET iSS01084G | E28: 594000 | F28: 29452.718 | G28: 1.7494914e+10 | H28: =F28*(1-K28) -> 28764.36 | I28: =E28*H28 -> 1.708603e+10 | J28: =G28-I28 -> 4.0888419e+08 | K28: 0.023371603 | L28: =G28*$E$45 -> 1.0388381e+09 | M28: =J28-L28 -> -6.2995388e+08 | N28: =M28/G28 -> -0.036007829
B29: ** | C29: Niagara-US | D29: Hạt nhựa rPET WSS01G 1 | E29: 572000 | F29: 26863.555 | G29: 1.5365954e+10 | H29: =F29*(1-K29) -> 25463.673 | I29: =E29*H29 -> 1.4565221e+10 | J29: =G29-I29 -> 8.007325e+08 | K29: 0.052110824 | L29: =G29*$E$45 -> 9.124216e+08 | M29: =J29-L29 -> -1.116891e+08 | N29: =M29/G29 -> -0.0072686084
C34: Doanh thu kế toán | D34: 1.7330582e+11
C35: Biến phí hàng bán | D35: =SUM(D36:D39) -> 5.1292186e+09
C36: Cp xuất khẩu | D36: 1805602205
C37: Cp thuê xe giao hàng nội địa | D37: 556120832
C38: Chiết khấu/hoa hồng | D38: 2221270799
C39: Pallet xuất hàng | D39: 5.4622475e+08
C40: Doanh thu EXW | D40: =D34-D35 -> 1.681766e+11
C41: CPBH còn lại | D41: 1662701952 | E41: =D41/D$40 -> 0.0098866425
C42: CPQLDN | D42: 7329810589 | E42: =D42/D$40 -> 0.043584009
C43: Chi phí lãi vay | D43: 959718564 | E43: =D43/D$40 -> 0.0057066116
C44: Cp khác (811) | D44: 34000105 | E44: =D44/D$40 -> 0.00020216905
...
