Workbook
Name mth: Mth!$B$2
Name year: Mth!$B$1

Sheet Mth
B1: 2025
B2: 11

Sheet S6
C4: =C12/C7 -> 0.010874696
A5: ĐVT: VND; kg; VND/kg; USD/ton | K5: TÁC ĐỘNG
B6: KH | C6: TT | D6: +/ | F6: %Cơ cấu SL-KH | G6: %Cơ cấu SL-TT | H6: SL-TT-Cơ cấu KH | I6: DT-TT-Cơ cấu KH | K6: Sản lượng | L6: Cơ cấu ngành | M6: Giá bán | N6: Tỷ giá | O6: Khác | P6: Cp vận chuyển, hoa hồng, chiết khấu | U6: Label chart-SL-KH | V6: Label chart-SL-TT
A7: Sản lượng SPC | B7: =SUM(B8:B12) -> 5968970 | C7: =SUM(C8:C12) -> 2510415 | D7: =C7-B7 -> -3458555 | E7: =D7/B7 -> -0.57942241 | H7: =SUM(H8:H12) -> 2510415
A8: rPET | B8: ='S7'!P43*10^6 -> 4678780 | C8: ='S7'!Q43*10^6 -> 2027640 | D8: =C8-B8 -> -2651140 | E8: =D8/B8 -> -0.56663062 | F8: =B8/B$7 -> 0.78385048 | G8: =C8/C$7 -> 0.80769116 | H8: =F8*C$7 -> 1967790 | K8: =I14-B20 -> -8.7707975e+10 | L8: =C8*B14-I14 -> 1.9363118e+09 | M8: =D33*C8/10^3*$B$39 -> -3.5577563e+09 | N8: =IFERROR(C20-C20/C40*B40,0) -> 2.9478354e+09 | Q8: =SUM(K8:P8) -> -8.6381584e+10 | R8: =SUM(K8:L8) -> -8.5771663e+10 | S8: -2.4223451e+10 | U8: =_xlfn.TEXTJOIN(" | ",FALSE,TEXT(B8/10^3,"#,###"),TEXT(F8,"0.0%")) -> 4,679 | 78.4% | V8: =_xlfn.TEXTJOIN(" | ",FALSE,TEXT(C8/10^3,"#,###"),TEXT(G8,"0.0%")) -> 2,028 | 80.8%
A9: rHDPE thổi | B9: ='S7'!P44*10^6 -> 927000 | C9: ='S7'!Q44*10^6 -> 268725 | D9: =C9-B9 -> -658275 | E9: =D9/B9 -> -0.71011327 | F9: =B9/B$7 -> 0.15530318 | G9: =C9/C$7 -> 0.10704405 | H9: =F9*C$7 -> 389875.42 | K9: =I15-B21 -> -1.7952969e+10 | L9: =C9*B15-I15 -> -4.0493581e+09 | M9: =D34*C9/10^3*$B$39 -> -2.1972615e+09 | N9: =IFERROR(C21-C21/C41*B41,0) -> 3.2332892e+08 | Q9: =SUM(K9:P9) -> -2.387626e+10 | R9: =SUM(K9:L9) -> -2.2002327e+10 | S9: -1.6262315e+10 | U9: =_xlfn.TEXTJOIN(" | ",FALSE,TEXT(B9/10^3,"#,###"),TEXT(F9,"0.0%")) -> 927 | 15.5% | V9: =_xlfn.TEXTJOIN(" | ",FALSE,TEXT(C9/10^3,"#,###"),TEXT(G9,"0.0%")) -> 269 | 10.7%
A10: rHDPE ép | B10: ='S7'!P45*10^6 -> 155750 | C10: ='S7'!Q45*10^6 -> 186750 | D10: =C10-B10 -> 31000 | E10: =D10/B10 -> 0.19903692 | F10: =B10/B$7 -> 0.026093279 | G10: =C10/C$7 -> 0.074390091 | H10: =F10*C$7 -> 65504.959 | K10: =I16-B22 -> -1.8805517e+09 | L10: =C10*B16-I16 -> 2.5265384e+09 | M10: =D35*C10/10^3*$B$39 -> -9.226508e+08 | N10: =IFERROR(C22-C22/C42*B42,0) -> 1.4111161e+08 | Q10: =SUM(K10:P10) -> -1.3555243e+08 | R10: =SUM(K10:L10) -> 6.4598676e+08 | S10: -1.6304001e+09 | U10: =_xlfn.TEXTJOIN(" | ",FALSE,TEXT(B10/10^3,"#,###"),TEXT(F10,"0.0%")) -> 156 | 2.6% | V10: =_xlfn.TEXTJOIN(" | ",FALSE,TEXT(C10/10^3,"#,###"),TEXT(G10,"0.0%")) -> 187 | 7.4%
A11: rPP | B11: ='S7'!P46*10^6 -> 107440 | C11: ='S7'!Q46*10^6 -> 0 | D11: =C11-B11 -> -107440 | E11: =D11/B11 -> -1 | F11: =B11/B$7 -> 0.017999755 | G11: =C11/C$7 -> 0 | H11: =F11*C$7 -> 45186.856 | K11: =I17-B23 -> -1.3770698e+09 | L11: =C11*B17-I17 -> -9.9955521e+08 | M11: =D36*C11/10^3*$B$39 -> 0 | N11: =IFERROR(C23-C23/C43*B43,0) -> 0 | Q11: =SUM(K11:P11) -> -2.376625e+09 | R11: =SUM(K11:L11) -> -2.376625e+09 | S11: -1.1216801e+09 | U11: =_xlfn.TEXTJOIN(" | ",FALSE,TEXT(B11/10^3,"#,###"),TEXT(F11,"0.0%")) -> 107 | 1.8% | V11: =_xlfn.TEXTJOIN(" | ",FALSE,TEXT(C11/10^3,"#,###"),TEXT(G11,"0.0%")) -> | 0.0%
A12: Xơ sợi | B12: ='S7'!P47*10^6 -> 100000 | C12: ='S7'!Q47*10^6 -> 27300 | D12: =C12-B12 -> -72700 | E12: =D12/B12 -> -0.727 | F12: =B12/B$7 -> 0.016753309 | G12: =C12/C$7 -> 0.010874696 | H12: =F12*C$7 -> 42057.759 | K12: =I18-B24 -> -1.5934116e+09 | L12: =C12*B18-I18 -> -4.0583836e+08 | M12: =D37*C12/10^3*$B$39 -> -3.2015983e+08 | N12: =IFERROR(C24-C24/C44*B44,0) -> 20488657 | Q12: =SUM(K12:P12) -> -2.2989212e+09 | R12: =SUM(K12:L12) -> -1.99925e+09 | S12: 1.28645e+10 | U12: =_xlfn.TEXTJOIN(" | ",FALSE,TEXT(B12/10^3,"#,###"),TEXT(F12,"0.0%")) -> 100 | 1.7% | V12: =_xlfn.TEXTJOIN(" | ",FALSE,TEXT(C12/10^3,"#,###"),TEXT(G12,"0.0%")) -> 27 | 1.1%
A13: GB EXW (VND/kg) | B13: 30553.285 | C13: 28801.443 | D13: =C13-B13 -> -1751.8418 | I13: =SUM(I14:I18) -> 8.0215848e+10
A14: rPET | B14: =B33*B40/10^3 -> 32352.747 | C14: =C33*C40/10^3 -> 32051.944 | I14: =H8*B14 -> 6.3663413e+10
A15: rHDPE thổi | B15: =B34*B41/10^3 -> 33424.218 | C15: =C34*C41/10^3 -> 26450.797 | I15: =H9*B15 -> 1.3031281e+10
A16: rHDPE ép | B16: =B35*B42/10^3 -> 20838.283 | C16: =C35*C42/10^3 -> 16653.334 | I16: =H10*B16 -> 1.3650108e+09
A17: rPP | B17: =B36*B43/10^3 -> 22120.486 | C17: =C36*C43/10^3 -> 0 | I17: =H11*B17 -> 9.9955521e+08
A18: Xơ sợi | B18: =B37*B44/10^3 -> 27500 | C18: =C37*C44/10^3 -> 16523.034 | I18: =H12*B18 -> 1.1565884e+09
A19: Doanh thu SPC | B19: =SUM(B20:B24) -> 1.9072782e+11 | C19: =SUM(C20:C24) -> 7.5658883e+10 | D19: =C19-B19 -> -1.1506894e+11
A20: rPET | B20: =B8*B14 -> 1.5137139e+11 | C20: =C8*C14 -> 6.4989804e+10 | E20: =C20-B20 -> -8.6381584e+10 | F20: =E20/B20 -> -0.57065992
A21: rHDPE thổi | B21: =B9*B15 -> 3.098425e+10 | C21: =C9*C15 -> 7107990427 | E21: =C21-B21 -> -2.387626e+10 | F21: =E21/B21 -> -0.77059343
A22: rHDPE ép | B22: =B10*B16 -> 3.2455625e+09 | C22: =C10*C16 -> 3.1100101e+09 | E22: =C22-B22 -> -1.3555243e+08 | F22: =E22/B22 -> -0.041765467
A23: rPP | B23: =B11*B17 -> 2.376625e+09 | C23: =C11*C17 -> 0 | E23: =C23-B23 -> -2.376625e+09 | F23: =E23/B23 -> -1
A24: Xơ sợi | B24: =B12*B18 -> 2.75e+09 | C24: =C12*C18 -> 4.5107882e+08 | E24: =C24-B24 -> -2.2989212e+09 | F24: =E24/B24 -> -0.83597134
A25: Tài trợ | B25: 3408550000 | C25: 3395251201 | D25: =C25-B25 -> -13298799 | O25: =D25 -> -13298799 | Q25: =SUM(K25:P25) -> -13298799
A26: Dây đai, phó sản | B26: 2640000000 | C26: 6989889073 | D26: =C26-B26 -> 4349889073 | O26: =D26 -> 4349889073 | Q26: =SUM(K26:P26) -> 4349889073
A27: Khác | C27: 63558813 | D27: =C27-B27 -> 63558813 | O27: =D27 -> 63558813 | Q27: =SUM(K27:P27) -> 63558813
A28: Cp vận chuyển, hoa hồng, chiết khấu | B28: ='S7'!C20 -> 12485577500 | C28: ='S7'!G20 -> 2.2402986e+09 | D28: =C28-B28 -> -1.0245279e+10 | P28: =D28 -> -1.0245279e+10
A29: Tổng dthu thuần | B29: =B19+B25+B26+B27+B28 -> 2.0926195e+11 | C29: =C19+C25+C26+C27+C28 -> 88347880802 | D29: =C29-B29 -> -1.2091407e+11 | K29: =SUM(K7:K28) -> -1.1051198e+11 | L29: =SUM(L7:L28) -> -9.9190147e+08 | M29: =SUM(M7:M28) -> -6.9978284e+09 | N29: =SUM(N7:N28) -> 3.4327645e+09 | O29: =SUM(O7:O28) -> 4.4001491e+09 | P29: =SUM(P7:P28) -> -1.0245279e+10 | Q29: =SUM(K29:P29) -> -1.2091407e+11
A30: check | B30: =B29-'S7'!C3 -> 0 | C30: =C29-'S7'!G17 -> 0 | D30: =D29/B29 -> -0.57781202 | P30: Check | Q30: =Q29-D29 -> 0
A32: GB EXW (USD/ton) | B32: KH | C32: TT
A33: rPET | B33: 1294.1099 | C33: 1223.9247 | D33: =C33-B33 -> -70.185167 | E33: =IFERROR(D33/B33,0) -> -0.054234317 | Q33: -52808442002
A34: rHDPE thổi | B34: 1336.9687 | C34: 1009.904 | D34: =C34-B34 -> -327.06469 | E34: =IFERROR(D34/B34,0) -> -0.24463152 | Q34: =Q33-Q29 -> 6.810563e+10
A35: rHDPE ép | B35: 833.5313 | C35: 635.90864 | D35: =C35-B35 -> -197.62266 | E35: =IFERROR(D35/B35,0) -> -0.23709087
A36: rPP | B36: 884.81943 | C36: 0 | D36: =C36-B36 -> -884.81943 | E36: =IFERROR(D36/B36,0) -> -1
A37: Xơ sợi | B37: 1100 | C37: 630.90134 | D37: =C37-B37 -> -469.09866 | E37: =IFERROR(D37/B37,0) -> -0.42645332
A39: Exchange rate | B39: 25000 | C39: 26188.206 | D39: =C39-B39 -> 1188.2064 | E39: =IFERROR(D39/B39,0) -> 0.047528257
A40: rPET | B40: 25000 | C40: 26187.839
A41: rHDPE thổi | B41: 25000 | C41: 26191.397
A42: rHDPE ép | B42: 25000 | C42: 26188.249
A43: rPP | B43: 25000 | C43: 0
A44: Xơ sợi | B44: 25000 | C44: 26189.568
A47: Vẽ (VND nhưng thể hiện là tỷ)
...

Sheet S7
A1: ĐVT: VND nhưng show là tỷ đồng | AE1: Dthu (theo tỷ giá KH)
C2: Start | D2: Hidden | E2: Increase | F2: Decrease | G2: End | H2: Chênh lệch | K2: T/Đ làm từng SKU | M2: T/Đ nếu như nhóm ngành | P2: KH | Q2: TT | U2: KH | V2: TT | Z2: Tổng tác động | AA2: SL | AB2: GB | AC2: EXR | AE2: KH | AF2: TT
A3: KH T11 | C3: =H3 -> 209261952500 | H3: 209261952500
A4: rPET | B4: Sản lượng | D4: =C3+E3-F4 -> 1.2349029e+11 | E4: =IF(H4>0,H4,0) -> 0 | F4: =IF(H4<0,-H4,0) -> 8.5771663e+10 | H4: =M4 -> -8.5771663e+10 | K4: -8.5106687e+10 | M4: =AA4 -> -8.5771663e+10 | O4: tấn | P4: 4678.78 | Q4: 2027.64 | R4: =Q4-P4 -> -2651.14 | S4: =R4/P4 -> -0.56663062 | Z4: =SUM(AA4:AC4) -> -8.6381584e+10 | AA4: =R4*P5*U5 -> -8.5771663e+10 | AB4: =R5*Q4*U5 -> -3.5577563e+09 | AC4: =Q4*Q5*W5 -> 2.9478354e+09 | AE4: =P4*P5*U5 -> 151371387500 | AF4: =Q4*Q5*U5 -> 6.2041968e+10 | AH4: =Q4*Q5*V5 -> 6.4989804e+10 | AI4: =AH4-AF4-AC4 -> 0 | AK4: =AF4-AE4 -> -8.9329419e+10 | AL4: =AK4/AE4 -> -0.59013411
B5: Giá bán | D5: =D4+E4-F5 -> 1.1993253e+11 | E5: =IF(H5>0,H5,0) -> 0 | F5: =IF(H5<0,-H5,0) -> 3.5577563e+09 | H5: =M5 -> -3.5577563e+09 | K5: -3.8258734e+09 | L5: =SUM(K4:K5)-SUM(M4:M5) -> 3.9685854e+08 | M5: =AB4 -> -3.5577563e+09 | O5: $/tấn | P5: 1294.1099 | Q5: 1223.9247 | R5: =Q5-P5 -> -70.185167 | S5: =R5/P5 -> -0.054234317 | U5: 25000 | V5: 26187.839 | W5: =V5-U5 -> 1187.8392 | X5: =W5/U5 -> 0.047513569
A6: rHDPE thổi | B6: Sản lượng | D6: =D5+E5-F6 -> 9.7930206e+10 | E6: =IF(H6>0,H6,0) -> 0 | F6: =IF(H6<0,-H6,0) -> 2.2002327e+10 | H6: =M6 -> -2.2002327e+10 | K6: -2.3477828e+10 | M6: =AA6 -> -2.2002327e+10 | O6: tấn | P6: 927 | Q6: 268.725 | R6: =Q6-P6 -> -658.275 | S6: =R6/P6 -> -0.71011327 | Z6: =SUM(AA6:AC6) -> -2.387626e+10 | AA6: =R6*P7*U7 -> -2.2002327e+10 | AB6: =R7*Q6*U7 -> -2.1972615e+09 | AC6: =Q6*Q7*W7 -> 3.2332892e+08 | AE6: =P6*P7*U7 -> 30984250000 | AF6: =Q6*Q7*U7 -> 6.7846615e+09 | AH6: =Q6*Q7*V7 -> 7107990427 | AI6: =AH6-AF6-AC6 -> 0 | AK6: =AF6-AE6 -> -2.4199588e+10 | AL6: =AK6/AE6 -> -0.7810287
B7: Giá bán | D7: =D6+E6-F7 -> 9.5732945e+10 | E7: =IF(H7>0,H7,0) -> 0 | F7: =IF(H7<0,-H7,0) -> 2.1972615e+09 | H7: =M7 -> -2.1972615e+09 | K7: -6.6481021e+08 | L7: =SUM(K6:K7)-SUM(M6:M7) -> 56950537 | M7: =AB6 -> -2.1972615e+09 | O7: $/tấn | P7: 1336.9687 | Q7: 1009.904 | R7: =Q7-P7 -> -327.06469 | S7: =R7/P7 -> -0.24463152 | U7: 25000 | V7: 26191.397 | W7: =V7-U7 -> 1191.3967 | X7: =W7/U7 -> 0.047655866
A8: rHDPE ép | B8: Sản lượng | D8: =D7+E7-F8 -> 9.5732945e+10 | E8: =IF(H8>0,H8,0) -> 6.4598676e+08 | F8: =IF(H8<0,-H8,0) -> 0 | H8: =M8 -> 6.4598676e+08 | K8: -77313570 | M8: =AA8 -> 6.4598676e+08 | O8: tấn | P8: 155.75 | Q8: 186.75 | R8: =Q8-P8 -> 31 | S8: =R8/P8 -> 0.19903692 | Z8: =SUM(AA8:AC8) -> -1.3555243e+08 | AA8: =R8*P9*U9 -> 6.4598676e+08 | AB8: =R9*Q8*U9 -> -9.226508e+08 | AC8: =Q8*Q9*W9 -> 1.4111161e+08 | AE8: =P8*P9*U9 -> 3245562500 | AF8: =Q8*Q9*U9 -> 2.9688985e+09 | AH8: =Q8*Q9*V9 -> 3.1100101e+09 | AI8: =AH8-AF8-AC8 -> 2.682209e-07 | AK8: =AF8-AE8 -> -2.7666404e+08 | AL8: =AK8/AE8 -> -0.085243789
B9: Giá bán | D9: =D8+E8-F9 -> 9.5456281e+10 | E9: =IF(H9>0,H9,0) -> 0 | F9: =IF(H9<0,-H9,0) -> 9.226508e+08 | H9: =M9 -> -9.226508e+08 | K9: -66770463 | L9: =SUM(K8:K9)-SUM(M8:M9) -> 1.3258001e+08 | M9: =AB8 -> -9.226508e+08 | O9: $/tấn | P9: 833.5313 | Q9: 635.90864 | R9: =Q9-P9 -> -197.62266 | S9: =R9/P9 -> -0.23709087 | U9: 25000 | V9: 26188.249 | W9: =V9-U9 -> 1188.2489 | X9: =W9/U9 -> 0.047529955
A10: rPP | B10: Sản lượng | D10: =D9+E9-F10 -> 9.3079656e+10 | E10: =IF(H10>0,H10,0) -> 0 | F10: =IF(H10<0,-H10,0) -> 2.376625e+09 | H10: =M10 -> -2.376625e+09 | K10: -2376625000 | M10: =AA10 -> -2.376625e+09 | O10: tấn | P10: 107.44 | Q10: 0 | R10: =Q10-P10 -> -107.44 | S10: =R10/P10 -> -1 | Z10: =SUM(AA10:AC10) -> -2.376625e+09 | AA10: =R10*P11*U11 -> -2.376625e+09 | AB10: =R11*Q10*U11 -> 0 | AC10: =Q10*Q11*W11 -> 0 | AE10: =P10*P11*U11 -> 2.376625e+09 | AF10: =Q10*Q11*U11 -> 0 | AH10: =Q10*Q11*V11 -> 0 | AI10: =AH10-AF10-AC10 -> 0 | AK10: =AF10-AE10 -> -2.376625e+09 | AL10: =AK10/AE10 -> -1
B11: Giá bán | D11: =D10+E10-F11 -> 9.3079656e+10 | E11: =IF(H11>0,H11,0) -> 0 | F11: =IF(H11<0,-H11,0) -> 0 | H11: =M11 -> 0 | K11: 0 | L11: =SUM(K10:K11)-SUM(M10:M11) -> 0 | M11: =AB10 -> 0 | O11: $/tấn | P11: 884.81943 | Q11: 0 | R11: =Q11-P11 -> -884.81943 | S11: =R11/P11 -> -1 | U11: 25000 | V11: 0 | W11: =V11-U11 -> -25000 | X11: =W11/U11 -> -1
A12: Xơ sợi | B12: Sản lượng | D12: =D11+E11-F12 -> 9.1080406e+10 | E12: =IF(H12>0,H12,0) -> 0 | F12: =IF(H12<0,-H12,0) -> 1999250000 | H12: =M12 -> -1999250000 | K12: -2.2989212e+09 | M12: =AA12 -> -1999250000 | O12: tấn | P12: 100 | Q12: 27.3 | R12: =Q12-P12 -> -72.7 | S12: =R12/P12 -> -0.727 | Z12: =SUM(AA12:AC12) -> -2.2989212e+09 | AA12: =R12*P13*U13 -> -1999250000 | AB12: =R13*Q12*U13 -> -3.2015983e+08 | AC12: =Q12*Q13*W13 -> 20488657 | AE12: =P12*P13*U13 -> 2750000000 | AF12: =Q12*Q13*U13 -> 4.3059017e+08 | AH12: =Q12*Q13*V13 -> 4.5107882e+08 | AI12: =AH12-AF12-AC12 -> 0 | AK12: =AF12-AE12 -> -2.3194098e+09 | AL12: =AK12/AE12 -> -0.84342176
B13: Giá bán | D13: =D12+E12-F13 -> 9.0760246e+10 | E13: =IF(H13>0,H13,0) -> 0 | F13: =IF(H13<0,-H13,0) -> 3.2015983e+08 | H13: =M13 -> -3.2015983e+08 | K13: 0 | L13: =SUM(K12:K13)-SUM(M12:M13) -> 20488657 | M13: =AB12 -> -3.2015983e+08 | O13: $/tấn | P13: 1100 | Q13: 630.90134 | R13: =Q13-P13 -> -469.09866 | S13: =R13/P13 -> -0.42645332 | U13: 25000 | V13: 26189.568 | W13: =V13-U13 -> 1189.5683 | X13: =W13/U13 -> 0.047582733
A14: Tỷ giá | D14: =D13+E13-F14 -> 9.0760246e+10 | E14: =IF(H14>0,H14,0) -> 3.4327645e+09 | F14: =IF(H14<0,-H14,0) -> 0 | H14: =M14 -> 3.4327645e+09 | K14: 2.9466752e+09 | M14: =AC4+AC6+AC8+AC10+AC12 -> 3.4327645e+09
A15: Khác | D15: =D14+E14-F15 -> 9.4193011e+10 | E15: =IF(H15>0,H15,0) -> 4.4001491e+09 | F15: =IF(H15<0,-H15,0) -> 0 | H15: =H17-SUM(H3:H14,H16) -> 4.4001491e+09 | AE15: =AE17-SUM(AE3:AE14) -> 18534127500 | AF15: =AF17-SUM(AF3:AF14) -> 1.2688998e+10
A16: hoa hồng, chiết khấu | B16: Cp vận chuyển | D16: =D15+E15-F16 -> 88347880802 | E16: =IF(H16>0,H16,0) -> 0 | F16: =IF(H16<0,-H16,0) -> 1.0245279e+10 | H16: =G20-C20 -> -1.0245279e+10
A17: TT T11 | G17: =D16+E16 -> 88347880802 | H17: 88347880802 | I17: =H17-H3 -> -120914071698 | J17: =H17/H3-1 -> -0.57781202 | U17: 25000 | V17: 26188.206 | W17: =V17-U17 -> 1188.2064 | X17: =W17/U17 -> 0.047528257 | AE17: =C3 -> 209261952500 | AF17: =G17-H14 -> 8.4915116e+10 | AH17: =G17-AF17 -> 3.4327645e+09
A18: Check | G18: =G17-H17 -> 0
O19: Dthu (tỷ VND) | P19: KH | Q19: TT
A20: Cp vận chuyển, hoa hồng, chiết khấu | C20: =C3-C21 -> 12485577500 | G20: =H17-G21 -> 2.2402986e+09 | O20: rPET | P20: =P4*P5*U5/10^9 -> 151.37139 | Q20: =Q4*Q5*V5/10^9 -> 64.989804 | R20: =Q20-P20 -> -86.381584 | S20: =IFERROR(R20/P20,0) -> -0.57065992 | U20: =Q20/Q27 -> 0.73561248
A21: Doanh thu EXW | C21: 196776375000 | G21: 8.6107582e+10 | O21: rHDPE thổi | P21: =P6*P7*U7/10^9 -> 30.98425 | Q21: =Q6*Q7*V7/10^9 -> 7.1079904 | R21: =Q21-P21 -> -23.87626 | S21: =IFERROR(R21/P21,0) -> -0.77059343
O22: rHDPE ép | P22: =P8*P9*U9/10^9 -> 3.2455625 | Q22: =Q8*Q9*V9/10^9 -> 3.1100101 | R22: =Q22-P22 -> -0.13555243 | S22: =IFERROR(R22/P22,0) -> -0.041765467
C23: 12485577500 | O23: rPP | P23: =P10*P11*U11/10^9 -> 2.376625 | Q23: =Q10*Q11*V11/10^9 -> 0 | R23: =Q23-P23 -> -2.376625 | S23: =IFERROR(R23/P23,0) -> -1
O24: Xơ sợi | P24: =P12*P13*U13/10^9 -> 2.75 | Q24: =Q12*Q13*V13/10^9 -> 0.45107882 | R24: =Q24-P24 -> -2.2989212 | S24: =IFERROR(R24/P24,0) -> -0.83597134
O25: Khác | P25: =C3/10^9-SUM(P20:P24,P26) -> 6.04855 | Q25: =G17/10^9-SUM(Q20:Q24,Q26) -> 10.448699 | R25: =Q25-P25 -> 4.4001491 | S25: =IFERROR(R25/P25,0) -> 0.72747172
O26: Cp vận chuyển, hoa hồng, chiết khấu | P26: =C20/10^9 -> 12.485577 | Q26: =G20/10^9 -> 2.2402986 | R26: =Q26-P26 -> -10.245279 | S26: =IFERROR(R26/P26,0) -> -0.82056909
G27: SL | H27: =H4+H6+H8+H10+H12 -> -1.1150388e+11 | O27: Tổng | P27: =SUM(P20:P26) -> 209.26195 | Q27: =SUM(Q20:Q26) -> 88.347881 | R27: =Q27-P27 -> -120.91407 | S27: =IFERROR(R27/P27,0) -> -0.57781202
G28: GB | H28: =H5+H7+H9+H11+H13 -> -6.9978284e+09
O30: Dthu (tỷ VND) | P30: KH | Q30: TT | R30: - Loại trừ chênh lệch tỷ giá
O31: rPET | P31: =P4*P5*U5/10^9 -> 151.37139 | Q31: =Q4*Q5*U5/10^9 -> 62.041968 | R31: =Q31-P31 -> -89.329419 | S31: =IFERROR(R31/P31,0) -> -0.59013411
O32: rHDPE thổi | P32: =P6*P7*U7/10^9 -> 30.98425 | Q32: =Q6*Q7*U7/10^9 -> 6.7846615 | R32: =Q32-P32 -> -24.199588 | S32: =IFERROR(R32/P32,0) -> -0.7810287
O33: rHDPE ép | P33: =P8*P9*U9/10^9 -> 3.2455625 | Q33: =Q8*Q9*U9/10^9 -> 2.9688985 | R33: =Q33-P33 -> -0.27666404 | S33: =IFERROR(R33/P33,0) -> -0.085243789
O34: rPP | P34: =P10*P11*U11/10^9 -> 2.376625 | Q34: =Q10*Q11*U11/10^9 -> 0 | R34: =Q34-P34 -> -2.376625 | S34: =IFERROR(R34/P34,0) -> -1
O35: Xơ sợi | P35: =P12*P13*U13/10^9 -> 2.75 | Q35: =Q12*Q13*U13/10^9 -> 0.43059017 | R35: =Q35-P35 -> -2.3194098 | S35: =IFERROR(R35/P35,0) -> -0.84342176
O36: Chênh lệch tỷ giá | Q36: =(AC4+AC6+AC8+AC10+AC12)/10^9 -> 3.4327645 | R36: =Q36-P36 -> 3.4327645 | S36: =IFERROR(R36/P36,0) -> 0
O37: Khác | P37: =C3/10^9-SUM(P31:P36,P38) -> 6.04855 | Q37: =G17/10^9-SUM(Q31:Q36,Q38) -> 10.448699 | R37: =Q37-P37 -> 4.4001491 | S37: =IFERROR(R37/P37,0) -> 0.72747172
O38: Cp vận chuyển, hoa hồng, chiết khấu | P38: =C20/10^9 -> 12.485577 | Q38: =G20/10^9 -> 2.2402986 | R38: =Q38-P38 -> -10.245279 | S38: =IFERROR(R38/P38,0) -> -0.82056909
O39: Tổng | P39: =SUM(P31:P38) -> 209.26195 | Q39: =SUM(Q31:Q38) -> 88.347881 | R39: =Q39-P39 -> -120.91407 | S39: =IFERROR(R39/P39,0) -> -0.57781202
O42: Sản lượng (ng.tấn) | P42: KH | Q42: TT | R42: +-/- | S42: %+-/- | T42: %Thực hiện
O43: rPET | P43: =P4/10^3 -> 4.67878 | Q43: =Q4/10^3 -> 2.02764 | R43: =Q43-P43 -> -2.65114 | S43: =IFERROR(R43/P43,0) -> -0.56663062 | T43: =Q43/P43 -> 0.43336938
...

Sheet S8
A1: ĐVT: VND nhưng show là tỷ đồng | AH1: LG EXW (THEO TỶ GIÁ KH) | AO1: DTHU EXW (THEO TỶ GIÁ KH) | AR1: %Biên
C2: Start | D2: Hidden | E2: Increase | F2: Decrease | G2: End | H2: Chênh lệch | M2: T/Đ nếu như nhóm ngành | P2: KH | Q2: TT | U2: KH | V2: TT | Z2: Tổng tác động | AA2: SL | AB2: GB | AC2: GV | AD2: EXR | AE2: Model | AH2: KH | AI2: TT | AJ2: +/- | AK2: %+/- | AO2: KH | AP2: TT
A3: ='S7'!A3 -> KH T11 | C3: =H3 -> 4.8459973e+10 | H3: 4.8459973e+10
A4: rPET | B4: Sản lượng | D4: =C3+E3-F4 -> 3.2103197e+10 | E4: =IF(H4>0,H4,0) -> 0 | F4: =IF(H4<0,-H4,0) -> 1.6356776e+10 | H4: =M4 -> -1.6356776e+10 | M4: {=TRANSPOSE(AA4:AC4)} -> -1.6356776e+10 | O4: tấn | P4: 4678.78 | Q4: 2027.64 | R4: =Q4-P4 -> -2651.14 | S4: =R4/P4 -> -0.56663062 | Z4: =SUM(AA4:AD4) -> -2.1969183e+10 | AA4: =R4*(P5*U5-P6*10^3) -> -1.6356776e+10 | AB4: =R5*Q4*U5 -> -3.5577563e+09 | AC4: =-R6*Q4*10^3 -> -5.0024859e+09 | AD4: =Q4*Q5*W5 -> 2.9478354e+09 | AE4: -2.1969183e+10 | AF4: =Z4-AE4 -> 0 | AH4: =P4*(P5*U5-P6*10^3) -> 2.8866735e+10 | AI4: =Q4*(Q5*U5-Q6*10^3) -> 3.9497169e+09 | AJ4: =AI4-AH4 -> -2.4917018e+10 | AK4: =AJ4/AH4 -> -0.8631741 | AM4: =Q4*(Q5*V5-Q6*10^3) -> 6.8975523e+09 | AN4: =AM4-AI4-AD4 -> 0 | AO4: ='S7'!AE4 -> 151371387500 | AP4: ='S7'!AF4 -> 6.2041968e+10 | AR4: =AH4/AO4 -> 0.1907014 | AS4: =AI4/AP4 -> 0.063662019
B5: Giá bán | D5: =D4+E4-F5 -> 2.8545441e+10 | E5: =IF(H5>0,H5,0) -> 0 | F5: =IF(H5<0,-H5,0) -> 3.5577563e+09 | H5: =M5 -> -3.5577563e+09 | I5: =H5*(1-13.11%) -> -3.0913344e+09 | M5: -3.5577563e+09 | O5: $/tấn | P5: 1294.1099 | Q5: 1223.9247 | R5: =Q5-P5 -> -70.185167 | S5: =R5/P5 -> -0.054234317 | U5: 25000 | V5: 26187.839 | W5: =V5-U5 -> 1187.8392 | X5: =W5/U5 -> 0.047513569
B6: Giá vốn | D6: =D5+E5-F6 -> 2.3542955e+10 | E6: =IF(H6>0,H6,0) -> 0 | F6: =IF(H6<0,-H6,0) -> 5.0024859e+09 | H6: =M6 -> -5.0024859e+09 | I6: =H6*(1-13.11%) -> -4.34666e+09 | M6: -5.0024859e+09 | O6: VND/kg | P6: 26183.033 | Q6: 28650.18 | R6: =Q6-P6 -> 2467.147 | S6: =R6/P6 -> 0.094226936
A7: rHDPE thổi | B7: Sản lượng | D7: =D6+E6-F7 -> 1.9768025e+10 | E7: =IF(H7>0,H7,0) -> 0 | F7: =IF(H7<0,-H7,0) -> 3.77493e+09 | H7: =M7 -> -3.77493e+09 | M7: {=TRANSPOSE(AA7:AC7)} -> -3.77493e+09 | O7: tấn | P7: 927 | Q7: 268.725 | R7: =Q7-P7 -> -658.275 | S7: =R7/P7 -> -0.71011327 | Z7: =SUM(AA7:AD7) -> -5.2640945e+09 | AA7: =R7*(P8*U8-P9*10^3) -> -3.77493e+09 | AB7: =R8*Q7*U8 -> -2.1972615e+09 | AC7: =-R9*Q7*10^3 -> 3.84768e+08 | AD7: =Q7*Q8*W8 -> 3.2332892e+08 | AE7: -5.2640945e+09 | AF7: =Z7-AE7 -> 0 | AH7: =P7*(P8*U8-P9*10^3) -> 5.3159547e+09 | AI7: =Q7*(Q8*U8-Q9*10^3) -> -2.7146872e+08 | AJ7: =AI7-AH7 -> -5.5874234e+09 | AK7: =AJ7/AH7 -> -1.0510668 | AM7: =Q7*(Q8*V8-Q9*10^3) -> 51860203 | AN7: =AM7-AI7-AD7 -> -5.9604645e-07 | AO7: ='S7'!AE6 -> 30984250000 | AP7: ='S7'!AF6 -> 6.7846615e+09 | AR7: =AH7/AO7 -> 0.17156958 | AS7: =AI7/AP7 -> -0.040012124
B8: Giá bán | D8: =D7+E7-F8 -> 1.7570764e+10 | E8: =IF(H8>0,H8,0) -> 0 | F8: =IF(H8<0,-H8,0) -> 2.1972615e+09 | H8: =M8 -> -2.1972615e+09 | M8: -2.1972615e+09 | O8: $/tấn | P8: 1336.9687 | Q8: 1009.904 | R8: =Q8-P8 -> -327.06469 | S8: =R8/P8 -> -0.24463152 | U8: 25000 | V8: 26191.397 | W8: =V8-U8 -> 1191.3967 | X8: =W8/U8 -> 0.047655866
B9: Giá vốn | D9: =D8+E8-F9 -> 1.7570764e+10 | E9: =IF(H9>0,H9,0) -> 3.84768e+08 | F9: =IF(H9<0,-H9,0) -> 0 | H9: =M9 -> 3.84768e+08 | M9: 3.84768e+08 | O9: VND/kg | P9: 27689.639 | Q9: 26257.811 | R9: =Q9-P9 -> -1431.8281 | S9: =R9/P9 -> -0.051709886
A10: rHDPE ép | B10: Sản lượng | D10: =D9+E9-F10 -> 1.7955532e+10 | E10: =IF(H10>0,H10,0) -> 1.6391134e+08 | F10: =IF(H10<0,-H10,0) -> 0 | H10: =M10 -> 1.6391134e+08 | M10: {=TRANSPOSE(AA10:AC10)} -> 1.6391134e+08 | O10: tấn | P10: 155.75 | Q10: 186.75 | R10: =Q10-P10 -> 31 | S10: =R10/P10 -> 0.19903692 | Z10: =SUM(AA10:AD10) -> -2.3913266e+09 | AA10: =R10*(P11*U11-P12*10^3) -> 1.6391134e+08 | AB10: =R11*Q10*U11 -> -9.226508e+08 | AC10: =-R12*Q10*10^3 -> -1.7736988e+09 | AD10: =Q10*Q11*W11 -> 1.4111161e+08 | AE10: -2.3913266e+09 | AF10: =Z10-AE10 -> 0 | AH10: =P10*(P11*U11-P12*10^3) -> 8.2352231e+08 | AI10: =Q10*(Q11*U11-Q12*10^3) -> -1.708916e+09 | AJ10: =AI10-AH10 -> -2.5324383e+09 | AK10: =AJ10/AH10 -> -3.0751301 | AM10: =Q10*(Q11*V11-Q12*10^3) -> -1.5678043e+09 | AN10: =AM10-AI10-AD10 -> 0 | AO10: ='S7'!AE8 -> 3245562500 | AP10: ='S7'!AF8 -> 2.9688985e+09 | AR10: =AH10/AO10 -> 0.25373793 | AS10: =AI10/AP10 -> -0.57560606
B11: Giá bán | D11: =D10+E10-F11 -> 1.7196792e+10 | E11: =IF(H11>0,H11,0) -> 0 | F11: =IF(H11<0,-H11,0) -> 9.226508e+08 | H11: =M11 -> -9.226508e+08 | M11: -9.226508e+08 | O11: $/tấn | P11: 833.5313 | Q11: 635.90864 | R11: =Q11-P11 -> -197.62266 | S11: =R11/P11 -> -0.23709087 | U11: 25000 | V11: 26188.249 | W11: =V11-U11 -> 1188.2489 | X11: =W11/U11 -> 0.047529955
B12: Giá vốn | D12: =D11+E11-F12 -> 1.5423093e+10 | E12: =IF(H12>0,H12,0) -> 0 | F12: =IF(H12<0,-H12,0) -> 1.7736988e+09 | H12: =M12 -> -1.7736988e+09 | M12: -1.7736988e+09 | O12: VND/kg | P12: 15550.82 | Q12: 25048.538 | R12: =Q12-P12 -> 9497.7178 | S12: =R12/P12 -> 0.61075351
A13: rPP | B13: Sản lượng | D13: =D12+E12-F13 -> 1.5423093e+10 | E13: =IF(H13>0,H13,0) -> 4.5543577e+08 | F13: =IF(H13<0,-H13,0) -> 0 | H13: =M13 -> 4.5543577e+08 | M13: {=TRANSPOSE(AA13:AC13)} -> 4.5543577e+08 | O13: tấn | P13: 107.44 | Q13: 0 | R13: =Q13-P13 -> -107.44 | S13: =R13/P13 -> -1 | Z13: =SUM(AA13:AD13) -> 4.5543577e+08 | AA13: =R13*(P14*U14-P15*10^3) -> 4.5543577e+08 | AB13: =R14*Q13*U14 -> 0 | AC13: =-R15*Q13*10^3 -> 0 | AD13: =Q13*Q14*W14 -> 0 | AE13: 4.5543577e+08 | AF13: =Z13-AE13 -> 5.364418e-07 | AH13: =P13*(P14*U14-P15*10^3) -> -4.5543577e+08 | AI13: =Q13*(Q14*U14-Q15*10^3) -> 0 | AJ13: =AI13-AH13 -> 4.5543577e+08 | AK13: =AJ13/AH13 -> -1 | AM13: =Q13*(Q14*V14-Q15*10^3) -> 0 | AN13: =AM13-AI13-AD13 -> 0 | AO13: ='S7'!AE10 -> 2.376625e+09 | AP13: ='S7'!AF10 -> 0 | AR13: =AH13/AO13 -> -0.19163131 | AS13: =AI13/AP13 -> #DIV/0!
B14: Giá bán | D14: =D13+E13-F14 -> 1.5878529e+10 | E14: =IF(H14>0,H14,0) -> 0 | F14: =IF(H14<0,-H14,0) -> 0 | H14: =M14 -> 0 | M14: 0 | O14: $/tấn | P14: 884.81943 | Q14: 0 | R14: =Q14-P14 -> -884.81943 | S14: =R14/P14 -> -1 | U14: 25000 | V14: 0 | W14: =V14-U14 -> -25000 | X14: =W14/U14 -> -1
B15: Giá vốn | D15: =D14+E14-F15 -> 1.5878529e+10 | E15: =IF(H15>0,H15,0) -> 0 | F15: =IF(H15<0,-H15,0) -> 0 | H15: =M15 -> 0 | M15: 0 | O15: VND/kg | P15: 26359.464 | Q15: 0 | R15: =Q15-P15 -> -26359.464 | S15: =R15/P15 -> -1
A16: Xơ sợi | B16: Sản lượng | D16: =D15+E15-F16 -> 1.5878529e+10 | E16: =IF(H16>0,H16,0) -> 11327184 | F16: =IF(H16<0,-H16,0) -> 0 | H16: =M16 -> 11327184 | M16: {=TRANSPOSE(AA16:AC16)} -> 11327184 | O16: tấn | P16: 100 | Q16: 27.3 | R16: =Q16-P16 -> -72.7 | S16: =R16/P16 -> -0.727 | Z16: =SUM(AA16:AD16) -> -3.2523057e+08 | AA16: =R16*(P17*U17-P18*10^3) -> 11327184 | AB16: =R17*Q16*U17 -> -3.2015983e+08 | AC16: =-R18*Q16*10^3 -> -36886578 | AD16: =Q16*Q17*W17 -> 20488657 | AE16: -3.2523057e+08 | AF16: =Z16-AE16 -> 0 | AH16: =P16*(P17*U17-P18*10^3) -> -15580720 | AI16: =Q16*(Q17*U17-Q18*10^3) -> -3.6129995e+08 | AJ16: =AI16-AH16 -> -3.4571923e+08 | AK16: =AJ16/AH16 -> 22.188912 | AM16: =Q16*(Q17*V17-Q18*10^3) -> -3.4081129e+08 | AN16: =AM16-AI16-AD16 -> 0 | AO16: ='S7'!AE12 -> 2750000000 | AP16: ='S7'!AF12 -> 4.3059017e+08 | AR16: =AH16/AO16 -> -0.0056657165 | AS16: =AI16/AP16 -> -0.83908081
B17: Giá bán | D17: =D16+E16-F17 -> 1.5569696e+10 | E17: =IF(H17>0,H17,0) -> 0 | F17: =IF(H17<0,-H17,0) -> 3.2015983e+08 | H17: =M17 -> -3.2015983e+08 | M17: -3.2015983e+08 | O17: $/tấn | P17: 1100 | Q17: 630.90134 | R17: =Q17-P17 -> -469.09866 | S17: =R17/P17 -> -0.42645332 | U17: 25000 | V17: 26189.568 | W17: =V17-U17 -> 1189.5683 | X17: =W17/U17 -> 0.047582733
B18: Giá vốn | D18: =D17+E17-F18 -> 1.553281e+10 | E18: =IF(H18>0,H18,0) -> 0 | F18: =IF(H18<0,-H18,0) -> 36886578 | H18: =M18 -> -36886578 | M18: -36886578 | O18: VND/kg | P18: 27655.807 | Q18: 29006.964 | R18: =Q18-P18 -> 1351.1567 | S18: =R18/P18 -> 0.048856166
A19: Tỷ giá | D19: =D18+E18-F19 -> 1.553281e+10 | E19: =IF(H19>0,H19,0) -> 3.4327645e+09 | F19: =IF(H19<0,-H19,0) -> 0 | H19: =M19 -> 3.4327645e+09 | M19: =AD4+AD7+AD10+AD13+AD16 -> 3.4327645e+09
A20: Khác | D20: =D19+E19-F20 -> 1.7652559e+10 | E20: =IF(H20>0,H20,0) -> 0 | F20: =IF(H20<0,-H20,0) -> 1.3130155e+09 | H20: =H22-SUM(H3:H19,H21) -> -1.3130155e+09 | AH20: =AH22-SUM(AH3:AH19) -> 1.3924777e+10 | AI20: =AI22-SUM(AI3:AI19) -> 2.3664831e+09 | AJ20: =AI20-AH20 -> -1.1558294e+10 | AK20: =AJ20/AH20 -> -0.83005236 | AO20: ='S7'!AE15 -> 18534127500 | AP20: ='S7'!AF15 -> 1.2688998e+10
A21: Cp vận chuyển, hoa hồng, chiết khấu | D21: =D20+E20-F21 -> 7.40728e+09 | E21: =IF(H21>0,H21,0) -> 0 | F21: =IF(H21<0,-H21,0) -> 1.0245279e+10 | H21: =G27-C27 -> -1.0245279e+10
A22: ='S7'!A17 -> TT T11 | G22: =D21+E21 -> 7.40728e+09 | H22: 7.40728e+09 | I22: =H22-H3 -> -4.1052693e+10 | J22: =H22/H3-1 -> -0.84714643 | U22: 25000 | V22: 26188.206 | W22: =V22-U22 -> 1188.2064 | X22: =W22/U22 -> 0.047528257 | AH22: =C3 -> 4.8459973e+10 | AI22: =G22-H19 -> 3.9745154e+09 | AJ22: =AI22-AH22 -> -4.4485458e+10 | AK22: =AJ22/AH22 -> -0.91798354 | AO22: =SUM(AO3:AO20) -> 209261952500 | AP22: =SUM(AP3:AP20) -> 8.4915116e+10
A23: Check | F23: =G22-C3 -> -4.1052693e+10 | G23: =G22-H22 -> 0 | AO23: =AO22-'S7'!AE17 -> 0 | AP23: =AP22-'S7'!AF17 -> 0
F24: =F23/C3 -> -0.84714643 | AI24: =G24 -> 0
C26: KH | G26: TT
A27: Cp vận chuyển, hoa hồng, chiết khấu | C27: ='S7'!C20 -> 12485577500 | G27: ='S7'!G20 -> 2.2402986e+09
A28: Trong đó: Pallet | C28: 0 | G28: 2.4096988e+08
A29: LG EXW | C29: =C3-C27 -> 3.5974396e+10 | G29: =G22-G27 -> 5.1669814e+09 | H29: =G29-C29 -> -3.0807414e+10
A31: Tài trợ | C31: ='S6'!B25 -> 3408550000 | G31: ='S6'!C25 -> 3395251201
A32: LG EXW không gồm tài trợ | C32: =C29-C31 -> 3.2565846e+10 | G32: =G29-G31 -> 1.7717302e+09 | H32: =G32-G23 -> 1.7717302e+09
A33: Dthu EXW không gồm tài trợ | C33: ='S6'!B29-'S6'!B28-C31 -> 1.9336782e+11 | G33: ='S6'!C29-'S6'!C28-'S6'!C25 -> 8.2712331e+10
A34: %Biên | C34: =IFERROR(C32/C33,0) -> 0.16841398 | G34: =IFERROR(G32/G33,0) -> 0.021420387
H39: =SUM(H5:H6,H8:H9,H11:H12,H14:H15,H17:H18) -> -1.3426132e+10
G40: Tổng t/đ SL | H40: =H4+H7+H10+H13+H16 -> -1.9501032e+10
G41: SL-LNST | H41: =H40*(1-13.11%) -> -1.6944446e+10
G43: Tổng t/đ LG đơn vị | H43: =H5+H6+H8+H9+H11+H12+H14+H15+H17+H18 -> -1.3426132e+10
G44: LGĐV-LNST | H44: =H43*(1-13.11%) -> -1.1665966e+10
G46: PET | H46: =SUM(H5:H6) -> -8.5602422e+09
G47: PET-LNST | H47: =H46*(1-13.11%) -> -7.4379945e+09
G49: Xơ sợi | H49: =SUM(H17:H18) -> -3.5704641e+08
...

Sheet BĐ-LG EXW-v2
C4: =C12/C7 -> 0.010874696
A5: ĐVT: VND; kg; VND/kg; USD/ton | K5: TÁC ĐỘNG
B6: KH | C6: TT | D6: +/ | F6: %Cơ cấu SL-KH | G6: %Cơ cấu SL-TT | H6: SL-TT-Cơ cấu KH | I6: DT-TT-Cơ cấu KH | K6: Sản lượng | L6: Cơ cấu ngành | M6: Giá bán | N6: Tỷ giá | O6: Khác | P6: Cp vận chuyển, hoa hồng, chiết khấu
A7: Sản lượng SPC | B7: =SUM(B8:B12) -> 5968970 | C7: =SUM(C8:C12) -> 2510415 | D7: =C7-B7 -> -3458555 | E7: =D7/B7 -> -0.57942241 | H7: =SUM(H8:H12) -> 2510415
A8: rPET | B8: ='S6'!B8 -> 4678780 | C8: ='S6'!C8 -> 2027640 | D8: =C8-B8 -> -2651140 | F8: =B8/B$7 -> 0.78385048 | G8: =C8/C$7 -> 0.80769116 | H8: =F8*C$7 -> 1967790
A9: rHDPE thổi | B9: ='S6'!B9 -> 927000 | C9: ='S6'!C9 -> 268725 | D9: =C9-B9 -> -658275 | F9: =B9/B$7 -> 0.15530318 | G9: =C9/C$7 -> 0.10704405 | H9: =F9*C$7 -> 389875.42
A10: rHDPE ép | B10: ='S6'!B10 -> 155750 | C10: ='S6'!C10 -> 186750 | D10: =C10-B10 -> 31000 | F10: =B10/B$7 -> 0.026093279 | G10: =C10/C$7 -> 0.074390091 | H10: =F10*C$7 -> 65504.959
A11: rPP | B11: ='S6'!B11 -> 107440 | C11: ='S6'!C11 -> 0 | D11: =C11-B11 -> -107440 | F11: =B11/B$7 -> 0.017999755 | G11: =C11/C$7 -> 0 | H11: =F11*C$7 -> 45186.856
A12: Xơ sợi | B12: ='S6'!B12 -> 100000 | C12: ='S6'!C12 -> 27300 | D12: =C12-B12 -> -72700 | F12: =B12/B$7 -> 0.016753309 | G12: =C12/C$7 -> 0.010874696 | H12: =F12*C$7 -> 42057.759
A13: GB EXW (VND/kg) | B13: 30553.285 | C13: 28801.443 | D13: =C13-B13 -> -1751.8418 | I13: =SUM(I14:I18) -> 8.0215848e+10
A14: rPET | B14: ='S6'!B14 -> 32352.747 | C14: ='S6'!C14 -> 32051.944 | I14: =H8*B14 -> 6.3663413e+10
A15: rHDPE thổi | B15: ='S6'!B15 -> 33424.218 | C15: ='S6'!C15 -> 26450.797 | I15: =H9*B15 -> 1.3031281e+10
A16: rHDPE ép | B16: ='S6'!B16 -> 20838.283 | C16: ='S6'!C16 -> 16653.334 | I16: =H10*B16 -> 1.3650108e+09
A17: rPP | B17: ='S6'!B17 -> 22120.486 | C17: ='S6'!C17 -> 0 | I17: =H11*B17 -> 9.9955521e+08
A18: Xơ sợi | B18: ='S6'!B18 -> 27500 | C18: ='S6'!C18 -> 16523.034 | I18: =H12*B18 -> 1.1565884e+09
A19: Doanh thu SPC | B19: =SUM(B20:B24) -> 1.9072782e+11 | C19: =SUM(C20:C24) -> 7.5658883e+10 | D19: =C19-B19 -> -1.1506894e+11
A20: rPET | B20: =B8*B14 -> 1.5137139e+11 | C20: =C8*C14 -> 6.4989804e+10 | D20: =C20-B20 -> -8.6381584e+10 | K20: =I14-B20 -> -8.7707975e+10 | L20: =C8*B14-I14 -> 1.9363118e+09 | M20: =D63*C8/10^3*$B$69 -> -3.5577563e+09 | N20: =IFERROR(C20-C20/C70*B70,0) -> 2.9478354e+09
A21: rHDPE thổi | B21: =B9*B15 -> 3.098425e+10 | C21: =C9*C15 -> 7107990427 | D21: =C21-B21 -> -2.387626e+10 | K21: =I15-B21 -> -1.7952969e+10 | L21: =C9*B15-I15 -> -4.0493581e+09 | M21: =D64*C9/10^3*$B$69 -> -2.1972615e+09 | N21: =IFERROR(C21-C21/C71*B71,0) -> 3.2332892e+08
A22: rHDPE ép | B22: =B10*B16 -> 3.2455625e+09 | C22: =C10*C16 -> 3.1100101e+09 | D22: =C22-B22 -> -1.3555243e+08 | K22: =I16-B22 -> -1.8805517e+09 | L22: =C10*B16-I16 -> 2.5265384e+09 | M22: =D65*C10/10^3*$B$69 -> -9.226508e+08 | N22: =IFERROR(C22-C22/C72*B72,0) -> 1.4111161e+08
A23: rPP | B23: =B11*B17 -> 2.376625e+09 | C23: =C11*C17 -> 0 | D23: =C23-B23 -> -2.376625e+09 | K23: =I17-B23 -> -1.3770698e+09 | L23: =C11*B17-I17 -> -9.9955521e+08 | M23: =D66*C11/10^3*$B$69 -> 0 | N23: =IFERROR(C23-C23/C73*B73,0) -> 0
A24: Xơ sợi | B24: =B12*B18 -> 2.75e+09 | C24: =C12*C18 -> 4.5107882e+08 | D24: =C24-B24 -> -2.2989212e+09 | K24: =I18-B24 -> -1.5934116e+09 | L24: =C12*B18-I18 -> -4.0583836e+08 | M24: =D67*C12/10^3*$B$69 -> -3.2015983e+08 | N24: =IFERROR(C24-C24/C74*B74,0) -> 20488657
A25: Tài trợ | B25: ='S6'!B25 -> 3408550000 | C25: ='S6'!C25 -> 3395251201 | D25: =C25-B25 -> -13298799 | O25: =D25 -> -13298799 | Q25: =SUM(K25:P25) -> -13298799
A26: Dây đai, phó sản | B26: ='S6'!B26 -> 2640000000 | C26: ='S6'!C26 -> 6989889073 | D26: =C26-B26 -> 4349889073 | O26: =D26 -> 4349889073 | Q26: =SUM(K26:P26) -> 4349889073
A27: Khác | B27: ='S6'!B27 -> 0 | C27: ='S6'!C27 -> 63558813 | D27: =C27-B27 -> 63558813 | O27: =D27 -> 63558813 | Q27: =SUM(K27:P27) -> 63558813
A28: Cp vận chuyển, hoa hồng, chiết khấu | B28: ='S8'!C27 -> 12485577500 | C28: ='S8'!G27 -> 2.2402986e+09 | D28: =C28-B28 -> -1.0245279e+10 | P28: =D28 -> -1.0245279e+10 | Q28: =SUM(K28:P28) -> -1.0245279e+10
A29: Tổng dthu thuần | B29: =B19+B25+B26+B27+B28 -> 2.0926195e+11 | C29: =C19+C25+C26+C27+C28 -> 88347880802 | D29: =C29-B29 -> -1.2091407e+11 | K29: =SUM(K7:K28) -> -1.1051198e+11 | L29: =SUM(L7:L28) -> -9.9190147e+08 | M29: =SUM(M7:M28) -> -6.9978284e+09 | N29: =SUM(N7:N28) -> 3.4327645e+09 | O29: =SUM(O7:O28) -> 4.4001491e+09 | P29: =SUM(P7:P28) -> -1.0245279e+10 | Q29: =SUM(K29:P29) -> -1.2091407e+11
P30: Check | Q30: =Q29-D29 -> 0
A31: GVĐV (đ/kg)
A32: rPET | B32: 26183.033 | C32: 28650.18 | D32: =C32-B32 -> 2467.147
A33: rHDPE thổi | B33: 27689.639 | C33: 26257.811 | D33: =C33-B33 -> -1431.8281
A34: rHDPE ép | B34: 15550.82 | C34: 25048.538 | D34: =C34-B34 -> 9497.7178
A35: rPP | B35: 26359.464 | C35: 0 | D35: =C35-B35 -> -26359.464
A36: Xơ sợi | B36: 27655.807 | C36: 29006.964 | D36: =C36-B36 -> 1351.1567
A38: GVHB-SPC | B38: =SUM(B39:B43) -> 1.5619263e+11 | C38: =SUM(C39:C43) -> 7.0618086e+10
A39: rPET | B39: =B32*B8 -> 1.2250465e+11 | C39: =C32*C8 -> 5.8092252e+10
A40: rHDPE thổi | B40: =B33*B9 -> 2.5668295e+10 | C40: =C33*C9 -> 7.0561302e+09
A41: rHDPE ép | B41: =B34*B10 -> 2.4220402e+09 | C41: =C34*C10 -> 4677814409
A42: rPP | B42: =B35*B11 -> 2.8320608e+09 | C42: =C35*C11 -> 0
A43: Xơ sợi | B43: =B36*B12 -> 2.7655807e+09 | C43: =C36*C12 -> 791890115
A44: Tài trợ
...

Sheet S10
A1: -1
A2: CHỈ TIÊU | B2: KH | C2: TT | D2: +/- | E2: %+/-
A3: LG EXW | B3: ='S8'!C3-('S8'!C27-'S8'!C28) -> 3.5974396e+10 | C3: ='S8'!G22-('S8'!G27-'S8'!G28) -> 5.4079513e+09 | D3: =C3-B3 -> -3.0566444e+10 | E3: =IFERROR(D3/B3,0) -> -0.84967221
A4: CPBH | B4: -1.7088592e+09 | C4: -1414420938 | D4: =C4-B4 -> 2.9443822e+08 | E4: =IFERROR(D4/B4,0) -> -0.17230105
A5: CPQLDN | B5: -7.7451752e+09 | C5: -9875644458 | D5: =C5-B5 -> -2.1304693e+09 | E5: =IFERROR(D5/B5,0) -> 0.27507051
A6: Cp lãi vay | B6: -4874877877 | C6: -1256132292 | D6: =C6-B6 -> 3618745585 | E6: =IFERROR(D6/B6,0) -> -0.74232538
A7: Dthu/Cp tài chính-Tỷ giá | C7: 130246672 | D7: =C7-B7 -> 130246672 | E7: =IFERROR(D7/B7,0) -> 0
A8: Lãi tiền gửi | B8: 326826000 | C8: 339620636 | D8: =C8-B8 -> 12794636 | E8: =IFERROR(D8/B8,0) -> 0.039148158
A9: Thu nhập/Chi phí khác | C9: -1106151805 | D9: =C9-B9 -> -1106151805 | E9: =IFERROR(D9/B9,0) -> 0
A10: Thuế TNDN | B10: -3.0761233e+09 | C10: 8.54241e+08 | D10: =C10-B10 -> 3.9303643e+09 | E10: =IFERROR(D10/B10,0) -> -1.2777005
A11: LNST | B11: =SUM(B3:B10) -> 1.8896186e+10 | C11: =SUM(C3:C10) -> -6.9202899e+09 | D11: =C11-B11 -> -2.5816476e+10 | E11: =IFERROR(D11/B11,0) -> -1.3662268
B14: Start | C14: Hidden | D14: Increase | E14: Decrease | F14: End | I14: Increase | J14: Decrease
A15: ='S7'!A3 -> KH T11 | B15: =B11 -> 1.8896186e+10
A16: LG EXW | D16: =B15 -> 1.8896186e+10 | E16: =H16 -> -1.1670258e+10 | G16: =D3 -> -3.0566444e+10 | H16: =B15+G16 -> -1.1670258e+10 | J16: =ABS($G16) -> 3.0566444e+10
A17: CPBH | C17: =E16+G17 -> -1.137582e+10 | D17: =-G17 -> -2.9443822e+08 | G17: =D4 -> 2.9443822e+08 | H17: =H16+G17 -> -1.137582e+10 | I17: =ABS($G17) -> 2.9443822e+08
A18: CPQLDN | C18: =C17 -> -1.137582e+10 | E18: =G18 -> -2.1304693e+09 | G18: =D5 -> -2.1304693e+09 | H18: =H17+G18 -> -1.3506289e+10 | J18: =ABS($G18) -> 2.1304693e+09
A19: Cp lãi vay | C19: =C18+G18+G19 -> -9.8875437e+09 | D19: =-G19 -> -3618745585 | G19: =D6 -> 3618745585 | H19: =H18+G19 -> -9.8875437e+09 | I19: =ABS($G19) -> 3618745585
A20: Dthu/Cp tài chính-Tỷ giá | C20: =C19+G20 -> -9.7572971e+09 | D20: =-G20 -> -130246672 | G20: =D7 -> 130246672 | H20: =H19+G20 -> -9.7572971e+09 | I20: =ABS($G20) -> 130246672
A21: Lãi tiền gửi | C21: =C20+G21 -> -9.7445024e+09 | D21: =-G21 -> -12794636 | G21: =D8 -> 12794636 | H21: =H20+G21 -> -9.7445024e+09 | I21: =ABS($G21) -> 12794636
A22: Thu nhập khác | C22: =C21 -> -9.7445024e+09 | E22: =G22 -> -1106151805 | G22: =D9 -> -1106151805 | H22: =H21+G22 -> -1.0850654e+10 | J22: =ABS($G22) -> 1106151805
A23: Thuế TNDN | C23: =C22+G22+G23 -> -6.9202899e+09 | D23: =-G23 -> -3.9303643e+09 | G23: =D10 -> 3.9303643e+09 | H23: =H22+G23 -> -6.9202899e+09 | I23: =ABS($G23) -> 3.9303643e+09
A24: ='S7'!A17 -> TT T11 | F24: =C23 -> -6.9202899e+09
F25: =F24-C11 -> 0
A27: Dthu | B27: ='S7'!C3 -> 209261952500 | C27: ='S7'!G17 -> 88347880802
B28: =B11/B27 -> 0.090299196 | C28: =C11/C27 -> -0.078330005
B58: Tổng t/đ SL | C58: -2.2184183e+10
B59: SL-LNST | C59: -1.9275837e+10
B61: Tổng t/đ LG đơn vị | C61: -1.4265745e+10
B62: LGĐV-LNST | C62: -1.2395506e+10

Sheet BĐ-LG EXW-v2 (PDM)
C4: =C12/C7 -> 0.010874696
A5: ĐVT: VND; kg; VND/kg; USD/ton | K5: TÁC ĐỘNG
B6: KH | C6: TT | D6: +/ | F6: %Cơ cấu SL-KH | G6: %Cơ cấu SL-TT | H6: SL-TT-Cơ cấu KH | I6: DT-TT-Cơ cấu KH | K6: Sản lượng | L6: Cơ cấu ngành | M6: Giá bán | N6: Tỷ giá | O6: Khác | P6: Cp vận chuyển, hoa hồng, chiết khấu
A7: Sản lượng SPC | B7: =SUM(B8:B12) -> 5968970 | C7: =SUM(C8:C12) -> 2510415 | D7: =C7-B7 -> -3458555 | E7: =D7/B7 -> -0.57942241 | H7: =SUM(H8:H12) -> 2510415
A8: rPET | B8: ='S6'!B8 -> 4678780 | C8: ='S6'!C8 -> 2027640 | D8: =C8-B8 -> -2651140 | F8: =B8/B$7 -> 0.78385048 | G8: =C8/C$7 -> 0.80769116 | H8: =F8*C$7 -> 1967790
A9: rHDPE thổi | B9: ='S6'!B9 -> 927000 | C9: ='S6'!C9 -> 268725 | D9: =C9-B9 -> -658275 | F9: =B9/B$7 -> 0.15530318 | G9: =C9/C$7 -> 0.10704405 | H9: =F9*C$7 -> 389875.42
A10: rHDPE ép | B10: ='S6'!B10 -> 155750 | C10: ='S6'!C10 -> 186750 | D10: =C10-B10 -> 31000 | F10: =B10/B$7 -> 0.026093279 | G10: =C10/C$7 -> 0.074390091 | H10: =F10*C$7 -> 65504.959
A11: rPP | B11: ='S6'!B11 -> 107440 | C11: ='S6'!C11 -> 0 | D11: =C11-B11 -> -107440 | F11: =B11/B$7 -> 0.017999755 | G11: =C11/C$7 -> 0 | H11: =F11*C$7 -> 45186.856
A12: Xơ sợi | B12: ='S6'!B12 -> 100000 | C12: ='S6'!C12 -> 27300 | D12: =C12-B12 -> -72700 | F12: =B12/B$7 -> 0.016753309 | G12: =C12/C$7 -> 0.010874696 | H12: =F12*C$7 -> 42057.759
A13: GB EXW (VND/kg) | B13: 30553.285 | C13: 28801.443 | D13: =C13-B13 -> -1751.8418 | I13: =SUM(I14:I18) -> 8.0215848e+10
A14: rPET | B14: ='S6'!B14 -> 32352.747 | C14: ='S6'!C14 -> 32051.944 | I14: =H8*B14 -> 6.3663413e+10
A15: rHDPE thổi | B15: ='S6'!B15 -> 33424.218 | C15: ='S6'!C15 -> 26450.797 | I15: =H9*B15 -> 1.3031281e+10
A16: rHDPE ép | B16: ='S6'!B16 -> 20838.283 | C16: ='S6'!C16 -> 16653.334 | I16: =H10*B16 -> 1.3650108e+09
A17: rPP | B17: ='S6'!B17 -> 22120.486 | C17: ='S6'!C17 -> 0 | I17: =H11*B17 -> 9.9955521e+08
A18: Xơ sợi | B18: ='S6'!B18 -> 27500 | C18: ='S6'!C18 -> 16523.034 | I18: =H12*B18 -> 1.1565884e+09
A19: Doanh thu SPC | B19: =SUM(B20:B24) -> 1.9072782e+11 | C19: =SUM(C20:C24) -> 7.5658883e+10 | D19: =C19-B19 -> -1.1506894e+11
A20: rPET | B20: =B8*B14 -> 1.5137139e+11 | C20: =C8*C14 -> 6.4989804e+10 | D20: =C20-B20 -> -8.6381584e+10 | K20: =I14-B20 -> -8.7707975e+10 | L20: =C8*B14-I14 -> 1.9363118e+09 | M20: =D63*C8/10^3*$B$69 -> -3.5577563e+09 | N20: =IFERROR(C20-C20/C70*B70,0) -> 2.9478354e+09
A21: rHDPE thổi | B21: =B9*B15 -> 3.098425e+10 | C21: =C9*C15 -> 7107990427 | D21: =C21-B21 -> -2.387626e+10 | K21: =I15-B21 -> -1.7952969e+10 | L21: =C9*B15-I15 -> -4.0493581e+09 | M21: =D64*C9/10^3*$B$69 -> -2.1972615e+09 | N21: =IFERROR(C21-C21/C71*B71,0) -> 3.2332892e+08
A22: rHDPE ép | B22: =B10*B16 -> 3.2455625e+09 | C22: =C10*C16 -> 3.1100101e+09 | D22: =C22-B22 -> -1.3555243e+08 | K22: =I16-B22 -> -1.8805517e+09 | L22: =C10*B16-I16 -> 2.5265384e+09 | M22: =D65*C10/10^3*$B$69 -> -9.226508e+08 | N22: =IFERROR(C22-C22/C72*B72,0) -> 1.4111161e+08
A23: rPP | B23: =B11*B17 -> 2.376625e+09 | C23: =C11*C17 -> 0 | D23: =C23-B23 -> -2.376625e+09 | K23: =I17-B23 -> -1.3770698e+09 | L23: =C11*B17-I17 -> -9.9955521e+08 | M23: =D66*C11/10^3*$B$69 -> 0 | N23: =IFERROR(C23-C23/C73*B73,0) -> 0
A24: Xơ sợi | B24: =B12*B18 -> 2.75e+09 | C24: =C12*C18 -> 4.5107882e+08 | D24: =C24-B24 -> -2.2989212e+09 | K24: =I18-B24 -> -1.5934116e+09 | L24: =C12*B18-I18 -> -4.0583836e+08 | M24: =D67*C12/10^3*$B$69 -> -3.2015983e+08 | N24: =IFERROR(C24-C24/C74*B74,0) -> 20488657
A25: Tài trợ | B25: ='S6'!B25 -> 3408550000 | C25: ='S6'!C25 -> 3395251201 | D25: =C25-B25 -> -13298799 | O25: =D25 -> -13298799 | Q25: =SUM(K25:P25) -> -13298799
A26: Dây đai, phó sản | B26: ='S6'!B26 -> 2640000000 | C26: ='S6'!C26 -> 6989889073 | D26: =C26-B26 -> 4349889073 | O26: =D26 -> 4349889073 | Q26: =SUM(K26:P26) -> 4349889073
A27: Khác | B27: ='S6'!B27 -> 0 | C27: ='S6'!C27 -> 63558813 | D27: =C27-B27 -> 63558813 | O27: =D27 -> 63558813 | Q27: =SUM(K27:P27) -> 63558813
A28: Cp vận chuyển, hoa hồng, chiết khấu | B28: ='S8'!C27 -> 12485577500 | C28: ='S8'!G27 -> 2.2402986e+09 | D28: =C28-B28 -> -1.0245279e+10 | P28: =D28 -> -1.0245279e+10 | Q28: =SUM(K28:P28) -> -1.0245279e+10
A29: Tổng dthu thuần | B29: =B19+B25+B26+B27+B28 -> 2.0926195e+11 | C29: =C19+C25+C26+C27+C28 -> 88347880802 | D29: =C29-B29 -> -1.2091407e+11 | K29: =SUM(K7:K28) -> -1.1051198e+11 | L29: =SUM(L7:L28) -> -9.9190147e+08 | M29: =SUM(M7:M28) -> -6.9978284e+09 | N29: =SUM(N7:N28) -> 3.4327645e+09 | O29: =SUM(O7:O28) -> 4.4001491e+09 | P29: =SUM(P7:P28) -> -1.0245279e+10 | Q29: =SUM(K29:P29) -> -1.2091407e+11
P30: Check | Q30: =Q29-D29 -> 0
A31: GVĐV (đ/kg)
A32: rPET | B32: 26183.033 | C32: 28650.18 | D32: =C32-B32 -> 2467.147
A33: rHDPE thổi | B33: 27689.639 | C33: 26257.811 | D33: =C33-B33 -> -1431.8281
A34: rHDPE ép | B34: 15550.82 | C34: 25048.538 | D34: =C34-B34 -> 9497.7178
A35: rPP | B35: 26359.464 | C35: 0 | D35: =C35-B35 -> -26359.464
A36: Xơ sợi | B36: 27655.807 | C36: 29006.964 | D36: =C36-B36 -> 1351.1567
A38: GVHB-SPC | B38: =SUM(B39:B43) -> 1.5619263e+11 | C38: =SUM(C39:C43) -> 7.0618086e+10
A39: rPET | B39: =B32*B8 -> 1.2250465e+11 | C39: =C32*C8 -> 5.8092252e+10
A40: rHDPE thổi | B40: =B33*B9 -> 2.5668295e+10 | C40: =C33*C9 -> 7.0561302e+09
A41: rHDPE ép | B41: =B34*B10 -> 2.4220402e+09 | C41: =C34*C10 -> 4677814409
A42: rPP | B42: =B35*B11 -> 2.8320608e+09 | C42: =C35*C11 -> 0
A43: Xơ sợi | B43: =B36*B12 -> 2.7655807e+09 | C43: =C36*C12 -> 791890115
A44: Tài trợ
...

Sheet Sheet3
C3: Sản lượng | F3: Giá | I3: Doanh thu | L3: GVHB (ĐV) | O3: GVHB | R3: LNG
C4: KH | D4: TT | E4: +/ | F4: KH | G4: TT | H4: +/ | I4: KH | J4: TT | K4: +/ | L4: KH | M4: TT | N4: +/ | O4: KH | P4: TT | Q4: +/ | R4: KH | S4: TT | T4: +/
B5: Cộng | C5: =SUM(C6:C10) -> 5968970 | D5: =SUM(D6:D10) -> 2510415 | I5: =SUM(I6:I14) -> 2.0926195e+11 | J5: =SUM(J6:J14) -> 88347880802 | O5: =SUM(O6:O14) -> 1.6080198e+11 | P5: =SUM(P6:P14) -> 8.0940601e+10 | R5: =SUM(R6:R14) -> 3.5974396e+10 | S5: =SUM(S6:S14) -> 5.1669814e+09
B6: ='BĐ-LG EXW-v2 (PDM)'!A8 -> rPET | C6: ='BĐ-LG EXW-v2 (PDM)'!B8 -> 4678780 | D6: ='BĐ-LG EXW-v2 (PDM)'!C8 -> 2027640 | F6: ='BĐ-LG EXW-v2 (PDM)'!B14 -> 32352.747 | G6: ='BĐ-LG EXW-v2 (PDM)'!C14 -> 32051.944 | I6: ='BĐ-LG EXW-v2 (PDM)'!B20 -> 1.5137139e+11 | J6: ='BĐ-LG EXW-v2 (PDM)'!C20 -> 6.4989804e+10 | L6: ='BĐ-LG EXW-v2 (PDM)'!B32 -> 26183.033 | M6: ='BĐ-LG EXW-v2 (PDM)'!C32 -> 28650.18 | O6: ='BĐ-LG EXW-v2 (PDM)'!B39 -> 1.2250465e+11 | P6: ='BĐ-LG EXW-v2 (PDM)'!C39 -> 5.8092252e+10 | R6: =I6-O6 -> 2.8866735e+10 | S6: =J6-P6 -> 6.8975523e+09
B7: ='BĐ-LG EXW-v2 (PDM)'!A9 -> rHDPE thổi | C7: ='BĐ-LG EXW-v2 (PDM)'!B9 -> 927000 | D7: ='BĐ-LG EXW-v2 (PDM)'!C9 -> 268725 | F7: ='BĐ-LG EXW-v2 (PDM)'!B15 -> 33424.218 | G7: ='BĐ-LG EXW-v2 (PDM)'!C15 -> 26450.797 | I7: ='BĐ-LG EXW-v2 (PDM)'!B21 -> 3.098425e+10 | J7: ='BĐ-LG EXW-v2 (PDM)'!C21 -> 7107990427 | L7: ='BĐ-LG EXW-v2 (PDM)'!B33 -> 27689.639 | M7: ='BĐ-LG EXW-v2 (PDM)'!C33 -> 26257.811 | O7: ='BĐ-LG EXW-v2 (PDM)'!B40 -> 2.5668295e+10 | P7: ='BĐ-LG EXW-v2 (PDM)'!C40 -> 7.0561302e+09 | R7: =I7-O7 -> 5.3159547e+09 | S7: =J7-P7 -> 51860203
B8: ='BĐ-LG EXW-v2 (PDM)'!A10 -> rHDPE ép | C8: ='BĐ-LG EXW-v2 (PDM)'!B10 -> 155750 | D8: ='BĐ-LG EXW-v2 (PDM)'!C10 -> 186750 | F8: ='BĐ-LG EXW-v2 (PDM)'!B16 -> 20838.283 | G8: ='BĐ-LG EXW-v2 (PDM)'!C16 -> 16653.334 | I8: ='BĐ-LG EXW-v2 (PDM)'!B22 -> 3.2455625e+09 | J8: ='BĐ-LG EXW-v2 (PDM)'!C22 -> 3.1100101e+09 | L8: ='BĐ-LG EXW-v2 (PDM)'!B34 -> 15550.82 | M8: ='BĐ-LG EXW-v2 (PDM)'!C34 -> 25048.538 | O8: ='BĐ-LG EXW-v2 (PDM)'!B41 -> 2.4220402e+09 | P8: ='BĐ-LG EXW-v2 (PDM)'!C41 -> 4677814409 | R8: =I8-O8 -> 8.2352231e+08 | S8: =J8-P8 -> -1.5678043e+09
B9: ='BĐ-LG EXW-v2 (PDM)'!A11 -> rPP | C9: ='BĐ-LG EXW-v2 (PDM)'!B11 -> 107440 | D9: ='BĐ-LG EXW-v2 (PDM)'!C11 -> 0 | F9: ='BĐ-LG EXW-v2 (PDM)'!B17 -> 22120.486 | G9: ='BĐ-LG EXW-v2 (PDM)'!C17 -> 0 | I9: ='BĐ-LG EXW-v2 (PDM)'!B23 -> 2.376625e+09 | J9: ='BĐ-LG EXW-v2 (PDM)'!C23 -> 0 | L9: ='BĐ-LG EXW-v2 (PDM)'!B35 -> 26359.464 | M9: ='BĐ-LG EXW-v2 (PDM)'!C35 -> 0 | O9: ='BĐ-LG EXW-v2 (PDM)'!B42 -> 2.8320608e+09 | P9: ='BĐ-LG EXW-v2 (PDM)'!C42 -> 0 | R9: =I9-O9 -> -4.5543577e+08 | S9: =J9-P9 -> 0
B10: ='BĐ-LG EXW-v2 (PDM)'!A12 -> Xơ sợi | C10: ='BĐ-LG EXW-v2 (PDM)'!B12 -> 100000 | D10: ='BĐ-LG EXW-v2 (PDM)'!C12 -> 27300 | F10: ='BĐ-LG EXW-v2 (PDM)'!B18 -> 27500 | G10: ='BĐ-LG EXW-v2 (PDM)'!C18 -> 16523.034 | I10: ='BĐ-LG EXW-v2 (PDM)'!B24 -> 2.75e+09 | J10: ='BĐ-LG EXW-v2 (PDM)'!C24 -> 4.5107882e+08 | L10: ='BĐ-LG EXW-v2 (PDM)'!B36 -> 27655.807 | M10: ='BĐ-LG EXW-v2 (PDM)'!C36 -> 29006.964 | O10: ='BĐ-LG EXW-v2 (PDM)'!B43 -> 2.7655807e+09 | P10: ='BĐ-LG EXW-v2 (PDM)'!C43 -> 791890115 | R10: =I10-O10 -> -15580720 | S10: =J10-P10 -> -3.4081129e+08
B11: ='BĐ-LG EXW-v2 (PDM)'!A25 -> Tài trợ | I11: ='BĐ-LG EXW-v2 (PDM)'!B25 -> 3408550000 | J11: ='BĐ-LG EXW-v2 (PDM)'!C25 -> 3395251201 | O11: ='BĐ-LG EXW-v2 (PDM)'!B44 -> 0 | P11: ='BĐ-LG EXW-v2 (PDM)'!C44 -> 0 | R11: =I11-O11 -> 3408550000 | S11: =J11-P11 -> 3395251201
B12: ='BĐ-LG EXW-v2 (PDM)'!A26 -> Dây đai, phó sản | I12: ='BĐ-LG EXW-v2 (PDM)'!B26 -> 2640000000 | J12: ='BĐ-LG EXW-v2 (PDM)'!C26 -> 6989889073 | O12: ='BĐ-LG EXW-v2 (PDM)'!B45 -> 2359350000 | P12: ='BĐ-LG EXW-v2 (PDM)'!C45 -> 6217736669 | R12: =I12-O12 -> 280650000 | S12: =J12-P12 -> 772152404
B13: ='BĐ-LG EXW-v2 (PDM)'!A27 -> Khác | I13: ='BĐ-LG EXW-v2 (PDM)'!B27 -> 0 | J13: ='BĐ-LG EXW-v2 (PDM)'!C27 -> 63558813 | O13: ='BĐ-LG EXW-v2 (PDM)'!B46 -> 2250000000 | P13: ='BĐ-LG EXW-v2 (PDM)'!C46 -> 4.1047779e+09 | R13: =I13-O13 -> -2250000000 | S13: =J13-P13 -> -4.0412191e+09
B14: ='BĐ-LG EXW-v2 (PDM)'!A28 -> Cp vận chuyển, hoa hồng, chiết khấu | I14: ='BĐ-LG EXW-v2 (PDM)'!B28 -> 12485577500 | J14: ='BĐ-LG EXW-v2 (PDM)'!C28 -> 2.2402986e+09

Sheet Sheet3 (2)
B3: Nhóm SP | C3: Sản lượng | H3: Giá | K3: Doanh thu | P3: GVHB (ĐV) | S3: GVHB | X3: LNG
C4: KH | E4: TT | G4: +/ | H4: KH | I4: TT | J4: +/ | K4: KH | M4: TT | O4: +/ | P4: KH | Q4: TT | R4: +/ | S4: KH | U4: TT | W4: +/ | X4: KH | Z4: TT | AB4: +/
C5: GT | D5: % | E5: GT | F5: % | K5: GT | L5: % | M5: GT | N5: % | S5: GT | T5: % | U5: GT | V5: % | X5: GT | Y5: % | Z5: GT | AA5: %
B6: Cộng | C6: =SUM(C7:C11) -> 5968970 | D6: =C6/$C$6 -> 1 | E6: =SUM(E7:E11) -> 2510415 | F6: =E6/$E$6 -> 1 | K6: =SUM(K7:K15) -> 2.0926195e+11 | L6: =K6/$K$6 -> 1 | M6: =SUM(M7:M15) -> 88347880802 | N6: =M6/M$6 -> 1 | S6: =SUM(S7:S15) -> 1.6080198e+11 | T6: =S6/S$6 -> 1 | U6: =SUM(U7:U15) -> 8.0940601e+10 | V6: =U6/U$6 -> 1 | X6: =SUM(X7:X15) -> 3.5974396e+10 | Y6: =X6/X$6 -> 1 | Z6: =SUM(Z7:Z15) -> 5.1669814e+09 | AA6: =Z6/Z$6 -> 1
B7: ='BĐ-LG EXW-v2 (PDM)'!A8 -> rPET | C7: ='BĐ-LG EXW-v2 (PDM)'!B8 -> 4678780 | D7: =C7/$C$6 -> 0.78385048 | E7: ='BĐ-LG EXW-v2 (PDM)'!C8 -> 2027640 | F7: =E7/$E$6 -> 0.80769116 | H7: ='BĐ-LG EXW-v2 (PDM)'!B14 -> 32352.747 | I7: ='BĐ-LG EXW-v2 (PDM)'!C14 -> 32051.944 | J7: =I7-H7 -> -300.80336 | K7: ='BĐ-LG EXW-v2 (PDM)'!B20 -> 1.5137139e+11 | L7: =K7/$K$6 -> 0.72335838 | M7: ='BĐ-LG EXW-v2 (PDM)'!C20 -> 6.4989804e+10 | N7: =M7/M$6 -> 0.73561248 | P7: ='BĐ-LG EXW-v2 (PDM)'!B32 -> 26183.033 | Q7: ='BĐ-LG EXW-v2 (PDM)'!C32 -> 28650.18 | R7: =Q7-P7 -> 2467.147 | S7: ='BĐ-LG EXW-v2 (PDM)'!B39 -> 1.2250465e+11 | T7: =S7/S$6 -> 0.76183548 | U7: ='BĐ-LG EXW-v2 (PDM)'!C39 -> 5.8092252e+10 | V7: =U7/U$6 -> 0.71771461 | X7: =K7-S7 -> 2.8866735e+10 | Y7: =X7/X$6 -> 0.80242446 | Z7: =M7-U7 -> 6.8975523e+09 | AA7: =Z7/Z$6 -> 1.3349288
B8: ='BĐ-LG EXW-v2 (PDM)'!A9 -> rHDPE thổi | C8: ='BĐ-LG EXW-v2 (PDM)'!B9 -> 927000 | D8: =C8/$C$6 -> 0.15530318 | E8: ='BĐ-LG EXW-v2 (PDM)'!C9 -> 268725 | F8: =E8/$E$6 -> 0.10704405 | H8: ='BĐ-LG EXW-v2 (PDM)'!B15 -> 33424.218 | I8: ='BĐ-LG EXW-v2 (PDM)'!C15 -> 26450.797 | J8: =I8-H8 -> -6973.4209 | K8: ='BĐ-LG EXW-v2 (PDM)'!B21 -> 3.098425e+10 | L8: =K8/$K$6 -> 0.14806442 | M8: ='BĐ-LG EXW-v2 (PDM)'!C21 -> 7107990427 | N8: =M8/M$6 -> 0.080454566 | P8: ='BĐ-LG EXW-v2 (PDM)'!B33 -> 27689.639 | Q8: ='BĐ-LG EXW-v2 (PDM)'!C33 -> 26257.811 | R8: =Q8-P8 -> -1431.8281 | S8: ='BĐ-LG EXW-v2 (PDM)'!B40 -> 2.5668295e+10 | T8: =S8/S$6 -> 0.15962674 | U8: ='BĐ-LG EXW-v2 (PDM)'!C40 -> 7.0561302e+09 | V8: =U8/U$6 -> 0.087176647 | X8: =K8-S8 -> 5.3159547e+09 | Y8: =X8/X$6 -> 0.14777051 | Z8: =M8-U8 -> 51860203 | AA8: =Z8/Z$6 -> 0.010036847
B9: ='BĐ-LG EXW-v2 (PDM)'!A10 -> rHDPE ép | C9: ='BĐ-LG EXW-v2 (PDM)'!B10 -> 155750 | D9: =C9/$C$6 -> 0.026093279 | E9: ='BĐ-LG EXW-v2 (PDM)'!C10 -> 186750 | F9: =E9/$E$6 -> 0.074390091 | H9: ='BĐ-LG EXW-v2 (PDM)'!B16 -> 20838.283 | I9: ='BĐ-LG EXW-v2 (PDM)'!C16 -> 16653.334 | J9: =I9-H9 -> -4184.9488 | K9: ='BĐ-LG EXW-v2 (PDM)'!B22 -> 3.2455625e+09 | L9: =K9/$K$6 -> 0.015509568 | M9: ='BĐ-LG EXW-v2 (PDM)'!C22 -> 3.1100101e+09 | N9: =M9/M$6 -> 0.035201864 | P9: ='BĐ-LG EXW-v2 (PDM)'!B34 -> 15550.82 | Q9: ='BĐ-LG EXW-v2 (PDM)'!C34 -> 25048.538 | R9: =Q9-P9 -> 9497.7178 | S9: ='BĐ-LG EXW-v2 (PDM)'!B41 -> 2.4220402e+09 | T9: =S9/S$6 -> 0.015062254 | U9: ='BĐ-LG EXW-v2 (PDM)'!C41 -> 4677814409 | V9: =U9/U$6 -> 0.057793176 | X9: =K9-S9 -> 8.2352231e+08 | Y9: =X9/X$6 -> 0.022891901 | Z9: =M9-U9 -> -1.5678043e+09 | AA9: =Z9/Z$6 -> -0.30342752
B10: ='BĐ-LG EXW-v2 (PDM)'!A11 -> rPP | C10: ='BĐ-LG EXW-v2 (PDM)'!B11 -> 107440 | D10: =C10/$C$6 -> 0.017999755 | E10: ='BĐ-LG EXW-v2 (PDM)'!C11 -> 0 | F10: =E10/$E$6 -> 0 | H10: ='BĐ-LG EXW-v2 (PDM)'!B17 -> 22120.486 | I10: ='BĐ-LG EXW-v2 (PDM)'!C17 -> 0 | J10: =I10-H10 -> -22120.486 | K10: ='BĐ-LG EXW-v2 (PDM)'!B23 -> 2.376625e+09 | L10: =K10/$K$6 -> 0.011357177 | M10: ='BĐ-LG EXW-v2 (PDM)'!C23 -> 0 | N10: =M10/M$6 -> 0 | P10: ='BĐ-LG EXW-v2 (PDM)'!B35 -> 26359.464 | Q10: ='BĐ-LG EXW-v2 (PDM)'!C35 -> 0 | R10: =Q10-P10 -> -26359.464 | S10: ='BĐ-LG EXW-v2 (PDM)'!B42 -> 2.8320608e+09 | T10: =S10/S$6 -> 0.017612101 | U10: ='BĐ-LG EXW-v2 (PDM)'!C42 -> 0 | V10: =U10/U$6 -> 0 | X10: =K10-S10 -> -4.5543577e+08 | Y10: =X10/X$6 -> -0.012659998 | Z10: =M10-U10 -> 0 | AA10: =Z10/Z$6 -> 0
B11: ='BĐ-LG EXW-v2 (PDM)'!A12 -> Xơ sợi | C11: ='BĐ-LG EXW-v2 (PDM)'!B12 -> 100000 | D11: =C11/$C$6 -> 0.016753309 | E11: ='BĐ-LG EXW-v2 (PDM)'!C12 -> 27300 | F11: =E11/$E$6 -> 0.010874696 | H11: ='BĐ-LG EXW-v2 (PDM)'!B18 -> 27500 | I11: ='BĐ-LG EXW-v2 (PDM)'!C18 -> 16523.034 | J11: =I11-H11 -> -10976.966 | K11: ='BĐ-LG EXW-v2 (PDM)'!B24 -> 2.75e+09 | L11: =K11/$K$6 -> 0.013141424 | M11: ='BĐ-LG EXW-v2 (PDM)'!C24 -> 4.5107882e+08 | N11: =M11/M$6 -> 0.0051057119 | P11: ='BĐ-LG EXW-v2 (PDM)'!B36 -> 27655.807 | Q11: ='BĐ-LG EXW-v2 (PDM)'!C36 -> 29006.964 | R11: =Q11-P11 -> 1351.1567 | S11: ='BĐ-LG EXW-v2 (PDM)'!B43 -> 2.7655807e+09 | T11: =S11/S$6 -> 0.017198673 | U11: ='BĐ-LG EXW-v2 (PDM)'!C43 -> 791890115 | V11: =U11/U$6 -> 0.0097835957 | X11: =K11-S11 -> -15580720 | Y11: =X11/X$6 -> -0.00043310583 | Z11: =M11-U11 -> -3.4081129e+08 | AA11: =Z11/Z$6 -> -0.065959458
B12: ='BĐ-LG EXW-v2 (PDM)'!A25 -> Tài trợ | D12: =C12/$C$6 -> 0 | F12: =E12/$E$6 -> 0 | K12: ='BĐ-LG EXW-v2 (PDM)'!B25 -> 3408550000 | L12: =K12/$K$6 -> 0.016288436 | M12: ='BĐ-LG EXW-v2 (PDM)'!C25 -> 3395251201 | N12: =M12/M$6 -> 0.038430477 | S12: ='BĐ-LG EXW-v2 (PDM)'!B44 -> 0 | T12: =S12/S$6 -> 0 | U12: ='BĐ-LG EXW-v2 (PDM)'!C44 -> 0 | V12: =U12/U$6 -> 0 | X12: =K12-S12 -> 3408550000 | Y12: =X12/X$6 -> 0.094749333 | Z12: =M12-U12 -> 3395251201 | AA12: =Z12/Z$6 -> 0.65710537
B13: ='BĐ-LG EXW-v2 (PDM)'!A26 -> Dây đai, phó sản | D13: =C13/$C$6 -> 0 | F13: =E13/$E$6 -> 0 | K13: ='BĐ-LG EXW-v2 (PDM)'!B26 -> 2640000000 | L13: =K13/$K$6 -> 0.012615767 | M13: ='BĐ-LG EXW-v2 (PDM)'!C26 -> 6989889073 | N13: =M13/M$6 -> 0.07911779 | S13: ='BĐ-LG EXW-v2 (PDM)'!B45 -> 2359350000 | T13: =S13/S$6 -> 0.014672394 | U13: ='BĐ-LG EXW-v2 (PDM)'!C45 -> 6217736669 | V13: =U13/U$6 -> 0.076818514 | X13: =K13-S13 -> 280650000 | Y13: =X13/X$6 -> 0.0078013819 | Z13: =M13-U13 -> 772152404 | AA13: =Z13/Z$6 -> 0.14943975
B14: ='BĐ-LG EXW-v2 (PDM)'!A27 -> Khác | D14: =C14/$C$6 -> 0 | F14: =E14/$E$6 -> 0 | K14: ='BĐ-LG EXW-v2 (PDM)'!B27 -> 0 | L14: =K14/$K$6 -> 0 | M14: ='BĐ-LG EXW-v2 (PDM)'!C27 -> 63558813 | N14: =M14/M$6 -> 0.00071941525 | S14: ='BĐ-LG EXW-v2 (PDM)'!B46 -> 2250000000 | T14: =S14/S$6 -> 0.013992365 | U14: ='BĐ-LG EXW-v2 (PDM)'!C46 -> 4.1047779e+09 | V14: =U14/U$6 -> 0.05071346 | X14: =K14-S14 -> -2250000000 | Y14: =X14/X$6 -> -0.062544484 | Z14: =M14-U14 -> -4.0412191e+09 | AA14: =Z14/Z$6 -> -0.7821238
B15: ='BĐ-LG EXW-v2 (PDM)'!A28 -> Cp vận chuyển, hoa hồng, chiết khấu | D15: =C15/$C$6 -> 0 | F15: =E15/$E$6 -> 0 | K15: ='BĐ-LG EXW-v2 (PDM)'!B28 -> 12485577500 | L15: =K15/$K$6 -> 0.059664824 | M15: ='BĐ-LG EXW-v2 (PDM)'!C28 -> 2.2402986e+09 | N15: =M15/M$6 -> 0.025357695 | T15: =S15/S$6 -> 0 | V15: =U15/U$6 -> 0 | Y15: =X15/X$6 -> 0 | AA15: =Z15/Z$6 -> 0
B18: Nhóm SP/SP

Sheet S11
A1: ĐVT: VND nhưng show là tỷ đồng | AH1: LG EXW (THEO TỶ GIÁ KH) | AO1: DTHU EXW (THEO TỶ GIÁ KH) | AR1: %Biên
C2: Start | D2: Hidden | E2: Increase | F2: Decrease | G2: End | H2: Chênh lệch | M2: T/Đ nếu như nhóm ngành | P2: KH | Q2: TT | U2: KH | V2: TT | Z2: Tổng tác động | AA2: SL | AB2: GB | AC2: GV | AD2: EXR | AE2: Model | AH2: KH | AI2: TT | AJ2: +/- | AK2: %+/- | AO2: KH | AP2: TT
A3: ='S7'!A3 -> KH T11 | C3: =H3 -> 4.8459973e+10 | H3: 4.8459973e+10
A4: rPET | B4: Sản lượng | D4: =C3+E3-F4 -> 3.2103197e+10 | E4: =IF(H4>0,H4,0) -> 0 | F4: =IF(H4<0,-H4,0) -> 1.6356776e+10 | H4: =M4 -> -1.6356776e+10 | M4: {=TRANSPOSE(AA4:AC4)} -> -1.6356776e+10 | O4: tấn | P4: 4678.78 | Q4: 2027.64 | R4: =Q4-P4 -> -2651.14 | S4: =R4/P4 -> -0.56663062 | Z4: =SUM(AA4:AD4) -> -2.1969183e+10 | AA4: =R4*(P5*U5-P6*10^3) -> -1.6356776e+10 | AB4: =R5*Q4*U5 -> -3.5577563e+09 | AC4: =-R6*Q4*10^3 -> -5.0024859e+09 | AD4: =Q4*Q5*W5 -> 2.9478354e+09 | AE4: -2.1969183e+10 | AF4: =Z4-AE4 -> 0 | AH4: =P4*(P5*U5-P6*10^3) -> 2.8866735e+10 | AI4: =Q4*(Q5*U5-Q6*10^3) -> 3.9497169e+09 | AJ4: =AI4-AH4 -> -2.4917018e+10 | AK4: =AJ4/AH4 -> -0.8631741 | AM4: =Q4*(Q5*V5-Q6*10^3) -> 6.8975523e+09 | AN4: =AM4-AI4-AD4 -> 0 | AO4: ='S7'!AE4 -> 151371387500 | AP4: ='S7'!AF4 -> 6.2041968e+10 | AR4: =AH4/AO4 -> 0.1907014 | AS4: =AI4/AP4 -> 0.063662019
B5: Giá bán | D5: =D4+E4-F5 -> 2.8545441e+10 | E5: =IF(H5>0,H5,0) -> 0 | F5: =IF(H5<0,-H5,0) -> 3.5577563e+09 | H5: =M5 -> -3.5577563e+09 | I5: =H5*(1-13.11%) -> -3.0913344e+09 | M5: -3.5577563e+09 | O5: $/tấn | P5: 1294.1099 | Q5: 1223.9247 | R5: =Q5-P5 -> -70.185167 | S5: =R5/P5 -> -0.054234317 | U5: 25000 | V5: 26187.839 | W5: =V5-U5 -> 1187.8392 | X5: =W5/U5 -> 0.047513569
B6: Giá vốn | D6: =D5+E5-F6 -> 2.3542955e+10 | E6: =IF(H6>0,H6,0) -> 0 | F6: =IF(H6<0,-H6,0) -> 5.0024859e+09 | H6: =M6 -> -5.0024859e+09 | I6: =H6*(1-13.11%) -> -4.34666e+09 | M6: -5.0024859e+09 | O6: VND/kg | P6: 26183.033 | Q6: 28650.18 | R6: =Q6-P6 -> 2467.147 | S6: =R6/P6 -> 0.094226936
A7: rHDPE thổi | B7: Sản lượng | D7: =D6+E6-F7 -> 1.9768025e+10 | E7: =IF(H7>0,H7,0) -> 0 | F7: =IF(H7<0,-H7,0) -> 3.77493e+09 | H7: =M7 -> -3.77493e+09 | M7: {=TRANSPOSE(AA7:AC7)} -> -3.77493e+09 | O7: tấn | P7: 927 | Q7: 268.725 | R7: =Q7-P7 -> -658.275 | S7: =R7/P7 -> -0.71011327 | Z7: =SUM(AA7:AD7) -> -5.2640945e+09 | AA7: =R7*(P8*U8-P9*10^3) -> -3.77493e+09 | AB7: =R8*Q7*U8 -> -2.1972615e+09 | AC7: =-R9*Q7*10^3 -> 3.84768e+08 | AD7: =Q7*Q8*W8 -> 3.2332892e+08 | AE7: -5.2640945e+09 | AF7: =Z7-AE7 -> 0 | AH7: =P7*(P8*U8-P9*10^3) -> 5.3159547e+09 | AI7: =Q7*(Q8*U8-Q9*10^3) -> -2.7146872e+08 | AJ7: =AI7-AH7 -> -5.5874234e+09 | AK7: =AJ7/AH7 -> -1.0510668 | AM7: =Q7*(Q8*V8-Q9*10^3) -> 51860203 | AN7: =AM7-AI7-AD7 -> -5.9604645e-07 | AO7: ='S7'!AE6 -> 30984250000 | AP7: ='S7'!AF6 -> 6.7846615e+09 | AR7: =AH7/AO7 -> 0.17156958 | AS7: =AI7/AP7 -> -0.040012124
B8: Giá bán | D8: =D7+E7-F8 -> 1.7570764e+10 | E8: =IF(H8>0,H8,0) -> 0 | F8: =IF(H8<0,-H8,0) -> 2.1972615e+09 | H8: =M8 -> -2.1972615e+09 | M8: -2.1972615e+09 | O8: $/tấn | P8: 1336.9687 | Q8: 1009.904 | R8: =Q8-P8 -> -327.06469 | S8: =R8/P8 -> -0.24463152 | U8: 25000 | V8: 26191.397 | W8: =V8-U8 -> 1191.3967 | X8: =W8/U8 -> 0.047655866
B9: Giá vốn | D9: =D8+E8-F9 -> 1.7570764e+10 | E9: =IF(H9>0,H9,0) -> 3.84768e+08 | F9: =IF(H9<0,-H9,0) -> 0 | H9: =M9 -> 3.84768e+08 | M9: 3.84768e+08 | O9: VND/kg | P9: 27689.639 | Q9: 26257.811 | R9: =Q9-P9 -> -1431.8281 | S9: =R9/P9 -> -0.051709886
A10: rHDPE ép | B10: Sản lượng | D10: =D9+E9-F10 -> 1.7955532e+10 | E10: =IF(H10>0,H10,0) -> 1.6391134e+08 | F10: =IF(H10<0,-H10,0) -> 0 | H10: =M10 -> 1.6391134e+08 | M10: {=TRANSPOSE(AA10:AC10)} -> 1.6391134e+08 | O10: tấn | P10: 155.75 | Q10: 186.75 | R10: =Q10-P10 -> 31 | S10: =R10/P10 -> 0.19903692 | Z10: =SUM(AA10:AD10) -> -2.3913266e+09 | AA10: =R10*(P11*U11-P12*10^3) -> 1.6391134e+08 | AB10: =R11*Q10*U11 -> -9.226508e+08 | AC10: =-R12*Q10*10^3 -> -1.7736988e+09 | AD10: =Q10*Q11*W11 -> 1.4111161e+08 | AE10: -2.3913266e+09 | AF10: =Z10-AE10 -> 0 | AH10: =P10*(P11*U11-P12*10^3) -> 8.2352231e+08 | AI10: =Q10*(Q11*U11-Q12*10^3) -> -1.708916e+09 | AJ10: =AI10-AH10 -> -2.5324383e+09 | AK10: =AJ10/AH10 -> -3.0751301 | AM10: =Q10*(Q11*V11-Q12*10^3) -> -1.5678043e+09 | AN10: =AM10-AI10-AD10 -> 0 | AO10: ='S7'!AE8 -> 3245562500 | AP10: ='S7'!AF8 -> 2.9688985e+09 | AR10: =AH10/AO10 -> 0.25373793 | AS10: =AI10/AP10 -> -0.57560606
B11: Giá bán | D11: =D10+E10-F11 -> 1.7196792e+10 | E11: =IF(H11>0,H11,0) -> 0 | F11: =IF(H11<0,-H11,0) -> 9.226508e+08 | H11: =M11 -> -9.226508e+08 | M11: -9.226508e+08 | O11: $/tấn | P11: 833.5313 | Q11: 635.90864 | R11: =Q11-P11 -> -197.62266 | S11: =R11/P11 -> -0.23709087 | U11: 25000 | V11: 26188.249 | W11: =V11-U11 -> 1188.2489 | X11: =W11/U11 -> 0.047529955
B12: Giá vốn | D12: =D11+E11-F12 -> 1.5423093e+10 | E12: =IF(H12>0,H12,0) -> 0 | F12: =IF(H12<0,-H12,0) -> 1.7736988e+09 | H12: =M12 -> -1.7736988e+09 | M12: -1.7736988e+09 | O12: VND/kg | P12: 15550.82 | Q12: 25048.538 | R12: =Q12-P12 -> 9497.7178 | S12: =R12/P12 -> 0.61075351
A13: rPP | B13: Sản lượng | D13: =D12+E12-F13 -> 1.5423093e+10 | E13: =IF(H13>0,H13,0) -> 4.5543577e+08 | F13: =IF(H13<0,-H13,0) -> 0 | H13: =M13 -> 4.5543577e+08 | M13: {=TRANSPOSE(AA13:AC13)} -> 4.5543577e+08 | O13: tấn | P13: 107.44 | Q13: 0 | R13: =Q13-P13 -> -107.44 | S13: =R13/P13 -> -1 | Z13: =SUM(AA13:AD13) -> 4.5543577e+08 | AA13: =R13*(P14*U14-P15*10^3) -> 4.5543577e+08 | AB13: =R14*Q13*U14 -> 0 | AC13: =-R15*Q13*10^3 -> 0 | AD13: =Q13*Q14*W14 -> 0 | AE13: 4.5543577e+08 | AF13: =Z13-AE13 -> 5.364418e-07 | AH13: =P13*(P14*U14-P15*10^3) -> -4.5543577e+08 | AI13: =Q13*(Q14*U14-Q15*10^3) -> 0 | AJ13: =AI13-AH13 -> 4.5543577e+08 | AK13: =AJ13/AH13 -> -1 | AM13: =Q13*(Q14*V14-Q15*10^3) -> 0 | AN13: =AM13-AI13-AD13 -> 0 | AO13: ='S7'!AE10 -> 2.376625e+09 | AP13: ='S7'!AF10 -> 0 | AR13: =AH13/AO13 -> -0.19163131 | AS13: =AI13/AP13 -> #DIV/0!
B14: Giá bán | D14: =D13+E13-F14 -> 1.5878529e+10 | E14: =IF(H14>0,H14,0) -> 0 | F14: =IF(H14<0,-H14,0) -> 0 | H14: =M14 -> 0 | M14: 0 | O14: $/tấn | P14: 884.81943 | Q14: 0 | R14: =Q14-P14 -> -884.81943 | S14: =R14/P14 -> -1 | U14: 25000 | V14: 0 | W14: =V14-U14 -> -25000 | X14: =W14/U14 -> -1
B15: Giá vốn | D15: =D14+E14-F15 -> 1.5878529e+10 | E15: =IF(H15>0,H15,0) -> 0 | F15: =IF(H15<0,-H15,0) -> 0 | H15: =M15 -> 0 | M15: 0 | O15: VND/kg | P15: 26359.464 | Q15: 0 | R15: =Q15-P15 -> -26359.464 | S15: =R15/P15 -> -1
