Workbook
Name \0: #REF!
Name \0: #REF!
Name \A: #REF!
Name \A: #REF!
Name \B: #REF!
Name \B: #REF!
Name \c: #REF!
Name \D: #REF!
Name \E: #REF!
Name \F: #REF!
Name \g: #REF!
Name \H: #REF!
Name \L: #REF!
Name \P: #REF!
Name \S: #REF!
Name \T: #REF!
Name \V: #REF!
Name _: #REF!
Name __2PrintPi: #REF!
Name _1_0PrintPi: #REF!
Name _1DealsMAVCPMJVExt: #REF!
Name _1tradebloc: #REF!
Name _2: #REF!
Name _2AFGearingRatios: #REF!
Name _2PrintPi: #REF!
Name _2RAWAssetFinancing: #REF!
Name _2RAWEquityProviders: #REF!
Name _2RAWSellers: #REF!
Name _483_1M: #REF!
Name _BIG6: #REF!
Name _DAT1: #REF!
Name _DAT10: #REF!
Name _DAT11: #REF!
Name _DAT12: #REF!
Name _DAT13: #REF!
Name _DAT14: #REF!
Name _DAT2: #REF!
Name _DAT3: #REF!
Name _DAT4: #REF!
Name _DAT5: #REF!
Name _DAT6: #REF!
Name _DAT7: #REF!
Name _DAT8: #REF!
Name _DAT9: #REF!
Name _DLX1.USE: #REF!
Name _DLX2.USE7: #REF!
Name _newscore: #REF!
Name _PLT40: #REF!
Name _Regression_Int: 1
Name A: #REF!
Name AAE: #REF!
Name AAH: #REF!
Name AAP: #REF!
Name ABE: #REF!
Name ABH: #REF!
Name ABP: #REF!
Name AE: #REF!
Name AFKAIRCURRENT: #REF!
Name AH: #REF!
Name AIRCOVMTHLYD: #REF!

Sheet SC CONSIDERATION
E1: • Mã: 39076100 áp dụng cho hạt rPET có chỉ số độ nhớt từ 78ml/g trở lên | F1: 39076100
E2: • Mã: 39076910 áp dụng cho hạt rPET có chỉ số độ nhớt dưới 78ml/g | F2: 39076910
E4: GNI per Capita by Country 2024 (worldpopulationreview.com)
A5: GNIPC.pdf (worldbank.org) | E5: GNI per Capita by Country 2024
A6: Country | B6: GNI per capita ($) | E6: Country | F6: GNI per capita, Atlas | G6: GNI per capita, PPP | H6: GNI, Atlas | I6: TO CONSIDER | J6: EXPORT OF RPET | K6: IMPORT OF RPET | L6: EXPORT SURPLUS | M6: PIC
A7: Liechtenstein | B7: 116600 | C7: 2009 | E7: China | F7: 11880 | G7: 19160 | H7: $16.79 Mn | J7: =SUMIFS('Export Data'!$B$13:$B$176,'Export Data'!$A$13:$A$176,'SC CONSIDERATION'!E7) -> 10750920 | K7: =SUMIFS('Imports Data'!$B$13:$B$234,'Imports Data'!$A$13:$A$234,'SC CONSIDERATION'!E7) -> 6969491 | L7: =J7-K7 -> 3781429
A8: Norway | B8: 102460 | C8: 2023 | E8: United States of America | F8: 70930 | G8: 70480 | H8: $23.54 Mn | J8: =SUMIFS('Export Data'!$B$13:$B$176,'Export Data'!$A$13:$A$176,'SC CONSIDERATION'!E8) -> 5633830 | K8: =SUMIFS('Imports Data'!$B$13:$B$234,'Imports Data'!$A$13:$A$234,'SC CONSIDERATION'!E8) -> 4483176 | L8: =J8-K8 -> 1150654
A9: San Marino | B9: 47120 | C9: 2021 | E9: Korea, Republic of | F9: 35110 | G9: 47770 | H9: $1.82 Mn | J9: =SUMIFS('Export Data'!$B$13:$B$176,'Export Data'!$A$13:$A$176,'SC CONSIDERATION'!E9) -> 5306241 | K9: =SUMIFS('Imports Data'!$B$13:$B$234,'Imports Data'!$A$13:$A$234,'SC CONSIDERATION'!E9) -> 1254778 | L9: =J9-K9 -> 4051463
A10: Austria | B10: 55070 | C10: 2023 | E10: Germany | F10: 51660 | G10: 59630 | H10: $4.30 Mn | J10: =SUMIFS('Export Data'!$B$13:$B$176,'Export Data'!$A$13:$A$176,'SC CONSIDERATION'!E10) -> 4885272 | K10: =SUMIFS('Imports Data'!$B$13:$B$234,'Imports Data'!$A$13:$A$234,'SC CONSIDERATION'!E10) -> 4248847 | L10: =J10-K10 -> 636425
A11: French Polynesia (France) | B11: 18560 | C11: 2000 | E11: Netherlands | F11: 55200 | G11: 63370 | H11: 967837.42 | J11: =SUMIFS('Export Data'!$B$13:$B$176,'Export Data'!$A$13:$A$176,'SC CONSIDERATION'!E11) -> 4148736 | K11: =SUMIFS('Imports Data'!$B$13:$B$234,'Imports Data'!$A$13:$A$234,'SC CONSIDERATION'!E11) -> 1198553 | L11: =J11-K11 -> 2950183
A12: Costa Rica | B12: 13850 | C12: 2023 | E12: Belgium | F12: 50490 | G12: 59430 | H12: 585375.4 | J12: =SUMIFS('Export Data'!$B$13:$B$176,'Export Data'!$A$13:$A$176,'SC CONSIDERATION'!E12) -> 3402459 | K12: =SUMIFS('Imports Data'!$B$13:$B$234,'Imports Data'!$A$13:$A$234,'SC CONSIDERATION'!E12) -> 2097351 | L12: =J12-K12 -> 1305108
A13: United Arab Emirates | B13: 53290 | C13: 2023 | E13: Italy | F13: 35990 | G13: 46450 | H13: $2.13 Mn | J13: =SUMIFS('Export Data'!$B$13:$B$176,'Export Data'!$A$13:$A$176,'SC CONSIDERATION'!E13) -> 2433530 | K13: =SUMIFS('Imports Data'!$B$13:$B$234,'Imports Data'!$A$13:$A$234,'SC CONSIDERATION'!E13) -> 2897825 | L13: =J13-K13 -> -464295
A14: Israel | B14: 55020 | C14: 2023 | E14: Thailand | F14: 7090 | G14: 18120 | H14: 507856.67 | J14: =SUMIFS('Export Data'!$B$13:$B$176,'Export Data'!$A$13:$A$176,'SC CONSIDERATION'!E14) -> 2365823 | K14: =SUMIFS('Imports Data'!$B$13:$B$234,'Imports Data'!$A$13:$A$234,'SC CONSIDERATION'!E14) -> 1075708 | L14: =J14-K14 -> 1290115 | M14: TÂN
A15: Singapore | B15: 70590 | C15: 2023 | E15: Japan | F15: 42650 | G15: 44570 | H15: $5.36 Mn | J15: =SUMIFS('Export Data'!$B$13:$B$176,'Export Data'!$A$13:$A$176,'SC CONSIDERATION'!E15) -> 2335669 | K15: =SUMIFS('Imports Data'!$B$13:$B$234,'Imports Data'!$A$13:$A$234,'SC CONSIDERATION'!E15) -> 2289039 | L15: =J15-K15 -> 46630
A16: Macau (China) | B16: 43940 | C16: 2022 | E16: Spain | F16: 29690 | G16: 40910 | H16: $1.41 Mn | J16: =SUMIFS('Export Data'!$B$13:$B$176,'Export Data'!$A$13:$A$176,'SC CONSIDERATION'!E16) -> 1851425 | K16: =SUMIFS('Imports Data'!$B$13:$B$234,'Imports Data'!$A$13:$A$234,'SC CONSIDERATION'!E16) -> 1438278 | L16: =J16-K16 -> 413147
A17: Turkmenistan | B17: 7080 | C17: 2019 | E17: Singapore | F17: 64010 | G17: 102450 | H17: 349100.86 | J17: =SUMIFS('Export Data'!$B$13:$B$176,'Export Data'!$A$13:$A$176,'SC CONSIDERATION'!E17) -> 1344380 | K17: =SUMIFS('Imports Data'!$B$13:$B$234,'Imports Data'!$A$13:$A$234,'SC CONSIDERATION'!E17) -> 573907 | L17: =J17-K17 -> 770473
A18: Bahrain | B18: 28280 | C18: 2023 | E18: Malaysia | F18: 10710 | G18: 28150 | H18: 359707.78 | J18: =SUMIFS('Export Data'!$B$13:$B$176,'Export Data'!$A$13:$A$176,'SC CONSIDERATION'!E18) -> 1155784 | K18: =SUMIFS('Imports Data'!$B$13:$B$234,'Imports Data'!$A$13:$A$234,'SC CONSIDERATION'!E18) -> 951759 | L18: =J18-K18 -> 204025
A19: Spain | B19: 32180 | C19: 2023 | E19: Saudi Arabia | F19: 21540 | G19: 46130 | H19: 755462.63 | J19: =SUMIFS('Export Data'!$B$13:$B$176,'Export Data'!$A$13:$A$176,'SC CONSIDERATION'!E19) -> 990414 | K19: =SUMIFS('Imports Data'!$B$13:$B$234,'Imports Data'!$A$13:$A$234,'SC CONSIDERATION'!E19) -> 290614 | L19: =J19-K19 -> 699800
A20: Canada | B20: 53930 | C20: 2023 | E20: France | F20: 44160 | G20: 51660 | H20: $2.99 Mn | J20: =SUMIFS('Export Data'!$B$13:$B$176,'Export Data'!$A$13:$A$176,'SC CONSIDERATION'!E20) -> 949718 | K20: =SUMIFS('Imports Data'!$B$13:$B$234,'Imports Data'!$A$13:$A$234,'SC CONSIDERATION'!E20) -> 2054554 | L20: =J20-K20 -> -1104836
A21: Sweden | B21: 61650 | C21: 2023 | E21: Viet Nam | F21: 3590 | G21: 11080 | H21: 350209.13 | I21: Vietnam | J21: =SUMIFS('Export Data'!$B$13:$B$176,'Export Data'!$A$13:$A$176,'SC CONSIDERATION'!E21) -> 920122 | K21: =SUMIFS('Imports Data'!$B$13:$B$234,'Imports Data'!$A$13:$A$234,'SC CONSIDERATION'!E21) -> 1953058 | L21: =J21-K21 -> -1032936
A22: Germany | B22: 53970 | C22: 2023 | E22: United Kingdom | F22: 44480 | G22: 49420 | H22: $2.99 Mn | J22: =SUMIFS('Export Data'!$B$13:$B$176,'Export Data'!$A$13:$A$176,'SC CONSIDERATION'!E22) -> 731627 | K22: =SUMIFS('Imports Data'!$B$13:$B$234,'Imports Data'!$A$13:$A$234,'SC CONSIDERATION'!E22) -> 1525023 | L22: =J22-K22 -> -793396
A23: Bermuda (UK) | B23: 134640 | C23: 2022 | E23: India | F23: 2150 | G23: 7130 | H23: $3.02 Mn | J23: =SUMIFS('Export Data'!$B$13:$B$176,'Export Data'!$A$13:$A$176,'SC CONSIDERATION'!E23) -> 726681 | K23: =SUMIFS('Imports Data'!$B$13:$B$234,'Imports Data'!$A$13:$A$234,'SC CONSIDERATION'!E23) -> 2491784 | L23: =J23-K23 -> -1765103 | M23: TÂN
A24: Denmark | B24: 73360 | C24: 2023 | E24: Mexico | F24: 9590 | G24: 19740 | H24: $1.21 Mn | J24: =SUMIFS('Export Data'!$B$13:$B$176,'Export Data'!$A$13:$A$176,'SC CONSIDERATION'!E24) -> 695311 | K24: =SUMIFS('Imports Data'!$B$13:$B$234,'Imports Data'!$A$13:$A$234,'SC CONSIDERATION'!E24) -> 2659901 | L24: =J24-K24 -> -1964590 | M24: TÂN
A25: South Korea | B25: 35490 | C25: 2023 | E25: Poland | F25: 16850 | G25: 36060 | H25: 636064.2 | J25: =SUMIFS('Export Data'!$B$13:$B$176,'Export Data'!$A$13:$A$176,'SC CONSIDERATION'!E25) -> 638928 | K25: =SUMIFS('Imports Data'!$B$13:$B$234,'Imports Data'!$A$13:$A$234,'SC CONSIDERATION'!E25) -> 1168470 | L25: =J25-K25 -> -529542
A26: Bosnia and Herzegovina | B26: 8160 | C26: 2023 | E26: Switzerland | F26: 90600 | G26: 75810 | H26: 788512.43 | J26: =SUMIFS('Export Data'!$B$13:$B$176,'Export Data'!$A$13:$A$176,'SC CONSIDERATION'!E26) -> 634341 | K26: =SUMIFS('Imports Data'!$B$13:$B$234,'Imports Data'!$A$13:$A$234,'SC CONSIDERATION'!E26) -> 601372 | L26: =J26-K26 -> 32969
A27: Micronesia | B27: 4150 | C27: 2023 | E27: Lithuania | F27: 21740 | G27: 41170 | H27: 60884.17 | J27: =SUMIFS('Export Data'!$B$13:$B$176,'Export Data'!$A$13:$A$176,'SC CONSIDERATION'!E27) -> 617698 | K27: =SUMIFS('Imports Data'!$B$13:$B$234,'Imports Data'!$A$13:$A$234,'SC CONSIDERATION'!E27) -> 172147 | L27: =J27-K27 -> 445551
A28: Brunei | B28: 34970 | C28: 2023 | E28: Canada | F28: 48310 | G28: 51690 | H28: $1.85 Mn | J28: =SUMIFS('Export Data'!$B$13:$B$176,'Export Data'!$A$13:$A$176,'SC CONSIDERATION'!E28) -> 533376 | K28: =SUMIFS('Imports Data'!$B$13:$B$234,'Imports Data'!$A$13:$A$234,'SC CONSIDERATION'!E28) -> 1137298 | L28: =J28-K28 -> -603922
A29: Belarus | B29: 7780 | C29: 2023 | E29: Hong Kong, China | F29: 54460 | G29: 70600 | H29: 403721.37 | J29: =SUMIFS('Export Data'!$B$13:$B$176,'Export Data'!$A$13:$A$176,'SC CONSIDERATION'!E29) -> 458319 | K29: =SUMIFS('Imports Data'!$B$13:$B$234,'Imports Data'!$A$13:$A$234,'SC CONSIDERATION'!E29) -> 423883 | L29: =J29-K29 -> 34436
A30: Cayman Islands (UK) | B30: 68790 | C30: 2022 | E30: Egypt | F30: 3350 | G30: 12320 | H30: 365799.86 | I30: Y | J30: =SUMIFS('Export Data'!$B$13:$B$176,'Export Data'!$A$13:$A$176,'SC CONSIDERATION'!E30) -> 453422 | K30: =SUMIFS('Imports Data'!$B$13:$B$234,'Imports Data'!$A$13:$A$234,'SC CONSIDERATION'!E30) -> 327095 | L30: =J30-K30 -> 126327 | M30: MAI
A31: Dominica | B31: 8920 | C31: 2023 | E31: Austria | F31: 52760 | G31: 58370 | H31: 472474.25 | J31: =SUMIFS('Export Data'!$B$13:$B$176,'Export Data'!$A$13:$A$176,'SC CONSIDERATION'!E31) -> 392195 | K31: =SUMIFS('Imports Data'!$B$13:$B$234,'Imports Data'!$A$13:$A$234,'SC CONSIDERATION'!E31) -> 688473 | L31: =J31-K31 -> -296278
A32: Turkey | B32: 11650 | C32: 2023 | E32: Czech Republic | F32: 24430 | G32: 43360 | H32: 256631.3 | J32: =SUMIFS('Export Data'!$B$13:$B$176,'Export Data'!$A$13:$A$176,'SC CONSIDERATION'!E32) -> 357483 | K32: =SUMIFS('Imports Data'!$B$13:$B$234,'Imports Data'!$A$13:$A$234,'SC CONSIDERATION'!E32) -> 946256 | L32: =J32-K32 -> -588773
A33: Switzerland | B33: 95160 | C33: 2023 | E33: Indonesia | F33: 4180 | G33: 12680 | H33: $1.14 Mn | J33: =SUMIFS('Export Data'!$B$13:$B$176,'Export Data'!$A$13:$A$176,'SC CONSIDERATION'!E33) -> 286712 | K33: =SUMIFS('Imports Data'!$B$13:$B$234,'Imports Data'!$A$13:$A$234,'SC CONSIDERATION'!E33) -> 1024301 | L33: =J33-K33 -> -737589 | M33: TÂN
A34: Guatemala | B34: 5580 | C34: 2023 | E34: Oman | F34: 17950 | G34: 35120 | H34: 81164.63 | J34: =SUMIFS('Export Data'!$B$13:$B$176,'Export Data'!$A$13:$A$176,'SC CONSIDERATION'!E34) -> 222355 | K34: =SUMIFS('Imports Data'!$B$13:$B$234,'Imports Data'!$A$13:$A$234,'SC CONSIDERATION'!E34) -> 49962 | L34: =J34-K34 -> 172393
A35: Saint Vincent and the Grenadines | B35: 10070 | C35: 2023 | E35: Hungary | F35: 17740 | G35: 35640 | H35: 172210.65 | J35: =SUMIFS('Export Data'!$B$13:$B$176,'Export Data'!$A$13:$A$176,'SC CONSIDERATION'!E35) -> 196105 | K35: =SUMIFS('Imports Data'!$B$13:$B$234,'Imports Data'!$A$13:$A$234,'SC CONSIDERATION'!E35) -> 576155 | L35: =J35-K35 -> -380050
A36: United States | B36: 80300 | C36: 2023 | E36: Brazil | F36: 7740 | G36: 15600 | H36: $1.66 Mn | J36: =SUMIFS('Export Data'!$B$13:$B$176,'Export Data'!$A$13:$A$176,'SC CONSIDERATION'!E36) -> 194663 | K36: =SUMIFS('Imports Data'!$B$13:$B$234,'Imports Data'!$A$13:$A$234,'SC CONSIDERATION'!E36) -> 876307 | L36: =J36-K36 -> -681644 | M36: MAI
A37: Curaçao (Netherlands) | B37: 20590 | C37: 2022 | E37: Romania | F37: 14160 | G37: 35260 | H37: 270676.86 | J37: =SUMIFS('Export Data'!$B$13:$B$176,'Export Data'!$A$13:$A$176,'SC CONSIDERATION'!E37) -> 190123 | K37: =SUMIFS('Imports Data'!$B$13:$B$234,'Imports Data'!$A$13:$A$234,'SC CONSIDERATION'!E37) -> 574385 | L37: =J37-K37 -> -384262
A38: Luxembourg | B38: 88370 | C38: 2023 | E38: Pakistan | F38: 1470 | G38: 5680 | H38: 340808.73 | J38: =SUMIFS('Export Data'!$B$13:$B$176,'Export Data'!$A$13:$A$176,'SC CONSIDERATION'!E38) -> 177961 | K38: =SUMIFS('Imports Data'!$B$13:$B$234,'Imports Data'!$A$13:$A$234,'SC CONSIDERATION'!E38) -> 157518 | L38: =J38-K38 -> 20443
A39: Mexico | B39: 12100 | C39: 2023 | E39: Sweden | F39: 59540 | G39: 61090 | H39: 620153.67 | J39: =SUMIFS('Export Data'!$B$13:$B$176,'Export Data'!$A$13:$A$176,'SC CONSIDERATION'!E39) -> 174226 | K39: =SUMIFS('Imports Data'!$B$13:$B$234,'Imports Data'!$A$13:$A$234,'SC CONSIDERATION'!E39) -> 409895 | L39: =J39-K39 -> -235669
A40: South Africa | B40: 6750 | C40: 2023 | E40: Slovakia | F40: 20640 | G40: 32450 | H40: 112424.24 | J40: =SUMIFS('Export Data'!$B$13:$B$176,'Export Data'!$A$13:$A$176,'SC CONSIDERATION'!E40) -> 132375 | K40: =SUMIFS('Imports Data'!$B$13:$B$234,'Imports Data'!$A$13:$A$234,'SC CONSIDERATION'!E40) -> 410472 | L40: =J40-K40 -> -278097
A41: Serbia | B41: 10030 | C41: 2023 | E41: United Arab Emirates | F41: 41770 | G41: 71280 | H41: 387961.14 | J41: =SUMIFS('Export Data'!$B$13:$B$176,'Export Data'!$A$13:$A$176,'SC CONSIDERATION'!E41) -> 129249 | K41: =SUMIFS('Imports Data'!$B$13:$B$234,'Imports Data'!$A$13:$A$234,'SC CONSIDERATION'!E41) -> 668314 | L41: =J41-K41 -> -539065
...

Sheet EX-1A SV Summary
B1: rPET from Vietnam Duy Tan Group to US
B2: Circumvention & Scope Inquiries: Vietnam
B3: Vietnam Part - Surrogate Values from Egypt
B5: SV Worksheet
B7: CODE | C7: Full Name | D7: HPS | E7: Source | F7: Time Period | G7: Source Value | H7: Source Unit of Measure | I7: Reported Unit of Measure | J7: Converter | K7: Inflator | L7: Surrogate Value (Currency per Reported Unit of Measure) | M7: Exrate (USD/Currency) | N7: Surrogate Value (USD per Reported Unit of Measure)
B8: 150000003 | C8: Chai PET B1 | D8: 39159010 | E8: UNComtrade | F8: IP | G8: ='EX-2.1 Chai & vảy'!$D$69 -> 0.55177264 | H8: USD/KG | I8: KG | J8: 1 | K8: ='EX-3 CPI'!$D$38 -> 1 | L8: =G8/J8*K8 -> 0.55177264 | M8: 1 | N8: =L8*M8 -> 0.55177264
B9: 150000113 | C9: Chai PET B1 Không Phân Loại | D9: 39159010 | E9: UNComtrade | F9: IP | G9: ='EX-2.1 Chai & vảy'!$D$69 -> 0.55177264 | H9: USD/KG | I9: KG | J9: 1 | K9: ='EX-3 CPI'!$D$38 -> 1 | L9: =G9/J9*K9 -> 0.55177264 | M9: 1 | N9: =L9*M9 -> 0.55177264
B10: 150000004 | C10: Chai PET-B2.1 | D10: 39159010 | E10: UNComtrade | F10: IP | G10: ='EX-2.1 Chai & vảy'!$D$69 -> 0.55177264 | H10: USD/KG | I10: KG | J10: 1 | K10: ='EX-3 CPI'!$D$38 -> 1 | L10: =G10/J10*K10 -> 0.55177264 | M10: 1 | N10: =L10*M10 -> 0.55177264
B11: 150000050 | C11: Chai PET-B2.2 | D11: 39159010 | E11: UNComtrade | F11: IP | G11: ='EX-2.1 Chai & vảy'!$D$69 -> 0.55177264 | H11: USD/KG | I11: KG | J11: 1 | K11: ='EX-3 CPI'!$D$38 -> 1 | L11: =G11/J11*K11 -> 0.55177264 | M11: 1 | N11: =L11*M11 -> 0.55177264
B12: 150000005 | C12: Chai PET-B3 | D12: 39159010 | E12: UNComtrade | F12: IP | G12: ='EX-2.1 Chai & vảy'!$D$69 -> 0.55177264 | H12: USD/KG | I12: KG | J12: 1 | K12: ='EX-3 CPI'!$D$38 -> 1 | L12: =G12/J12*K12 -> 0.55177264 | M12: 1 | N12: =L12*M12 -> 0.55177264
B13: 150000014 | C13: Chai PET B4 | D13: 39159010 | E13: UNComtrade | F13: IP | G13: ='EX-2.1 Chai & vảy'!$D$69 -> 0.55177264 | H13: USD/KG | I13: KG | J13: 1 | K13: ='EX-3 CPI'!$D$38 -> 1 | L13: =G13/J13*K13 -> 0.55177264 | M13: 1 | N13: =L13*M13 -> 0.55177264
B14: 150000015 | C14: Chai PET B5 | D14: 39159010 | E14: UNComtrade | F14: IP | G14: ='EX-2.1 Chai & vảy'!$D$69 -> 0.55177264 | H14: USD/KG | I14: KG | J14: 1 | K14: ='EX-3 CPI'!$D$38 -> 1 | L14: =G14/J14*K14 -> 0.55177264 | M14: 1 | N14: =L14*M14 -> 0.55177264
B15: 150000016 | C15: Chai PET B6.1 | D15: 39159010 | E15: UNComtrade | F15: IP | G15: ='EX-2.1 Chai & vảy'!$D$69 -> 0.55177264 | H15: USD/KG | I15: KG | J15: 1 | K15: ='EX-3 CPI'!$D$38 -> 1 | L15: =G15/J15*K15 -> 0.55177264 | M15: 1 | N15: =L15*M15 -> 0.55177264
B16: 150000114 | C16: Chai PET B6.2 | D16: 39159010 | E16: UNComtrade | F16: IP | G16: ='EX-2.1 Chai & vảy'!$D$69 -> 0.55177264 | H16: USD/KG | I16: KG | J16: 1 | K16: ='EX-3 CPI'!$D$38 -> 1 | L16: =G16/J16*K16 -> 0.55177264 | M16: 1 | N16: =L16*M16 -> 0.55177264
B17: 150000010 | C17: Chai PET B7.1 | D17: 39159010 | E17: UNComtrade | F17: IP | G17: ='EX-2.1 Chai & vảy'!$D$69 -> 0.55177264 | H17: USD/KG | I17: KG | J17: 1 | K17: ='EX-3 CPI'!$D$38 -> 1 | L17: =G17/J17*K17 -> 0.55177264 | M17: 1 | N17: =L17*M17 -> 0.55177264
B18: 150000051 | C18: Vảy PET B1_A5.1 | D18: 39159010 | E18: UNComtrade | F18: IP | G18: ='EX-2.1 Chai & vảy'!$D$69 -> 0.55177264 | H18: USD/KG | I18: KG | J18: 1 | K18: ='EX-3 CPI'!$D$38 -> 1 | L18: =G18/J18*K18 -> 0.55177264 | M18: 1 | N18: =L18*M18 -> 0.55177264
B19: 150000052 | C19: Vảy PET B1_A5.2 | D19: 39159010 | E19: UNComtrade | F19: IP | G19: ='EX-2.1 Chai & vảy'!$D$69 -> 0.55177264 | H19: USD/KG | I19: KG | J19: 1 | K19: ='EX-3 CPI'!$D$38 -> 1 | L19: =G19/J19*K19 -> 0.55177264 | M19: 1 | N19: =L19*M19 -> 0.55177264
B20: 150000053 | C20: Vảy PET B1_A6 | D20: 39159010 | E20: UNComtrade | F20: IP | G20: ='EX-2.1 Chai & vảy'!$D$69 -> 0.55177264 | H20: USD/KG | I20: KG | J20: 1 | K20: ='EX-3 CPI'!$D$38 -> 1 | L20: =G20/J20*K20 -> 0.55177264 | M20: 1 | N20: =L20*M20 -> 0.55177264
B21: 700000196 | C21: Phụ gia 409 | D21: 32061990 | E21: UNComtrade | F21: IP | G21: ='EX-2.3 Phụ gia 409'!$G$6 -> 4.8268556 | H21: USD/KG | I21: KG | J21: 1 | K21: ='EX-3 CPI'!$D$38 -> 1 | L21: =G21/J21*K21 -> 4.8268556 | M21: 1 | N21: =L21*M21 -> 4.8268556
B22: 700000169 | C22: Phụ gia 0090 | D22: 32049000 | E22: UNComtrade | F22: 2023 | G22: ='EX-2.4 Phụ gia khác'!$D$6 -> 0.059997551 | H22: USD/KG | I22: KG | J22: 1 | K22: =VLOOKUP(F22,'EX-3 CPI'!$B$33:$D$38,3,0) -> 1.2017885 | L22: =G22/J22*K22 -> 0.07210437 | M22: 1 | N22: =L22*M22 -> 0.07210437
B23: 120003033 | C23: Phụ gia CC10379752ZF | D23: 32049000 | E23: UNComtrade | F23: 2023 | G23: ='EX-2.4 Phụ gia khác'!$D$6 -> 0.059997551 | H23: USD/KG | I23: KG | J23: 1 | K23: =VLOOKUP(F23,'EX-3 CPI'!$B$33:$D$38,3,0) -> 1.2017885 | L23: =G23/J23*K23 -> 0.07210437 | M23: 1 | N23: =L23*M23 -> 0.07210437
B24: 120002994 | C24: Phụ gia 00185 | D24: 32049000 | E24: UNComtrade | F24: 2023 | G24: ='EX-2.4 Phụ gia khác'!$D$6 -> 0.059997551 | H24: USD/KG | I24: KG | J24: 1 | K24: =VLOOKUP(F24,'EX-3 CPI'!$B$33:$D$38,3,0) -> 1.2017885 | L24: =G24/J24*K24 -> 0.07210437 | M24: 1 | N24: =L24*M24 -> 0.07210437
B25: 120003028 | C25: Phụ gia RHC-2 | D25: 3206199 | E25: UNComtrade | F25: 2023 | G25: ='EX-2.5 Phụ gia RHC'!D7 -> 4.8241431 | H25: USD/KG | I25: KG | J25: 1 | K25: =VLOOKUP(F25,'EX-3 CPI'!$B$33:$D$38,3,0) -> 1.2017885 | L25: =G25/J25*K25 -> 5.7975999 | M25: 1 | N25: =L25*M25 -> 5.7975999
B26: 150000078 | C26: Vảy PET B3_A5.1 | D26: 39159010 | E26: UNComtrade | F26: IP | G26: ='EX-2.1 Chai & vảy'!$D$69 -> 0.55177264 | H26: USD/KG | I26: KG | J26: 1 | K26: ='EX-3 CPI'!$D$38 -> 1 | L26: =G26/J26*K26 -> 0.55177264 | M26: 1 | N26: =L26*M26 -> 0.55177264
B27: 150000018 | C27: Vảy PET B3_A6 | D27: 39159010 | E27: UNComtrade | F27: IP | G27: ='EX-2.1 Chai & vảy'!$D$69 -> 0.55177264 | H27: USD/KG | I27: KG | J27: 1 | K27: ='EX-3 CPI'!$D$38 -> 1 | L27: =G27/J27*K27 -> 0.55177264 | M27: 1 | N27: =L27*M27 -> 0.55177264
B28: 150000061 | C28: Vảy PET B6.2_A6 | D28: 39159010 | E28: UNComtrade | F28: IP | G28: ='EX-2.1 Chai & vảy'!$D$69 -> 0.55177264 | H28: USD/KG | I28: KG | J28: 1 | K28: ='EX-3 CPI'!$D$38 -> 1 | L28: =G28/J28*K28 -> 0.55177264 | M28: 1 | N28: =L28*M28 -> 0.55177264
B29: 120003031 | C29: Hạt TiO2 White MTP | D29: 32061990 | E29: UNComtrade | F29: IP | G29: ='EX-2.3 Phụ gia 409'!$G$6 -> 4.8268556 | H29: USD/KG | I29: KG | J29: 1 | K29: ='EX-3 CPI'!$D$38 -> 1 | L29: =G29/J29*K29 -> 4.8268556 | M29: 1 | N29: =L29*M29 -> 4.8268556
B30: 120003027 | C30: Lỏng TiO2 Gumi White 2 | D30: 32061990 | E30: UNComtrade | F30: IP | G30: ='EX-2.3 Phụ gia 409'!$G$6 -> 4.8268556 | H30: USD/KG | I30: KG | J30: 1 | K30: ='EX-3 CPI'!$D$38 -> 1 | L30: =G30/J30*K30 -> 4.8268556 | M30: 1 | N30: =L30*M30 -> 4.8268556
B31: 700000185 | C31: Phá bọt Antifoam CS04 | D31: 38249970 | E31: UNComtrade | F31: IP | G31: ='EX-2.6 Phá bọt'!D6 -> 4.7189261 | H31: USD/KG | I31: KG | J31: 1 | K31: ='EX-3 CPI'!$D$38 -> 1 | L31: =G31/J31*K31 -> 4.7189261 | M31: 1 | N31: =L31*M31 -> 4.7189261
B32: 120002594 | C32: Thủy tinh lỏng Na2SiO3.9H2O | D32: 28391990 | E32: UNComtrade | F32: IP | G32: ='EX-2.7- Thủy tinh lỏng'!D6 -> 0.58017401 | H32: USD/KG | I32: KG | J32: 1 | K32: ='EX-3 CPI'!$D$38 -> 1 | L32: =G32/J32*K32 -> 0.58017401 | M32: 1 | N32: =L32*M32 -> 0.58017401
B33: 700000180 | C33: Sodium Hydroxide (32%) NaOH (rắn) | D33: 28151100 | E33: UNComtrade | F33: IP | G33: ='EX-2.8 Sodium 281511'!$D$6 -> 0.87114878 | H33: USD/KG | I33: KG | J33: 1 | K33: ='EX-3 CPI'!$D$38 -> 1 | L33: =G33/J33*K33 -> 0.87114878 | M33: 1 | N33: =L33*M33 -> 0.87114878
B34: 700000180 | C34: Sodium Hydroxide (32%) NaOH (lỏng) | D34: 28151200 | E34: UNComtrade | F34: IP | G34: ='EX-2.9 Sodium 281512'!D6 -> 0.45179295 | H34: USD/KG | I34: KG | J34: 1 | K34: ='EX-3 CPI'!$D$38 -> 1 | L34: =G34/J34*K34 -> 0.45179295 | M34: 1 | N34: =L34*M34 -> 0.45179295
B35: 140005072 | C35: Bao Jumbo 950x950x1300mm Đai Trắng rPET | D35: 39232990 | E35: UNComtrade | F35: IP | G35: ='EX-2.11 Bao bì'!$D$6 -> 6.3871807 | H35: USD/KG | I35: KG | J35: 1 | K35: ='EX-3 CPI'!$D$38 -> 1 | L35: =G35/J35*K35 -> 6.3871807 | M35: 1 | N35: =L35*M35 -> 6.3871807
B36: 140006135 | C36: Bao PE 2000x2700x5z | D36: 39232990 | E36: UNComtrade | F36: IP | G36: ='EX-2.11 Bao bì'!$D$6 -> 6.3871807 | H36: USD/KG | I36: KG | J36: 1 | K36: ='EX-3 CPI'!$D$38 -> 1 | L36: =G36/J36*K36 -> 6.3871807 | M36: 1 | N36: =L36*M36 -> 6.3871807
B37: 140006103 | C37: Bao PE lót ngoài 2000x2700x7z | D37: 39232990 | E37: UNComtrade | F37: IP | G37: ='EX-2.11 Bao bì'!$D$6 -> 6.3871807 | H37: USD/KG | I37: KG | J37: 1 | K37: ='EX-3 CPI'!$D$38 -> 1 | L37: =G37/J37*K37 -> 6.3871807 | M37: 1 | N37: =L37*M37 -> 6.3871807
B38: 140006125 | C38: Bao Jumbo 950x950x1300mm Đai Xanh Xơ Sợi | D38: 39232990 | E38: UNComtrade | F38: IP | G38: ='EX-2.11 Bao bì'!$D$6 -> 6.3871807 | H38: USD/KG | I38: KG | J38: 1 | K38: ='EX-3 CPI'!$D$38 -> 1 | L38: =G38/J38*K38 -> 6.3871807 | M38: 1 | N38: =L38*M38 -> 6.3871807
B39: 140006123 | C39: Bao jumbo 950x950x1300mm_Không logo | D39: 39232990 | E39: UNComtrade | F39: IP | G39: ='EX-2.11 Bao bì'!$D$6 -> 6.3871807 | H39: USD/KG | I39: KG | J39: 1 | K39: ='EX-3 CPI'!$D$38 -> 1 | L39: =G39/J39*K39 -> 6.3871807 | M39: 1 | N39: =L39*M39 -> 6.3871807
B40: 140006107 | C40: Pallet gỗ 1 mặt 1100x1000x100mm | D40: 44152000 | E40: UNComtrade | F40: IP | G40: ='EX-2.10 Pallet gỗ'!D6 -> 12.096353 | H40: USD/KG | I40: KG | J40: 1 | K40: ='EX-3 CPI'!$D$38 -> 1 | L40: =G40/J40*K40 -> 12.096353 | M40: 1 | N40: =L40*M40 -> 12.096353
B42: DIRLAB | C42: Direct Labor | D42: n/a | F42: 2022 | G42: ='EX-5A LABOR'!$I$20 -> 0.93853993 | H42: USD/Hour | I42: Hour | J42: 1 | K42: =VLOOKUP(F42,'EX-3 CPI'!$B$33:$D$38,3,0) -> 1.6090119 | L42: =G42/J42*K42 -> 1.5101219 | M42: 1 | N42: =L42*M42 -> 1.5101219
B43: INDLAB | C43: Indirect Labor | D43: n/a | F43: 2022 | G43: ='EX-5A LABOR'!$I$20 -> 0.93853993 | H43: USD/Hour | I43: Hour | J43: 1 | K43: =VLOOKUP(F43,'EX-3 CPI'!$B$33:$D$38,3,0) -> 1.6090119 | L43: =G43/J43*K43 -> 1.5101219 | M43: 1 | N43: =L43*M43 -> 1.5101219
...

Sheet Movement
B1: Doing Business in Egypt, Arab Rep. - World Bank Group
B3: IP
B4: Domestic Brokerage & Handling - Import | C4: 554
B5: Domestic Brokerage & Handling - Export | C5: 258
B7: Inland Freight Trucking Expense - Import | C7: =D7/E7 -> 1.3392857 | D7: 300 | E7: 224
B8: Inland Freight Trucking Expense - Export | C8: =D8/E7 -> 1.2053571 | D8: 270
B9: Quantity | C9: 15000

Sheet Water
B2: Egypt - Bottled water - price, January 2024 | GlobalProductPrices.com
B3: First price hike on water bills for Egyptian households in nearly a decade - Economy - Business - Ahram Online
B5: Egypt - Bottled water - price, January 2024
B6: EGP | C6: 5.35
B7: USD | C7: 0.11
B8: EUR | C8: 0.101

Sheet NME list
B2: EXCLUDE NME COUNTRIES
B3: Republic of Armenia (see 57 FR 23380) Review Request Submitted by the Government of Armenia on 12/21/2023
B4: Republic of Azerbaijan (see 57 FR 23380)
B5: Republic of Belarus (see 57 FR 23380)
B6: People’s Republic of China (see 82 FR 50858)
B7: Georgia (see 57 FR 23380)
B8: Kyrgyz Republic (see 57 FR 23380)
B9: Republic of Moldova (see 57 FR 23380)
B10: Russian Federation (see 87 FR 69002)
B11: Republic of Tajikistan (see 57 FR 23380)
B12: Turkmenistan (see 57 FR 23380)
B13: Republic of Uzbekistan (see 57 FR 23380)
B14: Socialist Republic of Vietnam (see 68 FR 37116)

Sheet Export Data
A1: List of exporters for the selected product in 2023
A2: Product : 3907 Polyacetals, other polyethers and epoxide resins, in primary forms; polycarbonates, alkyd resins, ...
A4: Sources: ITC calculations based on UN COMTRADE and ITC statistics.
A5: The world aggregation represents the sum of reporting and non reporting countries
A6: The data in orange represents mirror figures based on partner data.
A7: The quantities shown in dark green are estimated by ITC. For further information, please refer to the ITC explanatory note.
A8: The quantities shown in light green are estimated by UNSD. For further information, please refer to the UNSD explanatory note.
A11: Exporters | B11: Select your indicators
B12: Value exported in 2023 (USD thousand) | C12: Trade balance in 2023 (USD thousand) | D12: Quantity exported in 2023 | E12: Quantity Unit | F12: Unit value (USD/unit) | G12: Annual growth in value between 2019-2023 (%) | H12: Annual growth in quantity between 2019-2023 (%) | I12: Annual growth in value between 2022-2023 (%) | J12: Share in world exports (%) | K12: Average distance of importing countries (km) | L12: Concentration of importing countries
A13: World | B13: 62971259 | C13: -1390078 | D13: 0 | E13: No quantity | G13: 7 | H13: 3 | I13: -20 | J13: 100 | K13: 4181 | L13: 0.04
A14: China | B14: 10750920 | C14: 3781429 | D14: 8553332 | E14: Tons | F14: 1257 | G14: 20 | H14: 18 | I14: -9 | J14: 17.1 | K14: 6925 | L14: 0.03
A15: United States of America | B15: 5633830 | C15: 1150654 | D15: 1666353 | E15: Tons | F15: 3381 | G15: 3 | H15: -4 | I15: -17 | J15: 8.9 | K15: 5795 | L15: 0.17
A16: Korea, Republic of | B16: 5306241 | C16: 4051463 | D16: 2653321 | E16: Tons | F16: 2000 | G16: 6 | H16: 0 | I16: -22 | J16: 8.4 | K16: 5987 | L16: 0.09
A17: Germany | B17: 4885272 | C17: 636425 | D17: 1454792 | E17: Tons | F17: 3358 | G17: 4 | H17: -5 | I17: -21 | J17: 7.8 | K17: 1955 | L17: 0.05
A18: Netherlands | B18: 4148736 | C18: 2950183 | D18: 1702960 | E18: Tons | F18: 2436 | G18: 4 | H18: -5 | I18: -27 | J18: 6.6 | K18: 1665 | L18: 0.09
A19: Taipei, Chinese | B19: 3703519 | C19: 2864429 | D19: 2167075 | E19: Tons | F19: 1709 | G19: 3 | H19: -1 | I19: -31 | J19: 5.9 | K19: 4749 | L19: 0.17
A20: Belgium | B20: 3402459 | C20: 1305108 | D20: 1346318 | E20: Tons | F20: 2527 | G20: 11 | H20: 1 | I20: -18 | J20: 5.4 | K20: 1513 | L20: 0.11
A21: Italy | B21: 2433530 | C21: -464295 | D21: 689765 | E21: Tons | F21: 3528 | G21: 10 | H21: 1 | I21: -11 | J21: 3.9 | K21: 2579 | L21: 0.07
A22: Thailand | B22: 2365823 | C22: 1290115 | D22: 1385727 | E22: Tons | F22: 1707 | G22: 6 | H22: 1 | I22: -16 | J22: 3.8 | K22: 4339 | L22: 0.11
A23: Japan | B23: 2335669 | C23: 46630 | D23: 576440 | E23: Tons | F23: 4052 | G23: -1 | H23: -2 | I23: -18 | J23: 3.7 | K23: 4082 | L23: 0.18
A24: Spain | B24: 1851425 | C24: 413147 | D24: 0 | E24: No quantity | G24: 3 | I24: -23 | J24: 2.9 | K24: 2162 | L24: 0.09
A25: Singapore | B25: 1344380 | C25: 770473 | D25: 588010 | E25: Tons | F25: 2286 | G25: 0 | H25: -2 | I25: -16 | J25: 2.1 | K25: 3817 | L25: 0.1
A26: Türkiye | B26: 1171798 | C26: -402327 | D26: 715815 | E26: Tons | F26: 1637 | G26: 25 | H26: 18 | I26: -15 | J26: 1.9 | K26: 2396 | L26: 0.06
A27: Malaysia | B27: 1155784 | C27: 204025 | D27: 764477 | E27: Tons | F27: 1512 | G27: 3 | H27: -2 | I27: -17 | J27: 1.8 | K27: 5655 | L27: 0.1
A28: Saudi Arabia | B28: 990414 | C28: 699800 | D28: 0 | E28: No quantity | G28: -4 | H28: -2 | I28: -40 | J28: 1.6 | K28: 5330 | L28: 0.13
A29: France | B29: 949718 | C29: -1104836 | D29: 352503 | E29: Tons | F29: 2694 | G29: 5 | H29: -2 | I29: -15 | J29: 1.5 | K29: 1582 | L29: 0.09
A30: Viet Nam | B30: 920122 | C30: -1032936 | D30: 761238 | E30: Tons | F30: 1209 | G30: 24 | H30: 13 | I30: -15 | J30: 1.5 | K30: 7994 | L30: 0.08
A31: United Kingdom | B31: 731627 | C31: -793396 | D31: 83941 | E31: Tons | F31: 8716 | G31: 3 | H31: -7 | I31: -16 | J31: 1.2 | K31: 3898 | L31: 0.12
A32: India | B32: 726681 | C32: -1765103 | D32: 570472 | E32: Tons | F32: 1274 | G32: -7 | H32: -14 | I32: -42 | J32: 1.2 | K32: 5928 | L32: 0.03
A33: Mexico | B33: 695311 | C33: -1964590 | D33: 0 | E33: No quantity | G33: 9 | I33: -31 | J33: 1.1 | K33: 2054 | L33: 0.71
A34: Poland | B34: 638928 | C34: -529542 | D34: 0 | E34: No quantity | G34: 19 | I34: -11 | J34: 1 | K34: 1005 | L34: 0.17
A35: Switzerland | B35: 634341 | C35: 32969 | D35: 100134 | E35: Tons | F35: 6335 | G35: 5 | H35: -2 | I35: -4 | J35: 1 | K35: 2538 | L35: 0.17
A36: Lithuania | B36: 617698 | C36: 445551 | D36: 485172 | E36: Tons | F36: 1273 | G36: 5 | H36: -3 | I36: -33 | J36: 1 | K36: 1224 | L36: 0.1
A37: Canada | B37: 533376 | C37: -603922 | D37: 182228 | E37: Tons | F37: 2927 | G37: 9 | H37: 0 | I37: -9 | J37: 0.8 | K37: 1834 | L37: 0.85
A38: Hong Kong, China | B38: 458319 | C38: 34436 | D38: 125286 | E38: Tons | F38: 3658 | G38: -19 | H38: -23 | I38: -36 | J38: 0.7 | K38: 1204 | L38: 0.79
A39: Egypt | B39: 453422 | C39: 126327 | D39: 345576 | E39: Tons | F39: 1312 | G39: 16 | H39: 6 | I39: -30 | J39: 0.7 | K39: 2877 | L39: 0.15
A40: Austria | B40: 392195 | C40: -296278 | D40: 94440 | E40: Tons | F40: 4153 | G40: 7 | H40: 1 | I40: -5 | J40: 0.6 | K40: 1549 | L40: 0.14
A41: Czech Republic | B41: 357483 | C41: -588773 | D41: 110298 | E41: Tons | F41: 3241 | G41: 8 | H41: -4 | I41: -27 | J41: 0.6 | K41: 777 | L41: 0.13
A42: Indonesia | B42: 286712 | C42: -737589 | D42: 300476 | E42: Tons | F42: 954 | G42: -5 | H42: -8 | I42: -2 | J42: 0.5 | K42: 6346 | L42: 0.1
A43: Oman | B43: 222355 | C43: 172393 | D43: 0 | E43: No quantity | G43: 13 | H43: 6 | I43: -64 | J43: 0.4 | K43: 7473 | L43: 0.13
...

Sheet Imports Data
A1: List of importers for the selected product in 2023
A2: Product : 3907 Polyacetals, other polyethers and epoxide resins, in primary forms; polycarbonates, alkyd resins, ...
A4: Sources: ITC calculations based on UN COMTRADE and ITC statistics.
A5: The world aggregation represents the sum of reporting and non reporting countries
A6: The data in orange represents mirror figures based on partner data.
A7: The quantities shown in dark green are estimated by ITC. For further information, please refer to the ITC explanatory note.
A8: The quantities shown in light green are estimated by UNSD. For further information, please refer to the UNSD explanatory note.
A11: Importers | B11: Select your indicators
B12: Value imported in 2023 (USD thousand) | C12: Trade balance in 2023 (USD thousand) | D12: Quantity imported in 2023 | E12: Quantity Unit | F12: Unit value (USD/unit) | G12: Annual growth in value between 2019-2023 (%) | H12: Annual growth in quantity between 2019-2023 (%) | I12: Annual growth in value between 2022-2023 (%) | J12: Share in world imports (%) | K12: Average distance of supplying countries (km) | L12: Concentration of supplying countries | M12: Average tariff (estimated) applied by the country (%)
A13: World | B13: 64361337 | C13: -1390078 | D13: 0 | E13: No quantity | G13: 6 | H13: 1 | I13: -22 | J13: 100 | K13: 4357 | L13: 0.07
A14: China | B14: 6969491 | C14: 3781429 | D14: 2904246 | E14: Tons | F14: 2400 | G14: -4 | H14: -8 | I14: -29 | J14: 10.8 | K14: 4171 | L14: 0.12 | M14: 7.9
A15: United States of America | B15: 4483176 | C15: 1150654 | D15: 2061898 | E15: Tons | F15: 2174 | G15: 16 | H15: 10 | I15: -32 | J15: 7 | K15: 8341 | L15: 0.1 | M15: 2.6
A16: Germany | B16: 4248847 | C16: 636425 | D16: 1498786 | E16: Tons | F16: 2835 | G16: 6 | H16: -1 | I16: -21 | J16: 6.6 | K16: 2047 | L16: 0.09 | M16: 2.1
A17: Italy | B17: 2897825 | C17: -464295 | D17: 1410475 | E17: Tons | F17: 2055 | G17: 10 | H17: 2 | I17: -21 | J17: 4.5 | K17: 2609 | L17: 0.1 | M17: 2.1
A18: Mexico | B18: 2659901 | C18: -1964590 | D18: 0 | E18: No quantity | G18: 10 | I18: -9 | J18: 4.1 | K18: 5377 | L18: 0.41 | M18: 3.8
A19: India | B19: 2491784 | C19: -1765103 | D19: 1407387 | E19: Tons | F19: 1771 | G19: 13 | H19: 5 | I19: -4 | J19: 3.9 | K19: 4712 | L19: 0.14 | M19: 6
A20: Japan | B20: 2289039 | C20: 46630 | D20: 1343808 | E20: Tons | F20: 1703 | G20: 3 | H20: -2 | I20: -18 | J20: 3.6 | K20: 3798 | L20: 0.16 | M20: 0.7
A21: Belgium | B21: 2097351 | C21: 1305108 | D21: 858651 | E21: Tons | F21: 2443 | G21: 14 | H21: 5 | I21: -25 | J21: 3.3 | K21: 3349 | L21: 0.1 | M21: 2.1
A22: France | B22: 2054554 | C22: -1104836 | D22: 870361 | E22: Tons | F22: 2361 | G22: 6 | H22: -3 | I22: -17 | J22: 3.2 | K22: 1768 | L22: 0.12 | M22: 2.1
A23: Viet Nam | B23: 1953058 | C23: -1032936 | D23: 1222438 | E23: Tons | F23: 1598 | G23: 5 | H23: 2 | I23: -16 | J23: 3 | K23: 2508 | L23: 0.23 | M23: 1.9
A24: Türkiye | B24: 1574125 | C24: -402327 | D24: 780423 | E24: Tons | F24: 2017 | G24: 11 | H24: 3 | I24: -28 | J24: 2.4 | K24: 5034 | L24: 0.14 | M24: 3.2
A25: United Kingdom | B25: 1525023 | C25: -793396 | D25: 599861 | E25: Tons | F25: 2542 | G25: 9 | H25: 3 | I25: -19 | J25: 2.4 | K25: 2531 | L25: 0.09 | M25: 1.4
A26: Spain | B26: 1438278 | C26: 413147 | D26: 0 | E26: No quantity | G26: 11 | I26: -18 | J26: 2.2 | K26: 3187 | L26: 0.09 | M26: 2.1
A27: Korea, Republic of | B27: 1254778 | C27: 4051463 | D27: 577362 | E27: Tons | F27: 2173 | G27: 6 | H27: 3 | I27: -11 | J27: 1.9 | K27: 3495 | L27: 0.25 | M27: 3.6
A28: Netherlands | B28: 1198553 | C28: 2950183 | D28: 453508 | E28: Tons | F28: 2643 | G28: 1 | H28: -5 | I28: -26 | J28: 1.9 | K28: 3270 | L28: 0.14 | M28: 2.1
A29: Poland | B29: 1168470 | C29: -529542 | D29: 526403 | E29: Tons | F29: 2220 | G29: 10 | H29: 6 | I29: -18 | J29: 1.8 | K29: 2392 | L29: 0.08 | M29: 2.1
A30: Canada | B30: 1137298 | C30: -603922 | D30: 429663 | E30: Tons | F30: 2647 | G30: 8 | H30: 2 | I30: -16 | J30: 1.8 | K30: 3428 | L30: 0.54 | M30: 0.3
A31: Thailand | B31: 1075708 | C31: 1290115 | D31: 403630 | E31: Tons | F31: 2665 | G31: 5 | H31: -1 | I31: -14 | J31: 1.7 | K31: 4089 | L31: 0.17 | M31: 2.4
A32: Indonesia | B32: 1024301 | C32: -737589 | D32: 659303 | E32: Tons | F32: 1554 | G32: 6 | H32: 3 | I32: -22 | J32: 1.6 | K32: 4865 | L32: 0.18 | M32: 3.5
A33: Russian Federation | B33: 1000099 | C33: -930560 | D33: 610129 | E33: Tons | F33: 1639 | G33: 12 | H33: 11 | I33: -11 | J33: 1.6 | K33: 4026 | L33: 0.38 | M33: 3.2
A34: Malaysia | B34: 951759 | C34: 204025 | D34: 486053 | E34: Tons | F34: 1958 | G34: 4 | H34: 1 | I34: -24 | J34: 1.5 | K34: 3952 | L34: 0.15 | M34: 3.6
A35: Czech Republic | B35: 946256 | C35: -588773 | D35: 355663 | E35: Tons | F35: 2661 | G35: 6 | I35: -11 | J35: 1.5 | K35: 1403 | L35: 0.16 | M35: 2.1
A36: Brazil | B36: 876307 | C36: -681644 | D36: 434690 | E36: Tons | F36: 2016 | G36: 11 | H36: 5 | I36: -21 | J36: 1.4 | K36: 12481 | L36: 0.16 | M36: 11.1
A37: Taipei, Chinese | B37: 839090 | C37: 2864429 | D37: 305202 | E37: Tons | F37: 2749 | G37: 0 | H37: -1 | I37: -29 | J37: 1.3 | K37: 3676 | L37: 0.17 | M37: 2.6
A38: Austria | B38: 688473 | C38: -296278 | D38: 239552 | E38: Tons | F38: 2874 | G38: 6 | H38: -4 | I38: -21 | J38: 1.1 | K38: 1154 | L38: 0.26 | M38: 2.1
A39: United Arab Emirates | B39: 668314 | C39: -539065 | D39: 0 | E39: No quantity | G39: 21 | H39: 28 | I39: -16 | J39: 1 | K39: 5545 | L39: 0.36 | M39: 4.5
A40: Portugal | B40: 642930 | C40: -525852 | D40: 0 | E40: No quantity | G40: 13 | I40: -16 | J40: 1 | K40: 2444 | L40: 0.22 | M40: 2.1
A41: Switzerland | B41: 601372 | C41: 32969 | D41: 177815 | E41: Tons | F41: 3382 | G41: 7 | H41: 0 | I41: -16 | J41: 0.9 | K41: 2972 | L41: 0.12 | M41: 0.1
A42: Hungary | B42: 576155 | C42: -380050 | D42: 0 | E42: No quantity | G42: 6 | I42: -21 | J42: 0.9 | K42: 2712 | L42: 0.09 | M42: 2.1
A43: Romania | B43: 574385 | C43: -384262 | D43: 0 | E43: No quantity | G43: 9 | I43: -10 | J43: 0.9 | K43: 1704 | L43: 0.1 | M43: 2.1
...

Sheet Costing flow
B2: LƯU ĐỒ TÍNH GIÁ THÀNH
AA4: FOP
AA9: OVH COST
B32: 1001603000 | C32: Khối SX - Xưởng 1 | D32: Khối gián tiếp
B33: 1001604000 | C33: Khối SX - Xưởng 2 | D33: Khối gián tiếp | G33: 1001602000 | H33: Xưởng sản xuất PET
B34: 1001605000 | C34: Khối SX - Xưởng 4 | D34: Khối gián tiếp | G34: 1001606000 | H34: Xưởng sản xuất HDPE
B35: 1001601500 | C35: Nghiên Cứu & Phát Triển | D35: Khối gián tiếp
B36: 1001607000 | C36: Kho | D36: Khối gián tiếp
B37: 1001601200 | C37: Khối SX - Kế hoạch | D37: Khối gián tiếp
B38: 1001601300 | C38: Kỹ thuật | D38: Khối gián tiếp
B39: 1001601400 | C39: Kiểm soát chất lượng | D39: Khối gián tiếp
B42: 1001608000 | C42: Xưởng sản xuất PP

Sheet EX-1B Data source
A1: Aluminum Wire and Cable from the People’s Republic of China (A-570-095, C-570-096)
A2: Circumvention & Scope Inquiries: Vietnam
A3: Vietnam Part - Surrogate Values from Indonesia
A5: Data source
A7: Exhibit | B7: Description | C7: Data source
A8: 1 | B8: Surrogate Value Summary Sheet
A9: 2 | B9: Trademap - Indonesia Import Data | C9: https://www.trademap.org/Index.aspx
A10: 3 | B10: Indonesia Exchange Rate | C10: https://access.trade.gov/resources/exchange/index.html
A11: 4 | B11: Consumer Price Index-Indonesia | C11: https://data.imf.org/regular.aspx?key=61545849
A12: 5A | B12: Labor Calculation | C12: https://rshiny.ilo.org/dataexplorer54/?lang=en&id=IDN_A
A13: 5B | B13: ILOSTAT Data
A14: 6A | B14: Electricity Rate Summary | C14: https://web.pln.co.id/pelanggan/tarif-tenaga-listrik/tariff-adjustment
A15: 6B | B15: PLN Tariff Rates
A16: 9A | B16: Freight Rate Summary | C16: https://archive.doingbusiness.org/content/dam/doingBusiness/country/i/indonesia/IDN.pdf
A17: 9B | B17: Doing Business Indonesia
A18: 10A | B18: Financial Ratio Summary
A19: 10B1 | B19: Financial Ratio Calculations - KMI | C19: https://kmi.id/index.php/investor/financial-statement
A20: 10B2 | B20: KMI Financial Statement
A21: 10C1 | B21: Financial Ratio Calculations - VOKSEL | C21: https://www.voksel.co.id/en/financial_report
A22: 10C2 | B22: VOKSEL Financial Statement

Sheet EX-2.1 Chai & vảy
B1: List of supplying markets for a product imported by Egypt | E1: ='EX-1A SV Summary'!D8 -> 39159010
B2: Product: Plastics n.e.c. in heading no. 3915; waste, parings and scrap
B3: Link: | C3: UN Comtrade
B5: EXCLUDE | C5: World
C6: China
C7: Hong Kong, China
C8: Taipei, Chinese
C9: Russian Federation
A11: 1/ | B11: Quantity | S11: PERIOD OF INVESTIGATION | T11: Y
B12: Unit : ton | S12: flowDesc | T12: Import
S13: reporterDesc | T13: Egypt
C14: 2023 | I14: 2024 | O14: Grand Total | P14: Mark | Q14: Note
B15: partnerDesc/ month | C15: 7 | D15: 8 | E15: 9 | F15: 10 | G15: 11 | H15: 12 | I15: 1 | J15: 2 | K15: 3 | L15: 4 | M15: 5 | N15: 6 | S15: Sum of qty | T15: refYear | U15: refMonth
B16: World | C16: 1798598.4 | D16: 1150297.3 | E16: 1594909.6 | F16: 1886942.6 | G16: 2965111.9 | H16: 401290.57 | I16: 2857655.9 | J16: 2209983 | K16: 3903209.6 | L16: 3086149.9 | M16: 776351.35 | N16: 899867.08 | O16: 23530367 | P16: Exclude | T16: 2023 | Z16: 2024 | AF16: Grand Total
B17: Spain | D17: 112718.34 | E17: 186577.67 | F17: 741812.51 | G17: 2003614.7 | H17: 116959.41 | I17: 1554447.4 | J17: 1309526.1 | K17: 1709751.1 | L17: 1305342.8 | M17: 55817.316 | N17: 85018.433 | O17: 9181585.7 | P17: Include | Q17: Qty | S17: partnerDesc | T17: 7 | U17: 8 | V17: 9 | W17: 10 | X17: 11 | Y17: 12 | Z17: 1 | AA17: 2 | AB17: 3 | AC17: 4 | AD17: 5 | AE17: 6
B18: Yemen | C18: 1213316.3 | E18: 790886.02 | F18: 377588.07 | I18: 1083004.5 | K18: 1541964.3 | L18: 972510.51 | N18: 808887.86 | O18: 6788157.6 | P18: Include | Q18: Qty | S18: World | T18: 1798598.4 | U18: 1150297.3 | V18: 1594909.6 | W18: 1886942.6 | X18: 2965111.9 | Y18: 401290.57 | Z18: 2857655.9 | AA18: 2209983 | AB18: 3903209.6 | AC18: 3086149.9 | AD18: 776351.35 | AE18: 899867.08 | AF18: 23530367
B19: Türkiye | D19: 252442.15 | E19: 162114.02 | F19: 194420.92 | G19: 283785.42 | H19: 191233.02 | J19: 271848.64 | K19: 248505.58 | L19: 297114.45 | M19: 187705.03 | O19: 2089169.2 | P19: Include | Q19: Qty | S19: Spain | U19: 112718.34 | V19: 186577.67 | W19: 741812.51 | X19: 2003614.7 | Y19: 116959.41 | Z19: 1554447.4 | AA19: 1309526.1 | AB19: 1709751.1 | AC19: 1305342.8 | AD19: 55817.316 | AE19: 85018.433 | AF19: 9181585.7
B20: Senegal | D20: 555376.43 | G20: 174744.25 | J20: 434372.61 | M20: 461061.17 | O20: 1625554.5 | P20: Include | Q20: Qty | S20: Yemen | T20: 1213316.3 | V20: 790886.02 | W20: 377588.07 | Z20: 1083004.5 | AB20: 1541964.3 | AC20: 972510.51 | AE20: 808887.86 | AF20: 6788157.6
B21: United Arab Emirates | E21: 198360.69 | F21: 16039.217 | G21: 463874.95 | H21: 9991.435 | K21: 117126.13 | O21: 805392.42 | P21: Include | Q21: Qty | S21: Türkiye | U21: 252442.15 | V21: 162114.02 | W21: 194420.92 | X21: 283785.42 | Y21: 191233.02 | AA21: 271848.64 | AB21: 248505.58 | AC21: 297114.45 | AD21: 187705.03 | AF21: 2089169.2
B22: Italy | C22: 410741.67 | F22: 16060.965 | J22: 154701.26 | K22: 55098.784 | M22: 58671.56 | N22: 5960.789 | O22: 701235.03 | P22: Include | Q22: Qty | S22: Senegal | U22: 555376.43 | X22: 174744.25 | AA22: 434372.61 | AD22: 461061.17 | AF22: 1625554.5
B23: United Kingdom | E23: 120527.34 | F23: 286475.9 | I23: 105431.31 | M23: 13096.269 | O23: 525530.82 | P23: Include | Q23: Qty | S23: United Arab Emirates | V23: 198360.69 | W23: 16039.217 | X23: 463874.95 | Y23: 9991.435 | AB23: 117126.13 | AF23: 805392.42
B24: Netherlands | C24: 91298.79 | F24: 231700.51 | L24: 201119.93 | O24: 524119.23 | P24: Include | Q24: Qty | S24: Italy | T24: 410741.67 | W24: 16060.965 | AA24: 154701.26 | AB24: 55098.784 | AD24: 58671.56 | AE24: 5960.789 | AF24: 701235.03
B25: Germany | G25: 38390.017 | H25: 22186.675 | I25: 73351.927 | K25: 206114.12 | O25: 340042.74 | P25: Include | Q25: Qty | S25: United Kingdom | V25: 120527.34 | W25: 286475.9 | Z25: 105431.31 | AD25: 13096.269 | AF25: 525530.82
B26: Lebanon | L26: 285950.78 | O26: 285950.78 | P26: Include | Q26: Qty | S26: Netherlands | T26: 91298.79 | W26: 231700.51 | AC26: 201119.93 | AF26: 524119.23
B27: China | C27: 27166.987 | E27: 136443.89 | H27: 60920.02 | O27: 224530.89 | P27: Exclude | S27: Germany | X27: 38390.017 | Y27: 22186.675 | Z27: 73351.927 | AB27: 206114.12 | AF27: 340042.74
B28: Nigeria | D28: 138642.02 | O28: 138642.02 | P28: Include | Q28: Qty | S28: Lebanon | AC28: 285950.78 | AF28: 285950.78
B29: United Rep. of Tanzania | D29: 91118.38 | O29: 91118.38 | P29: Include | Q29: Qty | S29: China | T29: 27166.987 | V29: 136443.89 | Y29: 60920.02 | AF29: 224530.89
B30: Greece | C30: 56074.632 | F30: 22844.554 | O30: 78919.186 | P30: Include | Q30: Qty | S30: Nigeria | U30: 138642.02 | AF30: 138642.02
B31: Other Europe, nes | I31: 41420.707 | O31: 41420.707 | P31: Include | Q31: Qty | S31: United Rep. of Tanzania | U31: 91118.38 | AF31: 91118.38
B32: France | J32: 39534.404 | O32: 39534.404 | P32: Include | Q32: Qty | S32: Greece | T32: 56074.632 | W32: 22844.554 | AF32: 78919.186
B33: Portugal | K33: 24649.646 | O33: 24649.646 | P33: Include | Q33: Qty | S33: Other Europe, nes | Z33: 41420.707 | AF33: 41420.707
B34: Belgium | L34: 24111.398 | O34: 24111.398 | P34: Include | Q34: Qty | S34: France | AA34: 39534.404 | AF34: 39534.404
B35: USA | G35: 702.49 | O35: 702.49 | P35: Include | Q35: Qty | S35: Portugal | AB35: 24649.646 | AF35: 24649.646
B36: Grand Total | C36: 3597196.8 | D36: 2300594.6 | E36: 3189819.2 | F36: 3773885.3 | G36: 5930223.7 | H36: 802581.13 | I36: 5715311.7 | J36: 4419965.9 | K36: 7806419.3 | L36: 6172299.8 | M36: 1552702.7 | N36: 1799734.2 | O36: 47060734 | S36: Belgium | AC36: 24111.398 | AF36: 24111.398
S37: USA | X37: 702.49 | AF37: 702.49
S38: Grand Total | T38: 3597196.8 | U38: 2300594.6 | V38: 3189819.2 | W38: 3773885.3 | X38: 5930223.7 | Y38: 802581.13 | Z38: 5715311.7 | AA38: 4419965.9 | AB38: 7806419.3 | AC38: 6172299.8 | AD38: 1552702.7 | AE38: 1799734.2 | AF38: 47060734
A39: 2/ | B39: Value
B40: Unit : US Dollar thousand | S40: PERIOD OF INVESTIGATION | T40: Y
S41: flowDesc | T41: Import
C42: 2023 | I42: 2024 | O42: Grand Total | P42: Mark | Q42: Note | S42: reporterDesc | T42: Egypt
...

Sheet EX-2.4 Phụ gia khác
A1: List of supplying markets for a product imported by Egypt | C1: ='EX-1A SV Summary'!D22 -> 32049000
A2: Product: 320490 Synthetic organic products of a kind used as luminophores, whether or not chemically defined
A3: Sources: ITC calculations based on UN COMTRADE statistics.
A5: Total quantity imported (ton) | B5: Total quantity imported (Kg) | C5: Total value imported (USD) | D5: Unit price (USD/Kg)
A6: =SUMIFS(M:M,N:N,"Include",O:O,"QTY") -> 8167 | B6: =A6*1000 -> 8167000 | C6: =SUMIFS(M:M,N:N,"Include",O:O,"Val")*1000 -> 490000 | D6: =C6/B6 -> 0.059997551
A9: Unit : US Dollar thousand
A10: Exporters | B10: Imported value in 2012 | C10: Imported value in 2013 | D10: Imported value in 2014 | E10: Imported value in 2015 | F10: Imported value in 2016 | G10: Imported value in 2017 | H10: Imported value in 2018 | I10: Imported value in 2019 | J10: Imported value in 2020 | K10: Imported value in 2021 | L10: Imported value in 2022 | M10: Imported value in 2023 | N10: Mark | O10: Note
A11: World | B11: 1194 | C11: 601 | D11: 1168 | E11: 657 | F11: 865 | G11: 617 | H11: 1214 | I11: 850 | J11: 525 | K11: 1117 | L11: 489 | M11: 604 | N11: =VLOOKUP(A11,'EX-2.3 Phụ gia 409'!$B$48:$P$72,15,0) -> Exclude
A12: India | B12: 150 | C12: 233 | D12: 391 | E12: 0 | F12: 22 | G12: 116 | H12: 22 | I12: 203 | J12: 110 | K12: 149 | L12: 40 | M12: 171 | N12: =VLOOKUP(A12,'EX-2.3 Phụ gia 409'!$B$48:$P$72,15,0) -> Include | O12: Val
A13: China | B13: 359 | C13: 94 | D13: 417 | E13: 155 | F13: 223 | G13: 28 | H13: 229 | I13: 85 | J13: 277 | K13: 384 | L13: 95 | M13: 102 | N13: =VLOOKUP(A13,'EX-2.3 Phụ gia 409'!$B$48:$P$72,15,0) -> Exclude
A14: Saudi Arabia | B14: 49 | C14: 35 | D14: 34 | E14: 0 | F14: 2 | G14: 1 | H14: 52 | I14: 0 | J14: 0 | L14: 210 | M14: 84 | N14: =VLOOKUP(A14,'EX-2.3 Phụ gia 409'!$B$48:$P$72,15,0) -> Include | O14: Val
A15: Germany | B15: 229 | C15: 40 | D15: 82 | E15: 285 | F15: 57 | G15: 69 | H15: 46 | I15: 0 | J15: 43 | K15: 3 | L15: 38 | M15: 73 | N15: =VLOOKUP(A15,'EX-2.3 Phụ gia 409'!$B$48:$P$72,15,0) -> Include | O15: Val
A16: France | B16: 9 | C16: 5 | D16: 3 | E16: 0 | F16: 0 | G16: 19 | H16: 21 | I16: 6 | J16: 0 | K16: 24 | L16: 13 | M16: 71 | N16: =VLOOKUP(A16,'EX-2.3 Phụ gia 409'!$B$48:$P$72,15,0) -> Include | O16: Val
A17: Türkiye | B17: 60 | C17: 13 | D17: 13 | E17: 59 | F17: 76 | G17: 56 | H17: 7 | I17: 6 | J17: 26 | K17: 44 | L17: 25 | M17: 32 | N17: =VLOOKUP(A17,'EX-2.3 Phụ gia 409'!$B$48:$P$72,15,0) -> Include | O17: Val
A18: Italy | B18: 26 | C18: 71 | D18: 10 | E18: 93 | F18: 76 | G18: 10 | H18: 49 | I18: 2 | J18: 1 | K18: 34 | L18: 45 | M18: 31 | N18: =VLOOKUP(A18,'EX-2.3 Phụ gia 409'!$B$48:$P$72,15,0) -> Include | O18: Val
A19: Libya, State of | B19: 0 | C19: 0 | D19: 0 | E19: 0 | F19: 0 | G19: 0 | H19: 0 | I19: 0 | J19: 0 | M19: 21 | N19: Include | O19: Val
A20: Russian Federation | B20: 0 | C20: 0 | D20: 0 | E20: 0 | F20: 0 | G20: 0 | H20: 0 | I20: 0 | J20: 0 | M20: 8 | N20: =VLOOKUP(A20,'EX-2.3 Phụ gia 409'!$B$48:$P$72,15,0) -> Exclude
A21: Sri Lanka | B21: 0 | C21: 0 | D21: 0 | E21: 0 | F21: 0 | G21: 0 | H21: 0 | I21: 0 | J21: 0 | M21: 4 | N21: Include | O21: Val
A22: Taipei, Chinese | B22: 0 | C22: 0 | D22: 64 | E22: 0 | F22: 116 | G22: 0 | H22: 0 | I22: 0 | J22: 0 | M22: 3 | N22: Exclude
A23: United States of America | B23: 138 | C23: 7 | D23: 0 | E23: 36 | F23: 0 | G23: 0 | H23: 31 | I23: 12 | J23: 22 | L23: 19 | M23: 3 | N23: Include | O23: Val
A26: List of supplying markets for a product imported by Egypt
A27: Product: 3204 Synthetic organic colouring matter, whether or not chemically defined; preparations based on ...
A28: Sources: ITC calculations based on UN COMTRADE statistics.
A30: Exporters | B30: 2012 | C30: 2013 | D30: 2014 | E30: 2015 | F30: 2016 | G30: 2017 | H30: 2018 | I30: 2019 | J30: 2020 | K30: 2021 | L30: 2022 | M30: 2023 | N30: Mark | O30: Note
B31: Imported quantity, Tons | C31: Imported quantity, Tons | D31: Imported quantity, Tons | E31: Imported quantity, Tons | F31: Imported quantity, Tons | G31: Imported quantity, Tons | H31: Imported quantity, Tons | I31: Imported quantity, Tons | J31: Imported quantity, Tons | K31: Imported quantity, Tons | L31: Imported quantity, Tons | M31: Imported quantity, Tons
A32: World | B32: No Quantity | C32: 26678 | D32: 28978 | E32: No Quantity | F32: No Quantity | G32: No Quantity | H32: No Quantity | I32: No Quantity | J32: No Quantity | K32: 13639 | L32: No Quantity | M32: No Quantity
A33: India | B33: No Quantity | C33: 5348 | D33: 7911 | E33: 3621 | F33: 3365 | G33: 3289 | H33: 3830 | I33: 3889 | J33: 3447 | K33: 4006 | L33: 3820 | M33: 3805 | N33: =VLOOKUP(A33,$A$11:$N$23,14,0) -> Include | O33: Qty
A34: China | B34: No Quantity | C34: 6708 | D34: 6137 | E34: 3624 | F34: 3149 | G34: 3769 | H34: 3458 | I34: 3492 | J34: 3283 | K34: 3938 | L34: 3402 | M34: 3364 | N34: =VLOOKUP(A34,$A$11:$N$23,14,0) -> Exclude | O34: Qty
A35: Korea, Republic of | B35: No Quantity | C35: 1952 | D35: 2095 | E35: 1644 | F35: 1678 | G35: 2033 | H35: 1973 | I35: 2071 | J35: 1727 | K35: 1947 | L35: 1543 | M35: 1342 | N35: Include | O35: Qty
A36: Türkiye | B36: No Quantity | C36: 2111 | D36: 1773 | E36: 1082 | F36: 1108 | G36: 1027 | H36: 1202 | I36: 1020 | J36: 1022 | K36: 984 | L36: 953 | M36: 878 | N36: =VLOOKUP(A36,$A$11:$N$23,14,0) -> Include | O36: Qty
A37: Switzerland | B37: No Quantity | C37: 431 | D37: 343 | E37: 526 | F37: 602 | G37: 209 | H37: 459 | I37: 151 | J37: 165 | K37: 188 | L37: 203 | M37: 427 | N37: Include | O37: Qty
A38: Germany | B38: No Quantity | C38: 2493 | D38: 1950 | E38: 982 | F38: 1026 | G38: 933 | H38: 747 | I38: 607 | J38: 472 | K38: 491 | L38: 454 | M38: 269 | N38: =VLOOKUP(A38,$A$11:$N$23,14,0) -> Include | O38: Qty
A39: Spain | B39: No Quantity | C39: 454 | D39: 482 | E39: 191 | F39: 249 | G39: 304 | H39: 295 | I39: 319 | J39: 232 | K39: 513 | L39: 269 | M39: 153 | N39: Include | O39: Qty
A40: Italy | B40: No Quantity | C40: 1213 | D40: 1278 | E40: 575 | F40: 387 | G40: 452 | H40: 335 | I40: 319 | J40: 225 | K40: 208 | L40: 184 | M40: 133 | N40: =VLOOKUP(A40,$A$11:$N$23,14,0) -> Include | O40: Qty
A41: United States of America | B41: No Quantity | C41: 702 | D41: 1900 | E41: 145 | F41: 91 | G41: 81 | H41: 99 | I41: 90 | J41: 172 | K41: 178 | L41: 185 | M41: 119 | N41: =VLOOKUP(A41,$A$11:$N$23,14,0) -> Include | O41: Qty
A42: Singapore | B42: No Quantity | C42: 258 | D42: 593 | E42: 130 | F42: 97 | G42: 72 | H42: 100 | I42: 125 | J42: 61 | K42: 74 | L42: 76 | M42: 114 | N42: Include | O42: Qty
A43: Israel | B43: No Quantity | C43: 177 | D43: 86 | E43: 7 | F43: 34 | G43: 10 | H43: 112 | I43: 50 | J43: 82 | K43: 22 | L43: 26 | M43: 113 | N43: Include | O43: Qty
A44: Canada | B44: 74 | C44: 130 | D44: 144 | E44: 48 | F44: 105 | G44: 38 | H44: 111 | I44: 120 | J44: 106 | K44: 108 | L44: 170 | M44: 100 | N44: Include | O44: Qty
A45: Thailand | B45: 65 | C45: 82 | D45: 312 | E45: 92 | F45: 79 | G45: 53 | H45: 48 | I45: 40 | J45: 24 | K45: 24 | L45: 21 | M45: 100 | N45: Include | O45: Qty
A46: United Arab Emirates | B46: No Quantity | C46: 678 | D46: 91 | E46: 64 | F46: 63 | G46: 97 | H46: 85 | I46: 117 | J46: 92 | K46: 92 | L46: 133 | M46: 93 | N46: Include | O46: Qty
...

Sheet EX-2.5 Phụ gia RHC
A1: List of supplying markets for a product imported by Egypt | D1: ='EX-1A SV Summary'!D25 -> 3206199
A2: Product: 320619 Pigments and preparations based on titanium dioxide of a kind used for colouring any material ...
A4: Sources: ITC calculations based on UN COMTRADE statistics.
A6: Total quantity imported (ton) | B6: Total quantity imported (Kg) | C6: Total value imported (USD) | D6: Unit price (USD/Kg)
A7: =SUMIFS(M:M,N:N,"Include",O:O,"QTY") -> 1342 | B7: =A7*1000 -> 1342000 | C7: =SUMIFS(M:M,N:N,"Include",O:O,"Val")*1000 -> 6474000 | D7: =C7/B7 -> 4.8241431
A9: Unit : US Dollar thousand
A11: Exporters | B11: Imported value in 2012 | C11: Imported value in 2013 | D11: Imported value in 2014 | E11: Imported value in 2015 | F11: Imported value in 2016 | G11: Imported value in 2017 | H11: Imported value in 2018 | I11: Imported value in 2019 | J11: Imported value in 2020 | K11: Imported value in 2021 | L11: Imported value in 2022 | M11: Imported value in 2023 | N11: Mark | O11: Note
A12: World | B12: 7953 | C12: 5408 | D12: 7334 | E12: 7384 | F12: 10890 | G12: 7149 | H12: 7321 | I12: 7705 | J12: 9027 | K12: 14361 | L12: 9056 | M12: 9214 | N12: Exclude | O12: Val
A13: China | B13: 229 | C13: 52 | D13: 299 | E13: 491 | F13: 2306 | G13: 555 | H13: 770 | I13: 1060 | J13: 2033 | K13: 3104 | L13: 1711 | M13: 2620 | N13: Exclude | O13: Val
A14: United States of America | B14: 476 | C14: 297 | D14: 906 | E14: 1164 | F14: 4453 | G14: 915 | H14: 1405 | I14: 995 | J14: 373 | K14: 1349 | L14: 781 | M14: 1130 | N14: Include | O14: Val
A15: United Kingdom | B15: 230 | C15: 255 | D15: 393 | E15: 189 | F15: 255 | G15: 324 | H15: 387 | I15: 384 | J15: 443 | K15: 550 | L15: 485 | M15: 1052 | N15: Include | O15: Val
A16: Germany | B16: 1159 | C16: 1713 | D16: 1366 | E16: 1888 | F16: 1516 | G16: 1477 | H16: 1591 | I16: 1385 | J16: 985 | K16: 1268 | L16: 804 | M16: 980 | N16: Include | O16: Val
A17: Japan | B17: 200 | C17: 616 | D17: 311 | E17: 585 | F17: 322 | G17: 516 | H17: 606 | I17: 504 | J17: 727 | K17: 806 | L17: 650 | M17: 809 | N17: Include | O17: Val
A18: Belgium | B18: 548 | C18: 319 | D18: 397 | E18: 84 | F18: 336 | G18: 558 | H18: 172 | I18: 587 | J18: 2048 | K18: 969 | L18: 1763 | M18: 430 | N18: Include | O18: Val
A19: Türkiye | B19: 9 | C19: 38 | D19: 4 | E19: 70 | F19: 0 | G19: 198 | H19: 0 | I19: 124 | J19: 363 | K19: 130 | L19: 117 | M19: 365 | N19: Include | O19: Val
A20: India | B20: 401 | C20: 214 | D20: 389 | E20: 386 | F20: 551 | G20: 869 | H20: 599 | I20: 970 | J20: 713 | K20: 489 | L20: 431 | M20: 353 | N20: Include | O20: Val
A21: Thailand | B21: 130 | C21: 1 | D21: 0 | E21: 123 | F21: 9 | G21: 0 | H21: 0 | I21: 7 | J21: 0 | K21: 15 | L21: 37 | M21: 337 | N21: Include | O21: Val
A22: Saudi Arabia | B22: 902 | C22: 67 | D22: 1435 | E22: 124 | F22: 44 | G22: 167 | H22: 46 | I22: 1 | J22: 385 | K22: 4487 | L22: 650 | M22: 197 | N22: Include | O22: Val
A23: Czech Republic | B23: 0 | C23: 6 | D23: 0 | E23: 0 | F23: 0 | G23: 0 | H23: 36 | I23: 171 | J23: 144 | K23: 84 | L23: 64 | M23: 189 | N23: Include | O23: Val
... A28: Hungary | B28: 0 | C28: 0 | D28: 0 | E28: 0 | F28: 0 | G28: 2 | H28: 55 | I28: 0 | J28: 77 | K28: 33 | L28: 57 | M28: 57 | N28: Include | O28: Val
A29: United Arab Emirates | B29: 65 | C29: 7 | D29: 0 | E29: 3 | F29: 2 | G29: 46 | H29: 118 | I29: 71 | J29: 2 | K29: 111 | M29: 33 | N29: Include | O29: Val
A30: Austria | B30: 11 | C30: 0 | D30: 0 | E30: 0 | F30: 0 | G30: 62 | H30: 1 | I30: 105 | J30: 90 | K30: 92 | M30: 32 | N30: Include | O30: Val
A31: Netherlands | B31: 0 | C31: 0 | D31: 123 | E31: 77 | F31: 56 | G31: 122 | H31: 31 | I31: 20 | J31: 0 | K31: 223 | L31: 2 | M31: 25 | N31: Include | O31: Val
A32: Korea, Republic of | B32: 1548 | C32: 54 | D32: 45 | E32: 228 | F32: 0 | G32: 163 | H32: 177 | I32: 81 | J32: 149 | K32: 60 | L32: 196 | M32: 12 | N32: Include | O32: Val
A33: France | B33: 37 | C33: 8 | D33: 11 | E33: 97 | F33: 58 | G33: 11 | H33: 49 | I33: 15 | J33: 9 | K33: 40 | L33: 4 | M33: 9 | N33: Include | O33: Val
A34: Finland | B34: 427 | C34: 198 | D34: 203 | E34: 109 | F34: 0 | G34: 0 | H34: 0 | I34: 0 | J34: 10 | K34: 1 | M34: 5 | N34: Include | O34: Val
A35: Russian Federation | B35: 0 | C35: 0 | D35: 0 | E35: 0 | F35: 0 | G35: 0 | H35: 0 | I35: 0 | J35: 0 | M35: 5 | N35: Exclude | O35: Val
A36: Europe Othr. Nes | B36: 0 | C36: 0 | D36: 0 | E36: 0 | F36: 0 | G36: 0 | H36: 0 | I36: 87 | J36: 36 | K36: 53 | L36: 21 | M36: 3 | N36: Include | O36: Val
A39: List of supplying markets for a product imported by Egypt
A40: Product: 320619 Pigments and preparations based on titanium dioxide of a kind used for colouring any material ...
A41: Sources: ITC calculations based on UN COMTRADE statistics.
A42: The quantities shown in light green are estimated by UNSD. For further information, please refer to the UNSD explanatory note.
A45: Exporters | B45: 2012 | C45: 2013 | D45: 2014 | E45: 2015 | F45: 2016 | G45: 2017 | H45: 2018 | I45: 2019 | J45: 2020 | K45: 2021 | L45: 2022 | M45: 2023
B46: Imported quantity, Tons | C46: Imported quantity, Tons | D46: Imported quantity, Tons | E46: Imported quantity, Tons | F46: Imported quantity, Tons | G46: Imported quantity, Tons | H46: Imported quantity, Tons | I46: Imported quantity, Tons | J46: Imported quantity, Tons | K46: Imported quantity, Tons | L46: Imported quantity, Tons | M46: Imported quantity, Tons | N46: Mark | O46: Note
A47: World | B47: 1968 | C47: 1393 | D47: 2654 | E47: 2288 | F47: 3207 | G47: 2178 | H47: 1978 | I47: 2180 | J47: 2305 | K47: 3577 | L47: 1904 | M47: 1909 | N47: =VLOOKUP(A47,$A$12:$N$36,14,0) -> Exclude | O47: Qty
A48: China | B48: 57 | C48: 262 | D48: 123 | E48: 152 | F48: 679 | G48: 169 | H48: 208 | I48: 300 | J48: 519 | K48: 773 | L48: 360 | M48: 543 | N48: =VLOOKUP(A48,$A$12:$N$36,14,0) -> Exclude | O48: Qty
A49: United States of America | B49: 118 | C49: 45 | D49: 99 | E49: 361 | F49: 1312 | G49: 279 | H49: 380 | I49: 281 | J49: 95 | K49: 336 | L49: 164 | M49: 234 | N49: =VLOOKUP(A49,$A$12:$N$36,14,0) -> Include | O49: Qty
A50: United Kingdom | B50: 57 | C50: 4 | D50: 5 | E50: 59 | F50: 75 | G50: 99 | H50: 105 | I50: 109 | J50: 113 | K50: 137 | L50: 102 | M50: 218 | N50: =VLOOKUP(A50,$A$12:$N$36,14,0) -> Include | O50: Qty
A51: Germany | B51: 287 | C51: 152 | D51: 118 | E51: 585 | F51: 447 | G51: 450 | H51: 430 | I51: 392 | J51: 252 | K51: 316 | L51: 169 | M51: 203 | N51: =VLOOKUP(A51,$A$12:$N$36,14,0) -> Include | O51: Qty
A52: Japan | B52: 50 | C52: 7 | D52: 4 | E52: 181 | F52: 95 | G52: 157 | H52: 164 | I52: 143 | J52: 186 | K52: 201 | L52: 137 | M52: 168 | N52: =VLOOKUP(A52,$A$12:$N$36,14,0) -> Include | O52: Qty
...

Sheet EX-2.3 Phụ gia 409
B1: List of supplying markets for a product imported by Egypt | E1: ='EX-1A SV Summary'!D21 -> 32061990
B2: Colouring matter; pigments and preparations based on titanium dioxide, containing less than 80% by weight of titanium dioxide calculated on the dry weight
B3: Link: | C3: UN Comtrade
B5: EXCLUDE | C5: World | E5: Total quantity imported (Kg) | F5: Total value imported (USD) | G5: Unit price (USD/Kg)
C6: China | E6: =SUMIFS(O:O,P:P,"Include",Q:Q,"QTY")*1000 -> 2.4325441e+09 | F6: =SUMIFS(O:O,P:P,"Include",Q:Q,"VAL")*1000 -> 11741539097 | G6: =F6/E6 -> 4.8268556
C7: Hong Kong, China | S7: PERIOD OF INVESTIGATION | T7: Y
C8: Taipei, Chinese | S8: flowDesc | T8: Import
C9: Russian Federation | S9: reporterDesc | T9: Egypt
A11: 1/ | B11: Quantity | S11: Sum of qty | T11: refYear | U11: refMonth
B12: Unit : ton | T12: 2023 | Z12: 2024 | AF12: Grand Total
C13: 2023 | I13: 2024 | O13: Grand Total | P13: Mark | Q13: Note | S13: partnerDesc | T13: 7 | U13: 8 | V13: 9 | W13: 10 | X13: 11 | Y13: 12 | Z13: 1 | AA13: 2 | AB13: 3 | AC13: 4 | AD13: 5 | AE13: 6
