Workbook

Sheet Sơ đồ
A1: BẢNG PHÂN TÍCH CHI PHÍ CHUỖI CUNG ỨNG
A4: CẤP THU MUA | G4: 4 | I4: 3 | K4: 2b | M4: 1
A6: THỊ TRƯỜNG | R6: PHÂN TÍCH VÀO GIAI ĐOẠN 2
A7: Đối tượng | C7: NGƯỜI TIÊU DÙNG | E7: NGƯỜI THU GOM VE CHAI | G7: VỰA (OUTLET) | I7: ĐẠI LÝ (LÁI) | K7: TRẠM XỬ LÝ CHAI | Q7: NHÀ SẢN XUẤT VẢY
A8: Chức năng | C8: Phát sinh phế liệu nhựa | E8: Nhặt, thu mua, tích trữ và bán đi | G8: Các cửa hàng thu mua phế liệu | I8: Thu gom và Vận chuyển phế liệu từ các vựa | K8: Sản xuất Chai (tách nhãn, phân loại, EK)
A9: Chi phí | C9: 0 | E9: 0 | G9: ='1.Vựa->ĐạiLý'!D16 -> 690 | I9: ='2.ĐạiLý->Chai'!D16 -> 1710 | K9: ='3.Chai->Vảy (mua hết)'!E16 -> 4466
A11: CÔNG TY
A12: Đối tượng | K12: ĐỒNG HÀNH | M12: TRẠM NỘI BỘ (CHAI) | O12: DTR (VẢY THÔ) | Q12: DTR (VẢY LẠNH/NÓNG)
A13: Chức năng | K13: Sản xuất Chai (thu mua Chai B0, ép kiện) | M13: Sản xuất Chai (mua chai, tách nhãn, phân loại, ép kiện) | O13: DTR xử lý ra vảy thô
A14: Chi phí | K14: ='2.ĐạiLý->Chai'!E16 -> 1915 | M14: ='Công ty xử lý'!D6 -> 2983 | O14: ='Công ty xử lý'!E6 -> 2316
A16: Đối tượng | M16: TRẠM NỘI BỘ (VẢY THÔ) | Q16: DTR (VẢY LẠNH/NÓNG)
A17: Chức năng | E17: ` | M17: Mua chai, phân loại, tách nhãn và sản xuất ra vảy thô
A18: Chi phí | M18: ='Công ty xử lý'!C6 -> 1378

Sheet 1.Vựa->ĐạiLý
A1: PHÂN TÍCH TÀI CHÍNH - CHẶNG: Vựa → Đại lý
A2: So sánh Nội bộ vs Bên ngoài vs OEM | Vựa phế liệu → Đại lý thu mua
A4: I. CƠ CẤU CHI PHÍ THEO KÊNH THU MUA
A5: STT | B5: Hạng mục chi phí | C5: Nội bộ (VNĐ/kg) | D5: Bên ngoài (VNĐ/kg) | E5: OEM (VNĐ/kg) | F5: Δ NB vs BN | G5: Δ NB vs OEM | H5: % Chênh lệch NB-BN | I5: Ghi chú
A6: 1 | B6: Giá thu mua nguyên liệu | C6: 5000 | D6: 5000 | E6: 5000 | F6: =C6-D6 -> 0 | G6: =C6-E6 -> 0 | H6: =IF(D6=0,0,(C6-D6)/D6) -> 0
A7: 2 | B7: Chi phí vận chuyển | C7: 1700 | D7: 690 | E7: 420 | F7: =C7-D7 -> 1010 | G7: =C7-E7 -> 1280 | H7: =IF(D7=0,0,(C7-D7)/D7) -> 1.4637681 | I7: Thời điểm bình thường, không ảnh hưởng xăng dầu (22000 đ/l), R~30km
A8: 3 | B8: Chi phí phân loại & xử lý | F8: =C8-D8 -> 0 | G8: =C8-E8 -> 0 | H8: =IF(D8=0,0,(C8-D8)/D8) -> 0
A9: 4 | B9: Chi phí ép kiện/đóng gói | F9: =C9-D9 -> 0 | G9: =C9-E9 -> 0 | H9: =IF(D9=0,0,(C9-D9)/D9) -> 0
A10: 5 | B10: Chi phí kiểm định chất lượng | F10: =C10-D10 -> 0 | G10: =C10-E10 -> 0 | H10: =IF(D10=0,0,(C10-D10)/D10) -> 0
A11: 6 | B11: Chi phí hao hụt & tạp chất | F11: =C11-D11 -> 0 | G11: =C11-E11 -> 0 | H11: =IF(D11=0,0,(C11-D11)/D11) -> 0
A12: 7 | B12: Chi phí quản lý & overhead | F12: =C12-D12 -> 0 | G12: =C12-E12 -> 0 | H12: =IF(D12=0,0,(C12-D12)/D12) -> 0
A13: 8 | B13: Chi phí tài chính (lãi vay) | F13: =C13-D13 -> 0 | G13: =C13-E13 -> 0 | H13: =IF(D13=0,0,(C13-D13)/D13) -> 0
A14: 9 | B14: Chi phí bảo hiểm & rủi ro | F14: =C14-D14 -> 0 | G14: =C14-E14 -> 0 | H14: =IF(D14=0,0,(C14-D14)/D14) -> 0
A15: 10 | B15: Chi phí cơ hội vốn | F15: =C15-D15 -> 0 | G15: =C15-E15 -> 0 | H15: =IF(D15=0,0,(C15-D15)/D15) -> 0
B16: TỔNG CHI PHÍ VẬN HÀNH / kg | C16: =SUM(C7:C15) -> 1700 | D16: =SUM(D7:D15) -> 690 | E16: =SUM(E7:E15) -> 420
B17: TỔNG CHI PHÍ / kg | C17: =SUM(C6:C15) -> 6700 | D17: =SUM(D6:D15) -> 5690 | E17: =SUM(E6:E15) -> 5420 | F17: =SUM(F6:F15) -> 1010 | G17: =SUM(G6:G15) -> 1280 | H17: =IF(D17=0,0,(C17-D17)/D17) -> 0.17750439
A19: II. PHÂN TÍCH BIÊN LỢI NHUẬN
A20: STT | B20: Chỉ tiêu | C20: Nội bộ | D20: Bên ngoài | E20: OEM | F20: Δ NB vs BN | G20: Δ NB vs OEM | H20: Đánh giá | I20: Ghi chú
A21: 1 | B21: Giá bán ra (VNĐ/kg) | C21: 7000 | D21: 7000 | E21: 7000 | I21: Giá nội bộ và OEM là cố định, trong khi giá đại lý bên ngoài biến động theo nhu cầu | J21: Định hướng loại bỏ nhóm đại lý (lái) để giảm biến động thị trường
A22: 2 | B22: Tổng chi phí (VNĐ/kg) | C22: =C17 -> 6700 | D22: =D17 -> 5690 | E22: =E17 -> 5420
A23: 3 | B23: Lợi nhuận gộp (VNĐ/kg) | C23: =C21-C22 -> 300 | D23: =D21-D22 -> 1310 | E23: =E21-E22 -> 1580 | F23: =C23-D23 -> -1010 | G23: =C23-E23 -> -1280
A24: 4 | B24: Biên lợi nhuận gộp (%) | C24: =IF(C21=0,0,C23/C21) -> 0.042857143 | D24: =IF(D21=0,0,D23/D21) -> 0.18714286 | E24: =IF(E21=0,0,E23/E21) -> 0.22571429 | F24: =C24-D24 -> -0.14428571 | G24: =C24-E24 -> -0.18285714 | H24: =IF(C24>D24,"NB tốt hơn",IF(C24<D24,"BN tốt hơn","Ngang nhau")) -> BN tốt hơn
A25: 5 | B25: Điểm hòa vốn (kg/tháng) | C25: =IF(C23=0,0,50000000/C23) -> 166666.67 | D25: =IF(D23=0,0,50000000/D23) -> 38167.939 | E25: =IF(E23=0,0,50000000/E23) -> 31645.57 | F25: =C25-D25 -> 128498.73 | G25: =C25-E25 -> 135021.1
A26: 6 | B26: ROI (%) | C26: =IF(C22=0,0,C23/C22) -> 0.044776119 | D26: =IF(D22=0,0,D23/D22) -> 0.23022847 | E26: =IF(E22=0,0,E23/E22) -> 0.29151292 | F26: =C26-D26 -> -0.18545235 | G26: =C26-E26 -> -0.2467368
A29: III. PHÂN TÍCH THEO SẢN LƯỢNG (Scenario Analysis)
A30: STT | B30: Sản lượng (tấn/tháng) | C30: NB - CP/kg | D30: BN - CP/kg | E30: OEM - CP/kg | F30: NB - LN gộp | G30: BN - LN gộp | H30: OEM - LN gộp | I30: Kênh tối ưu
A31: 1 | B31: 5 | C31: =C17*(1-LN(B31/5)*0.02) -> 6700 | D31: =D17*(1-LN(B31/5)*0.02) -> 5690 | E31: =E17*(1-LN(B31/5)*0.02) -> 5420 | F31: =(C21-C31)*B31*1000 -> 1500000 | G31: =(D21-D31)*B31*1000 -> 6550000 | H31: =(E21-E31)*B31*1000 -> 7900000 | I31: =IF(AND(F31>=G31,F31>=H31),"Nội bộ",IF(AND(G31>=F31,G31>=H31),"Bên ngoài","OEM")) -> OEM
A32: 2 | B32: 10 | C32: =C17*(1-LN(B32/5)*0.02) -> 6607.1183 | D32: =D17*(1-LN(B32/5)*0.02) -> 5611.1199 | E32: =E17*(1-LN(B32/5)*0.02) -> 5344.8628 | F32: =(C21-C32)*B32*1000 -> 3928817.2 | G32: =(D21-D32)*B32*1000 -> 13888801 | H32: =(E21-E32)*B32*1000 -> 16551372 | I32: =IF(AND(F32>=G32,F32>=H32),"Nội bộ",IF(AND(G32>=F32,G32>=H32),"Bên ngoài","OEM")) -> OEM
A33: 3 | B33: 20 | C33: =C17*(1-LN(B33/5)*0.02) -> 6514.2366 | D33: =D17*(1-LN(B33/5)*0.02) -> 5532.2397 | E33: =E17*(1-LN(B33/5)*0.02) -> 5269.7257 | F33: =(C21-C33)*B33*1000 -> 9715268.9 | G33: =(D21-D33)*B33*1000 -> 29355206 | H33: =(E21-E33)*B33*1000 -> 34605486 | I33: =IF(AND(F33>=G33,F33>=H33),"Nội bộ",IF(AND(G33>=F33,G33>=H33),"Bên ngoài","OEM")) -> OEM
A34: 4 | B34: 50 | C34: =C17*(1-LN(B34/5)*0.02) -> 6391.4536 | D34: =D17*(1-LN(B34/5)*0.02) -> 5427.9658 | E34: =E17*(1-LN(B34/5)*0.02) -> 5170.3998 | F34: =(C21-C34)*B34*1000 -> 30427320 | G34: =(D21-D34)*B34*1000 -> 78601709 | H34: =(E21-E34)*B34*1000 -> 91480011 | I34: =IF(AND(F34>=G34,F34>=H34),"Nội bộ",IF(AND(G34>=F34,G34>=H34),"Bên ngoài","OEM")) -> OEM
A35: 5 | B35: 100 | C35: =C17*(1-LN(B35/5)*0.02) -> 6298.5719 | D35: =D17*(1-LN(B35/5)*0.02) -> 5349.0857 | E35: =E17*(1-LN(B35/5)*0.02) -> 5095.2626 | F35: =(C21-C35)*B35*1000 -> 70142812 | G35: =(D21-D35)*B35*1000 -> 1.6509143e+08 | H35: =(E21-E35)*B35*1000 -> 1.9047374e+08 | I35: =IF(AND(F35>=G35,F35>=H35),"Nội bộ",IF(AND(G35>=F35,G35>=H35),"Bên ngoài","OEM")) -> OEM
A36: 6 | B36: 200 | C36: =C17*(1-LN(B36/5)*0.02) -> 6205.6902 | D36: =D17*(1-LN(B36/5)*0.02) -> 5270.2055 | E36: =E17*(1-LN(B36/5)*0.02) -> 5020.1255 | F36: =(C21-C36)*B36*1000 -> 1.5886197e+08 | G36: =(D21-D36)*B36*1000 -> 3.459589e+08 | H36: =(E21-E36)*B36*1000 -> 3.9597491e+08 | I36: =IF(AND(F36>=G36,F36>=H36),"Nội bộ",IF(AND(G36>=F36,G36>=H36),"Bên ngoài","OEM")) -> OEM
A37: 7 | B37: 500 | C37: =C17*(1-LN(B37/5)*0.02) -> 6082.9072 | D37: =D17*(1-LN(B37/5)*0.02) -> 5165.9316 | E37: =E17*(1-LN(B37/5)*0.02) -> 4920.7996 | F37: =(C21-C37)*B37*1000 -> 4.585464e+08 | G37: =(D21-D37)*B37*1000 -> 9.1703418e+08 | H37: =(E21-E37)*B37*1000 -> 1.0396002e+09 | I37: =IF(AND(F37>=G37,F37>=H37),"Nội bộ",IF(AND(G37>=F37,G37>=H37),"Bên ngoài","OEM")) -> OEM
A40: IV. MA TRẬN RỦI RO & ĐÁNH GIÁ TỔNG HỢP
A41: STT | B41: Tiêu chí đánh giá | C41: Trọng số | D41: NB (1-10) | E41: BN (1-10) | F41: OEM (1-10) | G41: NB Weighted | H41: BN Weighted | I41: OEM Weighted
A42: 1 | B42: Chi phí đơn vị | C42: 0.25 | D42: 8 | E42: 6 | F42: 5 | G42: =C42*D42 -> 2 | H42: =C42*E42 -> 1.5 | I42: =C42*F42 -> 1.25
A43: 2 | B43: Độ tin cậy nguồn cung | C43: 0.2 | D43: 9 | E43: 6 | F43: 7 | G43: =C43*D43 -> 1.8 | H43: =C43*E43 -> 1.2 | I43: =C43*F43 -> 1.4
A44: 3 | B44: Chất lượng nguyên liệu | C44: 0.15 | D44: 7 | E44: 6 | F44: 9 | G44: =C44*D44 -> 1.05 | H44: =C44*E44 -> 0.9 | I44: =C44*F44 -> 1.35
A45: 4 | B45: Linh hoạt sản lượng | C45: 0.15 | D45: 8 | E45: 7 | F45: 6 | G45: =C45*D45 -> 1.2 | H45: =C45*E45 -> 1.05 | I45: =C45*F45 -> 0.9
A46: 5 | B46: Rủi ro pháp lý & tuân thủ | C46: 0.1 | D46: 7 | E46: 5 | F46: 9 | G46: =C46*D46 -> 0.7 | H46: =C46*E46 -> 0.5 | I46: =C46*F46 -> 0.9
...

Sheet 2.ĐạiLý->Chai
A1: PHÂN TÍCH TÀI CHÍNH - CHẶNG: Đại lý → Nhà xử lý Chai
A2: So sánh Nội bộ vs Bên ngoài vs OEM | Đại lý thu mua → NCỨng đồng hành | J2: => không loại bỏ được cấp đại lý, cần nâng cấp NCU đồng hành
A4: I. CƠ CẤU CHI PHÍ THEO KÊNH THU MUA
A5: STT | B5: Hạng mục chi phí | C5: Nội bộ (VNĐ/kg) | D5: Bên ngoài (VNĐ/kg) | E5: OEM (VNĐ/kg) | F5: Δ NB vs BN | G5: Δ NB vs OEM | H5: % Chênh lệch NB-BN | I5: Ghi chú
A6: 1 | B6: Giá thu mua nguyên liệu | C6: ='[1]1.Vựa->ĐạiLý'!C21 -> 7000 | D6: ='[1]1.Vựa->ĐạiLý'!D21 -> 7000 | E6: ='[1]1.Vựa->ĐạiLý'!E21 -> 7000 | F6: =C6-D6 -> 0 | G6: =C6-E6 -> 0 | H6: =IF(D6=0,0,(C6-D6)/D6) -> 0
A7: 2 | B7: Chi phí vận chuyển | C7: 0 | D7: 0 | E7: 0 | F7: =C7-D7 -> 0 | G7: =C7-E7 -> 0 | H7: =IF(D7=0,0,(C7-D7)/D7) -> 0
A8: 3 | B8: Chi phí phân loại & xử lý | C8: 3180 | D8: 1360 | E8: 1565 | F8: =C8-D8 -> 1820 | G8: =C8-E8 -> 1615 | H8: =IF(D8=0,0,(C8-D8)/D8) -> 1.3382353
A9: 4 | B9: Chi phí ép kiện/đóng gói | F9: =C9-D9 -> 0 | G9: =C9-E9 -> 0 | H9: =IF(D9=0,0,(C9-D9)/D9) -> 0
A10: 5 | B10: Chi phí kiểm định chất lượng | F10: =C10-D10 -> 0 | G10: =C10-E10 -> 0 | H10: =IF(D10=0,0,(C10-D10)/D10) -> 0
A11: 6 | B11: Chi phí hao hụt & tạp chất | C11: =I11*C6 -> 350 | D11: =I11*D6 -> 350 | E11: =I11*E6 -> 350 | F11: =C11-D11 -> 0 | G11: =C11-E11 -> 0 | H11: =IF(D11=0,0,(C11-D11)/D11) -> 0 | I11: 0.05
A12: 7 | B12: Chi phí quản lý & overhead | F12: =C12-D12 -> 0 | G12: =C12-E12 -> 0 | H12: =IF(D12=0,0,(C12-D12)/D12) -> 0
A13: 8 | B13: Chi phí tài chính (lãi vay) | F13: =C13-D13 -> 0 | G13: =C13-E13 -> 0 | H13: =IF(D13=0,0,(C13-D13)/D13) -> 0
A14: 9 | B14: Chi phí bảo hiểm & rủi ro | F14: =C14-D14 -> 0 | G14: =C14-E14 -> 0 | H14: =IF(D14=0,0,(C14-D14)/D14) -> 0
A15: 10 | B15: Chi phí cơ hội vốn | F15: =C15-D15 -> 0 | G15: =C15-E15 -> 0 | H15: =IF(D15=0,0,(C15-D15)/D15) -> 0 | I15: OEM yêu cầu có lợi nhuận cố định 500đ
B16: TỔNG CHI PHÍ VẬN HÀNH / kg | C16: =SUM(C7:C15) -> 3530 | D16: =SUM(D7:D15) -> 1710 | E16: =SUM(E7:E15) -> 1915
B17: TỔNG CHI PHÍ / kg | C17: =SUM(C6:C15) -> 10530 | D17: =SUM(D6:D15) -> 8710 | E17: =SUM(E6:E15) -> 8915 | F17: =SUM(F6:F15) -> 1820 | G17: =SUM(G6:G15) -> 1615 | H17: =IF(D17=0,0,(C17-D17)/D17) -> 0.20895522
A19: II. PHÂN TÍCH BIÊN LỢI NHUẬN
A20: STT | B20: Chỉ tiêu | C20: Nội bộ | D20: Bên ngoài | E20: OEM | F20: Δ NB vs BN | G20: Δ NB vs OEM | H20: Đánh giá | I20: Ghi chú
A21: 1 | B21: Giá bán ra (VNĐ/kg) | C21: 11000 | D21: 11000 | E21: 11000 | I21: Bên ngoài tự vận hành và tự chịu chi phí, lấy công làm lời, giá bán là trung bình các loại chai (tuyển, loại 2, lá, lơ,…)
A22: 2 | B22: Tổng chi phí (VNĐ/kg) | C22: =C17 -> 10530 | D22: =D17 -> 8710 | E22: =E17 -> 8915
A23: 3 | B23: Lợi nhuận gộp (VNĐ/kg) | C23: =C21-C22 -> 470 | D23: =D21-D22 -> 2290 | E23: =E21-E22 -> 2085 | F23: =C23-D23 -> -1820 | G23: =C23-E23 -> -1615
A24: 4 | B24: Biên lợi nhuận gộp (%) | C24: =IF(C21=0,0,C23/C21) -> 0.042727273 | D24: =IF(D21=0,0,D23/D21) -> 0.20818182 | E24: =IF(E21=0,0,E23/E21) -> 0.18954545 | F24: =C24-D24 -> -0.16545455 | G24: =C24-E24 -> -0.14681818 | H24: =IF(C24>D24,"NB tốt hơn",IF(C24<D24,"BN tốt hơn","Ngang nhau")) -> BN tốt hơn
A25: 5 | B25: Điểm hòa vốn (kg/tháng) | C25: =IF(C23=0,0,50000000/C23) -> 106382.98 | D25: =IF(D23=0,0,50000000/D23) -> 21834.061 | E25: =IF(E23=0,0,50000000/E23) -> 23980.815 | F25: =C25-D25 -> 84548.918 | G25: =C25-E25 -> 82402.163
A26: 6 | B26: ROI (%) | C26: =IF(C22=0,0,C23/C22) -> 0.044634378 | D26: =IF(D22=0,0,D23/D22) -> 0.26291619 | E26: =IF(E22=0,0,E23/E22) -> 0.23387549 | F26: =C26-D26 -> -0.21828181 | G26: =C26-E26 -> -0.18924111
A29: III. PHÂN TÍCH THEO SẢN LƯỢNG (Scenario Analysis)
A30: STT | B30: Sản lượng (tấn/tháng) | C30: NB - CP/kg | D30: BN - CP/kg | E30: OEM - CP/kg | F30: NB - LN gộp | G30: BN - LN gộp | H30: OEM - LN gộp | I30: Kênh tối ưu
A31: 1 | B31: 5 | C31: =C17*(1-LN(B31/5)*0.02) -> 10530 | D31: =D17*(1-LN(B31/5)*0.02) -> 8710 | E31: =E17*(1-LN(B31/5)*0.02) -> 8915 | F31: =(C21-C31)*B31*1000 -> 2350000 | G31: =(D21-D31)*B31*1000 -> 11450000 | H31: =(E21-E31)*B31*1000 -> 10425000 | I31: =IF(AND(F31>=G31,F31>=H31),"Nội bộ",IF(AND(G31>=F31,G31>=H31),"Bên ngoài","OEM")) -> Bên ngoài
A32: 2 | B32: 10 | C32: =C17*(1-LN(B32/5)*0.02) -> 10384.023 | D32: =D17*(1-LN(B32/5)*0.02) -> 8589.2538 | E32: =E17*(1-LN(B32/5)*0.02) -> 8791.4119 | F32: =(C21-C32)*B32*1000 -> 6159768 | G32: =(D21-D32)*B32*1000 -> 24107462 | H32: =(E21-E32)*B32*1000 -> 22085881 | I32: =IF(AND(F32>=G32,F32>=H32),"Nội bộ",IF(AND(G32>=F32,G32>=H32),"Bên ngoài","OEM")) -> Bên ngoài
A33: 3 | B33: 20 | C33: =C17*(1-LN(B33/5)*0.02) -> 10238.046 | D33: =D17*(1-LN(B33/5)*0.02) -> 8468.5075 | E33: =E17*(1-LN(B33/5)*0.02) -> 8667.8237 | F33: =(C21-C33)*B33*1000 -> 15239072 | G33: =(D21-D33)*B33*1000 -> 50629850 | H33: =(E21-E33)*B33*1000 -> 46643526 | I33: =IF(AND(F33>=G33,F33>=H33),"Nội bộ",IF(AND(G33>=F33,G33>=H33),"Bên ngoài","OEM")) -> Bên ngoài
A34: 4 | B34: 50 | C34: =C17*(1-LN(B34/5)*0.02) -> 10045.076 | D34: =D17*(1-LN(B34/5)*0.02) -> 8308.8897 | E34: =E17*(1-LN(B34/5)*0.02) -> 8504.4491 | F34: =(C21-C34)*B34*1000 -> 47746221 | G34: =(D21-D34)*B34*1000 -> 1.3455552e+08 | H34: =(E21-E34)*B34*1000 -> 1.2477755e+08 | I34: =IF(AND(F34>=G34,F34>=H34),"Nội bộ",IF(AND(G34>=F34,G34>=H34),"Bên ngoài","OEM")) -> Bên ngoài
A35: 5 | B35: 100 | C35: =C17*(1-LN(B35/5)*0.02) -> 9899.0988 | D35: =D17*(1-LN(B35/5)*0.02) -> 8188.1434 | E35: =E17*(1-LN(B35/5)*0.02) -> 8380.8609 | F35: =(C21-C35)*B35*1000 -> 1.1009012e+08 | G35: =(D21-D35)*B35*1000 -> 2.8118566e+08 | H35: =(E21-E35)*B35*1000 -> 2.6191391e+08 | I35: =IF(AND(F35>=G35,F35>=H35),"Nội bộ",IF(AND(G35>=F35,G35>=H35),"Bên ngoài","OEM")) -> Bên ngoài
A36: 6 | B36: 200 | C36: =C17*(1-LN(B36/5)*0.02) -> 9753.122 | D36: =D17*(1-LN(B36/5)*0.02) -> 8067.3972 | E36: =E17*(1-LN(B36/5)*0.02) -> 8257.2728 | F36: =(C21-C36)*B36*1000 -> 2.493756e+08 | G36: =(D21-D36)*B36*1000 -> 5.8652056e+08 | H36: =(E21-E36)*B36*1000 -> 5.4854544e+08 | I36: =IF(AND(F36>=G36,F36>=H36),"Nội bộ",IF(AND(G36>=F36,G36>=H36),"Bên ngoài","OEM")) -> Bên ngoài
A37: 7 | B37: 500 | C37: =C17*(1-LN(B37/5)*0.02) -> 9560.1512 | D37: =D17*(1-LN(B37/5)*0.02) -> 7907.7794 | E37: =E17*(1-LN(B37/5)*0.02) -> 8093.8982 | F37: =(C21-C37)*B37*1000 -> 7.1992442e+08 | G37: =(D21-D37)*B37*1000 -> 1.5461103e+09 | H37: =(E21-E37)*B37*1000 -> 1.4530509e+09 | I37: =IF(AND(F37>=G37,F37>=H37),"Nội bộ",IF(AND(G37>=F37,G37>=H37),"Bên ngoài","OEM")) -> Bên ngoài
A40: IV. MA TRẬN RỦI RO & ĐÁNH GIÁ TỔNG HỢP
A41: STT | B41: Tiêu chí đánh giá | C41: Trọng số | D41: NB (1-10) | E41: BN (1-10) | F41: OEM (1-10) | G41: NB Weighted | H41: BN Weighted | I41: OEM Weighted
A42: 1 | B42: Chi phí đơn vị | C42: 0.25 | D42: 8 | E42: 6 | F42: 5 | G42: =C42*D42 -> 2 | H42: =C42*E42 -> 1.5 | I42: =C42*F42 -> 1.25
A43: 2 | B43: Độ tin cậy nguồn cung | C43: 0.2 | D43: 9 | E43: 6 | F43: 7 | G43: =C43*D43 -> 1.8 | H43: =C43*E43 -> 1.2 | I43: =C43*F43 -> 1.4
A44: 3 | B44: Chất lượng nguyên liệu | C44: 0.15 | D44: 7 | E44: 6 | F44: 9 | G44: =C44*D44 -> 1.05 | H44: =C44*E44 -> 0.9 | I44: =C44*F44 -> 1.35
A45: 4 | B45: Linh hoạt sản lượng | C45: 0.15 | D45: 8 | E45: 7 | F45: 6 | G45: =C45*D45 -> 1.2 | H45: =C45*E45 -> 1.05 | I45: =C45*F45 -> 0.9
A46: 5 | B46: Rủi ro pháp lý & tuân thủ | C46: 0.1 | D46: 7 | E46: 5 | F46: 9 | G46: =C46*D46 -> 0.7 | H46: =C46*E46 -> 0.5 | I46: =C46*F46 -> 0.9
...

Sheet 3.Chai->Vảy (mua hết)
A1: PHÂN TÍCH TÀI CHÍNH - CHẶNG: Nhà xử lý chai → Nhà băm vảy (theo thị trường)
A2: So sánh Nội bộ vs Bên ngoài vs OEM | NC Ứng đồng hành → Nhà băm vảy
A4: I. CƠ CẤU CHI PHÍ THEO KÊNH THU MUA
A5: STT | B5: Hạng mục chi phí | C5: Nội bộ (VNĐ/kg) | D5: Bên ngoài (VNĐ/kg) | E5: OEM (VNĐ/kg) | F5: Δ NB vs BN | G5: Δ NB vs OEM | H5: % Chênh lệch NB-BN | I5: Ghi chú
A6: 1 | B6: Giá thu mua nguyên liệu | C6: ='[1]2.ĐạiLý->Chai'!C21 -> 11000 | D6: ='[1]2.ĐạiLý->Chai'!D21 -> 11000 | E6: ='[1]2.ĐạiLý->Chai'!E21 -> 11000 | F6: =C6-D6 -> 0 | G6: =C6-E6 -> 0 | H6: =IF(D6=0,0,(C6-D6)/D6) -> 0 | I6: Giá chai trung bình (mua hết tất cả các loại)
A7: 2 | B7: Chi phí vận chuyển | C7: 440 | D7: 400 | E7: =D7 -> 400 | F7: =C7-D7 -> 40 | G7: =C7-E7 -> 40 | H7: =IF(D7=0,0,(C7-D7)/D7) -> 0.1 | I7: R~200km
A8: 3 | B8: Chi phí phân loại & xử lý (phân loại, tách nhãn, ép kiện) | C8: 1400 | E8: 2900 | F8: =C8-D8 -> 1400 | G8: =C8-E8 -> -1500 | H8: =IF(D8=0,0,(C8-D8)/D8) -> 0
A9: 4 | B9: Chi phí ép kiện/đóng gói (bao bì) | C9: 42 | E9: 66 | F9: =C9-D9 -> 42 | G9: =C9-E9 -> -24 | H9: =IF(D9=0,0,(C9-D9)/D9) -> 0 | I9: Bao đựng xoay vòng 5 lần
A10: 5 | B10: Chi phí kiểm định chất lượng | F10: =C10-D10 -> 0 | G10: =C10-E10 -> 0 | H10: =IF(D10=0,0,(C10-D10)/D10) -> 0
A11: 6 | B11: Chi phí hao hụt & tạp chất | C11: =I11*C6 -> 1100 | E11: =+I11*E6 -> 1100 | F11: =C11-D11 -> 1100 | G11: =C11-E11 -> 0 | H11: =IF(D11=0,0,(C11-D11)/D11) -> 0 | I11: 0.1
A12: 7 | B12: Chi phí quản lý & overhead | C12: =2610-C9-C15 -> 1875 | F12: =C12-D12 -> 1875 | G12: =C12-E12 -> 1875 | H12: =IF(D12=0,0,(C12-D12)/D12) -> 0
A13: 8 | B13: Chi phí tài chính (lãi vay) | F13: =C13-D13 -> 0 | G13: =C13-E13 -> 0 | H13: =IF(D13=0,0,(C13-D13)/D13) -> 0
A14: 9 | B14: Chi phí bảo hiểm & rủi ro | F14: =C14-D14 -> 0 | G14: =C14-E14 -> 0 | H14: =IF(D14=0,0,(C14-D14)/D14) -> 0
A15: 10 | B15: Chi phí cơ hội vốn | C15: 693 | F15: =C15-D15 -> 693 | G15: =C15-E15 -> 693 | H15: =IF(D15=0,0,(C15-D15)/D15) -> 0
B16: TỔNG CHI PHÍ VẬN HÀNH / kg | C16: =SUM(C7:C15) -> 5550 | D16: =SUM(D7:D15) -> 400 | E16: =SUM(E7:E15) -> 4466
B17: TỔNG CHI PHÍ / kg | C17: =SUM(C6:C15) -> 16550 | D17: =SUM(D6:D15) -> 11400 | E17: =SUM(E6:E15) -> 15466 | F17: =SUM(F6:F15) -> 5150 | G17: =SUM(G6:G15) -> 1084 | H17: =IF(D17=0,0,(C17-D17)/D17) -> 0.45175439
A19: II. PHÂN TÍCH BIÊN LỢI NHUẬN
A20: STT | B20: Chỉ tiêu | C20: Nội bộ | D20: Bên ngoài | E20: OEM | F20: Δ NB vs BN | G20: Δ NB vs OEM | H20: Đánh giá | I20: Ghi chú
A21: 1 | B21: Giá bán ra (VNĐ/kg) | C21: ='[1]Chuỗi giá trị chi tiết'!M24 -> 10956 | D21: ='[1]Chuỗi giá trị chi tiết'!M24 -> 10956 | E21: ='[1]Chuỗi giá trị chi tiết'!M24 -> 10956 | I21: Giá trung bình các loại hàng, đã bao gồm hao hụt
A22: 2 | B22: Tổng chi phí (VNĐ/kg) | C22: =C17 -> 16550 | D22: =D17 -> 11400 | E22: =E17 -> 15466
A23: 3 | B23: Lợi nhuận gộp (VNĐ/kg) | C23: =C21-C22 -> -5594 | D23: =D21-D22 -> -444 | E23: =E21-E22 -> -4510 | F23: =C23-D23 -> -5150 | G23: =C23-E23 -> -1084
A24: 4 | B24: Biên lợi nhuận gộp (%) | C24: =IF(C21=0,0,C23/C21) -> -0.51058781 | D24: =IF(D21=0,0,D23/D21) -> -0.040525739 | E24: =IF(E21=0,0,E23/E21) -> -0.41164659 | F24: =C24-D24 -> -0.47006207 | G24: =C24-E24 -> -0.098941219 | H24: =IF(C24>D24,"NB tốt hơn",IF(C24<D24,"BN tốt hơn","Ngang nhau")) -> BN tốt hơn
A25: 5 | B25: Điểm hòa vốn (kg/tháng) | C25: =IF(C23=0,0,50000000/C23) -> -8938.148 | D25: =IF(D23=0,0,50000000/D23) -> -112612.61 | E25: =IF(E23=0,0,50000000/E23) -> -11086.475 | F25: =C25-D25 -> 103674.46 | G25: =C25-E25 -> 2148.3265
A26: 6 | B26: ROI (%) | C26: =IF(C22=0,0,C23/C22) -> -0.33800604 | D26: =IF(D22=0,0,D23/D22) -> -0.038947368 | E26: =IF(E22=0,0,E23/E22) -> -0.2916074 | F26: =C26-D26 -> -0.29905867 | G26: =C26-E26 -> -0.046398645
A29: III. PHÂN TÍCH THEO SẢN LƯỢNG (Scenario Analysis)
A30: STT | B30: Sản lượng (tấn/tháng) | C30: NB - CP/kg | D30: BN - CP/kg | E30: OEM - CP/kg | F30: NB - LN gộp | G30: BN - LN gộp | H30: OEM - LN gộp | I30: Kênh tối ưu
A31: 1 | B31: 5 | C31: =C17*(1-LN(B31/5)*0.02) -> 16550 | D31: =D17*(1-LN(B31/5)*0.02) -> 11400 | E31: =E17*(1-LN(B31/5)*0.02) -> 15466 | F31: =(C21-C31)*B31*1000 -> -27970000 | G31: =(D21-D31)*B31*1000 -> -2220000 | H31: =(E21-E31)*B31*1000 -> -22550000 | I31: =IF(AND(F31>=G31,F31>=H31),"Nội bộ",IF(AND(G31>=F31,G31>=H31),"Bên ngoài","OEM")) -> Bên ngoài
A32: 2 | B32: 10 | C32: =C17*(1-LN(B32/5)*0.02) -> 16320.568 | D32: =D17*(1-LN(B32/5)*0.02) -> 11241.962 | E32: =E17*(1-LN(B32/5)*0.02) -> 15251.596 | F32: =(C21-C32)*B32*1000 -> -53645683 | G32: =(D21-D32)*B32*1000 -> -2859624.4 | H32: =(E21-E32)*B32*1000 -> -42955957 | I32: =IF(AND(F32>=G32,F32>=H32),"Nội bộ",IF(AND(G32>=F32,G32>=H32),"Bên ngoài","OEM")) -> Bên ngoài
A33: 3 | B33: 20 | C33: =C17*(1-LN(B33/5)*0.02) -> 16091.137 | D33: =D17*(1-LN(B33/5)*0.02) -> 11083.925 | E33: =E17*(1-LN(B33/5)*0.02) -> 15037.191 | F33: =(C21-C33)*B33*1000 -> -1.0270273e+08 | G33: =(D21-D33)*B33*1000 -> -2558497.7 | H33: =(E21-E33)*B33*1000 -> -81623829 | I33: =IF(AND(F33>=G33,F33>=H33),"Nội bộ",IF(AND(G33>=F33,G33>=H33),"Bên ngoài","OEM")) -> Bên ngoài
A34: 4 | B34: 50 | C34: =C17*(1-LN(B34/5)*0.02) -> 15787.844 | D34: =D17*(1-LN(B34/5)*0.02) -> 10875.011 | E34: =E17*(1-LN(B34/5)*0.02) -> 14753.764 | F34: =(C21-C34)*B34*1000 -> -2.4159222e+08 | G34: =(D21-D34)*B34*1000 -> 4049470.1 | H34: =(E21-E34)*B34*1000 -> -1.8988822e+08 | I34: =IF(AND(F34>=G34,F34>=H34),"Nội bộ",IF(AND(G34>=F34,G34>=H34),"Bên ngoài","OEM")) -> Bên ngoài
A35: 5 | B35: 100 | C35: =C17*(1-LN(B35/5)*0.02) -> 15558.413 | D35: =D17*(1-LN(B35/5)*0.02) -> 10716.973 | E35: =E17*(1-LN(B35/5)*0.02) -> 14539.36 | F35: =(C21-C35)*B35*1000 -> -4.6024126e+08 | G35: =(D21-D35)*B35*1000 -> 23902696 | H35: =(E21-E35)*B35*1000 -> -3.5833601e+08 | I35: =IF(AND(F35>=G35,F35>=H35),"Nội bộ",IF(AND(G35>=F35,G35>=H35),"Bên ngoài","OEM")) -> Bên ngoài
A36: 6 | B36: 200 | C36: =C17*(1-LN(B36/5)*0.02) -> 15328.981 | D36: =D17*(1-LN(B36/5)*0.02) -> 10558.935 | E36: =E17*(1-LN(B36/5)*0.02) -> 14324.956 | F36: =(C21-C36)*B36*1000 -> -8.7459618e+08 | G36: =(D21-D36)*B36*1000 -> 79412903 | H36: =(E21-E36)*B36*1000 -> -6.7379116e+08 | I36: =IF(AND(F36>=G36,F36>=H36),"Nội bộ",IF(AND(G36>=F36,G36>=H36),"Bên ngoài","OEM")) -> Bên ngoài
A37: 7 | B37: 500 | C37: =C17*(1-LN(B37/5)*0.02) -> 15025.689 | D37: =D17*(1-LN(B37/5)*0.02) -> 10350.021 | E37: =E17*(1-LN(B37/5)*0.02) -> 14041.529 | F37: =(C21-C37)*B37*1000 -> -2.0348443e+09 | G37: =(D21-D37)*B37*1000 -> 3.029894e+08 | H37: =(E21-E37)*B37*1000 -> -1.5427644e+09 | I37: =IF(AND(F37>=G37,F37>=H37),"Nội bộ",IF(AND(G37>=F37,G37>=H37),"Bên ngoài","OEM")) -> Bên ngoài
A40: IV. MA TRẬN RỦI RO & ĐÁNH GIÁ TỔNG HỢP
A41: STT | B41: Tiêu chí đánh giá | C41: Trọng số | D41: NB (1-10) | E41: BN (1-10) | F41: OEM (1-10) | G41: NB Weighted | H41: BN Weighted | I41: OEM Weighted
A42: 1 | B42: Chi phí đơn vị | C42: 0.25 | D42: 8 | E42: 6 | F42: 5 | G42: =C42*D42 -> 2 | H42: =C42*E42 -> 1.5 | I42: =C42*F42 -> 1.25
A43: 2 | B43: Độ tin cậy nguồn cung | C43: 0.2 | D43: 9 | E43: 6 | F43: 7 | G43: =C43*D43 -> 1.8 | H43: =C43*E43 -> 1.2 | I43: =C43*F43 -> 1.4
A44: 3 | B44: Chất lượng nguyên liệu | C44: 0.15 | D44: 7 | E44: 6 | F44: 9 | G44: =C44*D44 -> 1.05 | H44: =C44*E44 -> 0.9 | I44: =C44*F44 -> 1.35
A45: 4 | B45: Linh hoạt sản lượng | C45: 0.15 | D45: 8 | E45: 7 | F45: 6 | G45: =C45*D45 -> 1.2 | H45: =C45*E45 -> 1.05 | I45: =C45*F45 -> 0.9
A46: 5 | B46: Rủi ro pháp lý & tuân thủ | C46: 0.1 | D46: 7 | E46: 5 | F46: 9 | G46: =C46*D46 -> 0.7 | H46: =C46*E46 -> 0.5 | I46: =C46*F46 -> 0.9
...

Sheet Công ty xử lý
A5: STT | B5: NỘI DUNG | C5: TRẠM VẢY | D5: TRẠM CHAI | E5: DTR (Đến Vảy thô)
B6: Tổng chi phí nhé | C6: =SUM(C7,C13,C15) -> 1378 | D6: =SUM(D7,D13,D15) -> 2983 | E6: =SUM(E7,E13,E15) -> 2316
A7: 1 | B7: Chi phí sản xuất | C7: =SUM(C8:C12) -> 890 | D7: =SUM(D8:D12) -> 2487 | E7: =SUM(E8:E12) -> 2316
B8: Chi Phí Lương_Sản xuất trực tiếp | C8: 53 | D8: 586 | E8: 708
B9: Chi Phí Lương_Sản xuất gián tiếp | C9: 34 | D9: 464 | E9: 320
B10: Chi Phí Sản xuất chung -Điện | C10: 253 | D10: 74 | E10: 174
B11: Chi Phí Sản xuất chung | C11: 216 | D11: 670 | E11: 971
B12: Chi phí Khấu hao TSCD | C12: 334 | D12: 693 | E12: 143
A13: 2 | B13: Chi phí bán hàng | C13: =SUM(C14) -> 338 | D13: =SUM(D14) -> 373
B14: Thuê xe giao hàng | C14: 338 | D14: 373
A15: 3 | B15: Chi phí quản lý | C15: =SUM(C16) -> 150 | D15: =SUM(D16) -> 123
B16: Chi phí quản lý chung | C16: 150 | D16: 123
A17: 4 | B17: Lợi nhuận sau thuế | C17: 122 | D17: 1017
