Workbook
Name \T: #REF!
Name \T: #REF!
Name \T: #REF!
Name \T: #REF!
Name \T: #REF!
Name \T: #REF!
Name \T: #REF!
Name \T: #REF!
Name \T: #REF!
Name \T: #REF!
Name \T: #REF!
Name \T: #REF!
Name \T: #REF!
Name \T: #REF!
Name __dao1: '[1]CT Thang Mo'!$B$189:$H$189
Name __dao2: '[1]CT Thang Mo'!$B$161:$H$161
Name __dap2: '[1]CT Thang Mo'!$B$162:$H$162
Name __day1: '[2]Chiet tinh dz22'!#REF!
Name __day2: '[3]Chiet tinh dz35'!$H$3
Name __dbu1: '[1]CT Thang Mo'!#REF!
Name __dbu2: '[1]CT Thang Mo'!$B$93:$F$93
Name __doi3: '[4]truc tiep'!#REF!
Name __E99999: #REF!
Name __Jan02: '[5]FG waste'!#REF!
Name __lap1: #REF!
Name __lap2: #REF!
Name __vc1: '[1]CT Thang Mo'!$B$34:$H$34
Name __vc2: '[1]CT Thang Mo'!$B$35:$H$35
Name __vc3: '[1]CT Thang Mo'!$B$36:$H$36
Name _01_01_99: #REF!
Name _01_02_99: #REF!
Name _01_03_99: #REF!
Name _01_04_99: #REF!
Name _01_05_99: #REF!
Name _01_06_99: #REF!
Name _01_07_99: #REF!
Name _01_08_1999: #REF!
Name _1CAP002: [6]MTP!#REF!
Name _2STREO7: [7]MTP!#REF!
Name _4GOIC01: [8]MTP!#REF!
Name _4OSLCTT: [8]MTP!#REF!
Name _6BNTTTH: [7]MTP1!#REF!
Name _6DCTTBO: [7]MTP1!#REF!
Name _6DD24TT: [7]MTP1!#REF!
Name _6FCOTBU: [7]MTP1!#REF!
Name _6LATUBU: [7]MTP1!#REF!
Name _6SDTT24: [7]MTP1!#REF!
Name _6TBUDTT: [7]MTP1!#REF!
Name _6TDDDTT: [7]MTP1!#REF!
Name _6TLTTTH: [7]MTP1!#REF!
Name _6TUBUTT: [7]MTP1!#REF!
Name _6UCLVIS: [7]MTP1!#REF!
Name _7DNCABC: [7]MTP1!#REF!
Name _7HDCTBU: [7]MTP1!#REF!
Name _7PKTUBU: [7]MTP1!#REF!
Name _7TBHT20: [7]MTP1!#REF!
Name _7TBHT30: [7]MTP1!#REF!
Name _7TDCABC: [7]MTP1!#REF!
Name _dao1: '[1]CT Thang Mo'!$B$189:$H$189
Name _dao2: '[1]CT Thang Mo'!$B$161:$H$161

Sheet Nguyên tắc trình bày
A2: 1 | B2: Tiêu đề các biểu đồ font chữ size 24
A3: 2 | B3: Không để số âm vùng chênh lệch
A4: 3 | B4: font Size số, chữ đều là 14, time new roman , chữ đen
A5: 4 | B5: Zoom 90%, theo khung canh của anh Lộc, đã chỉnh làm mẫu tại sheet "vảy HDPE 2023-Tuần"
A6: 5 | B6: Kéo ngang và dọc cho nó cân xứng
A7: 6 | B7: trình bày 25 tuần gần nhất
A8: 7 | B8: Giá mua trung bình các loại vảy: (HDPE: vảy trong, PET: vảy A4 đến A6)

Sheet Chai B1- Tháng
BK2: Năm 2022 | BP2: Năm 2022
BI3: Data | BJ3: 13 | BK3: 1 | BL3: 2 | BM3: 3 | BN3: 4 | BO3: 5 | BP3: T6/22 | BQ3: 7 | BR3: 8 | BS3: 9 | BT3: 10 | BU3: 11 | BV3: 12 | BW3: 1/23 | BX3: 2 | BY3: 3 | BZ3: 4 | CA3: 5 | CB3: 6 | CC3: 7 | CD3: 8 | CE3: 9 | CF3: 10 | CG3: 11 | CH3: 12 | CI3: 1.24 | CJ3: 2 | CK3: 3 | CL3: 4 | CM3: 5 | CN3: 6 | CO3: 7 | CP3: 8 | CQ3: 9 | CR3: 10 | CS3: 11 | CT3: 12 | CU3: 1.25 | CV3: 2 | CW3: 3 | CX3: 4 | CY3: 5 | CZ3: 6 | DA3: 7 | DB3: 8 | DC3: 9 | DD3: 10 | DE3: 11 | DF3: 12
BI4: Tỷ giá USD | BJ4: 22920 | BK4: 23180 | BL4: 23108 | BM4: 23108 | BN4: 23108 | BO4: 23108 | BP4: 23150 | BQ4: 23150 | BR4: 23150 | BS4: 23150 | BT4: 23500 | BU4: 23500 | BV4: 23380 | BW4: 23250 | BX4: 23570 | BY4: 23260 | BZ4: 23260 | CA4: 23295 | CB4: 23330 | CC4: 23380 | CD4: 23840 | CE4: 23960 | CF4: 24280 | CG4: 24730 | CH4: 24930 | CI4: 24210 | CJ4: 24250 | CK4: 24490 | CL4: 24690 | CM4: 25475 | CN4: 25250 | CO4: 25750 | CP4: 25130 | CQ4: 24580 | CR4: 24410 | CS4: 25120 | CT4: 25140 | CU4: 25290 | CV4: 25050 | CW4: 25400 | CX4: 25460 | CY4: 25830 | CZ4: 25880 | DA4: 25920 | DB4: 26030 | DC4: 26180 | DD4: 26183 | DE4: 26107 | DF4: 26181
BI5: Giá keo chính phẩm | BJ5: 1122 | BK5: 1165 | BL5: 1272.5 | BM5: 1346 | BN5: 1297.5 | BO5: 1316.6667 | BP5: =B36*BP4/1000 -> 32178.5 | BQ5: =C36*BQ4/1000 -> 28243 | BR5: =D36*BR4/1000 -> 29400.5 | BS5: =E36*BS4/1000 -> 27548.5 | BT5: =F36*BT4/1000 -> 26555 | BU5: =G36*BU4/1000 -> 24440 | BV5: =H36*BV4/1000 -> 22853.95 | BW5: =I36*BW4/1000 -> 23250 | ... DF5: =AR36*DF4/1000 -> 20159.37
BI6: Giá duyệt mua chai B1 | BJ6: 688.17627 | BK6: =BK16/BK4*1000 -> 0 | BL6: =BL16/BL4*1000 -> 0 | BM6: =BM16/BM4*1000 -> 0 | BN6: =BN16/BN4*1000 -> 0 | BO6: =BO16/BO4*1000 -> 0 | BP6: 18000 | BQ6: 18000 | BR6: 18000 | BS6: 16500 | BT6: 16500 | BU6: 16500 | BV6: 15500 | BW6: 14500 | BX6: 14500 | BY6: 15500 | BZ6: 15500 | CA6: 15500 | CB6: 13500 | CC6: 13000 | CD6: 13000 | CE6: 13500 | CF6: 14500 | CG6: 15000 | CH6: 15000 | CI6: 16500 | CJ6: 16500 | CK6: 16500 | CL6: 17500 | CM6: 17500 | CN6: 17500 | CO6: 16500 | CP6: 17000 | CQ6: 17500 | CR6: 17400 | CS6: 17700 | CT6: 17700 | CU6: =+(16800) -> 16800 | CV6: =+(16800) -> 16800 | CW6: =+(17200) -> 17200 | CX6: 18000 | CY6: 17500 | CZ6: 17500 | DA6: 17800 | DB6: 16150 | DC6: =(14500+13500+13000)/3 -> 13666.667 | DD6: 13500 | DE6: 12700 | DF6: 12700
BI7: Giá bale ĐNA | BP7: =BP16*BP4/1000 -> 14237.25 | BQ7: =BQ16*BQ4/1000 -> 13890 | BR7: =BR16*BR4/1000 -> 13156.917 | BS7: =BS16*BS4/1000 -> 13156.917 | BT7: =BT16*BT4/1000 -> 13351.917 | BU7: =BU16*BU4/1000 -> 12220 | BV7: =BV16*BV4/1000 -> 10918.46 | BW7: =BW16*BW4/1000 -> 10776.375 | ... DF7: =DF16*DF4/1000 -> 11710.761
BI8: Giá chai B1 thực tế mua trung bình | BJ8: 15773 | BK8: 15974 | BL8: 15997 | BM8: 16512 | BN8: 17232 | BO8: 17845 | BP8: 17949.169 | BQ8: 18008.203 | BR8: 17709.211 | BS8: 16436.763 | BT8: 16498.897 | BU8: 16968.763 | BV8: 16873.812 | BW8: 14486.456 | BX8: 14337.016 | BY8: 15026.124 | BZ8: 14967.788 | CA8: 14928.984 | CB8: 13867.306 | CC8: 12969.009 | CD8: 12977.364 | CE8: 13498.82 | CF8: 14413.011 | CG8: 15100 | CH8: 15100 | CI8: 16099.441 | CJ8: 16332.331 | CK8: =16233.8475760353+377 -> 16610.848 | CL8: 17757.505 | CM8: 17263.633 | CN8: 17209.798 | CO8: 16215.033 | CP8: 16527.439 | CQ8: 16645.01 | CR8: 16492.39 | CS8: 16673.362 | CT8: 16581.723 | CU8: 16882.91 | CV8: 17290.286 | CW8: 17728.513 | CX8: 18247.4 | CY8: 18386.5 | CZ8: 18684.129 | DA8: 18901.794 | DB8: 18476.756 | DC8: 15949.265 | DD8: 14931.922 | DE8: 14871.888 | DF8: =DE8 -> 14871.888
BI9: Giá chai B1 thể hiện | BJ9: 688.17627 | BK9: 689.12856 | BL9: 692.27107 | BM9: 714.55773 | BN9: 745.71577 | BO9: 772.24338 | BP9: =BP6 -> 18000 | BQ9: =BQ6 -> 18000 | BR9: =BR6 -> 18000 | BS9: =BS6 -> 16500 | BT9: =BT6 -> 16500 | BU9: =BU6 -> 16500 | BV9: =BV6 -> 15500 | BW9: =BW6 -> 14500 | ... DF9: =DF6 -> 12700
BI10: % Keo chính phẩm so với chai B1 | BJ10: 0.63039625 | BK10: 0.69054088 | BL10: 0.83815278 | BM10: 0.88368266 | BN10: 0.73993907 | BO10: 0.70498926 | BP10: =BP13/BP6 -> 0.78769444 | BQ10: =BQ13/BQ6 -> 0.56905556 | BR10: =BR13/BR6 -> 0.63336111 | BS10: =BS13/BS6 -> 0.66960606 | BT10: =BT13/BT6 -> 0.60939394 | BU10: =BU13/BU6 -> 0.48121212 | BV10: =BV13/BV6 -> 0.47444839 | BW10: =BW13/BW6 -> 0.60344828 | ... DE10: =DE13/DE6 -> 0.58286535 | DF10: =IFERROR(DF13/DF6,0) -> 0.58735197
BI11: % Giá chính phẩm tháng sau so với tháng trước | BK11: 0.038324421 | BL11: 0.092274678 | BM11: 0.057760314 | BN11: -0.036032689 | BO11: 0.014771997 | BP11: 0.055696203 | BQ11: -0.12230216 | BR11: 0.040983607 | BS11: -0.062992126 | BT11: -0.050420168 | BU11: -0.079646018 | BV11: -0.13495575 | BW11: -0.038461538 | BX11: 0.069053708 | BY11: 0.02 | BZ11: 0.009569378 | CA11: -0.045098039 | CB11: -0.14691943 | CC11: -0.14691943 | CD11: -0.14691943 | CE11: -0.14691943 | CF11: -0.14691943 | CG11: -0.14691943 | CH11: -0.14691943 | CI11: -0.14691943 | CJ11: -0.14691943 | CK11: -0.14691943 | CL11: -0.14691943 | CM11: -0.14691943 | CN11: -0.14691943 | CO11: -0.14691943 | CP11: -0.14691943 | CQ11: -0.14691943 | CR11: -0.14691943 | CS11: -0.14691943 | CT11: -0.14691943 | CU11: -0.14691943 | CV11: -0.14691943 | CW11: -0.14691943 | CX11: -0.14691943 | CY11: -0.14691943 | CZ11: -0.14691943 | DA11: -0.14691943 | DB11: -0.14691943 | DC11: -0.14691943 | DD11: -0.14691943 | DE11: -0.14691943
BI12: % Giá chai B1 tháng sau so với tháng trước | BK12: 0.0013837935 | BL12: 0.00456013 | BM12: 0.032193536 | BN12: 0.043604651 | BO12: 0.035573352 | BP12: 0.0040031347 | BQ12: 0.0032870912 | BR12: -0.017658818 | BS12: -0.070830978 | BT12: -0.011177818 | BU12: 0.028486575 | BV12: -0.0059372285 | BW12: -0.16408421 | BX12: -0.14405873 | BY12: 0.037253294 | BZ12: 0.04399603 | CA12: -0.0064647859 | CB12: -0.06465806 | CC12: -0.06465806 | CD12: -0.06465806 | CE12: -0.06465806 | CF12: -0.06465806 | CG12: -0.06465806 | CH12: -0.06465806 | CI12: -0.06465806 | CJ12: -0.06465806 | CK12: -0.06465806 | CL12: -0.06465806 | CM12: -0.06465806 | CN12: -0.06465806 | CO12: -0.06465806 | CP12: -0.06465806 | CQ12: -0.06465806 | CR12: -0.06465806 | CS12: -0.06465806 | CT12: -0.06465806 | CU12: -0.06465806 | CV12: -0.06465806 | CW12: -0.06465806 | CX12: -0.06465806 | CY12: -0.06465806 | CZ12: -0.06465806 | DA12: -0.06465806 | DB12: -0.06465806 | DC12: -0.06465806 | DD12: -0.06465806 | DE12: -0.06465806
BI13: Chênh lệch | BJ13: 433.82373 | BK13: 475.87144 | BL13: 580.22893 | BM13: 631.44227 | BN13: 551.78423 | BO13: 544.42329 | BP13: =BP5-BP6 -> 14178.5 | BQ13: =BQ5-BQ6 -> 10243 | BR13: =BR5-BR6 -> 11400.5 | BS13: =BS5-BS6 -> 11048.5 | BT13: =BT5-BT6 -> 10055 | BU13: =BU5-BU6 -> 7940 | BV13: =BV5-BV6 -> 7353.95 | BW13: =BW5-BW6 -> 8750 | ... DF13: =DF5-DF6 -> 7459.37
BI14: Giá bán rPET | BK14: 1300 | BL14: 1300 | BM14: 1450 | BN14: 1550 | BO14: 1550 | BP14: 1550 | BQ14: 1550 | BR14: 1480 | BS14: 1409.7447 | BT14: 1409.7447 | BU14: 1379.9766 | BV14: 1330 | BW14: 1330 | BX14: 1330 | BY14: 1380 | BZ14: 1380 | CA14: 1380 | CB14: 1350 | CC14: 1300 | CD14: 1250 | CE14: 1250 | CF14: 1250 | CG14: 1250 | CH14: 1250 | CI14: 1250 | CJ14: 1250 | CK14: 1250 | CL14: 1250 | CM14: 1300 | CN14: 1300 | CO14: 1300 | CP14: 1300 | CQ14: 1310 | CR14: 1325 | CS14: 1325 | CT14: 1325 | CU14: 1325 | CV14: 1250 | CW14: 1250 | CX14: 1250 | CY14: 1250 | CZ14: 1250 | DA14: 1250 | DB14: 1250 | DC14: 1250
BI15: Giá chính phẩm dự báo | BK15: 1165 | BL15: 1272.5 | BM15: 1346 | BN15: 1297.5 | BO15: 1316.6667 | BP15: 1390 | BQ15: 1220 | BR15: 1270 | BS15: 1190 | BT15: 1130 | BU15: 1040 | BV15: 977.5 | BW15: 1000 | BX15: 1045 | BY15: 1020 | BZ15: 1055 | CA15: 974 | CB15: =CB5 -> 20880.35 | CC15: =CC5 -> 21112.14 | CD15: =CD5 -> 21885.12 | CE15: =CE5 -> 22282.8 | CF15: =CF5 -> 22398.3 | CG15: =CG5 -> 22257 | CH15: =CH5 -> 22437 | CI15: =CI5 -> 22515.3 | ... DF15: =DF5 -> 20159.37
BI16: Giá bale ĐNA ( USD) | BP16: 615 | BQ16: 600 | BR16: 568.33333 | BS16: 568.33333 | BT16: 568.16667 | BU16: 520 | BV16: 467 | BW16: 463.5 | BX16: 451.5 | BY16: 471.66667 | BZ16: 501.66667 | CA16: 472.5 | CB16: 454.33333 | CC16: 453 | CD16: 433.2 | CE16: 412.7 | CF16: 419.2 | CG16: 457.4 | CH16: 474.1 | CI16: 474.1 | CJ16: 495.7 | CK16: 494.3 | CL16: 515.7 | CM16: 560 | CN16: 563.5 | CO16: 567.2 | CP16: 579.4 | CQ16: 602 | CR16: 635.5 | CS16: 630.7 | CT16: 613.3 | CU16: 588.8 | CV16: 595.2 | CW16: 595.2 | CX16: 581.8 | CY16: 577.2 | CZ16: 578.7 | DA16: 555 | DB16: 522.6 | DC16: 496.7 | DD16: 463 | DE16: 447.3 | DF16: 447.3
BI17: Giá duyệt mua chai B0 | BW17: 8708.4662 | BX17: 9206.5027 | BY17: 10350.583 | BZ17: 10630.801 | CA17: 9861.484 | CB17: 9199.095 | CC17: 8896.0365 | CD17: 9246.3978 | CE17: 9607.8931 | CF17: 10586.188 | CG17: 11153.125 | CH17: 11113.72 | CI17: 11099.755 | CJ17: 11015.602 | CK17: 11145.196 | CL17: 12500 | CM17: 13000 | CN17: 13000 | CO17: 11500 | CP17: 11500 | CQ17: 12000 | CR17: 11700 | CS17: 12000 | CT17: 12000 | CU17: 12300 | CV17: 12300 | CW17: 12500 | CX17: 13500 | CY17: 13000 | CZ17: 13500 | DA17: 13800 | DB17: 12350 | DC17: =(10500+10300+10000)/3 -> 10266.667 | DD17: 10000 | DE17: 9700 | DF17: 9700
A35: Tháng | B35: 06/22 | C35: 7 | D35: 8 | E35: 9 | F35: 10 | G35: 11 | H35: 12 | I35: 1/23 | J35: 2 | K35: 3 | L35: 4 | M35: 5 | N35: 6 | O35: 7 | P35: 8 | Q35: 9 | R35: 10 | S35: 11 | T35: 12 | U35: 1.24 | V35: 2 | W35: 3 | X35: 4 | Y35: 5 | Z35: 6 | AA35: 7 | AB35: 8 | AC35: 9 | AD35: 10 | AE35: 11 | AF35: 12 | AG35: 1.25 | AH35: 2 | AI35: 3 | AJ35: 4 | AK35: 5 | AL35: 6 | AM35: 7 | AN35: 8 | AO35: 9 | AP35: 10 | AQ35: 11 | AR35: 12
A36: Giá RESIN (USD/ Tấn) | B36: 1390 | C36: 1220 | D36: 1270 | E36: 1190 | F36: 1130 | G36: 1040 | H36: 977.5 | I36: 1000 | J36: 1045 | K36: 1020 | L36: 1055 | M36: 974 | N36: 895 | O36: 903 | P36: 918 | Q36: 930 | R36: 922.5 | S36: 900 | T36: 900 | U36: 930 | V36: 943 | W36: 940 | X36: 940 | Y36: 942 | Z36: 950 | AA36: 948 | AB36: 930 | AC36: 880 | AD36: 862.5 | AE36: 852 | AF36: 840 | AG36: 828 | AH36: 840 | AI36: 823 | AJ36: 765 | AK36: 782 | AL36: 807.5 | AM36: 802 | AN36: 795 | AO36: 783 | AP36: 772 | AQ36: 770 | AR36: 770
A45: 1. Sửa lại Tiêu đề (đã chỉnh biểu đồ bên dưới)
A46: 2. chỉnh lại size để thấy 1 màn hình
A47: 3. biểu đồ trình bày bằng VNĐ/kg, lấy tỷ giá tại ngày cuối tháng
A48: 4. Bảng số liệu chỉ trình bày 1 dòng giá keo chính phẩm bằng usd/tấn
A49: 5. Thêm 1 đường giá thực mua trung bình hàng tháng

Sheet Chart B1_Tuần
AM43: Năm 2022
AK44: Data | AL44: 33 | AM44: 34 | AN44: 35 | AO44: 36 | AP44: 37 | AQ44: 38 | AR44: 39 | AS44: 40 | AT44: 41 | AU44: 42 | AV44: 43 | AW44: 44 | AX44: 45 | AY44: 46 | AZ44: 47 | BA44: 48 | BB44: 49 | BC44: 50 | BD44: 51 | BE44: 52 | BF44: 1 | BG44: 2 | BH44: 3 | BI44: 4 | BJ44: 5 | BK44: 6 | BL44: 7 | BM44: 8 | BN44: 9 | BO44: 10 | BP44: 11 | BQ44: 12 | BR44: 13 | BS44: 14 | BT44: 15 | BU44: 16 | BV44: 17 | BW44: 18 | BX44: 19 | BY44: 20 | BZ44: 21 | CA44: 22 | CB44: 23 | CC44: 24 | CD44: 25 | CE44: 26 | CF44: 27 | CG44: 28 | CH44: 29 | CI44: 30 | CJ44: 31 | CK44: 32 | CL44: 33 | CM44: 34
AK45: Tỷ giá USD | AL45: 23150 | AM45: 23150 | AN45: 23150 | AO45: 23500 | AP45: 23500 | AQ45: 23500 | AR45: 23500 | AS45: 23500 | AT45: 23500 | AU45: 23500 | AV45: 23500 | AW45: 24600 | AX45: 24600 | AY45: 24600 | AZ45: 24600 | BA45: 24600 | BB45: 24000 | BC45: 24000 | BD45: 24000 | BE45: 24000 | BF45: 24760 | BG45: 24200 | BH45: 24330 | BI45: 24410 | BJ45: 24380 | BK45: 24220 | BL45: 24250 | BM45: 24380 | BN45: 24550 | BO45: 24530 | BP45: 24500 | BQ45: 24570 | BR45: 24620 | BS45: 24650 | BT45: 24810 | BU45: 25020 | BV45: 25240 | BW45: 25150 | BX45: 25180 | BY45: 25230 | BZ45: 25250 | CA45: 25280 | CB45: 25260 | CC45: 25250 | CD45: 25260 | CE45: 25260 | CF45: 25260 | CG45: 25220 | CH45: 25190 | CI45: 25170 | CJ45: 25120 | CK45: 24930 | CL45: 24970 | CM45: 24810
AK46: Giá bale ĐNA | AL46: 1220 | AM46: 1190 | AN46: 1160 | AO46: 1160 | AP46: 1160 | AQ46: 1130 | AR46: 1130 | AS46: 1100 | AT46: 1100 | AU46: 1070 | AV46: 1040 | AW46: 995 | AX46: 538.5 | AY46: 520.66667 | AZ46: 520.66667 | BA46: 508 | BB46: 520 | BC46: 512.83333 | BD46: 464 | BE46: 467 | BF46: =BF55*BF45/1000 -> 12273.532 | BG46: =BG55*BG45/1000 -> 11995.94 | BH46: =BH55*BH45/1000 -> 12060.381 | BI46: =BI55*BI45/1000 -> 12100.037 | BJ46: =BJ55*BJ45/1000 -> 12085.166 | BK46: =BK55*BK45/1000 -> 11970.735 | BL46: =BL55*BL45/1000 -> 11985.562 | BM46: =BM55*BM45/1000 -> 12049.815 | ... CM46: =CM55*CM45/1000 -> 14375.658
AK47: Giá duyệt mua chai B1 | AL47: 774.65803 | AM47: 773.14615 | AN47: 776.38589 | AO47: 702.12766 | AP47: 702.12766 | AQ47: 702.12766 | AR47: 702.12766 | AS47: 702.12766 | AT47: 702.12766 | AU47: 702.12766 | AV47: 702.12766 | AW47: 670.73171 | AX47: 670.73171 | AY47: 695.81402 | AZ47: 706.10846 | BA47: 719.78422 | BB47: 714.51263 | BC47: 723.60817 | BD47: 716.11607 | BE47: 658.89104 | BF47: 16500 | BG47: 16500 | BH47: 16500 | BI47: 16500 | BJ47: 16500 | BK47: 16500 | BL47: 16500 | BM47: 16500 | BN47: 16500 | BO47: 16500 | BP47: 16500 | BQ47: 16500 | BR47: 16500 | BS47: 17500 | BT47: 17500 | BU47: 17500 | BV47: 17500 | BW47: 17500 | BX47: 17500 | BY47: 17500 | BZ47: 17500 | CA47: 17500 | CB47: 17000 | CC47: 17000 | CD47: 17000 | CE47: 17000 | CF47: 16000 | CG47: 16000 | CH47: 16500 | CI47: 16500 | CJ47: 16500 | CK47: 16500 | CL47: 17000 | CM47: 17000
AK48: Giá chai B1 thực tế mua trung bình | AL48: 17933.333 | AM48: 17898.333 | AN48: 17973.333 | AO48: 16500 | AP48: 16500 | AQ48: 16500 | AR48: 16500 | AS48: 16500 | AT48: 16500 | AU48: 16500 | AV48: 16500 | AW48: 16500 | AX48: 16500 | AY48: 17117.025 | AZ48: 17370.268 | BA48: 17706.692 | BB48: 17148.303 | BC48: 17366.596 | BD48: 17186.786 | BE48: 15813.385 | BF48: 16071.933 | BG48: 16132.36 | BH48: 15988.717 | BI48: 16054.687 | BJ48: 16330.181 | BK48: 16448.82 | BM48: 16368.322 | BN48: 16350.379 | BO48: 16240.766 | BP48: 16182.893 | BQ48: 16213.85 | BR48: 16205.294 | BS48: 17370.845 | BT48: 17486.483 | BU48: 17457.58 | BV48: 17456.87 | BW48: 17193.951 | BX48: 17260.101 | BY48: 17277.914 | BZ48: 17254.469 | CA48: 17259.324 | CB48: 17143.286 | CC48: 17175.785 | CD48: 17311.471 | CE48: 17213.644 | CF48: 16000 | CG48: 15933.143 | CH48: 16357.132 | CI48: 16422.84 | CJ48: 16500 | CK48: 16471.302 | CL48: 16618.706 | CM48: 17000
AK49: Giá chai B1 thể hiện | AL49: 774.65803 | AM49: 773.14615 | AN49: 776.38589 | AO49: 702.12766 | AP49: 702.12766 | AQ49: 702.12766 | AR49: 702.12766 | AS49: 702.12766 | AT49: 702.12766 | AU49: 702.12766 | AV49: 702.12766 | AW49: 670.73171 | AX49: 670.73171 | AY49: 695.81402 | AZ49: 706.10846 | BA49: 719.78422 | BB49: 714.51263 | BC49: 723.60817 | BD49: 716.11607 | BE49: 658.89104 | BF49: =BF47 -> 16500 | BG49: =BG47 -> 16500 | BH49: =BH47 -> 16500 | BI49: =BI47 -> 16500 | BJ49: =BJ47 -> 16500 | BK49: =BK47 -> 16500 | BL49: =BL47 -> 16500 | BM49: =BM47 -> 16500 | ... CM49: =CM47 -> 17000
AK50: % Giá chính phẩm so với với chai B1 | AL50: 0.57488848 | AM50: 0.53916566 | AN50: 0.49410237 | AO50: 0.65212121 | AP50: 0.65212121 | AQ50: 0.60939394 | AR50: 0.60939394 | AS50: 0.56666667 | AT50: 0.56666667 | AU50: 0.52393939 | AV50: 0.48121212 | AW50: 0.48345455 | AX50: 0.19714545 | AY50: 0.25171576 | AZ50: 0.26262508 | BA50: 0.29423293 | BB50: 0.27223119 | BC50: 0.29128311 | BD50: 0.35206034 | BE50: 0.29123335 | BF50: =BF53/BF47 -> 0.35054545 | BG50: =BG53/BG47 -> 0.37866667 | BH50: =BH53/BH47 -> 0.38607273 | BI50: =BI53/BI47 -> 0.3906303 | BJ50: =BJ53/BJ47 -> 0.40369697 | BK50: =BK53/BK47 -> 0.37980606 | BL50: =BL53/BL47 -> 0.38151515 | BM50: =BM53/BM47 -> 0.38892121 | ... CM50: =CM53/CM47 -> 0.37184706
AK51: % Giá chính phẩm tuần sau so với tuần trước | AM51: -0.024590164 | AN51: -0.025210084 | AO51: 0 | AP51: 0 | AQ51: -0.025862069 | AR51: 0 | AS51: -0.026548673 | AT51: 0 | AU51: -0.027272727 | AV51: -0.028037383 | AW51: -0.043269231 | AX51: -0.45879397 | AY51: -0.033116682 | AZ51: 0 | BA51: -0.024327785 | BB51: 0.023622047 | BC51: -0.013782051 | BD51: -0.095222619 | BE51: 0.0064655172 | BF51: -0.021413276 | BG51: 0.014587892 | BH51: 0.0082674335 | BI51: 0.0082674335 | BJ51: -0.0085561497 | BK51: -0.016540813 | BL51: -0.058590942 | BM51: -0.029475198 | BN51: -0.034224599 | BO51: -0.023013305 | BP51: 0.024497258 | BQ51: 0.073310424 | BR51: 0.048888889 | BS51: 0.080841639 | BT51: 0.081339713 | BU51: 0.057815846 | BV51: 0.070793312 | BW51: 0.069915254 | BX51: 0.039275956 | BY51: -0.0030633084 | BZ51: -0.040148448 | CA51: -0.058139535 | CB51: -0.07029703 | CC51: -0.074268814 | CD51: -0.074268814 | CE51: -0.074268814 | CF51: -0.074268814 | CG51: -0.074268814 | CH51: -0.074268814 | CI51: -0.074268814 | CJ51: -0.074268814 | CK51: -0.074268814 | CL51: -0.074268814 | CM51: -0.074268814
AK52: % Giá chai B1 tuần sau so với tuần trước | AM52: -0.0019516729 | AN52: 0.0041903343 | AO52: -0.095646032 | AP52: 0 | AQ52: 0 | AR52: 0 | AS52: 0 | AT52: 0 | AU52: 0 | AV52: 0 | AW52: -0.044715447 | AX52: 0 | AY52: 0.037395451 | AZ52: 0.014794811 | BA52: 0.019367794 | BB52: -0.0073238572 | BC52: 0.012729718 | BD52: -0.01035381 | BE52: -0.079910267 | BF52: -0.0844465 | BG52: -0.00020721094 | BH52: 0.0060794473 | BI52: 0.0060794473 | BJ52: -0.0050127034 | BK52: -0.0053830228 | BL52: -0.013195164 | BM52: -0.011813472 | BN52: 0.02087482 | BO52: 0.036783989 | BP52: 0.044407438 | BQ52: 0.048655839 | BR52: 0.05033557 | BS52: 0.0078697787 | BT52: -0.0061905079 | BU52: -0.0041190539 | BV52: -0.00013352026 | BW52: 0.002329606 | BX52: -0.0043379605 | BY52: -0.0050234427 | BZ52: -0.009006004 | CA52: 0.04199773 | CB52: -0.045487748 | CC52: -0.063543133 | CD52: -0.063543133 | CE52: -0.063543133 | CF52: -0.063543133 | CG52: -0.063543133 | CH52: -0.063543133 | CI52: -0.063543133 | CJ52: -0.063543133 | CK52: -0.063543133 | CL52: -0.063543133 | CM52: -0.063543133
AK53: Chênh lệch | AL53: 445.34197 | AM53: 416.85385 | AN53: 383.61411 | AO53: 457.87234 | AP53: 457.87234 | AQ53: 427.87234 | AR53: 427.87234 | AS53: 397.87234 | AT53: 397.87234 | AU53: 367.87234 | AV53: 337.87234 | AW53: 324.26829 | AX53: -132.23171 | AY53: -175.14736 | AZ53: -185.44179 | BA53: -211.78422 | BB53: -194.51263 | BC53: -210.77484 | BD53: -252.11607 | BE53: -191.89104 | BF53: =BF54-BF47 -> 5784 | BG53: =BG54-BG47 -> 6248 | BH53: =BH54-BH47 -> 6370.2 | BI53: =BI54-BI47 -> 6445.4 | BJ53: =BJ54-BJ47 -> 6661 | BK53: =BK54-BK47 -> 6266.8 | BL53: =BL54-BL47 -> 6295 | BM53: =BM54-BM47 -> 6417.2 | ... CM53: =CM54-CM47 -> 6321.4
AK54: Giá chính phẩm | BF54: =BF56*BF45/1000 -> 22284 | BG54: =BG56*BG45/1000 -> 22748 | BH54: =BH56*BH45/1000 -> 22870.2 | BI54: =BI56*BI45/1000 -> 22945.4 | BJ54: =BJ56*BJ45/1000 -> 23161 | BK54: =BK56*BK45/1000 -> 22766.8 | BL54: =BL56*BL45/1000 -> 22795 | BM54: =BM56*BM45/1000 -> 22917.2 | ... CM54: =CM56*CM45/1000 -> 23321.4
AK55: Giá bale ĐNA USD | BF55: 495.7 | BG55: 495.7 | BH55: 495.7 | BI55: 495.7 | BJ55: 495.7 | BK55: 494.25 | BL55: 494.25 | BM55: 494.25 | BN55: 494.25 | BO55: 514.42 | BP55: 514.42 | BQ55: 514.42 | BR55: 514.42 | BS55: 551 | BT55: 551 | BU55: 551 | BV55: 551 | BW55: 569.88 | BX55: 569.88 | BY55: 569.88 | BZ55: 569.88 | CA55: 569.88 | CB55: 567.17 | CC55: 567.17 | CD55: 567.17 | CE55: 567.17 | CF55: 579.43 | CG55: 579.43 | CH55: 579.43 | CI55: 579.43 | CJ55: 579.43 | CK55: 579.43 | CL55: 579.43 | CM55: 579.43
AK56: Giá chính phẩm USD | BF56: 900 | BG56: 940 | BH56: 940 | BI56: 940 | BJ56: 950 | BK56: 940 | BL56: 940 | BM56: 940 | BN56: 940 | BO56: 940 | BP56: 940 | BQ56: 940 | BR56: 940 | BS56: 940 | BT56: 940 | BU56: 940 | BV56: 940 | BW56: 940 | BX56: 940 | BY56: 950 | BZ56: 950 | CA56: 950 | CB56: 950 | CC56: 950 | CD56: 950 | CE56: 950 | CF56: 950 | CG56: 940 | CH56: 940 | CI56: 940 | CJ56: 940 | CK56: 940 | CL56: 940 | CM56: 940
AK57: Giá mua chai B0 | BF57: 11099.755 | BG57: 11099.755 | BH57: 11099.755 | BI57: 11099.755 | BJ57: 11015.602 | BK57: 11015.602 | BL57: 11015.602 | BM57: 11015.602 | BN57: 11145.196 | BO57: 11145.196 | BP57: 11145.196 | BQ57: 11145.196 | BR57: 11145.196 | BS57: 11936.111 | BT57: 12163.111 | BU57: 12344.4 | BV57: 12384.111 | BW57: 12580.25 | BX57: 12764.889 | BY57: 12785.778 | BZ57: 12764.056 | CA57: 12808.067 | CB57: 12816.278 | CC57: 12793.5 | CD57: 12766.722 | CE57: 12278.111 | CF57: 11307.167 | CG57: 11044.611 | CH57: 11307.111 | CI57: 11363.81 | CJ57: 11350.278 | CK57: 11352.056 | CL57: 11366.889 | CM57: 11454.42
B69: Tháng | P69: T6 | X69: T12 | Z69: GAP giữa T6 & T12
B70: % chênh lệch giữa keo chính phẩm so với chai B1 | P70: 0.85859936 | X70: 0.49014925 | Z70: 0.36845011
E71: 1165, | F71: 1272.5, | P71: 1346, | Q71: 1297.5, | R71: 1316.66666666665,1390,1220,1270,1190,1130,1040,1040 | T71: 1270 | U71: 1190 | V71: 1130 | W71: 1040 | X71: 1040
V72: -13700
E73: 1165,1272.5,1346,1297.5,1316.66666666665,1390,1220,1270,1190,1130,1040,1040
E75: 1165 | F75: 1272.5 | P75: 1346 | Q75: 1297.5 | R75: 1316.6667 | S75: 1390 | T75: 1220 | U75: 1270 | V75: 1190 | W75: 1130 | X75: 1040 | Y75: 1040
B76: tỉ lệ | E76: 27960 | F76: 30540 | P76: 32304 | Q76: 31140 | R76: 31600 | S76: 33360 | T76: 29280 | U76: 30480 | V76: 28560 | W76: 27120 | X76: 24960 | Y76: 24960

Sheet Chai B1- Tháng - Danh
BK2: Năm 2022 | BP2: Năm 2022 | CI2: 2024 | CU2: 2025
BI3: Data | BJ3: 13 | BK3: 1 | BL3: 2 | BM3: 3 | BN3: 4 | BO3: 5 | BP3: T6/22 | BQ3: 7 | BR3: 8 | BS3: 9 | BT3: 10 | BU3: 11 | BV3: 12 | BW3: 1/23 | BX3: 2 | BY3: 3 | BZ3: 4 | CA3: 5 | CB3: 6 | CC3: 7 | CD3: 8 | CE3: 9 | CF3: 10 | CG3: 11 | CH3: 12 | CI3: 1 | CJ3: 2 | CK3: 3 | CL3: 4 | CM3: 5 | CN3: 6 | CO3: 7 | CP3: 8 | CQ3: 9 | CR3: 10 | CS3: 11 | CT3: 12 | CU3: 1 | CV3: 2 | CW3: 3 | CX3: 4 | CY3: 5 | CZ3: 6 | DA3: 7 | DB3: 8 | DC3: 9 | DD3: 10 | DE3: 11
BI4: Tỷ giá USD | BJ4: 22920 | BK4: 23180 | BL4: 23108 | BM4: 23108 | BN4: 23108 | BO4: 23108 | BP4: 23150 | BQ4: 23150 | BR4: 23150 | BS4: 23150 | BT4: 23500 | BU4: 23500 | BV4: 23380 | BW4: 23250 | BX4: 23570 | BY4: 23260 | BZ4: 23260 | CA4: 23295 | CB4: 23330 | CC4: 23380 | CD4: 23840 | CE4: 23960 | CF4: 24280 | CG4: 24730 | CH4: 24930 | CI4: 24210 | CJ4: 24250 | CK4: 24490 | CL4: 24690 | CM4: 25475 | CN4: 25250 | CO4: 25750 | CP4: 25130 | CQ4: 24580 | CR4: 24410 | CS4: 25120 | CT4: 25140 | CU4: 25290 | CV4: 25050 | CW4: 25400 | CX4: 25460 | CY4: 25830 | CZ4: 25880 | DA4: 25920 | DB4: 26030 | DC4: 26180 | DD4: 26183 | DE4: 26107
BI5: Giá keo chính phẩm | BJ5: 1122 | BK5: 1165 | BL5: 1272.5 | BM5: 1346 | BN5: 1297.5 | BO5: 1316.6667 | BP5: =B36*BP4/1000 -> 32178.5 | BQ5: =C36*BQ4/1000 -> 28243 | BR5: =D36*BR4/1000 -> 29400.5 | BS5: =E36*BS4/1000 -> 27548.5 | BT5: =F36*BT4/1000 -> 26555 | BU5: =G36*BU4/1000 -> 24440 | BV5: =H36*BV4/1000 -> 22853.95 | BW5: =I36*BW4/1000 -> 23250 | ... DE5: =AQ36*DE4/1000 -> 20102.39 | DF5: x
BI6: Giá duyệt mua chai B1 | BJ6: 688.17627 | BK6: =BK16/BK4*1000 -> 0 | BL6: =BL16/BL4*1000 -> 0 | BM6: =BM16/BM4*1000 -> 0 | BN6: =BN16/BN4*1000 -> 0 | BO6: =BO16/BO4*1000 -> 0 | BP6: 18000 | BQ6: 18000 | BR6: 18000 | BS6: 16500 | BT6: 16500 | BU6: 16500 | BV6: 15500 | BW6: 14500 | BX6: 14500 | BY6: 15500 | BZ6: 15500 | CA6: 15500 | CB6: 13500 | CC6: 13000 | CD6: 13000 | CE6: 13500 | CF6: 14500 | CG6: 15000 | CH6: 15000 | CI6: 16500 | CJ6: 16500 | CK6: 16500 | CL6: 17500 | CM6: 17500 | CN6: 17500 | CO6: 16500 | CP6: 17000 | CQ6: 17500 | CR6: 17400 | CS6: 17700 | CT6: 17700 | CU6: =+(16800) -> 16800 | CV6: =+(16800) -> 16800 | CW6: =+(17200) -> 17200 | CX6: 18000 | CY6: 17500 | CZ6: 17500 | DA6: 17800 | DB6: 16150 | DC6: =(14500+13500+13000)/3 -> 13666.667 | DD6: 13500 | DE6: 12700
BI7: Giá bale ĐNA | BP7: =BP16*BP4/1000 -> 14237.25 | BQ7: =BQ16*BQ4/1000 -> 13890 | BR7: =BR16*BR4/1000 -> 13156.917 | BS7: =BS16*BS4/1000 -> 13156.917 | BT7: =BT16*BT4/1000 -> 13351.917 | BU7: =BU16*BU4/1000 -> 12220 | BV7: =BV16*BV4/1000 -> 10918.46 | BW7: =BW16*BW4/1000 -> 10776.375 | ... DE7: =DE16*DE4/1000 -> 12087.541
BI8: Giá chai B1 thực tế mua trung bình | BJ8: 15773 | BK8: 15974 | BL8: 15997 | BM8: 16512 | BN8: 17232 | BO8: 17845 | BP8: 17949.169 | BQ8: 18008.203 | BR8: 17709.211 | BS8: 16436.763 | BT8: 16498.897 | BU8: 16968.763 | BV8: 16873.812 | BW8: 14486.456 | BX8: 14337.016 | BY8: 15026.124 | BZ8: 14967.788 | CA8: 14928.984 | CB8: 13867.306 | CC8: 12969.009 | CD8: 12977.364 | CE8: 13498.82 | CF8: 14413.011 | CG8: 15100 | CH8: 15100 | CI8: 16099.441 | CJ8: 16332.331 | CK8: =16233.8475760353+377 -> 16610.848 | CL8: 17757.505 | CM8: 17263.633 | CN8: 17209.798 | CO8: 16215.033 | CP8: 16527.439 | CQ8: 16645.01 | CR8: 16492.39 | CS8: 16673.362 | CT8: 16581.723 | CU8: 16882.91 | CV8: 17173.91 | CW8: 17728.513 | CX8: 18247.4 | CY8: 18589.095 | CZ8: 18684.129 | DA8: 18901.794 | DB8: 18476.756 | DC8: 15949.265 | DD8: 14931.922 | DE8: 14927.828
BI9: Giá chai B1 thể hiện | BJ9: 688.17627 | BK9: 689.12856 | BL9: 692.27107 | BM9: 714.55773 | BN9: 745.71577 | BO9: 772.24338 | BP9: =BP6 -> 18000 | BQ9: =BQ6 -> 18000 | BR9: =BR6 -> 18000 | BS9: =BS6 -> 16500 | BT9: =BT6 -> 16500 | BU9: =BU6 -> 16500 | BV9: =BV6 -> 15500 | BW9: =BW6 -> 14500 | ... DE9: =DE6 -> 12700
BI10: % Keo chính phẩm so với chai B1 | BJ10: 0.63039625 | BK10: 0.69054088 | BL10: 0.83815278 | BM10: 0.88368266 | BN10: 0.73993907 | BO10: 0.70498926 | BP10: =BP13/BP6 -> 0.78769444 | BQ10: =BQ13/BQ6 -> 0.56905556 | BR10: =BR13/BR6 -> 0.63336111 | BS10: =BS13/BS6 -> 0.66960606 | BT10: =BT13/BT6 -> 0.60939394 | BU10: =BU13/BU6 -> 0.48121212 | BV10: =BV13/BV6 -> 0.47444839 | BW10: =BW13/BW6 -> 0.60344828 | ... DE10: =DE13/DE6 -> 0.58286535
BI11: % Giá chính phẩm tháng sau so với tháng trước | BK11: 0.038324421 | BL11: 0.092274678 | BM11: 0.057760314 | BN11: -0.036032689 | BO11: 0.014771997 | BP11: 0.055696203 | BQ11: -0.12230216 | BR11: 0.040983607 | BS11: -0.062992126 | BT11: -0.050420168 | BU11: -0.079646018 | BV11: -0.13495575 | BW11: -0.038461538 | BX11: 0.069053708 | BY11: 0.02 | BZ11: 0.009569378 | CA11: -0.045098039 | CB11: -0.14691943 | CC11: -0.14691943 | CD11: -0.14691943 | CE11: -0.14691943 | CF11: -0.14691943 | CG11: -0.14691943 | CH11: -0.14691943 | CI11: -0.14691943 | CJ11: -0.14691943 | CK11: -0.14691943 | CL11: -0.14691943 | CM11: -0.14691943 | CN11: -0.14691943 | CO11: -0.14691943 | CP11: -0.14691943 | CQ11: -0.14691943 | CR11: -0.14691943 | CS11: -0.14691943 | CT11: -0.14691943 | CU11: -0.14691943 | CV11: -0.14691943 | CW11: -0.14691943 | CX11: -0.14691943 | CY11: -0.14691943 | CZ11: -0.14691943 | DA11: -0.14691943 | DB11: -0.14691943 | DC11: -0.14691943 | DD11: -0.14691943 | DE11: -0.14691943
BI12: % Giá chai B1 tháng sau so với tháng trước | BK12: 0.0013837935 | BL12: 0.00456013 | BM12: 0.032193536 | BN12: 0.043604651 | BO12: 0.035573352 | BP12: 0.0040031347 | BQ12: 0.0032870912 | BR12: -0.017658818 | BS12: -0.070830978 | BT12: -0.011177818 | BU12: 0.028486575 | BV12: -0.0059372285 | BW12: -0.16408421 | BX12: -0.14405873 | BY12: 0.037253294 | BZ12: 0.04399603 | CA12: -0.0064647859 | CB12: -0.06465806 | CC12: -0.06465806 | CD12: -0.06465806 | CE12: -0.06465806 | CF12: -0.06465806 | CG12: -0.06465806 | CH12: -0.06465806 | CI12: -0.06465806 | CJ12: -0.06465806 | CK12: -0.06465806 | CL12: -0.06465806 | CM12: -0.06465806 | CN12: -0.06465806 | CO12: -0.06465806 | CP12: -0.06465806 | CQ12: -0.06465806 | CR12: -0.06465806 | CS12: -0.06465806 | CT12: -0.06465806 | CU12: -0.06465806 | CV12: -0.06465806 | CW12: -0.06465806 | CX12: -0.06465806 | CY12: -0.06465806 | CZ12: -0.06465806 | DA12: -0.06465806 | DB12: -0.06465806 | DC12: -0.06465806 | DD12: -0.06465806 | DE12: -0.06465806
BI13: Chênh lệch | BJ13: 433.82373 | BK13: 475.87144 | BL13: 580.22893 | BM13: 631.44227 | BN13: 551.78423 | BO13: 544.42329 | BP13: =BP5-BP6 -> 14178.5 | BQ13: =BQ5-BQ6 -> 10243 | BR13: =BR5-BR6 -> 11400.5 | BS13: =BS5-BS6 -> 11048.5 | BT13: =BT5-BT6 -> 10055 | BU13: =BU5-BU6 -> 7940 | BV13: =BV5-BV6 -> 7353.95 | BW13: =BW5-BW6 -> 8750 | ... DE13: =DE5-DE6 -> 7402.39
BI14: Giá bán rPET | BK14: 1300 | BL14: 1300 | BM14: 1450 | BN14: 1550 | BO14: 1550 | BP14: 1550 | BQ14: 1550 | BR14: 1480 | BS14: 1409.7447 | BT14: 1409.7447 | BU14: 1379.9766 | BV14: 1330 | BW14: 1330 | BX14: 1330 | BY14: 1380 | BZ14: 1380 | CA14: 1380 | CB14: 1350 | CC14: 1300 | CD14: 1250 | CE14: 1250 | CF14: 1250 | CG14: 1250 | CH14: 1250 | CI14: 1250 | CJ14: 1250 | CK14: 1250 | CL14: 1250 | CM14: 1300 | CN14: 1300 | CO14: 1300 | CP14: 1300 | CQ14: 1310 | CR14: 1325 | CS14: 1325 | CT14: 1325 | CU14: 1325 | CV14: 1250 | CW14: 1250 | CX14: 1250 | CY14: 1250 | CZ14: 1250 | DA14: 1250 | DB14: 1250 | DC14: 1250 | DD14: 1250 | DE14: 1250
BI15: Giá chính phẩm dự báo | BK15: 1165 | BL15: 1272.5 | BM15: 1346 | BN15: 1297.5 | BO15: 1316.6667 | BP15: 1390 | BQ15: 1220 | BR15: 1270 | BS15: 1190 | BT15: 1130 | BU15: 1040 | BV15: 977.5 | BW15: 1000 | BX15: 1045 | BY15: 1020 | BZ15: 1055 | CA15: 974 | CB15: =CB5 -> 20880.35 | CC15: =CC5 -> 21112.14 | CD15: =CD5 -> 21885.12 | CE15: =CE5 -> 22282.8 | CF15: =CF5 -> 22398.3 | CG15: =CG5 -> 22257 | CH15: =CH5 -> 22437 | CI15: =CI5 -> 22515.3 | ... DE15: =DE5 -> 20102.39
BI16: Giá bale ĐNA ( USD) | BP16: 615 | BQ16: 600 | BR16: 568.33333 | BS16: 568.33333 | BT16: 568.16667 | BU16: 520 | BV16: 467 | BW16: 463.5 | BX16: 451.5 | BY16: 471.66667 | BZ16: 501.66667 | CA16: 472.5 | CB16: 454.33333 | CC16: 453 | CD16: 433.2 | CE16: 412.7 | CF16: 419.2 | CG16: 457.4 | CH16: 474.1 | CI16: 474.1 | CJ16: 495.7 | CK16: 494.3 | CL16: 515.7 | CM16: 560 | CN16: 563.5 | CO16: 567.2 | CP16: 579.4 | CQ16: 602 | CR16: 635.5 | CS16: 630.7 | CT16: 613.3 | CU16: 588.8 | CV16: 595.2 | CW16: 595.2 | CX16: 581.8 | CY16: 577.2 | CZ16: 578.7 | DA16: 555 | DB16: 522.6 | DC16: 496.7 | DD16: 463 | DE16: 463
BI17: Giá mua chai B0 | BW17: 8708.4662 | BX17: 9206.5027 | BY17: 10350.583 | BZ17: 10630.801 | CA17: 9861.484 | CB17: 9199.095 | CC17: 8896.0365 | CD17: 9246.3978 | CE17: 9607.8931 | CF17: 10586.188 | CG17: 11153.125 | CH17: 11113.72 | CI17: 11037.143 | CJ17: 11020.853 | CK17: 11214.841 | CL17: 12186.078 | CM17: 12797.389 | CN17: 12681.898 | CO17: 11321.884 | CP17: 11447.006 | CQ17: 11654.137 | CR17: 11518.17 | CS17: 12011.497 | CT17: 11852.302 | CU17: 12060.749 | CV17: 12125.305 | CW17: 12519.736 | CX17: 13075.123 | CY17: 12848.716 | CZ17: 13370.127 | DA17: 13565.086 | DB17: 12327.306 | DC17: 9962.9823 | DD17: 9535.2548 | DE17: 9525.0112 | DF17: Dòng này xin lại của Huyền
BI18: Chênh lệch B1 thực tế và giá keo | CI18: =CI5-CI8 -> 6415.8586 | CJ18: =CJ5-CJ8 -> 6535.419 | CK18: =CK5-CK8 -> 6409.7524 | CL18: =CL5-CL8 -> 5451.0949 | CM18: =CM5-CM8 -> 6733.817 | CN18: =CN5-CN8 -> 6777.7024 | CO18: =CO5-CO8 -> 8195.9673 | CP18: =CP5-CP8 -> 6843.461 | ... DE18: =DE5-DE8 -> 5174.5622
BI19: % B1 TT sv Giá keo | CI19: =IFERROR(CI18/CI15,0) -> 0.2849555 | CJ19: =IFERROR(CJ18/CJ15,0) -> 0.28579196 | CK19: =IFERROR(CK18/CK15,0) -> 0.27843551 | CL19: =IFERROR(CL18/CL15,0) -> 0.23487392 | CM19: =IFERROR(CM18/CM15,0) -> 0.28060552 | CN19: =IFERROR(CN18/CN15,0) -> 0.28255143 | CO19: =IFERROR(CO18/CO15,0) -> 0.33574894 | CP19: =IFERROR(CP18/CP15,0) -> 0.29281975 | ... DE19: =IFERROR(DE18/DE15,0) -> 0.2574103
BI20: Label - Chênh lệch chai B0 TT và giá keo | CI20: =_xlfn.TEXTJOIN(CHAR(10),FALSE,TEXT(CI18,"#,###"),TEXT(CI19,"0.0%")) -> 6,416 28.5% | CJ20: =_xlfn.TEXTJOIN(CHAR(10),FALSE,TEXT(CJ18,"#,###"),TEXT(CJ19,"0.0%")) -> 6,535 28.6% | CK20: =_xlfn.TEXTJOIN(CHAR(10),FALSE,TEXT(CK18,"#,###"),TEXT(CK19,"0.0%")) -> 6,410 27.8% | CL20: =_xlfn.TEXTJOIN(CHAR(10),FALSE,TEXT(CL18,"#,###"),TEXT(CL19,"0.0%")) -> 5,451 23.5% | CM20: =_xlfn.TEXTJOIN(CHAR(10),FALSE,TEXT(CM18,"#,###"),TEXT(CM19,"0.0%")) -> 6,734 28.1% | CN20: =_xlfn.TEXTJOIN(CHAR(10),FALSE,TEXT(CN18,"#,###"),TEXT(CN19,"0.0%")) -> 6,778 28.3% | CO20: =_xlfn.TEXTJOIN(CHAR(10),FALSE,TEXT(CO18,"#,###"),TEXT(CO19,"0.0%")) -> 8,196 33.6% | CP20: =_xlfn.TEXTJOIN(CHAR(10),FALSE,TEXT(CP18,"#,###"),TEXT(CP19,"0.0%")) -> 6,843 29.3% | ... DE20: =_xlfn.TEXTJOIN(CHAR(10),FALSE,TEXT(DE18,"#,###"),TEXT(DE19,"0.0%")) -> 5,175 25.7%
BI21: Line-Trình bày-Chênh lệch B1 thực tế và giá keo | CI21: =CI8+CI18/2 -> 19307.371 | CJ21: =CJ8+CJ18/2 -> 19600.041 | CK21: =CK8+CK18/2 -> 19815.724 | CL21: =CL8+CL18/2 -> 20483.053 | CM21: =CM8+CM18/2 -> 20630.541 | CN21: =CN8+CN18/2 -> 20598.649 | CO21: =CO8+CO18/2 -> 20313.016 | CP21: =CP8+CP18/2 -> 19949.169 | ... DE21: =DE8+DE18/2 -> 17515.109
A35: Tháng | B35: 06/22 | C35: 7 | D35: 8 | E35: 9 | F35: 10 | G35: 11 | H35: 12 | I35: 1/23 | J35: 2 | K35: 3 | L35: 4 | M35: 5 | N35: 6 | O35: 7 | P35: 8 | Q35: 9 | R35: 10 | S35: 11 | T35: 12 | U35: 1.24 | V35: 2 | W35: 3 | X35: 4 | Y35: 5 | Z35: 6 | AA35: 7 | AB35: 8 | AC35: 9 | AD35: 10 | AE35: 11 | AF35: 12 | AG35: 1.25 | AH35: 2 | AI35: 3 | AJ35: 4 | AK35: 5 | AL35: 6 | AM35: 7 | AN35: 8 | AO35: 9 | AP35: 10 | AQ35: 11
A36: Giá RESIN (USD/ Tấn) | B36: 1390 | C36: 1220 | D36: 1270 | E36: 1190 | F36: 1130 | G36: 1040 | H36: 977.5 | I36: 1000 | J36: 1045 | K36: 1020 | L36: 1055 | M36: 974 | N36: 895 | O36: 903 | P36: 918 | Q36: 930 | R36: 922.5 | S36: 900 | T36: 900 | U36: 930 | V36: 943 | W36: 940 | X36: 940 | Y36: 942 | Z36: 950 | AA36: 948 | AB36: 930 | AC36: 880 | AD36: 862.5 | AE36: 852 | AF36: 840 | AG36: 828 | AH36: 840 | AI36: 823 | AJ36: 765 | AK36: 782 | AL36: 807.5 | AM36: 802 | AN36: 795 | AO36: 783 | AP36: 773 | AQ36: 770
A45: 1. Sửa lại Tiêu đề (đã chỉnh biểu đồ bên dưới)
A46: 2. chỉnh lại size để thấy 1 màn hình
A47: 3. biểu đồ trình bày bằng VNĐ/kg, lấy tỷ giá tại ngày cuối tháng
A48: 4. Bảng số liệu chỉ trình bày 1 dòng giá keo chính phẩm bằng usd/tấn
A49: 5. Thêm 1 đường giá thực mua trung bình hàng tháng

Sheet Vảy PET- Tháng
AR3: Data | AS3: 1.23 | AT3: 2 | AU3: 3 | AV3: 4 | AW3: 5 | AX3: 6 | AY3: 7 | AZ3: 8 | BA3: 9 | BB3: 10 | BC3: 11 | BD3: 12 | BE3: 1.24 | BF3: 2 | BG3: 3 | BH3: 4 | BI3: 5 | BJ3: 6 | BK3: 7 | BL3: 8 | BM3: 9 | BN3: 10 | BO3: 11 | BP3: 12 | BQ3: 1.25 | BR3: 2 | BS3: 3 | BT3: 4 | BU3: 5 | BV3: 6 | BW3: 7 | BX3: 8 | BY3: 9 | BZ3: 10 | CA3: 11 | CB3: 12
AR4: Tỷ giá USD | AS4: 23250 | AT4: 23570 | AU4: 23260 | AV4: 23260 | AW4: 23295 | AX4: 23330 | AY4: 23380 | AZ4: 23840 | BA4: 23960 | BB4: 24280 | BC4: 24730 | BD4: 24930 | BE4: 24210 | BF4: 24250 | BG4: 24490 | BH4: 24690 | BI4: 25475 | BJ4: 25250 | BK4: 25270 | BL4: 25130 | BM4: ='Chai B1- Tháng'!CQ4 -> 24580 | BN4: ='Chai B1- Tháng'!CR4 -> 24410 | BO4: ='Chai B1- Tháng'!CS4 -> 25120 | BP4: ='Chai B1- Tháng'!CT4 -> 25140 | BQ4: ='Chai B1- Tháng'!CU4 -> 25290 | BR4: ='Chai B1- Tháng'!CV4 -> 25050 | BS4: ='Chai B1- Tháng'!CW4 -> 25400 | BT4: ='Chai B1- Tháng'!CX4 -> 25460 | ... CB4: ='Chai B1- Tháng'!DF4 -> 26181
AR5: Giá keo chính phẩm | AS5: =C40*AS4/1000 -> 23250 | AT5: =D40*AT4/1000 -> 24630.65 | AU5: =E40*AU4/1000 -> 23725.2 | AV5: =F40*AV4/1000 -> 24539.3 | AW5: =G40*AW4/1000 -> 22689.33 | AX5: =H40*AX4/1000 -> 20880.35 | AY5: =I40*AY4/1000 -> 21112.14 | AZ5: =J40*AZ4/1000 -> 21885.12 | ... BY5: =AI40*BY4/1000 -> 20498.94 | BZ5: ='Chai B1- Tháng'!DD5 -> 20213.276 | CA5: ='Chai B1- Tháng'!DE5 -> 20102.39 | CB5: ='Chai B1- Tháng'!DF5 -> 20159.37
AR6: Giá duyệt mua vảy PET | AS6: 17500 | AT6: 17500 | AU6: 18500 | AV6: 18500 | AW6: 18500 | AX6: 17500 | AY6: 16000 | AZ6: 16000 | BA6: 16500 | BB6: 17500 | BC6: 18100 | BD6: 18100 | BE6: 18100 | BF6: =18500+100 -> 18600 | BG6: =18800+100 -> 18900 | BH6: 19300 | BI6: 19800 | BJ6: 19800 | BK6: 18300 | BL6: 18300 | BM6: =18300+350 -> 18650 | BN6: =18000+350 -> 18350 | BO6: =18000+350+200 -> 18550 | BP6: =18200+350 -> 18550 | BQ6: =18200+350 -> 18550 | BR6: =18500+350 -> 18850 | BS6: =19000+350+200 -> 19550 | BT6: =19700+350 -> 20050 | BU6: =19000+350 -> 19350 | BV6: =19500+350 -> 19850 | BW6: =19500+350 -> 19850 | BX6: =18500+350 -> 18850 | BY6: =(17000+16700+16300)/3 -> 16666.667 | BZ6: 16500 | CA6: 16000 | CB6: 16000
AR7: Giá vảy ĐNA | AS7: =AS14*AS4/1000 -> 22227 | AT7: =AT14*AT4/1000 -> 22462.21 | AU7: =AU14*AU4/1000 -> 21980.7 | AV7: =AV14*AV4/1000 -> 21282.9 | AW7: =AW14*AW4/1000 -> 20336.535 | AX7: =AX14*AX4/1000 -> 19958.815 | AY7: =AY14*AY4/1000 -> 20001.59 | AZ7: =AZ14*AZ4/1000 -> 21587.12 | ... CB7: =CB14*CB4/1000 -> 20562.557
AR8: Giá vảy thể hiện | AS8: =AS6 -> 17500 | AT8: =AT6 -> 17500 | AU8: =AU6 -> 18500 | AV8: =AV6 -> 18500 | AW8: =AW6 -> 18500 | AX8: =AX6 -> 17500 | AY8: =AY6 -> 16000 | AZ8: =AZ6 -> 16000 | ... CB8: =CB6 -> 16000
AR9: Giá vảy PET B1 thực tế mua trung bình | AS9: 17112 | AT9: 17235 | AU9: 17583 | AV9: 17672 | AW9: 17728 | AX9: 16972.6 | AY9: 15973.539 | AZ9: 15985.32 | BA9: 16507.339 | BB9: 16955.713 | BC9: 18100 | BD9: 18100 | BE9: 17983.907 | BF9: 18622.996 | BG9: 19295.577 | BH9: 19576.984 | BI9: 19725.621 | BJ9: 19648.515 | BK9: 17863.337 | BL9: 17899.536 | BM9: 18513.416 | BN9: 18204.855 | BO9: 18460.149 | BP9: 18530.381 | BQ9: 18233.79 | BR9: 18955.246 | BS9: 19549.833 | BT9: 20207.22 | BU9: 19559.258 | BV9: 20221.371 | BW9: 20096.025 | BX9: 19291.318 | BY9: 16751.836 | BZ9: 16016.425 | CA9: 15747.969 | CB9: =CB6 -> 16000
AR10: % Keo chính phẩm so với vảy PET | AS10: =AS5/AS6-1 -> 0.32857143 | AT10: =AT5/AT6-1 -> 0.40746571 | AU10: =AU5/AU6-1 -> 0.28244324 | AV10: =AV5/AV6-1 -> 0.32644865 | AW10: =AW5/AW6-1 -> 0.22645027 | AX10: =AX5/AX6-1 -> 0.19316286 | AY10: =AY5/AY6-1 -> 0.31950875 | AZ10: =AZ5/AZ6-1 -> 0.36782 | ... CB10: =CB5/CB6-1 -> 0.25996062
AR11: Chênh lệch | AS11: =AS5-AS6 -> 5750 | AT11: =AT5-AT6 -> 7130.65 | AU11: =AU5-AU6 -> 5225.2 | AV11: =AV5-AV6 -> 6039.3 | AW11: =AW5-AW6 -> 4189.33 | AX11: =AX5-AX6 -> 3380.35 | AY11: =AY5-AY6 -> 5112.14 | AZ11: =AZ5-AZ6 -> 5885.12 | ... CB11: =CB5-CB6 -> 4159.37
AR12: Giá bán rPET | AS12: 1330 | AT12: 1330 | AU12: 1380 | AV12: 1380 | AW12: 1380 | AX12: 1350 | AY12: 1300 | AZ12: 1250 | BA12: 1250 | BB12: 1250 | BC12: 1250 | BD12: 1250 | BE12: 1250 | BF12: 1250 | BG12: 1250 | BH12: 1250 | BI12: 1300 | BJ12: 1300 | BK12: 1300 | BL12: 1300
AR13: Giá chính phẩm dự báo | AS13: =AS5 -> 23250 | AT13: =AT5 -> 24630.65 | AU13: =AU5 -> 23725.2 | AV13: =AV5 -> 24539.3 | AW13: =AW5 -> 22689.33 | AX13: =AX5 -> 20880.35 | AY13: =AY5 -> 21112.14 | AZ13: =AZ5 -> 21885.12 | ... CB13: =CB5 -> 20159.37
AR14: Giá vảy ĐNA (usd) | AS14: 956 | AT14: 953 | AU14: 945 | AV14: 915 | AW14: 873 | AX14: =+(851+860)/2 -> 855.5 | AY14: =+(851+860)/2 -> 855.5 | AZ14: =(859+952)/2 -> 905.5 | BA14: =(825+941)/2 -> 883 | BB14: =(825+927)/2 -> 876 | BC14: =(840+945)/2 -> 892.5 | BD14: =(840+945)/2 -> 892.5 | BE14: =(840+955)/2 -> 897.5 | BF14: =(840+955)/2 -> 897.5 | BG14: =(840+955)/2 -> 897.5 | BH14: =(860+955)/2 -> 907.5 | BI14: 955 | BJ14: 1015 | BK14: 995 | BL14: 995 | BM14: 1020 | BN14: 1020 | BO14: 1020 | BP14: 1025 | BQ14: 1025 | BR14: 1010 | BS14: 1012.5 | BT14: 1015 | BU14: 1016.5 | BV14: 1047 | BW14: 961.9 | BX14: 914.0625 | BY14: 853.25 | BZ14: 810.2 | CA14: 785.4 | CB14: 785.4
K29: -13700
C30: 1165,1272.5,1346,1297.5,1316.66666666665,1390,1220,1270,1190,1130,1040,1040
C32: 1165 | D32: 1272.5 | E32: 1346 | F32: 1297.5 | G32: 1316.6667 | H32: 1390 | I32: 1220 | J32: 1270 | K32: 1190 | L32: 1130 | M32: 1040 | N32: 1040
B33: tỉ lệ | C33: 27960 | D33: 30540 | E33: 32304 | F33: 31140 | G33: 31600 | H33: 33360 | I33: 29280 | J33: 30480 | K33: 28560 | L33: 27120 | M33: 24960 | N33: 24960
B39: Tháng | C39: 01/23 | D39: 2 | E39: 3 | F39: 4 | G39: 5 | H39: 6 | I39: 7 | J39: 8 | K39: 9 | L39: 10 | M39: 11 | N39: 12 | O39: 1.24 | P39: 2 | Q39: 3 | R39: 4 | S39: 5 | T39: 6 | U39: 7 | V39: 8 | W39: 9 | X39: 10 | Y39: 11 | Z39: 12 | AA39: 1.25 | AB39: 2 | AC39: 3 | AD39: 4 | AE39: 5 | AF39: 6 | AG39: 7 | AH39: 8 | AI39: 9 | AJ39: 10 | AK39: 11 | AL39: 12
B40: Giá Resin (USD/ Tấn) | C40: 1000 | D40: 1045 | E40: 1020 | F40: 1055 | G40: 974 | H40: 895 | I40: 903 | J40: 918 | K40: 930 | L40: 922.5 | M40: 900 | N40: 900 | O40: 930 | P40: 943 | Q40: 940 | R40: 940 | S40: 942 | T40: 950 | U40: 948 | V40: 930 | W40: 880 | X40: 862.5 | Y40: 852 | Z40: 830 | AA40: 828 | AB40: 840 | AC40: 823 | AD40: 765 | AE40: 782 | AF40: 807.5 | AG40: 802 | AH40: 795 | AI40: ='Chai B1- Tháng'!AO36 -> 783 | AJ40: ='Chai B1- Tháng'!AP36 -> 772 | AK40: ='Chai B1- Tháng'!AQ36 -> 770 | AL40: ='Chai B1- Tháng'!AR36 -> 770

Sheet Chart Vảy PET_Tuần
V45: Data | W45: 1 | X45: 2 | Y45: 3 | Z45: 4 | AA45: 5 | AB45: 6 | AC45: 7 | AD45: 8 | AE45: 9 | AF45: 10 | AG45: 11 | AH45: 12 | AI45: 13 | AJ45: 14 | AK45: 15 | AL45: 16 | AM45: 17 | AN45: 18 | AO45: 19 | AP45: 20 | AQ45: 21 | AR45: 22 | AS45: 23 | AT45: 24 | AU45: 25 | AV45: 26 | AW45: 27 | AX45: 28 | AY45: 29 | AZ45: 30 | BA45: 31 | BB45: 32 | BC45: 33 | BD45: 34
V46: Tỷ giá USD | W46: ='Chart B1_Tuần'!BF45 -> 24760 | X46: ='Chart B1_Tuần'!BG45 -> 24200 | Y46: ='Chart B1_Tuần'!BH45 -> 24330 | Z46: ='Chart B1_Tuần'!BI45 -> 24410 | AA46: ='Chart B1_Tuần'!BJ45 -> 24380 | AB46: ='Chart B1_Tuần'!BK45 -> 24220 | AC46: ='Chart B1_Tuần'!BL45 -> 24250 | AD46: ='Chart B1_Tuần'!BM45 -> 24380 | ... BE46: ='Chart B1_Tuần'!CN45 -> 0
V47: Giá keo chính phẩm | W47: =W46*W53/1000 -> 22284 | X47: =X46*X53/1000 -> 22748 | Y47: =Y46*Y53/1000 -> 22870.2 | Z47: =Z46*Z53/1000 -> 22945.4 | AA47: =AA46*AA53/1000 -> 23161 | AB47: =AB46*AB53/1000 -> 22766.8 | AC47: =AC46*AC53/1000 -> 22795 | AD47: =AD46*AD53/1000 -> 22917.2 | ... BD47: =BD46*BD53/1000 -> 23321.4
V48: Giá duyệt mua vảy PET | W48: 18000 | X48: 18000 | Y48: 18000 | Z48: 18000 | AA48: 18500 | AB48: 18500 | AC48: 18500 | AD48: 18500 | AE48: 18500 | AF48: 18500 | AG48: 18500 | AH48: 18500 | AI48: 18500 | AJ48: 19000 | AK48: 19000 | AL48: 19000 | AM48: 19000 | AN48: 19500 | AO48: 19500 | AP48: 19500 | AQ48: 19500 | AR48: 19500 | AS48: 19500 | AT48: 19500 | AU48: 19500 | AV48: 19500 | AW48: 18000 | AX48: 18000 | AY48: 18000 | AZ48: 18000 | BA48: 18000 | BB48: 18000 | BC48: 18000 | BD48: 18000
V49: Giá vảy PET thể hiện | W49: =W48 -> 18000 | X49: =X48 -> 18000 | Y49: =Y48 -> 18000 | Z49: =Z48 -> 18000 | AA49: =AA48 -> 18500 | AB49: =AB48 -> 18500 | AC49: =AC48 -> 18500 | AD49: =AD48 -> 18500 | ... BD49: =BD48 -> 18000
V50: Giá vảy PET thực tế mua trung bình | W50: 17788.268 | X50: 17828.592 | Y50: 17854.223 | Z50: 17920.599 | AA50: 17910.699 | AB50: 17862.172 | AC50: 17862.172 | AD50: 17947.186 | AE50: 18173.051 | AF50: 18673.486 | AG50: 18747.334 | AH50: 18761.632 | AI50: 18757.926 | AJ50: 19026.001 | AK50: 18925.617 | AL50: 18914.749 | AM50: 18943.065 | AN50: 19077.338 | AO50: 19443.202 | AP50: 19415.534 | AQ50: 19403.916 | AR50: 19281.645 | AS50: 19318.549 | AT50: 19421.069 | AU50: 19388.157 | AV50: 19218.54 | AW50: 17763.704 | AX50: 17851.469 | AY50: 17795.9 | AZ50: 17825.036 | BA50: 17796.164 | BB50: 17664.788 | BC50: 17690.789 | BD50: 17605.585
V51: % chính phẩm với vảy PET | W51: =W52/W48 -> 0.238 | X51: =X52/X48 -> 0.26377778 | Y51: =Y52/Y48 -> 0.27056667 | Z51: =Z52/Z48 -> 0.27474444 | AA51: =AA52/AA48 -> 0.25194595 | AB51: =AB52/AB48 -> 0.23063784 | AC51: =AC52/AC48 -> 0.23216216 | AD51: =AD52/AD48 -> 0.23876757 | ... BD51: =BD52/BD48 -> 0.29563333
V52: Chênh lệch | W52: =W47-W48 -> 4284 | X52: =X47-X48 -> 4748 | Y52: =Y47-Y48 -> 4870.2 | Z52: =Z47-Z48 -> 4945.4 | AA52: =AA47-AA48 -> 4661 | AB52: =AB47-AB48 -> 4266.8 | AC52: =AC47-AC48 -> 4295 | AD52: =AD47-AD48 -> 4417.2 | ... BD52: =BD47-BD48 -> 5321.4
V53: Giá chính phẩm USD | W53: ='Chart B1_Tuần'!BF56 -> 900 | X53: ='Chart B1_Tuần'!BG56 -> 940 | Y53: ='Chart B1_Tuần'!BH56 -> 940 | Z53: ='Chart B1_Tuần'!BI56 -> 940 | AA53: ='Chart B1_Tuần'!BJ56 -> 950 | AB53: ='Chart B1_Tuần'!BK56 -> 940 | AC53: ='Chart B1_Tuần'!BL56 -> 940 | AD53: ='Chart B1_Tuần'!BM56 -> 940 | ... BD53: ='Chart B1_Tuần'!CM56 -> 940
B67: Tháng | P67: T6
B68: % chênh lệch giữa keo chính phẩm so với chai B1 | P68: 0.85859936
C69: 1165, | O69: 1272.5, | P69: 1346, | Q69: 1297.5, | R69: 1316.66666666665,1390,1220,1270,1190,1130,1040,1040 | T69: 1270
C71: 1165,1272.5,1346,1297.5,1316.66666666665,1390,1220,1270,1190,1130,1040,1040
C73: 1165 | O73: 1272.5 | P73: 1346 | Q73: 1297.5 | R73: 1316.6667 | S73: 1390 | T73: 1220
B74: tỉ lệ | C74: 27960 | O74: 30540 | P74: 32304 | Q74: 31140 | R74: 31600 | S74: 33360 | T74: 29280

Sheet Vảy PET- Tháng  - Danh
BE2: 2024 | BQ2: 2025
AR3: Data | AS3: 1.23 | AT3: 2 | AU3: 3 | AV3: 4 | AW3: 5 | AX3: 6 | AY3: 7 | AZ3: 8 | BA3: 9 | BB3: 10 | BC3: 11 | BD3: 12 | BE3: 1 | BF3: 2 | BG3: 3 | BH3: 4 | BI3: 5 | BJ3: 6 | BK3: 7 | BL3: 8 | BM3: 9 | BN3: 10 | BO3: 11 | BP3: 12 | BQ3: 1 | BR3: 2 | BS3: 3 | BT3: 4 | BU3: 5 | BV3: 6 | BW3: 7 | BX3: 8 | BY3: 9 | BZ3: 10 | CA3: 11
AR4: Tỷ giá USD | AS4: 23250 | AT4: 23570 | AU4: 23260 | AV4: 23260 | AW4: 23295 | AX4: 23330 | AY4: 23380 | AZ4: 23840 | BA4: 23960 | BB4: 24280 | BC4: 24730 | BD4: 24930 | BE4: 24210 | BF4: 24250 | BG4: 24490 | BH4: 24690 | BI4: 25475 | BJ4: 25250 | BK4: 25270 | BL4: 25130 | BM4: ='Chai B1- Tháng'!CQ4 -> 24580 | BN4: ='Chai B1- Tháng'!CR4 -> 24410 | BO4: ='Chai B1- Tháng'!CS4 -> 25120 | BP4: ='Chai B1- Tháng'!CT4 -> 25140 | BQ4: ='Chai B1- Tháng'!CU4 -> 25290 | BR4: ='Chai B1- Tháng'!CV4 -> 25050 | BS4: ='Chai B1- Tháng'!CW4 -> 25400 | BT4: ='Chai B1- Tháng'!CX4 -> 25460 | ... CA4: ='Chai B1- Tháng'!DE4 -> 26107
AR5: Giá keo chính phẩm | AS5: =C40*AS4/1000 -> 23250 | AT5: =D40*AT4/1000 -> 24630.65 | AU5: =E40*AU4/1000 -> 23725.2 | AV5: =F40*AV4/1000 -> 24539.3 | AW5: =G40*AW4/1000 -> 22689.33 | AX5: =H40*AX4/1000 -> 20880.35 | AY5: =I40*AY4/1000 -> 21112.14 | AZ5: =J40*AZ4/1000 -> 21885.12 | ... CA5: =AK40*CA4/1000 -> 20102.39
AR6: Giá duyệt mua vảy PET | AS6: 17500 | AT6: 17500 | AU6: 18500 | AV6: 18500 | AW6: 18500 | AX6: 17500 | AY6: 16000 | AZ6: 16000 | BA6: 16500 | BB6: 17500 | BC6: 18100 | BD6: 18100 | BE6: 18100 | BF6: =18500+100 -> 18600 | BG6: =18800+100 -> 18900 | BH6: 19300 | BI6: 19800 | BJ6: 19800 | BK6: 18300 | BL6: 18300 | BM6: =18300+350 -> 18650 | BN6: =18000+350 -> 18350 | BO6: =18000+350+200 -> 18550 | BP6: =18200+350 -> 18550 | BQ6: =18200+350 -> 18550 | BR6: =18500+350 -> 18850 | BS6: =19000+350+200 -> 19550 | BT6: =19700+350 -> 20050 | BU6: =19000+350 -> 19350 | BV6: =19500+350 -> 19850 | BW6: =19500+350 -> 19850 | BX6: =18500+350 -> 18850 | BY6: =(17000+16700+16300)/3 -> 16666.667 | BZ6: 16500 | CA6: 16000
AR7: Giá vảy ĐNA | AS7: =AS14*AS4/1000 -> 22227 | AT7: =AT14*AT4/1000 -> 22462.21 | AU7: =AU14*AU4/1000 -> 21980.7 | AV7: =AV14*AV4/1000 -> 21282.9 | AW7: =AW14*AW4/1000 -> 20336.535 | AX7: =AX14*AX4/1000 -> 19958.815 | AY7: =AY14*AY4/1000 -> 20001.59 | AZ7: =AZ14*AZ4/1000 -> 21587.12 | ... CA7: =CA14*CA4/1000 -> 21804.24
AR8: Giá vảy thể hiện | AS8: =AS6 -> 17500 | AT8: =AT6 -> 17500 | AU8: =AU6 -> 18500 | AV8: =AV6 -> 18500 | AW8: =AW6 -> 18500 | AX8: =AX6 -> 17500 | AY8: =AY6 -> 16000 | AZ8: =AZ6 -> 16000 | ... CA8: =CA6 -> 16000
AR9: Giá vảy PET B1 thực tế mua trung bình | AS9: 17112 | AT9: 17235 | AU9: 17583 | AV9: 17672 | AW9: 17728 | AX9: 16972.6 | AY9: 15973.539 | AZ9: 15985.32 | BA9: 16507.339 | BB9: 16955.713 | BC9: 18100 | BD9: 18100 | BE9: 17983.907 | BF9: 18622.996 | BG9: 19295.577 | BH9: 19569.896 | BI9: 19725.621 | BJ9: 19648.515 | BK9: 17878.189 | BL9: 17899.536 | BM9: 18513.416 | BN9: 18204.855 | BO9: 18460.149 | BP9: 18530.381 | BQ9: 18233.79 | BR9: 18955.246 | BS9: 19549.833 | BT9: 20207.22 | BU9: 19559.258 | BV9: 20221.371 | BW9: 20096.025 | BX9: 19291.318 | BY9: 16751.836 | BZ9: 16016.425 | CA9: 15757.62
AR10: % Keo chính phẩm so với vảy PET | AS10: =AS5/AS6-1 -> 0.32857143 | AT10: =AT5/AT6-1 -> 0.40746571 | AU10: =AU5/AU6-1 -> 0.28244324 | AV10: =AV5/AV6-1 -> 0.32644865 | AW10: =AW5/AW6-1 -> 0.22645027 | AX10: =AX5/AX6-1 -> 0.19316286 | AY10: =AY5/AY6-1 -> 0.31950875 | AZ10: =AZ5/AZ6-1 -> 0.36782 | ... CA10: =CA5/CA6-1 -> 0.25639937
AR11: Chênh lệch | AS11: =AS5-AS6 -> 5750 | AT11: =AT5-AT6 -> 7130.65 | AU11: =AU5-AU6 -> 5225.2 | AV11: =AV5-AV6 -> 6039.3 | AW11: =AW5-AW6 -> 4189.33 | AX11: =AX5-AX6 -> 3380.35 | AY11: =AY5-AY6 -> 5112.14 | AZ11: =AZ5-AZ6 -> 5885.12 | ... CA11: =CA5-CA6 -> 4102.39
AR12: Giá bán rPET | AS12: 1330 | AT12: 1330 | AU12: 1380 | AV12: 1380 | AW12: 1380 | AX12: 1350 | AY12: 1300 | AZ12: 1250 | BA12: 1250 | BB12: 1250 | BC12: 1250 | BD12: 1250 | BE12: 1250 | BF12: 1250 | BG12: 1250 | BH12: 1250 | BI12: 1300 | BJ12: 1300 | BK12: 1300 | BL12: 1300
AR13: Giá chính phẩm dự báo | AS13: =AS5 -> 23250 | AT13: =AT5 -> 24630.65 | AU13: =AU5 -> 23725.2 | AV13: =AV5 -> 24539.3 | AW13: =AW5 -> 22689.33 | AX13: =AX5 -> 20880.35 | AY13: =AY5 -> 21112.14 | AZ13: =AZ5 -> 21885.12 | ... CA13: =CA5 -> 20102.39
AR14: Giá vảy ĐNA (usd) | AS14: 956 | AT14: 953 | AU14: 945 | AV14: 915 | AW14: 873 | AX14: =+(851+860)/2 -> 855.5 | AY14: =+(851+860)/2 -> 855.5 | AZ14: =(859+952)/2 -> 905.5 | BA14: =(825+941)/2 -> 883 | BB14: =(825+927)/2 -> 876 | BC14: =(840+945)/2 -> 892.5 | BD14: =(840+945)/2 -> 892.5 | BE14: =(840+955)/2 -> 897.5 | BF14: =(840+955)/2 -> 897.5 | BG14: =(840+955)/2 -> 897.5 | BH14: =(860+955)/2 -> 907.5 | BI14: 955 | BJ14: 1015 | BK14: 995 | BL14: 995 | BM14: 1020 | BN14: 1020 | BO14: 1020 | BP14: 1025 | BQ14: 1025 | BR14: 1010 | BS14: 1012.5 | BT14: 1015 | BU14: 1016.5 | BV14: 1047 | BW14: 961.9 | BX14: 914.0625 | BY14: 853.25 | BZ14: 835.1875 | CA14: 835.1875
AR15: Chênh lệch Vảy thực tế và giá keo | BE15: =BE13-BE9 -> 4531.393 | BF15: =BF13-BF9 -> 4244.7539 | BG15: =BG13-BG9 -> 3725.0231 | BH15: =BH13-BH9 -> 3638.7041 | BI15: =BI13-BI9 -> 4271.8289 | BJ15: =BJ13-BJ9 -> 4338.9852 | BK15: =BK13-BK9 -> 6077.7713 | BL15: =BL13-BL9 -> 5471.3637 | ... CA15: =CA13-CA9 -> 4344.77
AR16: % | BE16: =IFERROR(BE15/BE13,0) -> 0.20125839 | BF16: =IFERROR(BF15/BF13,0) -> 0.18562184 | BG16: =IFERROR(BG15/BG13,0) -> 0.1618126 | BH16: =IFERROR(BH15/BH13,0) -> 0.15678258 | BI16: =IFERROR(BI15/BI13,0) -> 0.17801179 | BJ16: =IFERROR(BJ15/BJ13,0) -> 0.18088526 | BK16: =IFERROR(BK15/BK13,0) -> 0.25370602 | BL16: =IFERROR(BL15/BL13,0) -> 0.2341101 | ... CA16: =IFERROR(CA15/CA13,0) -> 0.21613201
AR17: Label - Chênh lệch Vảy thực tế và giá keo | BE17: =_xlfn.TEXTJOIN(CHAR(10),FALSE,TEXT(BE15,"#,###"),TEXT(BE16,"0.0%")) -> 4,531 20.1% | BF17: =_xlfn.TEXTJOIN(CHAR(10),FALSE,TEXT(BF15,"#,###"),TEXT(BF16,"0.0%")) -> 4,245 18.6% | BG17: =_xlfn.TEXTJOIN(CHAR(10),FALSE,TEXT(BG15,"#,###"),TEXT(BG16,"0.0%")) -> 3,725 16.2% | BH17: =_xlfn.TEXTJOIN(CHAR(10),FALSE,TEXT(BH15,"#,###"),TEXT(BH16,"0.0%")) -> 3,639 15.7% | BI17: =_xlfn.TEXTJOIN(CHAR(10),FALSE,TEXT(BI15,"#,###"),TEXT(BI16,"0.0%")) -> 4,272 17.8% | BJ17: =_xlfn.TEXTJOIN(CHAR(10),FALSE,TEXT(BJ15,"#,###"),TEXT(BJ16,"0.0%")) -> 4,339 18.1% | BK17: =_xlfn.TEXTJOIN(CHAR(10),FALSE,TEXT(BK15,"#,###"),TEXT(BK16,"0.0%")) -> 6,078 25.4% | BL17: =_xlfn.TEXTJOIN(CHAR(10),FALSE,TEXT(BL15,"#,###"),TEXT(BL16,"0.0%")) -> 5,471 23.4% | ... CA17: =_xlfn.TEXTJOIN(CHAR(10),FALSE,TEXT(CA15,"#,###"),TEXT(CA16,"0.0%")) -> 4,345 21.6%
AR18: Line-Trình bày-Chênh lệch Vảy thực tế và giá keo | BE18: =BE9+BE15/2 -> 20249.604 | BF18: =BF9+BF15/2 -> 20745.373 | BG18: =BG9+BG15/2 -> 21158.088 | BH18: =BH9+BH15/2 -> 21389.248 | BI18: =BI9+BI15/2 -> 21861.536 | BJ18: =BJ9+BJ15/2 -> 21818.007 | BK18: =BK9+BK15/2 -> 20917.074 | BL18: =BL9+BL15/2 -> 20635.218 | ... CA18: =CA9+CA15/2 -> 17930.005
K29: -13700
C30: 1165,1272.5,1346,1297.5,1316.66666666665,1390,1220,1270,1190,1130,1040,1040
C32: 1165 | D32: 1272.5 | E32: 1346 | F32: 1297.5 | G32: 1316.6667 | H32: 1390 | I32: 1220 | J32: 1270 | K32: 1190 | L32: 1130 | M32: 1040 | N32: 1040
B33: tỉ lệ | C33: 27960 | D33: 30540 | E33: 32304 | F33: 31140 | G33: 31600 | H33: 33360 | I33: 29280 | J33: 30480 | K33: 28560 | L33: 27120 | M33: 24960 | N33: 24960
B39: Tháng | C39: 01/23 | D39: 2 | E39: 3 | F39: 4 | G39: 5 | H39: 6 | I39: 7 | J39: 8 | K39: 9 | L39: 10 | M39: 11 | N39: 12 | O39: 1.24 | P39: 2 | Q39: 3 | R39: 4 | S39: 5 | T39: 6 | U39: 7 | V39: 8 | W39: 9 | X39: 10 | Y39: 11 | Z39: 12 | AA39: 1.25 | AB39: 2 | AC39: 3 | AD39: 4 | AE39: 5 | AF39: 6 | AG39: 7 | AH39: 8 | AI39: 9 | AJ39: 10 | AK39: 11
B40: Giá Resin (USD/ Tấn) | C40: 1000 | D40: 1045 | E40: 1020 | F40: 1055 | G40: 974 | H40: 895 | I40: 903 | J40: 918 | K40: 930 | L40: 922.5 | M40: 900 | N40: 900 | O40: 930 | P40: 943 | Q40: 940 | R40: 940 | S40: 942 | T40: 950 | U40: 948 | V40: 930 | W40: 880 | X40: 862.5 | Y40: 852 | Z40: 830 | AA40: 828 | AB40: 840 | AC40: 823 | AD40: 765 | AE40: 782 | AF40: 807.5 | AG40: 802 | AH40: 795 | AI40: 783 | AJ40: 773 | AK40: 770

Sheet HDPE- Tháng
AP3: Data | AQ3: 1.23 | AR3: 2 | AS3: 3 | AT3: 4 | AU3: 5 | AV3: 6 | AW3: 7 | AX3: 8 | AY3: 9 | AZ3: 10 | BA3: 11 | BB3: 12 | BC3: 1.24 | BD3: 2 | BE3: 3 | BF3: 4 | BG3: 5 | BH3: 6 | BI3: 7 | BJ3: 8 | BK3: 9 | BL3: 10 | BM3: 11 | BN3: 12 | BO3: 1.25 | BP3: 2 | BQ3: 3 | BR3: 4 | BS3: 5 | BT3: 6 | BU3: 7 | BV3: 8 | BW3: 9 | BX3: 10 | BY3: 11 | BZ3: 12
AP4: Tỷ giá USD | AQ4: 23250 | AR4: 23570 | AS4: 23260 | AT4: 23260 | AU4: 23295 | AV4: 23330 | AW4: 23380 | AX4: 23840 | AY4: 23960 | AZ4: 24280 | BA4: 24730 | BB4: 24930 | BC4: 24210 | BD4: 24250 | BE4: 24490 | BF4: 24690 | BG4: 25475 | BH4: 25250 | BI4: 25270 | BJ4: 25130 | BK4: ='Chai B1- Tháng'!CQ4 -> 24580 | BL4: ='Chai B1- Tháng'!CR4 -> 24410 | BM4: ='Chai B1- Tháng'!CS4 -> 25120 | BN4: ='Chai B1- Tháng'!CT4 -> 25140 | BO4: ='Chai B1- Tháng'!CU4 -> 25290 | BP4: ='Chai B1- Tháng'!CV4 -> 25050 | BQ4: ='Chai B1- Tháng'!CW4 -> 25400 | BR4: ='Chai B1- Tháng'!CX4 -> 25460 | ... BZ4: ='Chai B1- Tháng'!DF4 -> 26181
AP5: Giá keo chính phẩm | AQ5: =C37*AQ4/1000 -> 23656.875 | AR5: =D37*AR4/1000 -> 25750.225 | AS5: =E37*AS4/1000 -> 24946.35 | AT5: =F37*AT4/1000 -> 24423 | AU5: =G37*AU4/1000 -> 24319.98 | AV5: =H37*AV4/1000 -> 22630.1 | AW5: =I37*AW4/1000 -> 22444.8 | AX5: =J37*AX4/1000 -> 24030.72 | ... BZ5: =AL37*BZ4/1000 -> 21075.705
AP6: Giá duyệt mua vảy HDPE | AQ6: 21500 | AR6: 21500 | AS6: 21500 | AT6: 21500 | AU6: 21500 | AV6: 23000 | AW6: 23000 | AX6: 22500 | AY6: 22500 | AZ6: 22500 | BA6: 22500 | BB6: 22500 | BC6: 22500 | BD6: 22500 | BE6: 22000 | BF6: 22000 | BG6: 22000 | BH6: 22000 | BI6: 22000 | BJ6: 22000 | BK6: 22000 | BL6: 22000 | BM6: 21500 | BN6: 21500 | BO6: 21500 | BP6: 21500 | BQ6: 21500 | BR6: 21500 | BS6: 21500 | BT6: 21500 | BU6: 21500 | BV6: 21500 | BW6: 21500 | BX6: 19000 | BY6: 19000 | BZ6: 19000
AP7: Giá vảy thể hiện | AQ7: =AQ6 -> 21500 | AR7: =AR6 -> 21500 | AS7: =AS6 -> 21500 | AT7: =AT6 -> 21500 | AU7: =AU6 -> 21500 | AV7: =AV6 -> 23000 | AW7: =AW6 -> 23000 | AX7: =AX6 -> 22500 | ... BZ7: =BZ6 -> 19000
AP8: Giá vảy HDPE thực tế mua trung bình | AQ8: 21459.854 | AR8: 21913.814 | AS8: 23693.617 | AT8: 23254.478 | AU8: 21149.963 | AV8: 22556.707 | AW8: 21609.954 | AX8: 22500 | AY8: 21919.955 | AZ8: 22500 | BA8: 21972.366 | BB8: 21437.84 | BC8: 21039.935 | BD8: 20908.249 | BE8: 20865.772 | BF8: 20642.052 | BG8: 20686.277 | BH8: 21223.584 | BI8: 21243.396 | BJ8: 21527.191 | BK8: 21819.831 | BL8: 21769.364 | BM8: 21713.979 | BN8: 19595.344 | BO8: 21500 | BP8: 21500 | BQ8: 21500 | BR8: 21500 | BS8: 19979.618 | BT8: 19768.934 | BU8: 19426.363 | BV8: 19500 | BW8: 19470.422 | BX8: 18500 | BY8: 18018.325 | BZ8: =BZ7 -> 19000
AP9: % Keo chính phẩm so với vảy HDPE | AQ9: =AQ5/AQ6-1 -> 0.10031977 | AR9: =AR5/AR6-1 -> 0.19768488 | AS9: =AS5/AS6-1 -> 0.16029535 | AT9: =AT5/AT6-1 -> 0.13595349 | AU9: =AU5/AU6-1 -> 0.13116186 | AV9: =AV5/AV6-1 -> -0.016082609 | AW9: =AW5/AW6-1 -> -0.02413913 | AX9: =AX5/AX6-1 -> 0.068032 | ... BZ9: =BZ5/BZ6-1 -> 0.10924763
AP10: Chênh lệch | AQ10: =AQ5-AQ6 -> 2156.875 | AR10: =AR5-AR6 -> 4250.225 | AS10: =AS5-AS6 -> 3446.35 | AT10: =AT5-AT6 -> 2923 | AU10: =AU5-AU6 -> 2819.98 | AV10: =AV5-AV6 -> -369.9 | AW10: =AW5-AW6 -> -555.2 | AX10: =AX5-AX6 -> 1530.72 | ... BZ10: =BZ5-BZ6 -> 2075.705
AP11: Giá bán rHDPE | AQ11: 1400 | AR11: 1400 | AS11: 1400 | AT11: 1530 | AU11: 1530 | AV11: 1530 | AW11: 1450 | AX11: 1400 | AY11: 1400 | AZ11: 1400 | BA11: 1400 | BB11: 1400 | BC11: 1400 | BD11: 1400 | BE11: 1400 | BF11: 1400 | BG11: 1400 | BH11: 1400 | BI11: 1400 | BJ11: 1400 | BK11: 1400 | BL11: 1400 | BM11: 1400 | BN11: 1400
AP12: Giá chính phẩm dự báo | AQ12: =AQ5 -> 23656.875 | AR12: =AR5 -> 25750.225 | AS12: =AS5 -> 24946.35 | AT12: =AT5 -> 24423 | AU12: =AU5 -> 24319.98 | AV12: =AV5 -> 22630.1 | AW12: =AW5 -> 22444.8 | AX12: =AX5 -> 24030.72 | ... BZ12: =BZ5 -> 21075.705
AP13: Giá vảy ĐNA (USD) | AQ13: 779.5 | AR13: 785.25 | AS13: 763 | AT13: 802.25 | AU13: 804.38 | AV13: 749.25 | AW13: 719.94 | AX13: 714.7 | AY13: 723.13 | AZ13: 721.69 | BA13: 730.15 | BB13: 738.25 | BC13: 733.5 | BD13: 725.75 | BE13: 722.25 | BF13: 727 | BG13: 716.75
B36: Tháng | C36: 01/23 | D36: 2 | E36: 3 | F36: 4 | G36: 5 | H36: 6 | I36: 7 | J36: 8 | K36: 9 | L36: 10 | M36: 11 | N36: 12 | O36: 1.24 | P36: 2 | Q36: 3 | R36: 4 | S36: 5 | T36: 6 | U36: 7 | V36: 8 | W36: 9 | X36: 10 | Y36: 11 | Z36: 12 | AA36: 1.25 | AB36: 2 | AC36: 3 | AD36: 4 | AE36: 5 | AF36: 6 | AG36: 7 | AH36: 8 | AI36: 9 | AJ36: 10 | AK36: 11 | AL36: 12
B37: Giá Resin (USD/ Tấn) | C37: 1017.5 | D37: 1092.5 | E37: 1072.5 | F37: 1050 | G37: 1044 | H37: 970 | I37: 960 | J37: 1008 | K37: 1027.5 | L37: 1020 | M37: 955 | N37: 928 | O37: 940 | P37: 990 | Q37: 985 | R37: 963 | S37: 982 | T37: 1000 | U37: 1000 | V37: 984 | W37: 968 | X37: 965 | Y37: 974 | Z37: 956 | AA37: 940 | AB37: 918 | AC37: 896 | AD37: 891.5 | AE37: 864 | AF37: 833 | AG37: 833 | AH37: 815 | AI37: 813 | AJ37: 805 | AK37: 805 | AL37: 805

Sheet Chart HDPE_Tuần
AK48: Data | AL48: 1 | AM48: 2 | AN48: 3 | AO48: 4 | AP48: 5 | AQ48: 6 | AR48: 7 | AS48: 8 | AT48: 9 | AU48: 10 | AV48: 11 | AW48: 12 | AX48: 13 | AY48: 14 | AZ48: 15 | BA48: 16 | BB48: 17 | BC48: 18 | BD48: 19 | BE48: 20 | BF48: 21 | BG48: 22 | BH48: 23 | BI48: 24 | BJ48: 25 | BK48: 26 | BL48: 27 | BM48: 28 | BN48: 29 | BO48: 30 | BP48: 31 | BQ48: 32 | BR48: 33 | BS48: 34 | BT48: 35 | BU48: 36 | BV48: 37 | BW48: 38
AK49: Tỷ giá USD | AL49: ='Chart Vảy PET_Tuần'!W46 -> 24760 | AM49: ='Chart Vảy PET_Tuần'!X46 -> 24200 | AN49: ='Chart Vảy PET_Tuần'!Y46 -> 24330 | AO49: ='Chart Vảy PET_Tuần'!Z46 -> 24410 | AP49: ='Chart Vảy PET_Tuần'!AA46 -> 24380 | AQ49: ='Chart Vảy PET_Tuần'!AB46 -> 24220 | AR49: ='Chart Vảy PET_Tuần'!AC46 -> 24250 | AS49: ='Chart Vảy PET_Tuần'!AD46 -> 24380 | ... BW49: ='Chart Vảy PET_Tuần'!BH46 -> 0
AK50: Giá keo chính phẩm | AL50: =AL57*AL49/1000 -> 22779.2 | AM50: =AM57*AM49/1000 -> 22990 | AN50: =AN57*AN49/1000 -> 23113.5 | AO50: =AO57*AO49/1000 -> 23677.7 | AP50: =AP57*AP49/1000 -> 23892.4 | AQ50: =AQ57*AQ49/1000 -> 24220 | AR50: =AR57*AR49/1000 -> 24250 | AS50: =AS57*AS49/1000 -> 24380 | ... BS50: =BS57*BS49/1000 -> 24065.7
