Workbook
Name du_lieu: 'TD du an'!$A$8:$J$215
Name ngay_thang: 'TD du an'!$K$8:$AX$459
Name tieu_de: 'TD du an'!$5:$6

Sheet TD du an
A1: BẢNG TIẾN ĐỘ DỰ ÁN | K1: Dự án: | M1: Nghiên cứu tái chế các loại chai có tỷ lệ vảy PET dính keo cao
A3: Mã số: | B3: =VLOOKUP(M1,Sheet1!K:L,2,0) -> DA_2022_01 | D3: Trưởng dự án | E3: =VLOOKUP($M$1,Sheet1!$A:$H,3,FALSE) -> Trần Minh Hoàng | F3: Trưởng dự án | H3: =VLOOKUP($M$1,Sheet1!$A:$H,3,FALSE) -> Trần Minh Hoàng | K3: Ngày | M3: 12 | P3: Tháng | R3: 1 | U3: Năm | W3: 2022 | BR3: Đang thực hiện
D4: Thư ký | E4: =VLOOKUP($M$1,Sheet1!$A:$H,4,FALSE) -> Cao Thùy Linh | F4: Thư ký | H4: =VLOOKUP($M$1,Sheet1!$A:$H,4,FALSE) -> Cao Thùy Linh | BR4: Đang chờ xử lý
A5: STT | B5: Hạng mục công việc | C5: Thứ tự ưu tiên | D5: Kế hoạch | F5: Bắt đầu | G5: Số ngày | H5: Thực tế | J5: Tháng | K5: =EOMONTH(DATE(W3,R3,M3),-1)+1 -> 44562 | L5: =K5+7 -> 44569 | M5: =L5+7 -> 44576 | N5: =M5+7 -> 44583 | O5: =N5+7 -> 44590 | P5: =O5+7 -> 44597 | Q5: =P5+7 -> 44604 | R5: =Q5+7 -> 44611 | S5: =R5+7 -> 44618 | ... BK5: =BJ5+7 -> 44926 | BR5: Hoàn thành
D6: Bắt đầu | E6: Kết thúc | F6: Ngày | H6: Bắt đầu | I6: Kết thúc | J6: Tuần | K6: =WEEKNUM(K5,1) -> 1 | L6: =WEEKNUM(L5,1) -> 2 | M6: =WEEKNUM(M5,1) -> 3 | N6: =WEEKNUM(N5,1) -> 4 | O6: =WEEKNUM(O5,1) -> 5 | P6: =WEEKNUM(P5,1) -> 6 | Q6: =WEEKNUM(Q5,1) -> 7 | R6: =WEEKNUM(R5,1) -> 8 | ... BK6: =WEEKNUM(BK5,1) -> 53 | BR6: Trễ hạn
A7: =IF(B7="","",COUNTA($B$6:B7)) | G7: =SUM(G8:G12) -> 21 | BM7: =BM6+1 -> 1
A8: =IF(B8="","",COUNTA($B$6:B8)) -> 1 | B8: =IFERROR(VLOOKUP($BM8,Sheet1!$B:$H,4,FALSE),"") -> Triển khai và khởi động dự án | C8: 1 | D8: =IFERROR(VLOOKUP($BM8,Sheet1!$B:$H,6,FALSE),"") -> 44565 | E8: =IFERROR(VLOOKUP($BM8,Sheet1!$B:$H,7,FALSE),"") -> 44565 | F8: =IFERROR(VLOOKUP($BM8,Sheet1!$B:$H,6,FALSE),"") -> 44565 | G8: =IFERROR(VLOOKUP($BM8,Sheet1!$B:$H,5,FALSE),"") -> 1 | H8: =IFERROR(VLOOKUP($BM8,Sheet1!$B:$H,6,FALSE),"") -> 44565 | I8: =IFERROR(VLOOKUP($BM8,Sheet1!$B:$H,7,FALSE),"") -> 44565 | J8: =IF(I8="","",WEEKNUM(I8,1)) -> 2 | BM8: =VLOOKUP(M1,Sheet1!A:B,2,FALSE) -> 1
A9: =IF(B9="","",COUNTA($B$6:B9))-1 -> 1 | B9: =IFERROR(VLOOKUP($BM9,Sheet1!$B:$H,4,FALSE),"") -> Khảo sát đặc tính keo, nhãn dính trên vảy PET sau băm: 3 ngày | C9: 1 | D9: =IFERROR(VLOOKUP($BM9,Sheet1!$B:$H,6,FALSE),"") -> 44565 | E9: =IFERROR(VLOOKUP($BM9,Sheet1!$B:$H,7,FALSE),"") -> 44567 | F9: =IFERROR(VLOOKUP($BM9,Sheet1!$B:$H,6,FALSE),"") -> 44565 | G9: =IFERROR(VLOOKUP($BM9,Sheet1!$B:$H,5,FALSE),"") -> 3 | H9: =IFERROR(VLOOKUP($BM9,Sheet1!$B:$H,6,FALSE),"") -> 44565 | I9: =IFERROR(VLOOKUP($BM9,Sheet1!$B:$H,7,FALSE),"") -> 44567 | J9: =IF(I9="","",WEEKNUM(I9,1)) -> 2 | BM9: =BM8+1 -> 2
A10: =IF(B10="","",COUNTA($B$6:B10))-1 -> 2 | B10: =IFERROR(VLOOKUP($BM10,Sheet1!$B:$H,4,FALSE),"") -> Khảo sát hóa phẩm tẩy rửa phù hợp để tách keo, nhãn nhưng vẫn bảo lưu đặc tính vảy PET: 3 ngày | C10: 1 | D10: =IFERROR(VLOOKUP($BM10,Sheet1!$B:$H,6,FALSE),"") -> 44568 | E10: =IFERROR(VLOOKUP($BM10,Sheet1!$B:$H,7,FALSE),"") -> 44572 | F10: =IFERROR(VLOOKUP($BM10,Sheet1!$B:$H,6,FALSE),"") -> 44568 | G10: =IFERROR(VLOOKUP($BM10,Sheet1!$B:$H,5,FALSE),"") -> 3 | H10: =IFERROR(VLOOKUP($BM10,Sheet1!$B:$H,6,FALSE),"") -> 44568 | I10: =IFERROR(VLOOKUP($BM10,Sheet1!$B:$H,7,FALSE),"") -> 44572 | J10: =IF(I10="","",WEEKNUM(I10,1)) -> 3 | BM10: =BM9+1 -> 3
A11: =IF(B11="","",COUNTA($B$6:B11))-1 -> 3 | B11: =IFERROR(VLOOKUP($BM11,Sheet1!$B:$H,4,FALSE),"") -> Order hóa chất, lập danh sách thứ tự ưu tiên dựa trên đặc tính vảy thử nghiệm: 7 ngày | C11: 1 | D11: =IFERROR(VLOOKUP($BM11,Sheet1!$B:$H,6,FALSE),"") -> 44573 | E11: =IFERROR(VLOOKUP($BM11,Sheet1!$B:$H,7,FALSE),"") -> 44581 | F11: =IFERROR(VLOOKUP($BM11,Sheet1!$B:$H,6,FALSE),"") -> 44573 | G11: =IFERROR(VLOOKUP($BM11,Sheet1!$B:$H,5,FALSE),"") -> 7 | H11: =IFERROR(VLOOKUP($BM11,Sheet1!$B:$H,6,FALSE),"") -> 44573 | I11: =IFERROR(VLOOKUP($BM11,Sheet1!$B:$H,7,FALSE),"") -> 44581 | J11: =IF(I11="","",WEEKNUM(I11,1)) -> 4 | BM11: =BM10+1 -> 4
A12: =IF(B12="","",COUNTA($B$6:B12))-1 -> 4 | B12: =IFERROR(VLOOKUP($BM12,Sheet1!$B:$H,4,FALSE),"") -> Tiến hành thử nghiệm, đánh giá hiệu quả tẩy rửa và đặc tính vảy sau rửa: 7 ngày | C12: 1 | D12: =IFERROR(VLOOKUP($BM12,Sheet1!$B:$H,6,FALSE),"") -> 44582 | E12: =IFERROR(VLOOKUP($BM12,Sheet1!$B:$H,7,FALSE),"") -> 44599 | F12: =IFERROR(VLOOKUP($BM12,Sheet1!$B:$H,6,FALSE),"") -> 44582 | G12: =IFERROR(VLOOKUP($BM12,Sheet1!$B:$H,5,FALSE),"") -> 7 | H12: =IFERROR(VLOOKUP($BM12,Sheet1!$B:$H,6,FALSE),"") -> 44582 | I12: =IFERROR(VLOOKUP($BM12,Sheet1!$B:$H,7,FALSE),"") -> 44599 | J12: =IF(I12="","",WEEKNUM(I12,1)) -> 7 | BM12: =BM11+1 -> 5
A13: =IF(B13="","",COUNTA($B$6:B13))-1 -> 5 | B13: =IFERROR(VLOOKUP($BM13,Sheet1!$B:$H,4,FALSE),"") -> Báo cáo nghiệm thu và tiến hành thử nghiệm quy mô lớn 20 tấn vảy: 5 ngày | C13: 1 | D13: =IFERROR(VLOOKUP($BM13,Sheet1!$B:$H,6,FALSE),"") -> 44600 | E13: =IFERROR(VLOOKUP($BM13,Sheet1!$B:$H,7,FALSE),"") -> 44606 | F13: =IFERROR(VLOOKUP($BM13,Sheet1!$B:$H,6,FALSE),"") -> 44600 | G13: =IFERROR(VLOOKUP($BM13,Sheet1!$B:$H,5,FALSE),"") -> 5 | H13: =IFERROR(VLOOKUP($BM13,Sheet1!$B:$H,6,FALSE),"") -> 44600 | I13: =IFERROR(VLOOKUP($BM13,Sheet1!$B:$H,7,FALSE),"") -> 44606 | J13: =IF(I13="","",WEEKNUM(I13,1)) -> 8 | BM13: =BM12+1 -> 6
A14: =IF(B14="","",COUNTA($B$6:B14))-1 -> 6 | B14: =IFERROR(VLOOKUP($BM14,Sheet1!$B:$H,4,FALSE),"") -> Báo cáo nghiệm thu và bàn giao quy trình, yêu cầu kế hoạch áp dụng mass-production: 1 ngày | C14: 1 | D14: =IFERROR(VLOOKUP($BM14,Sheet1!$B:$H,6,FALSE),"") -> 44607 | E14: =IFERROR(VLOOKUP($BM14,Sheet1!$B:$H,7,FALSE),"") -> 44608 | F14: =IFERROR(VLOOKUP($BM14,Sheet1!$B:$H,6,FALSE),"") -> 44607 | G14: =IFERROR(VLOOKUP($BM14,Sheet1!$B:$H,5,FALSE),"") -> 1 | H14: =IFERROR(VLOOKUP($BM14,Sheet1!$B:$H,6,FALSE),"") -> 44607 | I14: =IFERROR(VLOOKUP($BM14,Sheet1!$B:$H,7,FALSE),"") -> 44608 | J14: =IF(I14="","",WEEKNUM(I14,1)) -> 8 | BM14: =BM13+1 -> 7
A15: =IF(B15="","",COUNTA($B$6:B15))-1 -> 7 | B15: =IFERROR(VLOOKUP($BM15,Sheet1!$B:$H,4,FALSE),"") -> Theo dõi và đánh giá hậu kiểm: 2 ngày | C15: 1 | D15: =IFERROR(VLOOKUP($BM15,Sheet1!$B:$H,6,FALSE),"") -> 44609 | E15: =IFERROR(VLOOKUP($BM15,Sheet1!$B:$H,7,FALSE),"") -> 44611 | F15: =IFERROR(VLOOKUP($BM15,Sheet1!$B:$H,6,FALSE),"") -> 44609 | G15: =IF(B15=0,0,IFERROR(VLOOKUP($BM15,Sheet1!$B:$H,5,FALSE),"")) -> 2 | H15: =IFERROR(VLOOKUP($BM15,Sheet1!$B:$H,6,FALSE),"") -> 44609 | I15: =IFERROR(VLOOKUP($BM15,Sheet1!$B:$H,7,FALSE),"") -> 44611 | J15: =IF(I15="","",WEEKNUM(I15,1)) -> 8 | BM15: =BM14+1 -> 8
A16: =IF(B16="","",COUNTA($B$6:B16))-1 -> #VALUE! | G16: =SUM(G8:G15) -> 29 | BM16: =BM15+1 -> 9
A17: =IF(B17="","",COUNTA($B$6:B17))-1 -> 8 | B17: =IFERROR(VLOOKUP($BM17,Sheet1!$B:$H,4,FALSE),"") -> Triển khai và khởi động dự án | F17: =IFERROR(VLOOKUP($BM17,Sheet1!$B:$H,6,FALSE),"") -> 44650 | G17: =IFERROR(VLOOKUP($BM17,Sheet1!$B:$H,5,FALSE),"") -> 1 | H17: =IFERROR(VLOOKUP($BM17,Sheet1!$B:$H,6,FALSE),"") -> 44650 | BM17: =BM16+1 -> 10
A18: =IF(B18="","",COUNTA($B$6:B18))-1 -> 9 | B18: =IFERROR(VLOOKUP($BM18,Sheet1!$B:$H,4,FALSE),"") -> Khảo sát đặc tính chai nhập đầu vào dựa trên màu sắc, thiết kế, độ nhớt và hàm lượng tạp trong vảy sau băm: 7 ngày | F18: =IFERROR(VLOOKUP($BM18,Sheet1!$B:$H,6,FALSE),"") -> 44650 | G18: =IFERROR(VLOOKUP($BM18,Sheet1!$B:$H,5,FALSE),"") -> 7 | H18: =IFERROR(VLOOKUP($BM18,Sheet1!$B:$H,6,FALSE),"") -> 44650 | BM18: =BM17+1 -> 11
A19: =IF(B19="","",COUNTA($B$6:B19))-1 -> 10 | B19: =IFERROR(VLOOKUP($BM19,Sheet1!$B:$H,4,FALSE),"") -> Đề xuất nhóm phân loại và đánh giá mức độ ảnh hưởng ánh vàng trên hạt nhựa theo từng nhóm phân loại: 21 ngày | F19: =IFERROR(VLOOKUP($BM19,Sheet1!$B:$H,6,FALSE),"") -> 44659 | G19: =IFERROR(VLOOKUP($BM19,Sheet1!$B:$H,5,FALSE),"") -> 21 | H19: =IFERROR(VLOOKUP($BM19,Sheet1!$B:$H,6,FALSE),"") -> 44659 | BM19: =BM18+1 -> 12
A20: =IF(B20="","",COUNTA($B$6:B20))-1 -> 11 | B20: =IFERROR(VLOOKUP($BM20,Sheet1!$B:$H,4,FALSE),"") -> Báo cáo đánh giá sơ bộ nhóm nguyên liệu, khảo sát nhóm thiết bị và thông số vận hành đang áp dụng trên chuyền: 3 ngày | F20: =IFERROR(VLOOKUP($BM20,Sheet1!$B:$H,6,FALSE),"") -> 44687 | G20: =IFERROR(VLOOKUP($BM20,Sheet1!$B:$H,5,FALSE),"") -> 3 | H20: =IFERROR(VLOOKUP($BM20,Sheet1!$B:$H,6,FALSE),"") -> 44687 | BM20: =BM19+1 -> 13
A21: =IF(B21="","",COUNTA($B$6:B21))-1 -> 12 | B21: =IFERROR(VLOOKUP($BM21,Sheet1!$B:$H,4,FALSE),"") -> Tiến hành thử nghiệm, đánh giá khả năng khử ánh vàng trên hạt nhựa bằng cách tối ưu thông số vận hành từng nhóm thiết bị (cô lập nhóm để khảo sát): 7 ngày | F21: =IFERROR(VLOOKUP($BM21,Sheet1!$B:$H,6,FALSE),"") -> 44692 | G21: =IFERROR(VLOOKUP($BM21,Sheet1!$B:$H,5,FALSE),"") -> 7 | H21: =IFERROR(VLOOKUP($BM21,Sheet1!$B:$H,6,FALSE),"") -> 44692 | BM21: =BM20+1 -> 14
A22: =IF(B22="","",COUNTA($B$6:B22))-1 -> #VALUE! | BM22: =BM21+1 -> 15
A23: =IF(B23="","",COUNTA($B$6:B23))-1 -> #VALUE!
A24: =IF(B24="","",COUNTA($B$6:B24))-1 -> #VALUE!
A25: =IF(B25="","",COUNTA($B$6:B25))-1 -> #VALUE!
A26: =IF(B26="","",COUNTA($B$6:B26))-1 -> #VALUE!
A27: =IF(B27="","",COUNTA($B$6:B27))-1 -> #VALUE!
A28: =IF(B28="","",COUNTA($B$6:B28))-1 -> #VALUE!
A29: =IF(B29="","",COUNTA($B$6:B29))-1 -> #VALUE!
A30: =IF(B30="","",COUNTA($B$6:B30))-1 -> #VALUE!
A31: =IF(B31="","",COUNTA($B$6:B31))-1 -> #VALUE!
A32: =IF(B32="","",COUNTA($B$6:B32))-1 -> #VALUE!
A33: =IF(B33="","",COUNTA($B$6:B33))-1 -> #VALUE!
A34: =IF(B34="","",COUNTA($B$6:B34))-1 -> #VALUE!
... A65: =IF(B65="","",COUNTA($B$6:B65))-1 -> #VALUE!
A66: =IF(B66="","",COUNTA($B$6:B66))-1 -> #VALUE! | I66: =IF(F66="","",F66+G66)
A67: =IF(B67="","",COUNTA($B$6:B67))-1 -> #VALUE! | I67: =IF(F67="","",F67+G67)
A68: =IF(B68="","",COUNTA($B$6:B68))-1 -> #VALUE! | I68: =IF(F68="","",F68+G68)
A69: =IF(B69="","",COUNTA($B$6:B69))-1 -> #VALUE! | I69: =IF(F69="","",F69+G69)
A70: =IF(B70="","",COUNTA($B$6:B70))-1 -> #VALUE! | I70: =IF(F70="","",F70+G70)
A71: =IF(B71="","",COUNTA($B$6:B71))-1 -> #VALUE! | I71: =IF(F71="","",F71+G71)
...

Sheet Sheet1
A1: 1 | C1: 2
A2: Dự án NC&PT | C2: Trưởng dự án | D2: Thư ký dự án | E2: Tiến độ và kế hoạch thực hiện | F2: Số ngày | G2: Ngày bắt đầu | H2: Ngày kết thúc | K2: Nghiên cứu tái chế các loại chai có tỷ lệ vảy PET dính keo cao | L2: DA_2022_01
A3: Nghiên cứu tái chế các loại chai có tỷ lệ vảy PET dính keo cao | B3: 1 | C3: Trần Minh Hoàng | D3: Cao Thùy Linh | E3: Triển khai và khởi động dự án | F3: 1 | G3: 44565 | H3: 44565 | K3: Nghiên cứu cách giảm ánh vàng trên hạt nhựa tái chế | L3: DA_2022_02
A4: Nghiên cứu tái chế các loại chai có tỷ lệ vảy PET dính keo cao | B4: 2 | C4: Trần Minh Hoàng | D4: Cao Thùy Linh | E4: Khảo sát đặc tính keo, nhãn dính trên vảy PET sau băm: 3 ngày | F4: 3 | G4: 44565 | H4: 44567 | K4: Thực hiện 75 thử nghiệm cho PET & HDPE, TB >6 thử nghiệm/tháng | L4: DA_2022_03
A5: Nghiên cứu tái chế các loại chai có tỷ lệ vảy PET dính keo cao | B5: 3 | C5: Trần Minh Hoàng | D5: Cao Thùy Linh | E5: Khảo sát hóa phẩm tẩy rửa phù hợp để tách keo, nhãn nhưng vẫn bảo lưu đặc tính vảy PET: 3 ngày | F5: 3 | G5: =WORKDAY.INTL(H4,1,11,[1]Holiday!$A$2:$A$16) -> 44568 | H5: =WORKDAY.INTL(G5,F5,11,[1]Holiday!$A$2:$A$16) -> 44572 | K5: Nghiên cứu và sản xuất thành công sản phẩm ứng dụng cho chai CSD | L5: DA_2022_04
A6: Nghiên cứu tái chế các loại chai có tỷ lệ vảy PET dính keo cao | B6: 4 | C6: Trần Minh Hoàng | D6: Cao Thùy Linh | E6: Order hóa chất, lập danh sách thứ tự ưu tiên dựa trên đặc tính vảy thử nghiệm: 7 ngày | F6: 7 | G6: =WORKDAY.INTL(H5,1,11,[1]Holiday!$A$2:$A$16) -> 44573 | H6: =WORKDAY.INTL(G6,F6,11,[1]Holiday!$A$2:$A$16) -> 44581 | K6: Nghiên cứu thành công phụ gia ổn định MI (rHDPE) | L6: DA_2022_05
A7: Nghiên cứu tái chế các loại chai có tỷ lệ vảy PET dính keo cao | B7: 5 | C7: Trần Minh Hoàng | D7: Cao Thùy Linh | E7: Tiến hành thử nghiệm, đánh giá hiệu quả tẩy rửa và đặc tính vảy sau rửa: 7 ngày | F7: 7 | G7: =WORKDAY.INTL(H6,1,11,[1]Holiday!$A$2:$A$16) -> 44582 | H7: =WORKDAY.INTL(G7,F7,11,[1]Holiday!$A$2:$A$16) -> 44599 | K7: Nghiên cứu công thức xử lý linh động theo nguồn nguyên vật liệu | L7: DA_2022_06
A8: Nghiên cứu tái chế các loại chai có tỷ lệ vảy PET dính keo cao | B8: 6 | C8: Trần Minh Hoàng | D8: Cao Thùy Linh | E8: Báo cáo nghiệm thu và tiến hành thử nghiệm quy mô lớn 20 tấn vảy: 5 ngày | F8: 5 | G8: =WORKDAY.INTL(H7,1,11,[1]Holiday!$A$2:$A$16) -> 44600 | H8: =WORKDAY.INTL(G8,F8,11,[1]Holiday!$A$2:$A$16) -> 44606 | K8: Nghiên cứu biện pháp giảm tạp chất trong vảy PET sau băm, sau rửa | L8: DA_2022_07
A9: Nghiên cứu tái chế các loại chai có tỷ lệ vảy PET dính keo cao | B9: 7 | C9: Trần Minh Hoàng | D9: Cao Thùy Linh | E9: Báo cáo nghiệm thu và bàn giao quy trình, yêu cầu kế hoạch áp dụng mass-production: 1 ngày | F9: 1 | G9: =WORKDAY.INTL(H8,1,11,[1]Holiday!$A$2:$A$16) -> 44607 | H9: 44608
A10: Nghiên cứu tái chế các loại chai có tỷ lệ vảy PET dính keo cao | B10: 8 | C10: Trần Minh Hoàng | D10: Cao Thùy Linh | E10: Theo dõi và đánh giá hậu kiểm: 2 ngày | F10: 2 | G10: =WORKDAY.INTL(H9,1,11,[1]Holiday!$A$2:$A$16) -> 44609 | H10: =WORKDAY.INTL(G10,F10,11,[1]Holiday!$A$2:$A$16) -> 44611
B11: 9 | F11: 55
A12: Nghiên cứu cách giảm ánh vàng trên hạt nhựa tái chế | B12: 10 | C12: Trần Minh Hoàng | D12: Phạm Thị Kim Hồng | E12: Triển khai và khởi động dự án | F12: 1 | G12: 44650 | H12: 44650
A13: Nghiên cứu cách giảm ánh vàng trên hạt nhựa tái chế | B13: 11 | C13: Trần Minh Hoàng | D13: Phạm Thị Kim Hồng | E13: Khảo sát đặc tính chai nhập đầu vào dựa trên màu sắc, thiết kế, độ nhớt và hàm lượng tạp trong vảy sau băm: 7 ngày | F13: 7 | G13: 44650 | H13: =WORKDAY.INTL(G13,F13,11,[1]Holiday!$A$2:$A$16) -> 44658
A14: Nghiên cứu cách giảm ánh vàng trên hạt nhựa tái chế | B14: 12 | C14: Trần Minh Hoàng | D14: Phạm Thị Kim Hồng | E14: Đề xuất nhóm phân loại và đánh giá mức độ ảnh hưởng ánh vàng trên hạt nhựa theo từng nhóm phân loại: 21 ngày | F14: 21 | G14: =WORKDAY.INTL(H13,1,11,[1]Holiday!$A$2:$A$16) -> 44659 | H14: =WORKDAY.INTL(G14,F14,11,[1]Holiday!$A$2:$A$16) -> 44686
A15: Nghiên cứu cách giảm ánh vàng trên hạt nhựa tái chế | B15: 13 | C15: Trần Minh Hoàng | D15: Phạm Thị Kim Hồng | E15: Báo cáo đánh giá sơ bộ nhóm nguyên liệu, khảo sát nhóm thiết bị và thông số vận hành đang áp dụng trên chuyền: 3 ngày | F15: 3 | G15: =WORKDAY.INTL(H14,1,11,[1]Holiday!$A$2:$A$16) -> 44687 | H15: =WORKDAY.INTL(G15,F15,11,[1]Holiday!$A$2:$A$16) -> 44691
A16: Nghiên cứu cách giảm ánh vàng trên hạt nhựa tái chế | B16: 14 | C16: Trần Minh Hoàng | D16: Phạm Thị Kim Hồng | E16: Tiến hành thử nghiệm, đánh giá khả năng khử ánh vàng trên hạt nhựa bằng cách tối ưu thông số vận hành từng nhóm thiết bị (cô lập nhóm để khảo sát): 7 ngày | F16: 7 | G16: =WORKDAY.INTL(H15,1,11,[1]Holiday!$A$2:$A$16) -> 44692 | H16: =WORKDAY.INTL(G16,F16,11,[1]Holiday!$A$2:$A$16) -> 44700
A17: Nghiên cứu cách giảm ánh vàng trên hạt nhựa tái chế | B17: 15 | C17: Trần Minh Hoàng | D17: Phạm Thị Kim Hồng | E17: Báo cáo nghiệm thu và tiến hành thử nghiệm quy mô lớn 20 tấn vảy/nhóm: 14 ngày | F17: 14 | G17: =WORKDAY.INTL(H16,1,11,[1]Holiday!$A$2:$A$16) -> 44701 | H17: =WORKDAY.INTL(G17,F17,11,[1]Holiday!$A$2:$A$16) -> 44718
A18: Nghiên cứu cách giảm ánh vàng trên hạt nhựa tái chế | B18: 16 | C18: Trần Minh Hoàng | D18: Phạm Thị Kim Hồng | E18: Báo cáo nghiệm thu và bàn giao quy trình, yêu cầu kế hoạch áp dụng mass-production: 1 ngày | F18: 1 | G18: =WORKDAY.INTL(H17,1,11,[1]Holiday!$A$2:$A$16) -> 44719 | H18: =WORKDAY.INTL(G18,F18,11,[1]Holiday!$A$2:$A$16) -> 44720
A19: Nghiên cứu cách giảm ánh vàng trên hạt nhựa tái chế | B19: 17 | C19: Trần Minh Hoàng | D19: Phạm Thị Kim Hồng | E19: Theo dõi và đánh giá hậu kiểm: 2 ngày | F19: 2 | G19: =WORKDAY.INTL(H18,1,11,[1]Holiday!$A$2:$A$16) -> 44721 | H19: =WORKDAY.INTL(G19,F19,11,[1]Holiday!$A$2:$A$16) -> 44723
B20: 18 | F20: 119
A21: Thực hiện 75 thử nghiệm cho PET & HDPE, TB >6 thử nghiệm/tháng | B21: 19 | C21: Đái Trung Quân | D21: Lê Văn Ty | E21: Khảo sát tình trạng sản phẩm, dây chuyền sản xuất và hiệu quả vận hành dựa trên báo cáo tuần của bộ phận Chất lượng/Kỹ thuật/Sản xuất: Định kỳ 1 tuần/lần | F21: 52 | G21: 44565 | H21: 44923
B22: 20 | E22: Tham khảo tiến bộ KH&CN (thông qua hội thảo, bài báo khoa học, ứng dụng và quảng cáo công nghiệp,...vv), báo cáo đánh giá tính khả thi theo từng tình trạng cần xử lý trong các cuộc họp giao ban: Định kỳ 1 tháng/lần | F22: 12 | G22: 44565 | H22: 44923
B23: 21 | E23: Lập biểu đồ kế hoạch thực hiện và báo cáo dự án theo từng giai đoạn: Định kỳ 1 tuần/lần | F23: 52 | G23: 44565 | H23: 44923
B24: 22 | E24: Báo cáo nghiệm thu và bàn giao quy trình, yêu cầu kế hoạch áp dụng mass-production: 1 ngày | F24: 1 | G24: 44923 | H24: 44923
B25: 23 | E25: Theo dõi và đánh giá hậu kiểm: 2 ngày | F25: 2 | G25: 44924 | H25: =WORKDAY.INTL(G25,F25,11,[1]Holiday!$A$2:$A$16) -> 44926
B26: 24 | F26: 44
A27: Nghiên cứu và sản xuất thành công sản phẩm ứng dụng cho chai CSD | B27: 25 | C27: Đặng Lê Châu Đoan | D27: Cao Thùy Linh | E27: Khảo sát đặc tính chai nhập đầu vào dựa trên màu sắc, thiết kế, độ nhớt và hàm lượng tạp trong vảy sau băm: 7 ngày | F27: 7 | G27: 44691 | H27: =WORKDAY.INTL(G27,F27,11,[1]Holiday!$A$2:$A$16) -> 44699
B28: 26 | E28: Đề xuất nhóm phân loại và đánh giá mức độ ảnh hưởng ánh vàng trên hạt nhựa theo từng nhóm phân loại: 21 ngày | F28: 21 | G28: =WORKDAY.INTL(H27,1,11,[1]Holiday!$A$2:$A$16) -> 44700 | H28: =WORKDAY.INTL(G28,F28,11,[1]Holiday!$A$2:$A$16) -> 44725
B29: 27 | E29: Báo cáo đánh giá sơ bộ nhóm nguyên liệu, khảo sát nhóm thiết bị và thông số vận hành đang áp dụng trên chuyền: 3 ngày | F29: 3 | G29: =WORKDAY.INTL(H28,1,11,[1]Holiday!$A$2:$A$16) -> 44726 | H29: 44730
B30: 28 | E30: Tham khảo tiến bộ KH&CN (thông qua hội thảo, bài báo khoa học, ứng dụng và quảng cáo công nghiệp,...vv), báo cáo đánh giá tính khả thi theo từng tình trạng cần xử lý trong các cuộc họp giao ban: Định kỳ 1 tháng/lần | F30: 2 | G30: 44691 | H30: 44730
B31: 29 | E31: Lập biểu đồ kế hoạch thực hiện và báo cáo dự án theo từng giai đoạn: Định kỳ 1 tuần/lần | F31: 8 | G31: 44691 | H31: 44730
B32: 30 | E32: Báo cáo nghiệm thu và bàn giao quy trình, yêu cầu kế hoạch áp dụng mass-production: 1 ngày | F32: 1 | G32: 44732 | H32: 44732
B33: 31 | E33: Theo dõi và đánh giá hậu kiểm: 2 ngày | F33: 2 | G33: 44733 | H33: 44734
B34: 32 | F34: 25
A35: Nghiên cứu thành công phụ gia ổn định MI (rHDPE) | B35: 33 | C35: Sầm Minh Tuấn | D35: Phạm Thị Kim Hồng | E35: Khảo sát đặc tính phụ gia và tính tương thích với nền mẫu HDPE: 5 ngày | F35: 5 | G35: 44634 | H35: =WORKDAY.INTL(G35,F35,11,[1]Holiday!$A$2:$A$16) -> 44639
B36: 34 | E36: Liên hệ đặt mẫu phụ gia và chuẩn bị các mẫu nguyên liệu rHDPE với mức MI từ thấp tới cao: 5 ngày | F36: 5 | G36: 44638 | H36: =WORKDAY.INTL(G36,F36,11,[1]Holiday!$A$2:$A$16) -> 44644
B37: 35 | E37: Tiến hành thử nghiệm với các tỉ lệ khác nhau, khảo sát biến thiên MI trong quy mô PTN: 3 ngày | F37: 3 | G37: =WORKDAY.INTL(H36,1,11,[1]Holiday!$A$2:$A$16) -> 44645 | H37: =WORKDAY.INTL(G37,F37,11,[1]Holiday!$A$2:$A$16) -> 44649
B38: 36 | E38: Báo cáo đánh giá sơ bộ và đề xuất thử nghiệm trên chuyền: 7 ngày | F38: 7 | G38: =WORKDAY.INTL(H37,1,11,[1]Holiday!$A$2:$A$16) -> 44650 | H38: =WORKDAY.INTL(G38,F38,11,[1]Holiday!$A$2:$A$16) -> 44658
B39: 37 | E39: Lập ma trận đánh giá hiệu quả và độ ổn định của MI thành phẩm theo từng tỷ lệ thử nghiệm: 2 ngày | F39: 2 | G39: =WORKDAY.INTL(H38,1,11,[1]Holiday!$A$2:$A$16) -> 44659 | H39: =WORKDAY.INTL(G39,F39,11,[1]Holiday!$A$2:$A$16) -> 44663
B40: 38 | E40: Báo cáo nghiệm thu và bàn giao công thức, áp dụng mass-production: 1 ngày | F40: 1 | G40: =WORKDAY.INTL(H39,1,11,[1]Holiday!$A$2:$A$16) -> 44664 | H40: 44664
...
