Workbook

Sheet 0.KQKD
B2: KẾT QUẢ KINH DOANH (ĐVT: triệu đồng) | F2: TỔNG CỘNG NĂM | AJ2: THỰC HIỆN CHI TIẾT THÁNG 2026 | AV2: THỰC HIỆN THÁNG 5, 2026 | BA2: THỰC HIỆN LŨY KẾ 5 THÁNG 2026
B3: STT | C3: CHỈ TIÊU | E3: Mã tham chiếu | F3: 2022 | G3: 2023 | H3: 2024 | I3: 1 | J3: 2 | K3: 3 | L3: 4 | M3: 5 | N3: 6 | O3: 7 | P3: 8 | Q3: 9 | R3: 10 | S3: 11 | T3: 12 | U3: 2025 | V3: 1 | W3: 2 | X3: 3 | Y3: 4 | Z3: 5 | AA3: 6 | AB3: 7 | AC3: 8 | AD3: 9 | AE3: 10 | AF3: 11 | AG3: 12 | AH3: Kế hoạch 2026 | AI3: Ước thực hiện 2026 | AJ3: 1 | AK3: 2 | AL3: 3 | AM3: 4 | AN3: 5 | AO3: 6 | AP3: 7 | AQ3: 8 | AR3: 9 | AS3: 10 | AT3: 11 | AU3: 12 | AV3: Thực hiện T4.2026 | AW3: Thực hiện T5.2026 | AX3: Kế hoạch T5.2026 | AY3: So với TH T4.2026 | AZ3: So với KH T5.2026 | BA3: Thực hiện LK 2025 | BB3: Thực hiện LK 2026 | BC3: Kế hoạch LK 2026P | BD3: So với TH LK 2025 | BE3: So với KH LK 2026 | BF3: So với KH Năm 2026
B4: 1 | C4: SẢN LƯỢNG BÁN (Tấn) | E4: (*) | U4: =SUM(I4:T4) -> 0 | V4: 760725 | W4: 591675 | X4: 845250 | Y4: 1055250 | Z4: 1055250 | AA4: 1055250 | AB4: 1055250 | AC4: 1055250 | AD4: 1055250 | AE4: 1057212 | AF4: 1057212 | AG4: 1057212 | AH4: =SUM(V4:AG4) -> 11700786 | AI4: =SUM(AJ4:AU4) -> 4015498 | AJ4: 783082 | AK4: 523873 | AL4: 990114 | AM4: 915417 | AN4: 803012 | AV4: =AM4 -> 915417 | AW4: =AN4 -> 803012 | AX4: =Z4 -> 1055250 | AY4: =IFERROR(AW4/AV4,0) -> 0.87720897 | AZ4: =IFERROR(AW4/AX4,0) -> 0.76096849 | BA4: =SUM(I4:M4) -> 0 | BB4: =SUM(AJ4:AN4) -> 4015498 | BC4: =SUM(V4:Z4) -> 4308150 | BD4: =IFERROR(BB4/BA4,0) -> 0 | BE4: =IFERROR(BB4/BC4,0) -> 0.93207015 | BF4: =IFERROR(BB4/AH4,0) -> 0.3431819
B5: 2 | C5: DOANH THU THUẦN | E5: (**) | U5: =SUM(I5:T5) -> 0 | V5: 11515218750 | W5: 8956281250 | X5: 12794687500 | Y5: 15974312500 | Z5: 15974312500 | AA5: 15974312500 | AB5: 15974312500 | AC5: 15974312500 | AD5: 15974312500 | AE5: 17334395000 | AF5: 17334395000 | AG5: 17334395000 | AH5: =SUM(V5:AG5) -> 181115247500 | AI5: =SUM(AJ5:AU5) -> 62246190240 | AJ5: 11775760050 | AK5: 8275817930 | AL5: 14654267870 | AM5: 14396490230 | AN5: 13143854160 | AV5: =AM5 -> 14396490230 | AW5: =AN5 -> 13143854160 | AX5: =Z5 -> 15974312500 | AY5: =IFERROR(AW5/AV5,0) -> 0.91299018 | AZ5: =IFERROR(AW5/AX5,0) -> 0.82281188 | BA5: =SUM(I5:M5) -> 0 | BB5: =SUM(AJ5:AN5) -> 62246190240 | BC5: =SUM(V5:Z5) -> 65214812500 | BD5: =IFERROR(BB5/BA5,0) -> 0 | BE5: =IFERROR(BB5/BC5,0) -> 0.95447933 | BF5: =IFERROR(BB5/AH5,0) -> 0.34368277
D6: Giá bán / Tấn (Triệu đồng/Tấn) | F6: =IFERROR(F5/F$4,0)*1000 -> 0 | G6: =IFERROR(G5/G$4,0)*1000 -> 0 | H6: =IFERROR(H5/H$4,0)*1000 -> 0 | I6: =IFERROR(I5/I$4,0)*1000 -> 0 | J6: =IFERROR(J5/J$4,0)*1000 -> 0 | K6: =IFERROR(K5/K$4,0)*1000 -> 0 | L6: =IFERROR(L5/L$4,0)*1000 -> 0 | M6: =IFERROR(M5/M$4,0)*1000 -> 0 | ... AX6: =IFERROR(AX5/AX$4,0)*1000 -> 15137941 | AY6: =IFERROR(AW6/AV6,0) -> 1.0407898 | AZ6: =IFERROR(AW6/AX6,0) -> 1.0812693 | BA6: =IFERROR(BA5/BA$4,0)*1000 -> 0 | BB6: =IFERROR(BB5/BB$4,0)*1000 -> 15501487 | BC6: =IFERROR(BC5/BC$4,0)*1000 -> 15137545 | BD6: =IFERROR(BB6/BA6,0) -> 0 | BE6: =IFERROR(BB6/BC6,0) -> 1.0240424 | BF6: =IFERROR(BB6/AH6,0) -> 1.0014595
B7: 3 | C7: BIẾN PHÍ | F7: =F10+F13 -> 0 | G7: =G10+G13 -> 0 | H7: =H10+H13 -> 0 | I7: =I10+I13 -> 0 | J7: =J10+J13 -> 0 | K7: =K10+K13 -> 0 | L7: =L10+L13 -> 0 | M7: =M10+M13 -> 0 | ... AU7: =AU10+AU13 -> 0 | AV7: =AM7 -> 11553794740 | AW7: =AN7 -> 10545666331 | AX7: =Z7 -> 1.3465381e+10 | AY7: =IFERROR(AW7/AV7,0) -> 0.91274482 | AZ7: =IFERROR(AW7/AX7,0) -> 0.78316879 | BA7: =SUM(I7:M7) -> 0 | BB7: =SUM(AJ7:AN7) -> 50157535139 | BC7: =SUM(V7:Z7) -> 5.4960776e+10 | BD7: =IFERROR(BB7/BA7,0) -> 0 | BE7: =IFERROR(BB7/BC7,0) -> 0.91260602 | BF7: =IFERROR(BB7/AH7,0) -> 0.33017268
D8: Biến phí / Doanh thu (%) | F8: =IFERROR(F7/F$5,0) -> 0 | G8: =IFERROR(G7/G$5,0) -> 0 | H8: =IFERROR(H7/H$5,0) -> 0 | I8: =IFERROR(I7/I$5,0) -> 0 | J8: =IFERROR(J7/J$5,0) -> 0 | K8: =IFERROR(K7/K$5,0) -> 0 | L8: =IFERROR(L7/L$5,0) -> 0 | M8: =IFERROR(M7/M$5,0) -> 0 | ... AX8: =IFERROR(AX7/AX$5,0) -> 0.84293964 | AY8: =IFERROR(AW8/AV8,0) -> 0.99973126 | AZ8: =IFERROR(AW8/AX8,0) -> 0.95181998 | BA8: =IFERROR(BA7/BA$5,0) -> 0 | BB8: =IFERROR(BB7/BB$5,0) -> 0.80579285 | BC8: =IFERROR(BC7/BC$5,0) -> 0.84276522 | BD8: =IFERROR(BB8/BA8,0) -> 0 | BE8: =IFERROR(BB8/BC8,0) -> 0.95612969 | BF8: =IFERROR(BB8/AH8,0) -> 0.96069024
D9: Biến phí / Tấn (Triệu đồng/Tấn) | F9: =IFERROR(F7/F$4,0)*1000 -> 0 | G9: =IFERROR(G7/G$4,0)*1000 -> 0 | H9: =IFERROR(H7/H$4,0)*1000 -> 0 | I9: =IFERROR(I7/I$4,0)*1000 -> 0 | J9: =IFERROR(J7/J$4,0)*1000 -> 0 | K9: =IFERROR(K7/K$4,0)*1000 -> 0 | L9: =IFERROR(L7/L$4,0)*1000 -> 0 | M9: =IFERROR(M7/M$4,0)*1000 -> 0 | ... AX9: =IFERROR(AX7/AX$4,0)*1000 -> 12760371 | AY9: =IFERROR(AW9/AV9,0) -> 1.0405101 | AZ9: =IFERROR(AW9/AX9,0) -> 1.0291737 | BA9: =IFERROR(BA7/BA$4,0)*1000 -> 0 | BB9: =IFERROR(BB7/BB$4,0)*1000 -> 12490987 | BC9: =IFERROR(BC7/BC$4,0)*1000 -> 12757396 | BD9: =IFERROR(BB9/BA9,0) -> 0 | BE9: =IFERROR(BB9/BC9,0) -> 0.97911732 | BF9: =IFERROR(BB9/AH9,0) -> 0.96209235
B10: 3.1 | C10: Biến phí bán hàng | E10: 01,02,03 | F10: =SUMIF('10. 170KMP'!$J:$J,"1",'10. 170KMP'!L:L) -> 0 | G10: =SUMIF('10. 170KMP'!$J:$J,"1",'10. 170KMP'!M:M) -> 0 | H10: =SUMIF('10. 170KMP'!$J:$J,"1",'10. 170KMP'!N:N) -> 0 | I10: =SUMIF('10. 170KMP'!$J:$J,"1",'10. 170KMP'!O:O) -> 0 | J10: =SUMIF('10. 170KMP'!$J:$J,"1",'10. 170KMP'!P:P) -> 0 | K10: =SUMIF('10. 170KMP'!$J:$J,"1",'10. 170KMP'!Q:Q) -> 0 | L10: =SUMIF('10. 170KMP'!$J:$J,"1",'10. 170KMP'!R:R) -> 0 | M10: =SUMIF('10. 170KMP'!$J:$J,"1",'10. 170KMP'!S:S) -> 0 | N10: =SUMIF('10. 170KMP'!$J:$J,"1",'10. 170KMP'!T:T) -> 0 | O10: =SUMIF('10. 170KMP'!$J:$J,"1",'10. 170KMP'!U:U) -> 0 | P10: =SUMIF('10. 170KMP'!$J:$J,"1",'10. 170KMP'!V:V) -> 0 | Q10: =SUMIF('10. 170KMP'!$J:$J,"1",'10. 170KMP'!W:W) -> 0 | R10: =SUMIF('10. 170KMP'!$J:$J,"1",'10. 170KMP'!X:X) -> 0 | S10: =SUMIF('10. 170KMP'!$J:$J,"1",'10. 170KMP'!Y:Y) -> 0 | T10: =SUMIF('10. 170KMP'!$J:$J,"1",'10. 170KMP'!Z:Z) -> 0 | U10: =SUMIF('10. 170KMP'!$J:$J,"1",'10. 170KMP'!AA:AA) -> 0 | V10: =SUMIF('10. 170KMP'!$J:$J,"1",'10. 170KMP'!AB:AB) -> 259100625 | W10: =SUMIF('10. 170KMP'!$J:$J,"1",'10. 170KMP'!AC:AC) -> 2.0152271e+08 | X10: =SUMIF('10. 170KMP'!$J:$J,"1",'10. 170KMP'!AD:AD) -> 2.8788958e+08 | Y10: =SUMIF('10. 170KMP'!$J:$J,"1",'10. 170KMP'!AE:AE) -> 359368750 | Z10: =SUMIF('10. 170KMP'!$J:$J,"1",'10. 170KMP'!AF:AF) -> 359368750 | AA10: =SUMIF('10. 170KMP'!$J:$J,"1",'10. 170KMP'!AG:AG) -> 359368750 | AB10: =SUMIF('10. 170KMP'!$J:$J,"1",'10. 170KMP'!AH:AH) -> 359368750 | AC10: =SUMIF('10. 170KMP'!$J:$J,"1",'10. 170KMP'!AI:AI) -> 359368750 | AD10: =SUMIF('10. 170KMP'!$J:$J,"1",'10. 170KMP'!AJ:AJ) -> 359368750 | AE10: =SUMIF('10. 170KMP'!$J:$J,"1",'10. 170KMP'!AK:AK) -> 3.2965703e+08 | AF10: =SUMIF('10. 170KMP'!$J:$J,"1",'10. 170KMP'!AL:AL) -> 3.2965703e+08 | AG10: =SUMIF('10. 170KMP'!$J:$J,"1",'10. 170KMP'!AM:AM) -> 3.2965703e+08 | AH10: =SUMIF('10. 170KMP'!$J:$J,"1",'10. 170KMP'!AN:AN) -> 3.8936965e+09 | AI10: =SUMIF('10. 170KMP'!$J:$J,"1",'10. 170KMP'!AO:AO) -> 1403800000 | AJ10: =SUMIF('10. 170KMP'!$J:$J,"1",'10. 170KMP'!AP:AP) -> 252400000 | AK10: =SUMIF('10. 170KMP'!$J:$J,"1",'10. 170KMP'!AQ:AQ) -> 167700000 | AL10: =SUMIF('10. 170KMP'!$J:$J,"1",'10. 170KMP'!AR:AR) -> 349500000 | AM10: =SUMIF('10. 170KMP'!$J:$J,"1",'10. 170KMP'!AS:AS) -> 338100000 | AN10: =SUMIF('10. 170KMP'!$J:$J,"1",'10. 170KMP'!AT:AT) -> 296100000 | AO10: =SUMIF('10. 170KMP'!$J:$J,"1",'10. 170KMP'!AU:AU) -> 0 | AP10: =SUMIF('10. 170KMP'!$J:$J,"1",'10. 170KMP'!AV:AV) -> 0 | AQ10: =SUMIF('10. 170KMP'!$J:$J,"1",'10. 170KMP'!AW:AW) -> 0 | AR10: =SUMIF('10. 170KMP'!$J:$J,"1",'10. 170KMP'!AX:AX) -> 0 | AS10: =SUMIF('10. 170KMP'!$J:$J,"1",'10. 170KMP'!AY:AY) -> 0 | AT10: =SUMIF('10. 170KMP'!$J:$J,"1",'10. 170KMP'!AZ:AZ) -> 0 | AU10: =SUMIF('10. 170KMP'!$J:$J,"1",'10. 170KMP'!BA:BA) -> 0 | AV10: =AM10 -> 338100000 | AW10: =AN10 -> 296100000 | AX10: =Z10 -> 359368750 | AY10: =IFERROR(AW10/AV10,0) -> 0.8757764 | AZ10: =IFERROR(AW10/AX10,0) -> 0.82394476 | BA10: =SUM(I10:M10) -> 0 | BB10: =SUM(AJ10:AN10) -> 1403800000 | BC10: =SUM(V10:Z10) -> 1.4672504e+09 | BD10: =IFERROR(BB10/BA10,0) -> 0 | BE10: =IFERROR(BB10/BC10,0) -> 0.95675556 | BF10: =IFERROR(BB10/AH10,0) -> 0.36053144
D11: Biến phí / Doanh thu (%) | F11: =IFERROR(F10/F$5,0) -> 0 | G11: =IFERROR(G10/G$5,0) -> 0 | H11: =IFERROR(H10/H$5,0) -> 0 | I11: =IFERROR(I10/I$5,0) -> 0 | J11: =IFERROR(J10/J$5,0) -> 0 | K11: =IFERROR(K10/K$5,0) -> 0 | L11: =IFERROR(L10/L$5,0) -> 0 | M11: =IFERROR(M10/M$5,0) -> 0 | ... AX11: =IFERROR(AX10/AX$5,0) -> 0.022496665 | AY11: =IFERROR(AW11/AV11,0) -> 0.95923967 | AZ11: =IFERROR(AW11/AX11,0) -> 1.0013768 | BA11: =IFERROR(BA10/BA$5,0) -> 0 | BB11: =IFERROR(BB10/BB$5,0) -> 0.022552384 | BC11: =IFERROR(BC10/BC$5,0) -> 0.022498729 | BD11: =IFERROR(BB11/BA11,0) -> 0 | BE11: =IFERROR(BB11/BC11,0) -> 1.0023848 | BF11: =IFERROR(BB11/AH11,0) -> 1.0490239
D12: Biến phí / Tấn (Triệu đồng/Tấn) | F12: =IFERROR(F10/F$4,0)*1000 -> 0 | G12: =IFERROR(G10/G$4,0)*1000 -> 0 | H12: =IFERROR(H10/H$4,0)*1000 -> 0 | I12: =IFERROR(I10/I$4,0)*1000 -> 0 | J12: =IFERROR(J10/J$4,0)*1000 -> 0 | K12: =IFERROR(K10/K$4,0)*1000 -> 0 | L12: =IFERROR(L10/L$4,0)*1000 -> 0 | M12: =IFERROR(M10/M$4,0)*1000 -> 0 | ... AX12: =IFERROR(AX10/AX$4,0)*1000 -> 340553.19 | AY12: =IFERROR(AW12/AV12,0) -> 0.9983669 | AZ12: =IFERROR(AW12/AX12,0) -> 1.0827581 | BA12: =IFERROR(BA10/BA$4,0)*1000 -> 0 | BB12: =IFERROR(BB10/BB$4,0)*1000 -> 349595.49 | BC12: =IFERROR(BC10/BC$4,0)*1000 -> 340575.52 | BD12: =IFERROR(BB12/BA12,0) -> 0 | BE12: =IFERROR(BB12/BC12,0) -> 1.0264845 | BF12: =IFERROR(BB12/AH12,0) -> 1.0505549
B13: 3.2 | C13: Biến phí sản xuất | F13: =F16+F17+F19+F20+F21+F22+F23+F24+F25+F26 -> 0 | G13: =G16+G17+G19+G20+G21+G22+G23+G24+G25+G26 -> 0 | H13: =H16+H17+H19+H20+H21+H22+H23+H24+H25+H26 -> 0 | I13: =I16+I17+I19+I20+I21+I22+I23+I24+I25+I26 -> 0 | J13: =J16+J17+J19+J20+J21+J22+J23+J24+J25+J26 -> 0 | K13: =K16+K17+K19+K20+K21+K22+K23+K24+K25+K26 -> 0 | L13: =L16+L17+L19+L20+L21+L22+L23+L24+L25+L26 -> 0 | M13: =M16+M17+M19+M20+M21+M22+M23+M24+M25+M26 -> 0 | ... AU13: =AU16+AU17+AU19+AU20+AU21+AU22+AU23+AU24+AU25+AU26 -> 0 | AV13: =AM13 -> 11215694740 | AW13: =AN13 -> 10249566331 | AX13: =Z13 -> 1.3106012e+10 | AY13: =IFERROR(AW13/AV13,0) -> 0.91385925 | AZ13: =IFERROR(AW13/AX13,0) -> 0.78205071 | BA13: =SUM(I13:M13) -> 0 | BB13: =SUM(AJ13:AN13) -> 48753735139 | BC13: =SUM(V13:Z13) -> 5.3493525e+10 | BD13: =IFERROR(BB13/BA13,0) -> 0 | BE13: =IFERROR(BB13/BC13,0) -> 0.91139507 | BF13: =IFERROR(BB13/AH13,0) -> 0.32937409
D14: Biến phí sản xuất/ Doanh thu (%) | F14: =IFERROR(F13/F$5,0) -> 0 | G14: =IFERROR(G13/G$5,0) -> 0 | H14: =IFERROR(H13/H$5,0) -> 0 | I14: =IFERROR(I13/I$5,0) -> 0 | J14: =IFERROR(J13/J$5,0) -> 0 | K14: =IFERROR(K13/K$5,0) -> 0 | L14: =IFERROR(L13/L$5,0) -> 0 | M14: =IFERROR(M13/M$5,0) -> 0 | ... AX14: =IFERROR(AX13/AX$5,0) -> 0.82044297 | AY14: =IFERROR(AW14/AV14,0) -> 1.0009519 | AZ14: =IFERROR(AW14/AX14,0) -> 0.95046112 | BA14: =IFERROR(BA13/BA$5,0) -> 0 | BB14: =IFERROR(BB13/BB$5,0) -> 0.78324047 | BC14: =IFERROR(BC13/BC$5,0) -> 0.82026649 | BD14: =IFERROR(BB14/BA14,0) -> 0 | BE14: =IFERROR(BB14/BC14,0) -> 0.95486098 | BF14: =IFERROR(BB14/AH14,0) -> 0.95836659
D15: Biến phí sản xuất/ Tấn (Triệu đồng/Tấn) | F15: =IFERROR(F13/F$4,0)*1000 -> 0 | G15: =IFERROR(G13/G$4,0)*1000 -> 0 | H15: =IFERROR(H13/H$4,0)*1000 -> 0 | I15: =IFERROR(I13/I$4,0)*1000 -> 0 | J15: =IFERROR(J13/J$4,0)*1000 -> 0 | K15: =IFERROR(K13/K$4,0)*1000 -> 0 | L15: =IFERROR(L13/L$4,0)*1000 -> 0 | M15: =IFERROR(M13/M$4,0)*1000 -> 0 | ... AX15: =IFERROR(AX13/AX$4,0)*1000 -> 12419818 | AY15: =IFERROR(AW15/AV15,0) -> 1.0417806 | AZ15: =IFERROR(AW15/AX15,0) -> 1.0277045 | BA15: =IFERROR(BA13/BA$4,0)*1000 -> 0 | BB15: =IFERROR(BB13/BB$4,0)*1000 -> 12141392 | BC15: =IFERROR(BC13/BC$4,0)*1000 -> 12416821 | BD15: =IFERROR(BB15/BA15,0) -> 0 | BE15: =IFERROR(BB15/BC15,0) -> 0.97781811 | BF15: =IFERROR(BB15/AH15,0) -> 0.95976532
D16: Chi phí nguyên liệu vật chính | E16: 04 | F16: =SUMIF('10. 170KMP'!$J:$J,'0.KQKD'!$E16,'10. 170KMP'!L:L) -> 0 | G16: =SUMIF('10. 170KMP'!$J:$J,'0.KQKD'!$E16,'10. 170KMP'!M:M) -> 0 | H16: =SUMIF('10. 170KMP'!$J:$J,'0.KQKD'!$E16,'10. 170KMP'!N:N) -> 0 | I16: =SUMIF('10. 170KMP'!$J:$J,'0.KQKD'!$E16,'10. 170KMP'!O:O) -> 0 | J16: =SUMIF('10. 170KMP'!$J:$J,'0.KQKD'!$E16,'10. 170KMP'!P:P) -> 0 | K16: =SUMIF('10. 170KMP'!$J:$J,'0.KQKD'!$E16,'10. 170KMP'!Q:Q) -> 0 | L16: =SUMIF('10. 170KMP'!$J:$J,'0.KQKD'!$E16,'10. 170KMP'!R:R) -> 0 | M16: =SUMIF('10. 170KMP'!$J:$J,'0.KQKD'!$E16,'10. 170KMP'!S:S) -> 0 | N16: =SUMIF('10. 170KMP'!$J:$J,'0.KQKD'!$E16,'10. 170KMP'!T:T) -> 0 | O16: =SUMIF('10. 170KMP'!$J:$J,'0.KQKD'!$E16,'10. 170KMP'!U:U) -> 0 | P16: =SUMIF('10. 170KMP'!$J:$J,'0.KQKD'!$E16,'10. 170KMP'!V:V) -> 0 | Q16: =SUMIF('10. 170KMP'!$J:$J,'0.KQKD'!$E16,'10. 170KMP'!W:W) -> 0 | R16: =SUMIF('10. 170KMP'!$J:$J,'0.KQKD'!$E16,'10. 170KMP'!X:X) -> 0 | S16: =SUMIF('10. 170KMP'!$J:$J,'0.KQKD'!$E16,'10. 170KMP'!Y:Y) -> 0 | T16: =SUMIF('10. 170KMP'!$J:$J,'0.KQKD'!$E16,'10. 170KMP'!Z:Z) -> 0 | U16: =SUM(I16:T16) -> 0 | V16: =SUMIF('10. 170KMP'!$J:$J,'0.KQKD'!$E16,'10. 170KMP'!AB:AB) -> 9000000000 | W16: =SUMIF('10. 170KMP'!$J:$J,'0.KQKD'!$E16,'10. 170KMP'!AC:AC) -> 7000000000 | X16: =SUMIF('10. 170KMP'!$J:$J,'0.KQKD'!$E16,'10. 170KMP'!AD:AD) -> 10000000000 | Y16: =SUMIF('10. 170KMP'!$J:$J,'0.KQKD'!$E16,'10. 170KMP'!AE:AE) -> 12500000000 | Z16: =SUMIF('10. 170KMP'!$J:$J,'0.KQKD'!$E16,'10. 170KMP'!AF:AF) -> 12500000000 | AA16: =SUMIF('10. 170KMP'!$J:$J,'0.KQKD'!$E16,'10. 170KMP'!AG:AG) -> 12500000000 | AB16: =SUMIF('10. 170KMP'!$J:$J,'0.KQKD'!$E16,'10. 170KMP'!AH:AH) -> 12500000000 | AC16: =SUMIF('10. 170KMP'!$J:$J,'0.KQKD'!$E16,'10. 170KMP'!AI:AI) -> 12500000000 | AD16: =SUMIF('10. 170KMP'!$J:$J,'0.KQKD'!$E16,'10. 170KMP'!AJ:AJ) -> 12500000000 | AE16: =SUMIF('10. 170KMP'!$J:$J,'0.KQKD'!$E16,'10. 170KMP'!AK:AK) -> 13000000000 | AF16: =SUMIF('10. 170KMP'!$J:$J,'0.KQKD'!$E16,'10. 170KMP'!AL:AL) -> 13000000000 | AG16: =SUMIF('10. 170KMP'!$J:$J,'0.KQKD'!$E16,'10. 170KMP'!AM:AM) -> 13000000000 | AH16: =SUM(V16:AG16) -> 140000000000 | AI16: =SUM(AJ16:AU16) -> 46516650441 | AJ16: =SUMIF('10. 170KMP'!$J:$J,'0.KQKD'!$E16,'10. 170KMP'!AP:AP) -> 9069607859 | AK16: =SUMIF('10. 170KMP'!$J:$J,'0.KQKD'!$E16,'10. 170KMP'!AQ:AQ) -> 5963035131 | AL16: =SUMIF('10. 170KMP'!$J:$J,'0.KQKD'!$E16,'10. 170KMP'!AR:AR) -> 11064188424 | AM16: =SUMIF('10. 170KMP'!$J:$J,'0.KQKD'!$E16,'10. 170KMP'!AS:AS) -> 10571670369 | AN16: =SUMIF('10. 170KMP'!$J:$J,'0.KQKD'!$E16,'10. 170KMP'!AT:AT) -> 9848148658 | AO16: =SUMIF('10. 170KMP'!$J:$J,'0.KQKD'!$E16,'10. 170KMP'!AU:AU) -> 0 | AP16: =SUMIF('10. 170KMP'!$J:$J,'0.KQKD'!$E16,'10. 170KMP'!AV:AV) -> 0 | AQ16: =SUMIF('10. 170KMP'!$J:$J,'0.KQKD'!$E16,'10. 170KMP'!AW:AW) -> 0 | AR16: =SUMIF('10. 170KMP'!$J:$J,'0.KQKD'!$E16,'10. 170KMP'!AX:AX) -> 0 | AS16: =SUMIF('10. 170KMP'!$J:$J,'0.KQKD'!$E16,'10. 170KMP'!AY:AY) -> 0 | AT16: =SUMIF('10. 170KMP'!$J:$J,'0.KQKD'!$E16,'10. 170KMP'!AZ:AZ) -> 0 | AU16: =SUMIF('10. 170KMP'!$J:$J,'0.KQKD'!$E16,'10. 170KMP'!BA:BA) -> 0 | AV16: =AM16 -> 10571670369 | AW16: =AN16 -> 9848148658 | AX16: =Z16 -> 12500000000 | AY16: =IFERROR(AW16/AV16,0) -> 0.93156032 | AZ16: =IFERROR(AW16/AX16,0) -> 0.78785189 | BA16: =SUM(I16:M16) -> 0 | BB16: =SUM(AJ16:AN16) -> 46516650441 | BC16: =SUM(V16:Z16) -> 51000000000 | BD16: =IFERROR(BB16/BA16,0) -> 0 | BE16: =IFERROR(BB16/BC16,0) -> 0.91209119 | BF16: =IFERROR(BB16/AH16,0) -> 0.33226179
D17: Chi phí nguyên vật liệu phụ | E17: 05 | F17: =SUMIF('10. 170KMP'!$J:$J,'0.KQKD'!$E17,'10. 170KMP'!L:L) -> 0 | G17: =SUMIF('10. 170KMP'!$J:$J,'0.KQKD'!$E17,'10. 170KMP'!M:M) -> 0 | H17: =SUMIF('10. 170KMP'!$J:$J,'0.KQKD'!$E17,'10. 170KMP'!N:N) -> 0 | I17: =SUMIF('10. 170KMP'!$J:$J,'0.KQKD'!$E17,'10. 170KMP'!O:O) -> 0 | J17: =SUMIF('10. 170KMP'!$J:$J,'0.KQKD'!$E17,'10. 170KMP'!P:P) -> 0 | K17: =SUMIF('10. 170KMP'!$J:$J,'0.KQKD'!$E17,'10. 170KMP'!Q:Q) -> 0 | L17: =SUMIF('10. 170KMP'!$J:$J,'0.KQKD'!$E17,'10. 170KMP'!R:R) -> 0 | M17: =SUMIF('10. 170KMP'!$J:$J,'0.KQKD'!$E17,'10. 170KMP'!S:S) -> 0 | N17: =SUMIF('10. 170KMP'!$J:$J,'0.KQKD'!$E17,'10. 170KMP'!T:T) -> 0 | O17: =SUMIF('10. 170KMP'!$J:$J,'0.KQKD'!$E17,'10. 170KMP'!U:U) -> 0 | P17: =SUMIF('10. 170KMP'!$J:$J,'0.KQKD'!$E17,'10. 170KMP'!V:V) -> 0 | Q17: =SUMIF('10. 170KMP'!$J:$J,'0.KQKD'!$E17,'10. 170KMP'!W:W) -> 0 | R17: =SUMIF('10. 170KMP'!$J:$J,'0.KQKD'!$E17,'10. 170KMP'!X:X) -> 0 | S17: =SUMIF('10. 170KMP'!$J:$J,'0.KQKD'!$E17,'10. 170KMP'!Y:Y) -> 0 | T17: =SUMIF('10. 170KMP'!$J:$J,'0.KQKD'!$E17,'10. 170KMP'!Z:Z) -> 0 | U17: =SUM(I17:T17) -> 0 | V17: =SUMIF('10. 170KMP'!$J:$J,'0.KQKD'!$E17,'10. 170KMP'!AB:AB) -> 0 | W17: =SUMIF('10. 170KMP'!$J:$J,'0.KQKD'!$E17,'10. 170KMP'!AC:AC) -> 0 | X17: =SUMIF('10. 170KMP'!$J:$J,'0.KQKD'!$E17,'10. 170KMP'!AD:AD) -> 0 | Y17: =SUMIF('10. 170KMP'!$J:$J,'0.KQKD'!$E17,'10. 170KMP'!AE:AE) -> 0 | Z17: =SUMIF('10. 170KMP'!$J:$J,'0.KQKD'!$E17,'10. 170KMP'!AF:AF) -> 0 | AA17: =SUMIF('10. 170KMP'!$J:$J,'0.KQKD'!$E17,'10. 170KMP'!AG:AG) -> 0 | AB17: =SUMIF('10. 170KMP'!$J:$J,'0.KQKD'!$E17,'10. 170KMP'!AH:AH) -> 0 | AC17: =SUMIF('10. 170KMP'!$J:$J,'0.KQKD'!$E17,'10. 170KMP'!AI:AI) -> 0 | AD17: =SUMIF('10. 170KMP'!$J:$J,'0.KQKD'!$E17,'10. 170KMP'!AJ:AJ) -> 0 | AE17: =SUMIF('10. 170KMP'!$J:$J,'0.KQKD'!$E17,'10. 170KMP'!AK:AK) -> 0 | AF17: =SUMIF('10. 170KMP'!$J:$J,'0.KQKD'!$E17,'10. 170KMP'!AL:AL) -> 0 | AG17: =SUMIF('10. 170KMP'!$J:$J,'0.KQKD'!$E17,'10. 170KMP'!AM:AM) -> 0 | AH17: =SUM(V17:AG17) -> 0 | AI17: =SUM(AJ17:AU17) -> 19346564 | AJ17: =SUMIF('10. 170KMP'!$J:$J,'0.KQKD'!$E17,'10. 170KMP'!AP:AP) -> 1000000 | AK17: =SUMIF('10. 170KMP'!$J:$J,'0.KQKD'!$E17,'10. 170KMP'!AQ:AQ) -> 1000000 | AL17: =SUMIF('10. 170KMP'!$J:$J,'0.KQKD'!$E17,'10. 170KMP'!AR:AR) -> 2000000 | AM17: =SUMIF('10. 170KMP'!$J:$J,'0.KQKD'!$E17,'10. 170KMP'!AS:AS) -> 14346564 | AN17: =SUMIF('10. 170KMP'!$J:$J,'0.KQKD'!$E17,'10. 170KMP'!AT:AT) -> 1000000 | AO17: =SUMIF('10. 170KMP'!$J:$J,'0.KQKD'!$E17,'10. 170KMP'!AU:AU) -> 0 | AP17: =SUMIF('10. 170KMP'!$J:$J,'0.KQKD'!$E17,'10. 170KMP'!AV:AV) -> 0 | AQ17: =SUMIF('10. 170KMP'!$J:$J,'0.KQKD'!$E17,'10. 170KMP'!AW:AW) -> 0 | AR17: =SUMIF('10. 170KMP'!$J:$J,'0.KQKD'!$E17,'10. 170KMP'!AX:AX) -> 0 | AS17: =SUMIF('10. 170KMP'!$J:$J,'0.KQKD'!$E17,'10. 170KMP'!AY:AY) -> 0 | AT17: =SUMIF('10. 170KMP'!$J:$J,'0.KQKD'!$E17,'10. 170KMP'!AZ:AZ) -> 0 | AU17: =SUMIF('10. 170KMP'!$J:$J,'0.KQKD'!$E17,'10. 170KMP'!BA:BA) -> 0 | AV17: =AM17 -> 14346564 | AW17: =AN17 -> 1000000 | AX17: =Z17 -> 0 | AY17: =IFERROR(AW17/AV17,0) -> 0.069703101 | AZ17: =IFERROR(AW17/AX17,0) -> 0 | BA17: =SUM(I17:M17) -> 0 | BB17: =SUM(AJ17:AN17) -> 19346564 | BC17: =SUM(V17:Z17) -> 0 | BD17: =IFERROR(BB17/BA17,0) -> 0 | BE17: =IFERROR(BB17/BC17,0) -> 0 | BF17: =IFERROR(BB17/AH17,0) -> 0
D18: Lãi nguyên liệu / Doanh thu (%) | F18: =IFERROR((F5-F16-F17)/F$5,0) -> 0 | G18: =IFERROR((G5-G16-G17)/G$5,0) -> 0 | H18: =IFERROR((H5-H16-H17)/H$5,0) -> 0 | I18: =IFERROR((I5-I16-I17)/I$5,0) -> 0 | J18: =IFERROR((J5-J16-J17)/J$5,0) -> 0 | K18: =IFERROR((K5-K16-K17)/K$5,0) -> 0 | L18: =IFERROR((L5-L16-L17)/L$5,0) -> 0 | M18: =IFERROR((M5-M16-M17)/M$5,0) -> 0 | ... AX18: =IFERROR((AX5-AX16-AX17)/AX$5,0) -> 0.21749371 | AY18: =IFERROR(AW18/AV18,0) -> 0.94704709 | AZ18: =IFERROR(AW18/AX18,0) -> 1.1525165 | BA18: =IFERROR((BA5-BA16-BA17)/BA$5,0) -> 0 | BB18: =IFERROR((BB5-BB16-BB17)/BB$5,0) -> 0.25238803 | BC18: =IFERROR((BC5-BC16-BC17)/BC$5,0) -> 0.21796908 | BD18: =IFERROR(BB18/BA18,0) -> 0 | BE18: =IFERROR(BB18/BC18,0) -> 1.1579075 | BF18: =IFERROR(BB18/AH18,0) -> 1.1117851
D19: Chi phí vật tư kỹ thuật phục vụ sản xuất | E19: 06 | F19: =SUMIF('10. 170KMP'!$J:$J,'0.KQKD'!$E19,'10. 170KMP'!L:L) -> 0 | G19: =SUMIF('10. 170KMP'!$J:$J,'0.KQKD'!$E19,'10. 170KMP'!M:M) -> 0 | H19: =SUMIF('10. 170KMP'!$J:$J,'0.KQKD'!$E19,'10. 170KMP'!N:N) -> 0 | I19: =SUMIF('10. 170KMP'!$J:$J,'0.KQKD'!$E19,'10. 170KMP'!O:O) -> 0 | J19: =SUMIF('10. 170KMP'!$J:$J,'0.KQKD'!$E19,'10. 170KMP'!P:P) -> 0 | K19: =SUMIF('10. 170KMP'!$J:$J,'0.KQKD'!$E19,'10. 170KMP'!Q:Q) -> 0 | L19: =SUMIF('10. 170KMP'!$J:$J,'0.KQKD'!$E19,'10. 170KMP'!R:R) -> 0 | M19: =SUMIF('10. 170KMP'!$J:$J,'0.KQKD'!$E19,'10. 170KMP'!S:S) -> 0 | N19: =SUMIF('10. 170KMP'!$J:$J,'0.KQKD'!$E19,'10. 170KMP'!T:T) -> 0 | O19: =SUMIF('10. 170KMP'!$J:$J,'0.KQKD'!$E19,'10. 170KMP'!U:U) -> 0 | P19: =SUMIF('10. 170KMP'!$J:$J,'0.KQKD'!$E19,'10. 170KMP'!V:V) -> 0 | Q19: =SUMIF('10. 170KMP'!$J:$J,'0.KQKD'!$E19,'10. 170KMP'!W:W) -> 0 | R19: =SUMIF('10. 170KMP'!$J:$J,'0.KQKD'!$E19,'10. 170KMP'!X:X) -> 0 | S19: =SUMIF('10. 170KMP'!$J:$J,'0.KQKD'!$E19,'10. 170KMP'!Y:Y) -> 0 | T19: =SUMIF('10. 170KMP'!$J:$J,'0.KQKD'!$E19,'10. 170KMP'!Z:Z) -> 0 | U19: =SUM(I19:T19) -> 0 | V19: =SUMIF('10. 170KMP'!$J:$J,'0.KQKD'!$E19,'10. 170KMP'!AB:AB) -> 1.4012364e+08 | W19: =SUMIF('10. 170KMP'!$J:$J,'0.KQKD'!$E19,'10. 170KMP'!AC:AC) -> 1.0830394e+08 | X19: =SUMIF('10. 170KMP'!$J:$J,'0.KQKD'!$E19,'10. 170KMP'!AD:AD) -> 1.5155499e+08 | Y19: =SUMIF('10. 170KMP'!$J:$J,'0.KQKD'!$E19,'10. 170KMP'!AE:AE) -> 1.8921165e+08 | Z19: =SUMIF('10. 170KMP'!$J:$J,'0.KQKD'!$E19,'10. 170KMP'!AF:AF) -> 1.8791165e+08 | AA19: =SUMIF('10. 170KMP'!$J:$J,'0.KQKD'!$E19,'10. 170KMP'!AG:AG) -> 1.8756999e+08 | AB19: =SUMIF('10. 170KMP'!$J:$J,'0.KQKD'!$E19,'10. 170KMP'!AH:AH) -> 1.8694665e+08 | AC19: =SUMIF('10. 170KMP'!$J:$J,'0.KQKD'!$E19,'10. 170KMP'!AI:AI) -> 1.8706165e+08 | AD19: =SUMIF('10. 170KMP'!$J:$J,'0.KQKD'!$E19,'10. 170KMP'!AJ:AJ) -> 1.8679665e+08 | AE19: =SUMIF('10. 170KMP'!$J:$J,'0.KQKD'!$E19,'10. 170KMP'!AK:AK) -> 3.5043588e+08 | AF19: =SUMIF('10. 170KMP'!$J:$J,'0.KQKD'!$E19,'10. 170KMP'!AL:AL) -> 3.4889588e+08 | AG19: =SUMIF('10. 170KMP'!$J:$J,'0.KQKD'!$E19,'10. 170KMP'!AM:AM) -> 3.4901088e+08 | AH19: =SUM(V19:AG19) -> 2.5738235e+09 | AI19: =SUM(AJ19:AU19) -> 770434165 | AJ19: =SUMIF('10. 170KMP'!$J:$J,'0.KQKD'!$E19,'10. 170KMP'!AP:AP) -> 135630857 | AK19: =SUMIF('10. 170KMP'!$J:$J,'0.KQKD'!$E19,'10. 170KMP'!AQ:AQ) -> 152677040 | AL19: =SUMIF('10. 170KMP'!$J:$J,'0.KQKD'!$E19,'10. 170KMP'!AR:AR) -> 138976171 | AM19: =SUMIF('10. 170KMP'!$J:$J,'0.KQKD'!$E19,'10. 170KMP'!AS:AS) -> 180279734 | AN19: =SUMIF('10. 170KMP'!$J:$J,'0.KQKD'!$E19,'10. 170KMP'!AT:AT) -> 162870363 | AO19: =SUMIF('10. 170KMP'!$J:$J,'0.KQKD'!$E19,'10. 170KMP'!AU:AU) -> 0 | AP19: =SUMIF('10. 170KMP'!$J:$J,'0.KQKD'!$E19,'10. 170KMP'!AV:AV) -> 0 | AQ19: =SUMIF('10. 170KMP'!$J:$J,'0.KQKD'!$E19,'10. 170KMP'!AW:AW) -> 0 | AR19: =SUMIF('10. 170KMP'!$J:$J,'0.KQKD'!$E19,'10. 170KMP'!AX:AX) -> 0 | AS19: =SUMIF('10. 170KMP'!$J:$J,'0.KQKD'!$E19,'10. 170KMP'!AY:AY) -> 0 | AT19: =SUMIF('10. 170KMP'!$J:$J,'0.KQKD'!$E19,'10. 170KMP'!AZ:AZ) -> 0 | AU19: =SUMIF('10. 170KMP'!$J:$J,'0.KQKD'!$E19,'10. 170KMP'!BA:BA) -> 0 | AV19: =AM19 -> 180279734 | AW19: =AN19 -> 162870363 | AX19: =Z19 -> 1.8791165e+08 | AY19: =IFERROR(AW19/AV19,0) -> 0.90343135 | AZ19: =IFERROR(AW19/AX19,0) -> 0.86673902 | BA19: =SUM(I19:M19) -> 0 | BB19: =SUM(AJ19:AN19) -> 770434165 | BC19: =SUM(V19:Z19) -> 7.7710587e+08 | BD19: =IFERROR(BB19/BA19,0) -> 0 | BE19: =IFERROR(BB19/BC19,0) -> 0.99141467 | BF19: =IFERROR(BB19/AH19,0) -> 0.2993345
D20: Chi phí bao bì | E20: 07 | F20: =SUMIF('10. 170KMP'!$J:$J,'0.KQKD'!$E20,'10. 170KMP'!L:L) -> 0 | G20: =SUMIF('10. 170KMP'!$J:$J,'0.KQKD'!$E20,'10. 170KMP'!M:M) -> 0 | H20: =SUMIF('10. 170KMP'!$J:$J,'0.KQKD'!$E20,'10. 170KMP'!N:N) -> 0 | I20: =SUMIF('10. 170KMP'!$J:$J,'0.KQKD'!$E20,'10. 170KMP'!O:O) -> 0 | J20: =SUMIF('10. 170KMP'!$J:$J,'0.KQKD'!$E20,'10. 170KMP'!P:P) -> 0 | K20: =SUMIF('10. 170KMP'!$J:$J,'0.KQKD'!$E20,'10. 170KMP'!Q:Q) -> 0 | L20: =SUMIF('10. 170KMP'!$J:$J,'0.KQKD'!$E20,'10. 170KMP'!R:R) -> 0 | M20: =SUMIF('10. 170KMP'!$J:$J,'0.KQKD'!$E20,'10. 170KMP'!S:S) -> 0 | N20: =SUMIF('10. 170KMP'!$J:$J,'0.KQKD'!$E20,'10. 170KMP'!T:T) -> 0 | O20: =SUMIF('10. 170KMP'!$J:$J,'0.KQKD'!$E20,'10. 170KMP'!U:U) -> 0 | P20: =SUMIF('10. 170KMP'!$J:$J,'0.KQKD'!$E20,'10. 170KMP'!V:V) -> 0 | Q20: =SUMIF('10. 170KMP'!$J:$J,'0.KQKD'!$E20,'10. 170KMP'!W:W) -> 0 | R20: =SUMIF('10. 170KMP'!$J:$J,'0.KQKD'!$E20,'10. 170KMP'!X:X) -> 0 | S20: =SUMIF('10. 170KMP'!$J:$J,'0.KQKD'!$E20,'10. 170KMP'!Y:Y) -> 0 | T20: =SUMIF('10. 170KMP'!$J:$J,'0.KQKD'!$E20,'10. 170KMP'!Z:Z) -> 0 | U20: =SUM(I20:T20) -> 0 | V20: =SUMIF('10. 170KMP'!$J:$J,'0.KQKD'!$E20,'10. 170KMP'!AB:AB) -> 77386422 | W20: =SUMIF('10. 170KMP'!$J:$J,'0.KQKD'!$E20,'10. 170KMP'!AC:AC) -> 60189440 | X20: =SUMIF('10. 170KMP'!$J:$J,'0.KQKD'!$E20,'10. 170KMP'!AD:AD) -> 85984914 | Y20: =SUMIF('10. 170KMP'!$J:$J,'0.KQKD'!$E20,'10. 170KMP'!AE:AE) -> 1.0745956e+08 | Z20: =SUMIF('10. 170KMP'!$J:$J,'0.KQKD'!$E20,'10. 170KMP'!AF:AF) -> 1.0745956e+08 | AA20: =SUMIF('10. 170KMP'!$J:$J,'0.KQKD'!$E20,'10. 170KMP'!AG:AG) -> 1.0745956e+08 | AB20: =SUMIF('10. 170KMP'!$J:$J,'0.KQKD'!$E20,'10. 170KMP'!AH:AH) -> 1.0745956e+08 | AC20: =SUMIF('10. 170KMP'!$J:$J,'0.KQKD'!$E20,'10. 170KMP'!AI:AI) -> 1.0745956e+08 | AD20: =SUMIF('10. 170KMP'!$J:$J,'0.KQKD'!$E20,'10. 170KMP'!AJ:AJ) -> 1.0745956e+08 | AE20: =SUMIF('10. 170KMP'!$J:$J,'0.KQKD'!$E20,'10. 170KMP'!AK:AK) -> 1.4211633e+08 | AF20: =SUMIF('10. 170KMP'!$J:$J,'0.KQKD'!$E20,'10. 170KMP'!AL:AL) -> 1.4211633e+08 | AG20: =SUMIF('10. 170KMP'!$J:$J,'0.KQKD'!$E20,'10. 170KMP'!AM:AM) -> 1.4211633e+08 | AH20: =SUM(V20:AG20) -> 1.2946671e+09 | AI20: =SUM(AJ20:AU20) -> 221985940 | AJ20: =SUMIF('10. 170KMP'!$J:$J,'0.KQKD'!$E20,'10. 170KMP'!AP:AP) -> 34725069 | AK20: =SUMIF('10. 170KMP'!$J:$J,'0.KQKD'!$E20,'10. 170KMP'!AQ:AQ) -> 23690775 | AL20: =SUMIF('10. 170KMP'!$J:$J,'0.KQKD'!$E20,'10. 170KMP'!AR:AR) -> 83036407 | AM20: =SUMIF('10. 170KMP'!$J:$J,'0.KQKD'!$E20,'10. 170KMP'!AS:AS) -> 46534296 | AN20: =SUMIF('10. 170KMP'!$J:$J,'0.KQKD'!$E20,'10. 170KMP'!AT:AT) -> 33999393 | AO20: =SUMIF('10. 170KMP'!$J:$J,'0.KQKD'!$E20,'10. 170KMP'!AU:AU) -> 0 | AP20: =SUMIF('10. 170KMP'!$J:$J,'0.KQKD'!$E20,'10. 170KMP'!AV:AV) -> 0 | AQ20: =SUMIF('10. 170KMP'!$J:$J,'0.KQKD'!$E20,'10. 170KMP'!AW:AW) -> 0 | AR20: =SUMIF('10. 170KMP'!$J:$J,'0.KQKD'!$E20,'10. 170KMP'!AX:AX) -> 0 | AS20: =SUMIF('10. 170KMP'!$J:$J,'0.KQKD'!$E20,'10. 170KMP'!AY:AY) -> 0 | AT20: =SUMIF('10. 170KMP'!$J:$J,'0.KQKD'!$E20,'10. 170KMP'!AZ:AZ) -> 0 | AU20: =SUMIF('10. 170KMP'!$J:$J,'0.KQKD'!$E20,'10. 170KMP'!BA:BA) -> 0 | AV20: =AM20 -> 46534296 | AW20: =AN20 -> 33999393 | AX20: =Z20 -> 1.0745956e+08 | AY20: =IFERROR(AW20/AV20,0) -> 0.73063087 | AZ20: =IFERROR(AW20/AX20,0) -> 0.31639246 | BA20: =SUM(I20:M20) -> 0 | BB20: =SUM(AJ20:AN20) -> 221985940 | BC20: =SUM(V20:Z20) -> 4.3847989e+08 | BD20: =IFERROR(BB20/BA20,0) -> 0 | BE20: =IFERROR(BB20/BC20,0) -> 0.50626253 | BF20: =IFERROR(BB20/AH20,0) -> 0.17146179
D21: Chi phí điện | E21: 08 | F21: =SUMIF('10. 170KMP'!$J:$J,'0.KQKD'!$E21,'10. 170KMP'!L:L) -> 0 | G21: =SUMIF('10. 170KMP'!$J:$J,'0.KQKD'!$E21,'10. 170KMP'!M:M) -> 0 | H21: =SUMIF('10. 170KMP'!$J:$J,'0.KQKD'!$E21,'10. 170KMP'!N:N) -> 0 | I21: =SUMIF('10. 170KMP'!$J:$J,'0.KQKD'!$E21,'10. 170KMP'!O:O) -> 0 | J21: =SUMIF('10. 170KMP'!$J:$J,'0.KQKD'!$E21,'10. 170KMP'!P:P) -> 0 | K21: =SUMIF('10. 170KMP'!$J:$J,'0.KQKD'!$E21,'10. 170KMP'!Q:Q) -> 0 | L21: =SUMIF('10. 170KMP'!$J:$J,'0.KQKD'!$E21,'10. 170KMP'!R:R) -> 0 | M21: =SUMIF('10. 170KMP'!$J:$J,'0.KQKD'!$E21,'10. 170KMP'!S:S) -> 0 | N21: =SUMIF('10. 170KMP'!$J:$J,'0.KQKD'!$E21,'10. 170KMP'!T:T) -> 0 | O21: =SUMIF('10. 170KMP'!$J:$J,'0.KQKD'!$E21,'10. 170KMP'!U:U) -> 0 | P21: =SUMIF('10. 170KMP'!$J:$J,'0.KQKD'!$E21,'10. 170KMP'!V:V) -> 0 | Q21: =SUMIF('10. 170KMP'!$J:$J,'0.KQKD'!$E21,'10. 170KMP'!W:W) -> 0 | R21: =SUMIF('10. 170KMP'!$J:$J,'0.KQKD'!$E21,'10. 170KMP'!X:X) -> 0 | S21: =SUMIF('10. 170KMP'!$J:$J,'0.KQKD'!$E21,'10. 170KMP'!Y:Y) -> 0 | T21: =SUMIF('10. 170KMP'!$J:$J,'0.KQKD'!$E21,'10. 170KMP'!Z:Z) -> 0 | U21: =SUM(I21:T21) -> 0 | V21: =SUMIF('10. 170KMP'!$J:$J,'0.KQKD'!$E21,'10. 170KMP'!AB:AB) -> 1.1567843e+08 | W21: =SUMIF('10. 170KMP'!$J:$J,'0.KQKD'!$E21,'10. 170KMP'!AC:AC) -> 89972114 | X21: =SUMIF('10. 170KMP'!$J:$J,'0.KQKD'!$E21,'10. 170KMP'!AD:AD) -> 1.2853159e+08 | Y21: =SUMIF('10. 170KMP'!$J:$J,'0.KQKD'!$E21,'10. 170KMP'!AE:AE) -> 1.6071292e+08 | Z21: =SUMIF('10. 170KMP'!$J:$J,'0.KQKD'!$E21,'10. 170KMP'!AF:AF) -> 1.6071292e+08 | AA21: =SUMIF('10. 170KMP'!$J:$J,'0.KQKD'!$E21,'10. 170KMP'!AG:AG) -> 1.6071292e+08 | AB21: =SUMIF('10. 170KMP'!$J:$J,'0.KQKD'!$E21,'10. 170KMP'!AH:AH) -> 1.6071292e+08 | AC21: =SUMIF('10. 170KMP'!$J:$J,'0.KQKD'!$E21,'10. 170KMP'!AI:AI) -> 1.6071292e+08 | AD21: =SUMIF('10. 170KMP'!$J:$J,'0.KQKD'!$E21,'10. 170KMP'!AJ:AJ) -> 1.6071292e+08 | AE21: =SUMIF('10. 170KMP'!$J:$J,'0.KQKD'!$E21,'10. 170KMP'!AK:AK) -> 3.4009604e+08 | AF21: =SUMIF('10. 170KMP'!$J:$J,'0.KQKD'!$E21,'10. 170KMP'!AL:AL) -> 3.4009604e+08 | AG21: =SUMIF('10. 170KMP'!$J:$J,'0.KQKD'!$E21,'10. 170KMP'!AM:AM) -> 3.4009604e+08 | AH21: =SUM(V21:AG21) -> 2.3187478e+09 | AI21: =SUM(AJ21:AU21) -> 762782095 | AJ21: =SUMIF('10. 170KMP'!$J:$J,'0.KQKD'!$E21,'10. 170KMP'!AP:AP) -> 143712301 | AK21: =SUMIF('10. 170KMP'!$J:$J,'0.KQKD'!$E21,'10. 170KMP'!AQ:AQ) -> 97799305 | AL21: =SUMIF('10. 170KMP'!$J:$J,'0.KQKD'!$E21,'10. 170KMP'!AR:AR) -> 189407823 | AM21: =SUMIF('10. 170KMP'!$J:$J,'0.KQKD'!$E21,'10. 170KMP'!AS:AS) -> 173664681 | AN21: =SUMIF('10. 170KMP'!$J:$J,'0.KQKD'!$E21,'10. 170KMP'!AT:AT) -> 158197985 | AO21: =SUMIF('10. 170KMP'!$J:$J,'0.KQKD'!$E21,'10. 170KMP'!AU:AU) -> 0 | AP21: =SUMIF('10. 170KMP'!$J:$J,'0.KQKD'!$E21,'10. 170KMP'!AV:AV) -> 0 | AQ21: =SUMIF('10. 170KMP'!$J:$J,'0.KQKD'!$E21,'10. 170KMP'!AW:AW) -> 0 | AR21: =SUMIF('10. 170KMP'!$J:$J,'0.KQKD'!$E21,'10. 170KMP'!AX:AX) -> 0 | AS21: =SUMIF('10. 170KMP'!$J:$J,'0.KQKD'!$E21,'10. 170KMP'!AY:AY) -> 0 | AT21: =SUMIF('10. 170KMP'!$J:$J,'0.KQKD'!$E21,'10. 170KMP'!AZ:AZ) -> 0 | AU21: =SUMIF('10. 170KMP'!$J:$J,'0.KQKD'!$E21,'10. 170KMP'!BA:BA) -> 0 | AV21: =AM21 -> 173664681 | AW21: =AN21 -> 158197985 | AX21: =Z21 -> 1.6071292e+08 | AY21: =IFERROR(AW21/AV21,0) -> 0.91093931 | AZ21: =IFERROR(AW21/AX21,0) -> 0.98435137 | BA21: =SUM(I21:M21) -> 0 | BB21: =SUM(AJ21:AN21) -> 762782095 | BC21: =SUM(V21:Z21) -> 6.5560798e+08 | BD21: =IFERROR(BB21/BA21,0) -> 0 | BE21: =IFERROR(BB21/BC21,0) -> 1.1634729 | BF21: =IFERROR(BB21/AH21,0) -> 0.32896294
D22: Chi phí nước | E22: 09 | F22: =SUMIF('10. 170KMP'!$J:$J,'0.KQKD'!$E22,'10. 170KMP'!L:L) -> 0 | G22: =SUMIF('10. 170KMP'!$J:$J,'0.KQKD'!$E22,'10. 170KMP'!M:M) -> 0 | H22: =SUMIF('10. 170KMP'!$J:$J,'0.KQKD'!$E22,'10. 170KMP'!N:N) -> 0 | I22: =SUMIF('10. 170KMP'!$J:$J,'0.KQKD'!$E22,'10. 170KMP'!O:O) -> 0 | J22: =SUMIF('10. 170KMP'!$J:$J,'0.KQKD'!$E22,'10. 170KMP'!P:P) -> 0 | K22: =SUMIF('10. 170KMP'!$J:$J,'0.KQKD'!$E22,'10. 170KMP'!Q:Q) -> 0 | L22: =SUMIF('10. 170KMP'!$J:$J,'0.KQKD'!$E22,'10. 170KMP'!R:R) -> 0 | M22: =SUMIF('10. 170KMP'!$J:$J,'0.KQKD'!$E22,'10. 170KMP'!S:S) -> 0 | N22: =SUMIF('10. 170KMP'!$J:$J,'0.KQKD'!$E22,'10. 170KMP'!T:T) -> 0 | O22: =SUMIF('10. 170KMP'!$J:$J,'0.KQKD'!$E22,'10. 170KMP'!U:U) -> 0 | P22: =SUMIF('10. 170KMP'!$J:$J,'0.KQKD'!$E22,'10. 170KMP'!V:V) -> 0 | Q22: =SUMIF('10. 170KMP'!$J:$J,'0.KQKD'!$E22,'10. 170KMP'!W:W) -> 0 | R22: =SUMIF('10. 170KMP'!$J:$J,'0.KQKD'!$E22,'10. 170KMP'!X:X) -> 0 | S22: =SUMIF('10. 170KMP'!$J:$J,'0.KQKD'!$E22,'10. 170KMP'!Y:Y) -> 0 | T22: =SUMIF('10. 170KMP'!$J:$J,'0.KQKD'!$E22,'10. 170KMP'!Z:Z) -> 0 | U22: =SUM(I22:T22) -> 0 | V22: =SUMIF('10. 170KMP'!$J:$J,'0.KQKD'!$E22,'10. 170KMP'!AB:AB) -> 14685000 | W22: =SUMIF('10. 170KMP'!$J:$J,'0.KQKD'!$E22,'10. 170KMP'!AC:AC) -> 11421667 | X22: =SUMIF('10. 170KMP'!$J:$J,'0.KQKD'!$E22,'10. 170KMP'!AD:AD) -> 16316667 | Y22: =SUMIF('10. 170KMP'!$J:$J,'0.KQKD'!$E22,'10. 170KMP'!AE:AE) -> 17948333 | Z22: =SUMIF('10. 170KMP'!$J:$J,'0.KQKD'!$E22,'10. 170KMP'!AF:AF) -> 17979279 | AA22: =SUMIF('10. 170KMP'!$J:$J,'0.KQKD'!$E22,'10. 170KMP'!AG:AG) -> 18010224 | AB22: =SUMIF('10. 170KMP'!$J:$J,'0.KQKD'!$E22,'10. 170KMP'!AH:AH) -> 18010224 | AC22: =SUMIF('10. 170KMP'!$J:$J,'0.KQKD'!$E22,'10. 170KMP'!AI:AI) -> 18010224 | AD22: =SUMIF('10. 170KMP'!$J:$J,'0.KQKD'!$E22,'10. 170KMP'!AJ:AJ) -> 18010224 | AE22: =SUMIF('10. 170KMP'!$J:$J,'0.KQKD'!$E22,'10. 170KMP'!AK:AK) -> 18010224 | AF22: =SUMIF('10. 170KMP'!$J:$J,'0.KQKD'!$E22,'10. 170KMP'!AL:AL) -> 18010224 | AG22: =SUMIF('10. 170KMP'!$J:$J,'0.KQKD'!$E22,'10. 170KMP'!AM:AM) -> 18010224 | AH22: =SUM(V22:AG22) -> 2.0442251e+08 | AI22: =SUM(AJ22:AU22) -> 74301500 | AJ22: =SUMIF('10. 170KMP'!$J:$J,'0.KQKD'!$E22,'10. 170KMP'!AP:AP) -> 10833000 | AK22: =SUMIF('10. 170KMP'!$J:$J,'0.KQKD'!$E22,'10. 170KMP'!AQ:AQ) -> 16525500 | AL22: =SUMIF('10. 170KMP'!$J:$J,'0.KQKD'!$E22,'10. 170KMP'!AR:AR) -> 9602500 | AM22: =SUMIF('10. 170KMP'!$J:$J,'0.KQKD'!$E22,'10. 170KMP'!AS:AS) -> 18733500 | AN22: =SUMIF('10. 170KMP'!$J:$J,'0.KQKD'!$E22,'10. 170KMP'!AT:AT) -> 18607000 | AO22: =SUMIF('10. 170KMP'!$J:$J,'0.KQKD'!$E22,'10. 170KMP'!AU:AU) -> 0 | AP22: =SUMIF('10. 170KMP'!$J:$J,'0.KQKD'!$E22,'10. 170KMP'!AV:AV) -> 0 | AQ22: =SUMIF('10. 170KMP'!$J:$J,'0.KQKD'!$E22,'10. 170KMP'!AW:AW) -> 0 | AR22: =SUMIF('10. 170KMP'!$J:$J,'0.KQKD'!$E22,'10. 170KMP'!AX:AX) -> 0 | AS22: =SUMIF('10. 170KMP'!$J:$J,'0.KQKD'!$E22,'10. 170KMP'!AY:AY) -> 0 | AT22: =SUMIF('10. 170KMP'!$J:$J,'0.KQKD'!$E22,'10. 170KMP'!AZ:AZ) -> 0 | AU22: =SUMIF('10. 170KMP'!$J:$J,'0.KQKD'!$E22,'10. 170KMP'!BA:BA) -> 0 | AV22: =AM22 -> 18733500 | AW22: =AN22 -> 18607000 | AX22: =Z22 -> 17979279 | AY22: =IFERROR(AW22/AV22,0) -> 0.99324739 | AZ22: =IFERROR(AW22/AX22,0) -> 1.0349136 | BA22: =SUM(I22:M22) -> 0 | BB22: =SUM(AJ22:AN22) -> 74301500 | BC22: =SUM(V22:Z22) -> 78350945 | BD22: =IFERROR(BB22/BA22,0) -> 0 | BE22: =IFERROR(BB22/BC22,0) -> 0.94831657 | BF22: =IFERROR(BB22/AH22,0) -> 0.36347024
D23: Chi phí xăng, dầu | E23: 10 | F23: =SUMIF('10. 170KMP'!$J:$J,'0.KQKD'!$E23,'10. 170KMP'!L:L) -> 0 | G23: =SUMIF('10. 170KMP'!$J:$J,'0.KQKD'!$E23,'10. 170KMP'!M:M) -> 0 | H23: =SUMIF('10. 170KMP'!$J:$J,'0.KQKD'!$E23,'10. 170KMP'!N:N) -> 0 | I23: =SUMIF('10. 170KMP'!$J:$J,'0.KQKD'!$E23,'10. 170KMP'!O:O) -> 0 | J23: =SUMIF('10. 170KMP'!$J:$J,'0.KQKD'!$E23,'10. 170KMP'!P:P) -> 0 | K23: =SUMIF('10. 170KMP'!$J:$J,'0.KQKD'!$E23,'10. 170KMP'!Q:Q) -> 0 | L23: =SUMIF('10. 170KMP'!$J:$J,'0.KQKD'!$E23,'10. 170KMP'!R:R) -> 0 | M23: =SUMIF('10. 170KMP'!$J:$J,'0.KQKD'!$E23,'10. 170KMP'!S:S) -> 0 | N23: =SUMIF('10. 170KMP'!$J:$J,'0.KQKD'!$E23,'10. 170KMP'!T:T) -> 0 | O23: =SUMIF('10. 170KMP'!$J:$J,'0.KQKD'!$E23,'10. 170KMP'!U:U) -> 0 | P23: =SUMIF('10. 170KMP'!$J:$J,'0.KQKD'!$E23,'10. 170KMP'!V:V) -> 0 | Q23: =SUMIF('10. 170KMP'!$J:$J,'0.KQKD'!$E23,'10. 170KMP'!W:W) -> 0 | R23: =SUMIF('10. 170KMP'!$J:$J,'0.KQKD'!$E23,'10. 170KMP'!X:X) -> 0 | S23: =SUMIF('10. 170KMP'!$J:$J,'0.KQKD'!$E23,'10. 170KMP'!Y:Y) -> 0 | T23: =SUMIF('10. 170KMP'!$J:$J,'0.KQKD'!$E23,'10. 170KMP'!Z:Z) -> 0 | U23: =SUM(I23:T23) -> 0 | V23: =SUMIF('10. 170KMP'!$J:$J,'0.KQKD'!$E23,'10. 170KMP'!AB:AB) -> 33298364 | W23: =SUMIF('10. 170KMP'!$J:$J,'0.KQKD'!$E23,'10. 170KMP'!AC:AC) -> 25898727 | X23: =SUMIF('10. 170KMP'!$J:$J,'0.KQKD'!$E23,'10. 170KMP'!AD:AD) -> 36998182 | Y23: =SUMIF('10. 170KMP'!$J:$J,'0.KQKD'!$E23,'10. 170KMP'!AE:AE) -> 46218068 | Z23: =SUMIF('10. 170KMP'!$J:$J,'0.KQKD'!$E23,'10. 170KMP'!AF:AF) -> 46218068 | AA23: =SUMIF('10. 170KMP'!$J:$J,'0.KQKD'!$E23,'10. 170KMP'!AG:AG) -> 46218068 | AB23: =SUMIF('10. 170KMP'!$J:$J,'0.KQKD'!$E23,'10. 170KMP'!AH:AH) -> 46218068 | AC23: =SUMIF('10. 170KMP'!$J:$J,'0.KQKD'!$E23,'10. 170KMP'!AI:AI) -> 46218068 | AD23: =SUMIF('10. 170KMP'!$J:$J,'0.KQKD'!$E23,'10. 170KMP'!AJ:AJ) -> 46218068 | AE23: =SUMIF('10. 170KMP'!$J:$J,'0.KQKD'!$E23,'10. 170KMP'!AK:AK) -> 63543976 | AF23: =SUMIF('10. 170KMP'!$J:$J,'0.KQKD'!$E23,'10. 170KMP'!AL:AL) -> 63543976 | AG23: =SUMIF('10. 170KMP'!$J:$J,'0.KQKD'!$E23,'10. 170KMP'!AM:AM) -> 63543976 | AH23: =SUM(V23:AG23) -> 5.6413561e+08 | AI23: =SUM(AJ23:AU23) -> 237880457 | AJ23: =SUMIF('10. 170KMP'!$J:$J,'0.KQKD'!$E23,'10. 170KMP'!AP:AP) -> 27244448 | AK23: =SUMIF('10. 170KMP'!$J:$J,'0.KQKD'!$E23,'10. 170KMP'!AQ:AQ) -> 19797175 | AL23: =SUMIF('10. 170KMP'!$J:$J,'0.KQKD'!$E23,'10. 170KMP'!AR:AR) -> 58970664 | AM23: =SUMIF('10. 170KMP'!$J:$J,'0.KQKD'!$E23,'10. 170KMP'!AS:AS) -> 78006420 | AN23: =SUMIF('10. 170KMP'!$J:$J,'0.KQKD'!$E23,'10. 170KMP'!AT:AT) -> 53861750 | AO23: =SUMIF('10. 170KMP'!$J:$J,'0.KQKD'!$E23,'10. 170KMP'!AU:AU) -> 0 | AP23: =SUMIF('10. 170KMP'!$J:$J,'0.KQKD'!$E23,'10. 170KMP'!AV:AV) -> 0 | AQ23: =SUMIF('10. 170KMP'!$J:$J,'0.KQKD'!$E23,'10. 170KMP'!AW:AW) -> 0 | AR23: =SUMIF('10. 170KMP'!$J:$J,'0.KQKD'!$E23,'10. 170KMP'!AX:AX) -> 0 | AS23: =SUMIF('10. 170KMP'!$J:$J,'0.KQKD'!$E23,'10. 170KMP'!AY:AY) -> 0 | AT23: =SUMIF('10. 170KMP'!$J:$J,'0.KQKD'!$E23,'10. 170KMP'!AZ:AZ) -> 0 | AU23: =SUMIF('10. 170KMP'!$J:$J,'0.KQKD'!$E23,'10. 170KMP'!BA:BA) -> 0 | AV23: =AM23 -> 78006420 | AW23: =AN23 -> 53861750 | AX23: =Z23 -> 46218068 | AY23: =IFERROR(AW23/AV23,0) -> 0.69047842 | AZ23: =IFERROR(AW23/AX23,0) -> 1.165383 | BA23: =SUM(I23:M23) -> 0 | BB23: =SUM(AJ23:AN23) -> 237880457 | BC23: =SUM(V23:Z23) -> 1.8863141e+08 | BD23: =IFERROR(BB23/BA23,0) -> 0 | BE23: =IFERROR(BB23/BC23,0) -> 1.2610861 | BF23: =IFERROR(BB23/AH23,0) -> 0.42167247
D24: Chi phí môi trường | E24: 11 | F24: =SUMIF('10. 170KMP'!$J:$J,'0.KQKD'!$E24,'10. 170KMP'!L:L) -> 0 | G24: =SUMIF('10. 170KMP'!$J:$J,'0.KQKD'!$E24,'10. 170KMP'!M:M) -> 0 | H24: =SUMIF('10. 170KMP'!$J:$J,'0.KQKD'!$E24,'10. 170KMP'!N:N) -> 0 | I24: =SUMIF('10. 170KMP'!$J:$J,'0.KQKD'!$E24,'10. 170KMP'!O:O) -> 0 | J24: =SUMIF('10. 170KMP'!$J:$J,'0.KQKD'!$E24,'10. 170KMP'!P:P) -> 0 | K24: =SUMIF('10. 170KMP'!$J:$J,'0.KQKD'!$E24,'10. 170KMP'!Q:Q) -> 0 | L24: =SUMIF('10. 170KMP'!$J:$J,'0.KQKD'!$E24,'10. 170KMP'!R:R) -> 0 | M24: =SUMIF('10. 170KMP'!$J:$J,'0.KQKD'!$E24,'10. 170KMP'!S:S) -> 0 | N24: =SUMIF('10. 170KMP'!$J:$J,'0.KQKD'!$E24,'10. 170KMP'!T:T) -> 0 | O24: =SUMIF('10. 170KMP'!$J:$J,'0.KQKD'!$E24,'10. 170KMP'!U:U) -> 0 | P24: =SUMIF('10. 170KMP'!$J:$J,'0.KQKD'!$E24,'10. 170KMP'!V:V) -> 0 | Q24: =SUMIF('10. 170KMP'!$J:$J,'0.KQKD'!$E24,'10. 170KMP'!W:W) -> 0 | R24: =SUMIF('10. 170KMP'!$J:$J,'0.KQKD'!$E24,'10. 170KMP'!X:X) -> 0 | S24: =SUMIF('10. 170KMP'!$J:$J,'0.KQKD'!$E24,'10. 170KMP'!Y:Y) -> 0 | T24: =SUMIF('10. 170KMP'!$J:$J,'0.KQKD'!$E24,'10. 170KMP'!Z:Z) -> 0 | U24: =SUM(I24:T24) -> 0 | V24: =SUMIF('10. 170KMP'!$J:$J,'0.KQKD'!$E24,'10. 170KMP'!AB:AB) -> 63414998 | W24: =SUMIF('10. 170KMP'!$J:$J,'0.KQKD'!$E24,'10. 170KMP'!AC:AC) -> 50699776 | X24: =SUMIF('10. 170KMP'!$J:$J,'0.KQKD'!$E24,'10. 170KMP'!AD:AD) -> 69772609 | Y24: =SUMIF('10. 170KMP'!$J:$J,'0.KQKD'!$E24,'10. 170KMP'!AE:AE) -> 85730980 | Z24: =SUMIF('10. 170KMP'!$J:$J,'0.KQKD'!$E24,'10. 170KMP'!AF:AF) -> 85730980 | AA24: =SUMIF('10. 170KMP'!$J:$J,'0.KQKD'!$E24,'10. 170KMP'!AG:AG) -> 85730980 | AB24: =SUMIF('10. 170KMP'!$J:$J,'0.KQKD'!$E24,'10. 170KMP'!AH:AH) -> 85730980 | AC24: =SUMIF('10. 170KMP'!$J:$J,'0.KQKD'!$E24,'10. 170KMP'!AI:AI) -> 85730980 | AD24: =SUMIF('10. 170KMP'!$J:$J,'0.KQKD'!$E24,'10. 170KMP'!AJ:AJ) -> 85730980 | AE24: =SUMIF('10. 170KMP'!$J:$J,'0.KQKD'!$E24,'10. 170KMP'!AK:AK) -> 1.2175687e+08 | AF24: =SUMIF('10. 170KMP'!$J:$J,'0.KQKD'!$E24,'10. 170KMP'!AL:AL) -> 1.2175687e+08 | AG24: =SUMIF('10. 170KMP'!$J:$J,'0.KQKD'!$E24,'10. 170KMP'!AM:AM) -> 1.2175687e+08 | AH24: =SUM(V24:AG24) -> 1.0635439e+09 | AI24: =SUM(AJ24:AU24) -> 333847543 | AJ24: =SUMIF('10. 170KMP'!$J:$J,'0.KQKD'!$E24,'10. 170KMP'!AP:AP) -> 83507301 | AK24: =SUMIF('10. 170KMP'!$J:$J,'0.KQKD'!$E24,'10. 170KMP'!AQ:AQ) -> 55749730 | AL24: =SUMIF('10. 170KMP'!$J:$J,'0.KQKD'!$E24,'10. 170KMP'!AR:AR) -> 56842126 | AM24: =SUMIF('10. 170KMP'!$J:$J,'0.KQKD'!$E24,'10. 170KMP'!AS:AS) -> 96189917 | AN24: =SUMIF('10. 170KMP'!$J:$J,'0.KQKD'!$E24,'10. 170KMP'!AT:AT) -> 41558469 | AO24: =SUMIF('10. 170KMP'!$J:$J,'0.KQKD'!$E24,'10. 170KMP'!AU:AU) -> 0 | AP24: =SUMIF('10. 170KMP'!$J:$J,'0.KQKD'!$E24,'10. 170KMP'!AV:AV) -> 0 | AQ24: =SUMIF('10. 170KMP'!$J:$J,'0.KQKD'!$E24,'10. 170KMP'!AW:AW) -> 0 | AR24: =SUMIF('10. 170KMP'!$J:$J,'0.KQKD'!$E24,'10. 170KMP'!AX:AX) -> 0 | AS24: =SUMIF('10. 170KMP'!$J:$J,'0.KQKD'!$E24,'10. 170KMP'!AY:AY) -> 0 | AT24: =SUMIF('10. 170KMP'!$J:$J,'0.KQKD'!$E24,'10. 170KMP'!AZ:AZ) -> 0 | AU24: =SUMIF('10. 170KMP'!$J:$J,'0.KQKD'!$E24,'10. 170KMP'!BA:BA) -> 0 | AV24: =AM24 -> 96189917 | AW24: =AN24 -> 41558469 | AX24: =Z24 -> 85730980 | AY24: =IFERROR(AW24/AV24,0) -> 0.432046 | AZ24: =IFERROR(AW24/AX24,0) -> 0.48475439 | BA24: =SUM(I24:M24) -> 0 | BB24: =SUM(AJ24:AN24) -> 333847543 | BC24: =SUM(V24:Z24) -> 3.5534934e+08 | BD24: =IFERROR(BB24/BA24,0) -> 0 | BE24: =IFERROR(BB24/BC24,0) -> 0.93949109 | BF24: =IFERROR(BB24/AH24,0) -> 0.31390105
D25: Chi phí gia công thuê ngoài | E25: 12 | F25: =SUMIF('10. 170KMP'!$J:$J,'0.KQKD'!$E25,'10. 170KMP'!L:L) -> 0 | G25: =SUMIF('10. 170KMP'!$J:$J,'0.KQKD'!$E25,'10. 170KMP'!M:M) -> 0 | H25: =SUMIF('10. 170KMP'!$J:$J,'0.KQKD'!$E25,'10. 170KMP'!N:N) -> 0 | I25: =SUMIF('10. 170KMP'!$J:$J,'0.KQKD'!$E25,'10. 170KMP'!O:O) -> 0 | J25: =SUMIF('10. 170KMP'!$J:$J,'0.KQKD'!$E25,'10. 170KMP'!P:P) -> 0 | K25: =SUMIF('10. 170KMP'!$J:$J,'0.KQKD'!$E25,'10. 170KMP'!Q:Q) -> 0 | L25: =SUMIF('10. 170KMP'!$J:$J,'0.KQKD'!$E25,'10. 170KMP'!R:R) -> 0 | M25: =SUMIF('10. 170KMP'!$J:$J,'0.KQKD'!$E25,'10. 170KMP'!S:S) -> 0 | N25: =SUMIF('10. 170KMP'!$J:$J,'0.KQKD'!$E25,'10. 170KMP'!T:T) -> 0 | O25: =SUMIF('10. 170KMP'!$J:$J,'0.KQKD'!$E25,'10. 170KMP'!U:U) -> 0 | P25: =SUMIF('10. 170KMP'!$J:$J,'0.KQKD'!$E25,'10. 170KMP'!V:V) -> 0 | Q25: =SUMIF('10. 170KMP'!$J:$J,'0.KQKD'!$E25,'10. 170KMP'!W:W) -> 0 | R25: =SUMIF('10. 170KMP'!$J:$J,'0.KQKD'!$E25,'10. 170KMP'!X:X) -> 0 | S25: =SUMIF('10. 170KMP'!$J:$J,'0.KQKD'!$E25,'10. 170KMP'!Y:Y) -> 0 | T25: =SUMIF('10. 170KMP'!$J:$J,'0.KQKD'!$E25,'10. 170KMP'!Z:Z) -> 0 | U25: =SUM(I25:T25) -> 0 | V25: =SUMIF('10. 170KMP'!$J:$J,'0.KQKD'!$E25,'10. 170KMP'!AB:AB) -> 0 | W25: =SUMIF('10. 170KMP'!$J:$J,'0.KQKD'!$E25,'10. 170KMP'!AC:AC) -> 0 | X25: =SUMIF('10. 170KMP'!$J:$J,'0.KQKD'!$E25,'10. 170KMP'!AD:AD) -> 0 | Y25: =SUMIF('10. 170KMP'!$J:$J,'0.KQKD'!$E25,'10. 170KMP'!AE:AE) -> 0 | Z25: =SUMIF('10. 170KMP'!$J:$J,'0.KQKD'!$E25,'10. 170KMP'!AF:AF) -> 0 | AA25: =SUMIF('10. 170KMP'!$J:$J,'0.KQKD'!$E25,'10. 170KMP'!AG:AG) -> 0 | AB25: =SUMIF('10. 170KMP'!$J:$J,'0.KQKD'!$E25,'10. 170KMP'!AH:AH) -> 0 | AC25: =SUMIF('10. 170KMP'!$J:$J,'0.KQKD'!$E25,'10. 170KMP'!AI:AI) -> 0 | AD25: =SUMIF('10. 170KMP'!$J:$J,'0.KQKD'!$E25,'10. 170KMP'!AJ:AJ) -> 0 | AE25: =SUMIF('10. 170KMP'!$J:$J,'0.KQKD'!$E25,'10. 170KMP'!AK:AK) -> 0 | AF25: =SUMIF('10. 170KMP'!$J:$J,'0.KQKD'!$E25,'10. 170KMP'!AL:AL) -> 0 | AG25: =SUMIF('10. 170KMP'!$J:$J,'0.KQKD'!$E25,'10. 170KMP'!AM:AM) -> 0 | AH25: =SUM(V25:AG25) -> 0 | AI25: =SUM(AJ25:AU25) -> 0 | AJ25: =SUMIF('10. 170KMP'!$J:$J,'0.KQKD'!$E25,'10. 170KMP'!AP:AP) -> 0 | AK25: =SUMIF('10. 170KMP'!$J:$J,'0.KQKD'!$E25,'10. 170KMP'!AQ:AQ) -> 0 | AL25: =SUMIF('10. 170KMP'!$J:$J,'0.KQKD'!$E25,'10. 170KMP'!AR:AR) -> 0 | AM25: =SUMIF('10. 170KMP'!$J:$J,'0.KQKD'!$E25,'10. 170KMP'!AS:AS) -> 0 | AN25: =SUMIF('10. 170KMP'!$J:$J,'0.KQKD'!$E25,'10. 170KMP'!AT:AT) -> 0 | AO25: =SUMIF('10. 170KMP'!$J:$J,'0.KQKD'!$E25,'10. 170KMP'!AU:AU) -> 0 | AP25: =SUMIF('10. 170KMP'!$J:$J,'0.KQKD'!$E25,'10. 170KMP'!AV:AV) -> 0 | AQ25: =SUMIF('10. 170KMP'!$J:$J,'0.KQKD'!$E25,'10. 170KMP'!AW:AW) -> 0 | AR25: =SUMIF('10. 170KMP'!$J:$J,'0.KQKD'!$E25,'10. 170KMP'!AX:AX) -> 0 | AS25: =SUMIF('10. 170KMP'!$J:$J,'0.KQKD'!$E25,'10. 170KMP'!AY:AY) -> 0 | AT25: =SUMIF('10. 170KMP'!$J:$J,'0.KQKD'!$E25,'10. 170KMP'!AZ:AZ) -> 0 | AU25: =SUMIF('10. 170KMP'!$J:$J,'0.KQKD'!$E25,'10. 170KMP'!BA:BA) -> 0 | AV25: =AM25 -> 0 | AW25: =AN25 -> 0 | AX25: =Z25 -> 0 | AY25: =IFERROR(AW25/AV25,0) -> 0 | AZ25: =IFERROR(AW25/AX25,0) -> 0 | BA25: =SUM(I25:M25) -> 0 | BB25: =SUM(AJ25:AN25) -> 0 | BC25: =SUM(V25:Z25) -> 0 | BD25: =IFERROR(BB25/BA25,0) -> 0 | BE25: =IFERROR(BB25/BC25,0) -> 0 | BF25: =IFERROR(BB25/AH25,0) -> 0
D26: Điều chỉnh giá vốn trong hàng tồn kho | U26: =SUM(I26:T26) -> 0 | AH26: =SUM(V26:AG26) -> 0 | AI26: =SUM(AJ26:AU26) -> -183493566 | AJ26: -5748175 | AK26: -56304451 | AL26: -89032912 | AM26: 36269259 | AN26: -68677287 | AV26: =AM26 -> 36269259 | AW26: =AN26 -> -68677287 | AX26: =Z26 -> 0 | AY26: =IFERROR(AW26/AV26,0) -> -1.8935398 | AZ26: =IFERROR(AW26/AX26,0) -> 0 | BA26: =SUM(I26:M26) -> 0 | BB26: =SUM(AJ26:AN26) -> -183493566 | BC26: =SUM(V26:Z26) -> 0 | BD26: =IFERROR(BB26/BA26,0) -> 0 | BE26: =IFERROR(BB26/BC26,0) -> 0 | BF26: =IFERROR(BB26/AH26,0) -> 0
D27: Đ/C lãi chưa thực hiện trong HTK khi Hợp nhất | AI27: =SUM(AJ27:AU27) -> 0 | AV27: =AM27 -> 0 | AW27: =AN27 -> 0 | AX27: =Z27 -> 0 | AY27: =IFERROR(AW27/AV27,0) -> 0 | AZ27: =IFERROR(AW27/AX27,0) -> 0 | BA27: =SUM(I27:L27) -> 0 | BB27: =SUM(AJ27:AM27) -> 0 | BC27: =SUM(V27:Y27) -> 0 | BD27: =IFERROR(BB27/BA27,0) -> 0 | BE27: =IFERROR(BB27/BC27,0) -> 0 | BF27: =IFERROR(BB27/AH27,0) -> 0
B28: 4 | C28: LÃI BIẾN PHÍ | F28: =F5-F10-F13 -> 0 | G28: =G5-G10-G13 -> 0 | H28: =H5-H10-H13 -> 0 | I28: =I5-I10-I13 -> 0 | J28: =J5-J10-J13 -> 0 | K28: =K5-K10-K13 -> 0 | L28: =L5-L10-L13 -> 0 | M28: =M5-M10-M13 -> 0 | ... AU28: =AU5-AU10-AU13 -> 0 | AV28: =AM28 -> 2842695490 | AW28: =AN28 -> 2598187829 | AX28: =Z28 -> 2.5089313e+09 | AY28: =IFERROR(AW28/AV28,0) -> 0.91398739 | AZ28: =IFERROR(AW28/AX28,0) -> 1.0355755 | BA28: =SUM(I28:M28) -> 0 | BB28: =SUM(AJ28:AN28) -> 12088655101 | BC28: =SUM(V28:Z28) -> 1.0254037e+10 | BD28: =IFERROR(BB28/BA28,0) -> 0 | BE28: =IFERROR(BB28/BC28,0) -> 1.1789167 | BF28: =IFERROR(BB28/AH28,0) -> 0.4139637
D29: Tỷ lệ Lãi biến phí (%) | F29: =IFERROR(F28/F$5,0) -> 0 | G29: =IFERROR(G28/G$5,0) -> 0 | H29: =IFERROR(H28/H$5,0) -> 0 | I29: =IFERROR(I28/I$5,0) -> 0 | J29: =IFERROR(J28/J$5,0) -> 0 | K29: =IFERROR(K28/K$5,0) -> 0 | L29: =IFERROR(L28/L$5,0) -> 0 | M29: =IFERROR(M28/M$5,0) -> 0 | ... AX29: =IFERROR(AX28/AX$5,0) -> 0.15706036 | AY29: =IFERROR(AW29/AV29,0) -> 1.0010922 | AZ29: =IFERROR(AW29/AX29,0) -> 1.2585811 | BA29: =IFERROR(BA28/BA$5,0) -> 0 | BB29: =IFERROR(BB28/BB$5,0) -> 0.19420715 | BC29: =IFERROR(BC28/BC$5,0) -> 0.15723478 | BD29: =IFERROR(BB29/BA29,0) -> 0 | BE29: =IFERROR(BB29/BC29,0) -> 1.2351412 | BF29: =IFERROR(BB29/AH29,0) -> 1.2044936
D30: Lãi biến phí / Tấn (Triệu đồng/Tấn) | F30: =IFERROR(F28/F$4,0)*1000 -> 0 | G30: =IFERROR(G28/G$4,0)*1000 -> 0 | H30: =IFERROR(H28/H$4,0)*1000 -> 0 | I30: =IFERROR(I28/I$4,0)*1000 -> 0 | J30: =IFERROR(J28/J$4,0)*1000 -> 0 | K30: =IFERROR(K28/K$4,0)*1000 -> 0 | L30: =IFERROR(L28/L$4,0)*1000 -> 0 | M30: =IFERROR(M28/M$4,0)*1000 -> 0 | ... AX30: =IFERROR(AX28/AX$4,0)*1000 -> 2377570.5 | AY30: =IFERROR(AW30/AV30,0) -> 1.0419266 | AZ30: =IFERROR(AW30/AX30,0) -> 1.3608652 | BA30: =IFERROR(BA28/BA$4,0)*1000 -> 0 | BB30: =IFERROR(BB28/BB$4,0)*1000 -> 3010499.6 | BC30: =IFERROR(BC28/BC$4,0)*1000 -> 2380148.5 | BD30: =IFERROR(BB30/BA30,0) -> 0 | BE30: =IFERROR(BB30/BC30,0) -> 1.2648369 | BF30: =IFERROR(BB30/AH30,0) -> 1.2062515
B31: 5 | C31: ĐỊNH PHÍ | F31: =F34+F61+F63+F65 -> 0 | G31: =G34+G61+G63+G65 -> 0 | H31: =H34+H61+H63+H65 -> 0 | I31: =I34+I61+I63+I65 -> 0 | J31: =J34+J61+J63+J65 -> 0 | K31: =K34+K61+K63+K65 -> 0 | L31: =L34+L61+L63+L65 -> 0 | M31: =M34+M61+M63+M65 -> 0 | ... AU31: =AU34+AU61+AU63+AU65 -> 0 | AV31: =AM31 -> 2903101307 | AW31: =AN31 -> 2427435730 | AX31: =Z31 -> 2.6416917e+09 | AY31: =IFERROR(AW31/AV31,0) -> 0.83615261 | AZ31: =IFERROR(AW31/AX31,0) -> 0.91889441 | BA31: =SUM(I31:M31) -> 0 | BB31: =SUM(AJ31:AN31) -> 13049782943 | BC31: =SUM(V31:Z31) -> 1.2815118e+10 | BD31: =IFERROR(BB31/BA31,0) -> 0 | BE31: =IFERROR(BB31/BC31,0) -> 1.0183116 | BF31: =IFERROR(BB31/AH31,0) -> 0.40430311
D32: Định phí / Doanh thu (%) | F32: =IFERROR(F31/F$5,0) -> 0 | G32: =IFERROR(G31/G$5,0) -> 0 | H32: =IFERROR(H31/H$5,0) -> 0 | I32: =IFERROR(I31/I$5,0) -> 0 | J32: =IFERROR(J31/J$5,0) -> 0 | K32: =IFERROR(K31/K$5,0) -> 0 | L32: =IFERROR(L31/L$5,0) -> 0 | M32: =IFERROR(M31/M$5,0) -> 0 | ... AX32: =IFERROR(AX31/AX$5,0) -> 0.16537123 | AY32: =IFERROR(AW32/AV32,0) -> 0.91583965 | AZ32: =IFERROR(AW32/AX32,0) -> 1.1167734 | BA32: =IFERROR(BA31/BA$5,0) -> 0 | BB32: =IFERROR(BB31/BB$5,0) -> 0.2096479 | BC32: =IFERROR(BC31/BC$5,0) -> 0.19650625 | BD32: =IFERROR(BB32/BA32,0) -> 0 | BE32: =IFERROR(BB32/BC32,0) -> 1.0668765 | BF32: =IFERROR(BB32/AH32,0) -> 1.1763846
D33: Định phí / Tấn (Triệu đồng/Tấn) | F33: =IFERROR(F31/F$4,0)*1000 -> 0 | G33: =IFERROR(G31/G$4,0)*1000 -> 0 | H33: =IFERROR(H31/H$4,0)*1000 -> 0 | I33: =IFERROR(I31/I$4,0)*1000 -> 0 | J33: =IFERROR(J31/J$4,0)*1000 -> 0 | K33: =IFERROR(K31/K$4,0)*1000 -> 0 | L33: =IFERROR(L31/L$4,0)*1000 -> 0 | M33: =IFERROR(M31/M$4,0)*1000 -> 0 | ... AX33: =IFERROR(AX31/AX$4,0)*1000 -> 2503379.9 | AY33: =IFERROR(AW33/AV33,0) -> 0.95319661 | AZ33: =IFERROR(AW33/AX33,0) -> 1.2075328 | BA33: =IFERROR(BA31/BA$4,0)*1000 -> 0 | BB33: =IFERROR(BB31/BB$4,0)*1000 -> 3249854.2 | BC33: =IFERROR(BC31/BC$4,0)*1000 -> 2974622 | BD33: =IFERROR(BB33/BA33,0) -> 0 | BE33: =IFERROR(BB33/BC33,0) -> 1.0925268 | BF33: =IFERROR(BB33/AH33,0) -> 1.1781015
B34: 5.1 | C34: Chi phí hoạt động | F34: =SUM(F36:F60) -> 0 | G34: =SUM(G36:G60) -> 0 | H34: =SUM(H36:H60) -> 0 | I34: =SUM(I36:I60) -> 0 | J34: =SUM(J36:J60) -> 0 | K34: =SUM(K36:K60) -> 0 | L34: =SUM(L36:L60) -> 0 | M34: =SUM(M36:M60) -> 0 | ... AU34: =SUM(AU36:AU60) -> 0 | AV34: =AM34 -> 1141642817 | AW34: =AN34 -> 912123006 | AX34: =Z34 -> 8.0659871e+08 | AY34: =IFERROR(AW34/AV34,0) -> 0.79895655 | AZ34: =IFERROR(AW34/AX34,0) -> 1.1308263 | BA34: =SUM(I34:M34) -> 0 | BB34: =SUM(AJ34:AN34) -> 4675330374 | BC34: =SUM(V34:Z34) -> 3.9265097e+09 | BD34: =IFERROR(BB34/BA34,0) -> 0 | BE34: =IFERROR(BB34/BC34,0) -> 1.190709 | BF34: =IFERROR(BB34/AH34,0) -> 0.46986556
D35: Chi phí hoạt động / Doanh thu (%) | F35: =IFERROR(F34/F$5,0) -> 0 | G35: =IFERROR(G34/G$5,0) -> 0 | H35: =IFERROR(H34/H$5,0) -> 0 | I35: =IFERROR(I34/I$5,0) -> 0 | J35: =IFERROR(J34/J$5,0) -> 0 | K35: =IFERROR(K34/K$5,0) -> 0 | L35: =IFERROR(L34/L$5,0) -> 0 | M35: =IFERROR(M34/M$5,0) -> 0 | ... AX35: =IFERROR(AX34/AX$5,0) -> 0.050493485 | AY35: =IFERROR(AW35/AV35,0) -> 0.87509874 | AZ35: =IFERROR(AW35/AX35,0) -> 1.3743436 | BA35: =IFERROR(BA34/BA$5,0) -> 0 | BB35: =IFERROR(BB34/BB$5,0) -> 0.075110306 | BC35: =IFERROR(BC34/BC$5,0) -> 0.060208863 | BD35: =IFERROR(BB35/BA35,0) -> 0 | BE35: =IFERROR(BB35/BC35,0) -> 1.2474958 | BF35: =IFERROR(BB35/AH35,0) -> 1.367149
D36: Chi phí sửa chữa, bảo trì | E36: 13 | F36: =SUMIF('10. 170KMP'!$J:$J,'0.KQKD'!$E36,'10. 170KMP'!L:L) -> 0 | G36: =SUMIF('10. 170KMP'!$J:$J,'0.KQKD'!$E36,'10. 170KMP'!M:M) -> 0 | H36: =SUMIF('10. 170KMP'!$J:$J,'0.KQKD'!$E36,'10. 170KMP'!N:N) -> 0 | I36: =SUMIF('10. 170KMP'!$J:$J,'0.KQKD'!$E36,'10. 170KMP'!O:O) -> 0 | J36: =SUMIF('10. 170KMP'!$J:$J,'0.KQKD'!$E36,'10. 170KMP'!P:P) -> 0 | K36: =SUMIF('10. 170KMP'!$J:$J,'0.KQKD'!$E36,'10. 170KMP'!Q:Q) -> 0 | L36: =SUMIF('10. 170KMP'!$J:$J,'0.KQKD'!$E36,'10. 170KMP'!R:R) -> 0 | M36: =SUMIF('10. 170KMP'!$J:$J,'0.KQKD'!$E36,'10. 170KMP'!S:S) -> 0 | N36: =SUMIF('10. 170KMP'!$J:$J,'0.KQKD'!$E36,'10. 170KMP'!T:T) -> 0 | O36: =SUMIF('10. 170KMP'!$J:$J,'0.KQKD'!$E36,'10. 170KMP'!U:U) -> 0 | P36: =SUMIF('10. 170KMP'!$J:$J,'0.KQKD'!$E36,'10. 170KMP'!V:V) -> 0 | Q36: =SUMIF('10. 170KMP'!$J:$J,'0.KQKD'!$E36,'10. 170KMP'!W:W) -> 0 | R36: =SUMIF('10. 170KMP'!$J:$J,'0.KQKD'!$E36,'10. 170KMP'!X:X) -> 0 | S36: =SUMIF('10. 170KMP'!$J:$J,'0.KQKD'!$E36,'10. 170KMP'!Y:Y) -> 0 | T36: =SUMIF('10. 170KMP'!$J:$J,'0.KQKD'!$E36,'10. 170KMP'!Z:Z) -> 0 | U36: =SUM(I36:T36) -> 0 | V36: =SUMIF('10. 170KMP'!$J:$J,'0.KQKD'!$E36,'10. 170KMP'!AB:AB) -> 1.7935325e+08 | W36: =SUMIF('10. 170KMP'!$J:$J,'0.KQKD'!$E36,'10. 170KMP'!AC:AC) -> 1.6965775e+08 | X36: =SUMIF('10. 170KMP'!$J:$J,'0.KQKD'!$E36,'10. 170KMP'!AD:AD) -> 1.5663343e+08 | Y36: =SUMIF('10. 170KMP'!$J:$J,'0.KQKD'!$E36,'10. 170KMP'!AE:AE) -> 1.5774093e+08 | Z36: =SUMIF('10. 170KMP'!$J:$J,'0.KQKD'!$E36,'10. 170KMP'!AF:AF) -> 1.8036165e+08 | AA36: =SUMIF('10. 170KMP'!$J:$J,'0.KQKD'!$E36,'10. 170KMP'!AG:AG) -> 1.9764366e+08 | AB36: =SUMIF('10. 170KMP'!$J:$J,'0.KQKD'!$E36,'10. 170KMP'!AH:AH) -> 2.0732248e+08 | AC36: =SUMIF('10. 170KMP'!$J:$J,'0.KQKD'!$E36,'10. 170KMP'!AI:AI) -> 2.1352517e+08 | AD36: =SUMIF('10. 170KMP'!$J:$J,'0.KQKD'!$E36,'10. 170KMP'!AJ:AJ) -> 2.560274e+08 | AE36: =SUMIF('10. 170KMP'!$J:$J,'0.KQKD'!$E36,'10. 170KMP'!AK:AK) -> 2.495229e+08 | AF36: =SUMIF('10. 170KMP'!$J:$J,'0.KQKD'!$E36,'10. 170KMP'!AL:AL) -> 2.7490302e+08 | AG36: =SUMIF('10. 170KMP'!$J:$J,'0.KQKD'!$E36,'10. 170KMP'!AM:AM) -> 2.7916358e+08 | AH36: =SUM(V36:AG36) -> 2.5218552e+09 | AI36: =SUM(AJ36:AU36) -> 581194724 | AJ36: =SUMIF('10. 170KMP'!$J:$J,'0.KQKD'!$E36,'10. 170KMP'!AP:AP) -> 119569951 | AK36: =SUMIF('10. 170KMP'!$J:$J,'0.KQKD'!$E36,'10. 170KMP'!AQ:AQ) -> 112133103 | AL36: =SUMIF('10. 170KMP'!$J:$J,'0.KQKD'!$E36,'10. 170KMP'!AR:AR) -> 117289856 | AM36: =SUMIF('10. 170KMP'!$J:$J,'0.KQKD'!$E36,'10. 170KMP'!AS:AS) -> 115465878 | AN36: =SUMIF('10. 170KMP'!$J:$J,'0.KQKD'!$E36,'10. 170KMP'!AT:AT) -> 116735936 | AO36: =SUMIF('10. 170KMP'!$J:$J,'0.KQKD'!$E36,'10. 170KMP'!AU:AU) -> 0 | AP36: =SUMIF('10. 170KMP'!$J:$J,'0.KQKD'!$E36,'10. 170KMP'!AV:AV) -> 0 | AQ36: =SUMIF('10. 170KMP'!$J:$J,'0.KQKD'!$E36,'10. 170KMP'!AW:AW) -> 0 | AR36: =SUMIF('10. 170KMP'!$J:$J,'0.KQKD'!$E36,'10. 170KMP'!AX:AX) -> 0 | AS36: =SUMIF('10. 170KMP'!$J:$J,'0.KQKD'!$E36,'10. 170KMP'!AY:AY) -> 0 | AT36: =SUMIF('10. 170KMP'!$J:$J,'0.KQKD'!$E36,'10. 170KMP'!AZ:AZ) -> 0 | AU36: =SUMIF('10. 170KMP'!$J:$J,'0.KQKD'!$E36,'10. 170KMP'!BA:BA) -> 0 | AV36: =AM36 -> 115465878 | AW36: =AN36 -> 116735936 | AX36: =Z36 -> 1.8036165e+08 | AY36: =IFERROR(AW36/AV36,0) -> 1.0109994 | AZ36: =IFERROR(AW36/AX36,0) -> 0.64723258 | BA36: =SUM(I36:M36) -> 0 | BB36: =SUM(AJ36:AN36) -> 581194724 | BC36: =SUM(V36:Z36) -> 8.43747e+08 | BD36: =IFERROR(BB36/BA36,0) -> 0 | BE36: =IFERROR(BB36/BC36,0) -> 0.68882583 | BF36: =IFERROR(BB36/AH36,0) -> 0.23046316
D37: Chi phí thử mẫu, thử khuôn, phát triển sản phẩm | E37: 14 | F37: =SUMIF('10. 170KMP'!$J:$J,'0.KQKD'!$E37,'10. 170KMP'!L:L) -> 0 | G37: =SUMIF('10. 170KMP'!$J:$J,'0.KQKD'!$E37,'10. 170KMP'!M:M) -> 0 | H37: =SUMIF('10. 170KMP'!$J:$J,'0.KQKD'!$E37,'10. 170KMP'!N:N) -> 0 | I37: =SUMIF('10. 170KMP'!$J:$J,'0.KQKD'!$E37,'10. 170KMP'!O:O) -> 0 | J37: =SUMIF('10. 170KMP'!$J:$J,'0.KQKD'!$E37,'10. 170KMP'!P:P) -> 0 | K37: =SUMIF('10. 170KMP'!$J:$J,'0.KQKD'!$E37,'10. 170KMP'!Q:Q) -> 0 | L37: =SUMIF('10. 170KMP'!$J:$J,'0.KQKD'!$E37,'10. 170KMP'!R:R) -> 0 | M37: =SUMIF('10. 170KMP'!$J:$J,'0.KQKD'!$E37,'10. 170KMP'!S:S) -> 0 | N37: =SUMIF('10. 170KMP'!$J:$J,'0.KQKD'!$E37,'10. 170KMP'!T:T) -> 0 | O37: =SUMIF('10. 170KMP'!$J:$J,'0.KQKD'!$E37,'10. 170KMP'!U:U) -> 0 | P37: =SUMIF('10. 170KMP'!$J:$J,'0.KQKD'!$E37,'10. 170KMP'!V:V) -> 0 | Q37: =SUMIF('10. 170KMP'!$J:$J,'0.KQKD'!$E37,'10. 170KMP'!W:W) -> 0 | R37: =SUMIF('10. 170KMP'!$J:$J,'0.KQKD'!$E37,'10. 170KMP'!X:X) -> 0 | S37: =SUMIF('10. 170KMP'!$J:$J,'0.KQKD'!$E37,'10. 170KMP'!Y:Y) -> 0 | T37: =SUMIF('10. 170KMP'!$J:$J,'0.KQKD'!$E37,'10. 170KMP'!Z:Z) -> 0 | U37: =SUM(I37:T37) -> 0 | V37: =SUMIF('10. 170KMP'!$J:$J,'0.KQKD'!$E37,'10. 170KMP'!AB:AB) -> 0 | W37: =SUMIF('10. 170KMP'!$J:$J,'0.KQKD'!$E37,'10. 170KMP'!AC:AC) -> 0 | X37: =SUMIF('10. 170KMP'!$J:$J,'0.KQKD'!$E37,'10. 170KMP'!AD:AD) -> 0 | Y37: =SUMIF('10. 170KMP'!$J:$J,'0.KQKD'!$E37,'10. 170KMP'!AE:AE) -> 0 | Z37: =SUMIF('10. 170KMP'!$J:$J,'0.KQKD'!$E37,'10. 170KMP'!AF:AF) -> 0 | AA37: =SUMIF('10. 170KMP'!$J:$J,'0.KQKD'!$E37,'10. 170KMP'!AG:AG) -> 0 | AB37: =SUMIF('10. 170KMP'!$J:$J,'0.KQKD'!$E37,'10. 170KMP'!AH:AH) -> 0 | AC37: =SUMIF('10. 170KMP'!$J:$J,'0.KQKD'!$E37,'10. 170KMP'!AI:AI) -> 0 | AD37: =SUMIF('10. 170KMP'!$J:$J,'0.KQKD'!$E37,'10. 170KMP'!AJ:AJ) -> 0 | AE37: =SUMIF('10. 170KMP'!$J:$J,'0.KQKD'!$E37,'10. 170KMP'!AK:AK) -> 0 | AF37: =SUMIF('10. 170KMP'!$J:$J,'0.KQKD'!$E37,'10. 170KMP'!AL:AL) -> 0 | AG37: =SUMIF('10. 170KMP'!$J:$J,'0.KQKD'!$E37,'10. 170KMP'!AM:AM) -> 0 | AH37: =SUM(V37:AG37) -> 0 | AI37: =SUM(AJ37:AU37) -> 0 | AJ37: =SUMIF('10. 170KMP'!$J:$J,'0.KQKD'!$E37,'10. 170KMP'!AP:AP) -> 0 | AK37: =SUMIF('10. 170KMP'!$J:$J,'0.KQKD'!$E37,'10. 170KMP'!AQ:AQ) -> 0 | AL37: =SUMIF('10. 170KMP'!$J:$J,'0.KQKD'!$E37,'10. 170KMP'!AR:AR) -> 0 | AM37: =SUMIF('10. 170KMP'!$J:$J,'0.KQKD'!$E37,'10. 170KMP'!AS:AS) -> 0 | AN37: =SUMIF('10. 170KMP'!$J:$J,'0.KQKD'!$E37,'10. 170KMP'!AT:AT) -> 0 | AO37: =SUMIF('10. 170KMP'!$J:$J,'0.KQKD'!$E37,'10. 170KMP'!AU:AU) -> 0 | AP37: =SUMIF('10. 170KMP'!$J:$J,'0.KQKD'!$E37,'10. 170KMP'!AV:AV) -> 0 | AQ37: =SUMIF('10. 170KMP'!$J:$J,'0.KQKD'!$E37,'10. 170KMP'!AW:AW) -> 0 | AR37: =SUMIF('10. 170KMP'!$J:$J,'0.KQKD'!$E37,'10. 170KMP'!AX:AX) -> 0 | AS37: =SUMIF('10. 170KMP'!$J:$J,'0.KQKD'!$E37,'10. 170KMP'!AY:AY) -> 0 | AT37: =SUMIF('10. 170KMP'!$J:$J,'0.KQKD'!$E37,'10. 170KMP'!AZ:AZ) -> 0 | AU37: =SUMIF('10. 170KMP'!$J:$J,'0.KQKD'!$E37,'10. 170KMP'!BA:BA) -> 0 | AV37: =AM37 -> 0 | AW37: =AN37 -> 0 | AX37: =Z37 -> 0 | AY37: =IFERROR(AW37/AV37,0) -> 0 | AZ37: =IFERROR(AW37/AX37,0) -> 0 | BA37: =SUM(I37:M37) -> 0 | BB37: =SUM(AJ37:AN37) -> 0 | BC37: =SUM(V37:Z37) -> 0 | BD37: =IFERROR(BB37/BA37,0) -> 0 | BE37: =IFERROR(BB37/BC37,0) -> 0 | BF37: =IFERROR(BB37/AH37,0) -> 0
