Workbook

Sheet Báo cáo
B1: Đvt: kg | H1: B6: đưa hết vào nguồn DTR
A2: STT | B2: Loại chai/vảy | D2: TỔNG | H2: NGUỒN DTR | L2: NGUỒN MUA NGOÀI | P2: NGUỒN UNKNOWN
D3: Sản lượng đầu vào | E3: Sản lượng thu hồi | F3: % Cơ cấu đầu ra | H3: Sản lượng đầu vào | I3: Sản lượng thu hồi | J3: % Cơ cấu đầu ra | L3: Sản lượng đầu vào | M3: Sản lượng thu hồi | N3: % Cơ cấu đầu ra | P3: Sản lượng đầu vào | Q3: Sản lượng thu hồi | R3: % Cơ cấu đầu ra
A4: 1 | B4: B1 | D4: =H4+L4+P4 -> 34662019 | E4: =I4+M4+Q4 -> 32683112 | F4: =IFERROR(E4/$E$14,0) -> 0.79257546 | H4: =SUMIFS(Data!$D$3:$D$300,Data!$I$3:$I$300,$B4,Data!$J$3:$J$300,"DTR") -> 9848801.8 | I4: =SUMIFS(Data!$E$3:$E$300,Data!$I$3:$I$300,$B4,Data!$J$3:$J$300,"DTR")+SUMIFS(Data!$F$3:$F$300,Data!$I$3:$I$300,$B4,Data!$J$3:$J$300,"DTR") -> 9161109.3 | J4: =IFERROR(I4/$I$14,0) -> 0.56910053 | L4: =SUMIFS(Data!$D$3:$D$300,Data!$I$3:$I$300,$B4,Data!$J$3:$J$300,"MN") -> 24813217 | M4: =SUMIFS(Data!$E$3:$E$300,Data!$I$3:$I$300,$B4,Data!$J$3:$J$300,"MN")+SUMIFS(Data!$F$3:$F$300,Data!$I$3:$I$300,$B4,Data!$J$3:$J$300,"MN") -> 23522003 | N4: =IFERROR(M4/$M$14,0) -> 0.94102804 | P4: =SUMIFS(Data!$D$3:$D$300,Data!$I$3:$I$300,$B4,Data!$J$3:$J$300,"Unknown") -> 0 | Q4: =SUMIFS(Data!$E$3:$E$300,Data!$I$3:$I$300,$B4,Data!$J$3:$J$300,"Unknown")+SUMIFS(Data!$F$3:$F$300,Data!$I$3:$I$300,$B4,Data!$J$3:$J$300,"Unknown") -> 0 | R4: =IFERROR(Q4/$H$14,0) -> 0
A5: 2 | B5: B2 | D5: =H5+L5+P5 -> 587311 | E5: =I5+M5+Q5 -> 550350 | F5: =IFERROR(E5/$E$14,0) -> 0.013346156 | H5: =SUMIFS(Data!$D$3:$D$300,Data!$I$3:$I$300,$B5,Data!$J$3:$J$300,"DTR") -> 522911 | I5: =SUMIFS(Data!$E$3:$E$300,Data!$I$3:$I$300,$B5,Data!$J$3:$J$300,"DTR")+SUMIFS(Data!$F$3:$F$300,Data!$I$3:$I$300,$B5,Data!$J$3:$J$300,"DTR") -> 489150 | J5: =IFERROR(I5/$I$14,0) -> 0.030386661 | L5: =SUMIFS(Data!$D$3:$D$300,Data!$I$3:$I$300,$B5,Data!$J$3:$J$300,"MN") -> 64400 | M5: =SUMIFS(Data!$E$3:$E$300,Data!$I$3:$I$300,$B5,Data!$J$3:$J$300,"MN")+SUMIFS(Data!$F$3:$F$300,Data!$I$3:$I$300,$B5,Data!$J$3:$J$300,"MN") -> 61200 | N5: =IFERROR(M5/$M$14,0) -> 0.0024483849 | P5: =SUMIFS(Data!$D$3:$D$300,Data!$I$3:$I$300,$B5,Data!$J$3:$J$300,"Unknown") -> 0 | Q5: =SUMIFS(Data!$E$3:$E$300,Data!$I$3:$I$300,$B5,Data!$J$3:$J$300,"Unknown")+SUMIFS(Data!$F$3:$F$300,Data!$I$3:$I$300,$B5,Data!$J$3:$J$300,"Unknown") -> 0 | R5: =IFERROR(Q5/$H$14,0) -> 0
A6: 3 | B6: B3 | D6: =H6+L6+P6 -> 103993 | E6: =I6+M6+Q6 -> 96500 | F6: =IFERROR(E6/$E$14,0) -> 0.0023401545 | H6: =SUMIFS(Data!$D$3:$D$300,Data!$I$3:$I$300,$B6,Data!$J$3:$J$300,"DTR") -> 38500 | I6: =SUMIFS(Data!$E$3:$E$300,Data!$I$3:$I$300,$B6,Data!$J$3:$J$300,"DTR")+SUMIFS(Data!$F$3:$F$300,Data!$I$3:$I$300,$B6,Data!$J$3:$J$300,"DTR") -> 37500 | J6: =IFERROR(I6/$I$14,0) -> 0.0023295508 | L6: =SUMIFS(Data!$D$3:$D$300,Data!$I$3:$I$300,$B6,Data!$J$3:$J$300,"MN") -> 65493 | M6: =SUMIFS(Data!$E$3:$E$300,Data!$I$3:$I$300,$B6,Data!$J$3:$J$300,"MN")+SUMIFS(Data!$F$3:$F$300,Data!$I$3:$I$300,$B6,Data!$J$3:$J$300,"MN") -> 59000 | N6: =IFERROR(M6/$M$14,0) -> 0.0023603711 | P6: =SUMIFS(Data!$D$3:$D$300,Data!$I$3:$I$300,$B6,Data!$J$3:$J$300,"Unknown") -> 0 | Q6: =SUMIFS(Data!$E$3:$E$300,Data!$I$3:$I$300,$B6,Data!$J$3:$J$300,"Unknown")+SUMIFS(Data!$F$3:$F$300,Data!$I$3:$I$300,$B6,Data!$J$3:$J$300,"Unknown") -> 0 | R6: =IFERROR(Q6/$H$14,0) -> 0
A7: 4 | B7: B4 | D7: =H7+L7+P7 -> 209050 | E7: =I7+M7+Q7 -> 195450 | F7: =IFERROR(E7/$E$14,0) -> 0.0047397222 | H7: =SUMIFS(Data!$D$3:$D$300,Data!$I$3:$I$300,$B7,Data!$J$3:$J$300,"DTR") -> 200050 | I7: =SUMIFS(Data!$E$3:$E$300,Data!$I$3:$I$300,$B7,Data!$J$3:$J$300,"DTR")+SUMIFS(Data!$F$3:$F$300,Data!$I$3:$I$300,$B7,Data!$J$3:$J$300,"DTR") -> 186450 | J7: =IFERROR(I7/$I$14,0) -> 0.011582527 | L7: =SUMIFS(Data!$D$3:$D$300,Data!$I$3:$I$300,$B7,Data!$J$3:$J$300,"MN") -> 9000 | M7: =SUMIFS(Data!$E$3:$E$300,Data!$I$3:$I$300,$B7,Data!$J$3:$J$300,"MN")+SUMIFS(Data!$F$3:$F$300,Data!$I$3:$I$300,$B7,Data!$J$3:$J$300,"MN") -> 9000 | N7: =IFERROR(M7/$M$14,0) -> 0.0003600566 | P7: =SUMIFS(Data!$D$3:$D$300,Data!$I$3:$I$300,$B7,Data!$J$3:$J$300,"Unknown") -> 0 | Q7: =SUMIFS(Data!$E$3:$E$300,Data!$I$3:$I$300,$B7,Data!$J$3:$J$300,"Unknown")+SUMIFS(Data!$F$3:$F$300,Data!$I$3:$I$300,$B7,Data!$J$3:$J$300,"Unknown") -> 0 | R7: =IFERROR(Q7/$H$14,0) -> 0
A8: 5 | B8: B5 | D8: =H8+L8+P8 -> 164500 | E8: =I8+M8+Q8 -> 154000 | F8: =IFERROR(E8/$E$14,0) -> 0.0037345471 | H8: =SUMIFS(Data!$D$3:$D$300,Data!$I$3:$I$300,$B8,Data!$J$3:$J$300,"DTR") -> 164500 | I8: =SUMIFS(Data!$E$3:$E$300,Data!$I$3:$I$300,$B8,Data!$J$3:$J$300,"DTR")+SUMIFS(Data!$F$3:$F$300,Data!$I$3:$I$300,$B8,Data!$J$3:$J$300,"DTR") -> 154000 | J8: =IFERROR(I8/$I$14,0) -> 0.0095666888 | L8: =SUMIFS(Data!$D$3:$D$300,Data!$I$3:$I$300,$B8,Data!$J$3:$J$300,"MN") -> 0 | M8: =SUMIFS(Data!$E$3:$E$300,Data!$I$3:$I$300,$B8,Data!$J$3:$J$300,"MN")+SUMIFS(Data!$F$3:$F$300,Data!$I$3:$I$300,$B8,Data!$J$3:$J$300,"MN") -> 0 | N8: =IFERROR(M8/$M$14,0) -> 0 | P8: =SUMIFS(Data!$D$3:$D$300,Data!$I$3:$I$300,$B8,Data!$J$3:$J$300,"Unknown") -> 0 | Q8: =SUMIFS(Data!$E$3:$E$300,Data!$I$3:$I$300,$B8,Data!$J$3:$J$300,"Unknown")+SUMIFS(Data!$F$3:$F$300,Data!$I$3:$I$300,$B8,Data!$J$3:$J$300,"Unknown") -> 0 | R8: =IFERROR(Q8/$H$14,0) -> 0
A9: 6 | B9: B6 | D9: =H9+L9+P9 -> 4888056 | E9: =I9+M9+Q9 -> 4363227.3 | F9: =IFERROR(E9/$E$14,0) -> 0.1058096 | H9: =SUMIFS(Data!$D$3:$D$300,Data!$I$3:$I$300,$B9,Data!$J$3:$J$300,"DTR") -> 4888056 | I9: =SUMIFS(Data!$E$3:$E$300,Data!$I$3:$I$300,$B9,Data!$J$3:$J$300,"DTR")+SUMIFS(Data!$F$3:$F$300,Data!$I$3:$I$300,$B9,Data!$J$3:$J$300,"DTR") -> 4363227.3 | J9: =IFERROR(I9/$I$14,0) -> 0.2710496 | L9: =SUMIFS(Data!$D$3:$D$300,Data!$I$3:$I$300,$B9,Data!$J$3:$J$300,"MN") -> 0 | M9: =SUMIFS(Data!$E$3:$E$300,Data!$I$3:$I$300,$B9,Data!$J$3:$J$300,"MN")+SUMIFS(Data!$F$3:$F$300,Data!$I$3:$I$300,$B9,Data!$J$3:$J$300,"MN") -> 0 | N9: =IFERROR(M9/$M$14,0) -> 0 | P9: =SUMIFS(Data!$D$3:$D$300,Data!$I$3:$I$300,$B9,Data!$J$3:$J$300,"Unknown") -> 0 | Q9: =SUMIFS(Data!$E$3:$E$300,Data!$I$3:$I$300,$B9,Data!$J$3:$J$300,"Unknown")+SUMIFS(Data!$F$3:$F$300,Data!$I$3:$I$300,$B9,Data!$J$3:$J$300,"Unknown") -> 0 | R9: =IFERROR(Q9/$H$14,0) -> 0
A10: 7 | B10: B7 | D10: =H10+L10+P10 -> 478665 | E10: =I10+M10+Q10 -> 458020 | F10: =IFERROR(E10/$E$14,0) -> 0.011107125 | H10: =SUMIFS(Data!$D$3:$D$300,Data!$I$3:$I$300,$B10,Data!$J$3:$J$300,"DTR") -> 434705 | I10: =SUMIFS(Data!$E$3:$E$300,Data!$I$3:$I$300,$B10,Data!$J$3:$J$300,"DTR")+SUMIFS(Data!$F$3:$F$300,Data!$I$3:$I$300,$B10,Data!$J$3:$J$300,"DTR") -> 417428.2 | J10: =IFERROR(I10/$I$14,0) -> 0.025931205 | L10: =SUMIFS(Data!$D$3:$D$300,Data!$I$3:$I$300,$B10,Data!$J$3:$J$300,"MN") -> 43960 | M10: =SUMIFS(Data!$E$3:$E$300,Data!$I$3:$I$300,$B10,Data!$J$3:$J$300,"MN")+SUMIFS(Data!$F$3:$F$300,Data!$I$3:$I$300,$B10,Data!$J$3:$J$300,"MN") -> 40591.803 | N10: =IFERROR(M10/$M$14,0) -> 0.0016239274 | P10: =SUMIFS(Data!$D$3:$D$300,Data!$I$3:$I$300,$B10,Data!$J$3:$J$300,"Unknown") -> 0 | Q10: =SUMIFS(Data!$E$3:$E$300,Data!$I$3:$I$300,$B10,Data!$J$3:$J$300,"Unknown")+SUMIFS(Data!$F$3:$F$300,Data!$I$3:$I$300,$B10,Data!$J$3:$J$300,"Unknown") -> 0 | R10: =IFERROR(Q10/$H$14,0) -> 0
A11: 8 | B11: Unknown | D11: =H11+L11+P11 -> 143000 | E11: =I11+M11+Q11 -> 79100 | F11: =IFERROR(E11/$E$14,0) -> 0.0019181992 | H11: =SUMIFS(Data!$D$3:$D$300,Data!$I$3:$I$300,$B11,Data!$J$3:$J$300,"DTR") -> 0 | I11: =SUMIFS(Data!$E$3:$E$300,Data!$I$3:$I$300,$B11,Data!$J$3:$J$300,"DTR")+SUMIFS(Data!$F$3:$F$300,Data!$I$3:$I$300,$B11,Data!$J$3:$J$300,"DTR") -> 0 | J11: =IFERROR(I11/$I$14,0) -> 0 | L11: =SUMIFS(Data!$D$3:$D$300,Data!$I$3:$I$300,$B11,Data!$J$3:$J$300,"MN") -> 0 | M11: =SUMIFS(Data!$E$3:$E$300,Data!$I$3:$I$300,$B11,Data!$J$3:$J$300,"MN")+SUMIFS(Data!$F$3:$F$300,Data!$I$3:$I$300,$B11,Data!$J$3:$J$300,"MN") -> 0 | N11: =IFERROR(M11/$M$14,0) -> 0 | P11: =SUMIFS(Data!$D$3:$D$300,Data!$I$3:$I$300,$B11,Data!$J$3:$J$300,"Unknown") -> 143000 | Q11: =SUMIFS(Data!$E$3:$E$300,Data!$I$3:$I$300,$B11,Data!$J$3:$J$300,"Unknown")+SUMIFS(Data!$F$3:$F$300,Data!$I$3:$I$300,$B11,Data!$J$3:$J$300,"Unknown") -> 79100 | R11: =IFERROR(Q11/$H$14,0) -> 0.0049137992
A12: 9 | B12: Phó sản | D12: =H12+L12+P12 -> 0 | E12: =I12+M12+Q12 -> 2048103.3 | F12: =IFERROR(E12/$E$14,0) -> 0.049667132 | I12: =SUMIFS(Data!$G$3:$G$300,Data!$J$3:$J$300,"DTR") -> 1049489.4 | J12: =IFERROR(I12/$I$14,0) -> 0.065195707 | M12: =SUMIFS(Data!$G$3:$G$300,Data!$J$3:$J$300,"MN") -> 943737.9 | N12: =IFERROR(M12/$M$14,0) -> 0.037755451 | Q12: =SUMIFS(Data!$G$3:$G$300,Data!$J$3:$J$300,"Unknown") -> 54876 | R12: =IFERROR(Q12/$H$14,0) -> 0.0034089715
A13: 10 | B13: Hao hụt mất đi | D13: =H13+L13+P13 -> 0 | E13: =I13+M13+Q13 -> 608731.01 | F13: =IFERROR(E13/$E$14,0) -> 0.014761913 | I13: =SUMIFS(Data!$H$3:$H$300,Data!$J$3:$J$300,"DTR") -> 239169.49 | J13: =IFERROR(I13/$I$14,0) -> 0.014857533 | M13: =SUMIFS(Data!$H$3:$H$300,Data!$J$3:$J$300,"MN") -> 360537.52 | N13: =IFERROR(M13/$M$14,0) -> 0.014423768 | Q13: =SUMIFS(Data!$H$3:$H$300,Data!$J$3:$J$300,"Unknown") -> 9024 | R13: =IFERROR(Q13/$H$14,0) -> 0.00056058311
B14: Tổng | D14: =SUM(D4:D13) -> 41236594 | E14: =SUM(E4:E13) -> 41236594 | F14: =IFERROR(E14/$E$14,0) -> 1 | H14: =SUM(H4:H13) -> 16097524 | I14: =SUM(I4:I13) -> 16097524 | J14: =IFERROR(I14/$I$14,0) -> 1 | L14: =SUM(L4:L13) -> 24996070 | M14: =SUM(M4:M13) -> 24996070 | N14: =IFERROR(M14/$M$14,0) -> 1 | P14: =SUM(P4:P13) -> 143000 | Q14: =SUM(Q4:Q13) -> 143000 | R14: =IFERROR(Q14/$H$14,0) -> 0.0088833539
E15: =E4/E9 -> 7.490582 | F15: =IFERROR(E15/$E$14,0) -> 1.816489e-07 | H15: =$H$14/$D$14 -> 0.39036987 | I15: =$I$14/$E$14 -> 0.39036987 | L15: =L14/D14 -> 0.60616234 | M15: =$M$14/$E$14 -> 0.60616234 | P15: =$P$14/$D$14 -> 0.0034677937 | Q15: =$Q$14/$E$14 -> 0.0034677937
E16: =53/29 -> 1.8275862
E17: =$E$16*E9 -> 7974174.1
E18: =E4-E17 -> 24708938
D19: MN=> | E19: =E18/E4 -> 0.75601546 | F19: =M15 -> 0.60616234
D20: DT => | E20: =100%-E19 -> 0.24398454 | F20: =I15 -> 0.39036987

Sheet Data
A1: (Loại phó sản)
A2: Year | Month | B2: Material-Xuất | C2: Material description-Xuất | D2: Xuất-NX | E2: Nhập-SPC-NX | F2: Nhập-SPP-NX | G2: Nhập-PS-NX | H2: HHMĐ-NX | I2: Loại | J2: Nguồn
A3: 2025 | 01 | B3: 150000051 | C3: Vảy PET B1_A5.1 | D3: 730500 | E3: 326000 | F3: 379000 | G3: 22010 | H3: 3490 | I3: =_xlfn.XLOOKUP($B3,MD!$A$3:$A$100,MD!$C$3:$C$100) -> B1 | J3: =_xlfn.XLOOKUP($B3,MD!$A$3:$A$100,MD!$D$3:$D$100) -> MN
B4: 160012368 | C4: Vảy PET B1 chưa rửa 2 | D4: 501300 | E4: 352629.09 | F4: 111309.09 | G4: 36033.091 | H4: 1328.7273 | I4: =_xlfn.XLOOKUP($B4,MD!$A$3:$A$100,MD!$C$3:$C$100) -> B1 | J4: =_xlfn.XLOOKUP($B4,MD!$A$3:$A$100,MD!$D$3:$D$100) -> DTR
B5: 160012682 | C5: Vảy PET B2.2 chưa rửa 2 | D5: 229500 | E5: 121845.71 | F5: 100404.29 | G5: 6020 | H5: 1230 | I5: =_xlfn.XLOOKUP($B5,MD!$A$3:$A$100,MD!$C$3:$C$100) -> B2 | J5: =_xlfn.XLOOKUP($B5,MD!$A$3:$A$100,MD!$D$3:$D$100) -> DTR
B6: 150000052 | C6: Vảy PET B1_A5.2_R2 | D6: 140000 | E6: 29062.318 | F6: 98008.445 | G6: 12672.334 | H6: 256.90254 | I6: =_xlfn.XLOOKUP($B6,MD!$A$3:$A$100,MD!$C$3:$C$100) -> B1 | J6: =_xlfn.XLOOKUP($B6,MD!$A$3:$A$100,MD!$D$3:$D$100) -> MN
B7: 160012689 | C7: Vảy PET B6.2_A3.2 | D7: 140000 | E7: 0 | F7: 134500 | G7: 4850 | H7: 650 | I7: =_xlfn.XLOOKUP($B7,MD!$A$3:$A$100,MD!$C$3:$C$100) -> B6 | J7: =_xlfn.XLOOKUP($B7,MD!$A$3:$A$100,MD!$D$3:$D$100) -> DTR
B8: 160012297 | C8: Vảy PET B1_A3 MN | D8: 133500 | E8: 88500 | F8: 41000 | G8: 3550 | H8: 450 | I8: =_xlfn.XLOOKUP($B8,MD!$A$3:$A$100,MD!$C$3:$C$100) -> B1 | J8: =_xlfn.XLOOKUP($B8,MD!$A$3:$A$100,MD!$D$3:$D$100) -> MN
B9: 160012293 | C9: Vảy PET B1_A2.2 DT | D9: 94500 | E9: 50911.429 | F9: 40542.857 | G9: 2577.2571 | H9: 468.45714 | I9: =_xlfn.XLOOKUP($B9,MD!$A$3:$A$100,MD!$C$3:$C$100) -> B1 | J9: =_xlfn.XLOOKUP($B9,MD!$A$3:$A$100,MD!$D$3:$D$100) -> DTR
B10: 160012294 | C10: Vảy PET B1_A3 DT | D10: 47000 | E10: 26588.571 | F10: 17457.143 | G10: 2642.7429 | H10: 311.54286 | I10: =_xlfn.XLOOKUP($B10,MD!$A$3:$A$100,MD!$C$3:$C$100) -> B1 | J10: =_xlfn.XLOOKUP($B10,MD!$A$3:$A$100,MD!$D$3:$D$100) -> DTR
B11: 150000061 | C11: Vảy PET B6.2_A6 | D11: 44775 | E11: 500 | F11: 28000 | G11: 16100 | H11: 175 | I11: =_xlfn.XLOOKUP($B11,MD!$A$3:$A$100,MD!$C$3:$C$100) -> B6 | J11: =_xlfn.XLOOKUP($B11,MD!$A$3:$A$100,MD!$D$3:$D$100) -> DTR
B12: 160011727 | C12: Vảy PET B7.1 chưa rửa 1 | D12: 24000 | E12: 23349.153 | F12: 0 | G12: 325.42373 | H12: 325.42373 | I12: =_xlfn.XLOOKUP($B12,MD!$A$3:$A$100,MD!$C$3:$C$100) -> B7 | J12: =_xlfn.XLOOKUP($B12,MD!$A$3:$A$100,MD!$D$3:$D$100) -> DTR
B13: 160012371 | C13: Vảy PET B5 chưa rửa 2 | D13: 23000 | E13: 9850 | F13: 12850 | G13: 295 | H13: 5 | I13: =_xlfn.XLOOKUP($B13,MD!$A$3:$A$100,MD!$C$3:$C$100) -> B5 | J13: =_xlfn.XLOOKUP($B13,MD!$A$3:$A$100,MD!$D$3:$D$100) -> DTR
B14: 150000189 | C14: Vảy PET B1_A5.2_R1 | D14: 22094 | E14: 8000 | F14: 13000 | G14: 850 | H14: 244 | I14: =_xlfn.XLOOKUP($B14,MD!$A$3:$A$100,MD!$C$3:$C$100) -> B1 | J14: =_xlfn.XLOOKUP($B14,MD!$A$3:$A$100,MD!$D$3:$D$100) -> MN
B15: 150000053 | C15: Vảy PET B1_A6 | D15: 17416 | E15: 4437.682 | F15: 11791.555 | G15: 1132.6655 | H15: 54.097457 | I15: =_xlfn.XLOOKUP($B15,MD!$A$3:$A$100,MD!$C$3:$C$100) -> B1 | J15: =_xlfn.XLOOKUP($B15,MD!$A$3:$A$100,MD!$D$3:$D$100) -> MN
... B21: 160012369 | C21: Vảy PET B2 chưa rửa 2 | D21: 2400 | E21: 1354.2857 | F21: 1045.7143 | G21: 0 | H21: 0 | I21: =_xlfn.XLOOKUP($B21,MD!$A$3:$A$100,MD!$C$3:$C$100) -> B2 | J21: =_xlfn.XLOOKUP($B21,MD!$A$3:$A$100,MD!$D$3:$D$100) -> DTR
A22: 2025 | 01 Total | D22: 2193598 | E22: 1063800 | F22: 1007750 | G22: 112755 | H22: 9293
A23: 2025 | 02 | B23: 150000051 | C23: Vảy PET B1_A5.1 | D23: 615751 | E23: 248782.84 | F23: 337322.67 | G23: 26663.649 | H23: 2981.8496 | I23: =_xlfn.XLOOKUP($B23,MD!$A$3:$A$100,MD!$C$3:$C$100) -> B1 | J23: =_xlfn.XLOOKUP($B23,MD!$A$3:$A$100,MD!$D$3:$D$100) -> MN
B24: 160012689 | C24: Vảy PET B6.2_A3.2 | D24: 492000 | E24: 139500 | F24: 325000 | G24: 25587.8 | H24: 1912.2 | I24: =_xlfn.XLOOKUP($B24,MD!$A$3:$A$100,MD!$C$3:$C$100) -> B6 | J24: =_xlfn.XLOOKUP($B24,MD!$A$3:$A$100,MD!$D$3:$D$100) -> DTR
B25: 160012906 | C25: Vảy PET B1.3 Chưa Rửa 2 | D25: 367500 | E25: 279500 | F25: 64000 | G25: 23069 | H25: 931 | I25: =_xlfn.XLOOKUP($B25,MD!$A$3:$A$100,MD!$C$3:$C$100) -> B1 | J25: =_xlfn.XLOOKUP($B25,MD!$A$3:$A$100,MD!$D$3:$D$100) -> DTR
B26: 150000061 | C26: Vảy PET B6.2_A6 | D26: 286060 | E26: 268500 | F26: 0 | G26: 16191 | H26: 1369 | I26: =_xlfn.XLOOKUP($B26,MD!$A$3:$A$100,MD!$C$3:$C$100) -> B6 | J26: =_xlfn.XLOOKUP($B26,MD!$A$3:$A$100,MD!$D$3:$D$100) -> DTR
B27: 160012293 | C27: Vảy PET B1_A2.2 DT | D27: 198000 | E27: 122524.51 | F27: 66078.068 | G27: 8389.6043 | H27: 1007.8206 | I27: =_xlfn.XLOOKUP($B27,MD!$A$3:$A$100,MD!$C$3:$C$100) -> B1 | J27: =_xlfn.XLOOKUP($B27,MD!$A$3:$A$100,MD!$D$3:$D$100) -> DTR
B28: 150000052 | C28: Vảy PET B1_A5.2_R2 | D28: 108844 | E28: 82500 | F28: 21500 | G28: 4450 | H28: 394 | I28: =_xlfn.XLOOKUP($B28,MD!$A$3:$A$100,MD!$C$3:$C$100) -> B1 | J28: =_xlfn.XLOOKUP($B28,MD!$A$3:$A$100,MD!$D$3:$D$100) -> MN
B29: 160009895 | C29: Vảy PET B1_A1 DT | D29: 105200 | E29: 76257.186 | F29: 26199.262 | G29: 2614.2319 | H29: 129.32036 | I29: =_xlfn.XLOOKUP($B29,MD!$A$3:$A$100,MD!$C$3:$C$100) -> B1 | J29: =_xlfn.XLOOKUP($B29,MD!$A$3:$A$100,MD!$D$3:$D$100) -> DTR
B30: 150000189 | C30: Vảy PET B1_A5.2_R1 | D30: 100238 | E30: 19717.164 | F30: 75177.334 | G30: 4888.0511 | H30: 455.45045 | I30: =_xlfn.XLOOKUP($B30,MD!$A$3:$A$100,MD!$C$3:$C$100) -> B1 | J30: =_xlfn.XLOOKUP($B30,MD!$A$3:$A$100,MD!$D$3:$D$100) -> MN
B31: 160012659 | C31: Vảy PET B1_A2.1 DT | D31: 87000 | E31: 62389.409 | F31: 22235.978 | G31: 2257.2133 | H31: 117.39899 | I31: =_xlfn.XLOOKUP($B31,MD!$A$3:$A$100,MD!$C$3:$C$100) -> B1 | J31: =_xlfn.XLOOKUP($B31,MD!$A$3:$A$100,MD!$D$3:$D$100) -> DTR
B32: 160012368 | C32: Vảy PET B1 chưa rửa 2 | D32: 70500 | E32: 34593.168 | F32: 30214.286 | G32: 5359.7516 | H32: 332.79503 | I32: =_xlfn.XLOOKUP($B32,MD!$A$3:$A$100,MD!$C$3:$C$100) -> B1 | J32: =_xlfn.XLOOKUP($B32,MD!$A$3:$A$100,MD!$D$3:$D$100) -> DTR
B33: 160012372 | C33: Vảy PET B6 chưa rửa 2 | D33: 49200 | E33: 7000 | F33: 32000 | G33: 9800 | H33: 400 | I33: =_xlfn.XLOOKUP($B33,MD!$A$3:$A$100,MD!$C$3:$C$100) -> B6 | J33: =_xlfn.XLOOKUP($B33,MD!$A$3:$A$100,MD!$D$3:$D$100) -> DTR
B34: 160012296 | C34: Vảy PET B1_A2.2 MN | D34: 27000 | E34: 11955.72 | F34: 14446.494 | G34: 323.80074 | H34: 273.98524 | I34: =_xlfn.XLOOKUP($B34,MD!$A$3:$A$100,MD!$C$3:$C$100) -> B1 | J34: =_xlfn.XLOOKUP($B34,MD!$A$3:$A$100,MD!$D$3:$D$100) -> MN
B35: 160012297 | C35: Vảy PET B1_A3 MN | D35: 23200 | E35: 10273.063 | F35: 12413.284 | G35: 278.22878 | H35: 235.42435 | I35: =_xlfn.XLOOKUP($B35,MD!$A$3:$A$100,MD!$C$3:$C$100) -> B1 | J35: =_xlfn.XLOOKUP($B35,MD!$A$3:$A$100,MD!$D$3:$D$100) -> MN
... B47: 160012242 | C47: Vảy PET B4 Chưa Rửa 1 | D47: 500 | E47: 0 | F47: 500 | G47: 0 | H47: 0 | I47: =_xlfn.XLOOKUP($B47,MD!$A$3:$A$100,MD!$C$3:$C$100) -> B4 | J47: =_xlfn.XLOOKUP($B47,MD!$A$3:$A$100,MD!$D$3:$D$100) -> DTR
A48: 2025 | 02 Total | D48: 2625393 | E48: 1407200 | F48: 1067600 | G48: 139576.5 | H48: 11016.5
A49: 2025 | 03 | B49: 150000051 | C49: Vảy PET B1_A5.1 | D49: 1499112 | E49: 506000 | F49: 912500 | G49: 75806.9 | H49: 4805.1 | I49: =_xlfn.XLOOKUP($B49,MD!$A$3:$A$100,MD!$C$3:$C$100) -> B1 | J49: =_xlfn.XLOOKUP($B49,MD!$A$3:$A$100,MD!$D$3:$D$100) -> MN
B50: 160012689 | C50: Vảy PET B6.2_A3.2 | D50: 243000 | E50: 65000 | F50: 169000 | G50: 8410 | H50: 590 | I50: =_xlfn.XLOOKUP($B50,MD!$A$3:$A$100,MD!$C$3:$C$100) -> B6 | J50: =_xlfn.XLOOKUP($B50,MD!$A$3:$A$100,MD!$D$3:$D$100) -> DTR
B51: 160012368 | C51: Vảy PET B1 chưa rửa 2 | D51: 150584.77 | E51: 85191.829 | F51: 55589.899 | G51: 9241.9612 | H51: 561.08047 | I51: =_xlfn.XLOOKUP($B51,MD!$A$3:$A$100,MD!$C$3:$C$100) -> B1 | J51: =_xlfn.XLOOKUP($B51,MD!$A$3:$A$100,MD!$D$3:$D$100) -> DTR
B52: 160012906 | C52: Vảy PET B1.3 Chưa Rửa 2 | D52: 129000 | E52: 74500 | F52: 47500 | G52: 6435 | H52: 565 | I52: =_xlfn.XLOOKUP($B52,MD!$A$3:$A$100,MD!$C$3:$C$100) -> B1 | J52: =_xlfn.XLOOKUP($B52,MD!$A$3:$A$100,MD!$D$3:$D$100) -> DTR
B53: 160011727 | C53: Vảy PET B7.1 chưa rửa 1 | D53: 67500 | E53: 64100 | F53: 700 | G53: 2450 | H53: 250 | I53: =_xlfn.XLOOKUP($B53,MD!$A$3:$A$100,MD!$C$3:$C$100) -> B7 | J53: =_xlfn.XLOOKUP($B53,MD!$A$3:$A$100,MD!$D$3:$D$100) -> DTR
B54: 150000052 | C54: Vảy PET B1_A5.2_R2 | D54: 57278 | E54: 14500 | F54: 40500 | G54: 1700 | H54: 578 | I54: =_xlfn.XLOOKUP($B54,MD!$A$3:$A$100,MD!$C$3:$C$100) -> B1 | J54: =_xlfn.XLOOKUP($B54,MD!$A$3:$A$100,MD!$D$3:$D$100) -> MN
B55: 150000061 | C55: Vảy PET B6.2_A6 | D55: 29287 | E55: 22500 | F55: 2000 | G55: 4676 | H55: 111 | I55: =_xlfn.XLOOKUP($B55,MD!$A$3:$A$100,MD!$C$3:$C$100) -> B6 | J55: =_xlfn.XLOOKUP($B55,MD!$A$3:$A$100,MD!$D$3:$D$100) -> DTR
B56: 160012239 | C56: Vảy PET B1 chưa rửa 1 | D56: 26000 | E56: 16308.171 | F56: 7410.1011 | G56: 2105.0388 | H56: 176.68953 | I56: =_xlfn.XLOOKUP($B56,MD!$A$3:$A$100,MD!$C$3:$C$100) -> B1 | J56: =_xlfn.XLOOKUP($B56,MD!$A$3:$A$100,MD!$D$3:$D$100) -> DTR
...

Sheet MD
A2: Material-Xuất | B2: Material description-Xuất | C2: Loại chai/vảy | D2: Nguồn
A3: 150000051 | B3: Vảy PET B1_A5.1 | C3: B1 | D3: MN
A4: 150000052 | B4: Vảy PET B1_A5.2_R2 | C4: B1 | D4: MN
A5: 150000053 | B5: Vảy PET B1_A6 | C5: B1 | D5: MN
A6: 150000061 | B6: Vảy PET B6.2_A6 | C6: B6 | D6: DTR
A7: 150000079 | B7: Vảy PET B3_A5.2 | C7: B3 | D7: MN
A8: 150000171 | B8: Vảy PET B2.2_A6 | C8: B2 | D8: DTR
A9: 150000189 | B9: Vảy PET B1_A5.2_R1 | C9: B1 | D9: MN
A10: 160009895 | B10: Vảy PET B1_A1 DT | C10: B1 | D10: DTR
A11: 160011727 | B11: Vảy PET B7.1 chưa rửa 1 | C11: B7 | D11: DTR
A12: 160011761 | B12: Vảy PET B1_A1 MN | C12: B1 | D12: MN
A13: 160011808 | B13: Vảy PET B7_A1 | C13: B7 | D13: MN
... A59: 160012964 | B59: Vảy PET B1.2_A3 DT | C59: B1 | D59: DTR
