Workbook
Name Application: #REF!
Name DATA1: #REF!
Name DATA10: #REF!
Name DATA100: #REF!
Name DATA101: #REF!
Name DATA102: #REF!
Name DATA103: #REF!
Name DATA104: #REF!
Name DATA105: #REF!
Name DATA106: #REF!
Name DATA107: #REF!
Name DATA108: #REF!
Name DATA109: #REF!
Name DATA11: #REF!
Name DATA110: #REF!
Name DATA111: #REF!
Name DATA12: #REF!
Name DATA13: #REF!
Name DATA14: #REF!
Name DATA15: #REF!
Name DATA16: #REF!
Name DATA17: #REF!
Name DATA18: #REF!
Name DATA19: #REF!
Name DATA2: #REF!
Name DATA20: #REF!
Name DATA21: #REF!
Name DATA22: #REF!
Name DATA23: #REF!
Name DATA24: #REF!
Name DATA25: #REF!
Name DATA26: #REF!
Name DATA27: #REF!
Name DATA28: #REF!
Name DATA29: #REF!
Name DATA3: #REF!
Name DATA30: #REF!
Name DATA31: #REF!
Name DATA32: #REF!
Name DATA33: #REF!
Name DATA34: #REF!
Name DATA35: #REF!
Name DATA36: #REF!
Name DATA37: #REF!
Name DATA38: #REF!
Name DATA39: #REF!
Name DATA4: #REF!
Name DATA40: #REF!
Name DATA41: #REF!
Name DATA42: #REF!
Name DATA43: #REF!
Name DATA44: #REF!
Name DATA45: #REF!
Name DATA46: #REF!
Name DATA47: #REF!
Name DATA48: #REF!
Name DATA49: #REF!
Name DATA5: #REF!
Name DATA50: #REF!
Name DATA51: #REF!

Sheet Báo cáo
C1: ĐỊNH MỨC DẦU DO, BAO JUMBO QUAY ĐẦU TRÊN TẤN LUÂN CHUYỂN
B2: 1. THEO DÕI CHÊNH LỆCH
B3: STT | C3: Mã SAP | D3: Tên vật tư /Nội dung | E3: Định nghĩa / Công thức | F3: Đơn vị tính | G3: T01 | H3: T02 | I3: T03 | J3: T04 | K3: T05 | L3: T06 | M3: T07 | N3: T08 | O3: T09 | P3: T10 | Q3: T11 | R3: T12 | S3: LK 2025
B5: 1 | D5: Dầu DO | F5: Lít | G5: =G39-G22 -> 0.15443167 | H5: =H39-H22 -> 0.013492391 | I5: =I39-I22 -> 0.0076223485 | J5: =J39-J22 -> -0.0028406927 | K5: =K39-K22 -> -0.030281503 | L5: =L39-L22 -> -0.039573615 | M5: =M39-M22 -> -0.04663765 | N5: =N39-N22 -> -0.082818473 | ... Q5: =Q39-Q22 -> -0.06198854 | S5: =S39-S22 -> -0.011550279
B6: 1.2 | D6: PET | E6: Số lít dầu/ số tấn luân chuyển | F6: Lít | G6: =G40-G23 -> 0.22740279 | H6: =H40-H23 -> -0.0080853004 | I6: =I40-I23 -> -0.042995636 | J6: =J40-J23 -> -0.03214005 | K6: =K40-K23 -> -0.037485288 | L6: =L40-L23 -> -0.099503834 | M6: =M40-M23 -> -0.12914465 | N6: =N40-N23 -> -0.16293784 | ... Q6: =Q40-Q23 -> -0.15611754 | S6: =S40-S23 -> -0.058320448
B7: 1.3 | D7: HDPP | F7: Lít | G7: =G41-G24 -> -0.27999847 | H7: =H41-H24 -> -0.43640708 | I7: =I41-I24 -> -0.68714679 | J7: =J41-J24 -> -0.49417862 | K7: =K41-K24 -> -0.46807601 | L7: =L41-L24 -> -0.45769371 | M7: =M41-M24 -> -0.36044446 | N7: =N41-N24 -> -0.71740956 | ... Q7: =Q41-Q24 -> -0.50889417 | S7: =S41-S24 -> -0.481575
B8: 1.4 | D8: Kho | F8: Lít | G8: =G42-G25 -> 0.015517809 | H8: =H42-H25 -> -0.05305947 | I8: =I42-I25 -> -0.032612648 | J8: =J42-J25 -> -0.068257826 | K8: =K42-K25 -> -0.11690556 | L8: =L42-L25 -> -0.098740983 | M8: =M42-M25 -> -0.093102196 | N8: =N42-N25 -> -0.10444545 | ... Q8: =Q42-Q25 -> -0.09135147 | S8: =S42-S25 -> -0.067690678
B9: 2 | D9: Bao jumbo quay đầu | E9: Số bao/tấn luân chuyển | G9: =G43-G26 -> 0.053724297 | H9: =H43-H26 -> -0.0044342455 | I9: =I43-I26 -> -0.030514816 | J9: =J43-J26 -> -0.011230829 | K9: =K43-K26 -> -0.02988941 | L9: =L43-L26 -> -0.0052803177 | M9: =M43-M26 -> -0.032612388 | N9: =N43-N26 -> -0.0086385338 | ... Q9: =Q43-Q26 -> -0.017496232 | S9: =S43-S26 -> -0.012034192
B10: 2.1 | D10: PET
B11: 2.1.1 | C11: 140006089 | D11: Bao Jumbo nâu đai nâu (AW3) | E11: Số bao/tấn luân chuyển | G11: =IF(G45=0,0,G45-G28) -> 0.033725974 | H11: =IF(H45=0,0,H45-H28) -> 0 | I11: =IF(I45=0,0,I45-I28) -> 0 | J11: =IF(J45=0,0,J45-J28) -> 0 | K11: =IF(K45=0,0,K45-K28) -> -0.0030946776 | L11: =IF(L45=0,0,L45-L28) -> 0.065480696 | M11: =IF(M45=0,0,M45-M28) -> 0.010385673 | N11: =IF(N45=0,0,N45-N28) -> 0.027376541 | ... Q11: =IF(Q45=0,0,Q45-Q28) -> 0 | S11: =IF(S45=0,0,S45-S28) -> 0.0086492161
B12: 2.1.2 | C12: 140006075 | D12: Bao Jumbo nâu đai trắng (AW3) | E12: Số bao/tấn luân chuyển | G12: =IF(G46=0,0,G46-G29) -> 0 | H12: =IF(H46=0,0,H46-H29) -> 0 | I12: =IF(I46=0,0,I46-I29) -> 0 | J12: =IF(J46=0,0,J46-J29) -> 0 | K12: =IF(K46=0,0,K46-K29) -> -0.0036899438 | L12: =IF(L46=0,0,L46-L29) -> 0 | M12: =IF(M46=0,0,M46-M29) -> 0 | N12: =IF(N46=0,0,N46-N29) -> 0.02132275 | ... Q12: =IF(Q46=0,0,Q46-Q29) -> 0.048271664 | S12: =IF(S46=0,0,S46-S29) -> -0.0050518319
B13: 2.2 | D13: HDPP
B14: 2.2.1 | C14: 140006120 | D14: Bao jumbo cũ | E14: Số bao/tấn luân chuyển | G14: =IF(G48=0,0,G48-G31) -> 0 | H14: =IF(H48=0,0,H48-H31) -> -0.092949534 | I14: =IF(I48=0,0,I48-I31) -> 0 | J14: =IF(J48=0,0,J48-J31) -> 0.13520293 | K14: =IF(K48=0,0,K48-K31) -> -0.083258915 | L14: =IF(L48=0,0,L48-L31) -> -0.110297 | M14: =IF(M48=0,0,M48-M31) -> 0 | N14: =IF(N48=0,0,N48-N31) -> -0.0083723404 | ... Q14: =IF(Q48=0,0,Q48-Q31) -> 0 | S14: =IF(S48=0,0,S48-S31) -> -0.095967486
B15: 2.3 | D15: Kho
B16: 2.3.1 | C16: 140005072 | D16: Bao Jumbo 950x950x1300mm Đai Trắng rPET | G16: =IF(G50=0,0,G50-G33) -> 0.029374422 | H16: =IF(H50=0,0,H50-H33) -> 0.013920816 | I16: =IF(I50=0,0,I50-I33) -> -0.0070708473 | J16: =IF(J50=0,0,J50-J33) -> -0.00073250099 | K16: =IF(K50=0,0,K50-K33) -> -0.028868984 | L16: =IF(L50=0,0,L50-L33) -> -0.022663843 | M16: =IF(M50=0,0,M50-M33) -> -0.028322854 | N16: =IF(N50=0,0,N50-N33) -> -0.03382161 | ... Q16: =IF(Q50=0,0,Q50-Q33) -> -0.034176446 | S16: =IF(S50=0,0,S50-S33) -> -0.014086272
B17: 2.3.2 | C17: 140006120 | D17: Bao jumbo cũ | E17: Số bao/tấn luân chuyển | G17: =IF(G51=0,0,G51-G34) -> 0.015036055 | H17: =IF(H51=0,0,H51-H34) -> 0 | I17: =IF(I51=0,0,I51-I34) -> 0 | J17: =IF(J51=0,0,J51-J34) -> 0 | K17: =IF(K51=0,0,K51-K34) -> 0 | L17: =IF(L51=0,0,L51-L34) -> 0 | M17: =IF(M51=0,0,M51-M34) -> 0 | N17: =IF(N51=0,0,N51-N34) -> 0 | ... Q17: =IF(Q51=0,0,Q51-Q34) -> 0 | S17: =IF(S51=0,0,S51-S34) -> -0.015397435
B19: 2. ĐỊNH MỨC
B20: STT | C20: Mã SAP | D20: Tên vật tư /Nội dung | E20: Định nghĩa / Công thức | F20: Đơn vị tính | G20: T01 | H20: T02 | I20: T03 | J20: T04 | K20: T05 | L20: T06 | M20: T07 | N20: T08 | O20: T09 | P20: T10 | Q20: T11 | R20: T12 | S20: 2025
B22: 1 | D22: Dầu DO | F22: Lít | G22: 0.3 | H22: 0.3 | I22: 0.3 | J22: 0.3 | K22: 0.3 | L22: 0.3 | M22: 0.3 | N22: 0.3 | O22: 0.3 | P22: 0.3 | Q22: 0.3 | R22: 0.3 | S22: 0.3
B23: 1.2 | D23: PET | E23: Số lít dầu/ số tấn luân chuyển | F23: Lít | G23: 0.35 | H23: 0.35 | I23: 0.35 | J23: 0.35 | K23: 0.35 | L23: 0.35 | M23: 0.35 | N23: 0.35 | O23: 0.35 | P23: 0.35 | Q23: 0.35 | R23: 0.35 | S23: 0.35
B24: 1.3 | D24: HDPP | F24: Lít | G24: 1.4119914 | H24: 1.4119914 | I24: 1.4119914 | J24: 1.4119914 | K24: 1.4119914 | L24: 1.4119914 | M24: 1.4119914 | N24: 1.4119914 | O24: 1.4119914 | P24: 1.4119914 | Q24: 1.4119914 | R24: 1.4119914 | S24: 1.4119914
B25: 1.4 | D25: Kho | F25: Lít | G25: 0.3 | H25: 0.3 | I25: 0.3 | J25: 0.3 | K25: 0.3 | L25: 0.3 | M25: 0.3 | N25: 0.3 | O25: 0.3 | P25: 0.3 | Q25: 0.3 | R25: 0.3 | S25: 0.3
B26: 2 | D26: Bao jumbo quay đầu | E26: Số bao/tấn luân chuyển | G26: 0.05 | H26: 0.05 | I26: 0.05 | J26: 0.05 | K26: 0.05 | L26: 0.05 | M26: 0.05 | N26: 0.05 | O26: 0.05 | P26: 0.05 | Q26: 0.05 | R26: 0.05 | S26: 0.05
B27: 2.1 | D27: PET
B28: 2.1.1 | C28: 140006089 | D28: Bao Jumbo nâu đai nâu (AW3) | E28: Số bao/tấn luân chuyển | G28: 0.015 | H28: 0.015 | I28: 0.015 | J28: 0.015 | K28: 0.015 | L28: 0.015 | M28: 0.015 | N28: 0.015 | O28: 0.015 | P28: 0.015 | Q28: 0.015 | R28: 0.015 | S28: 0.015
B29: 2.1.2 | C29: 140006075 | D29: Bao Jumbo nâu đai trắng (AW3) | E29: Số bao/tấn luân chuyển | G29: 0.015 | H29: 0.015 | I29: 0.015 | J29: 0.015 | K29: 0.015 | L29: 0.015 | M29: 0.015 | N29: 0.015 | O29: 0.015 | P29: 0.015 | Q29: 0.015 | R29: 0.015 | S29: 0.015
B30: 2.2 | D30: HDPP
B31: 2.2.1 | C31: 140006120 | D31: Bao jumbo cũ | E31: Số bao/tấn luân chuyển | G31: 0.16 | H31: 0.16 | I31: 0.16 | J31: 0.16 | K31: 0.16 | L31: 0.16 | M31: 0.16 | N31: 0.16 | O31: 0.16 | P31: 0.16 | Q31: 0.16 | R31: 0.16 | S31: 0.16
B32: 2.3 | D32: Kho
B33: 2.3.1 | C33: 140005072 | D33: Bao Jumbo 950x950x1300mm Đai Trắng rPET | G33: 0.041628179 | H33: 0.041628179 | I33: 0.041628179 | J33: 0.041628179 | K33: 0.041628179 | L33: 0.041628179 | M33: 0.041628179 | N33: 0.041628179 | O33: 0.041628179 | P33: 0.041628179 | Q33: 0.041628179 | R33: 0.041628179 | S33: 0.041628179
B34: 2.3.2 | C34: 140006120 | D34: Bao jumbo cũ | E34: Số bao/tấn luân chuyển | G34: 0.018778934 | H34: 0.018778934 | I34: 0.018778934 | J34: 0.018778934 | K34: 0.018778934 | L34: 0.018778934 | M34: 0.018778934 | N34: 0.018778934 | O34: 0.018778934 | P34: 0.018778934 | Q34: 0.018778934 | R34: 0.018778934 | S34: 0.018778934
B36: 3. THỰC TẾ
B37: STT | C37: Mã SAP | D37: Tên vật tư /Nội dung | E37: Định nghĩa / Công thức | F37: Đơn vị tính | G37: T01 | H37: T02 | I37: T03 | J37: T04 | K37: T05 | L37: T06 | M37: T07 | N37: T08 | O37: T09 | P37: T10 | Q37: T11 | R37: T12 | S37: LK
B39: 1 | D39: Dầu DO | F39: Lít | G39: ='03. Chi tiết thực tế sử dụng'!F41 -> 0.45443167 | H39: ='03. Chi tiết thực tế sử dụng'!G41 -> 0.31349239 | I39: ='03. Chi tiết thực tế sử dụng'!H41 -> 0.30762235 | J39: ='03. Chi tiết thực tế sử dụng'!I41 -> 0.29715931 | K39: ='03. Chi tiết thực tế sử dụng'!J41 -> 0.2697185 | L39: ='03. Chi tiết thực tế sử dụng'!K41 -> 0.26042638 | M39: ='03. Chi tiết thực tế sử dụng'!L41 -> 0.25336235 | N39: ='03. Chi tiết thực tế sử dụng'!M41 -> 0.21718153 | ... Q39: ='03. Chi tiết thực tế sử dụng'!P41 -> 0.23801146 | S39: =AVERAGE(G39:P39) -> 0.28844972
B40: 1.2 | D40: PET | E40: Số lít dầu/ số tấn luân chuyển | F40: Lít | G40: ='03. Chi tiết thực tế sử dụng'!F38 -> 0.57740279 | H40: ='03. Chi tiết thực tế sử dụng'!G38 -> 0.3419147 | I40: ='03. Chi tiết thực tế sử dụng'!H38 -> 0.30700436 | J40: ='03. Chi tiết thực tế sử dụng'!I38 -> 0.31785995 | K40: ='03. Chi tiết thực tế sử dụng'!J38 -> 0.31251471 | L40: ='03. Chi tiết thực tế sử dụng'!K38 -> 0.25049617 | M40: ='03. Chi tiết thực tế sử dụng'!L38 -> 0.22085535 | N40: ='03. Chi tiết thực tế sử dụng'!M38 -> 0.18706216 | ... Q40: ='03. Chi tiết thực tế sử dụng'!P38 -> 0.19388246 | S40: =AVERAGE(G40:P40) -> 0.29167955
B41: 1.3 | D41: HDPP | F41: Lít | G41: ='03. Chi tiết thực tế sử dụng'!F39 -> 1.1319929 | H41: ='03. Chi tiết thực tế sử dụng'!G39 -> 0.97558428 | I41: ='03. Chi tiết thực tế sử dụng'!H39 -> 0.72484457 | J41: ='03. Chi tiết thực tế sử dụng'!I39 -> 0.91781274 | K41: ='03. Chi tiết thực tế sử dụng'!J39 -> 0.94391534 | L41: ='03. Chi tiết thực tế sử dụng'!K39 -> 0.95429764 | M41: ='03. Chi tiết thực tế sử dụng'!L39 -> 1.0515469 | N41: ='03. Chi tiết thực tế sử dụng'!M39 -> 0.69458179 | ... Q41: ='03. Chi tiết thực tế sử dụng'!P39 -> 0.90309719 | S41: =AVERAGE(G41:P41) -> 0.93041636
B42: 1.4 | D42: Kho | F42: Lít | G42: ='03. Chi tiết thực tế sử dụng'!F40 -> 0.31551781 | H42: ='03. Chi tiết thực tế sử dụng'!G40 -> 0.24694053 | I42: ='03. Chi tiết thực tế sử dụng'!H40 -> 0.26738735 | J42: ='03. Chi tiết thực tế sử dụng'!I40 -> 0.23174217 | K42: ='03. Chi tiết thực tế sử dụng'!J40 -> 0.18309444 | L42: ='03. Chi tiết thực tế sử dụng'!K40 -> 0.20125902 | M42: ='03. Chi tiết thực tế sử dụng'!L40 -> 0.2068978 | N42: ='03. Chi tiết thực tế sử dụng'!M40 -> 0.19555455 | ... Q42: ='03. Chi tiết thực tế sử dụng'!P40 -> 0.20864853 | S42: =AVERAGE(G42:P42) -> 0.23230932
B43: 2 | D43: Bao jumbo quay đầu | E43: Số bao/tấn luân chuyển | G43: ='03. Chi tiết thực tế sử dụng'!F21 -> 0.1037243 | H43: ='03. Chi tiết thực tế sử dụng'!G21 -> 0.045565755 | I43: ='03. Chi tiết thực tế sử dụng'!H21 -> 0.019485184 | J43: ='03. Chi tiết thực tế sử dụng'!I21 -> 0.038769171 | K43: ='03. Chi tiết thực tế sử dụng'!J21 -> 0.02011059 | L43: ='03. Chi tiết thực tế sử dụng'!K21 -> 0.044719682 | M43: ='03. Chi tiết thực tế sử dụng'!L21 -> 0.017387612 | N43: ='03. Chi tiết thực tế sử dụng'!M21 -> 0.041361466 | ... Q43: ='03. Chi tiết thực tế sử dụng'!P21 -> 0.032503768 | S43: =AVERAGE(G43:P43) -> 0.037965808
B44: 2.1 | D44: PET
B45: 2.1.1 | C45: 140006089 | D45: Bao Jumbo nâu đai nâu (AW3) | E45: Số bao/tấn luân chuyển | G45: ='03. Chi tiết thực tế sử dụng'!F3/'03. Chi tiết thực tế sử dụng'!F7 -> 0.048725974 | H45: ='03. Chi tiết thực tế sử dụng'!G3/'03. Chi tiết thực tế sử dụng'!G7 -> 0 | I45: ='03. Chi tiết thực tế sử dụng'!H3/'03. Chi tiết thực tế sử dụng'!H7 -> 0 | J45: ='03. Chi tiết thực tế sử dụng'!I3/'03. Chi tiết thực tế sử dụng'!I7 -> 0 | K45: ='03. Chi tiết thực tế sử dụng'!J3/'03. Chi tiết thực tế sử dụng'!J7 -> 0.011905322 | L45: ='03. Chi tiết thực tế sử dụng'!K3/'03. Chi tiết thực tế sử dụng'!K7 -> 0.080480696 | M45: ='03. Chi tiết thực tế sử dụng'!L3/'03. Chi tiết thực tế sử dụng'!L7 -> 0.025385673 | N45: ='03. Chi tiết thực tế sử dụng'!M3/'03. Chi tiết thực tế sử dụng'!M7 -> 0.042376541 | ... Q45: ='03. Chi tiết thực tế sử dụng'!P3/'03. Chi tiết thực tế sử dụng'!P7 -> 0 | S45: =AVERAGE(G45:P45) -> 0.023649216
...

Sheet 01. MB51 - Data xuất 943
A1: Material | B1: Material Description | C1: Storage Location | D1: Movement Type | E1: Material Document | F1: Material Doc.Item | G1: Order | H1: Qty in Un. of Entry | I1: Unit of Entry | J1: Quantity | K1: Base Unit of Measure | L1: User name | M1: Reference | N1: Time of Entry | O1: Document Header Text | P1: Posting Date | Q1: Entry Date | R1: Batch | S1: Amount in LC | T1: Reservation | U1: Nhóm | V1: Tháng
A2: 140005072 | B2: Bao Jumbo 950x950x1300mm Đai Trắng rPET | C2: 1102 | D2: 943 | E2: 4907797725 | F2: 2 | H2: -100 | I2: EA | J2: -100 | K2: EA | L2: HONG.NTT | N2: 0.61025463 | O2: Kho Thành phẩm | P2: 45656 | Q2: 45656 | S2: -16501126 | T2: 1008673071 | U2: Kho | V2: =+MONTH(P2) -> 12
A3: 140006128 | B3: Bao Jumbo nâu đai dương nhạt (HD BLOW) | C3: 1102 | D3: 943 | E3: 4907796467 | F3: 1 | H3: -10 | I3: EA | J3: -10 | K3: EA | L3: HONG.NTT | N3: 0.35237269 | O3: Xuất hàng sản xuất HD | P3: 45654 | Q3: 45654 | S3: -1560000 | T3: 1008672880 | U3: HD | V3: =+MONTH(P3) -> 12
A4: 140005072 | B4: Bao Jumbo 950x950x1300mm Đai Trắng rPET | C4: 1102 | D4: 943 | E4: 4907792607 | F4: 1 | H4: -100 | I4: EA | J4: -100 | K4: EA | L4: HONG.NTT | N4: 0.57741898 | O4: Kho Thành phẩm | P4: 45649 | Q4: 45649 | S4: -16501420 | T4: 1008672522 | U4: Kho | V4: =+MONTH(P4) -> 12
A5: 140005072 | B5: Bao Jumbo 950x950x1300mm Đai Trắng rPET | C5: 1102 | D5: 943 | E5: 4907792603 | F5: 1 | H5: -100 | I5: EA | J5: -100 | K5: EA | L5: HONG.NTT | N5: 0.57671296 | O5: Kho Thành phẩm | P5: 45649 | Q5: 45649 | S5: -16501420 | T5: 1008672521 | U5: Kho | V5: =+MONTH(P5) -> 12
A6: 140005935 | B6: Bao jumbo 950x950x1300 AW2 | C6: 1102 | D6: 943 | E6: 4907791879 | F6: 1 | H6: -100 | I6: EA | J6: -100 | K6: EA | L6: HONG.NTT | N6: 0.40621528 | O6: xuất xưởng sản xuất HD | P6: 45647 | Q6: 45647 | S6: -18200000 | T6: 1008672474 | U6: HD | V6: =+MONTH(P6) -> 12
A7: 140006089 | B7: Bao Jumbo nâu đai nâu (AW3) | C7: 1102 | D7: 943 | E7: 4907791202 | F7: 1 | H7: -58 | I7: EA | J7: -58 | K7: EA | L7: HONG.NTT | N7: 0.53247685 | O7: xuất xưởng sản xuất PET | P7: 45645 | Q7: 45645 | S7: -8827260 | T7: 1008672145 | U7: PET | V7: =+MONTH(P7) -> 12
A8: 140005072 | B8: Bao Jumbo 950x950x1300mm Đai Trắng rPET | C8: 1102 | D8: 943 | E8: 4907790907 | F8: 1 | H8: -100 | I8: EA | J8: -100 | K8: EA | L8: HONG.NTT | N8: 0.36523148 | O8: Xuất kho vận | P8: 45644 | Q8: 45644 | S8: -16502390 | T8: 1008672301 | U8: Kho | V8: =+MONTH(P8) -> 12
A9: 140005072 | B9: Bao Jumbo 950x950x1300mm Đai Trắng rPET | C9: 1102 | D9: 943 | E9: 4907785674 | F9: 1 | H9: -100 | I9: EA | J9: -100 | K9: EA | L9: HONG.NTT | N9: 0.6558912 | O9: Kho Thành phẩm | P9: 45637 | Q9: 45637 | S9: -16502390 | T9: 1008671458 | U9: Kho | V9: =+MONTH(P9) -> 12
A10: 140005072 | B10: Bao Jumbo 950x950x1300mm Đai Trắng rPET | C10: 1102 | D10: 943 | E10: 4907785663 | F10: 1 | H10: -100 | I10: EA | J10: -100 | K10: EA | L10: HONG.NTT | N10: 0.65167824 | O10: Kho Thành phẩm | P10: 45637 | Q10: 45637 | S10: -16502390 | T10: 1008671908 | U10: Kho | V10: =+MONTH(P10) -> 12
A11: 140006120 | B11: Bao jumbo cũ | C11: 1102 | D11: 943 | E11: 4907785660 | F11: 1 | H11: -1649 | I11: EA | J11: -1649 | K11: EA | L11: HONG.NTT | N11: 0.65061343 | O11: Kho Vận | P11: 45637 | Q11: 45637 | S11: -92790773 | T11: 1008671456 | U11: Kho | V11: =+MONTH(P11) -> 12
A12: 140006089 | B12: Bao Jumbo nâu đai nâu (AW3) | C12: 1102 | D12: 943 | E12: 4907785513 | F12: 1 | H12: -300 | I12: EA | J12: -300 | K12: EA | L12: HONG.NTT | N12: 0.56149306 | O12: xuất xưởng sản xuất PET | P12: 45637 | Q12: 45637 | S12: -45658239 | T12: 1008671679 | U12: PET | V12: =+MONTH(P12) -> 12
A13: 140006089 | B13: Bao Jumbo nâu đai nâu (AW3) | C13: 1102 | D13: 943 | E13: 4907785344 | F13: 1 | H13: -300 | I13: EA | J13: -300 | K13: EA | L13: HONG.NTT | N13: 0.37203704 | O13: xuất xưởng sản xuất PET | P13: 45637 | Q13: 45637 | S13: -45658240 | T13: 1008671579 | U13: PET | V13: =+MONTH(P13) -> 12
... A109: 140006089 | B109: Bao Jumbo nâu đai nâu (AW3) | C109: 1102 | D109: 943 | E109: 4907987021 | F109: 1 | H109: -100 | I109: EA | J109: -100 | K109: EA | L109: NGOAN.DT | N109: 0.38427083 | O109: xuất sx PET | P109: 45959 | Q109: 45959 | S109: -15000000 | T109: 1008692517 | U109: PET | V109: =+MONTH(P109) -> 10
A110: 140006125 | B110: Bao Jumbo 950x950x1300mm Đai Xanh Xơ Sợi | C110: 1203 | D110: 943 | E110: 4907988746 | F110: 1 | H110: -13 | I110: EA | J110: -13 | K110: EA | L110: VY.HNT | M110: PET 31/10 | N110: 0.71846065 | O110: XƯỞNG XUẤT CHI PHÍ | P110: 45961 | Q110: 45961 | S110: -2157886 | T110: 1008692636 | U110: PET | V110: =+MONTH(P110) -> 10
A111: 140006125 | B111: Bao Jumbo 950x950x1300mm Đai Xanh Xơ Sợi | C111: 1102 | D111: 943 | E111: 4907971954 | F111: 2 | H111: -20 | I111: EA | J111: -20 | K111: EA | L111: NGOAN.DT | N111: 0.55965278 | O111: xuất kho TP1 | P111: 45937 | Q111: 45937 | S111: -3319825 | T111: 1008691150 | U111: Kho | V111: =+MONTH(P111) -> 10
A112: 140006129 | B112: Bao Jumbo nâu đai dương đậm (HD INJ)) | C112: 1102 | D112: 943 | E112: 4907983845 | F112: 1 | H112: -10 | I112: EA | J112: -10 | K112: EA | L112: NGOAN.DT | N112: 0.69677083 | O112: xuất kho TP1 | P112: 45953 | Q112: 45953 | S112: -1500021 | T112: 1008692238 | U112: Kho | V112: =+MONTH(P112) -> 10
A113: 140006154 | B113: Bao Jumbo 1050x1050x1300mm Đai Trắng PET | C113: 1102 | D113: 943 | E113: 4907982882 | F113: 1 | H113: -100 | I113: EA | J113: -100 | K113: EA | L113: NGOAN.DT | N113: 0.55332176 | O113: xuất sx PET | P113: 45952 | Q113: 45952 | S113: -17200000 | T113: 1008692152 | U113: PET | V113: =+MONTH(P113) -> 10
A114: 140005072 | B114: Bao Jumbo 950x950x1300mm Đai Trắng rPET | C114: 1102 | D114: 943 | E114: 4908000828 | F114: 1 | H114: -100 | I114: EA | J114: -100 | K114: EA | L114: NGOAN.DT | N114: 0.68569444 | O114: xuất TP1 | P114: 45982 | Q114: 45982 | S114: -16500113 | T114: 1008694045 | U114: Kho | V114: =+MONTH(P114) -> 11
A115: 140005072 | B115: Bao Jumbo 950x950x1300mm Đai Trắng rPET | C115: 1102 | D115: 943 | E115: 4907998810 | F115: 1 | H115: -20 | I115: EA | J115: -20 | K115: EA | L115: THAO.TTT | N115: 0.57320602 | O115: xuất TP1 | P115: 45979 | Q115: 45979 | S115: -3300019 | T115: 1008693665 | U115: Kho | V115: =+MONTH(P115) -> 11
A116: 140006075 | B116: Bao Jumbo nâu đai trắng (AW3) | C116: 1102 | D116: 943 | E116: 4908004297 | F116: 1 | H116: -200 | I116: EA | J116: -200 | K116: EA | L116: THAO.TTT | N116: 0.41635417 | O116: xuất xưởng pet | P116: 45988 | Q116: 45988 | S116: -30320000 | T116: 1008694422 | U116: PET | V116: =+MONTH(P116) -> 11
A117: 140006075 | B117: Bao Jumbo nâu đai trắng (AW3) | C117: 1102 | D117: 943 | E117: 4907998664 | F117: 1 | H117: -200 | I117: EA | J117: -200 | K117: EA | L117: NGOAN.DT | N117: 0.50204861 | O117: xuất sx PET | P117: 45979 | Q117: 45979 | S117: -30000000 | T117: 1008693770 | U117: PET | V117: =+MONTH(P117) -> 11
A118: 140006075 | B118: Bao Jumbo nâu đai trắng (AW3) | C118: 1102 | D118: 943 | E118: 4907996179 | F118: 1 | H118: -100 | I118: EA | J118: -100 | K118: EA | L118: NGOAN.DT | N118: 0.47446759 | O118: xuất sx PET | P118: 45974 | Q118: 45974 | S118: -15000000 | T118: 1008693510 | U118: PET | V118: =+MONTH(P118) -> 11
A119: 140006075 | B119: Bao Jumbo nâu đai trắng (AW3) | C119: 1102 | D119: 943 | E119: 4907993149 | F119: 1 | H119: -200 | I119: EA | J119: -200 | K119: EA | L119: NGOAN.DT | N119: 0.60346065 | O119: xuất sx PET | P119: 45969 | Q119: 45969 | S119: -30000000 | T119: 1008693228 | U119: PET | V119: =+MONTH(P119) -> 11
A120: 140006125 | B120: Bao Jumbo 950x950x1300mm Đai Xanh Xơ Sợi | C120: 1102 | D120: 943 | E120: 4907995435 | F120: 1 | H120: -100 | I120: EA | J120: -100 | K120: EA | L120: NGOAN.DT | N120: 0.36938657 | O120: xuất TP1 | P120: 45973 | Q120: 45973 | S120: -16545106 | T120: 1008693440 | U120: Kho | V120: =+MONTH(P120) -> 11
A121: 140006129 | B121: Bao Jumbo nâu đai dương đậm (HD INJ)) | C121: 1102 | D121: 943 | E121: 4907991040 | F121: 1 | H121: -10 | I121: EA | J121: -10 | K121: EA | L121: NGOAN.DT | N121: 0.408125 | O121: xuất TP1 | P121: 45966 | Q121: 45966 | S121: -1500021 | T121: 1008692921 | U121: Kho | V121: =+MONTH(P121) -> 11

Sheet 02. Số tấn luân chuyển
A3: Phân loại | B3: Đầu mã | C3: Mvt | D3: Loại giao dịch | E3: Bộ phận | G3: Hệ số | H3: 12 | I3: 1 | J3: 2 | K3: 3 | L3: 4 | M3: 5 | N3: 6 | O3: 7 | P3: 8 | Q3: 9 | R3: 10 | S3: 11 | U3: Nhóm | V3: 12 | W3: 1 | X3: 2 | Y3: 3 | Z3: 4 | AA3: 5 | AB3: 6 | AC3: 7 | AD3: 8 | AE3: 9 | AF3: 10 | AG3: 11
A4: Nguyên liệu | B4: 15 | C4: 101.102 | D4: Nhập Nguyên liệu | E4: Kho | F4: KHO | G4: 1 | H4: 3961871 | I4: 1738459 | J4: 2445384 | K4: 4442551 | L4: 6862672 | M4: 5306774 | N4: 4838797 | O4: 4960857.4 | P4: 6387095.8 | Q4: 3951380.8 | R4: 3368534.8 | S4: 3304076.6 | U4: PET | V4: =H24 -> 14174800 | W4: =I24 -> 6156880.5 | X4: =J24 -> 11625707 | Y4: =K24 -> 15651243 | Z4: =L24 -> 13685272 | AA4: =M24 -> 16799209 | AB4: =N24 -> 14910408 | AC4: =O24 -> 15756919 | ... AG4: =S24 -> 11063404
A5: Nguyên liệu | B5: 15 | C5: 261.262 | D5: Xuất nguyên liệu sản xuất | E5: PET | F5: KHO | G5: -1 | U5: HDPP | V5: =H25 -> 1673086.2 | W5: =I25 -> 1192587 | X5: =J25 -> 1491413.9 | Y5: =K25 -> 2255656 | Z5: =L25 -> 1863125.2 | AA5: =M25 -> 1954624.4 | AB5: =N25 -> 2011950.9 | AC5: =O25 -> 1954263.8 | ... AG5: =S25 -> 1445027.2
A6: Nguyên liệu | B6: 15 | C6: 261.262 | D6: Xuất nguyên liệu sản xuất | E6: HDPP | F6: KHO | G6: -1 | U6: KHO | V6: =H26 -> 19677153 | W6: =I26 -> 11267193 | X6: =J26 -> 19802339 | Y6: =K26 -> 23149936 | Z6: =L26 -> 22007216 | AA6: =M26 -> 23512456 | AB6: =N26 -> 21092223 | AC6: =O26 -> 22547364 | ... AG6: =S26 -> 16103636
A7: BTP | B7: 16 | C7: 101,102,531,532 | D7: Xưởng chuyển BTP về kho | E7: PET | F7: PET | G7: 1 | H7: 7313025.1 | I7: 3451861 | J7: 5540608 | K7: 7116802.9 | L7: 6506893 | M7: 8285717 | N7: 7250086 | O7: 6837084.8 | P7: 7557124 | Q7: 8094452.5 | R7: 8500015.4 | S7: 6629314.3 | U7: Tổng cộng | V7: =SUM(V4:V6) -> 35525040 | W7: =SUM(W4:W6) -> 18616660 | X7: =SUM(X4:X6) -> 32919459 | Y7: =SUM(Y4:Y6) -> 41056835 | Z7: =SUM(Z4:Z6) -> 37555613 | AA7: =SUM(AA4:AA6) -> 42266289 | AB7: =SUM(AB4:AB6) -> 38014581 | AC7: =SUM(AC4:AC6) -> 40258547 | ... AG7: =SUM(AG4:AG6) -> 28612068
A8: BTP | B8: 16 | C8: 101,102,531,532 | D8: Xưởng chuyển BTP về kho | E8: HDPP | F8: HDPP | G8: 1 | H8: 1126765.6 | I8: 798579.5 | J8: 914429.95 | K8: 1204215 | L8: 1136962.7 | M8: 1101884.4 | N8: 1197722.9 | O8: 1182805.1 | P8: 1218321.3 | Q8: 844641.12 | R8: 1078550 | S8: 943586.4
A9: BTP | B9: 16 | C9: 101.102 | D9: Nhập nguyên liệu BTP | E9: Kho | F9: KHO | G9: 1 | H9: 475725 | I9: 287311 | J9: 238920 | K9: 217196 | L9: 162300 | M9: 0 | N9: 14351 | O9: 0 | P9: 3140 | Q9: 1210 | R9: 995 | S9: 919.8 | U9: Nhóm | V9: 12 | W9: 1 | X9: 2 | Y9: 3 | Z9: 4 | AA9: 5 | AB9: 6 | AC9: 7 | AD9: 8 | AE9: 9 | AF9: 10 | AG9: 11
A10: BTP | B10: 16 | C10: 261.262 | D10: Kho chuyển BTP qua xưởng | E10: Kho | F10: KHO | G10: -1 | H10: 7873229.6 | I10: 4396854 | J10: 7533476 | K10: 8873026.3 | L10: 6912984.2 | M10: 8721019.8 | N10: 7845229.6 | O10: 7688039.2 | P10: 7870430.3 | Q10: 8935181.1 | R10: 8445398.7 | S10: 6995720.6 | U10: PET | V10: =+V4/10^3 -> 14174.8 | W10: =+W4/10^3 -> 6156.8805 | X10: =+X4/10^3 -> 11625.707 | Y10: =+Y4/10^3 -> 15651.243 | Z10: =+Z4/10^3 -> 13685.272 | AA10: =+AA4/10^3 -> 16799.209 | AB10: =+AB4/10^3 -> 14910.408 | AC10: =+AC4/10^3 -> 15756.919 | ... AG10: =+AG4/10^3 -> 11063.404
A11: BTP | B11: 16 | C11: 601.602 | D11: Kho xuất BTP | E11: Kho | F11: KHO | G11: -1 | H11: 299294 | I11: 34891 | J11: 23538 | K11: 179048 | L11: 86842 | M11: 120276 | N11: 123284 | O11: 73361 | P11: 387520 | Q11: 206785 | R11: 37569 | S11: 371113 | U11: HDPP | V11: =+V5/10^3 -> 1673.0862 | W11: =+W5/10^3 -> 1192.587 | X11: =+X5/10^3 -> 1491.4139 | Y11: =+Y5/10^3 -> 2255.656 | Z11: =+Z5/10^3 -> 1863.1252 | AA11: =+AA5/10^3 -> 1954.6244 | AB11: =+AB5/10^3 -> 2011.9509 | AC11: =+AC5/10^3 -> 1954.2638 | ... AG11: =+AG5/10^3 -> 1445.0272
A12: TP | B12: 11 | C12: 101,102,531,532 | D12: Xưởng chuyển về kho | E12: PET | F12: PET | G12: 1 | H12: 4887073 | I12: 1920685 | J12: 4950465 | K12: 6467167.6 | L12: 4690966 | M12: 5934361 | N12: 5328528 | O12: 6569633.5 | P12: 6296998.2 | Q12: 5348960 | R12: 3838712 | S12: 2833808 | U12: KHO | V12: =+V6/10^3 -> 19677.153 | W12: =+W6/10^3 -> 11267.193 | X12: =+X6/10^3 -> 19802.339 | Y12: =+Y6/10^3 -> 23149.936 | Z12: =+Z6/10^3 -> 22007.216 | AA12: =+AA6/10^3 -> 23512.456 | AB12: =+AB6/10^3 -> 21092.223 | AC12: =+AC6/10^3 -> 22547.364 | ... AG12: =+AG6/10^3 -> 16103.636
A13: TP | B13: 11 | C13: 101,102,531,532 | D13: Xưởng chuyển về kho | E13: HDPP | F13: HDPP | G13: 1 | H13: 515147.1 | I13: 361774 | J13: 517231.5 | K13: 994141 | L13: 678408.5 | M13: 792002 | N13: 575008 | O13: 712155 | P13: 818281 | Q13: 818860 | R13: 553122 | S13: 479302 | U13: Tổng cộng | V13: =SUM(V10:V12) -> 35525.04 | W13: =SUM(W10:W12) -> 18616.66 | X13: =SUM(X10:X12) -> 32919.459 | Y13: =SUM(Y10:Y12) -> 41056.835 | Z13: =SUM(Z10:Z12) -> 37555.613 | AA13: =SUM(AA10:AA12) -> 42266.289 | AB13: =SUM(AB10:AB12) -> 38014.581 | AC13: =SUM(AC10:AC12) -> 40258.547 | ... AG13: =SUM(AG10:AG12) -> 28612.068
A14: TP | B14: 11 | C14: 261.262 | D14: Kho chuyển qua xưởng | E14: Kho | F14: KHO | G14: -1 | H14: 1977050.2 | I14: 491209.8 | J14: 2493749.5 | K14: 2725816.5 | L14: 1389994.1 | M14: 2020752.8 | N14: 1747733.1 | O14: 2795746.3 | P14: 2634111.2 | Q14: 1663506.3 | R14: 1312086.9 | S14: 1054270.2
A15: TP | B15: 11 | C15: 601.602 | D15: Kho xuất bán hàng | E15: Kho | F15: KHO | G15: -1 | H15: 3084108 | I15: 3501900 | J15: 5872885 | K15: 4587725 | L15: 4057255.9 | M15: 4703764 | N15: 3951814.2 | O15: 4619855 | P15: 5506540 | Q15: 3062278 | R15: 3399720 | S15: 2755115
H16: =SUM(H4:H15,H17:H18) -> 35525040 | I16: =SUM(I4:I15,I17:I18) -> 18616660 | J16: =SUM(J4:J15,J17:J18) -> 32919459 | K16: =SUM(K4:K15,K17:K18) -> 41056835 | L16: =SUM(L4:L15,L17:L18) -> 37555613 | M16: =SUM(M4:M15,M17:M18) -> 42266289 | N16: =SUM(N4:N15,N17:N18) -> 38014581 | O16: =SUM(O4:O15,O17:O18) -> 40258547 | ... S16: =SUM(S4:S15,S17:S18) -> 28612068
H17: 3949404.1 | I17: 1568669 | J17: 2269267.3 | K17: 4134545.7 | L17: 4974826.8 | M17: 5158262.2 | N17: 4663587.7 | O17: 4700402 | P17: 5328902 | Q17: 4659001 | R17: 4289208.6 | S17: 3200564.1
H18: 62347 | I18: 64467 | J18: 119505 | K18: 114600 | L18: 95508 | M18: 121476 | N18: 478440 | O18: 118607.4 | P18: 332324 | Q18: 48036.8 | R18: 87268.8 | S18: 44277.6
F19: PET | H19: =+H17/2 -> 1974702 | I19: =+I17/2 -> 784334.51 | J19: =+J17/2 -> 1134633.7 | K19: =+K17/2 -> 2067272.8 | L19: =+L17/2 -> 2487413.4 | M19: =+M17/2 -> 2579131.1 | N19: =+N17/2 -> 2331793.8 | O19: =+O17/2 -> 2350201 | ... S19: =+S17/2 -> 1600282
F20: HDPP | H20: =+H18/2 -> 31173.5 | I20: =+I18/2 -> 32233.5 | J20: =+J18/2 -> 59752.5 | K20: =+K18/2 -> 57300 | L20: =+L18/2 -> 47754 | M20: =+M18/2 -> 60738 | N20: =+N18/2 -> 239220 | O20: =+O18/2 -> 59303.7 | ... S20: =+S18/2 -> 22138.8
F21: KHO | H21: =+H19 -> 1974702 | I21: =+I19 -> 784334.51 | J21: =+J19 -> 1134633.7 | K21: =+K19 -> 2067272.8 | L21: =+L19 -> 2487413.4 | M21: =+M19 -> 2579131.1 | N21: =+N19 -> 2331793.8 | O21: =+O19 -> 2350201 | ... S21: =+S19 -> 1600282
F22: KHO | H22: =+H20 -> 31173.5 | I22: =+I20 -> 32233.5 | J22: =+J20 -> 59752.5 | K22: =+K20 -> 57300 | L22: =+L20 -> 47754 | M22: =+M20 -> 60738 | N22: =+N20 -> 239220 | O22: =+O20 -> 59303.7 | ... S22: =+S20 -> 22138.8
F24: PET | H24: =+SUMIFS(H$4:H$22,$F$4:$F$22,$F24) -> 14174800 | I24: =+SUMIFS(I$4:I$22,$F$4:$F$22,$F24) -> 6156880.5 | J24: =+SUMIFS(J$4:J$22,$F$4:$F$22,$F24) -> 11625707 | K24: =+SUMIFS(K$4:K$22,$F$4:$F$22,$F24) -> 15651243 | L24: =+SUMIFS(L$4:L$22,$F$4:$F$22,$F24) -> 13685272 | M24: =+SUMIFS(M$4:M$22,$F$4:$F$22,$F24) -> 16799209 | N24: =+SUMIFS(N$4:N$22,$F$4:$F$22,$F24) -> 14910408 | O24: =+SUMIFS(O$4:O$22,$F$4:$F$22,$F24) -> 15756919 | ... S24: =+SUMIFS(S$4:S$22,$F$4:$F$22,$F24) -> 11063404
F25: HDPP | H25: =+SUMIFS(H$4:H$22,$F$4:$F$22,$F25) -> 1673086.2 | I25: =+SUMIFS(I$4:I$22,$F$4:$F$22,$F25) -> 1192587 | J25: =+SUMIFS(J$4:J$22,$F$4:$F$22,$F25) -> 1491413.9 | K25: =+SUMIFS(K$4:K$22,$F$4:$F$22,$F25) -> 2255656 | L25: =+SUMIFS(L$4:L$22,$F$4:$F$22,$F25) -> 1863125.2 | M25: =+SUMIFS(M$4:M$22,$F$4:$F$22,$F25) -> 1954624.4 | N25: =+SUMIFS(N$4:N$22,$F$4:$F$22,$F25) -> 2011950.9 | O25: =+SUMIFS(O$4:O$22,$F$4:$F$22,$F25) -> 1954263.8 | ... S25: =+SUMIFS(S$4:S$22,$F$4:$F$22,$F25) -> 1445027.2
F26: KHO | H26: =+SUMIFS(H$4:H$22,$F$4:$F$22,$F26) -> 19677153 | I26: =+SUMIFS(I$4:I$22,$F$4:$F$22,$F26) -> 11267193 | J26: =+SUMIFS(J$4:J$22,$F$4:$F$22,$F26) -> 19802339 | K26: =+SUMIFS(K$4:K$22,$F$4:$F$22,$F26) -> 23149936 | L26: =+SUMIFS(L$4:L$22,$F$4:$F$22,$F26) -> 22007216 | M26: =+SUMIFS(M$4:M$22,$F$4:$F$22,$F26) -> 23512456 | N26: =+SUMIFS(N$4:N$22,$F$4:$F$22,$F26) -> 21092223 | O26: =+SUMIFS(O$4:O$22,$F$4:$F$22,$F26) -> 22547364 | ... S26: =+SUMIFS(S$4:S$22,$F$4:$F$22,$F26) -> 16103636
F28: PET | H28: =+H24/10^3 -> 14174.8 | I28: =+I24/10^3 -> 6156.8805 | J28: =+J24/10^3 -> 11625.707 | K28: =+K24/10^3 -> 15651.243 | L28: =+L24/10^3 -> 13685.272 | M28: =+M24/10^3 -> 16799.209 | N28: =+N24/10^3 -> 14910.408 | O28: =+O24/10^3 -> 15756.919 | ... S28: =+S24/10^3 -> 11063.404
F29: HDPP | H29: =+H25/10^3 -> 1673.0862 | I29: =+I25/10^3 -> 1192.587 | J29: =+J25/10^3 -> 1491.4139 | K29: =+K25/10^3 -> 2255.656 | L29: =+L25/10^3 -> 1863.1252 | M29: =+M25/10^3 -> 1954.6244 | N29: =+N25/10^3 -> 2011.9509 | O29: =+O25/10^3 -> 1954.2638 | ... S29: =+S25/10^3 -> 1445.0272
F30: KHO | H30: =+H26/10^3 -> 19677.153 | I30: =+I26/10^3 -> 11267.193 | J30: =+J26/10^3 -> 19802.339 | K30: =+K26/10^3 -> 23149.936 | L30: =+L26/10^3 -> 22007.216 | M30: =+M26/10^3 -> 23512.456 | N30: =+N26/10^3 -> 21092.223 | O30: =+O26/10^3 -> 22547.364 | ... S30: =+S26/10^3 -> 16103.636
A36: Phân loại | B36: Đầu mã | C36: Mvt | D36: Loại giao dịch | E36: Nguyên liệu | F36: Bộ phận | G36: Hệ số | H36: Ghi chú
A37: Nguyên liệu | B37: 15 | C37: 101.102 | D37: Nhập Nguyên liệu | E37: Tất cả nguyên liệu | F37: Kho | G37: 1
A38: Nguyên liệu | B38: 15 | C38: 261.262 | D38: Xuất nguyên liệu sản xuất | E38: PET | F38: PET | G38: -0.5 | H38: Tính 50% cho PET, 50% cho Kho vì chia đôi quãng đường
A39: Nguyên liệu | B39: 15 | C39: 261.262 | D39: Xuất nguyên liệu sản xuất | E39: PET | F39: KHO | G39: -0.5
A40: Nguyên liệu | B40: 15 | C40: 261.262 | D40: Xuất nguyên liệu sản xuất | E40: HDPP | F40: HDPP | G40: -0.5 | H40: Tính 50% cho HDPP, 50% cho Kho vì chia đôi quãng đường
A41: Nguyên liệu | B41: 15 | C41: 261.262 | D41: Xuất nguyên liệu sản xuất | E41: HDPP | F41: KHO | G41: -0.5
A42: BTP | B42: 16 | C42: 101,102,531,532 | D42: Xưởng chuyển BTP về kho | E42: PET | F42: PET | G42: 1
A43: BTP | B43: 16 | C43: 101,102,531,532 | D43: Xưởng chuyển BTP về kho | E43: HDPP | F43: HDPP | G43: 1
A44: BTP | B44: 16 | C44: 101.102 | D44: Nhập Nguyên liệu | E44: Tất cả nguyên liệu | F44: Kho | G44: 1
A45: BTP | B45: 16 | C45: 261.262 | D45: Kho chuyển BTP qua xưởng | E45: Tất cả nguyên liệu | F45: Kho | G45: -1
A46: BTP | B46: 16 | C46: 601.602 | D46: Kho xuất bán hàng | E46: Tất cả nguyên liệu | F46: Kho | G46: -1
A47: TP | B47: 11 | C47: 101,102,531,532 | D47: Xưởng chuyển về kho | E47: PET | F47: PET | G47: 1
A48: TP | B48: 11 | C48: 101,102,531,532 | D48: Xưởng chuyển về kho | E48: HDPP | F48: HDPP | G48: 1
A49: TP | B49: 11 | C49: 261.262 | D49: Kho chuyển qua xưởng | E49: Tất cả nguyên liệu | F49: Kho | G49: -1
...

Sheet 03. Chi tiết thực tế sử dụng
T1: 140006089 Bao Jumbo nâu đai nâu (AW3) : vảy sạch
A2: Nhóm | B2: Material | C2: Material Description | D2: Công dụng | E2: 12 | F2: 1 | G2: =F2+1 -> 2 | H2: =G2+1 -> 3 | I2: =H2+1 -> 4 | J2: =I2+1 -> 5 | K2: =J2+1 -> 6 | L2: =K2+1 -> 7 | M2: =L2+1 -> 8 | N2: =M2+1 -> 9 | ... P2: =O2+1 -> 11 | R2: Tổng cộng | T2: 140005072 Bao Jumbo 950x950x1300mm Đai Trắng rPET : rách đựng phế
A3: PET | B3: 140006089 | C3: Bao Jumbo nâu đai nâu (AW3) | D3: Đựng vảy sạch | E3: =-SUMIFS('01. MB51 - Data xuất 943'!$J:$J,'01. MB51 - Data xuất 943'!$A:$A,'03. Chi tiết thực tế sử dụng'!$B3,'01. MB51 - Data xuất 943'!$U:$U,'03. Chi tiết thực tế sử dụng'!$A3,'01. MB51 - Data xuất 943'!$V:$V,'03. Chi tiết thực tế sử dụng'!E$2) -> 658 | F3: =-SUMIFS('01. MB51 - Data xuất 943'!$J:$J,'01. MB51 - Data xuất 943'!$A:$A,'03. Chi tiết thực tế sử dụng'!$B3,'01. MB51 - Data xuất 943'!$U:$U,'03. Chi tiết thực tế sử dụng'!$A3,'01. MB51 - Data xuất 943'!$V:$V,'03. Chi tiết thực tế sử dụng'!F$2) -> 300 | G3: =-SUMIFS('01. MB51 - Data xuất 943'!$J:$J,'01. MB51 - Data xuất 943'!$A:$A,'03. Chi tiết thực tế sử dụng'!$B3,'01. MB51 - Data xuất 943'!$U:$U,'03. Chi tiết thực tế sử dụng'!$A3,'01. MB51 - Data xuất 943'!$V:$V,'03. Chi tiết thực tế sử dụng'!G$2) -> 0 | H3: =-SUMIFS('01. MB51 - Data xuất 943'!$J:$J,'01. MB51 - Data xuất 943'!$A:$A,'03. Chi tiết thực tế sử dụng'!$B3,'01. MB51 - Data xuất 943'!$U:$U,'03. Chi tiết thực tế sử dụng'!$A3,'01. MB51 - Data xuất 943'!$V:$V,'03. Chi tiết thực tế sử dụng'!H$2) -> 0 | I3: =-SUMIFS('01. MB51 - Data xuất 943'!$J:$J,'01. MB51 - Data xuất 943'!$A:$A,'03. Chi tiết thực tế sử dụng'!$B3,'01. MB51 - Data xuất 943'!$U:$U,'03. Chi tiết thực tế sử dụng'!$A3,'01. MB51 - Data xuất 943'!$V:$V,'03. Chi tiết thực tế sử dụng'!I$2) -> 0 | J3: =-SUMIFS('01. MB51 - Data xuất 943'!$J:$J,'01. MB51 - Data xuất 943'!$A:$A,'03. Chi tiết thực tế sử dụng'!$B3,'01. MB51 - Data xuất 943'!$U:$U,'03. Chi tiết thực tế sử dụng'!$A3,'01. MB51 - Data xuất 943'!$V:$V,'03. Chi tiết thực tế sử dụng'!J$2) -> 200 | K3: =-SUMIFS('01. MB51 - Data xuất 943'!$J:$J,'01. MB51 - Data xuất 943'!$A:$A,'03. Chi tiết thực tế sử dụng'!$B3,'01. MB51 - Data xuất 943'!$U:$U,'03. Chi tiết thực tế sử dụng'!$A3,'01. MB51 - Data xuất 943'!$V:$V,'03. Chi tiết thực tế sử dụng'!K$2) -> 1200 | L3: =-SUMIFS('01. MB51 - Data xuất 943'!$J:$J,'01. MB51 - Data xuất 943'!$A:$A,'03. Chi tiết thực tế sử dụng'!$B3,'01. MB51 - Data xuất 943'!$U:$U,'03. Chi tiết thực tế sử dụng'!$A3,'01. MB51 - Data xuất 943'!$V:$V,'03. Chi tiết thực tế sử dụng'!L$2) -> 400 | ... Q3: =-SUMIFS('01. MB51 - Data xuất 943'!$J:$J,'01. MB51 - Data xuất 943'!$A:$A,'03. Chi tiết thực tế sử dụng'!$B3,'01. MB51 - Data xuất 943'!$U:$U,'03. Chi tiết thực tế sử dụng'!$A3,'01. MB51 - Data xuất 943'!$V:$V,'03. Chi tiết thực tế sử dụng'!Q$2) -> 0 | R3: =+SUM(E3:Q3) -> 3858 | S3: =+R3/$R$7 -> 0.023157449 | T3: 140006075 Bao Jumbo nâu đai trắng (AW3): vảy thô
A4: PET | B4: 140006075 | C4: Bao Jumbo nâu đai trắng (AW3) | D4: Đựng vảy thô | E4: =-SUMIFS('01. MB51 - Data xuất 943'!$J:$J,'01. MB51 - Data xuất 943'!$A:$A,'03. Chi tiết thực tế sử dụng'!$B4,'01. MB51 - Data xuất 943'!$U:$U,'03. Chi tiết thực tế sử dụng'!$A4,'01. MB51 - Data xuất 943'!$V:$V,'03. Chi tiết thực tế sử dụng'!E$2) -> 0 | F4: =-SUMIFS('01. MB51 - Data xuất 943'!$J:$J,'01. MB51 - Data xuất 943'!$A:$A,'03. Chi tiết thực tế sử dụng'!$B4,'01. MB51 - Data xuất 943'!$U:$U,'03. Chi tiết thực tế sử dụng'!$A4,'01. MB51 - Data xuất 943'!$V:$V,'03. Chi tiết thực tế sử dụng'!F$2) -> 0 | G4: =-SUMIFS('01. MB51 - Data xuất 943'!$J:$J,'01. MB51 - Data xuất 943'!$A:$A,'03. Chi tiết thực tế sử dụng'!$B4,'01. MB51 - Data xuất 943'!$U:$U,'03. Chi tiết thực tế sử dụng'!$A4,'01. MB51 - Data xuất 943'!$V:$V,'03. Chi tiết thực tế sử dụng'!G$2) -> 0 | H4: =-SUMIFS('01. MB51 - Data xuất 943'!$J:$J,'01. MB51 - Data xuất 943'!$A:$A,'03. Chi tiết thực tế sử dụng'!$B4,'01. MB51 - Data xuất 943'!$U:$U,'03. Chi tiết thực tế sử dụng'!$A4,'01. MB51 - Data xuất 943'!$V:$V,'03. Chi tiết thực tế sử dụng'!H$2) -> 0 | I4: =-SUMIFS('01. MB51 - Data xuất 943'!$J:$J,'01. MB51 - Data xuất 943'!$A:$A,'03. Chi tiết thực tế sử dụng'!$B4,'01. MB51 - Data xuất 943'!$U:$U,'03. Chi tiết thực tế sử dụng'!$A4,'01. MB51 - Data xuất 943'!$V:$V,'03. Chi tiết thực tế sử dụng'!I$2) -> 0 | J4: =-SUMIFS('01. MB51 - Data xuất 943'!$J:$J,'01. MB51 - Data xuất 943'!$A:$A,'03. Chi tiết thực tế sử dụng'!$B4,'01. MB51 - Data xuất 943'!$U:$U,'03. Chi tiết thực tế sử dụng'!$A4,'01. MB51 - Data xuất 943'!$V:$V,'03. Chi tiết thực tế sử dụng'!J$2) -> 190 | K4: =-SUMIFS('01. MB51 - Data xuất 943'!$J:$J,'01. MB51 - Data xuất 943'!$A:$A,'03. Chi tiết thực tế sử dụng'!$B4,'01. MB51 - Data xuất 943'!$U:$U,'03. Chi tiết thực tế sử dụng'!$A4,'01. MB51 - Data xuất 943'!$V:$V,'03. Chi tiết thực tế sử dụng'!K$2) -> 0 | L4: =-SUMIFS('01. MB51 - Data xuất 943'!$J:$J,'01. MB51 - Data xuất 943'!$A:$A,'03. Chi tiết thực tế sử dụng'!$B4,'01. MB51 - Data xuất 943'!$U:$U,'03. Chi tiết thực tế sử dụng'!$A4,'01. MB51 - Data xuất 943'!$V:$V,'03. Chi tiết thực tế sử dụng'!L$2) -> 0 | ... Q4: =-SUMIFS('01. MB51 - Data xuất 943'!$J:$J,'01. MB51 - Data xuất 943'!$A:$A,'03. Chi tiết thực tế sử dụng'!$B4,'01. MB51 - Data xuất 943'!$U:$U,'03. Chi tiết thực tế sử dụng'!$A4,'01. MB51 - Data xuất 943'!$V:$V,'03. Chi tiết thực tế sử dụng'!Q$2) -> 0 | R4: =+SUM(E4:Q4) -> 2290 | S4: =+R4/$R$7 -> 0.013745609
A5: PET | B5: 140006125 | C5: Bao Jumbo 950x950x1300mm Đai Xanh Xơ Sợi | E5: =-SUMIFS('01. MB51 - Data xuất 943'!$J:$J,'01. MB51 - Data xuất 943'!$A:$A,'03. Chi tiết thực tế sử dụng'!$B5,'01. MB51 - Data xuất 943'!$U:$U,'03. Chi tiết thực tế sử dụng'!$A5,'01. MB51 - Data xuất 943'!$V:$V,'03. Chi tiết thực tế sử dụng'!E$2) -> 0 | F5: =-SUMIFS('01. MB51 - Data xuất 943'!$J:$J,'01. MB51 - Data xuất 943'!$A:$A,'03. Chi tiết thực tế sử dụng'!$B5,'01. MB51 - Data xuất 943'!$U:$U,'03. Chi tiết thực tế sử dụng'!$A5,'01. MB51 - Data xuất 943'!$V:$V,'03. Chi tiết thực tế sử dụng'!F$2) -> 0 | G5: =-SUMIFS('01. MB51 - Data xuất 943'!$J:$J,'01. MB51 - Data xuất 943'!$A:$A,'03. Chi tiết thực tế sử dụng'!$B5,'01. MB51 - Data xuất 943'!$U:$U,'03. Chi tiết thực tế sử dụng'!$A5,'01. MB51 - Data xuất 943'!$V:$V,'03. Chi tiết thực tế sử dụng'!G$2) -> 0 | H5: =-SUMIFS('01. MB51 - Data xuất 943'!$J:$J,'01. MB51 - Data xuất 943'!$A:$A,'03. Chi tiết thực tế sử dụng'!$B5,'01. MB51 - Data xuất 943'!$U:$U,'03. Chi tiết thực tế sử dụng'!$A5,'01. MB51 - Data xuất 943'!$V:$V,'03. Chi tiết thực tế sử dụng'!H$2) -> 0 | I5: =-SUMIFS('01. MB51 - Data xuất 943'!$J:$J,'01. MB51 - Data xuất 943'!$A:$A,'03. Chi tiết thực tế sử dụng'!$B5,'01. MB51 - Data xuất 943'!$U:$U,'03. Chi tiết thực tế sử dụng'!$A5,'01. MB51 - Data xuất 943'!$V:$V,'03. Chi tiết thực tế sử dụng'!I$2) -> 0 | J5: =-SUMIFS('01. MB51 - Data xuất 943'!$J:$J,'01. MB51 - Data xuất 943'!$A:$A,'03. Chi tiết thực tế sử dụng'!$B5,'01. MB51 - Data xuất 943'!$U:$U,'03. Chi tiết thực tế sử dụng'!$A5,'01. MB51 - Data xuất 943'!$V:$V,'03. Chi tiết thực tế sử dụng'!J$2) -> 0 | K5: =-SUMIFS('01. MB51 - Data xuất 943'!$J:$J,'01. MB51 - Data xuất 943'!$A:$A,'03. Chi tiết thực tế sử dụng'!$B5,'01. MB51 - Data xuất 943'!$U:$U,'03. Chi tiết thực tế sử dụng'!$A5,'01. MB51 - Data xuất 943'!$V:$V,'03. Chi tiết thực tế sử dụng'!K$2) -> 0 | L5: =-SUMIFS('01. MB51 - Data xuất 943'!$J:$J,'01. MB51 - Data xuất 943'!$A:$A,'03. Chi tiết thực tế sử dụng'!$B5,'01. MB51 - Data xuất 943'!$U:$U,'03. Chi tiết thực tế sử dụng'!$A5,'01. MB51 - Data xuất 943'!$V:$V,'03. Chi tiết thực tế sử dụng'!L$2) -> 0 | ... Q5: =-SUMIFS('01. MB51 - Data xuất 943'!$J:$J,'01. MB51 - Data xuất 943'!$A:$A,'03. Chi tiết thực tế sử dụng'!$B5,'01. MB51 - Data xuất 943'!$U:$U,'03. Chi tiết thực tế sử dụng'!$A5,'01. MB51 - Data xuất 943'!$V:$V,'03. Chi tiết thực tế sử dụng'!Q$2) -> 0 | R5: =+SUM(E5:Q5) -> 13 | S5: =+R5/$R$7 -> 7.8031839e-05 | T5: 140006075 Bao Jumbo nâu đai trắng (AW3): vảy thô
A6: PET | B6: 140006154 | C6: Bao Jumbo 1050x1050x1300mm Đai Trắng PET | E6: =-SUMIFS('01. MB51 - Data xuất 943'!$J:$J,'01. MB51 - Data xuất 943'!$A:$A,'03. Chi tiết thực tế sử dụng'!$B6,'01. MB51 - Data xuất 943'!$U:$U,'03. Chi tiết thực tế sử dụng'!$A6,'01. MB51 - Data xuất 943'!$V:$V,'03. Chi tiết thực tế sử dụng'!E$2) -> 0 | F6: =-SUMIFS('01. MB51 - Data xuất 943'!$J:$J,'01. MB51 - Data xuất 943'!$A:$A,'03. Chi tiết thực tế sử dụng'!$B6,'01. MB51 - Data xuất 943'!$U:$U,'03. Chi tiết thực tế sử dụng'!$A6,'01. MB51 - Data xuất 943'!$V:$V,'03. Chi tiết thực tế sử dụng'!F$2) -> 0 | G6: =-SUMIFS('01. MB51 - Data xuất 943'!$J:$J,'01. MB51 - Data xuất 943'!$A:$A,'03. Chi tiết thực tế sử dụng'!$B6,'01. MB51 - Data xuất 943'!$U:$U,'03. Chi tiết thực tế sử dụng'!$A6,'01. MB51 - Data xuất 943'!$V:$V,'03. Chi tiết thực tế sử dụng'!G$2) -> 0 | H6: =-SUMIFS('01. MB51 - Data xuất 943'!$J:$J,'01. MB51 - Data xuất 943'!$A:$A,'03. Chi tiết thực tế sử dụng'!$B6,'01. MB51 - Data xuất 943'!$U:$U,'03. Chi tiết thực tế sử dụng'!$A6,'01. MB51 - Data xuất 943'!$V:$V,'03. Chi tiết thực tế sử dụng'!H$2) -> 0 | I6: =-SUMIFS('01. MB51 - Data xuất 943'!$J:$J,'01. MB51 - Data xuất 943'!$A:$A,'03. Chi tiết thực tế sử dụng'!$B6,'01. MB51 - Data xuất 943'!$U:$U,'03. Chi tiết thực tế sử dụng'!$A6,'01. MB51 - Data xuất 943'!$V:$V,'03. Chi tiết thực tế sử dụng'!I$2) -> 0 | J6: =-SUMIFS('01. MB51 - Data xuất 943'!$J:$J,'01. MB51 - Data xuất 943'!$A:$A,'03. Chi tiết thực tế sử dụng'!$B6,'01. MB51 - Data xuất 943'!$U:$U,'03. Chi tiết thực tế sử dụng'!$A6,'01. MB51 - Data xuất 943'!$V:$V,'03. Chi tiết thực tế sử dụng'!J$2) -> 0 | K6: =-SUMIFS('01. MB51 - Data xuất 943'!$J:$J,'01. MB51 - Data xuất 943'!$A:$A,'03. Chi tiết thực tế sử dụng'!$B6,'01. MB51 - Data xuất 943'!$U:$U,'03. Chi tiết thực tế sử dụng'!$A6,'01. MB51 - Data xuất 943'!$V:$V,'03. Chi tiết thực tế sử dụng'!K$2) -> 0 | L6: =-SUMIFS('01. MB51 - Data xuất 943'!$J:$J,'01. MB51 - Data xuất 943'!$A:$A,'03. Chi tiết thực tế sử dụng'!$B6,'01. MB51 - Data xuất 943'!$U:$U,'03. Chi tiết thực tế sử dụng'!$A6,'01. MB51 - Data xuất 943'!$V:$V,'03. Chi tiết thực tế sử dụng'!L$2) -> 0 | ... Q6: =-SUMIFS('01. MB51 - Data xuất 943'!$J:$J,'01. MB51 - Data xuất 943'!$A:$A,'03. Chi tiết thực tế sử dụng'!$B6,'01. MB51 - Data xuất 943'!$U:$U,'03. Chi tiết thực tế sử dụng'!$A6,'01. MB51 - Data xuất 943'!$V:$V,'03. Chi tiết thực tế sử dụng'!Q$2) -> 0 | R6: =+SUM(E6:Q6) -> 100 | S6: =+R6/$R$7 -> 0.00060024492
E7: ='02. Số tấn luân chuyển'!V10 -> 14174.8 | F7: ='02. Số tấn luân chuyển'!W10 -> 6156.8805 | G7: ='02. Số tấn luân chuyển'!X10 -> 11625.707 | H7: ='02. Số tấn luân chuyển'!Y10 -> 15651.243 | I7: ='02. Số tấn luân chuyển'!Z10 -> 13685.272 | J7: ='02. Số tấn luân chuyển'!AA10 -> 16799.209 | K7: ='02. Số tấn luân chuyển'!AB10 -> 14910.408 | L7: ='02. Số tấn luân chuyển'!AC10 -> 15756.919 | ... Q7: ='02. Số tấn luân chuyển'!AH10 -> 0 | R7: =+SUM(E7:Q7) -> 166598.66 | T7: =+R5+R6 -> 113 | U7: =+T7/R7 -> 0.00067827676
A8: HD | B8: 140006128 | C8: Bao Jumbo nâu đai dương nhạt (HD BLOW) | E8: =-SUMIFS('01. MB51 - Data xuất 943'!$J:$J,'01. MB51 - Data xuất 943'!$A:$A,'03. Chi tiết thực tế sử dụng'!$B8,'01. MB51 - Data xuất 943'!$U:$U,'03. Chi tiết thực tế sử dụng'!$A8,'01. MB51 - Data xuất 943'!$V:$V,'03. Chi tiết thực tế sử dụng'!E$2) -> 10 | F8: =-SUMIFS('01. MB51 - Data xuất 943'!$J:$J,'01. MB51 - Data xuất 943'!$A:$A,'03. Chi tiết thực tế sử dụng'!$B8,'01. MB51 - Data xuất 943'!$U:$U,'03. Chi tiết thực tế sử dụng'!$A8,'01. MB51 - Data xuất 943'!$V:$V,'03. Chi tiết thực tế sử dụng'!F$2) -> 0 | G8: =-SUMIFS('01. MB51 - Data xuất 943'!$J:$J,'01. MB51 - Data xuất 943'!$A:$A,'03. Chi tiết thực tế sử dụng'!$B8,'01. MB51 - Data xuất 943'!$U:$U,'03. Chi tiết thực tế sử dụng'!$A8,'01. MB51 - Data xuất 943'!$V:$V,'03. Chi tiết thực tế sử dụng'!G$2) -> 0 | H8: =-SUMIFS('01. MB51 - Data xuất 943'!$J:$J,'01. MB51 - Data xuất 943'!$A:$A,'03. Chi tiết thực tế sử dụng'!$B8,'01. MB51 - Data xuất 943'!$U:$U,'03. Chi tiết thực tế sử dụng'!$A8,'01. MB51 - Data xuất 943'!$V:$V,'03. Chi tiết thực tế sử dụng'!H$2) -> 0 | I8: =-SUMIFS('01. MB51 - Data xuất 943'!$J:$J,'01. MB51 - Data xuất 943'!$A:$A,'03. Chi tiết thực tế sử dụng'!$B8,'01. MB51 - Data xuất 943'!$U:$U,'03. Chi tiết thực tế sử dụng'!$A8,'01. MB51 - Data xuất 943'!$V:$V,'03. Chi tiết thực tế sử dụng'!I$2) -> 0 | J8: =-SUMIFS('01. MB51 - Data xuất 943'!$J:$J,'01. MB51 - Data xuất 943'!$A:$A,'03. Chi tiết thực tế sử dụng'!$B8,'01. MB51 - Data xuất 943'!$U:$U,'03. Chi tiết thực tế sử dụng'!$A8,'01. MB51 - Data xuất 943'!$V:$V,'03. Chi tiết thực tế sử dụng'!J$2) -> 0 | K8: =-SUMIFS('01. MB51 - Data xuất 943'!$J:$J,'01. MB51 - Data xuất 943'!$A:$A,'03. Chi tiết thực tế sử dụng'!$B8,'01. MB51 - Data xuất 943'!$U:$U,'03. Chi tiết thực tế sử dụng'!$A8,'01. MB51 - Data xuất 943'!$V:$V,'03. Chi tiết thực tế sử dụng'!K$2) -> 0 | L8: =-SUMIFS('01. MB51 - Data xuất 943'!$J:$J,'01. MB51 - Data xuất 943'!$A:$A,'03. Chi tiết thực tế sử dụng'!$B8,'01. MB51 - Data xuất 943'!$U:$U,'03. Chi tiết thực tế sử dụng'!$A8,'01. MB51 - Data xuất 943'!$V:$V,'03. Chi tiết thực tế sử dụng'!L$2) -> 0 | ... Q8: =-SUMIFS('01. MB51 - Data xuất 943'!$J:$J,'01. MB51 - Data xuất 943'!$A:$A,'03. Chi tiết thực tế sử dụng'!$B8,'01. MB51 - Data xuất 943'!$U:$U,'03. Chi tiết thực tế sử dụng'!$A8,'01. MB51 - Data xuất 943'!$V:$V,'03. Chi tiết thực tế sử dụng'!Q$2) -> 0 | R8: =+SUM(E8:Q8) -> 10 | S8: =+R8/$R$11 -> 0.00046712983
A9: HD | B9: 140006120 | C9: Bao jumbo cũ | E9: =-SUMIFS('01. MB51 - Data xuất 943'!$J:$J,'01. MB51 - Data xuất 943'!$A:$A,'03. Chi tiết thực tế sử dụng'!$B9,'01. MB51 - Data xuất 943'!$U:$U,'03. Chi tiết thực tế sử dụng'!$A9,'01. MB51 - Data xuất 943'!$V:$V,'03. Chi tiết thực tế sử dụng'!E$2) -> 0 | F9: =-SUMIFS('01. MB51 - Data xuất 943'!$J:$J,'01. MB51 - Data xuất 943'!$A:$A,'03. Chi tiết thực tế sử dụng'!$B9,'01. MB51 - Data xuất 943'!$U:$U,'03. Chi tiết thực tế sử dụng'!$A9,'01. MB51 - Data xuất 943'!$V:$V,'03. Chi tiết thực tế sử dụng'!F$2) -> 0 | G9: =-SUMIFS('01. MB51 - Data xuất 943'!$J:$J,'01. MB51 - Data xuất 943'!$A:$A,'03. Chi tiết thực tế sử dụng'!$B9,'01. MB51 - Data xuất 943'!$U:$U,'03. Chi tiết thực tế sử dụng'!$A9,'01. MB51 - Data xuất 943'!$V:$V,'03. Chi tiết thực tế sử dụng'!G$2) -> 100 | H9: =-SUMIFS('01. MB51 - Data xuất 943'!$J:$J,'01. MB51 - Data xuất 943'!$A:$A,'03. Chi tiết thực tế sử dụng'!$B9,'01. MB51 - Data xuất 943'!$U:$U,'03. Chi tiết thực tế sử dụng'!$A9,'01. MB51 - Data xuất 943'!$V:$V,'03. Chi tiết thực tế sử dụng'!H$2) -> 0 | I9: =-SUMIFS('01. MB51 - Data xuất 943'!$J:$J,'01. MB51 - Data xuất 943'!$A:$A,'03. Chi tiết thực tế sử dụng'!$B9,'01. MB51 - Data xuất 943'!$U:$U,'03. Chi tiết thực tế sử dụng'!$A9,'01. MB51 - Data xuất 943'!$V:$V,'03. Chi tiết thực tế sử dụng'!I$2) -> 550 | J9: =-SUMIFS('01. MB51 - Data xuất 943'!$J:$J,'01. MB51 - Data xuất 943'!$A:$A,'03. Chi tiết thực tế sử dụng'!$B9,'01. MB51 - Data xuất 943'!$U:$U,'03. Chi tiết thực tế sử dụng'!$A9,'01. MB51 - Data xuất 943'!$V:$V,'03. Chi tiết thực tế sử dụng'!J$2) -> 150 | K9: =-SUMIFS('01. MB51 - Data xuất 943'!$J:$J,'01. MB51 - Data xuất 943'!$A:$A,'03. Chi tiết thực tế sử dụng'!$B9,'01. MB51 - Data xuất 943'!$U:$U,'03. Chi tiết thực tế sử dụng'!$A9,'01. MB51 - Data xuất 943'!$V:$V,'03. Chi tiết thực tế sử dụng'!K$2) -> 100 | L9: =-SUMIFS('01. MB51 - Data xuất 943'!$J:$J,'01. MB51 - Data xuất 943'!$A:$A,'03. Chi tiết thực tế sử dụng'!$B9,'01. MB51 - Data xuất 943'!$U:$U,'03. Chi tiết thực tế sử dụng'!$A9,'01. MB51 - Data xuất 943'!$V:$V,'03. Chi tiết thực tế sử dụng'!L$2) -> 0 | ... Q9: =-SUMIFS('01. MB51 - Data xuất 943'!$J:$J,'01. MB51 - Data xuất 943'!$A:$A,'03. Chi tiết thực tế sử dụng'!$B9,'01. MB51 - Data xuất 943'!$U:$U,'03. Chi tiết thực tế sử dụng'!$A9,'01. MB51 - Data xuất 943'!$V:$V,'03. Chi tiết thực tế sử dụng'!Q$2) -> 0 | R9: =+SUM(E9:Q9) -> 1234 | S9: =+R9/$R$11 -> 0.057643821 | T9: =+S9+S10 -> 0.10202115
A10: HD | B10: 140005935 | C10: Bao jumbo 950x950x1300 AW2 | E10: =-SUMIFS('01. MB51 - Data xuất 943'!$J:$J,'01. MB51 - Data xuất 943'!$A:$A,'03. Chi tiết thực tế sử dụng'!$B10,'01. MB51 - Data xuất 943'!$U:$U,'03. Chi tiết thực tế sử dụng'!$A10,'01. MB51 - Data xuất 943'!$V:$V,'03. Chi tiết thực tế sử dụng'!E$2) -> 200 | F10: =-SUMIFS('01. MB51 - Data xuất 943'!$J:$J,'01. MB51 - Data xuất 943'!$A:$A,'03. Chi tiết thực tế sử dụng'!$B10,'01. MB51 - Data xuất 943'!$U:$U,'03. Chi tiết thực tế sử dụng'!$A10,'01. MB51 - Data xuất 943'!$V:$V,'03. Chi tiết thực tế sử dụng'!F$2) -> 450 | G10: =-SUMIFS('01. MB51 - Data xuất 943'!$J:$J,'01. MB51 - Data xuất 943'!$A:$A,'03. Chi tiết thực tế sử dụng'!$B10,'01. MB51 - Data xuất 943'!$U:$U,'03. Chi tiết thực tế sử dụng'!$A10,'01. MB51 - Data xuất 943'!$V:$V,'03. Chi tiết thực tế sử dụng'!G$2) -> 300 | H10: =-SUMIFS('01. MB51 - Data xuất 943'!$J:$J,'01. MB51 - Data xuất 943'!$A:$A,'03. Chi tiết thực tế sử dụng'!$B10,'01. MB51 - Data xuất 943'!$U:$U,'03. Chi tiết thực tế sử dụng'!$A10,'01. MB51 - Data xuất 943'!$V:$V,'03. Chi tiết thực tế sử dụng'!H$2) -> 0 | I10: =-SUMIFS('01. MB51 - Data xuất 943'!$J:$J,'01. MB51 - Data xuất 943'!$A:$A,'03. Chi tiết thực tế sử dụng'!$B10,'01. MB51 - Data xuất 943'!$U:$U,'03. Chi tiết thực tế sử dụng'!$A10,'01. MB51 - Data xuất 943'!$V:$V,'03. Chi tiết thực tế sử dụng'!I$2) -> 0 | J10: =-SUMIFS('01. MB51 - Data xuất 943'!$J:$J,'01. MB51 - Data xuất 943'!$A:$A,'03. Chi tiết thực tế sử dụng'!$B10,'01. MB51 - Data xuất 943'!$U:$U,'03. Chi tiết thực tế sử dụng'!$A10,'01. MB51 - Data xuất 943'!$V:$V,'03. Chi tiết thực tế sử dụng'!J$2) -> 0 | K10: =-SUMIFS('01. MB51 - Data xuất 943'!$J:$J,'01. MB51 - Data xuất 943'!$A:$A,'03. Chi tiết thực tế sử dụng'!$B10,'01. MB51 - Data xuất 943'!$U:$U,'03. Chi tiết thực tế sử dụng'!$A10,'01. MB51 - Data xuất 943'!$V:$V,'03. Chi tiết thực tế sử dụng'!K$2) -> 0 | L10: =-SUMIFS('01. MB51 - Data xuất 943'!$J:$J,'01. MB51 - Data xuất 943'!$A:$A,'03. Chi tiết thực tế sử dụng'!$B10,'01. MB51 - Data xuất 943'!$U:$U,'03. Chi tiết thực tế sử dụng'!$A10,'01. MB51 - Data xuất 943'!$V:$V,'03. Chi tiết thực tế sử dụng'!L$2) -> 0 | ... Q10: =-SUMIFS('01. MB51 - Data xuất 943'!$J:$J,'01. MB51 - Data xuất 943'!$A:$A,'03. Chi tiết thực tế sử dụng'!$B10,'01. MB51 - Data xuất 943'!$U:$U,'03. Chi tiết thực tế sử dụng'!$A10,'01. MB51 - Data xuất 943'!$V:$V,'03. Chi tiết thực tế sử dụng'!Q$2) -> 0 | R10: =+SUM(E10:Q10) -> 950 | S10: =+R10/$R$11 -> 0.044377334
E11: ='02. Số tấn luân chuyển'!V11 -> 1673.0862 | F11: ='02. Số tấn luân chuyển'!W11 -> 1192.587 | G11: ='02. Số tấn luân chuyển'!X11 -> 1491.4139 | H11: ='02. Số tấn luân chuyển'!Y11 -> 2255.656 | I11: ='02. Số tấn luân chuyển'!Z11 -> 1863.1252 | J11: ='02. Số tấn luân chuyển'!AA11 -> 1954.6244 | K11: ='02. Số tấn luân chuyển'!AB11 -> 2011.9509 | L11: ='02. Số tấn luân chuyển'!AC11 -> 1954.2638 | ... Q11: ='02. Số tấn luân chuyển'!AH11 -> 0 | R11: =+SUM(E11:Q11) -> 21407.325
A12: KHO | B12: 140005072 | C12: Bao Jumbo 950x950x1300mm Đai Trắng rPET | D12: Đựng TP | E12: =-SUMIFS('01. MB51 - Data xuất 943'!$J:$J,'01. MB51 - Data xuất 943'!$A:$A,'03. Chi tiết thực tế sử dụng'!$B12,'01. MB51 - Data xuất 943'!$U:$U,'03. Chi tiết thực tế sử dụng'!$A12,'01. MB51 - Data xuất 943'!$V:$V,'03. Chi tiết thực tế sử dụng'!E$2) -> 600 | F12: =-SUMIFS('01. MB51 - Data xuất 943'!$J:$J,'01. MB51 - Data xuất 943'!$A:$A,'03. Chi tiết thực tế sử dụng'!$B12,'01. MB51 - Data xuất 943'!$U:$U,'03. Chi tiết thực tế sử dụng'!$A12,'01. MB51 - Data xuất 943'!$V:$V,'03. Chi tiết thực tế sử dụng'!F$2) -> 800 | G12: =-SUMIFS('01. MB51 - Data xuất 943'!$J:$J,'01. MB51 - Data xuất 943'!$A:$A,'03. Chi tiết thực tế sử dụng'!$B12,'01. MB51 - Data xuất 943'!$U:$U,'03. Chi tiết thực tế sử dụng'!$A12,'01. MB51 - Data xuất 943'!$V:$V,'03. Chi tiết thực tế sử dụng'!G$2) -> 1100 | H12: =-SUMIFS('01. MB51 - Data xuất 943'!$J:$J,'01. MB51 - Data xuất 943'!$A:$A,'03. Chi tiết thực tế sử dụng'!$B12,'01. MB51 - Data xuất 943'!$U:$U,'03. Chi tiết thực tế sử dụng'!$A12,'01. MB51 - Data xuất 943'!$V:$V,'03. Chi tiết thực tế sử dụng'!H$2) -> 800 | I12: =-SUMIFS('01. MB51 - Data xuất 943'!$J:$J,'01. MB51 - Data xuất 943'!$A:$A,'03. Chi tiết thực tế sử dụng'!$B12,'01. MB51 - Data xuất 943'!$U:$U,'03. Chi tiết thực tế sử dụng'!$A12,'01. MB51 - Data xuất 943'!$V:$V,'03. Chi tiết thực tế sử dụng'!I$2) -> 900 | J12: =-SUMIFS('01. MB51 - Data xuất 943'!$J:$J,'01. MB51 - Data xuất 943'!$A:$A,'03. Chi tiết thực tế sử dụng'!$B12,'01. MB51 - Data xuất 943'!$U:$U,'03. Chi tiết thực tế sử dụng'!$A12,'01. MB51 - Data xuất 943'!$V:$V,'03. Chi tiết thực tế sử dụng'!J$2) -> 300 | K12: =-SUMIFS('01. MB51 - Data xuất 943'!$J:$J,'01. MB51 - Data xuất 943'!$A:$A,'03. Chi tiết thực tế sử dụng'!$B12,'01. MB51 - Data xuất 943'!$U:$U,'03. Chi tiết thực tế sử dụng'!$A12,'01. MB51 - Data xuất 943'!$V:$V,'03. Chi tiết thực tế sử dụng'!K$2) -> 400 | L12: =-SUMIFS('01. MB51 - Data xuất 943'!$J:$J,'01. MB51 - Data xuất 943'!$A:$A,'03. Chi tiết thực tế sử dụng'!$B12,'01. MB51 - Data xuất 943'!$U:$U,'03. Chi tiết thực tế sử dụng'!$A12,'01. MB51 - Data xuất 943'!$V:$V,'03. Chi tiết thực tế sử dụng'!L$2) -> 300 | ... Q12: =-SUMIFS('01. MB51 - Data xuất 943'!$J:$J,'01. MB51 - Data xuất 943'!$A:$A,'03. Chi tiết thực tế sử dụng'!$B12,'01. MB51 - Data xuất 943'!$U:$U,'03. Chi tiết thực tế sử dụng'!$A12,'01. MB51 - Data xuất 943'!$V:$V,'03. Chi tiết thực tế sử dụng'!Q$2) -> 0 | R12: =+SUM(E12:Q12) -> 5920 | S12: =+R12/$R$18 -> 0.024291627
A13: KHO | B13: 140006127 | C13: Bao Jumbo nâu đai xanh lá (PP INJ) | E13: =-SUMIFS('01. MB51 - Data xuất 943'!$J:$J,'01. MB51 - Data xuất 943'!$A:$A,'03. Chi tiết thực tế sử dụng'!$B13,'01. MB51 - Data xuất 943'!$U:$U,'03. Chi tiết thực tế sử dụng'!$A13,'01. MB51 - Data xuất 943'!$V:$V,'03. Chi tiết thực tế sử dụng'!E$2) -> 0 | F13: =-SUMIFS('01. MB51 - Data xuất 943'!$J:$J,'01. MB51 - Data xuất 943'!$A:$A,'03. Chi tiết thực tế sử dụng'!$B13,'01. MB51 - Data xuất 943'!$U:$U,'03. Chi tiết thực tế sử dụng'!$A13,'01. MB51 - Data xuất 943'!$V:$V,'03. Chi tiết thực tế sử dụng'!F$2) -> 0 | G13: =-SUMIFS('01. MB51 - Data xuất 943'!$J:$J,'01. MB51 - Data xuất 943'!$A:$A,'03. Chi tiết thực tế sử dụng'!$B13,'01. MB51 - Data xuất 943'!$U:$U,'03. Chi tiết thực tế sử dụng'!$A13,'01. MB51 - Data xuất 943'!$V:$V,'03. Chi tiết thực tế sử dụng'!G$2) -> 0 | H13: =-SUMIFS('01. MB51 - Data xuất 943'!$J:$J,'01. MB51 - Data xuất 943'!$A:$A,'03. Chi tiết thực tế sử dụng'!$B13,'01. MB51 - Data xuất 943'!$U:$U,'03. Chi tiết thực tế sử dụng'!$A13,'01. MB51 - Data xuất 943'!$V:$V,'03. Chi tiết thực tế sử dụng'!H$2) -> 0 | I13: =-SUMIFS('01. MB51 - Data xuất 943'!$J:$J,'01. MB51 - Data xuất 943'!$A:$A,'03. Chi tiết thực tế sử dụng'!$B13,'01. MB51 - Data xuất 943'!$U:$U,'03. Chi tiết thực tế sử dụng'!$A13,'01. MB51 - Data xuất 943'!$V:$V,'03. Chi tiết thực tế sử dụng'!I$2) -> 0 | J13: =-SUMIFS('01. MB51 - Data xuất 943'!$J:$J,'01. MB51 - Data xuất 943'!$A:$A,'03. Chi tiết thực tế sử dụng'!$B13,'01. MB51 - Data xuất 943'!$U:$U,'03. Chi tiết thực tế sử dụng'!$A13,'01. MB51 - Data xuất 943'!$V:$V,'03. Chi tiết thực tế sử dụng'!J$2) -> 5 | K13: =-SUMIFS('01. MB51 - Data xuất 943'!$J:$J,'01. MB51 - Data xuất 943'!$A:$A,'03. Chi tiết thực tế sử dụng'!$B13,'01. MB51 - Data xuất 943'!$U:$U,'03. Chi tiết thực tế sử dụng'!$A13,'01. MB51 - Data xuất 943'!$V:$V,'03. Chi tiết thực tế sử dụng'!K$2) -> 0 | L13: =-SUMIFS('01. MB51 - Data xuất 943'!$J:$J,'01. MB51 - Data xuất 943'!$A:$A,'03. Chi tiết thực tế sử dụng'!$B13,'01. MB51 - Data xuất 943'!$U:$U,'03. Chi tiết thực tế sử dụng'!$A13,'01. MB51 - Data xuất 943'!$V:$V,'03. Chi tiết thực tế sử dụng'!L$2) -> 0 | ... Q13: =-SUMIFS('01. MB51 - Data xuất 943'!$J:$J,'01. MB51 - Data xuất 943'!$A:$A,'03. Chi tiết thực tế sử dụng'!$B13,'01. MB51 - Data xuất 943'!$U:$U,'03. Chi tiết thực tế sử dụng'!$A13,'01. MB51 - Data xuất 943'!$V:$V,'03. Chi tiết thực tế sử dụng'!Q$2) -> 0 | R13: =+SUM(E13:Q13) -> 5 | S13: =+R13/$R$18 -> 2.0516577e-05
A14: KHO | B14: 140006128 | C14: Bao Jumbo nâu đai dương nhạt (HD BLOW) | E14: =-SUMIFS('01. MB51 - Data xuất 943'!$J:$J,'01. MB51 - Data xuất 943'!$A:$A,'03. Chi tiết thực tế sử dụng'!$B14,'01. MB51 - Data xuất 943'!$U:$U,'03. Chi tiết thực tế sử dụng'!$A14,'01. MB51 - Data xuất 943'!$V:$V,'03. Chi tiết thực tế sử dụng'!E$2) -> 0 | F14: =-SUMIFS('01. MB51 - Data xuất 943'!$J:$J,'01. MB51 - Data xuất 943'!$A:$A,'03. Chi tiết thực tế sử dụng'!$B14,'01. MB51 - Data xuất 943'!$U:$U,'03. Chi tiết thực tế sử dụng'!$A14,'01. MB51 - Data xuất 943'!$V:$V,'03. Chi tiết thực tế sử dụng'!F$2) -> 0 | G14: =-SUMIFS('01. MB51 - Data xuất 943'!$J:$J,'01. MB51 - Data xuất 943'!$A:$A,'03. Chi tiết thực tế sử dụng'!$B14,'01. MB51 - Data xuất 943'!$U:$U,'03. Chi tiết thực tế sử dụng'!$A14,'01. MB51 - Data xuất 943'!$V:$V,'03. Chi tiết thực tế sử dụng'!G$2) -> 0 | H14: =-SUMIFS('01. MB51 - Data xuất 943'!$J:$J,'01. MB51 - Data xuất 943'!$A:$A,'03. Chi tiết thực tế sử dụng'!$B14,'01. MB51 - Data xuất 943'!$U:$U,'03. Chi tiết thực tế sử dụng'!$A14,'01. MB51 - Data xuất 943'!$V:$V,'03. Chi tiết thực tế sử dụng'!H$2) -> 0 | I14: =-SUMIFS('01. MB51 - Data xuất 943'!$J:$J,'01. MB51 - Data xuất 943'!$A:$A,'03. Chi tiết thực tế sử dụng'!$B14,'01. MB51 - Data xuất 943'!$U:$U,'03. Chi tiết thực tế sử dụng'!$A14,'01. MB51 - Data xuất 943'!$V:$V,'03. Chi tiết thực tế sử dụng'!I$2) -> 0 | J14: =-SUMIFS('01. MB51 - Data xuất 943'!$J:$J,'01. MB51 - Data xuất 943'!$A:$A,'03. Chi tiết thực tế sử dụng'!$B14,'01. MB51 - Data xuất 943'!$U:$U,'03. Chi tiết thực tế sử dụng'!$A14,'01. MB51 - Data xuất 943'!$V:$V,'03. Chi tiết thực tế sử dụng'!J$2) -> 5 | K14: =-SUMIFS('01. MB51 - Data xuất 943'!$J:$J,'01. MB51 - Data xuất 943'!$A:$A,'03. Chi tiết thực tế sử dụng'!$B14,'01. MB51 - Data xuất 943'!$U:$U,'03. Chi tiết thực tế sử dụng'!$A14,'01. MB51 - Data xuất 943'!$V:$V,'03. Chi tiết thực tế sử dụng'!K$2) -> 0 | L14: =-SUMIFS('01. MB51 - Data xuất 943'!$J:$J,'01. MB51 - Data xuất 943'!$A:$A,'03. Chi tiết thực tế sử dụng'!$B14,'01. MB51 - Data xuất 943'!$U:$U,'03. Chi tiết thực tế sử dụng'!$A14,'01. MB51 - Data xuất 943'!$V:$V,'03. Chi tiết thực tế sử dụng'!L$2) -> 0 | ... Q14: =-SUMIFS('01. MB51 - Data xuất 943'!$J:$J,'01. MB51 - Data xuất 943'!$A:$A,'03. Chi tiết thực tế sử dụng'!$B14,'01. MB51 - Data xuất 943'!$U:$U,'03. Chi tiết thực tế sử dụng'!$A14,'01. MB51 - Data xuất 943'!$V:$V,'03. Chi tiết thực tế sử dụng'!Q$2) -> 0 | R14: =+SUM(E14:Q14) -> 5 | S14: =+R14/$R$18 -> 2.0516577e-05
