Workbook
Name _1: #REF!
Name _2: #REF!
Name _3: #REF!
Name _4: #REF!
Name _5: #REF!
Name a: #REF!
Name Accounts: #REF!
Name Activity_Reports: #REF!
Name ADM: #REF!
Name Application: #REF!
Name B: #REF!
Name back: #REF!
Name Calendar: #REF!
Name Catalogue_xls: #REF!
Name CompanyCode: #REF!
Name Contractingdiv: #REF!
Name corporate_affairs: #REF!
Name CTY: #REF!
Name Data_Values: #REF!
Name DATA13: #REF!
Name DATA14: #REF!
Name DATA15: #REF!
Name DATA16: #REF!
Name DATA17: #REF!
Name DATA18: #REF!
Name DATA19: #REF!
Name DATA20: #REF!
Name DATA21: #REF!
Name DATA22: #REF!
Name DATA23: #REF!
Name DATA24: #REF!
Name DATA25: #REF!
Name DATA26: #REF!
Name DATA27: #REF!
Name DATA28: #REF!
Name DATA29: #REF!
Name DATA30: #REF!
Name DATA31: #REF!
Name DATA32: #REF!
Name DATA33: #REF!
Name DATA34: #REF!
Name DATA35: #REF!
Name DATA36: #REF!
Name DATA37: #REF!
Name Date_of_separation: #REF!
Name DeptCode: #REF!
Name dinhbien2021: #REF!
Name DivisionCode: #REF!
Name DoCty: #REF!
Name DoDM: #REF!
Name DoMD: #REF!
Name dow: #REF!
Name DT: #REF!
Name ERP: #REF!
Name Excise: #REF!
Name Expectations: #REF!
Name EXR: #REF!
Name fdg: #REF!
Name Finanacialsys: #REF!
Name Financialsys: #REF!

Sheet 0.KQKD
B2: KẾT QUẢ KINH DOANH (ĐVT: triệu đồng) | F2: TỔNG CỘNG NĂM | AJ2: THỰC HIỆN CHI TIẾT THÁNG 2026 | AV2: THỰC HIỆN THÁNG 5, 2026 | BA2: THỰC HIỆN LŨY KẾ 5 THÁNG 2026
B3: STT | C3: CHỈ TIÊU | E3: Mã tham chiếu | F3: 2022 | G3: 2023 | H3: 2024 | I3: 1 | J3: 2 | K3: 3 | L3: 4 | M3: 5 | N3: 6 | O3: 7 | P3: 8 | Q3: 9 | R3: 10 | S3: 11 | T3: 12 | U3: 2025 | V3: 1 | W3: 2 | X3: 3 | Y3: 4 | Z3: 5 | AA3: 6 | AB3: 7 | AC3: 8 | AD3: 9 | AE3: 10 | AF3: 11 | AG3: 12 | AH3: Kế hoạch 2026 | AI3: Ước thực hiện 2026 | AJ3: 1 | AK3: 2 | AL3: 3 | AM3: 4 | AN3: 5 | AO3: 6 | AP3: 7 | AQ3: 8 | AR3: 9 | AS3: 10 | AT3: 11 | AU3: 12 | AV3: Thực hiện T4.2026 | AW3: Thực hiện T5.2026 | AX3: Kế hoạch T5.2026 | AY3: So với TH T4.2026 | AZ3: So với KH T5.2026 | BA3: Thực hiện LK 2025 | BB3: Thực hiện LK 2026 | BC3: Kế hoạch LK 2026P | BD3: So với TH LK 2025 | BE3: So với KH LK 2026 | BF3: So với KH Năm 2026
B4: 1 | C4: SẢN LƯỢNG BÁN (Tấn) | E4: (*) | U4: =SUM(I4:T4) -> 0 | V4: 667500 | W4: 400500 | X4: 884000 | Y4: 984348 | Z4: 1025362.5 | AA4: 1025362.5 | AB4: 1066377 | AC4: 1067144 | AD4: 1026100 | AE4: 1066546 | AF4: 1025525 | AG4: 1066377 | AH4: =SUM(V4:AG4) -> 11305142 | AI4: =SUM(AJ4:AU4) -> 2738069 | AJ4: 513461 | AK4: 321709 | AL4: 698891 | AM4: 493240 | AN4: 710768 | AV4: =AM4 -> 493240 | AW4: =AN4 -> 710768 | AX4: =Z4 -> 1025362.5 | AY4: =IFERROR(AW4/AV4,0) -> 1.4410186 | AZ4: =IFERROR(AW4/AX4,0) -> 0.69318704 | BA4: =SUM(I4:M4) -> 0 | BB4: =SUM(AJ4:AN4) -> 2738069 | BC4: =SUM(V4:Z4) -> 3961710.5 | BD4: =IFERROR(BB4/BA4,0) -> 0 | BE4: =IFERROR(BB4/BC4,0) -> 0.69113303 | BF4: =IFERROR(BB4/AH4,0) -> 0.24219678
B5: 2 | C5: DOANH THU THUẦN | E5: (**) | U5: =SUM(I5:T5) -> 0 | V5: 9420187500 | W5: 5652112500 | X5: 12443100000 | Y5: 15779640000 | Z5: 16437125000 | AA5: 16437125000 | AB5: 17094610000 | AC5: 17118140000 | AD5: 16459750000 | AE5: 17105172500 | AF5: 16447281250 | AG5: 17094610000 | AH5: =SUM(V5:AG5) -> 177488853750 | AI5: =SUM(AJ5:AU5) -> 39568213997 | AJ5: 7320017770 | AK5: 4596489350 | AL5: 9617317135 | AM5: 7009495222 | AN5: 11024894520 | AV5: =AM5 -> 7009495222 | AW5: =AN5 -> 11024894520 | AX5: =Z5 -> 16437125000 | AY5: =IFERROR(AW5/AV5,0) -> 1.5728514 | AZ5: =IFERROR(AW5/AX5,0) -> 0.67073132 | BA5: =SUM(I5:M5) -> 0 | BB5: =SUM(AJ5:AN5) -> 39568213997 | BC5: =SUM(V5:Z5) -> 59732165000 | BD5: =IFERROR(BB5/BA5,0) -> 0 | BE5: =IFERROR(BB5/BC5,0) -> 0.66242725 | BF5: =IFERROR(BB5/AH5,0) -> 0.22293351
D6: Giá bán / Tấn (Triệu đồng/Tấn) | F6: =IFERROR(F5/F$4,0)*1000 -> 0 | G6: =IFERROR(G5/G$4,0)*1000 -> 0 | H6: =IFERROR(H5/H$4,0)*1000 -> 0 | I6: =IFERROR(I5/I$4,0)*1000 -> 0 | J6: =IFERROR(J5/J$4,0)*1000 -> 0 | K6: =IFERROR(K5/K$4,0)*1000 -> 0 | L6: =IFERROR(L5/L$4,0)*1000 -> 0 | M6: =IFERROR(M5/M$4,0)*1000 -> 0 | ... AX6: =IFERROR(AX5/AX$4,0)*1000 -> 16030550 | AY6: =IFERROR(AW6/AV6,0) -> 1.0914859 | AZ6: =IFERROR(AW6/AX6,0) -> 0.9676051 | BA6: =IFERROR(BA5/BA$4,0)*1000 -> 0 | BB6: =IFERROR(BB5/BB$4,0)*1000 -> 14451138 | BC6: =IFERROR(BC5/BC$4,0)*1000 -> 15077367 | BD6: =IFERROR(BB6/BA6,0) -> 0 | BE6: =IFERROR(BB6/BC6,0) -> 0.95846562 | BF6: =IFERROR(BB6/AH6,0) -> 0.9204644
B7: 3 | C7: BIẾN PHÍ | F7: =F10+F13 -> #REF! | G7: =G10+G13 -> #REF! | H7: =H10+H13 -> #REF! | I7: =I10+I13 -> #REF! | J7: =J10+J13 -> #REF! | K7: =K10+K13 -> #REF! | L7: =L10+L13 -> #REF! | M7: =M10+M13 -> #REF! | ... AU7: =AU10+AU13 -> 0 | AV7: =AM7 -> 5580731745 | AW7: =AN7 -> 8790464926 | AX7: =Z7 -> 1.4171683e+10 | AY7: =IFERROR(AW7/AV7,0) -> 1.5751456 | AZ7: =IFERROR(AW7/AX7,0) -> 0.62028376 | BA7: =SUM(I7:M7) -> #REF! | BB7: =SUM(AJ7:AN7) -> 31873001564 | BC7: =SUM(V7:Z7) -> 5.0855535e+10 | BD7: =IFERROR(BB7/BA7,0) -> 0 | BE7: =IFERROR(BB7/BC7,0) -> 0.62673614 | BF7: =IFERROR(BB7/AH7,0) -> 0.20924708
D8: Biến phí / Doanh thu (%) | F8: =IFERROR(F7/F$5,0) -> 0 | G8: =IFERROR(G7/G$5,0) -> 0 | H8: =IFERROR(H7/H$5,0) -> 0 | I8: =IFERROR(I7/I$5,0) -> 0 | J8: =IFERROR(J7/J$5,0) -> 0 | K8: =IFERROR(K7/K$5,0) -> 0 | L8: =IFERROR(L7/L$5,0) -> 0 | M8: =IFERROR(M7/M$5,0) -> 0 | ... AX8: =IFERROR(AX7/AX$5,0) -> 0.8621753 | AY8: =IFERROR(AW8/AV8,0) -> 1.0014586 | AZ8: =IFERROR(AW8/AX8,0) -> 0.92478723 | BA8: =IFERROR(BA7/BA$5,0) -> 0 | BB8: =IFERROR(BB7/BB$5,0) -> 0.80552035 | BC8: =IFERROR(BC7/BC$5,0) -> 0.85139279 | BD8: =IFERROR(BB8/BA8,0) -> 0 | BE8: =IFERROR(BB8/BC8,0) -> 0.94612071 | BF8: =IFERROR(BB8/AH8,0) -> 0.93860754
D9: Biến phí / Tấn (Triệu đồng/Tấn) | F9: =IFERROR(F7/F$4,0)*1000 -> 0 | G9: =IFERROR(G7/G$4,0)*1000 -> 0 | H9: =IFERROR(H7/H$4,0)*1000 -> 0 | I9: =IFERROR(I7/I$4,0)*1000 -> 0 | J9: =IFERROR(J7/J$4,0)*1000 -> 0 | K9: =IFERROR(K7/K$4,0)*1000 -> 0 | L9: =IFERROR(L7/L$4,0)*1000 -> 0 | M9: =IFERROR(M7/M$4,0)*1000 -> 0 | ... AX9: =IFERROR(AX7/AX$4,0)*1000 -> 13821144 | AY9: =IFERROR(AW9/AV9,0) -> 1.0930779 | AZ9: =IFERROR(AW9/AX9,0) -> 0.89482884 | BA9: =IFERROR(BA7/BA$4,0)*1000 -> 0 | BB9: =IFERROR(BB7/BB$4,0)*1000 -> 11640686 | BC9: =IFERROR(BC7/BC$4,0)*1000 -> 12836762 | BD9: =IFERROR(BB9/BA9,0) -> 0 | BE9: =IFERROR(BB9/BC9,0) -> 0.90682417 | BF9: =IFERROR(BB9/AH9,0) -> 0.86395483
B10: 3.1 | C10: Biến phí bán hàng | E10: 01,02,03 | F10: =SUMIF('10. 170KMP'!$J:$J,"1",'10. 170KMP'!L:L) -> #REF! | G10: =SUMIF('10. 170KMP'!$J:$J,"1",'10. 170KMP'!M:M) -> #REF! | H10: =SUMIF('10. 170KMP'!$J:$J,"1",'10. 170KMP'!N:N) -> #REF! | I10: =SUMIF('10. 170KMP'!$J:$J,"1",'10. 170KMP'!O:O) -> #REF! | J10: =SUMIF('10. 170KMP'!$J:$J,"1",'10. 170KMP'!P:P) -> #REF! | K10: =SUMIF('10. 170KMP'!$J:$J,"1",'10. 170KMP'!Q:Q) -> #REF! | L10: =SUMIF('10. 170KMP'!$J:$J,"1",'10. 170KMP'!R:R) -> #REF! | M10: =SUMIF('10. 170KMP'!$J:$J,"1",'10. 170KMP'!S:S) -> #REF! | N10: =SUMIF('10. 170KMP'!$J:$J,"1",'10. 170KMP'!T:T) -> #REF! | O10: =SUMIF('10. 170KMP'!$J:$J,"1",'10. 170KMP'!U:U) -> #REF! | P10: =SUMIF('10. 170KMP'!$J:$J,"1",'10. 170KMP'!V:V) -> #REF! | Q10: =SUMIF('10. 170KMP'!$J:$J,"1",'10. 170KMP'!W:W) -> #REF! | R10: =SUMIF('10. 170KMP'!$J:$J,"1",'10. 170KMP'!X:X) -> #REF! | S10: =SUMIF('10. 170KMP'!$J:$J,"1",'10. 170KMP'!Y:Y) -> #REF! | T10: =SUMIF('10. 170KMP'!$J:$J,"1",'10. 170KMP'!Z:Z) -> #REF! | U10: =SUMIF('10. 170KMP'!$J:$J,"1",'10. 170KMP'!AA:AA) -> #REF! | V10: =SUMIF('10. 170KMP'!$J:$J,"1",'10. 170KMP'!AB:AB) -> 267000000 | W10: =SUMIF('10. 170KMP'!$J:$J,"1",'10. 170KMP'!AC:AC) -> 160200000 | X10: =SUMIF('10. 170KMP'!$J:$J,"1",'10. 170KMP'!AD:AD) -> 353600000 | Y10: =SUMIF('10. 170KMP'!$J:$J,"1",'10. 170KMP'!AE:AE) -> 317703360 | Z10: =SUMIF('10. 170KMP'!$J:$J,"1",'10. 170KMP'!AF:AF) -> 330941000 | AA10: =SUMIF('10. 170KMP'!$J:$J,"1",'10. 170KMP'!AG:AG) -> 330941000 | AB10: =SUMIF('10. 170KMP'!$J:$J,"1",'10. 170KMP'!AH:AH) -> 344178640 | AC10: =SUMIF('10. 170KMP'!$J:$J,"1",'10. 170KMP'!AI:AI) -> 344398080 | AD10: =SUMIF('10. 170KMP'!$J:$J,"1",'10. 170KMP'!AJ:AJ) -> 331152000 | AE10: =SUMIF('10. 170KMP'!$J:$J,"1",'10. 170KMP'!AK:AK) -> 344232720 | AF10: =SUMIF('10. 170KMP'!$J:$J,"1",'10. 170KMP'!AL:AL) -> 330993000 | AG10: =SUMIF('10. 170KMP'!$J:$J,"1",'10. 170KMP'!AM:AM) -> 344178640 | AH10: =SUMIF('10. 170KMP'!$J:$J,"1",'10. 170KMP'!AN:AN) -> 3799518440 | AI10: =SUMIF('10. 170KMP'!$J:$J,"1",'10. 170KMP'!AO:AO) -> 1047100000 | AJ10: =SUMIF('10. 170KMP'!$J:$J,"1",'10. 170KMP'!AP:AP) -> 195900000 | AK10: =SUMIF('10. 170KMP'!$J:$J,"1",'10. 170KMP'!AQ:AQ) -> 121800000 | AL10: =SUMIF('10. 170KMP'!$J:$J,"1",'10. 170KMP'!AR:AR) -> 271300000 | AM10: =SUMIF('10. 170KMP'!$J:$J,"1",'10. 170KMP'!AS:AS) -> 195300000 | AN10: =SUMIF('10. 170KMP'!$J:$J,"1",'10. 170KMP'!AT:AT) -> 262800000 | AO10: =SUMIF('10. 170KMP'!$J:$J,"1",'10. 170KMP'!AU:AU) -> 0 | AP10: =SUMIF('10. 170KMP'!$J:$J,"1",'10. 170KMP'!AV:AV) -> 0 | AQ10: =SUMIF('10. 170KMP'!$J:$J,"1",'10. 170KMP'!AW:AW) -> 0 | AR10: =SUMIF('10. 170KMP'!$J:$J,"1",'10. 170KMP'!AX:AX) -> 0 | AS10: =SUMIF('10. 170KMP'!$J:$J,"1",'10. 170KMP'!AY:AY) -> 0 | AT10: =SUMIF('10. 170KMP'!$J:$J,"1",'10. 170KMP'!AZ:AZ) -> 0 | AU10: =SUMIF('10. 170KMP'!$J:$J,"1",'10. 170KMP'!BA:BA) -> 0 | AV10: =AM10 -> 195300000 | AW10: =AN10 -> 262800000 | AX10: =Z10 -> 330941000 | AY10: =IFERROR(AW10/AV10,0) -> 1.3456221 | AZ10: =IFERROR(AW10/AX10,0) -> 0.79409925 | BA10: =SUM(I10:M10) -> #REF! | BB10: =SUM(AJ10:AN10) -> 1047100000 | BC10: =SUM(V10:Z10) -> 1429444360 | BD10: =IFERROR(BB10/BA10,0) -> 0 | BE10: =IFERROR(BB10/BC10,0) -> 0.73252239 | BF10: =IFERROR(BB10/AH10,0) -> 0.27558756
D11: Biến phí / Doanh thu (%) | F11: =IFERROR(F10/F$5,0) -> 0 | G11: =IFERROR(G10/G$5,0) -> 0 | H11: =IFERROR(H10/H$5,0) -> 0 | I11: =IFERROR(I10/I$5,0) -> 0 | J11: =IFERROR(J10/J$5,0) -> 0 | K11: =IFERROR(K10/K$5,0) -> 0 | L11: =IFERROR(L10/L$5,0) -> 0 | M11: =IFERROR(M10/M$5,0) -> 0 | ... AX11: =IFERROR(AX10/AX$5,0) -> 0.020133752 | AY11: =IFERROR(AW11/AV11,0) -> 0.85553035 | AZ11: =IFERROR(AW11/AX11,0) -> 1.1839305 | BA11: =IFERROR(BA10/BA$5,0) -> 0 | BB11: =IFERROR(BB10/BB$5,0) -> 0.026463161 | BC11: =IFERROR(BC10/BC$5,0) -> 0.023930898 | BD11: =IFERROR(BB11/BA11,0) -> 0 | BE11: =IFERROR(BB11/BC11,0) -> 1.1058156 | BF11: =IFERROR(BB11/AH11,0) -> 1.2361872
D12: Biến phí / Tấn (Triệu đồng/Tấn) | F12: =IFERROR(F10/F$4,0)*1000 -> 0 | G12: =IFERROR(G10/G$4,0)*1000 -> 0 | H12: =IFERROR(H10/H$4,0)*1000 -> 0 | I12: =IFERROR(I10/I$4,0)*1000 -> 0 | J12: =IFERROR(J10/J$4,0)*1000 -> 0 | K12: =IFERROR(K10/K$4,0)*1000 -> 0 | L12: =IFERROR(L10/L$4,0)*1000 -> 0 | M12: =IFERROR(M10/M$4,0)*1000 -> 0 | ... AX12: =IFERROR(AX10/AX$4,0)*1000 -> 322755.12 | AY12: =IFERROR(AW12/AV12,0) -> 0.93379929 | AZ12: =IFERROR(AW12/AX12,0) -> 1.1455772 | BA12: =IFERROR(BA10/BA$4,0)*1000 -> 0 | BB12: =IFERROR(BB10/BB$4,0)*1000 -> 382422.8 | BC12: =IFERROR(BC10/BC$4,0)*1000 -> 360814.95 | BD12: =IFERROR(BB12/BA12,0) -> 0 | BE12: =IFERROR(BB12/BC12,0) -> 1.0598862 | BF12: =IFERROR(BB12/AH12,0) -> 1.1378663
B13: 3.2 | C13: Biến phí sản xuất | F13: =F16+F17+F19+F20+F21+F22+F23+F24+F25+F26 -> #REF! | G13: =G16+G17+G19+G20+G21+G22+G23+G24+G25+G26 -> #REF! | H13: =H16+H17+H19+H20+H21+H22+H23+H24+H25+H26 -> #REF! | I13: =I16+I17+I19+I20+I21+I22+I23+I24+I25+I26 -> #REF! | J13: =J16+J17+J19+J20+J21+J22+J23+J24+J25+J26 -> #REF! | K13: =K16+K17+K19+K20+K21+K22+K23+K24+K25+K26 -> #REF! | L13: =L16+L17+L19+L20+L21+L22+L23+L24+L25+L26 -> #REF! | M13: =M16+M17+M19+M20+M21+M22+M23+M24+M25+M26 -> #REF! | ... AU13: =AU16+AU17+AU19+AU20+AU21+AU22+AU23+AU24+AU25+AU26 -> 0 | AV13: =AM13 -> 5385431745 | AW13: =AN13 -> 8527664926 | AX13: =Z13 -> 1.3840742e+10 | AY13: =IFERROR(AW13/AV13,0) -> 1.5834691 | AZ13: =IFERROR(AW13/AX13,0) -> 0.61612772 | BA13: =SUM(I13:M13) -> #REF! | BB13: =SUM(AJ13:AN13) -> 30825901564 | BC13: =SUM(V13:Z13) -> 4.942609e+10 | BD13: =IFERROR(BB13/BA13,0) -> 0 | BE13: =IFERROR(BB13/BC13,0) -> 0.62367671 | BF13: =IFERROR(BB13/AH13,0) -> 0.20754995
D14: Biến phí sản xuất/ Doanh thu (%) | F14: =IFERROR(F13/F$5,0) -> 0 | G14: =IFERROR(G13/G$5,0) -> 0 | H14: =IFERROR(H13/H$5,0) -> 0 | I14: =IFERROR(I13/I$5,0) -> 0 | J14: =IFERROR(J13/J$5,0) -> 0 | K14: =IFERROR(K13/K$5,0) -> 0 | L14: =IFERROR(L13/L$5,0) -> 0 | M14: =IFERROR(M13/M$5,0) -> 0 | ... AX14: =IFERROR(AX13/AX$5,0) -> 0.84204155 | AY14: =IFERROR(AW14/AV14,0) -> 1.0067506 | AZ14: =IFERROR(AW14/AX14,0) -> 0.91859095 | BA14: =IFERROR(BA13/BA$5,0) -> 0 | BB14: =IFERROR(BB13/BB$5,0) -> 0.77905719 | BC14: =IFERROR(BC13/BC$5,0) -> 0.82746189 | BD14: =IFERROR(BB14/BA14,0) -> 0 | BE14: =IFERROR(BB14/BC14,0) -> 0.9415022 | BF14: =IFERROR(BB14/AH14,0) -> 0.93099484
D15: Biến phí sản xuất/ Tấn (Triệu đồng/Tấn) | F15: =IFERROR(F13/F$4,0)*1000 -> 0 | G15: =IFERROR(G13/G$4,0)*1000 -> 0 | H15: =IFERROR(H13/H$4,0)*1000 -> 0 | I15: =IFERROR(I13/I$4,0)*1000 -> 0 | J15: =IFERROR(J13/J$4,0)*1000 -> 0 | K15: =IFERROR(K13/K$4,0)*1000 -> 0 | L15: =IFERROR(L13/L$4,0)*1000 -> 0 | M15: =IFERROR(M13/M$4,0)*1000 -> 0 | ... AX15: =IFERROR(AX13/AX$4,0)*1000 -> 13498389 | AY15: =IFERROR(AW15/AV15,0) -> 1.0988541 | AZ15: =IFERROR(AW15/AX15,0) -> 0.88883328 | BA15: =IFERROR(BA13/BA$4,0)*1000 -> 0 | BB15: =IFERROR(BB13/BB$4,0)*1000 -> 11258263 | BC15: =IFERROR(BC13/BC$4,0)*1000 -> 12475947 | BD15: =IFERROR(BB15/BA15,0) -> 0 | BE15: =IFERROR(BB15/BC15,0) -> 0.90239749 | BF15: =IFERROR(BB15/AH15,0) -> 0.85694761
D16: Chi phí nguyên liệu vật chính | E16: 04 | F16: =SUMIF('10. 170KMP'!$J:$J,'0.KQKD'!$E16,'10. 170KMP'!L:L) -> #REF! | G16: =SUMIF('10. 170KMP'!$J:$J,'0.KQKD'!$E16,'10. 170KMP'!M:M) -> #REF! | H16: =SUMIF('10. 170KMP'!$J:$J,'0.KQKD'!$E16,'10. 170KMP'!N:N) -> #REF! | I16: =SUMIF('10. 170KMP'!$J:$J,'0.KQKD'!$E16,'10. 170KMP'!O:O) -> #REF! | J16: =SUMIF('10. 170KMP'!$J:$J,'0.KQKD'!$E16,'10. 170KMP'!P:P) -> #REF! | K16: =SUMIF('10. 170KMP'!$J:$J,'0.KQKD'!$E16,'10. 170KMP'!Q:Q) -> #REF! | L16: =SUMIF('10. 170KMP'!$J:$J,'0.KQKD'!$E16,'10. 170KMP'!R:R) -> #REF! | M16: =SUMIF('10. 170KMP'!$J:$J,'0.KQKD'!$E16,'10. 170KMP'!S:S) -> #REF! | N16: =SUMIF('10. 170KMP'!$J:$J,'0.KQKD'!$E16,'10. 170KMP'!T:T) -> #REF! | O16: =SUMIF('10. 170KMP'!$J:$J,'0.KQKD'!$E16,'10. 170KMP'!U:U) -> #REF! | P16: =SUMIF('10. 170KMP'!$J:$J,'0.KQKD'!$E16,'10. 170KMP'!V:V) -> #REF! | Q16: =SUMIF('10. 170KMP'!$J:$J,'0.KQKD'!$E16,'10. 170KMP'!W:W) -> #REF! | R16: =SUMIF('10. 170KMP'!$J:$J,'0.KQKD'!$E16,'10. 170KMP'!X:X) -> #REF! | S16: =SUMIF('10. 170KMP'!$J:$J,'0.KQKD'!$E16,'10. 170KMP'!Y:Y) -> #REF! | T16: =SUMIF('10. 170KMP'!$J:$J,'0.KQKD'!$E16,'10. 170KMP'!Z:Z) -> #REF! | U16: =SUM(I16:T16) -> #REF! | V16: =SUMIF('10. 170KMP'!$J:$J,'0.KQKD'!$E16,'10. 170KMP'!AB:AB) -> 7275000000 | W16: =SUMIF('10. 170KMP'!$J:$J,'0.KQKD'!$E16,'10. 170KMP'!AC:AC) -> 4275000000 | X16: =SUMIF('10. 170KMP'!$J:$J,'0.KQKD'!$E16,'10. 170KMP'!AD:AD) -> 10000000000 | Y16: =SUMIF('10. 170KMP'!$J:$J,'0.KQKD'!$E16,'10. 170KMP'!AE:AE) -> 12000000000 | Z16: =SUMIF('10. 170KMP'!$J:$J,'0.KQKD'!$E16,'10. 170KMP'!AF:AF) -> 12500000000 | AA16: =SUMIF('10. 170KMP'!$J:$J,'0.KQKD'!$E16,'10. 170KMP'!AG:AG) -> 12500000000 | AB16: =SUMIF('10. 170KMP'!$J:$J,'0.KQKD'!$E16,'10. 170KMP'!AH:AH) -> 13000000000 | AC16: =SUMIF('10. 170KMP'!$J:$J,'0.KQKD'!$E16,'10. 170KMP'!AI:AI) -> 13000000000 | AD16: =SUMIF('10. 170KMP'!$J:$J,'0.KQKD'!$E16,'10. 170KMP'!AJ:AJ) -> 12500000000 | AE16: =SUMIF('10. 170KMP'!$J:$J,'0.KQKD'!$E16,'10. 170KMP'!AK:AK) -> 13000000000 | AF16: =SUMIF('10. 170KMP'!$J:$J,'0.KQKD'!$E16,'10. 170KMP'!AL:AL) -> 12500000000 | AG16: =SUMIF('10. 170KMP'!$J:$J,'0.KQKD'!$E16,'10. 170KMP'!AM:AM) -> 13000000000 | AH16: =SUM(V16:AG16) -> 135550000000 | AI16: =SUM(AJ16:AU16) -> 29843104307 | AJ16: =SUMIF('10. 170KMP'!$J:$J,'0.KQKD'!$E16,'10. 170KMP'!AP:AP) -> 5578831855 | AK16: =SUMIF('10. 170KMP'!$J:$J,'0.KQKD'!$E16,'10. 170KMP'!AQ:AQ) -> 3437777528 | AL16: =SUMIF('10. 170KMP'!$J:$J,'0.KQKD'!$E16,'10. 170KMP'!AR:AR) -> 7441576343 | AM16: =SUMIF('10. 170KMP'!$J:$J,'0.KQKD'!$E16,'10. 170KMP'!AS:AS) -> 5155085629 | AN16: =SUMIF('10. 170KMP'!$J:$J,'0.KQKD'!$E16,'10. 170KMP'!AT:AT) -> 8229832952 | AO16: =SUMIF('10. 170KMP'!$J:$J,'0.KQKD'!$E16,'10. 170KMP'!AU:AU) -> 0 | AP16: =SUMIF('10. 170KMP'!$J:$J,'0.KQKD'!$E16,'10. 170KMP'!AV:AV) -> 0 | AQ16: =SUMIF('10. 170KMP'!$J:$J,'0.KQKD'!$E16,'10. 170KMP'!AW:AW) -> 0 | AR16: =SUMIF('10. 170KMP'!$J:$J,'0.KQKD'!$E16,'10. 170KMP'!AX:AX) -> 0 | AS16: =SUMIF('10. 170KMP'!$J:$J,'0.KQKD'!$E16,'10. 170KMP'!AY:AY) -> 0 | AT16: =SUMIF('10. 170KMP'!$J:$J,'0.KQKD'!$E16,'10. 170KMP'!AZ:AZ) -> 0 | AU16: =SUMIF('10. 170KMP'!$J:$J,'0.KQKD'!$E16,'10. 170KMP'!BA:BA) -> 0 | AV16: =AM16 -> 5155085629 | AW16: =AN16 -> 8229832952 | AX16: =Z16 -> 12500000000 | AY16: =IFERROR(AW16/AV16,0) -> 1.5964493 | AZ16: =IFERROR(AW16/AX16,0) -> 0.65838664 | BA16: =SUM(I16:M16) -> #REF! | BB16: =SUM(AJ16:AN16) -> 29843104307 | BC16: =SUM(V16:Z16) -> 46050000000 | BD16: =IFERROR(BB16/BA16,0) -> 0 | BE16: =IFERROR(BB16/BC16,0) -> 0.64805873 | BF16: =IFERROR(BB16/AH16,0) -> 0.22016307
D17: Chi phí nguyên vật liệu phụ | E17: 05 | F17: =SUMIF('10. 170KMP'!$J:$J,'0.KQKD'!$E17,'10. 170KMP'!L:L) -> #REF! | G17: =SUMIF('10. 170KMP'!$J:$J,'0.KQKD'!$E17,'10. 170KMP'!M:M) -> #REF! | H17: =SUMIF('10. 170KMP'!$J:$J,'0.KQKD'!$E17,'10. 170KMP'!N:N) -> #REF! | I17: =SUMIF('10. 170KMP'!$J:$J,'0.KQKD'!$E17,'10. 170KMP'!O:O) -> #REF! | J17: =SUMIF('10. 170KMP'!$J:$J,'0.KQKD'!$E17,'10. 170KMP'!P:P) -> #REF! | K17: =SUMIF('10. 170KMP'!$J:$J,'0.KQKD'!$E17,'10. 170KMP'!Q:Q) -> #REF! | L17: =SUMIF('10. 170KMP'!$J:$J,'0.KQKD'!$E17,'10. 170KMP'!R:R) -> #REF! | M17: =SUMIF('10. 170KMP'!$J:$J,'0.KQKD'!$E17,'10. 170KMP'!S:S) -> #REF! | N17: =SUMIF('10. 170KMP'!$J:$J,'0.KQKD'!$E17,'10. 170KMP'!T:T) -> #REF! | O17: =SUMIF('10. 170KMP'!$J:$J,'0.KQKD'!$E17,'10. 170KMP'!U:U) -> #REF! | P17: =SUMIF('10. 170KMP'!$J:$J,'0.KQKD'!$E17,'10. 170KMP'!V:V) -> #REF! | Q17: =SUMIF('10. 170KMP'!$J:$J,'0.KQKD'!$E17,'10. 170KMP'!W:W) -> #REF! | R17: =SUMIF('10. 170KMP'!$J:$J,'0.KQKD'!$E17,'10. 170KMP'!X:X) -> #REF! | S17: =SUMIF('10. 170KMP'!$J:$J,'0.KQKD'!$E17,'10. 170KMP'!Y:Y) -> #REF! | T17: =SUMIF('10. 170KMP'!$J:$J,'0.KQKD'!$E17,'10. 170KMP'!Z:Z) -> #REF! | U17: =SUM(I17:T17) -> #REF! | V17: =SUMIF('10. 170KMP'!$J:$J,'0.KQKD'!$E17,'10. 170KMP'!AB:AB) -> 0 | W17: =SUMIF('10. 170KMP'!$J:$J,'0.KQKD'!$E17,'10. 170KMP'!AC:AC) -> 0 | X17: =SUMIF('10. 170KMP'!$J:$J,'0.KQKD'!$E17,'10. 170KMP'!AD:AD) -> 0 | Y17: =SUMIF('10. 170KMP'!$J:$J,'0.KQKD'!$E17,'10. 170KMP'!AE:AE) -> 0 | Z17: =SUMIF('10. 170KMP'!$J:$J,'0.KQKD'!$E17,'10. 170KMP'!AF:AF) -> 0 | AA17: =SUMIF('10. 170KMP'!$J:$J,'0.KQKD'!$E17,'10. 170KMP'!AG:AG) -> 0 | AB17: =SUMIF('10. 170KMP'!$J:$J,'0.KQKD'!$E17,'10. 170KMP'!AH:AH) -> 0 | AC17: =SUMIF('10. 170KMP'!$J:$J,'0.KQKD'!$E17,'10. 170KMP'!AI:AI) -> 0 | AD17: =SUMIF('10. 170KMP'!$J:$J,'0.KQKD'!$E17,'10. 170KMP'!AJ:AJ) -> 0 | AE17: =SUMIF('10. 170KMP'!$J:$J,'0.KQKD'!$E17,'10. 170KMP'!AK:AK) -> 0 | AF17: =SUMIF('10. 170KMP'!$J:$J,'0.KQKD'!$E17,'10. 170KMP'!AL:AL) -> 0 | AG17: =SUMIF('10. 170KMP'!$J:$J,'0.KQKD'!$E17,'10. 170KMP'!AM:AM) -> 0 | AH17: =SUM(V17:AG17) -> 0 | AI17: =SUM(AJ17:AU17) -> 0 | AJ17: =SUMIF('10. 170KMP'!$J:$J,'0.KQKD'!$E17,'10. 170KMP'!AP:AP) -> 0 | AK17: =SUMIF('10. 170KMP'!$J:$J,'0.KQKD'!$E17,'10. 170KMP'!AQ:AQ) -> 0 | AL17: =SUMIF('10. 170KMP'!$J:$J,'0.KQKD'!$E17,'10. 170KMP'!AR:AR) -> 0 | AM17: =SUMIF('10. 170KMP'!$J:$J,'0.KQKD'!$E17,'10. 170KMP'!AS:AS) -> 0 | AN17: =SUMIF('10. 170KMP'!$J:$J,'0.KQKD'!$E17,'10. 170KMP'!AT:AT) -> 0 | AO17: =SUMIF('10. 170KMP'!$J:$J,'0.KQKD'!$E17,'10. 170KMP'!AU:AU) -> 0 | AP17: =SUMIF('10. 170KMP'!$J:$J,'0.KQKD'!$E17,'10. 170KMP'!AV:AV) -> 0 | AQ17: =SUMIF('10. 170KMP'!$J:$J,'0.KQKD'!$E17,'10. 170KMP'!AW:AW) -> 0 | AR17: =SUMIF('10. 170KMP'!$J:$J,'0.KQKD'!$E17,'10. 170KMP'!AX:AX) -> 0 | AS17: =SUMIF('10. 170KMP'!$J:$J,'0.KQKD'!$E17,'10. 170KMP'!AY:AY) -> 0 | AT17: =SUMIF('10. 170KMP'!$J:$J,'0.KQKD'!$E17,'10. 170KMP'!AZ:AZ) -> 0 | AU17: =SUMIF('10. 170KMP'!$J:$J,'0.KQKD'!$E17,'10. 170KMP'!BA:BA) -> 0 | AV17: =AM17 -> 0 | AW17: =AN17 -> 0 | AX17: =Z17 -> 0 | AY17: =IFERROR(AW17/AV17,0) -> 0 | AZ17: =IFERROR(AW17/AX17,0) -> 0 | BA17: =SUM(I17:M17) -> #REF! | BB17: =SUM(AJ17:AN17) -> 0 | BC17: =SUM(V17:Z17) -> 0 | BD17: =IFERROR(BB17/BA17,0) -> 0 | BE17: =IFERROR(BB17/BC17,0) -> 0 | BF17: =IFERROR(BB17/AH17,0) -> 0
D18: Lãi nguyên liệu / Doanh thu (%) | F18: =IFERROR((F5-F16-F17)/F$5,0) -> 0 | G18: =IFERROR((G5-G16-G17)/G$5,0) -> 0 | H18: =IFERROR((H5-H16-H17)/H$5,0) -> 0 | I18: =IFERROR((I5-I16-I17)/I$5,0) -> 0 | J18: =IFERROR((J5-J16-J17)/J$5,0) -> 0 | K18: =IFERROR((K5-K16-K17)/K$5,0) -> 0 | L18: =IFERROR((L5-L16-L17)/L$5,0) -> 0 | M18: =IFERROR((M5-M16-M17)/M$5,0) -> 0 | ... AX18: =IFERROR((AX5-AX16-AX17)/AX$5,0) -> 0.23952638 | AY18: =IFERROR(AW18/AV18,0) -> 0.95829234 | AZ18: =IFERROR(AW18/AX18,0) -> 1.0584335 | BA18: =IFERROR((BA5-BA16-BA17)/BA$5,0) -> 0 | BB18: =IFERROR((BB5-BB16-BB17)/BB$5,0) -> 0.24578086 | BC18: =IFERROR((BC5-BC16-BC17)/BC$5,0) -> 0.22905858 | BD18: =IFERROR(BB18/BA18,0) -> 0 | BE18: =IFERROR(BB18/BC18,0) -> 1.0730044 | BF18: =IFERROR(BB18/AH18,0) -> 1.0401658
D19: Chi phí vật tư kỹ thuật phục vụ sản xuất | E19: 06 | F19: =SUMIF('10. 170KMP'!$J:$J,'0.KQKD'!$E19,'10. 170KMP'!L:L) -> #REF! | G19: =SUMIF('10. 170KMP'!$J:$J,'0.KQKD'!$E19,'10. 170KMP'!M:M) -> #REF! | H19: =SUMIF('10. 170KMP'!$J:$J,'0.KQKD'!$E19,'10. 170KMP'!N:N) -> #REF! | I19: =SUMIF('10. 170KMP'!$J:$J,'0.KQKD'!$E19,'10. 170KMP'!O:O) -> #REF! | J19: =SUMIF('10. 170KMP'!$J:$J,'0.KQKD'!$E19,'10. 170KMP'!P:P) -> #REF! | K19: =SUMIF('10. 170KMP'!$J:$J,'0.KQKD'!$E19,'10. 170KMP'!Q:Q) -> #REF! | L19: =SUMIF('10. 170KMP'!$J:$J,'0.KQKD'!$E19,'10. 170KMP'!R:R) -> #REF! | M19: =SUMIF('10. 170KMP'!$J:$J,'0.KQKD'!$E19,'10. 170KMP'!S:S) -> #REF! | N19: =SUMIF('10. 170KMP'!$J:$J,'0.KQKD'!$E19,'10. 170KMP'!T:T) -> #REF! | O19: =SUMIF('10. 170KMP'!$J:$J,'0.KQKD'!$E19,'10. 170KMP'!U:U) -> #REF! | P19: =SUMIF('10. 170KMP'!$J:$J,'0.KQKD'!$E19,'10. 170KMP'!V:V) -> #REF! | Q19: =SUMIF('10. 170KMP'!$J:$J,'0.KQKD'!$E19,'10. 170KMP'!W:W) -> #REF! | R19: =SUMIF('10. 170KMP'!$J:$J,'0.KQKD'!$E19,'10. 170KMP'!X:X) -> #REF! | S19: =SUMIF('10. 170KMP'!$J:$J,'0.KQKD'!$E19,'10. 170KMP'!Y:Y) -> #REF! | T19: =SUMIF('10. 170KMP'!$J:$J,'0.KQKD'!$E19,'10. 170KMP'!Z:Z) -> #REF! | U19: =SUM(I19:T19) -> #REF! | V19: =SUMIF('10. 170KMP'!$J:$J,'0.KQKD'!$E19,'10. 170KMP'!AB:AB) -> 44281989 | W19: =SUMIF('10. 170KMP'!$J:$J,'0.KQKD'!$E19,'10. 170KMP'!AC:AC) -> 27769193 | X19: =SUMIF('10. 170KMP'!$J:$J,'0.KQKD'!$E19,'10. 170KMP'!AD:AD) -> 57671578 | Y19: =SUMIF('10. 170KMP'!$J:$J,'0.KQKD'!$E19,'10. 170KMP'!AE:AE) -> 73568786 | Z19: =SUMIF('10. 170KMP'!$J:$J,'0.KQKD'!$E19,'10. 170KMP'!AF:AF) -> 1.7969125e+08 | AA19: =SUMIF('10. 170KMP'!$J:$J,'0.KQKD'!$E19,'10. 170KMP'!AG:AG) -> 1.7969125e+08 | AB19: =SUMIF('10. 170KMP'!$J:$J,'0.KQKD'!$E19,'10. 170KMP'!AH:AH) -> 1.865589e+08 | AC19: =SUMIF('10. 170KMP'!$J:$J,'0.KQKD'!$E19,'10. 170KMP'!AI:AI) -> 1.8671313e+08 | AD19: =SUMIF('10. 170KMP'!$J:$J,'0.KQKD'!$E19,'10. 170KMP'!AJ:AJ) -> 1.7983955e+08 | AE19: =SUMIF('10. 170KMP'!$J:$J,'0.KQKD'!$E19,'10. 170KMP'!AK:AK) -> 1.8657654e+08 | AF19: =SUMIF('10. 170KMP'!$J:$J,'0.KQKD'!$E19,'10. 170KMP'!AL:AL) -> 1.7970822e+08 | AG19: =SUMIF('10. 170KMP'!$J:$J,'0.KQKD'!$E19,'10. 170KMP'!AM:AM) -> 1.865589e+08 | AH19: =SUM(V19:AG19) -> 1.6686293e+09 | AI19: =SUM(AJ19:AU19) -> 123875011 | AJ19: =SUMIF('10. 170KMP'!$J:$J,'0.KQKD'!$E19,'10. 170KMP'!AP:AP) -> 12043011 | AK19: =SUMIF('10. 170KMP'!$J:$J,'0.KQKD'!$E19,'10. 170KMP'!AQ:AQ) -> 0 | AL19: =SUMIF('10. 170KMP'!$J:$J,'0.KQKD'!$E19,'10. 170KMP'!AR:AR) -> 0 | AM19: =SUMIF('10. 170KMP'!$J:$J,'0.KQKD'!$E19,'10. 170KMP'!AS:AS) -> 56483000 | AN19: =SUMIF('10. 170KMP'!$J:$J,'0.KQKD'!$E19,'10. 170KMP'!AT:AT) -> 55349000 | AO19: =SUMIF('10. 170KMP'!$J:$J,'0.KQKD'!$E19,'10. 170KMP'!AU:AU) -> 0 | AP19: =SUMIF('10. 170KMP'!$J:$J,'0.KQKD'!$E19,'10. 170KMP'!AV:AV) -> 0 | AQ19: =SUMIF('10. 170KMP'!$J:$J,'0.KQKD'!$E19,'10. 170KMP'!AW:AW) -> 0 | AR19: =SUMIF('10. 170KMP'!$J:$J,'0.KQKD'!$E19,'10. 170KMP'!AX:AX) -> 0 | AS19: =SUMIF('10. 170KMP'!$J:$J,'0.KQKD'!$E19,'10. 170KMP'!AY:AY) -> 0 | AT19: =SUMIF('10. 170KMP'!$J:$J,'0.KQKD'!$E19,'10. 170KMP'!AZ:AZ) -> 0 | AU19: =SUMIF('10. 170KMP'!$J:$J,'0.KQKD'!$E19,'10. 170KMP'!BA:BA) -> 0 | AV19: =AM19 -> 56483000 | AW19: =AN19 -> 55349000 | AX19: =Z19 -> 1.7969125e+08 | AY19: =IFERROR(AW19/AV19,0) -> 0.97992316 | AZ19: =IFERROR(AW19/AX19,0) -> 0.3080228 | BA19: =SUM(I19:M19) -> #REF! | BB19: =SUM(AJ19:AN19) -> 123875011 | BC19: =SUM(V19:Z19) -> 3.8298279e+08 | BD19: =IFERROR(BB19/BA19,0) -> 0 | BE19: =IFERROR(BB19/BC19,0) -> 0.32344798 | BF19: =IFERROR(BB19/AH19,0) -> 0.074237587
D20: Chi phí bao bì | E20: 07 | F20: =SUMIF('10. 170KMP'!$J:$J,'0.KQKD'!$E20,'10. 170KMP'!L:L) -> #REF! | G20: =SUMIF('10. 170KMP'!$J:$J,'0.KQKD'!$E20,'10. 170KMP'!M:M) -> #REF! | H20: =SUMIF('10. 170KMP'!$J:$J,'0.KQKD'!$E20,'10. 170KMP'!N:N) -> #REF! | I20: =SUMIF('10. 170KMP'!$J:$J,'0.KQKD'!$E20,'10. 170KMP'!O:O) -> #REF! | J20: =SUMIF('10. 170KMP'!$J:$J,'0.KQKD'!$E20,'10. 170KMP'!P:P) -> #REF! | K20: =SUMIF('10. 170KMP'!$J:$J,'0.KQKD'!$E20,'10. 170KMP'!Q:Q) -> #REF! | L20: =SUMIF('10. 170KMP'!$J:$J,'0.KQKD'!$E20,'10. 170KMP'!R:R) -> #REF! | M20: =SUMIF('10. 170KMP'!$J:$J,'0.KQKD'!$E20,'10. 170KMP'!S:S) -> #REF! | N20: =SUMIF('10. 170KMP'!$J:$J,'0.KQKD'!$E20,'10. 170KMP'!T:T) -> #REF! | O20: =SUMIF('10. 170KMP'!$J:$J,'0.KQKD'!$E20,'10. 170KMP'!U:U) -> #REF! | P20: =SUMIF('10. 170KMP'!$J:$J,'0.KQKD'!$E20,'10. 170KMP'!V:V) -> #REF! | Q20: =SUMIF('10. 170KMP'!$J:$J,'0.KQKD'!$E20,'10. 170KMP'!W:W) -> #REF! | R20: =SUMIF('10. 170KMP'!$J:$J,'0.KQKD'!$E20,'10. 170KMP'!X:X) -> #REF! | S20: =SUMIF('10. 170KMP'!$J:$J,'0.KQKD'!$E20,'10. 170KMP'!Y:Y) -> #REF! | T20: =SUMIF('10. 170KMP'!$J:$J,'0.KQKD'!$E20,'10. 170KMP'!Z:Z) -> #REF! | U20: =SUM(I20:T20) -> #REF! | V20: =SUMIF('10. 170KMP'!$J:$J,'0.KQKD'!$E20,'10. 170KMP'!AB:AB) -> 54093661 | W20: =SUMIF('10. 170KMP'!$J:$J,'0.KQKD'!$E20,'10. 170KMP'!AC:AC) -> 60737290 | X20: =SUMIF('10. 170KMP'!$J:$J,'0.KQKD'!$E20,'10. 170KMP'!AD:AD) -> 1.1063872e+08 | Y20: =SUMIF('10. 170KMP'!$J:$J,'0.KQKD'!$E20,'10. 170KMP'!AE:AE) -> 1.3739306e+08 | Z20: =SUMIF('10. 170KMP'!$J:$J,'0.KQKD'!$E20,'10. 170KMP'!AF:AF) -> 1.4311777e+08 | AA20: =SUMIF('10. 170KMP'!$J:$J,'0.KQKD'!$E20,'10. 170KMP'!AG:AG) -> 1.4311777e+08 | AB20: =SUMIF('10. 170KMP'!$J:$J,'0.KQKD'!$E20,'10. 170KMP'!AH:AH) -> 1.4884248e+08 | AC20: =SUMIF('10. 170KMP'!$J:$J,'0.KQKD'!$E20,'10. 170KMP'!AI:AI) -> 1.4848162e+08 | AD20: =SUMIF('10. 170KMP'!$J:$J,'0.KQKD'!$E20,'10. 170KMP'!AJ:AJ) -> 1.4277079e+08 | AE20: =SUMIF('10. 170KMP'!$J:$J,'0.KQKD'!$E20,'10. 170KMP'!AK:AK) -> 1.4838615e+08 | AF20: =SUMIF('10. 170KMP'!$J:$J,'0.KQKD'!$E20,'10. 170KMP'!AL:AL) -> 1.4267899e+08 | AG20: =SUMIF('10. 170KMP'!$J:$J,'0.KQKD'!$E20,'10. 170KMP'!AM:AM) -> 1.4884248e+08 | AH20: =SUM(V20:AG20) -> 1.5291008e+09 | AI20: =SUM(AJ20:AU20) -> 109875448 | AJ20: =SUMIF('10. 170KMP'!$J:$J,'0.KQKD'!$E20,'10. 170KMP'!AP:AP) -> 18966344 | AK20: =SUMIF('10. 170KMP'!$J:$J,'0.KQKD'!$E20,'10. 170KMP'!AQ:AQ) -> 20394307 | AL20: =SUMIF('10. 170KMP'!$J:$J,'0.KQKD'!$E20,'10. 170KMP'!AR:AR) -> 26965725 | AM20: =SUMIF('10. 170KMP'!$J:$J,'0.KQKD'!$E20,'10. 170KMP'!AS:AS) -> 12536111 | AN20: =SUMIF('10. 170KMP'!$J:$J,'0.KQKD'!$E20,'10. 170KMP'!AT:AT) -> 31012961 | AO20: =SUMIF('10. 170KMP'!$J:$J,'0.KQKD'!$E20,'10. 170KMP'!AU:AU) -> 0 | AP20: =SUMIF('10. 170KMP'!$J:$J,'0.KQKD'!$E20,'10. 170KMP'!AV:AV) -> 0 | AQ20: =SUMIF('10. 170KMP'!$J:$J,'0.KQKD'!$E20,'10. 170KMP'!AW:AW) -> 0 | AR20: =SUMIF('10. 170KMP'!$J:$J,'0.KQKD'!$E20,'10. 170KMP'!AX:AX) -> 0 | AS20: =SUMIF('10. 170KMP'!$J:$J,'0.KQKD'!$E20,'10. 170KMP'!AY:AY) -> 0 | AT20: =SUMIF('10. 170KMP'!$J:$J,'0.KQKD'!$E20,'10. 170KMP'!AZ:AZ) -> 0 | AU20: =SUMIF('10. 170KMP'!$J:$J,'0.KQKD'!$E20,'10. 170KMP'!BA:BA) -> 0 | AV20: =AM20 -> 12536111 | AW20: =AN20 -> 31012961 | AX20: =Z20 -> 1.4311777e+08 | AY20: =IFERROR(AW20/AV20,0) -> 2.4738901 | AZ20: =IFERROR(AW20/AX20,0) -> 0.21669539 | BA20: =SUM(I20:M20) -> #REF! | BB20: =SUM(AJ20:AN20) -> 109875448 | BC20: =SUM(V20:Z20) -> 5.059805e+08 | BD20: =IFERROR(BB20/BA20,0) -> 0 | BE20: =IFERROR(BB20/BC20,0) -> 0.21715352 | BF20: =IFERROR(BB20/AH20,0) -> 0.07185625
D21: Chi phí điện | E21: 08 | F21: =SUMIF('10. 170KMP'!$J:$J,'0.KQKD'!$E21,'10. 170KMP'!L:L) -> #REF! | G21: =SUMIF('10. 170KMP'!$J:$J,'0.KQKD'!$E21,'10. 170KMP'!M:M) -> #REF! | H21: =SUMIF('10. 170KMP'!$J:$J,'0.KQKD'!$E21,'10. 170KMP'!N:N) -> #REF! | I21: =SUMIF('10. 170KMP'!$J:$J,'0.KQKD'!$E21,'10. 170KMP'!O:O) -> #REF! | J21: =SUMIF('10. 170KMP'!$J:$J,'0.KQKD'!$E21,'10. 170KMP'!P:P) -> #REF! | K21: =SUMIF('10. 170KMP'!$J:$J,'0.KQKD'!$E21,'10. 170KMP'!Q:Q) -> #REF! | L21: =SUMIF('10. 170KMP'!$J:$J,'0.KQKD'!$E21,'10. 170KMP'!R:R) -> #REF! | M21: =SUMIF('10. 170KMP'!$J:$J,'0.KQKD'!$E21,'10. 170KMP'!S:S) -> #REF! | N21: =SUMIF('10. 170KMP'!$J:$J,'0.KQKD'!$E21,'10. 170KMP'!T:T) -> #REF! | O21: =SUMIF('10. 170KMP'!$J:$J,'0.KQKD'!$E21,'10. 170KMP'!U:U) -> #REF! | P21: =SUMIF('10. 170KMP'!$J:$J,'0.KQKD'!$E21,'10. 170KMP'!V:V) -> #REF! | Q21: =SUMIF('10. 170KMP'!$J:$J,'0.KQKD'!$E21,'10. 170KMP'!W:W) -> #REF! | R21: =SUMIF('10. 170KMP'!$J:$J,'0.KQKD'!$E21,'10. 170KMP'!X:X) -> #REF! | S21: =SUMIF('10. 170KMP'!$J:$J,'0.KQKD'!$E21,'10. 170KMP'!Y:Y) -> #REF! | T21: =SUMIF('10. 170KMP'!$J:$J,'0.KQKD'!$E21,'10. 170KMP'!Z:Z) -> #REF! | U21: =SUM(I21:T21) -> #REF! | V21: =SUMIF('10. 170KMP'!$J:$J,'0.KQKD'!$E21,'10. 170KMP'!AB:AB) -> 1.1441557e+08 | W21: =SUMIF('10. 170KMP'!$J:$J,'0.KQKD'!$E21,'10. 170KMP'!AC:AC) -> 68649341 | X21: =SUMIF('10. 170KMP'!$J:$J,'0.KQKD'!$E21,'10. 170KMP'!AD:AD) -> 1.7292809e+08 | Y21: =SUMIF('10. 170KMP'!$J:$J,'0.KQKD'!$E21,'10. 170KMP'!AE:AE) -> 4.4672949e+08 | Z21: =SUMIF('10. 170KMP'!$J:$J,'0.KQKD'!$E21,'10. 170KMP'!AF:AF) -> 4.6534322e+08 | AA21: =SUMIF('10. 170KMP'!$J:$J,'0.KQKD'!$E21,'10. 170KMP'!AG:AG) -> 4.6534322e+08 | AB21: =SUMIF('10. 170KMP'!$J:$J,'0.KQKD'!$E21,'10. 170KMP'!AH:AH) -> 4.8395695e+08 | AC21: =SUMIF('10. 170KMP'!$J:$J,'0.KQKD'!$E21,'10. 170KMP'!AI:AI) -> 4.8435908e+08 | AD21: =SUMIF('10. 170KMP'!$J:$J,'0.KQKD'!$E21,'10. 170KMP'!AJ:AJ) -> 4.6572989e+08 | AE21: =SUMIF('10. 170KMP'!$J:$J,'0.KQKD'!$E21,'10. 170KMP'!AK:AK) -> 4.8399951e+08 | AF21: =SUMIF('10. 170KMP'!$J:$J,'0.KQKD'!$E21,'10. 170KMP'!AL:AL) -> 4.6538414e+08 | AG21: =SUMIF('10. 170KMP'!$J:$J,'0.KQKD'!$E21,'10. 170KMP'!AM:AM) -> 4.8395695e+08 | AH21: =SUM(V21:AG21) -> 4.6007954e+09 | AI21: =SUM(AJ21:AU21) -> 439933572 | AJ21: =SUMIF('10. 170KMP'!$J:$J,'0.KQKD'!$E21,'10. 170KMP'!AP:AP) -> 55733801 | AK21: =SUMIF('10. 170KMP'!$J:$J,'0.KQKD'!$E21,'10. 170KMP'!AQ:AQ) -> 34523239 | AL21: =SUMIF('10. 170KMP'!$J:$J,'0.KQKD'!$E21,'10. 170KMP'!AR:AR) -> 120602820 | AM21: =SUMIF('10. 170KMP'!$J:$J,'0.KQKD'!$E21,'10. 170KMP'!AS:AS) -> 105676472 | AN21: =SUMIF('10. 170KMP'!$J:$J,'0.KQKD'!$E21,'10. 170KMP'!AT:AT) -> 123397240 | AO21: =SUMIF('10. 170KMP'!$J:$J,'0.KQKD'!$E21,'10. 170KMP'!AU:AU) -> 0 | AP21: =SUMIF('10. 170KMP'!$J:$J,'0.KQKD'!$E21,'10. 170KMP'!AV:AV) -> 0 | AQ21: =SUMIF('10. 170KMP'!$J:$J,'0.KQKD'!$E21,'10. 170KMP'!AW:AW) -> 0 | AR21: =SUMIF('10. 170KMP'!$J:$J,'0.KQKD'!$E21,'10. 170KMP'!AX:AX) -> 0 | AS21: =SUMIF('10. 170KMP'!$J:$J,'0.KQKD'!$E21,'10. 170KMP'!AY:AY) -> 0 | AT21: =SUMIF('10. 170KMP'!$J:$J,'0.KQKD'!$E21,'10. 170KMP'!AZ:AZ) -> 0 | AU21: =SUMIF('10. 170KMP'!$J:$J,'0.KQKD'!$E21,'10. 170KMP'!BA:BA) -> 0 | AV21: =AM21 -> 105676472 | AW21: =AN21 -> 123397240 | AX21: =Z21 -> 4.6534322e+08 | AY21: =IFERROR(AW21/AV21,0) -> 1.1676889 | AZ21: =IFERROR(AW21/AX21,0) -> 0.26517468 | BA21: =SUM(I21:M21) -> #REF! | BB21: =SUM(AJ21:AN21) -> 439933572 | BC21: =SUM(V21:Z21) -> 1.2680657e+09 | BD21: =IFERROR(BB21/BA21,0) -> 0 | BE21: =IFERROR(BB21/BC21,0) -> 0.34693279 | BF21: =IFERROR(BB21/AH21,0) -> 0.095621198
D22: Chi phí nước | E22: 09 | F22: =SUMIF('10. 170KMP'!$J:$J,'0.KQKD'!$E22,'10. 170KMP'!L:L) -> #REF! | G22: =SUMIF('10. 170KMP'!$J:$J,'0.KQKD'!$E22,'10. 170KMP'!M:M) -> #REF! | H22: =SUMIF('10. 170KMP'!$J:$J,'0.KQKD'!$E22,'10. 170KMP'!N:N) -> #REF! | I22: =SUMIF('10. 170KMP'!$J:$J,'0.KQKD'!$E22,'10. 170KMP'!O:O) -> #REF! | J22: =SUMIF('10. 170KMP'!$J:$J,'0.KQKD'!$E22,'10. 170KMP'!P:P) -> #REF! | K22: =SUMIF('10. 170KMP'!$J:$J,'0.KQKD'!$E22,'10. 170KMP'!Q:Q) -> #REF! | L22: =SUMIF('10. 170KMP'!$J:$J,'0.KQKD'!$E22,'10. 170KMP'!R:R) -> #REF! | M22: =SUMIF('10. 170KMP'!$J:$J,'0.KQKD'!$E22,'10. 170KMP'!S:S) -> #REF! | N22: =SUMIF('10. 170KMP'!$J:$J,'0.KQKD'!$E22,'10. 170KMP'!T:T) -> #REF! | O22: =SUMIF('10. 170KMP'!$J:$J,'0.KQKD'!$E22,'10. 170KMP'!U:U) -> #REF! | P22: =SUMIF('10. 170KMP'!$J:$J,'0.KQKD'!$E22,'10. 170KMP'!V:V) -> #REF! | Q22: =SUMIF('10. 170KMP'!$J:$J,'0.KQKD'!$E22,'10. 170KMP'!W:W) -> #REF! | R22: =SUMIF('10. 170KMP'!$J:$J,'0.KQKD'!$E22,'10. 170KMP'!X:X) -> #REF! | S22: =SUMIF('10. 170KMP'!$J:$J,'0.KQKD'!$E22,'10. 170KMP'!Y:Y) -> #REF! | T22: =SUMIF('10. 170KMP'!$J:$J,'0.KQKD'!$E22,'10. 170KMP'!Z:Z) -> #REF! | U22: =SUM(I22:T22) -> #REF! | V22: =SUMIF('10. 170KMP'!$J:$J,'0.KQKD'!$E22,'10. 170KMP'!AB:AB) -> 5000000 | W22: =SUMIF('10. 170KMP'!$J:$J,'0.KQKD'!$E22,'10. 170KMP'!AC:AC) -> 5000000 | X22: =SUMIF('10. 170KMP'!$J:$J,'0.KQKD'!$E22,'10. 170KMP'!AD:AD) -> 5000000 | Y22: =SUMIF('10. 170KMP'!$J:$J,'0.KQKD'!$E22,'10. 170KMP'!AE:AE) -> 5000000 | Z22: =SUMIF('10. 170KMP'!$J:$J,'0.KQKD'!$E22,'10. 170KMP'!AF:AF) -> 5000000 | AA22: =SUMIF('10. 170KMP'!$J:$J,'0.KQKD'!$E22,'10. 170KMP'!AG:AG) -> 5000000 | AB22: =SUMIF('10. 170KMP'!$J:$J,'0.KQKD'!$E22,'10. 170KMP'!AH:AH) -> 5000000 | AC22: =SUMIF('10. 170KMP'!$J:$J,'0.KQKD'!$E22,'10. 170KMP'!AI:AI) -> 5000000 | AD22: =SUMIF('10. 170KMP'!$J:$J,'0.KQKD'!$E22,'10. 170KMP'!AJ:AJ) -> 5000000 | AE22: =SUMIF('10. 170KMP'!$J:$J,'0.KQKD'!$E22,'10. 170KMP'!AK:AK) -> 5000000 | AF22: =SUMIF('10. 170KMP'!$J:$J,'0.KQKD'!$E22,'10. 170KMP'!AL:AL) -> 5000000 | AG22: =SUMIF('10. 170KMP'!$J:$J,'0.KQKD'!$E22,'10. 170KMP'!AM:AM) -> 5000000 | AH22: =SUM(V22:AG22) -> 60000000 | AI22: =SUM(AJ22:AU22) -> 0 | AJ22: =SUMIF('10. 170KMP'!$J:$J,'0.KQKD'!$E22,'10. 170KMP'!AP:AP) -> 0 | AK22: =SUMIF('10. 170KMP'!$J:$J,'0.KQKD'!$E22,'10. 170KMP'!AQ:AQ) -> 0 | AL22: =SUMIF('10. 170KMP'!$J:$J,'0.KQKD'!$E22,'10. 170KMP'!AR:AR) -> 0 | AM22: =SUMIF('10. 170KMP'!$J:$J,'0.KQKD'!$E22,'10. 170KMP'!AS:AS) -> 0 | AN22: =SUMIF('10. 170KMP'!$J:$J,'0.KQKD'!$E22,'10. 170KMP'!AT:AT) -> 0 | AO22: =SUMIF('10. 170KMP'!$J:$J,'0.KQKD'!$E22,'10. 170KMP'!AU:AU) -> 0 | AP22: =SUMIF('10. 170KMP'!$J:$J,'0.KQKD'!$E22,'10. 170KMP'!AV:AV) -> 0 | AQ22: =SUMIF('10. 170KMP'!$J:$J,'0.KQKD'!$E22,'10. 170KMP'!AW:AW) -> 0 | AR22: =SUMIF('10. 170KMP'!$J:$J,'0.KQKD'!$E22,'10. 170KMP'!AX:AX) -> 0 | AS22: =SUMIF('10. 170KMP'!$J:$J,'0.KQKD'!$E22,'10. 170KMP'!AY:AY) -> 0 | AT22: =SUMIF('10. 170KMP'!$J:$J,'0.KQKD'!$E22,'10. 170KMP'!AZ:AZ) -> 0 | AU22: =SUMIF('10. 170KMP'!$J:$J,'0.KQKD'!$E22,'10. 170KMP'!BA:BA) -> 0 | AV22: =AM22 -> 0 | AW22: =AN22 -> 0 | AX22: =Z22 -> 5000000 | AY22: =IFERROR(AW22/AV22,0) -> 0 | AZ22: =IFERROR(AW22/AX22,0) -> 0 | BA22: =SUM(I22:M22) -> #REF! | BB22: =SUM(AJ22:AN22) -> 0 | BC22: =SUM(V22:Z22) -> 25000000 | BD22: =IFERROR(BB22/BA22,0) -> 0 | BE22: =IFERROR(BB22/BC22,0) -> 0 | BF22: =IFERROR(BB22/AH22,0) -> 0
D23: Chi phí xăng, dầu | E23: 10 | F23: =SUMIF('10. 170KMP'!$J:$J,'0.KQKD'!$E23,'10. 170KMP'!L:L) -> #REF! | G23: =SUMIF('10. 170KMP'!$J:$J,'0.KQKD'!$E23,'10. 170KMP'!M:M) -> #REF! | H23: =SUMIF('10. 170KMP'!$J:$J,'0.KQKD'!$E23,'10. 170KMP'!N:N) -> #REF! | I23: =SUMIF('10. 170KMP'!$J:$J,'0.KQKD'!$E23,'10. 170KMP'!O:O) -> #REF! | J23: =SUMIF('10. 170KMP'!$J:$J,'0.KQKD'!$E23,'10. 170KMP'!P:P) -> #REF! | K23: =SUMIF('10. 170KMP'!$J:$J,'0.KQKD'!$E23,'10. 170KMP'!Q:Q) -> #REF! | L23: =SUMIF('10. 170KMP'!$J:$J,'0.KQKD'!$E23,'10. 170KMP'!R:R) -> #REF! | M23: =SUMIF('10. 170KMP'!$J:$J,'0.KQKD'!$E23,'10. 170KMP'!S:S) -> #REF! | N23: =SUMIF('10. 170KMP'!$J:$J,'0.KQKD'!$E23,'10. 170KMP'!T:T) -> #REF! | O23: =SUMIF('10. 170KMP'!$J:$J,'0.KQKD'!$E23,'10. 170KMP'!U:U) -> #REF! | P23: =SUMIF('10. 170KMP'!$J:$J,'0.KQKD'!$E23,'10. 170KMP'!V:V) -> #REF! | Q23: =SUMIF('10. 170KMP'!$J:$J,'0.KQKD'!$E23,'10. 170KMP'!W:W) -> #REF! | R23: =SUMIF('10. 170KMP'!$J:$J,'0.KQKD'!$E23,'10. 170KMP'!X:X) -> #REF! | S23: =SUMIF('10. 170KMP'!$J:$J,'0.KQKD'!$E23,'10. 170KMP'!Y:Y) -> #REF! | T23: =SUMIF('10. 170KMP'!$J:$J,'0.KQKD'!$E23,'10. 170KMP'!Z:Z) -> #REF! | U23: =SUM(I23:T23) -> #REF! | V23: =SUMIF('10. 170KMP'!$J:$J,'0.KQKD'!$E23,'10. 170KMP'!AB:AB) -> 18221016 | W23: =SUMIF('10. 170KMP'!$J:$J,'0.KQKD'!$E23,'10. 170KMP'!AC:AC) -> 10932610 | X23: =SUMIF('10. 170KMP'!$J:$J,'0.KQKD'!$E23,'10. 170KMP'!AD:AD) -> 25970903 | Y23: =SUMIF('10. 170KMP'!$J:$J,'0.KQKD'!$E23,'10. 170KMP'!AE:AE) -> 44160617 | Z23: =SUMIF('10. 170KMP'!$J:$J,'0.KQKD'!$E23,'10. 170KMP'!AF:AF) -> 45923976 | AA23: =SUMIF('10. 170KMP'!$J:$J,'0.KQKD'!$E23,'10. 170KMP'!AG:AG) -> 45923976 | AB23: =SUMIF('10. 170KMP'!$J:$J,'0.KQKD'!$E23,'10. 170KMP'!AH:AH) -> 47687335 | AC23: =SUMIF('10. 170KMP'!$J:$J,'0.KQKD'!$E23,'10. 170KMP'!AI:AI) -> 47720451 | AD23: =SUMIF('10. 170KMP'!$J:$J,'0.KQKD'!$E23,'10. 170KMP'!AJ:AJ) -> 45955818 | AE23: =SUMIF('10. 170KMP'!$J:$J,'0.KQKD'!$E23,'10. 170KMP'!AK:AK) -> 47689714 | AF23: =SUMIF('10. 170KMP'!$J:$J,'0.KQKD'!$E23,'10. 170KMP'!AL:AL) -> 45926263 | AG23: =SUMIF('10. 170KMP'!$J:$J,'0.KQKD'!$E23,'10. 170KMP'!AM:AM) -> 47687335 | AH23: =SUM(V23:AG23) -> 4.7380001e+08 | AI23: =SUM(AJ23:AU23) -> 202367103 | AJ23: =SUMIF('10. 170KMP'!$J:$J,'0.KQKD'!$E23,'10. 170KMP'!AP:AP) -> 35286568 | AK23: =SUMIF('10. 170KMP'!$J:$J,'0.KQKD'!$E23,'10. 170KMP'!AQ:AQ) -> 20200309 | AL23: =SUMIF('10. 170KMP'!$J:$J,'0.KQKD'!$E23,'10. 170KMP'!AR:AR) -> 50686792 | AM23: =SUMIF('10. 170KMP'!$J:$J,'0.KQKD'!$E23,'10. 170KMP'!AS:AS) -> 44676097 | AN23: =SUMIF('10. 170KMP'!$J:$J,'0.KQKD'!$E23,'10. 170KMP'!AT:AT) -> 51517337 | AO23: =SUMIF('10. 170KMP'!$J:$J,'0.KQKD'!$E23,'10. 170KMP'!AU:AU) -> 0 | AP23: =SUMIF('10. 170KMP'!$J:$J,'0.KQKD'!$E23,'10. 170KMP'!AV:AV) -> 0 | AQ23: =SUMIF('10. 170KMP'!$J:$J,'0.KQKD'!$E23,'10. 170KMP'!AW:AW) -> 0 | AR23: =SUMIF('10. 170KMP'!$J:$J,'0.KQKD'!$E23,'10. 170KMP'!AX:AX) -> 0 | AS23: =SUMIF('10. 170KMP'!$J:$J,'0.KQKD'!$E23,'10. 170KMP'!AY:AY) -> 0 | AT23: =SUMIF('10. 170KMP'!$J:$J,'0.KQKD'!$E23,'10. 170KMP'!AZ:AZ) -> 0 | AU23: =SUMIF('10. 170KMP'!$J:$J,'0.KQKD'!$E23,'10. 170KMP'!BA:BA) -> 0 | AV23: =AM23 -> 44676097 | AW23: =AN23 -> 51517337 | AX23: =Z23 -> 45923976 | AY23: =IFERROR(AW23/AV23,0) -> 1.1531298 | AZ23: =IFERROR(AW23/AX23,0) -> 1.1217961 | BA23: =SUM(I23:M23) -> #REF! | BB23: =SUM(AJ23:AN23) -> 202367103 | BC23: =SUM(V23:Z23) -> 1.4520912e+08 | BD23: =IFERROR(BB23/BA23,0) -> 0 | BE23: =IFERROR(BB23/BC23,0) -> 1.3936253 | BF23: =IFERROR(BB23/AH23,0) -> 0.42711502
D24: Chi phí môi trường | E24: 11 | F24: =SUMIF('10. 170KMP'!$J:$J,'0.KQKD'!$E24,'10. 170KMP'!L:L) -> #REF! | G24: =SUMIF('10. 170KMP'!$J:$J,'0.KQKD'!$E24,'10. 170KMP'!M:M) -> #REF! | H24: =SUMIF('10. 170KMP'!$J:$J,'0.KQKD'!$E24,'10. 170KMP'!N:N) -> #REF! | I24: =SUMIF('10. 170KMP'!$J:$J,'0.KQKD'!$E24,'10. 170KMP'!O:O) -> #REF! | J24: =SUMIF('10. 170KMP'!$J:$J,'0.KQKD'!$E24,'10. 170KMP'!P:P) -> #REF! | K24: =SUMIF('10. 170KMP'!$J:$J,'0.KQKD'!$E24,'10. 170KMP'!Q:Q) -> #REF! | L24: =SUMIF('10. 170KMP'!$J:$J,'0.KQKD'!$E24,'10. 170KMP'!R:R) -> #REF! | M24: =SUMIF('10. 170KMP'!$J:$J,'0.KQKD'!$E24,'10. 170KMP'!S:S) -> #REF! | N24: =SUMIF('10. 170KMP'!$J:$J,'0.KQKD'!$E24,'10. 170KMP'!T:T) -> #REF! | O24: =SUMIF('10. 170KMP'!$J:$J,'0.KQKD'!$E24,'10. 170KMP'!U:U) -> #REF! | P24: =SUMIF('10. 170KMP'!$J:$J,'0.KQKD'!$E24,'10. 170KMP'!V:V) -> #REF! | Q24: =SUMIF('10. 170KMP'!$J:$J,'0.KQKD'!$E24,'10. 170KMP'!W:W) -> #REF! | R24: =SUMIF('10. 170KMP'!$J:$J,'0.KQKD'!$E24,'10. 170KMP'!X:X) -> #REF! | S24: =SUMIF('10. 170KMP'!$J:$J,'0.KQKD'!$E24,'10. 170KMP'!Y:Y) -> #REF! | T24: =SUMIF('10. 170KMP'!$J:$J,'0.KQKD'!$E24,'10. 170KMP'!Z:Z) -> #REF! | U24: =SUM(I24:T24) -> #REF! | V24: =SUMIF('10. 170KMP'!$J:$J,'0.KQKD'!$E24,'10. 170KMP'!AB:AB) -> 24439522 | W24: =SUMIF('10. 170KMP'!$J:$J,'0.KQKD'!$E24,'10. 170KMP'!AC:AC) -> 14436764 | X24: =SUMIF('10. 170KMP'!$J:$J,'0.KQKD'!$E24,'10. 170KMP'!AD:AD) -> 26273250 | Y24: =SUMIF('10. 170KMP'!$J:$J,'0.KQKD'!$E24,'10. 170KMP'!AE:AE) -> 4.8203661e+08 | Z24: =SUMIF('10. 170KMP'!$J:$J,'0.KQKD'!$E24,'10. 170KMP'!AF:AF) -> 5.0166604e+08 | AA24: =SUMIF('10. 170KMP'!$J:$J,'0.KQKD'!$E24,'10. 170KMP'!AG:AG) -> 5.0172712e+08 | AB24: =SUMIF('10. 170KMP'!$J:$J,'0.KQKD'!$E24,'10. 170KMP'!AH:AH) -> 5.21403e+08 | AC24: =SUMIF('10. 170KMP'!$J:$J,'0.KQKD'!$E24,'10. 170KMP'!AI:AI) -> 5.2193494e+08 | AD24: =SUMIF('10. 170KMP'!$J:$J,'0.KQKD'!$E24,'10. 170KMP'!AJ:AJ) -> 5.0219992e+08 | AE24: =SUMIF('10. 170KMP'!$J:$J,'0.KQKD'!$E24,'10. 170KMP'!AK:AK) -> 5.2142237e+08 | AF24: =SUMIF('10. 170KMP'!$J:$J,'0.KQKD'!$E24,'10. 170KMP'!AL:AL) -> 5.017434e+08 | AG24: =SUMIF('10. 170KMP'!$J:$J,'0.KQKD'!$E24,'10. 170KMP'!AM:AM) -> 5.2119916e+08 | AH24: =SUM(V24:AG24) -> 4.6404821e+09 | AI24: =SUM(AJ24:AU24) -> 106746123 | AJ24: =SUMIF('10. 170KMP'!$J:$J,'0.KQKD'!$E24,'10. 170KMP'!AP:AP) -> 41433379 | AK24: =SUMIF('10. 170KMP'!$J:$J,'0.KQKD'!$E24,'10. 170KMP'!AQ:AQ) -> 6749436 | AL24: =SUMIF('10. 170KMP'!$J:$J,'0.KQKD'!$E24,'10. 170KMP'!AR:AR) -> 11033436 | AM24: =SUMIF('10. 170KMP'!$J:$J,'0.KQKD'!$E24,'10. 170KMP'!AS:AS) -> 10974436 | AN24: =SUMIF('10. 170KMP'!$J:$J,'0.KQKD'!$E24,'10. 170KMP'!AT:AT) -> 36555436 | AO24: =SUMIF('10. 170KMP'!$J:$J,'0.KQKD'!$E24,'10. 170KMP'!AU:AU) -> 0 | AP24: =SUMIF('10. 170KMP'!$J:$J,'0.KQKD'!$E24,'10. 170KMP'!AV:AV) -> 0 | AQ24: =SUMIF('10. 170KMP'!$J:$J,'0.KQKD'!$E24,'10. 170KMP'!AW:AW) -> 0 | AR24: =SUMIF('10. 170KMP'!$J:$J,'0.KQKD'!$E24,'10. 170KMP'!AX:AX) -> 0 | AS24: =SUMIF('10. 170KMP'!$J:$J,'0.KQKD'!$E24,'10. 170KMP'!AY:AY) -> 0 | AT24: =SUMIF('10. 170KMP'!$J:$J,'0.KQKD'!$E24,'10. 170KMP'!AZ:AZ) -> 0 | AU24: =SUMIF('10. 170KMP'!$J:$J,'0.KQKD'!$E24,'10. 170KMP'!BA:BA) -> 0 | AV24: =AM24 -> 10974436 | AW24: =AN24 -> 36555436 | AX24: =Z24 -> 5.0166604e+08 | AY24: =IFERROR(AW24/AV24,0) -> 3.3309626 | AZ24: =IFERROR(AW24/AX24,0) -> 0.072868069 | BA24: =SUM(I24:M24) -> #REF! | BB24: =SUM(AJ24:AN24) -> 106746123 | BC24: =SUM(V24:Z24) -> 1.0488522e+09 | BD24: =IFERROR(BB24/BA24,0) -> 0 | BE24: =IFERROR(BB24/BC24,0) -> 0.10177423 | BF24: =IFERROR(BB24/AH24,0) -> 0.02300324
D25: Chi phí gia công thuê ngoài | E25: 12 | F25: =SUMIF('10. 170KMP'!$J:$J,'0.KQKD'!$E25,'10. 170KMP'!L:L) -> #REF! | G25: =SUMIF('10. 170KMP'!$J:$J,'0.KQKD'!$E25,'10. 170KMP'!M:M) -> #REF! | H25: =SUMIF('10. 170KMP'!$J:$J,'0.KQKD'!$E25,'10. 170KMP'!N:N) -> #REF! | I25: =SUMIF('10. 170KMP'!$J:$J,'0.KQKD'!$E25,'10. 170KMP'!O:O) -> #REF! | J25: =SUMIF('10. 170KMP'!$J:$J,'0.KQKD'!$E25,'10. 170KMP'!P:P) -> #REF! | K25: =SUMIF('10. 170KMP'!$J:$J,'0.KQKD'!$E25,'10. 170KMP'!Q:Q) -> #REF! | L25: =SUMIF('10. 170KMP'!$J:$J,'0.KQKD'!$E25,'10. 170KMP'!R:R) -> #REF! | M25: =SUMIF('10. 170KMP'!$J:$J,'0.KQKD'!$E25,'10. 170KMP'!S:S) -> #REF! | N25: =SUMIF('10. 170KMP'!$J:$J,'0.KQKD'!$E25,'10. 170KMP'!T:T) -> #REF! | O25: =SUMIF('10. 170KMP'!$J:$J,'0.KQKD'!$E25,'10. 170KMP'!U:U) -> #REF! | P25: =SUMIF('10. 170KMP'!$J:$J,'0.KQKD'!$E25,'10. 170KMP'!V:V) -> #REF! | Q25: =SUMIF('10. 170KMP'!$J:$J,'0.KQKD'!$E25,'10. 170KMP'!W:W) -> #REF! | R25: =SUMIF('10. 170KMP'!$J:$J,'0.KQKD'!$E25,'10. 170KMP'!X:X) -> #REF! | S25: =SUMIF('10. 170KMP'!$J:$J,'0.KQKD'!$E25,'10. 170KMP'!Y:Y) -> #REF! | T25: =SUMIF('10. 170KMP'!$J:$J,'0.KQKD'!$E25,'10. 170KMP'!Z:Z) -> #REF! | U25: =SUM(I25:T25) -> #REF! | V25: =SUMIF('10. 170KMP'!$J:$J,'0.KQKD'!$E25,'10. 170KMP'!AB:AB) -> 0 | W25: =SUMIF('10. 170KMP'!$J:$J,'0.KQKD'!$E25,'10. 170KMP'!AC:AC) -> 0 | X25: =SUMIF('10. 170KMP'!$J:$J,'0.KQKD'!$E25,'10. 170KMP'!AD:AD) -> 0 | Y25: =SUMIF('10. 170KMP'!$J:$J,'0.KQKD'!$E25,'10. 170KMP'!AE:AE) -> 0 | Z25: =SUMIF('10. 170KMP'!$J:$J,'0.KQKD'!$E25,'10. 170KMP'!AF:AF) -> 0 | AA25: =SUMIF('10. 170KMP'!$J:$J,'0.KQKD'!$E25,'10. 170KMP'!AG:AG) -> 0 | AB25: =SUMIF('10. 170KMP'!$J:$J,'0.KQKD'!$E25,'10. 170KMP'!AH:AH) -> 0 | AC25: =SUMIF('10. 170KMP'!$J:$J,'0.KQKD'!$E25,'10. 170KMP'!AI:AI) -> 0 | AD25: =SUMIF('10. 170KMP'!$J:$J,'0.KQKD'!$E25,'10. 170KMP'!AJ:AJ) -> 0 | AE25: =SUMIF('10. 170KMP'!$J:$J,'0.KQKD'!$E25,'10. 170KMP'!AK:AK) -> 0 | AF25: =SUMIF('10. 170KMP'!$J:$J,'0.KQKD'!$E25,'10. 170KMP'!AL:AL) -> 0 | AG25: =SUMIF('10. 170KMP'!$J:$J,'0.KQKD'!$E25,'10. 170KMP'!AM:AM) -> 0 | AH25: =SUM(V25:AG25) -> 0 | AI25: =SUM(AJ25:AU25) -> 0 | AJ25: =SUMIF('10. 170KMP'!$J:$J,'0.KQKD'!$E25,'10. 170KMP'!AP:AP) -> 0 | AK25: =SUMIF('10. 170KMP'!$J:$J,'0.KQKD'!$E25,'10. 170KMP'!AQ:AQ) -> 0 | AL25: =SUMIF('10. 170KMP'!$J:$J,'0.KQKD'!$E25,'10. 170KMP'!AR:AR) -> 0 | AM25: =SUMIF('10. 170KMP'!$J:$J,'0.KQKD'!$E25,'10. 170KMP'!AS:AS) -> 0 | AN25: =SUMIF('10. 170KMP'!$J:$J,'0.KQKD'!$E25,'10. 170KMP'!AT:AT) -> 0 | AO25: =SUMIF('10. 170KMP'!$J:$J,'0.KQKD'!$E25,'10. 170KMP'!AU:AU) -> 0 | AP25: =SUMIF('10. 170KMP'!$J:$J,'0.KQKD'!$E25,'10. 170KMP'!AV:AV) -> 0 | AQ25: =SUMIF('10. 170KMP'!$J:$J,'0.KQKD'!$E25,'10. 170KMP'!AW:AW) -> 0 | AR25: =SUMIF('10. 170KMP'!$J:$J,'0.KQKD'!$E25,'10. 170KMP'!AX:AX) -> 0 | AS25: =SUMIF('10. 170KMP'!$J:$J,'0.KQKD'!$E25,'10. 170KMP'!AY:AY) -> 0 | AT25: =SUMIF('10. 170KMP'!$J:$J,'0.KQKD'!$E25,'10. 170KMP'!AZ:AZ) -> 0 | AU25: =SUMIF('10. 170KMP'!$J:$J,'0.KQKD'!$E25,'10. 170KMP'!BA:BA) -> 0 | AV25: =AM25 -> 0 | AW25: =AN25 -> 0 | AX25: =Z25 -> 0 | AY25: =IFERROR(AW25/AV25,0) -> 0 | AZ25: =IFERROR(AW25/AX25,0) -> 0 | BA25: =SUM(I25:M25) -> #REF! | BB25: =SUM(AJ25:AN25) -> 0 | BC25: =SUM(V25:Z25) -> 0 | BD25: =IFERROR(BB25/BA25,0) -> 0 | BE25: =IFERROR(BB25/BC25,0) -> 0 | BF25: =IFERROR(BB25/AH25,0) -> 0
D26: Điều chỉnh giá vốn trong hàng tồn kho | AI26: =SUM(AJ26:AU26) -> 0 | AV26: =AM26 -> 0 | AW26: =AN26 -> 0 | AX26: =Z26 -> 0 | AY26: =IFERROR(AW26/AV26,0) -> 0 | AZ26: =IFERROR(AW26/AX26,0) -> 0 | BA26: =SUM(I26:M26) -> 0 | BB26: =SUM(AJ26:AN26) -> 0 | BC26: =SUM(V26:Z26) -> 0 | BD26: =IFERROR(BB26/BA26,0) -> 0 | BE26: =IFERROR(BB26/BC26,0) -> 0 | BF26: =IFERROR(BB26/AH26,0) -> 0
D27: Đ/C lãi chưa thực hiện trong HTK khi Hợp nhất | AI27: =SUM(AJ27:AU27) -> 0 | AV27: =AM27 -> 0 | AW27: =AN27 -> 0 | AX27: =Z27 -> 0 | AY27: =IFERROR(AW27/AV27,0) -> 0 | AZ27: =IFERROR(AW27/AX27,0) -> 0 | BA27: =SUM(I27:L27) -> 0 | BB27: =SUM(AJ27:AM27) -> 0 | BC27: =SUM(V27:Y27) -> 0 | BD27: =IFERROR(BB27/BA27,0) -> 0 | BE27: =IFERROR(BB27/BC27,0) -> 0 | BF27: =IFERROR(BB27/AH27,0) -> 0
B28: 4 | C28: LÃI BIẾN PHÍ | F28: =F5-F10-F13 -> #REF! | G28: =G5-G10-G13 -> #REF! | H28: =H5-H10-H13 -> #REF! | I28: =I5-I10-I13 -> #REF! | J28: =J5-J10-J13 -> #REF! | K28: =K5-K10-K13 -> #REF! | L28: =L5-L10-L13 -> #REF! | M28: =M5-M10-M13 -> #REF! | ... AU28: =AU5-AU10-AU13 -> 0 | AV28: =AM28 -> 1428763477 | AW28: =AN28 -> 2234429594 | AX28: =Z28 -> 2.2654417e+09 | AY28: =IFERROR(AW28/AV28,0) -> 1.5638905 | AZ28: =IFERROR(AW28/AX28,0) -> 0.98631077 | BA28: =SUM(I28:M28) -> #REF! | BB28: =SUM(AJ28:AN28) -> 7695212433 | BC28: =SUM(V28:Z28) -> 8.8766303e+09 | BD28: =IFERROR(BB28/BA28,0) -> 0 | BE28: =IFERROR(BB28/BC28,0) -> 0.86690694 | BF28: =IFERROR(BB28/AH28,0) -> 0.30577172
D29: Tỷ lệ Lãi biến phí (%) | F29: =IFERROR(F28/F$5,0) -> 0 | G29: =IFERROR(G28/G$5,0) -> 0 | H29: =IFERROR(H28/H$5,0) -> 0 | I29: =IFERROR(I28/I$5,0) -> 0 | J29: =IFERROR(J28/J$5,0) -> 0 | K29: =IFERROR(K28/K$5,0) -> 0 | L29: =IFERROR(L28/L$5,0) -> 0 | M29: =IFERROR(M28/M$5,0) -> 0 | ... AX29: =IFERROR(AX28/AX$5,0) -> 0.1378247 | AY29: =IFERROR(AW29/AV29,0) -> 0.99430274 | AZ29: =IFERROR(AW29/AX29,0) -> 1.4705005 | BA29: =IFERROR(BA28/BA$5,0) -> 0 | BB29: =IFERROR(BB28/BB$5,0) -> 0.19447965 | BC29: =IFERROR(BC28/BC$5,0) -> 0.14860721 | BD29: =IFERROR(BB29/BA29,0) -> 0 | BE29: =IFERROR(BB29/BC29,0) -> 1.3086825 | BF29: =IFERROR(BB29/AH29,0) -> 1.3715826
D30: Lãi biến phí / Tấn (Triệu đồng/Tấn) | F30: =IFERROR(F28/F$4,0)*1000 -> 0 | G30: =IFERROR(G28/G$4,0)*1000 -> 0 | H30: =IFERROR(H28/H$4,0)*1000 -> 0 | I30: =IFERROR(I28/I$4,0)*1000 -> 0 | J30: =IFERROR(J28/J$4,0)*1000 -> 0 | K30: =IFERROR(K28/K$4,0)*1000 -> 0 | L30: =IFERROR(L28/L$4,0)*1000 -> 0 | M30: =IFERROR(M28/M$4,0)*1000 -> 0 | ... AX30: =IFERROR(AX28/AX$4,0)*1000 -> 2209405.7 | AY30: =IFERROR(AW30/AV30,0) -> 1.0852674 | AZ30: =IFERROR(AW30/AX30,0) -> 1.4228638 | BA30: =IFERROR(BA28/BA$4,0)*1000 -> 0 | BB30: =IFERROR(BB28/BB$4,0)*1000 -> 2810452.3 | BC30: =IFERROR(BC28/BC$4,0)*1000 -> 2240605.5 | BD30: =IFERROR(BB30/BA30,0) -> 0 | BE30: =IFERROR(BB30/BC30,0) -> 1.2543272 | BF30: =IFERROR(BB30/AH30,0) -> 1.2624929
B31: 5 | C31: ĐỊNH PHÍ | F31: =F34+F61+F63+F65 -> #REF! | G31: =G34+G61+G63+G65 -> #REF! | H31: =H34+H61+H63+H65 -> #REF! | I31: =I34+I61+I63+I65 -> #REF! | J31: =J34+J61+J63+J65 -> #REF! | K31: =K34+K61+K63+K65 -> #REF! | L31: =L34+L61+L63+L65 -> #REF! | M31: =M34+M61+M63+M65 -> #REF! | ... AU31: =AU34+AU61+AU63+AU65 -> 0 | AV31: =AM31 -> 990061974 | AW31: =AN31 -> 1115395366 | AX31: =Z31 -> 2.1605429e+09 | AY31: =IFERROR(AW31/AV31,0) -> 1.1265915 | AZ31: =IFERROR(AW31/AX31,0) -> 0.516257 | BA31: =SUM(I31:M31) -> #REF! | BB31: =SUM(AJ31:AN31) -> 5152487527 | BC31: =SUM(V31:Z31) -> 8.032541e+09 | BD31: =IFERROR(BB31/BA31,0) -> 0 | BE31: =IFERROR(BB31/BC31,0) -> 0.64145176 | BF31: =IFERROR(BB31/AH31,0) -> 0.21633817
D32: Định phí / Doanh thu (%) | F32: =IFERROR(F31/F$5,0) -> 0 | G32: =IFERROR(G31/G$5,0) -> 0 | H32: =IFERROR(H31/H$5,0) -> 0 | I32: =IFERROR(I31/I$5,0) -> 0 | J32: =IFERROR(J31/J$5,0) -> 0 | K32: =IFERROR(K31/K$5,0) -> 0 | L32: =IFERROR(L31/L$5,0) -> 0 | M32: =IFERROR(M31/M$5,0) -> 0 | ... AX32: =IFERROR(AX31/AX$5,0) -> 0.13144287 | AY32: =IFERROR(AW32/AV32,0) -> 0.71627329 | AZ32: =IFERROR(AW32/AX32,0) -> 0.7696927 | BA32: =IFERROR(BA31/BA$5,0) -> 0 | BB32: =IFERROR(BB31/BB$5,0) -> 0.13021784 | BC32: =IFERROR(BC31/BC$5,0) -> 0.13447597 | BD32: =IFERROR(BB32/BA32,0) -> 0 | BE32: =IFERROR(BB32/BC32,0) -> 0.9683354 | BF32: =IFERROR(BB32/AH32,0) -> 0.97041565
D33: Định phí / Tấn (Triệu đồng/Tấn) | F33: =IFERROR(F31/F$4,0)*1000 -> 0 | G33: =IFERROR(G31/G$4,0)*1000 -> 0 | H33: =IFERROR(H31/H$4,0)*1000 -> 0 | I33: =IFERROR(I31/I$4,0)*1000 -> 0 | J33: =IFERROR(J31/J$4,0)*1000 -> 0 | K33: =IFERROR(K31/K$4,0)*1000 -> 0 | L33: =IFERROR(L31/L$4,0)*1000 -> 0 | M33: =IFERROR(M31/M$4,0)*1000 -> 0 | ... AX33: =IFERROR(AX31/AX$4,0)*1000 -> 2107101.5 | AY33: =IFERROR(AW33/AV33,0) -> 0.78180218 | AZ33: =IFERROR(AW33/AX33,0) -> 0.74475858 | BA33: =IFERROR(BA31/BA$4,0)*1000 -> 0 | BB33: =IFERROR(BB31/BB$4,0)*1000 -> 1881796.1 | BC33: =IFERROR(BC31/BC$4,0)*1000 -> 2027543.6 | BD33: =IFERROR(BB33/BA33,0) -> 0 | BE33: =IFERROR(BB33/BC33,0) -> 0.92811619 | BF33: =IFERROR(BB33/AH33,0) -> 0.89323306
B34: 5.1 | C34: Chi phí hoạt động | F34: =SUM(F36:F60) -> #REF! | G34: =SUM(G36:G60) -> #REF! | H34: =SUM(H36:H60) -> #REF! | I34: =SUM(I36:I60) -> #REF! | J34: =SUM(J36:J60) -> #REF! | K34: =SUM(K36:K60) -> #REF! | L34: =SUM(L36:L60) -> #REF! | M34: =SUM(M36:M60) -> #REF! | ... AU34: =SUM(AU36:AU60) -> 0 | AV34: =AM34 -> 172118323 | AW34: =AN34 -> 287665915 | AX34: =Z34 -> 5.8530496e+08 | AY34: =IFERROR(AW34/AV34,0) -> 1.6713265 | AZ34: =IFERROR(AW34/AX34,0) -> 0.4914804 | BA34: =SUM(I34:M34) -> #REF! | BB34: =SUM(AJ34:AN34) -> 1021658996 | BC34: =SUM(V34:Z34) -> 1.7421535e+09 | BD34: =IFERROR(BB34/BA34,0) -> 0 | BE34: =IFERROR(BB34/BC34,0) -> 0.58643454 | BF34: =IFERROR(BB34/AH34,0) -> 0.16610026
D35: Chi phí hoạt động / Doanh thu (%) | F35: =IFERROR(F34/F$5,0) -> 0 | G35: =IFERROR(G34/G$5,0) -> 0 | H35: =IFERROR(H34/H$5,0) -> 0 | I35: =IFERROR(I34/I$5,0) -> 0 | J35: =IFERROR(J34/J$5,0) -> 0 | K35: =IFERROR(K34/K$5,0) -> 0 | L35: =IFERROR(L34/L$5,0) -> 0 | M35: =IFERROR(M34/M$5,0) -> 0 | ... AX35: =IFERROR(AX34/AX$5,0) -> 0.035608719 | AY35: =IFERROR(AW35/AV35,0) -> 1.0626093 | AZ35: =IFERROR(AW35/AX35,0) -> 0.73275302 | BA35: =IFERROR(BA34/BA$5,0) -> 0 | BB35: =IFERROR(BB34/BB$5,0) -> 0.025820195 | BC35: =IFERROR(BC34/BC$5,0) -> 0.029166087 | BD35: =IFERROR(BB35/BA35,0) -> 0 | BE35: =IFERROR(BB35/BC35,0) -> 0.88528142 | BF35: =IFERROR(BB35/AH35,0) -> 0.74506636
D36: Chi phí sửa chữa, bảo trì | E36: 13 | F36: =SUMIF('10. 170KMP'!$J:$J,'0.KQKD'!$E36,'10. 170KMP'!L:L) -> #REF! | G36: =SUMIF('10. 170KMP'!$J:$J,'0.KQKD'!$E36,'10. 170KMP'!M:M) -> #REF! | H36: =SUMIF('10. 170KMP'!$J:$J,'0.KQKD'!$E36,'10. 170KMP'!N:N) -> #REF! | I36: =SUMIF('10. 170KMP'!$J:$J,'0.KQKD'!$E36,'10. 170KMP'!O:O) -> #REF! | J36: =SUMIF('10. 170KMP'!$J:$J,'0.KQKD'!$E36,'10. 170KMP'!P:P) -> #REF! | K36: =SUMIF('10. 170KMP'!$J:$J,'0.KQKD'!$E36,'10. 170KMP'!Q:Q) -> #REF! | L36: =SUMIF('10. 170KMP'!$J:$J,'0.KQKD'!$E36,'10. 170KMP'!R:R) -> #REF! | M36: =SUMIF('10. 170KMP'!$J:$J,'0.KQKD'!$E36,'10. 170KMP'!S:S) -> #REF! | N36: =SUMIF('10. 170KMP'!$J:$J,'0.KQKD'!$E36,'10. 170KMP'!T:T) -> #REF! | O36: =SUMIF('10. 170KMP'!$J:$J,'0.KQKD'!$E36,'10. 170KMP'!U:U) -> #REF! | P36: =SUMIF('10. 170KMP'!$J:$J,'0.KQKD'!$E36,'10. 170KMP'!V:V) -> #REF! | Q36: =SUMIF('10. 170KMP'!$J:$J,'0.KQKD'!$E36,'10. 170KMP'!W:W) -> #REF! | R36: =SUMIF('10. 170KMP'!$J:$J,'0.KQKD'!$E36,'10. 170KMP'!X:X) -> #REF! | S36: =SUMIF('10. 170KMP'!$J:$J,'0.KQKD'!$E36,'10. 170KMP'!Y:Y) -> #REF! | T36: =SUMIF('10. 170KMP'!$J:$J,'0.KQKD'!$E36,'10. 170KMP'!Z:Z) -> #REF! | U36: =SUM(I36:T36) -> #REF! | V36: =SUMIF('10. 170KMP'!$J:$J,'0.KQKD'!$E36,'10. 170KMP'!AB:AB) -> 57866887 | W36: =SUMIF('10. 170KMP'!$J:$J,'0.KQKD'!$E36,'10. 170KMP'!AC:AC) -> 74341222 | X36: =SUMIF('10. 170KMP'!$J:$J,'0.KQKD'!$E36,'10. 170KMP'!AD:AD) -> 156561428 | Y36: =SUMIF('10. 170KMP'!$J:$J,'0.KQKD'!$E36,'10. 170KMP'!AE:AE) -> 2.2372083e+08 | Z36: =SUMIF('10. 170KMP'!$J:$J,'0.KQKD'!$E36,'10. 170KMP'!AF:AF) -> 280012500 | AA36: =SUMIF('10. 170KMP'!$J:$J,'0.KQKD'!$E36,'10. 170KMP'!AG:AG) -> 284050000 | AB36: =SUMIF('10. 170KMP'!$J:$J,'0.KQKD'!$E36,'10. 170KMP'!AH:AH) -> 3.1427222e+08 | AC36: =SUMIF('10. 170KMP'!$J:$J,'0.KQKD'!$E36,'10. 170KMP'!AI:AI) -> 3.1717222e+08 | AD36: =SUMIF('10. 170KMP'!$J:$J,'0.KQKD'!$E36,'10. 170KMP'!AJ:AJ) -> 3.2029722e+08 | AE36: =SUMIF('10. 170KMP'!$J:$J,'0.KQKD'!$E36,'10. 170KMP'!AK:AK) -> 3.2029722e+08 | AF36: =SUMIF('10. 170KMP'!$J:$J,'0.KQKD'!$E36,'10. 170KMP'!AL:AL) -> 3.2048722e+08 | AG36: =SUMIF('10. 170KMP'!$J:$J,'0.KQKD'!$E36,'10. 170KMP'!AM:AM) -> 3.1279279e+08 | AH36: =SUM(V36:AG36) -> 2.9818718e+09 | AI36: =SUM(AJ36:AU36) -> 247537013 | AJ36: =SUMIF('10. 170KMP'!$J:$J,'0.KQKD'!$E36,'10. 170KMP'!AP:AP) -> 44138249 | AK36: =SUMIF('10. 170KMP'!$J:$J,'0.KQKD'!$E36,'10. 170KMP'!AQ:AQ) -> 43901457 | AL36: =SUMIF('10. 170KMP'!$J:$J,'0.KQKD'!$E36,'10. 170KMP'!AR:AR) -> 65626478 | AM36: =SUMIF('10. 170KMP'!$J:$J,'0.KQKD'!$E36,'10. 170KMP'!AS:AS) -> 38302564 | AN36: =SUMIF('10. 170KMP'!$J:$J,'0.KQKD'!$E36,'10. 170KMP'!AT:AT) -> 55568265 | AO36: =SUMIF('10. 170KMP'!$J:$J,'0.KQKD'!$E36,'10. 170KMP'!AU:AU) -> 0 | AP36: =SUMIF('10. 170KMP'!$J:$J,'0.KQKD'!$E36,'10. 170KMP'!AV:AV) -> 0 | AQ36: =SUMIF('10. 170KMP'!$J:$J,'0.KQKD'!$E36,'10. 170KMP'!AW:AW) -> 0 | AR36: =SUMIF('10. 170KMP'!$J:$J,'0.KQKD'!$E36,'10. 170KMP'!AX:AX) -> 0 | AS36: =SUMIF('10. 170KMP'!$J:$J,'0.KQKD'!$E36,'10. 170KMP'!AY:AY) -> 0 | AT36: =SUMIF('10. 170KMP'!$J:$J,'0.KQKD'!$E36,'10. 170KMP'!AZ:AZ) -> 0 | AU36: =SUMIF('10. 170KMP'!$J:$J,'0.KQKD'!$E36,'10. 170KMP'!BA:BA) -> 0 | AV36: =AM36 -> 38302564 | AW36: =AN36 -> 55568265 | AX36: =Z36 -> 280012500 | AY36: =IFERROR(AW36/AV36,0) -> 1.4507714 | AZ36: =IFERROR(AW36/AX36,0) -> 0.19844923 | BA36: =SUM(I36:M36) -> #REF! | BB36: =SUM(AJ36:AN36) -> 247537013 | BC36: =SUM(V36:Z36) -> 7.9250287e+08 | BD36: =IFERROR(BB36/BA36,0) -> 0 | BE36: =IFERROR(BB36/BC36,0) -> 0.31234841 | BF36: =IFERROR(BB36/AH36,0) -> 0.08301397
D37: Chi phí thử mẫu, thử khuôn, phát triển sản phẩm | E37: 14 | F37: =SUMIF('10. 170KMP'!$J:$J,'0.KQKD'!$E37,'10. 170KMP'!L:L) -> #REF! | G37: =SUMIF('10. 170KMP'!$J:$J,'0.KQKD'!$E37,'10. 170KMP'!M:M) -> #REF! | H37: =SUMIF('10. 170KMP'!$J:$J,'0.KQKD'!$E37,'10. 170KMP'!N:N) -> #REF! | I37: =SUMIF('10. 170KMP'!$J:$J,'0.KQKD'!$E37,'10. 170KMP'!O:O) -> #REF! | J37: =SUMIF('10. 170KMP'!$J:$J,'0.KQKD'!$E37,'10. 170KMP'!P:P) -> #REF! | K37: =SUMIF('10. 170KMP'!$J:$J,'0.KQKD'!$E37,'10. 170KMP'!Q:Q) -> #REF! | L37: =SUMIF('10. 170KMP'!$J:$J,'0.KQKD'!$E37,'10. 170KMP'!R:R) -> #REF! | M37: =SUMIF('10. 170KMP'!$J:$J,'0.KQKD'!$E37,'10. 170KMP'!S:S) -> #REF! | N37: =SUMIF('10. 170KMP'!$J:$J,'0.KQKD'!$E37,'10. 170KMP'!T:T) -> #REF! | O37: =SUMIF('10. 170KMP'!$J:$J,'0.KQKD'!$E37,'10. 170KMP'!U:U) -> #REF! | P37: =SUMIF('10. 170KMP'!$J:$J,'0.KQKD'!$E37,'10. 170KMP'!V:V) -> #REF! | Q37: =SUMIF('10. 170KMP'!$J:$J,'0.KQKD'!$E37,'10. 170KMP'!W:W) -> #REF! | R37: =SUMIF('10. 170KMP'!$J:$J,'0.KQKD'!$E37,'10. 170KMP'!X:X) -> #REF! | S37: =SUMIF('10. 170KMP'!$J:$J,'0.KQKD'!$E37,'10. 170KMP'!Y:Y) -> #REF! | T37: =SUMIF('10. 170KMP'!$J:$J,'0.KQKD'!$E37,'10. 170KMP'!Z:Z) -> #REF! | U37: =SUM(I37:T37) -> #REF! | V37: =SUMIF('10. 170KMP'!$J:$J,'0.KQKD'!$E37,'10. 170KMP'!AB:AB) -> 0 | W37: =SUMIF('10. 170KMP'!$J:$J,'0.KQKD'!$E37,'10. 170KMP'!AC:AC) -> 0 | X37: =SUMIF('10. 170KMP'!$J:$J,'0.KQKD'!$E37,'10. 170KMP'!AD:AD) -> 0 | Y37: =SUMIF('10. 170KMP'!$J:$J,'0.KQKD'!$E37,'10. 170KMP'!AE:AE) -> 0 | Z37: =SUMIF('10. 170KMP'!$J:$J,'0.KQKD'!$E37,'10. 170KMP'!AF:AF) -> 0 | AA37: =SUMIF('10. 170KMP'!$J:$J,'0.KQKD'!$E37,'10. 170KMP'!AG:AG) -> 0 | AB37: =SUMIF('10. 170KMP'!$J:$J,'0.KQKD'!$E37,'10. 170KMP'!AH:AH) -> 0 | AC37: =SUMIF('10. 170KMP'!$J:$J,'0.KQKD'!$E37,'10. 170KMP'!AI:AI) -> 0 | AD37: =SUMIF('10. 170KMP'!$J:$J,'0.KQKD'!$E37,'10. 170KMP'!AJ:AJ) -> 0 | AE37: =SUMIF('10. 170KMP'!$J:$J,'0.KQKD'!$E37,'10. 170KMP'!AK:AK) -> 0 | AF37: =SUMIF('10. 170KMP'!$J:$J,'0.KQKD'!$E37,'10. 170KMP'!AL:AL) -> 0 | AG37: =SUMIF('10. 170KMP'!$J:$J,'0.KQKD'!$E37,'10. 170KMP'!AM:AM) -> 0 | AH37: =SUM(V37:AG37) -> 0 | AI37: =SUM(AJ37:AU37) -> 0 | AJ37: =SUMIF('10. 170KMP'!$J:$J,'0.KQKD'!$E37,'10. 170KMP'!AP:AP) -> 0 | AK37: =SUMIF('10. 170KMP'!$J:$J,'0.KQKD'!$E37,'10. 170KMP'!AQ:AQ) -> 0 | AL37: =SUMIF('10. 170KMP'!$J:$J,'0.KQKD'!$E37,'10. 170KMP'!AR:AR) -> 0 | AM37: =SUMIF('10. 170KMP'!$J:$J,'0.KQKD'!$E37,'10. 170KMP'!AS:AS) -> 0 | AN37: =SUMIF('10. 170KMP'!$J:$J,'0.KQKD'!$E37,'10. 170KMP'!AT:AT) -> 0 | AO37: =SUMIF('10. 170KMP'!$J:$J,'0.KQKD'!$E37,'10. 170KMP'!AU:AU) -> 0 | AP37: =SUMIF('10. 170KMP'!$J:$J,'0.KQKD'!$E37,'10. 170KMP'!AV:AV) -> 0 | AQ37: =SUMIF('10. 170KMP'!$J:$J,'0.KQKD'!$E37,'10. 170KMP'!AW:AW) -> 0 | AR37: =SUMIF('10. 170KMP'!$J:$J,'0.KQKD'!$E37,'10. 170KMP'!AX:AX) -> 0 | AS37: =SUMIF('10. 170KMP'!$J:$J,'0.KQKD'!$E37,'10. 170KMP'!AY:AY) -> 0 | AT37: =SUMIF('10. 170KMP'!$J:$J,'0.KQKD'!$E37,'10. 170KMP'!AZ:AZ) -> 0 | AU37: =SUMIF('10. 170KMP'!$J:$J,'0.KQKD'!$E37,'10. 170KMP'!BA:BA) -> 0 | AV37: =AM37 -> 0 | AW37: =AN37 -> 0 | AX37: =Z37 -> 0 | AY37: =IFERROR(AW37/AV37,0) -> 0 | AZ37: =IFERROR(AW37/AX37,0) -> 0 | BA37: =SUM(I37:M37) -> #REF! | BB37: =SUM(AJ37:AN37) -> 0 | BC37: =SUM(V37:Z37) -> 0 | BD37: =IFERROR(BB37/BA37,0) -> 0 | BE37: =IFERROR(BB37/BC37,0) -> 0 | BF37: =IFERROR(BB37/AH37,0) -> 0
